{"event": "subscribe", "arg": {"channel": "books", "instId": "BTC-USDT"}, "connId": "bcfdcf0f"}
{"arg": {"channel": "books", "instId": "BTC-USDT"}, "action": "snapshot", "data": [{"asks": [["88490", "0.03174759", "0", "4"], ["88490.1", "0.00069028", "0", "3"], ["88490.3", "0.0000637", "0", "1"], ["88490.8", "0.00001117", "0", "1"], ["88491.3", "0.00294232", "0", "1"], ["88491.5", "0.00004369", "0", "1"], ["88492", "0.0155", "0", "1"], ["88492.1", "0.00002611", "0", "1"], ["88492.4", "0.00001", "0", "1"], ["88492.5", "0.01", "0", "2"], ["88492.6", "0.002", "0", "1"], ["88492.7", "0.0001", "0", "1"], ["88493", "0.00011024", "0", "2"], ["88493.2", "0.00002708", "0", "2"], ["88493.3", "0.00001653", "0", "1"], ["88493.8", "0.00002958", "0", "2"], ["88494", "0.0164", "0", "1"], ["88494.1", "0.00004943", "0", "1"], ["88494.3", "0.03986541", "0", "1"], ["88494.4", "0.11299924", "0", "1"], ["88494.6", "0.00107012", "0", "4"], ["88495.2", "0.00003551", "0", "1"], ["88496", "0.0164", "0", "1"], ["88496.1", "0.00020109", "0", "2"], ["88496.2", "0.00001203", "0", "1"], ["88496.3", "0.0000204", "0", "2"], ["88496.5", "0.00001068", "0", "1"], ["88496.6", "0.00119834", "0", "2"], ["88497.1", "0.000911", "0", "2"], ["88497.2", "0.0000263", "0", "1"], ["88497.4", "0.06124064", "0", "2"], ["88497.5", "0.0306765", "0", "2"], ["88497.7", "0.00006", "0", "1"], ["88498.4", "0.03062032", "0", "1"], ["88498.5", "0.00001402", "0", "1"], ["88498.7", "0.00001833", "0", "1"], ["88499.5", "0.42973541", "0", "1"], ["88499.8", "0.00452168", "0", "2"], ["88499.9", "0.00189006", "0", "13"], ["88500", "1.09280095", "0", "200"], ["88500.5", "0.00011869", "0", "1"], ["88500.8", "0.00025", "0", "1"], ["88500.9", "0.01363486", "0", "2"], ["88501", "0.00006989", "0", "1"], ["88501.7", "0.0000114", "0", "1"], ["88502.1", "0.01385832", "0", "2"], ["88502.3", "0.00001", "0", "1"], ["88502.5", "0.000015", "0", "1"], ["88502.6", "0.14012249", "0", "2"], ["88503.2", "0.00033134", "0", "12"], ["88503.5", "0.00001057", "0", "1"], ["88503.9", "0.00001666", "0", "1"], ["88504.4", "0.34065911", "0", "2"], ["88504.6", "0.00001", "0", "1"], ["88505.1", "0.0001034", "0", "4"], ["88505.2", "0.01865935", "0", "2"], ["88505.4", "0.00003147", "0", "2"], ["88505.5", "0.04506989", "0", "2"], ["88505.6", "0.0004229", "0", "2"], ["88506.2", "0.07196676", "0", "2"], ["88506.3", "0.00003702", "0", "2"], ["88506.6", "0.00001007", "0", "1"], ["88506.9", "0.051", "0", "1"], ["88507.1", "0.00001265", "0", "1"], ["88507.3", "0.01228601", "0", "5"], ["88507.4", "0.01129871", "0", "1"], ["88508.4", "0.00028226", "0", "5"], ["88508.9", "0.0000123", "0", "1"], ["88509", "0.00001063", "0", "1"], ["88509.3", "0.0000114", "0", "1"], ["88509.8", "0.00001014", "0", "1"], ["88510.4", "0.31571083", "0", "5"], ["88510.5", "0.00001038", "0", "1"], ["88510.6", "0.00001016", "0", "1"], ["88510.7", "0.00005172", "0", "1"], ["88510.8", "0.128225", "0", "2"], ["88510.9", "0.0019077", "0", "10"], ["88511", "0.00005648", "0", "1"], ["88511.1", "0.00001035", "0", "1"], ["88511.2", "0.04085012", "0", "2"], ["88511.5", "0.0188839", "0", "1"], ["88511.6", "0.00001009", "0", "1"], ["88511.7", "0.00791791", "0", "1"], ["88511.9", "0.00011512", "0", "2"], ["88512.2", "0.00001155", "0", "1"], ["88512.7", "0.00022607", "0", "1"], ["88512.8", "0.0000311", "0", "1"], ["88512.9", "0.00162386", "0", "1"], ["88513", "0.01357284", "0", "1"], ["88513.3", "0.00003735", "0", "3"], ["88514", "0.01846384", "0", "2"], ["88514.1", "0.207", "0", "1"], ["88514.2", "0.00003161", "0", "2"], ["88514.4", "0.11298877", "0", "2"], ["88514.5", "0.00086796", "0", "10"], ["88514.6", "0.00009813", "0", "1"], ["88514.8", "0.56780627", "0", "1"], ["88515", "0.00012123", "0", "1"], ["88515.2", "0.90244663", "0", "1"], ["88515.3", "0.18391502", "0", "1"], ["88515.4", "0.04", "0", "1"], ["88515.5", "0.00007", "0", "1"], ["88516.1", "0.00450749", "0", "1"], ["88516.3", "0.147132", "0", "2"], ["88516.4", "0.00097792", "0", "19"], ["88516.6", "0.00528366", "0", "4"], ["88516.7", "0.11297085", "0", "1"], ["88517", "0.00014778", "0", "1"], ["88517.1", "0.02259832", "0", "1"], ["88517.2", "0.00003114", "0", "3"], ["88517.3", "0.11343045", "0", "1"], ["88517.5", "0.00039794", "0", "1"], ["88517.9", "0.183915", "0", "1"], ["88518", "0.00001", "0", "1"], ["88518.5", "0.00006981", "0", "2"], ["88518.6", "0.34056098", "0", "1"], ["88518.7", "0.00204517", "0", "15"], ["88518.8", "0.00003082", "0", "3"], ["88519.6", "0.66704711", "0", "2"], ["88519.8", "1.6190241", "0", "1"], ["88520", "0.00132605", "0", "7"], ["88520.4", "0.00835442", "0", "1"], ["88520.6", "0.00083", "0", "1"], ["88520.7", "0.447736", "0", "1"], ["88521.1", "0.0002264", "0", "1"], ["88521.7", "0.00139857", "0", "3"], ["88521.9", "0.00001028", "0", "1"], ["88522.3", "0.00040563", "0", "4"], ["88522.4", "0.0001407", "0", "4"], ["88522.7", "0.00061748", "0", "1"], ["88522.9", "0.00083", "0", "1"], ["88523", "0.207", "0", "1"], ["88523.2", "0.000015", "0", "1"], ["88523.3", "0.00001021", "0", "1"], ["88523.7", "0.31356546", "0", "1"], ["88523.8", "0.04023979", "0", "4"], ["88524.1", "0.00001636", "0", "1"], ["88524.3", "0.00003088", "0", "2"], ["88524.4", "0.00001314", "0", "1"], ["88524.5", "0.00001006", "0", "1"], ["88525", "0.00005642", "0", "2"], ["88525.3", "0.00001147", "0", "1"], ["88525.5", "0.00083", "0", "1"], ["88526.2", "0.0018169", "0", "3"], ["88526.3", "0.00001053", "0", "1"], ["88526.4", "0.00006179", "0", "2"], ["88526.6", "0.00002533", "0", "1"], ["88526.7", "0.00019019", "0", "6"], ["88527.1", "0.0000102", "0", "1"], ["88527.3", "0.22602747", "0", "2"], ["88527.4", "0.147132", "0", "2"], ["88528", "0.91245986", "0", "3"], ["88528.1", "0.49801102", "0", "2"], ["88528.4", "0.00029378", "0", "2"], ["88528.5", "0.0052", "0", "1"], ["88528.6", "0.00045714", "0", "1"], ["88529", "1.00001678", "0", "2"], ["88529.4", "0.34056098", "0", "1"], ["88529.6", "0.00003358", "0", "2"], ["88529.8", "0.00002635", "0", "2"], ["88529.9", "0.00003508", "0", "2"], ["88530", "0.12009419", "0", "6"], ["88530.1", "0.00001295", "0", "1"], ["88530.3", "0.03742653", "0", "1"], ["88530.4", "0.00015135", "0", "7"], ["88530.6", "0.00001446", "0", "1"], ["88530.8", "0.00001156", "0", "1"], ["88531", "0.03", "0", "1"], ["88531.3", "0.00001896", "0", "1"], ["88531.7", "0.00010983", "0", "2"], ["88531.9", "0.2072131", "0", "3"], ["88532", "0.000015", "0", "1"], ["88532.3", "0.00011329", "0", "1"], ["88532.4", "0.00037328", "0", "1"], ["88532.8", "0.14506699", "0", "1"], ["88532.9", "0.00002239", "0", "2"], ["88533.3", "0.01783903", "0", "18"], ["88533.4", "0.00026258", "0", "2"], ["88533.5", "0.00001131", "0", "1"], ["88533.6", "0.0006568", "0", "3"], ["88533.7", "0.02258982", "0", "1"], ["88533.9", "0.00004614", "0", "1"], ["88534", "0.00001007", "0", "1"], ["88534.4", "0.00031094", "0", "2"], ["88534.5", "0.00008095", "0", "4"], ["88534.8", "0.21796933", "0", "2"], ["88534.9", "0.00001003", "0", "1"], ["88535.1", "0.11343045", "0", "1"], ["88535.2", "0.00012748", "0", "1"], ["88535.5", "0.00037194", "0", "10"], ["88535.7", "0.0000114", "0", "1"], ["88535.8", "0.00026192", "0", "1"], ["88535.9", "0.00025932", "0", "1"], ["88536.4", "0.00019692", "0", "2"], ["88536.7", "0.00001", "0", "1"], ["88537", "0.00005129", "0", "1"], ["88537.1", "0.24771912", "0", "27"], ["88537.2", "0.00007282", "0", "1"], ["88537.3", "0.00002092", "0", "1"], ["88537.5", "0.00002316", "0", "2"], ["88538.1", "0.00007794", "0", "3"], ["88538.3", "0.00124659", "0", "9"], ["88538.4", "0.14741614", "0", "6"], ["88539.6", "0.00031761", "0", "2"], ["88539.9", "0.00003598", "0", "1"], ["88540", "0.00503926", "0", "4"], ["88540.1", "0.00003293", "0", "1"], ["88540.2", "0.00007853", "0", "1"], ["88540.3", "0.00083", "0", "1"], ["88540.5", "0.00072792", "0", "3"], ["88540.6", "0.24740518", "0", "1"], ["88540.8", "0.207015", "0", "2"], ["88540.9", "0.0052", "0", "1"], ["88541", "0.00004407", "0", "3"], ["88541.1", "0.498074", "0", "1"], ["88541.2", "0.000015", "0", "1"], ["88541.5", "0.00001152", "0", "1"], ["88541.6", "0.0004477", "0", "2"], ["88541.7", "0.00002123", "0", "2"], ["88541.8", "0.02258776", "0", "1"], ["88542.1", "0.00010289", "0", "1"], ["88542.2", "0.00026414", "0", "4"], ["88542.3", "0.00005413", "0", "1"], ["88542.9", "0.03", "0", "1"], ["88543", "0.00007419", "0", "2"], ["88543.2", "0.01", "0", "1"], ["88543.3", "0.39102338", "0", "2"], ["88543.4", "0.90355708", "0", "3"], ["88543.5", "0.00001124", "0", "1"], ["88543.6", "0.34056098", "0", "1"], ["88543.7", "0.00001033", "0", "1"], ["88543.9", "0.00001817", "0", "1"], ["88544", "0.00084248", "0", "2"], ["88544.1", "0.05654459", "0", "2"], ["88544.3", "0.00012172", "0", "2"], ["88544.5", "0.00111578", "0", "1"], ["88544.6", "0.00040015", "0", "2"], ["88544.8", "0.00001536", "0", "1"], ["88545.1", "0.49806283", "0", "2"], ["88545.2", "0.00002513", "0", "1"], ["88545.4", "0.00013356", "0", "4"], ["88545.5", "0.00001035", "0", "1"], ["88545.9", "0.00007302", "0", "1"], ["88546", "0.00011484", "0", "3"], ["88546.3", "0.00013676", "0", "1"], ["88546.4", "0.00026336", "0", "7"], ["88546.5", "0.00001", "0", "1"], ["88546.6", "0.00001512", "0", "1"], ["88546.8", "0.26425293", "0", "2"], ["88546.9", "0.44619", "0", "1"], ["88547", "0.00001139", "0", "1"], ["88547.7", "0.00738035", "0", "1"], ["88547.8", "0.0000129", "0", "1"], ["88548", "0.00018353", "0", "1"], ["88548.1", "0.00001011", "0", "1"], ["88548.2", "0.00002329", "0", "1"], ["88548.3", "0.00048118", "0", "4"], ["88548.4", "0.00002745", "0", "2"], ["88548.8", "0.00001", "0", "1"], ["88549", "0.00006618", "0", "2"], ["88549.3", "0.00004828", "0", "1"], ["88549.5", "0.147132", "0", "2"], ["88549.6", "0.100015", "0", "2"], ["88549.7", "0.207", "0", "1"], ["88549.9", "0.00076516", "0", "6"], ["88550", "0.00109016", "0", "9"], ["88550.2", "0.21893609", "0", "1"], ["88550.3", "0.06406", "0", "1"], ["88550.7", "0.00003658", "0", "1"], ["88550.8", "2.94728807", "0", "1"], ["88551", "0.00003451", "0", "2"], ["88551.3", "0.00001204", "0", "1"], ["88551.6", "0.0000114", "0", "1"], ["88551.8", "0.00001097", "0", "1"], ["88552", "0.00023792", "0", "2"], ["88552.1", "0.00137118", "0", "1"], ["88552.6", "0.1", "0", "1"], ["88552.8", "0.00001007", "0", "1"], ["88552.9", "0.01129269", "0", "1"], ["88553.3", "0.56190084", "0", "1"], ["88553.9", "0.00001014", "0", "1"], ["88554", "0.000035", "0", "1"], ["88554.1", "0.00001148", "0", "1"], ["88554.2", "0.00070666", "0", "2"], ["88554.4", "0.001296", "0", "2"], ["88554.6", "0.00199223", "0", "5"], ["88555", "0.2915477", "0", "4"], ["88555.1", "0.00001032", "0", "1"], ["88555.2", "0.00570893", "0", "3"], ["88555.3", "0.00016236", "0", "2"], ["88555.5", "0.0007951", "0", "5"], ["88555.7", "0.00112923", "0", "1"], ["88556", "0.00001349", "0", "1"], ["88556.5", "0.00004488", "0", "2"], ["88556.6", "0.00083", "0", "1"], ["88556.7", "0.000345", "0", "1"], ["88557.7", "0.00083", "0", "1"], ["88557.8", "0.34056098", "0", "1"], ["88558", "0.00055957", "0", "4"], ["88558.2", "0.00574872", "0", "2"], ["88558.3", "0.0000114", "0", "1"], ["88558.4", "0.000015", "0", "1"], ["88558.6", "0.207", "0", "1"], ["88558.8", "0.00001001", "0", "1"], ["88559", "0.00003008", "0", "1"], ["88559.4", "0.00032673", "0", "1"], ["88559.5", "0.00008048", "0", "3"], ["88559.7", "0.24276", "0", "1"], ["88559.8", "0.00001637", "0", "1"], ["88559.9", "0.01740138", "0", "1"], ["88560", "0.00474113", "0", "6"], ["88560.1", "0.00017777", "0", "3"], ["88560.4", "0.00031641", "0", "2"], ["88560.6", "0.01693795", "0", "1"], ["88560.9", "0.0005061", "0", "12"], ["88561.1", "0.0000134", "0", "1"], ["88561.6", "0.11343045", "0", "1"], ["88562", "0.00003029", "0", "2"], ["88562.2", "0.00001021", "0", "1"], ["88562.7", "0.00003921", "0", "2"], ["88562.9", "0.00560051", "0", "1"], ["88563", "0.00237119", "0", "1"], ["88563.6", "0.00001026", "0", "1"], ["88564", "0.00001139", "0", "1"], ["88564.9", "0.00001626", "0", "1"], ["88565.2", "0.00020897", "0", "2"], ["88565.5", "0.0000112", "0", "1"], ["88565.6", "0.00001088", "0", "1"], ["88565.7", "0.00001139", "0", "1"], ["88565.8", "0.00002084", "0", "2"], ["88565.9", "0.0000114", "0", "1"], ["88566.4", "0.00570052", "0", "1"], ["88566.5", "0.63068237", "0", "1"], ["88566.6", "0.00368388", "0", "9"], ["88566.8", "0.0000907", "0", "1"], ["88567.2", "0.000015", "0", "1"], ["88567.4", "0.00560051", "0", "1"], ["88567.5", "0.207", "0", "1"], ["88567.9", "0.00001005", "0", "1"], ["88568.1", "0.00007008", "0", "2"], ["88568.3", "0.0399405", "0", "1"], ["88568.7", "0.00600426", "0", "2"], ["88568.8", "0.00191408", "0", "1"], ["88568.9", "0.03005367", "0", "3"], ["88569", "0.0000615", "0", "1"], ["88569.4", "0.00292156", "0", "1"], ["88569.8", "0.00560051", "0", "1"], ["88569.9", "0.34068508", "0", "3"], ["88570.4", "0.0000191", "0", "1"], ["88570.9", "0.01571364", "0", "2"], ["88571.1", "0.49884", "0", "1"], ["88571.3", "0.21205244", "0", "1"], ["88571.4", "0.01558794", "0", "21"], ["88571.5", "0.00026029", "0", "3"], ["88571.6", "0.00003981", "0", "1"], ["88571.7", "0.03", "0", "1"], ["88571.8", "0.75255252", "0", "2"], ["88572", "0.03020483", "0", "1"], ["88572.1", "0.03", "0", "1"], ["88572.2", "0.00001253", "0", "1"], ["88572.4", "0.00453294", "0", "2"], ["88572.5", "0.00452139", "0", "1"], ["88573.1", "0.00002277", "0", "1"], ["88574", "0.00001006", "0", "1"], ["88574.3", "0.00001009", "0", "1"], ["88574.4", "0.00015275", "0", "4"], ["88574.6", "0.00560051", "0", "1"], ["88574.7", "0.746827", "0", "1"], ["88575", "0.0000626", "0", "2"], ["88575.1", "0.00024988", "0", "1"], ["88575.3", "0.01056929", "0", "3"], ["88575.7", "0.00011584", "0", "1"], ["88575.9", "0.00001673", "0", "1"], ["88576", "0.0132977", "0", "3"], ["88576.1", "0.00001765", "0", "1"], ["88576.3", "0.00570052", "0", "1"], ["88576.4", "0.207", "0", "1"], ["88576.8", "0.02161136", "0", "3"], ["88576.9", "0.01155915", "0", "2"], ["88577.5", "0.09918502", "0", "1"], ["88577.6", "0.00004084", "0", "4"], ["88577.8", "0.00014237", "0", "1"], ["88578.1", "0.00009546", "0", "3"], ["88578.8", "0.00011937", "0", "1"], ["88578.9", "0.00548888", "0", "2"], ["88579", "0.00276168", "0", "4"], ["88579.1", "0.0398225", "0", "1"], ["88579.5", "0.00019186", "0", "2"], ["88579.6", "0.00002913", "0", "1"], ["88579.8", "0.00001056", "0", "1"], ["88579.9", "0.00606981", "0", "3"], ["88580", "0.03", "0", "1"], ["88580.3", "0.00037848", "0", "1"], ["88580.5", "0.00002973", "0", "1"], ["88580.7", "0.00311789", "0", "1"], ["88580.8", "0.00005364", "0", "1"], ["88581", "0.00017534", "0", "2"], ["88581.3", "0.00004102", "0", "1"], ["88581.7", "0.00019458", "0", "5"], ["88581.8", "0.00010363", "0", "4"]], "bids": [["88489.9", "0.2346761", "0", "10"], ["88488.7", "0.08562464", "0", "1"], ["88488.5", "0.02948328", "0", "1"], ["88488.3", "0.02948328", "0", "1"], ["88488.2", "0.11300709", "0", "1"], ["88488", "0.0155", "0", "1"], ["88487.6", "0.00224308", "0", "1"], ["88487.4", "0.00937", "0", "1"], ["88486", "0.0155", "0", "1"], ["88484.2", "0.03062032", "0", "1"], ["88484.1", "0.03062032", "0", "1"], ["88484", "0.0155", "0", "1"], ["88482.7", "0.00145491", "0", "1"], ["88482.6", "0.04", "0", "1"], ["88482.1", "0.07781416", "0", "2"], ["88481.7", "0.05194673", "0", "2"], ["88480.8", "0.0001", "0", "1"], ["88480.7", "0.0001", "0", "1"], ["88480.5", "0.11301694", "0", "1"], ["88480.4", "0.02813", "0", "1"], ["88480.1", "0.00002624", "0", "1"], ["88480", "0.06247009", "0", "5"], ["88479.1", "0.00001138", "0", "1"], ["88478.9", "0.2815362", "0", "1"], ["88478.8", "0.33906", "0", "1"], ["88478.2", "0.01861722", "0", "1"], ["88478", "0.0172", "0", "1"], ["88477.6", "0.000015", "0", "1"], ["88477.1", "0.33907", "0", "1"], ["88476.5", "0.00734628", "0", "1"], ["88476", "0.0172", "0", "1"], ["88475.6", "0.02259881", "0", "1"], ["88475.1", "0.64644062", "0", "1"], ["88475", "1.10244663", "0", "2"], ["88474", "0.0172", "0", "1"], ["88473.4", "0.00001138", "0", "1"], ["88472.9", "0.00937", "0", "1"], ["88472.4", "0.05650882", "0", "1"], ["88472.1", "0.00734628", "0", "1"], ["88472", "0.0172", "0", "1"], ["88471.9", "0.11301981", "0", "3"], ["88471.4", "0.04", "0", "1"], ["88471.1", "0.207", "0", "1"], ["88471", "0.33929724", "0", "1"], ["88470.8", "0.78136204", "0", "2"], ["88470", "1.0172", "0", "2"], ["88469.8", "0.01650401", "0", "1"], ["88469.7", "0.06", "0", "2"], ["88468.9", "0.00198343", "0", "1"], ["88468.8", "0.00001501", "0", "1"], ["88468.6", "0.22600208", "0", "1"], ["88468.5", "1.60573679", "0", "1"], ["88467.8", "0.00001138", "0", "1"], ["88466.6", "0.00057148", "0", "1"], ["88466.2", "0.12", "0", "4"], ["88466.1", "0.39951597", "0", "1"], ["88465.1", "0.98787554", "0", "2"], ["88463.5", "0.128239", "0", "1"], ["88462.4", "0.0006", "0", "2"], ["88462.1", "0.00001138", "0", "1"], ["88462", "0.25159926", "0", "1"], ["88461.9", "0.05194673", "0", "2"], ["88461.6", "0.00029879", "0", "1"], ["88461.2", "0.33929724", "0", "1"], ["88461.1", "0.147132", "0", "2"], ["88460.8", "0.02260842", "0", "1"], ["88460", "0.000015", "0", "1"], ["88459.2", "0.1130441", "0", "1"], ["88458.1", "0.01178373", "0", "2"], ["88457.6", "0.90059292", "0", "1"], ["88457.1", "0.498547", "0", "1"], ["88456.5", "0.00001138", "0", "1"], ["88456.1", "0.90244663", "0", "1"], ["88455.8", "0.30873931", "0", "5"], ["88455.5", "0.18391502", "0", "1"], ["88455.3", "0.183915", "0", "1"], ["88454.7", "0.20567", "0", "1"], ["88453.8", "0.11343045", "0", "1"], ["88453.2", "0.15391788", "0", "1"], ["88452.3", "0.00678331", "0", "1"], ["88452.2", "0.04520742", "0", "1"], ["88452", "0.00016958", "0", "1"], ["88451.8", "0.33929724", "0", "1"], ["88451.2", "0.000015", "0", "1"], ["88450.8", "0.00001139", "0", "1"], ["88450", "0.207132", "0", "4"], ["88449.9", "0.00057148", "0", "1"], ["88449", "0.06", "0", "2"], ["88448", "0.03", "0", "1"], ["88447.9", "0.002", "0", "1"], ["88446.9", "0.207", "0", "1"], ["88446.6", "0.65025471", "0", "1"], ["88446.5", "0.30754406", "0", "1"], ["88445.9", "0.90244663", "0", "1"], ["88445.4", "0.01129261", "0", "1"], ["88445.1", "0.00001139", "0", "1"], ["88445", "0.00001", "0", "1"], ["88444.6", "0.946211", "0", "2"], ["88444.2", "0.32811833", "0", "3"], ["88443.8", "0.02075056", "0", "1"], ["88443.2", "0.1", "0", "1"], ["88443", "0.43181", "0", "1"], ["88442.4", "0.000015", "0", "1"], ["88441.3", "0.33929724", "0", "1"], ["88439.8", "0.49945342", "0", "1"], ["88439.5", "0.00001139", "0", "1"], ["88439", "0.147132", "0", "2"], ["88437.9", "0.02261427", "0", "1"], ["88437.8", "0.47921", "0", "1"], ["88437.4", "0.01740138", "0", "1"], ["88437.3", "0.002", "0", "1"], ["88436.6", "0.02698183", "0", "1"], ["88436.2", "0.11343045", "0", "1"], ["88436.1", "0.90244663", "0", "1"], ["88435", "0.29944629", "0", "1"], ["88434.9", "0.06349", "0", "1"], ["88433.8", "0.21830525", "0", "3"], ["88433.6", "0.000015", "0", "1"], ["88433.3", "0.00057148", "0", "1"], ["88432.9", "0.01696241", "0", "1"], ["88432.1", "0.08196", "0", "1"], ["88432", "0.33929724", "0", "1"], ["88431.9", "0.05194673", "0", "2"], ["88430.8", "0.03495586", "0", "1"], ["88430.6", "0.25964719", "0", "1"], ["88430.5", "0.54717517", "0", "3"], ["88430.1", "0.08542891", "0", "1"], ["88429.5", "0.01672", "0", "1"], ["88428.2", "0.00001139", "0", "1"], ["88427.9", "0.147132", "0", "2"], ["88427.6", "0.01129386", "0", "1"], ["88426.7", "0.0010271", "0", "1"], ["88426.6", "0.11343045", "0", "1"], ["88426.5", "1.81723691", "0", "2"], ["88426.4", "0.90244663", "0", "1"], ["88424.8", "0.000015", "0", "1"], ["88424.6", "2.12624221", "0", "1"], ["88423", "0.237", "0", "2"], ["88422.9", "0.33929724", "0", "1"], ["88422.6", "0.00343", "0", "1"], ["88422.5", "2.86408323", "0", "2"], ["88422.3", "0.01129417", "0", "1"], ["88421.8", "0.06", "0", "2"], ["88421.2", "0.03", "0", "1"], ["88420.5", "0.23542423", "0", "1"], ["88420.4", "0.33929", "0", "1"], ["88419.9", "0.01", "0", "2"], ["88419.4", "0.00098743", "0", "1"], ["88419.3", "0.43447", "0", "1"], ["88417.7", "0.39475395", "0", "1"], ["88416.9", "0.147132", "0", "2"], ["88416.8", "0.00001139", "0", "1"], ["88416.6", "0.00057148", "0", "1"], ["88416.2", "0.90244663", "0", "1"], ["88416", "0.748182", "0", "2"], ["88415.7", "0.03", "0", "1"], ["88413.6", "0.00019382", "0", "1"], ["88413.5", "0.11343045", "0", "1"], ["88412.4", "0.00001148", "0", "1"], ["88412.1", "0.207", "0", "1"], ["88411.5", "0.016", "0", "1"], ["88411.3", "0.57929724", "0", "2"], ["88411.2", "0.00001139", "0", "1"], ["88410", "0.08542891", "0", "1"], ["88409.6", "2.88024", "0", "1"], ["88408.8", "0.01903243", "0", "1"], ["88408.1", "0.01096169", "0", "1"], ["88407.2", "0.000015", "0", "1"], ["88407", "0.90246163", "0", "2"], ["88405.9", "0.00093027", "0", "1"], ["88405.5", "0.00001139", "0", "1"], ["88405.3", "0.05194673", "0", "2"], ["88403.9", "0.02260371", "0", "1"], ["88403.6", "0.00548084", "0", "1"], ["88402.8", "0.00565035", "0", "1"], ["88402.7", "0.74828", "0", "1"], ["88402.3", "0.05194673", "0", "2"], ["88402.1", "0.207", "0", "1"], ["88400.5", "0.00565035", "0", "1"], ["88400.4", "0.05194673", "0", "2"], ["88400.2", "0.33929724", "0", "1"], ["88399.9", "0.05655808", "0", "6"], ["88399.7", "0.0565601", "0", "1"], ["88399.3", "0.05194673", "0", "2"], ["88399.2", "0.00548084", "0", "1"], ["88398.8", "0.01804", "0", "1"], ["88398.4", "0.000015", "0", "1"], ["88397.7", "0.11343045", "0", "1"], ["88394.2", "0.00001139", "0", "1"], ["88393.2", "0.08485", "0", "1"], ["88391.8", "0.01071209", "0", "2"], ["88391", "0.207", "0", "1"], ["88389.8", "0.33929724", "0", "1"], ["88389.6", "0.00001501", "0", "1"], ["88389.4", "2.16256986", "0", "1"], ["88389.3", "0.08542891", "0", "1"], ["88388.6", "0.00001139", "0", "1"], ["88387.8", "0.00115031", "0", "1"], ["88386.7", "0.1", "0", "1"], ["88384.2", "0.00565142", "0", "1"], ["88383.9", "0.77200148", "0", "2"], ["88383.3", "0.00057148", "0", "1"], ["88382.9", "0.00001139", "0", "1"], ["88381.8", "0.00560013", "0", "1"], ["88381.7", "0.00452139", "0", "1"], ["88381.5", "0.207", "0", "1"], ["88380.8", "0.00001501", "0", "1"], ["88380.5", "0.06876194", "0", "2"], ["88380.3", "0.11343045", "0", "1"], ["88379.2", "0.33929724", "0", "1"], ["88379.1", "0.1", "0", "1"], ["88378.8", "0.03", "0", "1"], ["88378.7", "0.00452139", "0", "1"], ["88378.6", "0.00452148", "0", "1"], ["88377.2", "0.00453254", "0", "2"], ["88376", "0.0339297", "0", "1"], ["88375.9", "0.01232", "0", "1"], ["88375.5", "0.01690206", "0", "1"], ["88375.3", "0.09", "0", "3"], ["88375.2", "0.09855368", "0", "1"], ["88372.8", "0.00452139", "0", "1"], ["88372.7", "0.03569987", "0", "2"], ["88372.2", "0.05647078", "0", "2"], ["88372", "0.000015", "0", "1"], ["88371.6", "0.0000114", "0", "1"], ["88371.3", "0.207", "0", "1"], ["88370.5", "0.03", "0", "1"], ["88370.1", "0.00452171", "0", "1"], ["88369.7", "0.00170703", "0", "1"], ["88369.5", "0.1", "0", "1"], ["88368.2", "0.33929724", "0", "1"], ["88366.7", "0.00212677", "0", "1"], ["88366.6", "0.00057148", "0", "1"], ["88366.3", "3.22004", "0", "1"], ["88366.2", "0.02260296", "0", "1"], ["88365.9", "0.0000114", "0", "1"], ["88365.7", "2.85388", "0", "1"], ["88365", "0.00452202", "0", "1"], ["88364", "0.11343045", "0", "1"], ["88363.6", "0.00003889", "0", "1"], ["88363.3", "0.00623578", "0", "1"], ["88363.2", "0.203598", "0", "2"], ["88362.8", "0.000015", "0", "1"], ["88361.6", "0.17401523", "0", "1"], ["88361.5", "0.207", "0", "1"], ["88361.2", "0.08542891", "0", "1"], ["88360.3", "0.0000114", "0", "1"], ["88360.1", "0.08487", "0", "1"], ["88359.6", "0.00565083", "0", "1"], ["88358.1", "0.33929724", "0", "1"], ["88355.4", "0.01658826", "0", "1"], ["88354.6", "0.0000114", "0", "1"], ["88354.5", "0.00935368", "0", "1"], ["88354.4", "0.000015", "0", "1"], ["88353.3", "0.00009543", "0", "1"], ["88352.1", "0.00001", "0", "1"], ["88352", "0.06666822", "0", "1"], ["88351.8", "0.11318155", "0", "1"], ["88350.1", "0.207", "0", "1"], ["88350", "0.00113152", "0", "1"], ["88349.9", "0.00368044", "0", "2"], ["88349", "0.0000114", "0", "1"], ["88347.3", "0.11343045", "0", "1"], ["88347.2", "0.33929724", "0", "1"], ["88347.1", "0.25455", "0", "1"], ["88346.8", "0.0052", "0", "1"], ["88345.9", "0.2334614", "0", "1"], ["88345.6", "0.000015", "0", "1"], ["88345.3", "0.01129386", "0", "1"], ["88344.5", "0.05088726", "0", "1"], ["88343.7", "0.174079", "0", "1"], ["88343.3", "0.0000114", "0", "1"], ["88341.9", "0.01695249", "0", "3"], ["88341.6", "0.00001148", "0", "1"], ["88339", "0.207", "0", "1"], ["88338.8", "0.00452325", "0", "1"], ["88338.7", "0.00452335", "0", "1"], ["88338.6", "0.00452376", "0", "1"], ["88338.3", "0.00092705", "0", "1"], ["88337.7", "0.0000114", "0", "1"], ["88337.6", "0.33929724", "0", "1"], ["88336.8", "0.00001501", "0", "1"], ["88335.7", "0.01656552", "0", "1"], ["88333.5", "0.00452376", "0", "1"], ["88333.3", "0.00462987", "0", "4"], ["88333.1", "0.03", "0", "1"], ["88333", "2", "0", "1"], ["88332.7", "0.00015664", "0", "1"], ["88332.3", "0.00003597", "0", "1"], ["88332", "0.0000114", "0", "1"], ["88330.6", "0.06", "0", "2"], ["88330.5", "0.03", "0", "1"], ["88330.4", "0.08542891", "0", "1"], ["88330.1", "0.20813211", "0", "2"], ["88329.4", "0.08493", "0", "1"], ["88328.6", "0.11343045", "0", "1"], ["88328", "0.000015", "0", "1"], ["88327.8", "0.3395507", "0", "1"], ["88326.5", "0.00452381", "0", "1"], ["88326.4", "0.0300114", "0", "2"], ["88323.2", "0.03", "0", "1"], ["88323", "0.99474", "0", "1"], ["88322.8", "3.22224", "0", "1"], ["88322.7", "0.00566", "0", "1"], ["88322.6", "0.01698", "0", "1"], ["88320.9", "0.207", "0", "1"], ["88320.7", "0.0000114", "0", "1"], ["88320", "0.00005816", "0", "1"], ["88319.2", "0.000015", "0", "1"], ["88318.6", "0.000015", "0", "1"], ["88317.8", "0.3395507", "0", "1"], ["88317.6", "0.02367633", "0", "1"], ["88316.6", "0.00057148", "0", "1"], ["88315.1", "0.0182114", "0", "2"], ["88311.8", "0.11343045", "0", "1"], ["88310.4", "0.000015", "0", "1"], ["88309.3", "0.0000134", "0", "1"], ["88309.1", "0.0135", "0", "1"], ["88309", "0.027", "0", "2"], ["88308.8", "0.027", "0", "2"], ["88308.5", "0.00589961", "0", "1"], ["88307.2", "2.12495248", "0", "1"], ["88306.9", "0.0135", "0", "1"], ["88306.8", "0.0135", "0", "1"], ["88306.4", "0.3395507", "0", "1"], ["88305.9", "0.16100828", "0", "1"], ["88305.8", "0.08494", "0", "1"], ["88305.3", "0.207", "0", "1"], ["88303.7", "0.00001139", "0", "1"], ["88303.2", "0.27969405", "0", "1"], ["88301.4", "0.00003447", "0", "1"], ["88300", "0.00484161", "0", "5"], ["88299.9", "0.00057148", "0", "1"], ["88296.3", "0.11343045", "0", "1"], ["88296.2", "0.34056098", "0", "1"], ["88294.1", "0.00289318", "0", "3"], ["88292.7", "0.207", "0", "1"], ["88292.4", "0.00001139", "0", "1"], ["88292.3", "0.00002159", "0", "1"], ["88292", "0.0025", "0", "1"], ["88291.4", "0.25615", "0", "1"], ["88291", "0.005", "0", "2"], ["88290.5", "0.0203", "0", "1"], ["88290.3", "0.0609", "0", "3"], ["88290.1", "0.0203", "0", "1"], ["88289.4", "0.03", "0", "1"], ["88287.1", "0.03", "0", "1"], ["88287", "0.03", "0", "1"], ["88286.3", "0.03", "0", "1"], ["88284.9", "0.08542891", "0", "1"], ["88283.8", "0.207", "0", "1"], ["88283.5", "0.11343045", "0", "1"], ["88283.3", "5.89423083", "0", "3"], ["88283", "0.00001722", "0", "1"], ["88281.2", "0.00006263", "0", "1"], ["88281.1", "0.34078752", "0", "2"], ["88280.5", "0.00002567", "0", "1"], ["88276.1", "0.00007", "0", "1"], ["88275.5", "0.00567139", "0", "2"], ["88275", "0.00004437", "0", "1"], ["88274.9", "0.207", "0", "1"], ["88274.6", "0.00001339", "0", "1"], ["88274.4", "0.000015", "0", "1"], ["88274.2", "0.00002298", "0", "1"], ["88274.1", "0.03", "0", "1"], ["88273.4", "0.01785714", "0", "1"], ["88272.7", "0.00003889", "0", "1"], ["88272", "0.0025", "0", "1"], ["88271.5", "0.01148", "0", "1"], ["88271.3", "0.00002208", "0", "1"], ["88270.8", "0.00001148", "0", "1"], ["88270", "0.00004066", "0", "1"], ["88269.4", "0.11343045", "0", "1"], ["88269.3", "0.34056098", "0", "1"], ["88269.2", "0.08542891", "0", "1"], ["88267.2", "0.00002851", "0", "1"], ["88266.6", "0.00461561", "0", "4"], ["88266", "0.207", "0", "1"], ["88265.3", "0.00004344", "0", "1"], ["88264.7", "0.00004446", "0", "3"], ["88264.2", "0.00001139", "0", "1"], ["88262.9", "0.00735012", "0", "3"], ["88261.8", "0.00074456", "0", "1"], ["88260", "0.00002148", "0", "1"], ["88259.2", "0.00005974", "0", "1"], ["88259.1", "0.00011181", "0", "1"], ["88258.7", "0.00282652", "0", "1"], ["88257.8", "0.5999", "0", "1"], ["88257.6", "0.00003493", "0", "1"], ["88256.9", "0.34056098", "0", "1"], ["88256.4", "0.0000172", "0", "1"], ["88255.8", "0.00003183", "0", "1"], ["88255.6", "0.12221196", "0", "1"], ["88255", "0.01785714", "0", "1"], ["88254.3", "0.0000248", "0", "1"], ["88253.7", "0.00326441", "0", "1"], ["88252", "0.00002018", "0", "1"], ["88250.7", "0.11343045", "0", "1"], ["88250", "0.00006688", "0", "1"], ["88249.9", "0.00060139", "0", "2"]], "ts": "1741338227105", "checksum": -1173729312, "seqId": 48070562574, "prevSeqId": -1}]}
{"arg": {"channel": "books", "instId": "BTC-USDT"}, "action": "update", "data": [{"asks": [["88490", "0.07234759", "0", "5"], ["88492.2", "0.0001", "0", "1"], ["88492.4", "0.00011", "0", "2"], ["88492.7", "0", "0", "0"], ["88493", "0.00001024", "0", "1"], ["88498.9", "0.00006675", "0", "1"], ["88507.1", "0.01211465", "0", "2"], ["88507.3", "0.00018401", "0", "4"], ["88581.8", "0", "0", "0"]], "bids": [["88489.9", "0.2007761", "0", "9"], ["88478.9", "0.02489319", "0", "1"], ["88478.8", "0", "0", "0"], ["88477.1", "0", "0", "0"], ["88475", "1.00244663", "0", "2"], ["88473.9", "0.003855", "0", "1"], ["88470.8", "0.54440612", "0", "1"], ["88470", "0.0172", "0", "1"], ["88468.7", "0.226005", "0", "1"], ["88468.6", "0", "0", "0"], ["88451", "0.06", "0", "2"], ["88450", "0.147132", "0", "2"], ["88400.3", "0.06071591", "0", "1"], ["88268.1", "0.033899", "0", "1"], ["88250", "0", "0", "0"], ["88249.9", "0", "0", "0"]], "ts": "1741338227205", "checksum": 623188267, "seqId": 48070562643, "prevSeqId": 48070562574}]}
{"arg": {"channel": "books", "instId": "BTC-USDT"}, "action": "update", "data": [{"asks": [["88492.2", "0", "0", "0"], ["88492.3", "0.0001", "0", "1"], ["88492.4", "0.00001", "0", "1"], ["88492.7", "0.0001", "0", "1"], ["88498.9", "0", "0", "0"], ["88507", "0.012102", "0", "1"], ["88507.1", "0.00001265", "0", "1"], ["88528.1", "0.1971395", "0", "1"], ["88529", "0.00001678", "0", "1"], ["88581.7", "0", "0", "0"]], "bids": [["88489.9", "0.1813733", "0", "8"], ["88482.7", "0.00112478", "0", "1"], ["88482.3", "0.0194028", "0", "1"], ["88482.1", "0.17014754", "0", "5"], ["88480.8", "0", "0", "0"], ["88480.7", "0", "0", "0"], ["88480.6", "0.33906", "0", "1"], ["88471.2", "0.22600348", "0", "1"], ["88468.7", "0", "0", "0"], ["88444.2", "0.30140574", "0", "2"]], "ts": "1741338227305", "checksum": -1790181695, "seqId": 48070562692, "prevSeqId": 48070562643}]}
{"arg": {"channel": "books", "instId": "BTC-USDT"}, "action": "update", "data": [{"asks": [["88490", "0.02044688", "0", "3"], ["88492.3", "0", "0", "0"], ["88492.7", "0", "0", "0"], ["88497.3", "0.0001", "0", "1"], ["88497.9", "0.0001", "0", "1"], ["88506.5", "0.012102", "0", "1"], ["88507", "0", "0", "0"], ["88527.3", "0.00002616", "0", "1"], ["88529.3", "0.2260002", "0", "1"], ["88581.3", "0", "0", "0"]], "bids": [["88489.9", "0.16743984", "0", "7"], ["88489.7", "0.0002", "0", "2"], ["88488.8", "0.00138108", "0", "1"], ["88482.7", "0", "0", "0"], ["88482.1", "0.16994754", "0", "3"], ["88478.9", "0.12349954", "0", "2"], ["88478.8", "0.33906", "0", "1"], ["88473.9", "0", "0", "0"], ["88472", "0.2432002", "0", "2"], ["88471.2", "0", "0", "0"], ["88469.8", "0", "0", "0"], ["88437.4", "0.04411397", "0", "2"], ["88250", "0.00006688", "0", "1"]], "ts": "1741338227405", "checksum": -1966238567, "seqId": 48070562748, "prevSeqId": 48070562692}]}
{"arg": {"channel": "books", "instId": "BTC-USDT"}, "action": "update", "data": [{"asks": [["88494.3", "0", "0", "0"], ["88494.4", "0", "0", "0"], ["88495.9", "0.03956287", "0", "1"], ["88496.7", "0.11299638", "0", "1"], ["88497.3", "0", "0", "0"], ["88497.6", "0.0001", "0", "1"], ["88497.9", "0", "0", "0"], ["88498.1", "0.0001", "0", "1"], ["88498.9", "0.00006675", "0", "1"], ["88500.6", "0.02581379", "0", "1"], ["88501.4", "0.02971546", "0", "1"], ["88501.6", "0.02883382", "0", "1"], ["88502.1", "0.00024832", "0", "1"], ["88504.4", "0.35426911", "0", "3"], ["88504.7", "0.08221351", "0", "1"], ["88505.7", "0.08818965", "0", "1"], ["88506.2", "0.07469136", "0", "1"], ["88506.4", "0.08090668", "0", "1"], ["88506.5", "0", "0", "0"], ["88506.8", "0.012102", "0", "1"], ["88507.7", "0.12373306", "0", "1"], ["88510.5", "0.1404252", "0", "2"], ["88513.5", "0.13884605", "0", "1"], ["88519.6", "0.2430721", "0", "1"], ["88519.8", "0", "0", "0"], ["88533.6", "0.0000568", "0", "1"], ["88534.4", "0.00061094", "0", "3"], ["88535.2", "0.00042748", "0", "2"], ["88550.8", "0", "0", "0"], ["88579.9", "0", "0", "0"], ["88580", "0", "0", "0"], ["88580.3", "0", "0", "0"], ["88580.5", "0", "0", "0"], ["88580.7", "0", "0", "0"], ["88580.8", "0", "0", "0"], ["88581", "0", "0", "0"]], "bids": [["88489.9", "0.19907499", "0", "8"], ["88489.8", "0.00937", "0", "1"], ["88489.7", "0", "0", "0"], ["88489.3", "0.0002", "0", "2"], ["88487.4", "0", "0", "0"], ["88484.2", "0.03400549", "0", "2"], ["88482.6", "0.06694918", "0", "2"], ["88481.7", "0.05195787", "0", "3"], ["88481.4", "0.02992886", "0", "1"], ["88481", "0.02900596", "0", "1"], ["88479.3", "0.003855", "0", "1"], ["88478.9", "0.12661119", "0", "1"], ["88478.6", "0.0789018", "0", "1"], ["88477.2", "0.0808522", "0", "1"], ["88476.3", "0.08074658", "0", "1"], ["88475.5", "0.12194851", "0", "1"], ["88472.4", "0.2017645", "0", "2"], ["88470.8", "0.02888559", "0", "1"], ["88469.1", "0.14435854", "0", "1"], ["88469", "0.01650401", "0", "1"], ["88468.5", "0", "0", "0"], ["88462.4", "0", "0", "0"], ["88461.6", "0.00059879", "0", "2"], ["88460.8", "0.02290721", "0", "2"], ["88426.5", "0.03", "0", "1"], ["88422.5", "0.00001139", "0", "1"], ["88366.4", "1.82896031", "0", "1"], ["88339.1", "0.06345698", "0", "1"], ["88268.1", "0", "0", "0"], ["88255.8", "0", "0", "0"], ["88255.6", "0", "0", "0"], ["88255", "0", "0", "0"], ["88254.3", "0", "0", "0"], ["88253.7", "0", "0", "0"], ["88252", "0", "0", "0"], ["88250.7", "0", "0", "0"], ["88250", "0", "0", "0"]], "ts": "1741338227505", "checksum": -1924754283, "seqId": 48070562896, "prevSeqId": 48070562748}]}
{"arg": {"channel": "books", "instId": "BTC-USDT"}, "action": "update", "data": [{"asks": [["88497.5", "0.0307765", "0", "3"], ["88497.6", "0", "0", "0"], ["88498", "0.0001", "0", "1"], ["88498.1", "0", "0", "0"], ["88498.9", "0", "0", "0"], ["88506.2", "0.12674686", "0", "2"], ["88506.6", "0.01211207", "0", "2"], ["88506.8", "0", "0", "0"], ["88510.4", "0.40596501", "0", "6"], ["88527.3", "0.22602717", "0", "2"], ["88529.2", "1.59999895", "0", "1"], ["88529.3", "0", "0", "0"], ["88560.1", "2.82471341", "0", "4"], ["88579.9", "0.00606981", "0", "3"], ["88580", "0.03", "0", "1"], ["88580.3", "0.00037848", "0", "1"]], "bids": [["88489.4", "0.0002", "0", "2"], ["88489.3", "0", "0", "0"], ["88482.1", "0.16881038", "0", "2"], ["88481.7", "0.05194673", "0", "2"], ["88478.9", "0.21951952", "0", "2"], ["88472", "0.0172", "0", "1"], ["88470.8", "0.59893085", "0", "1"], ["88469.9", "1.55836733", "0", "1"], ["88469.8", "0.22600101", "0", "1"], ["88469.2", "0.01650401", "0", "1"], ["88469", "0", "0", "0"], ["88462.4", "0.0006", "0", "2"], ["88461.6", "0.00029879", "0", "1"], ["88460.8", "0.02260842", "0", "1"], ["88451", "0", "0", "0"], ["88450", "0.207132", "0", "4"], ["88438.9", "2.8565982", "0", "1"], ["88257.6", "0", "0", "0"], ["88256.9", "0", "0", "0"], ["88256.4", "0", "0", "0"]], "ts": "1741338227605", "checksum": -1310390639, "seqId": 48070562969, "prevSeqId": 48070562896}]}
{"arg": {"channel": "books", "instId": "BTC-USDT"}, "action": "update", "data": [{"asks": [["88497.4", "0.06144064", "0", "4"], ["88497.5", "0.0306765", "0", "2"], ["88498", "0", "0", "0"], ["88500.8", "0.02952895", "0", "2"], ["88505", "0.08407836", "0", "1"], ["88506.5", "0.012102", "0", "1"], ["88506.6", "0.00001007", "0", "1"], ["88509.6", "0.13861142", "0", "1"], ["88530", "0.06009419", "0", "4"], ["88531", "0.09", "0", "3"], ["88540.3", "0", "0", "0"], ["88580.3", "0", "0", "0"]], "bids": [["88489.4", "0.0001", "0", "1"], ["88489.3", "0.0001", "0", "1"], ["88488.8", "0.1", "0", "1"], ["88484.1", "0.03176859", "0", "2"], ["88482.7", "0.00145491", "0", "1"], ["88482", "0.02672639", "0", "1"], ["88477.8", "0.0830084", "0", "1"], ["88473.2", "0.1299727", "0", "1"], ["88462.4", "0", "0", "0"], ["88461.6", "0.00059879", "0", "2"], ["88460.8", "0.02290721", "0", "2"], ["88259.2", "0", "0", "0"], ["88259.1", "0", "0", "0"], ["88258.7", "0", "0", "0"], ["88257.8", "0", "0", "0"]], "ts": "1741338227705", "checksum": -1423692985, "seqId": 48070563053, "prevSeqId": 48070562969}]}
{"arg": {"channel": "books", "instId": "BTC-USDT"}, "action": "update", "data": [{"asks": [["88492", "0.01653458", "0", "2"], ["88497.4", "0.06124064", "0", "2"], ["88497.6", "0.0002", "0", "2"], ["88504.7", "0", "0", "0"], ["88505.7", "0", "0", "0"], ["88506.3", "0.01213902", "0", "3"], ["88506.4", "0", "0", "0"], ["88506.5", "0", "0", "0"], ["88507.7", "0.13199866", "0", "1"], ["88510.5", "0.00001038", "0", "1"], ["88513.5", "0", "0", "0"], ["88527.3", "0.00002616", "0", "1"], ["88529.1", "0.22599911", "0", "1"], ["88530", "0.12009419", "0", "6"], ["88531", "0.03", "0", "1"], ["88533.6", "0.0006568", "0", "3"], ["88534.4", "0.00031094", "0", "2"], ["88535.2", "0.00012748", "0", "1"], ["88550", "0.20109016", "0", "10"], ["88580.3", "0.00037848", "0", "1"], ["88580.5", "0.00002973", "0", "1"], ["88580.7", "0.00311789", "0", "1"]], "bids": [["88489.4", "0.0002", "0", "2"], ["88489.3", "0", "0", "0"], ["88488.9", "0.00114135", "0", "1"], ["88482.7", "0", "0", "0"], ["88482.6", "0.04", "0", "1"], ["88481.4", "0", "0", "0"], ["88481", "0", "0", "0"], ["88477.2", "0", "0", "0"], ["88476.3", "0", "0", "0"], ["88472.4", "0.05650882", "0", "1"], ["88471.5", "0.22599911", "0", "1"], ["88469.8", "0", "0", "0"], ["88469.1", "0", "0", "0"], ["88462.4", "0.0006", "0", "2"], ["88461.6", "0.00029879", "0", "1"], ["88460.8", "0.02260842", "0", "1"], ["88451", "0.06", "0", "2"], ["88450", "0.147132", "0", "2"], ["88259.2", "0.00005974", "0", "1"], ["88259.1", "0.00011181", "0", "1"], ["88258.7", "0.00282652", "0", "1"], ["88257.8", "0.5999", "0", "1"]], "ts": "1741338227805", "checksum": 1370499055, "seqId": 48070563144, "prevSeqId": 48070563053}]}
{"arg": {"channel": "books", "instId": "BTC-USDT"}, "action": "update", "data": [{"asks": [["88497.6", "0", "0", "0"], ["88497.8", "0.0001", "0", "1"], ["88497.9", "0.0001", "0", "1"], ["88498.9", "0.00006675", "0", "1"], ["88504.6", "0.07971175", "0", "2"], ["88505.6", "0.07916407", "0", "3"], ["88506.2", "0.22203124", "0", "2"], ["88506.3", "0.08835595", "0", "3"], ["88510.3", "0.14467514", "0", "1"], ["88510.4", "0.31571083", "0", "5"], ["88513.4", "0.14401424", "0", "1"], ["88532.6", "0.01696", "0", "1"], ["88579.9", "0", "0", "0"], ["88580", "0", "0", "0"], ["88580.3", "0", "0", "0"], ["88580.5", "0", "0", "0"], ["88580.7", "0", "0", "0"]], "bids": [["88489.4", "0.0001", "0", "1"], ["88489.2", "0.0001", "0", "1"], ["88488.9", "0", "0", "0"], ["88488.8", "0", "0", "0"], ["88482.7", "0.00109845", "0", "1"], ["88482.6", "0.0657587", "0", "2"], ["88481.5", "0.02913713", "0", "1"], ["88481.1", "0.02635697", "0", "1"], ["88477.2", "0.08960879", "0", "1"], ["88476.3", "0.08383943", "0", "1"], ["88472.5", "0.14845433", "0", "1"], ["88469.4", "0.01650401", "0", "1"], ["88469.3", "0.14149009", "0", "1"], ["88469.2", "0", "0", "0"], ["88455.8", "0.2974726", "0", "4"], ["88261.8", "0", "0", "0"], ["88260", "0", "0", "0"], ["88259.2", "0", "0", "0"], ["88259.1", "0", "0", "0"], ["88258.7", "0", "0", "0"], ["88257.8", "0", "0", "0"]], "ts": "1741338227905", "checksum": 1359210337, "seqId": 48070563224, "prevSeqId": 48070563144}]}
{"arg": {"channel": "books", "instId": "BTC-USDT"}, "action": "update", "data": [{"asks": [["88494.9", "0.0001", "0", "1"], ["88495.1", "0.0001", "0", "1"], ["88497.5", "0.00005618", "0", "1"], ["88497.8", "0", "0", "0"], ["88497.9", "0", "0", "0"], ["88498.4", "0", "0", "0"], ["88498.9", "0", "0", "0"], ["88501.3", "0.02921024", "0", "1"], ["88501.4", "0", "0", "0"], ["88506.1", "0.012102", "0", "1"], ["88506.2", "0.20992924", "0", "1"], ["88528.9", "0.22599823", "0", "1"], ["88529", "1.00001678", "0", "2"], ["88529.1", "0", "0", "0"], ["88579.9", "0.00606981", "0", "3"]], "bids": [["88489.9", "0.19818599", "0", "8"], ["88489.4", "0.0002", "0", "2"], ["88489.2", "0", "0", "0"], ["88488.8", "0.00049652", "0", "1"], ["88482.7", "0", "0", "0"], ["88472", "0.24319778", "0", "2"], ["88471.5", "0", "0", "0"], ["88469.4", "0", "0", "0"], ["88469.3", "0.01650401", "0", "1"], ["88469.2", "0.13728267", "0", "1"], ["88467", "1", "0", "1"], ["88372.2", "0.05335289", "0", "1"], ["88363.3", "0", "0", "0"], ["88354.5", "0", "0", "0"], ["88261.8", "0.00074456", "0", "1"], ["88260", "0.00002148", "0", "1"], ["88259.2", "0.00005974", "0", "1"]], "ts": "1741338228005", "checksum": 528336157, "seqId": 48070563304, "prevSeqId": 48070563224}]}
{"arg": {"channel": "books", "instId": "BTC-USDT"}, "action": "update", "data": [{"asks": [["88494.6", "0.0406744", "0", "5"], ["88494.7", "0.1129989", "0", "1"], ["88495.1", "0", "0", "0"], ["88495.4", "0.0001", "0", "1"], ["88495.9", "0", "0", "0"], ["88496.7", "0", "0", "0"], ["88498.8", "0.000066", "0", "1"], ["88500", "1.12065356", "0", "201"], ["88500.2", "0.02854896", "0", "1"], ["88500.6", "0", "0", "0"], ["88500.8", "0.02793622", "0", "2"], ["88501", "0.02897921", "0", "2"], ["88501.3", "0", "0", "0"], ["88501.6", "0", "0", "0"], ["88502.6", "0.2101721", "0", "3"], ["88504.1", "0.07543999", "0", "1"], ["88504.4", "0.43460695", "0", "4"], ["88504.6", "0.00001", "0", "1"], ["88505", "0.08342662", "0", "1"], ["88505.2", "0.03076135", "0", "3"], ["88505.6", "0.0004229", "0", "2"], ["88505.7", "0.08868689", "0", "1"], ["88506.1", "0", "0", "0"], ["88506.2", "0.13970918", "0", "1"], ["88506.3", "0.00003702", "0", "2"], ["88507.1", "0.12755335", "0", "2"], ["88507.7", "0", "0", "0"], ["88509", "0.14357655", "0", "2"], ["88509.6", "0", "0", "0"], ["88509.8", "0.1380336", "0", "2"], ["88510.3", "0", "0", "0"], ["88512.8", "0.14144565", "0", "2"], ["88513.4", "0", "0", "0"], ["88528.1", "0.9780107", "0", "2"], ["88528.9", "0", "0", "0"], ["88530.9", "0.22599844", "0", "1"], ["88559.6", "0.01740152", "0", "1"], ["88559.9", "0", "0", "0"], ["88580", "0.03", "0", "1"], ["88580.3", "0.00037848", "0", "1"], ["88580.5", "0.00002973", "0", "1"], ["88580.8", "0.00005364", "0", "1"], ["88581", "0.00017534", "0", "2"]], "bids": [["88489.4", "0", "0", "0"], ["88489.1", "0.0002", "0", "2"], ["88484.2", "0.03062032", "0", "1"], ["88482.6", "0.04", "0", "1"], ["88482.1", "0.19345596", "0", "3"], ["88482", "0", "0", "0"], ["88481.5", "0.02830702", "0", "1"], ["88481.1", "0", "0", "0"], ["88480.9", "0.0263457", "0", "1"], ["88480.5", "0.13923851", "0", "2"], ["88479.3", "0", "0", "0"], ["88478.9", "0.1837785", "0", "2"], ["88478.6", "0", "0", "0"], ["88478", "0.09232261", "0", "2"], ["88477.8", "0", "0", "0"], ["88477.3", "0.08009495", "0", "1"], ["88477.2", "0", "0", "0"], ["88476.7", "0.08298632", "0", "1"], ["88476.3", "0", "0", "0"], ["88475.8", "0.08023107", "0", "1"], ["88475.5", "0", "0", "0"], ["88475", "1.03118905", "0", "2"], ["88473.2", "0", "0", "0"], ["88472.7", "0.13903265", "0", "1"], ["88472.5", "0", "0", "0"], ["88472", "0.14862067", "0", "2"], ["88471.5", "0.22599844", "0", "1"], ["88469.3", "0", "0", "0"], ["88469.2", "0", "0", "0"], ["88468.8", "0.01651902", "0", "2"], ["88468.7", "0.13291535", "0", "1"], ["88467", "0", "0", "0"], ["88437.4", "0.02671259", "0", "1"], ["88436.7", "0.01740152", "0", "1"], ["88426.5", "1.11253274", "0", "2"], ["88366.4", "0", "0", "0"], ["88259.1", "0.00011181", "0", "1"], ["88258.7", "0.00282652", "0", "1"], ["88257.8", "0.5999", "0", "1"], ["88257.6", "0.00003493", "0", "1"], ["88256.9", "0.34056098", "0", "1"], ["88256.4", "0.0000172", "0", "1"]], "ts": "1741338228105", "checksum": -1064187644, "seqId": 48070563473, "prevSeqId": 48070563304}]}
{"arg": {"channel": "books", "instId": "BTC-USDT"}, "action": "update", "data": [{"asks": [["88494.7", "0.1130989", "0", "2"], ["88494.9", "0", "0", "0"], ["88495.2", "0.00013551", "0", "2"], ["88495.4", "0", "0", "0"], ["88498.8", "0", "0", "0"], ["88498.9", "0.00006675", "0", "1"], ["88505.1", "0.0122054", "0", "5"], ["88505.2", "0.01865935", "0", "2"], ["88530.9", "0.22599897", "0", "1"], ["88559.6", "0", "0", "0"], ["88560.3", "0.01740167", "0", "1"], ["88581.3", "0.00004102", "0", "1"], ["88581.7", "0.00019458", "0", "5"]], "bids": [["88489.3", "0.0002", "0", "2"], ["88489.1", "0", "0", "0"], ["88488.8", "0", "0", "0"], ["88475.8", "0.08154507", "0", "2"], ["88469", "0.01650401", "0", "1"], ["88468.8", "0.00001501", "0", "1"], ["88437.9", "0.04001594", "0", "2"], ["88436.7", "0", "0", "0"], ["88255.8", "0.00003183", "0", "1"]], "ts": "1741338228205", "checksum": -401492240, "seqId": 48070563542, "prevSeqId": 48070563473}]}
{"arg": {"channel": "books", "instId": "BTC-USDT"}, "action": "update", "data": [{"asks": [["88490", "0.06104688", "0", "4"], ["88494.2", "0.0001", "0", "1"], ["88495.2", "0.00003551", "0", "1"], ["88498.8", "0.000066", "0", "1"], ["88498.9", "0", "0", "0"], ["88499.5", "0.45521357", "0", "2"], ["88499.7", "0.02602795", "0", "1"], ["88500", "1.09280095", "0", "200"], ["88500.2", "0", "0", "0"], ["88500.3", "0.02682096", "0", "1"], ["88500.5", "0.02944984", "0", "2"], ["88500.8", "0.00025", "0", "1"], ["88501", "0.00006989", "0", "1"], ["88501.9", "0.01361", "0", "1"], ["88502.6", "0.14012249", "0", "2"], ["88503.6", "0.07867368", "0", "1"], ["88503.9", "0.08151462", "0", "2"], ["88504.1", "0", "0", "0"], ["88504.4", "0.34065911", "0", "2"], ["88504.5", "0.08296692", "0", "1"], ["88505", "0.012102", "0", "1"], ["88505.1", "0.0001034", "0", "4"], ["88505.2", "0.10862282", "0", "3"], ["88505.7", "0", "0", "0"], ["88506.2", "0.10247222", "0", "2"], ["88506.6", "0.12268545", "0", "2"], ["88507.1", "0.00001265", "0", "1"], ["88508.6", "0.13431353", "0", "1"], ["88509", "0.00001063", "0", "1"], ["88509.3", "0.14370107", "0", "2"], ["88509.8", "0.00001014", "0", "1"], ["88512.3", "0.13581902", "0", "1"], ["88512.8", "0.0000311", "0", "1"], ["88525.9", "0.03795331", "0", "1"], ["88527.3", "0.22602508", "0", "2"], ["88530.3", "0", "0", "0"], ["88530.9", "0", "0", "0"], ["88580.8", "0", "0", "0"], ["88581", "0", "0", "0"], ["88581.3", "0", "0", "0"], ["88581.7", "0", "0", "0"]], "bids": [["88489.8", "0", "0", "0"], ["88489.4", "0.0002", "0", "2"], ["88489.3", "0", "0", "0"], ["88487.3", "0.00937", "0", "1"], ["88482.1", "0.16881038", "0", "2"], ["88481.6", "0.02428487", "0", "1"], ["88481.5", "0", "0", "0"], ["88481", "0.02821234", "0", "1"], ["88480.9", "0", "0", "0"], ["88480.5", "0.11301694", "0", "1"], ["88480.4", "0.05520645", "0", "2"], ["88480", "0.09138199", "0", "6"], ["88478.9", "0.18789858", "0", "2"], ["88478", "0.0172", "0", "1"], ["88477.5", "0.07812931", "0", "1"], ["88477.3", "0", "0", "0"], ["88476.8", "0.08708165", "0", "1"], ["88476.7", "0", "0", "0"], ["88476.2", "0.08340072", "0", "1"], ["88475.8", "0.001314", "0", "1"], ["88475.3", "0.08524957", "0", "1"], ["88475", "0.90244663", "0", "1"], ["88474.5", "0.13345485", "0", "1"], ["88472.7", "0", "0", "0"], ["88472.5", "0.22599892", "0", "1"], ["88472.2", "0.13398994", "0", "1"], ["88472", "0.0172", "0", "1"], ["88471.5", "0.14250065", "0", "1"], ["88469", "0", "0", "0"], ["88468.7", "0", "0", "0"], ["88468.3", "0.01650401", "0", "1"], ["88468.2", "0.13678288", "0", "1"], ["88257.6", "0", "0", "0"], ["88256.9", "0", "0", "0"], ["88256.4", "0", "0", "0"], ["88255.8", "0", "0", "0"]], "ts": "1741338228305", "checksum": -81496441, "seqId": 48070563672, "prevSeqId": 48070563542}]}
{"arg": {"channel": "books", "instId": "BTC-USDT"}, "action": "update", "data": [{"asks": [["88490", "0.00494688", "0", "2"], ["88494.2", "0", "0", "0"], ["88494.5", "0.0001", "0", "1"], ["88494.6", "0.00107012", "0", "4"], ["88494.7", "0.1129989", "0", "1"], ["88495.2", "0.00013551", "0", "2"], ["88498.8", "0", "0", "0"], ["88499.5", "0.02547816", "0", "1"], ["88502.6", "0.20765231", "0", "3"], ["88504.5", "0", "0", "0"], ["88506.2", "0.1784553", "0", "1"], ["88516.3", "0.073566", "0", "1"], ["88527.3", "0.00002616", "0", "1"], ["88528.1", "0.1971395", "0", "1"], ["88529", "0.00001678", "0", "1"], ["88529.1", "0.22599709", "0", "1"], ["88578.3", "0.3", "0", "1"]], "bids": [["88489.4", "0", "0", "0"], ["88489.3", "0.0001", "0", "1"], ["88489.1", "0.0001", "0", "1"], ["88472.5", "0.22599709", "0", "1"], ["88416.9", "0.073566", "0", "1"], ["88257.8", "0", "0", "0"]], "ts": "1741338228405", "checksum": 1054541049, "seqId": 48070563767, "prevSeqId": 48070563672}]}
{"arg": {"channel": "books", "instId": "BTC-USDT"}, "action": "update", "data": [{"asks": [["88490", "0", "0", "0"], ["88490.1", "0", "0", "0"], ["88490.3", "0", "0", "0"], ["88490.8", "0", "0", "0"], ["88491.3", "0", "0", "0"], ["88491.5", "0", "0", "0"], ["88492", "0.00109039", "0", "2"], ["88494.5", "0", "0", "0"], ["88494.7", "0", "0", "0"], ["88495.2", "0.00003551", "0", "1"], ["88495.5", "0.0001", "0", "1"], ["88495.9", "0.0001", "0", "1"], ["88496.7", "0.11299636", "0", "1"], ["88497.4", "0", "0", "0"], ["88497.7", "0", "0", "0"], ["88499.5", "0", "0", "0"], ["88499.7", "0", "0", "0"], ["88499.8", "0.00001419", "0", "1"], ["88500.3", "0", "0", "0"], ["88500.5", "0.00011869", "0", "1"], ["88500.8", "0.000316", "0", "2"], ["88501.8", "0.00450749", "0", "1"], ["88501.9", "0", "0", "0"], ["88502.6", "0.14012249", "0", "2"], ["88503.6", "0", "0", "0"], ["88503.9", "0.00001666", "0", "1"], ["88505", "0", "0", "0"], ["88505.2", "0.01865935", "0", "2"], ["88506.2", "0.15351356", "0", "2"], ["88506.6", "0.00001007", "0", "1"], ["88507", "0.00006", "0", "1"], ["88507.1", "0.01362265", "0", "2"], ["88508.6", "0", "0", "0"], ["88509.3", "0.0000114", "0", "1"], ["88510.3", "0.012102", "0", "1"], ["88510.4", "0.40664558", "0", "6"], ["88512.3", "0", "0", "0"], ["88513", "0", "0", "0"], ["88516.6", "0.0188565", "0", "5"], ["88529.1", "0", "0", "0"], ["88530", "0.06009419", "0", "4"], ["88531", "0.09", "0", "3"], ["88532.6", "0", "0", "0"], ["88532.7", "0.2259913", "0", "1"], ["88533.6", "0.0000568", "0", "1"], ["88534.4", "0.00061094", "0", "3"], ["88535.2", "0.00042748", "0", "2"], ["88552.6", "0", "0", "0"], ["88554.6", "0.10199223", "0", "6"], ["88579.1", "0", "0", "0"], ["88580.5", "0.04523158", "0", "2"], ["88580.8", "0.00005364", "0", "1"], ["88581", "0.00017534", "0", "2"], ["88581.3", "0.00004102", "0", "1"], ["88581.7", "0.00019458", "0", "5"], ["88581.8", "0.00010363", "0", "4"], ["88581.9", "0.00002381", "0", "2"], ["88582.2", "0.0000374", "0", "2"], ["88582.4", "0.00003804", "0", "1"], ["88582.5", "0.00001055", "0", "1"], ["88583", "0.00004369", "0", "1"], ["88583.2", "0.07227879", "0", "3"], ["88583.3", "0.00203114", "0", "9"], ["88583.5", "0.00832769", "0", "2"], ["88583.6", "0.65165933", "0", "8"], ["88583.8", "0.00001033", "0", "1"], ["88583.9", "0.00008291", "0", "1"]], "bids": [["88491.9", "0.27809186", "0", "11"], ["88491.5", "0.02948328", "0", "1"], ["88490.6", "0.05695423", "0", "1"], ["88490.5", "0.11300418", "0", "1"], ["88490.4", "0.0001", "0", "1"], ["88490.3", "0.0001", "0", "1"], ["88490.1", "0.03062032", "0", "1"], ["88490", "0.0155", "0", "1"], ["88489.9", "0", "0", "0"], ["88489.3", "0", "0", "0"], ["88489.1", "0", "0", "0"], ["88488.7", "0", "0", "0"], ["88488.5", "0", "0", "0"], ["88488.3", "0.06162313", "0", "2"], ["88488.2", "0", "0", "0"], ["88487.3", "0", "0", "0"], ["88486.2", "0.0164472", "0", "1"], ["88486.1", "0.02813", "0", "1"], ["88484.8", "0.0306317", "0", "2"], ["88484.3", "0.00145491", "0", "1"], ["88484.2", "0.03405805", "0", "2"], ["88482.8", "0.18016021", "0", "1"], ["88482.3", "0", "0", "0"], ["88482.1", "0.00001844", "0", "1"], ["88481.6", "0", "0", "0"], ["88481", "0", "0", "0"], ["88480.6", "0", "0", "0"], ["88480.4", "0", "0", "0"], ["88480.2", "0.33929724", "0", "1"], ["88480.1", "0", "0", "0"], ["88480", "0.06247009", "0", "5"], ["88478.9", "0.12661119", "0", "1"], ["88478.8", "0", "0", "0"], ["88477.5", "0", "0", "0"], ["88476.8", "0", "0", "0"], ["88476.2", "0", "0", "0"], ["88475.3", "0", "0", "0"], ["88475.2", "0.2259913", "0", "1"], ["88474.5", "0", "0", "0"], ["88472.7", "0.00452117", "0", "1"], ["88472.5", "0", "0", "0"], ["88472.2", "0", "0", "0"], ["88471.5", "0", "0", "0"], ["88468.3", "0", "0", "0"], ["88468.2", "0", "0", "0"], ["88466.3", "0.01650401", "0", "1"], ["88463.2", "0.0006", "0", "2"], ["88462.4", "0.00029879", "0", "1"], ["88461.6", "0", "0", "0"], ["88450.2", "0.0112", "0", "1"], ["88450", "0.207132", "0", "4"], ["88449", "0.03", "0", "1"], ["88448", "0", "0", "0"], ["88445.2", "0.1", "0", "1"], ["88443.2", "0", "0", "0"], ["88443", "0.44310219", "0", "2"], ["88433.8", "0.20701139", "0", "2"], ["88428", "0.00102714", "0", "1"], ["88426.7", "0", "0", "0"], ["88420.5", "0", "0", "0"], ["88420.4", "0", "0", "0"], ["88400", "0.00004369", "0", "1"], ["88386.1", "0.06666822", "0", "1"], ["88385.7", "0.02260092", "0", "1"], ["88366.2", "0", "0", "0"], ["88352", "0", "0", "0"], ["88315.1", "0.0182", "0", "1"], ["88283.3", "0.00416498", "0", "2"], ["88257.8", "0.5999", "0", "1"], ["88257.6", "0.00003493", "0", "1"], ["88256.9", "0.34056098", "0", "1"], ["88256.4", "0.0000172", "0", "1"], ["88255.8", "0.00003183", "0", "1"], ["88255.6", "0.12221196", "0", "1"], ["88255", "0.01785714", "0", "1"], ["88254.7", "0.06798501", "0", "1"]], "ts": "1741338228505", "checksum": -847921307, "seqId": 48070564197, "prevSeqId": 48070563767}]}
{"arg": {"channel": "books", "instId": "BTC-USDT"}, "action": "update", "data": [{"asks": [["88494", "0", "0", "0"], ["88495.5", "0", "0", "0"], ["88496.2", "0.00011203", "0", "2"], ["88496.7", "0", "0", "0"], ["88499.9", "0.33397218", "0", "14"], ["88503.6", "0.02662671", "0", "1"], ["88503.9", "0.02805018", "0", "2"], ["88504.4", "0.36700051", "0", "3"], ["88504.6", "0.02963503", "0", "2"], ["88505.5", "0.00006989", "0", "1"], ["88506.2", "0.16870205", "0", "2"], ["88507.7", "0.08260623", "0", "1"], ["88508.1", "0.0807", "0", "1"], ["88508.7", "0.08225811", "0", "1"], ["88509.4", "0.0837433", "0", "1"], ["88509.7", "0.012102", "0", "1"], ["88510.3", "0", "0", "0"], ["88510.4", "0.44227538", "0", "6"], ["88510.8", "0.25039873", "0", "3"], ["88512.7", "0.14734821", "0", "2"], ["88513.4", "0.14457242", "0", "1"], ["88516.5", "0.1497868", "0", "1"], ["88530.9", "0.22599441", "0", "1"], ["88532.7", "0", "0", "0"], ["88550", "0.00109016", "0", "9"], ["88558.9", "0.01740094", "0", "1"], ["88560.3", "0", "0", "0"], ["88580.5", "0.00002973", "0", "1"], ["88580.9", "0.04520192", "0", "1"], ["88583.3", "0", "0", "0"], ["88583.5", "0", "0", "0"], ["88583.6", "0", "0", "0"], ["88583.8", "0", "0", "0"], ["88583.9", "0", "0", "0"]], "bids": [["88490.4", "0", "0", "0"], ["88490.3", "0.0002", "0", "2"], ["88485.7", "0.02681575", "0", "1"], ["88485.1", "0.02805981", "0", "1"], ["88484.6", "0.02986536", "0", "1"], ["88484.3", "0", "0", "0"], ["88484.2", "0.06273953", "0", "3"], ["88484.1", "0.00114827", "0", "1"], ["88482.9", "0.00145491", "0", "1"], ["88481.7", "0.13182758", "0", "3"], ["88480.9", "0.08833933", "0", "1"], ["88480.3", "0.08025705", "0", "1"], ["88479.4", "0.08484432", "0", "1"], ["88478.9", "0.16343866", "0", "2"], ["88478.6", "0.12841311", "0", "2"], ["88476.3", "0.13647559", "0", "1"], ["88475.8", "0", "0", "0"], ["88475.6", "0.16073763", "0", "2"], ["88475.2", "0", "0", "0"], ["88472.5", "0.22599441", "0", "1"], ["88472.3", "0.14963414", "0", "1"], ["88437.9", "0.02261427", "0", "1"], ["88436.3", "0.01740094", "0", "1"], ["88368.3", "0.00212656", "0", "1"], ["88366.7", "0", "0", "0"], ["88361.6", "0", "0", "0"], ["88360.2", "0.17400945", "0", "1"], ["88293.4", "0.04093218", "0", "1"], ["88258.7", "0", "0", "0"], ["88257.8", "0", "0", "0"], ["88257.6", "0", "0", "0"], ["88256.9", "0", "0", "0"], ["88256.4", "0", "0", "0"], ["88255.8", "0", "0", "0"], ["88255.6", "0", "0", "0"], ["88255", "0", "0", "0"], ["88254.7", "0", "0", "0"]], "ts": "1741338228605", "checksum": -1992301623, "seqId": 48070564446, "prevSeqId": 48070564197}]}
{"arg": {"channel": "books", "instId": "BTC-USDT"}, "action": "update", "data": [{"asks": [["88492", "0.04169039", "0", "3"], ["88494", "0.0155", "0", "1"], ["88495.2", "0.00013551", "0", "2"], ["88495.9", "0", "0", "0"], ["88496", "0.0165", "0", "2"], ["88496.2", "0.00001203", "0", "1"], ["88502.8", "0.02647394", "0", "1"], ["88503.6", "0.02903614", "0", "1"], ["88503.8", "0.02828365", "0", "1"], ["88503.9", "0.00001666", "0", "1"], ["88504.4", "0.34065911", "0", "2"], ["88504.6", "0.00001", "0", "1"], ["88506.2", "0.07106076", "0", "1"], ["88507.7", "0", "0", "0"], ["88507.9", "0.08931315", "0", "1"], ["88508.1", "0", "0", "0"], ["88508.7", "0", "0", "0"], ["88509.3", "0.0121134", "0", "2"], ["88509.4", "0", "0", "0"], ["88509.7", "0", "0", "0"], ["88510", "0.12188859", "0", "1"], ["88510.4", "0.31571083", "0", "5"], ["88510.6", "0.04501016", "0", "2"], ["88510.8", "0.128225", "0", "2"], ["88512.7", "0.00022607", "0", "1"], ["88513.4", "0", "0", "0"], ["88515.6", "0.14589832", "0", "1"], ["88516.5", "0", "0", "0"], ["88530.9", "0.22599616", "0", "1"], ["88570.9", "0.00003364", "0", "1"], ["88583.3", "0.00203114", "0", "9"], ["88583.5", "0.00832769", "0", "2"]], "bids": [["88491.9", "0.26451902", "0", "10"], ["88485.7", "0", "0", "0"], ["88485.1", "0", "0", "0"], ["88484.6", "0", "0", "0"], ["88484.2", "0.03405805", "0", "2"], ["88484.1", "0.02975021", "0", "2"], ["88483.8", "0.02627407", "0", "1"], ["88483.3", "0.02946668", "0", "1"], ["88481.7", "0.05194673", "0", "2"], ["88480.9", "0", "0", "0"], ["88480.3", "0", "0", "0"], ["88479.9", "0.08337527", "0", "1"], ["88479.4", "0", "0", "0"], ["88478.9", "0.02489319", "0", "1"], ["88478.6", "0", "0", "0"], ["88476.3", "0", "0", "0"], ["88475.6", "0.02259881", "0", "1"], ["88475.3", "0.13673192", "0", "1"], ["88472.5", "0.22599616", "0", "1"], ["88472.3", "0", "0", "0"], ["88469", "0.01650401", "0", "1"], ["88466.3", "0", "0", "0"], ["88459.4", "0.02075056", "0", "1"], ["88443.8", "0", "0", "0"], ["88391.8", "0.01382998", "0", "3"], ["88382.9", "0.00624717", "0", "2"], ["88374.1", "0.00935368", "0", "1"], ["88298.3", "5.96308196", "0", "1"], ["88258.7", "0.00282652", "0", "1"], ["88257.8", "0.5999", "0", "1"], ["88257.6", "0.00003493", "0", "1"]], "ts": "1741338228705", "checksum": -325348288, "seqId": 48070564558, "prevSeqId": 48070564446}]}
{"arg": {"channel": "books", "instId": "BTC-USDT"}, "action": "update", "data": [{"asks": [["88495.2", "0.00003551", "0", "1"], ["88495.4", "0.0001", "0", "1"], ["88495.5", "0.0001", "0", "1"], ["88495.9", "0.03953288", "0", "1"], ["88496", "0.0164", "0", "1"], ["88496.6", "0.11419478", "0", "3"], ["88501.9", "0.02915918", "0", "1"], ["88502.6", "0.16981847", "0", "3"], ["88502.8", "0.02824716", "0", "1"], ["88503.6", "0", "0", "0"], ["88503.8", "0", "0", "0"], ["88506.2", "0.07879236", "0", "1"], ["88506.8", "0.08899066", "0", "1"], ["88507.9", "0", "0", "0"], ["88508.9", "0.12382622", "0", "2"], ["88509.2", "0.012102", "0", "1"], ["88509.3", "0.0000114", "0", "1"], ["88510", "0", "0", "0"], ["88514.6", "0.14610322", "0", "2"], ["88515.6", "0", "0", "0"], ["88530.9", "0", "0", "0"], ["88532.7", "0.22599114", "0", "1"], ["88542.9", "0", "0", "0"]], "bids": [["88491.9", "0.27809186", "0", "11"], ["88490.6", "0.04268311", "0", "1"], ["88484.1", "0", "0", "0"], ["88483.8", "0", "0", "0"], ["88483.3", "0", "0", "0"], ["88483.1", "0.02854256", "0", "1"], ["88482.7", "0.02841544", "0", "1"], ["88482.3", "0.02663436", "0", "1"], ["88479.9", "0", "0", "0"], ["88478.9", "0.26707633", "0", "2"], ["88478.4", "0.08650992", "0", "1"], ["88476.1", "0.22599114", "0", "1"], ["88476", "0.2172", "0", "2"], ["88475.3", "0", "0", "0"], ["88472.5", "0", "0", "0"], ["88470", "0.03370401", "0", "2"], ["88469", "0", "0", "0"], ["88387.1", "0.1", "0", "1"], ["88355.7", "0.01129231", "0", "1"], ["88345.3", "0", "0", "0"], ["88256.9", "0.34056098", "0", "1"]], "ts": "1741338228805", "checksum": -505358433, "seqId": 48070564696, "prevSeqId": 48070564558}]}
{"arg": {"channel": "books", "instId": "BTC-USDT"}, "action": "update", "data": [{"asks": [["88492", "0.00120611", "0", "3"], ["88495.4", "0", "0", "0"], ["88495.5", "0", "0", "0"], ["88495.9", "0.0002", "0", "2"], ["88501.9", "0", "0", "0"], ["88502.6", "0.14012249", "0", "2"], ["88502.7", "0.05510436", "0", "2"], ["88502.8", "0", "0", "0"], ["88503.5", "0.02957619", "0", "2"], ["88503.7", "0.02664568", "0", "1"], ["88506.2", "0.17345637", "0", "2"], ["88506.8", "0.07719881", "0", "1"], ["88506.9", "0.13745683", "0", "2"], ["88507.8", "0.07850913", "0", "1"], ["88508.4", "0.0816287", "0", "6"], ["88508.9", "0.0000123", "0", "1"], ["88509.2", "0", "0", "0"], ["88509.7", "0.012102", "0", "1"], ["88510.4", "0.34932875", "0", "5"], ["88511.5", "0.15492125", "0", "2"], ["88512.5", "0.13336341", "0", "1"], ["88514.6", "0.00009813", "0", "1"], ["88515.5", "0.14739578", "0", "2"], ["88530", "0.00009419", "0", "2"], ["88531", "0.06", "0", "2"], ["88532", "0.090015", "0", "4"], ["88532.7", "0.22599245", "0", "1"], ["88534.4", "0.00001094", "0", "1"], ["88534.6", "0.01696", "0", "1"], ["88535.2", "0.00072748", "0", "3"], ["88536", "0.0003", "0", "1"], ["88583.3", "0", "0", "0"], ["88583.5", "0", "0", "0"]], "bids": [["88484.9", "0.00145491", "0", "1"], ["88484.8", "0.0555981", "0", "3"], ["88484.1", "0.00115198", "0", "1"], ["88484", "0.04442806", "0", "2"], ["88483.7", "0.02738168", "0", "1"], ["88483.2", "0.02654665", "0", "1"], ["88483.1", "0", "0", "0"], ["88482.9", "0", "0", "0"], ["88482.7", "0", "0", "0"], ["88482.3", "0", "0", "0"], ["88480.8", "0.07803161", "0", "1"], ["88479.8", "0.08857053", "0", "1"], ["88479.4", "0.08933601", "0", "1"], ["88478.9", "0.17993981", "0", "1"], ["88478.7", "0.003855", "0", "1"], ["88478.5", "0.08596888", "0", "1"], ["88478.4", "0", "0", "0"], ["88477.7", "0.13474972", "0", "1"], ["88476.8", "0.22599245", "0", "1"], ["88476.1", "0", "0", "0"], ["88474.7", "0.13704254", "0", "1"], ["88471.4", "0.17860667", "0", "2"], ["88369.5", "0", "0", "0"], ["88259.1", "0", "0", "0"], ["88258.7", "0", "0", "0"], ["88257.8", "0", "0", "0"], ["88257.6", "0", "0", "0"], ["88256.9", "0", "0", "0"]], "ts": "1741338228905", "checksum": -2032122760, "seqId": 48070564855, "prevSeqId": 48070564696}]}
{"arg": {"channel": "books", "instId": "BTC-USDT"}, "action": "update", "data": [{"asks": [["88492", "0", "0", "0"], ["88492.1", "0", "0", "0"], ["88492.4", "0", "0", "0"], ["88492.5", "0", "0", "0"], ["88492.6", "0", "0", "0"], ["88493", "0", "0", "0"], ["88493.2", "0", "0", "0"], ["88493.3", "0", "0", "0"], ["88493.8", "0", "0", "0"], ["88494", "0", "0", "0"], ["88494.1", "0", "0", "0"], ["88494.6", "0", "0", "0"], ["88495.2", "0", "0", "0"], ["88495.9", "0", "0", "0"], ["88496", "0", "0", "0"], ["88496.1", "0", "0", "0"], ["88496.2", "0", "0", "0"], ["88496.3", "0", "0", "0"], ["88496.5", "0", "0", "0"], ["88496.6", "0", "0", "0"], ["88497.1", "0", "0", "0"], ["88497.2", "0", "0", "0"], ["88497.5", "0", "0", "0"], ["88498.7", "0.1130121", "0", "2"], ["88499.9", "0.00189006", "0", "13"], ["88502.6", "0.00001067", "0", "1"], ["88502.7", "0", "0", "0"], ["88503.2", "0.02516258", "0", "13"], ["88503.3", "0.02960811", "0", "1"], ["88503.5", "0.00001057", "0", "1"], ["88503.7", "0", "0", "0"], ["88504", "0.02722966", "0", "1"], ["88504.2", "0.02634081", "0", "1"], ["88504.4", "0.00009813", "0", "1"], ["88505.6", "0.0004079", "0", "1"], ["88506.2", "0", "0", "0"], ["88506.8", "0", "0", "0"], ["88506.9", "0.051", "0", "1"], ["88507.2", "0.08364094", "0", "1"], ["88507.5", "0.08856769", "0", "1"], ["88507.8", "0", "0", "0"], ["88508.2", "0.08010034", "0", "1"], ["88508.4", "0.00028226", "0", "5"], ["88508.9", "0.08238092", "0", "2"], ["88509.7", "0", "0", "0"], ["88510.3", "0.13933271", "0", "1"], ["88510.4", "0.174", "0", "4"], ["88510.8", "0.000013", "0", "1"], ["88511.5", "0.0188839", "0", "1"], ["88512.1", "0.13736805", "0", "1"], ["88512.5", "0", "0", "0"], ["88513", "0.13100671", "0", "1"], ["88515.2", "0", "0", "0"], ["88515.5", "0.00007", "0", "1"], ["88516", "0.14308143", "0", "1"], ["88517.3", "0", "0", "0"], ["88530.9", "0.22599456", "0", "1"], ["88532.7", "0", "0", "0"], ["88559.6", "0.90244663", "0", "1"], ["88583.3", "0.00203114", "0", "9"], ["88583.5", "0.00832769", "0", "2"], ["88583.6", "0.65165933", "0", "8"], ["88583.8", "0.00001033", "0", "1"], ["88583.9", "0.00008291", "0", "1"], ["88584", "0.11343045", "0", "1"], ["88584.1", "0.34056098", "0", "1"], ["88584.7", "0.00001142", "0", "1"], ["88584.8", "0.000015", "0", "1"], ["88584.9", "0.00023201", "0", "1"], ["88585", "0.00002037", "0", "1"], ["88585.1", "0.00560051", "0", "1"], ["88585.3", "0.00017079", "0", "13"], ["88585.4", "0.0057422", "0", "3"], ["88585.5", "0.00001377", "0", "1"], ["88585.8", "0.00001023", "0", "1"], ["88586", "0.01354615", "0", "1"], ["88586.1", "0.02272221", "0", "2"], ["88586.2", "0.00561764", "0", "2"], ["88586.6", "0.00016218", "0", "2"], ["88586.7", "0.00001139", "0", "1"]], "bids": [["88498.4", "0.04389775", "0", "1"], ["88492", "0.02663", "0", "2"], ["88490.7", "0.90244663", "0", "1"], ["88490.3", "0", "0", "0"], ["88490.2", "0.0002", "0", "2"], ["88485.3", "0.0264062", "0", "1"], ["88484.9", "0", "0", "0"], ["88484.8", "0.0306317", "0", "2"], ["88484.6", "0.02896281", "0", "1"], ["88484.1", "0.02711972", "0", "1"], ["88484", "0.0155", "0", "1"], ["88483.7", "0.02740247", "0", "1"], ["88483.2", "0", "0", "0"], ["88482.9", "0.00145491", "0", "1"], ["88481.2", "0.07567943", "0", "1"], ["88480.8", "0", "0", "0"], ["88480.4", "0.07915586", "0", "1"], ["88479.9", "0.0823921", "0", "1"], ["88479.8", "0", "0", "0"], ["88479.4", "0", "0", "0"], ["88479", "0.08948908", "0", "1"], ["88478.9", "0.08604969", "0", "1"], ["88478.5", "0", "0", "0"], ["88478.2", "0.1426427", "0", "2"], ["88477.7", "0", "0", "0"], ["88476.8", "0", "0", "0"], ["88475.7", "0.1346452", "0", "1"], ["88475.1", "0.78074182", "0", "2"], ["88474.7", "0", "0", "0"], ["88472.5", "0.22599456", "0", "1"], ["88471.9", "0.24435488", "0", "4"], ["88471.4", "0.04", "0", "1"], ["88424.3", "0.08483", "0", "1"], ["88411.8", "0.33932", "0", "1"], ["88407", "0.000015", "0", "1"], ["88305.8", "0", "0", "0"], ["88262.9", "0", "0", "0"], ["88261.8", "0", "0", "0"], ["88260", "0", "0", "0"], ["88259.2", "0", "0", "0"]], "ts": "1741338229005", "checksum": -1682130510, "seqId": 48070565044, "prevSeqId": 48070564855}]}
{"arg": {"channel": "books", "instId": "BTC-USDT"}, "action": "update", "data": [{"asks": [["88498.5", "0", "0", "0"], ["88498.7", "0", "0", "0"], ["88499.8", "0", "0", "0"], ["88499.9", "0", "0", "0"], ["88500", "0", "0", "0"], ["88500.5", "0", "0", "0"], ["88500.8", "0", "0", "0"], ["88500.9", "0", "0", "0"], ["88501", "0", "0", "0"], ["88501.7", "0", "0", "0"], ["88501.8", "0", "0", "0"], ["88502.1", "0", "0", "0"], ["88502.3", "0", "0", "0"], ["88502.5", "0", "0", "0"], ["88502.6", "0", "0", "0"], ["88503.2", "0", "0", "0"], ["88503.3", "0", "0", "0"], ["88503.5", "0", "0", "0"], ["88503.9", "0", "0", "0"], ["88504", "0", "0", "0"], ["88504.2", "0", "0", "0"], ["88504.4", "0", "0", "0"], ["88504.6", "0", "0", "0"], ["88505.1", "0", "0", "0"], ["88505.2", "0", "0", "0"], ["88505.4", "0", "0", "0"], ["88505.5", "0", "0", "0"], ["88505.6", "0", "0", "0"], ["88506.3", "0", "0", "0"], ["88506.6", "0", "0", "0"], ["88506.9", "0", "0", "0"], ["88507", "0", "0", "0"], ["88507.1", "0", "0", "0"], ["88507.2", "0", "0", "0"], ["88507.3", "0", "0", "0"], ["88507.4", "0", "0", "0"], ["88507.5", "0", "0", "0"], ["88508.2", "0", "0", "0"], ["88508.4", "0", "0", "0"], ["88508.9", "0", "0", "0"], ["88509", "0", "0", "0"], ["88509.3", "0", "0", "0"], ["88509.8", "0", "0", "0"], ["88510.3", "0", "0", "0"], ["88510.4", "0", "0", "0"], ["88510.5", "0", "0", "0"], ["88510.6", "0", "0", "0"], ["88510.7", "0", "0", "0"], ["88510.8", "0", "0", "0"], ["88510.9", "0.11221015", "0", "13"], ["88511.2", "0.00001012", "0", "1"], ["88511.5", "0", "0", "0"], ["88512", "0.0155", "0", "1"], ["88512.1", "0", "0", "0"], ["88513", "0", "0", "0"], ["88514", "0.0155", "0", "1"], ["88514.1", "0", "0", "0"], ["88514.4", "0", "0", "0"], ["88514.8", "0", "0", "0"], ["88515.3", "0", "0", "0"], ["88515.4", "0", "0", "0"], ["88515.7", "0.0001", "0", "1"], ["88516", "0.0155", "0", "1"], ["88516.1", "0", "0", "0"], ["88516.2", "0.0001", "0", "1"], ["88516.3", "0", "0", "0"], ["88516.6", "0.00528366", "0", "4"], ["88516.7", "0", "0", "0"], ["88517", "0.01144519", "0", "2"], ["88517.1", "0", "0", "0"], ["88517.9", "0", "0", "0"], ["88518", "0", "0", "0"], ["88518.6", "0", "0", "0"], ["88519.6", "0", "0", "0"], ["88519.8", "0.00006675", "0", "1"], ["88520.4", "0", "0", "0"], ["88520.7", "0", "0", "0"], ["88523", "0", "0", "0"], ["88523.6", "0.1497581", "0", "5"], ["88523.7", "0.0748356", "0", "1"], ["88523.8", "0.02736328", "0", "4"], ["88525", "0.06129706", "0", "4"], ["88525.7", "0.06124064", "0", "2"], ["88525.8", "0.0186343", "0", "1"], ["88525.9", "0", "0", "0"], ["88526.1", "0.00225374", "0", "1"], ["88526.8", "0.06124064", "0", "2"], ["88526.9", "0.0225957", "0", "1"], ["88527", "0.0188839", "0", "1"], ["88527.4", "0", "0", "0"], ["88527.6", "0.045", "0", "1"], ["88527.8", "0.0786305", "0", "1"], ["88528", "0.00001323", "0", "1"], ["88528.1", "0.0663278", "0", "1"], ["88528.5", "0", "0", "0"], ["88528.9", "0.000084", "0", "1"], ["88529.1", "0.015", "0", "1"], ["88529.2", "0", "0", "0"], ["88529.4", "0", "0", "0"], ["88530.9", "0", "0", "0"], ["88531", "0", "0", "0"], ["88532", "0.000015", "0", "1"], ["88532.8", "0.11103254", "0", "1"], ["88533.7", "0", "0", "0"], ["88534.6", "0", "0", "0"], ["88534.7", "0.33929724", "0", "1"], ["88534.8", "0.00092933", "0", "1"], ["88535.1", "0", "0", "0"], ["88535.2", "0.00012748", "0", "1"], ["88536", "0", "0", "0"], ["88536.6", "0.04", "0", "1"], ["88537.1", "0.1029341", "0", "27"], ["88538.4", "0.00028414", "0", "4"], ["88540.4", "0.11343045", "0", "1"], ["88540.6", "0", "0", "0"], ["88540.9", "0", "0", "0"], ["88541.1", "0", "0", "0"], ["88541.8", "0.183915", "0", "1"], ["88541.9", "0.18391502", "0", "1"], ["88543.2", "0", "0", "0"], ["88544.1", "0.00007666", "0", "1"], ["88544.2", "0.03748327", "0", "1"], ["88545.1", "0.00001083", "0", "1"], ["88545.9", "0.14042966", "0", "2"], ["88546.8", "0.00019039", "0", "1"], ["88546.9", "0", "0", "0"], ["88549.5", "0.22593875", "0", "1"], ["88549.7", "0.219102", "0", "2"], ["88550.2", "0.13540439", "0", "1"], ["88550.3", "0", "0", "0"], ["88552", "0.12023792", "0", "6"], ["88552.5", "0.447564", "0", "1"], ["88552.9", "0", "0", "0"], ["88553", "0.03", "0", "1"], ["88553.3", "0", "0", "0"], ["88554.4", "0.00016676", "0", "1"], ["88554.6", "0.00199223", "0", "5"], ["88554.9", "0.25659681", "0", "1"], ["88555", "0.2967477", "0", "5"], ["88555.2", "0.00006893", "0", "2"], ["88555.7", "0", "0", "0"], ["88558.9", "0", "0", "0"], ["88559.2", "0.02258331", "0", "1"], ["88559.5", "0.40896957", "0", "4"], ["88559.7", "0", "0", "0"], ["88560.1", "0.00017777", "0", "3"], ["88560.6", "0.147132", "0", "2"], ["88561.1", "0.1000134", "0", "2"], ["88562.9", "0", "0", "0"], ["88564.4", "0.13365531", "0", "1"], ["88564.5", "0.21704", "0", "1"], ["88566.4", "0", "0", "0"], ["88566.5", "0", "0", "0"], ["88567.4", "0", "0", "0"], ["88568.2", "0.0057003", "0", "1"], ["88568.3", "0", "0", "0"], ["88568.7", "0.00030374", "0", "1"], ["88569.4", "0.31809214", "0", "2"], ["88569.5", "0.44619", "0", "1"], ["88569.8", "0.01739603", "0", "1"], ["88571", "0.0057003", "0", "1"], ["88571.1", "0", "0", "0"], ["88571.6", "0.14717181", "0", "3"], ["88571.8", "0", "0", "0"], ["88572", "0", "0", "0"], ["88572.4", "0.00001155", "0", "1"], ["88572.5", "0", "0", "0"], ["88574.5", "0.0057003", "0", "1"], ["88574.6", "0", "0", "0"], ["88574.7", "0", "0", "0"], ["88575.9", "0.06611134", "0", "2"], ["88576.3", "0", "0", "0"], ["88576.8", "0.00001088", "0", "1"], ["88576.9", "0.00007915", "0", "1"], ["88577.1", "0.0052", "0", "1"], ["88577.3", "0.90244663", "0", "1"], ["88577.9", "0.06406", "0", "1"], ["88578.2", "0.0057003", "0", "1"], ["88579.9", "0.0004693", "0", "2"], ["88580.8", "0.00575394", "0", "2"], ["88580.9", "0", "0", "0"], ["88581.4", "0.01693398", "0", "1"], ["88583.2", "0.00001006", "0", "1"], ["88583.6", "0.00044862", "0", "7"], ["88585", "0.00572067", "0", "2"], ["88585.1", "0", "0", "0"], ["88585.3", "0.20717079", "0", "14"], ["88585.4", "0.00004168", "0", "2"], ["88586", "0", "0", "0"], ["88586.1", "0.00012221", "0", "1"], ["88586.2", "0.00001765", "0", "1"], ["88586.6", "0.0058629", "0", "3"], ["88586.8", "0.00776843", "0", "3"], ["88586.9", "0.00001998", "0", "1"], ["88587", "0.0399405", "0", "1"], ["88587.2", "0.00003998", "0", "1"], ["88587.4", "0.00013832", "0", "5"], ["88587.8", "0.0000916", "0", "6"], ["88587.9", "0.63069311", "0", "2"], ["88588", "0.00003475", "0", "2"], ["88588.2", "0.00001503", "0", "1"], ["88588.4", "0.00025918", "0", "1"], ["88588.5", "0.00006713", "0", "1"], ["88588.6", "0.03", "0", "1"], ["88588.7", "0.0057003", "0", "1"], ["88588.8", "0.00581154", "0", "2"], ["88589", "0.00001077", "0", "1"], ["88590", "0.00001453", "0", "1"], ["88590.2", "0.00077757", "0", "6"], ["88590.5", "0.00002281", "0", "2"], ["88591.1", "0.00103894", "0", "1"], ["88591.4", "0.00004418", "0", "1"], ["88591.5", "0.00001557", "0", "1"], ["88591.6", "0.0057003", "0", "1"], ["88591.9", "0.00311789", "0", "1"], ["88592", "0.00588266", "0", "2"], ["88592.1", "0.00005062", "0", "3"], ["88592.3", "0.00013101", "0", "3"], ["88592.5", "0.00002347", "0", "1"], ["88592.6", "0.00004428", "0", "1"], ["88593.2", "0.00022454", "0", "9"], ["88593.4", "0.02432771", "0", "2"], ["88593.6", "0.000015", "0", "1"], ["88593.7", "0.00006257", "0", "1"], ["88593.8", "0.00001139", "0", "1"], ["88594.1", "0.00018837", "0", "7"], ["88594.2", "0.207", "0", "1"], ["88594.5", "0.00014518", "0", "1"], ["88594.9", "0.00183765", "0", "1"], ["88595", "0.03005751", "0", "3"], ["88595.1", "0.05807858", "0", "2"], ["88595.4", "0.00007", "0", "1"], ["88595.7", "0.01140102", "0", "2"], ["88595.9", "0.746649", "0", "1"], ["88596", "0.00003743", "0", "2"], ["88596.4", "0.00570072", "0", "1"], ["88596.5", "0.00004569", "0", "1"], ["88596.7", "0.00001016", "0", "1"], ["88596.8", "0.00002128", "0", "1"], ["88597.1", "0.00002384", "0", "1"], ["88597.5", "0.11908342", "0", "3"], ["88597.6", "0.0000601", "0", "1"], ["88598", "0.00002736", "0", "1"], ["88598.1", "0.00001026", "0", "1"], ["88598.2", "0.00018525", "0", "1"], ["88598.3", "0.34056098", "0", "1"], ["88598.5", "0.49884", "0", "1"], ["88599.2", "0.04519393", "0", "1"], ["88599.4", "0.00003797", "0", "1"], ["88599.7", "0.00002124", "0", "2"], ["88599.9", "0.24751403", "0", "8"], ["88600", "0.18514492", "0", "94"], ["88600.1", "0.0057003", "0", "1"], ["88600.3", "0.0226", "0", "1"], ["88600.9", "0.00001055", "0", "1"], ["88601.1", "0.0001772", "0", "1"], ["88601.3", "0.00072895", "0", "4"], ["88601.4", "0.00001181", "0", "1"], ["88601.6", "0.0045196", "0", "1"], ["88601.9", "0.00451934", "0", "1"], ["88602", "0.00451934", "0", "1"], ["88602.1", "0.00003678", "0", "3"]], "bids": [["88510.8", "0.17381329", "0", "5"], ["88510.7", "0.0002", "0", "2"], ["88510.3", "0.01417312", "0", "1"], ["88510", "0.0155", "0", "1"], ["88508.8", "0.00028228", "0", "2"], ["88508.4", "0.03518804", "0", "2"], ["88508", "0.0155", "0", "1"], ["88506.9", "0.00145491", "0", "1"], ["88506.8", "0.05534953", "0", "2"], ["88506.6", "0.04", "0", "1"], ["88506.5", "0.34171562", "0", "1"], ["88506", "0.0155", "0", "1"], ["88505.9", "0.1", "0", "1"], ["88504", "0.0155", "0", "1"], ["88503.7", "0.02913816", "0", "1"], ["88503.3", "0.04176152", "0", "2"], ["88503.2", "0.17227413", "0", "6"], ["88502", "0.0155", "0", "1"], ["88501.9", "0.90244663", "0", "1"], ["88501.6", "0.00937", "0", "1"], ["88501", "0.00838873", "0", "1"], ["88500", "0.0155", "0", "1"], ["88499.8", "0.0339", "0", "1"], ["88499.5", "0.08418929", "0", "1"], ["88499.4", "0.04", "0", "1"], ["88498.6", "0.08649586", "0", "1"], ["88498.4", "0.06429897", "0", "5"], ["88498", "0.0155", "0", "1"], ["88496.8", "0.22593875", "0", "1"], ["88496.6", "0.03036296", "0", "2"], ["88496", "0.0155", "0", "1"], ["88495.2", "0.00001501", "0", "1"], ["88494.7", "0.1429321", "0", "1"], ["88494.4", "0.002415", "0", "1"], ["88494", "0.0155", "0", "1"], ["88493.9", "0.04251936", "0", "3"], ["88492.7", "0.00452015", "0", "1"], ["88492.4", "0.12717488", "0", "2"], ["88492", "0.56483917", "0", "2"], ["88491.9", "0.016", "0", "1"], ["88491.8", "0.00006", "0", "1"], ["88491.5", "0.14230958", "0", "1"], ["88490.7", "1.24174387", "0", "2"], ["88490.6", "0", "0", "0"], ["88490.5", "0", "0", "0"], ["88490.4", "0.00001138", "0", "1"], ["88490.2", "0", "0", "0"], ["88490.1", "0", "0", "0"], ["88489.5", "0.207", "0", "1"], ["88488.3", "0", "0", "0"], ["88488.1", "0.00937", "0", "1"], ["88488", "0", "0", "0"], ["88487.6", "0", "0", "0"], ["88486.4", "0.000015", "0", "1"], ["88486.2", "0", "0", "0"], ["88486.1", "0", "0", "0"], ["88486", "0", "0", "0"], ["88485.3", "0", "0", "0"], ["88484.8", "0.00001138", "0", "1"], ["88484.6", "0", "0", "0"], ["88484.5", "0.01650401", "0", "1"], ["88484.4", "0.128201", "0", "1"], ["88484.2", "0", "0", "0"], ["88484.1", "0", "0", "0"], ["88484", "0.00115384", "0", "1"], ["88483.7", "0", "0", "0"], ["88483.5", "0.08542891", "0", "1"], ["88483.3", "0.00057148", "0", "1"], ["88483.2", "0.147132", "0", "2"], ["88483", "0.015", "0", "1"], ["88482.9", "0", "0", "0"], ["88482.8", "0.27384199", "0", "2"], ["88482.6", "0", "0", "0"], ["88482.3", "0.00198343", "0", "1"], ["88482.1", "0", "0", "0"], ["88482", "0.03", "0", "1"], ["88481.4", "0.183915", "0", "1"], ["88481.2", "0", "0", "0"], ["88480.6", "0.207", "0", "1"], ["88480.4", "0", "0", "0"], ["88480", "0.05209548", "0", "4"], ["88479.9", "0", "0", "0"], ["88479", "0", "0", "0"], ["88478.9", "0.066845", "0", "1"], ["88478.7", "0", "0", "0"], ["88478.2", "0", "0", "0"], ["88478", "0", "0", "0"], ["88476.8", "0.18391502", "0", "1"], ["88476.5", "0", "0", "0"], ["88476.2", "0.00343", "0", "1"], ["88476", "0", "0", "0"], ["88475.7", "0", "0", "0"], ["88475.6", "0", "0", "0"], ["88475.1", "0.64644062", "0", "1"], ["88474.1", "0.52927486", "0", "1"], ["88474", "0", "0", "0"], ["88473.3", "0.03585546", "0", "1"], ["88472.9", "0", "0", "0"], ["88472.7", "0", "0", "0"], ["88472.6", "0.11343045", "0", "1"], ["88472.5", "0", "0", "0"], ["88472.2", "0.147132", "0", "2"], ["88472.1", "0", "0", "0"], ["88472", "0", "0", "0"], ["88471.9", "0.20567", "0", "1"], ["88471.6", "0.02671259", "0", "1"], ["88471.4", "0", "0", "0"], ["88470.8", "1.03074085", "0", "2"], ["88470", "0.04519342", "0", "1"], ["88468.9", "0", "0", "0"], ["88467", "0.00343", "0", "1"], ["88465.6", "0.47921", "0", "1"], ["88464.9", "0.06349", "0", "1"], ["88463.8", "0.01128935", "0", "1"], ["88463.5", "0", "0", "0"], ["88462.3", "0.02698183", "0", "1"], ["88462", "0.17555399", "0", "1"], ["88459.2", "0.01695737", "0", "1"], ["88458.7", "0.08478", "0", "1"], ["88458.1", "0", "0", "0"], ["88457.6", "0", "0", "0"], ["88457.1", "0", "0", "0"], ["88455.8", "0.25894673", "0", "3"], ["88455.5", "0", "0", "0"], ["88455.3", "0", "0", "0"], ["88454.7", "0.01128989", "0", "1"], ["88453.1", "0.01129003", "0", "1"], ["88453", "0.06", "0", "2"], ["88452.2", "0", "0", "0"], ["88451.2", "0.00003", "0", "2"], ["88450.2", "0", "0", "0"], ["88450", "0.177132", "0", "3"], ["88449.6", "0.00151669", "0", "1"], ["88449", "0", "0", "0"], ["88447", "0.01739603", "0", "1"], ["88445.4", "0.00102649", "0", "1"], ["88445.3", "0.00564951", "0", "1"], ["88445.2", "0", "0", "0"], ["88444.6", "0.447594", "0", "1"], ["88444.2", "0.11280696", "0", "1"], ["88443.1", "0.00564951", "0", "1"], ["88443", "0", "0", "0"], ["88439.9", "0.00564951", "0", "1"], ["88439.8", "0", "0", "0"], ["88438.1", "0.00098674", "0", "1"], ["88438", "2.13189172", "0", "2"], ["88437.8", "0", "0", "0"], ["88437.4", "0", "0", "0"], ["88436.6", "0", "0", "0"], ["88436.5", "0.43447", "0", "1"], ["88436.3", "0", "0", "0"], ["88435", "0", "0", "0"], ["88434.9", "0", "0", "0"], ["88433.9", "0.00564951", "0", "1"], ["88432.9", "0", "0", "0"], ["88432.2", "0.00564951", "0", "1"], ["88430.8", "0", "0", "0"], ["88430.6", "0", "0", "0"], ["88430.5", "0.01", "0", "2"], ["88430.2", "0.0045196", "0", "1"], ["88429.5", "0.00451934", "0", "1"], ["88428", "0", "0", "0"], ["88427.9", "0", "0", "0"], ["88427.6", "0", "0", "0"], ["88426.7", "0.0045196", "0", "1"], ["88426.5", "0.50146496", "0", "2"], ["88424.6", "0", "0", "0"], ["88424.4", "0.00451934", "0", "1"], ["88423.1", "0.0045196", "0", "1"], ["88422.6", "0", "0", "0"], ["88422.3", "0", "0", "0"], ["88419.4", "0", "0", "0"], ["88419.3", "0", "0", "0"], ["88418.5", "0.02259802", "0", "1"], ["88417.7", "0", "0", "0"], ["88416.9", "0", "0", "0"], ["88416.6", "0.00060139", "0", "2"], ["88416.2", "0", "0", "0"], ["88416", "0.000015", "0", "1"], ["88414.7", "3.19658", "0", "1"], ["88414.2", "0.01064", "0", "1"], ["88413.8", "0.06804094", "0", "1"], ["88413.7", "0.01128332", "0", "1"], ["88411.8", "0", "0", "0"], ["88405.7", "0.05651526", "0", "2"], ["88405.3", "0", "0", "0"], ["88403.9", "0", "0", "0"], ["88402.7", "0", "0", "0"], ["88402.3", "0", "0", "0"], ["88400.4", "0", "0", "0"], ["88400.3", "0", "0", "0"], ["88400", "0.00153064", "0", "3"], ["88399.9", "0.00461135", "0", "4"], ["88399.3", "0", "0", "0"], ["88398.8", "0", "0", "0"], ["88391.8", "0.00318998", "0", "2"], ["88387.8", "0", "0", "0"], ["88385.7", "0", "0", "0"], ["88381.8", "0", "0", "0"], ["88380.5", "0.000721", "0", "1"], ["88379.3", "0.11314637", "0", "1"], ["88376.2", "0.00564982", "0", "1"], ["88376", "0", "0", "0"], ["88372.7", "0.03", "0", "1"], ["88371.4", "0.17396031", "0", "1"], ["88369.7", "0", "0", "0"], ["88365.7", "3.84862", "0", "2"], ["88360.2", "0", "0", "0"], ["88359.6", "0", "0", "0"], ["88358.5", "0.01694853", "0", "3"], ["88355.7", "0", "0", "0"], ["88351.8", "0", "0", "0"], ["88350", "0.00194323", "0", "2"], ["88341.9", "0", "0", "0"], ["88339.1", "0", "0", "0"], ["88338.8", "0", "0", "0"], ["88338.7", "0", "0", "0"], ["88338.6", "0", "0", "0"], ["88333.5", "0", "0", "0"], ["88333.3", "0.00466192", "0", "5"], ["88332", "0", "0", "0"], ["88329.7", "0.0405", "0", "3"], ["88329.6", "0.054", "0", "4"], ["88329.4", "0", "0", "0"], ["88326.5", "0", "0", "0"], ["88325.2", "0.01128332", "0", "1"], ["88323", "0", "0", "0"], ["88322.8", "0", "0", "0"], ["88320.7", "0", "0", "0"], ["88320.5", "0.00005177", "0", "1"], ["88319.2", "0", "0", "0"], ["88314.2", "0.00001992", "0", "1"], ["88311.1", "0.0406", "0", "2"], ["88311", "0.0609", "0", "3"], ["88310.4", "0", "0", "0"], ["88309.1", "0", "0", "0"], ["88309", "0.00010748", "0", "1"], ["88308.8", "0.00001835", "0", "1"], ["88306.9", "0", "0", "0"], ["88306.8", "0", "0", "0"], ["88294.7", "0.00001118", "0", "1"], ["88290.5", "0", "0", "0"], ["88290.3", "0", "0", "0"], ["88290.1", "0", "0", "0"], ["88290", "0.00001172", "0", "1"], ["88283.8", "0", "0", "0"], ["88280.9", "0.00566386", "0", "1"], ["88279.9", "0.00001655", "0", "1"], ["88275.5", "0.00001139", "0", "1"], ["88275", "0.00009665", "0", "2"], ["88274.9", "0", "0", "0"], ["88270.7", "0.00003554", "0", "1"], ["88266.6", "0.00488183", "0", "7"], ["88266", "0", "0", "0"], ["88264.4", "0.00024852", "0", "1"], ["88262.9", "0.00168511", "0", "2"], ["88261.8", "0.00074456", "0", "1"], ["88260", "0.00002148", "0", "1"], ["88259.2", "0.00005974", "0", "1"], ["88259.1", "0.00011181", "0", "1"], ["88258.7", "0.00282652", "0", "1"]], "ts": "1741338229105", "checksum": 1817609819, "seqId": 48070567922, "prevSeqId": 48070565044}]}
{"arg": {"channel": "books", "instId": "BTC-USDT"}, "action": "update", "data": [{"asks": [["88510.9", "0.14448915", "0", "14"], ["88513.6", "0.00067669", "0", "1"], ["88514.2", "0.00013161", "0", "3"], ["88514.3", "0.0001", "0", "1"], ["88515.7", "0", "0", "0"], ["88516.2", "0", "0", "0"], ["88520.8", "0.08478364", "0", "2"], ["88520.9", "0.06124342", "0", "2"], ["88521", "0.02853077", "0", "1"], ["88523.5", "0.06124342", "0", "2"], ["88523.6", "0.03062171", "0", "1"], ["88523.7", "0.11371355", "0", "2"], ["88523.8", "0.00023979", "0", "3"], ["88525", "0.03067674", "0", "3"], ["88525.1", "0.08354114", "0", "1"], ["88525.7", "0.15091647", "0", "3"], ["88526.9", "0", "0", "0"], ["88527.8", "0", "0", "0"], ["88528.1", "0.2039694", "0", "2"], ["88529.8", "0.13622845", "0", "3"], ["88531.3", "0.06126238", "0", "3"], ["88531.6", "0.042", "0", "1"], ["88531.8", "0.06124342", "0", "2"], ["88532.1", "0.093", "0", "2"], ["88532.8", "0.25424281", "0", "2"], ["88535.9", "0.02285283", "0", "2"], ["88536.6", "0", "0", "0"], ["88538.7", "0.04", "0", "1"], ["88542.4", "0.128201", "0", "1"], ["88543.8", "0.04", "0", "1"], ["88544.3", "0.11305736", "0", "3"], ["88549.5", "0", "0", "0"], ["88549.6", "0.22595983", "0", "2"], ["88549.7", "0.207", "0", "1"], ["88552", "0.06023792", "0", "4"], ["88553", "0.09", "0", "3"], ["88556.4", "0.012102", "0", "1"], ["88561.1", "0.0000134", "0", "1"], ["88563", "0.50032219", "0", "2"], ["88564", "0.54608111", "0", "2"], ["88564.4", "0.59839525", "0", "2"], ["88564.9", "1.6222363", "0", "2"], ["88567.7", "0.497924", "0", "1"], ["88568.1", "0.02265112", "0", "3"], ["88569.8", "0", "0", "0"], ["88573", "0.01739617", "0", "1"], ["88592.2", "0.03489447", "0", "1"], ["88594.9", "0", "0", "0"], ["88597.4", "0.00183765", "0", "1"], ["88598.6", "2.86478929", "0", "1"], ["88600", "0", "0", "0"], ["88600.1", "0", "0", "0"], ["88600.3", "0", "0", "0"], ["88600.9", "0", "0", "0"], ["88601.1", "0", "0", "0"], ["88601.3", "0", "0", "0"], ["88601.4", "0", "0", "0"], ["88601.6", "0", "0", "0"], ["88601.9", "0", "0", "0"], ["88602", "0", "0", "0"], ["88602.1", "0", "0", "0"]], "bids": [["88510.7", "0", "0", "0"], ["88510.6", "0.08102393", "0", "1"], ["88510.5", "0.11297862", "0", "1"], ["88507.7", "0.0002", "0", "2"], ["88506.8", "0.0194028", "0", "1"], ["88506.5", "0", "0", "0"], ["88503.7", "0", "0", "0"], ["88503.3", "0.34345007", "0", "2"], ["88501.1", "0.04823348", "0", "1"], ["88501", "0.03606759", "0", "2"], ["88500.5", "0.02757565", "0", "1"], ["88499.5", "0", "0", "0"], ["88498.6", "0", "0", "0"], ["88496.9", "0.07114787", "0", "1"], ["88496.8", "0", "0", "0"], ["88496.7", "0.08678486", "0", "1"], ["88495.8", "0.08524674", "0", "1"], ["88494.7", "0", "0", "0"], ["88494.6", "0.00375", "0", "1"], ["88494.4", "0", "0", "0"], ["88493.9", "0", "0", "0"], ["88492.5", "0.22594483", "0", "1"], ["88492.4", "0.11300176", "0", "1"], ["88492.1", "0.01650401", "0", "1"], ["88492", "0.70331253", "0", "3"], ["88491.5", "0", "0", "0"], ["88488.7", "0.13387246", "0", "1"], ["88485.2", "0.03", "0", "1"], ["88484.5", "0.0384603", "0", "1"], ["88484", "0", "0", "0"], ["88483", "0", "0", "0"], ["88481.6", "0.09", "0", "3"], ["88481.3", "0.49841", "0", "1"], ["88469.7", "0.03", "0", "1"], ["88468.6", "0.498482", "0", "1"], ["88466.2", "0.09", "0", "3"], ["88456.2", "0.38583411", "0", "1"], ["88453.2", "0.21301963", "0", "2"], ["88450.4", "0.0306025", "0", "1"], ["88450", "0.19452817", "0", "4"], ["88447", "0", "0", "0"], ["88445.5", "0.747917", "0", "1"], ["88440", "0.00098677", "0", "1"], ["88439", "2.08616738", "0", "3"], ["88438.1", "0", "0", "0"], ["88432.2", "0.3720215", "0", "2"], ["88431.5", "0.748036", "0", "1"], ["88430.2", "0.03573457", "0", "2"], ["88427.4", "0.01316", "0", "1"], ["88426.8", "0.00093027", "0", "1"], ["88421.9", "0.03677941", "0", "1"], ["88414.8", "0.52704188", "0", "1"], ["88405.9", "0", "0", "0"], ["88386.8", "0.00212232", "0", "1"], ["88376.2", "0.00657648", "0", "2"], ["88374.2", "0.17396178", "0", "1"], ["88371.4", "0", "0", "0"], ["88368.3", "0", "0", "0"], ["88338.3", "0", "0", "0"], ["88264.7", "0", "0", "0"], ["88264.4", "0", "0", "0"], ["88264.2", "0", "0", "0"], ["88262.9", "0", "0", "0"], ["88261.8", "0", "0", "0"], ["88260", "0", "0", "0"], ["88259.2", "0", "0", "0"], ["88259.1", "0", "0", "0"], ["88258.7", "0", "0", "0"]], "ts": "1741338229205", "checksum": -540147055, "seqId": 48070568231, "prevSeqId": 48070567922}]}
{"arg": {"channel": "books", "instId": "BTC-USDT"}, "action": "update", "data": [{"asks": [["88510.9", "0.16183598", "0", "18"], ["88513.9", "0.0001", "0", "1"], ["88514.3", "0", "0", "0"], ["88516.9", "0.03809694", "0", "1"], ["88517.6", "0.11296974", "0", "1"], ["88519.5", "0.08851328", "0", "1"], ["88519.6", "0.06124342", "0", "2"], ["88519.7", "0.000066", "0", "1"], ["88519.8", "0.01353", "0", "1"], ["88520.4", "0.02818598", "0", "1"], ["88520.6", "0.0282429", "0", "2"], ["88520.8", "0", "0", "0"], ["88521", "0", "0", "0"], ["88522.3", "0.06164905", "0", "6"], ["88523.6", "0", "0", "0"], ["88523.7", "0.0748356", "0", "1"], ["88524.6", "0.07972537", "0", "1"], ["88524.8", "0.01353", "0", "1"], ["88525.1", "0", "0", "0"], ["88525.3", "0.08024848", "0", "2"], ["88525.7", "0.03062032", "0", "1"], ["88526.4", "0.04065179", "0", "3"], ["88529.3", "0.14033538", "0", "1"], ["88529.8", "0.00002635", "0", "2"], ["88531.8", "0", "0", "0"], ["88532.4", "0.3466828", "0", "3"], ["88532.7", "0.11295043", "0", "1"], ["88532.8", "0", "0", "0"], ["88534.1", "0.039", "0", "1"], ["88550.9", "0.012102", "0", "1"], ["88556.4", "0", "0", "0"], ["88567.6", "0.52689572", "0", "1"], ["88569.4", "0.00292156", "0", "1"], ["88573.5", "0.1", "0", "1"], ["88578", "0.00112894", "0", "1"], ["88582.4", "0.00116693", "0", "2"], ["88598.2", "0", "0", "0"], ["88598.3", "0", "0", "0"], ["88598.5", "0", "0", "0"], ["88598.6", "0", "0", "0"], ["88599.2", "0", "0", "0"], ["88599.4", "0", "0", "0"], ["88599.7", "0", "0", "0"], ["88599.9", "0", "0", "0"]], "bids": [["88510.8", "0.13537128", "0", "5"], ["88510.3", "0", "0", "0"], ["88508.8", "0", "0", "0"], ["88507.7", "0", "0", "0"], ["88505", "0.00943", "0", "1"], ["88503.2", "0.05929109", "0", "3"], ["88501.6", "0", "0", "0"], ["88501", "0.00838873", "0", "1"], ["88500.5", "0.02889217", "0", "1"], ["88500.1", "0.02915016", "0", "1"], ["88496.9", "0.06653766", "0", "2"], ["88496.7", "0.00943", "0", "1"], ["88496.3", "0.07918074", "0", "1"], ["88495.9", "0.0002", "0", "2"], ["88495.8", "0", "0", "0"], ["88495.4", "0.08092323", "0", "1"], ["88494.6", "0", "0", "0"], ["88494.2", "0.03", "0", "1"], ["88492.1", "0", "0", "0"], ["88492", "0.56483917", "0", "2"], ["88491.5", "0.13757351", "0", "1"], ["88491.2", "0.01650401", "0", "1"], ["88491.1", "0.03", "0", "1"], ["88489.2", "0.002703", "0", "1"], ["88488.7", "0", "0", "0"], ["88488.4", "0.09228845", "0", "1"], ["88488.3", "0.14824693", "0", "1"], ["88488.1", "0", "0", "0"], ["88484.5", "0", "0", "0"], ["88484.1", "0.00115384", "0", "1"], ["88482.8", "0.4360692", "0", "1"], ["88466.2", "0.03", "0", "1"], ["88464", "0.1", "0", "1"], ["88428", "0.00019382", "0", "1"], ["88427.4", "0.0143098", "0", "2"], ["88414.8", "0", "0", "0"], ["88413.7", "0", "0", "0"], ["88413.6", "0", "0", "0"], ["88407.8", "0.0017066", "0", "1"], ["88402.2", "0.01128186", "0", "1"], ["88325.2", "0", "0", "0"], ["88296.1", "0.01127961", "0", "1"], ["88269.2", "0", "0", "0"], ["88267.2", "0", "0", "0"], ["88266.6", "0", "0", "0"], ["88265.3", "0", "0", "0"]], "ts": "1741338229305", "checksum": 941170897, "seqId": 48070568462, "prevSeqId": 48070568231}]}
{"arg": {"channel": "books", "instId": "BTC-USDT"}, "action": "update", "data": [{"asks": [["88513.7", "0.0001", "0", "1"], ["88513.8", "0.0001", "0", "1"], ["88513.9", "0", "0", "0"], ["88514.2", "0.00003161", "0", "2"], ["88514.9", "0.08428397", "0", "1"], ["88515", "0.06136465", "0", "3"], ["88515.9", "0.06124342", "0", "2"], ["88516.9", "0", "0", "0"], ["88517.6", "0", "0", "0"], ["88519.5", "0.13034984", "0", "2"], ["88519.8", "0.22053", "0", "2"], ["88519.9", "0.02912164", "0", "1"], ["88520.2", "0.02751548", "0", "1"], ["88520.4", "0", "0", "0"], ["88520.6", "0.00083", "0", "1"], ["88523.7", "0.15365159", "0", "1"], ["88524.2", "0.08358742", "0", "1"], ["88524.6", "0", "0", "0"], ["88524.9", "0.08755326", "0", "1"], ["88525.3", "0.00001147", "0", "1"], ["88525.6", "0.33929724", "0", "1"], ["88525.7", "0", "0", "0"], ["88526.8", "0", "0", "0"], ["88528.1", "0.50753108", "0", "3"], ["88528.9", "0", "0", "0"], ["88529.3", "0", "0", "0"], ["88531.3", "0.00001896", "0", "1"], ["88531.8", "0.90244663", "0", "1"], ["88532.4", "0.2017754", "0", "2"], ["88537.1", "0.16864938", "0", "28"], ["88540.3", "0.22595874", "0", "1"], ["88544", "0.01294448", "0", "3"], ["88545.9", "0.06542966", "0", "2"], ["88549.5", "0.147132", "0", "2"], ["88549.6", "0.000015", "0", "1"], ["88550.9", "0", "0", "0"], ["88573.5", "0", "0", "0"], ["88597.4", "0", "0", "0"]], "bids": [["88510.8", "0.1", "0", "1"], ["88510.6", "0", "0", "0"], ["88510.5", "0", "0", "0"], ["88510", "0", "0", "0"], ["88508.4", "0", "0", "0"], ["88506.9", "0", "0", "0"], ["88506.6", "0", "0", "0"], ["88506.1", "0.00145491", "0", "1"], ["88506", "0.07258733", "0", "2"], ["88505", "0", "0", "0"], ["88503.3", "0.01357284", "0", "1"], ["88503.2", "0.00734436", "0", "1"], ["88502.1", "0.0001", "0", "1"], ["88501.9", "0", "0", "0"], ["88501.1", "0.06791478", "0", "2"], ["88500.5", "0", "0", "0"], ["88500.1", "0.02777391", "0", "1"], ["88499.7", "0.02837633", "0", "1"], ["88499.2", "0.04", "0", "1"], ["88496.9", "0", "0", "0"], ["88496.7", "0.04587339", "0", "2"], ["88496.3", "0", "0", "0"], ["88495.9", "0.0001", "0", "1"], ["88495.8", "0.08979572", "0", "1"], ["88495.4", "0", "0", "0"], ["88494.2", "0.06", "0", "2"], ["88492.5", "0", "0", "0"], ["88491.5", "0", "0", "0"], ["88491.2", "0", "0", "0"], ["88490.7", "1.33174387", "0", "5"], ["88489.6", "0.01650401", "0", "1"], ["88489.2", "0", "0", "0"], ["88488.4", "0.15012479", "0", "2"], ["88488.3", "0", "0", "0"], ["88485.3", "0.22595874", "0", "1"], ["88484.1", "0", "0", "0"], ["88483.5", "0.08658276", "0", "2"], ["88482", "0", "0", "0"], ["88481.6", "0.06", "0", "2"], ["88469.9", "0", "0", "0"], ["88469.7", "0", "0", "0"], ["88466.2", "0", "0", "0"], ["88414.8", "0.1702034", "0", "2"], ["88402.2", "0", "0", "0"], ["88296.1", "0", "0", "0"], ["88294", "0.0025", "0", "1"], ["88274", "0.06797011", "0", "1"], ["88269.2", "0.08542891", "0", "1"], ["88268.6", "0.00282509", "0", "1"], ["88267.2", "0.00002851", "0", "1"], ["88266.6", "0.00488183", "0", "7"], ["88265.3", "0.00004344", "0", "1"], ["88264.7", "0.00004446", "0", "3"], ["88264.4", "0.00024852", "0", "1"], ["88264.2", "0.00001139", "0", "1"], ["88262.9", "0.00168511", "0", "2"], ["88261.8", "0.00074456", "0", "1"], ["88260", "0.00002148", "0", "1"], ["88259.2", "0.00005974", "0", "1"], ["88259.1", "0.00011181", "0", "1"], ["88258.7", "0.00282652", "0", "1"]], "ts": "1741338229405", "checksum": 1382170897, "seqId": 48070568741, "prevSeqId": 48070568462}]}
{"arg": {"channel": "books", "instId": "BTC-USDT"}, "action": "update", "data": [{"asks": [["88513.7", "0", "0", "0"], ["88513.8", "0.0002", "0", "2"], ["88513.9", "0.02332234", "0", "1"], ["88514.7", "0.06124342", "0", "2"], ["88514.9", "0.02916489", "0", "1"], ["88515.9", "0", "0", "0"], ["88516.2", "0.01353", "0", "1"], ["88518", "0.00064009", "0", "1"], ["88519.4", "0.02845386", "0", "1"], ["88519.6", "0.08778544", "0", "3"], ["88519.8", "0.207", "0", "1"], ["88519.9", "0", "0", "0"], ["88520.2", "0", "0", "0"], ["88523.6", "0.08260762", "0", "1"], ["88524.2", "0", "0", "0"], ["88524.3", "0.08380641", "0", "3"], ["88524.9", "0", "0", "0"], ["88528.4", "0.14196075", "0", "3"], ["88531.4", "0.14129578", "0", "1"], ["88539.5", "0.012102", "0", "1"], ["88544", "0.00084248", "0", "2"], ["88545.9", "0.10139968", "0", "3"], ["88568.9", "0.00005367", "0", "2"], ["88573.4", "0.1", "0", "1"], ["88578", "0.00362894", "0", "2"], ["88597.4", "0.00183765", "0", "1"], ["88597.5", "0", "0", "0"], ["88597.6", "0", "0", "0"], ["88598", "0", "0", "0"], ["88598.1", "0", "0", "0"]], "bids": [["88508.3", "0.11298138", "0", "1"], ["88504.7", "0.04", "0", "1"], ["88502.1", "0", "0", "0"], ["88501.4", "0.00943", "0", "1"], ["88500.1", "0", "0", "0"], ["88499.7", "0", "0", "0"], ["88499.5", "0.02651241", "0", "2"], ["88499.3", "0.0001", "0", "1"], ["88499.2", "0", "0", "0"], ["88499.1", "0.02812715", "0", "1"], ["88496.7", "0.06785988", "0", "3"], ["88495.9", "0", "0", "0"], ["88495.8", "0", "0", "0"], ["88495.3", "0.08856054", "0", "1"], ["88494.4", "0.08120748", "0", "1"], ["88490.5", "0.13105005", "0", "1"], ["88487.3", "0.13293672", "0", "1"], ["88486.8", "0.0000165", "0", "1"], ["88483.6", "0.015", "0", "1"], ["88483.5", "1.73407075", "0", "3"], ["88481.6", "0", "0", "0"], ["88470.8", "0.59612099", "0", "2"], ["88414.8", "0.60485326", "0", "2"], ["88261.8", "0", "0", "0"], ["88260", "0", "0", "0"], ["88259.2", "0", "0", "0"], ["88259.1", "0", "0", "0"], ["88258.7", "0", "0", "0"]], "ts": "1741338229505", "checksum": -1329005306, "seqId": 48070568905, "prevSeqId": 48070568741}]}
{"arg": {"channel": "books", "instId": "BTC-USDT"}, "action": "update", "data": [{"asks": [["88510.9", "0.26551177", "0", "21"], ["88511", "0.06518326", "0", "2"], ["88511.1", "0.1129883", "0", "2"], ["88513.8", "0", "0", "0"], ["88513.9", "0", "0", "0"], ["88514.1", "0.000333", "0", "1"], ["88514.3", "0.0001", "0", "1"], ["88514.4", "0.0001", "0", "1"], ["88514.9", "0.04814333", "0", "2"], ["88518.7", "0.06328859", "0", "17"], ["88519.4", "0", "0", "0"], ["88519.6", "0", "0", "0"], ["88521", "0.0406", "0", "1"], ["88523.6", "0", "0", "0"], ["88524.3", "0.00003088", "0", "2"], ["88524.4", "0.00226688", "0", "2"], ["88526.4", "0.00006179", "0", "2"], ["88528.1", "0.51096183", "0", "4"], ["88528.4", "0.00029378", "0", "2"], ["88531.4", "0", "0", "0"], ["88538", "0.012102", "0", "1"], ["88539.5", "0", "0", "0"], ["88541.5", "0.08544043", "0", "2"], ["88578.3", "0", "0", "0"], ["88586.9", "0.03247359", "0", "2"], ["88592.2", "0", "0", "0"], ["88597.5", "0.11908342", "0", "3"], ["88597.6", "0.0000601", "0", "1"], ["88598", "0.00002736", "0", "1"], ["88598.1", "0.00001026", "0", "1"]], "bids": [["88510.8", "0.1101", "0", "2"], ["88508.3", "0", "0", "0"], ["88506.8", "0", "0", "0"], ["88506.2", "0.00145491", "0", "1"], ["88506.1", "0.11298419", "0", "1"], ["88506", "0.0155", "0", "1"], ["88501.1", "0.03776701", "0", "2"], ["88501", "0", "0", "0"], ["88499.5", "0", "0", "0"], ["88499.4", "0", "0", "0"], ["88499.3", "0", "0", "0"], ["88499.1", "0", "0", "0"], ["88498.4", "0.01235224", "0", "3"], ["88497.5", "0.0194028", "0", "1"], ["88496.7", "0.10264887", "0", "3"], ["88495.3", "0", "0", "0"], ["88495.1", "0.00345618", "0", "1"], ["88494.4", "0", "0", "0"], ["88494.1", "0.04", "0", "1"], ["88492.5", "0.26186811", "0", "1"], ["88492", "0.01861722", "0", "1"], ["88490.8", "0.33929724", "0", "1"], ["88490.7", "0.09", "0", "3"], ["88490.5", "0", "0", "0"], ["88489.5", "0", "0", "0"], ["88488.4", "0.35822423", "0", "1"], ["88487.3", "0", "0", "0"], ["88486.8", "0", "0", "0"], ["88485.4", "0.90244663", "0", "1"], ["88485.2", "0", "0", "0"], ["88483.6", "0.34443365", "0", "2"], ["88483.5", "0", "0", "0"], ["88482.8", "0", "0", "0"], ["88481.3", "0", "0", "0"], ["88480.7", "0.0002", "0", "2"], ["88480.2", "0.34106724", "0", "2"], ["88474.1", "0", "0", "0"], ["88472.6", "0", "0", "0"], ["88471.6", "0", "0", "0"], ["88470.8", "0.43181", "0", "1"], ["88470", "0", "0", "0"], ["88468.6", "0", "0", "0"], ["88465", "0.03519612", "0", "1"], ["88460.5", "0.02671259", "0", "1"], ["88450.4", "0", "0", "0"], ["88445.2", "0.0325233", "0", "1"], ["88439", "1.22918792", "0", "3"], ["88438.9", "0", "0", "0"], ["88414.8", "0.97783196", "0", "2"], ["88413.8", "0", "0", "0"], ["88411.4", "1.06349326", "0", "1"], ["88408.9", "0.02025345", "0", "1"], ["88400.3", "0.15431393", "0", "1"], ["88386.1", "0.13470916", "0", "2"], ["88283.8", "0.207", "0", "1"], ["88261.8", "0.00074456", "0", "1"], ["88260", "0.00002148", "0", "1"], ["88259.2", "0.00005974", "0", "1"], ["88259.1", "0.00011181", "0", "1"], ["88258.7", "0.00282652", "0", "1"], ["88257.9", "0.00020125", "0", "2"], ["88257.8", "0.5999", "0", "1"], ["88257.6", "0.00003493", "0", "1"], ["88256.9", "0.34056098", "0", "1"], ["88256.4", "0.0000172", "0", "1"]], "ts": "1741338229605", "checksum": -1621903366, "seqId": 48070569118, "prevSeqId": 48070568905}]}
{"arg": {"channel": "books", "instId": "BTC-USDT"}, "action": "update", "data": [{"asks": [["88510.9", "0.15483598", "0", "17"], ["88513.2", "0.0001", "0", "1"], ["88514.1", "0", "0", "0"], ["88514.3", "0", "0", "0"], ["88514.4", "0", "0", "0"], ["88514.5", "0.00096796", "0", "11"], ["88514.9", "0.16419899", "0", "1"], ["88515", "0.00012123", "0", "1"], ["88516.5", "0.33929724", "0", "1"], ["88517.6", "0.02646779", "0", "1"], ["88517.7", "0.02646492", "0", "1"], ["88519.5", "0.13472629", "0", "2"], ["88520.9", "0", "0", "0"], ["88521.4", "0.08367227", "0", "1"], ["88522", "0.08757616", "0", "1"], ["88522.3", "0.00040563", "0", "4"], ["88525.7", "0.13927143", "0", "1"], ["88528.5", "0.13940964", "0", "1"], ["88538", "0", "0", "0"], ["88538.6", "0.012102", "0", "1"], ["88597.4", "0", "0", "0"], ["88597.6", "0", "0", "0"], ["88598", "0", "0", "0"], ["88598.1", "0", "0", "0"]], "bids": [["88510.8", "0.1122", "0", "3"], ["88506.2", "0", "0", "0"], ["88506.1", "0.00145491", "0", "1"], ["88506", "0.07307516", "0", "2"], ["88501.1", "0.07983119", "0", "1"], ["88500.1", "0.06124342", "0", "2"], ["88499.9", "0.06124342", "0", "2"], ["88499.5", "0.02989169", "0", "1"], ["88499.1", "0.02632329", "0", "1"], ["88496.8", "0.06124342", "0", "2"], ["88496.7", "0.10414401", "0", "3"], ["88495.7", "0.08465285", "0", "1"], ["88494.8", "0.08142975", "0", "1"], ["88492.5", "0.18694313", "0", "1"], ["88491.4", "0.14465453", "0", "1"], ["88490.8", "0", "0", "0"], ["88489.6", "0", "0", "0"], ["88488.5", "0.01650401", "0", "1"], ["88488.4", "0.50243085", "0", "2"], ["88483.6", "0.34558935", "0", "3"], ["88481", "0.0001", "0", "1"], ["88480.7", "0.0001", "0", "1"], ["88480.2", "0.33929724", "0", "1"], ["88408.1", "0", "0", "0"], ["88403.6", "0", "0", "0"], ["88399.2", "0", "0", "0"], ["88257.8", "0", "0", "0"], ["88257.6", "0", "0", "0"], ["88256.9", "0", "0", "0"], ["88256.4", "0", "0", "0"]], "ts": "1741338229705", "checksum": -1975665842, "seqId": 48070569294, "prevSeqId": 48070569118}]}
{"arg": {"channel": "books", "instId": "BTC-USDT"}, "action": "update", "data": [{"asks": [["88510.9", "0.18474417", "0", "19"], ["88511", "0.03125988", "0", "2"], ["88511.1", "0.00001035", "0", "1"], ["88513.2", "0", "0", "0"], ["88513.3", "0.00013735", "0", "4"], ["88513.8", "0.0001", "0", "1"], ["88514.5", "0.00086796", "0", "10"], ["88514.8", "0.02938692", "0", "1"], ["88514.9", "0", "0", "0"], ["88516.2", "0", "0", "0"], ["88516.5", "0", "0", "0"], ["88517.6", "0", "0", "0"], ["88517.7", "0", "0", "0"], ["88518.9", "0.02726238", "0", "1"], ["88519.1", "0.02873559", "0", "1"], ["88519.5", "0.05735333", "0", "3"], ["88519.7", "0", "0", "0"], ["88519.8", "0.00006675", "0", "1"], ["88520.4", "0.000963", "0", "1"], ["88521", "0", "0", "0"], ["88521.4", "0", "0", "0"], ["88522", "0", "0", "0"], ["88522.8", "0.08564073", "0", "1"], ["88523.4", "0.09003787", "0", "1"], ["88525.7", "0", "0", "0"], ["88526.8", "0.04059", "0", "1"], ["88527.1", "0.14690296", "0", "2"], ["88528.5", "0", "0", "0"], ["88529.9", "0.14981486", "0", "3"], ["88538.6", "0", "0", "0"], ["88541.4", "0.012102", "0", "1"], ["88551", "0.06003451", "0", "4"], ["88552", "0.09023792", "0", "5"], ["88553", "0", "0", "0"], ["88597.4", "0.00183765", "0", "1"], ["88597.6", "0.0000601", "0", "1"], ["88598", "0.00002736", "0", "1"], ["88598.1", "0.00001026", "0", "1"], ["88598.2", "0.00018525", "0", "1"]], "bids": [["88510.8", "0.26922194", "0", "6"], ["88510", "0.0155", "0", "1"], ["88504.8", "0.00943", "0", "1"], ["88503.3", "0", "0", "0"], ["88501.4", "0", "0", "0"], ["88501.1", "0.04736954", "0", "1"], ["88500.9", "0.02621558", "0", "1"], ["88500.5", "0.02883091", "0", "1"], ["88499.9", "0", "0", "0"], ["88499.5", "0", "0", "0"], ["88499.1", "0", "0", "0"], ["88497.3", "0.0002", "0", "2"], ["88497", "0.08543409", "0", "1"], ["88496.9", "0.15540609", "0", "1"], ["88496.7", "0.00943", "0", "1"], ["88496.2", "0.08854746", "0", "1"], ["88495.7", "0", "0", "0"], ["88494.8", "0", "0", "0"], ["88493", "0.207", "0", "1"], ["88492.7", "0.46025138", "0", "3"], ["88492.6", "0.33929724", "0", "1"], ["88492.5", "0", "0", "0"], ["88491.4", "0", "0", "0"], ["88489.8", "0.1407848", "0", "1"], ["88488.4", "0.35822423", "0", "1"], ["88487.1", "0.0021645", "0", "1"], ["88483.6", "0.79690056", "0", "4"], ["88481.5", "1.6426886", "0", "1"], ["88481", "0", "0", "0"], ["88480.7", "0", "0", "0"], ["88473.9", "0.53770529", "0", "1"], ["88473.6", "0.498454", "0", "1"], ["88469.1", "0.03720836", "0", "1"], ["88469", "0.06", "0", "2"], ["88468", "0.06", "0", "2"], ["88467", "0.03343", "0", "2"], ["88466.2", "0.11343045", "0", "1"], ["88462", "0.34067442", "0", "2"], ["88460.2", "0.498529", "0", "1"], ["88453.2", "0.15391788", "0", "1"], ["88453", "0", "0", "0"], ["88451", "0", "0", "0"], ["88450", "0.16452817", "0", "3"], ["88448", "1.70661047", "0", "1"], ["88447.9", "3.03697919", "0", "2"], ["88446.6", "0", "0", "0"], ["88420.6", "0.00205", "0", "1"], ["88416.2", "0.00205", "0", "1"], ["88414.8", "0.12048679", "0", "1"], ["88411.8", "0.00205", "0", "1"], ["88411.4", "0", "0", "0"], ["88400.3", "0", "0", "0"], ["88264.2", "0", "0", "0"], ["88262.9", "0", "0", "0"], ["88261.8", "0", "0", "0"], ["88260", "0", "0", "0"], ["88259.2", "0", "0", "0"], ["88259.1", "0", "0", "0"], ["88258.7", "0", "0", "0"], ["88257.9", "0", "0", "0"]], "ts": "1741338229805", "checksum": 547703374, "seqId": 48070569534, "prevSeqId": 48070569294}]}
{"arg": {"channel": "books", "instId": "BTC-USDT"}, "action": "update", "data": [{"asks": [["88510.9", "0.15662857", "0", "18"], ["88513.3", "0.00023735", "0", "5"], ["88513.8", "0", "0", "0"], ["88518.9", "0", "0", "0"], ["88519.1", "0.02959438", "0", "1"], ["88519.3", "0.03007437", "0", "1"], ["88519.5", "0.07883466", "0", "2"], ["88522.8", "0", "0", "0"], ["88523", "0.08814443", "0", "1"], ["88523.4", "0", "0", "0"], ["88523.6", "0.07874388", "0", "1"], ["88527.1", "0.0000102", "0", "1"], ["88527.3", "0.13701537", "0", "2"], ["88529.9", "0.00003508", "0", "2"], ["88530.1", "0.13111332", "0", "2"], ["88538", "0.012102", "0", "1"], ["88541.4", "0", "0", "0"], ["88556.8", "0.0006", "0", "2"], ["88557.6", "0.0003", "0", "1"], ["88598.2", "0", "0", "0"]], "bids": [["88510.8", "0.26712194", "0", "5"], ["88501.1", "0.10488948", "0", "3"], ["88500.9", "0", "0", "0"], ["88500.7", "0.02847019", "0", "1"], ["88500.5", "0", "0", "0"], ["88497.3", "0.0001", "0", "1"], ["88497.2", "0.0852893", "0", "2"], ["88497", "0", "0", "0"], ["88496.4", "0.08113301", "0", "1"], ["88496.2", "0", "0", "0"], ["88493", "0.3397801", "0", "2"], ["88492.7", "0.31474596", "0", "2"], ["88490.1", "0.01650401", "0", "1"], ["88490", "0.16400996", "0", "2"], ["88489.8", "0", "0", "0"], ["88488.5", "0", "0", "0"], ["88475.1", "0.92333225", "0", "2"], ["88468", "0", "0", "0"], ["88467", "0.06343", "0", "3"], ["88466", "0.03", "0", "1"], ["88264.2", "0.00001139", "0", "1"], ["88262.9", "0.00168511", "0", "2"]], "ts": "1741338229905", "checksum": 285579859, "seqId": 48070569633, "prevSeqId": 48070569534}]}
{"arg": {"channel": "books", "instId": "BTC-USDT"}, "action": "update", "data": [{"asks": [["88510.9", "0.16016814", "0", "20"], ["88513.3", "0.00003735", "0", "3"], ["88513.6", "0.00087669", "0", "3"], ["88519.1", "0.02998978", "0", "1"], ["88519.3", "0.02837444", "0", "1"], ["88519.5", "0.08239916", "0", "3"], ["88519.8", "0.00004725", "0", "1"], ["88520.3", "0.00021", "0", "1"], ["88520.4", "0", "0", "0"], ["88523", "0.08755327", "0", "1"], ["88523.6", "0.08328016", "0", "1"], ["88527.3", "0.13467778", "0", "2"], ["88530", "0.14456076", "0", "3"], ["88530.1", "0.00001295", "0", "1"], ["88537.1", "0.1029341", "0", "27"], ["88537.5", "0.01212516", "0", "3"], ["88538", "0", "0", "0"], ["88540.3", "0", "0", "0"], ["88541.8", "0.776686", "0", "2"], ["88543.3", "0.00001005", "0", "1"], ["88549.4", "0.22594973", "0", "1"], ["88551.6", "0.0100114", "0", "2"], ["88554.6", "0.01895223", "0", "6"], ["88578.2", "0.0157003", "0", "2"], ["88598.2", "0.00018525", "0", "1"]], "bids": [["88501.1", "0.10304641", "0", "3"], ["88500.7", "0.02993311", "0", "1"], ["88497.3", "0", "0", "0"], ["88497.2", "0.08750523", "0", "1"], ["88497.1", "0.0002", "0", "2"], ["88496.9", "0.51410548", "0", "2"], ["88496.8", "0", "0", "0"], ["88496.4", "0.08417998", "0", "1"], ["88494.3", "0.90244663", "0", "1"], ["88493", "0.207", "0", "1"], ["88492.9", "0.14745806", "0", "1"], ["88491.2", "0.22594973", "0", "1"], ["88485.3", "0", "0", "0"], ["88468", "0.06", "0", "2"], ["88467", "0.03343", "0", "2"], ["88466", "0", "0", "0"], ["88431.5", "1.087286", "0", "2"], ["88426.5", "0.03", "0", "1"], ["88355.4", "0", "0", "0"]], "ts": "1741338230005", "checksum": -1201752357, "seqId": 48070569736, "prevSeqId": 48070569633}]}
{"arg": {"channel": "books", "instId": "BTC-USDT"}, "action": "update", "data": [{"asks": [["88510.9", "0.00975012", "0", "16"], ["88511", "0.00005648", "0", "1"], ["88512", "0", "0", "0"], ["88513.5", "0.0000195", "0", "1"], ["88513.6", "0.00067669", "0", "1"], ["88514.7", "0", "0", "0"], ["88514.8", "0", "0", "0"], ["88517", "0.00014778", "0", "1"], ["88517.2", "0.00013114", "0", "4"], ["88517.4", "0.0001", "0", "1"], ["88518.7", "0.00204517", "0", "15"], ["88519.1", "0", "0", "0"], ["88519.3", "0", "0", "0"], ["88519.5", "0", "0", "0"], ["88520.3", "0", "0", "0"], ["88523", "0", "0", "0"], ["88523.2", "0", "0", "0"], ["88523.6", "0", "0", "0"], ["88523.7", "0", "0", "0"], ["88524.4", "0.00001314", "0", "1"], ["88526", "0.01129639", "0", "1"], ["88526.1", "0", "0", "0"], ["88526.8", "0", "0", "0"], ["88527.3", "0.00002616", "0", "1"], ["88527.6", "0.01353", "0", "1"], ["88528.1", "0.31806002", "0", "1"], ["88530", "0.00009419", "0", "2"], ["88531.6", "0", "0", "0"], ["88532.1", "0", "0", "0"], ["88534.1", "0", "0", "0"], ["88534.2", "0.04059", "0", "1"], ["88537.5", "0.00002316", "0", "2"], ["88538.7", "0", "0", "0"], ["88540.1", "0.00228667", "0", "2"], ["88541.5", "0.00001152", "0", "1"], ["88544.2", "0", "0", "0"], ["88545.3", "0.04", "0", "1"], ["88545.7", "0.10949624", "0", "1"], ["88545.9", "0.00007302", "0", "1"], ["88547.6", "0.012102", "0", "1"], ["88549.4", "0", "0", "0"], ["88554.8", "0.22593229", "0", "1"], ["88556.4", "0.00225374", "0", "1"], ["88556.9", "0.03600262", "0", "1"], ["88563", "0.00237119", "0", "1"], ["88564", "0.00001139", "0", "1"], ["88564.4", "0.13365531", "0", "1"], ["88564.9", "0.00001626", "0", "1"], ["88567.7", "0", "0", "0"], ["88570.9", "0.49793964", "0", "2"], ["88573", "0", "0", "0"], ["88574.3", "0.01740693", "0", "2"], ["88586.9", "0.00001998", "0", "1"], ["88595.9", "0", "0", "0"], ["88598.3", "0.34056098", "0", "1"], ["88598.5", "0.49884", "0", "1"], ["88599.2", "0.04519393", "0", "1"], ["88599.4", "0.00003797", "0", "1"], ["88599.7", "0.00002124", "0", "2"], ["88599.9", "0.24751403", "0", "8"], ["88600", "0.93175892", "0", "95"], ["88600.1", "0.0057003", "0", "1"], ["88600.9", "0.00001055", "0", "1"], ["88601.3", "0.00072895", "0", "4"], ["88601.4", "0.00001181", "0", "1"], ["88601.6", "0.0045196", "0", "1"]], "bids": [["88510.8", "0.30699474", "0", "8"], ["88510.4", "0.06810512", "0", "1"], ["88510.3", "0.08542891", "0", "1"], ["88508.8", "0.00943", "0", "1"], ["88508.2", "0.09824832", "0", "3"], ["88506.6", "0.01853488", "0", "1"], ["88506", "0.23880137", "0", "3"], ["88504.8", "0", "0", "0"], ["88503.2", "0.12766794", "0", "5"], ["88502.3", "0.22593036", "0", "1"], ["88502.2", "0.33929724", "0", "1"], ["88502.1", "0.02829", "0", "1"], ["88501.6", "0.04789949", "0", "1"], ["88501.1", "0", "0", "0"], ["88501", "0.00001046", "0", "1"], ["88500.8", "0.08542891", "0", "1"], ["88500.7", "0", "0", "0"], ["88500.3", "0.00827091", "0", "1"], ["88500.1", "0", "0", "0"], ["88498.4", "0.00105468", "0", "2"], ["88497.5", "0", "0", "0"], ["88497.2", "0", "0", "0"], ["88497.1", "0", "0", "0"], ["88496.9", "0.36286189", "0", "1"], ["88496.6", "0.00224296", "0", "1"], ["88496.4", "0", "0", "0"], ["88496.1", "0.00001138", "0", "1"], ["88495.5", "0.0001", "0", "1"], ["88494.1", "0", "0", "0"], ["88493.6", "0.0001", "0", "1"], ["88492.9", "0", "0", "0"], ["88492.7", "0.21626114", "0", "2"], ["88492", "0", "0", "0"], ["88491.2", "0", "0", "0"], ["88490.8", "0.01650401", "0", "1"], ["88490.1", "0", "0", "0"], ["88490", "0.0155", "0", "1"], ["88489.6", "0.08542891", "0", "1"], ["88487.1", "0", "0", "0"], ["88486", "0.03635172", "0", "1"], ["88483.6", "0.78190056", "0", "3"], ["88482.8", "0.03838275", "0", "1"], ["88473.6", "0", "0", "0"], ["88473.3", "0", "0", "0"], ["88465", "0", "0", "0"], ["88462", "0.17555399", "0", "1"], ["88460.2", "0", "0", "0"], ["88450.1", "0.017397", "0", "1"], ["88450", "0.147132", "0", "2"], ["88448.1", "0.00102678", "0", "1"], ["88445.4", "0", "0", "0"], ["88445.2", "0", "0", "0"], ["88434", "0.00019382", "0", "1"], ["88431.5", "0.748036", "0", "1"], ["88428", "0", "0", "0"], ["88426.5", "0.0647436", "0", "2"], ["88425.3", "0.01657651", "0", "1"], ["88387.2", "0.00212325", "0", "1"], ["88386.8", "0", "0", "0"], ["88384.6", "0.00565", "0", "1"], ["88375.6", "0.17396847", "0", "1"], ["88374.2", "0", "0", "0"], ["88340.7", "0.00001138", "0", "1"], ["88264.7", "0", "0", "0"], ["88264.4", "0", "0", "0"], ["88264.2", "0", "0", "0"], ["88262.9", "0", "0", "0"]], "ts": "1741338230105", "checksum": 931657079, "seqId": 48070570094, "prevSeqId": 48070569736}]}
{"arg": {"channel": "books", "instId": "BTC-USDT"}, "action": "update", "data": [{"asks": [["88510.9", "0.00410755", "0", "4"], ["88514", "0", "0", "0"], ["88517.2", "0.00003114", "0", "3"], ["88517.4", "0", "0", "0"], ["88519.9", "0.00112803", "0", "1"], ["88521.8", "0.0001", "0", "1"], ["88522.2", "0.03734726", "0", "1"], ["88522.3", "0.06164905", "0", "6"], ["88522.4", "0.0002407", "0", "5"], ["88524.2", "0.02807176", "0", "1"], ["88524.4", "0.02951022", "0", "2"], ["88524.6", "0.07780029", "0", "2"], ["88524.7", "0.03062171", "0", "1"], ["88524.9", "0.06124342", "0", "2"], ["88525", "0.00005642", "0", "2"], ["88525.6", "0", "0", "0"], ["88527.6", "0", "0", "0"], ["88528.1", "0.14725491", "0", "2"], ["88528.7", "0.08409675", "0", "1"], ["88530.7", "0.00333616", "0", "1"], ["88531.8", "0", "0", "0"], ["88532.4", "0.34091761", "0", "3"], ["88536.8", "0.045", "0", "1"], ["88540.3", "0.135", "0", "3"], ["88543", "0.00008419", "0", "3"], ["88547.6", "0", "0", "0"], ["88550.2", "0.23392029", "0", "2"], ["88554.7", "0.012102", "0", "1"], ["88554.8", "0.22593339", "0", "1"], ["88571.7", "0", "0", "0"], ["88574.3", "0.00001009", "0", "1"], ["88576", "0.0306943", "0", "4"], ["88591.9", "0", "0", "0"], ["88593.4", "0.00172782", "0", "1"], ["88599.2", "0", "0", "0"], ["88600", "0.97695114", "0", "96"], ["88600.7", "0.02930087", "0", "1"], ["88600.9", "0", "0", "0"], ["88601.3", "0", "0", "0"], ["88601.4", "0", "0", "0"], ["88601.6", "0", "0", "0"]], "bids": [["88510.8", "0.30925004", "0", "9"], ["88510.6", "0.0001", "0", "1"], ["88510.5", "0.00145491", "0", "1"], ["88510.1", "0.0001", "0", "1"], ["88506.2", "0.02972572", "0", "1"], ["88506.1", "0", "0", "0"], ["88506", "0.4926473", "0", "4"], ["88505.8", "0.02735451", "0", "1"], ["88503.3", "0.90244663", "0", "1"], ["88502.3", "0.0813111", "0", "1"], ["88501.6", "0.11658184", "0", "1"], ["88501.5", "0.08095855", "0", "1"], ["88501", "0.00002096", "0", "1"], ["88500.9", "0.22592872", "0", "1"], ["88498", "0.15820883", "0", "2"], ["88496.6", "0", "0", "0"], ["88495.5", "0", "0", "0"], ["88495.1", "0.14967408", "0", "2"], ["88493.6", "0", "0", "0"], ["88492.7", "0.21174099", "0", "1"], ["88491.2", "0.01650401", "0", "1"], ["88490.8", "0", "0", "0"], ["88470.6", "0.0019", "0", "1"], ["88469", "0.12", "0", "4"], ["88468", "0.03", "0", "1"], ["88467", "0.00343", "0", "1"], ["88459", "0.03083963", "0", "1"], ["88453.3", "0.0173966", "0", "1"], ["88450.1", "0", "0", "0"], ["88430.5", "0.005", "0", "1"], ["88426.4", "0", "0", "0"], ["88419.9", "0.005", "0", "1"], ["88391.8", "0.00007209", "0", "1"], ["88382.9", "0.00001139", "0", "1"], ["88377.3", "0.17396609", "0", "1"], ["88375.6", "0", "0", "0"], ["88374.1", "0", "0", "0"], ["88268.6", "0", "0", "0"], ["88267.2", "0", "0", "0"], ["88266.6", "0", "0", "0"], ["88265.3", "0", "0", "0"]], "ts": "1741338230205", "checksum": 1737951647, "seqId": 48070570355, "prevSeqId": 48070570094}]}
{"arg": {"channel": "books", "instId": "BTC-USDT"}, "action": "update", "data": [{"asks": [["88510.9", "0", "0", "0"], ["88511", "0", "0", "0"], ["88511.1", "0", "0", "0"], ["88511.2", "0", "0", "0"], ["88511.6", "0", "0", "0"], ["88511.7", "0", "0", "0"], ["88511.9", "0", "0", "0"], ["88512.2", "0", "0", "0"], ["88512.7", "0", "0", "0"], ["88512.8", "0", "0", "0"], ["88512.9", "0", "0", "0"], ["88513.3", "0", "0", "0"], ["88513.5", "0", "0", "0"], ["88513.6", "0", "0", "0"], ["88514.2", "0", "0", "0"], ["88516", "0", "0", "0"], ["88519.8", "0", "0", "0"], ["88521.6", "0.0001", "0", "1"], ["88521.8", "0", "0", "0"], ["88522", "0.0001", "0", "1"], ["88522.2", "0", "0", "0"], ["88522.3", "0.00040563", "0", "4"], ["88522.4", "0.0001407", "0", "4"], ["88523.5", "0", "0", "0"], ["88524.1", "0.03692228", "0", "2"], ["88524.2", "0", "0", "0"], ["88524.4", "0.00001314", "0", "1"], ["88524.6", "0", "0", "0"], ["88524.7", "0", "0", "0"], ["88524.9", "0", "0", "0"], ["88525.8", "0", "0", "0"], ["88526", "0.12425531", "0", "2"], ["88527", "0", "0", "0"], ["88528.1", "0", "0", "0"], ["88528.7", "0", "0", "0"], ["88528.9", "0.01353", "0", "1"], ["88529.1", "0", "0", "0"], ["88530.7", "0", "0", "0"], ["88531.9", "0.0002131", "0", "2"], ["88532.4", "0.14892407", "0", "3"], ["88532.7", "0", "0", "0"], ["88535.9", "0.00025932", "0", "1"], ["88536.3", "0.0186343", "0", "1"], ["88536.8", "0.09", "0", "2"], ["88537.1", "0.14173788", "0", "28"], ["88537.6", "0.01888533", "0", "1"], ["88540.3", "0.174", "0", "4"], ["88541.7", "0.01502123", "0", "3"], ["88542.4", "0", "0", "0"], ["88543.8", "0", "0", "0"], ["88544.9", "0.02259135", "0", "1"], ["88549.8", "0.11292863", "0", "1"], ["88550.2", "0.13540439", "0", "1"], ["88551", "0.00003451", "0", "2"], ["88552", "0.00023792", "0", "2"], ["88552.1", "0.04137118", "0", "2"], ["88554.6", "0.00199223", "0", "5"], ["88554.7", "0", "0", "0"], ["88554.8", "0", "0", "0"], ["88556.4", "0", "0", "0"], ["88556.8", "0", "0", "0"], ["88557.6", "0", "0", "0"], ["88557.7", "0.22674777", "0", "2"], ["88559.7", "0.012102", "0", "1"], ["88560", "0.12474113", "0", "10"], ["88561", "0.03", "0", "1"], ["88564.8", "0.0006", "0", "2"], ["88565.6", "0.00031088", "0", "2"], ["88572.1", "0", "0", "0"], ["88573.3", "0.07116087", "0", "1"], ["88573.4", "0", "0", "0"], ["88575.9", "0.00001673", "0", "1"], ["88576", "0.0132977", "0", "3"], ["88577.2", "0.34437848", "0", "1"], ["88577.6", "0.49790984", "0", "5"], ["88578.9", "0.02288464", "0", "3"], ["88582.7", "0.147132", "0", "2"], ["88595.7", "0.0057003", "0", "1"], ["88597.4", "0", "0", "0"], ["88598.1", "0.00184781", "0", "2"], ["88600", "0.93175892", "0", "95"], ["88600.9", "0.00001055", "0", "1"], ["88601.3", "0.00072895", "0", "4"], ["88601.4", "0.00001181", "0", "1"], ["88601.6", "0.0045196", "0", "1"], ["88601.9", "0.00451934", "0", "1"], ["88602", "0.00451934", "0", "1"], ["88602.1", "0.00003678", "0", "3"], ["88602.4", "0.000015", "0", "1"], ["88602.8", "0.00001008", "0", "1"], ["88602.9", "0.00010012", "0", "1"], ["88603", "0.00001028", "0", "1"], ["88603.1", "0.207", "0", "1"], ["88603.3", "0.00659021", "0", "3"], ["88603.4", "0.00005116", "0", "5"], ["88603.7", "0.00001139", "0", "1"], ["88603.8", "0.00003683", "0", "1"], ["88604", "0.00001042", "0", "1"], ["88604.1", "0.0001929", "0", "5"], ["88604.3", "0.00001362", "0", "1"], ["88605.2", "0.0000166", "0", "1"], ["88605.3", "0.00569815", "0", "1"], ["88605.6", "0.31324478", "0", "2"], ["88605.7", "0.0045196", "0", "1"], ["88605.9", "0.00451934", "0", "1"], ["88606", "0.0049834", "0", "4"], ["88606.1", "0.174119", "0", "1"], ["88606.5", "0.0057003", "0", "1"], ["88606.9", "0.00052479", "0", "1"]], "bids": [["88514.4", "0.29822467", "0", "9"], ["88514.2", "0.54923596", "0", "3"], ["88514.1", "0.17134953", "0", "4"], ["88514", "0.35731562", "0", "3"], ["88512.7", "0.11357284", "0", "2"], ["88512.6", "0.06137673", "0", "3"], ["88512.1", "0.02907", "0", "1"], ["88512", "0.0155", "0", "1"], ["88511.7", "0.00145491", "0", "1"], ["88511.6", "0.05194673", "0", "2"], ["88511.3", "0.0001", "0", "1"], ["88510.9", "0.00224276", "0", "1"], ["88510.8", "0.05194673", "0", "2"], ["88510.6", "0", "0", "0"], ["88510.5", "0", "0", "0"], ["88510.4", "0.04", "0", "1"], ["88510.1", "0", "0", "0"], ["88508.8", "0", "0", "0"], ["88508.4", "0.06069746", "0", "1"], ["88508.2", "0.14", "0", "2"], ["88507.5", "0.02829", "0", "1"], ["88506.2", "0", "0", "0"], ["88506", "0.46202559", "0", "3"], ["88505.9", "0", "0", "0"], ["88505.8", "0", "0", "0"], ["88504.7", "0", "0", "0"], ["88504", "0.01551501", "0", "2"], ["88503.4", "0.22591795", "0", "1"], ["88502.7", "0.207", "0", "1"], ["88502.3", "0", "0", "0"], ["88502.2", "0.39578634", "0", "2"], ["88502.1", "0", "0", "0"], ["88501.7", "0.128196", "0", "1"], ["88501.6", "0.0516269", "0", "1"], ["88501.5", "0", "0", "0"], ["88501.4", "0.00943", "0", "1"], ["88501", "0", "0", "0"], ["88500.9", "0", "0", "0"], ["88499.8", "0", "0", "0"], ["88498", "0.0155", "0", "1"], ["88496.7", "0", "0", "0"], ["88495.1", "0.00345618", "0", "1"], ["88494.4", "0.01650401", "0", "1"], ["88491.2", "0", "0", "0"], ["88490", "0", "0", "0"], ["88486.6", "0.49838", "0", "1"], ["88486", "0.03978172", "0", "2"], ["88484.4", "0", "0", "0"], ["88483.7", "0.11343045", "0", "1"], ["88483.6", "0.33058935", "0", "2"], ["88482.8", "0", "0", "0"], ["88481.5", "0", "0", "0"], ["88480.5", "0.13972953", "0", "2"], ["88479.7", "0.04519138", "0", "1"], ["88476", "0.02075056", "0", "1"], ["88474.3", "0.0008", "0", "1"], ["88473.4", "0.49846638", "0", "2"], ["88472.4", "0", "0", "0"], ["88470.6", "0", "0", "0"], ["88467", "0", "0", "0"], ["88464", "0", "0", "0"], ["88460.5", "0", "0", "0"], ["88459.4", "0", "0", "0"], ["88456.3", "0.01739576", "0", "1"], ["88453.3", "0", "0", "0"], ["88448", "0.78605178", "0", "1"], ["88447.9", "0.002", "0", "1"], ["88441.4", "0.00098669", "0", "1"], ["88440", "0", "0", "0"], ["88432.9", "0.0225952", "0", "1"], ["88432.2", "0.35449403", "0", "3"], ["88426.5", "0.23168777", "0", "3"], ["88418.5", "0", "0", "0"], ["88414.8", "0.76752325", "0", "1"], ["88411.5", "0", "0", "0"], ["88406.7", "0.05335289", "0", "1"], ["88380.6", "0.17395764", "0", "1"], ["88379.1", "0.10001", "0", "2"], ["88377.3", "0", "0", "0"], ["88372.2", "0", "0", "0"], ["88367.7", "0.01694663", "0", "3"], ["88358.5", "0", "0", "0"], ["88352.1", "0", "0", "0"], ["88340.7", "0", "0", "0"], ["88328", "0", "0", "0"], ["88283.8", "0", "0", "0"], ["88268.6", "0.00282509", "0", "1"], ["88267.2", "0.00002851", "0", "1"], ["88266.6", "0.00489219", "0", "8"], ["88265.3", "0.00004344", "0", "1"], ["88264.7", "0.00004446", "0", "3"], ["88264.4", "0.00024852", "0", "1"], ["88264.2", "0.00001139", "0", "1"]], "ts": "1741338230305", "checksum": 1028375169, "seqId": 48070571106, "prevSeqId": 48070570355}]}
{"arg": {"channel": "books", "instId": "BTC-USDT"}, "action": "update", "data": [{"asks": [["88514.5", "0", "0", "0"], ["88514.6", "0", "0", "0"], ["88515", "0", "0", "0"], ["88521.5", "0.0001", "0", "1"], ["88521.6", "0", "0", "0"], ["88521.9", "0.00011028", "0", "2"], ["88522", "0", "0", "0"], ["88524.1", "0.00001636", "0", "1"], ["88524.3", "0.00009613", "0", "3"], ["88524.8", "0", "0", "0"], ["88526", "0.01129639", "0", "1"], ["88528.9", "0", "0", "0"], ["88530.9", "0.01353", "0", "1"], ["88532", "0", "0", "0"], ["88532.4", "0.00037328", "0", "1"], ["88534.7", "0", "0", "0"], ["88540.4", "0", "0", "0"], ["88545.3", "0", "0", "0"], ["88546.3", "0.04013676", "0", "2"], ["88551.5", "0.128196", "0", "1"], ["88552.1", "0.00137118", "0", "1"], ["88554.9", "0.78704093", "0", "2"], ["88555.5", "1.61550839", "0", "6"], ["88556.2", "0.04", "0", "1"], ["88557.7", "0.00083", "0", "1"], ["88559.7", "0", "0", "0"], ["88560", "0.00474113", "0", "6"], ["88561", "0.06", "0", "2"], ["88561.5", "0.012102", "0", "1"], ["88562", "0.09003029", "0", "5"], ["88564.2", "0.13136686", "0", "1"], ["88564.4", "0", "0", "0"], ["88564.5", "0", "0", "0"], ["88564.8", "0", "0", "0"], ["88565.6", "0.00001088", "0", "1"], ["88566.4", "0.0006", "0", "2"], ["88567.2", "0.000315", "0", "2"], ["88567.4", "0.22590613", "0", "1"], ["88573.3", "0.12737776", "0", "2"], ["88573.4", "0.53547542", "0", "1"], ["88574.1", "0.21704", "0", "1"], ["88577", "0.1", "0", "1"], ["88578.9", "0.00548888", "0", "2"], ["88587", "0", "0", "0"], ["88588.7", "0.02309534", "0", "2"], ["88589.1", "2.98532044", "0", "1"], ["88595.1", "0.96052521", "0", "3"], ["88597.5", "0.11344342", "0", "2"], ["88598.1", "0.00001026", "0", "1"], ["88600.6", "0.00183755", "0", "1"], ["88601.6", "0", "0", "0"], ["88601.9", "0", "0", "0"], ["88602", "0", "0", "0"], ["88605.7", "0", "0", "0"], ["88605.9", "0", "0", "0"], ["88606", "0.00046406", "0", "3"], ["88606.1", "0", "0", "0"], ["88607.1", "0.0399405", "0", "1"], ["88607.8", "0.01355291", "0", "2"], ["88607.9", "0.00001139", "0", "1"], ["88608", "0.0005953", "0", "1"], ["88608.4", "0.0057003", "0", "1"], ["88608.6", "0.00007393", "0", "1"], ["88609", "0.0609", "0", "3"], ["88609.1", "0.08578964", "0", "3"], ["88609.2", "0.00002478", "0", "1"]], "bids": [["88515.4", "0.51671825", "0", "19"], ["88515.3", "0.0001", "0", "1"], ["88515.1", "0.0001", "0", "1"], ["88515", "0.02847873", "0", "1"], ["88514.9", "0.04", "0", "1"], ["88514.7", "0.32812368", "0", "2"], ["88514.5", "0.11297358", "0", "1"], ["88514.4", "0.00001", "0", "1"], ["88514.2", "0.33929724", "0", "1"], ["88514.1", "0.05194673", "0", "2"], ["88514", "0.35721562", "0", "2"], ["88512.7", "0", "0", "0"], ["88511.3", "0", "0", "0"], ["88511.1", "0.22590613", "0", "1"], ["88511", "0.1", "0", "1"], ["88510.4", "0.13186746", "0", "2"], ["88508.4", "0", "0", "0"], ["88508.2", "0.04", "0", "1"], ["88506.4", "0.01357284", "0", "1"], ["88503.4", "0", "0", "0"], ["88500.5", "0.1", "0", "1"], ["88499.4", "0.003279", "0", "1"], ["88494.3", "1.04957863", "0", "3"], ["88488.4", "0.91117481", "0", "2"], ["88486.6", "0.59838", "0", "2"], ["88486", "0.00343", "0", "1"], ["88485.2", "1.64587474", "0", "1"], ["88480.7", "0.20567", "0", "1"], ["88478", "0.02698183", "0", "1"], ["88474.3", "0", "0", "0"], ["88472", "0.06", "0", "2"], ["88471.9", "0", "0", "0"], ["88471", "0.36929724", "0", "2"], ["88470", "0.00338919", "0", "1"], ["88469.1", "0.0185967", "0", "1"], ["88469", "0.06", "0", "2"], ["88468", "0", "0", "0"], ["88467.9", "0.00139113", "0", "1"], ["88466.3", "0.01739504", "0", "1"], ["88464.8", "0.1", "0", "1"], ["88462.3", "0", "0", "0"], ["88456.3", "0", "0", "0"], ["88453.2", "1.04143811", "0", "2"], ["88451.6", "3.02928123", "0", "1"], ["88451.3", "0.00102654", "0", "1"], ["88449.6", "0", "0", "0"], ["88448.1", "0", "0", "0"], ["88443.2", "0.00098666", "0", "1"], ["88441.4", "0", "0", "0"], ["88439", "1.08205592", "0", "1"], ["88432.2", "0.14586925", "0", "2"], ["88430.2", "0.0045196", "0", "1"], ["88426.5", "0.03", "0", "1"], ["88421.9", "0", "0", "0"], ["88414.8", "0", "0", "0"], ["88409.9", "0.76748", "0", "1"], ["88391.1", "0.17395049", "0", "1"], ["88389.9", "0.00212161", "0", "1"], ["88387.2", "0", "0", "0"], ["88386.7", "0.15086293", "0", "2"], ["88386", "0.00564873", "0", "1"], ["88383.9", "0.00452148", "0", "1"], ["88380.6", "0", "0", "0"], ["88376.2", "0.00092666", "0", "1"], ["88365", "0", "0", "0"], ["88347.4", "0.027", "0", "2"], ["88347.3", "0.12693045", "0", "2"], ["88344.5", "0", "0", "0"], ["88329.7", "0.027", "0", "2"], ["88329.6", "0.027", "0", "2"], ["88328.8", "0.0203", "0", "1"], ["88311", "0.0406", "0", "2"], ["88270", "0", "0", "0"], ["88269.4", "0", "0", "0"], ["88269.3", "0", "0", "0"], ["88269.2", "0", "0", "0"], ["88268.6", "0", "0", "0"], ["88267.2", "0", "0", "0"], ["88266.6", "0", "0", "0"], ["88265.3", "0", "0", "0"], ["88264.7", "0", "0", "0"], ["88264.4", "0", "0", "0"], ["88264.2", "0", "0", "0"]], "ts": "1741338230405", "checksum": 707808594, "seqId": 48070571610, "prevSeqId": 48070571106}]}
{"arg": {"channel": "books", "instId": "BTC-USDT"}, "action": "update", "data": [{"asks": [["88515.5", "0", "0", "0"], ["88516.5", "0.00001781", "0", "1"], ["88519.1", "0.00001949", "0", "1"], ["88521.5", "0", "0", "0"], ["88521.9", "0.00001028", "0", "1"], ["88522", "0.0155", "0", "1"], ["88523.4", "0.0001", "0", "1"], ["88523.8", "0.00033979", "0", "4"], ["88524.3", "0.00003088", "0", "2"], ["88525.2", "0.00004575", "0", "1"], ["88526", "0", "0", "0"], ["88532.4", "0.01390328", "0", "2"], ["88533.7", "0.07056152", "0", "1"], ["88533.8", "0.11294908", "0", "1"], ["88534.2", "0", "0", "0"], ["88535.1", "0.01129523", "0", "1"], ["88538.3", "0.00138609", "0", "10"], ["88539.1", "0.04059", "0", "1"], ["88541.8", "0.62009448", "0", "2"], ["88544.3", "0.00012172", "0", "2"], ["88554.9", "0.25659681", "0", "1"], ["88555.5", "0.0007951", "0", "5"], ["88559.2", "0", "0", "0"], ["88559.5", "0.943384", "0", "5"], ["88560.5", "0.22591161", "0", "1"], ["88560.8", "0.11291454", "0", "1"], ["88561", "0", "0", "0"], ["88561.4", "1.65465822", "0", "1"], ["88561.5", "0", "0", "0"], ["88562", "0.06003029", "0", "4"], ["88563", "0.09237119", "0", "4"], ["88564", "0.06714615", "0", "2"], ["88564.2", "0", "0", "0"], ["88566.4", "0", "0", "0"], ["88567.2", "0.000615", "0", "3"], ["88567.4", "0", "0", "0"], ["88567.6", "0.22320781", "0", "1"], ["88568", "0.0003", "0", "1"], ["88568.2", "0", "0", "0"], ["88569.4", "0.01502356", "0", "2"], ["88569.5", "0", "0", "0"], ["88570.9", "0.00003364", "0", "1"], ["88571", "0", "0", "0"], ["88573.3", "0.28099327", "0", "1"], ["88574.5", "0", "0", "0"], ["88577", "0", "0", "0"], ["88578", "0.10362894", "0", "3"], ["88578.2", "0.01", "0", "1"], ["88580.8", "0.00005364", "0", "1"], ["88585", "0.00002037", "0", "1"], ["88585.8", "0.02258678", "0", "2"], ["88586.6", "0.00016218", "0", "2"], ["88588.7", "0", "0", "0"], ["88588.8", "0.00011082", "0", "1"], ["88590.8", "0.44619", "0", "1"], ["88591.6", "0", "0", "0"], ["88592", "0.00018194", "0", "1"], ["88593.1", "0.01739436", "0", "1"], ["88595.7", "0", "0", "0"], ["88596.4", "0", "0", "0"], ["88600.6", "0", "0", "0"], ["88602", "0.00183755", "0", "1"], ["88605.6", "0.30754406", "0", "1"], ["88608.3", "0.00167684", "0", "1"], ["88608.9", "0.00570112", "0", "1"], ["88609", "0", "0", "0"], ["88609.1", "0", "0", "0"], ["88609.3", "0.00003049", "0", "3"], ["88609.4", "0.00147212", "0", "2"], ["88609.5", "0.02259758", "0", "1"], ["88610", "0.00004062", "0", "1"]], "bids": [["88516.3", "0.55263449", "0", "15"], ["88516.1", "0.02866253", "0", "1"], ["88516", "0.0155", "0", "1"], ["88515.7", "0.46002361", "0", "1"], ["88515.6", "0.0135", "0", "1"], ["88515.5", "0.1223923", "0", "2"], ["88515.4", "0.47481624", "0", "20"], ["88515.3", "0", "0", "0"], ["88515.1", "0", "0", "0"], ["88515", "0", "0", "0"], ["88514.9", "0", "0", "0"], ["88514.7", "0", "0", "0"], ["88514.5", "0", "0", "0"], ["88512.6", "0.05194673", "0", "2"], ["88512.1", "0", "0", "0"], ["88511.7", "0", "0", "0"], ["88511.1", "0.00145491", "0", "1"], ["88510.4", "0.06409303", "0", "1"], ["88506.5", "0.00005719", "0", "1"], ["88505.6", "0.00451949", "0", "1"], ["88503.4", "0.22591161", "0", "1"], ["88502.4", "0.03", "0", "1"], ["88501.6", "0.07408569", "0", "2"], ["88501.3", "0.00006", "0", "1"], ["88499.4", "0", "0", "0"], ["88498.1", "0.01650401", "0", "1"], ["88497.6", "0.03", "0", "1"], ["88496.7", "0.02671259", "0", "1"], ["88495.1", "0", "0", "0"], ["88494.4", "0", "0", "0"], ["88494", "0", "0", "0"], ["88493.6", "0.02698183", "0", "1"], ["88492.7", "0.30521516", "0", "2"], ["88492.2", "0.43181", "0", "1"], ["88491.8", "0", "0", "0"], ["88487", "0.47921", "0", "1"], ["88483.6", "0.32943365", "0", "1"], ["88483.4", "0.0001", "0", "1"], ["88480.5", "0.11301694", "0", "1"], ["88478", "0", "0", "0"], ["88470.8", "0", "0", "0"], ["88470.1", "0.01739436", "0", "1"], ["88469.1", "0.04627211", "0", "2"], ["88467.6", "0.1", "0", "1"], ["88466.3", "0", "0", "0"], ["88465.6", "0", "0", "0"], ["88464.8", "0", "0", "0"], ["88463.9", "0.00451898", "0", "1"], ["88452.4", "0.00102638", "0", "1"], ["88451.3", "0", "0", "0"], ["88444.7", "0.00098646", "0", "1"], ["88443.2", "0", "0", "0"], ["88439", "0.62268958", "0", "1"], ["88438.8", "0.33922", "0", "1"], ["88436.6", "0.00019389", "0", "1"], ["88434.3", "0.01316", "0", "1"], ["88434", "0", "0", "0"], ["88432.2", "0.00564951", "0", "1"], ["88427.4", "0.0011498", "0", "1"], ["88418.4", "0.01655332", "0", "1"], ["88408.8", "0", "0", "0"], ["88401.6", "0.25417", "0", "1"], ["88393.3", "0.1739436", "0", "1"], ["88391.9", "0.00212078", "0", "1"], ["88391.1", "0", "0", "0"], ["88389.9", "0", "0", "0"], ["88348.7", "0.0135", "0", "1"], ["88348.6", "0.0135", "0", "1"], ["88348.5", "0.0135", "0", "1"], ["88348.3", "0.0135", "0", "1"], ["88335.7", "0", "0", "0"], ["88330.1", "0.24873211", "0", "4"], ["88329.9", "0.0406", "0", "2"], ["88329.8", "0.00282493", "0", "1"], ["88329.7", "0", "0", "0"], ["88329.6", "0", "0", "0"], ["88328.3", "0.5999", "0", "1"], ["88311.1", "0", "0", "0"], ["88311", "0", "0", "0"], ["88291.4", "0", "0", "0"], ["88273.4", "0", "0", "0"], ["88272.7", "0", "0", "0"], ["88272", "0", "0", "0"], ["88271.5", "0", "0", "0"], ["88271.3", "0", "0", "0"], ["88270.8", "0", "0", "0"], ["88270.7", "0", "0", "0"]], "ts": "1741338230505", "checksum": 1668906210, "seqId": 48070572066, "prevSeqId": 48070571610}]}
{"arg": {"channel": "books", "instId": "BTC-USDT"}, "action": "update", "data": [{"asks": [["88522", "0", "0", "0"], ["88522.9", "0.00093", "0", "2"], ["88523.3", "0.00011021", "0", "2"], ["88523.4", "0", "0", "0"], ["88523.8", "0.00023979", "0", "3"], ["88533.2", "0.06124024", "0", "2"], ["88533.7", "0.03667679", "0", "1"], ["88533.8", "0", "0", "0"], ["88534.8", "0.06216957", "0", "3"], ["88536.1", "0.06124024", "0", "2"], ["88536.7", "0.06125024", "0", "3"], ["88536.8", "0", "0", "0"], ["88537.1", "0.1029341", "0", "27"], ["88538", "0.00225374", "0", "1"], ["88538.3", "0.00124659", "0", "9"], ["88540.3", "0", "0", "0"], ["88544", "0.04584248", "0", "3"], ["88545.7", "0.1543097", "0", "2"], ["88547.5", "0.087", "0", "2"], ["88547.6", "0.048", "0", "1"], ["88560.5", "0", "0", "0"], ["88562", "0.00003029", "0", "2"], ["88562.9", "0.22591061", "0", "1"], ["88563", "0.06237119", "0", "3"], ["88564", "0.15714615", "0", "5"], ["88567.2", "0.000015", "0", "1"], ["88567.6", "0.23530981", "0", "2"], ["88568", "0", "0", "0"], ["88568.8", "0.00251408", "0", "3"], ["88569.4", "0.00292156", "0", "1"], ["88569.6", "0.0003", "0", "1"], ["88570.3", "0.0046", "0", "1"], ["88573.3", "0.13456278", "0", "1"], ["88573.4", "0", "0", "0"], ["88575.7", "0.49799584", "0", "2"], ["88577.2", "0.60911385", "0", "2"], ["88578", "0.00362894", "0", "2"], ["88578.9", "0.10548888", "0", "3"], ["88579", "0.55963131", "0", "5"], ["88583.4", "0.0048", "0", "1"], ["88583.5", "0.01472769", "0", "3"], ["88583.7", "0.0069", "0", "1"], ["88593.1", "0", "0", "0"], ["88596.4", "0.01739457", "0", "1"], ["88609.5", "0", "0", "0"], ["88610", "0", "0", "0"]], "bids": [["88516.3", "0.57096029", "0", "13"], ["88515.7", "0.46012361", "0", "2"], ["88515.4", "0.45541344", "0", "19"], ["88514.7", "0.0001", "0", "1"], ["88511.9", "0.02698183", "0", "1"], ["88510.4", "0.1294767", "0", "2"], ["88507.6", "0.22591061", "0", "1"], ["88505.9", "0.002532", "0", "1"], ["88503.4", "0", "0", "0"], ["88502.4", "0.06", "0", "2"], ["88501.8", "0.00001138", "0", "1"], ["88501.6", "0.10226384", "0", "1"], ["88498.9", "0.01650401", "0", "1"], ["88498.8", "0.09", "0", "3"], ["88498.1", "0", "0", "0"], ["88495.3", "0.00198343", "0", "1"], ["88494.2", "0.03", "0", "1"], ["88493.6", "0", "0", "0"], ["88491.1", "0", "0", "0"], ["88490.7", "0.06", "0", "2"], ["88489.6", "0.08602891", "0", "3"], ["88488.8", "0.00029893", "0", "1"], ["88483.7", "0.11458986", "0", "2"], ["88482.3", "0", "0", "0"], ["88477", "0.06", "0", "2"], ["88475", "0.96244663", "0", "3"], ["88474", "0.03", "0", "1"], ["88473.5", "0.01739457", "0", "1"], ["88472", "0", "0", "0"], ["88471", "0.33929724", "0", "1"], ["88470.1", "0", "0", "0"], ["88469.1", "0", "0", "0"], ["88469", "0", "0", "0"], ["88468.7", "0.0305922", "0", "1"], ["88468.6", "0.1", "0", "1"], ["88467.6", "0", "0", "0"], ["88463.2", "0", "0", "0"], ["88462.4", "0", "0", "0"], ["88453.2", "1.56837069", "0", "1"], ["88451.1", "2.12624221", "0", "1"], ["88439.1", "0.00019389", "0", "1"], ["88439", "0", "0", "0"], ["88438.6", "0.01902607", "0", "1"], ["88438", "0.00564951", "0", "1"], ["88436.6", "0", "0", "0"], ["88400.7", "0.00564867", "0", "1"], ["88397.8", "0.17394575", "0", "1"], ["88393.3", "0", "0", "0"], ["88386", "0", "0", "0"], ["88385.2", "0.01694601", "0", "3"], ["88367.7", "0", "0", "0"], ["88307.5", "0.00566215", "0", "1"], ["88280.9", "0", "0", "0"], ["88274.2", "0", "0", "0"], ["88274.1", "0", "0", "0"], ["88274", "0", "0", "0"]], "ts": "1741338230605", "checksum": -541157074, "seqId": 48070572264, "prevSeqId": 48070572066}]}
{"arg": {"channel": "books", "instId": "BTC-USDT"}, "action": "update", "data": [{"asks": [["88518", "0", "0", "0"], ["88522.9", "0.00083", "0", "1"], ["88523", "0.0001", "0", "1"], ["88523.1", "0.0001275", "0", "2"], ["88523.3", "0.00001021", "0", "1"], ["88532.2", "0.02257704", "0", "1"], ["88532.3", "0.06135353", "0", "3"], ["88533.2", "0", "0", "0"], ["88533.7", "0.09115161", "0", "1"], ["88533.9", "0.11299498", "0", "2"], ["88540", "0.01354126", "0", "5"], ["88544", "0.09084248", "0", "4"], ["88544.7", "0.00345075", "0", "1"], ["88545.7", "0.22233715", "0", "1"], ["88547.5", "0.126", "0", "3"], ["88549.4", "0.11343045", "0", "1"], ["88562.9", "0", "0", "0"], ["88564", "0.21634654", "0", "6"], ["88567.1", "0.012102", "0", "1"], ["88567.4", "0.22590746", "0", "1"], ["88567.6", "0.22320781", "0", "1"], ["88573.3", "0.26710643", "0", "2"], ["88575", "0.2000626", "0", "3"], ["88608.3", "0", "0", "0"], ["88609.2", "0", "0", "0"], ["88609.3", "0", "0", "0"], ["88609.4", "0", "0", "0"]], "bids": [["88516.3", "0.63407471", "0", "16"], ["88515.7", "0.46002361", "0", "1"], ["88515.6", "0.0137", "0", "3"], ["88515.5", "0.1129723", "0", "1"], ["88514.7", "0", "0", "0"], ["88514.4", "0", "0", "0"], ["88511.9", "0", "0", "0"], ["88508.3", "0.22590746", "0", "1"], ["88507.6", "0", "0", "0"], ["88496.7", "0", "0", "0"], ["88495.1", "0.00330632", "0", "1"], ["88490.7", "0", "0", "0"], ["88477.3", "0.03580796", "0", "1"], ["88469.6", "0.0305967", "0", "1"], ["88469.5", "0.1", "0", "1"], ["88468.7", "0", "0", "0"], ["88468.6", "0", "0", "0"], ["88453.3", "0.00102634", "0", "1"], ["88452.4", "0", "0", "0"], ["88438.1", "0.02079188", "0", "1"], ["88422", "0.1", "0", "1"], ["88379.1", "0.00001", "0", "1"], ["88274.2", "0.00002298", "0", "1"]], "ts": "1741338230705", "checksum": -853094837, "seqId": 48070572361, "prevSeqId": 48070572264}]}
{"arg": {"channel": "books", "instId": "BTC-USDT"}, "action": "update", "data": [{"asks": [["88518.7", "0.00207267", "0", "16"], ["88523", "0", "0", "0"], ["88523.1", "0.0000275", "0", "1"], ["88524", "0.0001", "0", "1"], ["88524.1", "0.00011636", "0", "2"], ["88531.8", "0.02264097", "0", "1"], ["88531.9", "0.06145334", "0", "4"], ["88532.2", "0", "0", "0"], ["88532.3", "0.00011329", "0", "1"], ["88536.7", "0.00001", "0", "1"], ["88540", "0.00503926", "0", "4"], ["88544.7", "0", "0", "0"], ["88566.5", "0.012102", "0", "1"], ["88567.1", "0", "0", "0"], ["88580", "0", "0", "0"], ["88589", "0.02017077", "0", "2"], ["88601.4", "0.0031297", "0", "2"], ["88609", "0.1", "0", "1"], ["88609.2", "0.00002478", "0", "1"]], "bids": [["88516.3", "0.64764755", "0", "17"], ["88515.7", "0.46012361", "0", "2"], ["88515.6", "0.0135", "0", "1"], ["88514.7", "0.0001", "0", "1"], ["88512.1", "0.0042345", "0", "1"], ["88506.4", "0", "0", "0"], ["88505.9", "0", "0", "0"], ["88494.2", "0", "0", "0"], ["88424.2", "0.00311789", "0", "1"], ["88415.4", "0.00623578", "0", "1"], ["88406.5", "0.00935368", "0", "1"], ["88375.5", "0", "0", "0"], ["88274.2", "0", "0", "0"]], "ts": "1741338230805", "checksum": 1706301781, "seqId": 48070572437, "prevSeqId": 48070572361}]}
{"arg": {"channel": "books", "instId": "BTC-USDT"}, "action": "update", "data": [{"asks": [["88518.2", "0.005", "0", "1"], ["88522.5", "0.0002", "0", "2"], ["88524", "0", "0", "0"], ["88524.1", "0.00001636", "0", "1"], ["88528.8", "0.005", "0", "1"], ["88530.7", "0.04511415", "0", "1"], ["88530.8", "0.0612518", "0", "3"], ["88531.8", "0", "0", "0"], ["88533.2", "0.06124024", "0", "2"], ["88540", "0.00522826", "0", "5"], ["88545.2", "0.00341689", "0", "2"], ["88565.4", "0.012102", "0", "1"], ["88566.5", "0", "0", "0"], ["88608.9", "0", "0", "0"], ["88609", "0", "0", "0"], ["88609.2", "0", "0", "0"]], "bids": [["88516.3", "0.64765755", "0", "18"], ["88515.7", "0.46002361", "0", "1"], ["88514.7", "0.0002", "0", "2"], ["88512.1", "0", "0", "0"], ["88474.1", "0.02728", "0", "1"], ["88458.3", "0.01688898", "0", "1"], ["88446.5", "0.31254406", "0", "2"], ["88435.9", "0.005", "0", "1"], ["88274.6", "0", "0", "0"], ["88274.4", "0", "0", "0"]], "ts": "1741338230905", "checksum": 1837057894, "seqId": 48070572483, "prevSeqId": 48070572437}]}
{"arg": {"channel": "books", "instId": "BTC-USDT"}, "action": "update", "data": [{"asks": [["88522.5", "0.0001", "0", "1"], ["88522.9", "0.00093", "0", "2"], ["88530.7", "0.07336038", "0", "2"], ["88531.7", "0.1130615", "0", "3"], ["88533.1", "0.07952688", "0", "1"], ["88533.7", "0", "0", "0"], ["88533.9", "0.00004614", "0", "1"], ["88565.2", "0.01231097", "0", "3"], ["88565.4", "0", "0", "0"], ["88608.9", "0.00570112", "0", "1"]], "bids": [["88515.8", "0.33892", "0", "1"], ["88514.7", "0", "0", "0"], ["88514.5", "0.0001", "0", "1"], ["88514.3", "0.0001", "0", "1"], ["88512.3", "0.33894", "0", "1"], ["88471.6", "0.33909", "0", "1"], ["88438.8", "0", "0", "0"], ["88276.1", "0", "0", "0"], ["88275.5", "0", "0", "0"], ["88275", "0", "0", "0"]], "ts": "1741338231005", "checksum": -2134821807, "seqId": 48070572530, "prevSeqId": 48070572483}]}
{"arg": {"channel": "books", "instId": "BTC-USDT"}, "action": "update", "data": [{"asks": [["88516.4", "0", "0", "0"], ["88516.5", "0", "0", "0"], ["88516.6", "0", "0", "0"], ["88517", "0", "0", "0"], ["88517.2", "0", "0", "0"], ["88517.5", "0", "0", "0"], ["88518.2", "0", "0", "0"], ["88518.5", "0", "0", "0"], ["88518.7", "0", "0", "0"], ["88518.8", "0", "0", "0"], ["88519.1", "0", "0", "0"], ["88519.9", "0", "0", "0"], ["88520", "0", "0", "0"], ["88520.6", "0", "0", "0"], ["88522.5", "0", "0", "0"], ["88522.9", "0.00083", "0", "1"], ["88523.2", "0.00001875", "0", "1"], ["88524.3", "0.00001948", "0", "1"], ["88525.2", "0", "0", "0"], ["88528.9", "0.00112783", "0", "1"], ["88529.5", "0.00004725", "0", "1"], ["88530.7", "0", "0", "0"], ["88530.8", "0.00001156", "0", "1"], ["88530.9", "0", "0", "0"], ["88531.4", "0.0001", "0", "1"], ["88531.7", "0.00020983", "0", "3"], ["88531.9", "0.0002131", "0", "2"], ["88532.4", "0.00037328", "0", "1"], ["88533.1", "0", "0", "0"], ["88533.2", "0.01359642", "0", "1"], ["88534.8", "0.00092933", "0", "1"], ["88535.6", "0.01353", "0", "1"], ["88536.1", "0", "0", "0"], ["88536.3", "0", "0", "0"], ["88537.1", "0.0028354", "0", "26"], ["88537.6", "0", "0", "0"], ["88538", "0", "0", "0"], ["88538.1", "0.06132136", "0", "5"], ["88539.1", "0", "0", "0"], ["88539.6", "0.06156103", "0", "4"], ["88540", "0.00503926", "0", "4"], ["88540.1", "0.00003293", "0", "1"], ["88540.4", "0.01353", "0", "1"], ["88540.8", "0.06125842", "0", "3"], ["88541.6", "0.06169112", "0", "4"], ["88541.8", "0.43617948", "0", "1"], ["88541.9", "0", "0", "0"], ["88544.9", "0", "0", "0"], ["88545", "0.002163", "0", "1"], ["88545.2", "0.00002513", "0", "1"], ["88546.3", "0.00013676", "0", "1"], ["88547.1", "0.04059", "0", "1"], ["88548.4", "0.01866175", "0", "3"], ["88549.5", "0", "0", "0"], ["88551", "0.00228825", "0", "3"], ["88551.5", "0", "0", "0"], ["88551.6", "0.0000114", "0", "1"], ["88554.4", "0.02275568", "0", "2"], ["88555.2", "0.04006893", "0", "3"], ["88556.2", "0", "0", "0"], ["88556.9", "0", "0", "0"], ["88559.5", "0.40896957", "0", "4"], ["88561.2", "0.183915", "0", "1"], ["88561.4", "0", "0", "0"], ["88561.9", "0.18391502", "0", "1"], ["88563", "0.00237119", "0", "1"], ["88563.2", "0.04", "0", "1"], ["88564", "0.12634654", "0", "3"], ["88564.7", "0.03557417", "0", "1"], ["88565.2", "0.00020897", "0", "2"], ["88566", "0.12", "0", "4"], ["88567", "0.03", "0", "1"], ["88567.3", "0.00225374", "0", "1"], ["88567.4", "0", "0", "0"], ["88567.6", "0.24016781", "0", "2"], ["88568.8", "0.00191408", "0", "1"], ["88569.6", "0", "0", "0"], ["88570.3", "0.016702", "0", "2"], ["88570.4", "0.0006191", "0", "3"], ["88571.2", "0.0003", "0", "1"], ["88571.3", "0", "0", "0"], ["88573.1", "0.19458555", "0", "2"], ["88573.3", "0", "0", "0"], ["88575.7", "0.00011584", "0", "1"], ["88576.3", "0.22587633", "0", "1"], ["88577.2", "0.34437848", "0", "1"], ["88577.6", "0.00004084", "0", "4"], ["88578", "0.0025", "0", "1"], ["88578.9", "0.00548888", "0", "2"], ["88579", "0.00276168", "0", "4"], ["88582.4", "0.00003804", "0", "1"], ["88587.9", "0.00001074", "0", "1"], ["88589.1", "0", "0", "0"], ["88593.8", "0.07357739", "0", "2"], ["88600", "0.18514492", "0", "94"], ["88600.1", "0", "0", "0"], ["88600.7", "0", "0", "0"], ["88603.3", "0.00088991", "0", "2"], ["88606.5", "0.02948486", "0", "1"], ["88608.4", "0", "0", "0"], ["88609", "0.1", "0", "1"], ["88609.2", "0.00002478", "0", "1"], ["88609.3", "0.63071286", "0", "4"], ["88609.4", "0.00147212", "0", "2"], ["88610", "0.00004062", "0", "1"], ["88610.1", "0.11285173", "0", "1"], ["88610.2", "0.00623578", "0", "1"], ["88610.4", "0.00001013", "0", "1"], ["88610.5", "0.00003079", "0", "2"], ["88610.6", "0.1370973", "0", "2"], ["88610.7", "0.00151215", "0", "1"], ["88611", "0.00001016", "0", "1"], ["88611.1", "0.00028247", "0", "7"], ["88611.2", "0.000015", "0", "1"], ["88611.4", "0.01417453", "0", "2"], ["88611.8", "0.00009341", "0", "1"], ["88611.9", "0.00576114", "0", "2"], ["88612", "0.20703465", "0", "3"], ["88612.5", "0.34056098", "0", "1"], ["88612.6", "0.00570112", "0", "1"], ["88613", "0.00013037", "0", "1"], ["88613.3", "0.00005053", "0", "5"]], "bids": [["88521", "0.04092", "0", "2"], ["88520.6", "0.00086", "0", "1"], ["88520.5", "1.05596223", "0", "18"], ["88520", "0.05387978", "0", "4"], ["88519.9", "0.00224267", "0", "1"], ["88519.8", "0.00942", "0", "1"], ["88519.4", "0.0002", "0", "2"], ["88519.1", "0.39512295", "0", "2"], ["88518.8", "0.39366235", "0", "3"], ["88518", "0.04248183", "0", "2"], ["88517.5", "0.02671259", "0", "1"], ["88516.5", "0.00145491", "0", "1"], ["88516.3", "0.09195673", "0", "4"], ["88516.1", "0.1", "0", "1"], ["88515.8", "0", "0", "0"], ["88515.7", "0", "0", "0"], ["88515.5", "0", "0", "0"], ["88515.4", "0.34451344", "0", "15"], ["88514.7", "0.02828", "0", "1"], ["88514.5", "0", "0", "0"], ["88514.4", "0.70317626", "0", "1"], ["88514.3", "0.90244663", "0", "1"], ["88513.1", "0.00001138", "0", "1"], ["88512.3", "0", "0", "0"], ["88511.6", "0.25894673", "0", "3"], ["88511.3", "0.00018", "0", "1"], ["88511.1", "0", "0", "0"], ["88511", "0", "0", "0"], ["88510.9", "0", "0", "0"], ["88510.7", "0.00004629", "0", "1"], ["88510.4", "0.02234288", "0", "1"], ["88510.3", "0", "0", "0"], ["88508.5", "0.00943", "0", "1"], ["88508.3", "0", "0", "0"], ["88508.2", "0", "0", "0"], ["88507.5", "0", "0", "0"], ["88507.4", "0.00001138", "0", "1"], ["88506.5", "0", "0", "0"], ["88505.6", "0", "0", "0"], ["88502.8", "0.01650401", "0", "1"], ["88501.4", "0", "0", "0"], ["88499.9", "0.00057148", "0", "1"], ["88498.9", "0", "0", "0"], ["88498.4", "0", "0", "0"], ["88498", "0", "0", "0"], ["88497.9", "0.00198343", "0", "1"], ["88497.3", "0.1129955", "0", "1"], ["88496", "0", "0", "0"], ["88495.3", "0", "0", "0"], ["88487.1", "0.02260169", "0", "1"], ["88486.6", "0.1", "0", "1"], ["88480.5", "0", "0", "0"], ["88478.9", "0.10081994", "0", "2"], ["88478", "0.06", "0", "2"], ["88477.3", "0", "0", "0"], ["88477", "0", "0", "0"], ["88476", "0.08075056", "0", "3"], ["88475.1", "0.64644062", "0", "1"], ["88475", "0.93244663", "0", "2"], ["88474", "0", "0", "0"], ["88473.4", "0.00001138", "0", "1"], ["88471.6", "0", "0", "0"], ["88469.6", "0", "0", "0"], ["88469.5", "0", "0", "0"], ["88464.7", "0.02939549", "0", "1"], ["88459", "0", "0", "0"], ["88456.2", "0.97578541", "0", "2"], ["88453.7", "2.12624221", "0", "1"], ["88453.2", "0.81643262", "0", "1"], ["88451.1", "0", "0", "0"], ["88437.9", "0", "0", "0"], ["88436.1", "0", "0", "0"], ["88435.5", "0.05653725", "0", "1"], ["88408.9", "0", "0", "0"], ["88399.9", "0.00820485", "0", "5"], ["88399.7", "0", "0", "0"], ["88360", "0.00009638", "0", "1"], ["88347", "0.00002977", "0", "1"], ["88343.3", "0", "0", "0"], ["88337.5", "0.00006665", "0", "1"], ["88333.3", "0.00472124", "0", "6"], ["88322.7", "0", "0", "0"], ["88292.7", "0", "0", "0"], ["88276.1", "0.00007", "0", "1"], ["88275.5", "0.00001139", "0", "1"], ["88275", "0.00009665", "0", "2"], ["88274.6", "0.00001339", "0", "1"], ["88274.4", "0.000015", "0", "1"]], "ts": "1741338231105", "checksum": -1271471834, "seqId": 48070573326, "prevSeqId": 48070572530}]}
{"arg": {"channel": "books", "instId": "BTC-USDT"}, "action": "update", "data": [{"asks": [["88521.1", "0", "0", "0"], ["88521.7", "0", "0", "0"], ["88521.9", "0", "0", "0"], ["88522.3", "0", "0", "0"], ["88522.4", "0", "0", "0"], ["88522.7", "0", "0", "0"], ["88522.9", "0", "0", "0"], ["88523.1", "0", "0", "0"], ["88523.2", "0", "0", "0"], ["88523.3", "0", "0", "0"], ["88523.8", "0", "0", "0"], ["88524.1", "0", "0", "0"], ["88524.3", "0", "0", "0"], ["88524.4", "0", "0", "0"], ["88524.5", "0", "0", "0"], ["88525", "0", "0", "0"], ["88525.3", "0", "0", "0"], ["88525.5", "0", "0", "0"], ["88526", "0.0769", "0", "3"], ["88526.1", "0.00006921", "0", "1"], ["88528", "0.01551323", "0", "2"], ["88529.3", "0.0001", "0", "1"], ["88529.4", "0.0001", "0", "1"], ["88529.5", "0", "0", "0"], ["88530", "0.01559419", "0", "3"], ["88531.4", "0", "0", "0"], ["88531.7", "0.00010983", "0", "2"], ["88533.2", "0.04578067", "0", "2"], ["88536.2", "0.11294602", "0", "1"], ["88538", "0.04317954", "0", "1"], ["88539.6", "0.00031761", "0", "2"], ["88540", "0.08602943", "0", "5"], ["88543", "0.00007419", "0", "2"], ["88544.6", "0.13092417", "0", "3"], ["88545", "0", "0", "0"], ["88549.4", "0.24162645", "0", "2"], ["88549.7", "0.22588533", "0", "2"], ["88560.2", "0.0083294", "0", "1"], ["88566", "0", "0", "0"], ["88566.9", "0.22589763", "0", "1"], ["88567", "0.06", "0", "2"], ["88567.3", "0", "0", "0"], ["88567.6", "0.16478267", "0", "1"], ["88568", "0.09", "0", "3"], ["88569.8", "0.012102", "0", "1"], ["88570.3", "0.0046", "0", "1"], ["88570.4", "0.0000191", "0", "1"], ["88571.2", "0", "0", "0"], ["88572.8", "0.0006", "0", "2"], ["88573.6", "0.0003", "0", "1"], ["88576.3", "0", "0", "0"], ["88581.4", "0", "0", "0"], ["88582.6", "0.189137", "0", "1"], ["88593.8", "0.14714339", "0", "3"], ["88602", "0", "0", "0"], ["88603", "0.01694013", "0", "2"], ["88605.2", "0.00185413", "0", "2"], ["88607.8", "0.00001009", "0", "1"], ["88609.2", "0.00572586", "0", "2"], ["88612.4", "0.00570108", "0", "1"], ["88613.5", "0.65121071", "0", "1"], ["88614", "0.00076545", "0", "4"], ["88614.1", "0.746496", "0", "1"], ["88614.4", "0.00003119", "0", "3"], ["88614.5", "0.01568", "0", "1"], ["88615", "0.00001139", "0", "1"], ["88615.2", "0.0036953", "0", "1"], ["88615.3", "0.00001787", "0", "1"], ["88615.4", "0.00002919", "0", "1"], ["88615.9", "0.00001023", "0", "1"], ["88616", "0.01592033", "0", "2"], ["88616.1", "0.00014217", "0", "1"], ["88616.2", "0.00570112", "0", "1"]], "bids": [["88525.9", "0.36478422", "0", "13"], ["88525.5", "0.06423267", "0", "1"], ["88525.4", "0.11295967", "0", "1"], ["88524.6", "0.04", "0", "1"], ["88524", "0.0155", "0", "1"], ["88523.7", "0.0002", "0", "2"], ["88522", "0.0155", "0", "1"], ["88521.6", "0.08100812", "0", "1"], ["88521.5", "0.1", "0", "1"], ["88521", "0.07971401", "0", "4"], ["88520.6", "0", "0", "0"], ["88520.5", "0.06551957", "0", "3"], ["88520", "0.0155", "0", "1"], ["88519.4", "0", "0", "0"], ["88519.1", "0", "0", "0"], ["88518.9", "0.14716553", "0", "1"], ["88518.8", "0.05194673", "0", "2"], ["88518", "0.0155", "0", "1"], ["88517.5", "0", "0", "0"], ["88516.5", "0", "0", "0"], ["88516.1", "0", "0", "0"], ["88514.4", "0.50767692", "0", "1"], ["88514", "0.0155", "0", "1"], ["88512.8", "0.00001501", "0", "1"], ["88510.9", "0.00006", "0", "1"], ["88510.7", "0.00451923", "0", "1"], ["88510.4", "0.09631931", "0", "2"], ["88509.6", "0.00734247", "0", "1"], ["88507.1", "0.22589763", "0", "1"], ["88507", "0.03", "0", "1"], ["88503.5", "0.06", "0", "2"], ["88503.4", "0.03", "0", "1"], ["88503.2", "0.11298048", "0", "3"], ["88502", "0", "0", "0"], ["88501.6", "0.1758346", "0", "2"], ["88501.3", "0", "0", "0"], ["88500", "0", "0", "0"], ["88498.8", "0.06", "0", "2"], ["88498.1", "0.18391502", "0", "1"], ["88497.5", "0.00343", "0", "1"], ["88495", "0.02698183", "0", "1"], ["88488.5", "0.0112", "0", "1"], ["88485.7", "0.00138144", "0", "1"], ["88483.4", "0", "0", "0"], ["88483", "0.06", "0", "2"], ["88480", "0.11209548", "0", "6"], ["88479.1", "0.02649405", "0", "2"], ["88479", "0.03", "0", "1"], ["88478.9", "0", "0", "0"], ["88478.8", "0.03751", "0", "1"], ["88478", "0", "0", "0"], ["88476.8", "0", "0", "0"], ["88476.2", "0", "0", "0"], ["88476", "0.02075056", "0", "1"], ["88475", "0.90244663", "0", "1"], ["88472.1", "0.1", "0", "1"], ["88470", "0", "0", "0"], ["88456.4", "0.00102616", "0", "1"], ["88453.3", "0", "0", "0"], ["88448.1", "0.00098628", "0", "1"], ["88446.3", "0.02259359", "0", "1"], ["88444.7", "0", "0", "0"], ["88438.1", "0", "0", "0"], ["88436.6", "0.07979668", "0", "1"], ["88432.9", "0", "0", "0"], ["88430.5", "0", "0", "0"], ["88423.5", "0.02259347", "0", "1"], ["88419.9", "0", "0", "0"], ["88405.7", "0.0339183", "0", "1"], ["88393.3", "0.0021195", "0", "1"], ["88391.9", "0", "0", "0"], ["88384.2", "0", "0", "0"], ["88349", "0", "0", "0"], ["88347.8", "0.00127828", "0", "1"], ["88345", "0.00022659", "0", "1"], ["88336.8", "0", "0", "0"], ["88300.1", "0.00001316", "0", "1"], ["88283", "0", "0", "0"], ["88281.2", "0", "0", "0"], ["88281.1", "0", "0", "0"], ["88280.5", "0", "0", "0"], ["88279.9", "0", "0", "0"], ["88276.1", "0", "0", "0"], ["88275.5", "0", "0", "0"], ["88275", "0", "0", "0"], ["88274.6", "0", "0", "0"], ["88274.4", "0", "0", "0"]], "ts": "1741338231205", "checksum": 1283267483, "seqId": 48070573912, "prevSeqId": 48070573326}]}
{"arg": {"channel": "books", "instId": "BTC-USDT"}, "action": "update", "data": [{"asks": [["88526", "0.26338218", "0", "7"], ["88527.1", "0.0001102", "0", "2"], ["88527.3", "0.00012616", "0", "2"], ["88528.6", "0.00047589", "0", "2"], ["88529.3", "0", "0", "0"], ["88529.4", "0", "0", "0"], ["88533.1", "0.06124342", "0", "2"], ["88533.2", "0.06647563", "0", "2"], ["88533.6", "0.02718009", "0", "2"], ["88533.7", "0.02875137", "0", "1"], ["88534.1", "0.02755099", "0", "1"], ["88534.4", "0.02602115", "0", "2"], ["88534.8", "0.01450583", "0", "3"], ["88536.2", "0", "0", "0"], ["88536.4", "0.06144034", "0", "4"], ["88537.3", "0.08916921", "0", "2"], ["88537.5", "0.06126658", "0", "4"], ["88537.9", "0.08791508", "0", "1"], ["88538", "0.12014763", "0", "2"], ["88538.1", "0.137756", "0", "6"], ["88538.6", "0.08244863", "0", "1"], ["88540", "0.00503926", "0", "4"], ["88540.4", "0", "0", "0"], ["88541.2", "0.13908919", "0", "2"], ["88541.4", "0.18977811", "0", "2"], ["88543.2", "0.13738089", "0", "1"], ["88544", "0.00084248", "0", "2"], ["88544.1", "0.137462", "0", "2"], ["88544.6", "0.00040015", "0", "2"], ["88547.1", "0", "0", "0"], ["88547.5", "0", "0", "0"], ["88547.6", "0", "0", "0"], ["88549.2", "0.045", "0", "1"], ["88552", "0.00101398", "0", "3"], ["88564", "0.1370165", "0", "3"], ["88564.6", "0.012102", "0", "1"], ["88566.9", "0", "0", "0"], ["88567", "0", "0", "0"], ["88567.4", "0.22589984", "0", "1"], ["88567.6", "0.25668369", "0", "2"], ["88568", "0.12", "0", "4"], ["88569", "0.0300615", "0", "2"], ["88569.8", "0", "0", "0"], ["88573.1", "0.66970784", "0", "3"], ["88574.8", "1.66450879", "0", "1"], ["88582.6", "0.49353026", "0", "1"], ["88583.4", "0.502636", "0", "2"], ["88584.6", "0.5604939", "0", "1"], ["88586.8", "0.50558543", "0", "4"], ["88588.5", "0.10006713", "0", "2"], ["88597.1", "0.00115254", "0", "2"], ["88600.1", "0.00112866", "0", "1"], ["88605.2", "0.0000166", "0", "1"], ["88608.8", "3.06892824", "0", "1"], ["88609.9", "0.00183753", "0", "1"], ["88615.4", "0", "0", "0"], ["88615.9", "0", "0", "0"], ["88616", "0", "0", "0"], ["88616.1", "0", "0", "0"], ["88616.2", "0", "0", "0"]], "bids": [["88525.9", "0.36511706", "0", "12"], ["88524.3", "0.0002", "0", "2"], ["88523.7", "0", "0", "0"], ["88521.6", "0.04333658", "0", "1"], ["88521", "0.02671259", "0", "1"], ["88520.5", "0", "0", "0"], ["88519.8", "0", "0", "0"], ["88518.9", "0.20428323", "0", "2"], ["88516.3", "0.11973036", "0", "4"], ["88516.2", "0.0276254", "0", "1"], ["88515.9", "0.02706348", "0", "1"], ["88515.7", "0.02705217", "0", "1"], ["88512.5", "0.07972327", "0", "1"], ["88512.2", "0.07976485", "0", "1"], ["88511.7", "0.0832428", "0", "1"], ["88511.6", "0.05194673", "0", "2"], ["88511.5", "0.07865783", "0", "1"], ["88510.9", "0.22595984", "0", "2"], ["88510.4", "0.10131578", "0", "1"], ["88509.1", "0.12806063", "0", "1"], ["88508.4", "0.14877222", "0", "1"], ["88507.1", "0", "0", "0"], ["88506.9", "0.17048192", "0", "2"], ["88505.6", "0.13274869", "0", "1"], ["88503.4", "0.06", "0", "2"], ["88498.8", "0", "0", "0"], ["88494.3", "1.54791563", "0", "4"], ["88483.6", "0.51419049", "0", "2"], ["88480.7", "0.704083", "0", "2"], ["88472.1", "0", "0", "0"], ["88468", "0.00001", "0", "1"], ["88462.1", "0.00103757", "0", "2"], ["88456.4", "0", "0", "0"], ["88453.3", "0.00098631", "0", "1"], ["88453.2", "0.15158551", "0", "1"], ["88451.6", "0", "0", "0"], ["88448.1", "0", "0", "0"], ["88445", "0", "0", "0"], ["88443.2", "0.00019388", "0", "1"], ["88439.1", "0", "0", "0"], ["88436.6", "0.15589555", "0", "2"], ["88432.2", "0.3720215", "0", "2"], ["88430.2", "0.01769638", "0", "2"], ["88424.4", "0.11324115", "0", "2"], ["88414.8", "0.03759798", "0", "1"], ["88402.2", "0.00211958", "0", "1"], ["88393.3", "0", "0", "0"], ["88287", "0", "0", "0"], ["88286.3", "0", "0", "0"], ["88284.9", "0", "0", "0"], ["88283.5", "0", "0", "0"], ["88283.3", "0", "0", "0"]], "ts": "1741338231305", "checksum": -1321939171, "seqId": 48070574298, "prevSeqId": 48070573912}]}
{"arg": {"channel": "books", "instId": "BTC-USDT"}, "action": "update", "data": [{"asks": [["88526", "0.27816218", "0", "8"], ["88527.1", "0.0000102", "0", "1"], ["88527.3", "0.00002616", "0", "1"], ["88527.6", "0.0001", "0", "1"], ["88527.7", "0.0001", "0", "1"], ["88527.9", "0.01173502", "0", "1"], ["88528.6", "0.00045714", "0", "1"], ["88528.7", "0.0000195", "0", "1"], ["88534.8", "0.01450508", "0", "3"], ["88538.1", "0.06132136", "0", "5"], ["88539.2", "0.000591", "0", "1"], ["88541.6", "0.0004477", "0", "2"], ["88543.1", "0.01095", "0", "1"], ["88547.1", "0.00341821", "0", "1"], ["88549.2", "0.09", "0", "2"], ["88552.8", "0.13501007", "0", "4"], ["88563.1", "0.22590877", "0", "1"], ["88563.5", "0.012102", "0", "1"], ["88564", "0.06714615", "0", "2"], ["88564.6", "0", "0", "0"], ["88567.4", "0", "0", "0"], ["88614", "0", "0", "0"], ["88614.1", "0", "0", "0"], ["88614.4", "0", "0", "0"], ["88614.5", "0", "0", "0"], ["88615", "0", "0", "0"], ["88615.2", "0", "0", "0"], ["88615.3", "0", "0", "0"]], "bids": [["88525.9", "0.21551112", "0", "8"], ["88524.3", "0", "0", "0"], ["88522.1", "0.02698183", "0", "1"], ["88521.5", "0", "0", "0"], ["88521", "0.02678388", "0", "2"], ["88518.8", "0.03594673", "0", "1"], ["88515.7", "0", "0", "0"], ["88512.2", "0", "0", "0"], ["88511.5", "0", "0", "0"], ["88511.3", "0", "0", "0"], ["88510.9", "0.00006", "0", "1"], ["88510.6", "0.0002", "0", "2"], ["88510.4", "0.22274411", "0", "1"], ["88509.1", "0", "0", "0"], ["88506.9", "0.03", "0", "1"], ["88506", "0.70998728", "0", "2"], ["88503.6", "0.22591085", "0", "1"], ["88502.4", "0", "0", "0"], ["88501.6", "0.64565599", "0", "1"], ["88501.5", "1.69885581", "0", "1"], ["88497.6", "0", "0", "0"], ["88495", "0", "0", "0"], ["88481", "0.06", "0", "2"], ["88480", "0.08209548", "0", "5"], ["88479.1", "0.01749405", "0", "2"], ["88479", "0", "0", "0"], ["88450.1", "0.00019387", "0", "1"], ["88443.2", "0", "0", "0"], ["88432.2", "0.00564951", "0", "1"], ["88424.4", "0.00451934", "0", "1"], ["88414.8", "0", "0", "0"], ["88308.6", "0.00012119", "0", "1"], ["88287", "0.03", "0", "1"], ["88286.3", "0.03", "0", "1"], ["88284.9", "0.08542891", "0", "1"], ["88283.5", "0.11343045", "0", "1"], ["88283.3", "0.00416498", "0", "2"], ["88283", "0.00001722", "0", "1"]], "ts": "1741338231405", "checksum": 207728782, "seqId": 48070574431, "prevSeqId": 48070574298}]}
{"arg": {"channel": "books", "instId": "BTC-USDT"}, "action": "update", "data": [{"asks": [["88526", "0.27616218", "0", "7"], ["88527.2", "0.0001", "0", "1"], ["88527.6", "0", "0", "0"], ["88527.7", "0.0051", "0", "2"], ["88527.9", "0", "0", "0"], ["88528.7", "0", "0", "0"], ["88532", "0.01353", "0", "1"], ["88533.5", "0.02714314", "0", "2"], ["88533.6", "0.0000568", "0", "1"], ["88534.1", "0", "0", "0"], ["88534.8", "0.00092933", "0", "1"], ["88537.3", "0.00002092", "0", "1"], ["88537.8", "0.08737593", "0", "1"], ["88537.9", "0", "0", "0"], ["88538.1", "0.1369342", "0", "6"], ["88538.4", "0.00528414", "0", "5"], ["88541.4", "0.1804288", "0", "2"], ["88544", "0.14765026", "0", "3"], ["88544.1", "0.00007666", "0", "1"], ["88552.8", "0.17401007", "0", "5"], ["88560.8", "0.12501654", "0", "2"], ["88563.5", "0", "0", "0"], ["88614", "0.00076545", "0", "4"], ["88614.1", "0.746496", "0", "1"], ["88614.4", "0.00003119", "0", "3"]], "bids": [["88525.9", "0.17598847", "0", "9"], ["88522.2", "0.01806735", "0", "1"], ["88521.6", "0", "0", "0"], ["88517.7", "0.0194028", "0", "1"], ["88517.2", "0.00942", "0", "1"], ["88516.3", "0.09194673", "0", "3"], ["88516.2", "0.02924473", "0", "1"], ["88516.1", "0.0247986", "0", "1"], ["88515.9", "0", "0", "0"], ["88515.8", "0.02989438", "0", "1"], ["88515.6", "0.04148305", "0", "2"], ["88514.7", "0", "0", "0"], ["88514.3", "0.90264663", "0", "3"], ["88511.4", "0.08764099", "0", "1"], ["88510.6", "0", "0", "0"], ["88510.4", "0.25060981", "0", "2"], ["88510", "0.04378", "0", "2"], ["88509", "0.13047331", "0", "1"], ["88508.4", "0.13731215", "0", "1"], ["88508.2", "0.1", "0", "1"], ["88507.8", "0.004236", "0", "1"], ["88506.8", "0.14074329", "0", "1"], ["88505.6", "0", "0", "0"], ["88505.5", "0.14255972", "0", "1"], ["88503.7", "0.1", "0", "1"], ["88479.2", "0.04478608", "0", "1"], ["88479.1", "0.10001138", "0", "2"], ["88452.1", "0.005", "0", "1"], ["88441.5", "0.005", "0", "1"], ["88438.3", "0.33922", "0", "1"], ["88420.6", "0", "0", "0"], ["88416.2", "0", "0", "0"], ["88411.8", "0", "0", "0"], ["88298.2", "0.033885", "0", "1"], ["88290", "0", "0", "0"], ["88289.4", "0", "0", "0"], ["88287.1", "0", "0", "0"], ["88287", "0", "0", "0"], ["88286.3", "0", "0", "0"], ["88284.9", "0", "0", "0"], ["88283.5", "0", "0", "0"], ["88283.3", "0", "0", "0"], ["88283", "0", "0", "0"]], "ts": "1741338231505", "checksum": -569415234, "seqId": 48070574555, "prevSeqId": 48070574431}]}
{"arg": {"channel": "books", "instId": "BTC-USDT"}, "action": "update", "data": [{"asks": [["88526.9", "0.0002", "0", "2"], ["88527.2", "0", "0", "0"], ["88527.7", "0.005", "0", "1"], ["88528.7", "0.0000195", "0", "1"], ["88534", "0.02698903", "0", "2"], ["88534.8", "0.00097508", "0", "2"], ["88537.2", "0.08677433", "0", "2"], ["88545.6", "0.00225374", "0", "1"], ["88547.5", "0.00547861", "0", "1"], ["88560.8", "0.11291454", "0", "1"], ["88561", "0.012102", "0", "1"], ["88567", "0.06", "0", "2"], ["88567.6", "0.16478267", "0", "1"], ["88568", "0.09", "0", "3"], ["88569", "0.0000615", "0", "1"], ["88588.6", "0", "0", "0"], ["88613.5", "0", "0", "0"], ["88614", "0", "0", "0"], ["88614.1", "0", "0", "0"], ["88614.4", "0", "0", "0"]], "bids": [["88525.9", "0.17378518", "0", "9"], ["88522.2", "0.1255141", "0", "2"], ["88520.6", "0.3389", "0", "1"], ["88517.1", "0.33892", "0", "1"], ["88514.3", "0.90244663", "0", "1"], ["88514.2", "0.33949724", "0", "3"], ["88512", "0.09354246", "0", "2"], ["88509", "0", "0", "0"], ["88508.9", "0.12282073", "0", "1"], ["88482", "0.06", "0", "2"], ["88481", "0.03", "0", "1"], ["88480", "0.05209548", "0", "4"], ["88454.5", "0.00570389", "0", "1"], ["88450.1", "0.00567248", "0", "2"], ["88445.7", "0.00547861", "0", "1"], ["88438.3", "0", "0", "0"], ["88436.6", "0.07979668", "0", "1"], ["88292.4", "0", "0", "0"], ["88292.3", "0", "0", "0"], ["88292", "0", "0", "0"], ["88291", "0", "0", "0"]], "ts": "1741338231605", "checksum": -1255586023, "seqId": 48070574652, "prevSeqId": 48070574555}]}
{"arg": {"channel": "books", "instId": "BTC-USDT"}, "action": "update", "data": [{"asks": [["88526.6", "0.00012533", "0", "2"], ["88526.7", "0.00029019", "0", "7"], ["88526.9", "0", "0", "0"], ["88528.7", "0", "0", "0"], ["88534.8", "0.00092933", "0", "1"], ["88560.6", "0.159234", "0", "3"], ["88561", "0", "0", "0"], ["88613.5", "0.65121071", "0", "1"], ["88614", "0.00076545", "0", "4"], ["88614.1", "0.746496", "0", "1"]], "bids": [["88521.1", "0.00145491", "0", "1"], ["88518.9", "0.37510873", "0", "1"], ["88518.8", "0.37485673", "0", "2"], ["88514.3", "0.90264663", "0", "3"], ["88514.2", "0.33929724", "0", "1"], ["88507", "0.03006508", "0", "2"], ["88293.4", "0", "0", "0"]], "ts": "1741338231705", "checksum": -921647610, "seqId": 48070574720, "prevSeqId": 48070574652}]}
{"arg": {"channel": "books", "instId": "BTC-USDT"}, "action": "update", "data": [{"asks": [["88526", "0", "0", "0"], ["88526.1", "0", "0", "0"], ["88526.2", "0.00184648", "0", "4"], ["88526.6", "0.00002533", "0", "1"], ["88526.7", "0.00019019", "0", "6"], ["88528", "0.00001323", "0", "1"], ["88528.8", "0.0050195", "0", "2"], ["88531.7", "0.00030983", "0", "4"], ["88532", "0.0155", "0", "1"], ["88533.1", "0", "0", "0"], ["88533.2", "0", "0", "0"], ["88533.5", "0.00001131", "0", "1"], ["88533.7", "0", "0", "0"], ["88534", "0.00001007", "0", "1"], ["88534.4", "0.00001094", "0", "1"], ["88535.1", "0.00004725", "0", "1"], ["88536.4", "0.00019692", "0", "2"], ["88537.2", "0.00007282", "0", "1"], ["88537.5", "0.00002316", "0", "2"], ["88537.8", "0", "0", "0"], ["88538", "0", "0", "0"], ["88538.1", "0.00007794", "0", "3"], ["88538.6", "0", "0", "0"], ["88539.2", "0", "0", "0"], ["88540.8", "0", "0", "0"], ["88541.2", "0", "0", "0"], ["88541.4", "0", "0", "0"], ["88541.8", "0", "0", "0"], ["88542.5", "0.01353", "0", "1"], ["88543.2", "0", "0", "0"], ["88543.3", "0.10334901", "0", "2"], ["88543.4", "0.00111045", "0", "2"], ["88543.5", "0.00260924", "0", "2"], ["88544", "0.00084248", "0", "2"], ["88545.6", "0", "0", "0"], ["88545.7", "0.45797453", "0", "2"], ["88546.5", "0.01130381", "0", "2"], ["88547.1", "0", "0", "0"], ["88549.1", "0.90244663", "0", "1"], ["88550.2", "0.19020268", "0", "2"], ["88550.8", "0.04059", "0", "1"], ["88551", "0.00003451", "0", "2"], ["88555.2", "0.00006893", "0", "2"], ["88560.2", "0", "0", "0"], ["88560.6", "0.147132", "0", "2"], ["88563.1", "0", "0", "0"], ["88563.6", "0.04001026", "0", "2"], ["88567", "0", "0", "0"], ["88567.6", "0.25305217", "0", "2"], ["88567.9", "0.225904", "0", "2"], ["88568", "0", "0", "0"], ["88569", "0.0600615", "0", "3"], ["88570", "0.09", "0", "3"], ["88572.8", "0", "0", "0"], ["88573.1", "0.19458555", "0", "2"], ["88573.6", "0", "0", "0"], ["88574.8", "0", "0", "0"], ["88575.1", "0.01235188", "0", "2"], ["88575.2", "0.0006", "0", "2"], ["88576", "0.0135977", "0", "4"], ["88582.6", "0.189137", "0", "1"], ["88583.4", "0.0048", "0", "1"], ["88584.6", "0", "0", "0"], ["88586.8", "0.00776843", "0", "3"], ["88588.5", "0.00006713", "0", "1"], ["88601.4", "0.00001181", "0", "1"], ["88606.5", "0", "0", "0"], ["88608.8", "0", "0", "0"], ["88609.9", "0", "0", "0"], ["88610.2", "0", "0", "0"], ["88611.3", "0.0299468", "0", "1"], ["88612.3", "0.0018375", "0", "1"], ["88614.1", "0", "0", "0"], ["88614.4", "0.00003119", "0", "3"], ["88614.5", "0.01568", "0", "1"], ["88615", "0.00001139", "0", "1"], ["88615.2", "0.0036953", "0", "1"], ["88615.3", "0.00001787", "0", "1"], ["88615.4", "0.00002919", "0", "1"], ["88615.9", "0.00001023", "0", "1"], ["88616", "0.01592033", "0", "2"], ["88616.1", "0.00014217", "0", "1"], ["88616.2", "0.00570112", "0", "1"], ["88616.6", "0.000657", "0", "2"], ["88616.7", "0.00006147", "0", "2"], ["88616.8", "0.00570108", "0", "1"], ["88617.6", "0.00002674", "0", "2"], ["88617.9", "0.0009692", "0", "1"], ["88618.2", "0.0000551", "0", "1"], ["88618.5", "0.00002031", "0", "2"], ["88618.7", "0.00165291", "0", "3"], ["88618.9", "0.00003018", "0", "2"], ["88619", "0.04518438", "0", "1"], ["88619.2", "0.00002036", "0", "2"], ["88619.4", "0.05335289", "0", "1"]], "bids": [["88526.1", "0.50077961", "0", "20"], ["88526", "0.23536876", "0", "5"], ["88525.9", "0.0432992", "0", "3"], ["88525.5", "0", "0", "0"], ["88524.6", "0", "0", "0"], ["88522.8", "0.07117598", "0", "1"], ["88522.7", "0.11296096", "0", "3"], ["88522.3", "0.06124342", "0", "2"], ["88522.2", "0", "0", "0"], ["88522.1", "0", "0", "0"], ["88521.9", "0.01853488", "0", "1"], ["88521.1", "0", "0", "0"], ["88521", "0.00007129", "0", "1"], ["88520.7", "0.02828", "0", "1"], ["88520.6", "0", "0", "0"], ["88519", "0.00145491", "0", "1"], ["88518.9", "0.15507207", "0", "1"], ["88518.8", "0.03594673", "0", "1"], ["88517.7", "0", "0", "0"], ["88517.2", "0", "0", "0"], ["88517.1", "0", "0", "0"], ["88516.5", "0.0225883", "0", "1"], ["88516.4", "0.22593787", "0", "2"], ["88516.2", "0", "0", "0"], ["88516.1", "0", "0", "0"], ["88515.8", "0", "0", "0"], ["88515.6", "0.0135", "0", "1"], ["88514.3", "0.90244663", "0", "1"], ["88512.5", "0", "0", "0"], ["88512", "0.0155", "0", "1"], ["88511.7", "0", "0", "0"], ["88511.4", "0", "0", "0"], ["88510.7", "0", "0", "0"], ["88510.4", "0.08904402", "0", "1"], ["88510", "0.0155", "0", "1"], ["88508.9", "0", "0", "0"], ["88508.4", "0", "0", "0"], ["88508.2", "0.1033645", "0", "2"], ["88507.8", "0", "0", "0"], ["88506.8", "0", "0", "0"], ["88506.6", "0", "0", "0"], ["88506.3", "0.183915", "0", "1"], ["88505.5", "0", "0", "0"], ["88505.4", "0.01650401", "0", "1"], ["88505.3", "0.073566", "0", "1"], ["88504", "0.00001501", "0", "1"], ["88503.6", "0", "0", "0"], ["88503.2", "0", "0", "0"], ["88502.8", "0", "0", "0"], ["88496.1", "0.03500213", "0", "2"], ["88488.5", "0", "0", "0"], ["88481.4", "0", "0", "0"], ["88479.7", "0", "0", "0"], ["88479.2", "0.01748608", "0", "1"], ["88479.1", "0.00001138", "0", "1"], ["88469.5", "0.0344909", "0", "1"], ["88464.7", "0", "0", "0"], ["88455.9", "0.00098626", "0", "1"], ["88453.3", "0", "0", "0"], ["88453.2", "0.92647489", "0", "2"], ["88452", "2.88040958", "0", "2"], ["88450", "0.073566", "0", "1"], ["88448", "0", "0", "0"], ["88446.6", "0.01627888", "0", "1"], ["88445.5", "0", "0", "0"], ["88444.2", "0", "0", "0"], ["88436.6", "0", "0", "0"], ["88434", "0.00570085", "0", "1"], ["88430.2", "0.0045196", "0", "1"], ["88424.2", "0", "0", "0"], ["88415.4", "0", "0", "0"], ["88406.5", "0", "0", "0"], ["88370.1", "0", "0", "0"], ["88365.7", "0.99474", "0", "1"], ["88298.2", "0", "0", "0"], ["88293.4", "0.04093218", "0", "1"], ["88292.4", "0.00001139", "0", "1"], ["88292.3", "0.00002159", "0", "1"], ["88292", "0.0025", "0", "1"], ["88291", "0.005", "0", "2"], ["88290", "0.00001172", "0", "1"], ["88289.4", "0.03", "0", "1"], ["88287.1", "0.03", "0", "1"], ["88287", "0.03", "0", "1"], ["88286.3", "0.03", "0", "1"], ["88284.9", "0.08542891", "0", "1"], ["88283.5", "0.11343045", "0", "1"], ["88283.3", "0.00416498", "0", "2"], ["88283", "0.00001722", "0", "1"], ["88281.2", "0.00006263", "0", "1"], ["88281.1", "0.34078752", "0", "2"], ["88280.5", "0.00002567", "0", "1"], ["88279.9", "0.00001655", "0", "1"], ["88276.1", "0.00007", "0", "1"], ["88275.5", "0.00001139", "0", "1"], ["88275", "0.00009665", "0", "2"], ["88274.6", "0.00001339", "0", "1"]], "ts": "1741338231805", "checksum": 361962249, "seqId": 48070575131, "prevSeqId": 48070574720}]}
{"arg": {"channel": "books", "instId": "BTC-USDT"}, "action": "update", "data": [{"asks": [["88531.5", "0.0001", "0", "1"], ["88531.6", "0.0001", "0", "1"], ["88531.7", "0.00010983", "0", "2"], ["88542", "0.21571349", "0", "2"], ["88542.1", "0.03072128", "0", "2"], ["88543", "0.06131097", "0", "4"], ["88543.3", "0.00001005", "0", "1"], ["88551", "0.00340559", "0", "3"], ["88564", "0.13338489", "0", "3"], ["88567.4", "0.22589646", "0", "1"], ["88567.9", "0.00001005", "0", "1"], ["88569", "0.0000615", "0", "1"], ["88570", "0.12", "0", "4"], ["88571", "0.03", "0", "1"], ["88571.5", "0.01236229", "0", "4"], ["88575.1", "0.00024988", "0", "1"], ["88588.7", "0.1", "0", "1"], ["88589.9", "0.4978", "0", "1"], ["88596.4", "0", "0", "0"], ["88601.2", "0.01739323", "0", "1"], ["88618.2", "0", "0", "0"], ["88618.5", "0", "0", "0"], ["88618.7", "0", "0", "0"], ["88618.9", "0", "0", "0"], ["88619", "0", "0", "0"], ["88619.2", "0", "0", "0"], ["88619.4", "0", "0", "0"]], "bids": [["88526.1", "0.50057961", "0", "18"], ["88524.5", "0.0002", "0", "2"], ["88516.4", "0.00004392", "0", "1"], ["88512.7", "0.22589646", "0", "1"], ["88500.3", "0", "0", "0"], ["88484", "0.06", "0", "2"], ["88483", "0", "0", "0"], ["88479.3", "0.03929608", "0", "1"], ["88479.2", "0.1", "0", "1"], ["88476.1", "0.01739323", "0", "1"], ["88473.5", "0", "0", "0"], ["88462", "0.40627987", "0", "2"], ["88460.8", "0.77039642", "0", "2"], ["88414.8", "0.00565", "0", "1"], ["88402.9", "0.17393231", "0", "1"], ["88397.8", "0", "0", "0"], ["88275.5", "0", "0", "0"], ["88275", "0", "0", "0"], ["88274.6", "0", "0", "0"]], "ts": "1741338231905", "checksum": 1194008935, "seqId": 48070575223, "prevSeqId": 48070575131}]}
{"arg": {"channel": "books", "instId": "BTC-USDT"}, "action": "update", "data": [{"asks": [["88531.5", "0", "0", "0"], ["88531.6", "0.0002", "0", "2"], ["88539.5", "0.06123678", "0", "2"], ["88542", "0.129982", "0", "1"], ["88543", "0.03069258", "0", "3"], ["88543.5", "0.00001124", "0", "1"], ["88564", "0.06714615", "0", "2"], ["88567.4", "0", "0", "0"], ["88568.9", "0.22594534", "0", "3"], ["88569", "0.0600615", "0", "3"], ["88570", "0.09", "0", "3"], ["88571", "0", "0", "0"], ["88571.4", "0.02768994", "0", "22"], ["88571.5", "0.00026029", "0", "3"], ["88574.4", "0.00075275", "0", "6"], ["88575.2", "0.0003", "0", "1"], ["88576", "0.0132977", "0", "3"], ["88576.8", "0.81675346", "0", "2"], ["88576.9", "1.62927231", "0", "2"], ["88577.2", "0", "0", "0"], ["88578.2", "0", "0", "0"], ["88579.7", "0.01", "0", "1"], ["88586.1", "0.56334344", "0", "2"], ["88586.3", "0.49782", "0", "1"], ["88595.4", "0.01135727", "0", "2"], ["88610.9", "2.90530705", "0", "1"], ["88618.2", "0.0000551", "0", "1"]], "bids": [["88525.9", "0.0432892", "0", "2"], ["88519.1", "0.00145491", "0", "1"], ["88519", "0", "0", "0"], ["88516.4", "0.22593559", "0", "2"], ["88512.7", "0", "0", "0"], ["88508.2", "0.1", "0", "1"], ["88496.8", "0.0006", "0", "2"], ["88496", "0.00029891", "0", "1"], ["88489.6", "0.08542891", "0", "1"], ["88488.8", "0", "0", "0"], ["88483.7", "0.12587713", "0", "3"], ["88479.4", "0.04772644", "0", "1"], ["88479.3", "0.1", "0", "1"], ["88479.2", "0", "0", "0"], ["88445", "0.33919", "0", "1"], ["88395.2", "0.01128727", "0", "1"], ["88279.9", "0", "0", "0"], ["88276.1", "0", "0", "0"]], "ts": "1741338232005", "checksum": -788119664, "seqId": 48070575359, "prevSeqId": 48070575223}]}
{"arg": {"channel": "books", "instId": "BTC-USDT"}, "action": "update", "data": [{"asks": [["88526.2", "0.02264648", "0", "5"], ["88528", "0.01551323", "0", "2"], ["88529", "0.00011678", "0", "2"], ["88531.5", "0.0001", "0", "1"], ["88531.6", "0", "0", "0"], ["88539.4", "0.02353946", "0", "1"], ["88541", "0.06128085", "0", "5"], ["88541.7", "0.00002123", "0", "2"], ["88541.8", "0.06123678", "0", "2"], ["88542.1", "0.00010289", "0", "1"], ["88542.5", "0", "0", "0"], ["88543.6", "0.34058198", "0", "2"], ["88548.4", "0.03219175", "0", "4"], ["88548.7", "0.0112935", "0", "1"], ["88549.2", "0", "0", "0"], ["88551", "0.00003451", "0", "2"], ["88552.4", "0.015", "0", "1"], ["88552.8", "0.00001007", "0", "1"], ["88555.4", "0.045", "0", "1"], ["88561.4", "0.00225374", "0", "1"], ["88564.7", "0", "0", "0"], ["88568.9", "0.00005367", "0", "2"], ["88569", "0.0000615", "0", "1"], ["88569.4", "0.03907376", "0", "2"], ["88570", "0.12", "0", "4"], ["88570.2", "0.012102", "0", "1"], ["88570.9", "0.22592208", "0", "2"], ["88571", "0.03", "0", "1"], ["88571.4", "0.01558794", "0", "21"], ["88574.4", "0.00015275", "0", "4"], ["88575.2", "0.0006", "0", "2"], ["88576", "0.0135977", "0", "4"], ["88577.7", "0.00225374", "0", "1"], ["88577.9", "0", "0", "0"], ["88601.2", "0.01739297", "0", "1"], ["88607.5", "0.06391", "0", "1"], ["88616.6", "0", "0", "0"], ["88616.7", "0", "0", "0"], ["88616.8", "0", "0", "0"], ["88617.6", "0", "0", "0"], ["88617.9", "0", "0", "0"], ["88618.2", "0", "0", "0"]], "bids": [["88526.1", "0.44822416", "0", "16"], ["88526", "0.21936876", "0", "4"], ["88524.5", "0", "0", "0"], ["88523.2", "0.01129675", "0", "1"], ["88522.9", "0.0002", "0", "2"], ["88522.3", "0", "0", "0"], ["88519.1", "0.22734335", "0", "2"], ["88518.8", "0.03595811", "0", "2"], ["88516.4", "0.00004392", "0", "1"], ["88516.3", "0.05194673", "0", "2"], ["88501.3", "0.498298", "0", "1"], ["88494.3", "1.04957863", "0", "3"], ["88486", "0", "0", "0"], ["88483.7", "0.12471772", "0", "2"], ["88483.6", "0.32943365", "0", "1"], ["88483", "0.06", "0", "2"], ["88482", "0.03", "0", "1"], ["88481", "0", "0", "0"], ["88480.7", "0.20567", "0", "1"], ["88478.2", "0.01695373", "0", "1"], ["88473.9", "0", "0", "0"], ["88459.3", "0.00343", "0", "1"], ["88459.2", "0", "0", "0"], ["88433.9", "0.03955697", "0", "2"], ["88431.5", "0", "0", "0"], ["88405.7", "0", "0", "0"], ["88402.9", "0.17392972", "0", "1"], ["88354.8", "0.00001138", "0", "1"], ["88301", "0.033884", "0", "1"]], "ts": "1741338232105", "checksum": -1245409040, "seqId": 48070575567, "prevSeqId": 48070575359}]}
{"arg": {"channel": "books", "instId": "BTC-USDT"}, "action": "update", "data": [{"asks": [["88526.2", "0", "0", "0"], ["88526.3", "0", "0", "0"], ["88526.4", "0", "0", "0"], ["88526.6", "0.00002356", "0", "1"], ["88528", "0.00001323", "0", "1"], ["88529", "0.00001678", "0", "1"], ["88530", "0.00009419", "0", "2"], ["88531.5", "0", "0", "0"], ["88532", "0", "0", "0"], ["88535.6", "0", "0", "0"], ["88539.4", "0", "0", "0"], ["88539.5", "0", "0", "0"], ["88541.2", "0.0001", "0", "1"], ["88541.6", "0.0005477", "0", "3"], ["88541.7", "0.01355123", "0", "3"], ["88542", "0", "0", "0"], ["88543", "0.00007419", "0", "2"], ["88543.6", "0.000021", "0", "1"], ["88545.7", "0", "0", "0"], ["88546.8", "0.06142717", "0", "3"], ["88546.9", "0.03061839", "0", "1"], ["88547.8", "0.06124968", "0", "3"], ["88548.3", "0.06171796", "0", "6"], ["88548.8", "0.20416949", "0", "2"], ["88548.9", "0.33929724", "0", "1"], ["88549.1", "0", "0", "0"], ["88549.4", "0.11343045", "0", "1"], ["88549.8", "0", "0", "0"], ["88555.3", "0.04516236", "0", "3"], ["88558.9", "0.135", "0", "3"], ["88563.2", "0", "0", "0"], ["88564", "0.10081558", "0", "3"], ["88566", "0.00001", "0", "1"], ["88566.9", "0.04", "0", "1"], ["88567.3", "0.11290627", "0", "1"], ["88570", "0", "0", "0"], ["88570.2", "0", "0", "0"], ["88570.9", "0.00003364", "0", "1"], ["88571", "0", "0", "0"], ["88572", "0.12", "0", "4"], ["88572.9", "0.012102", "0", "1"], ["88573", "0.03", "0", "1"], ["88573.1", "0.13476555", "0", "2"], ["88575", "0.0000626", "0", "2"], ["88575.2", "0", "0", "0"], ["88576", "0.0132977", "0", "3"], ["88576.3", "0.2258744", "0", "1"], ["88576.8", "0.81735346", "0", "4"], ["88577.6", "0.00034084", "0", "5"], ["88586.1", "0.00012221", "0", "1"], ["88595.4", "0.00007", "0", "1"], ["88601.2", "0", "0", "0"], ["88602.8", "0.01740247", "0", "2"], ["88603.5", "0.01128624", "0", "1"], ["88616", "0.00002123", "0", "1"], ["88616.6", "0.000657", "0", "2"], ["88616.7", "0.00006147", "0", "2"], ["88616.8", "0.00570108", "0", "1"], ["88617.6", "0.00002674", "0", "2"], ["88617.9", "0.0009692", "0", "1"], ["88618.2", "0.0000551", "0", "1"]], "bids": [["88526.5", "0.42452584", "0", "3"], ["88526.3", "0.16276", "0", "4"], ["88526.2", "0.49880885", "0", "8"], ["88526.1", "0.90317337", "0", "33"], ["88526", "0.18080086", "0", "3"], ["88523.3", "0.2258744", "0", "1"], ["88523.2", "0.13706229", "0", "2"], ["88522.9", "0", "0", "0"], ["88522.8", "0", "0", "0"], ["88521.6", "0.0002", "0", "2"], ["88519.2", "0.0000555", "0", "1"], ["88519.1", "0", "0", "0"], ["88519", "0.00145491", "0", "1"], ["88517.2", "0.207", "0", "1"], ["88513.6", "0.00942", "0", "1"], ["88508.5", "0", "0", "0"], ["88508.3", "0.01650401", "0", "1"], ["88505.4", "0", "0", "0"], ["88505.3", "0.147132", "0", "2"], ["88494.9", "0.5381229", "0", "1"], ["88491.3", "0.01128674", "0", "1"], ["88490.4", "0.01129802", "0", "2"], ["88486", "0.06", "0", "2"], ["88484.9", "0.447483", "0", "1"], ["88484.6", "0.01128624", "0", "1"], ["88484", "0.00116498", "0", "1"], ["88483.7", "0.11343045", "0", "1"], ["88480.3", "0.01739239", "0", "1"], ["88476.1", "0", "0", "0"], ["88469.6", "0.01433224", "0", "1"], ["88463.8", "0", "0", "0"], ["88454.7", "0", "0", "0"], ["88450", "0", "0", "0"], ["88444.6", "0", "0", "0"], ["88396.1", "0.01128624", "0", "1"], ["88395.2", "0", "0", "0"], ["88284.9", "0", "0", "0"], ["88283.5", "0", "0", "0"], ["88283.3", "0", "0", "0"], ["88283", "0", "0", "0"], ["88281.2", "0", "0", "0"], ["88281.1", "0", "0", "0"], ["88280.5", "0", "0", "0"]], "ts": "1741338232205", "checksum": 676971172, "seqId": 48070575919, "prevSeqId": 48070575567}]}
{"arg": {"channel": "books", "instId": "BTC-USDT"}, "action": "update", "data": [{"asks": [["88526.6", "0", "0", "0"], ["88526.7", "0.06159019", "0", "8"], ["88526.8", "0.00002964", "0", "1"], ["88528.8", "0.005", "0", "1"], ["88530", "0.01559419", "0", "3"], ["88532", "0.0155", "0", "1"], ["88533.3", "0.01793903", "0", "19"], ["88533.5", "0.00011131", "0", "2"], ["88535.1", "0", "0", "0"], ["88539.6", "0.06156075", "0", "4"], ["88540.4", "0.01860263", "0", "1"], ["88541.2", "0", "0", "0"], ["88541.6", "0.0004477", "0", "2"], ["88541.7", "0.03325085", "0", "4"], ["88543.1", "0", "0", "0"], ["88544.5", "0.06235892", "0", "3"], ["88545.9", "0.06131616", "0", "3"], ["88546.9", "0", "0", "0"], ["88547.5", "0", "0", "0"], ["88548.4", "0.01866175", "0", "3"], ["88548.7", "0.91374013", "0", "2"], ["88550.2", "0.02448291", "0", "1"], ["88552.5", "0", "0", "0"], ["88555", "0.30005911", "0", "6"], ["88558.9", "0.174", "0", "4"], ["88561.5", "0.128195", "0", "1"], ["88569.3", "0.22588905", "0", "1"], ["88570.2", "0.012102", "0", "1"], ["88572.6", "0.14621521", "0", "1"], ["88572.9", "0", "0", "0"], ["88573.1", "0.00002277", "0", "1"], ["88574.1", "0", "0", "0"], ["88576.3", "0", "0", "0"], ["88582", "0.3885197", "0", "1"], ["88582.1", "0.447483", "0", "1"], ["88582.6", "0", "0", "0"], ["88583.4", "0.22184", "0", "2"], ["88588.7", "0", "0", "0"], ["88588.8", "0.55059679", "0", "2"], ["88589.1", "0.1", "0", "1"], ["88599.9", "0.00475403", "0", "7"], ["88612.3", "0", "0", "0"], ["88612.9", "0.00183749", "0", "1"], ["88618.5", "0.00002031", "0", "2"], ["88618.7", "0.00165291", "0", "3"]], "bids": [["88526.6", "1.34869366", "0", "21"], ["88526.5", "0.27535105", "0", "2"], ["88526.3", "0", "0", "0"], ["88526.2", "0.11295858", "0", "1"], ["88526.1", "0.40611", "0", "17"], ["88525.4", "0", "0", "0"], ["88523.5", "0.00096909", "0", "1"], ["88523.4", "0.12915494", "0", "1"], ["88523.3", "0", "0", "0"], ["88523.2", "0.01129675", "0", "1"], ["88522.6", "0.128195", "0", "1"], ["88522.5", "0.0001", "0", "1"], ["88522.4", "0.0001", "0", "1"], ["88521.6", "0", "0", "0"], ["88519.2", "0", "0", "0"], ["88519.1", "0.28108514", "0", "1"], ["88519", "0", "0", "0"], ["88518.9", "0", "0", "0"], ["88516.8", "0.00004536", "0", "1"], ["88516.6", "0.00451893", "0", "1"], ["88516.4", "0", "0", "0"], ["88515.5", "0.22588905", "0", "1"], ["88511.3", "0.03", "0", "1"], ["88501.7", "0", "0", "0"], ["88499.2", "0.0006", "0", "2"], ["88498.4", "0.0002989", "0", "1"], ["88496.9", "0.50481943", "0", "2"], ["88496.8", "0", "0", "0"], ["88496", "0", "0", "0"], ["88495.1", "0", "0", "0"], ["88494.5", "0.0001", "0", "1"], ["88491.8", "0.20567", "0", "1"], ["88487", "0.53921", "0", "3"], ["88486.9", "0.498378", "0", "1"], ["88486", "0", "0", "0"], ["88485", "0.06", "0", "2"], ["88484", "0.03116498", "0", "2"], ["88483.6", "0.2446306", "0", "1"], ["88483", "0", "0", "0"], ["88482", "0", "0", "0"], ["88480.7", "0", "0", "0"], ["88479.7", "0.1", "0", "1"], ["88479.4", "0.0225722", "0", "1"], ["88479.3", "0", "0", "0"], ["88456.5", "0.00099745", "0", "2"], ["88456.4", "0.43447", "0", "1"], ["88455.9", "0", "0", "0"], ["88453.2", "0.47434535", "0", "2"], ["88448.6", "0.747891", "0", "1"], ["88445", "0", "0", "0"], ["88436.5", "0", "0", "0"], ["88315.7", "0.00001054", "0", "1"], ["88286.3", "0", "0", "0"]], "ts": "1741338232305", "checksum": -1165981248, "seqId": 48070576245, "prevSeqId": 48070575919}]}
{"arg": {"channel": "books", "instId": "BTC-USDT"}, "action": "update", "data": [{"asks": [["88526.7", "0", "0", "0"], ["88526.8", "0", "0", "0"], ["88527.1", "0", "0", "0"], ["88527.3", "0", "0", "0"], ["88527.7", "0", "0", "0"], ["88528", "0.08337239", "0", "3"], ["88528.1", "0.0000345", "0", "1"], ["88530.9", "0.0001", "0", "1"], ["88533.2", "0.0001", "0", "1"], ["88533.3", "0.01783903", "0", "18"], ["88533.5", "0.00001131", "0", "1"], ["88533.9", "0.11299501", "0", "2"], ["88536.3", "0.01843502", "0", "1"], ["88536.4", "0.06144006", "0", "4"], ["88538", "0.04060947", "0", "1"], ["88538.1", "0.06132108", "0", "5"], ["88539.2", "0.02877205", "0", "1"], ["88539.3", "0.02777197", "0", "1"], ["88539.5", "0.02956699", "0", "1"], ["88539.6", "0.00031761", "0", "2"], ["88540.4", "0", "0", "0"], ["88541.7", "0.06554547", "0", "4"], ["88542.9", "0.08914031", "0", "1"], ["88543.1", "0.00131779", "0", "1"], ["88543.3", "0.06125319", "0", "3"], ["88543.5", "0.08610927", "0", "2"], ["88544.4", "0.06124314", "0", "2"], ["88544.5", "0.00111578", "0", "1"], ["88545.8", "0.06124314", "0", "2"], ["88545.9", "0.00007302", "0", "1"], ["88547", "0.14270084", "0", "2"], ["88548.3", "0.00048118", "0", "4"], ["88548.6", "0.47828453", "0", "1"], ["88548.8", "0.00001", "0", "1"], ["88549.6", "0.13514201", "0", "2"], ["88552.4", "0", "0", "0"], ["88554.8", "0.015", "0", "1"], ["88567.2", "0.012117", "0", "2"], ["88570.2", "0", "0", "0"], ["88572.6", "0.07845078", "0", "1"], ["88589.1", "0", "0", "0"], ["88589.2", "0.1", "0", "1"], ["88600.8", "0.01128658", "0", "1"], ["88603.5", "0", "0", "0"], ["88616.8", "0", "0", "0"], ["88617.6", "0", "0", "0"], ["88617.9", "0", "0", "0"], ["88618.2", "0", "0", "0"], ["88618.5", "0", "0", "0"], ["88618.7", "0", "0", "0"]], "bids": [["88527.9", "0.49141651", "0", "12"], ["88527.7", "0.00145491", "0", "1"], ["88527.6", "0.01484048", "0", "4"], ["88527.3", "0.11295724", "0", "1"], ["88527.2", "0.39200777", "0", "1"], ["88527", "0.00952", "0", "2"], ["88526.7", "0.0001", "0", "1"], ["88526.6", "0.14216722", "0", "5"], ["88526.5", "0.03594673", "0", "1"], ["88526.2", "0", "0", "0"], ["88526.1", "0.2124", "0", "9"], ["88526", "0.0155", "0", "1"], ["88523.5", "0", "0", "0"], ["88523.4", "0.1593204", "0", "2"], ["88522.7", "0", "0", "0"], ["88522.5", "0", "0", "0"], ["88522.4", "0", "0", "0"], ["88521.8", "0.02919927", "0", "1"], ["88521.5", "0.02628618", "0", "1"], ["88521.1", "0.02839618", "0", "1"], ["88520.8", "0.3389", "0", "1"], ["88519.1", "0.22445345", "0", "2"], ["88518.1", "0.08740139", "0", "2"], ["88517.3", "0.42584651", "0", "2"], ["88517.2", "0", "0", "0"], ["88517", "0.08206857", "0", "1"], ["88516.8", "0", "0", "0"], ["88515.5", "0", "0", "0"], ["88514", "0.15446178", "0", "2"], ["88512.7", "0.2258925", "0", "1"], ["88512.4", "0.13670247", "0", "1"], ["88511.1", "0.13642297", "0", "1"], ["88509.6", "0", "0", "0"], ["88506.9", "0", "0", "0"], ["88499.2", "0.0005989", "0", "2"], ["88487.3", "0.01128658", "0", "1"], ["88486", "0.06", "0", "2"], ["88485", "0.03", "0", "1"], ["88484.6", "0", "0", "0"], ["88484", "0", "0", "0"], ["88479.6", "0.00338939", "0", "1"], ["88464", "0.00102608", "0", "1"], ["88462.1", "0.00001138", "0", "1"], ["88453.2", "0.72497678", "0", "2"], ["88403", "0.0021182", "0", "1"], ["88402.2", "0", "0", "0"], ["88398.8", "0.01128658", "0", "1"], ["88396.1", "0", "0", "0"], ["88301", "0", "0", "0"], ["88292.4", "0", "0", "0"], ["88292.3", "0", "0", "0"], ["88292", "0", "0", "0"], ["88291", "0", "0", "0"], ["88290", "0", "0", "0"], ["88289.4", "0", "0", "0"], ["88287.1", "0", "0", "0"], ["88287", "0", "0", "0"]], "ts": "1741338232405", "checksum": 1726069060, "seqId": 48070576819, "prevSeqId": 48070576245}]}
{"arg": {"channel": "books", "instId": "BTC-USDT"}, "action": "update", "data": [{"asks": [["88528", "0.20686541", "0", "7"], ["88529.3", "0.1129548", "0", "1"], ["88529.5", "0.0001", "0", "1"], ["88529.7", "0.0001", "0", "1"], ["88530.9", "0", "0", "0"], ["88533.2", "0", "0", "0"], ["88533.8", "0.04917326", "0", "2"], ["88533.9", "0.00004614", "0", "1"], ["88535.5", "0.06161508", "0", "12"], ["88535.8", "0.02842228", "0", "2"], ["88536", "0.02740521", "0", "1"], ["88536.2", "0.05432209", "0", "2"], ["88536.3", "0", "0", "0"], ["88538", "0.06691771", "0", "1"], ["88539.2", "0", "0", "0"], ["88539.3", "0", "0", "0"], ["88539.5", "0.08815913", "0", "1"], ["88540.4", "0.08767915", "0", "1"], ["88540.8", "0.000015", "0", "1"], ["88541.7", "0.06996621", "0", "4"], ["88541.8", "0", "0", "0"], ["88542.9", "0", "0", "0"], ["88543.5", "0.00001124", "0", "1"], ["88544.4", "0", "0", "0"], ["88544.9", "0.12943409", "0", "1"], ["88545.8", "0", "0", "0"], ["88546.2", "0.04059", "0", "1"], ["88546.4", "0.01379336", "0", "8"], ["88546.8", "0.00019039", "0", "1"], ["88547", "0.00001139", "0", "1"], ["88547.3", "0.11293179", "0", "1"], ["88547.8", "0.0000129", "0", "1"], ["88548.1", "0.06125325", "0", "3"], ["88549.6", "0.000015", "0", "1"], ["88550.2", "0", "0", "0"], ["88550.8", "0", "0", "0"], ["88560.1", "0.01227977", "0", "4"], ["88564", "0.13369219", "0", "3"], ["88567.2", "0.000015", "0", "1"], ["88567.3", "0", "0", "0"], ["88567.4", "0.22589598", "0", "1"], ["88569.3", "0", "0", "0"], ["88569.4", "0.00292156", "0", "1"], ["88577.7", "0", "0", "0"], ["88589.2", "0", "0", "0"], ["88601.2", "0.0173938", "0", "1"], ["88602.8", "0.00001008", "0", "1"], ["88606.4", "0.02991829", "0", "1"], ["88611.3", "0", "0", "0"], ["88612.9", "0", "0", "0"], ["88613.9", "0.00183748", "0", "1"], ["88616.8", "0.00570108", "0", "1"], ["88617.6", "0.00002674", "0", "2"]], "bids": [["88527.9", "0.2690041", "0", "7"], ["88527.7", "0", "0", "0"], ["88527.6", "0.11295682", "0", "1"], ["88527.3", "0.00145491", "0", "1"], ["88527.2", "0.04015863", "0", "1"], ["88527", "0", "0", "0"], ["88526.6", "0.0194028", "0", "1"], ["88526.5", "0.0001", "0", "1"], ["88525.9", "0.00734247", "0", "1"], ["88523.4", "0.06588618", "0", "1"], ["88521.8", "0", "0", "0"], ["88521.5", "0", "0", "0"], ["88521.1", "0", "0", "0"], ["88520.8", "0", "0", "0"], ["88520.7", "0", "0", "0"], ["88519.1", "0.15120765", "0", "1"], ["88518.8", "0.00001138", "0", "1"], ["88518.6", "0.02471157", "0", "1"], ["88518.5", "0.139344", "0", "4"], ["88518.1", "0.02810384", "0", "1"], ["88517.8", "0.02841441", "0", "1"], ["88517.3", "0", "0", "0"], ["88517", "0", "0", "0"], ["88515.8", "0.02828", "0", "1"], ["88515.5", "0.22589598", "0", "1"], ["88515.3", "0.02698183", "0", "1"], ["88514", "0.0155", "0", "1"], ["88513.7", "0.08744224", "0", "1"], ["88512.7", "0", "0", "0"], ["88512.4", "0", "0", "0"], ["88511.7", "0.02671259", "0", "1"], ["88511.1", "0", "0", "0"], ["88510.4", "0.18294682", "0", "2"], ["88509.2", "0.12959542", "0", "1"], ["88508.3", "0", "0", "0"], ["88507.1", "0.01650401", "0", "1"], ["88501.3", "0", "0", "0"], ["88500", "0.0006", "0", "2"], ["88499.2", "0.0002989", "0", "1"], ["88498.4", "0", "0", "0"], ["88496.1", "0.00001138", "0", "1"], ["88496", "0.03519005", "0", "1"], ["88495.1", "0.00347144", "0", "1"], ["88486.9", "0", "0", "0"], ["88484", "0.00116684", "0", "1"], ["88480.3", "0", "0", "0"], ["88479.7", "0", "0", "0"], ["88479.6", "0", "0", "0"], ["88479.4", "0.01653734", "0", "1"], ["88478.8", "0", "0", "0"], ["88476.1", "0.0173938", "0", "1"], ["88469.7", "0.03634171", "0", "1"], ["88469.6", "0", "0", "0"], ["88469.5", "0", "0", "0"], ["88464.7", "0.03019056", "0", "1"], ["88446.6", "0.10549324", "0", "2"], ["88443.9", "0.00093027", "0", "1"], ["88426.8", "0", "0", "0"], ["88304.9", "0.033885", "0", "1"], ["88292.4", "0.00001139", "0", "1"], ["88292.3", "0.00002159", "0", "1"], ["88292", "0.0025", "0", "1"], ["88291", "0.005", "0", "2"]], "ts": "1741338232505", "checksum": -1517286174, "seqId": 48070577245, "prevSeqId": 48070576819}]}
{"arg": {"channel": "books", "instId": "BTC-USDT"}, "action": "update", "data": [{"asks": [["88528", "0.20486541", "0", "6"], ["88528.5", "0.0002", "0", "2"], ["88529.3", "0", "0", "0"], ["88529.5", "0", "0", "0"], ["88529.7", "0", "0", "0"], ["88530.6", "0.00003321", "0", "2"], ["88533.2", "0.06124314", "0", "2"], ["88533.7", "0.06124314", "0", "2"], ["88533.8", "0", "0", "0"], ["88535.8", "0.04054925", "0", "3"], ["88536", "0.02980367", "0", "1"], ["88536.2", "0.05321841", "0", "2"], ["88536.4", "0.00019692", "0", "2"], ["88536.8", "0.0000465", "0", "1"], ["88538", "0", "0", "0"], ["88539.5", "0", "0", "0"], ["88539.6", "0.0814689", "0", "3"], ["88539.9", "0.19723637", "0", "2"], ["88540", "0.3443365", "0", "5"], ["88540.1", "0.08102799", "0", "2"], ["88540.2", "0.08228223", "0", "2"], ["88540.8", "0", "0", "0"], ["88541", "0.00004407", "0", "3"], ["88541.7", "0.01355123", "0", "3"], ["88543.1", "0.1441111", "0", "2"], ["88543.2", "0.13245476", "0", "1"], ["88543.3", "0.00001005", "0", "1"], ["88543.6", "0", "0", "0"], ["88543.7", "0.14892279", "0", "2"], ["88546.3", "0.14128428", "0", "2"], ["88546.5", "0.00001", "0", "1"], ["88547.7", "0.00963409", "0", "2"], ["88548.1", "0.00001011", "0", "1"], ["88556.4", "0.012102", "0", "1"], ["88560.1", "0.00017777", "0", "3"], ["88562.1", "0.0364177", "0", "1"], ["88563.4", "0.15510243", "0", "1"], ["88564", "0.00001139", "0", "1"], ["88566.8", "0.22599277", "0", "2"], ["88567.4", "0", "0", "0"], ["88571", "0.06", "0", "2"], ["88572", "0.09", "0", "3"], ["88573", "0", "0", "0"], ["88590.5", "0.10002281", "0", "3"], ["88617.9", "0.0009692", "0", "1"]], "bids": [["88527.9", "0.3020551", "0", "9"], ["88527.7", "0.00145491", "0", "1"], ["88527.6", "0", "0", "0"], ["88527.3", "0", "0", "0"], ["88527.2", "0", "0", "0"], ["88526.7", "0", "0", "0"], ["88526.5", "0", "0", "0"], ["88526.2", "0.28007165", "0", "2"], ["88525.4", "0.33889", "0", "1"], ["88524.4", "0.0001", "0", "1"], ["88523.8", "0.0001", "0", "1"], ["88523.7", "0.33889", "0", "1"], ["88521.8", "0.00942", "0", "1"], ["88519.1", "0.22885467", "0", "2"], ["88518.6", "0.02584334", "0", "1"], ["88518.5", "0.17938287", "0", "5"], ["88518.2", "0.00003975", "0", "1"], ["88518.1", "0.02917789", "0", "1"], ["88515.5", "0", "0", "0"], ["88514.8", "0.07965247", "0", "1"], ["88514.6", "0.07294467", "0", "1"], ["88514.3", "0", "0", "0"], ["88514", "0.09526428", "0", "2"], ["88511.6", "0.18502626", "0", "3"], ["88510.7", "0.14753866", "0", "1"], ["88509.3", "0.22590207", "0", "1"], ["88507.8", "0.14985806", "0", "1"], ["88500", "0.00059915", "0", "2"], ["88486", "0", "0", "0"], ["88485", "0.06", "0", "2"], ["88484", "0.03", "0", "1"], ["88483.6", "0.38835885", "0", "2"], ["88481.1", "0.1", "0", "1"], ["88480.3", "0.498416", "0", "1"], ["88469.8", "0.01150221", "0", "1"], ["88428.5", "0.1", "0", "1"], ["88386.7", "0.05086293", "0", "1"], ["88304.9", "0", "0", "0"], ["88294.7", "0", "0", "0"], ["88294.1", "0", "0", "0"], ["88294", "0", "0", "0"], ["88293.4", "0", "0", "0"], ["88292.4", "0", "0", "0"], ["88292.3", "0", "0", "0"], ["88292", "0", "0", "0"], ["88291", "0", "0", "0"]], "ts": "1741338232605", "checksum": 2068597172, "seqId": 48070577502, "prevSeqId": 48070577245}]}
{"arg": {"channel": "books", "instId": "BTC-USDT"}, "action": "update", "data": [{"asks": [["88528", "0.20185914", "0", "5"], ["88528.5", "0", "0", "0"], ["88528.8", "0.0051", "0", "2"], ["88529.4", "0.11305464", "0", "2"], ["88530.6", "0.00001446", "0", "1"], ["88533.7", "0", "0", "0"], ["88535.7", "0.02962905", "0", "2"], ["88535.8", "0.01155702", "0", "2"], ["88535.9", "0.02985198", "0", "2"], ["88536", "0", "0", "0"], ["88536.1", "0.02480136", "0", "1"], ["88536.2", "0.02619312", "0", "1"], ["88536.8", "0", "0", "0"], ["88537", "0.01358129", "0", "2"], ["88538", "0.11232126", "0", "1"], ["88539.4", "0.08231836", "0", "1"], ["88539.6", "0.00031761", "0", "2"], ["88539.9", "0.00003598", "0", "1"], ["88540", "0.16902284", "0", "6"], ["88540.1", "0.00003293", "0", "1"], ["88540.2", "0.00007853", "0", "1"], ["88540.4", "0.07856182", "0", "1"], ["88540.5", "0.00462792", "0", "4"], ["88543", "0.11827565", "0", "4"], ["88543.1", "0.13139679", "0", "2"], ["88543.2", "0", "0", "0"], ["88543.5", "0.14572645", "0", "2"], ["88543.7", "0.00001033", "0", "1"], ["88544.9", "0.14845055", "0", "1"], ["88546.2", "0.18798873", "0", "2"], ["88546.3", "0.00013676", "0", "1"], ["88546.4", "0.00026336", "0", "7"], ["88548.6", "0.20757039", "0", "1"], ["88548.7", "0.0112935", "0", "1"], ["88556", "0.01211549", "0", "2"], ["88556.4", "0", "0", "0"], ["88577.5", "0", "0", "0"], ["88586.2", "0.32317953", "0", "2"], ["88595.9", "0.01739428", "0", "1"], ["88600.8", "0", "0", "0"], ["88601.2", "0", "0", "0"], ["88613.2", "0.01128501", "0", "1"], ["88618.2", "0.0000551", "0", "1"], ["88618.5", "0.00002031", "0", "2"], ["88618.7", "0.00165291", "0", "3"]], "bids": [["88527.9", "0.30111783", "0", "9"], ["88527.7", "0", "0", "0"], ["88527.5", "0.00145491", "0", "1"], ["88527.4", "0.112957", "0", "1"], ["88526.2", "0.27861674", "0", "1"], ["88525.5", "0.0002", "0", "2"], ["88524.4", "0", "0", "0"], ["88523.8", "0", "0", "0"], ["88523.4", "0.1536624", "0", "2"], ["88522.5", "0.3389", "0", "1"], ["88518.6", "0", "0", "0"], ["88518.5", "0.18053882", "0", "5"], ["88518.4", "0.02832027", "0", "1"], ["88518.2", "0", "0", "0"], ["88518.1", "0.0000405", "0", "1"], ["88518", "0.04403789", "0", "2"], ["88517.8", "0.0282525", "0", "1"], ["88514.8", "0", "0", "0"], ["88514.7", "0.69960033", "0", "2"], ["88514.6", "0.90244663", "0", "1"], ["88514.5", "0.07345082", "0", "1"], ["88514.4", "0", "0", "0"], ["88514", "0.0155", "0", "1"], ["88513.9", "0.08719218", "0", "1"], ["88513.7", "0.08307161", "0", "1"], ["88511.6", "0.05194673", "0", "2"], ["88511.4", "0.12960003", "0", "1"], ["88510.7", "0", "0", "0"], ["88510.5", "0.14284572", "0", "1"], ["88509.3", "0", "0", "0"], ["88509.2", "0.14828677", "0", "1"], ["88507.8", "0", "0", "0"], ["88507.7", "0.13953904", "0", "1"], ["88507.1", "0.24240788", "0", "2"], ["88506.7", "0.000168", "0", "1"], ["88501.6", "0.64682259", "0", "2"], ["88493", "0.705344", "0", "2"], ["88488.4", "0.58616671", "0", "1"], ["88487.3", "0", "0", "0"], ["88485.2", "0", "0", "0"], ["88480", "0.05202747", "0", "3"], ["88479.4", "0.0113192", "0", "1"], ["88476.1", "0", "0", "0"], ["88474.9", "0.01128501", "0", "1"], ["88472.3", "0.01739428", "0", "1"], ["88446.6", "0.19099365", "0", "1"], ["88402.9", "0", "0", "0"], ["88397.8", "0.17394284", "0", "1"], ["88296.2", "0", "0", "0"]], "ts": "1741338232705", "checksum": 1448724691, "seqId": 48070577722, "prevSeqId": 48070577502}]}
