{"arg": {"channel": "books", "instId": "BTC-USDT"}, "action": "update", "data": [{"asks": [["84102.3", "0.48949113", "0", "9"], ["84112.6", "0", "0", "0"], ["84113.2", "0.00564", "0", "1"], ["84113.3", "0", "0", "0"], ["84113.7", "0.35297072", "0", "2"], ["84113.9", "0.03126846", "0", "1"], ["84114", "0.35671", "0", "1"], ["84114.7", "0.03205452", "0", "1"], ["84114.8", "0.06557917", "0", "2"], ["84116.5", "0.53476581", "0", "2"], ["84117.9", "0.52533015", "0", "2"], ["84119.1", "0.11893621", "0", "1"], ["84119.6", "0", "0", "0"], ["84120.9", "0.03358922", "0", "1"], ["84121.1", "1.03442428", "0", "2"], ["84121.5", "0.00011161", "0", "1"], ["84121.9", "0", "0", "0"], ["84122", "0", "0", "0"], ["84123.3", "0.05940838", "0", "1"], ["84123.5", "0.03480363", "0", "1"], ["84123.6", "0.06707155", "0", "3"], ["84126.6", "0", "0", "0"], ["84127.9", "0.0683271", "0", "1"], ["84128.7", "0", "0", "0"], ["84130.2", "0.44062406", "0", "2"], ["84130.5", "0.06436154", "0", "1"], ["84132.2", "0.06300707", "0", "1"], ["84262.4", "0", "0", "0"], ["84262.9", "0", "0", "0"], ["84263.9", "0", "0", "0"], ["84264", "0", "0", "0"]], "bids": [["84102.2", "0.11890453", "0", "5"], ["84102", "0.0146", "0", "1"], ["84086.7", "0.0347089", "0", "1"], ["84086.6", "0.03440397", "0", "1"], ["84086.1", "0.03266444", "0", "1"], ["84085.4", "0.0312681", "0", "1"], ["84085.3", "0", "0", "0"], ["84085.2", "0", "0", "0"], ["84084.6", "0.102", "0", "2"], ["84084", "0.33187565", "0", "3"], ["84083.9", "0.01596287", "0", "1"], ["84083.7", "0.35671", "0", "1"], ["84083.1", "0.01596287", "0", "1"], ["84082.6", "1", "0", "1"], ["84082.2", "0.04", "0", "1"], ["84080.3", "0", "0", "0"], ["84079.6", "0.81134378", "0", "3"], ["84079.1", "0.0331681", "0", "1"], ["84078.3", "0", "0", "0"], ["84078", "0.03704149", "0", "2"], ["84077.6", "0", "0", "0"], ["84077.4", "0.03514086", "0", "1"], ["84076.4", "0", "0", "0"], ["84075.8", "1.58638802", "0", "1"], ["84072.7", "0.17835", "0", "1"], ["84072.6", "0.06333876", "0", "1"], ["84071.3", "0", "0", "0"], ["84070.7", "0.06675135", "0", "1"], ["84069.6", "0.06481043", "0", "1"], ["84069.2", "0.06420434", "0", "1"], ["84053.4", "0", "0", "0"], ["84048.8", "0.01774536", "0", "1"], ["84000.1", "2.74101717", "0", "2"], ["83992.7", "0.01179931", "0", "2"], ["83945.1", "0", "0", "0"], ["83944.8", "0", "0", "0"], ["83944.6", "0", "0", "0"], ["83943.8", "0", "0", "0"], ["83943.5", "0", "0", "0"], ["83943.1", "0", "0", "0"], ["83942", "0", "0", "0"]], "ts": "1742554968904", "checksum": 1356114286, "seqId": 49927376514, "prevSeqId": 49927376344}], "record_time": 1742554968.90392, "EXCHANGE": "OKX"}
{"arg": {"channel": "books", "instId": "BTC-USDT"}, "action": "update", "data": [{"asks": [["84113.9", "0", "0", "0"], ["84114.1", "0.03702524", "0", "2"], ["84114.7", "0", "0", "0"], ["84114.8", "0", "0", "0"], ["84115.1", "0.10053403", "0", "3"], ["84120.9", "0", "0", "0"], ["84121.1", "1.03340858", "0", "2"], ["84121.4", "0.03358672", "0", "1"], ["84123.5", "0", "0", "0"], ["84123.6", "0.03379289", "0", "2"], ["84123.8", "0.03319015", "0", "1"], ["84123.9", "0.03433527", "0", "1"], ["84124", "0.2379267", "0", "1"], ["84126.5", "0", "0", "0"], ["84127.9", "0", "0", "0"], ["84128.1", "0.06778487", "0", "1"], ["84130.2", "0.37803235", "0", "1"], ["84130.5", "0.06578011", "0", "1"], ["84130.8", "0.06464961", "0", "1"], ["84132.2", "0", "0", "0"], ["84132.6", "0.07223784", "0", "2"], ["84262.4", "0.0000221", "0", "1"]], "bids": [["84102.2", "0.1205435", "0", "5"], ["84098.5", "0.11896516", "0", "1"], ["84096.9", "0", "0", "0"], ["84096.7", "0", "0", "0"], ["84088.2", "0.57105656", "0", "4"], ["84087.1", "0.06792183", "0", "2"], ["84086.8", "0.03266952", "0", "1"], ["84086.7", "0", "0", "0"], ["84086.6", "0", "0", "0"], ["84086.4", "0.0328548", "0", "1"], ["84086.1", "0", "0", "0"], ["84085.7", "0.06293785", "0", "3"], ["84085.4", "0", "0", "0"], ["84084.2", "1", "0", "1"], ["84082.6", "0", "0", "0"], ["84079.8", "0.0335594", "0", "1"], ["84079.6", "0.78048658", "0", "2"], ["84079.4", "0.03311168", "0", "1"], ["84079.1", "0", "0", "0"], ["84078.3", "0.03410952", "0", "1"], ["84078", "0.002", "0", "1"], ["84077.7", "0.0332202", "0", "1"], ["84077.4", "0", "0", "0"], ["84072.8", "0.06592757", "0", "1"], ["84072.6", "0", "0", "0"], ["84071.4", "0", "0", "0"], ["84071", "0.0727975", "0", "3"], ["84070.7", "0", "0", "0"], ["84069.9", "0.42054863", "0", "2"], ["84069.6", "0.0666981", "0", "1"], ["84069.2", "0", "0", "0"], ["84067.6", "0.2379267", "0", "1"], ["84066", "1", "0", "1"], ["83945.1", "0.002378", "0", "1"], ["83944.8", "0.00011161", "0", "1"]], "ts": "1742554969004", "checksum": -1956938259, "seqId": 49927376590, "prevSeqId": 49927376514}], "record_time": 1742554969.008722, "EXCHANGE": "OKX"}
{"arg": {"channel": "books", "instId": "BTC-USDT"}, "action": "update", "data": [{"asks": [["84102.3", "0.48449113", "0", "8"], ["84105.2", "0.01991583", "0", "1"], ["84112.3", "0", "0", "0"], ["84135.3", "1.24", "0", "1"], ["84140", "0.24006695", "0", "5"]], "bids": [["84102.2", "0.1206173", "0", "6"], ["84088.2", "0.56605656", "0", "3"], ["84086.2", "1.39671", "0", "3"], ["84084.2", "0", "0", "0"], ["84078.1", "0", "0", "0"], ["84059.2", "0.1", "0", "2"], ["84058.4", "0.05", "0", "1"], ["84057.6", "0", "0", "0"], ["84011.4", "0", "0", "0"], ["84009.1", "0.00007197", "0", "1"], ["83997.5", "0", "0", "0"], ["83944.6", "0.00421935", "0", "1"], ["83943.8", "0.2025", "0", "1"], ["83943.5", "0.03", "0", "1"]], "ts": "1742554969104", "checksum": 1502052906, "seqId": 49927376612, "prevSeqId": 49927376590}], "record_time": 1742554969.10739, "EXCHANGE": "OKX"}
{"arg": {"channel": "books", "instId": "BTC-USDT"}, "action": "update", "data": [{"asks": [["84105.9", "0", "0", "0"], ["84108.2", "0.03856295", "0", "1"], ["84138", "1", "0", "1"], ["84262.4", "0", "0", "0"]], "bids": [["84093.7", "0", "0", "0"], ["84091.5", "0.03856295", "0", "1"], ["84088.2", "0.30480309", "0", "2"], ["84086.2", "0.39671", "0", "2"], ["84084", "0.52439206", "0", "4"], ["84083.7", "0", "0", "0"], ["84082.7", "1", "0", "1"], ["84071", "0.0702975", "0", "2"]], "ts": "1742554969204", "checksum": 510604308, "seqId": 49927376626, "prevSeqId": 49927376612}], "record_time": 1742554969.205255, "EXCHANGE": "OKX"}
{"arg": {"channel": "books", "instId": "BTC-USDT"}, "action": "update", "data": [{"asks": [["84104", "0.0246", "0", "3"], ["84114.1", "0.04202524", "0", "3"], ["84119.3", "1", "0", "1"], ["84121.1", "0.03340858", "0", "1"], ["84262.2", "0", "0", "0"]], "bids": [["84094.6", "0.2", "0", "1"], ["84093.8", "0.01", "0", "2"], ["84084.4", "1.01339", "0", "2"], ["84083.8", "0.01", "0", "2"], ["84082.7", "0", "0", "0"], ["84072", "0", "0", "0"], ["84066", "0", "0", "0"], ["84006.8", "0.059995", "0", "1"], ["83943.1", "0.01775819", "0", "1"]], "ts": "1742554969304", "checksum": 955187295, "seqId": 49927376638, "prevSeqId": 49927376626}], "record_time": 1742554969.311336, "EXCHANGE": "OKX"}
{"arg": {"channel": "books", "instId": "BTC-USDT"}, "action": "update", "data": [{"asks": [["84114.1", "0.01", "0", "2"], ["84115.1", "0", "0", "0"], ["84121.1", "0", "0", "0"], ["84121.4", "0", "0", "0"], ["84123.8", "0", "0", "0"], ["84123.9", "0", "0", "0"], ["84128.1", "0", "0", "0"], ["84130.5", "0", "0", "0"], ["84130.8", "0", "0", "0"], ["84132.6", "0.00420263", "0", "1"], ["84138", "0", "0", "0"], ["84138.4", "0.35782292", "0", "3"], ["84139.2", "0.03999999", "0", "1"], ["84140", "0.00006696", "0", "3"], ["84262.2", "0.00003778", "0", "1"], ["84262.4", "0.0000221", "0", "1"], ["84262.9", "0.17821722", "0", "1"], ["84263.9", "0.00003969", "0", "2"], ["84264", "0.00074396", "0", "1"], ["84264.9", "0.00031778", "0", "3"], ["84265.1", "0.00418989", "0", "1"], ["84265.8", "0.00001156", "0", "1"], ["84266", "0.11878326", "0", "1"]], "bids": [["84102.2", "0.12042564", "0", "6"], ["84102", "0", "0", "0"], ["84087.1", "0.0372423", "0", "1"], ["84086.8", "0", "0", "0"], ["84086.4", "0", "0", "0"], ["84085.7", "0.02786162", "0", "2"], ["84084.4", "0.01339", "0", "1"], ["84084", "0.63154929", "0", "3"], ["84083.7", "0.35671", "0", "1"], ["84083.1", "1.01596287", "0", "2"], ["84079.8", "0", "0", "0"], ["84079.4", "0", "0", "0"], ["84078.3", "0", "0", "0"], ["84077.7", "0", "0", "0"], ["84072.8", "0", "0", "0"], ["84071", "0.0025", "0", "1"], ["84070", "0.0025", "0", "1"], ["84069.9", "0.35641581", "0", "1"], ["84069.6", "0", "0", "0"], ["84063.2", "0.08", "0", "2"], ["84062.4", "0.04", "0", "1"], ["84061.6", "0.026", "0", "2"], ["83942", "0.00007352", "0", "1"], ["83941.8", "0.00001197", "0", "1"], ["83941.1", "0.00001807", "0", "1"], ["83940.4", "0.00002279", "0", "1"], ["83939.8", "2.4621163", "0", "2"], ["83939.7", "0.03", "0", "1"], ["83939.5", "0.00007329", "0", "1"]], "ts": "1742554969404", "checksum": 1583940444, "seqId": 49927376689, "prevSeqId": 49927376638}], "record_time": 1742554969.404201, "EXCHANGE": "OKX"}
{"arg": {"channel": "books", "instId": "BTC-USDT"}, "action": "update", "data": [{"asks": [["84114", "0.39178845", "0", "2"], ["84114.9", "0.03502607", "0", "1"], ["84115", "0.06518491", "0", "3"], ["84121", "0.03455263", "0", "2"], ["84121.2", "0.03145705", "0", "1"], ["84123.7", "0.03494177", "0", "1"], ["84123.8", "0.03338421", "0", "1"], ["84128", "0.0678377", "0", "1"], ["84130.4", "0.31900499", "0", "4"], ["84130.7", "0.06992944", "0", "1"], ["84132.5", "0.06411384", "0", "1"], ["84134.9", "0.64816163", "0", "2"], ["84164.2", "0.45667601", "0", "2"], ["84262.9", "0", "0", "0"], ["84263.9", "0", "0", "0"], ["84264", "0", "0", "0"], ["84264.9", "0", "0", "0"], ["84265.1", "0", "0", "0"], ["84265.8", "0", "0", "0"], ["84266", "0", "0", "0"]], "bids": [["84087", "0.03447934", "0", "1"], ["84086.7", "0.03496362", "0", "1"], ["84086.3", "0.21021317", "0", "2"], ["84085.5", "0.03216422", "0", "2"], ["84083.1", "0.01596287", "0", "1"], ["84081.7", "1", "0", "1"], ["84079.7", "0.17445328", "0", "2"], ["84079.2", "0.03242987", "0", "1"], ["84078.2", "0.38114183", "0", "5"], ["84077.6", "0.03110586", "0", "1"], ["84072.7", "0.24355898", "0", "2"], ["84070.9", "0.06206818", "0", "1"], ["84070", "0.33677074", "0", "2"], ["84069.8", "0.06640091", "0", "1"], ["84069.5", "0.06855389", "0", "2"], ["84042.5", "0.00001501", "0", "1"], ["84037.4", "0.17507445", "0", "1"], ["84032.6", "0", "0", "0"], ["84031.2", "0", "0", "0"], ["84011.1", "0.56049124", "0", "2"], ["84000.1", "0", "0", "0"], ["83941.1", "0", "0", "0"], ["83940.4", "0", "0", "0"], ["83939.8", "0", "0", "0"], ["83939.7", "0", "0", "0"], ["83939.5", "0", "0", "0"]], "ts": "1742554969504", "checksum": 1583940444, "seqId": 49927376728, "prevSeqId": 49927376689}], "record_time": 1742554969.509621, "EXCHANGE": "OKX"}
{"arg": {"channel": "books", "instId": "BTC-USDT"}, "action": "update", "data": [{"asks": [["84113.2", "0", "0", "0"], ["84114", "0.35671", "0", "1"], ["84114.3", "0.01753471", "0", "2"], ["84114.6", "0.03438283", "0", "1"], ["84114.9", "0", "0", "0"], ["84115", "0.00001501", "0", "1"], ["84115.6", "0.03115035", "0", "1"], ["84115.7", "0.06691253", "0", "2"], ["84119.3", "0", "0", "0"], ["84120.9", "1", "0", "1"], ["84121", "0.0035118", "0", "1"], ["84121.2", "0", "0", "0"], ["84121.6", "0.0309233", "0", "1"], ["84121.9", "0.03127064", "0", "1"], ["84123.7", "0", "0", "0"], ["84123.8", "0", "0", "0"], ["84124.4", "0.03694888", "0", "2"], ["84124.5", "0.03363562", "0", "1"], ["84128", "0", "0", "0"], ["84128.6", "0.06635638", "0", "1"], ["84130.4", "0.25453713", "0", "3"], ["84130.7", "0", "0", "0"], ["84131.1", "0.06780965", "0", "1"], ["84131.4", "0.06674853", "0", "1"], ["84132.5", "0", "0", "0"], ["84133.2", "0.06774275", "0", "1"], ["84180.9", "0.07127514", "0", "1"], ["84262.2", "0", "0", "0"], ["84262.4", "0", "0", "0"]], "bids": [["84102", "0.0146", "0", "1"], ["84101.3", "0.11896119", "0", "1"], ["84098.5", "0", "0", "0"], ["84088.2", "0.55982749", "0", "3"], ["84087.7", "0.03442572", "0", "1"], ["84087.3", "0.03362808", "0", "1"], ["84087", "0.03491156", "0", "1"], ["84086.7", "0", "0", "0"], ["84086.3", "0.17835", "0", "1"], ["84086.2", "0.42974355", "0", "3"], ["84085.5", "0.00001197", "0", "1"], ["84085", "1", "0", "1"], ["84084", "0.35028647", "0", "3"], ["84081.7", "0", "0", "0"], ["84080.3", "0.03418587", "0", "1"], ["84079.9", "0.03186471", "0", "1"], ["84079.7", "0.1403523", "0", "1"], ["84079.2", "0", "0", "0"], ["84078.9", "0.03211227", "0", "1"], ["84078.3", "0.03350388", "0", "1"], ["84078.2", "0.34917405", "0", "4"], ["84077.6", "0", "0", "0"], ["84073.3", "0.0644006", "0", "1"], ["84072.7", "0.17835", "0", "1"], ["84071.6", "0.06585626", "0", "1"], ["84070.9", "0", "0", "0"], ["84070.5", "0.06742423", "0", "1"], ["84070.2", "0.06358345", "0", "1"], ["84069.8", "0", "0", "0"], ["84069.5", "0.00357", "0", "1"], ["84015.8", "0.07141506", "0", "1"], ["83944.6", "0", "0", "0"], ["83943.8", "0", "0", "0"], ["83943.5", "0", "0", "0"], ["83943.1", "0", "0", "0"], ["83942", "0", "0", "0"], ["83941.8", "0", "0", "0"]], "ts": "1742554969804", "checksum": 2101402546, "seqId": 49927376845, "prevSeqId": 49927376728}], "record_time": 1742554969.805603, "EXCHANGE": "OKX"}
{"arg": {"channel": "books", "instId": "BTC-USDT"}, "action": "update", "data": [{"asks": [["84114.6", "0", "0", "0"], ["84115", "0.0316029", "0", "2"], ["84115.6", "0", "0", "0"], ["84115.7", "0.03235492", "0", "1"], ["84115.8", "0.03190538", "0", "1"], ["84115.9", "0.03463041", "0", "1"], ["84117.9", "0.26888154", "0", "1"], ["84120.9", "0", "0", "0"], ["84121.6", "0", "0", "0"], ["84121.9", "0", "0", "0"], ["84122", "0.03308254", "0", "1"], ["84122.2", "0.32880893", "0", "2"], ["84123.1", "1", "0", "1"], ["84124", "0", "0", "0"], ["84124.4", "0.00420325", "0", "1"], ["84124.5", "0.03362352", "0", "1"], ["84124.6", "0.03279657", "0", "1"], ["84125.7", "0.23792357", "0", "1"], ["84128.6", "0", "0", "0"], ["84129", "0.06847922", "0", "1"], ["84131.1", "0", "0", "0"], ["84131.2", "0.06863577", "0", "1"], ["84131.4", "0", "0", "0"], ["84131.7", "0.06661989", "0", "1"], ["84180.9", "0.14255028", "0", "2"]], "bids": [["84102.2", "0.46562564", "0", "9"], ["84091.7", "0.48051819", "0", "2"], ["84088.9", "1", "0", "1"], ["84088.2", "0.30480309", "0", "2"], ["84087.7", "0.06854194", "0", "2"], ["84087.3", "0", "0", "0"], ["84087.1", "0.0699003", "0", "2"], ["84087", "0", "0", "0"], ["84086.5", "0.03271907", "0", "1"], ["84086.2", "0.39671", "0", "2"], ["84085", "0", "0", "0"], ["84084", "0.26390721", "0", "3"], ["84083.7", "0", "0", "0"], ["84080.7", "0.03465498", "0", "1"], ["84080.3", "0", "0", "0"], ["84080.2", "0.03396432", "0", "1"], ["84079.9", "0", "0", "0"], ["84079", "0.03197577", "0", "1"], ["84078.9", "0", "0", "0"], ["84078.4", "0.38962065", "0", "2"], ["84078.3", "0", "0", "0"], ["84073.7", "0.0698458", "0", "1"], ["84073.3", "0", "0", "0"], ["84071.7", "0.06262131", "0", "1"], ["84071.6", "0", "0", "0"], ["84070.8", "0.06885303", "0", "1"], ["84070.5", "0", "0", "0"], ["84070.3", "0.23792357", "0", "1"], ["84070", "0.0025", "0", "1"], ["84067.6", "0", "0", "0"], ["84034.2", "0.00235597", "0", "1"], ["84024.9", "0.01901687", "0", "1"], ["84015.8", "0.14283012", "0", "2"], ["83944.6", "0.00421935", "0", "1"]], "ts": "1742554969904", "checksum": -1483625703, "seqId": 49927377006, "prevSeqId": 49927376845}], "record_time": 1742554969.906249, "EXCHANGE": "OKX"}
{"arg": {"channel": "books", "instId": "BTC-USDT"}, "action": "update", "data": [{"asks": [["84102.3", "0.42621339", "0", "8"], ["84102.7", "0", "0", "0"], ["84102.8", "0", "0", "0"], ["84105", "0", "0", "0"], ["84109.2", "0.15661744", "0", "1"], ["84113.8", "0.0103941", "0", "1"], ["84114", "0.03166", "0", "1"], ["84114.3", "0.01189471", "0", "1"], ["84115", "0.00001501", "0", "1"], ["84115.5", "0.07224313", "0", "2"], ["84115.7", "0", "0", "0"], ["84115.8", "0", "0", "0"], ["84115.9", "0.06695834", "0", "2"], ["84116.1", "0.03332225", "0", "1"], ["84117.6", "0.00564", "0", "1"], ["84122", "0", "0", "0"], ["84122.2", "0.29684137", "0", "1"], ["84122.4", "0.03133152", "0", "1"], ["84122.5", "0.03116812", "0", "1"], ["84124.1", "0.15638943", "0", "2"], ["84124.5", "0", "0", "0"], ["84124.6", "0.03149041", "0", "1"], ["84124.7", "0.0330942", "0", "1"], ["84125.7", "0", "0", "0"], ["84129", "0", "0", "0"], ["84129.2", "0", "0", "0"], ["84129.5", "0.20404356", "0", "2"], ["84131.2", "0.23791429", "0", "1"], ["84131.3", "0.06192238", "0", "1"], ["84131.7", "0", "0", "0"], ["84131.9", "0.06872297", "0", "1"], ["84133.2", "0", "0", "0"], ["84133.4", "0.06367796", "0", "1"], ["84138.4", "0.27782292", "0", "1"], ["84139.2", "0.07999999", "0", "2"], ["84140", "0.04006695", "0", "4"], ["84143.4", "0.35641581", "0", "1"], ["84174.6", "0.579576", "0", "2"], ["84262.2", "0.00003778", "0", "1"], ["84262.4", "0.0000221", "0", "1"], ["84262.9", "0.17821722", "0", "1"]], "bids": [["84102.2", "0.68597312", "0", "15"], ["84094.2", "0.01339", "0", "1"], ["84090.3", "1", "0", "1"], ["84089.3", "0", "0", "0"], ["84088.9", "0", "0", "0"], ["84088.2", "0.33793376", "0", "3"], ["84087.9", "0.07352883", "0", "2"], ["84087.7", "0", "0", "0"], ["84087.2", "0.03350189", "0", "1"], ["84087.1", "0.0372423", "0", "1"], ["84086.7", "0.03327897", "0", "1"], ["84086.5", "0", "0", "0"], ["84083", "0", "0", "0"], ["84081.2", "0.1707214", "0", "4"], ["84080.7", "0", "0", "0"], ["84080.4", "0.03312453", "0", "1"], ["84080.2", "0", "0", "0"], ["84079.1", "0.03419203", "0", "1"], ["84079", "0", "0", "0"], ["84078.5", "0.03364915", "0", "1"], ["84078.4", "0.35641581", "0", "1"], ["84077.9", "0.00475749", "0", "1"], ["84074.9", "0.02745264", "0", "1"], ["84074.2", "0.06859883", "0", "1"], ["84073.9", "0.23796756", "0", "2"], ["84073.7", "0", "0", "0"], ["84071.8", "0.06783155", "0", "1"], ["84071.7", "0", "0", "0"], ["84071", "0.06564446", "0", "2"], ["84070.8", "0", "0", "0"], ["84070.4", "0.06484542", "0", "1"], ["84070.3", "0", "0", "0"], ["84070.2", "0.02817312", "0", "1"], ["84063.2", "0", "0", "0"], ["84062.4", "0.08", "0", "2"], ["84061.6", "0.066", "0", "3"], ["84059.2", "0", "0", "0"], ["84058.4", "0.1", "0", "2"], ["84057.6", "0.05", "0", "1"], ["84054.9", "0", "0", "0"], ["84051.9", "0", "0", "0"], ["83943.8", "0.2025", "0", "1"], ["83943.5", "0.03", "0", "1"]], "ts": "1742554970004", "checksum": -1068179699, "seqId": 49927377127, "prevSeqId": 49927377006}], "record_time": 1742554970.004393, "EXCHANGE": "OKX"}
{"arg": {"channel": "books", "instId": "BTC-USDT"}, "action": "snapshot", "data": [{"asks": [["84104.1", "0.6471702", "0", "22"], ["84104.9", "0.0978316", "0", "1"], ["84105.5", "0.11895537", "0", "1"], ["84106", "0.0146", "0", "1"], ["84108.1", "0.0252911", "0", "1"], ["84108.5", "0.2385", "0", "2"], ["84108.9", "0.03166", "0", "1"], ["84109.3", "0.0178063", "0", "1"], ["84110", "0.0146", "0", "1"], ["84110.2", "0.00001197", "0", "1"], ["84110.3", "0.03027833", "0", "2"], ["84110.4", "0.036", "0", "1"], ["84110.6", "0.03760803", "0", "1"], ["84111.6", "0.00349255", "0", "1"], ["84111.9", "0.00111889", "0", "1"], ["84112", "0.0146", "0", "1"], ["84112.2", "0.002", "0", "1"], ["84112.4", "0.008567", "0", "2"], ["84113.9", "0.00772812", "0", "1"], ["84114", "0.0146", "0", "1"], ["84114.1", "0.17835", "0", "1"], ["84114.2", "0.30319525", "0", "1"], ["84114.3", "0.3567", "0", "1"], ["84114.4", "0.0153941", "0", "2"], ["84115", "0.000015", "0", "1"], ["84115.2", "0.00001197", "0", "1"], ["84115.6", "0.17821722", "0", "1"], ["84115.8", "0.12666879", "0", "2"], ["84115.9", "0.0001185", "0", "1"], ["84116", "0.0146", "0", "1"], ["84116.5", "0.03499693", "0", "1"], ["84117.2", "0.0318792", "0", "1"], ["84117.3", "0.06669701", "0", "2"], ["84117.5", "0.2025", "0", "1"], ["84117.9", "0.07165995", "0", "1"], ["84118", "0.0429014", "0", "2"], ["84118.3", "0.01055", "0", "1"], ["84118.5", "0.01189411", "0", "1"], ["84120", "0.0146", "0", "1"], ["84120.1", "0.00001197", "0", "1"], ["84120.3", "0.06", "0", "2"], ["84120.4", "0.04", "0", "1"], ["84121.7", "0.11890903", "0", "1"], ["84122", "0.01548436", "0", "2"], ["84122.1", "0.33792366", "0", "1"], ["84122.2", "0.002", "0", "1"], ["84122.4", "0.005", "0", "1"], ["84122.9", "0.1189308", "0", "1"], ["84123.4", "0.237929", "0", "2"], ["84123.5", "0.03114033", "0", "1"], ["84123.6", "0.1526351", "0", "5"], ["84123.7", "0.04", "0", "1"], ["84124", "0.0146", "0", "1"], ["84124.4", "0.005", "0", "1"], ["84124.5", "0.00420325", "0", "1"], ["84124.6", "0.00006", "0", "1"], ["84125.1", "0.00001197", "0", "1"], ["84125.7", "0.35641581", "0", "1"], ["84125.8", "0.17821722", "0", "1"], ["84125.9", "0.14622342", "0", "3"], ["84126", "0.04745226", "0", "2"], ["84126.4", "0.3080173", "0", "1"], ["84126.5", "1", "0", "1"], ["84127.6", "0.0054", "0", "1"], ["84130.1", "0.01775733", "0", "2"], ["84130.2", "0.88948391", "0", "2"], ["84130.3", "0.11890903", "0", "1"], ["84130.5", "0.26602468", "0", "2"], ["84130.8", "0.10885393", "0", "2"], ["84131.2", "1.61022407", "0", "1"], ["84131.7", "0.00107928", "0", "1"], ["84131.8", "0.00001501", "0", "1"], ["84132.6", "0.00420263", "0", "1"], ["84132.7", "0.06363152", "0", "1"], ["84133", "0.06350637", "0", "1"], ["84133.3", "0.00101534", "0", "2"], ["84133.6", "0.24967", "0", "1"], ["84134.2", "0.48124581", "0", "2"], ["84134.4", "0.17821722", "0", "1"], ["84134.7", "0.06480082", "0", "1"], ["84135", "0.55951707", "0", "2"], ["84135.1", "1.24", "0", "1"], ["84136.5", "0.11228184", "0", "2"], ["84137.6", "0.08991011", "0", "1"], ["84137.7", "0.1871364", "0", "1"], ["84138.1", "0.1403523", "0", "1"], ["84138.8", "0.21812487", "0", "1"], ["84139.4", "0.0054", "0", "1"], ["84140", "0.00006696", "0", "3"], ["84140.2", "0.000015", "0", "1"], ["84140.3", "0.00056011", "0", "1"], ["84140.6", "0.2025", "0", "1"], ["84140.8", "0.08", "0", "2"], ["84141.1", "0.2741073", "0", "2"], ["84141.2", "0.00011161", "0", "1"], ["84141.6", "0.03999999", "0", "1"], ["84142.2", "0.05940838", "0", "1"], ["84142.6", "0.00420121", "0", "1"], ["84142.9", "0.00357", "0", "1"], ["84143.3", "0.27816937", "0", "2"], ["84143.4", "0.35641581", "0", "1"], ["84143.5", "0.17821722", "0", "1"], ["84144", "0.01153332", "0", "1"], ["84144.5", "0.25755", "0", "1"], ["84145", "0.00001197", "0", "1"], ["84146.6", "0.001784", "0", "1"], ["84146.7", "0.17880403", "0", "2"], ["84147", "0.11228184", "0", "2"], ["84147.2", "0.01603713", "0", "1"], ["84147.5", "0.53182", "0", "1"], ["84148", "0.470927", "0", "1"], ["84148.2", "0.00576666", "0", "1"], ["84148.6", "0.00001501", "0", "1"], ["84148.7", "0.1", "0", "1"], ["84149.2", "0.36421998", "0", "1"], ["84149.3", "0.2497", "0", "1"], ["84149.9", "0.00061841", "0", "2"], ["84150.1", "0.21853713", "0", "2"], ["84150.2", "0.62521106", "0", "3"], ["84151.6", "0.05715626", "0", "1"], ["84151.9", "0.00357", "0", "1"], ["84152.4", "0.00576666", "0", "1"], ["84152.6", "0.17549939", "0", "1"], ["84152.7", "0.18821722", "0", "2"], ["84152.9", "0.35641581", "0", "1"], ["84153.1", "0.02377761", "0", "1"], ["84154.1", "0.01657538", "0", "1"], ["84154.9", "0.00001196", "0", "1"], ["84155.8", "0.01188291", "0", "1"], ["84155.9", "0.11890903", "0", "1"], ["84156", "0.0118827", "0", "1"], ["84156.3", "0.00420026", "0", "1"], ["84156.5", "0.01783312", "0", "1"], ["84157", "0.00001501", "0", "1"], ["84157.3", "0.01189464", "0", "1"], ["84157.5", "0.11228184", "0", "2"], ["84158", "0.00001", "0", "1"], ["84158.8", "0.00004312", "0", "1"], ["84158.9", "0.2025", "0", "1"], ["84159.8", "0.00001196", "0", "1"], ["84159.9", "0.06", "0", "2"], ["84160", "0.00004", "0", "1"], ["84160.4", "0.00357", "0", "1"], ["84160.5", "1.33872033", "0", "2"], ["84160.6", "2.8886602", "0", "1"], ["84160.8", "0.00011161", "0", "1"], ["84161", "0.11846252", "0", "1"], ["84162.2", "0.02376576", "0", "2"], ["84162.6", "0.56532317", "0", "1"], ["84162.8", "0.17821722", "0", "1"], ["84163.8", "0.4", "0", "1"], ["84164.2", "0.44974346", "0", "2"], ["84164.3", "0.35641581", "0", "1"], ["84164.4", "0.916956", "0", "1"], ["84164.5", "0.00419925", "0", "1"], ["84164.8", "0.00001196", "0", "1"], ["84164.9", "0.11890903", "0", "1"], ["84165.4", "0.000015", "0", "1"], ["84166.6", "0.00104525", "0", "3"], ["84167.4", "0.01124493", "0", "1"], ["84167.5", "0.2025", "0", "1"], ["84168.6", "0.01188285", "0", "1"], ["84169.8", "0.00001196", "0", "1"], ["84170", "0.03", "0", "1"], ["84171.6", "0.17821722", "0", "1"], ["84173.1", "0.22650126", "0", "1"], ["84173.2", "0.35641581", "0", "1"], ["84173.6", "0.11890903", "0", "1"], ["84173.8", "0.000015", "0", "1"], ["84174.1", "0.05459", "0", "1"], ["84174.6", "0.00712804", "0", "1"], ["84174.7", "0.00001196", "0", "1"], ["84175.8", "0.00419826", "0", "1"], ["84176.1", "0.2025", "0", "1"], ["84177.9", "0.01", "0", "1"], ["84178", "0.21297795", "0", "1"], ["84178.1", "0.47216", "0", "1"], ["84179.1", "0.05942571", "0", "1"], ["84179.7", "0.00001196", "0", "1"], ["84180.4", "0.00011161", "0", "1"], ["84180.5", "0.17821722", "0", "1"], ["84180.6", "0.19170269", "0", "1"], ["84181.4", "0.00192246", "0", "1"], ["84181.5", "0.0054", "0", "1"], ["84181.8", "0.00003887", "0", "1"], ["84182.1", "0.000015", "0", "1"], ["84182.2", "0.11892404", "0", "2"], ["84182.6", "0.35641581", "0", "1"], ["84183.3", "0.00060645", "0", "1"], ["84184.1", "0.00594496", "0", "1"], ["84184.2", "0.00419766", "0", "1"], ["84184.7", "0.00001196", "0", "1"], ["84184.9", "0.00012217", "0", "1"], ["84185", "0.13155233", "0", "2"], ["84185.1", "0.1", "0", "1"], ["84185.2", "0.1", "0", "1"], ["84185.4", "0.08991011", "0", "1"], ["84186.5", "0.089801", "0", "1"], ["84186.8", "0.02376554", "0", "2"], ["84187.1", "0.14253978", "0", "2"], ["84189.4", "0.00594496", "0", "1"], ["84189.6", "1.29104218", "0", "2"], ["84189.7", "3.288", "0", "1"], ["84190", "0.00001057", "0", "1"], ["84190.6", "0.00001501", "0", "1"], ["84191", "0.1841611", "0", "2"], ["84191.1", "0.35641581", "0", "1"], ["84191.3", "0.11890903", "0", "1"], ["84191.5", "0.3025", "0", "2"], ["84192.2", "0.06", "0", "2"], ["84192.5", "0.00594388", "0", "1"], ["84192.6", "0.0041965", "0", "1"], ["84193.2", "0.05141781", "0", "2"], ["84193.6", "0.01799989", "0", "1"], ["84193.8", "0.0001964", "0", "1"], ["84194.6", "0.00001196", "0", "1"], ["84194.7", "0.08991011", "0", "1"], ["84196.1", "0.08751", "0", "1"], ["84196.2", "0.00594388", "0", "1"], ["84197.1", "0.03", "0", "1"], ["84198.6", "0.03", "0", "1"], ["84199", "0.00001501", "0", "1"], ["84199.2", "1.87716699", "0", "1"], ["84199.6", "0.00001196", "0", "1"], ["84199.7", "0.35641581", "0", "1"], ["84199.8", "0.11890903", "0", "1"], ["84199.9", "0.18857973", "0", "8"], ["84200", "5.34702668", "0", "34"], ["84200.1", "0.00011161", "0", "1"], ["84200.4", "0.00419565", "0", "1"], ["84200.5", "0.03", "0", "1"], ["84201.8", "0.4826249", "0", "2"], ["84201.9", "1.374821", "0", "1"], ["84202", "0.00005073", "0", "1"], ["84202.8", "0.00002241", "0", "1"], ["84204", "0.01425109", "0", "1"], ["84204.5", "0.00033082", "0", "3"], ["84204.7", "0.12861537", "0", "2"], ["84205", "0.00181735", "0", "1"], ["84206.4", "1.11585279", "0", "2"], ["84206.5", "0.2025", "0", "1"], ["84206.6", "0.03566288", "0", "1"], ["84206.9", "0.00118755", "0", "1"], ["84207.4", "0.000015", "0", "1"], ["84207.5", "0.02377817", "0", "1"], ["84207.7", "0.00419514", "0", "1"], ["84208.5", "0.00040805", "0", "13"], ["84208.7", "0.00001096", "0", "1"], ["84209.3", "0.00011444", "0", "1"], ["84209.5", "0.00001197", "0", "1"], ["84209.6", "3.52391", "0", "1"], ["84210.5", "0.00013667", "0", "2"], ["84210.6", "0.21299237", "0", "1"], ["84211.1", "0.00002037", "0", "1"], ["84211.7", "0.00003107", "0", "2"], ["84212.1", "0.00001023", "0", "1"], ["84212.5", "0.00001995", "0", "1"], ["84213", "0.00600038", "0", "1"], ["84213.1", "0.17821722", "0", "1"], ["84213.5", "0.35641581", "0", "1"], ["84214.2", "0.00001575", "0", "1"], ["84214.5", "0.00001197", "0", "1"], ["84214.8", "0.00032751", "0", "1"], ["84215.3", "0.09825623", "0", "2"], ["84215.4", "0.11879524", "0", "2"], ["84215.8", "0.00001501", "0", "1"], ["84216", "0.00001565", "0", "1"], ["84216.6", "0.00060645", "0", "1"], ["84216.9", "0.08991011", "0", "1"], ["84217.8", "0.00600038", "0", "1"], ["84217.9", "0.00419368", "0", "1"], ["84218", "0.00016867", "0", "1"], ["84218.1", "0.07103359", "0", "2"], ["84218.7", "0.08228864", "0", "1"], ["84219", "0.001964", "0", "1"], ["84219.3", "0.00007814", "0", "1"], ["84219.4", "0.00001503", "0", "1"], ["84219.7", "0.01798586", "0", "2"], ["84220", "0.18842744", "0", "1"], ["84220.1", "0.05700028", "0", "1"], ["84220.7", "0.07125036", "0", "1"], ["84221.3", "0.00037549", "0", "1"], ["84222.2", "0.2025", "0", "1"], ["84222.3", "0.35641581", "0", "1"], ["84223.5", "0.06399704", "0", "1"], ["84223.8", "0.17846554", "0", "2"], ["84224.1", "0.00298666", "0", "1"], ["84224.2", "0.00043002", "0", "3"], ["84224.3", "0.0004", "0", "1"], ["84224.4", "0.00001197", "0", "1"], ["84225", "0.00017601", "0", "1"], ["84225.5", "0.03", "0", "1"], ["84225.9", "0.00419367", "0", "1"], ["84226.5", "0.00002974", "0", "1"], ["84226.6", "0.00001653", "0", "1"], ["84227.8", "0.00001197", "0", "1"], ["84228.4", "0.00010514", "0", "1"], ["84228.5", "0.00002372", "0", "1"], ["84228.9", "0.00008", "0", "1"], ["84229.8", "0.35129716", "0", "1"], ["84229.9", "0.6", "0", "1"], ["84230", "0.00023762", "0", "1"], ["84230.1", "0.000548", "0", "2"], ["84230.7", "0.2025", "0", "1"], ["84230.9", "0.35582144", "0", "2"], ["84231.1", "0.36630664", "0", "2"], ["84232", "0.6505", "0", "3"], ["84232.3", "0.29700048", "0", "2"], ["84232.6", "0.00598833", "0", "2"], ["84232.9", "0.08747", "0", "1"], ["84233", "0.06012728", "0", "2"], ["84233.3", "0.18417134", "0", "3"], ["84233.5", "0.00002296", "0", "1"], ["84233.8", "0.00003542", "0", "1"], ["84233.9", "0.00419323", "0", "1"], ["84234", "0.00036", "0", "1"], ["84234.4", "0.00001197", "0", "1"], ["84235", "0.00025", "0", "1"], ["84235.2", "0.28745545", "0", "2"], ["84236", "0.00036", "0", "1"], ["84236.6", "0.00593", "0", "1"], ["84236.8", "0.00001738", "0", "1"], ["84237", "0.00036", "0", "1"], ["84237.2", "0.00001115", "0", "1"], ["84237.8", "0.00007018", "0", "2"], ["84238.1", "0.00006534", "0", "2"], ["84238.5", "0.71313968", "0", "1"], ["84239.2", "0.2025", "0", "1"], ["84239.3", "0.00012358", "0", "2"], ["84239.7", "0.1792492", "0", "2"], ["84239.8", "0.35579296", "0", "1"], ["84240", "0.00039685", "0", "3"], ["84240.1", "0.00001005", "0", "1"], ["84240.2", "0.00001197", "0", "1"], ["84240.9", "0.05349948", "0", "1"], ["84241", "0.008975", "0", "2"], ["84242", "0.0000185", "0", "1"], ["84242.1", "0.00594502", "0", "1"], ["84242.4", "0.00469113", "0", "3"], ["84242.5", "0.00011938", "0", "1"], ["84242.6", "0.00419183", "0", "1"], ["84244.1", "0.00083", "0", "1"], ["84244.2", "0.03", "0", "1"], ["84244.3", "0.00605088", "0", "2"], ["84244.5", "0.04676886", "0", "1"], ["84244.6", "0.5999", "0", "1"], ["84245.2", "0.00003034", "0", "1"], ["84245.5", "0.00009384", "0", "1"], ["84245.8", "0.00040029", "0", "4"], ["84246.3", "0.00083", "0", "1"], ["84246.4", "1.89972", "0", "1"], ["84246.5", "0.00239792", "0", "2"], ["84247.2", "0.00153761", "0", "2"], ["84247.3", "0.08991011", "0", "1"], ["84247.5", "0.00001525", "0", "1"], ["84247.7", "0.2025", "0", "1"], ["84247.8", "0.00075298", "0", "4"], ["84248.3", "0.04188156", "0", "2"], ["84248.4", "0.03", "0", "1"], ["84248.6", "0.03", "0", "1"], ["84248.8", "0.00009125", "0", "1"], ["84249.1", "0.29700048", "0", "2"], ["84249.2", "0.35579296", "0", "1"], ["84249.3", "0.0001897", "0", "5"], ["84249.4", "0.01196165", "0", "2"], ["84249.7", "0.213985", "0", "1"], ["84249.9", "0.00064653", "0", "3"], ["84250", "0.00922541", "0", "31"], ["84251.6", "0.22237151", "0", "2"], ["84252.1", "0.00002281", "0", "1"], ["84252.5", "0.00002342", "0", "2"], ["84252.6", "0.00332577", "0", "1"], ["84252.7", "0.00001362", "0", "1"], ["84252.8", "0.01511839", "0", "1"], ["84253.2", "0.03", "0", "1"], ["84253.3", "0.00001026", "0", "1"], ["84253.5", "0.00004188", "0", "4"], ["84253.7", "0.0000821", "0", "1"], ["84253.9", "0.00001787", "0", "1"], ["84254.3", "0.00001034", "0", "1"], ["84254.5", "0.00001063", "0", "1"], ["84255", "0.00001181", "0", "1"], ["84256.2", "0.2025", "0", "1"], ["84257.6", "0.00008291", "0", "1"], ["84258.1", "0.00003542", "0", "1"], ["84258.2", "0.37072628", "0", "2"], ["84258.3", "0.00002584", "0", "1"], ["84258.9", "0.00001016", "0", "1"], ["84259", "0.01794667", "0", "4"], ["84259.2", "0.00001197", "0", "1"], ["84259.7", "0.00419094", "0", "1"], ["84259.9", "0.00018194", "0", "1"], ["84260", "0.00033268", "0", "4"], ["84260.2", "0.00168601", "0", "1"], ["84260.6", "0.0000142", "0", "1"], ["84260.8", "0.00001852", "0", "1"], ["84261.1", "0.01299784", "0", "1"], ["84262.2", "0.00003778", "0", "1"], ["84262.4", "0.0000221", "0", "1"], ["84262.9", "0.17821722", "0", "1"]], "bids": [["84104", "0.16543626", "0", "5"], ["84103.2", "0.00056579", "0", "1"], ["84102.2", "0.01", "0", "2"], ["84102", "0.0146", "0", "1"], ["84101.9", "0.00111523", "0", "2"], ["84100.8", "0.11896199", "0", "1"], ["84100.4", "0.00001197", "0", "1"], ["84100", "0.01461", "0", "2"], ["84099.9", "0.00833497", "0", "2"], ["84099.7", "0.0446026", "0", "1"], ["84098.3", "0.06257236", "0", "2"], ["84098.2", "0.17821722", "0", "1"], ["84098", "0.02369063", "0", "2"], ["84096.6", "0.20651803", "0", "1"], ["84096.5", "0.35641581", "0", "1"], ["84096.2", "0.133725", "0", "1"], ["84096", "0.0252911", "0", "1"], ["84095.4", "0.00001197", "0", "1"], ["84094.7", "0.102", "0", "2"], ["84094.5", "0.11228184", "0", "2"], ["84094.4", "0.01596287", "0", "1"], ["84093.7", "0.02339", "0", "2"], ["84093.4", "0.03989517", "0", "1"], ["84093.1", "0.0292169", "0", "1"], ["84093", "0.00420386", "0", "1"], ["84092.9", "0.000015", "0", "1"], ["84092.3", "0.59838334", "0", "2"], ["84092.1", "0.01", "0", "2"], ["84092", "0.01189786", "0", "1"], ["84091.7", "1", "0", "1"], ["84091.6", "0.00348506", "0", "1"], ["84091.5", "0.04", "0", "1"], ["84090.6", "0.01339", "0", "1"], ["84090.5", "0.00001197", "0", "1"], ["84090", "0.25446287", "0", "3"], ["84089.2", "0.06388784", "0", "2"], ["84089", "0.3567", "0", "1"], ["84088.9", "0.0021525", "0", "1"], ["84088.8", "0.17835", "0", "1"], ["84088.7", "0.17821722", "0", "1"], ["84088.6", "0.03251763", "0", "1"], ["84088.1", "0.26104908", "0", "1"], ["84088", "0.35641581", "0", "1"], ["84087.9", "0.03502692", "0", "1"], ["84087.2", "0.18", "0", "4"], ["84087.1", "0.04", "0", "1"], ["84086.3", "0.02379239", "0", "1"], ["84085.7", "0.01596287", "0", "1"], ["84085.5", "0.00001197", "0", "1"], ["84084.7", "0.00420528", "0", "1"], ["84084.5", "0.000015", "0", "1"], ["84084.3", "0.04019", "0", "1"], ["84084.2", "0.06226151", "0", "1"], ["84084", "0.11228184", "0", "2"], ["84083.9", "0.01596287", "0", "1"], ["84083.3", "0.00060645", "0", "1"], ["84083.1", "0.01596287", "0", "1"], ["84082.3", "0.00011161", "0", "1"], ["84082.2", "0.03295073", "0", "1"], ["84082", "0.26777189", "0", "1"], ["84081.9", "0.1871364", "0", "1"], ["84081.6", "0.03539115", "0", "1"], ["84081.5", "0.00713593", "0", "1"], ["84080.8", "0.11899027", "0", "1"], ["84080.5", "0.51989197", "0", "2"], ["84080.4", "0.03095883", "0", "1"], ["84080", "0.00001", "0", "1"], ["84079.8", "0.56678461", "0", "2"], ["84079.7", "0.6297023", "0", "2"], ["84078.4", "0.35641581", "0", "1"], ["84078.2", "0.23018009", "0", "3"], ["84077.7", "0.17835", "0", "1"], ["84076.9", "0.00004578", "0", "1"], ["84076.7", "0.0054", "0", "1"], ["84076.6", "0.00420551", "0", "1"], ["84076.1", "0.000015", "0", "1"], ["84076", "0.25446287", "0", "3"], ["84075.8", "0.1189973", "0", "1"], ["84075.6", "0.00001197", "0", "1"], ["84075.2", "0.06680501", "0", "1"], ["84074.7", "0.01672", "0", "1"], ["84073.9", "0.01779863", "0", "2"], ["84073.8", "0.56703152", "0", "1"], ["84073.7", "1.57800049", "0", "1"], ["84073.5", "0.11228184", "0", "2"], ["84073.4", "0.05940838", "0", "1"], ["84073.2", "0.06368222", "0", "2"], ["84073", "0.00001", "0", "1"], ["84072.1", "0.20889886", "0", "2"], ["84071.7", "0.06677115", "0", "1"], ["84071", "1.0067", "0", "3"], ["84070.7", "0.0238009", "0", "1"], ["84070.6", "0.00001197", "0", "1"], ["84070", "0.0025", "0", "1"], ["84069.9", "0.35641581", "0", "1"], ["84069.5", "0.00357", "0", "1"], ["84068.8", "0.001783", "0", "1"], ["84068.1", "0.23791399", "0", "1"], ["84068", "0.08", "0", "2"], ["84067.7", "0.00001501", "0", "1"], ["84067.5", "0.23258722", "0", "2"], ["84067.4", "0.2025", "0", "1"], ["84067.3", "0.00420625", "0", "1"], ["84067.2", "0.04", "0", "1"], ["84066.7", "0.470928", "0", "1"], ["84066.6", "0.00504382", "0", "4"], ["84066.4", "0.026", "0", "2"], ["84066.1", "0.12485", "0", "1"], ["84066", "0.20908", "0", "1"], ["84065.7", "0.00001197", "0", "1"], ["84065.6", "0.013", "0", "1"], ["84065.2", "0.2497", "0", "1"], ["84064.9", "0.0054", "0", "1"], ["84064.7", "0.0214248", "0", "1"], ["84064", "0.1", "0", "2"], ["84063.2", "0.05", "0", "1"], ["84063.1", "0.11890903", "0", "1"], ["84063", "0.11228184", "0", "2"], ["84062.6", "0.00011161", "0", "1"], ["84061.5", "0.4", "0", "1"], ["84061.4", "0.35641581", "0", "1"], ["84061.2", "0.00005328", "0", "1"], ["84060.7", "0.00001197", "0", "1"], ["84060.6", "0.00099847", "0", "1"], ["84060.5", "0.55568714", "0", "1"], ["84060.2", "0.02204823", "0", "2"], ["84060.1", "0.12485", "0", "1"], ["84060", "0.21624782", "0", "3"], ["84059.8", "0.00768566", "0", "1"], ["84059.3", "0.000015", "0", "1"], ["84058.5", "0.17821722", "0", "1"], ["84058.3", "0.08157614", "0", "1"], ["84058", "0.0103941", "0", "1"], ["84057.5", "0.00007494", "0", "1"], ["84055.7", "0.00001197", "0", "1"], ["84055.6", "0.00576666", "0", "1"], ["84055.5", "0.00039387", "0", "1"], ["84054.8", "1.12065", "0", "2"], ["84054.6", "0.00100367", "0", "1"], ["84054.3", "0.02745264", "0", "1"], ["84054.2", "0.1", "0", "1"], ["84054", "0.03", "0", "1"], ["84053.9", "0.03", "0", "1"], ["84053.7", "0.02817312", "0", "1"], ["84053.3", "0.33760347", "0", "2"], ["84053.2", "0.11890903", "0", "1"], ["84052.9", "0.3568907", "0", "1"], ["84052.7", "0.02380601", "0", "1"], ["84052.3", "0.00420804", "0", "1"], ["84051.4", "0.00576666", "0", "1"], ["84050.9", "0.060015", "0", "3"], ["84050.8", "0.00001197", "0", "1"], ["84050.5", "0.61797733", "0", "3"], ["84050.4", "0.01785561", "0", "1"], ["84050.2", "0.12485", "0", "1"], ["84050", "0.00033629", "0", "3"], ["84049.9", "0.00060645", "0", "1"], ["84049.8", "0.0118827", "0", "1"], ["84049.5", "0.24969", "0", "1"], ["84048.7", "0.17821722", "0", "1"], ["84047.3", "0.29695266", "0", "1"], ["84047.2", "0.98397", "0", "1"], ["84046.6", "0.00009543", "0", "1"], ["84046", "0.03", "0", "1"], ["84045.8", "0.20672021", "0", "3"], ["84045.6", "1.90288565", "0", "2"], ["84045.5", "3.24576", "0", "1"], ["84045.1", "0.00005207", "0", "1"], ["84044.9", "0.21816467", "0", "1"], ["84044.3", "0.35579296", "0", "1"], ["84044.2", "2.87759619", "0", "2"], ["84043.3", "0.00357", "0", "1"], ["84043", "0.00011161", "0", "1"], ["84042.5", "0.00001501", "0", "1"], ["84042.4", "0.00001196", "0", "1"], ["84041.7", "0.11805472", "0", "1"], ["84041.6", "0.11890903", "0", "1"], ["84040.7", "0.00285176", "0", "1"], ["84040.6", "0.08925", "0", "1"], ["84039.9", "0.00594406", "0", "1"], ["84039.8", "0.18535669", "0", "2"], ["84039.1", "0.12485", "0", "1"], ["84037.6", "0.00105148", "0", "1"], ["84037.5", "0.05952577", "0", "1"], ["84037.4", "0.19364581", "0", "1"], ["84037.3", "0.2025", "0", "1"], ["84036.4", "0.04755634", "0", "1"], ["84035.9", "0.00001196", "0", "1"], ["84035.8", "0.35579296", "0", "1"], ["84035.6", "0.014", "0", "1"], ["84035.5", "0.0054", "0", "1"], ["84035.1", "0.01", "0", "1"], ["84034.1", "0.00001501", "0", "1"], ["84033.8", "0.00420994", "0", "1"], ["84033.7", "0.01", "0", "1"], ["84033.3", "0.00101534", "0", "2"], ["84032.7", "0.0059445", "0", "1"], ["84032.6", "0.99791256", "0", "2"], ["84032.5", "3.56733903", "0", "2"], ["84031.9", "0.059977", "0", "1"], ["84031.5", "0.00103791", "0", "1"], ["84031.4", "0.00012658", "0", "1"], ["84031", "0.00235616", "0", "1"], ["84030.9", "0.00001196", "0", "1"], ["84030.8", "0.0059445", "0", "1"], ["84030.1", "0.08991011", "0", "1"], ["84030", "0.00001196", "0", "1"], ["84029.5", "0.17821722", "0", "1"], ["84028.9", "0.18496456", "0", "1"], ["84028.8", "0.2025", "0", "1"], ["84027.7", "0.00007596", "0", "1"], ["84027.5", "0.03", "0", "1"], ["84027.3", "0.35579296", "0", "1"], ["84026.9", "0.29002871", "0", "1"], ["84026.8", "0.02377866", "0", "1"], ["84026.6", "0.00017505", "0", "1"], ["84026.1", "0.00421091", "0", "1"], ["84025.7", "0.000015", "0", "1"], ["84025", "0.00596215", "0", "2"], ["84024.7", "0.0000313", "0", "1"], ["84024.1", "0.51527662", "0", "1"], ["84024", "1.377731", "0", "1"], ["84023.3", "0.00011161", "0", "1"], ["84022.8", "0.00594488", "0", "1"], ["84022.6", "0.00002208", "0", "1"], ["84022", "0.1428196", "0", "2"], ["84021.7", "0.01901761", "0", "1"], ["84021.6", "0.01189308", "0", "1"], ["84021.5", "0.11890903", "0", "1"], ["84021.1", "0.00594568", "0", "1"], ["84021", "0.17822918", "0", "2"], ["84020.4", "0.22228051", "0", "2"], ["84020.3", "0.2025", "0", "1"], ["84019.8", "0.07963915", "0", "1"], ["84018.9", "0.00594568", "0", "1"], ["84018.7", "0.35579296", "0", "1"], ["84017.7", "0.00001196", "0", "1"], ["84017.5", "0.1", "0", "1"], ["84017.3", "0.00001501", "0", "1"], ["84016.9", "0.00421155", "0", "1"], ["84016.6", "0.00060645", "0", "1"], ["84016.5", "0.03", "0", "1"], ["84014.6", "0.00298666", "0", "1"], ["84014.1", "0.00016271", "0", "1"], ["84014", "0.21694", "0", "1"], ["84013.2", "0.06", "0", "2"], ["84012.9", "0.00594571", "0", "1"], ["84012.7", "0.11890903", "0", "1"], ["84012.2", "0.17821722", "0", "1"], ["84011.8", "0.2238", "0", "2"], ["84011.7", "0.0639", "0", "3"], ["84011.2", "0.00579986", "0", "1"], ["84011.1", "0.02141196", "0", "2"], ["84011", "0.1", "0", "1"], ["84010.8", "0.00007195", "0", "1"], ["84010.7", "0.00005963", "0", "1"], ["84010.2", "0.35579296", "0", "1"], ["84010", "0.00014389", "0", "1"], ["84009.1", "0.00579986", "0", "1"], ["84009", "0.03", "0", "1"], ["84008.9", "0.000015", "0", "1"], ["84008.8", "0.00421282", "0", "1"], ["84008.5", "0.59432247", "0", "1"], ["84008.4", "0.00001501", "0", "1"], ["84008.3", "0.03572487", "0", "2"], ["84008.1", "0.0007196", "0", "1"], ["84007.5", "0.01484", "0", "1"], ["84006.4", "0.00600043", "0", "1"], ["84006.3", "0.00579998", "0", "1"], ["84006.2", "0.00598528", "0", "2"], ["84005.3", "0.00001196", "0", "1"], ["84004.1", "0.00579987", "0", "1"], ["84004", "0.00579986", "0", "1"], ["84003.9", "0.00609969", "0", "1"], ["84003.8", "0.69509", "0", "3"], ["84003.7", "0.26823894", "0", "3"], ["84003.4", "0.00609981", "0", "1"], ["84003.3", "0.2025", "0", "1"], ["84003.2", "0.00579971", "0", "1"], ["84003.1", "0.089997", "0", "1"], ["84002.7", "0.02377811", "0", "1"], ["84002.6", "0.00579986", "0", "1"], ["84002.5", "0.01149496", "0", "1"], ["84001.5", "0.36179339", "0", "2"], ["84001.1", "0.00008", "0", "1"], ["84000.5", "0.00601505", "0", "2"], ["84000.4", "0.00421334", "0", "1"], ["84000", "20.55840459", "0", "33"], ["83999.9", "0.06217207", "0", "9"], ["83999.4", "0.08239598", "0", "1"], ["83998.9", "0.00599985", "0", "1"], ["83998.8", "0.0117995", "0", "2"], ["83998.7", "0.1", "0", "1"], ["83998.1", "0.01188266", "0", "1"], ["83997.7", "0.00895999", "0", "1"], ["83997.2", "0.00609981", "0", "1"], ["83997.1", "0.00609981", "0", "1"], ["83997", "0.00579988", "0", "1"], ["83996.3", "0.00001196", "0", "1"], ["83996.1", "0.00579986", "0", "1"], ["83996", "0.00579971", "0", "1"], ["83995.9", "0.00579994", "0", "1"], ["83995.6", "0.00595", "0", "1"], ["83995.5", "0.01188314", "0", "1"], ["83995.4", "1.48377", "0", "1"], ["83995", "0.0061", "0", "1"], ["83994.9", "0.00579994", "0", "1"], ["83994.8", "0.2025", "0", "1"], ["83994.7", "0.01180024", "0", "2"], ["83994.6", "0.07102314", "0", "1"], ["83994.5", "0.0059997", "0", "1"], ["83994.3", "0.17821722", "0", "1"], ["83993.9", "0.00421443", "0", "1"], ["83993.7", "0.07125036", "0", "1"], ["83992.7", "0.00579961", "0", "1"], ["83992.5", "0.35579296", "0", "1"], ["83992.4", "0.40201959", "0", "2"], ["83992.1", "0.00001501", "0", "1"], ["83991.8", "0.0058", "0", "1"], ["83991.7", "0.00256065", "0", "1"], ["83991.5", "0.11878326", "0", "1"], ["83991.4", "0.01159951", "0", "2"], ["83991.3", "0.00001196", "0", "1"], ["83991.1", "0.0166188", "0", "1"], ["83990.3", "0.00009235", "0", "1"], ["83989.9", "0.00579971", "0", "1"], ["83989.3", "0.01194665", "0", "1"], ["83988.3", "0.0000469", "0", "1"], ["83988", "0.00005334", "0", "1"], ["83987.8", "0.00007308", "0", "1"], ["83987.7", "0.00023813", "0", "1"], ["83987.2", "0.002378", "0", "1"], ["83986.6", "0.11912367", "0", "1"], ["83986.5", "0.0142", "0", "1"], ["83986.4", "0.0142", "0", "1"], ["83986.3", "0.20251197", "0", "2"], ["83986.1", "0.2094027", "0", "1"], ["83985.9", "0.0568", "0", "4"], ["83985.8", "0.00003265", "0", "1"], ["83985.7", "0.00001677", "0", "1"], ["83985", "0.00001785", "0", "1"], ["83984.1", "0.00011161", "0", "1"], ["83983.7", "0.00001501", "0", "1"], ["83983.6", "0.17821722", "0", "1"], ["83983.5", "0.35579296", "0", "1"], ["83983.4", "0.00004752", "0", "1"], ["83983.3", "0.00482138", "0", "2"], ["83981.9", "0.00599422", "0", "2"], ["83981.5", "0.00005685", "0", "1"], ["83981.4", "0.00001197", "0", "1"], ["83980.9", "0.01493332", "0", "1"], ["83980.7", "0.183154", "0", "1"], ["83980.6", "0.00001196", "0", "1"], ["83980.4", "0.03", "0", "1"], ["83980", "0.00005457", "0", "1"], ["83979.7", "0.11878326", "0", "1"], ["83979.5", "0.00004344", "0", "1"], ["83979", "0.0035896", "0", "1"], ["83978.3", "0.18319683", "0", "1"], ["83978.2", "0.00421569", "0", "1"], ["83977.8", "0.2025", "0", "1"], ["83977.2", "0.00005459", "0", "1"], ["83976.5", "0.03", "0", "1"], ["83975.5", "0.00005458", "0", "1"], ["83975.3", "0.01188219", "0", "1"], ["83975.1", "0.17821722", "0", "1"], ["83975", "0.35581966", "0", "2"], ["83974.6", "0.00003456", "0", "1"], ["83974.3", "0.00003395", "0", "1"], ["83973.8", "0.01188156", "0", "1"], ["83973.2", "0.00201345", "0", "1"], ["83973.1", "1.69295", "0", "1"], ["83972.9", "0.0118822", "0", "1"], ["83972.1", "0.00001", "0", "1"], ["83971.5", "0.00001197", "0", "1"], ["83971.4", "0.00068806", "0", "1"], ["83971.1", "0.08991011", "0", "1"], ["83970.9", "0.00002851", "0", "1"], ["83970.7", "0.11878326", "0", "1"], ["83970.5", "0.01188222", "0", "1"], ["83969.9", "0.014", "0", "1"], ["83969.3", "0.2025", "0", "1"], ["83969", "0.0536206", "0", "2"], ["83968.6", "0.214033", "0", "1"], ["83968.3", "0.00001197", "0", "1"], ["83967.7", "0.00004003", "0", "1"], ["83967.4", "0.00013882", "0", "1"], ["83967.2", "0.00001508", "0", "1"], ["83967", "0.08933", "0", "1"], ["83966.8", "0.0042171", "0", "1"], ["83966.7", "0.17821722", "0", "1"], ["83966.6", "0.3604018", "0", "4"], ["83966.3", "0.00001501", "0", "1"], ["83966.1", "0.03", "0", "1"], ["83965.1", "0.01783506", "0", "3"], ["83964.4", "0.00011161", "0", "1"], ["83962.9", "0.00350324", "0", "1"], ["83962.4", "0.00083", "0", "1"], ["83962.3", "1.32078776", "0", "2"], ["83961.6", "0.00001197", "0", "1"]], "ts": "1742555025004", "checksum": -2063912086, "seqId": 49927410088, "prevSeqId": -1}], "record_time": 1742555025.00872, "EXCHANGE": "OKX"}
{"arg": {"channel": "books", "instId": "BTC-USDT"}, "action": "update", "data": [{"asks": [["84122.1", "0.65970529", "0", "2"], ["84125.2", "1", "0", "1"], ["84126.4", "0", "0", "0"], ["84126.5", "0", "0", "0"], ["84162.2", "0.01188288", "0", "1"], ["84189.7", "3.29988276", "0", "2"], ["84263.9", "0.00003969", "0", "2"]], "bids": [["84091.7", "0", "0", "0"], ["84089.4", "1", "0", "1"], ["84071", "0.0067", "0", "2"]], "ts": "1742555025104", "checksum": -2063912086, "seqId": 49927410111, "prevSeqId": 49927410088}], "record_time": 1742555025.105594, "EXCHANGE": "OKX"}
{"arg": {"channel": "books", "instId": "BTC-USDT"}, "action": "update", "data": [{"asks": [["84140", "1.00006696", "0", "4"]], "bids": [], "ts": "1742555025204", "checksum": -2063912086, "seqId": 49927410145, "prevSeqId": 49927410111}], "record_time": 1742555025.216586, "EXCHANGE": "OKX"}
{"arg": {"channel": "books", "instId": "BTC-USDT"}, "action": "update", "data": [{"asks": [], "bids": [["84090.7", "1", "0", "1"], ["84089.4", "0", "0", "0"]], "ts": "1742555025304", "checksum": -2063912086, "seqId": 49927410155, "prevSeqId": 49927410145}], "record_time": 1742555025.304624, "EXCHANGE": "OKX"}
{"arg": {"channel": "books", "instId": "BTC-USDT"}, "action": "update", "data": [{"asks": [["84116.5", "0.0328932", "0", "1"], ["84117.2", "0.03287571", "0", "1"], ["84117.3", "0.06531996", "0", "2"], ["84123.5", "0.03319347", "0", "1"], ["84123.6", "0.15437416", "0", "5"], ["84125.9", "0.11228184", "0", "2"], ["84130.5", "0.26776191", "0", "2"], ["84131.2", "0", "0", "0"], ["84132.7", "0.06238899", "0", "1"], ["84133", "0.06170969", "0", "1"], ["84134.7", "0.06987851", "0", "1"], ["84142", "0.2", "0", "1"], ["84160.6", "0", "0", "0"], ["84162.2", "0.02376576", "0", "2"], ["84189.7", "3.288", "0", "1"], ["84264", "0.00074396", "0", "1"]], "bids": [["84104", "0.17256626", "0", "6"], ["84100.8", "0", "0", "0"], ["84100.5", "0.11896238", "0", "1"], ["84090.7", "0", "0", "0"], ["84090.1", "1", "0", "1"], ["84089.2", "0.06686543", "0", "2"], ["84088.6", "0.03085476", "0", "1"], ["84087.9", "0.03331218", "0", "1"], ["84082.2", "0.0336488", "0", "1"], ["84081.6", "0.03232776", "0", "1"], ["84080.4", "0", "0", "0"], ["84075.2", "0.0644053", "0", "1"], ["84073.7", "0", "0", "0"], ["84073.2", "0.06732753", "0", "2"], ["84072.1", "0.20735776", "0", "2"], ["84071.7", "0.06389794", "0", "1"], ["83961.5", "0.00083", "0", "1"], ["83961", "0.01782134", "0", "1"]], "ts": "1742555025404", "checksum": -1183187458, "seqId": 49927410224, "prevSeqId": 49927410155}], "record_time": 1742555025.429355, "EXCHANGE": "OKX"}
{"arg": {"channel": "books", "instId": "BTC-USDT"}, "action": "update", "data": [{"asks": [["84112.4", "0.005", "0", "1"], ["84123.4", "0.00001501", "0", "1"], ["84125.1", "0.23792615", "0", "2"], ["84126", "0.08152498", "0", "3"], ["84130.2", "0.47626222", "0", "1"], ["84131.3", "1.58927824", "0", "1"], ["84160.5", "0.08991011", "0", "1"], ["84160.8", "2.90069883", "0", "2"], ["84264", "0", "0", "0"]], "bids": [["84080.5", "0.55360794", "0", "3"], ["84075.8", "1.71328611", "0", "2"], ["84073.9", "0.00005327", "0", "1"], ["84073.8", "0", "0", "0"], ["84070", "0.24041417", "0", "2"], ["84068.1", "0", "0", "0"], ["84054.9", "0.01774536", "0", "1"], ["84046.3", "2.9135527", "0", "1"], ["84045.6", "0.8594935", "0", "1"], ["84044.2", "0.01804", "0", "1"]], "ts": "1742555025504", "checksum": 2068369937, "seqId": 49927410262, "prevSeqId": 49927410224}], "record_time": 1742555025.504775, "EXCHANGE": "OKX"}
{"arg": {"channel": "books", "instId": "BTC-USDT"}, "action": "update", "data": [{"asks": [["84123.4", "0.23792925", "0", "2"], ["84125.1", "0.00001197", "0", "1"], ["84142", "0", "0", "0"], ["84240.2", "0.01189467", "0", "2"], ["84248.3", "0.03", "0", "1"], ["84264", "0.00074396", "0", "1"]], "bids": [["84099.8", "0.2", "0", "1"], ["84091.6", "1.00348506", "0", "2"], ["84090.1", "0", "0", "0"], ["84070", "0.0025", "0", "1"], ["84068.1", "0.23791424", "0", "1"], ["83961", "0", "0", "0"]], "ts": "1742555025604", "checksum": 962949493, "seqId": 49927410278, "prevSeqId": 49927410262}], "record_time": 1742555025.623, "EXCHANGE": "OKX"}
{"arg": {"channel": "books", "instId": "BTC-USDT"}, "action": "update", "data": [{"asks": [], "bids": [["84063", "0.21228184", "0", "3"]], "ts": "1742555025704", "checksum": 962949493, "seqId": 49927410293, "prevSeqId": 49927410278}], "record_time": 1742555025.704788, "EXCHANGE": "OKX"}
{"arg": {"channel": "books", "instId": "BTC-USDT"}, "action": "update", "data": [{"asks": [["84123.4", "0.00001501", "0", "1"], ["84125.1", "0.23792602", "0", "2"], ["84130.2", "0.87777135", "0", "2"], ["84140", "0.00006696", "0", "3"], ["84160.7", "1.25594025", "0", "1"], ["84162.2", "0.01188288", "0", "1"], ["84189.7", "3.29988276", "0", "2"], ["84264", "0", "0", "0"]], "bids": [["84091.6", "0.00348506", "0", "1"], ["84089.5", "1", "0", "1"], ["84076.1", "0.01776036", "0", "2"], ["84068", "0", "0", "0"], ["84067.2", "0.08", "0", "2"], ["84066.4", "0.066", "0", "3"], ["84063", "0.11228184", "0", "2"], ["84061.6", "0.50520401", "0", "1"], ["84054.9", "0", "0", "0"], ["84011.9", "0.42160362", "0", "1"], ["83961.5", "0", "0", "0"]], "ts": "1742555025804", "checksum": 962949493, "seqId": 49927410316, "prevSeqId": 49927410293}], "record_time": 1742555025.80519, "EXCHANGE": "OKX"}
{"arg": {"channel": "books", "instId": "BTC-USDT"}, "action": "update", "data": [{"asks": [], "bids": [["84104", "0.19041126", "0", "8"], ["84071", "0", "0", "0"], ["83961.5", "0.00083", "0", "1"]], "ts": "1742555025904", "checksum": -1903065853, "seqId": 49927410333, "prevSeqId": 49927410316}], "record_time": 1742555025.955596, "EXCHANGE": "OKX"}
{"arg": {"channel": "books", "instId": "BTC-USDT"}, "action": "update", "data": [{"asks": [["84116.5", "0", "0", "0"], ["84116.6", "0.03483584", "0", "1"], ["84117.2", "0", "0", "0"], ["84117.3", "0.03262579", "0", "1"], ["84117.4", "0.06445005", "0", "2"], ["84123.5", "0.2379142", "0", "1"], ["84123.6", "0.15308025", "0", "5"], ["84123.7", "0.07542677", "0", "2"], ["84125.1", "0.00001197", "0", "1"], ["84126", "0.0146", "0", "1"], ["84126.1", "0.03402061", "0", "1"], ["84126.2", "0.03510134", "0", "1"], ["84130.5", "0.2025", "0", "1"], ["84130.6", "0.06652253", "0", "1"], ["84132.7", "0", "0", "0"], ["84132.8", "0.06685662", "0", "1"], ["84133", "0", "0", "0"], ["84133.1", "0.0666972", "0", "1"], ["84134.7", "0", "0", "0"], ["84134.8", "0.06331757", "0", "1"], ["84162.2", "0.02376576", "0", "2"], ["84189.7", "3.288", "0", "1"], ["84204", "0", "0", "0"], ["84206.9", "0", "0", "0"], ["84263.9", "0", "0", "0"]], "bids": [["84094.7", "0.048", "0", "1"], ["84091.4", "1", "0", "1"], ["84089.5", "0", "0", "0"], ["84089.3", "0.06456613", "0", "2"], ["84089.2", "0", "0", "0"], ["84088.7", "0.21337793", "0", "2"], ["84088.6", "0", "0", "0"], ["84088", "0.38765715", "0", "2"], ["84087.9", "0", "0", "0"], ["84082.3", "0.03520204", "0", "2"], ["84082.2", "0", "0", "0"], ["84081.7", "0.03355124", "0", "1"], ["84081.6", "0", "0", "0"], ["84080.6", "0.032897", "0", "1"], ["84080.5", "0.51989197", "0", "2"], ["84080", "0.03323866", "0", "2"], ["84079.8", "0.53333599", "0", "1"], ["84075.3", "0.06593688", "0", "1"], ["84075.2", "0", "0", "0"], ["84073.3", "0.06355606", "0", "1"], ["84073.2", "0.00005206", "0", "1"], ["84072.2", "0.06342432", "0", "1"], ["84072.1", "0.1403523", "0", "1"], ["84072", "0.0025", "0", "1"], ["84071.8", "0.06640593", "0", "1"], ["84071.7", "0", "0", "0"], ["84068.1", "0", "0", "0"], ["84067.6", "0.2379142", "0", "1"], ["84067.2", "0.106", "0", "4"], ["84066.4", "0.053", "0", "2"], ["84065.6", "0", "0", "0"], ["84031", "0", "0", "0"], ["84021.7", "0", "0", "0"], ["83979", "0", "0", "0"], ["83961", "0.01782134", "0", "1"], ["83960.9", "0.00083", "0", "1"], ["83960.8", "0.2025", "0", "1"]], "ts": "1742555026004", "checksum": -197213789, "seqId": 49927410410, "prevSeqId": 49927410333}], "record_time": 1742555026.006626, "EXCHANGE": "OKX"}
{"arg": {"channel": "books", "instId": "BTC-USDT"}, "action": "update", "data": [{"asks": [["84104.1", "0.63616838", "0", "21"], ["84108.5", "0.2025", "0", "1"], ["84108.7", "0.01055", "0", "1"], ["84108.9", "0", "0", "0"], ["84110.4", "0", "0", "0"], ["84115", "0.031675", "0", "2"], ["84116.6", "0", "0", "0"], ["84117.3", "0", "0", "0"], ["84117.4", "0", "0", "0"], ["84123.6", "0.12", "0", "4"], ["84123.7", "0.04", "0", "1"], ["84126.1", "0", "0", "0"], ["84126.2", "0", "0", "0"], ["84130.6", "0", "0", "0"], ["84132.8", "0", "0", "0"], ["84133.1", "0", "0", "0"], ["84134.8", "0", "0", "0"], ["84151.6", "0", "0", "0"], ["84263.9", "0.00003969", "0", "2"], ["84264", "0.00074396", "0", "1"], ["84264.9", "0.00031778", "0", "3"], ["84265.1", "0.00418989", "0", "1"], ["84265.8", "0.00001156", "0", "1"], ["84266", "0.11878326", "0", "1"], ["84266.4", "0.00001402", "0", "1"], ["84266.5", "0.00054835", "0", "1"], ["84266.6", "0.01217191", "0", "13"], ["84266.7", "0.00002129", "0", "1"], ["84266.9", "0.00013853", "0", "2"]], "bids": [["84104", "0.40790868", "0", "9"], ["84100.5", "0", "0", "0"], ["84098.5", "0.11896515", "0", "1"], ["84092.8", "0.01339", "0", "1"], ["84090.6", "0", "0", "0"], ["84090.5", "0.05401197", "0", "2"], ["84089.3", "0", "0", "0"], ["84089", "0.39688", "0", "2"], ["84088.7", "0.17821722", "0", "1"], ["84088", "0.35641581", "0", "1"], ["84084.3", "0", "0", "0"], ["84082.3", "0.00011161", "0", "1"], ["84081.7", "0", "0", "0"], ["84080.6", "0", "0", "0"], ["84080", "0.00001", "0", "1"], ["84075.3", "0", "0", "0"], ["84073.3", "0", "0", "0"], ["84072.2", "0", "0", "0"], ["84071.8", "0", "0", "0"], ["84070", "1.0025", "0", "2"], ["84050.6", "0.01831942", "0", "1"], ["84050.5", "0.59965765", "0", "2"], ["83978.3", "0.18319426", "0", "1"], ["83960.8", "0", "0", "0"], ["83960", "0.0241926", "0", "4"], ["83959.9", "0.00001022", "0", "1"], ["83959.8", "0.00421771", "0", "1"], ["83959.1", "0.00001009", "0", "1"], ["83958.8", "0.00005335", "0", "1"], ["83958.3", "0.00006061", "0", "1"], ["83956.6", "0.00001197", "0", "1"], ["83955.9", "0.00001197", "0", "1"]], "ts": "1742555026104", "checksum": -1098977015, "seqId": 49927410474, "prevSeqId": 49927410410}], "record_time": 1742555026.1465, "EXCHANGE": "OKX"}
{"arg": {"channel": "books", "instId": "BTC-USDT"}, "action": "update", "data": [{"asks": [["84109.9", "0.02352943", "0", "1"], ["84110.3", "0", "0", "0"], ["84117.3", "0.03220623", "0", "1"], ["84117.7", "0.06652345", "0", "2"], ["84117.9", "0.10568325", "0", "2"], ["84123.5", "0.23791553", "0", "1"], ["84124.2", "0.03136387", "0", "1"], ["84124.3", "0.03326056", "0", "1"], ["84126.4", "0.03139435", "0", "1"], ["84126.5", "0.03143095", "0", "1"], ["84131.3", "1.65586958", "0", "2"], ["84133.1", "0.06267513", "0", "1"], ["84133.7", "0.06478385", "0", "1"], ["84135.2", "0.06274976", "0", "1"], ["84147.3", "0.05925269", "0", "1"], ["84162.2", "0.01188288", "0", "1"], ["84189.7", "3.29988276", "0", "2"], ["84193.6", "0.03225274", "0", "2"], ["84196.5", "0.00118769", "0", "1"], ["84263.9", "0", "0", "0"], ["84264", "0", "0", "0"], ["84264.9", "0", "0", "0"], ["84265.1", "0", "0", "0"], ["84265.8", "0", "0", "0"], ["84266", "0", "0", "0"], ["84266.4", "0", "0", "0"], ["84266.5", "0", "0", "0"], ["84266.6", "0", "0", "0"], ["84266.7", "0", "0", "0"], ["84266.9", "0", "0", "0"]], "bids": [["84094.7", "0", "0", "0"], ["84091.4", "0", "0", "0"], ["84090", "0.28519045", "0", "4"], ["84089.7", "0.0336014", "0", "1"], ["84089.6", "1", "0", "1"], ["84089", "0.43014183", "0", "3"], ["84088.5", "0.03452989", "0", "1"], ["84083", "0.03456077", "0", "1"], ["84082.2", "0.03139034", "0", "1"], ["84080.9", "0.03095466", "0", "1"], ["84080.3", "0.03080024", "0", "1"], ["84076", "0.32353516", "0", "4"], ["84073.6", "0.06790899", "0", "1"], ["84072.8", "0.06228046", "0", "1"], ["84072.2", "0.06201089", "0", "1"], ["84068.1", "0.23791529", "0", "1"], ["84068", "0.08", "0", "2"], ["84067.6", "0", "0", "0"], ["84067.2", "0.066", "0", "3"], ["84066.4", "0.013", "0", "1"], ["84028", "0.00235628", "0", "1"], ["84018.8", "0.01901854", "0", "1"], ["83975.9", "0.00358974", "0", "1"], ["83961.6", "0", "0", "0"], ["83961.5", "0", "0", "0"], ["83961", "0", "0", "0"], ["83960.9", "0", "0", "0"], ["83960", "0", "0", "0"], ["83959.9", "0", "0", "0"], ["83959.8", "0", "0", "0"], ["83959.1", "0", "0", "0"], ["83958.8", "0", "0", "0"], ["83958.3", "0", "0", "0"], ["83956.6", "0", "0", "0"], ["83955.9", "0", "0", "0"]], "ts": "1742555026204", "checksum": -289916883, "seqId": 49927410533, "prevSeqId": 49927410474}], "record_time": 1742555026.204281, "EXCHANGE": "OKX"}
{"arg": {"channel": "books", "instId": "BTC-USDT"}, "action": "update", "data": [{"asks": [["84162.2", "0.02376576", "0", "2"], ["84189.7", "3.288", "0", "1"]], "bids": [["84099.9", "0.17857765", "0", "3"], ["84098.3", "0.002", "0", "1"], ["84095.4", "0.01340197", "0", "2"], ["84092.8", "0", "0", "0"], ["84090.5", "0.10201197", "0", "3"], ["83961.6", "0.00001197", "0", "1"]], "ts": "1742555026304", "checksum": -467153006, "seqId": 49927410541, "prevSeqId": 49927410533}], "record_time": 1742555026.304111, "EXCHANGE": "OKX"}
{"arg": {"channel": "books", "instId": "BTC-USDT"}, "action": "update", "data": [{"asks": [["84162.2", "0.01188288", "0", "1"], ["84189.7", "3.29988276", "0", "2"]], "bids": [["84084.2", "0", "0", "0"], ["83961.5", "0.00083", "0", "1"]], "ts": "1742555026404", "checksum": -467153006, "seqId": 49927410548, "prevSeqId": 49927410541}], "record_time": 1742555026.477222, "EXCHANGE": "OKX"}
{"arg": {"channel": "books", "instId": "BTC-USDT"}, "action": "update", "data": [{"asks": [], "bids": [["84079.9", "0.06188799", "0", "1"], ["84068.1", "0", "0", "0"], ["84068", "0", "0", "0"], ["84067.6", "0.23791508", "0", "1"], ["84067.2", "0.106", "0", "4"], ["84066.4", "0.053", "0", "2"], ["83999", "0.00599985", "0", "1"], ["83961.5", "0", "0", "0"]], "ts": "1742555026504", "checksum": -467153006, "seqId": 49927410576, "prevSeqId": 49927410548}], "record_time": 1742555026.536672, "EXCHANGE": "OKX"}
{"arg": {"channel": "books", "instId": "BTC-USDT"}, "action": "update", "data": [{"asks": [["84162.2", "0.02376576", "0", "2"], ["84189.7", "3.288", "0", "1"]], "bids": [["84068", "0.08", "0", "2"], ["84067.2", "0.066", "0", "3"], ["84066.4", "0.013", "0", "1"], ["83973.8", "0", "0", "0"], ["83965.7", "0.0118827", "0", "1"], ["83961.6", "0", "0", "0"]], "ts": "1742555026604", "checksum": -467153006, "seqId": 49927410590, "prevSeqId": 49927410576}], "record_time": 1742555026.66975, "EXCHANGE": "OKX"}
{"arg": {"channel": "books", "instId": "BTC-USDT"}, "action": "update", "data": [{"asks": [["84104.8", "0.003567", "0", "1"], ["84123.5", "0", "0", "0"], ["84124.1", "0.23791392", "0", "1"], ["84187.1", "0.07126989", "0", "1"], ["84262.9", "0", "0", "0"]], "bids": [["84101.9", "0.00211885", "0", "3"], ["84101.2", "0.11896131", "0", "1"], ["84098.5", "0", "0", "0"], ["84068", "0", "0", "0"], ["84067.2", "0.106", "0", "4"], ["84066.4", "0.053", "0", "2"], ["84064", "0", "0", "0"], ["84063.2", "0.1", "0", "2"], ["84062.4", "0.05", "0", "1"], ["84022", "0.0714098", "0", "1"], ["83961.6", "0.00001197", "0", "1"]], "ts": "1742555026704", "checksum": -167497995, "seqId": 49927410618, "prevSeqId": 49927410590}], "record_time": 1742555026.707443, "EXCHANGE": "OKX"}
{"arg": {"channel": "books", "instId": "BTC-USDT"}, "action": "update", "data": [{"asks": [["84104.1", "0.63973538", "0", "22"], ["84104.8", "0", "0", "0"], ["84122.1", "0.33792366", "0", "1"], ["84124.1", "0.2379133", "0", "1"], ["84125.2", "0", "0", "0"], ["84126.6", "1", "0", "1"], ["84138.8", "0.47264556", "0", "2"], ["84162.2", "0.01188288", "0", "1"], ["84171.5", "0.05346517", "0", "1"], ["84187.1", "0.14253978", "0", "2"], ["84189.7", "3.29988276", "0", "2"]], "bids": [["84091.3", "1", "0", "1"], ["84089.6", "0", "0", "0"], ["84070", "0.0025", "0", "1"], ["84068.1", "0.2379133", "0", "1"], ["84068", "0.08", "0", "2"], ["84067.6", "0", "0", "0"], ["84067.2", "0.066", "0", "3"], ["84066.4", "0.013", "0", "1"], ["84064", "0.1", "0", "2"], ["84063.2", "0.05", "0", "1"], ["84063", "0.21228184", "0", "3"], ["84062.4", "0", "0", "0"], ["84022", "0.1428196", "0", "2"], ["84014.1", "0.12070113", "0", "2"], ["83961.6", "0", "0", "0"]], "ts": "1742555026804", "checksum": -2103696846, "seqId": 49927410662, "prevSeqId": 49927410618}], "record_time": 1742555026.804231, "EXCHANGE": "OKX"}
{"arg": {"channel": "books", "instId": "BTC-USDT"}, "action": "update", "data": [{"asks": [["84123.5", "0.23791384", "0", "1"], ["84124.1", "0", "0", "0"], ["84138.8", "0.21812487", "0", "1"]], "bids": [["84101.2", "0", "0", "0"], ["84092.5", "1", "0", "1"], ["84091.3", "0", "0", "0"], ["84068.1", "0.23791384", "0", "1"], ["84068", "0", "0", "0"], ["84067.2", "0.106", "0", "4"], ["84066.4", "0.053", "0", "2"], ["84064", "0", "0", "0"], ["84063.2", "0.1", "0", "2"], ["84063", "0.11228184", "0", "2"], ["84062.4", "0.05", "0", "1"], ["83961.6", "0.00001197", "0", "1"], ["83961.5", "0.00083", "0", "1"]], "ts": "1742555026904", "checksum": -1566680655, "seqId": 49927410698, "prevSeqId": 49927410662}], "record_time": 1742555026.904525, "EXCHANGE": "OKX"}
{"arg": {"channel": "books", "instId": "BTC-USDT"}, "action": "update", "data": [{"asks": [["84122.1", "0.63992179", "0", "2"], ["84124.9", "1", "0", "1"], ["84126.6", "0", "0", "0"]], "bids": [["84092.5", "0", "0", "0"], ["84092.3", "0.64773491", "0", "2"], ["84090.5", "1.10201197", "0", "4"], ["83961", "0.01782134", "0", "1"]], "ts": "1742555027004", "checksum": -1566680655, "seqId": 49927410721, "prevSeqId": 49927410698}], "record_time": 1742555027.007706, "EXCHANGE": "OKX"}
{"arg": {"channel": "books", "instId": "BTC-USDT"}, "action": "update", "data": [{"asks": [["84162.2", "0.02376576", "0", "2"], ["84189.7", "3.288", "0", "1"]], "bids": [["84068", "0.08", "0", "2"], ["84067.2", "0.066", "0", "3"], ["84066.4", "0.013", "0", "1"], ["84064", "0.1", "0", "2"], ["84063.2", "0.05", "0", "1"], ["84062.4", "0", "0", "0"], ["83961", "0", "0", "0"]], "ts": "1742555027104", "checksum": -1566680655, "seqId": 49927410741, "prevSeqId": 49927410721}], "record_time": 1742555027.108992, "EXCHANGE": "OKX"}
{"arg": {"channel": "books", "instId": "BTC-USDT"}, "action": "update", "data": [{"asks": [["84162.2", "0.01188288", "0", "1"], ["84187.1", "0.07126989", "0", "1"], ["84189.7", "3.29988276", "0", "2"]], "bids": [["84022", "0.0714098", "0", "1"]], "ts": "1742555027204", "checksum": -1566680655, "seqId": 49927410753, "prevSeqId": 49927410741}], "record_time": 1742555027.206671, "EXCHANGE": "OKX"}
{"arg": {"channel": "books", "instId": "BTC-USDT"}, "action": "update", "data": [{"asks": [["84130.7", "0.00107928", "0", "1"], ["84131.7", "0", "0", "0"], ["84162.2", "0.02376576", "0", "2"], ["84187.1", "0", "0", "0"], ["84189.7", "3.288", "0", "1"], ["84262.9", "0.17821722", "0", "1"]], "bids": [["84022", "0", "0", "0"], ["83961", "0.01782134", "0", "1"]], "ts": "1742555027304", "checksum": -1566680655, "seqId": 49927410769, "prevSeqId": 49927410753}], "record_time": 1742555027.307585, "EXCHANGE": "OKX"}
{"arg": {"channel": "books", "instId": "BTC-USDT"}, "action": "update", "data": [{"asks": [["84104.9", "0.05081894", "0", "1"], ["84108.5", "0", "0", "0"], ["84115.9", "0", "0", "0"], ["84116.1", "0.000837", "0", "1"], ["84162.2", "0.01188288", "0", "1"], ["84187.1", "0.07126989", "0", "1"], ["84189.7", "3.29988276", "0", "2"]], "bids": [["84102.3", "0.11895986", "0", "1"], ["84022", "0.0714098", "0", "1"], ["83961.5", "0", "0", "0"], ["83961", "0", "0", "0"]], "ts": "1742555027404", "checksum": -1655056001, "seqId": 49927410799, "prevSeqId": 49927410769}], "record_time": 1742555027.404603, "EXCHANGE": "OKX"}
{"arg": {"channel": "books", "instId": "BTC-USDT"}, "action": "update", "data": [{"asks": [["84104.1", "0.63616838", "0", "21"], ["84130.4", "0.00107928", "0", "1"], ["84130.7", "0", "0", "0"], ["84162.2", "0.02376576", "0", "2"], ["84189.7", "3.288", "0", "1"]], "bids": [], "ts": "1742555027504", "checksum": -947125025, "seqId": 49927410808, "prevSeqId": 49927410799}], "record_time": 1742555027.527536, "EXCHANGE": "OKX"}
{"arg": {"channel": "books", "instId": "BTC-USDT"}, "action": "update", "data": [{"asks": [["84145", "0.20001197", "0", "2"], ["84162.2", "0.01188288", "0", "1"], ["84187.1", "0.14253978", "0", "2"], ["84189.7", "3.29988276", "0", "2"]], "bids": [["84102.3", "0", "0", "0"], ["84022", "0.1428196", "0", "2"], ["83961.5", "0.00083", "0", "1"]], "ts": "1742555027604", "checksum": 1069323270, "seqId": 49927410826, "prevSeqId": 49927410808}], "record_time": 1742555027.609857, "EXCHANGE": "OKX"}
{"arg": {"channel": "books", "instId": "BTC-USDT"}, "action": "update", "data": [{"asks": [["84111.6", "0", "0", "0"], ["84116.1", "0", "0", "0"], ["84117.5", "0.20814", "0", "2"], ["84117.9", "0.18610094", "0", "3"], ["84121.6", "0.23791726", "0", "1"], ["84123.5", "0", "0", "0"], ["84145", "0.00001197", "0", "1"], ["84162.2", "0.02376576", "0", "2"], ["84189.7", "3.288", "0", "1"], ["84263.9", "0.00003969", "0", "2"], ["84264", "0.00074396", "0", "1"]], "bids": [["84066.7", "0", "0", "0"], ["84059.6", "0.470946", "0", "1"]], "ts": "1742555027704", "checksum": 651629690, "seqId": 49927410849, "prevSeqId": 49927410826}], "record_time": 1742555027.716255, "EXCHANGE": "OKX"}
{"arg": {"channel": "books", "instId": "BTC-USDT"}, "action": "update", "data": [{"asks": [["84117.9", "0.10568325", "0", "2"], ["84121.6", "0", "0", "0"], ["84122.1", "0.33792366", "0", "1"], ["84123.5", "0.23791269", "0", "1"], ["84124.9", "0", "0", "0"], ["84126.2", "1", "0", "1"], ["84126.3", "0.02579479", "0", "1"], ["84140", "1.00006696", "0", "4"], ["84155.8", "0.15575383", "0", "2"], ["84162.2", "0.01188288", "0", "1"], ["84189.7", "3.29988276", "0", "2"], ["84264", "0", "0", "0"]], "bids": [["84091.9", "1", "0", "1"], ["84090.5", "0.10201197", "0", "3"], ["84079.8", "0.96567732", "0", "2"], ["84076.1", "0.000015", "0", "1"], ["84072", "1.0025", "0", "2"], ["84068.1", "0.23791269", "0", "1"], ["84061.7", "0.01774536", "0", "1"], ["84047.3", "1.13216636", "0", "2"], ["84011.9", "0", "0", "0"], ["83961.5", "0", "0", "0"]], "ts": "1742555027804", "checksum": 651629690, "seqId": 49927410893, "prevSeqId": 49927410849}], "record_time": 1742555027.804667, "EXCHANGE": "OKX"}
{"arg": {"channel": "books", "instId": "BTC-USDT"}, "action": "update", "data": [{"asks": [["84162.2", "0.02376576", "0", "2"], ["84189.7", "3.288", "0", "1"]], "bids": [["84072", "0.0025", "0", "1"], ["84063", "0.31228184", "0", "3"]], "ts": "1742555027904", "checksum": 651629690, "seqId": 49927410903, "prevSeqId": 49927410893}], "record_time": 1742555027.906813, "EXCHANGE": "OKX"}
{"arg": {"channel": "books", "instId": "BTC-USDT"}, "action": "update", "data": [{"asks": [["84122.8", "0.23791471", "0", "1"], ["84123.5", "0", "0", "0"], ["84140", "0.00006696", "0", "3"]], "bids": [["84091.9", "0", "0", "0"], ["84090", "1.28519045", "0", "5"], ["84076.1", "0.01776036", "0", "2"], ["84068.1", "0", "0", "0"], ["84068", "0", "0", "0"], ["84067.6", "0.23791471", "0", "1"], ["84067.2", "0.106", "0", "4"], ["84066.4", "0.053", "0", "2"], ["84064", "0", "0", "0"], ["84063.2", "0.1", "0", "2"], ["84062.4", "0.05", "0", "1"], ["84061.7", "0", "0", "0"], ["83961.5", "0.00083", "0", "1"], ["83961", "0.01782134", "0", "1"], ["83960.9", "0.00083", "0", "1"]], "ts": "1742555028004", "checksum": 651629690, "seqId": 49927410936, "prevSeqId": 49927410903}], "record_time": 1742555028.051483, "EXCHANGE": "OKX"}
{"arg": {"channel": "books", "instId": "BTC-USDT"}, "action": "update", "data": [{"asks": [["84122.1", "0.63992205", "0", "2"], ["84122.8", "0", "0", "0"], ["84123.5", "0.23791465", "0", "1"], ["84124.9", "1", "0", "1"], ["84126.2", "0", "0", "0"]], "bids": [["84068.1", "0.23791467", "0", "1"], ["84068", "0.08", "0", "2"], ["84067.6", "0", "0", "0"], ["84067.2", "0.066", "0", "3"], ["84066.4", "0.013", "0", "1"], ["84064", "0.1", "0", "2"], ["84063.2", "0.05", "0", "1"], ["84062.4", "0", "0", "0"], ["84014.2", "0.00016264", "0", "1"], ["84014.1", "0.12053842", "0", "1"], ["83961", "0", "0", "0"], ["83960.9", "0", "0", "0"]], "ts": "1742555028104", "checksum": 651629690, "seqId": 49927410961, "prevSeqId": 49927410936}], "record_time": 1742555028.111691, "EXCHANGE": "OKX"}
{"arg": {"channel": "books", "instId": "BTC-USDT"}, "action": "update", "data": [{"asks": [["84130.2", "0.47626222", "0", "1"], ["84131.3", "0.06659134", "0", "1"], ["84160.7", "0", "0", "0"], ["84160.8", "0.00011161", "0", "1"], ["84162.2", "0.01188288", "0", "1"], ["84189.7", "3.29988276", "0", "2"], ["84264", "0.00074396", "0", "1"]], "bids": [["84079.8", "0.53333599", "0", "1"], ["84075.8", "0.1189973", "0", "1"], ["84070", "0.24041474", "0", "2"], ["84068.1", "0", "0", "0"], ["84047.3", "0.29695266", "0", "1"], ["84046.3", "0", "0", "0"], ["84011.9", "0.42160362", "0", "1"], ["83961", "0.01782134", "0", "1"]], "ts": "1742555028304", "checksum": 651629690, "seqId": 49927410987, "prevSeqId": 49927410961}], "record_time": 1742555028.305609, "EXCHANGE": "OKX"}
{"arg": {"channel": "books", "instId": "BTC-USDT"}, "action": "update", "data": [{"asks": [["84130.1", "0.00001197", "0", "1"], ["84131.3", "1.64572963", "0", "2"], ["84160.8", "2.84276911", "0", "2"], ["84162.2", "0.02376576", "0", "2"], ["84187.1", "0.07126989", "0", "1"], ["84189.5", "0.01774536", "0", "1"], ["84189.7", "3.288", "0", "1"], ["84264", "0", "0", "0"]], "bids": [["84076.6", "1.53581352", "0", "2"], ["84076.1", "0.000015", "0", "1"], ["84070", "0.0025", "0", "1"], ["84068.1", "0.23791471", "0", "1"], ["84061.7", "0.01774536", "0", "1"], ["84047.1", "2.73942159", "0", "1"], ["84022", "0.0714098", "0", "1"], ["83961.6", "0", "0", "0"], ["83961.5", "0", "0", "0"], ["83961", "0", "0", "0"]], "ts": "1742555028404", "checksum": 651629690, "seqId": 49927411011, "prevSeqId": 49927410987}], "record_time": 1742555028.405452, "EXCHANGE": "OKX"}
{"arg": {"channel": "books", "instId": "BTC-USDT"}, "action": "update", "data": [{"asks": [["84112.1", "0.00349592", "0", "1"], ["84117.5", "0.2025", "0", "1"], ["84162.2", "0.01188288", "0", "1"], ["84187.1", "0", "0", "0"], ["84189.7", "3.29988276", "0", "2"]], "bids": [["84068.1", "0", "0", "0"], ["84068", "0", "0", "0"], ["84067.6", "0.23791445", "0", "1"], ["84067.2", "0.106", "0", "4"], ["84066.4", "0.053", "0", "2"], ["84064", "0", "0", "0"], ["84063.2", "0.1", "0", "2"], ["84062.4", "0.05", "0", "1"], ["84022", "0", "0", "0"], ["83961.6", "0.00001197", "0", "1"], ["83961.5", "0.00083", "0", "1"]], "ts": "1742555028504", "checksum": -704513409, "seqId": 49927411031, "prevSeqId": 49927411011}], "record_time": 1742555028.576306, "EXCHANGE": "OKX"}
{"arg": {"channel": "books", "instId": "BTC-USDT"}, "action": "update", "data": [{"asks": [["84116.6", "0.00564", "0", "1"], ["84123.5", "0.23791527", "0", "1"], ["84130.1", "0.01775733", "0", "2"], ["84162.2", "0.02376576", "0", "2"], ["84189.5", "0", "0", "0"], ["84189.7", "3.288", "0", "1"], ["84224.1", "0", "0", "0"], ["84232.6", "0.00001501", "0", "1"], ["84241", "0.00001501", "0", "1"], ["84249.4", "0.000015", "0", "1"], ["84258.2", "0.35579296", "0", "1"], ["84264", "0.00074396", "0", "1"]], "bids": [["84091.6", "1.00348506", "0", "2"], ["84090", "0.28519045", "0", "4"], ["84078.5", "0.01774536", "0", "1"], ["84061.7", "0", "0", "0"], ["84014.6", "0", "0", "0"], ["84006.2", "0.00001196", "0", "1"], ["83997.7", "0", "0", "0"], ["83989.3", "0", "0", "0"], ["83980.9", "0", "0", "0"], ["83961", "0.01782134", "0", "1"], ["83960.9", "0.00083", "0", "1"], ["83960.8", "0.2025", "0", "1"], ["83960", "0.0241926", "0", "4"]], "ts": "1742555028604", "checksum": -704513409, "seqId": 49927411087, "prevSeqId": 49927411031}], "record_time": 1742555028.607028, "EXCHANGE": "OKX"}
{"arg": {"channel": "books", "instId": "BTC-USDT"}, "action": "update", "data": [{"asks": [["84118.5", "0", "0", "0"], ["84120.1", "0.00357897", "0", "2"], ["84130", "0.00107928", "0", "1"], ["84130.4", "0", "0", "0"], ["84142", "0.2", "0", "1"], ["84162.2", "0.01188288", "0", "1"], ["84187.1", "0.14253978", "0", "2"], ["84189.7", "3.29988276", "0", "2"], ["84264", "0", "0", "0"]], "bids": [["84092", "0", "0", "0"], ["84091.6", "0.00348506", "0", "1"], ["84090.1", "1", "0", "1"], ["84068", "0.08", "0", "2"], ["84067.2", "0.066", "0", "3"], ["84066.4", "0.013", "0", "1"], ["84064", "0.1", "0", "2"], ["84063.2", "0.05", "0", "1"], ["84063", "0.11228184", "0", "2"], ["84062.4", "0", "0", "0"], ["84022", "0.1428196", "0", "2"], ["83960.8", "0", "0", "0"], ["83960", "0", "0", "0"]], "ts": "1742555028704", "checksum": -704513409, "seqId": 49927411123, "prevSeqId": 49927411087}], "record_time": 1742555028.768489, "EXCHANGE": "OKX"}
{"arg": {"channel": "books", "instId": "BTC-USDT"}, "action": "update", "data": [{"asks": [], "bids": [["84099.5", "0.11896379", "0", "1"], ["83960.9", "0", "0", "0"]], "ts": "1742555028804", "checksum": 515046701, "seqId": 49927411128, "prevSeqId": 49927411123}], "record_time": 1742555028.805912, "EXCHANGE": "OKX"}
{"arg": {"channel": "books", "instId": "BTC-USDT"}, "action": "update", "data": [{"asks": [["84120.1", "0.00001197", "0", "1"], ["84130.2", "0.8758125", "0", "2"], ["84134.4", "0.18178422", "0", "2"], ["84160.7", "1.23499647", "0", "1"], ["84263.9", "0", "0", "0"]], "bids": [["84099.9", "0.11857724", "0", "3"], ["84099.8", "0", "0", "0"], ["84079.8", "0.94687308", "0", "2"], ["84078.5", "0", "0", "0"], ["84061.7", "0.01774536", "0", "1"], ["84047.3", "1.07992702", "0", "2"], ["84011.9", "0", "0", "0"], ["83960.9", "0.00083", "0", "1"], ["83960.8", "0.2025", "0", "1"]], "ts": "1742555028904", "checksum": -814670826, "seqId": 49927411156, "prevSeqId": 49927411128}], "record_time": 1742555028.904794, "EXCHANGE": "OKX"}
{"arg": {"channel": "books", "instId": "BTC-USDT"}, "action": "update", "data": [{"asks": [["84104.8", "0.003567", "0", "1"], ["84112.1", "0", "0", "0"], ["84116.6", "0", "0", "0"], ["84123.5", "0", "0", "0"], ["84124.1", "0.23791314", "0", "1"], ["84134.4", "0.17821722", "0", "1"], ["84139", "1", "0", "1"]], "bids": [["84104", "0.45870868", "0", "10"], ["84100.1", "0.07893614", "0", "1"], ["84099.9", "0.00833497", "0", "2"], ["84099.5", "0", "0", "0"], ["84091.5", "1.04", "0", "2"], ["84090.1", "0", "0", "0"], ["84090", "0.40416772", "0", "5"], ["84088.9", "0", "0", "0"], ["84075.8", "0", "0", "0"], ["84070", "0.24041314", "0", "2"], ["84067.6", "0", "0", "0"], ["83960", "0.0241926", "0", "4"], ["83959.9", "0.00001022", "0", "1"], ["83959.8", "0.00421771", "0", "1"], ["83959.1", "0.00001009", "0", "1"]], "ts": "1742555029004", "checksum": -1299997171, "seqId": 49927411191, "prevSeqId": 49927411156}], "record_time": 1742555029.004618, "EXCHANGE": "OKX"}
{"arg": {"channel": "books", "instId": "BTC-USDT"}, "action": "update", "data": [{"asks": [["84112.2", "0", "0", "0"], ["84117.7", "0.07098295", "0", "3"], ["84122.2", "0", "0", "0"], ["84162.2", "0.02376576", "0", "2"], ["84189.7", "3.288", "0", "1"], ["84263.9", "0.00003969", "0", "2"], ["84264", "0.00074396", "0", "1"]], "bids": [["84098.3", "0", "0", "0"], ["84092.3", "0.65337491", "0", "3"], ["84091.5", "0.04", "0", "1"], ["84090.1", "1", "0", "1"]], "ts": "1742555029104", "checksum": 943119084, "seqId": 49927411207, "prevSeqId": 49927411191}], "record_time": 1742555029.111891, "EXCHANGE": "OKX"}
{"arg": {"channel": "books", "instId": "BTC-USDT"}, "action": "update", "data": [{"asks": [["84104.8", "0", "0", "0"], ["84124.1", "0.23791353", "0", "1"], ["84136.2", "0.003567", "0", "1"], ["84139", "0", "0", "0"], ["84142", "0", "0", "0"], ["84162.2", "0.01188288", "0", "1"], ["84189.7", "3.29988276", "0", "2"], ["84264.7", "0.2025", "0", "1"], ["84264.9", "0.00031778", "0", "3"]], "bids": [["84070", "0.0025", "0", "1"], ["84068.1", "0.23791372", "0", "1"], ["83959.1", "0", "0", "0"]], "ts": "1742555029204", "checksum": 57201624, "seqId": 49927411231, "prevSeqId": 49927411207}], "record_time": 1742555029.205265, "EXCHANGE": "OKX"}
{"arg": {"channel": "books", "instId": "BTC-USDT"}, "action": "update", "data": [{"asks": [["84108.7", "0", "0", "0"], ["84111", "0.01055", "0", "1"], ["84115.6", "0", "0", "0"], ["84117.7", "0.06652345", "0", "2"], ["84122.1", "0.33792366", "0", "1"], ["84124.1", "0", "0", "0"], ["84124.9", "0", "0", "0"], ["84125.6", "0.23791133", "0", "1"], ["84126.2", "1", "0", "1"], ["84265.1", "0.00418989", "0", "1"]], "bids": [["84104", "0.68159346", "0", "17"], ["84097.6", "0.01339", "0", "1"], ["84095.4", "0.00001197", "0", "1"], ["84092.3", "0.64773491", "0", "2"], ["84091.3", "1", "0", "1"], ["84090.1", "0", "0", "0"], ["84070", "0.24041154", "0", "2"], ["84068.1", "0", "0", "0"]], "ts": "1742555029304", "checksum": -549502250, "seqId": 49927411266, "prevSeqId": 49927411231}], "record_time": 1742555029.305673, "EXCHANGE": "OKX"}
{"arg": {"channel": "books", "instId": "BTC-USDT"}, "action": "update", "data": [{"asks": [["84112.6", "0.002", "0", "1"], ["84117.1", "0.00348949", "0", "1"], ["84121.9", "0.00564", "0", "1"], ["84122.6", "0.002", "0", "1"], ["84123.5", "0.23791357", "0", "1"], ["84125.6", "0", "0", "0"], ["84264", "0", "0", "0"], ["84264.7", "0", "0", "0"], ["84264.9", "0", "0", "0"], ["84265.1", "0", "0", "0"]], "bids": [["84104", "0.47909346", "0", "16"], ["84102.1", "0.002", "0", "1"], ["84096.6", "0.49679725", "0", "2"], ["84092.8", "1", "0", "1"], ["84092.3", "0.36110837", "0", "1"], ["84092", "0.002", "0", "1"], ["84091.3", "0", "0", "0"], ["84070", "0.24041261", "0", "2"], ["83959.9", "0", "0", "0"], ["83959.8", "0", "0", "0"]], "ts": "1742555029404", "checksum": -1852750175, "seqId": 49927411304, "prevSeqId": 49927411266}], "record_time": 1742555029.405821, "EXCHANGE": "OKX"}
{"arg": {"channel": "books", "instId": "BTC-USDT"}, "action": "update", "data": [{"asks": [["84104.1", "0.54267612", "0", "18"], ["84121.9", "0", "0", "0"], ["84136.2", "0", "0", "0"], ["84162.2", "0.02376576", "0", "2"], ["84189.7", "3.288", "0", "1"], ["84264", "0.00074396", "0", "1"], ["84264.9", "0.00031778", "0", "3"]], "bids": [["84104", "0.68159346", "0", "17"], ["84093.1", "0.0311519", "0", "2"]], "ts": "1742555029504", "checksum": -160147473, "seqId": 49927411322, "prevSeqId": 49927411304}], "record_time": 1742555029.505878, "EXCHANGE": "OKX"}
{"arg": {"channel": "books", "instId": "BTC-USDT"}, "action": "update", "data": [{"asks": [["84119.4", "0.00564", "0", "1"], ["84212.8", "0.00298666", "0", "1"], ["84221.2", "0.00597332", "0", "1"], ["84231", "0.00895999", "0", "1"], ["84240.7", "0.01194665", "0", "1"], ["84249.1", "0.3119338", "0", "3"], ["84262.4", "0", "0", "0"], ["84262.9", "0", "0", "0"], ["84263.9", "0", "0", "0"], ["84264", "0", "0", "0"], ["84264.9", "0", "0", "0"]], "bids": [["84104", "0.47909346", "0", "16"], ["84098.4", "0.01189644", "0", "1"], ["84096.6", "0.20651803", "0", "1"], ["84092.8", "0", "0", "0"], ["84092.3", "0.67981298", "0", "2"], ["84091.4", "1", "0", "1"], ["84070", "0.0025", "0", "1"], ["84068.1", "0.23791326", "0", "1"], ["84001.6", "0.00298666", "0", "1"], ["83993.2", "0.00597332", "0", "1"], ["83984.8", "0.00895999", "0", "1"], ["83976.4", "0.01194665", "0", "1"], ["83968", "0.01493332", "0", "1"], ["83962.3", "0", "0", "0"], ["83961.6", "0", "0", "0"], ["83961.5", "0", "0", "0"], ["83961", "0", "0", "0"], ["83960.9", "0", "0", "0"], ["83960.8", "0", "0", "0"], ["83960", "0", "0", "0"]], "ts": "1742555029604", "checksum": 866949134, "seqId": 49927411350, "prevSeqId": 49927411322}], "record_time": 1742555029.631467, "EXCHANGE": "OKX"}
{"arg": {"channel": "books", "instId": "BTC-USDT"}, "action": "update", "data": [{"asks": [["84119.4", "0", "0", "0"], ["84123.5", "0.23791354", "0", "1"], ["84262.4", "0.0000221", "0", "1"]], "bids": [["84100.7", "0.12411482", "0", "1"], ["84100.6", "0.11896225", "0", "1"], ["84100.1", "0", "0", "0"], ["84068.1", "0.23791354", "0", "1"], ["84060", "0.41624782", "0", "4"], ["83962.4", "0", "0", "0"]], "ts": "1742555029704", "checksum": -266170167, "seqId": 49927411372, "prevSeqId": 49927411350}], "record_time": 1742555029.706275, "EXCHANGE": "OKX"}
{"arg": {"channel": "books", "instId": "BTC-USDT"}, "action": "update", "data": [{"asks": [["84104.1", "0.74348208", "0", "7"], ["84104.9", "0", "0", "0"], ["84105.4", "0.04327394", "0", "1"], ["84107", "0.01189628", "0", "1"], ["84108", "0.0146", "0", "1"], ["84108.1", "0", "0", "0"], ["84109.2", "0.01654115", "0", "1"], ["84109.9", "0", "0", "0"], ["84110.6", "0", "0", "0"], ["84111", "0", "0", "0"], ["84112.2", "0.0252911", "0", "1"], ["84114.1", "0", "0", "0"], ["84114.2", "0.1319054", "0", "1"], ["84114.3", "0", "0", "0"], ["84115", "0.000015", "0", "1"], ["84115.8", "0.16406695", "0", "3"], ["84116.3", "0.01055", "0", "1"], ["84117.1", "0", "0", "0"], ["84117.3", "0.03254666", "0", "1"], ["84117.7", "0.06502326", "0", "2"], ["84117.9", "0.10282183", "0", "2"], ["84120", "0.0227345", "0", "2"], ["84122.6", "0.03365", "0", "2"], ["84123.5", "0", "0", "0"], ["84124.2", "0.03409859", "0", "1"], ["84124.3", "0.03092086", "0", "1"], ["84125.6", "0.23790909", "0", "1"], ["84126.2", "0", "0", "0"], ["84126.3", "0", "0", "0"], ["84126.4", "0.03227794", "0", "1"], ["84126.5", "1.03104525", "0", "2"], ["84131.3", "1.64576527", "0", "2"], ["84133.1", "0.06557101", "0", "1"], ["84133.7", "0.06590718", "0", "1"], ["84135.2", "0.06845892", "0", "1"], ["84140.8", "0.07999999", "0", "2"], ["84146.6", "0", "0", "0"], ["84150", "0.001784", "0", "1"], ["84162.2", "0.01188288", "0", "1"], ["84189.7", "3.29988276", "0", "2"], ["84262.9", "0.17821722", "0", "1"], ["84263.9", "0.00003969", "0", "2"], ["84264", "0.00074396", "0", "1"], ["84264.7", "0.2025", "0", "1"]], "bids": [["84104", "0.76595346", "0", "18"], ["84101.8", "0.03568818", "0", "1"], ["84101.7", "0.11896061", "0", "1"], ["84100.8", "0.15616546", "0", "2"], ["84100.7", "0", "0", "0"], ["84100.6", "0", "0", "0"], ["84099.5", "0.0252911", "0", "1"], ["84098.4", "0", "0", "0"], ["84097.6", "0", "0", "0"], ["84096.6", "0.4963081", "0", "2"], ["84096", "0", "0", "0"], ["84093.1", "0.0292169", "0", "1"], ["84093", "1.00420386", "0", "2"], ["84092.3", "0.36110837", "0", "1"], ["84091.4", "0", "0", "0"], ["84090", "0.40472118", "0", "5"], ["84089.7", "0.03333824", "0", "1"], ["84089", "0.38994307", "0", "2"], ["84088.5", "0.03310281", "0", "1"], ["84083", "0.03502505", "0", "1"], ["84082.2", "0.03458093", "0", "1"], ["84080.9", "0.03231617", "0", "1"], ["84080.3", "0.03338714", "0", "1"], ["84076", "0.32460429", "0", "4"], ["84073.6", "0.06303604", "0", "1"], ["84072.8", "0.06854511", "0", "1"], ["84072.2", "0.06232127", "0", "1"], ["84070.8", "0.23790909", "0", "1"], ["84068.5", "0.02817312", "0", "1"], ["84068.1", "0", "0", "0"], ["84060", "0.21624782", "0", "3"], ["84053.7", "0", "0", "0"], ["83962.4", "0.00083", "0", "1"], ["83962.3", "1.32078776", "0", "2"]], "ts": "1742555029804", "checksum": -941360813, "seqId": 49927411604, "prevSeqId": 49927411372}], "record_time": 1742555029.815963, "EXCHANGE": "OKX"}
{"arg": {"channel": "books", "instId": "BTC-USDT"}, "action": "update", "data": [{"asks": [["84126.4", "0.3488625", "0", "2"], ["84162.2", "0.02376576", "0", "2"], ["84189.7", "3.288", "0", "1"]], "bids": [["84095.8", "0.0000165", "0", "1"], ["84094.5", "1.11228184", "0", "3"], ["84093", "0.00420386", "0", "1"], ["84072.3", "0.11890903", "0", "1"], ["84072", "1.0025", "0", "2"], ["84070.8", "0.53837807", "0", "2"], ["84014.1", "0", "0", "0"], ["84000", "20.46992299", "0", "32"], ["83962.3", "0", "0", "0"]], "ts": "1742555029904", "checksum": 265820264, "seqId": 49927411628, "prevSeqId": 49927411604}], "record_time": 1742555029.904466, "EXCHANGE": "OKX"}
{"arg": {"channel": "books", "instId": "BTC-USDT"}, "action": "update", "data": [{"asks": [["84104.1", "0.72343981", "0", "6"], ["84109.3", "0", "0", "0"], ["84110.7", "0.01055", "0", "1"], ["84114.1", "0.17835", "0", "1"], ["84114.2", "0.22983458", "0", "2"], ["84114.3", "0.3567", "0", "1"], ["84116.3", "0", "0", "0"], ["84117", "0.03166", "0", "1"], ["84117.1", "0.00358116", "0", "1"], ["84120", "0.0146", "0", "1"], ["84122.1", "0.56866615", "0", "2"], ["84122.6", "0.002", "0", "1"], ["84125.2", "1", "0", "1"], ["84125.6", "0", "0", "0"], ["84126.4", "0.03227794", "0", "1"], ["84126.5", "0.03104525", "0", "1"], ["84130.1", "0.25566308", "0", "3"], ["84140", "0.08006696", "0", "5"], ["84140.8", "0.03999999", "0", "1"], ["84141.6", "0", "0", "0"], ["84162.2", "0.01188288", "0", "1"], ["84189.7", "3.29988276", "0", "2"], ["84264", "0", "0", "0"], ["84264.7", "0", "0", "0"]], "bids": [["84104", "0.76345346", "0", "18"], ["84100.8", "0.09289422", "0", "1"], ["84097.3", "0.01339", "0", "1"], ["84096.6", "0.20651803", "0", "1"], ["84094.5", "0.11228184", "0", "2"], ["84092.3", "0.67946632", "0", "2"], ["84092", "1.002", "0", "2"], ["84091", "0.04018", "0", "1"], ["84078.5", "0.01774536", "0", "1"], ["84072.9", "0.23790442", "0", "1"], ["84070.8", "0.30046898", "0", "1"], ["84061.7", "0", "0", "0"], ["83964.4", "0", "0", "0"], ["83962.9", "0", "0", "0"], ["83962.4", "0", "0", "0"]], "ts": "1742555030004", "checksum": 1290330063, "seqId": 49927411676, "prevSeqId": 49927411628}], "record_time": 1742555030.004065, "EXCHANGE": "OKX"}
{"arg": {"channel": "books", "instId": "BTC-USDT"}, "action": "update", "data": [{"asks": [["84119.4", "0.0000105", "0", "1"], ["84162.2", "0.02376576", "0", "2"], ["84189.7", "3.288", "0", "1"], ["84263.9", "0", "0", "0"]], "bids": [["84104", "0.51265346", "0", "16"], ["84103.4", "0.0444729", "0", "1"], ["84103.3", "0.11895835", "0", "1"], ["84101.8", "0", "0", "0"], ["84101.7", "0", "0", "0"], ["84073.5", "0.3501856", "0", "3"], ["84072.9", "0", "0", "0"], ["83964.4", "0.00011161", "0", "1"]], "ts": "1742555030104", "checksum": 1075001947, "seqId": 49927411699, "prevSeqId": 49927411676}], "record_time": 1742555030.149738, "EXCHANGE": "OKX"}
{"arg": {"channel": "books", "instId": "BTC-USDT"}, "action": "update", "data": [{"asks": [["84143", "1", "0", "1"], ["84262.9", "0", "0", "0"]], "bids": [["84104", "0.49481846", "0", "15"]], "ts": "1742555030204", "checksum": -1725926895, "seqId": 49927411708, "prevSeqId": 49927411699}], "record_time": 1742555030.20517, "EXCHANGE": "OKX"}
{"arg": {"channel": "books", "instId": "BTC-USDT"}, "action": "update", "data": [{"asks": [["84143", "0", "0", "0"], ["84162.2", "0.01188288", "0", "1"], ["84189.7", "3.29988276", "0", "2"], ["84262.9", "0.17821722", "0", "1"]], "bids": [["84103.3", "0", "0", "0"], ["84092", "0.002", "0", "1"], ["84090.2", "1", "0", "1"]], "ts": "1742555030304", "checksum": 232004532, "seqId": 49927411718, "prevSeqId": 49927411708}], "record_time": 1742555030.33996, "EXCHANGE": "OKX"}
{"arg": {"channel": "books", "instId": "BTC-USDT"}, "action": "update", "data": [{"asks": [["84162.2", "0.02376576", "0", "2"], ["84189.7", "3.288", "0", "1"]], "bids": [["84103.4", "0", "0", "0"], ["84073.5", "0.11228184", "0", "2"], ["84072.4", "0.23790566", "0", "1"], ["84072", "0.0025", "0", "1"]], "ts": "1742555030404", "checksum": 2018934990, "seqId": 49927411743, "prevSeqId": 49927411718}], "record_time": 1742555030.404246, "EXCHANGE": "OKX"}
{"arg": {"channel": "books", "instId": "BTC-USDT"}, "action": "update", "data": [{"asks": [], "bids": [["84072.4", "0", "0", "0"], ["84070.9", "0.23790727", "0", "1"]], "ts": "1742555030504", "checksum": 2018934990, "seqId": 49927411752, "prevSeqId": 49927411743}], "record_time": 1742555030.504434, "EXCHANGE": "OKX"}
{"arg": {"channel": "books", "instId": "BTC-USDT"}, "action": "update", "data": [{"asks": [["84125.1", "0.23792095", "0", "2"], ["84130.1", "0.01775733", "0", "2"], ["84162.2", "0.01188288", "0", "1"], ["84187.1", "0.07126989", "0", "1"], ["84189.7", "3.29988276", "0", "2"]], "bids": [["84104", "0.51265246", "0", "16"], ["84101", "0.06", "0", "1"], ["84100.9", "0.2", "0", "1"], ["84090.2", "0", "0", "0"], ["84088.9", "1", "0", "1"], ["84070.9", "0", "0", "0"], ["84070", "0.24041063", "0", "2"], ["84022", "0.0714098", "0", "1"], ["83964.4", "0", "0", "0"]], "ts": "1742555030604", "checksum": 195137955, "seqId": 49927411786, "prevSeqId": 49927411752}], "record_time": 1742555030.675547, "EXCHANGE": "OKX"}
{"arg": {"channel": "books", "instId": "BTC-USDT"}, "action": "update", "data": [{"asks": [["84124.1", "0.2379126", "0", "1"], ["84125.1", "0.00001197", "0", "1"], ["84187.1", "0.14253978", "0", "2"], ["84262.9", "0", "0", "0"]], "bids": [["84090.2", "1", "0", "1"], ["84088.9", "0", "0", "0"], ["84070", "0.0025", "0", "1"], ["84068.6", "0.2379126", "0", "1"], ["84022", "0.1428196", "0", "2"], ["83965.1", "0", "0", "0"]], "ts": "1742555030704", "checksum": 195137955, "seqId": 49927411823, "prevSeqId": 49927411786}], "record_time": 1742555030.705984, "EXCHANGE": "OKX"}
{"arg": {"channel": "books", "instId": "BTC-USDT"}, "action": "update", "data": [{"asks": [["84162.2", "0.02376576", "0", "2"], ["84189.7", "3.288", "0", "1"]], "bids": [], "ts": "1742555030804", "checksum": 195137955, "seqId": 49927411838, "prevSeqId": 49927411823}], "record_time": 1742555030.865287, "EXCHANGE": "OKX"}
{"arg": {"channel": "books", "instId": "BTC-USDT"}, "action": "update", "data": [{"asks": [["84122", "0.25339943", "0", "3"], ["84124.1", "0", "0", "0"], ["84126.3", "0.02626794", "0", "1"]], "bids": [["84100.9", "0", "0", "0"], ["84090.2", "0", "0", "0"], ["84088.9", "1", "0", "1"], ["84066.1", "0.38489229", "0", "2"], ["84020.4", "0.01723503", "0", "1"], ["83965.1", "0.01783506", "0", "3"]], "ts": "1742555030904", "checksum": 1867397031, "seqId": 49927411859, "prevSeqId": 49927411838}], "record_time": 1742555030.904152, "EXCHANGE": "OKX"}
{"arg": {"channel": "books", "instId": "BTC-USDT"}, "action": "update", "data": [{"asks": [], "bids": [["84104", "0.41399246", "0", "11"], ["84101", "0", "0", "0"], ["83964.4", "0.00011161", "0", "1"]], "ts": "1742555031004", "checksum": -848999862, "seqId": 49927411883, "prevSeqId": 49927411859}], "record_time": 1742555031.786739, "EXCHANGE": "OKX"}
{"arg": {"channel": "books", "instId": "BTC-USDT"}, "action": "update", "data": [{"asks": [["84104.1", "0.78947981", "0", "7"], ["84108.3", "0.01055", "0", "1"], ["84110.7", "0", "0", "0"]], "bids": [["84104", "0.37547368", "0", "7"], ["84098.3", "0.11896551", "0", "1"], ["84097.3", "0", "0", "0"], ["84095.8", "0", "0", "0"], ["84094.9", "0.01339", "0", "1"]], "ts": "1742555031104", "checksum": 701190569, "seqId": 49927411905, "prevSeqId": 49927411883}], "record_time": 1742555031.788714, "EXCHANGE": "OKX"}
{"arg": {"channel": "books", "instId": "BTC-USDT"}, "action": "update", "data": [{"asks": [["84117.9", "0.17967469", "0", "3"], ["84121.6", "0.23791811", "0", "1"], ["84122", "0.01548436", "0", "2"], ["84143", "0.2", "0", "1"], ["84162.2", "0.01188288", "0", "1"], ["84189.7", "3.29988276", "0", "2"], ["84262.2", "0", "0", "0"], ["84262.4", "0", "0", "0"]], "bids": [["84100.8", "0", "0", "0"], ["84099.6", "0.10384934", "0", "1"], ["84089.8", "0.0044115", "0", "1"], ["84076.6", "0.00420551", "0", "1"], ["84068.6", "0", "0", "0"], ["84067.6", "0.23791811", "0", "1"], ["84047.1", "0", "0", "0"]], "ts": "1742555031204", "checksum": 1868037572, "seqId": 49927411926, "prevSeqId": 49927411905}], "record_time": 1742555031.790072, "EXCHANGE": "OKX"}
{"arg": {"channel": "books", "instId": "BTC-USDT"}, "action": "update", "data": [{"asks": [["84130.2", "0.47626222", "0", "1"], ["84131.3", "0.06662698", "0", "1"], ["84139", "1", "0", "1"], ["84143", "0", "0", "0"], ["84160.7", "0.38219922", "0", "1"], ["84160.8", "0.00011161", "0", "1"], ["84162.2", "0.02376576", "0", "2"], ["84189.7", "3.288", "0", "1"]], "bids": [["84097.8", "0.01189654", "0", "1"], ["84079.8", "0.53333599", "0", "1"], ["84078.5", "0", "0", "0"], ["84061.7", "0.01774536", "0", "1"], ["84047.3", "0.29695266", "0", "1"], ["84020.4", "0.22798608", "0", "2"], ["83964.4", "0", "0", "0"]], "ts": "1742555031304", "checksum": -1280571281, "seqId": 49927411949, "prevSeqId": 49927411926}], "record_time": 1742555031.791151, "EXCHANGE": "OKX"}
{"arg": {"channel": "books", "instId": "BTC-USDT"}, "action": "update", "data": [{"asks": [["84130.1", "0.00001197", "0", "1"], ["84131.3", "1.63033892", "0", "2"], ["84160.8", "2.7791171", "0", "2"], ["84187.1", "0.07126989", "0", "1"], ["84189.5", "0.01774536", "0", "1"], ["84261.1", "0", "0", "0"]], "bids": [["84075.9", "1.60928977", "0", "1"], ["84070", "1.0025", "0", "2"], ["84067.6", "0", "0", "0"], ["84066.2", "0.23791834", "0", "1"], ["84046.5", "2.8130142", "0", "1"], ["84022", "0.0714098", "0", "1"], ["83965.7", "0", "0", "0"], ["83965.1", "0", "0", "0"]], "ts": "1742555031404", "checksum": -1280571281, "seqId": 49927411969, "prevSeqId": 49927411949}], "record_time": 1742555031.792192, "EXCHANGE": "OKX"}
{"arg": {"channel": "books", "instId": "BTC-USDT"}, "action": "update", "data": [{"asks": [["84139", "0", "0", "0"], ["84162.2", "0.01188288", "0", "1"], ["84189.7", "3.29988276", "0", "2"], ["84261.1", "0.01299784", "0", "1"]], "bids": [["84091.5", "0.04564", "0", "2"], ["84091", "1.04018", "0", "2"], ["84089.8", "0", "0", "0"], ["84088.9", "0", "0", "0"], ["83965.7", "0.0118827", "0", "1"], ["83965.1", "0.01783506", "0", "3"]], "ts": "1742555031504", "checksum": -1280571281, "seqId": 49927411994, "prevSeqId": 49927411969}], "record_time": 1742555031.793188, "EXCHANGE": "OKX"}
{"arg": {"channel": "books", "instId": "BTC-USDT"}, "action": "update", "data": [{"asks": [["84117.9", "0.10282183", "0", "2"], ["84119.4", "0", "0", "0"], ["84121.6", "0", "0", "0"], ["84122.8", "0.23791507", "0", "1"], ["84130.1", "0.01775733", "0", "2"], ["84162.2", "0.02376576", "0", "2"], ["84187.1", "0.14253978", "0", "2"], ["84189.5", "0", "0", "0"], ["84189.7", "3.288", "0", "1"], ["84262.2", "0.00003778", "0", "1"], ["84262.4", "0.0000221", "0", "1"]], "bids": [["84099.9", "0.1534444", "0", "3"], ["84099.8", "0.2", "0", "1"], ["84099.6", "0", "0", "0"], ["84098.3", "0", "0", "0"], ["84076.1", "0.01776036", "0", "2"], ["84068.1", "0.23791507", "0", "1"], ["84066.2", "0", "0", "0"], ["84061.7", "0", "0", "0"], ["84022", "0.1428196", "0", "2"], ["83964.4", "0.00011161", "0", "1"], ["83962.9", "0.00350324", "0", "1"]], "ts": "1742555031604", "checksum": -9668466, "seqId": 49927412025, "prevSeqId": 49927411994}], "record_time": 1742555031.794743, "EXCHANGE": "OKX"}
{"arg": {"channel": "books", "instId": "BTC-USDT"}, "action": "update", "data": [{"asks": [["84117.9", "0.17967209", "0", "3"], ["84121.6", "0.23791822", "0", "1"], ["84122.1", "0.33792366", "0", "1"], ["84122.8", "0", "0", "0"], ["84125.1", "1.00001197", "0", "2"], ["84125.2", "0", "0", "0"], ["84162.2", "0.01188288", "0", "1"], ["84189.7", "3.29988276", "0", "2"], ["84262.9", "0.17821722", "0", "1"]], "bids": [["84092.4", "0.52245697", "0", "1"], ["84092.3", "0", "0", "0"], ["84091", "0.04018", "0", "1"], ["84090.3", "1", "0", "1"], ["84068.1", "0", "0", "0"], ["84066.2", "0.23791995", "0", "1"], ["84060", "0.41624782", "0", "4"], ["83962.9", "0", "0", "0"]], "ts": "1742555031804", "checksum": -9668466, "seqId": 49927412068, "prevSeqId": 49927412025}], "record_time": 1742555031.815985, "EXCHANGE": "OKX"}
{"arg": {"channel": "books", "instId": "BTC-USDT"}, "action": "update", "data": [{"asks": [["84117.6", "0.0027855", "0", "1"], ["84122.1", "0.56866615", "0", "2"], ["84130.2", "0.87240105", "0", "2"], ["84262.9", "0", "0", "0"]], "bids": [["84090.3", "0", "0", "0"], ["84088.9", "1", "0", "1"], ["84079.8", "0.94012277", "0", "2"], ["84060", "0.21624782", "0", "3"], ["84047.3", "1.10200481", "0", "2"], ["84020.4", "0.01723503", "0", "1"]], "ts": "1742555031904", "checksum": -9668466, "seqId": 49927412083, "prevSeqId": 49927412068}], "record_time": 1742555031.914073, "EXCHANGE": "OKX"}
{"arg": {"channel": "books", "instId": "BTC-USDT"}, "action": "update", "data": [{"asks": [["84117.6", "0", "0", "0"], ["84262.9", "0.17821722", "0", "1"]], "bids": [["84067.6", "0.23791679", "0", "1"], ["84066.2", "0", "0", "0"]], "ts": "1742555032004", "checksum": -9668466, "seqId": 49927412098, "prevSeqId": 49927412083}], "record_time": 1742555032.00604, "EXCHANGE": "OKX"}
{"arg": {"channel": "books", "instId": "BTC-USDT"}, "action": "update", "data": [{"asks": [["84117.5", "0.2025315", "0", "2"], ["84117.9", "0.17967119", "0", "3"], ["84121.6", "0.23791694", "0", "1"]], "bids": [["84090.3", "1", "0", "1"], ["84088.9", "0", "0", "0"], ["84067.6", "0.23791694", "0", "1"], ["84014.2", "0", "0", "0"], ["84014.1", "0.00016264", "0", "1"]], "ts": "1742555032104", "checksum": -9668466, "seqId": 49927412139, "prevSeqId": 49927412098}], "record_time": 1742555032.112585, "EXCHANGE": "OKX"}
{"arg": {"channel": "books", "instId": "BTC-USDT"}, "action": "update", "data": [{"asks": [["84117.9", "0.17967095", "0", "3"], ["84121.6", "0.23791615", "0", "1"], ["84145", "0.20001197", "0", "2"], ["84162.2", "0.02376576", "0", "2"], ["84189.7", "3.288", "0", "1"]], "bids": [["84067.6", "0.23791615", "0", "1"]], "ts": "1742555032304", "checksum": -9668466, "seqId": 49927412167, "prevSeqId": 49927412139}], "record_time": 1742555032.307049, "EXCHANGE": "OKX"}
{"arg": {"channel": "books", "instId": "BTC-USDT"}, "action": "update", "data": [{"asks": [["84145", "0.00001197", "0", "1"]], "bids": [["84104", "0.38616868", "0", "6"]], "ts": "1742555032404", "checksum": -56361033, "seqId": 49927412185, "prevSeqId": 49927412167}], "record_time": 1742555032.441868, "EXCHANGE": "OKX"}
{"arg": {"channel": "books", "instId": "BTC-USDT"}, "action": "update", "data": [{"asks": [["84139", "1", "0", "1"], ["84228.7", "0.183148", "0", "1"], ["84233.3", "0.00101534", "0", "2"], ["84262.4", "0", "0", "0"], ["84262.9", "0", "0", "0"]], "bids": [["84073", "0", "0", "0"], ["84070", "0.0025", "0", "1"], ["83962.9", "0.00350324", "0", "1"]], "ts": "1742555032504", "checksum": -56361033, "seqId": 49927412198, "prevSeqId": 49927412185}], "record_time": 1742555032.505924, "EXCHANGE": "OKX"}
{"arg": {"channel": "books", "instId": "BTC-USDT"}, "action": "update", "data": [{"asks": [["84121.6", "0.2379175", "0", "1"], ["84187.1", "0.07126989", "0", "1"]], "bids": [["84067.6", "0.2379175", "0", "1"], ["84022", "0.0714098", "0", "1"]], "ts": "1742555032604", "checksum": -56361033, "seqId": 49927412232, "prevSeqId": 49927412198}], "record_time": 1742555032.606798, "EXCHANGE": "OKX"}
{"arg": {"channel": "books", "instId": "BTC-USDT"}, "action": "update", "data": [{"asks": [["84139", "0", "0", "0"], ["84187.1", "0.14253978", "0", "2"], ["84262.4", "0.0000221", "0", "1"]], "bids": [["84067.6", "0", "0", "0"], ["84066.2", "0.23791936", "0", "1"], ["84022", "0.1428196", "0", "2"]], "ts": "1742555032704", "checksum": -56361033, "seqId": 49927412251, "prevSeqId": 49927412232}], "record_time": 1742555032.778597, "EXCHANGE": "OKX"}
{"arg": {"channel": "books", "instId": "BTC-USDT"}, "action": "update", "data": [{"asks": [["84117.9", "0.17967085", "0", "3"], ["84121.6", "0", "0", "0"], ["84122.1", "0.33792366", "0", "1"], ["84122.8", "0.23791454", "0", "1"], ["84125.1", "0.00001197", "0", "1"], ["84126.4", "1.03227794", "0", "2"]], "bids": [["84100.3", "0.11896261", "0", "1"], ["84090.3", "0", "0", "0"], ["84088.9", "1", "0", "1"], ["84068.6", "0.23791454", "0", "1"], ["84066.2", "0", "0", "0"], ["83962.9", "0", "0", "0"]], "ts": "1742555032804", "checksum": 1711048058, "seqId": 49927412293, "prevSeqId": 49927412251}], "record_time": 1742555032.805267, "EXCHANGE": "OKX"}
{"arg": {"channel": "books", "instId": "BTC-USDT"}, "action": "update", "data": [{"asks": [["84117.9", "0.10282183", "0", "2"]], "bids": [["84104", "0.39219868", "0", "7"], ["84090.6", "1", "0", "1"], ["84088.9", "0", "0", "0"]], "ts": "1742555032904", "checksum": -1086487025, "seqId": 49927412304, "prevSeqId": 49927412293}], "record_time": 1742555032.972674, "EXCHANGE": "OKX"}
{"arg": {"channel": "books", "instId": "BTC-USDT"}, "action": "update", "data": [{"asks": [["84104.1", "0.65016639", "0", "7"], ["84108.3", "0", "0", "0"], ["84110.7", "0.01055", "0", "1"], ["84117.1", "0", "0", "0"], ["84126.3", "0.32298445", "0", "2"], ["84150", "0", "0", "0"], ["84160.7", "1.16812596", "0", "2"], ["84162.2", "0.01188288", "0", "1"], ["84189.7", "3.29988276", "0", "2"], ["84262.9", "0.17821722", "0", "1"], ["84263.9", "0.00003969", "0", "2"]], "bids": [["84104", "0.84234107", "0", "14"], ["84102.3", "0.11895979", "0", "1"], ["84100.3", "0", "0", "0"], ["84097.3", "0.01339", "0", "1"], ["84094.9", "0", "0", "0"], ["84092.1", "1.01", "0", "3"], ["84091.5", "0.04", "0", "1"], ["84090.6", "0", "0", "0"], ["84073.6", "0.23234704", "0", "2"], ["84020.4", "0", "0", "0"], ["83962.9", "0.00350324", "0", "1"], ["83962.4", "0.00083", "0", "1"]], "ts": "1742555033004", "checksum": 545381832, "seqId": 49927412337, "prevSeqId": 49927412304}], "record_time": 1742555033.005566, "EXCHANGE": "OKX"}
{"arg": {"channel": "books", "instId": "BTC-USDT"}, "action": "update", "data": [{"asks": [["84104.1", "0.58412639", "0", "6"], ["84122.8", "0", "0", "0"], ["84124.1", "0.23791157", "0", "1"], ["84146.7", "0.11890903", "0", "1"]], "bids": [["84104", "0.63984107", "0", "13"], ["84093.2", "0.00564", "0", "1"], ["83962.4", "0", "0", "0"]], "ts": "1742555033104", "checksum": -554232919, "seqId": 49927412354, "prevSeqId": 49927412337}], "record_time": 1742555033.105524, "EXCHANGE": "OKX"}
{"arg": {"channel": "books", "instId": "BTC-USDT"}, "action": "update", "data": [{"asks": [["84162.2", "0.02376576", "0", "2"], ["84189.7", "3.288", "0", "1"]], "bids": [["84068", "0", "0", "0"], ["84067.2", "0.106", "0", "4"], ["84066.4", "0.053", "0", "2"], ["83962.4", "0.00083", "0", "1"]], "ts": "1742555033204", "checksum": -554232919, "seqId": 49927412363, "prevSeqId": 49927412354}], "record_time": 1742555033.204589, "EXCHANGE": "OKX"}
{"arg": {"channel": "books", "instId": "BTC-USDT"}, "action": "update", "data": [{"asks": [["84104.1", "0.58234239", "0", "5"], ["84117.1", "0.00355546", "0", "1"], ["84142.3", "0.059899", "0", "1"], ["84146.3", "0.001784", "0", "1"], ["84162.2", "0.01188288", "0", "1"], ["84189.7", "3.29988276", "0", "2"], ["84262.4", "0", "0", "0"], ["84262.9", "0", "0", "0"], ["84263.9", "0", "0", "0"]], "bids": [["84068", "0.08", "0", "2"], ["84067.2", "0.066", "0", "3"], ["84066.4", "0.013", "0", "1"], ["83962.4", "0", "0", "0"]], "ts": "1742555033304", "checksum": -1349224036, "seqId": 49927412382, "prevSeqId": 49927412363}], "record_time": 1742555033.307022, "EXCHANGE": "OKX"}
{"arg": {"channel": "books", "instId": "BTC-USDT"}, "action": "update", "data": [{"asks": [["84143", "0.2", "0", "1"], ["84162.2", "0.02376576", "0", "2"], ["84189.7", "3.288", "0", "1"], ["84262.2", "0", "0", "0"]], "bids": [["84104", "0.84234107", "0", "14"], ["84093.2", "0", "0", "0"], ["83962.4", "0.00083", "0", "1"]], "ts": "1742555033404", "checksum": -915618967, "seqId": 49927412391, "prevSeqId": 49927412382}], "record_time": 1742555033.48576, "EXCHANGE": "OKX"}
{"arg": {"channel": "books", "instId": "BTC-USDT"}, "action": "update", "data": [{"asks": [["84162.2", "0.01188288", "0", "1"], ["84189.7", "3.29988276", "0", "2"]], "bids": [["84072", "1.0025", "0", "2"]], "ts": "1742555033504", "checksum": -915618967, "seqId": 49927412398, "prevSeqId": 49927412391}], "record_time": 1742555033.504269, "EXCHANGE": "OKX"}
{"arg": {"channel": "books", "instId": "BTC-USDT"}, "action": "update", "data": [{"asks": [["84104.1", "0.64597239", "0", "6"], ["84117.9", "0.17967085", "0", "3"], ["84121.6", "0.23791581", "0", "1"], ["84124.1", "0", "0", "0"], ["84143", "0", "0", "0"], ["84262.2", "0.00003778", "0", "1"]], "bids": [["84104", "0.46740607", "0", "8"], ["84102.3", "0", "0", "0"], ["84099.9", "0.0974614", "0", "3"], ["84099.8", "0", "0", "0"], ["84098.6", "0.1189651", "0", "1"], ["84095.8", "0.000024", "0", "1"], ["84092.1", "0.01", "0", "2"], ["84089.7", "1.03333824", "0", "2"], ["84073", "0.00001", "0", "1"], ["84072", "0.0025", "0", "1"], ["84068.6", "0", "0", "0"], ["84067.6", "0.23791581", "0", "1"], ["83962.4", "0", "0", "0"]], "ts": "1742555033604", "checksum": -1366920909, "seqId": 49927412433, "prevSeqId": 49927412398}], "record_time": 1742555033.606272, "EXCHANGE": "OKX"}
{"arg": {"channel": "books", "instId": "BTC-USDT"}, "action": "update", "data": [{"asks": [["84122.1", "0.56866615", "0", "2"], ["84125.2", "1", "0", "1"], ["84126.3", "0.02626794", "0", "1"], ["84126.4", "0.03227794", "0", "1"], ["84162.2", "0.02376576", "0", "2"], ["84189.7", "3.288", "0", "1"], ["84262.2", "0", "0", "0"]], "bids": [["84089.7", "0.03333824", "0", "1"], ["84088.3", "1", "0", "1"], ["84068", "0", "0", "0"], ["84067.2", "0.106", "0", "4"], ["84066.4", "0.053", "0", "2"], ["84064", "0", "0", "0"], ["84063.2", "0.1", "0", "2"], ["84062.4", "0.05", "0", "1"]], "ts": "1742555033704", "checksum": -1366920909, "seqId": 49927412467, "prevSeqId": 49927412433}], "record_time": 1742555033.705815, "EXCHANGE": "OKX"}
{"arg": {"channel": "books", "instId": "BTC-USDT"}, "action": "update", "data": [{"asks": [["84117.9", "0.10282183", "0", "2"], ["84121.6", "0", "0", "0"], ["84122.8", "0.23791458", "0", "1"], ["84162.2", "0.01188288", "0", "1"], ["84189.7", "3.29988276", "0", "2"]], "bids": [["84068.6", "0.23791458", "0", "1"], ["84067.6", "0", "0", "0"], ["84064", "0.1", "0", "2"], ["84063.2", "0.05", "0", "1"], ["84062.4", "0", "0", "0"]], "ts": "1742555033804", "checksum": -1366920909, "seqId": 49927412488, "prevSeqId": 49927412467}], "record_time": 1742555033.82301, "EXCHANGE": "OKX"}
{"arg": {"channel": "books", "instId": "BTC-USDT"}, "action": "update", "data": [{"asks": [["84117.1", "0", "0", "0"], ["84262.2", "0.00003778", "0", "1"]], "bids": [["84104", "0.68050607", "0", "11"], ["84102", "0.05092378", "0", "2"], ["84101.9", "0.12107926", "0", "4"], ["84098.6", "0", "0", "0"], ["84091", "1.04018", "0", "2"], ["84088.3", "0", "0", "0"], ["84068", "0.08", "0", "2"], ["84067.2", "0.066", "0", "3"], ["84066.4", "0.013", "0", "1"], ["84060", "0.41624782", "0", "4"], ["83962.4", "0.00083", "0", "1"]], "ts": "1742555033904", "checksum": -302985330, "seqId": 49927412509, "prevSeqId": 49927412488}], "record_time": 1742555033.907898, "EXCHANGE": "OKX"}
{"arg": {"channel": "books", "instId": "BTC-USDT"}, "action": "update", "data": [{"asks": [["84122.8", "0", "0", "0"], ["84124.1", "0.23791208", "0", "1"], ["84147.4", "0.66077858", "0", "1"], ["84149.2", "0", "0", "0"]], "bids": [["84096.6", "0.48872797", "0", "2"], ["84092.6", "1", "0", "1"], ["84091", "0.04018", "0", "1"], ["84068", "0", "0", "0"], ["84067.2", "0.106", "0", "4"], ["84066.4", "0.053", "0", "2"], ["84064", "0", "0", "0"], ["84063.2", "0.1", "0", "2"], ["84062.4", "0.05", "0", "1"], ["84060", "0.21624782", "0", "3"], ["84058.3", "0.33129155", "0", "2"], ["84024.1", "0", "0", "0"], ["83962.3", "1.32078776", "0", "2"]], "ts": "1742555034004", "checksum": -1407610042, "seqId": 49927412535, "prevSeqId": 49927412509}], "record_time": 1742555034.015325, "EXCHANGE": "OKX"}
{"arg": {"channel": "books", "instId": "BTC-USDT"}, "action": "update", "data": [{"asks": [["84130.2", "0.47626222", "0", "1"], ["84131.3", "0.06662698", "0", "1"], ["84146.3", "0", "0", "0"], ["84147.9", "0.001784", "0", "1"], ["84160.7", "0.38219922", "0", "1"], ["84160.8", "0.00011161", "0", "1"], ["84162.2", "0.02376576", "0", "2"], ["84189.7", "3.288", "0", "1"]], "bids": [["84104", "0.69834107", "0", "12"], ["84101.9", "0.00211885", "0", "3"], ["84099.9", "0.2164246", "0", "4"], ["84079.8", "0.53333599", "0", "1"], ["84075.9", "0", "0", "0"], ["84070", "0.24041207", "0", "2"], ["84068.6", "0", "0", "0"], ["84047.3", "0.29695266", "0", "1"], ["84046.5", "0", "0", "0"], ["84024.1", "0.23819668", "0", "1"], ["83961.6", "0.00001197", "0", "1"], ["83961.5", "0.00083", "0", "1"]], "ts": "1742555034104", "checksum": -1737754411, "seqId": 49927412565, "prevSeqId": 49927412535}], "record_time": 1742555034.106954, "EXCHANGE": "OKX"}
{"arg": {"channel": "books", "instId": "BTC-USDT"}, "action": "update", "data": [{"asks": [["84124.1", "0.23791212", "0", "1"], ["84130.1", "0.00001197", "0", "1"], ["84131.3", "1.67242465", "0", "2"], ["84160.7", "3.3271393", "0", "2"], ["84162.2", "0.01188288", "0", "1"], ["84189.5", "0.01774536", "0", "1"], ["84189.7", "3.29988276", "0", "2"], ["84262.2", "0", "0", "0"]], "bids": [["84104", "0.68050607", "0", "11"], ["84102", "0.0146", "0", "1"], ["84099.9", "0.0974614", "0", "3"], ["84096.6", "0.20651803", "0", "1"], ["84092.6", "0", "0", "0"], ["84091.1", "1", "0", "1"], ["84076.3", "1.5537545", "0", "1"], ["84076.1", "0.000015", "0", "1"], ["84070", "0.0025", "0", "1"], ["84068.7", "0.23791213", "0", "1"], ["84064", "0.1", "0", "2"], ["84063.2", "0.05", "0", "1"], ["84062.4", "0", "0", "0"], ["84061.7", "0.01774536", "0", "1"], ["84046.9", "2.81584508", "0", "1"], ["84014.1", "0", "0", "0"], ["83962.3", "0", "0", "0"], ["83961.6", "0", "0", "0"], ["83961.5", "0", "0", "0"]], "ts": "1742555034204", "checksum": 732720164, "seqId": 49927412639, "prevSeqId": 49927412565}], "record_time": 1742555034.205525, "EXCHANGE": "OKX"}
{"arg": {"channel": "books", "instId": "BTC-USDT"}, "action": "update", "data": [{"asks": [["84112.4", "0", "0", "0"], ["84122.4", "0", "0", "0"], ["84124.1", "0.23791175", "0", "1"], ["84262.2", "0.00003778", "0", "1"], ["84262.4", "0.0000221", "0", "1"]], "bids": [["84102.2", "0.005", "0", "1"], ["84092.1", "0.005", "0", "1"], ["84070", "0.24041175", "0", "2"], ["84068.7", "0", "0", "0"], ["84014.1", "0.00016264", "0", "1"]], "ts": "1742555034304", "checksum": -1661565260, "seqId": 49927412671, "prevSeqId": 49927412639}], "record_time": 1742555034.345187, "EXCHANGE": "OKX"}
{"arg": {"channel": "books", "instId": "BTC-USDT"}, "action": "update", "data": [{"asks": [["84130.1", "0.01775733", "0", "2"], ["84162.2", "0.02376576", "0", "2"], ["84189.5", "0", "0", "0"], ["84189.7", "3.288", "0", "1"], ["84262.9", "0.17821722", "0", "1"]], "bids": [["84078.5", "0.01774536", "0", "1"], ["84061.7", "0", "0", "0"]], "ts": "1742555034404", "checksum": -1661565260, "seqId": 49927412681, "prevSeqId": 49927412671}], "record_time": 1742555034.403901, "EXCHANGE": "OKX"}
{"arg": {"channel": "books", "instId": "BTC-USDT"}, "action": "update", "data": [{"asks": [["84224.3", "0", "0", "0"], ["84263.9", "0.00003969", "0", "2"]], "bids": [], "ts": "1742555034504", "checksum": -1661565260, "seqId": 49927412686, "prevSeqId": 49927412681}], "record_time": 1742555034.536743, "EXCHANGE": "OKX"}
{"arg": {"channel": "books", "instId": "BTC-USDT"}, "action": "update", "data": [{"asks": [["84144", "0.21153332", "0", "2"], ["84187.1", "0.07126989", "0", "1"]], "bids": [["84104", "0.69834107", "0", "12"], ["84070", "1.24041175", "0", "3"], ["84022", "0.0714098", "0", "1"]], "ts": "1742555034604", "checksum": 415854236, "seqId": 49927412704, "prevSeqId": 49927412686}], "record_time": 1742555034.60489, "EXCHANGE": "OKX"}
{"arg": {"channel": "books", "instId": "BTC-USDT"}, "action": "snapshot", "data": [{"asks": [["84076.7", "0.78480406", "0", "11"], ["84077", "0.01055", "0", "1"], ["84078", "0.13359438", "0", "2"], ["84078.3", "0.21658368", "0", "1"], ["84078.4", "0.2103941", "0", "2"], ["84078.5", "0.31540487", "0", "8"], ["84078.6", "0.12846161", "0", "2"], ["84078.9", "0.02915443", "0", "1"], ["84079.3", "0.0011893", "0", "1"], ["84080", "0.01476891", "0", "2"], ["84081.7", "0.00773087", "0", "1"], ["84081.9", "0.03679071", "0", "1"], ["84082", "0.0146", "0", "1"], ["84082.6", "0.00352559", "0", "1"], ["84083.3", "0.08991011", "0", "1"], ["84084", "0.0146", "0", "1"], ["84084.3", "0.34467649", "0", "1"], ["84084.4", "0.0011191", "0", "1"], ["84084.5", "0.00015454", "0", "1"], ["84084.9", "0.03166", "0", "1"], ["84085.2", "0.01055", "0", "1"], ["84085.4", "0.00001197", "0", "1"], ["84085.8", "0.01913376", "0", "1"], ["84086", "0.0546", "0", "2"], ["84086.4", "0.06", "0", "2"], ["84086.6", "0.1784", "0", "1"], ["84086.8", "0.01", "0", "2"], ["84086.9", "0.17821722", "0", "1"], ["84087", "0.2025", "0", "1"], ["84087.1", "0.03364761", "0", "1"], ["84087.3", "0.35681", "0", "1"], ["84087.7", "0.03417517", "0", "1"], ["84087.8", "0.06593763", "0", "3"], ["84088", "0.0146", "0", "1"], ["84088.4", "0.47134091", "0", "2"], ["84088.5", "0.35641581", "0", "1"], ["84088.7", "0.11890903", "0", "1"], ["84089.6", "1", "0", "1"], ["84089.8", "0.060015", "0", "3"], ["84090", "0.0156", "0", "2"], ["84090.4", "0.00001197", "0", "1"], ["84091.8", "0.00420676", "0", "1"], ["84092", "0.0146", "0", "1"], ["84092.5", "0.25781015", "0", "4"], ["84093", "0.04", "0", "1"], ["84093.2", "0.00059468", "0", "1"], ["84094.1", "0.0685273", "0", "2"], ["84094.4", "0.05617506", "0", "1"], ["84095.2", "0.009071", "0", "1"], ["84095.3", "0.00001197", "0", "1"], ["84096.1", "0.17821722", "0", "1"], ["84096.2", "0.1189686", "0", "1"], ["84096.5", "0.15475407", "0", "3"], ["84096.8", "0.01", "0", "2"], ["84096.9", "0.36561419", "0", "1"], ["84097.2", "0.11890903", "0", "1"], ["84097.7", "0.01189705", "0", "1"], ["84097.8", "0.23800119", "0", "1"], ["84097.9", "0.38975022", "0", "2"], ["84098", "0.0146", "0", "1"], ["84098.1", "0.35641581", "0", "1"], ["84098.2", "0.000015", "0", "1"], ["84099.3", "0.052", "0", "2"], ["84099.5", "0.00420581", "0", "1"], ["84099.9", "0.00060645", "0", "1"], ["84100", "0.00055921", "0", "1"], ["84100.1", "0.11896312", "0", "1"], ["84100.3", "0.00001197", "0", "1"], ["84100.4", "0.05944451", "0", "1"], ["84101.1", "0.06955836", "0", "1"], ["84101.5", "0.002", "0", "1"], ["84101.9", "0.00011161", "0", "1"], ["84102", "0.052", "0", "2"], ["84102.1", "0.01774536", "0", "1"], ["84102.2", "0.71287721", "0", "1"], ["84102.3", "1.61050943", "0", "1"], ["84102.4", "0.24977", "0", "1"], ["84103", "0.052", "0", "2"], ["84103.2", "0.06491852", "0", "1"], ["84103.6", "0.06869864", "0", "1"], ["84104.3", "0.0369405", "0", "1"], ["84104.8", "0.17821722", "0", "1"], ["84104.9", "0.11235012", "0", "2"], ["84105.1", "0.08376", "0", "1"], ["84105.2", "0.06945997", "0", "2"], ["84105.7", "0.42029712", "0", "1"], ["84105.8", "0.47705", "0", "1"], ["84106.6", "0.00541501", "0", "2"], ["84107.2", "0.00420428", "0", "1"], ["84107.4", "0.35641581", "0", "1"], ["84107.5", "0.2185", "0", "2"], ["84109.1", "0.27403166", "0", "2"], ["84109.2", "0.47358537", "0", "1"], ["84109.3", "0.12488", "0", "1"], ["84109.4", "0.016", "0", "1"], ["84109.5", "0.00357", "0", "1"], ["84110", "1.24", "0", "1"], ["84110.2", "0.00001197", "0", "1"], ["84111", "1", "0", "1"], ["84111.2", "0.016", "0", "1"], ["84111.5", "0.002", "0", "1"], ["84112", "0.31890903", "0", "2"], ["84112.1", "0.00367825", "0", "1"], ["84112.5", "0.02378909", "0", "1"], ["84113.6", "0.17821722", "0", "1"], ["84114.4", "0.08", "0", "2"], ["84115", "0.000015", "0", "1"], ["84115.2", "0.04001196", "0", "2"], ["84115.4", "0.11235012", "0", "2"], ["84116.3", "0.00367825", "0", "1"], ["84116.4", "0.41874336", "0", "2"], ["84116.5", "0.00911661", "0", "1"], ["84116.6", "0.00060645", "0", "1"], ["84116.8", "0.00420428", "0", "1"], ["84117.9", "0.00357", "0", "1"], ["84118.4", "0.0054", "0", "1"], ["84120.1", "0.00001197", "0", "1"], ["84120.4", "0.09411353", "0", "2"], ["84120.5", "0.00367825", "0", "1"], ["84121.2", "0.1", "0", "1"], ["84121.5", "0.00011161", "0", "1"], ["84121.6", "0.14043766", "0", "1"], ["84121.8", "0.01", "0", "1"], ["84122.7", "0.17821722", "0", "1"], ["84122.8", "0.11890903", "0", "1"], ["84123.1", "0.215004", "0", "3"], ["84123.2", "0.471052", "0", "1"], ["84123.4", "0.249785", "0", "2"], ["84125", "0.35641581", "0", "1"], ["84125.1", "0.00001197", "0", "1"], ["84125.9", "0.11235012", "0", "2"], ["84126.4", "0.01783958", "0", "1"], ["84126.7", "0.01188684", "0", "1"], ["84127", "0.00001", "0", "1"], ["84127.9", "0.01188667", "0", "1"], ["84128.1", "0.01188664", "0", "1"], ["84128.6", "0.02004759", "0", "1"], ["84128.7", "0.01188656", "0", "1"], ["84130.1", "0.00001197", "0", "1"], ["84130.3", "1.57125964", "0", "2"], ["84130.5", "0.25755", "0", "1"], ["84130.6", "0.01188653", "0", "1"], ["84131.3", "0.917317", "0", "1"], ["84131.4", "0.1947926", "0", "2"], ["84131.6", "0.2025", "0", "1"], ["84131.8", "0.059921", "0", "2"], ["84132", "0.00004312", "0", "1"], ["84132.1", "2.89752098", "0", "1"], ["84132.4", "0.11890903", "0", "1"], ["84133.3", "0.00101534", "0", "2"], ["84133.6", "0.02378313", "0", "1"], ["84133.9", "0.0177", "0", "1"], ["84134", "0.00420221", "0", "1"], ["84134.3", "0.35641581", "0", "1"], ["84134.6", "0.08991011", "0", "1"], ["84134.9", "0.24149598", "0", "1"], ["84135", "0.52989197", "0", "2"], ["84136.5", "0.11235012", "0", "2"], ["84138.9", "0.35321362", "0", "1"], ["84139", "0.58539886", "0", "1"], ["84140", "0.00006697", "0", "3"], ["84140.1", "0.2025", "0", "1"], ["84140.2", "0.00001501", "0", "1"], ["84141.1", "0.01128873", "0", "1"], ["84141.2", "0.00011161", "0", "1"], ["84141.6", "0.00579957", "0", "1"], ["84141.7", "0.00420136", "0", "1"], ["84142.2", "0.16638478", "0", "1"], ["84142.7", "0.17821722", "0", "1"], ["84142.8", "0.22024891", "0", "1"], ["84144.6", "0.0054", "0", "1"], ["84145", "0.00001197", "0", "1"], ["84145.2", "0.05466", "0", "1"], ["84145.8", "0.03", "0", "1"], ["84146.6", "0.36830227", "0", "2"], ["84146.7", "0.11890903", "0", "1"], ["84147", "0.13966633", "0", "3"], ["84148.5", "0.05944734", "0", "1"], ["84148.6", "0.00001501", "0", "1"], ["84149.6", "0.00579957", "0", "1"], ["84149.7", "0.01188644", "0", "1"], ["84149.9", "0.00061841", "0", "2"], ["84150.1", "0.2025", "0", "1"], ["84150.2", "0.00420106", "0", "1"], ["84150.7", "0.07130066", "0", "1"], ["84151.4", "0.00713", "0", "1"], ["84152.6", "0.19832148", "0", "1"], ["84152.7", "0.17821722", "0", "1"], ["84154.9", "0.00001196", "0", "1"], ["84155.1", "0.08991011", "0", "1"], ["84155.3", "0.35641581", "0", "1"], ["84155.7", "0.00579957", "0", "1"], ["84155.8", "0.18052957", "0", "2"], ["84155.9", "0.11890903", "0", "1"], ["84156.3", "0.00420026", "0", "1"], ["84156.5", "0.09", "0", "3"], ["84157", "0.00001501", "0", "1"], ["84158.7", "0.07129388", "0", "1"], ["84158.9", "0.2025", "0", "1"], ["84159.2", "0.03", "0", "1"], ["84159.8", "0.18961175", "0", "3"], ["84160.8", "0.02389911", "0", "2"], ["84161.7", "0.47216", "0", "1"], ["84162.7", "0.00579957", "0", "1"], ["84162.8", "0.17821722", "0", "1"], ["84163", "0.00594549", "0", "1"], ["84164.2", "0.63075985", "0", "2"], ["84164.3", "0.3623613", "0", "2"], ["84164.5", "0.00419925", "0", "1"], ["84164.8", "0.00001196", "0", "1"], ["84164.9", "0.11890903", "0", "1"], ["84165.4", "0.000015", "0", "1"], ["84165.8", "1.375411", "0", "1"], ["84166", "0.0001965", "0", "1"], ["84166.2", "0.0237875", "0", "1"], ["84166.4", "0.00594624", "0", "1"], ["84166.6", "0.00104525", "0", "3"], ["84167.4", "0.09576649", "0", "2"], ["84167.5", "0.2025", "0", "1"], ["84168.1", "0.17984585", "0", "2"], ["84168.5", "0.03567916", "0", "1"], ["84168.9", "0.00579957", "0", "1"], ["84169", "0.01425702", "0", "1"], ["84169.3", "0.11846252", "0", "1"], ["84169.8", "0.00001196", "0", "1"], ["84170", "0.08752", "0", "1"], ["84170.1", "0.00118807", "0", "1"], ["84170.2", "0.2271431", "0", "1"], ["84171.6", "0.17821722", "0", "1"], ["84173.1", "2.11712303", "0", "1"], ["84173.2", "0.35641581", "0", "1"], ["84173.3", "3.59288314", "0", "2"], ["84173.6", "0.11890903", "0", "1"], ["84173.7", "0.07125036", "0", "1"], ["84173.8", "0.000015", "0", "1"], ["84174.7", "0.00001196", "0", "1"], ["84175.7", "0.00579957", "0", "1"], ["84175.8", "3.19706783", "0", "3"], ["84176.1", "0.2025", "0", "1"], ["84179", "0.08194995", "0", "1"], ["84179.1", "0.05700028", "0", "1"], ["84179.3", "0.03", "0", "1"], ["84179.7", "0.10001196", "0", "2"], ["84180.4", "0.00011161", "0", "1"], ["84180.5", "0.17821722", "0", "1"], ["84181.8", "0.00003887", "0", "1"], ["84182.1", "0.15300834", "0", "2"], ["84182.2", "0.11892404", "0", "2"], ["84182.6", "0.35641581", "0", "1"], ["84182.9", "0.00023777", "0", "1"], ["84183.2", "0.00579996", "0", "1"], ["84183.3", "0.00060645", "0", "1"], ["84184.2", "0.00419766", "0", "1"], ["84184.7", "0.00001196", "0", "1"], ["84185.1", "0.07277513", "0", "1"], ["84185.2", "0.1", "0", "1"], ["84185.4", "0.08991011", "0", "1"], ["84188.8", "0.00594477", "0", "1"], ["84188.9", "0.04672887", "0", "1"], ["84189.6", "0.00001196", "0", "1"], ["84190", "0.00001057", "0", "1"], ["84190.6", "0.00001501", "0", "1"], ["84190.9", "0.27607157", "0", "1"], ["84191", "0.17821722", "0", "1"], ["84191.1", "0.35641581", "0", "1"], ["84191.3", "0.11890903", "0", "1"], ["84191.5", "0.2025", "0", "1"], ["84191.8", "0.001964", "0", "1"], ["84192.2", "0.06", "0", "2"], ["84192.6", "0.0041965", "0", "1"], ["84194.6", "0.22879676", "0", "3"], ["84194.7", "0.08991011", "0", "1"], ["84195.4", "0.64996", "0", "1"], ["84197", "0.00594421", "0", "1"], ["84197.1", "0.03", "0", "1"], ["84198.6", "0.03594421", "0", "2"], ["84199", "0.00001501", "0", "1"], ["84199.2", "1.87716699", "0", "1"], ["84199.6", "0.00001196", "0", "1"], ["84199.7", "0.35641581", "0", "1"], ["84199.8", "0.11890903", "0", "1"], ["84199.9", "0.18857973", "0", "8"], ["84200", "5.34702668", "0", "34"], ["84200.1", "0.00011161", "0", "1"], ["84200.4", "0.01483565", "0", "2"], ["84200.5", "0.03", "0", "1"], ["84200.6", "0.08749", "0", "1"], ["84201.7", "0.00594421", "0", "1"], ["84202", "0.00005073", "0", "1"], ["84202.8", "0.00002241", "0", "1"], ["84204.4", "0.01511839", "0", "1"], ["84204.5", "0.00033082", "0", "3"], ["84204.7", "0.11881537", "0", "1"], ["84205", "0.00181735", "0", "1"], ["84206.1", "0.21161094", "0", "2"], ["84206.5", "0.2025", "0", "1"], ["84207.3", "0.183172", "0", "1"], ["84207.4", "0.000015", "0", "1"], ["84207.5", "0.214069", "0", "1"], ["84207.7", "0.00419514", "0", "1"], ["84207.8", "0.07619455", "0", "1"], ["84208.5", "0.00040805", "0", "13"], ["84208.7", "0.00001096", "0", "1"], ["84209.3", "0.00011444", "0", "1"], ["84209.5", "0.00001197", "0", "1"], ["84210.5", "0.05365541", "0", "3"], ["84210.6", "1.26279953", "0", "2"], ["84211.1", "0.00002037", "0", "1"], ["84211.2", "0.1", "0", "1"], ["84211.7", "0.00003107", "0", "2"], ["84212", "0.0000594", "0", "1"], ["84212.1", "0.00001023", "0", "1"], ["84212.3", "0.01188664", "0", "1"], ["84212.5", "0.00001995", "0", "1"], ["84212.7", "0.01299784", "0", "1"], ["84213.1", "0.18059522", "0", "2"], ["84213.5", "0.35641581", "0", "1"], ["84213.8", "3.56205", "0", "1"], ["84214.2", "0.00001575", "0", "1"], ["84214.5", "0.00001197", "0", "1"], ["84214.8", "0.00032751", "0", "1"], ["84215.3", "0.06946337", "0", "1"], ["84215.4", "0.11879524", "0", "2"], ["84215.8", "0.00001501", "0", "1"], ["84216", "0.00001565", "0", "1"], ["84216.6", "0.00060645", "0", "1"], ["84216.9", "0.08991011", "0", "1"], ["84217.9", "0.00419368", "0", "1"], ["84218", "0.00016867", "0", "1"], ["84218.1", "0.00001045", "0", "1"], ["84219.3", "0.00007814", "0", "1"], ["84219.4", "0.00001503", "0", "1"], ["84219.7", "0.01798586", "0", "2"], ["84221.3", "0.00037549", "0", "1"], ["84222", "0.0059464", "0", "1"], ["84222.2", "0.2025", "0", "1"], ["84222.3", "0.35641581", "0", "1"], ["84223.5", "0.21567694", "0", "1"], ["84223.8", "0.17846554", "0", "2"], ["84224.2", "0.00003002", "0", "2"], ["84224.3", "0.03", "0", "1"], ["84224.4", "0.40001197", "0", "2"], ["84225", "0.00017601", "0", "1"], ["84225.5", "0.03", "0", "1"], ["84225.9", "0.00419367", "0", "1"], ["84226.5", "0.00002974", "0", "1"], ["84226.6", "0.00001653", "0", "1"], ["84227.8", "0.00001197", "0", "1"], ["84228.4", "0.00010514", "0", "1"], ["84228.5", "0.00002372", "0", "1"], ["84228.9", "0.00008", "0", "1"], ["84230.1", "0.000548", "0", "2"], ["84230.6", "0.16928013", "0", "1"], ["84230.7", "0.2025", "0", "1"], ["84230.9", "0.35582144", "0", "2"], ["84231.1", "0.15159501", "0", "1"], ["84232", "0.00054", "0", "2"], ["84232.3", "0.29700048", "0", "2"], ["84232.6", "0.00001501", "0", "1"], ["84232.9", "0.08747", "0", "1"], ["84233", "0.06012728", "0", "2"], ["84233.3", "0.00101534", "0", "2"], ["84233.5", "0.00002296", "0", "1"], ["84233.8", "0.00003542", "0", "1"], ["84233.9", "0.00419323", "0", "1"], ["84234", "0.00036", "0", "1"], ["84234.4", "0.00001197", "0", "1"], ["84235", "0.00025", "0", "1"], ["84235.2", "0.00002902", "0", "1"], ["84235.7", "0.03", "0", "1"], ["84236", "0.00036", "0", "1"], ["84236.6", "0.00593", "0", "1"], ["84236.8", "0.00001738", "0", "1"], ["84237", "0.00036", "0", "1"], ["84237.2", "0.00001115", "0", "1"], ["84237.6", "0.0142", "0", "1"], ["84237.7", "0.0284", "0", "2"], ["84237.8", "0.00007018", "0", "2"], ["84238.1", "0.00006534", "0", "2"], ["84238.8", "0.0178392", "0", "3"], ["84239", "0.00593856", "0", "1"], ["84239.2", "0.2025", "0", "1"], ["84239.3", "0.00011161", "0", "1"], ["84239.7", "0.1792492", "0", "2"], ["84239.8", "0.35579296", "0", "1"], ["84240", "0.00039685", "0", "3"], ["84240.1", "0.00001005", "0", "1"], ["84241", "0.00001501", "0", "1"], ["84242", "0.0000185", "0", "1"], ["84242.4", "0.00469113", "0", "3"], ["84242.5", "0.00011938", "0", "1"], ["84242.6", "0.00419183", "0", "1"], ["84242.8", "0.03", "0", "1"], ["84243.2", "0.03", "0", "1"], ["84244", "0.03", "0", "1"], ["84244.1", "0.00083", "0", "1"], ["84244.3", "0.00605088", "0", "2"], ["84244.5", "0.2723811", "0", "1"], ["84244.6", "0.5999", "0", "1"], ["84245.2", "1.89975034", "0", "2"]], "bids": [["84076.6", "0.00733807", "0", "2"], ["84076.5", "0.002", "0", "1"], ["84075.7", "0.00056605", "0", "1"], ["84075.6", "0.00001197", "0", "1"], ["84073.9", "0.00005327", "0", "1"], ["84073.2", "0.00005206", "0", "1"], ["84072.6", "0.11900181", "0", "1"], ["84072", "0.0025", "0", "1"], ["84071", "0.0025", "0", "1"], ["84070.6", "0.00001197", "0", "1"], ["84070", "0.0025", "0", "1"], ["84069.9", "0.35641581", "0", "1"], ["84069.4", "0.01190057", "0", "1"], ["84068.1", "0.2025", "0", "1"], ["84067.7", "0.00001501", "0", "1"], ["84067.5", "0.17821722", "0", "1"], ["84066.6", "0.00504382", "0", "4"], ["84066.5", "0.01", "0", "2"], ["84066.4", "0.00973104", "0", "2"], ["84066.3", "0.00006", "0", "1"], ["84065.7", "0.00001197", "0", "1"], ["84064.6", "0.0541583", "0", "1"], ["84064.5", "0.14816853", "0", "2"], ["84063", "0.59448235", "0", "3"], ["84062.9", "0.01", "0", "1"], ["84062.6", "0.00011161", "0", "1"], ["84062.4", "0.18725022", "0", "1"], ["84062.2", "0.0000105", "0", "1"], ["84062", "0.14551111", "0", "2"], ["84061.9", "0.0134", "0", "1"], ["84061.4", "0.35641581", "0", "1"], ["84061.2", "0.00005328", "0", "1"], ["84061", "0.19756982", "0", "3"], ["84060.7", "0.00001197", "0", "1"], ["84060.2", "0.00420823", "0", "1"], ["84060", "0.00557886", "0", "2"], ["84059.8", "0.03163279", "0", "1"], ["84059.7", "0.03516623", "0", "2"], ["84059.3", "1.000015", "0", "2"], ["84059.2", "0.0134", "0", "1"], ["84059.1", "0.03269475", "0", "1"], ["84058.9", "0.102", "0", "2"], ["84058.8", "0.2186", "0", "2"], ["84058.7", "0.042", "0", "1"], ["84058.6", "0.26708015", "0", "1"], ["84058.5", "0.17821722", "0", "1"], ["84058.4", "0.03457969", "0", "1"], ["84057.5", "0.11909824", "0", "2"], ["84057.2", "0.03611792", "0", "1"], ["84057", "0.35681", "0", "1"], ["84056.9", "0.02979707", "0", "1"], ["84055.7", "0.00001197", "0", "1"], ["84055.6", "0.15585", "0", "4"], ["84055.5", "0.00039387", "0", "1"], ["84054.8", "0.2025", "0", "1"], ["84054.6", "0.2383603", "0", "1"], ["84054.1", "0.00713826", "0", "1"], ["84053.3", "0.04475889", "0", "2"], ["84052.9", "0.3568907", "0", "1"], ["84052.8", "0.03139272", "0", "1"], ["84052.5", "0.11235012", "0", "2"], ["84052.3", "0.00420804", "0", "1"], ["84052.1", "0.03369479", "0", "1"], ["84051.3", "0.14043766", "0", "1"], ["84051", "0.03337353", "0", "1"], ["84050.9", "0.000015", "0", "1"], ["84050.8", "0.00001197", "0", "1"], ["84050.5", "0.000015", "0", "1"], ["84050.3", "0.03486888", "0", "1"], ["84050", "0.00033629", "0", "3"], ["84049.9", "0.00060645", "0", "1"], ["84049.3", "0.1784", "0", "1"], ["84049.1", "0.1214991", "0", "2"], ["84048.9", "0.14357321", "0", "1"], ["84048.7", "0.17821722", "0", "1"], ["84048.6", "0.00357", "0", "1"], ["84047.1", "0.20908", "0", "1"], ["84047", "0.02380761", "0", "1"], ["84046.6", "0.00009543", "0", "1"], ["84046.2", "0.12488", "0", "1"], ["84045.9", "1.09704058", "0", "2"], ["84045.8", "0.27205785", "0", "4"], ["84045.7", "0.05427", "0", "1"], ["84045.3", "1.59063794", "0", "1"], ["84045.1", "0.00005207", "0", "1"], ["84045", "0.00001", "0", "1"], ["84044.3", "0.35579296", "0", "1"], ["84044.2", "0.01804", "0", "1"], ["84043.7", "0.06588076", "0", "1"], ["84043", "0.00011161", "0", "1"], ["84042.7", "0.0690703", "0", "1"], ["84042.5", "0.00001501", "0", "1"], ["84042.4", "0.00001196", "0", "1"], ["84042.2", "0.06223887", "0", "1"], ["84042.1", "0.470924", "0", "1"], ["84042", "0.11235012", "0", "2"], ["84041.6", "0.11890903", "0", "1"], ["84040.8", "0.23800119", "0", "1"], ["84040.6", "0.48399661", "0", "1"], ["84040.5", "0.48822", "0", "1"], ["84040", "0.08001", "0", "3"], ["84039.8", "0.17821722", "0", "1"], ["84039.3", "0.76645", "0", "2"], ["84039.2", "0.066", "0", "3"], ["84038.4", "0.013", "0", "1"], ["84038.2", "0.0214248", "0", "1"], ["84037.6", "0.1989532", "0", "1"], ["84037.5", "0.05952577", "0", "1"], ["84037.3", "0.2025", "0", "1"], ["84036", "0.101784", "0", "3"], ["84035.9", "0.00001196", "0", "1"], ["84035.8", "0.35579296", "0", "1"], ["84035.6", "0.01785886", "0", "1"], ["84035.2", "0.05", "0", "1"], ["84035", "0.12488", "0", "1"], ["84034.1", "0.00001501", "0", "1"], ["84033.8", "0.00420994", "0", "1"], ["84033.3", "0.00101534", "0", "2"], ["84033.2", "0.03", "0", "1"], ["84032.5", "0.11890903", "0", "1"], ["84031.5", "0.11695803", "0", "4"], ["84031.4", "0.00012658", "0", "1"], ["84031.1", "0.03", "0", "1"], ["84030.9", "0.00001196", "0", "1"], ["84030", "0.00001196", "0", "1"], ["84029.5", "0.17821722", "0", "1"], ["84028.9", "0.30234296", "0", "1"], ["84028.8", "0.2025", "0", "1"], ["84028.6", "0.02817312", "0", "1"], ["84027.9", "0.009425", "0", "1"], ["84027.7", "0.00007596", "0", "1"], ["84027.3", "0.91425798", "0", "2"], ["84026.9", "0.29002871", "0", "1"], ["84026.8", "0.1", "0", "1"], ["84026.6", "0.00017505", "0", "1"], ["84026.2", "0.02381352", "0", "1"], ["84026.1", "0.00421091", "0", "1"], ["84025.7", "0.000015", "0", "1"], ["84025.4", "0.0054", "0", "1"], ["84025.2", "0.12588367", "0", "2"], ["84025", "0.00001719", "0", "1"], ["84024.7", "0.0000313", "0", "1"], ["84024.3", "0.0183263", "0", "1"], ["84024.2", "0.00256053", "0", "1"], ["84023.7", "0.004675", "0", "1"], ["84023.3", "0.00011161", "0", "1"], ["84022.6", "0.00102079", "0", "2"], ["84022.1", "0.01188664", "0", "1"], ["84021.5", "0.11890903", "0", "1"], ["84021", "0.17822918", "0", "2"], ["84020.4", "0.17438074", "0", "1"], ["84020.3", "0.2025", "0", "1"], ["84020", "0.00001", "0", "1"], ["84019.5", "0.004675", "0", "1"], ["84018.7", "0.35579296", "0", "1"], ["84018.3", "0.24977", "0", "1"], ["84017.9", "0.00714133", "0", "1"], ["84017.7", "0.00001196", "0", "1"], ["84017.3", "0.00001501", "0", "1"], ["84016.9", "0.00421155", "0", "1"], ["84016.6", "1.49474051", "0", "3"], ["84016.5", "0.948569", "0", "2"], ["84015.8", "0.00235652", "0", "1"], ["84015.6", "2.80325968", "0", "1"], ["84015.5", "0.00594565", "0", "1"], ["84014.2", "0.00285286", "0", "1"], ["84014.1", "0.00594568", "0", "1"], ["84014", "0.34762004", "0", "3"], ["84013.4", "0.98397", "0", "1"], ["84013.3", "0.00594549", "0", "1"], ["84013.2", "0.06", "0", "2"], ["84012.7", "0.11890903", "0", "1"], ["84012.4", "0.00594549", "0", "1"], ["84012.3", "0.35271192", "0", "3"], ["84012.2", "0.18401726", "0", "2"], ["84011.8", "0.2025", "0", "1"], ["84011.2", "0.4", "0", "1"], ["84011.1", "0.00001196", "0", "1"], ["84010.7", "0.00005963", "0", "1"], ["84010.6", "0.00105282", "0", "1"], ["84010.5", "0.059992", "0", "1"], ["84010.3", "0.00594568", "0", "1"], ["84010.2", "0.35579296", "0", "1"], ["84010", "0.00014389", "0", "1"], ["84009.7", "0.00594549", "0", "1"], ["84008.9", "0.00581504", "0", "2"], ["84008.8", "0.00421282", "0", "1"], ["84008.6", "0.03", "0", "1"], ["84008.4", "0.00001501", "0", "1"], ["84008.3", "0.00001365", "0", "1"], ["84007.4", "0.50592148", "0", "2"], ["84007.3", "3.26457", "0", "1"], ["84006.2", "0.00001196", "0", "1"], ["84005.3", "0.00001196", "0", "1"], ["84003.9", "0.0190223", "0", "1"], ["84003.8", "0.08929", "0", "1"], ["84003.7", "0.26823894", "0", "3"], ["84003.3", "0.2025", "0", "1"], ["84001.9", "0.0054", "0", "1"], ["84001.5", "0.35579296", "0", "1"], ["84001.1", "0.00008", "0", "1"], ["84000.6", "0.00580004", "0", "1"], ["84000.5", "0.04758674", "0", "2"], ["84000.4", "0.08385249", "0", "2"], ["84000.1", "0.40718646", "0", "1"], ["84000", "20.47587537", "0", "33"], ["83999.9", "0.00517179", "0", "8"], ["83998.6", "3.44638", "0", "1"], ["83996.3", "0.00001196", "0", "1"], ["83996.2", "0.01149261", "0", "1"], ["83995.6", "0.00595", "0", "1"], ["83995.1", "0.00580004", "0", "1"], ["83994.8", "0.2025", "0", "1"], ["83994.3", "0.17821722", "0", "1"], ["83993.9", "0.00421443", "0", "1"], ["83993.8", "0.07143383", "0", "1"], ["83993.6", "0.03571772", "0", "1"], ["83992.5", "0.35579296", "0", "1"], ["83992.4", "0.40201959", "0", "2"], ["83992.1", "0.00001501", "0", "1"], ["83991.6", "1.53542416", "0", "2"], ["83991.5", "0.11878326", "0", "1"], ["83991.3", "0.00001196", "0", "1"], ["83991.1", "0.0166188", "0", "1"], ["83990.4", "0.01810015", "0", "1"], ["83990.3", "0.00009235", "0", "1"], ["83988.4", "0.00016249", "0", "1"], ["83988.3", "0.0000469", "0", "1"], ["83988.2", "0.00580004", "0", "1"], ["83988", "0.00005334", "0", "1"], ["83987.8", "0.00007308", "0", "1"], ["83987.7", "0.00023813", "0", "1"], ["83987.3", "0.107", "0", "5"], ["83986.6", "0.11912367", "0", "1"], ["83986.3", "0.20251197", "0", "2"], ["83986.1", "0.2094027", "0", "1"], ["83985.8", "0.07147328", "0", "2"], ["83985.7", "0.00001677", "0", "1"], ["83985", "0.00001785", "0", "1"], ["83984.1", "0.00011161", "0", "1"], ["83983.7", "0.00001501", "0", "1"], ["83983.6", "0.17821722", "0", "1"], ["83983.5", "0.35579296", "0", "1"], ["83983.4", "0.00004752", "0", "1"], ["83983.3", "0.00482138", "0", "2"], ["83983", "0.00007198", "0", "1"], ["83982.1", "0.4671992", "0", "1"], ["83982", "1.37842", "0", "1"], ["83981.9", "0.0000492", "0", "1"], ["83981.8", "0.00579982", "0", "1"], ["83981.5", "0.00005685", "0", "1"], ["83981.4", "0.00001197", "0", "1"], ["83980.6", "0.00001197", "0", "1"], ["83980.5", "0.0061", "0", "1"], ["83980.4", "0.03", "0", "1"], ["83980", "0.00005457", "0", "1"], ["83979.7", "0.12488326", "0", "2"], ["83979.5", "0.00004344", "0", "1"], ["83979.1", "0.00609975", "0", "1"], ["83979", "0.00579982", "0", "1"], ["83978.9", "0.0007196", "0", "1"], ["83978.3", "0.03", "0", "1"], ["83978.2", "0.00421569", "0", "1"], ["83978", "0.03", "0", "1"], ["83977.9", "0.00580011", "0", "1"], ["83977.8", "0.2025", "0", "1"], ["83977.7", "0.05700028", "0", "1"], ["83977.6", "0.04830033", "0", "4"], ["83977.2", "0.00005459", "0", "1"], ["83976.6", "0.0054", "0", "1"], ["83976.5", "0.03", "0", "1"], ["83975.5", "0.00005458", "0", "1"], ["83975.2", "0.00579982", "0", "1"], ["83975.1", "0.17821722", "0", "1"], ["83975", "0.38581966", "0", "3"], ["83974.9", "0.090027", "0", "1"], ["83974.6", "0.00003456", "0", "1"], ["83974.3", "0.00003395", "0", "1"], ["83973.8", "0.00609975", "0", "1"], ["83973.7", "0.02378746", "0", "1"], ["83972", "0.00579982", "0", "1"], ["83971.9", "0.07125036", "0", "1"], ["83971.6", "0.00580011", "0", "1"], ["83971.5", "0.08843544", "0", "5"], ["83971.4", "0.00068806", "0", "1"], ["83971.1", "0.08991011", "0", "1"], ["83970.9", "0.00002851", "0", "1"], ["83970.7", "0.12458302", "0", "2"], ["83969.9", "0.014", "0", "1"], ["83969.4", "0.01189648", "0", "1"], ["83969.3", "0.2025", "0", "1"], ["83969", "0.00005519", "0", "1"], ["83968.3", "0.00001197", "0", "1"], ["83967.8", "0.00610955", "0", "2"], ["83967.7", "0.10004003", "0", "2"], ["83967.4", "0.00013882", "0", "1"], ["83967.2", "0.00001508", "0", "1"], ["83967.1", "0.00609975", "0", "1"], ["83967", "0.08933", "0", "1"], ["83966.8", "0.0042171", "0", "1"], ["83966.7", "0.17821722", "0", "1"], ["83966.6", "0.3604018", "0", "4"], ["83966.3", "0.00001501", "0", "1"], ["83964.4", "0.04271161", "0", "4"], ["83964.1", "0.0142", "0", "1"], ["83963.2", "0.00579976", "0", "1"], ["83963.1", "0.00579976", "0", "1"], ["83963", "0.00579976", "0", "1"], ["83962.9", "0.00350324", "0", "1"], ["83962.3", "0.11878326", "0", "1"], ["83961.6", "0.00001197", "0", "1"], ["83960.8", "0.20609061", "0", "2"], ["83960.1", "0.00083", "0", "1"], ["83960", "0.00012381", "0", "2"], ["83959.9", "0.00001022", "0", "1"], ["83959.8", "0.00421771", "0", "1"], ["83959.1", "0.00001009", "0", "1"], ["83958.8", "0.00005335", "0", "1"], ["83958.6", "0.0059464", "0", "1"], ["83958.5", "0.00083", "0", "1"], ["83958.4", "0.214062", "0", "1"], ["83958.3", "0.00006061", "0", "1"], ["83956.9", "0.00268856", "0", "1"], ["83956.6", "0.18317497", "0", "2"], ["83955.9", "0.00001197", "0", "1"], ["83954.6", "0.00083", "0", "1"], ["83954.5", "0.17821722", "0", "1"], ["83954.4", "0.35579296", "0", "1"], ["83952.9", "0.08991011", "0", "1"], ["83952.7", "0.00001065", "0", "1"], ["83952.4", "0.18326305", "0", "1"], ["83952.3", "0.2025", "0", "1"], ["83951.7", "0.01784475", "0", "1"], ["83950.7", "0.01785873", "0", "1"], ["83950.3", "3.24944", "0", "1"], ["83950", "0.00013403", "0", "2"], ["83949.9", "0.00482516", "0", "2"], ["83948.1", "0.00201772", "0", "1"], ["83947.6", "0.0142", "0", "1"], ["83947.5", "0.0142", "0", "1"], ["83947.3", "0.00103791", "0", "1"], ["83946.7", "0.00002763", "0", "2"], ["83946.1", "0.17821722", "0", "1"], ["83946", "0.38579296", "0", "2"], ["83945.4", "0.11890903", "0", "1"], ["83945.1", "0.002378", "0", "1"], ["83944.8", "0.00011161", "0", "1"], ["83944.6", "0.00421935", "0", "1"], ["83943.8", "0.2025", "0", "1"], ["83942", "0.00007352", "0", "1"], ["83941.8", "0.01785117", "0", "4"], ["83941.5", "1.69295", "0", "1"], ["83941.1", "0.03001807", "0", "2"], ["83940.4", "0.00002279", "0", "1"], ["83939.8", "0.08991011", "0", "1"], ["83939.5", "0.00007329", "0", "1"], ["83939", "0.03", "0", "1"], ["83938.4", "0.00001883", "0", "1"], ["83938.2", "0.6000735", "0", "2"], ["83938.1", "0.01188664", "0", "1"], ["83937.2", "0.59432247", "0", "1"], ["83936.9", "0.06", "0", "2"], ["83936.8", "0.00001197", "0", "1"], ["83936.1", "0.00625367", "0", "2"], ["83935.6", "0.00001925", "0", "1"], ["83935.3", "0.2025", "0", "1"], ["83934.9", "0.17821722", "0", "1"], ["83934.2", "0.35579296", "0", "1"], ["83934.1", "0.00422012", "0", "1"], ["83933.8", "0.00011948", "0", "1"], ["83933.3", "0.00525171", "0", "7"], ["83933", "0.01774245", "0", "1"], ["83932.9", "0.00001845", "0", "1"], ["83932.8", "0.014", "0", "1"], ["83931.9", "0.00001197", "0", "1"], ["83931.3", "0.00001197", "0", "1"], ["83930.7", "0.00001807", "0", "1"], ["83930.5", "0.00001316", "0", "1"], ["83930.2", "0.00606454", "0", "2"], ["83929.9", "0.00007149", "0", "1"], ["83928.5", "0.14848165", "0", "4"], ["83927.9", "0.00199404", "0", "5"], ["83926.8", "0.2025", "0", "1"], ["83926.1", "0.00007821", "0", "1"], ["83925.9", "0.00001002", "0", "1"], ["83925.8", "0.17821722", "0", "1"], ["83925.6", "0.35579296", "0", "1"], ["83925.3", "0.00008", "0", "1"], ["83925.2", "0.00011161", "0", "1"], ["83925", "0.00027367", "0", "1"], ["83924.8", "0.00422077", "0", "1"], ["83924.6", "0.00004441", "0", "2"], ["83924.2", "0.000015", "0", "1"], ["83923", "0.00001987", "0", "1"], ["83922.4", "0.03", "0", "1"], ["83922", "0.00001197", "0", "1"], ["83921.7", "0.0535785", "0", "1"], ["83921.3", "0.0016853", "0", "2"], ["83921", "0.00001002", "0", "1"], ["83920", "0.00001096", "0", "1"]], "ts": "1742555170204", "checksum": 2142820803, "seqId": 49927499775, "prevSeqId": -1}], "record_time": 1742555170.207793, "EXCHANGE": "OKX"}
{"arg": {"channel": "books", "instId": "BTC-USDT"}, "action": "update", "data": [{"asks": [["84076.7", "0.8948774", "0", "14"], ["84078.3", "0.11866098", "0", "1"], ["84078.4", "0.0103941", "0", "1"], ["84078.5", "0.31362087", "0", "7"], ["84089.3", "1", "0", "1"], ["84089.6", "0", "0", "0"], ["84096.5", "0.12310557", "0", "2"], ["84097.8", "0.23800163", "0", "1"]], "bids": [["84071", "0", "0", "0"], ["84068.1", "0", "0", "0"], ["84059.3", "0.000015", "0", "1"], ["84058.7", "0.67601279", "0", "2"], ["84058.6", "1", "0", "1"], ["84051", "0", "0", "0"], ["84040.8", "0", "0", "0"], ["84040.7", "0.23800167", "0", "1"], ["84015.8", "0", "0", "0"], ["83919.2", "0.00003545", "0", "1"], ["83918.3", "0.2025", "0", "1"], ["83917.6", "0.00005114", "0", "1"], ["83917.5", "0.11890903", "0", "1"]], "ts": "1742555170304", "checksum": -433382104, "seqId": 49927499824, "prevSeqId": 49927499775}], "record_time": 1742555170.305312, "EXCHANGE": "OKX"}
{"arg": {"channel": "books", "instId": "BTC-USDT"}, "action": "update", "data": [{"asks": [["84076.7", "0.89492318", "0", "15"], ["84077.9", "0.18492441", "0", "1"], ["84078.3", "0", "0", "0"], ["84096.4", "0.03283097", "0", "1"], ["84097.1", "0.23800124", "0", "1"], ["84097.8", "0", "0", "0"], ["84130.2", "0.00004312", "0", "1"], ["84132", "0", "0", "0"], ["84143.3", "0.00357", "0", "1"], ["84178.2", "0.1", "0", "1"], ["84244.5", "0", "0", "0"], ["84244.6", "0", "0", "0"], ["84245.2", "0", "0", "0"]], "bids": [["84072", "0", "0", "0"], ["84058.8", "0.86521279", "0", "3"], ["84058.7", "1.042", "0", "2"], ["84058.6", "0", "0", "0"], ["84050.9", "0.03448584", "0", "2"], ["84040.7", "0.23800124", "0", "1"], ["84004.1", "0.00235651", "0", "1"], ["83988.4", "0", "0", "0"], ["83986.7", "0.00016249", "0", "1"], ["83917.4", "0.17821722", "0", "1"]], "ts": "1742555170404", "checksum": -856577750, "seqId": 49927499856, "prevSeqId": 49927499824}], "record_time": 1742555170.404081, "EXCHANGE": "OKX"}
{"arg": {"channel": "books", "instId": "BTC-USDT"}, "action": "update", "data": [{"asks": [["84096.8", "0.24800144", "0", "3"], ["84097.1", "0", "0", "0"], ["84211.2", "0", "0", "0"], ["84244.6", "0.5999", "0", "1"], ["84245.2", "1.89975034", "0", "2"]], "bids": [["84076.6", "0.00776677", "0", "4"], ["84040.7", "0.23800144", "0", "1"], ["84003.9", "0", "0", "0"], ["83996.4", "0.03", "0", "1"], ["83980.4", "0", "0", "0"], ["83973.7", "0.02988714", "0", "2"], ["83967.9", "0.00609968", "0", "1"], ["83960.8", "0.2025", "0", "1"]], "ts": "1742555170504", "checksum": -1612941117, "seqId": 49927499874, "prevSeqId": 49927499856}], "record_time": 1742555170.504925, "EXCHANGE": "OKX"}
{"arg": {"channel": "books", "instId": "BTC-USDT"}, "action": "update", "data": [{"asks": [["84182.5", "0.00298666", "0", "1"], ["84190.9", "0.28204489", "0", "2"], ["84199.3", "0.00895999", "0", "1"], ["84207.7", "0.01614179", "0", "2"], ["84216.1", "0.01493332", "0", "1"], ["84244.3", "0", "0", "0"], ["84244.6", "0", "0", "0"], ["84245.2", "0", "0", "0"]], "bids": [["84063", "0.45285917", "0", "3"], ["84059.6", "1", "0", "1"], ["84058.8", "0.56521279", "0", "3"], ["84058.7", "0.042", "0", "1"], ["83979", "0.00878648", "0", "2"], ["83964", "0.00597332", "0", "1"], ["83955.1", "0.00895999", "0", "1"], ["83952.7", "0.00360057", "0", "2"], ["83946.7", "0.01197428", "0", "3"], ["83937.7", "0.01493332", "0", "1"], ["83918.3", "0", "0", "0"], ["83917.6", "0", "0", "0"], ["83917.5", "0", "0", "0"], ["83917.4", "0", "0", "0"]], "ts": "1742555170604", "checksum": 1363092524, "seqId": 49927499894, "prevSeqId": 49927499874}], "record_time": 1742555170.605169, "EXCHANGE": "OKX"}
{"arg": {"channel": "books", "instId": "BTC-USDT"}, "action": "update", "data": [{"asks": [["84096.8", "0.01", "0", "2"], ["84099.2", "0.23799942", "0", "1"], ["84244.1", "0", "0", "0"]], "bids": [["84064.7", "0.009", "0", "1"], ["84063", "0.71029554", "0", "4"], ["84051.2", "0.00908528", "0", "1"], ["84042.2", "0.30023829", "0", "2"], ["84040.7", "0", "0", "0"], ["84037", "1", "0", "1"], ["83920", "0", "0", "0"], ["83919.2", "0", "0", "0"]], "ts": "1742555170704", "checksum": 293770640, "seqId": 49927499907, "prevSeqId": 49927499894}], "record_time": 1742555170.704256, "EXCHANGE": "OKX"}
{"arg": {"channel": "books", "instId": "BTC-USDT"}, "action": "update", "data": [{"asks": [["84097.1", "0.2380012", "0", "1"], ["84099.2", "0", "0", "0"], ["84109.2", "0.76545333", "0", "2"], ["84178.1", "0.13960232", "0", "1"], ["84179", "0", "0", "0"]], "bids": [["84049.4", "0.25186481", "0", "1"], ["84048.9", "0", "0", "0"], ["84042.2", "0.06223887", "0", "1"], ["84040.7", "0.2380012", "0", "1"], ["84037", "0", "0", "0"], ["84021.6", "0.08914146", "0", "1"], ["83998.7", "0.90848591", "0", "1"], ["83937.2", "0", "0", "0"], ["83934", "0.59432247", "0", "1"], ["83921.3", "0", "0", "0"], ["83921", "0", "0", "0"]], "ts": "1742555170804", "checksum": 293770640, "seqId": 49927499927, "prevSeqId": 49927499907}], "record_time": 1742555170.804823, "EXCHANGE": "OKX"}
{"arg": {"channel": "books", "instId": "BTC-USDT"}, "action": "update", "data": [{"asks": [], "bids": [["84068.1", "0.2025", "0", "1"], ["84045.9", "0.01774536", "0", "1"], ["84042.1", "0", "0", "0"], ["84026.5", "0.471072", "0", "1"], ["83921.7", "0", "0", "0"]], "ts": "1742555170904", "checksum": 1059799957, "seqId": 49927499936, "prevSeqId": 49927499927}], "record_time": 1742555170.905358, "EXCHANGE": "OKX"}
{"arg": {"channel": "books", "instId": "BTC-USDT"}, "action": "update", "data": [{"asks": [["84078.4", "0", "0", "0"], ["84078.6", "0.0385515", "0", "1"], ["84079.9", "0.01550993", "0", "1"], ["84081.9", "0", "0", "0"], ["84082.6", "0", "0", "0"], ["84082.7", "0.0103941", "0", "1"], ["84083.3", "0", "0", "0"], ["84087.1", "0", "0", "0"], ["84087.2", "0.03505937", "0", "1"], ["84087.8", "0.03494037", "0", "2"], ["84087.9", "0.03516665", "0", "1"], ["84094.1", "0", "0", "0"], ["84094.2", "0.0673923", "0", "2"], ["84096.4", "0", "0", "0"], ["84096.5", "0.12184931", "0", "2"], ["84096.6", "0.0316952", "0", "1"], ["84097.1", "0", "0", "0"], ["84099.2", "0.23799878", "0", "1"], ["84101.1", "0", "0", "0"], ["84101.2", "0.06978901", "0", "1"], ["84102.3", "0", "0", "0"], ["84132.1", "0", "0", "0"], ["84244.1", "0.00083", "0", "1"], ["84244.3", "0.00605088", "0", "2"], ["84244.6", "0.5999", "0", "1"]], "bids": [["84076.6", "0.00816677", "0", "5"], ["84070", "0.2025", "0", "2"], ["84059.9", "0.03384738", "0", "1"], ["84059.8", "0", "0", "0"], ["84058.5", "0.21042321", "0", "2"], ["84058.4", "0", "0", "0"], ["84052.9", "0.39051669", "0", "2"], ["84052.8", "0", "0", "0"], ["84052.2", "0.03519881", "0", "1"], ["84052.1", "0", "0", "0"], ["84051", "0.03233308", "0", "1"], ["84050.9", "0.000015", "0", "1"], ["84050.4", "0.03177465", "0", "1"], ["84050.3", "0", "0", "0"], ["84045.9", "0.08757489", "0", "2"], ["84045.8", "0.20672021", "0", "3"], ["84042.8", "0.23799878", "0", "1"], ["84040.7", "0", "0", "0"], ["84015.6", "0", "0", "0"], ["83995.8", "0.01902212", "0", "1"], ["83921.7", "0.0535785", "0", "1"]], "ts": "1742555171004", "checksum": -77102839, "seqId": 49927499989, "prevSeqId": 49927499936}], "record_time": 1742555171.00486, "EXCHANGE": "OKX"}
{"arg": {"channel": "books", "instId": "BTC-USDT"}, "action": "update", "data": [{"asks": [["84101.6", "1.62579003", "0", "1"], ["84102.1", "0", "0", "0"], ["84102.2", "0", "0", "0"], ["84130.3", "0.12488", "0", "1"], ["84131.4", "3.15290043", "0", "3"], ["84164.1", "0.01774536", "0", "1"]], "bids": [["84047.9", "1.59372756", "0", "1"], ["84045.3", "0", "0", "0"], ["84018.1", "2.92572297", "0", "1"], ["84016.6", "0.74707063", "0", "2"], ["83921.7", "0", "0", "0"]], "ts": "1742555171104", "checksum": -77102839, "seqId": 49927499999, "prevSeqId": 49927499989}], "record_time": 1742555171.106634, "EXCHANGE": "OKX"}
{"arg": {"channel": "books", "instId": "BTC-USDT"}, "action": "update", "data": [{"asks": [["84089.3", "0", "0", "0"], ["84090.8", "1", "0", "1"], ["84128.6", "0", "0", "0"], ["84245.2", "1.89975034", "0", "2"]], "bids": [["84070", "0.20351854", "0", "3"], ["84049.5", "0.01774536", "0", "1"], ["84045.9", "0.06982953", "0", "1"], ["84026", "0.1", "0", "1"], ["83922.4", "0", "0", "0"], ["83922", "0", "0", "0"]], "ts": "1742555171204", "checksum": -920469808, "seqId": 49927500009, "prevSeqId": 49927499999}], "record_time": 1742555171.204424, "EXCHANGE": "OKX"}
{"arg": {"channel": "books", "instId": "BTC-USDT"}, "action": "update", "data": [{"asks": [], "bids": [["84070", "0.20453708", "0", "4"], ["84026", "0", "0", "0"], ["83922.4", "0.03", "0", "1"]], "ts": "1742555171304", "checksum": -627887974, "seqId": 49927500012, "prevSeqId": 49927500009}], "record_time": 1742555171.304782, "EXCHANGE": "OKX"}
{"arg": {"channel": "books", "instId": "BTC-USDT"}, "action": "update", "data": [{"asks": [["84101.5", "0.01974536", "0", "2"], ["84164.1", "0", "0", "0"], ["84245.5", "0.00009384", "0", "1"]], "bids": [["84070", "0.20555562", "0", "5"]], "ts": "1742555171404", "checksum": 991304887, "seqId": 49927500015, "prevSeqId": 49927500012}], "record_time": 1742555171.405917, "EXCHANGE": "OKX"}
{"arg": {"channel": "books", "instId": "BTC-USDT"}, "action": "update", "data": [{"asks": [], "bids": [["84070", "0.20759269", "0", "7"], ["84065.5", "0.0385515", "0", "1"], ["84061", "0.15901832", "0", "2"], ["83922.4", "0", "0", "0"]], "ts": "1742555171504", "checksum": 947937012, "seqId": 49927500020, "prevSeqId": 49927500015}], "record_time": 1742555171.505618, "EXCHANGE": "OKX"}
{"arg": {"channel": "books", "instId": "BTC-USDT"}, "action": "update", "data": [{"asks": [], "bids": [["84070", "0.20861123", "0", "8"], ["84058.8", "0.45745768", "0", "3"], ["84057", "0", "0", "0"], ["83922.4", "0.03", "0", "1"]], "ts": "1742555171604", "checksum": 504313894, "seqId": 49927500025, "prevSeqId": 49927500020}], "record_time": 1742555171.60477, "EXCHANGE": "OKX"}
{"arg": {"channel": "books", "instId": "BTC-USDT"}, "action": "update", "data": [{"asks": [["84076.7", "0.8931391", "0", "15"], ["84087.1", "0.03445949", "0", "1"], ["84087.2", "0", "0", "0"], ["84087.8", "0.06935732", "0", "3"], ["84087.9", "0", "0", "0"], ["84094.1", "0.06284339", "0", "2"], ["84094.2", "0", "0", "0"], ["84096.5", "0.15291464", "0", "3"], ["84096.6", "0", "0", "0"], ["84101.1", "0.06311241", "0", "1"], ["84101.2", "0", "0", "0"], ["84245.8", "0.00040029", "0", "4"], ["84246.3", "0.00083", "0", "1"]], "bids": [["84070", "0.00962977", "0", "8"], ["84059.9", "0", "0", "0"], ["84059.8", "0.03458563", "0", "1"], ["84058.5", "0.17821722", "0", "1"], ["84058.4", "0.03465796", "0", "1"], ["84052.9", "0.3568907", "0", "1"], ["84052.8", "0.03219234", "0", "1"], ["84052.2", "0", "0", "0"], ["84052.1", "0.03191585", "0", "1"], ["84050.4", "0", "0", "0"], ["84050.3", "0.03373275", "0", "1"], ["84045.9", "0", "0", "0"], ["84045.8", "0.27089808", "0", "4"], ["83960.1", "0", "0", "0"]], "ts": "1742555171704", "checksum": 1404464510, "seqId": 49927500054, "prevSeqId": 49927500025}], "record_time": 1742555171.705814, "EXCHANGE": "OKX"}
{"arg": {"channel": "books", "instId": "BTC-USDT"}, "action": "update", "data": [{"asks": [["84080", "0.0146", "0", "1"], ["84089.5", "1", "0", "1"], ["84090.8", "0", "0", "0"]], "bids": [["84037", "1", "0", "1"], ["83956.7", "0.00083", "0", "1"], ["83923", "0", "0", "0"], ["83922.4", "0", "0", "0"]], "ts": "1742555171804", "checksum": 2055431961, "seqId": 49927500061, "prevSeqId": 49927500054}], "record_time": 1742555171.804565, "EXCHANGE": "OKX"}
{"arg": {"channel": "books", "instId": "BTC-USDT"}, "action": "update", "data": [{"asks": [["84088.4", "0.17092757", "0", "1"], ["84089.2", "1", "0", "1"], ["84089.5", "0", "0", "0"], ["84092.5", "0.54768878", "0", "5"], ["84101.5", "0.75198435", "0", "3"], ["84131.2", "1.45639919", "0", "1"], ["84246.3", "0", "0", "0"]], "bids": [["84049.4", "0.69849997", "0", "2"], ["84037", "0", "0", "0"], ["84020.4", "1.10315764", "0", "2"], ["83992.6", "0.55930815", "0", "1"]], "ts": "1742555171904", "checksum": 2055431961, "seqId": 49927500079, "prevSeqId": 49927500061}], "record_time": 1742555171.904926, "EXCHANGE": "OKX"}
{"arg": {"channel": "books", "instId": "BTC-USDT"}, "action": "update", "data": [{"asks": [["84088.4", "0.44956162", "0", "2"], ["84092.5", "0.25781015", "0", "4"], ["84096.8", "0.24800061", "0", "3"], ["84099.2", "0", "0", "0"], ["84113.6", "0.25821722", "0", "3"], ["84114.4", "0.03999999", "0", "1"], ["84115.2", "0.00001197", "0", "1"], ["84246.3", "0.00083", "0", "1"]], "bids": [["84057", "0.35682", "0", "1"], ["84042.8", "0", "0", "0"], ["84040.7", "0.23800097", "0", "1"], ["83924.2", "0", "0", "0"]], "ts": "1742555172004", "checksum": 2055431961, "seqId": 49927500104, "prevSeqId": 49927500079}], "record_time": 1742555172.005652, "EXCHANGE": "OKX"}
{"arg": {"channel": "books", "instId": "BTC-USDT"}, "action": "update", "data": [{"asks": [["84096.4", "0.23800075", "0", "1"], ["84096.8", "0.01", "0", "2"], ["84112", "0.11890903", "0", "1"], ["84113.6", "0.17821722", "0", "1"], ["84114.4", "0.07999999", "0", "2"], ["84115.2", "0.04001196", "0", "2"], ["84141.1", "0.01128912", "0", "1"], ["84246.3", "0", "0", "0"]], "bids": [["84059.6", "0", "0", "0"], ["84058", "1", "0", "1"], ["84040.7", "0.23800075", "0", "1"], ["84024.3", "0", "0", "0"], ["84023.8", "0.01832618", "0", "1"], ["83952.4", "0.18326187", "0", "1"], ["83948.1", "0", "0", "0"], ["83946.2", "0.00201766", "0", "1"]], "ts": "1742555172104", "checksum": 2055431961, "seqId": 49927500181, "prevSeqId": 49927500104}], "record_time": 1742555172.104783, "EXCHANGE": "OKX"}
{"arg": {"channel": "books", "instId": "BTC-USDT"}, "action": "update", "data": [{"asks": [["84076.7", "1.00578467", "0", "16"], ["84082.6", "0.00348775", "0", "1"], ["84096", "0.23800208", "0", "1"], ["84096.4", "0.03453551", "0", "1"], ["84096.5", "0.12097544", "0", "2"], ["84101.5", "0.74998435", "0", "2"], ["84111.5", "0", "0", "0"], ["84245.8", "0", "0", "0"]], "bids": [["84076.5", "0", "0", "0"], ["84068.1", "0", "0", "0"], ["84066.4", "0.00773104", "0", "1"], ["84063", "0.45285917", "0", "3"], ["84062", "0.01190211", "0", "1"], ["84059.5", "0.35682", "0", "1"], ["84058.8", "0.83538207", "0", "4"], ["84051", "0", "0", "0"], ["84050.9", "0.03130237", "0", "2"], ["84040.7", "0.23800208", "0", "1"], ["83982.1", "0", "0", "0"], ["83967.9", "0.01219936", "0", "2"], ["83924.2", "0.000015", "0", "1"], ["83923", "0.00001987", "0", "1"], ["83922.4", "0.03", "0", "1"]], "ts": "1742555172204", "checksum": -134384099, "seqId": 49927500218, "prevSeqId": 49927500181}], "record_time": 1742555172.205163, "EXCHANGE": "OKX"}
{"arg": {"channel": "books", "instId": "BTC-USDT"}, "action": "update", "data": [{"asks": [], "bids": [["84059.6", "0.133612", "0", "1"], ["84058", "0", "0", "0"], ["84057", "0", "0", "0"], ["84056.4", "1", "0", "1"], ["84040.7", "0", "0", "0"], ["84039.4", "0.23800368", "0", "1"], ["83986.7", "0", "0", "0"], ["83922", "0.00001197", "0", "1"]], "ts": "1742555172304", "checksum": -134384099, "seqId": 49927500234, "prevSeqId": 49927500218}], "record_time": 1742555172.304752, "EXCHANGE": "OKX"}
{"arg": {"channel": "books", "instId": "BTC-USDT"}, "action": "update", "data": [{"asks": [["84113.6", "0.25821722", "0", "3"], ["84114.4", "0.03999999", "0", "1"], ["84115.2", "0.00001197", "0", "1"]], "bids": [["84076.6", "0.00776677", "0", "4"], ["84057.7", "1", "0", "1"], ["84056.4", "0", "0", "0"], ["83986.7", "0.00016249", "0", "1"], ["83922", "0", "0", "0"]], "ts": "1742555172404", "checksum": -390718901, "seqId": 49927500243, "prevSeqId": 49927500234}], "record_time": 1742555172.405067, "EXCHANGE": "OKX"}
{"arg": {"channel": "books", "instId": "BTC-USDT"}, "action": "update", "data": [{"asks": [["84113.6", "0.17821722", "0", "1"], ["84114.4", "0.60860999", "0", "3"], ["84115.2", "0.04001196", "0", "2"], ["84134.9", "0", "0", "0"], ["84135", "0.00001197", "0", "1"], ["84139.3", "3.17888", "0", "1"]], "bids": [["84059.7", "0.03154105", "0", "1"], ["84051.2", "0", "0", "0"], ["84039.4", "0", "0", "0"], ["84037.7", "0.238004", "0", "1"], ["83922", "0.00001197", "0", "1"]], "ts": "1742555172504", "checksum": -390718901, "seqId": 49927500261, "prevSeqId": 49927500243}], "record_time": 1742555172.504209, "EXCHANGE": "OKX"}
{"arg": {"channel": "books", "instId": "BTC-USDT"}, "action": "update", "data": [{"asks": [["84101.5", "0.75198435", "0", "3"], ["84107", "1", "0", "1"], ["84111.5", "0.002", "0", "1"], ["84113.6", "0.25821722", "0", "3"], ["84114.4", "0.56860999", "0", "2"], ["84115.2", "0.00001197", "0", "1"], ["84245.2", "0", "0", "0"], ["84245.5", "0", "0", "0"]], "bids": [["84074.7", "0.002", "0", "1"], ["84070", "0.0106483", "0", "9"], ["84064.8", "0.0814556", "0", "1"], ["84064.6", "0.002", "0", "1"], ["84040.7", "0.23800226", "0", "1"], ["84037.7", "0", "0", "0"], ["83922.4", "0", "0", "0"], ["83922", "0", "0", "0"]], "ts": "1742555172604", "checksum": -1231892966, "seqId": 49927500275, "prevSeqId": 49927500261}], "record_time": 1742555172.60468, "EXCHANGE": "OKX"}
{"arg": {"channel": "books", "instId": "BTC-USDT"}, "action": "update", "data": [{"asks": [], "bids": [["84058.8", "0.45745768", "0", "3"], ["84057.7", "0", "0", "0"], ["83922.4", "0.03", "0", "1"]], "ts": "1742555172704", "checksum": -1231892966, "seqId": 49927500277, "prevSeqId": 49927500275}], "record_time": 1742555172.70472, "EXCHANGE": "OKX"}
{"arg": {"channel": "books", "instId": "BTC-USDT"}, "action": "update", "data": [{"asks": [["84076.7", "0.8931391", "0", "15"], ["84096", "0", "0", "0"], ["84097.8", "0.23799937", "0", "1"]], "bids": [["84063", "0.87115529", "0", "4"], ["84059.1", "1.03269475", "0", "2"], ["84042.3", "0.23799937", "0", "1"], ["84040.7", "0", "0", "0"]], "ts": "1742555172804", "checksum": 856193475, "seqId": 49927500287, "prevSeqId": 49927500277}], "record_time": 1742555172.804342, "EXCHANGE": "OKX"}
{"arg": {"channel": "books", "instId": "BTC-USDT"}, "action": "update", "data": [{"asks": [["84096.3", "0.23800075", "0", "1"], ["84097.8", "0", "0", "0"], ["84114.3", "0.33520081", "0", "1"], ["84138.9", "1.25570765", "0", "2"], ["84244.6", "0", "0", "0"]], "bids": [["84076.6", "0.00812677", "0", "5"], ["84045.9", "0.37402233", "0", "1"], ["84042.3", "0", "0", "0"], ["84040.7", "0.23800075", "0", "1"], ["84007.4", "0.91613799", "0", "1"], ["83992.6", "0", "0", "0"], ["83991.6", "1.48377", "0", "1"], ["83986.7", "0", "0", "0"], ["83922", "0.00001197", "0", "1"]], "ts": "1742555172904", "checksum": 1117472923, "seqId": 49927500308, "prevSeqId": 49927500287}], "record_time": 1742555172.905456, "EXCHANGE": "OKX"}
{"arg": {"channel": "books", "instId": "BTC-USDT"}, "action": "update", "data": [{"asks": [["84080.6", "0.08991011", "0", "1"], ["84096", "0.23800266", "0", "1"], ["84096.3", "0", "0", "0"], ["84244.3", "0", "0", "0"]], "bids": [["84069.9", "0", "0", "0"], ["84059.4", "0.00362054", "0", "1"], ["84040.7", "0", "0", "0"], ["84039.9", "0.23800266", "0", "1"], ["83986.7", "0.00016248", "0", "1"], ["83922", "0", "0", "0"]], "ts": "1742555173004", "checksum": 23314889, "seqId": 49927500322, "prevSeqId": 49927500308}], "record_time": 1742555173.005039, "EXCHANGE": "OKX"}
{"arg": {"channel": "books", "instId": "BTC-USDT"}, "action": "update", "data": [{"asks": [["84076.7", "0.93203462", "0", "16"], ["84078.5", "0.27472535", "0", "6"], ["84079.9", "0.04465811", "0", "2"], ["84086.5", "0.03081701", "0", "1"], ["84087.1", "0", "0", "0"], ["84087.2", "0.06508558", "0", "2"], ["84087.3", "0.39019676", "0", "2"], ["84087.7", "0", "0", "0"], ["84087.8", "0.0000375", "0", "1"], ["84092.5", "0.33826698", "0", "5"], ["84093.5", "0.06699626", "0", "2"], ["84094.1", "0", "0", "0"], ["84094.3", "0.23800818", "0", "1"], ["84094.4", "0.11235012", "0", "2"], ["84096", "0.03352744", "0", "1"], ["84096.1", "0.21128451", "0", "2"], ["84096.4", "0", "0", "0"], ["84096.5", "0.08991011", "0", "1"], ["84100.5", "0.06898245", "0", "1"], ["84101.1", "0", "0", "0"], ["84102.7", "0.06274276", "0", "1"], ["84103", "0.12262665", "0", "3"], ["84103.2", "0", "0", "0"], ["84103.6", "0", "0", "0"], ["84104.7", "0.06324285", "0", "1"], ["84105.2", "0.00001197", "0", "1"], ["84107", "1.2", "0", "2"], ["84147", "0.08352541", "0", "2"]], "bids": [["84059.8", "0", "0", "0"], ["84059.7", "0", "0", "0"], ["84059.5", "0", "0", "0"], ["84059.2", "0.07894573", "0", "3"], ["84059.1", "1", "0", "1"], ["84058.6", "0.03371212", "0", "1"], ["84058.4", "0", "0", "0"], ["84057.8", "0.0337637", "0", "1"], ["84052.8", "0", "0", "0"], ["84052.2", "0.03192931", "0", "1"], ["84052.1", "0", "0", "0"], ["84051.5", "0.03471301", "0", "1"], ["84050.9", "0.000015", "0", "1"], ["84050.5", "0.03106633", "0", "2"], ["84050.3", "0", "0", "0"], ["84049.9", "0.03212209", "0", "2"], ["84049.3", "0", "0", "0"], ["84045.9", "0", "0", "0"], ["84045.8", "0.20672021", "0", "3"], ["84045.2", "0.06172037", "0", "1"], ["84043.7", "0", "0", "0"], ["84043.2", "0.07026784", "0", "1"], ["84042.7", "0", "0", "0"], ["84042.2", "0", "0", "0"], ["84042.1", "0.06762906", "0", "1"], ["84041.7", "0.06760393", "0", "1"], ["84039.9", "0", "0", "0"], ["84037.7", "0.23800818", "0", "1"], ["83922", "0.00001197", "0", "1"], ["83921.7", "0.0535785", "0", "1"], ["83921.3", "0.0016853", "0", "2"], ["83921", "0.00001002", "0", "1"]], "ts": "1742555173104", "checksum": -1935035110, "seqId": 49927500396, "prevSeqId": 49927500322}], "record_time": 1742555173.105073, "EXCHANGE": "OKX"}
{"arg": {"channel": "books", "instId": "BTC-USDT"}, "action": "update", "data": [{"asks": [["84070.1", "1.58260459", "0", "17"], ["84071.9", "0.0128655", "0", "1"], ["84072", "0.0146", "0", "1"], ["84073.3", "0.001784", "0", "1"], ["84073.9", "0.011901", "0", "1"], ["84074", "0.0146", "0", "1"], ["84075.7", "0.00111914", "0", "1"], ["84075.8", "0.01055", "0", "1"], ["84076", "0.0146", "0", "1"], ["84076.5", "0.14354561", "0", "1"], ["84076.6", "0.002", "0", "1"], ["84076.7", "0.11002928", "0", "4"], ["84077", "0", "0", "0"], ["84077.9", "0", "0", "0"], ["84078.5", "0.26282487", "0", "5"], ["84079.3", "0", "0", "0"], ["84079.9", "0.07990141", "0", "1"], ["84080.4", "0.03168197", "0", "2"], ["84081.4", "0.000015", "0", "1"], ["84081.5", "0.03399651", "0", "1"], ["84082.3", "0.03404151", "0", "1"], ["84082.4", "0.06388427", "0", "2"], ["84082.7", "0", "0", "0"], ["84084.4", "0", "0", "0"], ["84084.5", "0", "0", "0"], ["84084.9", "0", "0", "0"], ["84086.5", "0", "0", "0"], ["84087.2", "0", "0", "0"], ["84087.3", "0.35681", "0", "1"], ["84088.5", "0.39010069", "0", "2"], ["84088.7", "0.16271696", "0", "3"], ["84091", "0.03299189", "0", "1"], ["84091.1", "0.03153134", "0", "1"], ["84093.5", "0", "0", "0"], ["84094.3", "0", "0", "0"], ["84095.4", "0.23800647", "0", "1"], ["84095.5", "0.06694988", "0", "1"], ["84096", "0", "0", "0"], ["84096.1", "0.17821722", "0", "1"], ["84096.7", "0.08354", "0", "1"], ["84097.8", "0.07078184", "0", "1"], ["84098", "0", "0", "0"], ["84098.1", "0.42146088", "0", "2"], ["84099.8", "0.06860854", "0", "1"], ["84100.1", "0", "0", "0"], ["84100.5", "0", "0", "0"], ["84102.7", "0", "0", "0"], ["84103", "0.052", "0", "2"], ["84104.7", "0", "0", "0"], ["84107", "1", "0", "1"], ["84109.2", "0.47358537", "0", "1"], ["84111", "0", "0", "0"], ["84121.2", "0", "0", "0"], ["84126.7", "0", "0", "0"], ["84127.9", "0", "0", "0"], ["84128.7", "0", "0", "0"], ["84130.6", "0", "0", "0"], ["84146.6", "0.35641581", "0", "1"], ["84149.7", "0", "0", "0"], ["84210.6", "0.21299237", "0", "1"], ["84227.8", "0", "0", "0"], ["84234.2", "0.01188711", "0", "1"], ["84238.3", "0.01188708", "0", "1"], ["84239.7", "0.01652", "0", "1"]], "bids": [["84076.6", "0", "0", "0"], ["84075.7", "0", "0", "0"], ["84075.6", "0", "0", "0"], ["84074.7", "0", "0", "0"], ["84073.9", "0", "0", "0"], ["84073.2", "0", "0", "0"], ["84072.6", "0", "0", "0"], ["84070.6", "0", "0", "0"], ["84069.4", "0", "0", "0"], ["84067.1", "0.00055965", "0", "1"], ["84066.5", "0.021901", "0", "3"], ["84066.4", "0", "0", "0"], ["84066.3", "0", "0", "0"], ["84065.2", "0.00773164", "0", "1"], ["84064.9", "0.009", "0", "1"], ["84064.8", "0.0393243", "0", "1"], ["84064.7", "0", "0", "0"], ["84064.5", "0.00773087", "0", "1"], ["84063", "0.45285917", "0", "3"], ["84062.4", "0", "0", "0"], ["84062.2", "0", "0", "0"], ["84061.9", "0", "0", "0"], ["84059.4", "0", "0", "0"], ["84059.2", "0.0134", "0", "1"], ["84059.1", "0", "0", "0"], ["84058.8", "0.51958142", "0", "2"], ["84058.6", "0", "0", "0"], ["84057.8", "0", "0", "0"], ["84057.4", "1", "0", "1"], ["84056.1", "0.0134", "0", "1"], ["84055.8", "0.00006", "0", "1"], ["84054.3", "0.03186354", "0", "1"], ["84054.2", "0.03494408", "0", "1"], ["84054.1", "0", "0", "0"], ["84053.7", "0.03524012", "0", "1"], ["84053", "0.03293098", "0", "1"], ["84052.2", "0", "0", "0"], ["84051.5", "0.14043766", "0", "1"], ["84050.5", "0.000015", "0", "1"], ["84049.9", "0.00060645", "0", "1"], ["84049.7", "0.04021", "0", "1"], ["84049.4", "0.25186481", "0", "1"], ["84048.6", "0", "0", "0"], ["84048", "0.18725022", "0", "1"], ["84047.9", "0", "0", "0"], ["84047.2", "0.03408527", "0", "1"], ["84046.7", "0.03459661", "0", "1"], ["84045.5", "0.03201317", "0", "1"], ["84045.2", "0", "0", "0"], ["84044.9", "0.03359641", "0", "1"], ["84043.2", "0", "0", "0"], ["84042.1", "0", "0", "0"], ["84041.8", "0.17842", "0", "1"], ["84041.7", "0", "0", "0"], ["84040.7", "0.23800647", "0", "1"], ["84040.2", "0.06589034", "0", "1"], ["84040.1", "0.00357", "0", "1"], ["84040", "0.00001", "0", "1"], ["84039.2", "0", "0", "0"], ["84038.4", "0", "0", "0"], ["84038.3", "0.06335298", "0", "1"], ["84037.7", "0", "0", "0"], ["84037.6", "0.2789532", "0", "3"], ["84037.2", "0.06736205", "0", "1"], ["84036.8", "0.13568127", "0", "4"], ["84036", "0.014784", "0", "2"], ["84035.2", "0", "0", "0"], ["84033.6", "0.1", "0", "2"], ["84032.8", "0.05", "0", "1"], ["84026.8", "0", "0", "0"], ["84022.1", "0.02377349", "0", "2"], ["84021.5", "0.13079597", "0", "2"], ["84021.4", "0.01188695", "0", "1"], ["84021.3", "0.01188696", "0", "1"], ["84020.5", "0.01188708", "0", "1"], ["84020.4", "0.17438074", "0", "1"], ["84020.3", "0.21438711", "0", "2"], ["84018.1", "0", "0", "0"], ["84014.2", "0", "0", "0"], ["84010.6", "0", "0", "0"], ["84007.5", "0.00285291", "0", "1"], ["84005.8", "0.00357", "0", "1"], ["84003.9", "0.00105288", "0", "1"], ["83991.6", "1.48987016", "0", "2"], ["83983.7", "0.00611517", "0", "2"], ["83982.1", "0.10931709", "0", "1"], ["83979.1", "0.01219991", "0", "2"], ["83973.8", "0.01219991", "0", "2"], ["83968", "0.00610016", "0", "1"], ["83963.3", "0.00580015", "0", "1"], ["83934", "0", "0", "0"], ["83933.2", "0.59432247", "0", "1"], ["83920", "0.00001096", "0", "1"]], "ts": "1742555173204", "checksum": 777476602, "seqId": 49927500887, "prevSeqId": 49927500396}], "record_time": 1742555173.205404, "EXCHANGE": "OKX"}
{"arg": {"channel": "books", "instId": "BTC-USDT"}, "action": "update", "data": [{"asks": [["84070.1", "1.67196811", "0", "20"], ["84114.6", "0.1", "0", "1"], ["84164.5", "0.02071925", "0", "2"], ["84244.1", "0", "0", "0"]], "bids": [["84064.9", "0", "0", "0"], ["84059.9", "0.0044625", "0", "1"], ["84054.6", "0.35749109", "0", "2"], ["84054.5", "0.35685", "0", "1"], ["84049.5", "0", "0", "0"], ["84041.8", "0", "0", "0"], ["84031.1", "0", "0", "0"], ["84023", "0.1", "0", "1"], ["84020.2", "0.1", "0", "1"], ["84016.7", "0.01774536", "0", "1"], ["83946.2", "0", "0", "0"], ["83939.6", "0.00201765", "0", "1"], ["83920", "0", "0", "0"]], "ts": "1742555173304", "checksum": -1779614757, "seqId": 49927500916, "prevSeqId": 49927500887}], "record_time": 1742555173.305725, "EXCHANGE": "OKX"}
{"arg": {"channel": "books", "instId": "BTC-USDT"}, "action": "update", "data": [{"asks": [["84070.1", "1.68251811", "0", "21"], ["84074.8", "0.03167", "0", "1"], ["84075.8", "0", "0", "0"], ["84080.4", "0.00001197", "0", "1"], ["84105.1", "0", "0", "0"], ["84124.9", "0.00004312", "0", "1"], ["84130.2", "0", "0", "0"], ["84244.1", "0.00083", "0", "1"]], "bids": [["84070", "0.0106783", "0", "10"], ["84059.9", "0", "0", "0"], ["84056.3", "0.17842", "0", "1"], ["84045.3", "1.54205986", "0", "1"], ["84044.3", "0.53421296", "0", "2"], ["84040.7", "0", "0", "0"], ["84038.4", "0.23800612", "0", "1"], ["84023", "0", "0", "0"], ["84015.9", "2.7130948", "0", "1"], ["83987.6", "0.01484", "0", "1"], ["83986.7", "0", "0", "0"], ["83980.6", "0.00017447", "0", "2"], ["83921", "0", "0", "0"]], "ts": "1742555173404", "checksum": 757214984, "seqId": 49927500943, "prevSeqId": 49927500916}], "record_time": 1742555173.405084, "EXCHANGE": "OKX"}
{"arg": {"channel": "books", "instId": "BTC-USDT"}, "action": "update", "data": [{"asks": [["84081.4", "0.03340516", "0", "2"], ["84081.5", "0", "0", "0"], ["84082.3", "0.06564316", "0", "2"], ["84082.4", "0.03144166", "0", "1"], ["84087.8", "0", "0", "0"], ["84088.4", "0.48438972", "0", "3"], ["84088.5", "0.35641581", "0", "1"], ["84088.6", "0.03406233", "0", "1"], ["84088.7", "0.12930313", "0", "2"], ["84095.4", "0.29999764", "0", "2"], ["84095.5", "0", "0", "0"], ["84098", "0.07089724", "0", "1"], ["84098.1", "0.35641581", "0", "1"], ["84244.3", "0.00605088", "0", "2"]], "bids": [["84064.8", "0", "0", "0"], ["84063", "0.35124828", "0", "3"], ["84058.5", "0.18385122", "0", "2"], ["84054.2", "0", "0", "0"], ["84054.1", "0.03331038", "0", "1"], ["84053", "0", "0", "0"], ["84052.9", "0.39002728", "0", "2"], ["84047.2", "0", "0", "0"], ["84047.1", "0.24321388", "0", "2"], ["84046.7", "0", "0", "0"], ["84046.6", "0.03501904", "0", "2"], ["84040.2", "0", "0", "0"], ["84040.1", "0.06527248", "0", "2"], ["84037.6", "0.1989532", "0", "1"], ["84037.2", "0", "0", "0"], ["84037.1", "0.06620142", "0", "1"], ["84036.8", "0.17568127", "0", "5"], ["84036", "0.054784", "0", "3"], ["83921", "0.00001002", "0", "1"], ["83920", "0.00001096", "0", "1"], ["83919.2", "0.00003545", "0", "1"], ["83918.9", "0.00001197", "0", "1"], ["83918.3", "0.2025", "0", "1"]], "ts": "1742555173504", "checksum": 1499420892, "seqId": 49927500978, "prevSeqId": 49927500943}], "record_time": 1742555173.504859, "EXCHANGE": "OKX"}
{"arg": {"channel": "books", "instId": "BTC-USDT"}, "action": "update", "data": [{"asks": [], "bids": [["84070", "0.01079507", "0", "11"], ["84045.9", "0.01774536", "0", "1"], ["84016.7", "0", "0", "0"]], "ts": "1742555173604", "checksum": -1369730065, "seqId": 49927500982, "prevSeqId": 49927500978}], "record_time": 1742555173.605794, "EXCHANGE": "OKX"}
{"arg": {"channel": "books", "instId": "BTC-USDT"}, "action": "update", "data": [{"asks": [["84081.4", "0.000015", "0", "1"], ["84081.5", "0.03161021", "0", "1"], ["84082.2", "0.00564", "0", "1"], ["84082.3", "0.03404151", "0", "1"], ["84082.4", "0.0632129", "0", "2"], ["84088.4", "0.44956162", "0", "2"], ["84088.5", "0.38822385", "0", "2"], ["84088.6", "0", "0", "0"], ["84088.7", "0.16016734", "0", "3"], ["84091", "0", "0", "0"], ["84091.1", "0.03121044", "0", "1"], ["84091.2", "0.03460577", "0", "1"], ["84095.4", "0.23800647", "0", "1"], ["84095.5", "0.06575928", "0", "1"], ["84098", "0", "0", "0"], ["84098.2", "0.0639386", "0", "2"], ["84244.3", "0", "0", "0"]], "bids": [["84066.6", "0.03164368", "0", "5"], ["84058.7", "1.042", "0", "2"], ["84057.4", "0", "0", "0"], ["84054.2", "0.0313242", "0", "1"], ["84054.1", "0", "0", "0"], ["84053", "0.03461362", "0", "1"], ["84052.9", "0.3568907", "0", "1"], ["84047.2", "0.03103168", "0", "1"], ["84047.1", "0.20908", "0", "1"], ["84046.7", "0.03504653", "0", "1"], ["84046.6", "0.00009543", "0", "1"], ["84045.6", "0.03368607", "0", "1"], ["84045.5", "0", "0", "0"], ["84045", "0.03526522", "0", "2"], ["84044.9", "0", "0", "0"], ["84041.8", "0.17842", "0", "1"], ["84040.2", "0.06453951", "0", "1"], ["84040.1", "0.00357", "0", "1"], ["84037.3", "0.2708344", "0", "2"], ["84037.1", "0", "0", "0"], ["83918.9", "0", "0", "0"], ["83918.3", "0", "0", "0"]], "ts": "1742555173704", "checksum": -450066110, "seqId": 49927501025, "prevSeqId": 49927500982}], "record_time": 1742555173.706866, "EXCHANGE": "OKX"}
{"arg": {"channel": "books", "instId": "BTC-USDT"}, "action": "update", "data": [{"asks": [["84081.5", "0", "0", "0"], ["84081.6", "0.03143227", "0", "1"], ["84082.4", "0.06664965", "0", "2"], ["84088.5", "0.35641581", "0", "1"], ["84088.6", "0.03192117", "0", "1"], ["84088.7", "0.16124644", "0", "3"], ["84091", "0.03332628", "0", "1"], ["84091.1", "0.03535118", "0", "1"], ["84091.2", "0", "0", "0"], ["84095.5", "0", "0", "0"], ["84095.6", "0.06133678", "0", "1"], ["84098.2", "0.07083412", "0", "2"], ["84113.6", "0.25821721", "0", "3"], ["84244.1", "0", "0", "0"]], "bids": [["84066.6", "0.00504382", "0", "4"], ["84065.6", "0.05050924", "0", "1"], ["84060.3", "0.009", "0", "1"], ["84058.5", "0.17821722", "0", "1"], ["84054.3", "0.06600179", "0", "2"], ["84054.2", "0", "0", "0"], ["84053", "0.03158762", "0", "1"], ["84047.3", "0.03381097", "0", "1"], ["84047.2", "0", "0", "0"], ["84046.7", "0.03505949", "0", "1"], ["84045.6", "0", "0", "0"], ["84045.5", "0.03194682", "0", "1"], ["84045", "0.00001", "0", "1"], ["84044.9", "0.0321499", "0", "1"], ["84040.3", "0.06218471", "0", "1"], ["84040.2", "0", "0", "0"], ["84037.3", "0.26552832", "0", "2"], ["83983", "0", "0", "0"], ["83978.9", "0", "0", "0"], ["83972.7", "0.00007198", "0", "1"], ["83962.1", "0.0007199", "0", "1"], ["83920", "0", "0", "0"], ["83919.2", "0", "0", "0"]], "ts": "1742555173804", "checksum": 1634521814, "seqId": 49927501102, "prevSeqId": 49927501025}], "record_time": 1742555173.80619, "EXCHANGE": "OKX"}
{"arg": {"channel": "books", "instId": "BTC-USDT"}, "action": "update", "data": [{"asks": [["84101.5", "0.01974536", "0", "2"], ["84101.6", "0", "0", "0"], ["84105.7", "0.64814789", "0", "2"], ["84131.2", "0", "0", "0"], ["84131.4", "0.1947926", "0", "2"], ["84134.5", "0.06068166", "0", "1"], ["84244.1", "0.00083", "0", "1"]], "bids": [["84070", "0.01069507", "0", "12"], ["84058.4", "0.000345", "0", "1"], ["84045.3", "0", "0", "0"], ["84015.9", "0", "0", "0"], ["84000.4", "0.00421334", "0", "1"], ["83986.4", "0.10922386", "0", "1"], ["83983.4", "0.07968667", "0", "2"]], "ts": "1742555173904", "checksum": -980078010, "seqId": 49927501125, "prevSeqId": 49927501102}], "record_time": 1742555173.904815, "EXCHANGE": "OKX"}
{"arg": {"channel": "books", "instId": "BTC-USDT"}, "action": "update", "data": [{"asks": [["84070.1", "1.58127531", "0", "20"], ["84079.9", "0.07806036", "0", "2"], ["84081.6", "0", "0", "0"], ["84082.1", "0.03437827", "0", "1"], ["84082.2", "0", "0", "0"], ["84082.3", "0", "0", "0"], ["84082.4", "0", "0", "0"], ["84082.5", "0.03289381", "0", "1"], ["84082.6", "0.03744967", "0", "2"], ["84082.8", "0.03213097", "0", "1"], ["84084.6", "0.00564", "0", "1"], ["84088.6", "0", "0", "0"], ["84088.7", "0.12930313", "0", "2"], ["84089.1", "0.0673247", "0", "2"], ["84091", "0", "0", "0"], ["84091.1", "0", "0", "0"], ["84091.3", "0.06534829", "0", "2"], ["84095.4", "0", "0", "0"], ["84095.6", "0", "0", "0"], ["84096", "0.23800326", "0", "1"], ["84096.1", "0.24768701", "0", "2"], ["84096.9", "1.9635397", "0", "2"], ["84097.8", "0", "0", "0"], ["84098", "0.07004304", "0", "1"], ["84098.2", "0.000015", "0", "1"], ["84098.5", "0.07011642", "0", "1"], ["84099.8", "0", "0", "0"], ["84100", "0.07079475", "0", "2"], ["84101.5", "0.002", "0", "1"], ["84105.6", "0.01774536", "0", "1"], ["84126.3", "2.93043379", "0", "1"]], "bids": [["84059.3", "0.00355594", "0", "2"], ["84054.8", "0.23492478", "0", "2"], ["84054.5", "0.39164918", "0", "2"], ["84054.3", "0", "0", "0"], ["84053.9", "0.03229915", "0", "1"], ["84053.7", "0", "0", "0"], ["84053.4", "0.03376562", "0", "1"], ["84053", "0", "0", "0"], ["84047.8", "0.03345533", "0", "1"], ["84047.3", "0", "0", "0"], ["84047.1", "0.24010264", "0", "2"], ["84046.7", "0", "0", "0"], ["84045.9", "0", "0", "0"], ["84045.8", "0.24114957", "0", "4"], ["84045.5", "0", "0", "0"], ["84045.1", "0.03307313", "0", "2"], ["84044.9", "0", "0", "0"], ["84044.7", "1.59882977", "0", "1"], ["84041.8", "0", "0", "0"], ["84040.8", "0.06378303", "0", "1"], ["84040.7", "0.01774536", "0", "1"], ["84040.3", "0", "0", "0"], ["84038.6", "0.23800558", "0", "1"], ["84038.5", "0.06906845", "0", "1"], ["84038.4", "0", "0", "0"], ["84038.3", "0", "0", "0"], ["84037.6", "0.34440952", "0", "4"], ["84037.3", "0.2025", "0", "1"], ["84037", "0.06419157", "0", "1"], ["84036.8", "0.066", "0", "3"], ["84036", "0.014784", "0", "2"], ["84015.3", "2.9231505", "0", "1"], ["83920", "0.00001096", "0", "1"], ["83919.2", "0.00003545", "0", "1"]], "ts": "1742555174004", "checksum": -900663750, "seqId": 49927501217, "prevSeqId": 49927501125}], "record_time": 1742555174.005054, "EXCHANGE": "OKX"}
{"arg": {"channel": "books", "instId": "BTC-USDT"}, "action": "update", "data": [{"asks": [["84070.1", "1.22796549", "0", "14"], ["84071.9", "0.04958796", "0", "2"], ["84072", "0.13360284", "0", "2"], ["84073.1", "0.01055", "0", "1"], ["84073.3", "0", "0", "0"], ["84074.8", "0", "0", "0"], ["84076.7", "0.07402928", "0", "3"], ["84079.4", "0.03167", "0", "1"], ["84079.9", "0.05410854", "0", "2"], ["84080.6", "0", "0", "0"], ["84082.1", "0", "0", "0"], ["84082.5", "0", "0", "0"], ["84082.6", "0.00348775", "0", "1"], ["84082.8", "0", "0", "0"], ["84083.3", "0.03155498", "0", "1"], ["84083.7", "0.06525798", "0", "2"], ["84083.9", "0.03538394", "0", "1"], ["84084.6", "0", "0", "0"], ["84086.9", "0", "0", "0"], ["84089.1", "0", "0", "0"], ["84089.2", "0", "0", "0"], ["84090.2", "0.03487503", "0", "1"], ["84090.3", "0.03133819", "0", "1"], ["84091", "1", "0", "1"], ["84091.3", "0", "0", "0"], ["84092.4", "0.03280702", "0", "1"], ["84092.5", "0.29135747", "0", "5"], ["84096", "0", "0", "0"], ["84096.1", "0.17821722", "0", "1"], ["84097.3", "0.06408158", "0", "1"], ["84098", "0", "0", "0"], ["84098.5", "0", "0", "0"], ["84099.1", "0.06842701", "0", "1"], ["84099.7", "0.06661155", "0", "1"], ["84100", "0.00055921", "0", "1"], ["84101.1", "0.23799532", "0", "1"], ["84101.2", "0.06279278", "0", "1"], ["84105.7", "0.42029712", "0", "1"], ["84107", "0", "0", "0"], ["84117", "0.001784", "0", "1"], ["84138.8", "0.01128873", "0", "1"], ["84141.1", "0", "0", "0"], ["84178.1", "0.23960232", "0", "2"]], "bids": [["84070", "0.7411362", "0", "17"], ["84059.7", "0.0134", "0", "1"], ["84058.8", "0.69800142", "0", "3"], ["84056.1", "0", "0", "0"], ["84056", "0.03061222", "0", "1"], ["84055.7", "0.03230851", "0", "2"], ["84055", "0.03391", "0", "1"], ["84054.8", "0.2025", "0", "1"], ["84054.5", "0.38990896", "0", "2"], ["84054.4", "0.04021", "0", "1"], ["84053.9", "0", "0", "0"], ["84053.4", "0", "0", "0"], ["84049.7", "0", "0", "0"], ["84049", "0.03116228", "0", "1"], ["84048.2", "0.03277114", "0", "1"], ["84047.8", "0", "0", "0"], ["84047.1", "0.20908", "0", "1"], ["84046.9", "0.03350492", "0", "1"], ["84046.3", "0.03146214", "0", "1"], ["84045.8", "0.20672021", "0", "3"], ["84045.1", "0.00005207", "0", "1"], ["84044.3", "0.35579296", "0", "1"], ["84042.1", "0.23799562", "0", "1"], ["84042", "0.17725076", "0", "3"], ["84040.8", "0", "0", "0"], ["84039.6", "0.06270757", "0", "1"], ["84038.8", "0.06244157", "0", "1"], ["84038.6", "0", "0", "0"], ["84038.5", "0", "0", "0"], ["84038.2", "0.08273297", "0", "2"], ["84037.6", "0.2789532", "0", "3"], ["84037", "0", "0", "0"], ["84023.8", "0", "0", "0"], ["84021.6", "0.10746793", "0", "2"], ["83952.4", "0", "0", "0"], ["83950", "0.18339881", "0", "3"], ["83938.1", "0", "0", "0"], ["83936.8", "0.01189899", "0", "2"], ["83918.9", "0.00001197", "0", "1"]], "ts": "1742555174104", "checksum": 1024043135, "seqId": 49927501397, "prevSeqId": 49927501217}], "record_time": 1742555174.105765, "EXCHANGE": "OKX"}
{"arg": {"channel": "books", "instId": "BTC-USDT"}, "action": "update", "data": [{"asks": [["84086.9", "0.00564", "0", "1"], ["84100.3", "0.23800936", "0", "2"], ["84101.1", "0", "0", "0"], ["84175.8", "0.00999783", "0", "2"], ["84185.1", "0.04277513", "0", "1"], ["84185.2", "0", "0", "0"], ["84237.7", "0.071", "0", "5"], ["84244.3", "0.00605088", "0", "2"]], "bids": [["84070", "0.7390762", "0", "16"], ["84067.6", "0.05346517", "0", "1"], ["84058.8", "0.41727768", "0", "2"], ["84058.7", "0.042", "0", "1"], ["84056.3", "0", "0", "0"], ["84054.6", "0.2383603", "0", "1"], ["84054.5", "0.03305896", "0", "1"], ["84049.3", "0.17842", "0", "1"], ["84044.8", "0.25574226", "0", "2"], ["84042.1", "0", "0", "0"], ["84040.7", "0", "0", "0"], ["84019.6", "0.02745264", "0", "1"], ["83964.4", "0.00011161", "0", "1"], ["83947.5", "0.0568", "0", "4"], ["83918.9", "0", "0", "0"]], "ts": "1742555174204", "checksum": 168939954, "seqId": 49927501434, "prevSeqId": 49927501397}], "record_time": 1742555174.206134, "EXCHANGE": "OKX"}
{"arg": {"channel": "books", "instId": "BTC-USDT"}, "action": "update", "data": [{"asks": [["84086.9", "0", "0", "0"], ["84089.7", "1", "0", "1"], ["84091", "0", "0", "0"], ["84094.3", "0.23800658", "0", "1"], ["84100.3", "0.00001197", "0", "1"], ["84173.1", "0", "0", "0"], ["84244.6", "0.5999", "0", "1"]], "bids": [["84058.8", "0.70692581", "0", "3"], ["84058.4", "1.000345", "0", "2"], ["84058", "0.0025", "0", "1"], ["84057", "0.35685", "0", "1"], ["84049.3", "0", "0", "0"], ["84044.8", "0.01774536", "0", "1"], ["84038.3", "0.23800658", "0", "1"], ["83964.1", "0", "0", "0"], ["83947.3", "0.01523791", "0", "2"], ["83919.2", "0", "0", "0"]], "ts": "1742555174304", "checksum": 168939954, "seqId": 49927501461, "prevSeqId": 49927501434}], "record_time": 1742555174.306297, "EXCHANGE": "OKX"}
{"arg": {"channel": "books", "instId": "BTC-USDT"}, "action": "update", "data": [{"asks": [["84070.1", "1.23122549", "0", "15"], ["84086", "0.06024", "0", "3"], ["84094.3", "0", "0", "0"], ["84096", "0.23800611", "0", "1"], ["84237.3", "0.0142", "0", "1"], ["84244.6", "0", "0", "0"]], "bids": [["84070", "0.55869077", "0", "13"], ["84067.6", "0", "0", "0"], ["84058.4", "1", "0", "1"], ["84057", "0.35935", "0", "2"], ["84056.3", "0.17842", "0", "1"], ["84038.3", "0.23800611", "0", "1"], ["84023", "0.2", "0", "1"], ["83920", "0", "0", "0"]], "ts": "1742555174404", "checksum": -1518790415, "seqId": 49927501486, "prevSeqId": 49927501461}], "record_time": 1742555174.405001, "EXCHANGE": "OKX"}
{"arg": {"channel": "books", "instId": "BTC-USDT"}, "action": "update", "data": [{"asks": [["84087.2", "0.17821722", "0", "1"], ["84244.3", "0", "0", "0"]], "bids": [["84044.3", "0.53421296", "0", "2"], ["84023", "0", "0", "0"], ["83920", "0.00001096", "0", "1"]], "ts": "1742555174504", "checksum": -1518790415, "seqId": 49927501493, "prevSeqId": 49927501486}], "record_time": 1742555174.5092, "EXCHANGE": "OKX"}
{"arg": {"channel": "books", "instId": "BTC-USDT"}, "action": "update", "data": [{"asks": [["84086", "0.0546", "0", "2"], ["84096", "0.23800319", "0", "1"], ["84125.4", "0.01188702", "0", "1"], ["84128.1", "0", "0", "0"], ["84209.6", "0.01188702", "0", "1"], ["84212.3", "0", "0", "0"]], "bids": [["84057", "0.0025", "0", "1"], ["84054.6", "0.33897816", "0", "2"], ["84040.7", "0.23800319", "0", "1"], ["84038.3", "0", "0", "0"], ["84022.1", "0.01188685", "0", "1"], ["84020.9", "0.01188702", "0", "1"], ["83920", "0", "0", "0"]], "ts": "1742555174604", "checksum": -1518790415, "seqId": 49927501517, "prevSeqId": 49927501493}], "record_time": 1742555174.604661, "EXCHANGE": "OKX"}
{"arg": {"channel": "books", "instId": "BTC-USDT"}, "action": "update", "data": [{"asks": [["84085.7", "0.0020355", "0", "1"], ["84244.1", "0", "0", "0"]], "bids": [["84058.6", "0.005625", "0", "1"], ["84040.7", "0", "0", "0"], ["84038.3", "0.23800619", "0", "1"], ["83921", "0", "0", "0"]], "ts": "1742555174704", "checksum": -1518790415, "seqId": 49927501522, "prevSeqId": 49927501517}], "record_time": 1742555174.705629, "EXCHANGE": "OKX"}
{"arg": {"channel": "books", "instId": "BTC-USDT"}, "action": "update", "data": [{"asks": [], "bids": [["84054.5", "0.38990896", "0", "2"]], "ts": "1742555174804", "checksum": -1518790415, "seqId": 49927501525, "prevSeqId": 49927501522}], "record_time": 1742555174.805045, "EXCHANGE": "OKX"}
{"arg": {"channel": "books", "instId": "BTC-USDT"}, "action": "update", "data": [{"asks": [["84096.8", "0.84725821", "0", "3"], ["84096.9", "1.59792551", "0", "1"], ["84126.2", "0.8844886", "0", "1"], ["84244", "0", "0", "0"]], "bids": [["84070", "0.56595077", "0", "14"], ["84044.8", "0.71628698", "0", "2"], ["84031", "1", "0", "1"], ["84016.6", "1.52731504", "0", "3"], ["83991.6", "1.51882828", "0", "3"], ["83921.3", "0", "0", "0"]], "ts": "1742555174904", "checksum": 1676757817, "seqId": 49927501537, "prevSeqId": 49927501525}], "record_time": 1742555174.906811, "EXCHANGE": "OKX"}
{"arg": {"channel": "books", "instId": "BTC-USDT"}, "action": "update", "data": [{"asks": [], "bids": [["84031", "0", "0", "0"], ["83921.3", "0.0016853", "0", "2"]], "ts": "1742555175004", "checksum": 1676757817, "seqId": 49927501543, "prevSeqId": 49927501537}], "record_time": 1742555175.00534, "EXCHANGE": "OKX"}
{"arg": {"channel": "books", "instId": "BTC-USDT"}, "action": "update", "data": [{"asks": [["84110", "2.24", "0", "2"]], "bids": [], "ts": "1742555175104", "checksum": 1676757817, "seqId": 49927501546, "prevSeqId": 49927501543}], "record_time": 1742555175.108906, "EXCHANGE": "OKX"}
{"arg": {"channel": "books", "instId": "BTC-USDT"}, "action": "update", "data": [{"asks": [["84110", "2.44", "0", "3"], ["84158.7", "0", "0", "0"], ["84244", "0.03", "0", "1"]], "bids": [["83993.8", "0", "0", "0"], ["83921", "0.00001002", "0", "1"]], "ts": "1742555175204", "checksum": 1676757817, "seqId": 49927501553, "prevSeqId": 49927501546}], "record_time": 1742555175.205917, "EXCHANGE": "OKX"}
{"arg": {"channel": "books", "instId": "BTC-USDT"}, "action": "update", "data": [{"asks": [["84089.7", "0", "0", "0"], ["84091.2", "1", "0", "1"]], "bids": [], "ts": "1742555175304", "checksum": 1676757817, "seqId": 49927501567, "prevSeqId": 49927501553}], "record_time": 1742555175.315266, "EXCHANGE": "OKX"}
{"arg": {"channel": "books", "instId": "BTC-USDT"}, "action": "update", "data": [{"asks": [["84089.4", "1", "0", "1"], ["84091.2", "0", "0", "0"], ["84112.8", "0.08", "0", "2"], ["84113.6", "0.21821721", "0", "2"], ["84114.4", "0.52861", "0", "1"], ["84150.7", "0.14260132", "0", "2"], ["84244", "0", "0", "0"]], "bids": [["84070", "0.56596077", "0", "15"], ["84051.1", "0.00871048", "0", "1"], ["83985.8", "0.14291391", "0", "3"], ["83980.6", "0.00001197", "0", "1"], ["83921", "0", "0", "0"]], "ts": "1742555175404", "checksum": 1666735930, "seqId": 49927501583, "prevSeqId": 49927501567}], "record_time": 1742555175.409164, "EXCHANGE": "OKX"}
{"arg": {"channel": "books", "instId": "BTC-USDT"}, "action": "update", "data": [{"asks": [["84084.3", "0.22009589", "0", "1"], ["84085", "0.00564", "0", "1"], ["84085.7", "0", "0", "0"], ["84087.3", "0", "0", "0"], ["84244", "0.03", "0", "1"]], "bids": [["84070", "0.35121327", "0", "14"], ["84049.1", "0.06205459", "0", "1"], ["84045", "0.05945451", "0", "2"], ["83980.6", "0.00017447", "0", "2"], ["83968.1", "0.00610016", "0", "1"], ["83921.3", "0", "0", "0"]], "ts": "1742555175504", "checksum": 1405485828, "seqId": 49927501598, "prevSeqId": 49927501583}], "record_time": 1742555175.505168, "EXCHANGE": "OKX"}
{"arg": {"channel": "books", "instId": "BTC-USDT"}, "action": "update", "data": [{"asks": [["84084.7", "0.35685", "0", "1"], ["84086.6", "0", "0", "0"], ["84130.3", "0", "0", "0"], ["84244.1", "0.00083", "0", "1"]], "bids": [["84059.3", "0.000015", "0", "1"], ["84058.6", "0", "0", "0"], ["83921.3", "0.0016853", "0", "2"]], "ts": "1742555175604", "checksum": 1405485828, "seqId": 49927501604, "prevSeqId": 49927501598}], "record_time": 1742555175.605471, "EXCHANGE": "OKX"}
{"arg": {"channel": "books", "instId": "BTC-USDT"}, "action": "update", "data": [{"asks": [["84084.1", "0.17842", "0", "1"], ["84085", "0", "0", "0"], ["84094.3", "0.23800824", "0", "1"], ["84096", "0", "0", "0"], ["84110", "1.24", "0", "1"]], "bids": [["84058.9", "0.107643", "0", "3"], ["84038.3", "0", "0", "0"], ["84036.9", "0.23800824", "0", "1"], ["83956.6", "0.00001197", "0", "1"], ["83943.1", "0.183204", "0", "1"], ["83921.3", "0", "0", "0"]], "ts": "1742555175704", "checksum": 1405485828, "seqId": 49927501615, "prevSeqId": 49927501604}], "record_time": 1742555175.705964, "EXCHANGE": "OKX"}
{"arg": {"channel": "books", "instId": "BTC-USDT"}, "action": "update", "data": [{"asks": [["84084.8", "0.001341", "0", "1"], ["84244.1", "0", "0", "0"]], "bids": [], "ts": "1742555175804", "checksum": 1405485828, "seqId": 49927501619, "prevSeqId": 49927501615}], "record_time": 1742555175.806816, "EXCHANGE": "OKX"}
{"arg": {"channel": "books", "instId": "BTC-USDT"}, "action": "update", "data": [{"asks": [["84088.3", "0.1249", "0", "1"], ["84092.3", "0.23801183", "0", "1"], ["84094.3", "0", "0", "0"], ["84244", "0", "0", "0"]], "bids": [["84070", "0.34394327", "0", "12"], ["84058.7", "0.04551178", "0", "2"], ["84036.9", "0", "0", "0"], ["84035.1", "0.23801183", "0", "1"]], "ts": "1742555175904", "checksum": -1709745113, "seqId": 49927501628, "prevSeqId": 49927501619}], "record_time": 1742555175.904955, "EXCHANGE": "OKX"}
{"arg": {"channel": "books", "instId": "BTC-USDT"}, "action": "update", "data": [{"asks": [["84084.8", "0", "0", "0"], ["84102.3", "0.18878335", "0", "1"], ["84131.2", "0.56896684", "0", "1"], ["84173.2", "1.55682588", "0", "2"], ["84177.7", "0.1", "0", "1"], ["84179.7", "0.00001196", "0", "1"], ["84242.8", "0", "0", "0"], ["84243.2", "0", "0", "0"]], "bids": [["84070", "0.4245887", "0", "13"], ["84035.1", "0", "0", "0"], ["84033.7", "0.23801571", "0", "1"], ["84030", "1.00001196", "0", "2"], ["84028.9", "0.58471641", "0", "2"], ["84000.1", "1.06271164", "0", "2"], ["83998.7", "0", "0", "0"], ["83982.1", "0", "0", "0"], ["83921.3", "0.0016853", "0", "2"], ["83921", "0.00001002", "0", "1"]], "ts": "1742555176004", "checksum": -1398552097, "seqId": 49927501649, "prevSeqId": 49927501628}], "record_time": 1742555176.004498, "EXCHANGE": "OKX"}
{"arg": {"channel": "books", "instId": "BTC-USDT"}, "action": "update", "data": [{"asks": [["84076.7", "0.07419819", "0", "4"], ["84112.8", "0", "0", "0"], ["84113.6", "0.25821721", "0", "3"], ["84114.4", "0.56860999", "0", "2"], ["84242.8", "0.03", "0", "1"]], "bids": [["84035.1", "0.23801258", "0", "1"], ["84033.7", "0", "0", "0"], ["84030", "0.00001196", "0", "1"], ["84021.6", "0.08914146", "0", "1"], ["84021.4", "0.03021421", "0", "2"], ["83987.3", "0.0428", "0", "2"], ["83970.5", "0.0642", "0", "3"], ["83950", "0.00013403", "0", "2"], ["83947.7", "0.18327262", "0", "1"], ["83921.3", "0", "0", "0"], ["83921", "0", "0", "0"]], "ts": "1742555176104", "checksum": 24154572, "seqId": 49927501683, "prevSeqId": 49927501649}], "record_time": 1742555176.105331, "EXCHANGE": "OKX"}
{"arg": {"channel": "books", "instId": "BTC-USDT"}, "action": "update", "data": [{"asks": [["84086.2", "0.0010695", "0", "1"], ["84112.8", "0.08", "0", "2"], ["84113.6", "0.21821721", "0", "2"], ["84114.4", "0.52861", "0", "1"], ["84242.6", "0", "0", "0"], ["84242.8", "0", "0", "0"]], "bids": [["84058.9", "0.102", "0", "2"], ["84041.6", "0", "0", "0"], ["84035.1", "0", "0", "0"], ["84033.7", "0.2380147", "0", "1"], ["83987.3", "0", "0", "0"], ["83970.5", "0.107", "0", "5"], ["83921.3", "0.0016853", "0", "2"], ["83921", "0.00001002", "0", "1"]], "ts": "1742555176204", "checksum": 24154572, "seqId": 49927501704, "prevSeqId": 49927501683}], "record_time": 1742555176.205238, "EXCHANGE": "OKX"}
{"arg": {"channel": "books", "instId": "BTC-USDT"}, "action": "update", "data": [{"asks": [["84112.8", "0", "0", "0"], ["84113.6", "0.25821721", "0", "3"], ["84114.4", "0.56860999", "0", "2"], ["84242.6", "0.00419183", "0", "1"]], "bids": [["84058.9", "0.107622", "0", "3"], ["84033.7", "0.23801345", "0", "1"]], "ts": "1742555176304", "checksum": 24154572, "seqId": 49927501722, "prevSeqId": 49927501704}], "record_time": 1742555176.30744, "EXCHANGE": "OKX"}
{"arg": {"channel": "books", "instId": "BTC-USDT"}, "action": "update", "data": [{"asks": [], "bids": [["84070", "0.35018327", "0", "13"], ["84033.7", "0.23801352", "0", "1"]], "ts": "1742555176404", "checksum": 1961800381, "seqId": 49927501730, "prevSeqId": 49927501722}], "record_time": 1742555176.407571, "EXCHANGE": "OKX"}
{"arg": {"channel": "books", "instId": "BTC-USDT"}, "action": "update", "data": [{"asks": [], "bids": [["84020", "0.20001", "0", "2"]], "ts": "1742555176504", "checksum": 1961800381, "seqId": 49927501731, "prevSeqId": 49927501730}], "record_time": 1742555176.505884, "EXCHANGE": "OKX"}
{"arg": {"channel": "books", "instId": "BTC-USDT"}, "action": "update", "data": [{"asks": [["84112.8", "0.08", "0", "2"], ["84113.6", "0.21821721", "0", "2"], ["84114.4", "0.52861", "0", "1"], ["84150.7", "0.07130066", "0", "1"], ["84242.6", "0", "0", "0"]], "bids": [["84020", "0.00001", "0", "1"], ["83985.8", "0.07147328", "0", "2"]], "ts": "1742555176604", "checksum": 1961800381, "seqId": 49927501744, "prevSeqId": 49927501731}], "record_time": 1742555176.61384, "EXCHANGE": "OKX"}
{"arg": {"channel": "books", "instId": "BTC-USDT"}, "action": "update", "data": [{"asks": [["84110", "2.44", "0", "3"], ["84150.7", "0.14260132", "0", "2"]], "bids": [["83985.8", "0.14291391", "0", "3"]], "ts": "1742555176704", "checksum": 1961800381, "seqId": 49927501752, "prevSeqId": 49927501744}], "record_time": 1742555176.705475, "EXCHANGE": "OKX"}
{"arg": {"channel": "books", "instId": "BTC-USDT"}, "action": "update", "data": [{"asks": [["84150.7", "0.07130066", "0", "1"]], "bids": [["83985.8", "0.07147328", "0", "2"]], "ts": "1742555176804", "checksum": 1961800381, "seqId": 49927501760, "prevSeqId": 49927501752}], "record_time": 1742555176.804852, "EXCHANGE": "OKX"}
{"arg": {"channel": "books", "instId": "BTC-USDT"}, "action": "update", "data": [{"asks": [["84112.8", "0", "0", "0"], ["84113.6", "0.25821721", "0", "3"], ["84114.4", "0.56860999", "0", "2"], ["84242.6", "0.00419183", "0", "1"]], "bids": [["84070", "0.35019327", "0", "14"]], "ts": "1742555176904", "checksum": 1955184316, "seqId": 49927501782, "prevSeqId": 49927501760}], "record_time": 1742555176.905609, "EXCHANGE": "OKX"}
{"arg": {"channel": "books", "instId": "BTC-USDT"}, "action": "update", "data": [{"asks": [["84086.2", "0", "0", "0"], ["84109.2", "0.76545333", "0", "2"], ["84242.8", "0.03", "0", "1"]], "bids": [["84037.6", "0.41020846", "0", "4"]], "ts": "1742555177004", "checksum": 1955184316, "seqId": 49927501787, "prevSeqId": 49927501782}], "record_time": 1742555177.004524, "EXCHANGE": "OKX"}
{"arg": {"channel": "books", "instId": "BTC-USDT"}, "action": "update", "data": [{"asks": [["84077", "0.02530935", "0", "1"], ["84078.6", "0", "0", "0"], ["84086.8", "0.005", "0", "1"], ["84087.1", "0.0003555", "0", "1"], ["84096.8", "0.84225821", "0", "2"], ["84110", "2.24", "0", "2"], ["84147", "0.12536414", "0", "3"], ["84150.7", "0.14260132", "0", "2"], ["84242.8", "0", "0", "0"]], "bids": [["84066.5", "0.016901", "0", "2"], ["84065.9", "0.02530935", "0", "1"], ["84065.5", "0", "0", "0"], ["84058.9", "0.102", "0", "2"], ["84035.1", "0.23801279", "0", "1"], ["84033.7", "0", "0", "0"], ["84030", "1.00001196", "0", "2"], ["83985.8", "0.14291391", "0", "3"]], "ts": "1742555177104", "checksum": 1487186257, "seqId": 49927501822, "prevSeqId": 49927501787}], "record_time": 1742555177.107811, "EXCHANGE": "OKX"}
{"arg": {"channel": "books", "instId": "BTC-USDT"}, "action": "update", "data": [{"asks": [], "bids": [["84060.1", "0.00564", "0", "1"], ["84030", "0.00001196", "0", "1"], ["83921", "0", "0", "0"]], "ts": "1742555177204", "checksum": 1484281062, "seqId": 49927501826, "prevSeqId": 49927501822}], "record_time": 1742555177.205152, "EXCHANGE": "OKX"}
{"arg": {"channel": "books", "instId": "BTC-USDT"}, "action": "update", "data": [{"asks": [["84093.2", "0.13420468", "0", "2"], ["84109.1", "0.14043766", "0", "1"]], "bids": [["84035.1", "0.23801232", "0", "1"]], "ts": "1742555177304", "checksum": 1484281062, "seqId": 49927501842, "prevSeqId": 49927501826}], "record_time": 1742555177.305184, "EXCHANGE": "OKX"}
{"arg": {"channel": "books", "instId": "BTC-USDT"}, "action": "update", "data": [{"asks": [["84123.1", "0.21439273", "0", "2"]], "bids": [["84035.9", "0.23802293", "0", "2"], ["84035.1", "0", "0", "0"], ["83921", "0.00001002", "0", "1"]], "ts": "1742555177404", "checksum": 1484281062, "seqId": 49927501861, "prevSeqId": 49927501842}], "record_time": 1742555177.404687, "EXCHANGE": "OKX"}
{"arg": {"channel": "books", "instId": "BTC-USDT"}, "action": "update", "data": [{"asks": [["84150.7", "0.07130066", "0", "1"]], "bids": [["84070", "0.34434551", "0", "9"], ["84035.9", "0.00001196", "0", "1"], ["84033.7", "0.23801338", "0", "1"], ["83985.8", "0.07147328", "0", "2"], ["83921", "0", "0", "0"]], "ts": "1742555177504", "checksum": -1180262457, "seqId": 49927501881, "prevSeqId": 49927501861}], "record_time": 1742555177.508785, "EXCHANGE": "OKX"}
{"arg": {"channel": "books", "instId": "BTC-USDT"}, "action": "update", "data": [{"asks": [["84084.3", "0.31443878", "0", "2"], ["84092.3", "0.23801476", "0", "1"], ["84150.7", "0.14260132", "0", "2"]], "bids": [["84033.7", "0.23801476", "0", "1"], ["84023", "0.2", "0", "1"], ["83985.8", "0.14291391", "0", "3"], ["83921.3", "0", "0", "0"]], "ts": "1742555177604", "checksum": -1180262457, "seqId": 49927501899, "prevSeqId": 49927501881}], "record_time": 1742555177.6052, "EXCHANGE": "OKX"}
