{"arg": {"channel": "books", "instId": "BTC-USDT"}, "action": "update", "data": [{"asks": [["88491.8", "0.37719134", "0", "8"], ["88494", "0.0171", "0", "1"], ["88496.2", "0.0002", "0", "2"], ["88499.2", "0", "0", "0"], ["88500.3", "0", "0", "0"], ["88502.1", "0.0039", "0", "1"], ["88503", "0", "0", "0"], ["88504.6", "0", "0", "0"], ["88507.1", "0.11298309", "0", "1"], ["88507.9", "0", "0", "0"], ["88523.2", "0.000015", "0", "1"], ["88525.3", "0.22600697", "0", "1"], ["88553.9", "0.0174125", "0", "2"], ["88605.2", "0.0000166", "0", "1"], ["88605.3", "0.00569815", "0", "1"]], "bids": [["88490.8", "0", "0", "0"], ["88490.6", "0.0001", "0", "1"], ["88483.4", "0.24150048", "0", "2"], ["88482.7", "0.33905", "0", "1"], ["88482", "0", "0", "0"], ["88481.9", "0.000027", "0", "1"], ["88480.9", "0", "0", "0"], ["88478.2", "0", "0", "0"], ["88476.9", "0", "0", "0"], ["88474.1", "0", "0", "0"], ["88470.8", "0.18460837", "0", "2"], ["88467.2", "0.22600697", "0", "1"], ["88462", "0", "0", "0"], ["88459", "0", "0", "0"], ["88455.9", "0.01650401", "0", "1"], ["88453.9", "0", "0", "0"], ["88428.6", "0.01740236", "0", "1"], ["88249.9", "0.00060139", "0", "2"], ["88248.9", "0.03", "0", "1"], ["88247.9", "0.0001", "0", "1"], ["88247.3", "0.00001139", "0", "1"], ["88246.9", "0.03", "0", "1"]], "ts": "1741338246905", "checksum": -523723819, "seqId": 48070608558, "prevSeqId": 48070608481}]}
{"arg": {"channel": "books", "instId": "BTC-USDT"}, "action": "update", "data": [{"asks": [["88491.8", "0.35096134", "0", "6"], ["88496", "0.0171", "0", "1"], ["88497.1", "0", "0", "0"], ["88498.4", "0", "0", "0"], ["88501.8", "0.34319724", "0", "2"], ["88502.1", "0", "0", "0"], ["88510.6", "0", "0", "0"], ["88512.3", "1.016", "0", "2"], ["88518.5", "0", "0", "0"], ["88525.3", "0", "0", "0"], ["88527.3", "0.2260004", "0", "1"], ["88536.9", "0.00339", "0", "1"], ["88605.6", "0.30754406", "0", "1"], ["88606", "0.00046406", "0", "3"], ["88606.9", "0.00052479", "0", "1"]], "bids": [["88491.7", "0.25750885", "0", "13"], ["88490.8", "0.0002", "0", "2"], ["88490.7", "0", "0", "0"], ["88490.6", "0", "0", "0"], ["88476", "0.03541477", "0", "2"], ["88471.5", "0.13189641", "0", "1"], ["88470.1", "0.2260004", "0", "1"], ["88467.2", "0", "0", "0"], ["88465", "0.207", "0", "1"], ["88464", "0.118038", "0", "2"], ["88463.2", "0.0005989", "0", "2"], ["88462.4", "0.00029891", "0", "1"], ["88456.2", "0.01650401", "0", "1"], ["88455.9", "0", "0", "0"], ["88450", "0.147132", "0", "2"], ["88449", "0.06", "0", "2"], ["88448", "0.03", "0", "1"], ["88393.3", "0", "0", "0"]], "ts": "1741338247005", "checksum": 1358033179, "seqId": 48070608627, "prevSeqId": 48070608558}]}
{"arg": {"channel": "books", "instId": "BTC-USDT"}, "action": "update", "data": [{"asks": [["88491.8", "0.30975704", "0", "7"], ["88491.9", "0.01860683", "0", "1"], ["88495.6", "0", "0", "0"], ["88496.2", "0", "0", "0"], ["88497.5", "0.0001", "0", "1"], ["88497.6", "0.0001", "0", "1"], ["88497.9", "0.01994229", "0", "1"], ["88498.5", "0.01364", "0", "1"], ["88499.4", "0", "0", "0"], ["88499.9", "0", "0", "0"], ["88500.8", "0", "0", "0"], ["88501.7", "0.03412208", "0", "2"], ["88501.8", "0", "0", "0"], ["88503.4", "0.012102", "0", "1"], ["88503.5", "0", "0", "0"], ["88505.3", "0", "0", "0"], ["88505.6", "0.05990904", "0", "3"], ["88505.9", "0.05989404", "0", "2"], ["88506.1", "0.17183717", "0", "3"], ["88509.7", "0", "0", "0"], ["88510.2", "0", "0", "0"], ["88512.3", "0.016", "0", "1"], ["88514", "1", "0", "1"], ["88553.9", "0.00001014", "0", "1"], ["88556.4", "0.01740153", "0", "1"], ["88562.2", "0.01130171", "0", "2"], ["88567", "0", "0", "0"], ["88571.2", "0.01021", "0", "1"], ["88607.8", "0.00001009", "0", "1"], ["88607.9", "0.00571153", "0", "2"], ["88608", "0.0305953", "0", "2"]], "bids": [["88490.8", "0", "0", "0"], ["88490.4", "0.0001", "0", "1"], ["88490.3", "0.0001", "0", "1"], ["88488.1", "0.02261569", "0", "1"], ["88483.7", "0.00935", "0", "1"], ["88481.5", "0", "0", "0"], ["88481.3", "0", "0", "0"], ["88480.8", "0", "0", "0"], ["88480.7", "0", "0", "0"], ["88477.4", "0", "0", "0"], ["88476.4", "0", "0", "0"], ["88473.7", "0", "0", "0"], ["88473.1", "0.002382", "0", "1"], ["88471.9", "0.002", "0", "1"], ["88471.5", "0", "0", "0"], ["88471.2", "0", "0", "0"], ["88457.7", "0.01650401", "0", "1"], ["88456.2", "0", "0", "0"], ["88440.3", "0", "0", "0"], ["88432.2", "0.01740153", "0", "1"], ["88429.3", "0.01129037", "0", "1"], ["88428.6", "0", "0", "0"], ["88361.4", "0", "0", "0"], ["88349.6", "0.0112915", "0", "1"], ["88246.8", "0.00560182", "0", "1"], ["88246.7", "0.00840315", "0", "1"], ["88246.4", "0.34056098", "0", "1"], ["88244.9", "0.00001267", "0", "1"], ["88244.2", "0.03", "0", "1"]], "ts": "1741338247105", "checksum": 212819324, "seqId": 48070608741, "prevSeqId": 48070608627}]}
{"arg": {"channel": "books", "instId": "BTC-USDT"}, "action": "update", "data": [{"asks": [["88491.8", "0", "0", "0"], ["88491.9", "0", "0", "0"], ["88492", "0", "0", "0"], ["88493.6", "0.0083", "0", "2"], ["88493.9", "0.01284683", "0", "1"], ["88497.4", "0.0001", "0", "1"], ["88497.5", "0", "0", "0"], ["88497.6", "0", "0", "0"], ["88497.7", "0.0001", "0", "1"], ["88498.5", "0", "0", "0"], ["88501.7", "0.03983829", "0", "2"], ["88502.2", "0", "0", "0"], ["88503.4", "0", "0", "0"], ["88503.7", "0.00001035", "0", "1"], ["88503.9", "0.012102", "0", "1"], ["88505.5", "0.05989404", "0", "2"], ["88505.6", "0.000015", "0", "1"], ["88505.9", "0", "0", "0"], ["88506.1", "0.12253502", "0", "3"], ["88506.2", "0.0017295", "0", "1"], ["88507.3", "0.00001138", "0", "1"], ["88510.5", "0.42931377", "0", "1"], ["88513.9", "0.90244663", "0", "1"], ["88514", "0", "0", "0"], ["88514.8", "0.20848733", "0", "2"], ["88519.2", "0", "0", "0"], ["88520", "0", "0", "0"], ["88521.6", "0.1153468", "0", "1"], ["88527.3", "0", "0", "0"], ["88528", "0.18474377", "0", "1"], ["88529.9", "0.22670594", "0", "2"], ["88531", "0", "0", "0"], ["88534.8", "0", "0", "0"], ["88537", "0.14172635", "0", "1"], ["88539", "0.00826549", "0", "1"], ["88540", "0.00533926", "0", "5"], ["88546.7", "0.02510254", "0", "1"], ["88556.4", "0", "0", "0"], ["88559.6", "0.91373847", "0", "2"], ["88559.8", "0.01741703", "0", "2"], ["88562.2", "0.00001021", "0", "1"], ["88608.6", "0.32547393", "0", "2"], ["88608.9", "0.00570112", "0", "1"], ["88609", "0.1", "0", "1"], ["88609.2", "0.00572586", "0", "2"], ["88609.3", "0.04063049", "0", "5"], ["88609.4", "0.04207212", "0", "4"]], "bids": [["88493.5", "0.5606244", "0", "11"], ["88493.4", "0.0000669", "0", "1"], ["88492", "0.26677519", "0", "3"], ["88491.9", "0.0001", "0", "1"], ["88491.8", "0.02022642", "0", "2"], ["88491.7", "0.02295058", "0", "8"], ["88491.6", "0", "0", "0"], ["88490.4", "0", "0", "0"], ["88490.3", "0", "0", "0"], ["88490", "0.0171", "0", "1"], ["88485.7", "0.0000465", "0", "1"], ["88485.5", "0", "0", "0"], ["88483.8", "0.05989404", "0", "2"], ["88483.4", "0.15376829", "0", "1"], ["88483", "0.08475366", "0", "2"], ["88482", "0.02825122", "0", "1"], ["88481.9", "0", "0", "0"], ["88481", "0", "0", "0"], ["88476.7", "0.05650244", "0", "1"], ["88476.1", "0.22599275", "0", "1"], ["88476", "0.00734477", "0", "1"], ["88474.8", "0.003", "0", "1"], ["88473.1", "0", "0", "0"], ["88470.8", "0.13366331", "0", "1"], ["88470.1", "0", "0", "0"], ["88462", "0.01650401", "0", "1"], ["88457.7", "0", "0", "0"], ["88453", "0.06", "0", "2"], ["88451", "0.44341", "0", "1"], ["88440.8", "0.01129184", "0", "1"], ["88435.7", "0.01740066", "0", "1"], ["88432.2", "0", "0", "0"], ["88429.3", "0", "0", "0"], ["88428.5", "0.00102743", "0", "1"], ["88414.8", "0.64092256", "0", "2"], ["88391.5", "0", "0", "0"], ["88360.2", "0.17400669", "0", "1"], ["88352.3", "0.01129184", "0", "1"], ["88351.2", "0", "0", "0"], ["88349.6", "0", "0", "0"], ["88246.7", "0", "0", "0"], ["88246.4", "0", "0", "0"], ["88244.9", "0", "0", "0"], ["88244.2", "0", "0", "0"]], "ts": "1741338247205", "checksum": -1733007679, "seqId": 48070609036, "prevSeqId": 48070608741}]}
{"arg": {"channel": "books", "instId": "BTC-USDT"}, "action": "update", "data": [{"asks": [["88493.6", "0.0485", "0", "4"], ["88493.9", "0", "0", "0"], ["88494.4", "0.11299928", "0", "1"], ["88495.9", "0.0001", "0", "1"], ["88496", "0.0172", "0", "2"], ["88497.4", "0", "0", "0"], ["88497.7", "0", "0", "0"], ["88503.6", "0.012102", "0", "1"], ["88503.7", "0", "0", "0"], ["88503.9", "0", "0", "0"], ["88508.9", "0.01364", "0", "1"], ["88518.8", "1", "0", "1"], ["88521.5", "0.015", "0", "1"], ["88529.1", "0.22599331", "0", "1"], ["88529.9", "0.00071319", "0", "1"], ["88550.3", "0", "0", "0"], ["88550.4", "0", "0", "0"], ["88550.5", "0.03235641", "0", "1"], ["88556.4", "0.01740056", "0", "1"], ["88559.8", "0.00001637", "0", "1"], ["88584.8", "0.000015", "0", "1"], ["88586.5", "0.00167705", "0", "1"], ["88607.2", "0.1", "0", "1"], ["88609", "0", "0", "0"], ["88609.2", "0", "0", "0"], ["88609.3", "0", "0", "0"], ["88609.4", "0", "0", "0"]], "bids": [["88493.5", "0.5440494", "0", "11"], ["88493", "0.05708644", "0", "1"], ["88492.9", "0.11300114", "0", "1"], ["88492", "0.0171", "0", "1"], ["88491.9", "0", "0", "0"], ["88491.8", "0", "0", "0"], ["88490.1", "0.0002", "0", "2"], ["88487.3", "0.00004575", "0", "1"], ["88486.9", "0.02806", "0", "1"], ["88485.7", "0", "0", "0"], ["88483.7", "0.000027", "0", "1"], ["88476.7", "0", "0", "0"], ["88476.1", "0", "0", "0"], ["88475.2", "0.22599331", "0", "1"], ["88465.6", "0.0005989", "0", "2"], ["88464.8", "0.0002989", "0", "1"], ["88463.2", "0", "0", "0"], ["88462.4", "0", "0", "0"], ["88459.9", "0.02260865", "0", "1"], ["88452", "0.06016958", "0", "3"], ["88451", "0.47341", "0", "2"], ["88449", "0", "0", "0"], ["88448", "0", "0", "0"], ["88445.2", "0.1", "0", "1"], ["88445", "0.03073953", "0", "2"], ["88435.7", "0", "0", "0"], ["88432.2", "0.01740056", "0", "1"], ["88431.2", "0.00102741", "0", "1"], ["88430.5", "0", "0", "0"], ["88428.5", "0", "0", "0"], ["88423.1", "0.00098754", "0", "1"], ["88421.9", "0", "0", "0"], ["88391.5", "0.00019394", "0", "1"], ["88389.1", "0.1", "0", "1"], ["88360.2", "0", "0", "0"], ["88352.4", "0.17400562", "0", "1"], ["88246.9", "0", "0", "0"], ["88246.8", "0", "0", "0"]], "ts": "1741338247305", "checksum": 230665425, "seqId": 48070609221, "prevSeqId": 48070609036}]}
{"arg": {"channel": "books", "instId": "BTC-USDT"}, "action": "update", "data": [{"asks": [["88493.6", "0.1494", "0", "6"], ["88494.3", "0.04164662", "0", "1"], ["88495.3", "0.0001", "0", "1"], ["88495.5", "0.00637993", "0", "2"], ["88495.9", "0", "0", "0"], ["88496", "0.0171", "0", "1"], ["88501.7", "0.08873767", "0", "3"], ["88503.4", "0.012102", "0", "1"], ["88503.5", "0.05989404", "0", "2"], ["88503.6", "0", "0", "0"], ["88505.9", "0.05989404", "0", "2"], ["88506.2", "0", "0", "0"], ["88515", "0.04093", "0", "1"], ["88516.9", "1.016", "0", "2"], ["88518.8", "0", "0", "0"], ["88529.1", "0", "0", "0"], ["88529.9", "0.22670413", "0", "2"], ["88535", "0.06", "0", "2"], ["88536", "0.09", "0", "3"], ["88539.2", "0", "0", "0"], ["88540", "0.00563926", "0", "6"], ["88540.8", "0.00031501", "0", "2"], ["88550.5", "0", "0", "0"], ["88552.2", "0.1", "0", "1"]], "bids": [["88493.5", "0.3890794", "0", "8"], ["88490.1", "0", "0", "0"], ["88489.6", "0.0002", "0", "2"], ["88475.2", "0.22599094", "0", "1"], ["88474.8", "0", "0", "0"], ["88465.6", "0", "0", "0"], ["88464.8", "0.0005989", "0", "2"], ["88464", "0.1183369", "0", "3"], ["88452", "0.00016958", "0", "1"], ["88451", "0.50341", "0", "3"], ["88450", "0.177132", "0", "3"], ["88445.2", "0", "0", "0"], ["88246.9", "0.03", "0", "1"], ["88246.8", "0.00560182", "0", "1"], ["88246.7", "0.00840315", "0", "1"]], "ts": "1741338247405", "checksum": 1811254848, "seqId": 48070609322, "prevSeqId": 48070609221}]}
{"arg": {"channel": "books", "instId": "BTC-USDT"}, "action": "update", "data": [{"asks": [["88493.6", "0.16832613", "0", "9"], ["88495.3", "0", "0", "0"], ["88495.5", "0.00627993", "0", "1"], ["88496.5", "0.0002", "0", "2"], ["88501.7", "0.05689324", "0", "3"], ["88503.7", "0.00001035", "0", "1"], ["88503.9", "0.33929724", "0", "1"], ["88505.2", "0.01364", "0", "1"], ["88505.5", "0", "0", "0"], ["88506.3", "0.0103035", "0", "1"], ["88508.9", "0", "0", "0"], ["88515.1", "1", "0", "1"], ["88516.9", "0.016", "0", "1"], ["88608", "0", "0", "0"], ["88608.6", "0", "0", "0"], ["88608.9", "0", "0", "0"]], "bids": [["88493.5", "0.4140294", "0", "8"], ["88493", "0", "0", "0"], ["88492.9", "0", "0", "0"], ["88490.4", "0.12235428", "0", "2"], ["88489.6", "0", "0", "0"], ["88489.5", "0.0002", "0", "2"], ["88466", "0.09680008", "0", "1"], ["88446.8", "0.1", "0", "1"], ["88246.7", "0", "0", "0"]], "ts": "1741338247505", "checksum": -899442926, "seqId": 48070609375, "prevSeqId": 48070609322}]}
{"arg": {"channel": "books", "instId": "BTC-USDT"}, "action": "update", "data": [{"asks": [["88493.6", "0.163", "0", "8"], ["88495.1", "0.0001", "0", "1"], ["88496.5", "0.0001", "0", "1"], ["88501.7", "0.15655054", "0", "2"], ["88503.7", "0", "0", "0"], ["88506.2", "0.001923", "0", "1"], ["88506.3", "0", "0", "0"], ["88513.7", "1", "0", "1"], ["88515.1", "0", "0", "0"], ["88527.3", "0.22599675", "0", "1"], ["88529.9", "0.00071319", "0", "1"], ["88607.9", "0", "0", "0"]], "bids": [["88493.5", "0.3932294", "0", "7"], ["88475.2", "0", "0", "0"], ["88473.6", "0.000168", "0", "1"], ["88471.1", "0.22599813", "0", "1"], ["88466", "0", "0", "0"]], "ts": "1741338247605", "checksum": -1886165609, "seqId": 48070609419, "prevSeqId": 48070609375}]}
{"arg": {"channel": "books", "instId": "BTC-USDT"}, "action": "update", "data": [{"asks": [["88494.2", "0.0002", "0", "2"], ["88495.1", "0", "0", "0"], ["88496.5", "0", "0", "0"], ["88501.6", "0.012102", "0", "1"], ["88502.5", "0.207", "0", "1"], ["88503.4", "0", "0", "0"], ["88510.5", "0.67564955", "0", "2"], ["88511.9", "1", "0", "1"], ["88513.7", "0", "0", "0"], ["88525.3", "0.2260021", "0", "1"], ["88527.3", "0", "0", "0"]], "bids": [["88493.5", "0.3396544", "0", "5"], ["88489.5", "0", "0", "0"], ["88489.4", "0.0002", "0", "2"], ["88483", "0", "0", "0"], ["88482", "0", "0", "0"], ["88471.1", "0", "0", "0"], ["88470.8", "0.18460691", "0", "2"], ["88467.2", "0.22600384", "0", "1"], ["88464.8", "0", "0", "0"], ["88464", "0.1186369", "0", "4"], ["88463.2", "0.0002989", "0", "1"], ["88462", "0", "0", "0"], ["88461.3", "0.23527718", "0", "3"], ["88453", "0", "0", "0"], ["88452", "0.06016958", "0", "3"], ["88451", "0.44341", "0", "1"], ["88450", "0.207132", "0", "4"], ["88449", "0.03", "0", "1"], ["88246.7", "0.00840315", "0", "1"], ["88246.4", "0.34056098", "0", "1"], ["88244.9", "0.00001267", "0", "1"]], "ts": "1741338247705", "checksum": 710025550, "seqId": 48070609484, "prevSeqId": 48070609419}]}
{"arg": {"channel": "books", "instId": "BTC-USDT"}, "action": "update", "data": [{"asks": [["88493.6", "0.19905327", "0", "9"], ["88502.8", "0.01364", "0", "1"], ["88503.7", "0.00001035", "0", "1"], ["88505.2", "0", "0", "0"], ["88506.2", "0", "0", "0"], ["88510.3", "0.04094", "0", "1"], ["88515", "0", "0", "0"], ["88521.5", "0.22601546", "0", "1"], ["88525.3", "0", "0", "0"], ["88607.9", "0.00571153", "0", "2"]], "bids": [["88493.5", "0.23438529", "0", "3"], ["88492", "0", "0", "0"], ["88490.4", "0.11300428", "0", "1"], ["88489.4", "0.0001", "0", "1"], ["88489.3", "0.0001", "0", "1"], ["88488.1", "0", "0", "0"], ["88488", "0.02757851", "0", "3"], ["88486.9", "0", "0", "0"], ["88483.9", "0.03908909", "0", "1"], ["88483.4", "0", "0", "0"], ["88482.7", "0", "0", "0"], ["88482.3", "0.02807", "0", "1"], ["88479.6", "0.02837516", "0", "2"], ["88479.1", "0.00936138", "0", "2"], ["88477.9", "0.05989404", "0", "2"], ["88477.8", "0.02012642", "0", "1"], ["88477.7", "0.05007344", "0", "2"], ["88477.3", "0", "0", "0"], ["88475.8", "0.00852541", "0", "1"], ["88473.6", "0", "0", "0"], ["88470.8", "0.13366331", "0", "1"], ["88467.2", "0", "0", "0"], ["88464.8", "0.0006", "0", "2"], ["88464", "0.1183369", "0", "3"], ["88463.2", "0", "0", "0"], ["88461.4", "0.22601546", "0", "1"], ["88461.3", "0.21877317", "0", "2"], ["88460.3", "0.01650401", "0", "1"], ["88451", "0.50341", "0", "3"], ["88450", "0.177132", "0", "3"], ["88449", "0", "0", "0"], ["88414.8", "0.73049236", "0", "3"]], "ts": "1741338247805", "checksum": -591036907, "seqId": 48070609567, "prevSeqId": 48070609484}]}
{"arg": {"channel": "books", "instId": "BTC-USDT"}, "action": "update", "data": [{"asks": [["88491.8", "0.31217779", "0", "12"], ["88491.9", "0.0002", "0", "2"], ["88492", "0.0171", "0", "1"], ["88492.9", "0.11842356", "0", "1"], ["88493", "0.11300108", "0", "1"], ["88493.5", "0.05989404", "0", "2"], ["88493.6", "0.05405327", "0", "3"], ["88494.2", "0", "0", "0"], ["88494.3", "0", "0", "0"], ["88494.4", "0", "0", "0"], ["88497", "0.06213689", "0", "3"], ["88497.9", "0.07354213", "0", "1"], ["88499", "0.05989404", "0", "2"], ["88499.2", "0.000054", "0", "1"], ["88500.4", "0.012102", "0", "1"], ["88500.5", "0.00209084", "0", "1"], ["88501.5", "0.05989404", "0", "2"], ["88501.6", "0", "0", "0"], ["88501.7", "0.24433131", "0", "3"], ["88503.7", "0", "0", "0"], ["88504.8", "0.13923877", "0", "1"], ["88505.9", "0", "0", "0"], ["88532.6", "0.44111832", "0", "1"], ["88534.2", "0", "0", "0"], ["88535", "0.12", "0", "4"], ["88536", "0.03", "0", "1"], ["88537.7", "0.00083", "0", "1"], ["88552.1", "0.10137118", "0", "2"], ["88552.2", "0", "0", "0"], ["88559.5", "0.00008048", "0", "3"], ["88561.6", "0.11343045", "0", "1"], ["88584.8", "0.00169217", "0", "2"], ["88586.5", "0", "0", "0"], ["88606.9", "0", "0", "0"], ["88607.2", "0", "0", "0"], ["88607.8", "0", "0", "0"], ["88607.9", "0", "0", "0"]], "bids": [["88493.5", "0", "0", "0"], ["88493.4", "0", "0", "0"], ["88491.6", "0.00007036", "0", "1"], ["88490.4", "0", "0", "0"], ["88490", "0", "0", "0"], ["88489.4", "0", "0", "0"], ["88489.3", "0", "0", "0"], ["88488", "0.01832851", "0", "3"], ["88487.9", "0.11300748", "0", "1"], ["88487.5", "0.0001", "0", "1"], ["88487.3", "0", "0", "0"], ["88485.5", "0.00004575", "0", "1"], ["88483.9", "0", "0", "0"], ["88483.8", "0", "0", "0"], ["88483.7", "0", "0", "0"], ["88483.3", "0.00057148", "0", "1"], ["88482.3", "0", "0", "0"], ["88481.9", "0.000027", "0", "1"], ["88480.2", "0.0540044", "0", "1"], ["88480.1", "0.06038161", "0", "3"], ["88479.7", "0.05981652", "0", "2"], ["88479.6", "0.1153058", "0", "2"], ["88478.1", "0.00974308", "0", "1"], ["88478", "0.05007344", "0", "2"], ["88477.9", "0", "0", "0"], ["88477.8", "0", "0", "0"], ["88477.7", "0", "0", "0"], ["88476.1", "0.05981652", "0", "2"], ["88475.9", "0.08529892", "0", "1"], ["88475.4", "0.05981652", "0", "2"], ["88473.9", "0", "0", "0"], ["88471.8", "0.14778266", "0", "1"], ["88469.3", "0.00369546", "0", "2"], ["88466.1", "0.39951597", "0", "1"], ["88465.7", "0.00343", "0", "1"], ["88464.8", "0", "0", "0"], ["88464", "0.1186369", "0", "4"], ["88463.2", "0.0002989", "0", "1"], ["88451", "0.44341", "0", "1"], ["88450", "0.207132", "0", "4"], ["88449", "0.03", "0", "1"], ["88446.8", "0", "0", "0"], ["88446.7", "0.1", "0", "1"], ["88440", "0", "0", "0"], ["88435.6", "0", "0", "0"], ["88434.9", "0", "0", "0"], ["88431.8", "0", "0", "0"], ["88431.2", "0", "0", "0"], ["88431.1", "0", "0", "0"], ["88428.5", "0.00102737", "0", "1"], ["88423.1", "0", "0", "0"], ["88422.2", "0.00098759", "0", "1"], ["88391.1", "0.02622351", "0", "1"], ["88364.1", "0.02045924", "0", "1"], ["88337.7", "0.10180917", "0", "1"], ["88244.2", "0.03", "0", "1"], ["88243.5", "0.03", "0", "1"], ["88243.4", "0.00001628", "0", "1"]], "ts": "1741338247905", "checksum": 413844374, "seqId": 48070609880, "prevSeqId": 48070609567}]}
{"arg": {"channel": "books", "instId": "BTC-USDT"}, "action": "update", "data": [{"asks": [["88491.8", "0.32581779", "0", "13"], ["88491.9", "0", "0", "0"], ["88492", "0.0173", "0", "3"], ["88497.8", "0.00209084", "0", "1"], ["88498.1", "0.04094", "0", "1"], ["88499.1", "0.0307363", "0", "2"], ["88500.4", "0", "0", "0"], ["88500.5", "0", "0", "0"], ["88502.8", "0", "0", "0"], ["88504.8", "0", "0", "0"], ["88510.3", "0", "0", "0"], ["88510.6", "1", "0", "1"], ["88511.9", "0", "0", "0"], ["88517.6", "0.22602057", "0", "1"], ["88521.5", "0", "0", "0"], ["88528.6", "0", "0", "0"], ["88532.4", "1.64801933", "0", "1"], ["88566.4", "3.02873809", "0", "1"], ["88606.9", "0.00052479", "0", "1"], ["88607.2", "0.1", "0", "1"], ["88607.8", "0.00001009", "0", "1"]], "bids": [["88491.7", "0.02285058", "0", "8"], ["88488", "0.00112851", "0", "1"], ["88487.9", "0", "0", "0"], ["88487.5", "0", "0", "0"], ["88486.5", "0.0001", "0", "1"], ["88486.2", "0.0001", "0", "1"], ["88486", "0", "0", "0"], ["88480.2", "0.01811448", "0", "1"], ["88479.7", "0", "0", "0"], ["88479.6", "0.08620704", "0", "1"], ["88476.7", "0.00935", "0", "1"], ["88475.9", "0", "0", "0"], ["88475.4", "0", "0", "0"], ["88471.8", "0", "0", "0"], ["88470.1", "0.02807", "0", "1"], ["88469.3", "0", "0", "0"], ["88467", "0.000018", "0", "1"], ["88462", "0.22602057", "0", "1"], ["88461.4", "0", "0", "0"], ["88460.3", "0", "0", "0"], ["88458.3", "1.67096093", "0", "1"], ["88456.2", "0.01650401", "0", "1"], ["88446.7", "0", "0", "0"], ["88445", "0.13073953", "0", "3"], ["88436.5", "0", "0", "0"], ["88434.9", "0.00086031", "0", "1"], ["88430.5", "0.00086031", "0", "1"], ["88426.1", "0.00086031", "0", "1"], ["88424.3", "3.17137254", "0", "2"], ["88243.2", "0.00015126", "0", "1"]], "ts": "1741338248005", "checksum": -1715485979, "seqId": 48070609986, "prevSeqId": 48070609880}]}
{"arg": {"channel": "books", "instId": "BTC-USDT"}, "action": "update", "data": [{"asks": [["88492", "0.0172", "0", "2"], ["88492.1", "0.0001", "0", "1"], ["88494.9", "0.02624917", "0", "1"], ["88495", "0.02897906", "0", "1"], ["88496.6", "0.0287445", "0", "1"], ["88497.9", "0.1526241", "0", "1"], ["88498.6", "0.08466563", "0", "1"], ["88499.2", "0", "0", "0"], ["88500.3", "0.08263396", "0", "1"], ["88501.7", "0.244917", "0", "3"], ["88503.5", "0", "0", "0"], ["88505.3", "0.14379303", "0", "1"], ["88506.1", "0.40092695", "0", "4"], ["88509", "1", "0", "1"], ["88510.5", "0.42931377", "0", "1"], ["88510.6", "0", "0", "0"], ["88517.6", "0.22602262", "0", "1"], ["88523.5", "0.01096146", "0", "1"], ["88550.4", "0.1", "0", "1"], ["88551.9", "0.01740333", "0", "1"], ["88552.1", "0.00137118", "0", "1"], ["88556.4", "0", "0", "0"], ["88605.2", "0", "0", "0"], ["88605.3", "0", "0", "0"], ["88605.6", "0", "0", "0"], ["88606", "0", "0", "0"], ["88606.9", "0", "0", "0"], ["88607.2", "0", "0", "0"], ["88607.8", "0", "0", "0"]], "bids": [["88486.5", "0", "0", "0"], ["88486.4", "0.0001", "0", "1"], ["88486.2", "0", "0", "0"], ["88485.7", "0.0001", "0", "1"], ["88481.9", "0.05984352", "0", "3"], ["88480.8", "0.09970085", "0", "2"], ["88480.7", "0.02990826", "0", "1"], ["88480.6", "0.02990826", "0", "1"], ["88480.5", "0.02990826", "0", "1"], ["88480.2", "0", "0", "0"], ["88480.1", "0.00056509", "0", "1"], ["88479.6", "0.05395563", "0", "1"], ["88477.6", "0.02813136", "0", "2"], ["88476.9", "0.02727589", "0", "1"], ["88473", "0.08665417", "0", "1"], ["88472.6", "0.08331271", "0", "1"], ["88472.2", "0.23579709", "0", "3"], ["88470.8", "0.29139561", "0", "2"], ["88467.3", "0.13005042", "0", "1"], ["88466.8", "0.14602282", "0", "1"], ["88462", "0", "0", "0"], ["88460.3", "0.22602262", "0", "1"], ["88456.2", "0", "0", "0"], ["88455.9", "0.01650401", "0", "1"], ["88432.2", "0", "0", "0"], ["88426.7", "0.01740333", "0", "1"], ["88422.2", "0", "0", "0"], ["88421.9", "0.00098761", "0", "1"], ["88391.5", "0.00019392", "0", "1"], ["88246.8", "0", "0", "0"], ["88246.7", "0", "0", "0"], ["88246.4", "0", "0", "0"], ["88244.9", "0", "0", "0"], ["88244.2", "0", "0", "0"], ["88243.5", "0", "0", "0"], ["88243.4", "0", "0", "0"], ["88243.2", "0", "0", "0"]], "ts": "1741338248105", "checksum": -1637921458, "seqId": 48070610218, "prevSeqId": 48070609986}]}
{"arg": {"channel": "books", "instId": "BTC-USDT"}, "action": "update", "data": [{"asks": [["88492.6", "0.002946", "0", "1"], ["88493.5", "0", "0", "0"], ["88494.9", "0", "0", "0"], ["88495", "0", "0", "0"], ["88496.6", "0", "0", "0"], ["88496.7", "0.00166276", "0", "1"], ["88497.8", "0", "0", "0"], ["88497.9", "0.13148582", "0", "2"], ["88498.6", "0", "0", "0"], ["88500.3", "0", "0", "0"], ["88505.3", "0", "0", "0"], ["88510.1", "0.048", "0", "1"], ["88513.6", "0.045", "0", "1"], ["88551.9", "0", "0", "0"], ["88554.9", "0.01740341", "0", "1"], ["88605.2", "0.0000166", "0", "1"], ["88605.3", "0.00569815", "0", "1"], ["88605.6", "0.30754406", "0", "1"], ["88606", "0.00046406", "0", "3"]], "bids": [["88488", "0.01822851", "0", "2"], ["88486.4", "0", "0", "0"], ["88486.3", "0.0002", "0", "2"], ["88486", "0.0171", "0", "1"], ["88485.7", "0", "0", "0"], ["88483.3", "0.060388", "0", "3"], ["88482.8", "0.0546125", "0", "1"], ["88482.1", "0.05981652", "0", "2"], ["88482", "0.02990826", "0", "1"], ["88481.9", "0.000027", "0", "1"], ["88480.9", "0.02990826", "0", "1"], ["88480.8", "0.02990826", "0", "1"], ["88480.6", "0", "0", "0"], ["88480.5", "0", "0", "0"], ["88479.6", "0.07937489", "0", "2"], ["88477.6", "0.000015", "0", "1"], ["88476.9", "0", "0", "0"], ["88476.1", "0", "0", "0"], ["88473", "0", "0", "0"], ["88472.6", "0", "0", "0"], ["88472.2", "0.147132", "0", "2"], ["88470.8", "0.2054633", "0", "2"], ["88467.3", "0", "0", "0"], ["88467", "0", "0", "0"], ["88466.8", "0", "0", "0"], ["88456.2", "0.01650401", "0", "1"], ["88455.9", "0", "0", "0"], ["88451", "0.50341", "0", "3"], ["88450", "0.177132", "0", "3"], ["88449", "0", "0", "0"], ["88430.9", "0.01740341", "0", "1"], ["88428.7", "0.0010274", "0", "1"], ["88428.5", "0", "0", "0"], ["88426.7", "0", "0", "0"], ["88246.8", "0.00560182", "0", "1"], ["88246.7", "0.00840315", "0", "1"], ["88246.4", "0.34056098", "0", "1"], ["88244.9", "0.00001267", "0", "1"], ["88244.2", "0.03", "0", "1"], ["88243.5", "0.03", "0", "1"]], "ts": "1741338248205", "checksum": 1305143455, "seqId": 48070610421, "prevSeqId": 48070610218}]}
{"arg": {"channel": "books", "instId": "BTC-USDT"}, "action": "update", "data": [{"asks": [["88491.8", "0.09718", "0", "4"], ["88492", "0.0171", "0", "1"], ["88492.1", "0", "0", "0"], ["88492.6", "0.0653455", "0", "1"], ["88492.7", "0.1131015", "0", "2"], ["88492.9", "0", "0", "0"], ["88493", "0.0001", "0", "1"], ["88493.6", "0.002", "0", "1"], ["88496.7", "0", "0", "0"], ["88497.9", "0.06272817", "0", "1"], ["88498.1", "0", "0", "0"], ["88499.1", "0.0186343", "0", "1"], ["88499.6", "0.02899369", "0", "1"], ["88499.7", "0.02729509", "0", "1"], ["88500.9", "0.02817361", "0", "1"], ["88501.4", "0.012102", "0", "1"], ["88501.7", "0.15655054", "0", "2"], ["88502.5", "0", "0", "0"], ["88503.3", "0.08110755", "0", "1"], ["88503.8", "0.0012006", "0", "1"], ["88503.9", "0.42749124", "0", "2"], ["88505.4", "0.08156646", "0", "1"], ["88506.1", "0.23117169", "0", "4"], ["88507.5", "0.13402834", "0", "1"], ["88508.2", "0.12540071", "0", "1"], ["88509", "0", "0", "0"], ["88510.3", "0.14228835", "0", "1"], ["88513.6", "0.132", "0", "3"], ["88515.6", "1", "0", "1"], ["88517.6", "0", "0", "0"], ["88518", "0.081", "0", "2"], ["88525.3", "0.22600424", "0", "1"], ["88528", "0.68740583", "0", "2"], ["88534", "0.06", "0", "2"], ["88535", "0.09", "0", "3"], ["88536", "0", "0", "0"], ["88553.9", "0.0174125", "0", "2"], ["88554.9", "0", "0", "0"], ["88559.6", "0.90244663", "0", "1"], ["88563.1", "0.01129139", "0", "1"], ["88591.2", "0.0226", "0", "1"], ["88599.8", "0", "0", "0"], ["88604.1", "0", "0", "0"], ["88604.3", "0", "0", "0"], ["88605.2", "0", "0", "0"], ["88605.3", "0", "0", "0"], ["88605.6", "0", "0", "0"], ["88606", "0", "0", "0"]], "bids": [["88491.7", "0.37296498", "0", "13"], ["88490.9", "0.11300358", "0", "1"], ["88490", "0.0171", "0", "1"], ["88488.3", "0.04674865", "0", "3"], ["88488.2", "0.04986902", "0", "2"], ["88486.3", "0", "0", "0"], ["88485.6", "0.000045", "0", "1"], ["88485.5", "0.02990826", "0", "1"], ["88483.4", "0.02990826", "0", "1"], ["88483.3", "0.03047974", "0", "2"], ["88482.8", "0.2288746", "0", "1"], ["88482.7", "0.33905", "0", "1"], ["88482.4", "0.1412561", "0", "3"], ["88482.3", "0.02939723", "0", "1"], ["88482.1", "0", "0", "0"], ["88482", "0.000027", "0", "1"], ["88481.9", "0.02826296", "0", "1"], ["88481.7", "0.02438873", "0", "1"], ["88481.4", "0.02825122", "0", "1"], ["88481.1", "0.02890798", "0", "1"], ["88480.9", "0", "0", "0"], ["88480.8", "0", "0", "0"], ["88480.7", "0", "0", "0"], ["88480.4", "0.00935", "0", "1"], ["88479.8", "0.33906", "0", "1"], ["88479.6", "0.06573064", "0", "1"], ["88478.6", "0.08366062", "0", "1"], ["88478.1", "0", "0", "0"], ["88478", "0", "0", "0"], ["88477.7", "0.08748527", "0", "1"], ["88477.6", "0.028085", "0", "2"], ["88477", "0.05650244", "0", "1"], ["88476.7", "0", "0", "0"], ["88476.6", "0.08208691", "0", "1"], ["88474.5", "0.14827761", "0", "1"], ["88473.9", "0.207", "0", "1"], ["88473.5", "0.002382", "0", "1"], ["88471.8", "0.13721317", "0", "1"], ["88471.5", "0.14362488", "0", "1"], ["88470.8", "0.13366331", "0", "1"], ["88470.1", "0", "0", "0"], ["88467.2", "0.22600449", "0", "1"], ["88462", "0.01650401", "0", "1"], ["88460.3", "0", "0", "0"], ["88456.2", "0", "0", "0"], ["88453", "0.06", "0", "2"], ["88451", "0.47341", "0", "2"], ["88450", "0.147132", "0", "2"], ["88440.8", "0", "0", "0"], ["88437.2", "0.01129139", "0", "1"], ["88430.9", "0", "0", "0"], ["88430.3", "0.01740236", "0", "1"], ["88352.3", "0", "0", "0"], ["88334.6", "0.01128958", "0", "1"], ["88252", "0", "0", "0"], ["88251.8", "0", "0", "0"], ["88250.7", "0", "0", "0"], ["88250", "0", "0", "0"], ["88249.9", "0", "0", "0"], ["88248.9", "0", "0", "0"], ["88247.9", "0", "0", "0"], ["88247.3", "0", "0", "0"], ["88246.9", "0", "0", "0"], ["88246.8", "0", "0", "0"], ["88246.7", "0", "0", "0"], ["88246.4", "0", "0", "0"], ["88244.9", "0", "0", "0"], ["88244.2", "0", "0", "0"], ["88243.5", "0", "0", "0"]], "ts": "1741338248305", "checksum": -1335690698, "seqId": 48070610792, "prevSeqId": 48070610421}]}
{"arg": {"channel": "books", "instId": "BTC-USDT"}, "action": "update", "data": [{"asks": [["88491.8", "0.42191524", "0", "11"], ["88492.3", "0.0001", "0", "1"], ["88492.5", "0.0001", "0", "1"], ["88492.7", "0.1130015", "0", "1"], ["88493", "0", "0", "0"], ["88497.9", "0.13684081", "0", "2"], ["88499.3", "0.02970326", "0", "1"], ["88499.4", "0.0273928", "0", "1"], ["88499.6", "0", "0", "0"], ["88499.7", "0", "0", "0"], ["88500.3", "0.0380625", "0", "2"], ["88500.7", "0.2349758", "0", "2"], ["88500.9", "0", "0", "0"], ["88501", "0.0039", "0", "1"], ["88501.4", "0.00157654", "0", "1"], ["88503", "0.08745311", "0", "1"], ["88503.3", "0", "0", "0"], ["88503.5", "0.08774907", "0", "1"], ["88503.8", "0", "0", "0"], ["88503.9", "0.33929724", "0", "1"], ["88504.6", "0.08307182", "0", "1"], ["88505.2", "0.08701545", "0", "1"], ["88505.4", "0", "0", "0"], ["88506.1", "0.24906535", "0", "4"], ["88507.1", "0.24399603", "0", "2"], ["88507.5", "0", "0", "0"], ["88507.9", "0.13175567", "0", "1"], ["88508.2", "0", "0", "0"], ["88509.7", "0.13298282", "0", "1"], ["88510", "0.15756646", "0", "2"], ["88510.1", "0.096", "0", "2"], ["88510.3", "0", "0", "0"], ["88510.5", "0.71524955", "0", "2"], ["88512.7", "1", "0", "1"], ["88513.6", "0.174", "0", "4"], ["88514.5", "0", "0", "0"], ["88514.8", "0.13626091", "0", "1"], ["88515.6", "0", "0", "0"], ["88521.5", "0.22601132", "0", "1"], ["88525.3", "0", "0", "0"], ["88529.9", "0", "0", "0"], ["88534", "0", "0", "0"], ["88535", "0.12", "0", "4"], ["88536", "0.03", "0", "1"], ["88553.9", "0.00001014", "0", "1"], ["88556.4", "0.01740209", "0", "1"], ["88603.8", "0", "0", "0"], ["88604", "0", "0", "0"]], "bids": [["88491.7", "0.10155058", "0", "9"], ["88488.3", "0", "0", "0"], ["88488.2", "0", "0", "0"], ["88488.1", "0.0001", "0", "1"], ["88487.7", "0.0001", "0", "1"], ["88486.7", "0", "0", "0"], ["88483.4", "0.05568278", "0", "2"], ["88482.8", "0.04", "0", "1"], ["88482.7", "0", "0", "0"], ["88482.4", "0", "0", "0"], ["88482.3", "0", "0", "0"], ["88482", "0", "0", "0"], ["88481.9", "0.026835", "0", "2"], ["88481.7", "0", "0", "0"], ["88481.5", "0.02831452", "0", "1"], ["88481.4", "0", "0", "0"], ["88481.3", "0.02559558", "0", "1"], ["88481.1", "0", "0", "0"], ["88480.9", "0.02923416", "0", "1"], ["88479.8", "0", "0", "0"], ["88479.6", "0.18198337", "0", "2"], ["88478.6", "0", "0", "0"], ["88478.2", "0.0788481", "0", "1"], ["88477.7", "0", "0", "0"], ["88477.4", "0.08122523", "0", "1"], ["88477", "0.07536734", "0", "1"], ["88476.6", "0.33907", "0", "1"], ["88476.4", "0.08077999", "0", "1"], ["88474.5", "0", "0", "0"], ["88474.1", "0.13632166", "0", "1"], ["88473.8", "0.12425202", "0", "1"], ["88473.5", "0", "0", "0"], ["88472.7", "0.06", "0", "2"], ["88471.8", "0", "0", "0"], ["88471.5", "0.14124447", "0", "1"], ["88471.2", "0.13210999", "0", "1"], ["88469.3", "0.00334508", "0", "1"], ["88469.2", "0.120015", "0", "5"], ["88467.2", "0", "0", "0"], ["88462", "0.22601743", "0", "1"], ["88460", "0.02151901", "0", "3"], ["88452", "0.00016958", "0", "1"], ["88451", "0.50341", "0", "3"], ["88450", "0.177132", "0", "3"], ["88432.2", "0.01740209", "0", "1"], ["88430.3", "0", "0", "0"], ["88352.4", "0", "0", "0"], ["88351.2", "0.17402093", "0", "1"], ["88350.5", "0.01129162", "0", "1"], ["88334.6", "0", "0", "0"], ["88252", "0.00002018", "0", "1"], ["88251.8", "0.00001302", "0", "1"], ["88250.7", "0.11343045", "0", "1"], ["88250", "0.11322175", "0", "21"], ["88249.9", "0.00060139", "0", "2"]], "ts": "1741338248405", "checksum": -1620820319, "seqId": 48070611052, "prevSeqId": 48070610792}]}
{"arg": {"channel": "books", "instId": "BTC-USDT"}, "action": "update", "data": [{"asks": [["88492.3", "0", "0", "0"], ["88492.5", "0", "0", "0"], ["88494", "0.03074", "0", "2"], ["88494.2", "0.0002", "0", "2"], ["88497.7", "0.02770137", "0", "1"], ["88497.8", "0.02970985", "0", "2"], ["88499.3", "0", "0", "0"], ["88499.4", "0", "0", "0"], ["88499.7", "0.02680026", "0", "1"], ["88500.3", "0", "0", "0"], ["88500.4", "0.012102", "0", "1"], ["88500.5", "0.04094", "0", "1"], ["88500.7", "0.207", "0", "1"], ["88501", "0", "0", "0"], ["88501.4", "0.08209206", "0", "1"], ["88501.9", "0.08661182", "0", "1"], ["88503", "0", "0", "0"], ["88503.5", "0", "0", "0"], ["88504.1", "0.08437908", "0", "1"], ["88504.6", "0", "0", "0"], ["88505.2", "0", "0", "0"], ["88506.1", "0.13853717", "0", "3"], ["88507.1", "0.11298309", "0", "1"], ["88507.9", "0", "0", "0"], ["88509.7", "0", "0", "0"], ["88510", "0.0171", "0", "1"], ["88518", "0.042", "0", "1"], ["88539.2", "0.0006", "0", "2"], ["88540", "0.00533926", "0", "5"], ["88540.8", "0.00001501", "0", "1"], ["88603.8", "0.00003683", "0", "1"], ["88604", "0.00001042", "0", "1"], ["88604.1", "0.0001929", "0", "5"]], "bids": [["88491.7", "0.02248699", "0", "9"], ["88490", "0", "0", "0"], ["88488.1", "0", "0", "0"], ["88487.7", "0", "0", "0"], ["88487.2", "0.0001", "0", "1"], ["88486.5", "0.0001", "0", "1"], ["88483.4", "0.04127048", "0", "2"], ["88481.9", "0.00002775", "0", "1"], ["88481.5", "0", "0", "0"], ["88481.3", "0", "0", "0"], ["88480.9", "0", "0", "0"], ["88480.4", "0.02715839", "0", "1"], ["88479.9", "0.02684515", "0", "1"], ["88479.8", "0.02888752", "0", "1"], ["88479.6", "0.12540272", "0", "1"], ["88478.2", "0", "0", "0"], ["88477.6", "0.000015", "0", "1"], ["88477.4", "0", "0", "0"], ["88477", "0", "0", "0"], ["88476.5", "0.00935", "0", "1"], ["88476.4", "0", "0", "0"], ["88474.1", "0", "0", "0"], ["88473.9", "0", "0", "0"], ["88473.8", "0", "0", "0"], ["88472.5", "0.04660488", "0", "2"], ["88471.5", "0", "0", "0"], ["88471.2", "0", "0", "0"], ["88464.8", "0.0006", "0", "2"], ["88464", "0.1183369", "0", "3"], ["88463.2", "0", "0", "0"], ["88460.3", "0.01650401", "0", "1"], ["88460", "0.005015", "0", "2"], ["88453", "0", "0", "0"], ["88452", "0.06016958", "0", "3"], ["88248.9", "0.03", "0", "1"], ["88247.9", "0.0001", "0", "1"], ["88247.3", "0.00001139", "0", "1"], ["88246.9", "0.03", "0", "1"], ["88246.8", "0.00560182", "0", "1"], ["88246.7", "0.00840315", "0", "1"], ["88246.4", "0.34056098", "0", "1"], ["88244.9", "0.00001267", "0", "1"], ["88244.2", "0.03", "0", "1"], ["88243.5", "0.03", "0", "1"]], "ts": "1741338248505", "checksum": -516807399, "seqId": 48070611253, "prevSeqId": 48070611052}]}
{"arg": {"channel": "books", "instId": "BTC-USDT"}, "action": "update", "data": [{"asks": [["88497.6", "0.00174772", "0", "1"], ["88497.8", "0.02856504", "0", "1"], ["88498.7", "0.02733308", "0", "1"], ["88501.5", "0", "0", "0"], ["88501.7", "0.21682639", "0", "3"], ["88503", "0.07856622", "0", "1"], ["88505.5", "0.13842666", "0", "1"], ["88506.1", "0.2462259", "0", "4"], ["88506.3", "0.12837686", "0", "1"], ["88508.1", "0.132191", "0", "1"], ["88509", "0.13442953", "0", "1"], ["88518", "0", "0", "0"], ["88521.5", "0.22601582", "0", "1"], ["88553.9", "0.01741326", "0", "2"], ["88556.4", "0", "0", "0"], ["88603.7", "0", "0", "0"], ["88603.8", "0", "0", "0"], ["88604", "0", "0", "0"], ["88604.1", "0", "0", "0"]], "bids": [["88487.2", "0", "0", "0"], ["88486.3", "0.0001", "0", "1"], ["88483.4", "0.06548067", "0", "3"], ["88479.7", "0.02736893", "0", "1"], ["88476.6", "0.08690698", "0", "1"], ["88475.8", "0.09086041", "0", "2"], ["88475.5", "0.07385078", "0", "1"], ["88475.4", "0.08647187", "0", "1"], ["88472.5", "0.18839818", "0", "3"], ["88472.2", "0.2702295", "0", "3"], ["88470.8", "0.20050238", "0", "2"], ["88470.5", "0.14148321", "0", "1"], ["88469.6", "0.13750166", "0", "1"], ["88462", "0.22601582", "0", "1"], ["88461.4", "0.01650401", "0", "1"], ["88460.3", "0", "0", "0"], ["88432.2", "0", "0", "0"], ["88428.8", "0.01740312", "0", "1"], ["88246.7", "0", "0", "0"], ["88246.4", "0", "0", "0"], ["88244.9", "0", "0", "0"], ["88244.2", "0", "0", "0"], ["88243.5", "0", "0", "0"]], "ts": "1741338248605", "checksum": -216251112, "seqId": 48070611317, "prevSeqId": 48070611253}]}
{"arg": {"channel": "books", "instId": "BTC-USDT"}, "action": "update", "data": [{"asks": [["88491.8", "0.43555524", "0", "12"], ["88494", "0.0171", "0", "1"], ["88497.6", "0", "0", "0"], ["88497.7", "0", "0", "0"], ["88497.8", "0.00169944", "0", "1"], ["88498.3", "0.02980613", "0", "1"], ["88498.4", "0.02989277", "0", "1"], ["88498.7", "0", "0", "0"], ["88499.3", "0.02446986", "0", "1"], ["88499.7", "0", "0", "0"], ["88500.1", "0.012102", "0", "1"], ["88500.2", "0.02830259", "0", "1"], ["88500.4", "0", "0", "0"], ["88501.4", "0", "0", "0"], ["88501.7", "0.15655054", "0", "2"], ["88501.9", "0", "0", "0"], ["88502", "0.10263274", "0", "2"], ["88502.5", "0.08866403", "0", "1"], ["88503", "0", "0", "0"], ["88503.6", "0.08200836", "0", "1"], ["88504.1", "0", "0", "0"], ["88504.6", "0.08058838", "0", "1"], ["88505.5", "0", "0", "0"], ["88506.1", "0.402796", "0", "5"], ["88506.3", "0", "0", "0"], ["88506.8", "0.15514455", "0", "2"], ["88508.1", "0", "0", "0"], ["88508.7", "0.16275834", "0", "2"], ["88509", "0", "0", "0"], ["88509.5", "0.13001487", "0", "1"], ["88530", "0.00001138", "0", "1"], ["88603.7", "0.00001139", "0", "1"], ["88603.8", "0.00003683", "0", "1"], ["88604", "0.00001042", "0", "1"], ["88604.1", "0.0001929", "0", "5"]], "bids": [["88491.7", "0.05678699", "0", "10"], ["88490", "0.0171", "0", "1"], ["88487.5", "0.0001", "0", "1"], ["88487.4", "0.0001", "0", "1"], ["88486.5", "0", "0", "0"], ["88486.3", "0", "0", "0"], ["88483.4", "0.0740415", "0", "3"], ["88480.9", "0.02865677", "0", "1"], ["88480.5", "0.02682608", "0", "1"], ["88480.4", "0", "0", "0"], ["88480.3", "0.05594432", "0", "2"], ["88479.9", "0", "0", "0"], ["88479.8", "0", "0", "0"], ["88479.7", "0", "0", "0"], ["88479.6", "0.13626399", "0", "1"], ["88477.2", "0.08690285", "0", "1"], ["88476.7", "0.05981652", "0", "2"], ["88476.6", "0", "0", "0"], ["88476.4", "0.08155868", "0", "1"], ["88476.1", "0.01996076", "0", "1"], ["88476", "0.0809543", "0", "2"], ["88475.9", "0.0785643", "0", "1"], ["88475.8", "0.00852541", "0", "1"], ["88475.5", "0", "0", "0"], ["88475.4", "0.01996076", "0", "1"], ["88473.1", "0.14439719", "0", "1"], ["88472.8", "0.12372212", "0", "1"], ["88472.5", "0.04660488", "0", "2"], ["88472.2", "0.147132", "0", "2"], ["88471", "0.47824538", "0", "2"], ["88470.8", "0.13366331", "0", "1"], ["88470.5", "0", "0", "0"], ["88470.2", "0.14398301", "0", "1"], ["88469.6", "0", "0", "0"], ["88462", "0.24251983", "0", "2"], ["88461.4", "0", "0", "0"], ["88247.3", "0", "0", "0"], ["88246.9", "0", "0", "0"], ["88246.8", "0", "0", "0"]], "ts": "1741338248705", "checksum": -415780339, "seqId": 48070611432, "prevSeqId": 48070611317}]}
{"arg": {"channel": "books", "instId": "BTC-USDT"}, "action": "update", "data": [{"asks": [["88491.8", "0.36212911", "0", "10"], ["88494.2", "0.0001", "0", "1"], ["88494.3", "0.0001", "0", "1"], ["88497.8", "0", "0", "0"], ["88498.3", "0", "0", "0"], ["88498.4", "0", "0", "0"], ["88499.3", "0", "0", "0"], ["88500.1", "0", "0", "0"], ["88500.2", "0", "0", "0"], ["88500.4", "0.01347904", "0", "2"], ["88500.5", "0.0675326", "0", "2"], ["88500.9", "0.002826", "0", "1"], ["88502", "0.0171", "0", "1"], ["88502.5", "0", "0", "0"], ["88503.6", "0", "0", "0"], ["88504.6", "0", "0", "0"], ["88504.9", "0.08269405", "0", "1"], ["88506.1", "0.29889061", "0", "4"], ["88506.8", "0.01888533", "0", "1"], ["88508.7", "0.01255986", "0", "1"], ["88509.5", "0", "0", "0"], ["88509.8", "0.14510445", "0", "1"], ["88512.7", "0", "0", "0"], ["88514.2", "0.11297405", "0", "1"], ["88514.3", "1", "0", "1"], ["88604.3", "0.00001362", "0", "1"], ["88605.2", "0.0000166", "0", "1"], ["88605.3", "0.00569815", "0", "1"], ["88605.6", "0.30754406", "0", "1"]], "bids": [["88491.7", "0.07618699", "0", "11"], ["88488.2", "0.0001", "0", "1"], ["88488.1", "0.01961795", "0", "1"], ["88487.8", "0.0001", "0", "1"], ["88487.5", "0", "0", "0"], ["88487.4", "0", "0", "0"], ["88483.4", "0.10145335", "0", "3"], ["88480.9", "0", "0", "0"], ["88480.6", "0.02870438", "0", "1"], ["88480.5", "0", "0", "0"], ["88480.3", "0", "0", "0"], ["88479.7", "0.05981652", "0", "2"], ["88479.6", "0.15320969", "0", "2"], ["88477.6", "0.03993652", "0", "3"], ["88477.2", "0", "0", "0"], ["88476.7", "0.02990826", "0", "1"], ["88476.4", "0", "0", "0"], ["88476.2", "0.08698745", "0", "1"], ["88476", "0.00734477", "0", "1"], ["88475.9", "0", "0", "0"], ["88473.1", "0", "0", "0"], ["88472.8", "0", "0", "0"], ["88471.3", "0.13122503", "0", "1"], ["88471", "0.33929724", "0", "1"], ["88470.2", "0", "0", "0"], ["88463.9", "0.01650401", "0", "1"], ["88462", "0.22601645", "0", "1"], ["88247.3", "0.00001139", "0", "1"], ["88246.9", "0.03", "0", "1"], ["88246.8", "0.00560182", "0", "1"]], "ts": "1741338248805", "checksum": -803280964, "seqId": 48070611640, "prevSeqId": 48070611432}]}
{"arg": {"channel": "books", "instId": "BTC-USDT"}, "action": "update", "data": [{"asks": [["88491.8", "0.28350911", "0", "8"], ["88494.2", "0.0002", "0", "2"], ["88494.3", "0", "0", "0"], ["88495.5", "0.01991993", "0", "2"], ["88497.9", "0.06272817", "0", "1"], ["88499.2", "0.02717199", "0", "1"], ["88499.3", "0.02860328", "0", "1"], ["88500.2", "0.012102", "0", "1"], ["88500.3", "0.02659441", "0", "1"], ["88500.4", "0", "0", "0"], ["88500.5", "0.04094", "0", "1"], ["88500.7", "0.02584055", "0", "1"], ["88502.9", "0.08801845", "0", "1"], ["88503.5", "0.08704808", "0", "1"], ["88504.6", "0.08160168", "0", "1"], ["88504.9", "0", "0", "0"], ["88505.1", "0.08817789", "0", "1"], ["88506.1", "0.28325673", "0", "3"], ["88507.1", "0.24631145", "0", "2"], ["88507.8", "0.13500975", "0", "1"], ["88509.7", "0.14927508", "0", "1"], ["88509.8", "0", "0", "0"], ["88510", "0.14682815", "0", "2"], ["88531", "1", "0", "1"], ["88557.7", "0.07331641", "0", "1"], ["88603.7", "0", "0", "0"], ["88603.8", "0", "0", "0"], ["88604", "0", "0", "0"], ["88604.1", "0", "0", "0"], ["88604.3", "0", "0", "0"], ["88605.2", "0", "0", "0"], ["88605.3", "0", "0", "0"], ["88605.6", "0", "0", "0"]], "bids": [["88491.7", "0.1576161", "0", "13"], ["88488.2", "0", "0", "0"], ["88488.1", "0.01981795", "0", "3"], ["88487.8", "0", "0", "0"], ["88483.4", "0.18825163", "0", "3"], ["88482.3", "0.33905", "0", "1"], ["88481.9", "0.02994277", "0", "1"], ["88481.5", "0.02875229", "0", "1"], ["88481.3", "0.02750085", "0", "1"], ["88480.8", "0.02699482", "0", "1"], ["88480.7", "0.00935", "0", "1"], ["88480.6", "0", "0", "0"], ["88479.6", "0.11803147", "0", "2"], ["88478.2", "0.08323366", "0", "1"], ["88477.3", "0.08873298", "0", "1"], ["88477", "0.0788767", "0", "1"], ["88476.5", "0", "0", "0"], ["88476.4", "0.08092878", "0", "1"], ["88476.2", "0", "0", "0"], ["88476.1", "0", "0", "0"], ["88474.1", "0.13202007", "0", "1"], ["88473.9", "0.207", "0", "1"], ["88473.7", "0.12651114", "0", "1"], ["88471.5", "0.13595312", "0", "1"], ["88471.3", "0", "0", "0"], ["88471.2", "0.13451241", "0", "1"], ["88464.1", "0.01650401", "0", "1"], ["88463.9", "0", "0", "0"], ["88462", "0.22601406", "0", "1"], ["88250", "0", "0", "0"], ["88249.9", "0", "0", "0"], ["88248.9", "0", "0", "0"], ["88247.9", "0", "0", "0"], ["88247.3", "0", "0", "0"], ["88246.9", "0", "0", "0"], ["88246.8", "0", "0", "0"]], "ts": "1741338248905", "checksum": 1946149, "seqId": 48070611797, "prevSeqId": 48070611640}]}
{"arg": {"channel": "books", "instId": "BTC-USDT"}, "action": "update", "data": [{"asks": [["88500.9", "0", "0", "0"], ["88603.7", "0.00001139", "0", "1"]], "bids": [["88483.4", "0.29237256", "0", "2"], ["88482", "0.000027", "0", "1"], ["88480.5", "0.33906", "0", "1"], ["88479.7", "0", "0", "0"], ["88479.6", "0.22869358", "0", "1"], ["88478.8", "0.33906", "0", "1"], ["88477.6", "0.000015", "0", "1"], ["88476.7", "0", "0", "0"], ["88475.4", "0", "0", "0"], ["88465.1", "0.91895064", "0", "2"], ["88464.1", "0", "0", "0"], ["88458", "0.0968111", "0", "1"]], "ts": "1741338249005", "checksum": 445554441, "seqId": 48070611827, "prevSeqId": 48070611797}]}
{"arg": {"channel": "books", "instId": "BTC-USDT"}, "action": "update", "data": [{"asks": [["88500.2", "0.03715983", "0", "2"], ["88500.3", "0", "0", "0"], ["88500.6", "0.02642386", "0", "1"], ["88500.7", "0.00105", "0", "1"], ["88503.4", "0.07986697", "0", "1"], ["88503.5", "0", "0", "0"], ["88504.5", "0.08208782", "0", "1"], ["88504.6", "0", "0", "0"], ["88506.1", "0.21795854", "0", "3"], ["88507", "0.13709652", "0", "1"], ["88507.1", "0.11298309", "0", "1"], ["88509.6", "0.13586823", "0", "1"], ["88509.7", "0", "0", "0"], ["88512.9", "1", "0", "1"], ["88514.3", "0", "0", "0"], ["88521.5", "0.22601335", "0", "1"], ["88547.6", "0.01474356", "0", "1"], ["88557.7", "0", "0", "0"], ["88603.7", "0", "0", "0"]], "bids": [["88491.7", "0.1382161", "0", "12"], ["88481.5", "0", "0", "0"], ["88481.4", "0.02721923", "0", "1"], ["88476.4", "0", "0", "0"], ["88476.3", "0.08825876", "0", "1"], ["88474.1", "0", "0", "0"], ["88474", "0.1392941", "0", "1"], ["88471.5", "0", "0", "0"], ["88471.4", "0.13040417", "0", "1"], ["88471.2", "0", "0", "0"], ["88471.1", "0.14355258", "0", "1"], ["88462", "0.22601335", "0", "1"]], "ts": "1741338249105", "checksum": -116342483, "seqId": 48070611873, "prevSeqId": 48070611827}]}
{"arg": {"channel": "books", "instId": "BTC-USDT"}, "action": "update", "data": [{"asks": [["88491.8", "0.26712911", "0", "7"], ["88495.5", "0.00627993", "0", "1"], ["88497.9", "0.0423826", "0", "1"], ["88498.4", "0.01364", "0", "1"], ["88499.2", "0", "0", "0"], ["88499.3", "0.02876795", "0", "1"], ["88499.5", "0.02847571", "0", "1"], ["88500.2", "0", "0", "0"], ["88500.5", "0.012102", "0", "1"], ["88500.6", "0.002805", "0", "1"], ["88500.7", "0", "0", "0"], ["88502.9", "0", "0", "0"], ["88503.1", "0.08215512", "0", "1"], ["88503.4", "0", "0", "0"], ["88504.5", "0", "0", "0"], ["88505", "0.04094", "0", "1"], ["88505.1", "0", "0", "0"], ["88505.2", "0.08080038", "0", "1"], ["88506.1", "0.13853717", "0", "3"], ["88507", "0", "0", "0"], ["88507.8", "0", "0", "0"], ["88509.6", "0", "0", "0"], ["88510", "0.0171", "0", "1"], ["88510.1", "0.23603834", "0", "3"], ["88510.5", "0.42931377", "0", "1"], ["88512.9", "0", "0", "0"], ["88516.9", "1.016", "0", "2"], ["88530", "0.1630998", "0", "2"], ["88545.8", "0.05857378", "0", "1"], ["88547.6", "0", "0", "0"], ["88603.7", "0.00001139", "0", "1"], ["88603.8", "0.00003683", "0", "1"], ["88604", "0.00001042", "0", "1"], ["88604.1", "0.0001929", "0", "5"], ["88604.3", "0.00001362", "0", "1"], ["88605.2", "0.0000166", "0", "1"]], "bids": [["88491.7", "0.22577526", "0", "16"], ["88483.6", "0.00935", "0", "1"], ["88482", "0.02769945", "0", "1"], ["88481.9", "0", "0", "0"], ["88481.6", "0.02743815", "0", "1"], ["88481.4", "0", "0", "0"], ["88481.3", "0", "0", "0"], ["88480.9", "0.02808254", "0", "1"], ["88480.8", "0", "0", "0"], ["88480.7", "0", "0", "0"], ["88479.6", "0.12539972", "0", "1"], ["88478.3", "0.08355099", "0", "1"], ["88478.2", "0", "0", "0"], ["88477.5", "0.08716442", "0", "1"], ["88477.3", "0", "0", "0"], ["88477", "0.02807", "0", "1"], ["88476.3", "0", "0", "0"], ["88474", "0", "0", "0"], ["88473.7", "0", "0", "0"], ["88472.5", "0.01853488", "0", "1"], ["88471.4", "0", "0", "0"], ["88471.1", "0", "0", "0"], ["88401.9", "0", "0", "0"], ["88390.2", "0.1", "0", "1"], ["88355.5", "0.173985", "0", "1"], ["88250", "0.11322175", "0", "21"], ["88249.9", "0.00060139", "0", "2"], ["88248.9", "0.03", "0", "1"], ["88247.9", "0.0001", "0", "1"], ["88247.3", "0.00001139", "0", "1"], ["88246.9", "0.03", "0", "1"]], "ts": "1741338249205", "checksum": -2038420913, "seqId": 48070611957, "prevSeqId": 48070611873}]}
{"arg": {"channel": "books", "instId": "BTC-USDT"}, "action": "update", "data": [{"asks": [["88497.9", "0.07016672", "0", "2"], ["88499.4", "0.02770184", "0", "1"], ["88499.5", "0", "0", "0"], ["88500.2", "0.012102", "0", "1"], ["88500.3", "0.02533051", "0", "1"], ["88500.5", "0", "0", "0"], ["88500.6", "0", "0", "0"], ["88500.8", "0.02642114", "0", "1"], ["88503", "0.08637718", "0", "1"], ["88503.1", "0", "0", "0"], ["88503.5", "0.08599798", "0", "1"], ["88504.6", "0.07372335", "0", "1"], ["88506.1", "0.28534044", "0", "4"], ["88507.1", "0.25538422", "0", "2"], ["88507.9", "0.13280534", "0", "1"], ["88509.7", "0.13973546", "0", "1"], ["88514.8", "0.38848274", "0", "2"], ["88521.5", "0", "0", "0"], ["88523.2", "0.22602534", "0", "2"], ["88550.3", "0.03757735", "0", "1"], ["88603.8", "0", "0", "0"], ["88604", "0", "0", "0"], ["88604.1", "0", "0", "0"], ["88604.3", "0", "0", "0"], ["88605.2", "0", "0", "0"]], "bids": [["88481.9", "0.00002775", "0", "1"], ["88481.6", "0", "0", "0"], ["88481.5", "0.02709432", "0", "1"], ["88481.4", "0.02733643", "0", "1"], ["88479.6", "0.20784891", "0", "2"], ["88477.5", "0", "0", "0"], ["88477.4", "0.08361149", "0", "1"], ["88477.1", "0.07395669", "0", "1"], ["88476.5", "0.08240842", "0", "1"], ["88474.1", "0.14294814", "0", "1"], ["88473.8", "0.12226561", "0", "1"], ["88471.6", "0.14708917", "0", "1"], ["88471.2", "0.13471561", "0", "1"], ["88464.7", "0.22601047", "0", "1"], ["88462", "0", "0", "0"], ["88461.3", "0.6911137", "0", "1"], ["88458", "0", "0", "0"], ["88433.9", "0.20766153", "0", "1"], ["88430.8", "0", "0", "0"], ["88430.2", "0", "0", "0"], ["88424.7", "2.12624221", "0", "1"], ["88408.1", "0.31086481", "0", "1"], ["88378.4", "0.85637646", "0", "1"], ["88252", "0", "0", "0"], ["88251.8", "0", "0", "0"], ["88250.7", "0", "0", "0"], ["88250", "0", "0", "0"], ["88249.9", "0", "0", "0"], ["88248.9", "0", "0", "0"], ["88247.9", "0", "0", "0"], ["88247.3", "0", "0", "0"], ["88246.9", "0", "0", "0"]], "ts": "1741338249305", "checksum": -936500621, "seqId": 48070612064, "prevSeqId": 48070611957}]}
{"arg": {"channel": "books", "instId": "BTC-USDT"}, "action": "update", "data": [{"asks": [["88499.4", "0.02960665", "0", "1"], ["88500.3", "0.02579185", "0", "1"], ["88500.6", "0.002805", "0", "1"], ["88500.7", "0.02833261", "0", "1"], ["88500.8", "0", "0", "0"], ["88503", "0.08917749", "0", "1"], ["88503.5", "0.0795617", "0", "1"], ["88504.6", "0.08219538", "0", "1"], ["88505.1", "0.0831814", "0", "1"], ["88505.2", "0", "0", "0"], ["88506.1", "0.28224597", "0", "4"], ["88507.1", "0.26015563", "0", "2"], ["88507.8", "0.12637065", "0", "1"], ["88507.9", "0", "0", "0"], ["88509.7", "0.13167677", "0", "1"], ["88510", "0.15654542", "0", "2"], ["88510.1", "0.096", "0", "2"], ["88515.5", "1", "0", "1"], ["88516.9", "0.016", "0", "1"], ["88543.8", "0.00143949", "0", "1"], ["88545.8", "0", "0", "0"], ["88603.4", "0", "0", "0"], ["88603.7", "0", "0", "0"]], "bids": [["88491.7", "0.17437526", "0", "14"], ["88482", "0.000027", "0", "1"], ["88481.9", "0.0293764", "0", "1"], ["88481.5", "0.02718147", "0", "1"], ["88481.4", "0", "0", "0"], ["88481.3", "0.02437012", "0", "1"], ["88479.6", "0.2101889", "0", "2"], ["88478.3", "0", "0", "0"], ["88478.2", "0.08655969", "0", "1"], ["88477.4", "0.08009169", "0", "1"], ["88477.1", "0", "0", "0"], ["88477", "0.11179972", "0", "2"], ["88476.5", "0", "0", "0"], ["88476.4", "0.0844994", "0", "1"], ["88474.1", "0.14090821", "0", "1"], ["88473.8", "0.12643247", "0", "1"], ["88471.6", "0", "0", "0"], ["88471.5", "0.13235168", "0", "1"], ["88471.2", "0.13341628", "0", "1"], ["88351.3", "0.06198995", "0", "1"]], "ts": "1741338249405", "checksum": -1403245731, "seqId": 48070612146, "prevSeqId": 48070612064}]}
{"arg": {"channel": "books", "instId": "BTC-USDT"}, "action": "update", "data": [{"asks": [["88494.2", "0.0001", "0", "1"], ["88494.3", "0.0001", "0", "1"], ["88514.8", "0.13626091", "0", "1"], ["88515.5", "0", "0", "0"], ["88516.9", "1.016", "0", "2"], ["88523.2", "0.000015", "0", "1"], ["88525.3", "0.22600635", "0", "1"], ["88531", "0", "0", "0"]], "bids": [["88491.7", "0.19377526", "0", "15"], ["88488.1", "0.0473357", "0", "4"], ["88486.1", "0.1", "0", "1"], ["88482.3", "0.4803061", "0", "4"], ["88481.4", "0.02825122", "0", "1"], ["88476", "0.06384721", "0", "2"], ["88467.2", "0.22600635", "0", "1"], ["88466.2", "0.01650401", "0", "1"], ["88465.1", "0.90244663", "0", "1"], ["88464.7", "0", "0", "0"], ["88254.3", "0", "0", "0"], ["88253.7", "0", "0", "0"], ["88253", "0", "0", "0"]], "ts": "1741338249505", "checksum": -495909279, "seqId": 48070612204, "prevSeqId": 48070612146}]}
{"arg": {"channel": "books", "instId": "BTC-USDT"}, "action": "update", "data": [{"asks": [["88491.8", "0.1788", "0", "6"], ["88492.7", "0", "0", "0"], ["88494.2", "0", "0", "0"], ["88494.3", "0", "0", "0"], ["88494.4", "0.0002", "0", "2"], ["88495.1", "0.11299843", "0", "1"], ["88497.9", "0.06964402", "0", "2"], ["88499.3", "0", "0", "0"], ["88499.4", "0.02629053", "0", "1"], ["88499.5", "0.02920722", "0", "1"], ["88500.2", "0", "0", "0"], ["88500.3", "0", "0", "0"], ["88500.5", "0.02627737", "0", "1"], ["88500.6", "0", "0", "0"], ["88500.7", "0", "0", "0"], ["88500.8", "0.02965731", "0", "1"], ["88501.5", "0.012102", "0", "1"], ["88501.6", "0.0003375", "0", "1"], ["88503", "0", "0", "0"], ["88503.1", "0.08331791", "0", "1"], ["88503.5", "0", "0", "0"], ["88503.7", "0.07992224", "0", "1"], ["88504.6", "0", "0", "0"], ["88504.8", "0.07435753", "0", "1"], ["88505.1", "0", "0", "0"], ["88505.2", "0.08213343", "0", "1"], ["88506.1", "0.28326005", "0", "4"], ["88507.1", "0.11298309", "0", "1"], ["88507.3", "0.14071762", "0", "2"], ["88507.8", "0", "0", "0"], ["88508", "0.15663464", "0", "2"], ["88509.7", "0", "0", "0"], ["88509.9", "0.13496325", "0", "1"], ["88510", "0.0171", "0", "1"], ["88510.1", "0.22884151", "0", "3"], ["88536.3", "0.18535449", "0", "2"], ["88543.8", "0", "0", "0"], ["88550.3", "0", "0", "0"], ["88550.4", "0", "0", "0"], ["88603.4", "0.00005116", "0", "5"], ["88603.7", "0.00001139", "0", "1"], ["88603.8", "0.00003683", "0", "1"], ["88604", "0.00001042", "0", "1"], ["88604.1", "0.0001929", "0", "5"]], "bids": [["88491.7", "0.21940268", "0", "16"], ["88491", "0.03903107", "0", "1"], ["88488.3", "0.0001", "0", "1"], ["88488.1", "0.0471357", "0", "2"], ["88487.7", "0.0001", "0", "1"], ["88482.1", "0.02996478", "0", "1"], ["88482", "0", "0", "0"], ["88481.9", "0.00002775", "0", "1"], ["88481.7", "0.02721527", "0", "1"], ["88481.5", "0.02477016", "0", "1"], ["88481.3", "0", "0", "0"], ["88478.4", "0.086279", "0", "1"], ["88478.2", "0", "0", "0"], ["88477.5", "0.0835273", "0", "1"], ["88477.4", "0", "0", "0"], ["88477.2", "0.07302647", "0", "1"], ["88477", "0.02807", "0", "1"], ["88476.5", "0.08221882", "0", "1"], ["88476.4", "0", "0", "0"], ["88474.3", "0.14374394", "0", "1"], ["88474.1", "0", "0", "0"], ["88473.9", "0.33475589", "0", "2"], ["88473.8", "0", "0", "0"], ["88472.9", "0", "0", "0"], ["88471.6", "0.14562139", "0", "1"], ["88471.5", "0", "0", "0"], ["88471.4", "0.14650805", "0", "1"], ["88471.2", "0", "0", "0"], ["88467.3", "0.01650401", "0", "1"], ["88466.2", "0", "0", "0"], ["88294", "0.0091", "0", "3"], ["88255.6", "0", "0", "0"], ["88255", "0", "0", "0"]], "ts": "1741338249605", "checksum": 753081438, "seqId": 48070612316, "prevSeqId": 48070612204}]}
{"arg": {"channel": "books", "instId": "BTC-USDT"}, "action": "update", "data": [{"asks": [["88492.6", "0", "0", "0"], ["88494.2", "0.0001", "0", "1"], ["88494.3", "0.0001", "0", "1"], ["88494.4", "0", "0", "0"], ["88495", "0.05955458", "0", "1"], ["88499.4", "0", "0", "0"], ["88499.5", "0", "0", "0"], ["88499.6", "0.02671493", "0", "1"], ["88499.7", "0.02643461", "0", "1"], ["88500.5", "0", "0", "0"], ["88500.6", "0.02434847", "0", "1"], ["88503.1", "0", "0", "0"], ["88503.3", "0.08857564", "0", "1"], ["88503.7", "0", "0", "0"], ["88503.9", "0.42575311", "0", "2"], ["88504.8", "0", "0", "0"], ["88504.9", "0.07847998", "0", "1"], ["88506.1", "0.2822825", "0", "4"], ["88507.3", "0.00001138", "0", "1"], ["88507.5", "0.13958261", "0", "1"], ["88508", "0.0171", "0", "1"], ["88508.2", "0.13306238", "0", "1"], ["88509.9", "0", "0", "0"], ["88510", "0.15640065", "0", "2"], ["88515.6", "1", "0", "1"], ["88516.9", "0.016", "0", "1"], ["88550.5", "0.1", "0", "1"], ["88603.8", "0", "0", "0"], ["88604", "0", "0", "0"], ["88604.1", "0", "0", "0"]], "bids": [["88491.7", "0.20000268", "0", "15"], ["88488.3", "0", "0", "0"], ["88488.2", "0.0001", "0", "1"], ["88488.1", "0.01961795", "0", "1"], ["88487.7", "0", "0", "0"], ["88486.1", "0", "0", "0"], ["88484.7", "0.0001", "0", "1"], ["88482.3", "0.5095162", "0", "5"], ["88482.1", "0", "0", "0"], ["88482", "0.000027", "0", "1"], ["88481.9", "0.02991478", "0", "1"], ["88481.7", "0.02656771", "0", "1"], ["88481.5", "0", "0", "0"], ["88478.6", "0.08745428", "0", "1"], ["88478.4", "0", "0", "0"], ["88477.7", "0.07877336", "0", "1"], ["88477.5", "0", "0", "0"], ["88477.4", "0.07884774", "0", "1"], ["88477.2", "0", "0", "0"], ["88474.5", "0.14038618", "0", "1"], ["88474.3", "0", "0", "0"], ["88474.1", "0.12179054", "0", "1"], ["88473.9", "0.207", "0", "1"], ["88471.5", "0.15057301", "0", "1"], ["88471.4", "0", "0", "0"], ["88451", "0.44341", "0", "1"], ["88450", "0.207132", "0", "4"], ["88449", "0.03", "0", "1"]], "ts": "1741338249705", "checksum": -2054814881, "seqId": 48070612420, "prevSeqId": 48070612316}]}
{"arg": {"channel": "books", "instId": "BTC-USDT"}, "action": "update", "data": [{"asks": [["88494.2", "0", "0", "0"], ["88494.3", "0", "0", "0"], ["88494.4", "0.0002", "0", "2"], ["88501.5", "0", "0", "0"], ["88501.6", "0.012102", "0", "1"], ["88510.5", "0.73294177", "0", "2"], ["88514.2", "1.11297405", "0", "2"], ["88515.6", "0", "0", "0"], ["88525.3", "0", "0", "0"], ["88527.3", "0.22600162", "0", "1"], ["88534.9", "0.07817355", "0", "1"], ["88536.3", "0.183915", "0", "1"], ["88603.8", "0.00003683", "0", "1"], ["88604", "0.00001042", "0", "1"]], "bids": [["88488.2", "0", "0", "0"], ["88484.7", "0.0002", "0", "2"], ["88467.3", "0", "0", "0"], ["88467.2", "0.24250601", "0", "2"], ["88465.6", "0.0006", "0", "2"], ["88464.8", "0.0002989", "0", "1"], ["88464", "0.118038", "0", "2"], ["88463", "0.0770631", "0", "1"], ["88453", "0.06", "0", "2"], ["88452", "0.00016958", "0", "1"], ["88451", "0.50341", "0", "3"], ["88450", "0.177132", "0", "3"], ["88449", "0", "0", "0"]], "ts": "1741338249805", "checksum": -1431025510, "seqId": 48070612475, "prevSeqId": 48070612420}]}
{"arg": {"channel": "books", "instId": "BTC-USDT"}, "action": "update", "data": [{"asks": [["88492.5", "0.06534552", "0", "1"], ["88492.6", "0.11300157", "0", "1"], ["88494.2", "0.0001", "0", "1"], ["88494.4", "0.0001", "0", "1"], ["88495", "0", "0", "0"], ["88495.1", "0", "0", "0"], ["88497.9", "0.06181445", "0", "2"], ["88499.4", "0.02751346", "0", "1"], ["88499.5", "0.02806648", "0", "1"], ["88499.6", "0", "0", "0"], ["88499.7", "0", "0", "0"], ["88500.4", "0.02619335", "0", "1"], ["88500.6", "0", "0", "0"], ["88501.7", "0.21596939", "0", "3"], ["88503.1", "0.08721121", "0", "1"], ["88503.3", "0", "0", "0"], ["88503.6", "0.09017704", "0", "1"], ["88503.9", "0.33929724", "0", "1"], ["88504.2", "0.002805", "0", "1"], ["88504.7", "0.08186045", "0", "1"], ["88504.9", "0", "0", "0"], ["88506.1", "0.28058196", "0", "4"], ["88507.2", "0.1541748", "0", "2"], ["88507.5", "0", "0", "0"], ["88508", "0.14956459", "0", "2"], ["88508.2", "0", "0", "0"], ["88509.8", "0.13327779", "0", "1"], ["88510", "0.0171", "0", "1"], ["88512.8", "1.33929724", "0", "2"], ["88514.2", "0.11297405", "0", "1"], ["88603.8", "0", "0", "0"], ["88604", "0", "0", "0"]], "bids": [["88491", "0", "0", "0"], ["88482.3", "0.4803061", "0", "4"], ["88482.1", "0.02629084", "0", "1"], ["88482", "0", "0", "0"], ["88481.9", "0.00002775", "0", "1"], ["88481.7", "0", "0", "0"], ["88481.6", "0.02667645", "0", "1"], ["88481.4", "0.05540788", "0", "2"], ["88478.6", "0", "0", "0"], ["88478.3", "0.08520137", "0", "1"], ["88477.7", "0", "0", "0"], ["88477.5", "0.08856293", "0", "1"], ["88477.4", "0", "0", "0"], ["88477.2", "0.07853005", "0", "1"], ["88474.5", "0", "0", "0"], ["88474.2", "0.13732032", "0", "1"], ["88474.1", "0", "0", "0"], ["88473.9", "0.33073278", "0", "2"], ["88471.5", "0", "0", "0"], ["88471.3", "0.14085463", "0", "1"], ["88463", "0", "0", "0"], ["88255.6", "0.12221196", "0", "1"], ["88255", "0.01785714", "0", "1"], ["88254.3", "0.00012967", "0", "2"]], "ts": "1741338249905", "checksum": -541512652, "seqId": 48070612558, "prevSeqId": 48070612475}]}
{"arg": {"channel": "books", "instId": "BTC-USDT"}, "action": "update", "data": [{"asks": [["88494.2", "0.0002", "0", "2"], ["88494.4", "0", "0", "0"], ["88499.3", "0.02756255", "0", "1"], ["88499.4", "0.02979442", "0", "1"], ["88499.5", "0", "0", "0"], ["88500.4", "0", "0", "0"], ["88500.8", "0", "0", "0"], ["88503", "0.08112198", "0", "1"], ["88503.1", "0", "0", "0"], ["88503.6", "0", "0", "0"], ["88504.7", "0", "0", "0"], ["88505.2", "0", "0", "0"], ["88506.1", "0.28049295", "0", "4"], ["88507.2", "0.01364", "0", "1"], ["88508", "0.0171", "0", "1"], ["88509.8", "0", "0", "0"], ["88510.1", "0.096", "0", "2"], ["88521.5", "0.22601211", "0", "1"], ["88527.3", "0", "0", "0"], ["88532", "1.00001501", "0", "2"], ["88553.9", "0.00001014", "0", "1"], ["88555.4", "0.01740263", "0", "1"], ["88603.8", "0.00003683", "0", "1"], ["88604", "0.00001042", "0", "1"], ["88604.1", "0.0001929", "0", "5"], ["88604.3", "0.00001362", "0", "1"], ["88605.2", "0.0000166", "0", "1"], ["88605.3", "0.00569815", "0", "1"]], "bids": [["88491.7", "0.13663268", "0", "13"], ["88482.3", "0.33905", "0", "1"], ["88482.1", "0", "0", "0"], ["88482", "0.02814917", "0", "1"], ["88481.6", "0", "0", "0"], ["88481.4", "0", "0", "0"], ["88480.9", "0", "0", "0"], ["88478.3", "0", "0", "0"], ["88477.5", "0", "0", "0"], ["88477.4", "0.07955718", "0", "1"], ["88477.2", "0", "0", "0"], ["88476.5", "0", "0", "0"], ["88474.2", "0", "0", "0"], ["88473.9", "0.207", "0", "1"], ["88471.6", "0", "0", "0"], ["88471.3", "0", "0", "0"], ["88467.2", "0", "0", "0"], ["88466.2", "0.01650401", "0", "1"], ["88465.6", "0", "0", "0"], ["88464.8", "0.0005989", "0", "2"], ["88464", "0.1183369", "0", "3"], ["88462", "0.22601211", "0", "1"], ["88453", "0", "0", "0"], ["88452", "0.06016958", "0", "3"], ["88432.1", "0.09936263", "0", "2"], ["88428.8", "0", "0", "0"], ["88355.6", "0.17402638", "0", "1"], ["88351.2", "0", "0", "0"], ["88253.7", "0.00326441", "0", "1"], ["88253", "0.00001297", "0", "1"], ["88252", "0.00002018", "0", "1"], ["88251.8", "0.00001302", "0", "1"], ["88250.7", "0.11343045", "0", "1"], ["88250", "0.11322175", "0", "21"], ["88249.9", "0.00060139", "0", "2"], ["88248.9", "0.03", "0", "1"], ["88247.9", "0.0001", "0", "1"], ["88247.3", "0.00001139", "0", "1"], ["88246.9", "0.03", "0", "1"]], "ts": "1741338250005", "checksum": 1553380444, "seqId": 48070612665, "prevSeqId": 48070612558}]}
{"arg": {"channel": "books", "instId": "BTC-USDT"}, "action": "update", "data": [{"asks": [["88491.8", "0.26347", "0", "8"], ["88493.5", "0.01364", "0", "1"], ["88497.9", "0.12195625", "0", "1"], ["88498", "0.04664817", "0", "2"], ["88498.1", "0.02626592", "0", "1"], ["88498.4", "0", "0", "0"], ["88498.9", "0.02578955", "0", "1"], ["88499.3", "0", "0", "0"], ["88499.4", "0", "0", "0"], ["88499.8", "0.02751439", "0", "1"], ["88500.1", "0.04094", "0", "1"], ["88500.7", "0.207", "0", "1"], ["88501.7", "0.30461024", "0", "4"], ["88502.3", "0.08738915", "0", "1"], ["88503", "0", "0", "0"], ["88503.1", "0.07505774", "0", "1"], ["88504.1", "0.08460673", "0", "1"], ["88504.2", "0", "0", "0"], ["88505", "0", "0", "0"], ["88505.9", "0.13357475", "0", "1"], ["88506.1", "0.25492648", "0", "4"], ["88506.3", "0.13772568", "0", "1"], ["88508.5", "0.14468427", "0", "1"], ["88508.9", "0.13510159", "0", "1"], ["88511.9", "0.02618522", "0", "1"], ["88517.6", "0.22602409", "0", "1"], ["88521.5", "0", "0", "0"], ["88527.7", "0", "0", "0"], ["88531.1", "0.02510254", "0", "1"], ["88546.7", "0", "0", "0"], ["88554.9", "0.01740269", "0", "1"], ["88555.4", "0", "0", "0"], ["88603.7", "0", "0", "0"], ["88603.8", "0", "0", "0"], ["88604", "0", "0", "0"], ["88604.1", "0", "0", "0"], ["88604.3", "0", "0", "0"], ["88605.2", "0", "0", "0"], ["88605.3", "0", "0", "0"]], "bids": [["88491.7", "0.01904441", "0", "9"], ["88485.1", "0.0001", "0", "1"], ["88484.9", "0.0001", "0", "1"], ["88484.7", "0", "0", "0"], ["88483.6", "0", "0", "0"], ["88483.4", "0.08763808", "0", "2"], ["88482.3", "0", "0", "0"], ["88482", "0", "0", "0"], ["88480.7", "0.02972659", "0", "1"], ["88480.5", "0", "0", "0"], ["88480.3", "0.05490798", "0", "2"], ["88480.2", "0.02728028", "0", "1"], ["88479.6", "0.12539972", "0", "1"], ["88478.8", "0", "0", "0"], ["88478.7", "0.00935", "0", "1"], ["88477.4", "0", "0", "0"], ["88477", "0.08214915", "0", "1"], ["88476.1", "0.0878379", "0", "1"], ["88476", "0.08181631", "0", "2"], ["88475.9", "0.08859889", "0", "1"], ["88473.9", "0", "0", "0"], ["88472.9", "0.14954189", "0", "1"], ["88472.8", "0.12515444", "0", "1"], ["88472.2", "0.15165319", "0", "3"], ["88472.1", "0.02807", "0", "1"], ["88471.1", "0.14351294", "0", "1"], ["88470", "0.32841389", "0", "2"], ["88467.2", "0.015", "0", "1"], ["88466.2", "0", "0", "0"], ["88465.2", "0.01650401", "0", "1"], ["88462", "0", "0", "0"], ["88458.4", "0.22602344", "0", "1"], ["88432.1", "0.08196", "0", "1"], ["88430.6", "0.01740269", "0", "1"], ["88428.9", "0.00102735", "0", "1"], ["88428.7", "0", "0", "0"], ["88393.3", "0.00560049", "0", "1"], ["88384.1", "0.00560049", "0", "1"], ["88251.8", "0", "0", "0"], ["88250.7", "0", "0", "0"], ["88250", "0", "0", "0"], ["88249.9", "0", "0", "0"], ["88248.9", "0", "0", "0"], ["88247.9", "0", "0", "0"], ["88247.3", "0", "0", "0"], ["88246.9", "0", "0", "0"]], "ts": "1741338250105", "checksum": 1409692597, "seqId": 48070612820, "prevSeqId": 48070612665}]}
{"arg": {"channel": "books", "instId": "BTC-USDT"}, "action": "update", "data": [{"asks": [["88498", "0.04380733", "0", "2"], ["88498.1", "0.02688664", "0", "1"], ["88498.9", "0.02767333", "0", "1"], ["88499.8", "0.02649818", "0", "1"], ["88501.7", "0.24389228", "0", "3"], ["88502.3", "0.08289246", "0", "1"], ["88502.8", "0.001314", "0", "1"], ["88503.1", "0.08158206", "0", "1"], ["88504.1", "0.08149639", "0", "1"], ["88505.9", "0.13166479", "0", "1"], ["88506.1", "0.12296644", "0", "3"], ["88506.3", "0.13398546", "0", "1"], ["88508.5", "0.13577908", "0", "1"], ["88508.9", "0.13679475", "0", "1"], ["88517.6", "0", "0", "0"], ["88521.5", "0.22601959", "0", "1"], ["88603.4", "0", "0", "0"]], "bids": [["88486.4", "0.0001", "0", "1"], ["88485.4", "0.0001", "0", "1"], ["88485.1", "0", "0", "0"], ["88484.9", "0", "0", "0"], ["88483.4", "0.07439963", "0", "3"], ["88480.7", "0.02664808", "0", "1"], ["88480.3", "0.05234392", "0", "2"], ["88480.2", "0.02633385", "0", "1"], ["88479.6", "0.08913751", "0", "2"], ["88477.1", "0.05981652", "0", "2"], ["88477", "0.08575099", "0", "1"], ["88476.1", "0.08073684", "0", "1"], ["88476", "0.08624987", "0", "2"], ["88475.9", "0.08846955", "0", "1"], ["88475.4", "0.01996076", "0", "1"], ["88472.9", "0.13741101", "0", "1"], ["88472.8", "0.12380493", "0", "1"], ["88471.1", "0.14526973", "0", "1"], ["88470", "0.33425018", "0", "2"], ["88461.4", "0.22601964", "0", "1"], ["88458.4", "0", "0", "0"], ["88253", "0", "0", "0"], ["88252", "0", "0", "0"]], "ts": "1741338250205", "checksum": -2051670647, "seqId": 48070612934, "prevSeqId": 48070612820}]}
{"arg": {"channel": "books", "instId": "BTC-USDT"}, "action": "update", "data": [{"asks": [["88506.1", "0.25164081", "0", "4"], ["88511.2", "1", "0", "1"], ["88512.8", "0.33929724", "0", "1"], ["88517.6", "0.22602232", "0", "1"], ["88521.5", "0", "0", "0"], ["88528", "0.94693026", "0", "1"], ["88553.9", "0.01741336", "0", "2"], ["88554.9", "0", "0", "0"], ["88564", "1.0836372", "0", "3"]], "bids": [["88486.4", "0", "0", "0"], ["88486.2", "0.0002", "0", "2"], ["88485.4", "0", "0", "0"], ["88479.6", "0.13101546", "0", "1"], ["88461.4", "0", "0", "0"], ["88458.4", "0.22602232", "0", "1"], ["88424.8", "1.76725974", "0", "2"], ["88424.4", "0.01689242", "0", "1"], ["88378.4", "0", "0", "0"], ["88355.6", "0", "0", "0"], ["88351.4", "0.17403222", "0", "1"], ["88337.7", "0", "0", "0"], ["88253", "0.00001297", "0", "1"], ["88252", "0.00002018", "0", "1"], ["88251.8", "0.00001302", "0", "1"]], "ts": "1741338250305", "checksum": -819192006, "seqId": 48070613004, "prevSeqId": 48070612934}]}
