{"arg": {"channel": "books", "instId": "BTC-USDT"}, "action": "snapshot", "data": [{"asks": [["84130.4", "0.22869368", "0", "6"], ["84131.7", "0.005", "0", "1"], ["84133.3", "0.00101534", "0", "2"], ["84134", "0.0146", "0", "1"], ["84135.6", "0.0077261", "0", "1"], ["84136", "0.02649216", "0", "2"], ["84138", "0.0005655", "0", "1"], ["84139.4", "0.10718534", "0", "1"], ["84139.7", "0.011", "0", "1"], ["84139.8", "0.005", "0", "1"], ["84140", "0.00006696", "0", "3"], ["84140.2", "0.000015", "0", "1"], ["84140.6", "0.2025", "0", "1"], ["84140.7", "0.03854779", "0", "1"], ["84141.2", "0.01066161", "0", "2"], ["84141.8", "0.005", "0", "1"], ["84142", "0.0445909", "0", "1"], ["84142.4", "0.04", "0", "1"], ["84143.3", "0.04458902", "0", "1"], ["84143.4", "0.2824485", "0", "2"], ["84143.5", "0.53480722", "0", "2"], ["84144.1", "0.03425718", "0", "1"], ["84144.2", "0.03394825", "0", "1"], ["84144.3", "0.17829", "0", "1"], ["84144.8", "0.03169728", "0", "1"], ["84144.9", "0.05187389", "0", "3"], ["84145", "0.00001197", "0", "1"], ["84145.4", "0.01", "0", "1"], ["84145.6", "0.01055", "0", "1"], ["84146.1", "0.06", "0", "2"], ["84146.2", "0.03728865", "0", "1"], ["84146.3", "0.03165", "0", "1"], ["84146.7", "0.11890903", "0", "1"], ["84147", "0.11228184", "0", "2"], ["84147.2", "0.01603713", "0", "1"], ["84147.8", "0.23972497", "0", "1"], ["84148", "0.06", "0", "2"], ["84148.2", "0.11889515", "0", "1"], ["84148.4", "0.04", "0", "1"], ["84148.6", "0.00001501", "0", "1"], ["84148.8", "0.00516789", "0", "2"], ["84149.4", "0.06", "0", "2"], ["84149.7", "0.0000675", "0", "1"], ["84149.9", "0.01101251", "0", "3"], ["84150.1", "0.21853713", "0", "2"], ["84150.2", "0.12901106", "0", "2"], ["84150.5", "0.02808545", "0", "1"], ["84150.8", "0.05940838", "0", "1"], ["84151.2", "0.03324752", "0", "1"], ["84151.8", "0.03320271", "0", "1"], ["84152.6", "1", "0", "1"], ["84152.7", "0.17821722", "0", "1"], ["84152.8", "0.42234824", "0", "2"], ["84152.9", "0.38743294", "0", "2"], ["84153", "0.1403523", "0", "1"], ["84153.3", "0.1403523", "0", "1"], ["84154.6", "0.1871364", "0", "1"], ["84154.9", "0.00001196", "0", "1"], ["84155.1", "0.47104457", "0", "2"], ["84155.4", "0.13363749", "0", "1"], ["84155.9", "0.11890903", "0", "1"], ["84156.3", "0.00420026", "0", "1"], ["84157", "0.13380501", "0", "2"], ["84157.1", "0.08629", "0", "1"], ["84157.5", "0.11228184", "0", "2"], ["84158", "0.00001", "0", "1"], ["84158.2", "1.60908856", "0", "1"], ["84158.7", "0.11888025", "0", "1"], ["84158.8", "0.06414646", "0", "1"], ["84158.9", "0.2025", "0", "1"], ["84159.3", "0.00007557", "0", "1"], ["84159.6", "0.07016913", "0", "1"], ["84159.8", "0.00001196", "0", "1"], ["84160.1", "0.23782243", "0", "1"], ["84160.2", "0.2719792", "0", "1"], ["84160.4", "0.00357", "0", "1"], ["84160.7", "0.06245848", "0", "1"], ["84160.8", "0.00011161", "0", "1"], ["84161.6", "0.06541304", "0", "1"], ["84162.3", "0.0054", "0", "1"], ["84162.8", "0.42791722", "0", "2"], ["84163", "0.04755377", "0", "1"], ["84163.3", "0.11846252", "0", "1"], ["84163.5", "0.00007557", "0", "1"], ["84163.8", "0.4", "0", "1"], ["84164.2", "0.24217784", "0", "1"], ["84164.3", "0.35641581", "0", "1"], ["84164.5", "0.00419925", "0", "1"], ["84164.8", "0.00001196", "0", "1"], ["84164.9", "0.11890903", "0", "1"], ["84165.4", "0.000015", "0", "1"], ["84166.6", "0.00104525", "0", "3"], ["84167.5", "0.2025", "0", "1"], ["84168", "0.11228184", "0", "2"], ["84168.4", "0.52573622", "0", "1"], ["84168.5", "0.49097", "0", "1"], ["84169.6", "0.07999999", "0", "2"], ["84169.8", "0.00001196", "0", "1"], ["84169.9", "0.57087491", "0", "1"], ["84170.4", "0.03999999", "0", "1"], ["84170.6", "0.01", "0", "1"], ["84171.2", "0.12483", "0", "1"], ["84171.6", "0.17821722", "0", "1"], ["84171.9", "0.25755", "0", "1"], ["84173.2", "0.35641581", "0", "1"], ["84173.4", "0.00214", "0", "1"], ["84173.6", "0.11890903", "0", "1"], ["84173.8", "0.05873456", "0", "2"], ["84174.3", "0.01782933", "0", "1"], ["84174.7", "0.00001196", "0", "1"], ["84175", "0.1", "0", "1"], ["84175.8", "0.00419826", "0", "1"], ["84176.1", "0.2025", "0", "1"], ["84176.9", "0.02377091", "0", "1"], ["84177.4", "0.00357", "0", "1"], ["84178.5", "0.05614092", "0", "1"], ["84179", "0.0731134", "0", "1"], ["84179.1", "0.05942571", "0", "1"], ["84179.7", "0.00001196", "0", "1"], ["84180.4", "0.02388154", "0", "2"], ["84180.5", "0.17821722", "0", "1"], ["84180.6", "0.19170269", "0", "1"], ["84181.8", "0.00003887", "0", "1"], ["84182.1", "0.000015", "0", "1"], ["84182.2", "0.11892404", "0", "2"], ["84182.6", "0.35641581", "0", "1"], ["84183.2", "0.0118916", "0", "1"], ["84183.3", "0.00060645", "0", "1"], ["84183.9", "0.24961", "0", "1"], ["84184", "0.01187875", "0", "1"], ["84184.2", "0.00419766", "0", "1"], ["84184.7", "0.00001196", "0", "1"], ["84184.9", "0.00004312", "0", "1"], ["84185", "0.11698603", "0", "1"], ["84185.1", "0.1", "0", "1"], ["84185.2", "0.1", "0", "1"], ["84185.4", "0.08991011", "0", "1"], ["84185.9", "0.0054", "0", "1"], ["84187.6", "0.01774536", "0", "1"], ["84187.7", "2.88741219", "0", "1"], ["84188", "0.53008", "0", "1"], ["84189.6", "0.00001196", "0", "1"], ["84190.6", "0.00001501", "0", "1"], ["84190.8", "0.03", "0", "1"], ["84191", "0.6725316", "0", "3"], ["84191.1", "0.35641581", "0", "1"], ["84191.3", "0.11890903", "0", "1"], ["84191.5", "0.3025", "0", "2"], ["84191.6", "0.05466", "0", "1"], ["84192.1", "0.916654", "0", "1"], ["84192.6", "0.0041965", "0", "1"], ["84193.2", "0.17420416", "0", "1"], ["84194.6", "0.00001196", "0", "1"], ["84194.7", "0.08991011", "0", "1"], ["84196.3", "0.0071262", "0", "1"], ["84196.4", "0.47216", "0", "1"], ["84199", "0.00001501", "0", "1"], ["84199.1", "0.01122532", "0", "1"], ["84199.2", "1.87716699", "0", "1"], ["84199.6", "0.00001196", "0", "1"], ["84199.7", "0.35641581", "0", "1"], ["84199.8", "0.26142729", "0", "3"], ["84199.9", "0.18857973", "0", "8"], ["84200", "5.34451668", "0", "33"], ["84200.1", "0.00011161", "0", "1"], ["84200.4", "0.00419565", "0", "1"], ["84201.8", "0.09190951", "0", "1"], ["84201.9", "0.06", "0", "2"], ["84202", "0.00005073", "0", "1"], ["84202.8", "0.00002241", "0", "1"], ["84204.5", "0.00033082", "0", "3"], ["84204.7", "0.11881537", "0", "1"], ["84205", "0.00181735", "0", "1"], ["84205.2", "0.09", "0", "3"], ["84206.4", "1.96172101", "0", "1"], ["84206.5", "0.2025", "0", "1"], ["84206.7", "0.01187909", "0", "1"], ["84206.9", "3.51787", "0", "1"], ["84207.4", "0.000015", "0", "1"], ["84207.7", "0.00419514", "0", "1"], ["84208.5", "3.27187805", "0", "14"], ["84208.7", "0.00001096", "0", "1"], ["84209.3", "0.00011444", "0", "1"], ["84209.5", "0.00001197", "0", "1"], ["84210.5", "0.00013667", "0", "2"], ["84210.6", "0.21299237", "0", "1"], ["84210.8", "0.02377359", "0", "1"], ["84211.1", "0.00002037", "0", "1"], ["84211.6", "0.00012217", "0", "1"], ["84211.7", "0.00003107", "0", "2"], ["84212.1", "0.00001023", "0", "1"], ["84212.4", "0.08748", "0", "1"], ["84212.5", "0.00001995", "0", "1"], ["84213.1", "0.17821722", "0", "1"], ["84213.4", "0.00594322", "0", "1"], ["84213.5", "0.35641581", "0", "1"], ["84214.2", "0.00001575", "0", "1"], ["84214.4", "0.03565949", "0", "1"], ["84214.5", "0.00001197", "0", "1"], ["84214.8", "0.00032751", "0", "1"], ["84215.3", "0.06946337", "0", "1"], ["84215.4", "0.11879524", "0", "2"], ["84215.8", "0.00001501", "0", "1"], ["84216", "0.00001565", "0", "1"], ["84216.5", "0.00594332", "0", "1"], ["84216.6", "0.00060645", "0", "1"], ["84216.9", "0.08991011", "0", "1"], ["84217.9", "0.00419368", "0", "1"], ["84218", "0.00016867", "0", "1"], ["84218.1", "0.00001045", "0", "1"], ["84218.7", "0.08248504", "0", "2"], ["84219.2", "0.60356828", "0", "1"], ["84219.3", "1.37461514", "0", "2"], ["84219.4", "0.00001503", "0", "1"], ["84219.5", "0.00298666", "0", "1"], ["84219.7", "0.01798586", "0", "2"], ["84220.1", "0.05700028", "0", "1"], ["84221.3", "0.00037549", "0", "1"], ["84222", "0.02377246", "0", "1"], ["84222.2", "0.2025", "0", "1"], ["84222.3", "0.35641581", "0", "1"], ["84223.6", "0.00118731", "0", "1"], ["84223.7", "0.06627339", "0", "2"], ["84223.8", "0.17846554", "0", "2"], ["84224.1", "0.012379", "0", "2"], ["84224.2", "0.00003002", "0", "2"], ["84224.4", "0.00001197", "0", "1"], ["84224.7", "0.0054", "0", "1"], ["84225", "0.00017601", "0", "1"], ["84225.1", "0.00594149", "0", "1"], ["84225.2", "0.01424751", "0", "1"], ["84225.9", "0.01013516", "0", "2"], ["84226.5", "0.00002974", "0", "1"], ["84226.6", "0.00001653", "0", "1"], ["84227.3", "0.07125036", "0", "1"], ["84227.5", "0.01188298", "0", "2"], ["84227.6", "0.5224664", "0", "1"], ["84227.8", "0.00001197", "0", "1"], ["84228.4", "0.00010514", "0", "1"], ["84228.5", "0.00002372", "0", "1"], ["84228.9", "0.00008", "0", "1"], ["84229.3", "0.00597332", "0", "1"], ["84230", "0.65019762", "0", "2"], ["84230.1", "0.000548", "0", "2"], ["84230.5", "0.60594197", "0", "2"], ["84230.6", "0.00594149", "0", "1"], ["84230.7", "0.2025", "0", "1"], ["84230.9", "0.35582144", "0", "2"], ["84231.1", "0.15159501", "0", "1"], ["84232", "0.00036", "0", "1"], ["84232.2", "0.00600013", "0", "1"], ["84232.3", "0.29700048", "0", "2"], ["84232.6", "0.00001501", "0", "1"], ["84233", "0.06048728", "0", "3"], ["84233.3", "0.00101534", "0", "2"], ["84233.5", "0.00002296", "0", "1"], ["84233.8", "0.00003542", "0", "1"], ["84233.9", "0.00419323", "0", "1"], ["84234", "0.00036", "0", "1"], ["84234.4", "0.00001197", "0", "1"], ["84234.6", "0.03", "0", "1"], ["84235", "0.00025", "0", "1"], ["84235.2", "0.28745545", "0", "2"], ["84236", "0.00036", "0", "1"], ["84236.6", "0.00593", "0", "1"], ["84236.8", "0.00001738", "0", "1"], ["84237", "0.00036", "0", "1"], ["84237.2", "0.00001115", "0", "1"], ["84237.8", "0.00007018", "0", "2"], ["84238.1", "0.00006534", "0", "2"], ["84238.5", "0.71313968", "0", "1"], ["84238.6", "0.00895999", "0", "1"], ["84238.9", "0.001964", "0", "1"], ["84239.2", "0.2025", "0", "1"], ["84239.3", "0.00012358", "0", "2"], ["84239.7", "0.1792492", "0", "2"], ["84239.8", "0.35579296", "0", "1"], ["84240", "0.00039685", "0", "3"], ["84240.1", "0.00001005", "0", "1"], ["84240.2", "0.00001197", "0", "1"], ["84240.9", "0.05349948", "0", "1"], ["84241", "0.00001501", "0", "1"], ["84242", "0.0000185", "0", "1"], ["84242.1", "0.08744", "0", "1"], ["84242.4", "0.00469113", "0", "3"], ["84242.5", "0.00011938", "0", "1"], ["84242.6", "0.00419183", "0", "1"], ["84244.1", "0.00083", "0", "1"], ["84244.2", "0.03", "0", "1"], ["84244.3", "0.00605088", "0", "2"], ["84244.5", "0.04676886", "0", "1"], ["84244.6", "0.5999", "0", "1"], ["84245.2", "0.00003034", "0", "1"], ["84245.5", "0.00009384", "0", "1"], ["84245.8", "0.00040029", "0", "4"], ["84246.3", "0.00083", "0", "1"], ["84246.4", "1.89972", "0", "1"], ["84246.5", "0.00001992", "0", "1"], ["84246.9", "0.10702", "0", "1"], ["84247.2", "0.00153761", "0", "2"], ["84247.3", "0.08991011", "0", "1"], ["84247.5", "0.00001525", "0", "1"], ["84247.7", "0.21444665", "0", "2"], ["84247.8", "0.00075298", "0", "4"], ["84248.3", "0.03", "0", "1"], ["84248.4", "0.03", "0", "1"], ["84248.6", "0.24794", "0", "2"], ["84248.8", "0.00009125", "0", "1"], ["84249.1", "0.29700048", "0", "2"], ["84249.2", "0.35579296", "0", "1"], ["84249.3", "0.0001897", "0", "5"], ["84249.4", "0.000015", "0", "1"], ["84249.8", "0.01188134", "0", "1"], ["84249.9", "0.00064653", "0", "3"], ["84250", "0.00809521", "0", "30"], ["84250.7", "0.01187886", "0", "1"], ["84251.6", "0.00419151", "0", "1"], ["84252.1", "0.00002281", "0", "1"], ["84252.5", "0.00002342", "0", "2"], ["84252.6", "0.00332577", "0", "1"], ["84252.7", "0.00001362", "0", "1"], ["84252.8", "0.01511839", "0", "1"], ["84253.2", "0.03", "0", "1"], ["84253.3", "0.00001026", "0", "1"], ["84253.5", "0.00004188", "0", "4"], ["84253.7", "0.0000821", "0", "1"], ["84253.9", "0.00001787", "0", "1"], ["84254.1", "0.00594417", "0", "1"], ["84254.3", "0.00001034", "0", "1"], ["84254.5", "0.00001063", "0", "1"], ["84255", "0.00001181", "0", "1"], ["84255.4", "0.183147", "0", "1"], ["84256.1", "0.01493332", "0", "1"], ["84256.2", "0.2025", "0", "1"], ["84257.6", "0.00008291", "0", "1"], ["84258.1", "0.00003542", "0", "1"], ["84258.2", "0.35579296", "0", "1"], ["84258.3", "0.00002584", "0", "1"], ["84258.9", "0.00001016", "0", "1"], ["84259", "0.00011161", "0", "1"], ["84259.2", "0.00001197", "0", "1"], ["84259.7", "0.00419094", "0", "1"], ["84259.9", "0.00018194", "0", "1"], ["84260", "0.00033268", "0", "4"], ["84260.2", "0.00168601", "0", "1"], ["84260.6", "0.0000142", "0", "1"], ["84260.8", "0.00001852", "0", "1"], ["84261.1", "0.01299784", "0", "1"], ["84262.2", "0.00003778", "0", "1"], ["84262.4", "0.0023991", "0", "2"], ["84262.9", "0.19009601", "0", "2"], ["84263.9", "0.00003969", "0", "2"], ["84264", "0.00074396", "0", "1"], ["84264.2", "0.00001197", "0", "1"], ["84264.7", "0.2025", "0", "1"], ["84264.9", "0.00032975", "0", "4"], ["84265.1", "0.00418989", "0", "1"], ["84265.3", "0.01187878", "0", "1"], ["84265.8", "0.00001156", "0", "1"], ["84266", "0.11878326", "0", "1"], ["84266.2", "0.213955", "0", "1"], ["84266.4", "0.00001402", "0", "1"], ["84266.5", "0.00054835", "0", "1"], ["84266.6", "0.01217191", "0", "13"], ["84266.7", "0.00002129", "0", "1"], ["84266.9", "0.00013853", "0", "2"], ["84267.3", "0.35615346", "0", "2"], ["84268.4", "0.00001026", "0", "1"], ["84268.5", "0.00002533", "0", "1"], ["84268.8", "0.08991011", "0", "1"], ["84269.1", "0.00002271", "0", "1"], ["84269.2", "0.72153373", "0", "1"], ["84269.9", "0.01188887", "0", "2"], ["84270.6", "0.08741", "0", "1"], ["84270.9", "0.01783251", "0", "3"], ["84271.4", "0.00006532", "0", "1"], ["84272.7", "0.01266518", "0", "6"], ["84273.2", "0.2025", "0", "1"], ["84273.3", "0.00009539", "0", "1"], ["84274.1", "0.00001196", "0", "1"], ["84275", "0.00065712", "0", "4"], ["84275.1", "0.00002685", "0", "2"], ["84275.2", "0.00001058", "0", "1"], ["84275.3", "0.00001048", "0", "1"], ["84276", "0.00376703", "0", "1"], ["84276.5", "0.35579296", "0", "1"], ["84276.8", "0.00418927", "0", "1"], ["84276.9", "0.00001881", "0", "1"], ["84277.3", "0.00002956", "0", "2"], ["84277.5", "0.00001001", "0", "1"], ["84278.3", "0.00005514", "0", "1"], ["84278.4", "0.00001024", "0", "1"], ["84278.6", "0.00011161", "0", "1"], ["84279.3", "0.00025932", "0", "1"], ["84279.5", "0.00002946", "0", "2"], ["84279.8", "0.17821722", "0", "1"], ["84280", "0.00010199", "0", "4"], ["84280.1", "0.00043993", "0", "1"], ["84280.7", "0.01484", "0", "1"], ["84281.7", "0.20252215", "0", "2"]], "bids": [["84130.3", "1.03343178", "0", "15"], ["84130", "0.0146", "0", "1"], ["84129.9", "0.01596287", "0", "1"], ["84129.5", "0.06653846", "0", "1"], ["84129.4", "0.11892152", "0", "1"], ["84129.3", "0.00111883", "0", "1"], ["84129.2", "0.01596287", "0", "1"], ["84128.6", "0.02724879", "0", "1"], ["84128", "0.0146", "0", "1"], ["84127.8", "0.02934287", "0", "2"], ["84126", "0.0146", "0", "1"], ["84125.9", "0.01596287", "0", "1"], ["84125.3", "0.18417642", "0", "1"], ["84125.2", "0.35641581", "0", "1"], ["84124.6", "0.03854779", "0", "1"], ["84124", "0.02232481", "0", "2"], ["84123.9", "0.05196287", "0", "2"], ["84122.2", "0.000021", "0", "1"], ["84122", "0.0146", "0", "1"], ["84120.7", "0.09024533", "0", "1"], ["84120.5", "0.04016", "0", "1"], ["84120.2", "0.00001197", "0", "1"], ["84120", "0.01461", "0", "2"], ["84119.6", "0.01338", "0", "1"], ["84118.4", "0.01", "0", "2"], ["84118.3", "0.08910279", "0", "3"], ["84118.1", "0.000015", "0", "1"], ["84118", "0.0146", "0", "1"], ["84117.7", "0.11893802", "0", "1"], ["84117.6", "0.52248236", "0", "1"], ["84117.5", "1.08304047", "0", "4"], ["84116.5", "0.53470581", "0", "2"], ["84116.3", "0.048", "0", "1"], ["84116.2", "0.054", "0", "1"], ["84116.1", "0.03193072", "0", "1"], ["84116", "0.27679028", "0", "5"], ["84115.8", "0.35659", "0", "1"], ["84115.5", "0.06470677", "0", "2"], ["84115.4", "0.02378378", "0", "1"], ["84115.3", "0.00001197", "0", "1"], ["84115.2", "0.00363721", "0", "1"], ["84114.5", "0.04", "0", "1"], ["84114", "0.0146", "0", "1"], ["84113.3", "0.01189485", "0", "1"], ["84113.2", "0.16185123", "0", "1"], ["84113.1", "0.00420227", "0", "1"], ["84112.9", "0.093", "0", "2"], ["84112.7", "0.17821722", "0", "1"], ["84112", "0.0146", "0", "1"], ["84111.9", "0.08719396", "0", "3"], ["84111.8", "0.02071845", "0", "2"], ["84110.9", "0.04", "0", "1"], ["84110.5", "0.03152002", "0", "1"], ["84110.3", "0.00001197", "0", "1"], ["84110", "0.0146", "0", "1"], ["84109.7", "0.000015", "0", "1"], ["84109.6", "0.00006", "0", "1"], ["84109.2", "0.03206445", "0", "1"], ["84108.5", "0.59328303", "0", "1"], ["84108.3", "0.06196287", "0", "4"], ["84108.1", "0.12481", "0", "1"], ["84107.9", "0.17829", "0", "1"], ["84107.8", "0.35641581", "0", "1"], ["84107.7", "0.133793", "0", "1"], ["84107.4", "0.1403523", "0", "1"], ["84107.3", "0.03185255", "0", "1"], ["84106.7", "0.12128224", "0", "2"], ["84106.4", "0.11003581", "0", "3"], ["84106.2", "0.1871364", "0", "1"], ["84105.8", "0.05196287", "0", "2"], ["84105.3", "0.00001197", "0", "1"], ["84105.2", "0.51815", "0", "1"], ["84105", "1.66885977", "0", "3"], ["84104.9", "0.26116372", "0", "2"], ["84104.8", "0.48084", "0", "1"], ["84103.5", "0.06119137", "0", "1"], ["84103.2", "0.002", "0", "1"], ["84103.1", "0.01596287", "0", "1"], ["84102.1", "0.23782243", "0", "1"], ["84102", "0.17821722", "0", "1"], ["84101.9", "0.00011161", "0", "1"], ["84101.5", "0.0042031", "0", "1"], ["84101.3", "0.000015", "0", "1"], ["84100.6", "0.12781565", "0", "2"], ["84100.5", "0.40869491", "0", "1"], ["84100.4", "0.00001197", "0", "1"], ["84100.1", "0.06181976", "0", "1"], ["84100", "0.25447287", "0", "4"], ["84099.9", "0.00060645", "0", "1"], ["84099.8", "0.31273207", "0", "2"], ["84099.7", "0.05940838", "0", "1"], ["84099.6", "0.11896366", "0", "1"], ["84098.6", "0.07002442", "0", "1"], ["84098.1", "0.35641581", "0", "1"], ["84096.7", "0.00420353", "0", "1"], ["84095.4", "0.02143677", "0", "2"], ["84094.5", "0.11228184", "0", "2"], ["84093.4", "0.0054", "0", "1"], ["84093.2", "0.002", "0", "1"], ["84092.9", "0.00001501", "0", "1"], ["84092.4", "0.27987362", "0", "3"], ["84092.3", "0.08991011", "0", "1"], ["84092.2", "0.00357", "0", "1"], ["84091.3", "0.05427", "0", "1"], ["84091.2", "0.106", "0", "4"], ["84090.5", "0.00001197", "0", "1"], ["84090.4", "0.053", "0", "2"], ["84090.1", "0.11890903", "0", "1"], ["84089.8", "0.01596287", "0", "1"], ["84088.7", "0.53463303", "0", "2"], ["84087.2", "0.1", "0", "2"], ["84087.1", "0.88974254", "0", "3"], ["84086.4", "0.06", "0", "2"], ["84086", "0.2", "0", "1"], ["84085.7", "0.21846287", "0", "2"], ["84085.5", "0.00001197", "0", "1"], ["84084.7", "0.00420528", "0", "1"], ["84084.5", "0.000015", "0", "1"], ["84084", "0.11228184", "0", "2"], ["84083.9", "0.01596287", "0", "1"], ["84083.5", "0.12484", "0", "1"], ["84083.3", "0.00060645", "0", "1"], ["84083.1", "0.01596287", "0", "1"], ["84082.7", "0.02379752", "0", "1"], ["84082.3", "0.00011161", "0", "1"], ["84082.1", "0.00357", "0", "1"], ["84082", "0.00100367", "0", "1"], ["84081.6", "0.0054", "0", "1"], ["84081.1", "0.11890903", "0", "1"], ["84080.9", "0.02745264", "0", "1"], ["84080.5", "0.10001197", "0", "2"], ["84080.4", "0.02375795", "0", "2"], ["84080.2", "0.00099836", "0", "1"], ["84080", "0.00001", "0", "1"], ["84079.4", "0.01831245", "0", "1"], ["84079.3", "0.00901076", "0", "1"], ["84078.9", "0.01774536", "0", "1"], ["84078.8", "0.24968", "0", "1"], ["84078.5", "1.57957002", "0", "2"], ["84078.4", "0.35641581", "0", "1"], ["84078.3", "0.41187862", "0", "2"], ["84078.2", "0.23018009", "0", "3"], ["84077.4", "0.917903", "0", "1"], ["84076.9", "0.00004578", "0", "1"], ["84076.6", "0.00420551", "0", "1"], ["84076.5", "3.20698", "0", "1"], ["84076.1", "0.000015", "0", "1"], ["84076", "0.25446287", "0", "3"], ["84075.6", "2.80738702", "0", "2"], ["84074.5", "0.02728", "0", "1"], ["84073.9", "0.00005327", "0", "1"], ["84073.5", "0.11228184", "0", "2"], ["84073.2", "0.00005206", "0", "1"], ["84072.9", "0.01785083", "0", "1"], ["84072.4", "0.11890903", "0", "1"], ["84072.1", "0.1403523", "0", "1"], ["84072", "0.0025", "0", "1"], ["84071.7", "0.01187872", "0", "1"], ["84071", "0.00251", "0", "2"], ["84070.9", "0.10144179", "0", "2"], ["84070.6", "0.00001197", "0", "1"], ["84070", "0.24026208", "0", "3"], ["84069.9", "0.35998581", "0", "2"], ["84069", "0.0103941", "0", "1"], ["84068.5", "0.01187873", "0", "1"], ["84068", "0.00235513", "0", "1"], ["84067.7", "0.00001501", "0", "1"], ["84067.6", "0.00285085", "0", "1"], ["84067.5", "0.17821722", "0", "1"], ["84067.4", "0.2025", "0", "1"], ["84067.3", "0.00420625", "0", "1"], ["84066.7", "0.00576584", "0", "1"], ["84066.6", "0.00504382", "0", "4"], ["84065.8", "1.22670691", "0", "1"], ["84065.7", "3.45616197", "0", "2"], ["84065.4", "0.01187851", "0", "1"], ["84064.6", "0.471023", "0", "1"], ["84064.2", "0.00105053", "0", "1"], ["84064.1", "0.03", "0", "1"], ["84063.1", "0.11890903", "0", "1"], ["84062.9", "0.00713751", "0", "1"], ["84062.7", "0.59964265", "0", "1"], ["84062.6", "0.00011161", "0", "1"], ["84062.5", "0.13057584", "0", "2"], ["84062.2", "0.001427", "0", "1"], ["84061.4", "0.35641581", "0", "1"], ["84061.2", "0.00005328", "0", "1"], ["84060.7", "0.02381571", "0", "2"], ["84060.2", "0.02204823", "0", "2"], ["84060", "0.00557886", "0", "2"], ["84059.3", "0.000015", "0", "1"], ["84058.5", "0.17821722", "0", "1"], ["84057.5", "0.00007494", "0", "1"], ["84055.7", "0.00001197", "0", "1"], ["84055.5", "0.00039387", "0", "1"], ["84055.4", "0.03", "0", "1"], ["84055.2", "0.01901128", "0", "1"], ["84054.8", "0.2025", "0", "1"], ["84053.3", "0.18669947", "0", "1"], ["84053.2", "0.11890903", "0", "1"], ["84052.9", "0.3568907", "0", "1"], ["84052.3", "0.00420804", "0", "1"], ["84052.1", "0.03", "0", "1"], ["84050.9", "0.000015", "0", "1"], ["84050.8", "0.00001197", "0", "1"], ["84050.5", "0.000015", "0", "1"], ["84050", "0.00033629", "0", "3"], ["84049.9", "0.00060645", "0", "1"], ["84049.6", "0.09276684", "0", "1"], ["84049.5", "0.08925", "0", "1"], ["84048.9", "0.005944", "0", "1"], ["84048.8", "0.00600022", "0", "1"], ["84048.7", "0.17821722", "0", "1"], ["84046.8", "0.02971592", "0", "2"], ["84046.6", "0.00009543", "0", "1"], ["84046", "0.03", "0", "1"], ["84045.8", "0.20672021", "0", "3"], ["84045.7", "0.98397", "0", "1"], ["84045.1", "0.00005207", "0", "1"], ["84045", "0.00600022", "0", "1"], ["84044.9", "0.21816467", "0", "1"], ["84044.3", "0.35579296", "0", "1"], ["84044.2", "0.01804", "0", "1"], ["84043.5", "0.059969", "0", "1"], ["84043", "0.00011161", "0", "1"], ["84042.9", "1.37742", "0", "1"], ["84042.5", "0.00001501", "0", "1"], ["84042.4", "0.00001196", "0", "1"], ["84042.2", "0.07125036", "0", "1"], ["84041.7", "0.09128274", "0", "1"], ["84041.6", "0.11890903", "0", "1"], ["84040.1", "0.0054", "0", "1"], ["84039.9", "0.00016273", "0", "1"], ["84039.8", "0.17821722", "0", "1"], ["84037.9", "0.01064", "0", "1"], ["84037.7", "0.00007195", "0", "1"], ["84037.6", "0.00600022", "0", "1"], ["84037.5", "0.05952577", "0", "1"], ["84037.4", "0.17746351", "0", "1"], ["84037.3", "0.2025", "0", "1"], ["84037.2", "0.04755377", "0", "1"], ["84035.9", "0.00001196", "0", "1"], ["84035.8", "0.36767183", "0", "2"], ["84035.3", "0.01", "0", "1"], ["84035.1", "0.03569988", "0", "1"], ["84034.7", "0.14279804", "0", "2"], ["84034.1", "0.00001501", "0", "1"], ["84033.8", "0.00420994", "0", "1"], ["84033.3", "0.00101534", "0", "2"], ["84032.5", "0.11890903", "0", "1"], ["84032.4", "0.14743651", "0", "1"], ["84032.3", "0.07963908", "0", "1"], ["84031.8", "0.03", "0", "1"], ["84031.5", "0.00103791", "0", "1"], ["84031.4", "0.00012658", "0", "1"], ["84030.9", "0.00001196", "0", "1"], ["84030.3", "0.00579975", "0", "1"], ["84030.2", "0.0426", "0", "2"], ["84030.1", "0.08991011", "0", "1"], ["84030", "0.06391196", "0", "4"], ["84029.6", "0.00600022", "0", "1"], ["84029.5", "0.17821722", "0", "1"], ["84029.3", "0.22225156", "0", "1"], ["84028.8", "0.2025", "0", "1"], ["84027.7", "0.00007596", "0", "1"], ["84027.5", "0.03", "0", "1"], ["84027.3", "0.35579296", "0", "1"], ["84027", "0.0007195", "0", "1"], ["84026.6", "0.00017505", "0", "1"], ["84026.1", "0.00421091", "0", "1"], ["84025.7", "0.000015", "0", "1"], ["84025", "0.00001719", "0", "1"], ["84024.7", "0.0000313", "0", "1"], ["84024.6", "0.02377274", "0", "1"], ["84023.3", "0.00011161", "0", "1"], ["84023", "0.00001138", "0", "1"], ["84022.9", "0.00579975", "0", "1"], ["84022.8", "0.00600022", "0", "1"], ["84022.7", "0.03", "0", "1"], ["84022.6", "0.00002208", "0", "1"], ["84021.8", "0.11943723", "0", "1"], ["84021.7", "0.08924", "0", "1"], ["84021.5", "0.12470925", "0", "2"], ["84021.1", "0.00594568", "0", "1"], ["84021", "0.17822918", "0", "2"], ["84020.7", "0.59432247", "0", "1"], ["84020.3", "0.2025", "0", "1"], ["84019.8", "1.48377", "0", "1"], ["84018.9", "0.00594568", "0", "1"], ["84018.7", "0.35579296", "0", "1"], ["84017.7", "0.00001196", "0", "1"], ["84017.5", "0.1", "0", "1"], ["84017.3", "0.00001501", "0", "1"], ["84017", "0.00600022", "0", "1"], ["84016.9", "0.00421155", "0", "1"], ["84016.6", "0.00060645", "0", "1"], ["84013.3", "0.00600024", "0", "1"], ["84013.2", "0.00580022", "0", "1"], ["84013.1", "0.00599963", "0", "1"], ["84013", "0.00599963", "0", "1"], ["84012.9", "0.00594571", "0", "1"], ["84012.8", "0.00579964", "0", "1"], ["84012.7", "0.11890903", "0", "1"], ["84012.2", "0.17821722", "0", "1"], ["84011.8", "0.20850022", "0", "2"], ["84011.2", "0.00358856", "0", "1"], ["84011.1", "0.00001196", "0", "1"], ["84011", "0.1", "0", "1"], ["84010.7", "0.00005963", "0", "1"], ["84010.5", "0.00298666", "0", "1"], ["84010.2", "0.35579296", "0", "1"], ["84010.1", "0.01199926", "0", "2"], ["84010", "0.00014389", "0", "1"], ["84009", "0.00600024", "0", "1"], ["84008.9", "0.00581522", "0", "2"], ["84008.8", "0.00421282", "0", "1"], ["84008.4", "0.00001501", "0", "1"], ["84008.3", "0.00001365", "0", "1"], ["84007.9", "0.18312454", "0", "1"], ["84007.8", "0.089992", "0", "1"], ["84007.5", "0.01484", "0", "1"], ["84007.3", "0.04801297", "0", "1"], ["84006.7", "0.09", "0", "3"], ["84006.2", "0.00001196", "0", "1"], ["84005.9", "0.00600022", "0", "1"], ["84005.8", "0.00600022", "0", "1"], ["84005.7", "0.00600022", "0", "1"], ["84005.6", "0.00579964", "0", "1"], ["84005.5", "0.21628", "0", "1"], ["84005.3", "0.00001196", "0", "1"], ["84005", "0.0568", "0", "4"], ["84004.7", "0.0284", "0", "2"], ["84003.7", "0.27403916", "0", "4"], ["84003.3", "0.2025", "0", "1"], ["84002.5", "0.01729518", "0", "2"], ["84001.9", "0.00597332", "0", "1"], ["84001.6", "0.00595316", "0", "2"], ["84001.5", "0.35579296", "0", "1"], ["84001.1", "0.00008", "0", "1"], ["84000.5", "0.00001501", "0", "1"], ["84000.4", "0.00421334", "0", "1"], ["84000", "20.46992299", "0", "32"], ["83999.9", "0.06217207", "0", "9"], ["83998.9", "0.00200739", "0", "1"], ["83998.8", "0.0059995", "0", "1"], ["83998.7", "0.1", "0", "1"], ["83998.5", "0.0118952", "0", "1"], ["83996.3", "0.00001196", "0", "1"], ["83995.9", "0.00579994", "0", "1"], ["83995.8", "0.08926", "0", "1"], ["83995.6", "0.00595", "0", "1"], ["83994.9", "0.00579994", "0", "1"], ["83994.8", "0.2025", "0", "1"], ["83994.7", "0.00580024", "0", "1"], ["83994.3", "0.20821722", "0", "2"], ["83994.1", "0.214059", "0", "1"], ["83993.9", "0.00421443", "0", "1"], ["83993.5", "0.00895999", "0", "1"], ["83992.5", "0.35579296", "0", "1"], ["83992.4", "0.40201959", "0", "2"], ["83992.1", "0.00001501", "0", "1"], ["83991.7", "0.00256065", "0", "1"], ["83991.5", "0.11878326", "0", "1"], ["83991.3", "0.00001196", "0", "1"], ["83991.1", "0.0166188", "0", "1"], ["83990.8", "0.0118794", "0", "1"], ["83990.3", "0.00009235", "0", "1"], ["83989.7", "0.00579994", "0", "1"], ["83989", "0.6", "0", "1"], ["83988.3", "0.0000469", "0", "1"], ["83988", "0.00005334", "0", "1"], ["83987.8", "0.00007308", "0", "1"], ["83987.7", "0.00023813", "0", "1"], ["83987.4", "0.002378", "0", "1"], ["83987.2", "0.00579994", "0", "1"], ["83987", "0.00580024", "0", "1"], ["83986.6", "0.11912367", "0", "1"], ["83986.3", "0.20251197", "0", "2"], ["83986.1", "0.2094027", "0", "1"], ["83985.8", "0.00003265", "0", "1"], ["83985.7", "0.00001677", "0", "1"], ["83985.1", "0.01194665", "0", "1"], ["83985", "0.00001785", "0", "1"], ["83984.1", "0.00011161", "0", "1"], ["83983.7", "0.00001501", "0", "1"], ["83983.6", "0.17821722", "0", "1"], ["83983.5", "0.35579296", "0", "1"], ["83983.4", "0.00004752", "0", "1"], ["83983.3", "0.00482138", "0", "2"], ["83981.9", "0.0000492", "0", "1"], ["83981.5", "0.00005685", "0", "1"], ["83981.4", "0.00001197", "0", "1"], ["83980.6", "0.00001196", "0", "1"], ["83980.4", "0.18316", "0", "1"], ["83980", "0.00005457", "0", "1"], ["83979.7", "0.11878326", "0", "1"], ["83979.5", "0.00004344", "0", "1"], ["83978.2", "0.00421569", "0", "1"], ["83977.8", "0.2325", "0", "2"], ["83977.2", "0.00005459", "0", "1"]], "ts": "1742554938604", "checksum": 1163799098, "seqId": 49927357952, "prevSeqId": -1}], "record_time": 1742554938.607631, "EXCHANGE": "OKX"}
{"arg": {"channel": "books", "instId": "BTC-USDT"}, "action": "update", "data": [{"asks": [["84148.8", "0.00151854", "0", "1"], ["84149.7", "0", "0", "0"], ["84175", "1.3", "0", "3"], ["84281.9", "0.00002668", "0", "1"]], "bids": [["84118.8", "0.08991011", "0", "1"], ["84086", "0", "0", "0"]], "ts": "1742554938704", "checksum": -579165794, "seqId": 49927357977, "prevSeqId": 49927357952}], "record_time": 1742554938.717427, "EXCHANGE": "OKX"}
{"arg": {"channel": "books", "instId": "BTC-USDT"}, "action": "update", "data": [{"asks": [["84148.9", "0.000015", "0", "1"], ["84156.9", "0.23782851", "0", "1"], ["84158.1", "0.01774536", "0", "1"], ["84160.1", "0", "0", "0"], ["84168.8", "0.08", "0", "2"], ["84169.6", "0.03999999", "0", "1"], ["84170.4", "0", "0", "0"], ["84175", "0.1", "0", "1"], ["84187.6", "0", "0", "0"], ["84281.9", "0", "0", "0"]], "bids": [["84102.1", "0", "0", "0"], ["84100.2", "0.23782851", "0", "1"], ["84088", "0.1", "0", "2"], ["84087.2", "0.05", "0", "1"], ["84086.4", "0.01", "0", "1"], ["83987.2", "0", "0", "0"], ["83987", "0", "0", "0"], ["83977", "0.03", "0", "1"]], "ts": "1742554938804", "checksum": -579165794, "seqId": 49927358001, "prevSeqId": 49927357977}], "record_time": 1742554938.803512, "EXCHANGE": "OKX"}
{"arg": {"channel": "books", "instId": "BTC-USDT"}, "action": "update", "data": [{"asks": [["84132", "0.0146", "0", "1"], ["84144", "0.03437038", "0", "1"], ["84144.1", "0.03374597", "0", "1"], ["84144.2", "0", "0", "0"], ["84144.7", "0.06664605", "0", "2"], ["84144.8", "0", "0", "0"], ["84144.9", "0.01961648", "0", "2"], ["84149", "0.00363008", "0", "1"], ["84151", "0.03426761", "0", "1"], ["84151.2", "0", "0", "0"], ["84151.7", "0.0341988", "0", "1"], ["84151.8", "0", "0", "0"], ["84155.8", "0.23782978", "0", "1"], ["84156.9", "0", "0", "0"], ["84158.7", "0.18213993", "0", "2"], ["84158.8", "0", "0", "0"], ["84159.5", "0.06550125", "0", "1"], ["84159.6", "0", "0", "0"], ["84160.5", "0.06417441", "0", "1"], ["84160.7", "0", "0", "0"], ["84161.5", "0.06473916", "0", "1"], ["84161.6", "0", "0", "0"], ["84168.8", "0", "0", "0"], ["84169.6", "0.07999999", "0", "2"], ["84170.4", "0.03999999", "0", "1"], ["84281.7", "0", "0", "0"]], "bids": [["84130.3", "1.03357408", "0", "16"], ["84117.5", "1.05196287", "0", "3"], ["84117.4", "0.03247064", "0", "1"], ["84116.1", "0", "0", "0"], ["84116", "0.31098455", "0", "6"], ["84115.5", "0", "0", "0"], ["84115.4", "0.05457924", "0", "2"], ["84115.3", "0.03098642", "0", "2"], ["84110.5", "0", "0", "0"], ["84110.4", "0.03509878", "0", "1"], ["84109.2", "0", "0", "0"], ["84109", "0.03190081", "0", "1"], ["84103.5", "0", "0", "0"], ["84103.4", "0.06984018", "0", "1"], ["84100.2", "0", "0", "0"], ["84100.1", "0", "0", "0"], ["84100", "0.32213242", "0", "5"], ["84099.8", "0.24966", "0", "1"], ["84099.6", "0.18760924", "0", "2"], ["84098.6", "0", "0", "0"], ["84098.5", "0.06322707", "0", "1"], ["84098.2", "0.23782978", "0", "1"], ["83976.7", "0.01493332", "0", "1"], ["83976.4", "0.01783251", "0", "3"]], "ts": "1742554938904", "checksum": -514814495, "seqId": 49927358056, "prevSeqId": 49927358001}], "record_time": 1742554938.914372, "EXCHANGE": "OKX"}
{"arg": {"channel": "books", "instId": "BTC-USDT"}, "action": "update", "data": [{"asks": [["84158.1", "0", "0", "0"], ["84168.8", "0.08", "0", "2"], ["84169.6", "0.03999999", "0", "1"], ["84170.4", "0", "0", "0"], ["84187.6", "0.01774536", "0", "1"], ["84243.3", "0.059827", "0", "1"], ["84279.2", "0.089702", "0", "1"], ["84280.1", "0", "0", "0"], ["84280.7", "0", "0", "0"]], "bids": [["84088", "0", "0", "0"], ["84087.2", "0.1", "0", "2"], ["84086.4", "0.06", "0", "2"], ["83975.5", "0.00005458", "0", "1"]], "ts": "1742554939004", "checksum": -514814495, "seqId": 49927358077, "prevSeqId": 49927358056}], "record_time": 1742554939.004394, "EXCHANGE": "OKX"}
{"arg": {"channel": "books", "instId": "BTC-USDT"}, "action": "update", "data": [{"asks": [["84152.5", "0.76149058", "0", "1"], ["84152.8", "0.03375424", "0", "1"], ["84155.1", "1.71104457", "0", "3"], ["84155.8", "0", "0", "0"], ["84159.4", "0.23782636", "0", "1"], ["84168.8", "0", "0", "0"], ["84169.6", "0.07999999", "0", "2"], ["84170.4", "0.03999999", "0", "1"], ["84185", "1.10454104", "0", "2"], ["84243.3", "0", "0", "0"], ["84279.2", "0", "0", "0"], ["84280.1", "0.00043993", "0", "1"]], "bids": [["84117.5", "0.05196287", "0", "2"], ["84117.1", "1", "0", "1"], ["84108.5", "1.0313143", "0", "2"], ["84100.7", "0.23782914", "0", "1"], ["84098.2", "0", "0", "0"], ["84078.5", "2.25939586", "0", "1"], ["84045.8", "0.51467721", "0", "4"], ["84029.3", "0", "0", "0"], ["84021.8", "0", "0", "0"], ["84007.3", "0", "0", "0"], ["83975.1", "0.17821722", "0", "1"], ["83975", "0.35581966", "0", "2"]], "ts": "1742554939104", "checksum": -514814495, "seqId": 49927358122, "prevSeqId": 49927358077}], "record_time": 1742554939.106559, "EXCHANGE": "OKX"}
{"arg": {"channel": "books", "instId": "BTC-USDT"}, "action": "update", "data": [{"asks": [["84157.4", "0.23782866", "0", "1"], ["84159.4", "0", "0", "0"]], "bids": [["84100.7", "0", "0", "0"], ["84098.6", "0.23782866", "0", "1"], ["84098", "1", "0", "1"], ["83975", "0", "0", "0"]], "ts": "1742554939204", "checksum": -514814495, "seqId": 49927358137, "prevSeqId": 49927358122}], "record_time": 1742554939.236762, "EXCHANGE": "OKX"}
{"arg": {"channel": "books", "instId": "BTC-USDT"}, "action": "update", "data": [{"asks": [["84145.7", "0.00894766", "0", "1"], ["84156.9", "0.01774536", "0", "1"], ["84187.6", "0", "0", "0"], ["84238.7", "0.089745", "0", "1"], ["84280", "0", "0", "0"], ["84280.1", "0", "0", "0"]], "bids": [["84105.3", "0.01775733", "0", "2"], ["84098", "0", "0", "0"], ["84078.9", "0", "0", "0"], ["83975", "0.35581966", "0", "2"], ["83974.6", "0.00003456", "0", "1"]], "ts": "1742554939304", "checksum": -514814495, "seqId": 49927358146, "prevSeqId": 49927358137}], "record_time": 1742554939.303596, "EXCHANGE": "OKX"}
{"arg": {"channel": "books", "instId": "BTC-USDT"}, "action": "update", "data": [{"asks": [["84169.6", "0.08", "0", "2"], ["84238.7", "0", "0", "0"], ["84280", "0.00010199", "0", "4"]], "bids": [], "ts": "1742554939404", "checksum": -514814495, "seqId": 49927358155, "prevSeqId": 49927358146}], "record_time": 1742554939.403961, "EXCHANGE": "OKX"}
{"arg": {"channel": "books", "instId": "BTC-USDT"}, "action": "update", "data": [{"asks": [], "bids": [["84105.3", "0.00001197", "0", "1"], ["84078.9", "0.01774536", "0", "1"], ["83974.6", "0", "0", "0"]], "ts": "1742554939504", "checksum": -514814495, "seqId": 49927358157, "prevSeqId": 49927358155}], "record_time": 1742554939.525328, "EXCHANGE": "OKX"}
{"arg": {"channel": "books", "instId": "BTC-USDT"}, "action": "update", "data": [{"asks": [["84139.2", "0.16721468", "0", "1"], ["84139.3", "0.2", "0", "1"], ["84139.4", "0", "0", "0"], ["84151.3", "1", "0", "1"], ["84152.6", "0", "0", "0"], ["84199.8", "0.19016816", "0", "2"], ["84249.8", "0", "0", "0"], ["84268.7", "0.01187868", "0", "1"], ["84280", "0", "0", "0"]], "bids": [["84034.7", "0.07139902", "0", "1"]], "ts": "1742554939604", "checksum": -102450180, "seqId": 49927358170, "prevSeqId": 49927358157}], "record_time": 1742554939.61687, "EXCHANGE": "OKX"}
{"arg": {"channel": "books", "instId": "BTC-USDT"}, "action": "update", "data": [{"asks": [["84165.9", "0.059882", "0", "1"], ["84199.8", "0.11890903", "0", "1"], ["84201.7", "0.089784", "0", "1"], ["84203", "0.07125642", "0", "1"], ["84279.3", "0", "0", "0"], ["84279.5", "0", "0", "0"], ["84279.8", "0", "0", "0"]], "bids": [["84117.1", "0", "0", "0"], ["84115.6", "1", "0", "1"], ["84037.9", "0.0820363", "0", "2"], ["84034.7", "0", "0", "0"], ["83974.6", "0.00003456", "0", "1"]], "ts": "1742554939704", "checksum": -102450180, "seqId": 49927358187, "prevSeqId": 49927358170}], "record_time": 1742554939.705309, "EXCHANGE": "OKX"}
{"arg": {"channel": "books", "instId": "BTC-USDT"}, "action": "update", "data": [{"asks": [["84130.4", "0.54518237", "0", "8"], ["84132.9", "0.04035957", "0", "1"], ["84133", "0.11891655", "0", "1"], ["84144", "0.06511096", "0", "2"], ["84144.5", "0.0317253", "0", "1"], ["84144.7", "0", "0", "0"], ["84150.8", "0.09234035", "0", "2"], ["84151", "0.03186979", "0", "1"], ["84151.7", "0", "0", "0"], ["84158", "0.06291122", "0", "2"], ["84158.7", "0.11888025", "0", "1"], ["84160.3", "0.06589347", "0", "1"], ["84160.5", "0", "0", "0"], ["84203", "0.14251284", "0", "2"], ["84278.6", "0", "0", "0"]], "bids": [["84118.8", "0", "0", "0"], ["84117.4", "0", "0", "0"], ["84116.7", "0.03174701", "0", "1"], ["84115.3", "0.00001197", "0", "1"], ["84115.1", "0.0311446", "0", "1"], ["84110.4", "0", "0", "0"], ["84109.7", "0.03210346", "0", "2"], ["84109", "0", "0", "0"], ["84108.8", "0.03498194", "0", "1"], ["84103.4", "0", "0", "0"], ["84102.7", "0.06543068", "0", "1"], ["84099.6", "0.11896366", "0", "1"], ["84099.4", "0.06986155", "0", "1"], ["84093", "0.1", "0", "1"], ["84037.9", "0.1534326", "0", "3"], ["83974.6", "0", "0", "0"]], "ts": "1742554939804", "checksum": 1855582605, "seqId": 49927358230, "prevSeqId": 49927358187}], "record_time": 1742554939.806097, "EXCHANGE": "OKX"}
{"arg": {"channel": "books", "instId": "BTC-USDT"}, "action": "update", "data": [{"asks": [["84130.4", "0.54458711", "0", "8"], ["84138.6", "0.01055", "0", "1"], ["84141.2", "0.00011161", "0", "1"], ["84143.3", "0.52697179", "0", "2"], ["84143.4", "0.35641581", "0", "1"], ["84143.6", "0.03098453", "0", "1"], ["84144", "0.06540007", "0", "2"], ["84144.1", "0", "0", "0"], ["84144.2", "0.03278931", "0", "1"], ["84144.5", "0", "0", "0"], ["84147.8", "0.50968106", "0", "2"], ["84149.9", "1.01101251", "0", "4"], ["84150.5", "0.06267199", "0", "2"], ["84150.6", "0.03410743", "0", "1"], ["84150.8", "0.05940838", "0", "1"], ["84151", "0", "0", "0"], ["84151.3", "0", "0", "0"], ["84152.7", "0.21127612", "0", "2"], ["84152.8", "0.0319612", "0", "1"], ["84152.9", "0.35641581", "0", "1"], ["84154.5", "0.23783338", "0", "1"], ["84157.4", "0", "0", "0"], ["84157.6", "0.06493533", "0", "1"], ["84158", "0.00001", "0", "1"], ["84159.4", "0.06533117", "0", "1"], ["84159.5", "0", "0", "0"], ["84160", "0.06937323", "0", "1"], ["84160.3", "0", "0", "0"], ["84278.4", "0", "0", "0"]], "bids": [["84130.3", "0.76478914", "0", "13"], ["84130.1", "0.10570733", "0", "1"], ["84130", "0.1146", "0", "2"], ["84129.9", "0", "0", "0"], ["84129.5", "0", "0", "0"], ["84127.8", "0.01596287", "0", "1"], ["84125.2", "0.36979581", "0", "2"], ["84116.7", "0", "0", "0"], ["84116.3", "0.07875806", "0", "2"], ["84115.6", "0", "0", "0"], ["84115.4", "0.02378378", "0", "1"], ["84115.3", "0.03153327", "0", "2"], ["84115.2", "0", "0", "0"], ["84115.1", "0", "0", "0"], ["84114.8", "0.0317969", "0", "1"], ["84113.4", "1", "0", "1"], ["84109.7", "0.000015", "0", "1"], ["84109.3", "0.03444423", "0", "1"], ["84108.8", "0", "0", "0"], ["84108.5", "1.06229612", "0", "3"], ["84107.3", "0", "0", "0"], ["84107.2", "0.03377004", "0", "1"], ["84106.7", "0.08991011", "0", "1"], ["84106.6", "0.03513328", "0", "1"], ["84102.7", "0", "0", "0"], ["84102.3", "0.06747319", "0", "1"], ["84100", "0.25447287", "0", "4"], ["84099.9", "0.06491364", "0", "2"], ["84099.4", "0", "0", "0"], ["84099.1", "0.06560157", "0", "1"], ["84098.6", "0", "0", "0"], ["84094.6", "0.23783338", "0", "1"], ["84093", "0", "0", "0"], ["83974.6", "0.00003456", "0", "1"], ["83974.3", "0.00003395", "0", "1"], ["83973.5", "0.0893", "0", "1"]], "ts": "1742554939904", "checksum": -1362434020, "seqId": 49927358303, "prevSeqId": 49927358230}], "record_time": 1742554939.905284, "EXCHANGE": "OKX"}
{"arg": {"channel": "books", "instId": "BTC-USDT"}, "action": "update", "data": [{"asks": [["84154.5", "0", "0", "0"], ["84156.9", "0.23783345", "0", "1"], ["84158.1", "0.01774536", "0", "1"]], "bids": [["84130.1", "0", "0", "0"], ["84130", "0.0146", "0", "1"], ["84129.5", "0.06252446", "0", "1"], ["84115", "1", "0", "1"], ["84113.4", "0", "0", "0"]], "ts": "1742554940004", "checksum": -1718822216, "seqId": 49927358314, "prevSeqId": 49927358303}], "record_time": 1742554940.005801, "EXCHANGE": "OKX"}
{"arg": {"channel": "books", "instId": "BTC-USDT"}, "action": "update", "data": [{"asks": [["84155.4", "0.81486106", "0", "2"]], "bids": [["84098.2", "0.23783231", "0", "1"], ["84094.6", "0.04069792", "0", "1"], ["84080.6", "0.01831326", "0", "1"], ["84079.4", "0", "0", "0"], ["84062.8", "0.3419052", "0", "1"], ["84040.2", "0.00016275", "0", "1"], ["84039.9", "0", "0", "0"], ["84037.4", "0", "0", "0"], ["84032.4", "0", "0", "0"], ["84009.1", "0.18313268", "0", "1"], ["84007.9", "0", "0", "0"]], "ts": "1742554940104", "checksum": -1718822216, "seqId": 49927358333, "prevSeqId": 49927358314}], "record_time": 1742554940.104843, "EXCHANGE": "OKX"}
{"arg": {"channel": "books", "instId": "BTC-USDT"}, "action": "update", "data": [{"asks": [["84156.9", "0", "0", "0"], ["84157.4", "0.23783217", "0", "1"]], "bids": [], "ts": "1742554940204", "checksum": -1718822216, "seqId": 49927358339, "prevSeqId": 49927358333}], "record_time": 1742554940.203782, "EXCHANGE": "OKX"}
{"arg": {"channel": "books", "instId": "BTC-USDT"}, "action": "update", "data": [{"asks": [["84156.9", "0.01774536", "0", "1"], ["84158.1", "0", "0", "0"], ["84203", "0.07125642", "0", "1"]], "bids": [["84098.2", "0.23783213", "0", "1"], ["84037.9", "0.0820363", "0", "2"]], "ts": "1742554940304", "checksum": -1718822216, "seqId": 49927358371, "prevSeqId": 49927358339}], "record_time": 1742554940.304825, "EXCHANGE": "OKX"}
{"arg": {"channel": "books", "instId": "BTC-USDT"}, "action": "update", "data": [{"asks": [["84157", "0.37163739", "0", "3"], ["84157.4", "0", "0", "0"], ["84203", "0", "0", "0"], ["84278.4", "0.00001024", "0", "1"], ["84278.6", "0.00011161", "0", "1"]], "bids": [["84098.2", "0", "0", "0"], ["84094.7", "0.23783238", "0", "1"], ["84076.4", "0.59964265", "0", "1"], ["84062.8", "0", "0", "0"], ["84062.7", "0", "0", "0"], ["84037.9", "0.01064", "0", "1"], ["84034.4", "0.59432247", "0", "1"], ["84020.7", "0", "0", "0"], ["83973.1", "1.69295", "0", "1"]], "ts": "1742554940404", "checksum": -1718822216, "seqId": 49927358397, "prevSeqId": 49927358371}], "record_time": 1742554940.422726, "EXCHANGE": "OKX"}
{"arg": {"channel": "books", "instId": "BTC-USDT"}, "action": "update", "data": [{"asks": [["84130.4", "0.86851711", "0", "10"], ["84135.9", "0.02284664", "0", "1"], ["84136.4", "0.01055", "0", "1"], ["84136.7", "0.03854779", "0", "1"], ["84138.6", "0", "0", "0"], ["84140.7", "0", "0", "0"], ["84154.5", "0.23783526", "0", "1"], ["84157", "0.13380501", "0", "2"], ["84203", "0.14251284", "0", "2"], ["84278.3", "0", "0", "0"], ["84278.4", "0", "0", "0"], ["84278.6", "0", "0", "0"]], "bids": [["84130.3", "0.74655914", "0", "11"], ["84125.3", "0.13761135", "0", "1"], ["84125.2", "0.35641581", "0", "1"], ["84124.6", "0", "0", "0"], ["84123", "0.01338", "0", "1"], ["84120.4", "0.03854779", "0", "1"], ["84115", "0", "0", "0"], ["84113.2", "0.42588753", "0", "2"], ["84113", "1", "0", "1"], ["84112.1", "0.00365612", "0", "1"], ["84037.9", "0.1534326", "0", "3"], ["83973.5", "0", "0", "0"], ["83973.1", "0", "0", "0"]], "ts": "1742554940504", "checksum": -656129409, "seqId": 49927358439, "prevSeqId": 49927358397}], "record_time": 1742554940.513212, "EXCHANGE": "OKX"}
{"arg": {"channel": "books", "instId": "BTC-USDT"}, "action": "update", "data": [{"asks": [["84139.2", "0.09248534", "0", "1"], ["84139.3", "0", "0", "0"], ["84154.5", "0", "0", "0"], ["84156.9", "0.23783417", "0", "1"], ["84158.1", "0.01774536", "0", "1"], ["84278.3", "0.00005514", "0", "1"]], "bids": [["84129.2", "0", "0", "0"], ["84031.6", "0.00580001", "0", "1"], ["84024.7", "0.01163132", "0", "3"]], "ts": "1742554940604", "checksum": 710567356, "seqId": 49927358452, "prevSeqId": 49927358439}], "record_time": 1742554940.608866, "EXCHANGE": "OKX"}
{"arg": {"channel": "books", "instId": "BTC-USDT"}, "action": "update", "data": [{"asks": [["84130.4", "0.66601711", "0", "9"], ["84149.9", "0.01101251", "0", "3"], ["84150.7", "1", "0", "1"], ["84156.9", "0", "0", "0"], ["84158.1", "0.25557604", "0", "2"]], "bids": [["84130.3", "0.76438814", "0", "12"], ["84115.9", "1", "0", "1"], ["84113.2", "0.16185123", "0", "1"], ["84113", "0", "0", "0"], ["84098.6", "0.23783068", "0", "1"], ["84094.7", "0", "0", "0"]], "ts": "1742554940704", "checksum": 1005930742, "seqId": 49927358476, "prevSeqId": 49927358452}], "record_time": 1742554940.704477, "EXCHANGE": "OKX"}
{"arg": {"channel": "books", "instId": "BTC-USDT"}, "action": "update", "data": [{"asks": [["84147.8", "0.23972497", "0", "1"], ["84150.7", "0", "0", "0"], ["84152.1", "1", "0", "1"], ["84158.1", "0.01774536", "0", "1"], ["84159.3", "0.2379044", "0", "2"]], "bids": [["84099.2", "0.23782883", "0", "1"], ["84098.6", "0", "0", "0"]], "ts": "1742554940804", "checksum": 1005930742, "seqId": 49927358490, "prevSeqId": 49927358476}], "record_time": 1742554940.805457, "EXCHANGE": "OKX"}
{"arg": {"channel": "books", "instId": "BTC-USDT"}, "action": "update", "data": [{"asks": [], "bids": [["84082", "0.20100367", "0", "2"]], "ts": "1742554940904", "checksum": 1005930742, "seqId": 49927358492, "prevSeqId": 49927358490}], "record_time": 1742554940.904974, "EXCHANGE": "OKX"}
{"arg": {"channel": "books", "instId": "BTC-USDT"}, "action": "update", "data": [{"asks": [["84155.4", "0.13363749", "0", "1"], ["84158.2", "0", "0", "0"], ["84158.6", "0.23783002", "0", "1"], ["84159.3", "0.00007557", "0", "1"], ["84185", "0.23299378", "0", "1"], ["84187.7", "0", "0", "0"], ["84278.4", "0.00001024", "0", "1"]], "bids": [["84108.5", "0.62426485", "0", "2"], ["84105", "0.11228184", "0", "2"], ["84100.7", "0.23783002", "0", "1"], ["84099.2", "0", "0", "0"], ["84082", "0.00100367", "0", "1"], ["84075.6", "0.00001197", "0", "1"]], "ts": "1742554941004", "checksum": 1005930742, "seqId": 49927358508, "prevSeqId": 49927358492}], "record_time": 1742554941.010552, "EXCHANGE": "OKX"}
{"arg": {"channel": "books", "instId": "BTC-USDT"}, "action": "update", "data": [{"asks": [["84156.9", "0.237832", "0", "1"], ["84157.8", "1.61430913", "0", "1"], ["84158.1", "0", "0", "0"], ["84158.6", "0", "0", "0"], ["84184", "0", "0", "0"], ["84184.5", "0.01187868", "0", "1"], ["84187.2", "2.83600685", "0", "1"], ["84190.9", "0.01774536", "0", "1"], ["84203", "0.07125642", "0", "1"], ["84278.3", "0", "0", "0"], ["84278.4", "0", "0", "0"]], "bids": [["84104.7", "1.57856969", "0", "1"], ["84100.7", "0", "0", "0"], ["84099.2", "0.237832", "0", "1"], ["84075.3", "2.8003938", "0", "1"], ["84037.9", "0.0820363", "0", "2"], ["84037.4", "0.35662968", "0", "1"], ["83994.2", "0.01187868", "0", "1"], ["83990.8", "0", "0", "0"], ["83975", "0", "0", "0"], ["83974.6", "0", "0", "0"], ["83974.3", "0", "0", "0"]], "ts": "1742554941104", "checksum": 1005930742, "seqId": 49927358529, "prevSeqId": 49927358508}], "record_time": 1742554941.105971, "EXCHANGE": "OKX"}
{"arg": {"channel": "books", "instId": "BTC-USDT"}, "action": "update", "data": [{"asks": [["84155.4", "0.81110319", "0", "2"], ["84156.9", "0", "0", "0"], ["84158.6", "0.23782983", "0", "1"], ["84184.9", "0", "0", "0"], ["84278.3", "0.00005514", "0", "1"]], "bids": [["84104.9", "0.66557234", "0", "1"], ["84103.2", "0", "0", "0"], ["84099.2", "0", "0", "0"], ["84098.6", "0.23782983", "0", "1"], ["84093.2", "0", "0", "0"], ["84075.4", "0.96946556", "0", "1"], ["84049.6", "0", "0", "0"], ["84045.8", "0.20672021", "0", "3"], ["84041.7", "0", "0", "0"], ["84037.4", "0", "0", "0"], ["83975", "0.35581966", "0", "2"], ["83974.6", "0.00003456", "0", "1"], ["83974.3", "0.00003395", "0", "1"], ["83973.5", "0.0893", "0", "1"]], "ts": "1742554941204", "checksum": 1005930742, "seqId": 49927358559, "prevSeqId": 49927358529}], "record_time": 1742554941.214224, "EXCHANGE": "OKX"}
{"arg": {"channel": "books", "instId": "BTC-USDT"}, "action": "update", "data": [{"asks": [["84132.2", "0.002", "0", "1"], ["84142.3", "0.002", "0", "1"], ["84156.9", "0.01774536", "0", "1"], ["84184.9", "0.00004312", "0", "1"], ["84190.9", "0", "0", "0"], ["84277.3", "0", "0", "0"], ["84277.5", "0", "0", "0"], ["84278.3", "0", "0", "0"]], "bids": [["84117.6", "0.52448236", "0", "2"], ["84117.4", "1", "0", "1"], ["84115.9", "0", "0", "0"], ["84107.5", "0.002", "0", "1"], ["84105.3", "0.01775733", "0", "2"], ["84097", "1", "0", "1"], ["84078.9", "0", "0", "0"], ["84003.4", "0.183127", "0", "1"], ["83980.4", "0", "0", "0"], ["83973.5", "0", "0", "0"]], "ts": "1742554941304", "checksum": -1630000690, "seqId": 49927358587, "prevSeqId": 49927358559}], "record_time": 1742554941.334991, "EXCHANGE": "OKX"}
{"arg": {"channel": "books", "instId": "BTC-USDT"}, "action": "update", "data": [{"asks": [["84158.6", "0.23782973", "0", "1"], ["84203", "0.14251284", "0", "2"]], "bids": [["84098.6", "0.23782973", "0", "1"], ["84097", "0", "0", "0"], ["84037.9", "0.1534326", "0", "3"], ["83973.5", "0.0893", "0", "1"]], "ts": "1742554941404", "checksum": -1630000690, "seqId": 49927358602, "prevSeqId": 49927358587}], "record_time": 1742554941.419197, "EXCHANGE": "OKX"}
{"arg": {"channel": "books", "instId": "BTC-USDT"}, "action": "update", "data": [{"asks": [["84158.6", "0", "0", "0"], ["84158.8", "0.23782929", "0", "1"]], "bids": [["84099.2", "0.23782929", "0", "1"], ["84098.6", "0", "0", "0"]], "ts": "1742554941504", "checksum": -1630000690, "seqId": 49927358619, "prevSeqId": 49927358602}], "record_time": 1742554941.517991, "EXCHANGE": "OKX"}
{"arg": {"channel": "books", "instId": "BTC-USDT"}, "action": "update", "data": [{"asks": [["84203", "0.07125642", "0", "1"]], "bids": [["84078.3", "0.41187868", "0", "2"], ["84037.9", "0.0820363", "0", "2"]], "ts": "1742554941604", "checksum": -1630000690, "seqId": 49927358627, "prevSeqId": 49927358619}], "record_time": 1742554941.613128, "EXCHANGE": "OKX"}
{"arg": {"channel": "books", "instId": "BTC-USDT"}, "action": "update", "data": [{"asks": [["84144.9", "0.0077261", "0", "1"], ["84152.1", "0", "0", "0"], ["84155.4", "1.81110319", "0", "3"], ["84158.8", "0", "0", "0"], ["84159.3", "0.23790467", "0", "2"], ["84277.3", "0.00002956", "0", "2"], ["84277.5", "0.00001001", "0", "1"]], "bids": [["84120.7", "0.391129", "0", "2"], ["84119.3", "1", "0", "1"], ["84117.4", "0", "0", "0"], ["84113.3", "0", "0", "0"], ["84099.2", "0", "0", "0"], ["84098.6", "0.2378291", "0", "1"], ["84065.8", "0", "0", "0"], ["84049.6", "0.09276684", "0", "1"], ["83973.1", "1.69295", "0", "1"]], "ts": "1742554941704", "checksum": -234076313, "seqId": 49927358665, "prevSeqId": 49927358627}], "record_time": 1742554941.712972, "EXCHANGE": "OKX"}
{"arg": {"channel": "books", "instId": "BTC-USDT"}, "action": "update", "data": [{"asks": [["84147.8", "0.50968106", "0", "2"], ["84151", "1", "0", "1"], ["84155.4", "0.81110319", "0", "2"], ["84169", "1", "0", "1"], ["84170", "0.2", "0", "1"], ["84203", "0.14251284", "0", "2"], ["84276.9", "0", "0", "0"], ["84277.3", "0", "0", "0"], ["84277.5", "0", "0", "0"]], "bids": [["84119.3", "0", "0", "0"], ["84117.7", "1.11893802", "0", "2"], ["84037.9", "0.1534326", "0", "3"], ["83971.5", "0.00001197", "0", "1"]], "ts": "1742554941804", "checksum": 1402595121, "seqId": 49927358678, "prevSeqId": 49927358665}], "record_time": 1742554941.818598, "EXCHANGE": "OKX"}
{"arg": {"channel": "books", "instId": "BTC-USDT"}, "action": "update", "data": [{"asks": [["84130.4", "0.86847314", "0", "10"], ["84154.5", "0.23783431", "0", "1"], ["84159.3", "0.00007557", "0", "1"], ["84168.8", "0.08", "0", "2"], ["84169", "0", "0", "0"], ["84169.6", "0.03999999", "0", "1"], ["84170.4", "0", "0", "0"]], "bids": [["84130.3", "0.68938814", "0", "11"], ["84120.7", "0.09024533", "0", "1"], ["84117.7", "0.11893802", "0", "1"], ["84114.9", "1", "0", "1"], ["84098.6", "0", "0", "0"], ["84094.7", "0.23783431", "0", "1"], ["84088", "0.1", "0", "2"], ["84087.2", "0.05", "0", "1"], ["84086.4", "0.01", "0", "1"], ["84031.7", "0.00580001", "0", "1"], ["84027.6", "0.00600001", "0", "1"], ["84024.8", "0.00580001", "0", "1"], ["83974.6", "0", "0", "0"], ["83974.3", "0", "0", "0"], ["83973.5", "0", "0", "0"], ["83973.1", "0", "0", "0"], ["83971.5", "0", "0", "0"]], "ts": "1742554941904", "checksum": 2026029131, "seqId": 49927358708, "prevSeqId": 49927358678}], "record_time": 1742554941.935246, "EXCHANGE": "OKX"}
{"arg": {"channel": "books", "instId": "BTC-USDT"}, "action": "update", "data": [{"asks": [["84130.4", "0.66597314", "0", "9"], ["84168", "0.19228184", "0", "4"], ["84168.8", "0.03999999", "0", "1"], ["84169.6", "0", "0", "0"], ["84276.9", "0.00001881", "0", "1"]], "bids": [["84129.5", "0", "0", "0"], ["84127.8", "0", "0", "0"], ["84100.6", "0.00890662", "0", "1"], ["84092", "0.08", "0", "2"], ["84091.2", "0.066", "0", "3"], ["84090.4", "0.013", "0", "1"], ["84076", "0.45446287", "0", "4"], ["84024.9", "0.00580001", "0", "1"]], "ts": "1742554942004", "checksum": -471226214, "seqId": 49927358728, "prevSeqId": 49927358708}], "record_time": 1742554942.016834, "EXCHANGE": "OKX"}
{"arg": {"channel": "books", "instId": "BTC-USDT"}, "action": "update", "data": [{"asks": [["84130.4", "0.86847314", "0", "10"], ["84145.7", "0", "0", "0"], ["84150.2", "1.12901106", "0", "3"], ["84151", "0", "0", "0"], ["84154.5", "0", "0", "0"], ["84156.9", "0.25557883", "0", "2"], ["84168", "0.11228184", "0", "2"], ["84168.8", "0.07999999", "0", "2"], ["84169.6", "0.03999999", "0", "1"], ["84170", "0", "0", "0"], ["84277.3", "0.00002956", "0", "2"], ["84277.5", "0.00001001", "0", "1"], ["84278.3", "0.00005514", "0", "1"]], "bids": [["84129.5", "0.05294674", "0", "1"], ["84114.9", "0", "0", "0"], ["84113.6", "1", "0", "1"], ["84105.3", "0.00001197", "0", "1"], ["84080.6", "0", "0", "0"], ["84080.3", "0.01831338", "0", "1"], ["84078.9", "0.01774536", "0", "1"], ["84076", "0.25446287", "0", "3"], ["84009.1", "0", "0", "0"], ["84008.9", "0.1889491", "0", "3"], ["83975", "0", "0", "0"]], "ts": "1742554942104", "checksum": -1417494441, "seqId": 49927358768, "prevSeqId": 49927358728}], "record_time": 1742554942.192417, "EXCHANGE": "OKX"}
{"arg": {"channel": "books", "instId": "BTC-USDT"}, "action": "update", "data": [{"asks": [["84156.9", "0.2555784", "0", "2"], ["84185", "1.06929487", "0", "2"]], "bids": [["84094.9", "0.23783304", "0", "1"], ["84094.7", "0", "0", "0"], ["84094.6", "0", "0", "0"], ["84065.8", "0.82699589", "0", "1"]], "ts": "1742554942204", "checksum": -1417494441, "seqId": 49927358786, "prevSeqId": 49927358768}], "record_time": 1742554942.218387, "EXCHANGE": "OKX"}
{"arg": {"channel": "books", "instId": "BTC-USDT"}, "action": "update", "data": [{"asks": [], "bids": [["84129.5", "0", "0", "0"], ["84098.2", "0.23783192", "0", "1"], ["84094.9", "0", "0", "0"], ["83975", "0.35581966", "0", "2"]], "ts": "1742554942304", "checksum": 1197793233, "seqId": 49927358792, "prevSeqId": 49927358786}], "record_time": 1742554942.331649, "EXCHANGE": "OKX"}
{"arg": {"channel": "books", "instId": "BTC-USDT"}, "action": "update", "data": [{"asks": [], "bids": [["84127.9", "0.00056056", "0", "1"], ["84114.4", "1", "0", "1"], ["84113.6", "0", "0", "0"], ["84098.2", "0", "0", "0"], ["84096.1", "0.23783287", "0", "1"], ["84096", "1", "0", "1"], ["83975.1", "0", "0", "0"], ["83975", "0", "0", "0"]], "ts": "1742554942404", "checksum": 497836167, "seqId": 49927358807, "prevSeqId": 49927358792}], "record_time": 1742554942.4202, "EXCHANGE": "OKX"}
{"arg": {"channel": "books", "instId": "BTC-USDT"}, "action": "update", "data": [{"asks": [["84156.9", "0.01774536", "0", "1"], ["84158.6", "0.23783018", "0", "1"], ["84193.1", "0.01121908", "0", "1"], ["84199.1", "0", "0", "0"], ["84211.9", "0.01316", "0", "1"], ["84277.5", "0", "0", "0"], ["84278.3", "0", "0", "0"]], "bids": [["84115.9", "1", "0", "1"], ["84114.4", "0", "0", "0"], ["84105.3", "0.01775733", "0", "2"], ["84098.6", "0.23783018", "0", "1"], ["84096.1", "0", "0", "0"], ["84096", "0", "0", "0"], ["84092", "0", "0", "0"], ["84091.2", "0.106", "0", "4"], ["84090.4", "0.053", "0", "2"], ["84080.3", "0", "0", "0"], ["84078.9", "0", "0", "0"], ["84076.7", "0.01831312", "0", "1"], ["84008.9", "0.00581522", "0", "2"], ["84005.1", "0.18313123", "0", "1"], ["83975.1", "0.17821722", "0", "1"], ["83975", "0.35581966", "0", "2"]], "ts": "1742554942504", "checksum": 497836167, "seqId": 49927358832, "prevSeqId": 49927358807}], "record_time": 1742554942.506614, "EXCHANGE": "OKX"}
{"arg": {"channel": "books", "instId": "BTC-USDT"}, "action": "update", "data": [{"asks": [["84146.1", "0.06880514", "0", "3"], ["84193.1", "0", "0", "0"], ["84199.1", "0.01121908", "0", "1"]], "bids": [["84080.3", "0.01831312", "0", "1"], ["84076.7", "0", "0", "0"], ["84008.9", "0.18894646", "0", "3"], ["84005.1", "0", "0", "0"], ["83974.6", "0.00003456", "0", "1"]], "ts": "1742554942604", "checksum": 497836167, "seqId": 49927358843, "prevSeqId": 49927358832}], "record_time": 1742554942.627989, "EXCHANGE": "OKX"}
{"arg": {"channel": "books", "instId": "BTC-USDT"}, "action": "update", "data": [{"asks": [["84147.8", "0.23972497", "0", "1"], ["84150.2", "0.12901106", "0", "2"], ["84151.5", "1", "0", "1"], ["84277.3", "0", "0", "0"]], "bids": [["84116.1", "1", "0", "1"], ["84115.9", "0", "0", "0"], ["84105.3", "0.00001197", "0", "1"], ["84078.9", "0.01774536", "0", "1"], ["83974.6", "0", "0", "0"]], "ts": "1742554942704", "checksum": 497836167, "seqId": 49927358852, "prevSeqId": 49927358843}], "record_time": 1742554942.718841, "EXCHANGE": "OKX"}
{"arg": {"channel": "books", "instId": "BTC-USDT"}, "action": "update", "data": [{"asks": [["84157", "0.00001501", "0", "1"], ["84167", "1", "0", "1"], ["84276.9", "0", "0", "0"]], "bids": [], "ts": "1742554942904", "checksum": 497836167, "seqId": 49927358856, "prevSeqId": 49927358852}], "record_time": 1742554942.918409, "EXCHANGE": "OKX"}
{"arg": {"channel": "books", "instId": "BTC-USDT"}, "action": "update", "data": [{"asks": [["84156.9", "0", "0", "0"], ["84157.4", "0.15151736", "0", "2"], ["84203", "0.07125642", "0", "1"]], "bids": [["84120.7", "0.391129", "0", "2"], ["84117.6", "1.52448236", "0", "3"], ["84116.1", "0", "0", "0"], ["84092", "0.08", "0", "2"], ["84091.2", "0.066", "0", "3"], ["84090.4", "0.013", "0", "1"], ["84037.9", "0.0820363", "0", "2"]], "ts": "1742554943004", "checksum": 299230192, "seqId": 49927358874, "prevSeqId": 49927358856}], "record_time": 1742554943.043746, "EXCHANGE": "OKX"}
{"arg": {"channel": "books", "instId": "BTC-USDT"}, "action": "update", "data": [{"asks": [["84151.4", "1.20491501", "0", "1"], ["84152.5", "0", "0", "0"], ["84157", "0.23784772", "0", "2"], ["84158.6", "0", "0", "0"], ["84168", "0.31228184", "0", "3"], ["84203", "0.14251284", "0", "2"], ["84276.9", "0.00001881", "0", "1"]], "bids": [["84098.6", "0", "0", "0"], ["84094.6", "0.23783222", "0", "1"], ["84093", "0.1", "0", "1"], ["84037.9", "0.1534326", "0", "3"], ["83975", "0", "0", "0"]], "ts": "1742554943104", "checksum": 299230192, "seqId": 49927358906, "prevSeqId": 49927358874}], "record_time": 1742554943.124042, "EXCHANGE": "OKX"}
{"arg": {"channel": "books", "instId": "BTC-USDT"}, "action": "update", "data": [{"asks": [["84156.9", "0.01774536", "0", "1"], ["84157", "0.00001501", "0", "1"], ["84157.3", "0.23783132", "0", "1"], ["84157.4", "0.133772", "0", "1"], ["84164.2", "0.58630581", "0", "2"], ["84168", "0.11228184", "0", "2"], ["84276.8", "0", "0", "0"], ["84276.9", "0", "0", "0"]], "bids": [["84105.3", "0.01775733", "0", "2"], ["84098.2", "0.2378313", "0", "1"], ["84094.6", "0", "0", "0"], ["84092", "0", "0", "0"], ["84091.2", "0.106", "0", "4"], ["84090.4", "0.053", "0", "2"], ["84078.9", "0", "0", "0"], ["83975", "0.35581966", "0", "2"], ["83974.6", "0.00003456", "0", "1"]], "ts": "1742554943204", "checksum": 299230192, "seqId": 49927358932, "prevSeqId": 49927358906}], "record_time": 1742554943.234179, "EXCHANGE": "OKX"}
{"arg": {"channel": "books", "instId": "BTC-USDT"}, "action": "update", "data": [{"asks": [["84168.8", "0", "0", "0"], ["84169.6", "0.07999999", "0", "2"], ["84170.4", "0.03999999", "0", "1"], ["84203", "0.07125642", "0", "1"]], "bids": [["84130.3", "0.68457694", "0", "12"], ["84093", "0", "0", "0"], ["84037.9", "0.0820363", "0", "2"], ["83974.3", "0.00003395", "0", "1"]], "ts": "1742554943304", "checksum": -2057897467, "seqId": 49927358967, "prevSeqId": 49927358932}], "record_time": 1742554943.325154, "EXCHANGE": "OKX"}
{"arg": {"channel": "books", "instId": "BTC-USDT"}, "action": "update", "data": [{"asks": [["84156.9", "0", "0", "0"], ["84157", "0.01776037", "0", "2"], ["84157.3", "0", "0", "0"], ["84159.3", "0.23790461", "0", "2"], ["84168.8", "0.08", "0", "2"], ["84169.6", "0.03999999", "0", "1"], ["84170.4", "0", "0", "0"], ["84203", "0.14251284", "0", "2"], ["84276.8", "0.00418927", "0", "1"], ["84276.9", "0.00001881", "0", "1"]], "bids": [["84105.3", "0.00001197", "0", "1"], ["84098.6", "0.23782904", "0", "1"], ["84098.2", "0", "0", "0"], ["84092", "0.08", "0", "2"], ["84091.2", "0.066", "0", "3"], ["84090.4", "0.013", "0", "1"], ["84078.9", "0.01774536", "0", "1"], ["84037.9", "0.1534326", "0", "3"], ["83974.6", "0", "0", "0"], ["83974.3", "0", "0", "0"]], "ts": "1742554943404", "checksum": -2057897467, "seqId": 49927358990, "prevSeqId": 49927358967}], "record_time": 1742554943.417032, "EXCHANGE": "OKX"}
{"arg": {"channel": "books", "instId": "BTC-USDT"}, "action": "update", "data": [{"asks": [], "bids": [["84096", "1", "0", "1"], ["84092", "0", "0", "0"], ["84091.2", "0.106", "0", "4"], ["84090.4", "0.053", "0", "2"]], "ts": "1742554943504", "checksum": -2057897467, "seqId": 49927358997, "prevSeqId": 49927358990}], "record_time": 1742554943.521156, "EXCHANGE": "OKX"}
{"arg": {"channel": "books", "instId": "BTC-USDT"}, "action": "update", "data": [{"asks": [["84157.3", "0.23783111", "0", "1"], ["84159.3", "0.00007557", "0", "1"], ["84203", "0.07125642", "0", "1"], ["84276.9", "0", "0", "0"]], "bids": [["84098.6", "0", "0", "0"], ["84098.2", "0.23783111", "0", "1"], ["84096", "0", "0", "0"], ["84037.9", "0.0820363", "0", "2"], ["83974.6", "0.00003456", "0", "1"]], "ts": "1742554943604", "checksum": -2057897467, "seqId": 49927359012, "prevSeqId": 49927358997}], "record_time": 1742554943.625056, "EXCHANGE": "OKX"}
{"arg": {"channel": "books", "instId": "BTC-USDT"}, "action": "update", "data": [{"asks": [["84157.3", "0", "0", "0"], ["84159.3", "0.23790452", "0", "2"], ["84203", "0", "0", "0"], ["84276.9", "0.00001881", "0", "1"], ["84277.3", "0.00002956", "0", "2"]], "bids": [["84098.6", "0.23782895", "0", "1"], ["84098.2", "0", "0", "0"], ["84037.9", "0.01064", "0", "1"]], "ts": "1742554943704", "checksum": -2057897467, "seqId": 49927359023, "prevSeqId": 49927359012}], "record_time": 1742554943.722469, "EXCHANGE": "OKX"}
{"arg": {"channel": "books", "instId": "BTC-USDT"}, "action": "update", "data": [{"asks": [["84147.8", "0.50968106", "0", "2"], ["84149.8", "1", "0", "1"], ["84151.4", "0", "0", "0"], ["84151.5", "0", "0", "0"], ["84155", "0.23783154", "0", "1"], ["84157", "0.00001501", "0", "1"], ["84157.3", "0.01774536", "0", "1"], ["84159.3", "0.00007557", "0", "1"], ["84203", "0.14251284", "0", "2"], ["84276.9", "0", "0", "0"], ["84277.3", "0", "0", "0"]], "bids": [["84130.3", "0.68458694", "0", "13"], ["84120.7", "0.09024533", "0", "1"], ["84117.6", "0.52448236", "0", "2"], ["84115.9", "1", "0", "1"], ["84098.6", "0", "0", "0"], ["84098.2", "0.23783154", "0", "1"], ["84062.6", "0.16209053", "0", "2"], ["84037.9", "0.1534326", "0", "3"], ["83974.6", "0", "0", "0"]], "ts": "1742554943804", "checksum": 854443161, "seqId": 49927359062, "prevSeqId": 49927359023}], "record_time": 1742554943.819848, "EXCHANGE": "OKX"}
{"arg": {"channel": "books", "instId": "BTC-USDT"}, "action": "update", "data": [{"asks": [["84155", "0", "0", "0"], ["84155.4", "0.13363749", "0", "1"], ["84157", "0.23784622", "0", "2"], ["84157.8", "0", "0", "0"], ["84185", "0.23299378", "0", "1"], ["84187.2", "0", "0", "0"], ["84276.9", "0.00001881", "0", "1"], ["84277.3", "0.00002956", "0", "2"], ["84277.5", "0.00001001", "0", "1"]], "bids": [["84104.9", "0", "0", "0"], ["84104.7", "0", "0", "0"], ["84075.4", "0", "0", "0"], ["84075.3", "0", "0", "0"], ["84037.4", "0.37859546", "0", "1"], ["83974.6", "0.00003456", "0", "1"], ["83974.3", "0.00003395", "0", "1"], ["83973.5", "0.0893", "0", "1"]], "ts": "1742554943904", "checksum": 854443161, "seqId": 49927359073, "prevSeqId": 49927359062}], "record_time": 1742554943.918591, "EXCHANGE": "OKX"}
{"arg": {"channel": "books", "instId": "BTC-USDT"}, "action": "update", "data": [{"asks": [["84120.8", "0.89676164", "0", "9"], ["84121.2", "1.5207452", "0", "15"], ["84122.1", "0.57743765", "0", "8"], ["84123.6", "0.1", "0", "1"], ["84124", "0.90883271", "0", "7"], ["84124.1", "1.57077164", "0", "8"], ["84125.3", "0.25203713", "0", "3"], ["84126", "0.0146", "0", "1"], ["84128", "0.0146", "0", "1"], ["84128.5", "0.03854779", "0", "1"], ["84130", "0.0146", "0", "1"], ["84130.2", "0.2297449", "0", "1"], ["84130.3", "0.31890903", "0", "2"], ["84130.4", "0.2599819", "0", "9"], ["84131.5", "0.01055", "0", "1"], ["84131.8", "0.00001501", "0", "1"], ["84132.9", "0", "0", "0"], ["84133", "0", "0", "0"], ["84133.4", "0.08991011", "0", "1"], ["84135", "0.00001197", "0", "1"], ["84135.6", "0", "0", "0"], ["84135.9", "0", "0", "0"], ["84136", "0.0146", "0", "1"], ["84136.4", "0", "0", "0"], ["84136.7", "0.02808545", "0", "1"], ["84137", "0.03728865", "0", "1"], ["84138", "0", "0", "0"], ["84138.9", "0.2378807", "0", "1"], ["84139", "0.17393921", "0", "1"], ["84139.2", "0", "0", "0"], ["84140.6", "0.23415", "0", "2"], ["84140.9", "0.01055", "0", "1"], ["84141.7", "1", "0", "1"], ["84142.9", "0.08991011", "0", "1"], ["84143.3", "0.31465075", "0", "2"], ["84143.5", "0.17821722", "0", "1"], ["84143.6", "0", "0", "0"], ["84144", "0", "0", "0"], ["84144.1", "0.04", "0", "1"], ["84144.2", "0", "0", "0"], ["84144.3", "0", "0", "0"], ["84144.9", "0", "0", "0"], ["84145.6", "0", "0", "0"], ["84146.2", "0", "0", "0"], ["84146.3", "0", "0", "0"], ["84147.8", "0", "0", "0"], ["84148.4", "0", "0", "0"], ["84148.9", "0", "0", "0"], ["84149.8", "0", "0", "0"], ["84149.9", "0.03369014", "0", "3"], ["84150.2", "0.00420106", "0", "1"], ["84150.5", "0", "0", "0"], ["84150.6", "0", "0", "0"], ["84152.4", "0.03084301", "0", "1"], ["84152.5", "0.03300258", "0", "1"], ["84152.7", "0.17821722", "0", "1"], ["84152.8", "0", "0", "0"], ["84157", "0.00001501", "0", "1"], ["84157.3", "0", "0", "0"], ["84157.6", "0", "0", "0"], ["84158.2", "1.53215589", "0", "1"], ["84158.7", "0", "0", "0"], ["84159.4", "0.06571345", "0", "1"], ["84160", "0", "0", "0"], ["84160.5", "0.08991011", "0", "1"], ["84161.1", "0.06235132", "0", "1"], ["84161.5", "0", "0", "0"], ["84162.8", "0.17821722", "0", "1"], ["84164.2", "0.24217784", "0", "1"], ["84165.9", "0", "0", "0"], ["84167", "0", "0", "0"], ["84169.1", "0.53008", "0", "1"], ["84171.2", "0", "0", "0"], ["84173.6", "0.13895662", "0", "2"], ["84173.8", "0.000015", "0", "1"], ["84180.4", "0.00011161", "0", "1"], ["84187.7", "2.72122471", "0", "1"], ["84188", "0", "0", "0"], ["84190.9", "0.01774536", "0", "1"], ["84191", "0.43170703", "0", "2"], ["84192.1", "0", "0", "0"], ["84204.9", "0.24963", "0", "1"], ["84206.7", "0", "0", "0"], ["84224.1", "0.0005", "0", "1"], ["84250.7", "0", "0", "0"], ["84262.9", "0.17821722", "0", "1"], ["84265.3", "0", "0", "0"], ["84269.9", "0.00001012", "0", "1"], ["84277.3", "0.00001759", "0", "1"], ["84278.3", "0.00005514", "0", "1"], ["84278.4", "0.00001024", "0", "1"]], "bids": [["84130.3", "0", "0", "0"], ["84130", "0", "0", "0"], ["84129.4", "0", "0", "0"], ["84129.3", "0", "0", "0"], ["84128.6", "0", "0", "0"], ["84128", "0", "0", "0"], ["84127.9", "0", "0", "0"], ["84126", "0", "0", "0"], ["84125.9", "0", "0", "0"], ["84125.3", "0", "0", "0"], ["84125.2", "0", "0", "0"], ["84124", "0", "0", "0"], ["84123.9", "0", "0", "0"], ["84123", "0", "0", "0"], ["84122.2", "0", "0", "0"], ["84122", "0", "0", "0"], ["84120.6", "0.00056558", "0", "1"], ["84120.5", "0", "0", "0"], ["84120.4", "0", "0", "0"], ["84119.6", "0", "0", "0"], ["84118.3", "0.03713992", "0", "1"], ["84117.6", "0.17981869", "0", "2"], ["84117.5", "0", "0", "0"], ["84116.5", "0.35641581", "0", "1"], ["84116.3", "0.048", "0", "1"], ["84116", "0.02232741", "0", "2"], ["84115.9", "0", "0", "0"], ["84115.8", "0", "0", "0"], ["84115.4", "0.03854779", "0", "1"], ["84115.3", "0.00001197", "0", "1"], ["84114.8", "0", "0", "0"], ["84114.5", "0", "0", "0"], ["84114.2", "0.03358998", "0", "1"], ["84112.9", "0", "0", "0"], ["84112.1", "0", "0", "0"], ["84111.8", "0.01596287", "0", "1"], ["84110.9", "0", "0", "0"], ["84109.3", "0.04", "0", "1"], ["84109", "0.2425", "0", "2"], ["84108.5", "0.59328303", "0", "1"], ["84108.1", "0", "0", "0"], ["84107.9", "0.03179495", "0", "1"], ["84107.7", "0", "0", "0"], ["84107.4", "0.14510812", "0", "2"], ["84107.2", "0", "0", "0"], ["84106.9", "0.03491016", "0", "1"], ["84106.7", "0", "0", "0"], ["84106.6", "0", "0", "0"], ["84106.4", "0.05196287", "0", "2"], ["84106.3", "0.03245154", "0", "1"], ["84105.2", "0", "0", "0"], ["84104.9", "0.67858551", "0", "1"], ["84102.8", "1.57546766", "0", "1"], ["84102.7", "1", "0", "1"], ["84102.3", "0", "0", "0"], ["84100.5", "0", "0", "0"], ["84099.9", "0.00060645", "0", "1"], ["84099.8", "0", "0", "0"], ["84099.1", "0", "0", "0"], ["84098.5", "0.06261784", "0", "1"], ["84098.2", "0", "0", "0"], ["84098.1", "0.42157324", "0", "2"], ["84092.3", "0", "0", "0"], ["84091.2", "0", "0", "0"], ["84090.4", "0", "0", "0"], ["84090.1", "0.51815", "0", "1"], ["84088", "0.08", "0", "2"], ["84087.2", "0.04", "0", "1"], ["84087.1", "0.76490254", "0", "2"], ["84084", "0.21228184", "0", "4"], ["84083.5", "0", "0", "0"], ["84083.2", "0.05", "0", "1"], ["84081.2", "0.2378807", "0", "1"], ["84080.9", "0", "0", "0"], ["84080.4", "0", "0", "0"], ["84077.4", "0", "0", "0"], ["84073.4", "2.81823529", "0", "1"], ["84071.7", "0", "0", "0"], ["84068.5", "0", "0", "0"], ["84065.4", "0", "0", "0"], ["84057.8", "0.24963", "0", "1"], ["84046.8", "0.00594346", "0", "1"], ["84043.5", "0", "0", "0"], ["84042.2", "0", "0", "0"], ["84040.5", "0.01790155", "0", "1"], ["84036.7", "0.24963", "0", "1"], ["84035.8", "0.35579296", "0", "1"], ["84011.9", "0.2646773", "0", "1"], ["84008", "0.07125036", "0", "1"], ["83995.6", "0.01782968", "0", "2"], ["83981.5", "0.01193661", "0", "2"], ["83973.1", "1.69295", "0", "1"], ["83971.5", "0.00001197", "0", "1"], ["83971.4", "0.00068806", "0", "1"], ["83971.1", "0.08991011", "0", "1"], ["83970.9", "0.00002851", "0", "1"], ["83970.7", "0.11878326", "0", "1"], ["83969.9", "0.014", "0", "1"], ["83969.3", "0.2025", "0", "1"], ["83969", "0.0536206", "0", "2"], ["83967.7", "0.00004003", "0", "1"], ["83967.4", "0.00013882", "0", "1"], ["83967.2", "0.00001508", "0", "1"], ["83966.8", "0.0042171", "0", "1"], ["83966.7", "0.17821722", "0", "1"], ["83966.6", "0.3604018", "0", "4"], ["83966.3", "0.00001501", "0", "1"], ["83964.4", "0.00011161", "0", "1"], ["83962.9", "0.00350324", "0", "1"], ["83962.4", "0.0245877", "0", "3"], ["83962.3", "1.32078776", "0", "2"], ["83961.6", "0.00001197", "0", "1"], ["83961.5", "0.00083", "0", "1"], ["83961", "0.01782134", "0", "1"], ["83960.9", "0.00083", "0", "1"], ["83960.8", "0.2025", "0", "1"], ["83960.4", "0.01187875", "0", "1"], ["83960", "0.01798541", "0", "3"], ["83959.9", "0.00001022", "0", "1"], ["83959.8", "0.00421771", "0", "1"], ["83959.1", "0.00001009", "0", "1"], ["83958.8", "0.00005335", "0", "1"], ["83958.3", "0.00006061", "0", "1"], ["83955", "0.00620748", "0", "1"], ["83954.5", "0.17821722", "0", "1"]], "ts": "1742554944004", "checksum": -1169005277, "seqId": 49927359763, "prevSeqId": 49927359073}], "record_time": 1742554944.02553, "EXCHANGE": "OKX"}
{"arg": {"channel": "books", "instId": "BTC-USDT"}, "action": "update", "data": [{"asks": [["84120.1", "1.68002051", "0", "17"], ["84120.5", "0.26715292", "0", "1"], ["84120.6", "0.00111884", "0", "1"], ["84120.7", "0.56214043", "0", "2"], ["84120.8", "0.05203713", "0", "2"], ["84121.2", "0", "0", "0"], ["84122", "0.0146", "0", "1"], ["84122.1", "0", "0", "0"], ["84123.6", "0", "0", "0"], ["84124", "0.0146", "0", "1"], ["84124.1", "0.05203713", "0", "2"], ["84124.2", "0.03854779", "0", "1"], ["84125.3", "0.05203713", "0", "2"], ["84125.6", "0.08991011", "0", "1"], ["84126.3", "0.02808545", "0", "1"], ["84127.9", "0.02032434", "0", "1"], ["84128.1", "0.03412235", "0", "1"], ["84128.5", "0", "0", "0"], ["84128.6", "0.03728865", "0", "1"], ["84128.7", "0.03060563", "0", "1"], ["84128.8", "0.06682359", "0", "2"], ["84130.1", "0.00001197", "0", "1"], ["84130.3", "0.11890903", "0", "1"], ["84130.4", "0.25879158", "0", "8"], ["84133.9", "0.04", "0", "1"], ["84134.4", "0.29713182", "0", "2"], ["84135.1", "0.06708269", "0", "2"], ["84136.4", "0.23788209", "0", "1"], ["84136.5", "0.33639734", "0", "2"], ["84136.7", "0.035", "0", "1"], ["84137", "1", "0", "1"], ["84137.5", "0.03153245", "0", "1"], ["84138.1", "0.04", "0", "1"], ["84138.9", "0", "0", "0"], ["84139", "0.1053998", "0", "2"], ["84141.7", "0", "0", "0"], ["84142.1", "0.06132376", "0", "1"], ["84142.4", "0", "0", "0"], ["84142.6", "0.00420121", "0", "1"], ["84143.3", "0.27006173", "0", "1"], ["84144.1", "0", "0", "0"], ["84144.2", "0.0666738", "0", "1"], ["84144.6", "0.06479575", "0", "1"], ["84145", "0.11891156", "0", "2"], ["84146.2", "0.06312384", "0", "1"], ["84148.2", "0", "0", "0"], ["84149", "0", "0", "0"], ["84149.9", "0.00061841", "0", "2"], ["84150.9", "0.49097", "0", "1"], ["84152.4", "0", "0", "0"], ["84152.5", "0", "0", "0"], ["84153.7", "0.02377746", "0", "1"], ["84158.6", "0.35663", "0", "1"], ["84159.4", "0", "0", "0"], ["84161.1", "0", "0", "0"], ["84168.5", "0", "0", "0"], ["84169.3", "0.1", "0", "1"], ["84170", "0.01188072", "0", "1"], ["84170.1", "0.01188071", "0", "1"], ["84170.3", "0.01188068", "0", "1"], ["84174.7", "0.0118926", "0", "2"], ["84175", "0", "0", "0"], ["84176", "0.01187988", "0", "1"], ["84184.5", "0", "0", "0"], ["84190.4", "0.01121908", "0", "1"], ["84190.5", "0.01188057", "0", "1"], ["84193.6", "0.01188055", "0", "1"], ["84199.1", "0", "0", "0"], ["84201.7", "0", "0", "0"], ["84204.4", "0.00012217", "0", "1"], ["84204.9", "0", "0", "0"], ["84211.6", "0", "0", "0"], ["84254.5", "0.01189131", "0", "2"], ["84268.7", "0", "0", "0"], ["84272.7", "0", "0", "0"], ["84273.2", "0", "0", "0"], ["84273.3", "0", "0", "0"], ["84274.1", "0", "0", "0"], ["84275", "0", "0", "0"], ["84275.1", "0", "0", "0"], ["84275.2", "0", "0", "0"], ["84275.3", "0", "0", "0"], ["84276", "0", "0", "0"], ["84276.5", "0", "0", "0"], ["84276.8", "0", "0", "0"], ["84276.9", "0", "0", "0"], ["84277.3", "0", "0", "0"], ["84277.5", "0", "0", "0"], ["84278.3", "0", "0", "0"], ["84278.4", "0", "0", "0"]], "bids": [["84120.7", "0", "0", "0"], ["84120.6", "0", "0", "0"], ["84120.2", "0", "0", "0"], ["84120", "0.00001", "0", "1"], ["84118.3", "0", "0", "0"], ["84118.1", "0", "0", "0"], ["84118", "0", "0", "0"], ["84117.7", "0", "0", "0"], ["84117.6", "0.002", "0", "1"], ["84116.5", "0", "0", "0"], ["84116.3", "0", "0", "0"], ["84116.2", "0", "0", "0"], ["84116", "0.0146", "0", "1"], ["84115.4", "0", "0", "0"], ["84115.3", "0", "0", "0"], ["84114.2", "0", "0", "0"], ["84113.2", "0.01380285", "0", "1"], ["84113.1", "0", "0", "0"], ["84112.7", "0", "0", "0"], ["84111.9", "0.00075966", "0", "2"], ["84109.3", "0", "0", "0"], ["84109", "0", "0", "0"], ["84108.5", "0.32039982", "0", "1"], ["84108.3", "0.02596287", "0", "3"], ["84107.9", "0", "0", "0"], ["84107.4", "0", "0", "0"], ["84106.9", "0", "0", "0"], ["84106.4", "0.01596287", "0", "1"], ["84106.3", "0", "0", "0"], ["84105.8", "0.01596287", "0", "1"], ["84105.1", "0.000735", "0", "1"], ["84104.9", "0.1192415", "0", "1"], ["84104.8", "0", "0", "0"], ["84104.5", "0.04", "0", "1"], ["84103.4", "0.04", "0", "1"], ["84103.2", "0.042", "0", "1"], ["84102.8", "0", "0", "0"], ["84102.7", "0", "0", "0"], ["84100.9", "0.11896186", "0", "1"], ["84100.8", "0.03405605", "0", "1"], ["84100.7", "0.03479396", "0", "1"], ["84100.6", "0", "0", "0"], ["84100.1", "0.27856903", "0", "2"], ["84099.7", "0", "0", "0"], ["84099.4", "0.03179059", "0", "1"], ["84098.5", "0", "0", "0"], ["84098.1", "0.35641581", "0", "1"], ["84095.7", "0.1403523", "0", "1"], ["84095.4", "0.00001197", "0", "1"], ["84093.8", "0.03345809", "0", "1"], ["84093.6", "0.05940838", "0", "1"], ["84093.1", "0.035365", "0", "1"], ["84092.2", "0", "0", "0"], ["84091.8", "0.48084", "0", "1"], ["84091.3", "0.03328319", "0", "1"], ["84088", "0", "0", "0"], ["84087.2", "0", "0", "0"], ["84087.1", "0.20908", "0", "1"], ["84085.8", "0.23787894", "0", "1"], ["84084.7", "0.06993655", "0", "2"], ["84084", "0.11228184", "0", "2"], ["84083.7", "0.06229592", "0", "1"], ["84083.2", "0.08", "0", "2"], ["84082.6", "0.0214248", "0", "1"], ["84082.4", "0.04", "0", "1"], ["84082", "0", "0", "0"], ["84081.2", "0", "0", "0"], ["84080.5", "0.00001197", "0", "1"], ["84080.3", "0", "0", "0"], ["84080.2", "0", "0", "0"], ["84079.7", "0.58172804", "0", "1"], ["84079.2", "0.1", "0", "2"], ["84078.8", "0", "0", "0"], ["84078.5", "0", "0", "0"], ["84078.4", "0.40641581", "0", "2"], ["84074.8", "0.1", "0", "1"], ["84072.4", "0.1199127", "0", "2"], ["84071.1", "0.01831719", "0", "1"], ["84069.6", "0.05427", "0", "1"], ["84068.6", "0.00099847", "0", "1"], ["84068", "0", "0", "0"], ["84067.6", "0", "0", "0"], ["84064.2", "0", "0", "0"], ["84062.5", "0.00576584", "0", "1"], ["84055.2", "0", "0", "0"], ["84053.4", "0.00105083", "0", "1"], ["84040.2", "0.00016279", "0", "1"], ["84031.7", "0", "0", "0"], ["84031.6", "0", "0", "0"], ["84030.6", "0.08240019", "0", "1"], ["84027.6", "0", "0", "0"], ["84024.9", "0", "0", "0"], ["84024.8", "0", "0", "0"], ["84024.7", "0.0000313", "0", "1"], ["84013.4", "0.00579997", "0", "1"], ["84011.2", "0", "0", "0"], ["84008.9", "0.00581522", "0", "2"], ["84001.6", "0.00001", "0", "1"], ["84000.1", "0.18317195", "0", "1"], ["83998.9", "0", "0", "0"], ["83995.6", "0.00595", "0", "1"], ["83993.6", "0.00200897", "0", "1"], ["83991.9", "0.00594389", "0", "1"], ["83981.5", "0.00005685", "0", "1"], ["83967.1", "0.01188009", "0", "1"], ["83962.4", "0.00083", "0", "1"], ["83960.4", "0", "0", "0"], ["83954.6", "0.01188017", "0", "1"], ["83954.4", "0.35579296", "0", "1"], ["83953", "0.00297157", "0", "1"], ["83952.9", "0.08991011", "0", "1"], ["83952.7", "0.00001065", "0", "1"], ["83952.6", "0.01188043", "0", "1"], ["83952.3", "0.2025", "0", "1"], ["83952.1", "0.03", "0", "1"], ["83950.6", "0.0118802", "0", "1"], ["83950", "0.00013403", "0", "2"], ["83949.9", "0.00482516", "0", "2"], ["83947.3", "0.00103791", "0", "1"], ["83946.7", "0.00002763", "0", "2"], ["83946.1", "0.17821722", "0", "1"], ["83946", "0.35579296", "0", "1"], ["83945.8", "3.17354", "0", "1"], ["83945.4", "0.11890903", "0", "1"]], "ts": "1742554944104", "checksum": -350739190, "seqId": 49927360660, "prevSeqId": 49927359763}], "record_time": 1742554944.11901, "EXCHANGE": "OKX"}
{"arg": {"channel": "books", "instId": "BTC-USDT"}, "action": "update", "data": [{"asks": [["84120.1", "1.60672378", "0", "18"], ["84120.5", "0.1575301", "0", "1"], ["84120.7", "0.2025", "0", "1"], ["84124.2", "0", "0", "0"], ["84124.6", "0.03166", "0", "1"], ["84127.9", "0.10999116", "0", "2"], ["84128.1", "0", "0", "0"], ["84128.7", "0", "0", "0"], ["84128.8", "0", "0", "0"], ["84128.9", "0.03235697", "0", "1"], ["84129", "0.03262637", "0", "1"], ["84129.1", "0.17832", "0", "1"], ["84129.9", "0.06889558", "0", "2"], ["84131.5", "0", "0", "0"], ["84132.6", "0.004488", "0", "1"], ["84135.1", "0", "0", "0"], ["84136", "0.04630386", "0", "2"], ["84136.2", "0.03136519", "0", "1"], ["84136.4", "0", "0", "0"], ["84136.5", "0.39253826", "0", "3"], ["84136.7", "0", "0", "0"], ["84137.5", "0", "0", "0"], ["84137.7", "0.06", "0", "2"], ["84138", "0.23787632", "0", "1"], ["84138.6", "0.03462585", "0", "1"], ["84138.7", "0.03433556", "0", "1"], ["84138.8", "0.0945107", "0", "1"], ["84139", "0.0103941", "0", "1"], ["84140.6", "0.2025", "0", "1"], ["84141.1", "0.03", "0", "1"], ["84142.1", "0", "0", "0"], ["84143", "0.06386621", "0", "1"], ["84144.2", "0", "0", "0"], ["84144.6", "0", "0", "0"], ["84145.3", "0.06954988", "0", "1"], ["84145.6", "0.07092625", "0", "1"], ["84146.2", "0", "0", "0"], ["84146.4", "0.06994627", "0", "1"], ["84146.8", "0.08616", "0", "1"], ["84150", "0.2", "0", "1"], ["84152.6", "0.01774536", "0", "1"], ["84155.1", "0.47104457", "0", "2"], ["84158.6", "0", "0", "0"], ["84170.4", "0.01657538", "0", "1"], ["84185", "0.87583622", "0", "2"], ["84190.9", "0", "0", "0"], ["84269.1", "0", "0", "0"], ["84269.2", "0", "0", "0"], ["84269.9", "0", "0", "0"], ["84270.6", "0", "0", "0"], ["84270.9", "0", "0", "0"], ["84271.4", "0", "0", "0"]], "bids": [["84118", "0.0146", "0", "1"], ["84113.2", "0", "0", "0"], ["84111.1", "0.04453619", "0", "1"], ["84111", "0.133767", "0", "1"], ["84108.5", "0.21494089", "0", "1"], ["84107", "0.01189514", "0", "1"], ["84105.9", "0.102", "0", "2"], ["84104.9", "0.2025532", "0", "3"], ["84104.7", "0.03713992", "0", "1"], ["84103.9", "0.17832", "0", "1"], ["84103.5", "0.03854779", "0", "1"], ["84103.4", "0", "0", "0"], ["84102.5", "0.045", "0", "1"], ["84101.7", "0.03292923", "0", "1"], ["84101.2", "0.03493012", "0", "1"], ["84100.9", "0.15309755", "0", "2"], ["84100.8", "0", "0", "0"], ["84100.7", "0", "0", "0"], ["84100.5", "0.07516109", "0", "2"], ["84100.1", "0.49926243", "0", "2"], ["84099.4", "0", "0", "0"], ["84098.6", "0.04018", "0", "1"], ["84097", "1", "0", "1"], ["84094.8", "0.53817183", "0", "1"], ["84094.7", "1.63515914", "0", "2"], ["84094.2", "0.03168814", "0", "1"], ["84093.8", "0", "0", "0"], ["84093.1", "0.03155736", "0", "1"], ["84092.5", "0.03163475", "0", "1"], ["84091.3", "0", "0", "0"], ["84087.7", "0.06805531", "0", "1"], ["84085.8", "0.06904054", "0", "1"], ["84084.7", "0.0749846", "0", "2"], ["84084.3", "0.06495597", "0", "1"], ["84083.7", "0", "0", "0"], ["84083.2", "0", "0", "0"], ["84082.8", "0.23787658", "0", "1"], ["84082.4", "0.08", "0", "2"], ["84081.6", "0.0454", "0", "2"], ["84079.8", "0.01774536", "0", "1"], ["84079.2", "0", "0", "0"], ["84078.9", "0", "0", "0"], ["84078.4", "1.86864258", "0", "4"], ["84077.6", "0.05", "0", "1"], ["84074.8", "0", "0", "0"], ["84070.2", "0.1", "0", "1"], ["84057.6", "0.00285133", "0", "1"], ["84054.9", "0.17832", "0", "1"], ["84047.3", "0.00235594", "0", "1"], ["84042.9", "0", "0", "0"], ["84007.8", "0", "0", "0"], ["83993.6", "0", "0", "0"], ["83989.8", "0.00200999", "0", "1"], ["83952.7", "0", "0", "0"], ["83952.6", "0", "0", "0"], ["83952.3", "0", "0", "0"], ["83952.1", "0", "0", "0"], ["83950.6", "0", "0", "0"], ["83950", "0", "0", "0"], ["83949.9", "0", "0", "0"], ["83947.3", "0", "0", "0"], ["83946.7", "0", "0", "0"], ["83946.1", "0", "0", "0"], ["83946", "0", "0", "0"], ["83945.8", "0", "0", "0"], ["83945.4", "0", "0", "0"]], "ts": "1742554944204", "checksum": -1246821501, "seqId": 49927360981, "prevSeqId": 49927360660}], "record_time": 1742554944.209699, "EXCHANGE": "OKX"}
{"arg": {"channel": "books", "instId": "BTC-USDT"}, "action": "update", "data": [{"asks": [["84117.7", "0.79880555", "0", "8"], ["84118.1", "1.33324346", "0", "15"], ["84118.4", "0.1996429", "0", "1"], ["84119.6", "0.11893544", "0", "1"], ["84120", "0.0146", "0", "1"], ["84120.1", "0.10113492", "0", "4"], ["84120.5", "0", "0", "0"], ["84124", "0.05545103", "0", "2"], ["84128.7", "0.03381037", "0", "1"], ["84129", "0", "0", "0"], ["84129.5", "0.06594749", "0", "2"], ["84129.9", "0", "0", "0"], ["84130.4", "0.25655784", "0", "5"], ["84132.6", "0", "0", "0"], ["84135.7", "0.03494981", "0", "1"], ["84135.8", "0.0329082", "0", "1"], ["84136", "0.02515", "0", "2"], ["84136.2", "0", "0", "0"], ["84138", "0", "0", "0"], ["84138.1", "0.07477046", "0", "2"], ["84138.2", "0.03286519", "0", "1"], ["84138.6", "0", "0", "0"], ["84138.7", "0", "0", "0"], ["84140.5", "0.23787854", "0", "1"], ["84140.9", "0", "0", "0"], ["84141.1", "0.12", "0", "4"], ["84142.7", "0.06175628", "0", "1"], ["84143", "0", "0", "0"], ["84144.9", "0.06926459", "0", "1"], ["84145.2", "0.06290893", "0", "1"], ["84145.3", "0", "0", "0"], ["84145.6", "0", "0", "0"], ["84146.1", "0.03880514", "0", "2"], ["84148", "0.03", "0", "1"], ["84151", "0.00357", "0", "1"], ["84153.4", "0.059891", "0", "1"], ["84156.1", "0.35664", "0", "1"], ["84157.1", "0", "0", "0"], ["84164.7", "0.1", "0", "1"], ["84169.3", "0", "0", "0"], ["84170", "0", "0", "0"], ["84174.7", "0.00001196", "0", "1"], ["84174.9", "0.00004312", "0", "1"], ["84180.1", "0.916785", "0", "1"], ["84183.1", "0.01121908", "0", "1"], ["84184.9", "0", "0", "0"], ["84185", "0", "0", "0"], ["84187.7", "0", "0", "0"], ["84189.7", "0.089797", "0", "1"], ["84190.4", "0", "0", "0"], ["84191", "0.43765091", "0", "3"], ["84192.5", "0.00594388", "0", "1"], ["84196.2", "0.00594388", "0", "1"], ["84214.8", "0.01220823", "0", "2"], ["84222.2", "0.20829988", "0", "2"], ["84230.9", "0.36770208", "0", "3"], ["84266.9", "0", "0", "0"], ["84267.3", "0", "0", "0"], ["84268.4", "0", "0", "0"], ["84268.5", "0", "0", "0"], ["84268.8", "0", "0", "0"]], "bids": [["84120", "0", "0", "0"], ["84118.4", "0", "0", "0"], ["84118", "0", "0", "0"], ["84113.8", "0.11894349", "0", "1"], ["84111.3", "0.16276836", "0", "1"], ["84111.2", "0.17821722", "0", "1"], ["84111.1", "0", "0", "0"], ["84110.8", "0.01339", "0", "1"], ["84109.5", "0.2025", "0", "1"], ["84105.1", "0", "0", "0"], ["84104.7", "0.04074937", "0", "2"], ["84101.7", "0", "0", "0"], ["84101.5", "0.0972031", "0", "3"], ["84101.4", "0.03103988", "0", "1"], ["84101.2", "0", "0", "0"], ["84100.8", "0.58592361", "0", "2"], ["84100.7", "1", "0", "1"], ["84100.5", "0.04", "0", "1"], ["84100.1", "0.03436119", "0", "1"], ["84097.5", "0.00475638", "0", "1"], ["84097", "0", "0", "0"], ["84095.5", "0.00713475", "0", "1"], ["84094.7", "1.60083799", "0", "1"], ["84094.4", "0.03201793", "0", "1"], ["84094.2", "0", "0", "0"], ["84093.8", "0.03216624", "0", "1"], ["84093.1", "0", "0", "0"], ["84092.6", "0.03451548", "0", "1"], ["84092.5", "0", "0", "0"], ["84092", "0.03425267", "0", "1"], ["84087.7", "0", "0", "0"], ["84087.4", "0.06580757", "0", "1"], ["84085.8", "0", "0", "0"], ["84085.4", "0.06272911", "0", "1"], ["84084.7", "0.00420528", "0", "1"], ["84084.3", "0.06654229", "0", "1"], ["84083.9", "0.08349726", "0", "2"], ["84082.4", "0", "0", "0"], ["84081.6", "0.0854", "0", "3"], ["84080.8", "0.04", "0", "1"], ["84078.4", "1.76864258", "0", "2"], ["84077.6", "0.1", "0", "2"], ["84076.8", "0.05", "0", "1"], ["84071.1", "0", "0", "0"], ["84066.8", "0.01831695", "0", "1"], ["84065.3", "0.35664", "0", "1"], ["84063.3", "0.918058", "0", "1"], ["84041.5", "0.12482", "0", "1"], ["84040.5", "0.02384543", "0", "2"], ["84040.2", "0", "0", "0"], ["84037.6", "0.02501546", "0", "2"], ["84028.5", "1.377657", "0", "1"], ["84028.2", "0.05998", "0", "1"], ["84020.5", "0.01188064", "0", "1"], ["84020.4", "0.12482", "0", "1"], ["84004.5", "0.01188072", "0", "1"], ["84001.9", "0.01785406", "0", "2"], ["84000.1", "0", "0", "0"], ["83995", "0.18316956", "0", "1"], ["83994.8", "0.20608972", "0", "2"], ["83991.9", "0.09595289", "0", "2"], ["83967.1", "0", "0", "0"], ["83959.8", "0", "0", "0"], ["83959.1", "0", "0", "0"], ["83958.8", "0", "0", "0"], ["83958.3", "0", "0", "0"], ["83955", "0", "0", "0"], ["83954.6", "0", "0", "0"], ["83954.5", "0", "0", "0"], ["83954.4", "0", "0", "0"], ["83953", "0", "0", "0"], ["83952.9", "0", "0", "0"]], "ts": "1742554944304", "checksum": -1624950593, "seqId": 49927361345, "prevSeqId": 49927360981}], "record_time": 1742554944.318537, "EXCHANGE": "OKX"}
{"arg": {"channel": "books", "instId": "BTC-USDT"}, "action": "update", "data": [{"asks": [["84116.1", "1.08346598", "0", "14"], ["84117.2", "0.1", "0", "1"], ["84117.4", "0.01055", "0", "1"], ["84117.5", "0.09592114", "0", "1"], ["84117.7", "0.036", "0", "1"], ["84118", "0.0146", "0", "1"], ["84118.1", "0", "0", "0"], ["84118.4", "0", "0", "0"], ["84119.6", "0", "0", "0"], ["84120.1", "0.09058492", "0", "3"], ["84124", "0.08156693", "0", "3"], ["84128.3", "0.03319352", "0", "1"], ["84128.7", "0", "0", "0"], ["84129.1", "0.20918176", "0", "2"], ["84129.2", "0.03413263", "0", "1"], ["84129.5", "0", "0", "0"], ["84130.2", "0.32952216", "0", "2"], ["84130.4", "0.25453713", "0", "3"], ["84134.3", "0.35641581", "0", "1"], ["84135.3", "0.03511802", "0", "1"], ["84135.4", "0.03962065", "0", "2"], ["84135.7", "0", "0", "0"], ["84135.8", "0", "0", "0"], ["84135.9", "0.23787816", "0", "1"], ["84137.8", "0.03511648", "0", "1"], ["84137.9", "0.03127568", "0", "1"], ["84138.1", "0.04", "0", "1"], ["84138.2", "0", "0", "0"], ["84140.5", "0", "0", "0"], ["84142.3", "0.06984416", "0", "2"], ["84142.7", "0", "0", "0"], ["84144.6", "0.0698109", "0", "1"], ["84144.9", "0.06944379", "0", "1"], ["84145.2", "0", "0", "0"], ["84145.5", "1.56516507", "0", "1"], ["84146.1", "0.00880514", "0", "1"], ["84149.4", "0.03", "0", "1"], ["84150.2", "0.12903106", "0", "2"], ["84152.6", "0", "0", "0"], ["84162.7", "0.1", "0", "1"], ["84164.7", "0", "0", "0"], ["84170.1", "0", "0", "0"], ["84170.3", "0", "0", "0"], ["84171.2", "0.12483", "0", "1"], ["84190.5", "0", "0", "0"], ["84193.6", "0", "0", "0"], ["84199.1", "0.01786753", "0", "2"], ["84204.4", "0", "0", "0"], ["84214.8", "0.00032751", "0", "1"], ["84225.2", "0", "0", "0"], ["84230.9", "0.35582144", "0", "2"], ["84234.1", "0.01188089", "0", "1"], ["84239.1", "0.01188086", "0", "1"], ["84258.1", "0.01191617", "0", "2"], ["84260.4", "0.01188074", "0", "1"], ["84262.6", "0.01188072", "0", "1"], ["84266.5", "0", "0", "0"], ["84266.6", "0", "0", "0"], ["84266.7", "0", "0", "0"]], "bids": [["84117.6", "0", "0", "0"], ["84116", "0.11961918", "0", "2"], ["84107.4", "0.03854779", "0", "1"], ["84104.9", "0.1891632", "0", "2"], ["84103.5", "0", "0", "0"], ["84102.1", "0.01339", "0", "1"], ["84101.4", "0", "0", "0"], ["84101", "0.03246197", "0", "1"], ["84100.8", "0.55500461", "0", "1"], ["84100.5", "0.07166704", "0", "2"], ["84100.1", "0", "0", "0"], ["84099.7", "0.03133224", "0", "1"], ["84095.5", "0", "0", "0"], ["84094.9", "0.01774536", "0", "1"], ["84094.4", "0", "0", "0"], ["84094", "0.03404988", "0", "1"], ["84093.8", "0", "0", "0"], ["84093.5", "0.00713492", "0", "1"], ["84093.4", "0.03688647", "0", "2"], ["84092.6", "0", "0", "0"], ["84092.3", "0.03464672", "0", "1"], ["84092", "0", "0", "0"], ["84091.7", "0.03214599", "0", "1"], ["84087.4", "0", "0", "0"], ["84087.1", "0.33391", "0", "2"], ["84087", "0.06546973", "0", "1"], ["84085.4", "0", "0", "0"], ["84085.1", "0.06234849", "0", "1"], ["84084.3", "0", "0", "0"], ["84084", "0.17615112", "0", "3"], ["84083.9", "0.01596287", "0", "1"], ["84083.6", "0.06140365", "0", "1"], ["84082.8", "0", "0", "0"], ["84081.7", "0.23787818", "0", "1"], ["84079.8", "0", "0", "0"], ["84070.2", "0", "0", "0"], ["84068.2", "0.1", "0", "1"], ["84067", "0.01188075", "0", "1"], ["84066.3", "0.01188084", "0", "1"], ["84066.2", "0.02376172", "0", "2"], ["84066.1", "0.12483", "0", "1"], ["84057.6", "0", "0", "0"], ["84053.5", "0.0028513", "0", "1"], ["84053.4", "0", "0", "0"], ["84050.1", "0.00105089", "0", "1"], ["84030.4", "0.00016281", "0", "1"], ["84029.8", "0.01188086", "0", "1"], ["84024.1", "0.01188089", "0", "1"], ["84020.5", "0", "0", "0"], ["84004.5", "0", "0", "0"], ["84001.9", "0.00597332", "0", "1"], ["83989.8", "0", "0", "0"], ["83986.7", "0.0020112", "0", "1"], ["83960.9", "0", "0", "0"], ["83960.8", "0", "0", "0"], ["83960", "0", "0", "0"], ["83959.9", "0", "0", "0"]], "ts": "1742554944404", "checksum": 1207217991, "seqId": 49927361636, "prevSeqId": 49927361345}], "record_time": 1742554944.411828, "EXCHANGE": "OKX"}
{"arg": {"channel": "books", "instId": "BTC-USDT"}, "action": "update", "data": [{"asks": [["84110.1", "0.97966237", "0", "13"], ["84111.7", "0.0219304", "0", "1"], ["84112", "0.0506", "0", "2"], ["84112.1", "0.0103941", "0", "1"], ["84114", "0.05991803", "0", "2"], ["84114.1", "0.036", "0", "1"], ["84114.7", "0.03854779", "0", "1"], ["84115.7", "0.00772797", "0", "1"], ["84116", "0.0146", "0", "1"], ["84116.1", "0", "0", "0"], ["84116.5", "0.08991011", "0", "1"], ["84117.2", "0", "0", "0"], ["84117.5", "0", "0", "0"], ["84118.9", "0.03166", "0", "1"], ["84120", "0.13350903", "0", "2"], ["84120.1", "0.05203713", "0", "2"], ["84120.3", "0.08788339", "0", "1"], ["84120.4", "0.03728865", "0", "1"], ["84120.6", "0", "0", "0"], ["84122.7", "0.30599791", "0", "1"], ["84122.8", "0.04", "0", "1"], ["84123.4", "0.000015", "0", "1"], ["84124", "0.0146", "0", "1"], ["84124.6", "0", "0", "0"], ["84125", "0.36414378", "0", "2"], ["84125.1", "0.17822919", "0", "2"], ["84125.2", "0.23791046", "0", "1"], ["84126.3", "0", "0", "0"], ["84127.2", "0.01055", "0", "1"], ["84127.5", "0.4123618", "0", "2"], ["84127.6", "0.00349565", "0", "1"], ["84127.7", "0.00564", "0", "1"], ["84127.9", "0", "0", "0"], ["84128.3", "0", "0", "0"], ["84128.6", "0", "0", "0"], ["84129.1", "0", "0", "0"], ["84129.2", "0", "0", "0"], ["84129.7", "1", "0", "1"], ["84129.8", "0.04", "0", "1"], ["84130.2", "0", "0", "0"], ["84130.3", "0.30604543", "0", "2"], ["84132.6", "0.00420263", "0", "1"], ["84133.9", "0", "0", "0"], ["84134", "0", "0", "0"], ["84134.8", "0.09", "0", "3"], ["84135.3", "0", "0", "0"], ["84135.4", "0", "0", "0"], ["84135.9", "0", "0", "0"], ["84136", "0", "0", "0"], ["84136.5", "0.11228184", "0", "2"], ["84137", "0", "0", "0"], ["84137.8", "0", "0", "0"], ["84137.9", "0", "0", "0"], ["84138.1", "0", "0", "0"], ["84139", "0", "0", "0"], ["84141.7", "0.133767", "0", "1"], ["84142.3", "0.002", "0", "1"], ["84144.6", "0", "0", "0"], ["84144.9", "0", "0", "0"], ["84148", "0", "0", "0"], ["84149.4", "0", "0", "0"], ["84150.2", "0.00420106", "0", "1"], ["84153.4", "0", "0", "0"], ["84154.6", "0", "0", "0"], ["84155.7", "0.25755", "0", "1"], ["84156.1", "0", "0", "0"], ["84157.4", "0", "0", "0"], ["84162.8", "0.42788722", "0", "2"], ["84166", "0.01188129", "0", "1"], ["84171.9", "0", "0", "0"], ["84174.6", "0.00712804", "0", "1"], ["84176", "0", "0", "0"], ["84180.1", "0", "0", "0"], ["84196.1", "0.00012217", "0", "1"], ["84196.3", "0", "0", "0"], ["84197.6", "0.02377835", "0", "1"], ["84199.1", "0.01774536", "0", "1"], ["84203.9", "0.02377835", "0", "1"], ["84210.8", "0", "0", "0"], ["84219.2", "0", "0", "0"], ["84219.3", "0.00007814", "0", "1"], ["84222", "0", "0", "0"], ["84223.6", "0", "0", "0"], ["84234.1", "0", "0", "0"], ["84239.1", "0", "0", "0"], ["84258.1", "0.00003542", "0", "1"], ["84260.4", "0", "0", "0"], ["84262.6", "0", "0", "0"], ["84263.3", "0.01188153", "0", "1"], ["84264.9", "0.00031778", "0", "3"], ["84266.5", "0.00054835", "0", "1"], ["84266.6", "0.01217191", "0", "13"], ["84266.7", "0.00002129", "0", "1"], ["84266.9", "0.00013853", "0", "2"], ["84267.3", "0.35615346", "0", "2"], ["84267.4", "0.02376246", "0", "2"], ["84267.5", "0.0118815", "0", "1"], ["84268.4", "0.00001026", "0", "1"]], "bids": [["84116", "0", "0", "0"], ["84114", "0", "0", "0"], ["84113.8", "0", "0", "0"], ["84112", "0", "0", "0"], ["84111.9", "0", "0", "0"], ["84111.8", "0", "0", "0"], ["84111.3", "0", "0", "0"], ["84111.2", "0", "0", "0"], ["84111", "0", "0", "0"], ["84110.8", "0", "0", "0"], ["84110.3", "0", "0", "0"], ["84110", "0.11961918", "0", "2"], ["84109.7", "0", "0", "0"], ["84109.6", "0", "0", "0"], ["84109.5", "0", "0", "0"], ["84108.5", "0", "0", "0"], ["84108", "0.0146", "0", "1"], ["84107.8", "0", "0", "0"], ["84107.4", "0", "0", "0"], ["84107", "0", "0", "0"], ["84106.2", "0", "0", "0"], ["84106", "0.0146", "0", "1"], ["84105.9", "0", "0", "0"], ["84105.3", "0", "0", "0"], ["84104.9", "0", "0", "0"], ["84104.7", "0", "0", "0"], ["84104.5", "0.00772797", "0", "1"], ["84103.9", "0", "0", "0"], ["84103.2", "0.0005658", "0", "1"], ["84102.5", "0.01339", "0", "1"], ["84102.1", "0.06857352", "0", "1"], ["84102", "0.19011301", "0", "2"], ["84101.5", "0.0042031", "0", "1"], ["84101", "0", "0", "0"], ["84100.9", "0.03413569", "0", "1"], ["84100.8", "0.25278299", "0", "1"], ["84100.7", "0", "0", "0"], ["84100.5", "0", "0", "0"], ["84099.8", "0.00006", "0", "1"], ["84099.7", "0", "0", "0"], ["84099.6", "0", "0", "0"], ["84098.6", "0", "0", "0"], ["84098.4", "0.03713992", "0", "1"], ["84098.1", "0.39641581", "0", "2"], ["84097.5", "0", "0", "0"], ["84096", "0.093", "0", "2"], ["84095.8", "0.19619509", "0", "1"], ["84095.2", "0.00772797", "0", "1"], ["84094.8", "0", "0", "0"], ["84094.7", "0", "0", "0"], ["84094", "0", "0", "0"], ["84093.6", "0", "0", "0"], ["84093.5", "0", "0", "0"], ["84093.4", "0", "0", "0"], ["84093.3", "0.04", "0", "1"], ["84092.9", "0.04019501", "0", "2"], ["84092.7", "0.042", "0", "1"], ["84092.4", "0.78762948", "0", "3"], ["84092.3", "0", "0", "0"], ["84091.9", "0.1871364", "0", "1"], ["84091.7", "0", "0", "0"], ["84088.6", "1", "0", "1"], ["84088.5", "0.02379125", "0", "1"], ["84087.1", "0", "0", "0"], ["84087", "0", "0", "0"], ["84086.4", "0.06940838", "0", "2"], ["84085.6", "0.11898342", "0", "1"], ["84085.1", "0", "0", "0"], ["84084", "0.11228184", "0", "2"], ["84083.6", "0", "0", "0"], ["84081.7", "0", "0", "0"], ["84081.6", "0", "0", "0"], ["84081.4", "0.0054", "0", "1"], ["84081.1", "0", "0", "0"], ["84080.8", "0", "0", "0"], ["84079.7", "0", "0", "0"], ["84078.3", "0.4", "0", "1"], ["84077.6", "0", "0", "0"], ["84076.8", "0", "0", "0"], ["84076", "0.33446287", "0", "5"], ["84075.2", "0.04", "0", "1"], ["84073.4", "0", "0", "0"], ["84072", "0.1025", "0", "3"], ["84071.2", "0.05", "0", "1"], ["84071.1", "0.20908", "0", "1"], ["84069.6", "0.05967", "0", "2"], ["84068.2", "0", "0", "0"], ["84067.6", "0.23791046", "0", "1"], ["84067", "0", "0", "0"], ["84066.3", "0", "0", "0"], ["84066.2", "0.1", "0", "1"], ["84065.3", "0", "0", "0"], ["84063.3", "0", "0", "0"], ["84062.9", "0", "0", "0"], ["84061.8", "0.01188124", "0", "1"], ["84060.4", "0.01188133", "0", "1"], ["84060.3", "0.01188136", "0", "1"], ["84059.8", "0.01188068", "0", "1"], ["84054.9", "0", "0", "0"], ["84053.5", "0", "0", "0"], ["84050.2", "0.00285153", "0", "1"], ["84050.1", "0", "0", "0"], ["84047.4", "0.00105113", "0", "1"], ["84042.8", "0.00357", "0", "1"], ["84040.5", "0.00594388", "0", "1"], ["84039.8", "0.18535669", "0", "2"], ["84037.7", "0", "0", "0"], ["84030.4", "0", "0", "0"], ["84030.3", "0", "0", "0"], ["84030.2", "0", "0", "0"], ["84030", "0.00001196", "0", "1"], ["84029.8", "0", "0", "0"], ["84028.2", "0", "0", "0"], ["84027", "0", "0", "0"], ["84026.8", "0.02377835", "0", "1"], ["84024.1", "0", "0", "0"], ["84022.9", "0", "0", "0"], ["84021.5", "0.12478119", "0", "3"], ["84016.6", "0.00640656", "0", "2"], ["84015.7", "0.24967", "0", "1"], ["84015.1", "0.02376282", "0", "2"], ["84011.4", "0.0642", "0", "3"], ["84011.3", "0.0428", "0", "2"], ["84010.8", "0.0007194", "0", "1"], ["84010.1", "0.01779937", "0", "3"], ["84009.6", "0.01188156", "0", "1"], ["84009.1", "0.00599993", "0", "1"], ["84005", "0", "0", "0"], ["84004.7", "0", "0", "0"], ["84003.7", "0.27983927", "0", "5"], ["83986.2", "0.0142", "0", "1"], ["83986.1", "0.2804027", "0", "6"], ["83960.9", "0.00083", "0", "1"], ["83960.8", "0.2025", "0", "1"], ["83960", "0.01798541", "0", "3"], ["83959.9", "0.00001022", "0", "1"], ["83959.8", "0.00421771", "0", "1"], ["83959.1", "0.00001009", "0", "1"], ["83958.8", "0.00005335", "0", "1"], ["83958.3", "0.00006061", "0", "1"], ["83955", "0.00620748", "0", "1"], ["83954.5", "0.17821722", "0", "1"], ["83954.4", "0.35579296", "0", "1"], ["83953", "0.00297157", "0", "1"], ["83952.9", "0.08991011", "0", "1"], ["83952.7", "0.00001065", "0", "1"], ["83952.3", "0.2025", "0", "1"], ["83952.1", "0.03", "0", "1"], ["83950", "0.00013403", "0", "2"], ["83949.9", "0.00482516", "0", "2"], ["83947.3", "0.00103791", "0", "1"], ["83946.7", "0.00002763", "0", "2"], ["83946.1", "0.17821722", "0", "1"], ["83946", "0.35579296", "0", "1"], ["83945.8", "3.17354", "0", "1"], ["83945.4", "0.11890903", "0", "1"], ["83945.1", "0.002378", "0", "1"], ["83944.8", "0.00011161", "0", "1"], ["83944.6", "0.00421935", "0", "1"], ["83943.8", "0.2025", "0", "1"], ["83943.5", "0.03", "0", "1"], ["83943.1", "0.01775819", "0", "1"], ["83942.5", "6.49843346", "0", "1"], ["83942", "0.00007352", "0", "1"], ["83941.1", "0.00001807", "0", "1"], ["83940.4", "0.00002279", "0", "1"], ["83939.8", "2.4621163", "0", "2"], ["83939.7", "0.03", "0", "1"], ["83939.5", "0.00007329", "0", "1"]], "ts": "1742554944504", "checksum": -404573264, "seqId": 49927362578, "prevSeqId": 49927361636}], "record_time": 1742554944.506784, "EXCHANGE": "OKX"}
{"arg": {"channel": "books", "instId": "BTC-USDT"}, "action": "update", "data": [{"asks": [["84110.1", "0.2639519", "0", "5"], ["84111.3", "0.054318", "0", "1"], ["84111.4", "0.11894702", "0", "1"], ["84111.7", "0", "0", "0"], ["84111.9", "0.00111889", "0", "1"], ["84112", "0.0146", "0", "1"], ["84114", "0.04366273", "0", "2"], ["84114.1", "0", "0", "0"], ["84116.5", "0.02808545", "0", "1"], ["84117.4", "0", "0", "0"], ["84117.7", "0", "0", "0"], ["84119.9", "0.14321517", "0", "1"], ["84120.1", "0.0520491", "0", "3"], ["84120.3", "0", "0", "0"], ["84123.5", "0.03410731", "0", "1"], ["84123.7", "0.06217413", "0", "2"], ["84124", "0.04546236", "0", "2"], ["84124.1", "0.08703794", "0", "3"], ["84125.2", "0", "0", "0"], ["84127.5", "0.02350429", "0", "1"], ["84128.2", "0.06", "0", "2"], ["84128.9", "0", "0", "0"], ["84129.7", "0", "0", "0"], ["84130.3", "0.34110238", "0", "3"], ["84130.5", "0.03204901", "0", "1"], ["84131.2", "1", "0", "1"], ["84132.4", "0.03087698", "0", "1"], ["84132.5", "0.03115839", "0", "1"], ["84133.3", "0.23890134", "0", "3"], ["84134.8", "0.12", "0", "4"], ["84136.8", "0.08609", "0", "1"], ["84137.5", "0.06950094", "0", "1"], ["84139.1", "0.07032032", "0", "1"], ["84139.7", "0.07959365", "0", "2"], ["84141.1", "0.09", "0", "3"], ["84141.2", "0.06542108", "0", "2"], ["84142", "0", "0", "0"], ["84142.3", "0.00557", "0", "2"], ["84143.7", "0.059898", "0", "1"], ["84146.4", "0", "0", "0"], ["84150.3", "0.0054", "0", "1"], ["84151.1", "0.35668", "0", "1"], ["84153.6", "0.06100748", "0", "1"], ["84160.7", "0.1", "0", "1"], ["84162.3", "0", "0", "0"], ["84162.7", "0", "0", "0"], ["84170.5", "0.916889", "0", "1"], ["84171.8", "0.00004312", "0", "1"], ["84173.9", "0.0054", "0", "1"], ["84174.9", "0", "0", "0"], ["84177.4", "0", "0", "0"], ["84178.4", "0.01121934", "0", "1"], ["84183.1", "0", "0", "0"], ["84185.9", "0.0712709", "0", "1"], ["84192.4", "0.00012217", "0", "1"], ["84194.6", "0.01426465", "0", "2"], ["84196.1", "0", "0", "0"], ["84197.1", "0.00118769", "0", "1"], ["84203", "0", "0", "0"], ["84205.5", "1.374762", "0", "1"], ["84266.4", "0", "0", "0"], ["84266.5", "0", "0", "0"], ["84266.6", "0", "0", "0"], ["84266.7", "0", "0", "0"], ["84266.9", "0", "0", "0"], ["84267.3", "0", "0", "0"], ["84267.4", "0", "0", "0"], ["84267.5", "0", "0", "0"], ["84268.4", "0", "0", "0"]], "bids": [["84110", "0.38009307", "0", "5"], ["84104.5", "0.14149497", "0", "2"], ["84103.4", "0.15812118", "0", "1"], ["84103.3", "0.2", "0", "1"], ["84102.1", "0", "0", "0"], ["84100.9", "0", "0", "0"], ["84097.8", "0.03854779", "0", "1"], ["84097.4", "0.01339", "0", "1"], ["84096.2", "0.03293451", "0", "1"], ["84096", "0.195", "0", "4"], ["84095.9", "0.007", "0", "1"], ["84095.7", "0.17292579", "0", "2"], ["84095", "0.03418974", "0", "1"], ["84094.9", "0", "0", "0"], ["84094.6", "0.03349081", "0", "1"], ["84092.7", "0.087", "0", "2"], ["84091.5", "1", "0", "1"], ["84089.2", "0.03075751", "0", "1"], ["84088.6", "0", "0", "0"], ["84088.3", "0.03544688", "0", "1"], ["84086.9", "0.03275801", "0", "1"], ["84086.3", "0.03175305", "0", "1"], ["84086.2", "0.05852253", "0", "1"], ["84083.7", "0.11898615", "0", "1"], ["84082.6", "0", "0", "0"], ["84082.2", "0.06473087", "0", "1"], ["84078.8", "0.0698841", "0", "1"], ["84078.5", "0.25563136", "0", "2"], ["84078.2", "0.2920791", "0", "4"], ["84076", "0.25446287", "0", "3"], ["84072", "0.0025", "0", "1"], ["84071.2", "0.1", "0", "2"], ["84071", "0.0239348", "0", "3"], ["84070.9", "0.08991011", "0", "1"], ["84070.4", "0.05", "0", "1"], ["84067.6", "0", "0", "0"], ["84066.8", "0", "0", "0"], ["84066.7", "0", "0", "0"], ["84066.2", "0", "0", "0"], ["84062.5", "0", "0", "0"], ["84062", "0.00024809", "0", "1"], ["84061.8", "0", "0", "0"], ["84060.8", "0.01831804", "0", "1"], ["84060.4", "0", "0", "0"], ["84060.3", "0", "0", "0"], ["84060.2", "0.12204823", "0", "3"], ["84059.9", "0.03933432", "0", "2"], ["84059.7", "0.01188148", "0", "1"], ["84057.8", "0.35692809", "0", "2"], ["84053.5", "0.00024809", "0", "1"], ["84053", "0.91817", "0", "1"], ["84050.2", "0", "0", "0"], ["84047.4", "0.00285155", "0", "1"], ["84044.4", "0.00105115", "0", "1"], ["84037.9", "0.01064", "0", "1"], ["84035.5", "0.0118816", "0", "1"], ["84026.2", "0.00016282", "0", "1"], ["84020.8", "0.07141082", "0", "1"], ["84017.3", "0.06000301", "0", "2"], ["84015.1", "0", "0", "0"], ["84009.6", "0", "0", "0"], ["83995", "0", "0", "0"], ["83989.1", "0.18318046", "0", "1"], ["83986.7", "0", "0", "0"], ["83981.4", "0.02377479", "0", "3"], ["83980.1", "0.00201143", "0", "1"], ["83976.6", "0.01188156", "0", "1"], ["83945.4", "0", "0", "0"], ["83945.1", "0", "0", "0"], ["83944.8", "0", "0", "0"], ["83944.6", "0", "0", "0"], ["83943.8", "0", "0", "0"], ["83943.5", "0", "0", "0"], ["83943.1", "0", "0", "0"], ["83942.5", "0", "0", "0"], ["83942", "0", "0", "0"], ["83941.1", "0", "0", "0"], ["83940.4", "0", "0", "0"], ["83939.8", "0", "0", "0"], ["83939.7", "0", "0", "0"], ["83939.5", "0", "0", "0"]], "ts": "1742554944604", "checksum": -897998559, "seqId": 49927362887, "prevSeqId": 49927362578}], "record_time": 1742554944.605863, "EXCHANGE": "OKX"}
{"arg": {"channel": "books", "instId": "BTC-USDT"}, "action": "update", "data": [{"asks": [["84110.1", "0.67194059", "0", "7"], ["84118.9", "0", "0", "0"], ["84123.3", "0.03508576", "0", "1"], ["84123.5", "0", "0", "0"], ["84123.6", "0.03165", "0", "1"], ["84123.9", "0.03185975", "0", "1"], ["84124", "0.0146", "0", "1"], ["84124.6", "0.00891395", "0", "1"], ["84126.5", "0.09817129", "0", "1"], ["84126.6", "0.17834", "0", "1"], ["84127.5", "0", "0", "0"], ["84128.6", "0.03", "0", "1"], ["84130.2", "0.03333974", "0", "1"], ["84130.3", "0.33982833", "0", "3"], ["84130.5", "0", "0", "0"], ["84132.7", "0.0054", "0", "1"], ["84133.3", "0.00101534", "0", "2"], ["84136.4", "0.23788119", "0", "1"], ["84137.3", "0.06934483", "0", "1"], ["84137.5", "0", "0", "0"], ["84137.7", "0.03", "0", "1"], ["84139.7", "0.07796991", "0", "2"], ["84141.1", "0", "0", "0"], ["84144.4", "0.0054", "0", "1"], ["84150.3", "0", "0", "0"], ["84154.7", "0.1", "0", "1"], ["84160.7", "0", "0", "0"], ["84166.5", "0.00004312", "0", "1"], ["84171.8", "0", "0", "0"], ["84185.9", "0.1425418", "0", "2"], ["84224.7", "0", "0", "0"], ["84265.1", "0", "0", "0"], ["84265.8", "0", "0", "0"], ["84266", "0", "0", "0"], ["84266.2", "0", "0", "0"]], "bids": [["84110", "0.52324176", "0", "9"], ["84108.8", "0.11895061", "0", "1"], ["84102.5", "0", "0", "0"], ["84098.5", "0.000369", "0", "1"], ["84097.9", "0.01339", "0", "1"], ["84097.5", "0.04018", "0", "1"], ["84096.8", "0.00358591", "0", "1"], ["84096.3", "0.17834", "0", "1"], ["84096.2", "0", "0", "0"], ["84096", "0.22985149", "0", "5"], ["84095.8", "0.48225277", "0", "2"], ["84094.6", "0", "0", "0"], ["84094.5", "0.14340625", "0", "3"], ["84093.5", "1", "0", "1"], ["84092.9", "0.00001501", "0", "1"], ["84092.4", "0.4678912", "0", "2"], ["84091.5", "0", "0", "0"], ["84089.2", "0", "0", "0"], ["84089", "0.03417764", "0", "1"], ["84088.3", "0", "0", "0"], ["84088.2", "0.03114866", "0", "1"], ["84082.2", "0", "0", "0"], ["84082", "0.06976303", "0", "1"], ["84079.7", "0.2378846", "0", "1"], ["84079.6", "0.06568733", "0", "1"], ["84078.8", "0.06530707", "0", "1"], ["84078.5", "0.01774536", "0", "1"], ["84075.2", "0", "0", "0"], ["84074.4", "0.04", "0", "1"], ["84071.2", "0", "0", "0"], ["84070.4", "0.1", "0", "2"], ["84069.6", "0.10967", "0", "3"], ["84061", "0.58720077", "0", "1"], ["84049.9", "0.17894645", "0", "2"], ["84026.2", "0", "0", "0"], ["84020.8", "0.14282164", "0", "2"], ["83998.5", "0", "0", "0"], ["83971.3", "0.01189343", "0", "1"], ["83946.7", "0", "0", "0"], ["83946.1", "0", "0", "0"], ["83946", "0", "0", "0"], ["83945.8", "0", "0", "0"]], "ts": "1742554944704", "checksum": -1586564385, "seqId": 49927362999, "prevSeqId": 49927362887}], "record_time": 1742554944.70453, "EXCHANGE": "OKX"}
{"arg": {"channel": "books", "instId": "BTC-USDT"}, "action": "update", "data": [{"asks": [["84111.3", "0.04039977", "0", "1"], ["84115.5", "0.01055", "0", "1"], ["84128.6", "0.06", "0", "2"], ["84137.7", "0", "0", "0"], ["84151.1", "0", "0", "0"], ["84155.1", "0.470969", "0", "1"], ["84159.3", "0", "0", "0"], ["84163.5", "0", "0", "0"], ["84265.1", "0.00418989", "0", "1"], ["84265.8", "0.00001156", "0", "1"], ["84266", "0.11878326", "0", "1"]], "bids": [["84108.8", "0", "0", "0"], ["84102", "0.20350301", "0", "3"], ["84098.5", "0", "0", "0"], ["84097.4", "0", "0", "0"], ["84082.7", "0", "0", "0"], ["84082.5", "1.52941916", "0", "1"], ["84057.8", "0.00024809", "0", "1"], ["84053.1", "2.78566807", "0", "1"], ["83946.7", "0.00002763", "0", "2"], ["83946.1", "0.17821722", "0", "1"]], "ts": "1742554944804", "checksum": -1319933761, "seqId": 49927363018, "prevSeqId": 49927362999}], "record_time": 1742554944.805875, "EXCHANGE": "OKX"}
{"arg": {"channel": "books", "instId": "BTC-USDT"}, "action": "update", "data": [{"asks": [["84128.6", "0.12", "0", "4"], ["84134.8", "0.06", "0", "2"], ["84143.5", "0.53489722", "0", "2"], ["84146.2", "0.00887164", "0", "1"], ["84150.2", "0.12904106", "0", "2"], ["84150.4", "0.00576625", "0", "1"], ["84154.6", "0.00576625", "0", "1"], ["84201.3", "0.01188188", "0", "1"], ["84206.9", "3.52975185", "0", "2"], ["84209.7", "0.01188184", "0", "1"], ["84263.3", "0", "0", "0"], ["84264.9", "0", "0", "0"], ["84265.1", "0", "0", "0"], ["84265.8", "0", "0", "0"], ["84266", "0", "0", "0"]], "bids": [["84097.1", "0.11896719", "0", "1"], ["84094.9", "1", "0", "1"], ["84093.5", "0", "0", "0"], ["84087.7", "0.17834", "0", "1"], ["84087.1", "0.12484", "0", "1"], ["84082.6", "0.01774536", "0", "1"], ["84078.5", "0", "0", "0"], ["84077.9", "0.35668", "0", "1"], ["84053.1", "2.80947395", "0", "2"], ["84049.9", "0.00060645", "0", "1"], ["84044.7", "0.02376346", "0", "2"], ["84041.5", "0", "0", "0"], ["84038.5", "0.01188188", "0", "1"], ["84020.4", "0", "0", "0"], ["84015.7", "0", "0", "0"], ["83996.9", "0.01189485", "0", "1"], ["83981.4", "0.00001197", "0", "1"], ["83976.6", "0", "0", "0"], ["83971.3", "0", "0", "0"], ["83946.7", "0", "0", "0"], ["83946.1", "0", "0", "0"]], "ts": "1742554944904", "checksum": -1319933761, "seqId": 49927363058, "prevSeqId": 49927363018}], "record_time": 1742554944.913764, "EXCHANGE": "OKX"}
{"arg": {"channel": "books", "instId": "BTC-USDT"}, "action": "update", "data": [{"asks": [["84134.8", "0.03", "0", "1"], ["84141.8", "0.25467", "0", "2"], ["84143.5", "0.17821722", "0", "1"], ["84146", "1", "0", "1"], ["84264.7", "0", "0", "0"]], "bids": [["84101.2", "0.000036", "0", "1"], ["84078.8", "0.31497707", "0", "2"], ["84077.9", "0", "0", "0"], ["84057.8", "0.24991809", "0", "2"], ["84044.7", "0", "0", "0"], ["84038.5", "0", "0", "0"], ["84018", "0.02376324", "0", "2"], ["84012.4", "0.01188177", "0", "1"], ["83955.9", "0.00001197", "0", "1"], ["83947.3", "0", "0", "0"]], "ts": "1742554945004", "checksum": -384604084, "seqId": 49927363081, "prevSeqId": 49927363058}], "record_time": 1742554945.020849, "EXCHANGE": "OKX"}
{"arg": {"channel": "books", "instId": "BTC-USDT"}, "action": "update", "data": [{"asks": [["84110.1", "0.54247944", "0", "6"], ["84115.5", "0", "0", "0"], ["84118.1", "0.01055", "0", "1"], ["84119", "0.0350009", "0", "1"], ["84125.9", "0.35668", "0", "1"], ["84134.8", "0", "0", "0"], ["84136.4", "0.23788687", "0", "1"], ["84143.2", "0.01774536", "0", "1"], ["84183.9", "0", "0", "0"], ["84199.1", "0", "0", "0"]], "bids": [["84110", "0.5391719", "0", "10"], ["84104.6", "0.01339", "0", "1"], ["84102", "0.19011301", "0", "2"], ["84096.2", "1", "0", "1"], ["84095.6", "0.35668", "0", "1"], ["84094.9", "0", "0", "0"], ["84079.7", "0", "0", "0"], ["84078.9", "0.23788687", "0", "1"], ["84072.4", "0.11890903", "0", "1"], ["84068.6", "0", "0", "0"], ["84060.1", "0.00100367", "0", "1"], ["84056.4", "0.00099859", "0", "1"], ["84036.7", "0", "0", "0"], ["83966.5", "0.00001197", "0", "1"], ["83952.1", "0", "0", "0"], ["83950", "0", "0", "0"], ["83949.9", "0", "0", "0"]], "ts": "1742554945104", "checksum": -291491374, "seqId": 49927363121, "prevSeqId": 49927363081}], "record_time": 1742554945.115677, "EXCHANGE": "OKX"}
{"arg": {"channel": "books", "instId": "BTC-USDT"}, "action": "update", "data": [{"asks": [["84110.1", "0.4590519", "0", "5"], ["84112.1", "0", "0", "0"], ["84115.4", "0.0103941", "0", "1"], ["84127.7", "0", "0", "0"], ["84143.3", "1.05495288", "0", "2"], ["84173.1", "0.22037851", "0", "1"], ["84201.8", "0.48938442", "0", "2"]], "bids": [["84110", "0.5347119", "0", "9"], ["84108.1", "0.05262227", "0", "1"], ["84101.2", "0", "0", "0"], ["84096.3", "0.80677133", "0", "2"], ["84095.8", "0", "0", "0"], ["84082.6", "0.50023109", "0", "2"], ["84053.3", "1.24797067", "0", "2"], ["84028.6", "0.53751157", "0", "1"]], "ts": "1742554945204", "checksum": -221257230, "seqId": 49927363147, "prevSeqId": 49927363121}], "record_time": 1742554945.219233, "EXCHANGE": "OKX"}
{"arg": {"channel": "books", "instId": "BTC-USDT"}, "action": "update", "data": [{"asks": [["84114", "0.03284226", "0", "2"], ["84114.7", "0", "0", "0"], ["84118.8", "0.03854779", "0", "1"], ["84127.8", "0.0000375", "0", "1"], ["84146.8", "0", "0", "0"]], "bids": [["84110", "0.4901119", "0", "7"], ["84102.3", "0.03854779", "0", "1"], ["84101.6", "0.0056625", "0", "1"], ["84097.8", "0", "0", "0"], ["84083.5", "0.12484", "0", "1"], ["84062.5", "0.12484", "0", "1"], ["83952.9", "0", "0", "0"], ["83952.7", "0", "0", "0"], ["83952.3", "0", "0", "0"]], "ts": "1742554945304", "checksum": 1344367988, "seqId": 49927363166, "prevSeqId": 49927363147}], "record_time": 1742554945.328201, "EXCHANGE": "OKX"}
{"arg": {"channel": "books", "instId": "BTC-USDT"}, "action": "update", "data": [{"asks": [["84110.1", "0.47564059", "0", "6"], ["84115.4", "0", "0", "0"], ["84118.7", "0.0103941", "0", "1"]], "bids": [], "ts": "1742554945404", "checksum": -742449347, "seqId": 49927363171, "prevSeqId": 49927363166}], "record_time": 1742554945.404449, "EXCHANGE": "OKX"}
{"arg": {"channel": "books", "instId": "BTC-USDT"}, "action": "update", "data": [{"asks": [["84126.5", "0.43022105", "0", "2"], ["84129.8", "1.04", "0", "2"], ["84131.2", "0", "0", "0"], ["84133.3", "0.23890628", "0", "3"], ["84136.4", "0", "0", "0"], ["84264.7", "0.2025", "0", "1"], ["84264.9", "0.00031778", "0", "3"]], "bids": [["84110", "0.5079449", "0", "8"], ["84105.1", "0.2", "0", "1"], ["84103.3", "0", "0", "0"], ["84078.9", "0", "0", "0"], ["84074.6", "0.23789094", "0", "1"]], "ts": "1742554945504", "checksum": -537654547, "seqId": 49927363184, "prevSeqId": 49927363171}], "record_time": 1742554945.505201, "EXCHANGE": "OKX"}
{"arg": {"channel": "books", "instId": "BTC-USDT"}, "action": "update", "data": [{"asks": [["84178.1", "0.01917563", "0", "1"], ["84218.1", "0.07103359", "0", "2"], ["84222.1", "0.006", "0", "1"], ["84232.2", "0", "0", "0"], ["84264.9", "0", "0", "0"]], "bids": [["84108.1", "0.10604449", "0", "2"], ["84104.6", "0.132393", "0", "2"], ["84103.4", "0", "0", "0"], ["84077", "1", "0", "1"], ["84075.2", "0.08", "0", "2"], ["84072.1", "0.16852542", "0", "2"], ["84007.7", "0.07102314", "0", "1"], ["83954.4", "0", "0", "0"], ["83953", "0", "0", "0"]], "ts": "1742554945604", "checksum": 1278703880, "seqId": 49927363197, "prevSeqId": 49927363184}], "record_time": 1742554945.604446, "EXCHANGE": "OKX"}
{"arg": {"channel": "books", "instId": "BTC-USDT"}, "action": "update", "data": [{"asks": [["84124.6", "0", "0", "0"], ["84149.6", "0.08", "0", "2"], ["84150.4", "0.04576624", "0", "2"], ["84168.8", "0", "0", "0"], ["84169.6", "0", "0", "0"], ["84264.9", "0.00031778", "0", "3"], ["84265.1", "0.00418989", "0", "1"]], "bids": [["84110", "0.5116449", "0", "9"], ["84104.4", "0.01189539", "0", "1"], ["84102", "0.17821722", "0", "1"], ["84096.8", "0", "0", "0"]], "ts": "1742554945704", "checksum": -1852728300, "seqId": 49927363211, "prevSeqId": 49927363197}], "record_time": 1742554945.724478, "EXCHANGE": "OKX"}
{"arg": {"channel": "books", "instId": "BTC-USDT"}, "action": "update", "data": [{"asks": [["84125.6", "0", "0", "0"], ["84265.8", "0.00001156", "0", "1"]], "bids": [["84104.6", "0.09226278", "0", "2"], ["84104.5", "0.00772797", "0", "1"], ["84005.9", "0.01180022", "0", "2"]], "ts": "1742554945804", "checksum": 848563135, "seqId": 49927363216, "prevSeqId": 49927363211}], "record_time": 1742554945.812253, "EXCHANGE": "OKX"}
{"arg": {"channel": "books", "instId": "BTC-USDT"}, "action": "update", "data": [{"asks": [["84110.1", "0.69544059", "0", "10"], ["84127.8", "0", "0", "0"], ["84128.5", "1", "0", "1"], ["84129.8", "0.04", "0", "1"]], "bids": [["84110", "0.43949334", "0", "7"], ["84108.1", "0", "0", "0"], ["84105.1", "0", "0", "0"], ["84101.6", "0", "0", "0"], ["84100.4", "0.13377797", "0", "2"], ["84077", "0", "0", "0"], ["84071.2", "0.1", "0", "2"], ["84070.4", "0.05", "0", "1"], ["84069.6", "0.05967", "0", "2"], ["83954.4", "0.35579296", "0", "1"], ["83953", "0.00297157", "0", "1"], ["83952.9", "0.08991011", "0", "1"]], "ts": "1742554945904", "checksum": -1708937146, "seqId": 49927363238, "prevSeqId": 49927363216}], "record_time": 1742554945.90736, "EXCHANGE": "OKX"}
{"arg": {"channel": "books", "instId": "BTC-USDT"}, "action": "update", "data": [{"asks": [["84110.1", "0.49294059", "0", "9"], ["84115.7", "0.01827797", "0", "2"], ["84118.1", "0", "0", "0"], ["84122.5", "0.0044595", "0", "1"], ["84132.3", "0.23789383", "0", "1"], ["84133.3", "0.00101534", "0", "2"], ["84265.8", "0", "0", "0"]], "bids": [["84110", "0.42166034", "0", "6"], ["84105", "0.05614092", "0", "1"], ["84104.6", "0.07887278", "0", "1"], ["84102.2", "0.01339", "0", "1"], ["84098.6", "0.00564", "0", "1"], ["84096.2", "0", "0", "0"], ["84094.8", "1", "0", "1"], ["84074.6", "0", "0", "0"], ["84073.6", "0.23789383", "0", "1"], ["83953", "0", "0", "0"], ["83952.9", "0", "0", "0"]], "ts": "1742554946004", "checksum": 1509044478, "seqId": 49927363253, "prevSeqId": 49927363238}], "record_time": 1742554946.004582, "EXCHANGE": "OKX"}
{"arg": {"channel": "books", "instId": "BTC-USDT"}, "action": "update", "data": [{"asks": [["84122.5", "0", "0", "0"], ["84132.3", "0", "0", "0"], ["84133.3", "0.23890744", "0", "3"], ["84139.8", "0", "0", "0"], ["84176.8", "0.01123025", "0", "1"], ["84178.4", "0", "0", "0"], ["84190.7", "0.00012217", "0", "1"], ["84192.4", "0", "0", "0"], ["84265.8", "0.00001156", "0", "1"], ["84266", "0.11878326", "0", "1"], ["84266.2", "0.213955", "0", "1"]], "bids": [["84108.3", "0.02096287", "0", "2"], ["84098.6", "0", "0", "0"], ["84074.6", "0.2378922", "0", "1"], ["84073.6", "0", "0", "0"], ["84063", "0.05614092", "0", "1"], ["84060.8", "0", "0", "0"], ["84060.3", "0.01831787", "0", "1"], ["84044.4", "0", "0", "0"], ["84043.1", "0.00105114", "0", "1"], ["84005.9", "0.01760022", "0", "3"], ["84003.4", "0", "0", "0"], ["83989.1", "0", "0", "0"], ["83987.8", "0.18325182", "0", "2"], ["83982.6", "0.183121", "0", "1"], ["83980.1", "0", "0", "0"], ["83978.3", "0.0020116", "0", "1"], ["83953", "0.00297157", "0", "1"]], "ts": "1742554946104", "checksum": -1829129827, "seqId": 49927363305, "prevSeqId": 49927363253}], "record_time": 1742554946.105217, "EXCHANGE": "OKX"}
{"arg": {"channel": "books", "instId": "BTC-USDT"}, "action": "update", "data": [{"asks": [["84125.5", "0.005772", "0", "1"], ["84130.2", "0.53433489", "0", "2"], ["84133.3", "0.2389075", "0", "3"], ["84155.4", "0.65515031", "0", "2"], ["84157.3", "0.01189464", "0", "1"], ["84183.2", "0", "0", "0"], ["84185", "0.12973557", "0", "1"], ["84220", "0.18842744", "0", "1"], ["84265.8", "0", "0", "0"], ["84266", "0", "0", "0"], ["84266.2", "0", "0", "0"]], "bids": [["84110", "0.41796034", "0", "5"], ["84098.7", "0.00564", "0", "1"], ["84076.6", "0.24209767", "0", "2"], ["84074.6", "0", "0", "0"], ["84071.2", "0.45787758", "0", "3"], ["84070", "0.005", "0", "2"], ["84045.8", "0.6827541", "0", "4"]], "ts": "1742554946204", "checksum": -1116146779, "seqId": 49927363332, "prevSeqId": 49927363305}], "record_time": 1742554946.216802, "EXCHANGE": "OKX"}
{"arg": {"channel": "books", "instId": "BTC-USDT"}, "action": "update", "data": [{"asks": [["84148.8", "0.08151854", "0", "3"], ["84149.6", "0.03999999", "0", "1"], ["84150.4", "0.00576625", "0", "1"], ["84164.2", "0.24222096", "0", "2"], ["84166.5", "0", "0", "0"], ["84265.8", "0.00001156", "0", "1"]], "bids": [["84076.4", "0", "0", "0"], ["84056.2", "0.59964265", "0", "1"], ["84037.4", "0", "0", "0"], ["84034.4", "0", "0", "0"], ["84020.4", "0.00016272", "0", "1"], ["84019.9", "0.30331235", "0", "1"], ["84014.2", "0.59432247", "0", "1"], ["83953", "0", "0", "0"]], "ts": "1742554946304", "checksum": -1116146779, "seqId": 49927363355, "prevSeqId": 49927363332}], "record_time": 1742554946.312124, "EXCHANGE": "OKX"}
{"arg": {"channel": "books", "instId": "BTC-USDT"}, "action": "update", "data": [{"asks": [], "bids": [["84110", "0.43579334", "0", "6"], ["84096.1", "1", "0", "1"], ["84094.8", "0", "0", "0"], ["84076.6", "0.00420551", "0", "1"], ["84074.6", "0.23789249", "0", "1"], ["84073", "0.2", "0", "1"], ["83954.5", "0", "0", "0"], ["83954.4", "0", "0", "0"]], "ts": "1742554946404", "checksum": -2025004800, "seqId": 49927363368, "prevSeqId": 49927363355}], "record_time": 1742554946.42193, "EXCHANGE": "OKX"}
{"arg": {"channel": "books", "instId": "BTC-USDT"}, "action": "update", "data": [{"asks": [["84185.9", "0.0712709", "0", "1"]], "bids": [["84076.6", "0.24209791", "0", "2"], ["84074.6", "0", "0", "0"], ["84073", "0", "0", "0"], ["84020.8", "0.07141082", "0", "1"], ["83954.5", "0.17821722", "0", "1"], ["83954.4", "0.35579296", "0", "1"]], "ts": "1742554946504", "checksum": -2025004800, "seqId": 49927363379, "prevSeqId": 49927363368}], "record_time": 1742554946.507384, "EXCHANGE": "OKX"}
{"arg": {"channel": "books", "instId": "BTC-USDT"}, "action": "update", "data": [{"asks": [["84185.9", "0.1425418", "0", "2"]], "bids": [["84076.6", "0.00420551", "0", "1"], ["84074.6", "0.23789302", "0", "1"], ["84020.8", "0.14282164", "0", "2"], ["83994.2", "0", "0", "0"], ["83973.8", "0.01188156", "0", "1"], ["83954.4", "0", "0", "0"]], "ts": "1742554946604", "checksum": -2025004800, "seqId": 49927363390, "prevSeqId": 49927363379}], "record_time": 1742554946.604894, "EXCHANGE": "OKX"}
{"arg": {"channel": "books", "instId": "BTC-USDT"}, "action": "update", "data": [{"asks": [["84133.3", "0.00101534", "0", "2"], ["84134.2", "0.23789099", "0", "1"], ["84265.8", "0", "0", "0"]], "bids": [["84110", "0.43878334", "0", "7"], ["84076.6", "0.2420965", "0", "2"], ["84074.6", "0", "0", "0"], ["83954.4", "0.35579296", "0", "1"]], "ts": "1742554946704", "checksum": 157651135, "seqId": 49927363396, "prevSeqId": 49927363390}], "record_time": 1742554946.708085, "EXCHANGE": "OKX"}
{"arg": {"channel": "books", "instId": "BTC-USDT"}, "action": "update", "data": [{"asks": [["84122.6", "0.005", "0", "1"], ["84125.5", "0", "0", "0"], ["84132.7", "0.0104", "0", "2"], ["84133.3", "0.23890806", "0", "3"], ["84134.2", "0", "0", "0"], ["84265.8", "0.00001156", "0", "1"]], "bids": [["84108.2", "0.005", "0", "1"], ["84098.7", "0", "0", "0"], ["84098.1", "0.40141581", "0", "3"], ["84076.6", "0.00420551", "0", "1"], ["84075.3", "0.23789272", "0", "1"], ["83954.4", "0", "0", "0"]], "ts": "1742554946804", "checksum": 213789372, "seqId": 49927363408, "prevSeqId": 49927363396}], "record_time": 1742554946.817843, "EXCHANGE": "OKX"}
{"arg": {"channel": "books", "instId": "BTC-USDT"}, "action": "update", "data": [{"asks": [["84120.4", "0.04918249", "0", "2"]], "bids": [["84092", "0.01189786", "0", "1"], ["83954.5", "0", "0", "0"]], "ts": "1742554946904", "checksum": -1758870864, "seqId": 49927363413, "prevSeqId": 49927363408}], "record_time": 1742554946.907769, "EXCHANGE": "OKX"}
{"arg": {"channel": "books", "instId": "BTC-USDT"}, "action": "update", "data": [{"asks": [["84125.5", "0.000042", "0", "1"], ["84133.3", "0.00101534", "0", "2"], ["84134.2", "0.23789171", "0", "1"], ["84265.1", "0", "0", "0"], ["84265.8", "0", "0", "0"]], "bids": [["84099", "0.0056625", "0", "1"], ["84097.5", "0.06742879", "0", "2"], ["84093.5", "0.00360124", "0", "1"], ["84078.9", "0.23789005", "0", "1"], ["84077", "1", "0", "1"], ["84075.3", "0", "0", "0"], ["83958.3", "0", "0", "0"], ["83955.9", "0", "0", "0"], ["83955", "0", "0", "0"]], "ts": "1742554947004", "checksum": -1758870864, "seqId": 49927363422, "prevSeqId": 49927363413}], "record_time": 1742554947.005617, "EXCHANGE": "OKX"}
{"arg": {"channel": "books", "instId": "BTC-USDT"}, "action": "update", "data": [{"asks": [["84134.2", "0", "0", "0"], ["84136.3", "0.23788971", "0", "1"]], "bids": [], "ts": "1742554947104", "checksum": -1758870864, "seqId": 49927363428, "prevSeqId": 49927363422}], "record_time": 1742554947.104908, "EXCHANGE": "OKX"}
{"arg": {"channel": "books", "instId": "BTC-USDT"}, "action": "update", "data": [{"asks": [["84131.7", "0", "0", "0"], ["84134.2", "0.23789001", "0", "1"], ["84136.3", "0", "0", "0"], ["84140.3", "1.24", "0", "1"], ["84141.8", "0.24967", "0", "1"], ["84149.9", "0.33280626", "0", "3"]], "bids": [["84110", "0.43579334", "0", "6"], ["84108.3", "0.01596287", "0", "1"], ["84087.2", "0.23137271", "0", "1"], ["84078.9", "0", "0", "0"], ["84077.1", "0.23789032", "0", "1"], ["84057.9", "0.32506203", "0", "1"], ["84032.6", "0.17587928", "0", "1"], ["84019.9", "0", "0", "0"], ["84011.9", "0", "0", "0"], ["83958.8", "0", "0", "0"]], "ts": "1742554947204", "checksum": 1227825811, "seqId": 49927363443, "prevSeqId": 49927363428}], "record_time": 1742554947.209661, "EXCHANGE": "OKX"}
{"arg": {"channel": "books", "instId": "BTC-USDT"}, "action": "update", "data": [{"asks": [["84122.6", "0.01", "0", "2"], ["84132.7", "0.0154", "0", "3"], ["84140.2", "0.01776036", "0", "2"], ["84143.2", "0", "0", "0"], ["84265.1", "0.00418989", "0", "1"]], "bids": [["84108.2", "0.01", "0", "2"], ["84098.1", "0.40641581", "0", "4"], ["84077.1", "0", "0", "0"], ["84075.3", "0.23789177", "0", "1"]], "ts": "1742554947304", "checksum": 178543941, "seqId": 49927363454, "prevSeqId": 49927363443}], "record_time": 1742554947.310436, "EXCHANGE": "OKX"}
{"arg": {"channel": "books", "instId": "BTC-USDT"}, "action": "update", "data": [{"asks": [], "bids": [["84077", "0", "0", "0"], ["83958.8", "0.00005335", "0", "1"]], "ts": "1742554947404", "checksum": 178543941, "seqId": 49927363457, "prevSeqId": 49927363454}], "record_time": 1742554947.407095, "EXCHANGE": "OKX"}
{"arg": {"channel": "books", "instId": "BTC-USDT"}, "action": "update", "data": [{"asks": [["84120.1", "0.0160491", "0", "2"], ["84125.5", "0", "0", "0"], ["84128.5", "0", "0", "0"], ["84130.2", "1.53433489", "0", "3"], ["84134.2", "0", "0", "0"], ["84136.4", "0.23788977", "0", "1"], ["84265.8", "0.00001156", "0", "1"], ["84266", "0.11878326", "0", "1"]], "bids": [["84110", "0.51398203", "0", "9"], ["84108.1", "0.03578", "0", "1"], ["84096.1", "0", "0", "0"], ["84093.5", "0", "0", "0"], ["84078.9", "0.23788977", "0", "1"], ["84075.3", "0", "0", "0"], ["83958.3", "0.00006061", "0", "1"]], "ts": "1742554947504", "checksum": -1438328517, "seqId": 49927363475, "prevSeqId": 49927363457}], "record_time": 1742554947.518632, "EXCHANGE": "OKX"}
{"arg": {"channel": "books", "instId": "BTC-USDT"}, "action": "update", "data": [{"asks": [["84123.2", "0.0044595", "0", "1"], ["84136.3", "0.23788969", "0", "1"], ["84136.4", "0", "0", "0"], ["84266", "0", "0", "0"]], "bids": [["84096.6", "0.62843133", "0", "1"], ["84096.5", "1", "0", "1"], ["84096.3", "0.17834", "0", "1"], ["84079.7", "0.23788969", "0", "1"], ["84078.9", "0", "0", "0"], ["83958.8", "0", "0", "0"], ["83958.3", "0", "0", "0"]], "ts": "1742554947604", "checksum": 1975217204, "seqId": 49927363491, "prevSeqId": 49927363475}], "record_time": 1742554947.623142, "EXCHANGE": "OKX"}
{"arg": {"channel": "books", "instId": "BTC-USDT"}, "action": "update", "data": [{"asks": [], "bids": [["84110", "0.51618203", "0", "10"], ["84099", "0", "0", "0"], ["84093.5", "0.00349233", "0", "1"]], "ts": "1742554947704", "checksum": 1031271939, "seqId": 49927363497, "prevSeqId": 49927363491}], "record_time": 1742554947.750992, "EXCHANGE": "OKX"}
{"arg": {"channel": "books", "instId": "BTC-USDT"}, "action": "update", "data": [{"asks": [["84136.3", "0", "0", "0"], ["84136.4", "0.23789036", "0", "1"], ["84148.8", "0.00151854", "0", "1"], ["84149.6", "0.07999999", "0", "2"], ["84150.4", "0.04576624", "0", "2"]], "bids": [["84108.1", "0.01893772", "0", "1"], ["84105", "0", "0", "0"], ["84079.7", "0", "0", "0"], ["84076.6", "0.24209587", "0", "2"], ["83958.8", "0.00005335", "0", "1"], ["83958.3", "0.00006061", "0", "1"]], "ts": "1742554947804", "checksum": 906740588, "seqId": 49927363511, "prevSeqId": 49927363497}], "record_time": 1742554947.838882, "EXCHANGE": "OKX"}
{"arg": {"channel": "books", "instId": "BTC-USDT"}, "action": "update", "data": [{"asks": [["84134.2", "0.2378917", "0", "1"], ["84136.4", "0", "0", "0"]], "bids": [["84110", "0.51741043", "0", "11"], ["84099.6", "0.0038025", "0", "1"], ["83958.3", "0", "0", "0"]], "ts": "1742554948004", "checksum": 777361870, "seqId": 49927363515, "prevSeqId": 49927363511}], "record_time": 1742554948.015186, "EXCHANGE": "OKX"}
{"arg": {"channel": "books", "instId": "BTC-USDT"}, "action": "update", "data": [{"asks": [["84110.1", "0.47564059", "0", "6"], ["84123.2", "0", "0", "0"], ["84176.8", "0", "0", "0"], ["84178", "0.01123701", "0", "1"], ["84194.6", "0.00001196", "0", "1"], ["84197.1", "0", "0", "0"], ["84233", "0.06012728", "0", "2"], ["84266", "0.11878326", "0", "1"], ["84266.2", "0.213955", "0", "1"]], "bids": [["84110", "0.52027918", "0", "13"], ["84099.6", "0", "0", "0"], ["84047.3", "0", "0", "0"], ["84037.6", "0.00600022", "0", "1"], ["83994.8", "0.2025", "0", "1"], ["83989.1", "0.18317686", "0", "1"], ["83987.8", "0.00007308", "0", "1"], ["83958.3", "0.00006061", "0", "1"]], "ts": "1742554948104", "checksum": 1667410283, "seqId": 49927363537, "prevSeqId": 49927363515}], "record_time": 1742554948.122066, "EXCHANGE": "OKX"}
{"arg": {"channel": "books", "instId": "BTC-USDT"}, "action": "update", "data": [{"asks": [["84133.3", "0.23890827", "0", "3"], ["84134.2", "0", "0", "0"], ["84138.8", "0.60836021", "0", "2"], ["84266.4", "0.00001402", "0", "1"]], "bids": [["84074.5", "0.16533174", "0", "2"], ["84047.4", "0", "0", "0"], ["84046.9", "0.00285148", "0", "1"], ["84037.4", "0.13711154", "0", "1"], ["84028.6", "0", "0", "0"], ["84019.1", "0.00235672", "0", "1"], ["84009.8", "0.01902088", "0", "1"], ["83967.1", "0.00359028", "0", "1"], ["83959.1", "0", "0", "0"], ["83958.8", "0", "0", "0"], ["83958.3", "0", "0", "0"]], "ts": "1742554948204", "checksum": 1667410283, "seqId": 49927363554, "prevSeqId": 49927363537}], "record_time": 1742554948.218502, "EXCHANGE": "OKX"}
{"arg": {"channel": "books", "instId": "BTC-USDT"}, "action": "update", "data": [{"asks": [["84110.1", "0.48150988", "0", "5"], ["84115.7", "0.00772797", "0", "1"], ["84119.5", "0.01055", "0", "1"], ["84120.8", "0.01603713", "0", "1"], ["84127.2", "0.0214385", "0", "2"], ["84133.3", "0.00101534", "0", "2"], ["84134.2", "0.2378927", "0", "1"], ["84138.7", "0.01774536", "0", "1"], ["84140.2", "0.000015", "0", "1"], ["84148.8", "0.08151854", "0", "3"], ["84149.6", "0.03999999", "0", "1"], ["84150.4", "0.00576625", "0", "1"], ["84266", "0", "0", "0"], ["84266.2", "0", "0", "0"], ["84266.4", "0", "0", "0"]], "bids": [["84110", "0.84420918", "0", "15"], ["84106.1", "0.01339", "0", "1"], ["84102.2", "0", "0", "0"]], "ts": "1742554948304", "checksum": 2050347420, "seqId": 49927363586, "prevSeqId": 49927363554}], "record_time": 1742554948.322881, "EXCHANGE": "OKX"}
{"arg": {"channel": "books", "instId": "BTC-USDT"}, "action": "update", "data": [{"asks": [["84110.1", "0.3597119", "0", "2"], ["84127.2", "0.01055", "0", "1"], ["84237", "0.01460551", "0", "2"], ["84239.9", "0.00118708", "0", "1"], ["84265.8", "0", "0", "0"]], "bids": [["84078", "1", "0", "1"], ["83959.8", "0", "0", "0"]], "ts": "1742554948404", "checksum": 1378495215, "seqId": 49927363598, "prevSeqId": 49927363586}], "record_time": 1742554948.415078, "EXCHANGE": "OKX"}
{"arg": {"channel": "books", "instId": "BTC-USDT"}, "action": "update", "data": [{"asks": [["84117.8", "0.21791116", "0", "1"], ["84117.9", "0.2", "0", "1"], ["84119.9", "0", "0", "0"], ["84126.5", "0.09817129", "0", "1"], ["84130.2", "0.53433489", "0", "2"], ["84131.9", "1", "0", "1"], ["84134.2", "0", "0", "0"], ["84136.4", "0.23789046", "0", "1"], ["84143.3", "0.27006173", "0", "1"], ["84146", "0", "0", "0"], ["84200.7", "0.0001964", "0", "1"], ["84218.7", "0.08228864", "0", "1"], ["84218.9", "0.001964", "0", "1"], ["84238.9", "0", "0", "0"], ["84264.9", "0", "0", "0"], ["84265.1", "0", "0", "0"]], "bids": [["84110", "0.84416181", "0", "15"], ["84076.7", "0.23789066", "0", "1"], ["84076.6", "0.00420551", "0", "1"], ["83959.9", "0", "0", "0"]], "ts": "1742554948504", "checksum": -871278395, "seqId": 49927363633, "prevSeqId": 49927363598}], "record_time": 1742554948.51316, "EXCHANGE": "OKX"}
{"arg": {"channel": "books", "instId": "BTC-USDT"}, "action": "update", "data": [{"asks": [["84127.8", "0.001107", "0", "1"], ["84136.4", "0.23789068", "0", "1"], ["84264.7", "0", "0", "0"]], "bids": [["84099.5", "0.0046245", "0", "1"], ["84078.9", "0.23789068", "0", "1"], ["84076.7", "0", "0", "0"], ["83960", "0", "0", "0"]], "ts": "1742554948604", "checksum": -871278395, "seqId": 49927363649, "prevSeqId": 49927363633}], "record_time": 1742554948.612487, "EXCHANGE": "OKX"}
{"arg": {"channel": "books", "instId": "BTC-USDT"}, "action": "update", "data": [{"asks": [["84110.1", "0.35900324", "0", "2"], ["84133.4", "0", "0", "0"], ["84134.2", "0.23789088", "0", "1"], ["84136.4", "0", "0", "0"], ["84264.7", "0.2025", "0", "1"]], "bids": [["84110", "0.84196181", "0", "14"], ["84078.9", "0", "0", "0"], ["84076.6", "0.24209639", "0", "2"], ["84074.4", "0.066", "0", "3"], ["84073.6", "0.013", "0", "1"]], "ts": "1742554948704", "checksum": -1414482222, "seqId": 49927363730, "prevSeqId": 49927363649}], "record_time": 1742554948.713327, "EXCHANGE": "OKX"}
{"arg": {"channel": "books", "instId": "BTC-USDT"}, "action": "update", "data": [{"asks": [["84127.6", "0", "0", "0"], ["84127.8", "0", "0", "0"], ["84130.2", "0.53790189", "0", "3"], ["84219.5", "0", "0", "0"], ["84229.3", "0", "0", "0"], ["84237", "0.00036", "0", "1"], ["84238.6", "0", "0", "0"], ["84239.9", "0", "0", "0"], ["84247.7", "0.2025", "0", "1"], ["84256.1", "0", "0", "0"], ["84264.9", "0.00031778", "0", "3"], ["84265.1", "0.00418989", "0", "1"], ["84265.8", "0.00001156", "0", "1"], ["84266", "0.11878326", "0", "1"], ["84266.2", "0.213955", "0", "1"], ["84266.4", "0.00001402", "0", "1"], ["84266.5", "0.00054835", "0", "1"]], "bids": [["84099.5", "0", "0", "0"], ["84018.8", "0.0058", "0", "1"], ["84012.3", "0.0058", "0", "1"], ["84010.5", "0", "0", "0"], ["84005.9", "0.02340022", "0", "4"], ["84001.9", "0", "0", "0"], ["83993.5", "0", "0", "0"], ["83985.1", "0", "0", "0"], ["83976.7", "0", "0", "0"], ["83960", "0.01798541", "0", "3"], ["83959.9", "0.00001022", "0", "1"], ["83959.8", "0.00421771", "0", "1"], ["83959.1", "0.00001009", "0", "1"]], "ts": "1742554948804", "checksum": -1414482222, "seqId": 49927363750, "prevSeqId": 49927363730}], "record_time": 1742554948.817546, "EXCHANGE": "OKX"}
{"arg": {"channel": "books", "instId": "BTC-USDT"}, "action": "update", "data": [{"asks": [["84118.7", "0", "0", "0"], ["84127.8", "0.000021", "0", "1"], ["84133.1", "0.0103941", "0", "1"], ["84266.5", "0", "0", "0"]], "bids": [["84099.5", "0.000654", "0", "1"], ["83959.1", "0", "0", "0"]], "ts": "1742554948904", "checksum": 1845638841, "seqId": 49927363760, "prevSeqId": 49927363750}], "record_time": 1742554948.9108, "EXCHANGE": "OKX"}
{"arg": {"channel": "books", "instId": "BTC-USDT"}, "action": "update", "data": [{"asks": [["84130.6", "1", "0", "1"], ["84131.9", "0", "0", "0"], ["84208.1", "0.0142504", "0", "1"], ["84211", "0.00118749", "0", "1"], ["84266.2", "0", "0", "0"], ["84266.4", "0", "0", "0"]], "bids": [], "ts": "1742554949004", "checksum": 1845638841, "seqId": 49927363765, "prevSeqId": 49927363760}], "record_time": 1742554949.017005, "EXCHANGE": "OKX"}
{"arg": {"channel": "books", "instId": "BTC-USDT"}, "action": "update", "data": [{"asks": [["84130.2", "0.53433489", "0", "2"], ["84149.4", "0.003567", "0", "1"], ["84185.9", "0.0712709", "0", "1"], ["84266", "0", "0", "0"]], "bids": [["84097.8", "1", "0", "1"], ["84096.5", "0", "0", "0"], ["84020.8", "0.07141082", "0", "1"]], "ts": "1742554949104", "checksum": 1845638841, "seqId": 49927363775, "prevSeqId": 49927363765}], "record_time": 1742554949.108485, "EXCHANGE": "OKX"}
{"arg": {"channel": "books", "instId": "BTC-USDT"}, "action": "update", "data": [{"asks": [["84134.2", "0", "0", "0"], ["84136.4", "0.23789113", "0", "1"], ["84143.3", "0.72910488", "0", "2"], ["84145", "0.00001197", "0", "1"], ["84185.9", "0.1425418", "0", "2"]], "bids": [["84110", "0.84407181", "0", "15"], ["84100.8", "0.57953709", "0", "2"], ["84096.6", "0.38298103", "0", "1"], ["84078", "0", "0", "0"], ["84076.7", "0.23789112", "0", "1"], ["84076.6", "0.00420551", "0", "1"], ["84062.6", "0.37108248", "0", "3"], ["84020.8", "0.14282164", "0", "2"]], "ts": "1742554949204", "checksum": 1751442802, "seqId": 49927363806, "prevSeqId": 49927363775}], "record_time": 1742554949.217848, "EXCHANGE": "OKX"}
{"arg": {"channel": "books", "instId": "BTC-USDT"}, "action": "update", "data": [{"asks": [["84110.1", "0", "0", "0"], ["84111.3", "0", "0", "0"], ["84111.4", "0.15914702", "0", "3"], ["84112", "0", "0", "0"], ["84115.7", "0", "0", "0"], ["84116.9", "0.00772775", "0", "1"], ["84117.8", "0.1318487", "0", "2"], ["84117.9", "0", "0", "0"], ["84119.5", "0", "0", "0"], ["84119.9", "0.2025", "0", "1"], ["84120.1", "0.00001197", "0", "1"], ["84120.7", "0", "0", "0"], ["84120.8", "0", "0", "0"], ["84122", "0.02515", "0", "2"], ["84122.7", "0.22527817", "0", "1"], ["84123.3", "0", "0", "0"], ["84123.6", "0", "0", "0"], ["84123.7", "0", "0", "0"], ["84123.9", "0", "0", "0"], ["84124.1", "0.05103794", "0", "2"], ["84125", "0.00772797", "0", "1"], ["84126.2", "0.03070715", "0", "1"], ["84126.3", "0.03275737", "0", "1"], ["84126.4", "0.03462866", "0", "1"], ["84126.5", "0.13868837", "0", "2"], ["84126.8", "0.0334263", "0", "1"], ["84128.3", "0.03165", "0", "1"], ["84130.2", "0.50099515", "0", "1"], ["84130.3", "0.30604543", "0", "2"], ["84130.6", "0.11891999", "0", "1"], ["84132.4", "0", "0", "0"], ["84132.5", "0", "0", "0"], ["84133.1", "0.04464739", "0", "2"], ["84133.4", "0.03401388", "0", "1"], ["84134.9", "0.03408501", "0", "1"], ["84135", "0.03353225", "0", "2"], ["84136.4", "0", "0", "0"], ["84136.7", "0.23788135", "0", "1"], ["84137.3", "0", "0", "0"], ["84139.1", "0", "0", "0"], ["84139.7", "0.011", "0", "1"], ["84140.4", "0.06881731", "0", "1"], ["84141.2", "0.00011161", "0", "1"], ["84141.7", "0.19637699", "0", "2"], ["84142.6", "0.06769032", "0", "2"], ["84142.9", "0", "0", "0"], ["84143.7", "0.12624492", "0", "2"], ["84148.8", "0.00151854", "0", "1"], ["84149.6", "0.07999999", "0", "2"], ["84150.4", "0.04576624", "0", "2"], ["84154.7", "0", "0", "0"], ["84219", "0.01188163", "0", "1"], ["84219.1", "0.01188161", "0", "1"], ["84266", "0.11878326", "0", "1"], ["84266.2", "0.213955", "0", "1"], ["84266.4", "0.00001402", "0", "1"], ["84266.5", "0.00054835", "0", "1"], ["84266.6", "0.01217191", "0", "13"], ["84266.7", "0.00002129", "0", "1"]], "bids": [["84111.3", "0.39596973", "0", "5"], ["84111.2", "0.37273723", "0", "5"], ["84110.1", "0.35641581", "0", "1"], ["84110", "0.22322705", "0", "6"], ["84108.1", "0", "0", "0"], ["84106.1", "0", "0", "0"], ["84105.7", "0.00772775", "0", "1"], ["84105.3", "0.00001197", "0", "1"], ["84102.2", "0.04018", "0", "1"], ["84100", "1.25447287", "0", "5"], ["84099.5", "0.11896382", "0", "1"], ["84099.1", "0.03440306", "0", "1"], ["84098.2", "0.03371798", "0", "1"], ["84097.8", "0", "0", "0"], ["84097.6", "0.03420677", "0", "1"], ["84097.5", "0.02724879", "0", "1"], ["84097.4", "0.03215719", "0", "1"], ["84097.1", "0", "0", "0"], ["84096", "0.195", "0", "4"], ["84095.7", "0.1403523", "0", "1"], ["84095.2", "0", "0", "0"], ["84095", "0", "0", "0"], ["84094.5", "0.11228184", "0", "2"], ["84092.1", "0.03404033", "0", "1"], ["84091.4", "0.08991011", "0", "1"], ["84091.3", "0.00475673", "0", "1"], ["84091.1", "0.0354599", "0", "1"], ["84089.4", "0.03068485", "0", "1"], ["84089", "0", "0", "0"], ["84088.8", "0.03132243", "0", "1"], ["84088.2", "0", "0", "0"], ["84086.9", "0", "0", "0"], ["84086.3", "0", "0", "0"], ["84082.7", "0.23788135", "0", "1"], ["84082.2", "0.06949143", "0", "1"], ["84082", "0", "0", "0"], ["84081.7", "0.06915948", "0", "1"], ["84081.4", "0", "0", "0"], ["84080.7", "0.06659317", "0", "1"], ["84079.6", "0", "0", "0"], ["84078.8", "0.24967", "0", "1"], ["84078.2", "0.23018009", "0", "3"], ["84076.7", "0", "0", "0"], ["84069.6", "0.05427", "0", "1"], ["84060.2", "0.02204823", "0", "2"], ["84059.9", "0.02745264", "0", "1"], ["84059.7", "0", "0", "0"], ["84057.7", "0.0054", "0", "1"], ["84045.8", "0.20672021", "0", "3"], ["84040.1", "0", "0", "0"], ["84035.5", "0", "0", "0"], ["84034.2", "0.0054", "0", "1"], ["84033.8", "0.01609165", "0", "2"], ["84030.7", "0.01188151", "0", "1"], ["84018", "0", "0", "0"], ["84012.4", "0", "0", "0"], ["84008.1", "0.01188163", "0", "1"], ["83987.5", "0.02376324", "0", "2"], ["83982.6", "0.19500277", "0", "2"], ["83975.3", "0.0054", "0", "1"], ["83961.5", "0", "0", "0"], ["83961", "0", "0", "0"], ["83960.9", "0", "0", "0"], ["83960.8", "0", "0", "0"], ["83960", "0", "0", "0"], ["83959.9", "0", "0", "0"], ["83959.8", "0", "0", "0"]], "ts": "1742554949304", "checksum": 129148675, "seqId": 49927364123, "prevSeqId": 49927363806}], "record_time": 1742554949.307197, "EXCHANGE": "OKX"}
{"arg": {"channel": "books", "instId": "BTC-USDT"}, "action": "update", "data": [{"asks": [["84114", "0.0146", "0", "1"], ["84116.5", "0", "0", "0"], ["84125.9", "0.38978564", "0", "2"], ["84126", "0.04805834", "0", "2"], ["84126.2", "0", "0", "0"], ["84126.3", "0.03141542", "0", "1"], ["84126.4", "0", "0", "0"], ["84126.6", "0.21293447", "0", "2"], ["84126.8", "0", "0", "0"], ["84128.3", "0.03514447", "0", "2"], ["84132.9", "0.03143079", "0", "1"], ["84133.1", "0.0103941", "0", "1"], ["84133.3", "0.03408363", "0", "3"], ["84133.4", "0", "0", "0"], ["84134.7", "0.03147404", "0", "1"], ["84134.8", "0.03234118", "0", "1"], ["84134.9", "0", "0", "0"], ["84135", "1.00001197", "0", "2"], ["84136.7", "0", "0", "0"], ["84138.7", "0.25562785", "0", "2"], ["84140.3", "1.30242994", "0", "2"], ["84140.4", "0", "0", "0"], ["84141.4", "0.06878721", "0", "1"], ["84141.7", "0.133767", "0", "1"], ["84142.3", "0.07641692", "0", "3"], ["84142.6", "0.00420121", "0", "1"], ["84143.4", "0.42152942", "0", "2"], ["84143.7", "0.059898", "0", "1"], ["84190.7", "0", "0", "0"], ["84192.4", "0.00012217", "0", "1"], ["84266.9", "0.00013853", "0", "2"], ["84267.3", "0.35615346", "0", "2"], ["84268.4", "0.00001026", "0", "1"], ["84268.5", "0.00002533", "0", "1"]], "bids": [["84111.3", "0.77880834", "0", "10"], ["84100.7", "0.001335", "0", "1"], ["84100", "0.25447287", "0", "4"], ["84099.1", "0", "0", "0"], ["84099", "0.03137515", "0", "1"], ["84098.6", "1", "0", "1"], ["84098.2", "0", "0", "0"], ["84097.9", "0.04663208", "0", "2"], ["84097.6", "0", "0", "0"], ["84097.4", "0", "0", "0"], ["84097.3", "0.0351614", "0", "1"], ["84097.2", "0.03202238", "0", "1"], ["84092.1", "0", "0", "0"], ["84092", "0.04362875", "0", "2"], ["84091.1", "0", "0", "0"], ["84090.9", "0.0354364", "0", "1"], ["84089.4", "0", "0", "0"], ["84089.2", "0.0319642", "0", "1"], ["84088.8", "0", "0", "0"], ["84088.6", "0.03327705", "0", "1"], ["84085", "0.06128206", "0", "1"], ["84082.8", "0.01774536", "0", "1"], ["84082.7", "0", "0", "0"], ["84082.6", "0.48248573", "0", "1"], ["84082.2", "0", "0", "0"], ["84081.9", "0.06455749", "0", "1"], ["84081.7", "0", "0", "0"], ["84081.4", "0.06971309", "0", "1"], ["84080.7", "0", "0", "0"], ["84080.4", "0.06734675", "0", "1"], ["84078.9", "0.23788264", "0", "1"], ["84061.4", "0.45641581", "0", "2"], ["84048.8", "0.00885167", "0", "2"], ["84046.9", "0", "0", "0"], ["84045.2", "0.00105115", "0", "1"], ["84043.1", "0", "0", "0"], ["83980.1", "0.00201123", "0", "1"], ["83978.3", "0", "0", "0"], ["83961.6", "0", "0", "0"]], "ts": "1742554949404", "checksum": -1145666761, "seqId": 49927364324, "prevSeqId": 49927364123}], "record_time": 1742554949.411848, "EXCHANGE": "OKX"}
{"arg": {"channel": "books", "instId": "BTC-USDT"}, "action": "update", "data": [{"asks": [["84111.4", "0.12204702", "0", "2"], ["84117.6", "0.20200565", "0", "1"], ["84117.7", "0.2", "0", "1"], ["84117.8", "0", "0", "0"], ["84122.6", "0.0397729", "0", "3"], ["84125.9", "0.35668", "0", "1"], ["84126", "0.0146", "0", "1"], ["84126.3", "0", "0", "0"], ["84126.4", "0.03500266", "0", "1"], ["84126.5", "0.30666778", "0", "3"], ["84126.6", "0.17834", "0", "1"], ["84126.9", "0.03177674", "0", "1"], ["84128.4", "0.35667", "0", "1"], ["84132.9", "0", "0", "0"], ["84133.3", "0.00101534", "0", "2"], ["84133.5", "0.03176982", "0", "1"], ["84134.7", "0", "0", "0"], ["84134.8", "0", "0", "0"], ["84135.1", "0.03083473", "0", "1"], ["84135.2", "0.03402411", "0", "1"], ["84140.3", "1.24", "0", "1"], ["84140.5", "0.06129555", "0", "1"], ["84141.4", "0", "0", "0"], ["84141.9", "0.06185307", "0", "1"], ["84142.3", "0.00557", "0", "2"], ["84142.7", "0.06393563", "0", "1"], ["84143.4", "0.35641581", "0", "1"], ["84143.9", "0.06239437", "0", "1"], ["84149.4", "0", "0", "0"], ["84150", "1.2", "0", "2"], ["84156", "0.1", "0", "1"], ["84169.4", "0.01188185", "0", "1"], ["84206.9", "3.51787", "0", "1"], ["84216.4", "0.01188163", "0", "1"], ["84266.4", "0", "0", "0"], ["84266.5", "0", "0", "0"], ["84266.6", "0", "0", "0"], ["84266.7", "0", "0", "0"], ["84266.9", "0", "0", "0"], ["84267.3", "0", "0", "0"], ["84268.4", "0", "0", "0"], ["84268.5", "0", "0", "0"]], "bids": [["84111.3", "0.65570577", "0", "9"], ["84110.2", "0.01339", "0", "1"], ["84099.2", "0.03417053", "0", "1"], ["84099", "0", "0", "0"], ["84098.4", "0.06890665", "0", "2"], ["84097.9", "0.01339", "0", "1"], ["84097.8", "0.03355546", "0", "1"], ["84097.5", "0.05955125", "0", "2"], ["84097.3", "0", "0", "0"], ["84097.2", "0", "0", "0"], ["84092.2", "0.0346183", "0", "1"], ["84092", "0.01189786", "0", "1"], ["84090.9", "0", "0", "0"], ["84089.2", "0", "0", "0"], ["84089", "0.03091486", "0", "1"], ["84088.6", "0", "0", "0"], ["84085.2", "0.06733242", "0", "1"], ["84085", "0", "0", "0"], ["84082.4", "0.06469501", "0", "1"], ["84081.9", "0", "0", "0"], ["84081.8", "0.06502045", "0", "1"], ["84081.4", "0", "0", "0"], ["84080.4", "0", "0", "0"], ["84066", "0.2", "0", "1"], ["84061.4", "0.35641581", "0", "1"], ["84030.8", "0.01188174", "0", "1"], ["84019.1", "0", "0", "0"], ["84009.8", "0", "0", "0"], ["83989", "0", "0", "0"], ["83987.5", "0.01188174", "0", "1"], ["83967.1", "0", "0", "0"], ["83961.6", "0.00001197", "0", "1"], ["83961.5", "0.00083", "0", "1"], ["83961", "0.01782134", "0", "1"], ["83960.9", "0.00083", "0", "1"]], "ts": "1742554949504", "checksum": 1414310980, "seqId": 49927364443, "prevSeqId": 49927364324}], "record_time": 1742554949.525599, "EXCHANGE": "OKX"}
{"arg": {"channel": "books", "instId": "BTC-USDT"}, "action": "update", "data": [{"asks": [["84111.4", "0.15914702", "0", "3"], ["84111.9", "0.01657722", "0", "2"], ["84112", "0.0146", "0", "1"], ["84122.7", "0.31429799", "0", "2"], ["84125.6", "0.03135273", "0", "1"], ["84125.7", "0.0311727", "0", "1"], ["84125.8", "0.35641581", "0", "1"], ["84126", "0.04532881", "0", "2"], ["84126.3", "0.03354359", "0", "1"], ["84126.4", "0", "0", "0"], ["84126.5", "0.14198023", "0", "1"], ["84126.9", "0", "0", "0"], ["84128.4", "0", "0", "0"], ["84132.6", "0.03709727", "0", "2"], ["84133", "0.03381725", "0", "1"], ["84133.5", "0", "0", "0"], ["84134.3", "0.38791464", "0", "2"], ["84134.4", "0.33023354", "0", "3"], ["84135.1", "0", "0", "0"], ["84135.2", "0", "0", "0"], ["84140", "0.06543138", "0", "4"], ["84140.5", "0", "0", "0"], ["84141.1", "0.06401823", "0", "1"], ["84141.9", "0", "0", "0"], ["84142", "0.06818328", "0", "1"], ["84142.7", "0", "0", "0"], ["84143.1", "0.06175827", "0", "1"], ["84143.9", "0", "0", "0"], ["84148.8", "0.08151854", "0", "3"], ["84149.6", "0.03999999", "0", "1"], ["84150.4", "0.00576625", "0", "1"], ["84164.1", "0.01188156", "0", "1"], ["84166", "0", "0", "0"], ["84248.3", "0.04188156", "0", "2"], ["84254.5", "0.00001063", "0", "1"], ["84266.4", "0.00001402", "0", "1"]], "bids": [["84111.2", "0.36265812", "0", "6"], ["84099.2", "0", "0", "0"], ["84098.7", "0.03199423", "0", "1"], ["84098.4", "0.03713992", "0", "1"], ["84097.8", "0", "0", "0"], ["84097.6", "0.0307431", "0", "1"], ["84097.5", "0.02724879", "0", "1"], ["84097", "0.03513084", "0", "1"], ["84096.9", "0.03464055", "0", "1"], ["84092.2", "0", "0", "0"], ["84091.7", "0.03219133", "0", "1"], ["84089", "0", "0", "0"], ["84088.2", "0.03360866", "0", "1"], ["84085.2", "0", "0", "0"], ["84084.7", "0.06639639", "0", "2"], ["84082.8", "0", "0", "0"], ["84082.7", "0.01774536", "0", "1"], ["84082.4", "0", "0", "0"], ["84081.8", "0", "0", "0"], ["84081.6", "0.06279506", "0", "1"], ["84081.1", "0.06204098", "0", "1"], ["84072", "0.1025", "0", "3"], ["84071.2", "0.40787758", "0", "2"], ["84070.4", "0", "0", "0"], ["84061.5", "0.1", "0", "1"], ["84059.8", "0", "0", "0"], ["84057.9", "0.33694359", "0", "2"], ["84034.1", "0.00237112", "0", "2"], ["84024.8", "0.01901749", "0", "1"], ["83982.1", "0.00358964", "0", "1"], ["83961", "0", "0", "0"], ["83960.9", "0", "0", "0"]], "ts": "1742554949604", "checksum": -2033166333, "seqId": 49927364576, "prevSeqId": 49927364443}], "record_time": 1742554949.641888, "EXCHANGE": "OKX"}
{"arg": {"channel": "books", "instId": "BTC-USDT"}, "action": "update", "data": [{"asks": [["84111.4", "0.12204702", "0", "2"], ["84111.9", "0.00111889", "0", "1"], ["84112", "0", "0", "0"], ["84114", "0", "0", "0"], ["84117.6", "0.1318487", "0", "2"], ["84117.7", "0", "0", "0"], ["84119.9", "0", "0", "0"], ["84125.6", "0", "0", "0"], ["84125.7", "0", "0", "0"], ["84126", "0.0146", "0", "1"], ["84126.3", "0", "0", "0"], ["84126.5", "0.17262143", "0", "2"], ["84126.6", "0.21265307", "0", "2"], ["84128.3", "0.03165", "0", "1"], ["84132.6", "0.00420263", "0", "1"], ["84133", "0", "0", "0"], ["84134.3", "0.35641581", "0", "1"], ["84134.4", "0.29713182", "0", "2"], ["84135.3", "0.03257262", "0", "1"], ["84140", "0.00006696", "0", "3"], ["84141.1", "0", "0", "0"], ["84142", "0.06292871", "0", "1"], ["84143.1", "0", "0", "0"], ["84143.3", "0.27006173", "0", "1"], ["84144", "0.06933872", "0", "1"], ["84145.5", "0", "0", "0"], ["84150", "0", "0", "0"], ["84155.4", "0.13363749", "0", "1"], ["84158.2", "0", "0", "0"], ["84220.2", "0.00298666", "0", "1"], ["84229.2", "0.00597332", "0", "1"], ["84238.8", "0.00895999", "0", "1"], ["84247.2", "0.01348426", "0", "3"], ["84255.6", "0.01493332", "0", "1"], ["84266.5", "0.00054835", "0", "1"], ["84266.6", "0.01217191", "0", "13"], ["84266.7", "0.00002129", "0", "1"], ["84266.9", "0.00013853", "0", "2"], ["84267.3", "0.35615346", "0", "2"], ["84268.4", "0.00001026", "0", "1"], ["84268.5", "0.00002533", "0", "1"]], "bids": [["84111.3", "0.65571577", "0", "10"], ["84098.7", "0", "0", "0"], ["84098.6", "0", "0", "0"], ["84098.5", "1.03195472", "0", "2"], ["84097.9", "0.04557906", "0", "2"], ["84097.6", "0", "0", "0"], ["84097", "0", "0", "0"], ["84096.9", "0", "0", "0"], ["84091.7", "0", "0", "0"], ["84091.5", "0.03482753", "0", "1"], ["84089.8", "0.04659169", "0", "2"], ["84088.2", "0", "0", "0"], ["84084.7", "0.00420528", "0", "1"], ["84082.6", "0", "0", "0"], ["84082.5", "0.06940393", "0", "1"], ["84081.6", "0", "0", "0"], ["84081.1", "0", "0", "0"], ["84081", "0.06841601", "0", "1"], ["84072", "0.0025", "0", "1"], ["84071.2", "0.45787758", "0", "3"], ["84070.4", "0.05", "0", "1"], ["84066", "0", "0", "0"], ["84053.3", "0.18669947", "0", "1"], ["84053.1", "0.02380588", "0", "1"], ["84019.9", "0.60646061", "0", "1"], ["84011.4", "0.06718666", "0", "4"], ["84000.1", "0.00597332", "0", "1"], ["83991.3", "0.00897195", "0", "2"], ["83982.9", "0.01194665", "0", "1"], ["83974.5", "0.01493332", "0", "1"], ["83961", "0.01782134", "0", "1"], ["83960.9", "0.00083", "0", "1"], ["83960.8", "0.2025", "0", "1"]], "ts": "1742554949704", "checksum": 1220251091, "seqId": 49927364692, "prevSeqId": 49927364576}], "record_time": 1742554949.704389, "EXCHANGE": "OKX"}
{"arg": {"channel": "books", "instId": "BTC-USDT"}, "action": "update", "data": [{"asks": [["84111.4", "0.11894702", "0", "1"], ["84114", "0.0146", "0", "1"], ["84117.6", "0.08125565", "0", "1"], ["84118.8", "0", "0", "0"], ["84122.7", "0.22527817", "0", "1"], ["84122.8", "0.07854779", "0", "2"], ["84125.8", "0", "0", "0"], ["84126.4", "0.03111176", "0", "1"], ["84126.5", "0.2934664", "0", "3"], ["84126.6", "0.17834", "0", "1"], ["84126.8", "0.03379693", "0", "1"], ["84127.1", "0.03458799", "0", "1"], ["84128.4", "0.35667", "0", "1"], ["84133.4", "0.03526534", "0", "1"], ["84133.8", "0.03414887", "0", "1"], ["84135", "0.00001197", "0", "1"], ["84135.3", "0", "0", "0"], ["84135.9", "1", "0", "1"], ["84136.4", "0.23788727", "0", "1"], ["84138.7", "0", "0", "0"], ["84140.3", "1.60340107", "0", "1"], ["84140.8", "0.06482721", "0", "1"], ["84141.9", "0.06534329", "0", "1"], ["84142", "0", "0", "0"], ["84143.9", "0.06497018", "0", "1"], ["84144", "0", "0", "0"], ["84148.8", "0.00151854", "0", "1"], ["84149.6", "0.07999999", "0", "2"], ["84150.4", "0.04576624", "0", "2"], ["84168.4", "1.5006613", "0", "2"], ["84169.7", "2.86190078", "0", "1"], ["84199.1", "0.01774536", "0", "1"], ["84266.4", "0", "0", "0"], ["84266.5", "0", "0", "0"], ["84266.6", "0", "0", "0"], ["84266.7", "0", "0", "0"], ["84266.9", "0", "0", "0"], ["84267.3", "0", "0", "0"], ["84268.4", "0", "0", "0"], ["84268.5", "0", "0", "0"]], "bids": [["84106.5", "0.03854779", "0", "1"], ["84102.3", "0", "0", "0"], ["84101.8", "0.002856", "0", "1"], ["84100.7", "0", "0", "0"], ["84099.5", "0.15091783", "0", "2"], ["84098.5", "1", "0", "1"], ["84098.4", "0.06831368", "0", "2"], ["84097.9", "0.01339", "0", "1"], ["84097.8", "0.03366845", "0", "1"], ["84097.7", "0.03404268", "0", "1"], ["84092.5", "0.03438307", "0", "1"], ["84091.5", "0", "0", "0"], ["84091.4", "0.12536448", "0", "2"], ["84089.8", "0.01596287", "0", "1"], ["84087.2", "0.67077136", "0", "2"], ["84085.7", "1.77779217", "0", "3"], ["84085.5", "0.06626121", "0", "2"], ["84082.7", "0", "0", "0"], ["84082.5", "0", "0", "0"], ["84082.4", "0.06425195", "0", "1"], ["84081", "0", "0", "0"], ["84080.9", "0.0691217", "0", "1"], ["84079", "0.01774536", "0", "1"], ["84078.9", "0.23788632", "0", "1"], ["84056.2", "3.32710935", "0", "2"], ["83960.9", "0", "0", "0"], ["83960.8", "0", "0", "0"]], "ts": "1742554949804", "checksum": -533220755, "seqId": 49927364842, "prevSeqId": 49927364692}], "record_time": 1742554949.806473, "EXCHANGE": "OKX"}
{"arg": {"channel": "books", "instId": "BTC-USDT"}, "action": "update", "data": [{"asks": [["84111.4", "0.15914702", "0", "3"], ["84117.6", "0.12028436", "0", "2"], ["84119.9", "0.2025", "0", "1"], ["84125.9", "0.39003207", "0", "2"], ["84126", "0.04796731", "0", "2"], ["84126.2", "0.03422553", "0", "1"], ["84126.4", "0", "0", "0"], ["84126.5", "0.29191168", "0", "3"], ["84126.8", "0", "0", "0"], ["84127.1", "0", "0", "0"], ["84132.8", "0.03118417", "0", "1"], ["84133.2", "0.03405316", "0", "1"], ["84133.4", "0", "0", "0"], ["84133.8", "0", "0", "0"], ["84134.7", "0.03451346", "0", "1"], ["84140.2", "0.06462796", "0", "2"], ["84140.8", "0", "0", "0"], ["84141.4", "0.06217464", "0", "1"], ["84141.9", "0", "0", "0"], ["84143.4", "0.42085009", "0", "2"], ["84143.9", "0", "0", "0"], ["84266.4", "0.00001402", "0", "1"], ["84266.5", "0.00054835", "0", "1"]], "bids": [["84101.8", "0", "0", "0"], ["84099.5", "0.11896382", "0", "1"], ["84098.9", "0.03178558", "0", "1"], ["84098.4", "0.03713992", "0", "1"], ["84097.9", "0.04803122", "0", "2"], ["84097.8", "0", "0", "0"], ["84097.7", "0", "0", "0"], ["84097.3", "0.03288354", "0", "1"], ["84097.1", "0.0345556", "0", "1"], ["84092.5", "0", "0", "0"], ["84091.9", "0.22204894", "0", "2"], ["84091.4", "0.08991011", "0", "1"], ["84090.8", "0.03332161", "0", "1"], ["84088.5", "0.05729148", "0", "2"], ["84085.5", "0.00001197", "0", "1"], ["84084.9", "0.0613477", "0", "1"], ["84082.4", "0", "0", "0"], ["84081.9", "0.06970322", "0", "1"], ["84080.9", "0", "0", "0"]], "ts": "1742554949904", "checksum": -2027418145, "seqId": 49927364927, "prevSeqId": 49927364842}], "record_time": 1742554949.928885, "EXCHANGE": "OKX"}
{"arg": {"channel": "books", "instId": "BTC-USDT"}, "action": "update", "data": [{"asks": [["84122.7", "0.32482329", "0", "2"], ["84125.8", "0.35641581", "0", "1"], ["84134.5", "1", "0", "1"], ["84134.7", "0.06703776", "0", "2"], ["84135.9", "0", "0", "0"], ["84142.3", "0.07227357", "0", "3"], ["84266.5", "0", "0", "0"]], "bids": [["84089.2", "0.03509846", "0", "1"], ["84081.4", "0.06534781", "0", "1"], ["84080.4", "0.06813937", "0", "1"], ["83961.6", "0", "0", "0"], ["83961.5", "0", "0", "0"], ["83961", "0", "0", "0"]], "ts": "1742554950004", "checksum": -1438725525, "seqId": 49927364939, "prevSeqId": 49927364927}], "record_time": 1742554950.031486, "EXCHANGE": "OKX"}
{"arg": {"channel": "books", "instId": "BTC-USDT"}, "action": "update", "data": [{"asks": [["84125.9", "0.38795094", "0", "2"], ["84126", "0.04565024", "0", "2"], ["84126.2", "0.03375959", "0", "1"], ["84126.5", "0.29519431", "0", "3"], ["84132.8", "0.03328161", "0", "1"], ["84133.2", "0.03500214", "0", "1"], ["84134.7", "0.06436717", "0", "2"], ["84136.4", "0", "0", "0"], ["84136.7", "0.23788568", "0", "1"], ["84138.7", "0.01774536", "0", "1"], ["84140.2", "0.06756684", "0", "2"], ["84141.4", "0.07078193", "0", "1"], ["84142.3", "0.07585569", "0", "3"], ["84143.4", "0.42553522", "0", "2"], ["84148.8", "0.08151854", "0", "3"], ["84149.6", "0.03999999", "0", "1"], ["84150.4", "0.00576625", "0", "1"], ["84164.2", "0.24217784", "0", "1"], ["84166.5", "0.00004312", "0", "1"], ["84199.1", "0", "0", "0"], ["84266.4", "0", "0", "0"]], "bids": [["84101.5", "0.0057916", "0", "2"], ["84098.9", "0.03275168", "0", "1"], ["84097.9", "0.04631693", "0", "2"], ["84097.3", "0.03356633", "0", "1"], ["84097.1", "0.03459542", "0", "1"], ["84091.9", "0.22097931", "0", "2"], ["84090.8", "0.03175845", "0", "1"], ["84089.2", "0.03148832", "0", "1"], ["84088.5", "0.0546287", "0", "2"], ["84084.9", "0.06389775", "0", "1"], ["84081.9", "0.0680147", "0", "1"], ["84081.4", "0.06893473", "0", "1"], ["84080.5", "0.23789761", "0", "2"], ["84080.4", "0.06133424", "0", "1"], ["84078.9", "0", "0", "0"], ["84060.8", "0.01831701", "0", "1"], ["84060.3", "0", "0", "0"], ["84021.8", "0.00016272", "0", "1"], ["84020.4", "0", "0", "0"], ["83989.1", "0", "0", "0"], ["83987.8", "0.18324172", "0", "2"], ["83961.6", "0.00001197", "0", "1"], ["83961.5", "0.00083", "0", "1"]], "ts": "1742554950104", "checksum": -258740231, "seqId": 49927365054, "prevSeqId": 49927364939}], "record_time": 1742554950.114407, "EXCHANGE": "OKX"}
{"arg": {"channel": "books", "instId": "BTC-USDT"}, "action": "update", "data": [{"asks": [["84136.4", "0.23788644", "0", "1"], ["84136.7", "0", "0", "0"]], "bids": [["84110", "0.22111705", "0", "5"], ["84098.5", "0", "0", "0"], ["84097.2", "1", "0", "1"], ["84080.5", "0.00001197", "0", "1"], ["84079", "0", "0", "0"], ["84078.9", "0.2556318", "0", "2"]], "ts": "1742554950204", "checksum": 126529259, "seqId": 49927365075, "prevSeqId": 49927365054}], "record_time": 1742554950.204609, "EXCHANGE": "OKX"}
{"arg": {"channel": "books", "instId": "BTC-USDT"}, "action": "update", "data": [{"asks": [["84134.4", "0.74732305", "0", "3"], ["84146.1", "0", "0", "0"], ["84266.4", "0.00001402", "0", "1"]], "bids": [["84083.8", "0.13871482", "0", "1"], ["84079.3", "0", "0", "0"], ["84079", "1", "0", "1"], ["84057.9", "1.11617085", "0", "3"], ["83961.5", "0", "0", "0"]], "ts": "1742554950304", "checksum": 126529259, "seqId": 49927365087, "prevSeqId": 49927365075}], "record_time": 1742554950.310323, "EXCHANGE": "OKX"}
{"arg": {"channel": "books", "instId": "BTC-USDT"}, "action": "update", "data": [{"asks": [["84111.4", "0.12204702", "0", "2"], ["84122.7", "0.22527817", "0", "1"], ["84125.3", "0.01603713", "0", "1"], ["84125.8", "0", "0", "0"], ["84125.9", "0.35668", "0", "1"], ["84126", "0.0146", "0", "1"], ["84126.2", "0", "0", "0"], ["84126.4", "0.03127338", "0", "1"], ["84126.5", "0.29199981", "0", "3"], ["84126.7", "0.03337063", "0", "1"], ["84127", "0.03180521", "0", "1"], ["84130.3", "0.3097019", "0", "3"], ["84132.8", "0", "0", "0"], ["84133.2", "0", "0", "0"], ["84133.3", "0.03399622", "0", "3"], ["84133.7", "0.03134473", "0", "1"], ["84134.4", "0.29713182", "0", "2"], ["84134.5", "0", "0", "0"], ["84134.7", "0", "0", "0"], ["84135.2", "0.03118369", "0", "1"], ["84136.4", "0", "0", "0"], ["84136.5", "1.11228184", "0", "3"], ["84138.7", "0.25562806", "0", "2"], ["84140.2", "0.000015", "0", "1"], ["84140.7", "0.06636378", "0", "1"], ["84141.4", "0", "0", "0"], ["84141.9", "0.06649558", "0", "1"], ["84142.3", "0.00557", "0", "2"], ["84142.7", "0.06196315", "0", "1"], ["84143.4", "0.35641581", "0", "1"], ["84143.9", "0.0680018", "0", "1"], ["84266.4", "0", "0", "0"]], "bids": [["84101.5", "0.12316409", "0", "2"], ["84101.3", "0.00135", "0", "2"], ["84100.1", "1", "0", "1"], ["84099.5", "0", "0", "0"], ["84099.4", "0.03339732", "0", "1"], ["84098.9", "0", "0", "0"], ["84098.4", "0.06836723", "0", "2"], ["84097.9", "0.01339", "0", "1"], ["84097.8", "0.03144794", "0", "1"], ["84097.6", "0.03429006", "0", "1"], ["84097.3", "0", "0", "0"], ["84097.2", "0", "0", "0"], ["84097.1", "0", "0", "0"], ["84092.4", "0.50067972", "0", "3"], ["84091.9", "0.1871364", "0", "1"], ["84091.3", "0.03998273", "0", "2"], ["84090.8", "0", "0", "0"], ["84089.2", "0", "0", "0"], ["84089", "0.031418", "0", "1"], ["84088.5", "0.02379125", "0", "1"], ["84085.4", "0.06186967", "0", "1"], ["84084.9", "0", "0", "0"], ["84082.4", "0.06833375", "0", "1"], ["84081.9", "0", "0", "0"], ["84081.8", "0.0672413", "0", "1"], ["84081.4", "0", "0", "0"], ["84080.9", "0.06773035", "0", "1"], ["84080.4", "0", "0", "0"], ["84079.1", "0.25562806", "0", "2"], ["84078.9", "0", "0", "0"], ["83961.5", "0.00083", "0", "1"], ["83961", "0.01782134", "0", "1"]], "ts": "1742554950404", "checksum": 1217416955, "seqId": 49927365222, "prevSeqId": 49927365087}], "record_time": 1742554950.405742, "EXCHANGE": "OKX"}
{"arg": {"channel": "books", "instId": "BTC-USDT"}, "action": "update", "data": [{"asks": [["84111.4", "0.47504964", "0", "6"], ["84112", "0.0146", "0", "1"], ["84116.8", "0.06231833", "0", "1"], ["84117.5", "0.2", "0", "1"], ["84119.7", "0.01055", "0", "1"], ["84122", "0.0146", "0", "1"], ["84122.7", "0.31381697", "0", "2"], ["84124.6", "0.03503043", "0", "1"], ["84125", "0.07187007", "0", "3"], ["84125.2", "0.03427995", "0", "1"], ["84125.8", "0.35641581", "0", "1"], ["84126.4", "0", "0", "0"], ["84126.5", "0.2608173", "0", "2"], ["84126.7", "0", "0", "0"], ["84127", "0", "0", "0"], ["84131.5", "0.03444379", "0", "1"], ["84131.6", "0.03365079", "0", "1"], ["84133.3", "0.00101534", "0", "2"], ["84133.7", "0.03139906", "0", "1"], ["84133.8", "0.03158785", "0", "1"], ["84134.2", "0.23789132", "0", "1"], ["84135.2", "0", "0", "0"], ["84136.4", "0.01774536", "0", "1"], ["84138.6", "0.06952333", "0", "1"], ["84138.7", "0", "0", "0"], ["84140.4", "0.06716414", "0", "1"], ["84140.7", "0", "0", "0"], ["84141", "0.06988017", "0", "1"], ["84141.9", "0", "0", "0"], ["84142.5", "0.06761627", "0", "1"], ["84142.7", "0", "0", "0"], ["84143.9", "0", "0", "0"], ["84264.2", "0", "0", "0"], ["84264.7", "0", "0", "0"], ["84264.9", "0", "0", "0"], ["84265.1", "0", "0", "0"], ["84265.8", "0", "0", "0"], ["84266", "0", "0", "0"], ["84266.2", "0", "0", "0"]], "bids": [["84111.3", "0.5326132", "0", "9"], ["84111.2", "0.32665812", "0", "5"], ["84110.2", "0", "0", "0"], ["84110", "0.01861705", "0", "4"], ["84106.9", "0.01339", "0", "1"], ["84101.5", "0.0042031", "0", "1"], ["84100.1", "0", "0", "0"], ["84099.4", "0", "0", "0"], ["84098.4", "0.03713992", "0", "1"], ["84097.8", "0", "0", "0"], ["84097.6", "0", "0", "0"], ["84097.3", "0.03301808", "0", "1"], ["84097.2", "1", "0", "1"], ["84097", "0.03287802", "0", "1"], ["84096.3", "0.21328442", "0", "2"], ["84095.8", "0.03383763", "0", "1"], ["84092.4", "0.4678912", "0", "2"], ["84091.3", "0.00475673", "0", "1"], ["84090.3", "0.03240129", "0", "1"], ["84089.5", "0.03256647", "0", "1"], ["84089", "0", "0", "0"], ["84088.2", "0.0350179", "0", "1"], ["84087.6", "0.03332095", "0", "1"], ["84085.4", "0", "0", "0"], ["84083.8", "0", "0", "0"], ["84083.3", "0.06464464", "0", "2"], ["84082.4", "0", "0", "0"], ["84081.8", "0", "0", "0"], ["84080.9", "0.06543076", "0", "1"], ["84080.1", "0.06609869", "0", "1"], ["84079.5", "0.06903719", "0", "1"], ["84079.1", "0.01774536", "0", "1"], ["84076.6", "0.24209683", "0", "2"], ["83961", "0", "0", "0"]], "ts": "1742554950504", "checksum": 1541941378, "seqId": 49927365361, "prevSeqId": 49927365222}], "record_time": 1742554950.506541, "EXCHANGE": "OKX"}
{"arg": {"channel": "books", "instId": "BTC-USDT"}, "action": "update", "data": [{"asks": [["84111.4", "0.49304964", "0", "8"], ["84123.9", "0.03165", "0", "1"], ["84124.5", "0.03134182", "0", "1"], ["84124.6", "0", "0", "0"], ["84126.5", "0.14198023", "0", "1"], ["84128.3", "0", "0", "0"], ["84128.4", "0", "0", "0"], ["84130.2", "0.76336757", "0", "2"], ["84131.4", "0.23789774", "0", "1"], ["84131.5", "0.06892543", "0", "2"], ["84131.6", "0", "0", "0"], ["84132.5", "1", "0", "1"], ["84134.2", "0", "0", "0"], ["84136.5", "0.11228184", "0", "2"], ["84138.5", "0.06227437", "0", "1"], ["84138.6", "0", "0", "0"], ["84140.9", "0.06367919", "0", "1"], ["84141", "0", "0", "0"], ["84264.2", "0.00001197", "0", "1"]], "bids": [["84111.3", "0.24939451", "0", "6"], ["84111.2", "0.017833", "0", "1"], ["84110.2", "0.15713969", "0", "1"], ["84106.9", "0", "0", "0"], ["84102.2", "0", "0", "0"], ["84100.8", "0.25278299", "0", "1"], ["84099.4", "0.11896386", "0", "1"], ["84097.8", "0.04018", "0", "1"], ["84097.3", "0", "0", "0"], ["84097.2", "0.03428239", "0", "1"], ["84096.6", "0.61360288", "0", "2"], ["84095.8", "1.03383763", "0", "2"], ["84090.3", "0", "0", "0"], ["84090.2", "0.03208092", "0", "1"], ["84083.3", "0.00060645", "0", "1"], ["84083.2", "0.0638414", "0", "1"], ["84080.1", "0", "0", "0"], ["84080", "0.06414566", "0", "2"], ["84076.6", "0.00420551", "0", "1"], ["84073.6", "0.25089791", "0", "2"]], "ts": "1742554950604", "checksum": -994050720, "seqId": 49927365428, "prevSeqId": 49927365361}], "record_time": 1742554950.603711, "EXCHANGE": "OKX"}
{"arg": {"channel": "books", "instId": "BTC-USDT"}, "action": "update", "data": [{"asks": [["84115.5", "0.01055", "0", "1"], ["84119.7", "0", "0", "0"], ["84131.4", "0", "0", "0"], ["84133.6", "0.23789555", "0", "1"], ["84136.4", "0", "0", "0"], ["84138.7", "0.01774536", "0", "1"], ["84148", "1", "0", "1"], ["84148.8", "0.00151854", "0", "1"], ["84149.6", "0.07999999", "0", "2"], ["84150", "0.2", "0", "1"], ["84150.4", "0.04576624", "0", "2"], ["84264", "0", "0", "0"], ["84264.2", "0", "0", "0"]], "bids": [["84111.3", "0.25863451", "0", "7"], ["84102", "0.19160722", "0", "2"], ["84079", "0", "0", "0"], ["84075.4", "0.0054", "0", "1"], ["84075.3", "0.23789555", "0", "1"], ["84073.6", "0.013", "0", "1"], ["84063.6", "0.0054", "0", "1"], ["84057.7", "0", "0", "0"], ["84006.7", "0.06", "0", "2"], ["83975.3", "0", "0", "0"]], "ts": "1742554950704", "checksum": 686612529, "seqId": 49927365471, "prevSeqId": 49927365428}], "record_time": 1742554950.70479, "EXCHANGE": "OKX"}
{"arg": {"channel": "books", "instId": "BTC-USDT"}, "action": "update", "data": [{"asks": [["84111.4", "0.4930345", "0", "8"], ["84124.5", "0", "0", "0"], ["84124.6", "0.03348934", "0", "1"], ["84131.1", "1", "0", "1"], ["84131.5", "0.03444379", "0", "1"], ["84131.6", "0.03460954", "0", "1"], ["84132.5", "0", "0", "0"], ["84133.6", "0", "0", "0"], ["84136.4", "0.23789219", "0", "1"], ["84138.5", "0", "0", "0"], ["84138.6", "0.06188018", "0", "1"], ["84140.9", "0", "0", "0"], ["84141", "0.06461028", "0", "1"], ["84263.9", "0", "0", "0"]], "bids": [["84111.3", "0.29915369", "0", "8"], ["84097.3", "0.03506229", "0", "1"], ["84097.2", "0", "0", "0"], ["84090.3", "0.0313641", "0", "1"], ["84090.2", "0", "0", "0"], ["84083.3", "0.06723827", "0", "2"], ["84083.2", "0", "0", "0"], ["84080.1", "0.07009073", "0", "1"], ["84080", "0.00001", "0", "1"], ["84079.1", "0", "0", "0"], ["84078.9", "0.01774536", "0", "1"], ["84076.6", "0.24209804", "0", "2"], ["84075.4", "0", "0", "0"], ["84075.3", "0", "0", "0"], ["84063.6", "0", "0", "0"], ["84057.7", "0.0054", "0", "1"], ["83975.3", "0.0054", "0", "1"], ["83961", "0.01782134", "0", "1"]], "ts": "1742554950804", "checksum": -184147802, "seqId": 49927365514, "prevSeqId": 49927365471}], "record_time": 1742554950.819239, "EXCHANGE": "OKX"}
{"arg": {"channel": "books", "instId": "BTC-USDT"}, "action": "update", "data": [{"asks": [["84126.5", "0.41368936", "0", "2"], ["84128.6", "1.12", "0", "5"], ["84130.2", "0.50099515", "0", "1"], ["84131.1", "0", "0", "0"], ["84236.7", "0.183127", "0", "1"], ["84255.4", "0", "0", "0"], ["84263.9", "0.00003969", "0", "2"]], "bids": [], "ts": "1742554950904", "checksum": -184147802, "seqId": 49927365524, "prevSeqId": 49927365514}], "record_time": 1742554950.903872, "EXCHANGE": "OKX"}
{"arg": {"channel": "books", "instId": "BTC-USDT"}, "action": "update", "data": [{"asks": [["84111.4", "0.42670376", "0", "7"]], "bids": [], "ts": "1742554951004", "checksum": 1259729048, "seqId": 49927365526, "prevSeqId": 49927365524}], "record_time": 1742554951.012903, "EXCHANGE": "OKX"}
{"arg": {"channel": "books", "instId": "BTC-USDT"}, "action": "update", "data": [{"asks": [["84111.4", "0.4781345", "0", "10"]], "bids": [], "ts": "1742554951104", "checksum": -1592400024, "seqId": 49927365533, "prevSeqId": 49927365526}], "record_time": 1742554951.104119, "EXCHANGE": "OKX"}
{"arg": {"channel": "books", "instId": "BTC-USDT"}, "action": "update", "data": [{"asks": [], "bids": [["84111.3", "0.29916369", "0", "9"]], "ts": "1742554951204", "checksum": 1958893275, "seqId": 49927365534, "prevSeqId": 49927365533}], "record_time": 1742554951.204372, "EXCHANGE": "OKX"}
{"arg": {"channel": "books", "instId": "BTC-USDT"}, "action": "update", "data": [{"asks": [["84115.5", "0", "0", "0"], ["84118", "0.02515", "0", "2"], ["84126.5", "0.14198023", "0", "1"], ["84128.6", "0.12", "0", "4"], ["84130.2", "0.6922878", "0", "2"], ["84130.5", "1", "0", "1"], ["84145", "1.00001197", "0", "2"], ["84147.9", "0.66883343", "0", "1"], ["84149.9", "0.00061841", "0", "2"], ["84150", "0", "0", "0"]], "bids": [["84111.3", "0.47286369", "0", "10"], ["84104.6", "0.09226278", "0", "2"], ["84102", "0.17821722", "0", "1"], ["84101.3", "0.000015", "0", "1"], ["84100.8", "0.59972198", "0", "2"], ["84097.2", "1", "0", "1"], ["84096.6", "0.38298103", "0", "1"], ["84095.8", "0.03383763", "0", "1"], ["84083.8", "0.13987571", "0", "1"], ["84072", "0.1025", "0", "3"], ["84071.2", "0.40787758", "0", "2"], ["84071", "0.0239248", "0", "2"], ["84070.4", "0", "0", "0"], ["84053.3", "0.41227025", "0", "2"], ["84019.9", "0", "0", "0"]], "ts": "1742554951304", "checksum": -79559916, "seqId": 49927365565, "prevSeqId": 49927365534}], "record_time": 1742554951.326601, "EXCHANGE": "OKX"}
{"arg": {"channel": "books", "instId": "BTC-USDT"}, "action": "update", "data": [{"asks": [["84111.4", "0.47510376", "0", "9"], ["84125.8", "0", "0", "0"], ["84130.5", "0", "0", "0"], ["84132.2", "1.002", "0", "2"], ["84208.1", "0", "0", "0"], ["84211", "0", "0", "0"], ["84264", "0.00074396", "0", "1"], ["84264.2", "0.00001197", "0", "1"], ["84264.7", "0.2025", "0", "1"], ["84264.9", "0.00031778", "0", "3"]], "bids": [["84111.3", "0.48882656", "0", "11"], ["84099.6", "0.000015", "0", "1"], ["84079.6", "0.23788995", "0", "1"], ["84076.6", "0.00420551", "0", "1"], ["84072", "0.0025", "0", "1"], ["84071.2", "0.45787758", "0", "3"], ["84070.4", "0.05", "0", "1"], ["84034.1", "0.00001501", "0", "1"], ["84024.8", "0", "0", "0"], ["84014.5", "0.6", "0", "1"], ["83982.1", "0", "0", "0"], ["83961.5", "0", "0", "0"], ["83961", "0", "0", "0"]], "ts": "1742554951404", "checksum": -1433131009, "seqId": 49927365587, "prevSeqId": 49927365565}], "record_time": 1742554951.404494, "EXCHANGE": "OKX"}
{"arg": {"channel": "books", "instId": "BTC-USDT"}, "action": "update", "data": [{"asks": [["84190", "0.00001057", "0", "1"], ["84199.2", "1.89141891", "0", "2"], ["84264.9", "0", "0", "0"]], "bids": [["84079.7", "0.01774536", "0", "1"], ["84078.9", "0", "0", "0"], ["84075.4", "0.0054", "0", "1"], ["84075.2", "0.106", "0", "4"], ["84074.4", "0.053", "0", "2"], ["84073.6", "0", "0", "0"], ["84063.6", "0.0054", "0", "1"], ["84057.7", "0", "0", "0"], ["84044.4", "0.00235582", "0", "1"], ["84035.1", "0.05471514", "0", "2"], ["83990.6", "0.00358931", "0", "1"], ["83975.3", "0", "0", "0"], ["83961.6", "0", "0", "0"]], "ts": "1742554951504", "checksum": -1433131009, "seqId": 49927365607, "prevSeqId": 49927365587}], "record_time": 1742554951.503946, "EXCHANGE": "OKX"}
{"arg": {"channel": "books", "instId": "BTC-USDT"}, "action": "update", "data": [{"asks": [["84111.4", "0.4759345", "0", "10"], ["84125.8", "0.35641581", "0", "1"], ["84264.7", "0", "0", "0"]], "bids": [["84021.8", "0", "0", "0"], ["83961.6", "0.00001197", "0", "1"]], "ts": "1742554951604", "checksum": 1381431329, "seqId": 49927365614, "prevSeqId": 49927365607}], "record_time": 1742554951.604041, "EXCHANGE": "OKX"}
{"arg": {"channel": "books", "instId": "BTC-USDT"}, "action": "update", "data": [{"asks": [["84209.8", "0.00118751", "0", "1"], ["84264.2", "0", "0", "0"]], "bids": [["84078", "1", "0", "1"], ["84073", "0.2", "0", "1"], ["84021.8", "0.0001627", "0", "1"], ["83962.4", "0", "0", "0"], ["83962.3", "0", "0", "0"], ["83961.6", "0", "0", "0"]], "ts": "1742554951704", "checksum": 1381431329, "seqId": 49927365619, "prevSeqId": 49927365614}], "record_time": 1742554951.704609, "EXCHANGE": "OKX"}
{"arg": {"channel": "books", "instId": "BTC-USDT"}, "action": "update", "data": [{"asks": [], "bids": [["84111.3", "0.31512656", "0", "10"], ["84111.2", "0", "0", "0"], ["84110.2", "0", "0", "0"], ["84095.9", "0", "0", "0"], ["84079.6", "0", "0", "0"], ["84078", "0", "0", "0"], ["84076.6", "0.24209793", "0", "2"], ["84073", "0", "0", "0"], ["83962.4", "0.00083", "0", "1"], ["83962.3", "1.32078776", "0", "2"], ["83961.6", "0.00001197", "0", "1"], ["83961.5", "0.00083", "0", "1"], ["83961", "0.01782134", "0", "1"], ["83960.9", "0.00083", "0", "1"]], "ts": "1742554951804", "checksum": -1661736894, "seqId": 49927365639, "prevSeqId": 49927365619}], "record_time": 1742554951.805729, "EXCHANGE": "OKX"}
{"arg": {"channel": "books", "instId": "BTC-USDT"}, "action": "update", "data": [{"asks": [["84111.4", "0.4896945", "0", "12"], ["84115.1", "0.01055", "0", "1"], ["84118", "0.0146", "0", "1"], ["84124.3", "0.03381608", "0", "1"], ["84124.6", "0", "0", "0"], ["84124.7", "0.0328724", "0", "1"], ["84124.8", "0.03121788", "0", "1"], ["84124.9", "0.03462581", "0", "1"], ["84125", "0.00772797", "0", "1"], ["84125.2", "0", "0", "0"], ["84130.9", "1", "0", "1"], ["84131.2", "0.03430698", "0", "1"], ["84131.3", "0.03062734", "0", "1"], ["84131.5", "0", "0", "0"], ["84131.6", "0", "0", "0"], ["84132.2", "0.002", "0", "1"], ["84133.5", "0.06281395", "0", "2"], ["84133.7", "0", "0", "0"], ["84133.8", "0", "0", "0"], ["84138.3", "0.06807425", "0", "1"], ["84138.6", "0", "0", "0"], ["84140.2", "0.06464047", "0", "2"], ["84140.4", "0", "0", "0"], ["84140.7", "0.06460336", "0", "1"], ["84141", "0", "0", "0"], ["84142.5", "0", "0", "0"], ["84173.4", "0", "0", "0"]], "bids": [["84111.3", "0.12014295", "0", "6"], ["84104.6", "0.07887278", "0", "1"], ["84101.6", "0.01339", "0", "1"], ["84097.3", "0", "0", "0"], ["84097", "0.03144823", "0", "1"], ["84096.7", "0.03785181", "0", "2"], ["84096.3", "0.17834", "0", "1"], ["84096.1", "0.03502189", "0", "1"], ["84095.8", "0", "0", "0"], ["84095.5", "0.03276429", "0", "1"], ["84093.5", "0", "0", "0"], ["84091.4", "0", "0", "0"], ["84090.3", "0", "0", "0"], ["84090", "0.03214986", "0", "1"], ["84089.5", "0", "0", "0"], ["84089.2", "0.03209402", "0", "1"], ["84088.2", "0", "0", "0"], ["84088", "0.03225355", "0", "1"], ["84087.6", "0", "0", "0"], ["84087.3", "0.03154114", "0", "1"], ["84083.8", "0", "0", "0"], ["84083.3", "0.00060645", "0", "1"], ["84083", "0.06485638", "0", "1"], ["84080.9", "0", "0", "0"], ["84080.7", "0.0696207", "0", "1"], ["84080.1", "0", "0", "0"], ["84079.8", "0.0680084", "0", "1"], ["84079.7", "0", "0", "0"], ["84079.5", "0", "0", "0"], ["84079.2", "0.06451941", "0", "1"], ["84078.9", "0.01774536", "0", "1"], ["84028.6", "0.10888055", "0", "1"]], "ts": "1742554951904", "checksum": 573690771, "seqId": 49927365781, "prevSeqId": 49927365639}], "record_time": 1742554951.904083, "EXCHANGE": "OKX"}
{"arg": {"channel": "books", "instId": "BTC-USDT"}, "action": "update", "data": [{"asks": [["84111.4", "0.7900545", "0", "13"], ["84117.6", "0.17551637", "0", "1"], ["84118.7", "0.03854779", "0", "1"], ["84119.6", "0.03166", "0", "1"], ["84122.6", "0.12968301", "0", "4"], ["84122.8", "0.04", "0", "1"], ["84123.9", "0", "0", "0"], ["84124.3", "0", "0", "0"], ["84124.7", "0", "0", "0"], ["84124.8", "0", "0", "0"], ["84124.9", "0", "0", "0"], ["84126.5", "0.49539472", "0", "2"], ["84127.7", "0.03160528", "0", "1"], ["84127.8", "0", "0", "0"], ["84127.9", "0.23790666", "0", "1"], ["84129.5", "1", "0", "1"], ["84130.2", "0.50099515", "0", "1"], ["84130.9", "0", "0", "0"], ["84131.2", "0", "0", "0"], ["84131.3", "0", "0", "0"], ["84133.5", "0", "0", "0"], ["84136.4", "0", "0", "0"], ["84138.3", "0.08991011", "0", "1"], ["84138.8", "0.67689997", "0", "3"], ["84140.2", "0.000015", "0", "1"], ["84140.7", "0", "0", "0"], ["84148.8", "0.08151854", "0", "3"], ["84149.6", "0.03999999", "0", "1"], ["84150.4", "0.00576625", "0", "1"], ["84154.7", "0.00214", "0", "1"], ["84176.8", "0.01124181", "0", "1"], ["84178", "0", "0", "0"], ["84264.2", "0.00001197", "0", "1"], ["84264.9", "0.00031778", "0", "3"], ["84265.1", "0.00418989", "0", "1"], ["84265.8", "0.00001156", "0", "1"], ["84266", "0.11878326", "0", "1"], ["84266.2", "0.213955", "0", "1"]], "bids": [["84111.3", "0.00926", "0", "3"], ["84110.1", "0", "0", "0"], ["84110", "0.00409715", "0", "3"], ["84108.3", "0", "0", "0"], ["84106.5", "0", "0", "0"], ["84106.4", "0", "0", "0"], ["84104.6", "0", "0", "0"], ["84104.4", "0", "0", "0"], ["84102.5", "0.06989713", "0", "1"], ["84102.4", "0.03854779", "0", "1"], ["84101.6", "0", "0", "0"], ["84101.5", "0.0160988", "0", "2"], ["84100.8", "0.25278299", "0", "1"], ["84099.6", "0", "0", "0"], ["84099.4", "0", "0", "0"], ["84097.8", "0", "0", "0"], ["84097.2", "0", "0", "0"], ["84097", "0", "0", "0"], ["84096.7", "0.00420353", "0", "1"], ["84096.6", "0.24979403", "0", "1"], ["84096.1", "0", "0", "0"], ["84095.6", "0", "0", "0"], ["84095.5", "0", "0", "0"], ["84093.1", "0.35667", "0", "1"], ["84092.4", "0.80467986", "0", "3"], ["84091.9", "1.2273164", "0", "3"], ["84090", "0", "0", "0"], ["84089.2", "0", "0", "0"], ["84088", "0", "0", "0"], ["84087.7", "0", "0", "0"], ["84087.3", "0", "0", "0"], ["84085.7", "1.80905281", "0", "4"], ["84083.5", "0", "0", "0"], ["84083", "0", "0", "0"], ["84080.7", "0", "0", "0"], ["84079.8", "0", "0", "0"], ["84079.2", "0", "0", "0"], ["84076.6", "0.00420551", "0", "1"], ["84075.8", "0.06633068", "0", "1"], ["84075.2", "0", "0", "0"], ["84074.4", "0.106", "0", "4"], ["84073.6", "0.053", "0", "2"], ["84071.3", "0.23790666", "0", "1"], ["84071.2", "0.35787758", "0", "1"], ["84070.4", "0.1", "0", "2"], ["84069.6", "0.10427", "0", "2"], ["84060.8", "0", "0", "0"], ["84060.3", "0.0183188", "0", "1"], ["84021.8", "0", "0", "0"], ["83960.8", "0.2025", "0", "1"], ["83960", "0.01798541", "0", "3"], ["83959.9", "0.00001022", "0", "1"], ["83959.8", "0.00421771", "0", "1"], ["83959.1", "0.00001009", "0", "1"], ["83958.8", "0.00005335", "0", "1"], ["83958.3", "0.00006061", "0", "1"], ["83955", "0.00620748", "0", "1"], ["83954.5", "0.17821722", "0", "1"], ["83954.4", "0.35579296", "0", "1"], ["83953", "0.00297157", "0", "1"], ["83952.9", "0.08991011", "0", "1"], ["83952.7", "0.00001065", "0", "1"], ["83952.3", "0.2025", "0", "1"], ["83950", "0.00013403", "0", "2"], ["83949.9", "0.00482516", "0", "2"], ["83947.3", "0.00103791", "0", "1"], ["83946.7", "0.00002763", "0", "2"], ["83946.1", "0.17821722", "0", "1"], ["83946", "0.35579296", "0", "1"], ["83945.8", "3.17354", "0", "1"]], "ts": "1742554952004", "checksum": 1029635544, "seqId": 49927366057, "prevSeqId": 49927365781}], "record_time": 1742554952.004256, "EXCHANGE": "OKX"}
{"arg": {"channel": "books", "instId": "BTC-USDT"}, "action": "update", "data": [{"asks": [["84111.4", "0.8006045", "0", "14"], ["84115.1", "0", "0", "0"], ["84117.8", "0.0000165", "0", "1"], ["84120.7", "0.03273359", "0", "1"], ["84121.3", "0.03374089", "0", "1"], ["84121.4", "0.06690114", "0", "2"], ["84127.7", "0.06489843", "0", "2"], ["84127.9", "0", "0", "0"], ["84130", "0.25250376", "0", "2"], ["84130.1", "0.03279374", "0", "2"], ["84130.2", "0.53588674", "0", "2"], ["84132.2", "0", "0", "0"], ["84134.7", "0.06718465", "0", "1"], ["84136.8", "0.14956743", "0", "2"], ["84137.2", "0.06910208", "0", "1"], ["84142.3", "0.00357", "0", "1"], ["84148.8", "0.00151854", "0", "1"], ["84149.6", "0.07999999", "0", "2"], ["84150.4", "0.04576624", "0", "2"], ["84264.7", "0.2025", "0", "1"], ["84265.1", "0", "0", "0"], ["84265.8", "0", "0", "0"], ["84266", "0", "0", "0"], ["84266.2", "0", "0", "0"]], "bids": [["84107.5", "0", "0", "0"], ["84096.6", "0.388904", "0", "2"], ["84096.4", "0.01339", "0", "1"], ["84095", "0.000015", "0", "1"], ["84093.8", "0.17834", "0", "1"], ["84093.4", "0.03249497", "0", "1"], ["84093.3", "0.07205814", "0", "2"], ["84092.7", "0.11890042", "0", "3"], ["84092", "0.04380646", "0", "2"], ["84086.4", "0.10046078", "0", "3"], ["84084.6", "0.03094838", "0", "1"], ["84084", "0.14759047", "0", "3"], ["84082.7", "0.17834", "0", "1"], ["84079.4", "0.06164342", "0", "1"], ["84077.3", "0.06991682", "0", "1"], ["84076.3", "0.07003565", "0", "1"], ["84074.4", "0.08", "0", "2"], ["84073.6", "0.066", "0", "3"], ["84072.8", "0.013", "0", "1"], ["84072.5", "0.23790475", "0", "1"], ["84071.3", "0", "0", "0"], ["84048.9", "0.00879557", "0", "2"], ["84048.8", "0.00600022", "0", "1"], ["83952.7", "0", "0", "0"], ["83952.3", "0", "0", "0"], ["83950", "0", "0", "0"], ["83949.9", "0", "0", "0"], ["83947.3", "0", "0", "0"], ["83946.7", "0", "0", "0"], ["83946.1", "0", "0", "0"], ["83946", "0", "0", "0"], ["83945.8", "0", "0", "0"]], "ts": "1742554952104", "checksum": 974893820, "seqId": 49927366133, "prevSeqId": 49927366057}], "record_time": 1742554952.105246, "EXCHANGE": "OKX"}
{"arg": {"channel": "books", "instId": "BTC-USDT"}, "action": "update", "data": [{"asks": [["84120.4", "0.08233731", "0", "3"], ["84120.7", "0", "0", "0"], ["84120.9", "0.06361089", "0", "2"], ["84121", "0.03089611", "0", "1"], ["84121.3", "0", "0", "0"], ["84121.4", "0", "0", "0"], ["84127.3", "0.03432114", "0", "1"], ["84127.4", "0.03430708", "0", "1"], ["84127.7", "0", "0", "0"], ["84129.6", "0.03285109", "0", "1"], ["84129.7", "0.03160094", "0", "1"], ["84130", "0.0146", "0", "1"], ["84130.1", "0.23791572", "0", "2"], ["84130.2", "0.50099515", "0", "1"], ["84134.4", "0.36591074", "0", "3"], ["84134.7", "0", "0", "0"], ["84136.3", "0.07069313", "0", "1"], ["84136.8", "0.15003109", "0", "2"], ["84137.2", "0", "0", "0"], ["84138.4", "0.06667428", "0", "1"], ["84138.8", "0.60836021", "0", "2"], ["84162.9", "0.01188188", "0", "1"], ["84171.2", "0", "0", "0"], ["84201.3", "0", "0", "0"], ["84264.7", "0", "0", "0"]], "bids": [["84111.3", "0.00001", "0", "1"], ["84108", "0", "0", "0"], ["84105.8", "0", "0", "0"], ["84100", "0.01597287", "0", "2"], ["84096.3", "0", "0", "0"], ["84094.3", "0.2025", "0", "1"], ["84093.4", "0", "0", "0"], ["84093.3", "0.04", "0", "1"], ["84093.1", "0.39065341", "0", "2"], ["84092.9", "0.03450502", "0", "2"], ["84092.7", "0.087", "0", "2"], ["84092.2", "0.03301893", "0", "1"], ["84092", "0.01189786", "0", "1"], ["84091.6", "0.03171685", "0", "1"], ["84089.9", "0.00351303", "0", "1"], ["84086.4", "0.06940838", "0", "2"], ["84086.1", "0.03392319", "0", "1"], ["84085.7", "1.77779217", "0", "3"], ["84085.3", "0.03429837", "0", "1"], ["84084.6", "0", "0", "0"], ["84084.1", "0.03102931", "0", "1"], ["84084", "0.11228184", "0", "2"], ["84083.5", "0.03401175", "0", "1"], ["84079.4", "0", "0", "0"], ["84079.1", "0.06387798", "0", "1"], ["84077.3", "0", "0", "0"], ["84076.8", "0.07030163", "0", "1"], ["84076.3", "0", "0", "0"], ["84075.9", "0.07023401", "0", "1"], ["84075.8", "0", "0", "0"], ["84075.4", "0.06777846", "0", "2"], ["84060.3", "0", "0", "0"], ["84058.6", "0.01831858", "0", "1"], ["84056.3", "0.59964265", "0", "1"], ["84056.2", "2.7274667", "0", "1"], ["84030.8", "0", "0", "0"], ["84021.9", "0.00016271", "0", "1"], ["84014.3", "0.59432247", "0", "1"], ["84014.2", "0", "0", "0"], ["84005.6", "0.01768125", "0", "2"], ["83954.4", "0", "0", "0"], ["83953", "0", "0", "0"], ["83952.9", "0", "0", "0"]], "ts": "1742554952204", "checksum": -1300108288, "seqId": 49927366273, "prevSeqId": 49927366133}], "record_time": 1742554952.220919, "EXCHANGE": "OKX"}
{"arg": {"channel": "books", "instId": "BTC-USDT"}, "action": "update", "data": [{"asks": [["84111.4", "0.8109986", "0", "15"], ["84114.9", "0.03854779", "0", "1"], ["84117.2", "0.00564", "0", "1"], ["84117.8", "0", "0", "0"], ["84118.7", "0", "0", "0"], ["84120.4", "0.04918249", "0", "2"], ["84120.9", "0.03095576", "0", "1"], ["84121.8", "0.002", "0", "1"], ["84127.4", "0", "0", "0"], ["84133.1", "0", "0", "0"], ["84134.4", "0.29713182", "0", "2"], ["84135.2", "0.05940838", "0", "1"], ["84138.4", "0", "0", "0"], ["84145", "1.20001197", "0", "3"], ["84150.8", "0", "0", "0"], ["84152.8", "0.36023777", "0", "1"], ["84169", "0.01124181", "0", "1"], ["84176.8", "0", "0", "0"], ["84264.7", "0.2025", "0", "1"]], "bids": [["84102.4", "0", "0", "0"], ["84100.8", "0.1515148", "0", "1"], ["84100.4", "0.00001197", "0", "1"], ["84098.4", "0.07568771", "0", "2"], ["84093.1", "0.35667", "0", "1"], ["84092.9", "0.00001501", "0", "1"], ["84091.9", "0.2273164", "0", "2"], ["84090.5", "1.35668197", "0", "3"], ["84086.1", "0", "0", "0"], ["84082.7", "0", "0", "0"], ["84080.1", "0.17834", "0", "1"], ["84079.1", "0", "0", "0"], ["84075.4", "0.0054", "0", "1"], ["84065.8", "1.13791599", "0", "2"], ["84063", "0.11228184", "0", "2"], ["84058.6", "0", "0", "0"], ["84052.4", "0.01831868", "0", "1"], ["84041.7", "0.09625488", "0", "1"], ["84041.5", "0.12483", "0", "1"], ["84033.8", "0.00420994", "0", "1"], ["84008.2", "0.0118816", "0", "1"], ["83987.8", "0.00007308", "0", "1"], ["83980.2", "0.18318683", "0", "1"], ["83954.5", "0", "0", "0"]], "ts": "1742554952304", "checksum": 245679896, "seqId": 49927366319, "prevSeqId": 49927366273}], "record_time": 1742554952.336487, "EXCHANGE": "OKX"}
{"arg": {"channel": "books", "instId": "BTC-USDT"}, "action": "update", "data": [{"asks": [["84117.2", "0", "0", "0"], ["84119.6", "0.04221", "0", "2"], ["84120.2", "0.03251372", "0", "1"], ["84120.7", "0.03224013", "0", "1"], ["84120.8", "0.03420392", "0", "1"], ["84120.9", "0.03289693", "0", "1"], ["84121", "0", "0", "0"], ["84124.1", "0.01603713", "0", "1"], ["84125.9", "0.41282092", "0", "2"], ["84127.2", "0.06710475", "0", "2"], ["84127.3", "0", "0", "0"], ["84128.1", "1.23790913", "0", "2"], ["84129.5", "0.03095338", "0", "1"], ["84129.6", "0.03138204", "0", "1"], ["84129.7", "0", "0", "0"], ["84130.1", "0.00001197", "0", "1"], ["84131.9", "0.002", "0", "1"], ["84134.2", "0.06880475", "0", "1"], ["84136.2", "0.07044812", "0", "1"], ["84136.3", "0", "0", "0"], ["84136.7", "0.06504037", "0", "1"], ["84136.8", "0.08609", "0", "1"], ["84138.2", "0.06246663", "0", "1"], ["84145.1", "0.03692255", "0", "1"], ["84155.8", "0.01783324", "0", "1"], ["84163", "0", "0", "0"], ["84167.9", "0.01124194", "0", "1"], ["84169", "0", "0", "0"], ["84174.3", "0", "0", "0"], ["84264", "0", "0", "0"], ["84264.2", "0", "0", "0"], ["84264.7", "0", "0", "0"], ["84264.9", "0", "0", "0"]], "bids": [["84109.4", "0.002", "0", "1"], ["84106", "0", "0", "0"], ["84101.5", "0.0042031", "0", "1"], ["84099.3", "0.002", "0", "1"], ["84098.4", "0.03854779", "0", "1"], ["84097.9", "0", "0", "0"], ["84096.6", "0.24979403", "0", "1"], ["84096.5", "0.11896806", "0", "1"], ["84096", "0.102", "0", "2"], ["84093.8", "0", "0", "0"], ["84093.5", "0.01339", "0", "1"], ["84093.1", "0", "0", "0"], ["84093", "0.03713992", "0", "1"], ["84092.9", "0.03512737", "0", "2"], ["84092.7", "0.12103727", "0", "3"], ["84092.2", "0", "0", "0"], ["84092.1", "0.03389499", "0", "1"], ["84091.6", "0", "0", "0"], ["84091.5", "0.03158685", "0", "1"], ["84090.5", "0.00001197", "0", "1"], ["84089.1", "1", "0", "1"], ["84086.4", "0.01", "0", "1"], ["84085.9", "0.0314422", "0", "1"], ["84085.3", "0", "0", "0"], ["84085.2", "0.03255276", "0", "1"], ["84084.1", "0", "0", "0"], ["84084", "0.14644563", "0", "3"], ["84083.5", "0", "0", "0"], ["84083.4", "0.03476895", "0", "1"], ["84080.1", "0", "0", "0"], ["84078.9", "0.08255602", "0", "2"], ["84078.4", "0.35641581", "0", "1"], ["84076.8", "0", "0", "0"], ["84076.7", "0.06699249", "0", "1"], ["84076.5", "0", "0", "0"], ["84075.9", "0", "0", "0"], ["84075.8", "0.07024878", "0", "1"], ["84075.2", "0.06473921", "0", "1"], ["84074.6", "0.2379065", "0", "1"], ["84074.4", "0", "0", "0"], ["84073.6", "0", "0", "0"], ["84072.8", "0", "0", "0"], ["84072.5", "0", "0", "0"], ["84072", "0.0825", "0", "3"], ["84071.2", "0.42387758", "0", "4"], ["84071", "0.0239348", "0", "3"], ["84070.4", "0.013", "0", "1"], ["84069.6", "0.05427", "0", "1"], ["84068", "0.1", "0", "2"], ["84067.2", "0.05", "0", "1"], ["84062.6", "0.16209053", "0", "2"], ["84061", "0", "0", "0"], ["84052.4", "0", "0", "0"], ["84050.1", "0.01831868", "0", "1"], ["84048.3", "3.20044", "0", "1"], ["84021.9", "0", "0", "0"], ["83980.3", "0.00201211", "0", "1"], ["83980.1", "0", "0", "0"], ["83954.5", "0.17821722", "0", "1"]], "ts": "1742554952404", "checksum": 1813207424, "seqId": 49927366467, "prevSeqId": 49927366319}], "record_time": 1742554952.422436, "EXCHANGE": "OKX"}
{"arg": {"channel": "books", "instId": "BTC-USDT"}, "action": "update", "data": [{"asks": [["84111.4", "1.04828725", "0", "17"], ["84116.3", "0.00564", "0", "1"], ["84119.2", "0.04459904", "0", "1"], ["84120.4", "0.01189384", "0", "1"], ["84126.6", "0", "0", "0"], ["84128.1", "1", "0", "1"], ["84129.1", "0.12483", "0", "1"], ["84134.1", "0.23790386", "0", "1"], ["84167.9", "0", "0", "0"], ["84173.8", "0.01125694", "0", "2"], ["84262.9", "0", "0", "0"], ["84263.9", "0", "0", "0"]], "bids": [["84100.1", "0.133768", "0", "1"], ["84098.4", "0.15751315", "0", "2"], ["84096.5", "0", "0", "0"], ["84090.9", "0.093", "0", "2"], ["84090.5", "1.00001197", "0", "2"], ["84089.1", "0", "0", "0"], ["84085.5", "0.35668197", "0", "2"], ["84079.7", "0.05940838", "0", "1"], ["84075.3", "0.23790386", "0", "1"], ["84074.6", "0", "0", "0"], ["84072.1", "0.1403523", "0", "1"], ["84061.5", "0.12817312", "0", "2"], ["84057.6", "0.01831876", "0", "1"], ["84050.1", "0", "0", "0"], ["84045.1", "0.12488207", "0", "2"], ["84021.9", "0.00016271", "0", "1"], ["83983.7", "0.18320267", "0", "2"], ["83980.2", "0", "0", "0"], ["83954.5", "0", "0", "0"]], "ts": "1742554952504", "checksum": 575293695, "seqId": 49927366504, "prevSeqId": 49927366467}], "record_time": 1742554952.522197, "EXCHANGE": "OKX"}
{"arg": {"channel": "books", "instId": "BTC-USDT"}, "action": "update", "data": [{"asks": [["84111.4", "1.03789315", "0", "16"], ["84118.7", "0.0103941", "0", "1"], ["84120.2", "0", "0", "0"], ["84120.7", "0", "0", "0"], ["84120.8", "0", "0", "0"], ["84120.9", "0", "0", "0"], ["84124.1", "0.19437713", "0", "2"], ["84125.9", "0.05614092", "0", "1"], ["84127.2", "0", "0", "0"], ["84128.1", "0", "0", "0"], ["84129.5", "0", "0", "0"], ["84129.6", "0", "0", "0"], ["84130", "1.0146", "0", "2"], ["84134.2", "0", "0", "0"], ["84136.2", "0", "0", "0"], ["84136.7", "0", "0", "0"], ["84138.2", "0", "0", "0"], ["84262.9", "0.17821722", "0", "1"], ["84263.9", "0.00003969", "0", "2"], ["84264", "0.00074396", "0", "1"], ["84264.2", "0.00001197", "0", "1"], ["84264.9", "0.00031778", "0", "3"], ["84265.1", "0.00418989", "0", "1"], ["84265.8", "0.00001156", "0", "1"], ["84266", "0.11878326", "0", "1"], ["84266.2", "0.213955", "0", "1"], ["84266.4", "0.00001402", "0", "1"], ["84266.5", "0.00054835", "0", "1"]], "bids": [["84102.5", "0", "0", "0"], ["84092.9", "0.00001501", "0", "1"], ["84092.7", "0.087", "0", "2"], ["84092.2", "1", "0", "1"], ["84092.1", "0", "0", "0"], ["84091.5", "0", "0", "0"], ["84090.5", "0.00001197", "0", "1"], ["84088.8", "0.17834", "0", "1"], ["84085.9", "0", "0", "0"], ["84085.2", "0", "0", "0"], ["84084", "0.11228184", "0", "2"], ["84083.4", "0", "0", "0"], ["84078.9", "0.01774536", "0", "1"], ["84076.7", "0", "0", "0"], ["84075.8", "0", "0", "0"], ["84075.2", "0", "0", "0"], ["84075.1", "0.17834", "0", "1"], ["84070.7", "0.56191569", "0", "1"], ["84064.1", "0", "0", "0"], ["84048.9", "0.00285157", "0", "1"], ["84046.8", "0", "0", "0"], ["84021.9", "0", "0", "0"], ["83954.5", "0.17821722", "0", "1"], ["83954.4", "0.35579296", "0", "1"], ["83952.9", "0.08991011", "0", "1"], ["83952.7", "0.00001065", "0", "1"], ["83950", "0.00013403", "0", "2"], ["83949.9", "0.00482516", "0", "2"], ["83947.3", "0.00103791", "0", "1"], ["83946.7", "0.00002763", "0", "2"]], "ts": "1742554952604", "checksum": -1377831092, "seqId": 49927366549, "prevSeqId": 49927366504}], "record_time": 1742554952.63803, "EXCHANGE": "OKX"}
{"arg": {"channel": "books", "instId": "BTC-USDT"}, "action": "update", "data": [{"asks": [["84120.1", "0.03344048", "0", "2"], ["84120.7", "0.0318364", "0", "1"], ["84120.8", "0.03152864", "0", "1"], ["84120.9", "0.0324819", "0", "1"], ["84122.7", "0.22527817", "0", "1"], ["84124.1", "0.01603713", "0", "1"], ["84127.1", "0.03138623", "0", "1"], ["84127.2", "0.03428381", "0", "1"], ["84129.5", "0.03213123", "0", "1"], ["84129.6", "0.0325893", "0", "1"], ["84129.7", "0.23790378", "0", "1"], ["84134.1", "0.06314795", "0", "1"], ["84136.2", "0.06609781", "0", "1"], ["84136.6", "0.06406079", "0", "1"], ["84138.2", "0.06308682", "0", "1"], ["84138.8", "0.0945107", "0", "1"], ["84140.3", "0", "0", "0"], ["84168.4", "0.52573622", "0", "1"], ["84169.7", "0", "0", "0"], ["84264", "0", "0", "0"], ["84264.2", "0", "0", "0"], ["84264.9", "0", "0", "0"], ["84265.1", "0", "0", "0"], ["84265.8", "0", "0", "0"], ["84266", "0", "0", "0"], ["84266.2", "0", "0", "0"], ["84266.4", "0", "0", "0"], ["84266.5", "0", "0", "0"]], "bids": [["84111.3", "0.00632", "0", "2"], ["84092.8", "0.03357901", "0", "1"], ["84092.7", "0.12157611", "0", "3"], ["84092.1", "0.03186574", "0", "1"], ["84091.5", "0.03362782", "0", "1"], ["84087.2", "0.23137271", "0", "1"], ["84085.8", "0.03269659", "0", "1"], ["84085.7", "0.21846287", "0", "2"], ["84085.2", "0.03524547", "0", "1"], ["84084", "0.14358445", "0", "3"], ["84083.4", "0.03097563", "0", "1"], ["84078.8", "0.31128092", "0", "2"], ["84076.7", "0.06750466", "0", "1"], ["84075.7", "0.06981263", "0", "1"], ["84075.3", "0", "0", "0"], ["84075.2", "0.30304659", "0", "2"], ["84057.9", "0.33694359", "0", "2"], ["84056.2", "0", "0", "0"], ["84032.7", "0.0059445", "0", "1"], ["84030.8", "0.0059445", "0", "1"], ["84021.8", "0.00016271", "0", "1"], ["83958.3", "0", "0", "0"], ["83955", "0", "0", "0"], ["83954.5", "0", "0", "0"], ["83954.4", "0", "0", "0"], ["83952.9", "0", "0", "0"], ["83952.7", "0", "0", "0"], ["83950", "0", "0", "0"], ["83949.9", "0", "0", "0"], ["83947.3", "0", "0", "0"], ["83946.7", "0", "0", "0"]], "ts": "1742554952704", "checksum": -1866069306, "seqId": 49927366650, "prevSeqId": 49927366549}], "record_time": 1742554952.720688, "EXCHANGE": "OKX"}
{"arg": {"channel": "books", "instId": "BTC-USDT"}, "action": "update", "data": [{"asks": [["84111.4", "0.84828725", "0", "16"], ["84117.6", "0.26974152", "0", "2"], ["84118.7", "0", "0", "0"], ["84120.8", "0.38819864", "0", "2"], ["84121.6", "0.17834", "0", "1"], ["84129", "0.23790393", "0", "1"], ["84129.7", "0", "0", "0"], ["84130.2", "0.90265348", "0", "2"], ["84134.3", "1.8990194", "0", "2"], ["84138.7", "0", "0", "0"], ["84145.3", "1.24", "0", "1"], ["84147.2", "0.09603712", "0", "3"], ["84148", "1.03999999", "0", "2"], ["84149.6", "0", "0", "0"], ["84150.4", "0.00576625", "0", "1"], ["84163.7", "2.69375335", "0", "1"], ["84199.1", "0.01774536", "0", "1"], ["84263.9", "0", "0", "0"]], "bids": [["84085.5", "0.00001197", "0", "1"], ["84078.8", "1.93055461", "0", "3"], ["84075.3", "0.23790393", "0", "1"], ["84075.2", "0.06514281", "0", "1"], ["84067", "1", "0", "1"], ["84062", "0.10024809", "0", "2"], ["84049.3", "2.87524823", "0", "1"], ["83959.8", "0", "0", "0"], ["83959.1", "0", "0", "0"], ["83958.8", "0", "0", "0"]], "ts": "1742554952804", "checksum": 227493921, "seqId": 49927366686, "prevSeqId": 49927366650}], "record_time": 1742554952.806191, "EXCHANGE": "OKX"}
{"arg": {"channel": "books", "instId": "BTC-USDT"}, "action": "update", "data": [{"asks": [["84111.4", "0.8109986", "0", "15"], ["84129", "0", "0", "0"], ["84134", "0.23790293", "0", "1"], ["84146.4", "0.08", "0", "2"], ["84147.2", "0.05603712", "0", "2"], ["84148", "1", "0", "1"], ["84262.9", "0", "0", "0"]], "bids": [["84088.8", "0", "0", "0"], ["84077.6", "0.17834", "0", "1"], ["84076.1", "0.23791793", "0", "2"], ["84075.3", "0", "0", "0"], ["84075.1", "0", "0", "0"], ["84067", "0", "0", "0"], ["84062", "0.00024809", "0", "1"], ["83959.8", "0.00421771", "0", "1"], ["83959.1", "0.00001009", "0", "1"], ["83958.8", "0.00005335", "0", "1"]], "ts": "1742554952904", "checksum": 1250703721, "seqId": 49927366702, "prevSeqId": 49927366686}], "record_time": 1742554952.923889, "EXCHANGE": "OKX"}
