{"arg": {"channel": "books", "instId": "BTC-USDT"}, "action": "snapshot", "data": [{"asks": [["85871.5", "0.69723328", "0", "10"], ["85871.8", "0.005", "0", "1"], ["85871.9", "0.03435213", "0", "1"], ["85872", "0.0567", "0", "1"], ["85872.1", "0.00110711", "0", "1"], ["85874", "0.0567", "0", "1"], ["85874.5", "0.00582186", "0", "1"], ["85874.6", "0.011644", "0", "1"], ["85875", "0.001", "0", "2"], ["85875.9", "0.04497784", "0", "1"], ["85876", "0.0567", "0", "1"], ["85878", "0.0567", "0", "1"], ["85878.1", "0.02970431", "0", "1"], ["85879.4", "0.01145", "0", "1"], ["85879.7", "0.21335184", "0", "1"], ["85879.8", "0.34924351", "0", "1"], ["85880", "0.07033901", "0", "5"], ["85880.2", "0.00022617", "0", "1"], ["85880.3", "0.00001172", "0", "1"], ["85880.5", "0.00756919", "0", "1"], ["85880.7", "0.03883416", "0", "1"], ["85881.4", "0.002", "0", "1"], ["85881.7", "0.00732878", "0", "2"], ["85882", "0.0567", "0", "1"], ["85882.1", "0.005", "0", "1"], ["85882.9", "0.01145", "0", "1"], ["85883.3", "0.00050009", "0", "1"], ["85883.7", "0.00011444", "0", "1"], ["85883.9", "0.08752127", "0", "2"], ["85884", "0.00002369", "0", "1"], ["85884.1", "0.07048901", "0", "1"], ["85884.4", "0.00018194", "0", "1"], ["85884.6", "0.00007591", "0", "2"], ["85884.9", "0.00005172", "0", "1"], ["85885", "0.06278182", "0", "1"], ["85885.3", "0.06318778", "0", "1"], ["85885.4", "0.00001174", "0", "1"], ["85885.5", "0.07536891", "0", "2"], ["85886.2", "0.00001", "0", "1"], ["85887.2", "0.00001501", "0", "1"], ["85887.6", "0.01131623", "0", "3"], ["85888", "0.01372672", "0", "2"], ["85888.1", "0.03435", "0", "1"], ["85888.4", "0.00403253", "0", "1"], ["85888.6", "0.20260514", "0", "2"], ["85888.8", "0.00011161", "0", "1"], ["85889.3", "0.43637052", "0", "2"], ["85889.4", "0.47741863", "0", "3"], ["85889.5", "0.04", "0", "1"], ["85889.6", "0.1755432", "0", "1"], ["85889.7", "0.11017586", "0", "2"], ["85889.9", "0.1679013", "0", "1"], ["85890", "0.05595044", "0", "1"], ["85890.2", "0.06", "0", "2"], ["85890.4", "0.00001174", "0", "1"], ["85890.6", "0.00001174", "0", "1"], ["85891.2", "0.18034748", "0", "2"], ["85891.3", "0.04", "0", "1"], ["85891.9", "0.00001", "0", "1"], ["85892", "0.10641189", "0", "2"], ["85892.1", "0.00564811", "0", "1"], ["85892.2", "0.09179063", "0", "1"], ["85892.6", "0.01072672", "0", "1"], ["85892.8", "0.10210279", "0", "1"], ["85893.1", "0.130289", "0", "1"], ["85893.2", "0.18342966", "0", "1"], ["85893.6", "0.12", "0", "4"], ["85894", "0.09458804", "0", "1"], ["85895.2", "0.00347697", "0", "1"], ["85895.8", "0.000015", "0", "1"], ["85896.3", "0.00403166", "0", "1"], ["85896.4", "0.00564811", "0", "1"], ["85897.3", "0.23288241", "0", "1"], ["85897.4", "0.11643803", "0", "2"], ["85897.5", "1.10895711", "0", "1"], ["85897.6", "1.57884051", "0", "1"], ["85898.2", "0.74773863", "0", "2"], ["85898.3", "0.003495", "0", "1"], ["85898.7", "0.1755432", "0", "1"], ["85898.8", "0.17511478", "0", "1"], ["85899", "0.17113546", "0", "1"], ["85899.2", "0.34924351", "0", "1"], ["85899.9", "0.00090898", "0", "2"], ["85900", "0.40872774", "0", "11"], ["85900.4", "0.12017586", "0", "3"], ["85900.6", "0.00024508", "0", "2"], ["85900.9", "0.16151541", "0", "1"], ["85901.8", "0.0053", "0", "1"], ["85902.1", "0.27540326", "0", "1"], ["85902.2", "0.49515", "0", "2"], ["85902.3", "0.13757225", "0", "1"], ["85902.4", "0.00007731", "0", "1"], ["85902.7", "0.00024459", "0", "1"], ["85902.8", "0.27322698", "0", "2"], ["85903.2", "0.00001174", "0", "1"], ["85904.4", "0.00001501", "0", "1"], ["85904.9", "0.24453", "0", "1"], ["85905.1", "0.00403053", "0", "1"], ["85906", "0.05823164", "0", "1"], ["85906.7", "0.20017745", "0", "1"], ["85906.8", "0.2025", "0", "1"], ["85906.9", "0.00001805", "0", "1"], ["85907.3", "0.0001482", "0", "1"], ["85907.4", "0.13771984", "0", "1"], ["85908.3", "0.00264521", "0", "1"], ["85908.5", "0.00011161", "0", "1"], ["85908.8", "0.0008", "0", "2"], ["85909", "0.32371526", "0", "2"], ["85909.6", "0.0004", "0", "1"], ["85909.8", "0.48552737", "0", "1"], ["85909.9", "0.846992", "0", "1"], ["85910", "0.17556854", "0", "2"], ["85910.7", "0.00001174", "0", "1"], ["85911.1", "0.11017586", "0", "2"], ["85911.6", "0.116533", "0", "1"], ["85911.7", "0.00402991", "0", "1"], ["85911.8", "0.34924351", "0", "1"], ["85913", "0.000015", "0", "1"], ["85913.1", "0.000015", "0", "1"], ["85913.2", "0.01584", "0", "1"], ["85914", "0.19442396", "0", "1"], ["85914.1", "0.22708", "0", "1"], ["85914.2", "0.00068775", "0", "1"], ["85915.2", "0.07999999", "0", "2"], ["85915.3", "0.001747", "0", "1"], ["85915.4", "0.2025", "0", "1"], ["85915.6", "0.0053", "0", "1"], ["85915.8", "0.00001174", "0", "1"], ["85915.9", "0.00001174", "0", "1"], ["85916", "0.03999999", "0", "1"], ["85916.1", "0.01745735", "0", "1"], ["85916.3", "0.11491574", "0", "1"], ["85916.6", "0.00144167", "0", "3"], ["85916.9", "0.1", "0", "1"], ["85917.9", "0.01329907", "0", "1"], ["85918", "0.00003364", "0", "1"], ["85918.1", "0.00007", "0", "1"], ["85918.3", "0.00212326", "0", "1"], ["85918.4", "0.00014547", "0", "1"], ["85918.6", "0.49959236", "0", "1"], ["85918.7", "0.1755432", "0", "1"], ["85920", "0.000532", "0", "3"], ["85920.1", "0.00402943", "0", "1"], ["85920.4", "0.35924351", "0", "2"], ["85920.5", "0.02327454", "0", "1"], ["85921", "0.00001", "0", "1"], ["85921.1", "0.57029", "0", "1"], ["85921.2", "0.00012652", "0", "1"], ["85921.6", "0.000015", "0", "1"], ["85921.9", "0.1585978", "0", "3"], ["85922.2", "0.08731", "0", "1"], ["85924", "0.2025", "0", "1"], ["85925", "0.00022901", "0", "2"], ["85925.4", "0.03333333", "0", "1"], ["85925.8", "0.08991011", "0", "1"], ["85925.9", "0.00001174", "0", "1"], ["85926.4", "0.24456", "0", "1"], ["85927.3", "0.00002918", "0", "1"], ["85927.4", "1.22540573", "0", "3"], ["85927.6", "2.89479863", "0", "1"], ["85928", "0.01", "0", "1"], ["85928.1", "0.00011161", "0", "1"], ["85928.5", "0.46118649", "0", "3"], ["85928.8", "0.2920762", "0", "2"], ["85928.9", "0.128304", "0", "1"], ["85929.3", "0.34924351", "0", "1"], ["85929.4", "0.00005109", "0", "1"], ["85930", "0.00012724", "0", "2"], ["85930.2", "0.00001501", "0", "1"], ["85930.3", "0.00580062", "0", "1"], ["85931.2", "0.00698233", "0", "1"], ["85931.3", "0.01566563", "0", "2"], ["85932.1", "0.00005937", "0", "1"], ["85932.2", "0.06506452", "0", "1"], ["85932.4", "0.0000568", "0", "1"], ["85932.6", "0.2025", "0", "1"], ["85933.3", "0.00539921", "0", "8"], ["85933.4", "0.00007302", "0", "1"], ["85934.4", "0.00001506", "0", "1"], ["85935.5", "0.1896803", "0", "1"], ["85936", "0.00001173", "0", "1"], ["85936.1", "0.00006129", "0", "1"], ["85937.4", "0.1755432", "0", "1"], ["85938.1", "0.02857142", "0", "1"], ["85938.3", "0.00580062", "0", "1"], ["85938.6", "0.00001678", "0", "1"], ["85938.7", "0.00009384", "0", "1"], ["85938.8", "0.00001501", "0", "1"], ["85939.1", "0.00402764", "0", "1"], ["85939.7", "0.34924351", "0", "1"], ["85939.9", "0.00883898", "0", "1"], ["85940", "0.02327744", "0", "1"], ["85940.6", "0.00001032", "0", "1"], ["85941.1", "0.1351837", "0", "4"], ["85941.2", "0.2025", "0", "1"], ["85941.6", "0.06981489", "0", "1"], ["85942", "0.00002241", "0", "1"], ["85942.1", "0.02326869", "0", "1"], ["85942.8", "0.00002372", "0", "1"], ["85943.4", "0.00002974", "0", "1"], ["85943.5", "0.116533", "0", "1"], ["85943.7", "0.00002534", "0", "1"], ["85943.9", "0.00002206", "0", "1"], ["85944.4", "0.30031748", "0", "3"], ["85944.8", "0.0001319", "0", "1"], ["85945", "0.00580062", "0", "1"], ["85945.1", "0.00017336", "0", "1"], ["85945.2", "0.00402719", "0", "1"], ["85945.6", "1.15732871", "0", "1"], ["85945.7", "3.23275", "0", "1"], ["85945.9", "0.07960315", "0", "1"], ["85946", "0.1755432", "0", "1"], ["85946.2", "0.00001171", "0", "1"], ["85946.8", "0.00004448", "0", "1"], ["85947.4", "0.000015", "0", "1"], ["85947.7", "0.00011161", "0", "1"], ["85947.8", "0.08991011", "0", "1"], ["85948.3", "0.35005814", "0", "1"], ["85948.5", "0.29836", "0", "2"], ["85948.7", "0.06980912", "0", "1"], ["85948.8", "0.37382429", "0", "1"], ["85949.3", "0.00001834", "0", "1"], ["85949.4", "0.04451395", "0", "1"], ["85949.7", "0.03333333", "0", "1"], ["85949.8", "0.2025", "0", "1"], ["85949.9", "0.00939359", "0", "3"], ["85950", "0.00293475", "0", "3"], ["85950.3", "1.269891", "0", "1"], ["85950.6", "0.1", "0", "1"], ["85951", "0.0025", "0", "1"], ["85951.3", "0.00001173", "0", "1"], ["85952", "0.00002367", "0", "1"], ["85952.6", "0.0116449", "0", "1"], ["85953", "0.01484", "0", "1"], ["85953.5", "0.00009227", "0", "1"], ["85953.7", "0.03980983", "0", "2"], ["85953.8", "0.00465865", "0", "1"], ["85953.9", "0.00580062", "0", "1"], ["85954", "0.0025", "0", "1"], ["85954.5", "0.00582261", "0", "1"], ["85954.6", "0.00199243", "0", "5"], ["85954.8", "0.07311591", "0", "1"], ["85954.9", "0.1755432", "0", "1"], ["85955", "0.005", "0", "2"], ["85956", "0.000015", "0", "1"], ["85956.1", "0.00001501", "0", "1"], ["85956.3", "0.00402634", "0", "1"], ["85956.5", "0.00582383", "0", "1"], ["85956.6", "0.03", "0", "1"], ["85956.7", "0.01446372", "0", "1"], ["85957.2", "0.00582261", "0", "1"], ["85957.3", "0.24250818", "0", "1"], ["85957.4", "0.35005814", "0", "1"], ["85957.8", "0.00465798", "0", "1"], ["85957.9", "0.03", "0", "1"], ["85958.4", "0.20830062", "0", "2"], ["85959.1", "0.04073731", "0", "2"], ["85959.6", "0.00582383", "0", "1"], ["85959.9", "0.00468936", "0", "2"], ["85960", "0.05815961", "0", "1"], ["85960.3", "0.03", "0", "1"], ["85960.7", "0.116533", "0", "1"], ["85960.9", "0.00582261", "0", "1"], ["85961", "0.01148", "0", "1"], ["85961.4", "0.00001173", "0", "1"], ["85961.5", "0.00376703", "0", "1"], ["85961.6", "0.00011172", "0", "1"], ["85961.9", "0.11597045", "0", "3"], ["85962", "0.3137", "0", "1"], ["85962.8", "0.03", "0", "1"], ["85962.9", "0.00402574", "0", "1"], ["85963.1", "0.00008634", "0", "1"], ["85964", "0.00001096", "0", "1"], ["85964.6", "0.000015", "0", "1"], ["85964.9", "0.00582261", "0", "1"], ["85965", "0.01639787", "0", "1"], ["85965.7", "0.00580062", "0", "1"], ["85965.8", "0.1755432", "0", "1"], ["85965.9", "0.24583102", "0", "2"], ["85966", "0.19762657", "0", "1"], ["85966.1", "0.06971564", "0", "1"], ["85966.2", "0.35005814", "0", "1"], ["85966.4", "0.00001173", "0", "1"], ["85966.6", "0.00707274", "0", "5"], ["85966.9", "0.00298666", "0", "1"], ["85967", "0.20829971", "0", "2"], ["85967.1", "0.00002296", "0", "1"], ["85967.2", "0.03", "0", "1"], ["85967.4", "0.00011161", "0", "1"], ["85967.7", "0.00009125", "0", "1"], ["85968.4", "0.00056798", "0", "1"], ["85969", "0.00582261", "0", "1"], ["85969.1", "0.00581", "0", "1"], ["85969.2", "0.05657473", "0", "3"], ["85969.3", "0.0000434", "0", "1"], ["85969.7", "0.00025154", "0", "2"], ["85969.9", "0.00004159", "0", "1"], ["85970.1", "0.03570044", "0", "2"], ["85970.4", "0.09209577", "0", "1"], ["85970.5", "0.19265001", "0", "4"], ["85970.8", "0.00003091", "0", "3"], ["85971.2", "0.0040248", "0", "1"], ["85971.5", "0.00001173", "0", "1"], ["85971.9", "0.00002584", "0", "1"], ["85973.2", "0.00003542", "0", "1"], ["85973.3", "0.00009539", "0", "1"], ["85973.6", "0.00005836", "0", "1"], ["85973.8", "0.02259745", "0", "1"], ["85973.9", "0.00020134", "0", "1"], ["85974", "0.00001464", "0", "1"], ["85974.2", "0.08724", "0", "1"], ["85974.3", "0.0000145", "0", "1"], ["85975", "0.00001274", "0", "1"], ["85975.1", "0.00007602", "0", "1"], ["85975.5", "0.00580021", "0", "1"], ["85975.6", "0.20820044", "0", "2"], ["85975.7", "0.0000109", "0", "1"], ["85975.9", "0.1755432", "0", "1"], ["85976", "0.00002123", "0", "1"], ["85976.5", "0.00002029", "0", "1"], ["85976.6", "0.00001173", "0", "1"], ["85977", "0.116533", "0", "1"], ["85977.3", "0.00001001", "0", "1"], ["85977.5", "0.35008348", "0", "2"], ["85978.3", "0.00003704", "0", "1"], ["85979", "0.00001173", "0", "1"], ["85979.3", "0.00005514", "0", "1"], ["85979.5", "0.00005465", "0", "1"], ["85981.4", "0.00580028", "0", "1"], ["85981.5", "0.00972419", "0", "2"], ["85981.9", "0.00294232", "0", "1"], ["85983.3", "0.00050009", "0", "1"], ["85983.6", "0.00001729", "0", "1"], ["85983.9", "0.00002993", "0", "1"], ["85984", "0.00603505", "0", "2"], ["85984.2", "0.2025", "0", "1"], ["85985.3", "0.00009917", "0", "1"], ["85985.4", "3.79909", "0", "1"], ["85985.5", "0.1755432", "0", "1"], ["85986", "0.00277747", "0", "1"], ["85986.1", "0.35005814", "0", "1"], ["85986.6", "0.00002041", "0", "2"], ["85986.8", "0.00001173", "0", "1"], ["85987", "0.00011161", "0", "1"], ["85987.3", "0.08991011", "0", "1"], ["85987.4", "0.69907078", "0", "1"], ["85988", "0.00193016", "0", "1"], ["85988.5", "0.19403", "0", "1"], ["85988.8", "0.00002325", "0", "1"], ["85989", "0.00402241", "0", "1"], ["85989.4", "0.0001749", "0", "1"], ["85989.8", "0.0000281", "0", "1"], ["85990", "0.0005", "0", "1"], ["85991.2", "0.00739036", "0", "2"], ["85991.4", "0.0003605", "0", "1"], ["85991.8", "0.0000229", "0", "2"], ["85992.8", "0.2025", "0", "1"], ["85993", "0.03895999", "0", "2"], ["85993.3", "0.00005922", "0", "2"], ["85994.2", "0.116533", "0", "1"], ["85994.7", "0.34973208", "0", "1"], ["85995", "0.01", "0", "1"], ["85995.6", "0.00007", "0", "1"], ["85996.1", "0.002331", "0", "1"], ["85996.9", "0.00001173", "0", "1"], ["85998.3", "0.00030279", "0", "1"], ["85998.8", "0.00402163", "0", "1"], ["85998.9", "0.00002848", "0", "1"], ["85999", "0.0116425", "0", "1"], ["85999.1", "0.000015", "0", "1"], ["85999.9", "0.2315903", "0", "84"], ["86000", "0.98559201", "0", "131"], ["86000.4", "0.00070104", "0", "2"], ["86001.2", "0.00402082", "0", "1"], ["86001.4", "0.412179", "0", "2"], ["86001.7", "0.00003969", "0", "2"], ["86001.8", "0.00320666", "0", "1"], ["86001.9", "0.01194665", "0", "1"], ["86002", "0.00001173", "0", "1"], ["86002.1", "0.00152395", "0", "9"], ["86002.3", "0.02", "0", "1"], ["86003.3", "0.34973208", "0", "1"], ["86004.1", "0.00002018", "0", "2"], ["86004.2", "0.00012404", "0", "1"], ["86004.3", "0.08992184", "0", "2"], ["86004.4", "0.00001984", "0", "1"], ["86004.7", "0.00011247", "0", "1"], ["86005.1", "0.11625826", "0", "1"], ["86005.8", "0.295881", "0", "2"], ["86005.9", "0.00582245", "0", "1"], ["86006.3", "0.00032751", "0", "1"], ["86006.6", "0.00011161", "0", "1"], ["86007.4", "0.05236875", "0", "1"], ["86007.7", "0.01316", "0", "1"], ["86008", "0.01746", "0", "1"], ["86008.6", "0.00002307", "0", "1"], ["86008.8", "0.00001771", "0", "1"], ["86008.9", "0.00001525", "0", "1"], ["86009.4", "0.00001645", "0", "1"], ["86009.6", "0.00024051", "0", "2"]], "bids": [["85871.4", "0.52124089", "0", "14"], ["85870", "0.056731", "0", "3"], ["85869.2", "0.00003", "0", "3"], ["85868.2", "0.005", "0", "1"], ["85868", "0.0567", "0", "1"], ["85867.3", "0.002", "0", "1"], ["85866.4", "0.0005", "0", "1"], ["85866.3", "0.0005", "0", "1"], ["85866", "0.0567", "0", "1"], ["85865.9", "0.01184", "0", "1"], ["85865.2", "0.00001172", "0", "1"], ["85864.9", "0.17296186", "0", "2"], ["85864.5", "0.00756957", "0", "1"], ["85864.2", "0.34924351", "0", "1"], ["85864.1", "0.1805432", "0", "2"], ["85864", "0.0567", "0", "1"], ["85863.3", "0.00055473", "0", "1"], ["85862.9", "0.00001", "0", "1"], ["85862.3", "0.00344226", "0", "1"], ["85862.1", "0.26308614", "0", "2"], ["85862", "0.0567", "0", "1"], ["85861.3", "0.000015", "0", "1"], ["85860.2", "0.52405", "0", "2"], ["85860.1", "0.00001172", "0", "1"], ["85860", "0.05671", "0", "2"], ["85859.4", "0.01224197", "0", "1"], ["85859", "0.03552", "0", "1"], ["85858.8", "0.009", "0", "1"], ["85858.4", "0.04", "0", "1"], ["85858.2", "0.06781899", "0", "1"], ["85858.1", "0.00403235", "0", "1"], ["85858", "0.23427225", "0", "3"], ["85857.9", "0.005", "0", "1"], ["85857.8", "0.24262133", "0", "1"], ["85857.7", "0.06412838", "0", "1"], ["85857.6", "0.01184", "0", "1"], ["85857.5", "0.00006", "0", "1"], ["85857.3", "0.07314215", "0", "2"], ["85857", "0.002", "0", "1"], ["85856.8", "0.06117339", "0", "1"], ["85856.7", "0.0288", "0", "1"], ["85856.6", "0.00756957", "0", "1"], ["85856.3", "0.00872586", "0", "1"], ["85855.6", "0.03628425", "0", "1"], ["85855.5", "0.34924351", "0", "1"], ["85855.4", "0.046271", "0", "2"], ["85855.2", "0.063", "0", "2"], ["85855.1", "0.00001172", "0", "1"], ["85855", "0.18005375", "0", "2"], ["85854.3", "0.05823164", "0", "1"], ["85853.8", "0.005", "0", "1"], ["85853.3", "0.02975368", "0", "1"], ["85853.1", "0.18474295", "0", "2"], ["85853", "0.06525", "0", "1"], ["85852.7", "0.1164795", "0", "2"], ["85852.2", "0.130281", "0", "1"], ["85851.8", "0.093", "0", "3"], ["85851.7", "0.03", "0", "1"], ["85851.4", "0.12842", "0", "1"], ["85850.8", "0.00403318", "0", "1"], ["85850.7", "0.10410172", "0", "1"], ["85850.2", "0.09432153", "0", "1"], ["85850", "0.00001172", "0", "1"], ["85849.9", "0.00050009", "0", "1"], ["85849.6", "0.00011161", "0", "1"], ["85849.4", "0.10119571", "0", "1"], ["85849.1", "0.83445618", "0", "1"], ["85848.5", "0.10291398", "0", "1"], ["85847.2", "0.00232971", "0", "1"], ["85847.1", "0.01749891", "0", "1"], ["85847", "0.1164722", "0", "1"], ["85846.8", "1.65814387", "0", "3"], ["85846.5", "0.12226", "0", "1"], ["85846.4", "0.2025", "0", "1"], ["85846.3", "0.08991011", "0", "1"], ["85846.2", "0.34924351", "0", "1"], ["85846.1", "0.1755432", "0", "1"], ["85845.6", "0.00324812", "0", "1"], ["85844.9", "0.00001172", "0", "1"], ["85844.8", "0.13971984", "0", "2"], ["85844.1", "0.000015", "0", "1"], ["85843.7", "0.16706409", "0", "1"], ["85843.5", "0.16331888", "0", "1"], ["85842.5", "0.00002534", "0", "1"], ["85841.5", "0.23287992", "0", "1"], ["85841.4", "0.17167097", "0", "1"], ["85840.6", "0.116533", "0", "1"], ["85840.5", "0.24453", "0", "1"], ["85840.4", "0.00403461", "0", "1"], ["85840.3", "0.18362646", "0", "1"], ["85840.2", "0.01", "0", "1"], ["85840", "0.00082147", "0", "2"], ["85839.9", "0.00001173", "0", "1"], ["85839.8", "0.16170568", "0", "1"], ["85839.5", "0.00347", "0", "1"], ["85838.3", "0.0288", "0", "1"], ["85838.2", "0.0054", "0", "1"], ["85837.1", "0.34924351", "0", "1"], ["85837", "0.2025", "0", "1"], ["85836.1", "0.11017586", "0", "2"], ["85836", "0.0008", "0", "2"], ["85835.5", "0.00001501", "0", "1"], ["85835.3", "0.4641461", "0", "1"], ["85835.2", "0.46153793", "0", "2"], ["85834.8", "0.00001173", "0", "1"], ["85834.6", "0.1755432", "0", "1"], ["85834.5", "0.002", "0", "1"], ["85833.7", "0.00179583", "0", "1"], ["85833.3", "0.00090898", "0", "2"], ["85833.2", "0.0288", "0", "1"], ["85832.6", "0.0288", "0", "1"], ["85832.4", "0.847756", "0", "1"], ["85832.2", "0.2201252", "0", "1"], ["85832.1", "0.21231", "0", "1"], ["85832", "0.00403461", "0", "1"], ["85830.5", "0.022", "0", "1"], ["85830.1", "0.116533", "0", "1"], ["85829.9", "0.00011161", "0", "1"], ["85829.7", "0.00001173", "0", "1"], ["85829.1", "0.0000362", "0", "1"], ["85828.1", "0.34924351", "0", "1"], ["85827.8", "0.003", "0", "1"], ["85827.2", "0.02329981", "0", "1"], ["85826.9", "0.000015", "0", "1"], ["85826.6", "0.00095157", "0", "1"], ["85826.4", "0.106", "0", "4"], ["85826.3", "0.01163721", "0", "1"], ["85825.8", "0.0448", "0", "2"], ["85825.6", "0.053", "0", "2"], ["85825.5", "0.30109292", "0", "1"], ["85825.4", "0.11017586", "0", "2"], ["85825", "0.12226", "0", "1"], ["85824.8", "0.0448", "0", "2"], ["85824.7", "0.17555493", "0", "2"], ["85824.4", "0.19809", "0", "2"], ["85824.2", "0.00403529", "0", "1"], ["85824.1", "0.08991011", "0", "1"], ["85824", "0.31414729", "0", "5"], ["85823.6", "0.02327468", "0", "2"], ["85823.2", "0.05", "0", "1"], ["85822.8", "0.32918216", "0", "2"], ["85822.7", "0.57113142", "0", "1"], ["85822", "0.0448", "0", "2"], ["85821.8", "0.12109256", "0", "2"], ["85821.2", "0.06027243", "0", "1"], ["85821", "0.01793172", "0", "1"], ["85820.9", "0.59645054", "0", "1"], ["85820.6", "0.55329", "0", "3"], ["85820.3", "0.03051575", "0", "1"], ["85820", "0.00001", "0", "1"], ["85819.6", "0.00001173", "0", "1"], ["85819.2", "0.02792096", "0", "1"], ["85819.1", "1.05726613", "0", "2"], ["85819", "0.2446", "0", "1"], ["85818.5", "0.34924351", "0", "1"], ["85818.3", "0.000015", "0", "1"], ["85817.3", "0.00986238", "0", "2"], ["85816.8", "2.71086886", "0", "1"], ["85816.6", "0.00050009", "0", "1"], ["85815.9", "0.116533", "0", "1"], ["85815.8", "0.1755432", "0", "1"], ["85815.5", "0.00170863", "0", "1"], ["85815.4", "0.0448", "0", "2"], ["85814.8", "0.11410015", "0", "1"], ["85814.7", "0.11017586", "0", "2"], ["85814.5", "0.01001173", "0", "2"], ["85813.1", "0.0288", "0", "1"], ["85812.7", "0.00001213", "0", "1"], ["85812.5", "0.0288", "0", "1"], ["85812", "0.20253412", "0", "3"], ["85810.5", "0.3968877", "0", "1"], ["85810.3", "0.00011161", "0", "1"], ["85809.9", "0.34924351", "0", "1"], ["85809.7", "0.00003001", "0", "2"], ["85809.5", "0.00001173", "0", "1"], ["85808.7", "0.00002534", "0", "1"], ["85807.1", "0.691633", "0", "2"], ["85806.9", "0.1755432", "0", "1"], ["85806.7", "0.00403753", "0", "1"], ["85806", "0.00001", "0", "1"], ["85805.1", "0.45975805", "0", "2"], ["85805", "0.06416174", "0", "1"], ["85804.6", "0.00582261", "0", "1"], ["85804.5", "0.01748005", "0", "1"], ["85804.4", "1.27206173", "0", "2"], ["85804.1", "0.00291416", "0", "1"], ["85803.3", "0.2025", "0", "1"], ["85802.3", "0.00347", "0", "1"], ["85802.1", "0.00582261", "0", "1"], ["85802", "0.00403753", "0", "1"], ["85801.6", "0.05136", "0", "1"], ["85801.4", "0.00427234", "0", "1"], ["85801.1", "0.000015", "0", "1"], ["85800.3", "0.28192295", "0", "1"], ["85800.2", "0.34924351", "0", "1"], ["85800", "0.00583261", "0", "2"], ["85799.9", "0.00493746", "0", "4"], ["85799.4", "0.00001173", "0", "1"], ["85799.1", "0.1457", "0", "1"], ["85799", "0.02330748", "0", "1"], ["85798.4", "0.0009536", "0", "1"], ["85798.3", "0.3", "0", "1"], ["85798.2", "0.116533", "0", "1"], ["85797.8", "0.17545965", "0", "2"], ["85797.7", "0.1755432", "0", "1"], ["85797.1", "0.00427234", "0", "1"], ["85796.2", "0.08991011", "0", "1"], ["85796.1", "0.01115851", "0", "1"], ["85796", "0.0288", "0", "1"], ["85795.7", "0.04659023", "0", "1"], ["85794.7", "0.2025", "0", "1"], ["85794.4", "0.0075", "0", "1"], ["85794.3", "0.00001173", "0", "1"], ["85792.8", "0.00427234", "0", "1"], ["85792.5", "0.00001501", "0", "1"], ["85792.3", "0.01804", "0", "1"], ["85792.1", "0.0075", "0", "1"], ["85792", "0.00465809", "0", "1"], ["85791.7", "0.01800008", "0", "1"], ["85791.4", "0.00060305", "0", "1"], ["85791.3", "0.12545875", "0", "2"], ["85791.2", "0.34924351", "0", "1"], ["85790.8", "0.0813", "0", "1"], ["85790.6", "0.00011161", "0", "1"], ["85789.6", "0.00403838", "0", "1"], ["85789.2", "0.00001173", "0", "1"], ["85788.8", "0.46922", "0", "1"], ["85788.2", "0.1755432", "0", "1"], ["85787.2", "0.00465809", "0", "1"], ["85786.5", "0.09", "0", "3"], ["85786.1", "0.2025", "0", "1"], ["85786", "0.145333", "0", "2"], ["85784.3", "0.00014958", "0", "1"], ["85784.2", "0.00581185", "0", "2"], ["85783.9", "0.000015", "0", "1"], ["85783.3", "0.00050009", "0", "1"], ["85782.4", "0.00403932", "0", "1"], ["85782.3", "0.05666404", "0", "1"], ["85782.2", "0.34924351", "0", "1"], ["85782", "0.01164463", "0", "1"], ["85781.8", "0.0288", "0", "1"], ["85781.4", "0.00699452", "0", "1"], ["85780.2", "0.06994616", "0", "1"], ["85779.1", "0.00001173", "0", "1"], ["85778.9", "0.00001012", "0", "1"], ["85778.2", "0.0232908", "0", "1"], ["85778", "0.57599743", "0", "1"], ["85777.6", "0.00465876", "0", "1"], ["85777.4", "0.2025", "0", "1"], ["85776.4", "0.1755432", "0", "1"], ["85776.3", "0.01398987", "0", "1"], ["85776.2", "0.00403998", "0", "1"], ["85776.1", "0.0054", "0", "1"], ["85775.9", "0.20644311", "0", "2"], ["85775.3", "0.06973064", "0", "2"], ["85775", "0.00002534", "0", "1"], ["85774.1", "0.00001173", "0", "1"], ["85773.7", "0.00465876", "0", "1"], ["85773.6", "0.00580051", "0", "1"], ["85773.1", "0.06995195", "0", "1"], ["85772.9", "0.00580066", "0", "1"], ["85772.7", "0.34924351", "0", "1"], ["85772.6", "0.06", "0", "2"], ["85771", "0.00011161", "0", "1"], ["85770.6", "0.00570065", "0", "1"], ["85770.5", "0.1", "0", "1"], ["85770", "0.00004238", "0", "1"], ["85769.2", "0.03", "0", "1"], ["85769", "0.00001174", "0", "1"], ["85768.2", "3.39682", "0", "1"], ["85768.1", "0.1", "0", "1"], ["85767.7", "0.00580051", "0", "1"], ["85767.6", "0.00580066", "0", "1"], ["85766.9", "0.01148", "0", "1"], ["85766.8", "0.00001501", "0", "1"], ["85766.7", "0.202515", "0", "2"], ["85766.6", "0.00090898", "0", "2"], ["85766.5", "0.116533", "0", "1"], ["85765.9", "0.00580051", "0", "1"], ["85765.8", "0.00974185", "0", "2"], ["85765.4", "0.1755432", "0", "1"], ["85765.1", "0.00298666", "0", "1"], ["85764.8", "0.1457", "0", "1"], ["85764.5", "0.08134", "0", "1"], ["85764.1", "0.34924351", "0", "1"], ["85763.9", "0.00001174", "0", "1"], ["85763.4", "0.6093", "0", "1"], ["85762.6", "0.00580012", "0", "1"], ["85762.5", "0.01793115", "0", "1"], ["85762", "0.06902533", "0", "1"], ["85761.6", "0.0406606", "0", "2"], ["85761.3", "0.00580067", "0", "1"], ["85760.9", "0.1", "0", "1"], ["85760.8", "0.0001028", "0", "1"], ["85760.4", "0.12670522", "0", "1"], ["85760.1", "0.00580067", "0", "1"], ["85759.8", "0.05829532", "0", "1"], ["85758.9", "0.00001174", "0", "1"], ["85758.3", "0.00404155", "0", "1"], ["85758.1", "0.00001501", "0", "1"], ["85757.7", "0.00580067", "0", "1"], ["85756.9", "0.2060202", "0", "2"], ["85756.5", "0.00597332", "0", "1"], ["85756.4", "0.2683032", "0", "2"], ["85756", "0.116533", "0", "1"], ["85755.5", "0.00580012", "0", "1"], ["85755.4", "0.0033251", "0", "1"], ["85755.2", "0.001028", "0", "1"], ["85754.9", "0.00001165", "0", "1"], ["85754.7", "0.34924351", "0", "1"], ["85753.8", "0.00001174", "0", "1"], ["85753.2", "0.01756286", "0", "1"], ["85751.8", "0.00570037", "0", "1"], ["85751.6", "0.00580054", "0", "1"], ["85751.5", "0.00617249", "0", "2"], ["85751.4", "0.00011161", "0", "1"], ["85749.9", "0.00144209", "0", "3"], ["85749.5", "0.00001501", "0", "1"], ["85748.8", "0.00001174", "0", "1"], ["85748.3", "0.00580012", "0", "1"], ["85748.2", "0.05523692", "0", "1"], ["85748.1", "0.179327", "0", "1"], ["85748", "0.02288368", "0", "3"], ["85747.9", "0.0139", "0", "1"], ["85747.4", "0.116533", "0", "1"], ["85747.3", "0.2025", "0", "1"], ["85746.9", "0.179349", "0", "1"], ["85746.6", "0.00009543", "0", "1"], ["85746.2", "0.00002", "0", "2"], ["85745.8", "0.34924351", "0", "1"], ["85745.7", "0.1755432", "0", "1"], ["85744.7", "0.08991011", "0", "1"], ["85744.3", "0.00001", "0", "1"], ["85744.2", "0.01789213", "0", "1"], ["85744", "3.83709", "0", "1"], ["85743.7", "0.00001174", "0", "1"], ["85743.5", "0.00001", "0", "1"], ["85743.2", "1.18048735", "0", "1"], ["85742.1", "0.00001", "0", "1"], ["85741.5", "0.00582524", "0", "1"], ["85741.2", "0.00002534", "0", "1"], ["85740.9", "0.000015", "0", "1"], ["85740.4", "0.01163721", "0", "1"], ["85740.3", "0.00404309", "0", "1"], ["85739.6", "0.00582245", "0", "1"], ["85739.4", "0.01194665", "0", "1"], ["85739.1", "0.00001", "0", "1"], ["85739", "0.08135", "0", "1"], ["85738.6", "0.00001174", "0", "1"], ["85738.4", "0.116533", "0", "1"], ["85737.4", "0.0139", "0", "1"], ["85737.3", "0.0278", "0", "2"], ["85737.1", "0.00580027", "0", "1"], ["85736.9", "0.52478671", "0", "2"], ["85734.5", "0.01751", "0", "1"], ["85734.3", "0.00580051", "0", "1"], ["85733.6", "0.00001174", "0", "1"], ["85733.3", "0.00493746", "0", "4"], ["85733.1", "0.1048", "0", "1"], ["85732.6", "0.2025", "0", "1"], ["85732.3", "0.00001501", "0", "1"], ["85731.9", "0.01024969", "0", "2"], ["85731.7", "0.00011161", "0", "1"], ["85731.3", "0.00404389", "0", "1"], ["85730.8", "0.01493332", "0", "1"], ["85730.6", "0.1457", "0", "1"], ["85730.4", "0.06", "0", "2"], ["85729.7", "0.20998421", "0", "1"], ["85729.2", "0.14040315", "0", "1"], ["85729.1", "0.116533", "0", "1"], ["85729", "0.00003709", "0", "1"], ["85728.9", "0.03", "0", "1"], ["85728.5", "0.00001174", "0", "1"], ["85728.1", "0.1778762", "0", "2"], ["85727.7", "0.34924351", "0", "1"], ["85727.2", "0.00003889", "0", "1"], ["85726.7", "0.00001172", "0", "1"], ["85726.1", "0.00580051", "0", "1"], ["85726", "0.20565", "0", "1"], ["85724.5", "0.00404486", "0", "1"], ["85723.9", "0.11665458", "0", "2"], ["85723.7", "0.000015", "0", "1"], ["85723.4", "0.20987", "0", "1"], ["85723.3", "0.2025", "0", "1"], ["85722.6", "0.88901", "0", "1"], ["85722.4", "0.01746735", "0", "3"], ["85721.6", "0.00580027", "0", "1"], ["85720.2", "0.116533", "0", "1"], ["85720", "0.00005171", "0", "1"], ["85719.6", "0.04413226", "0", "1"], ["85718.9", "0.34924351", "0", "1"], ["85718.7", "0.05244017", "0", "1"], ["85718.4", "0.00001172", "0", "1"], ["85716.6", "0.00409359", "0", "2"], ["85716.3", "0.1755432", "0", "1"], ["85715.3", "0.00580027", "0", "1"], ["85715.1", "0.00001501", "0", "1"], ["85714.7", "0.2025", "0", "1"], ["85714.4", "0.32367639", "0", "1"], ["85714.3", "0.00854583", "0", "2"]], "ts": "1742458820703", "checksum": -1435867678, "seqId": 49818451510, "prevSeqId": -1}], "record_time": 1742458821.195683}
{"arg": {"channel": "books", "instId": "BTC-USDT"}, "action": "update", "data": [{"asks": [["85875", "0.0005", "0", "1"], ["85875.1", "0.0005", "0", "1"], ["85883.4", "0.03435", "0", "1"], ["85888.1", "0", "0", "0"], ["85897.3", "0.23289049", "0", "1"], ["86009.6", "0", "0", "0"]], "bids": [["85871.4", "0.39517489", "0", "11"], ["85867.7", "0.11644418", "0", "1"], ["85866.5", "0.001", "0", "2"], ["85866.4", "0", "0", "0"], ["85866.3", "0", "0", "0"], ["85865.9", "0", "0", "0"], ["85857.7", "0.23880838", "0", "2"], ["85846.3", "0", "0", "0"], ["85841.5", "0", "0", "0"], ["85838.4", "0.23289049", "0", "1"], ["85828", "0.002096", "0", "1"], ["85714.2", "0.00020796", "0", "1"]], "ts": "1742458820803", "checksum": -980436521, "seqId": 49818451546, "prevSeqId": 49818451510}], "record_time": 1742458821.276685}
{"arg": {"channel": "books", "instId": "BTC-USDT"}, "action": "update", "data": [{"asks": [["85871.5", "0.68123328", "0", "9"], ["85874.5", "0", "0", "0"], ["85875.8", "0.00582196", "0", "1"], ["85876.4", "0.01145", "0", "1"], ["85879.4", "0", "0", "0"], ["85899.8", "0.0043665", "0", "1"], ["85966.9", "0", "0", "0"], ["85984", "0.00006173", "0", "1"], ["85993", "0.03", "0", "1"], ["86001.9", "0", "0", "0"], ["86009.6", "0.00024051", "0", "2"]], "bids": [["85871.4", "0.60016257", "0", "16"], ["85866.5", "0.0005", "0", "1"], ["85866.3", "0.0005", "0", "1"], ["85864.9", "0.07134238", "0", "1"], ["85864.2", "0", "0", "0"], ["85862.9", "0.01185", "0", "2"], ["85841", "1", "0", "1"], ["85765.1", "0", "0", "0"], ["85756.5", "0", "0", "0"], ["85748", "0.01392369", "0", "2"], ["85739.4", "0", "0", "0"], ["85730.8", "0", "0", "0"], ["85712.6", "0.0814", "0", "1"], ["85712.2", "0.00003896", "0", "1"], ["85712.1", "0.00011161", "0", "1"]], "ts": "1742458820903", "checksum": 1764291478, "seqId": 49818451576, "prevSeqId": 49818451546}], "record_time": 1742458821.376333}
{"arg": {"channel": "books", "instId": "BTC-USDT"}, "action": "update", "data": [{"asks": [["85871.5", "0.3876856", "0", "7"], ["85874.8", "0.001", "0", "2"], ["85875", "0", "0", "0"], ["85875.1", "0", "0", "0"], ["85875.8", "0", "0", "0"], ["85876.4", "0", "0", "0"], ["85877.9", "0.005822", "0", "1"], ["85899.8", "0", "0", "0"], ["85905.3", "0.003876", "0", "1"], ["86010", "0.20272681", "0", "3"], ["86010.4", "0.00001532", "0", "1"]], "bids": [["85871.4", "0.67698663", "0", "20"], ["85870.1", "0.11644097", "0", "1"], ["85867.7", "0", "0", "0"], ["85866.5", "0", "0", "0"], ["85866.3", "0", "0", "0"], ["85865.3", "0.001", "0", "2"], ["85864.9", "0.17302051", "0", "2"], ["85864.2", "0.34924351", "0", "1"], ["85862.8", "0.2025", "0", "1"], ["85857.7", "0.06412838", "0", "1"], ["85712.1", "0", "0", "0"]], "ts": "1742458821003", "checksum": 1990585790, "seqId": 49818451617, "prevSeqId": 49818451576}], "record_time": 1742458821.482717}
{"arg": {"channel": "books", "instId": "BTC-USDT"}, "action": "update", "data": [{"asks": [["85874.8", "0", "0", "0"], ["85874.9", "0.0005", "0", "1"], ["85875", "0.0005", "0", "1"], ["85880.3", "0.01146172", "0", "2"], ["85893", "0.16244353", "0", "1"], ["85897.3", "0.2328839", "0", "1"], ["85915", "1", "0", "1"], ["85923.9", "0.17116326", "0", "1"], ["86009.4", "0", "0", "0"], ["86009.6", "0", "0", "0"], ["86010", "0", "0", "0"], ["86010.4", "0", "0", "0"]], "bids": [["85870", "0.056721", "0", "2"], ["85866.9", "0.01184", "0", "1"], ["85862.9", "0.00001", "0", "1"], ["85841.5", "0.23288324", "0", "1"], ["85841", "0", "0", "0"], ["85840.6", "0.47477604", "0", "2"], ["85838.4", "0", "0", "0"], ["85827", "0.2", "0", "1"], ["85712.2", "0", "0", "0"]], "ts": "1742458821103", "checksum": -1321384489, "seqId": 49818451652, "prevSeqId": 49818451617}], "record_time": 1742458821.576198}
{"arg": {"channel": "books", "instId": "BTC-USDT"}, "action": "update", "data": [{"asks": [["85875", "0", "0", "0"], ["85875.1", "0.0005", "0", "1"], ["85881.4", "0", "0", "0"], ["85897.3", "0", "0", "0"], ["85902", "0.23288174", "0", "1"], ["85915", "0", "0", "0"], ["86009.4", "0.00001645", "0", "1"], ["86009.6", "0.00024051", "0", "2"]], "bids": [["85867.3", "0", "0", "0"], ["85857", "0", "0", "0"], ["85844.8", "0.13771984", "0", "1"], ["85834.5", "0", "0", "0"], ["85827", "0", "0", "0"], ["85712.2", "0.00003896", "0", "1"], ["85712.1", "0.00011161", "0", "1"], ["85711.2", "0.01064", "0", "1"], ["85711", "0.116533", "0", "1"]], "ts": "1742458821203", "checksum": -2012099045, "seqId": 49818451680, "prevSeqId": 49818451652}], "record_time": 1742458821.676203}
{"arg": {"channel": "books", "instId": "BTC-USDT"}, "action": "update", "data": [{"asks": [["85902", "0", "0", "0"], ["85902.7", "0.23312385", "0", "2"], ["86010", "0.00022681", "0", "2"]], "bids": [["85843.8", "0.23287926", "0", "1"], ["85841.5", "0", "0", "0"]], "ts": "1742458821303", "checksum": -2012099045, "seqId": 49818451686, "prevSeqId": 49818451680}], "record_time": 1742458821.781721}
{"arg": {"channel": "books", "instId": "BTC-USDT"}, "action": "update", "data": [{"asks": [["85871.5", "0.2074845", "0", "4"], ["85871.9", "0", "0", "0"], ["85873.3", "0.002", "0", "1"], ["85883.6", "0.002", "0", "1"], ["85900.7", "0.0005235", "0", "1"], ["85902.7", "0.00024459", "0", "1"], ["85904.8", "0.23287835", "0", "1"], ["85905.3", "0", "0", "0"], ["86009.6", "0", "0", "0"], ["86010", "0", "0", "0"]], "bids": [["85871.4", "0.77908263", "0", "22"], ["85870.2", "0.07401959", "0", "1"], ["85863.8", "0.002", "0", "1"], ["85853.5", "0.002", "0", "1"], ["85828", "0", "0", "0"], ["85826.4", "0.026", "0", "2"], ["85825.6", "0.093", "0", "3"], ["85824.8", "0.0848", "0", "3"], ["85791.3", "0.0395944", "0", "1"], ["85711.2", "0", "0", "0"], ["85711", "0", "0", "0"]], "ts": "1742458821403", "checksum": -276265760, "seqId": 49818451721, "prevSeqId": 49818451686}], "record_time": 1742458821.877734}
{"arg": {"channel": "books", "instId": "BTC-USDT"}, "action": "update", "data": [{"asks": [["85871.5", "0.12932411", "0", "3"], ["85874.6", "0", "0", "0"], ["85874.9", "0", "0", "0"], ["85875.1", "0", "0", "0"], ["85875.3", "0.0005", "0", "1"], ["85875.4", "0.0005", "0", "1"], ["85880.3", "0.00001172", "0", "1"], ["85883.4", "0", "0", "0"], ["85883.8", "0.01145", "0", "1"], ["85883.9", "0", "0", "0"], ["85884.1", "0", "0", "0"], ["85884.6", "0.08660115", "0", "3"], ["85884.7", "0.06191927", "0", "1"], ["85885", "0", "0", "0"], ["85885.3", "0", "0", "0"], ["85885.5", "0.0075687", "0", "1"], ["85885.6", "0.06496254", "0", "1"], ["85885.9", "0.12883553", "0", "2"], ["85888.6", "0.23695514", "0", "3"], ["85892", "0.005", "0", "1"], ["85892.2", "0", "0", "0"], ["85892.5", "0.09255103", "0", "1"], ["85892.8", "0", "0", "0"], ["85892.9", "0.09583317", "0", "1"], ["85893.5", "0.09476602", "0", "1"], ["85894", "0", "0", "0"], ["85894.4", "0.09312594", "0", "1"], ["85895.9", "0.3015399", "0", "1"], ["85898.8", "0", "0", "0"], ["85899", "0", "0", "0"], ["85899.2", "0.52168293", "0", "2"], ["85899.9", "0.17539109", "0", "3"], ["85900.9", "0", "0", "0"], ["85901.5", "0.17338555", "0", "1"], ["85902.8", "0.11639668", "0", "1"], ["85903.1", "0.16830323", "0", "1"], ["85904.8", "0", "0", "0"], ["85905.9", "0.23287311", "0", "1"], ["86009.6", "0.00024051", "0", "2"]], "bids": [["85870.3", "0.01184", "0", "1"], ["85866.9", "0", "0", "0"], ["85863.9", "0.03552", "0", "1"], ["85859", "0", "0", "0"], ["85858.8", "0.07701401", "0", "2"], ["85858.6", "0.06785146", "0", "1"], ["85858.2", "0", "0", "0"], ["85857.7", "0", "0", "0"], ["85857.6", "0.08170783", "0", "2"], ["85857.3", "0.01164646", "0", "1"], ["85857.2", "0.06898201", "0", "1"], ["85856.8", "0", "0", "0"], ["85851.6", "0.09560522", "0", "1"], ["85850.7", "0", "0", "0"], ["85850.5", "0.10119624", "0", "1"], ["85850.2", "0", "0", "0"], ["85850.1", "0.09843334", "0", "1"], ["85849.4", "0", "0", "0"], ["85849.2", "0.08991011", "0", "1"], ["85848.9", "0.10355565", "0", "1"], ["85848.5", "0", "0", "0"], ["85847.1", "0.25037202", "0", "2"], ["85844.6", "0.15979617", "0", "1"], ["85843.9", "0.1570555", "0", "1"], ["85843.8", "0", "0", "0"], ["85843.7", "0", "0", "0"], ["85843.5", "0", "0", "0"], ["85842", "0.17652627", "0", "1"], ["85841.4", "0", "0", "0"], ["85840.1", "0.17394677", "0", "1"], ["85839.8", "0", "0", "0"], ["85711.2", "0.01064", "0", "1"]], "ts": "1742458821503", "checksum": 572489556, "seqId": 49818451862, "prevSeqId": 49818451721}], "record_time": 1742458821.97628}
{"arg": {"channel": "books", "instId": "BTC-USDT"}, "action": "update", "data": [{"asks": [["85875.3", "0", "0", "0"], ["85875.4", "0", "0", "0"], ["85875.5", "0.001", "0", "2"], ["85877.9", "0", "0", "0"], ["85879.6", "0.00582164", "0", "1"], ["85900.7", "0", "0", "0"], ["85905.3", "0.0000225", "0", "1"], ["85905.9", "0", "0", "0"], ["85908.9", "0.23286771", "0", "1"], ["86010", "0.20272681", "0", "3"]], "bids": [["85871.4", "0.77920263", "0", "23"], ["85853.1", "0.30576449", "0", "1"], ["85850.6", "0.23286771", "0", "1"], ["85847.1", "0.01749891", "0", "1"], ["85797.8", "0.00465809", "0", "1"], ["85794.9", "0.01736", "0", "1"], ["85712.1", "0", "0", "0"], ["85711.2", "0", "0", "0"]], "ts": "1742458821603", "checksum": -1026635333, "seqId": 49818451896, "prevSeqId": 49818451862}], "record_time": 1742458822.077405}
{"arg": {"channel": "books", "instId": "BTC-USDT"}, "action": "update", "data": [{"asks": [["85872", "0", "0", "0"], ["85875.2", "0.0005", "0", "1"], ["85875.4", "0.0005", "0", "1"], ["85875.5", "0", "0", "0"], ["85893", "0.26059124", "0", "2"], ["86010", "0.00022681", "0", "2"]], "bids": [["85862.1", "0.09437295", "0", "1"], ["85860.2", "0", "0", "0"], ["85712.1", "0.00011161", "0", "1"]], "ts": "1742458821703", "checksum": -2027290657, "seqId": 49818451914, "prevSeqId": 49818451896}], "record_time": 1742458822.177424}
{"arg": {"channel": "books", "instId": "BTC-USDT"}, "action": "update", "data": [{"asks": [["85871.5", "0.01288502", "0", "2"], ["85874", "0.11643573", "0", "1"], ["85875.2", "0", "0", "0"], ["85875.4", "0", "0", "0"], ["85876.9", "0.0005", "0", "1"], ["85878.4", "0.0005", "0", "1"], ["85879.3", "0.01164337", "0", "1"], ["85879.6", "0", "0", "0"], ["85880", "0.05433901", "0", "4"], ["85881.6", "0.0058216", "0", "1"], ["85881.7", "0.005", "0", "1"], ["85883.8", "0", "0", "0"], ["85884.6", "0.00007591", "0", "2"], ["85884.7", "0", "0", "0"], ["85885.6", "0", "0", "0"], ["85885.9", "0.06995328", "0", "1"], ["85886", "0.06383826", "0", "1"], ["85886.5", "0.01145", "0", "1"], ["85886.9", "0.06369285", "0", "1"], ["85887.1", "0.06844988", "0", "1"], ["85887.2", "0.06438651", "0", "2"], ["85892.5", "0", "0", "0"], ["85892.9", "0", "0", "0"], ["85893.5", "0", "0", "0"], ["85893.8", "0.10173123", "0", "1"], ["85894.1", "0.10485523", "0", "1"], ["85894.3", "0.02328674", "0", "1"], ["85894.4", "0", "0", "0"], ["85894.7", "0.10215109", "0", "1"], ["85895.7", "0.09979201", "0", "1"], ["85898.3", "0", "0", "0"], ["85899.2", "0.34924351", "0", "1"], ["85899.9", "0.00090898", "0", "2"], ["85900.5", "0.16282736", "0", "1"], ["85901.1", "0.17371192", "0", "1"], ["85901.5", "0", "0", "0"], ["85902.8", "0.28369395", "0", "2"], ["85903.1", "0", "0", "0"], ["85904.4", "0.16553869", "0", "2"], ["85908.9", "0", "0", "0"], ["85913.9", "0.23635263", "0", "2"], ["85978", "0.00298666", "0", "1"], ["85988.6", "0.00597332", "0", "1"], ["85997.2", "0.00895999", "0", "1"], ["86005.8", "0.30782765", "0", "3"], ["86008.8", "0", "0", "0"], ["86008.9", "0", "0", "0"], ["86009.4", "0", "0", "0"], ["86009.6", "0", "0", "0"], ["86010", "0", "0", "0"]], "bids": [["85871.4", "0.79104263", "0", "24"], ["85870.3", "0.0005", "0", "1"], ["85870.2", "0.07451959", "0", "2"], ["85870", "0.0567", "0", "1"], ["85865.3", "0", "0", "0"], ["85864.9", "0.28116874", "0", "1"], ["85862.8", "0.37718", "0", "2"], ["85862.1", "0.21825157", "0", "2"], ["85860.2", "0.34936", "0", "1"], ["85860.1", "0.06954799", "0", "2"], ["85859.8", "0.06516275", "0", "1"], ["85858.9", "0.06406672", "0", "1"], ["85858.8", "0.009", "0", "1"], ["85858.6", "0", "0", "0"], ["85858.5", "0.06667734", "0", "1"], ["85857.6", "0.01184", "0", "1"], ["85857.2", "0", "0", "0"], ["85855.7", "0.23285764", "0", "1"], ["85853.1", "0.26868965", "0", "2"], ["85852.8", "0.09404292", "0", "1"], ["85851.8", "0.19278857", "0", "4"], ["85851.6", "0", "0", "0"], ["85851.3", "0.1011389", "0", "1"], ["85850.6", "0", "0", "0"], ["85850.5", "0", "0", "0"], ["85850.2", "0.10358558", "0", "1"], ["85850.1", "0", "0", "0"], ["85848.9", "0", "0", "0"], ["85847.2", "0", "0", "0"], ["85845.8", "0.16661098", "0", "1"], ["85845.2", "0.17436058", "0", "1"], ["85844.6", "0", "0", "0"], ["85843.9", "0", "0", "0"], ["85843.3", "0.16553218", "0", "1"], ["85842", "0", "0", "0"], ["85841.4", "0.15414228", "0", "1"], ["85840.1", "0", "0", "0"], ["85826.4", "0.106", "0", "4"], ["85825.6", "0.053", "0", "2"], ["85824.8", "0.0448", "0", "2"], ["85764.8", "0.14868666", "0", "2"], ["85756.2", "0.00597332", "0", "1"], ["85747.6", "0.00895999", "0", "1"], ["85739.1", "0.01195665", "0", "2"], ["85730.5", "0.01493332", "0", "1"], ["85712.2", "0", "0", "0"], ["85712.1", "0", "0", "0"]], "ts": "1742458821803", "checksum": -222217738, "seqId": 49818452173, "prevSeqId": 49818451914}], "record_time": 1742458822.28283}
{"arg": {"channel": "books", "instId": "BTC-USDT"}, "action": "update", "data": [{"asks": [["85871.5", "0", "0", "0"], ["85871.8", "0", "0", "0"], ["85872.1", "0", "0", "0"], ["85873.3", "0", "0", "0"], ["85874", "0", "0", "0"], ["85875.9", "0", "0", "0"], ["85876.9", "0", "0", "0"], ["85877.8", "0.0005", "0", "1"], ["85878", "0.0572", "0", "2"], ["85878.1", "0", "0", "0"], ["85878.4", "0", "0", "0"], ["85878.5", "0.01224197", "0", "1"], ["85879.3", "0", "0", "0"], ["85879.7", "0", "0", "0"], ["85879.8", "0", "0", "0"], ["85879.9", "0.07126304", "0", "2"], ["85880", "0.17076663", "0", "5"], ["85880.5", "0", "0", "0"], ["85880.7", "0", "0", "0"], ["85880.9", "0.00055467", "0", "1"], ["85881.5", "0.00756905", "0", "1"], ["85881.6", "0", "0", "0"], ["85883.9", "0.00582112", "0", "1"], ["85885.9", "0", "0", "0"], ["85886", "0", "0", "0"], ["85886.4", "0.02017113", "0", "1"], ["85886.5", "0", "0", "0"], ["85886.9", "0", "0", "0"], ["85887.1", "0", "0", "0"], ["85887.2", "0.00001501", "0", "1"], ["85887.6", "0.04204537", "0", "5"], ["85888.6", "0.00010514", "0", "1"], ["85889.3", "0.47520468", "0", "3"], ["85889.4", "0.36088563", "0", "2"], ["85890", "0.06963918", "0", "1"], ["85891", "0.06133517", "0", "1"], ["85891.1", "0.06905835", "0", "1"], ["85891.2", "0.17155", "0", "1"], ["85891.3", "0.10477194", "0", "2"], ["85893.2", "0.21777966", "0", "2"], ["85893.8", "0", "0", "0"], ["85894.1", "0", "0", "0"], ["85894.6", "0.00879489", "0", "1"], ["85894.7", "0", "0", "0"], ["85895.7", "0", "0", "0"], ["85897.5", "1.16851943", "0", "2"], ["85898", "0.18798856", "0", "2"], ["85898.2", "0.2025", "0", "1"], ["85898.7", "0.27127044", "0", "2"], ["85899.8", "0.09660703", "0", "1"], ["85900.5", "0", "0", "0"], ["85901.1", "0", "0", "0"], ["85902.8", "0.11639668", "0", "1"], ["85904.4", "0.00001501", "0", "1"], ["85904.6", "0.15551714", "0", "1"], ["85905", "0.15829509", "0", "1"], ["85905.3", "0", "0", "0"], ["85906.7", "0", "0", "0"], ["85906.8", "0.36555087", "0", "2"], ["85908.6", "0.16471244", "0", "1"], ["85908.8", "0", "0", "0"], ["85909", "0.00003887", "0", "1"], ["85909.6", "0", "0", "0"], ["85909.8", "0", "0", "0"], ["85909.9", "0", "0", "0"], ["85910.4", "0.0008", "0", "2"], ["85911.2", "0.0004", "0", "1"], ["85911.7", "0.00899191", "0", "2"], ["85913.9", "0.23634231", "0", "2"], ["85915.2", "0", "0", "0"], ["85916", "0", "0", "0"], ["85916.4", "0.55020584", "0", "1"], ["85916.8", "0.07999999", "0", "2"], ["85916.9", "0", "0", "0"], ["85917.6", "0.03999999", "0", "1"], ["85928.9", "0", "0", "0"], ["85998.9", "0.01166588", "0", "2"], ["86008.7", "0.02327468", "0", "2"], ["86008.8", "0.00001771", "0", "1"], ["86008.9", "0.00001525", "0", "1"], ["86009.4", "0.00001645", "0", "1"], ["86009.6", "0.00024051", "0", "2"], ["86010", "0.20272681", "0", "3"], ["86010.4", "0.00001532", "0", "1"], ["86010.5", "0.03", "0", "1"], ["86011.1", "0.00006532", "0", "1"], ["86011.2", "0.00200313", "0", "2"], ["86012.1", "0.00001172", "0", "1"], ["86012.5", "0.1755432", "0", "1"], ["86013.4", "0.0000412", "0", "3"], ["86014.1", "0.06", "0", "2"], ["86014.4", "0.36471456", "0", "3"], ["86014.6", "0.00402009", "0", "1"]], "bids": [["85875.9", "0.50226899", "0", "11"], ["85875.8", "0.0005", "0", "1"], ["85874", "0.0567", "0", "1"], ["85873.3", "0.00540936", "0", "1"], ["85873.2", "0.002096", "0", "1"], ["85872.1", "0.35182657", "0", "1"], ["85872", "0.0567", "0", "1"], ["85871.8", "0.24", "0", "1"], ["85871.7", "0.24113233", "0", "2"], ["85871.5", "0.2405", "0", "2"], ["85871.4", "0.19656259", "0", "11"], ["85870.9", "0.03552", "0", "1"], ["85870.3", "0", "0", "0"], ["85870.2", "0", "0", "0"], ["85870.1", "0.0379498", "0", "1"], ["85867.3", "0.00756933", "0", "1"], ["85866.1", "0.01224197", "0", "1"], ["85865.2", "0.02763684", "0", "2"], ["85864.8", "0.03628425", "0", "1"], ["85864.1", "0.24386087", "0", "3"], ["85863.9", "0", "0", "0"], ["85863.7", "0.0688978", "0", "1"], ["85863.3", "0", "0", "0"], ["85863.1", "0.06872794", "0", "1"], ["85862.8", "0.46709011", "0", "3"], ["85862.6", "0.06625282", "0", "1"], ["85862.1", "0.04994072", "0", "1"], ["85860.2", "0", "0", "0"], ["85860.1", "0.00001172", "0", "1"], ["85859.8", "0", "0", "0"], ["85859.4", "0", "0", "0"], ["85858.9", "0", "0", "0"], ["85858.5", "0", "0", "0"], ["85857.8", "0.38394395", "0", "2"], ["85856.8", "0.23284732", "0", "1"], ["85856.7", "0.12872347", "0", "2"], ["85856.6", "0", "0", "0"], ["85856", "0.09381715", "0", "1"], ["85855.7", "0", "0", "0"], ["85855.6", "0", "0", "0"], ["85855.3", "0.09742918", "0", "1"], ["85854.3", "0.15223596", "0", "2"], ["85853.3", "0", "0", "0"], ["85853.1", "0.17275568", "0", "2"], ["85852.8", "0", "0", "0"], ["85851.8", "0.093", "0", "3"], ["85851.4", "0", "0", "0"], ["85851.3", "0", "0", "0"], ["85850.2", "0", "0", "0"], ["85849.7", "0.16050128", "0", "1"], ["85849.3", "0.1564499", "0", "1"], ["85847.3", "0.17528637", "0", "1"], ["85845.8", "0", "0", "0"], ["85845.6", "0.17782424", "0", "2"], ["85845.2", "0", "0", "0"], ["85843.3", "0", "0", "0"], ["85841.4", "0", "0", "0"], ["85839.8", "0.03051575", "0", "1"], ["85836", "0.00079893", "0", "2"], ["85835.3", "0", "0", "0"], ["85832.4", "0", "0", "0"], ["85828.7", "0.05947306", "0", "1"], ["85827.2", "0.04929981", "0", "3"], ["85826.4", "0.093", "0", "3"], ["85825.6", "0.04", "0", "1"], ["85824.8", "0.1448", "0", "4"], ["85824", "0.26414729", "0", "4"], ["85823.6", "0", "0", "0"], ["85823.2", "0", "0", "0"], ["85821.8", "0.02109256", "0", "1"], ["85821.2", "0", "0", "0"], ["85820.3", "0", "0", "0"], ["85805.1", "0.0861203", "0", "1"], ["85800.3", "0", "0", "0"], ["85796.1", "0.03443319", "0", "3"], ["85784.3", "0", "0", "0"], ["85782.3", "0", "0", "0"], ["85769.3", "0.00570054", "0", "1"], ["85768.3", "0.02673767", "0", "1"], ["85712.2", "0.00003896", "0", "1"], ["85712.1", "0.00011161", "0", "1"], ["85711.2", "0.01064", "0", "1"]], "ts": "1742458821903", "checksum": 1342476175, "seqId": 49818452813, "prevSeqId": 49818452173}], "record_time": 1742458822.377947}
{"arg": {"channel": "books", "instId": "BTC-USDT"}, "action": "update", "data": [{"asks": [["85876", "0.0608", "0", "2"], ["85877.5", "0.11643106", "0", "1"], ["85877.7", "0.0005", "0", "1"], ["85877.8", "0", "0", "0"], ["85878", "0.0567", "0", "1"], ["85878.5", "0.01274197", "0", "2"], ["85879.9", "0.04811248", "0", "1"], ["85880", "0.05433901", "0", "4"], ["85882.8", "0.00582111", "0", "1"], ["85883.9", "0", "0", "0"], ["85889.5", "0.10780144", "0", "2"], ["85890", "0", "0", "0"], ["85890.1", "0.01145", "0", "1"], ["85890.5", "0.06354417", "0", "1"], ["85890.6", "0.06732739", "0", "2"], ["85890.7", "0.06754716", "0", "1"], ["85891", "0", "0", "0"], ["85891.1", "0", "0", "0"], ["85891.3", "0.04", "0", "1"], ["85893.7", "0.11598", "0", "1"], ["85897.4", "0.20935258", "0", "3"], ["85897.6", "1.67132108", "0", "2"], ["85898", "0", "0", "0"], ["85898.2", "0.30788887", "0", "2"], ["85898.7", "0.1755432", "0", "1"], ["85899.2", "0.44202754", "0", "2"], ["85899.8", "0", "0", "0"], ["85904", "0.16784582", "0", "1"], ["85904.6", "0.17029922", "0", "1"], ["85905", "0", "0", "0"], ["85906.3", "0.15769646", "0", "1"], ["85906.8", "0.2025", "0", "1"], ["85908", "0.16365946", "0", "1"], ["85908.6", "0", "0", "0"], ["85916.3", "0.96184474", "0", "2"], ["85927.3", "0", "0", "0"], ["85935.2", "0.128294", "0", "1"], ["85944.8", "0", "0", "0"], ["85952.2", "0.0001319", "0", "1"], ["86014.6", "0", "0", "0"]], "bids": [["85875.9", "1.36340715", "0", "17"], ["85875.8", "0", "0", "0"], ["85874.7", "0.0005", "0", "1"], ["85874.3", "0.0005", "0", "1"], ["85873.3", "0", "0", "0"], ["85872.1", "0.25130711", "0", "2"], ["85871.7", "0.24", "0", "1"], ["85871.5", "0.24", "0", "1"], ["85871.4", "0.04496", "0", "7"], ["85864.9", "0.42062968", "0", "2"], ["85864.1", "0.1805432", "0", "2"], ["85863.7", "0", "0", "0"], ["85863.6", "0.06385323", "0", "1"], ["85863.3", "0.06218352", "0", "1"], ["85863.1", "0", "0", "0"], ["85862.8", "0.81643011", "0", "4"], ["85862.6", "0", "0", "0"], ["85862.5", "0.06598947", "0", "1"], ["85862", "0.12044969", "0", "2"], ["85857.7", "0.12841", "0", "1"], ["85856.7", "0.0288", "0", "1"], ["85856.3", "0.11367325", "0", "2"], ["85856", "0", "0", "0"], ["85855.4", "0.15118381", "0", "3"], ["85855.3", "0", "0", "0"], ["85854.8", "0.09509169", "0", "1"], ["85854.3", "0.05823164", "0", "1"], ["85853.7", "0.09765469", "0", "1"], ["85849.7", "0", "0", "0"], ["85849.3", "0.15960096", "0", "1"], ["85848.7", "0.16570993", "0", "1"], ["85847.3", "0", "0", "0"], ["85846.8", "1.82025563", "0", "4"], ["85845.6", "0.00324812", "0", "1"], ["85845", "0.15817024", "0", "1"], ["85838.8", "0.847693", "0", "1"], ["85827.8", "0", "0", "0"], ["85827.2", "0.12929981", "0", "5"], ["85826.4", "0.053", "0", "2"], ["85825.6", "0", "0", "0"], ["85822.1", "0.1", "0", "1"], ["85820.7", "0.00170848", "0", "1"], ["85815.5", "0", "0", "0"], ["85796.2", "0.09291011", "0", "2"], ["85795.8", "0.0006029", "0", "1"], ["85791.4", "0", "0", "0"], ["85786.6", "0.00014958", "0", "1"], ["85756.5", "0.00212859", "0", "1"], ["85751.5", "0.00404291", "0", "1"], ["85712.2", "0", "0", "0"], ["85712.1", "0", "0", "0"], ["85711.2", "0", "0", "0"]], "ts": "1742458822003", "checksum": -899613117, "seqId": 49818453122, "prevSeqId": 49818452813}], "record_time": 1742458822.476724}
{"arg": {"channel": "books", "instId": "BTC-USDT"}, "action": "update", "data": [{"asks": [["85876", "0.0567", "0", "1"], ["85877.7", "0", "0", "0"], ["85877.8", "0.0005", "0", "1"], ["85878.5", "0.01224197", "0", "1"], ["85881.6", "0.0005", "0", "1"], ["85882.8", "0.00582116", "0", "1"], ["85889.5", "0.10489236", "0", "2"], ["85890.6", "0.06376223", "0", "2"], ["85897.6", "1.67877875", "0", "2"], ["85901.8", "0", "0", "0"], ["85904.6", "0.15441281", "0", "1"], ["85906.3", "0.15730504", "0", "1"], ["85911.5", "0.23285477", "0", "1"], ["85911.7", "0.00402991", "0", "1"], ["85913.9", "0.00349499", "0", "1"], ["85914", "0.60684114", "0", "2"], ["85915.6", "0", "0", "0"], ["85921.4", "0.1", "0", "1"], ["85925.3", "0.0053", "0", "1"], ["85932", "0.00002919", "0", "1"], ["85932.1", "0", "0", "0"], ["85935.4", "0.00005937", "0", "1"], ["85939.9", "0", "0", "0"], ["85941.9", "0.00883419", "0", "1"], ["85949.9", "0.00409359", "0", "2"], ["85952.8", "0.0053", "0", "1"], ["86012.5", "0", "0", "0"], ["86013.4", "0", "0", "0"], ["86014.1", "0", "0", "0"], ["86014.4", "0", "0", "0"]], "bids": [["85875.9", "1.36343815", "0", "19"], ["85874.7", "0", "0", "0"], ["85874.3", "0.001", "0", "2"], ["85863.6", "0.0638287", "0", "1"], ["85863.3", "0.06515119", "0", "1"], ["85856.8", "0", "0", "0"], ["85856.3", "0.1123982", "0", "2"], ["85854.4", "0.23285477", "0", "1"], ["85849.3", "0.15330061", "0", "1"], ["85846.8", "1.83010822", "0", "4"], ["85839.8", "0", "0", "0"], ["85828.6", "0.03051575", "0", "1"], ["85824.3", "0.02327492", "0", "2"], ["85822.9", "0.01792968", "0", "1"], ["85822.1", "0", "0", "0"], ["85821", "0", "0", "0"], ["85796.2", "0.08991011", "0", "1"], ["85796.1", "0.01115851", "0", "1"], ["85787.3", "0.00014958", "0", "1"], ["85786.6", "0", "0", "0"], ["85782", "0.01464463", "0", "2"], ["85750", "0.17929685", "0", "1"], ["85748.1", "0", "0", "0"], ["85712.2", "0.00003896", "0", "1"]], "ts": "1742458822103", "checksum": 716175328, "seqId": 49818453236, "prevSeqId": 49818453122}], "record_time": 1742458822.576063}
{"arg": {"channel": "books", "instId": "BTC-USDT"}, "action": "update", "data": [{"asks": [["85876", "0.0608", "0", "2"], ["85877.6", "0.001", "0", "2"], ["85877.8", "0", "0", "0"], ["85881.6", "0.00582119", "0", "1"], ["85882.8", "0", "0", "0"], ["85889.1", "0.06671812", "0", "1"], ["85889.5", "0.04", "0", "1"], ["85890.2", "0.18993655", "0", "4"], ["85890.5", "0.06924212", "0", "1"], ["85890.6", "0.00001174", "0", "1"], ["85890.7", "0", "0", "0"], ["85893.1", "0", "0", "0"], ["85897.1", "0.09597047", "0", "1"], ["85897.2", "0.09169708", "0", "1"], ["85897.4", "0.11643803", "0", "2"], ["85897.6", "1.57884051", "0", "1"], ["85897.8", "0.10079849", "0", "1"], ["85898.2", "0.2025", "0", "1"], ["85898.9", "0.10397568", "0", "1"], ["85899.2", "0.34924351", "0", "1"], ["85903.8", "0.15354661", "0", "1"], ["85904", "0", "0", "0"], ["85904.2", "0.1627566", "0", "1"], ["85904.6", "0", "0", "0"], ["85905.9", "0.17459772", "0", "1"], ["85906.3", "0", "0", "0"], ["85907.7", "0.15835461", "0", "1"], ["85908", "0", "0", "0"], ["85909.7", "0.0012645", "0", "1"], ["85909.9", "0.23286008", "0", "1"], ["85911.5", "0", "0", "0"], ["85923", "0.01", "0", "1"], ["85935.4", "0", "0", "0"], ["85938", "0.00005937", "0", "1"], ["86010.5", "0", "0", "0"], ["86011.1", "0", "0", "0"], ["86011.2", "0", "0", "0"], ["86012.1", "0", "0", "0"]], "bids": [["85875.9", "1.31695897", "0", "18"], ["85872.1", "0.18695857", "0", "2"], ["85871.4", "0.02896", "0", "6"], ["85863.6", "0", "0", "0"], ["85863.3", "0", "0", "0"], ["85863.2", "0.06913069", "0", "1"], ["85862.9", "0.06595791", "0", "2"], ["85862.8", "0.72652", "0", "3"], ["85862.5", "0", "0", "0"], ["85862.3", "0.09256905", "0", "2"], ["85862.2", "0.06367185", "0", "1"], ["85862.1", "0", "0", "0"], ["85862", "0.0567", "0", "1"], ["85861.8", "0.06694839", "0", "1"], ["85856.3", "0.00872586", "0", "1"], ["85855.9", "0.09241245", "0", "1"], ["85855.4", "0.046271", "0", "2"], ["85855.1", "0.0991081", "0", "2"], ["85854.8", "0", "0", "0"], ["85854.4", "0.09460552", "0", "1"], ["85853.7", "0", "0", "0"], ["85853.4", "0.09583855", "0", "1"], ["85852.3", "0.23286008", "0", "1"], ["85849.3", "0", "0", "0"], ["85848.9", "0.17071559", "0", "1"], ["85848.7", "0", "0", "0"], ["85848.5", "0.15779058", "0", "1"], ["85846.8", "1.65814387", "0", "3"], ["85846.4", "0.37153063", "0", "2"], ["85845", "0", "0", "0"], ["85844.7", "0.15856556", "0", "1"], ["85826.3", "0.11163721", "0", "2"], ["85824.3", "0", "0", "0"], ["85796.1", "0.03443319", "0", "3"], ["85787.3", "0", "0", "0"], ["85712.1", "0.00011161", "0", "1"], ["85711.2", "0.01064", "0", "1"]], "ts": "1742458822203", "checksum": 63846814, "seqId": 49818453360, "prevSeqId": 49818453236}], "record_time": 1742458822.677796}
{"arg": {"channel": "books", "instId": "BTC-USDT"}, "action": "update", "data": [{"asks": [["85876", "0.96921403", "0", "9"], ["85876.6", "0.00632151", "0", "2"], ["85876.7", "0.0005", "0", "1"], ["85877.4", "0.05591191", "0", "1"], ["85877.6", "0", "0", "0"], ["85881.6", "0", "0", "0"], ["85882.5", "0.01164301", "0", "1"], ["85884.5", "0.12336635", "0", "1"], ["85884.6", "0.20257591", "0", "3"], ["85886.4", "0", "0", "0"], ["85887.3", "0.00349499", "0", "1"], ["85887.5", "0.130271", "0", "1"], ["85887.6", "0.05349537", "0", "6"], ["85888.6", "0.06780764", "0", "2"], ["85889.1", "0", "0", "0"], ["85889.4", "0.47741863", "0", "3"], ["85889.5", "0.10425419", "0", "2"], ["85889.8", "0.06728365", "0", "1"], ["85890", "0.06260369", "0", "1"], ["85890.1", "0", "0", "0"], ["85890.2", "0.06", "0", "2"], ["85890.5", "0", "0", "0"], ["85893.7", "0", "0", "0"], ["85896.5", "0.09383741", "0", "1"], ["85896.7", "0.09951734", "0", "1"], ["85897.1", "0", "0", "0"], ["85897.2", "0", "0", "0"], ["85897.3", "0.09555429", "0", "1"], ["85897.8", "0", "0", "0"], ["85898.5", "0.09994239", "0", "1"], ["85898.9", "0", "0", "0"], ["85903.3", "0.15398765", "0", "1"], ["85903.5", "0.15362754", "0", "1"], ["85903.8", "0", "0", "0"], ["85904.2", "0", "0", "0"], ["85904.8", "0.23287479", "0", "1"], ["85905.4", "0.1566831", "0", "1"], ["85905.9", "0", "0", "0"], ["85907.3", "0.17131553", "0", "2"], ["85907.7", "0", "0", "0"], ["85909.7", "0", "0", "0"], ["85909.9", "0", "0", "0"], ["85913.9", "0", "0", "0"], ["85923", "0", "0", "0"], ["86010.5", "0.03", "0", "1"], ["86011.1", "0.00006532", "0", "1"]], "bids": [["85875.9", "0.43780445", "0", "8"], ["85874.3", "0", "0", "0"], ["85873.1", "0.0005", "0", "1"], ["85872.7", "0.0005", "0", "1"], ["85872.1", "0.00110711", "0", "1"], ["85871.8", "0", "0", "0"], ["85871.7", "0", "0", "0"], ["85871.5", "0", "0", "0"], ["85871.4", "0.00016", "0", "5"], ["85870.9", "0", "0", "0"], ["85864.7", "0.03552", "0", "1"], ["85864.2", "0", "0", "0"], ["85863.2", "0", "0", "0"], ["85862.9", "0.00001", "0", "1"], ["85862.7", "0.06871834", "0", "1"], ["85862.3", "0.10872509", "0", "3"], ["85862.2", "0.06754922", "0", "1"], ["85861.8", "0.06804996", "0", "1"], ["85861.3", "0.06969814", "0", "2"], ["85857.8", "0.24262133", "0", "1"], ["85855.9", "0", "0", "0"], ["85855.2", "0.15788223", "0", "3"], ["85855.1", "0.00001172", "0", "1"], ["85854.7", "0.1008971", "0", "1"], ["85854.4", "0", "0", "0"], ["85853.9", "0.10324429", "0", "1"], ["85853.4", "0", "0", "0"], ["85853", "0.16749042", "0", "2"], ["85852.3", "0", "0", "0"], ["85849.2", "0", "0", "0"], ["85848.9", "0", "0", "0"], ["85848.5", "0", "0", "0"], ["85848.2", "0.16701256", "0", "1"], ["85848", "0.17562385", "0", "1"], ["85847.1", "0.2503737", "0", "2"], ["85846.4", "0.2025", "0", "1"], ["85845.9", "0.1760273", "0", "1"], ["85844.7", "0", "0", "0"], ["85844.3", "0.16585398", "0", "1"], ["85836.8", "0.0008", "0", "2"], ["85836", "0.00039893", "0", "1"], ["85835.2", "0.461139", "0", "1"], ["85828", "0.026", "0", "2"], ["85827.2", "0.11629981", "0", "4"], ["85826.4", "0.04", "0", "1"], ["85791.4", "0.00014957", "0", "1"], ["85782", "0.01164463", "0", "1"], ["85774.7", "0.003", "0", "1"], ["85711", "0.116533", "0", "1"]], "ts": "1742458822303", "checksum": -353363638, "seqId": 49818453580, "prevSeqId": 49818453360}], "record_time": 1742458822.781899}
{"arg": {"channel": "books", "instId": "BTC-USDT"}, "action": "update", "data": [{"asks": [["85876", "0.97270884", "0", "10"], ["85876.5", "0.001", "0", "2"], ["85876.6", "0", "0", "0"], ["85876.7", "0", "0", "0"], ["85877.2", "0.00582169", "0", "1"], ["85877.8", "0.00107138", "0", "1"], ["85881.8", "0.03883416", "0", "1"], ["85882.5", "0", "0", "0"], ["85887.3", "0", "0", "0"], ["85887.5", "0", "0", "0"], ["85887.6", "0.08784537", "0", "7"], ["85889.3", "0.43637052", "0", "2"], ["85889.4", "0.54348735", "0", "4"], ["85889.5", "0.04", "0", "1"], ["85893.2", "0.18342966", "0", "1"], ["85896.4", "0.10867994", "0", "2"], ["85896.5", "0", "0", "0"], ["85903.4", "0.15813536", "0", "1"], ["85903.5", "0", "0", "0"], ["85904.5", "0.0043665", "0", "1"], ["85904.8", "0", "0", "0"], ["85905.3", "0.23287219", "0", "1"], ["85909.6", "0.0008", "0", "2"], ["85910.4", "0.0004", "0", "1"], ["85911.2", "0", "0", "0"], ["85916", "0.08", "0", "2"], ["85916.8", "0.03999999", "0", "1"], ["85917.6", "0", "0", "0"], ["86011.2", "0.00200313", "0", "2"]], "bids": [["85875.9", "0.30554936", "0", "7"], ["85873.2", "0", "0", "0"], ["85873.1", "0", "0", "0"], ["85872.7", "0", "0", "0"], ["85872", "0.0572", "0", "2"], ["85871.8", "0.0005", "0", "1"], ["85865.2", "0.00001172", "0", "1"], ["85864.8", "0", "0", "0"], ["85864.7", "0", "0", "0"], ["85864.2", "0.34924351", "0", "1"], ["85862.2", "0", "0", "0"], ["85862.1", "0.06908699", "0", "1"], ["85857.8", "0.33444118", "0", "2"], ["85857.7", "0.15603512", "0", "2"], ["85855.2", "0.063", "0", "2"], ["85855.1", "0.09284744", "0", "2"], ["85848.2", "0.23287219", "0", "1"], ["85848.1", "0.16926866", "0", "1"], ["85847.1", "0.01749891", "0", "1"], ["85837.6", "0.0008", "0", "2"], ["85836.8", "0.00039892", "0", "1"], ["85836", "0", "0", "0"], ["85829.6", "0.002096", "0", "1"], ["85710.3", "0.34924351", "0", "1"]], "ts": "1742458822403", "checksum": 1629825208, "seqId": 49818453673, "prevSeqId": 49818453580}], "record_time": 1742458822.876617}
{"arg": {"channel": "books", "instId": "BTC-USDT"}, "action": "update", "data": [{"asks": [["85877.8", "0.00214276", "0", "2"], ["85878.2", "0.01145", "0", "1"], ["85887.6", "0.07639537", "0", "6"], ["85888", "0.14399772", "0", "3"], ["85904.8", "0.23287585", "0", "1"], ["85905.3", "0", "0", "0"], ["86011.2", "0", "0", "0"]], "bids": [["85866.1", "0", "0", "0"], ["85864.8", "0.01184", "0", "1"], ["85861.4", "0.01224197", "0", "1"], ["85860.5", "0.03628425", "0", "1"], ["85858.3", "0.03552", "0", "1"], ["85848.2", "0.23287342", "0", "1"], ["85776", "0.00570026", "0", "1"], ["85770.7", "0.00570026", "0", "1"], ["85712.2", "0", "0", "0"], ["85712.1", "0", "0", "0"], ["85711.2", "0", "0", "0"], ["85711", "0", "0", "0"], ["85710.3", "0", "0", "0"]], "ts": "1742458822503", "checksum": 715351881, "seqId": 49818453722, "prevSeqId": 49818453673}], "record_time": 1742458822.97734}
{"arg": {"channel": "books", "instId": "BTC-USDT"}, "action": "update", "data": [{"asks": [["85876.5", "0", "0", "0"], ["85876.7", "0.001", "0", "2"], ["85877.2", "0", "0", "0"], ["85877.7", "0.00582169", "0", "1"], ["85884.5", "0.09010655", "0", "1"], ["85888", "0.01372672", "0", "2"], ["85889.4", "0.47741863", "0", "3"], ["85889.5", "0.10139021", "0", "2"], ["85896.4", "0.00564811", "0", "1"], ["85896.5", "0.10427937", "0", "1"], ["85903.4", "0", "0", "0"], ["85903.5", "0.1743204", "0", "1"], ["85904.5", "0", "0", "0"], ["85904.8", "0", "0", "0"], ["85909.9", "0.23286673", "0", "1"]], "bids": [["85875.9", "0.41179704", "0", "7"], ["85871.4", "0", "0", "0"], ["85870.6", "0.07273192", "0", "1"], ["85870.5", "0.11644041", "0", "1"], ["85870.1", "0", "0", "0"], ["85862.2", "0.0642372", "0", "1"], ["85862.1", "0", "0", "0"], ["85855.2", "0.16220292", "0", "3"], ["85855.1", "0.00001172", "0", "1"], ["85849.2", "0.23286925", "0", "1"], ["85848.2", "0.15630189", "0", "1"], ["85848.1", "0", "0", "0"], ["85824.3", "0.02327492", "0", "2"], ["85796.1", "0.01115851", "0", "1"], ["85712.6", "0", "0", "0"]], "ts": "1742458822603", "checksum": 886155954, "seqId": 49818453778, "prevSeqId": 49818453722}], "record_time": 1742458823.078032}
{"arg": {"channel": "books", "instId": "BTC-USDT"}, "action": "update", "data": [{"asks": [["85876", "0.97852884", "0", "11"], ["85876.5", "0.001", "0", "2"], ["85876.7", "0", "0", "0"], ["85877.7", "0", "0", "0"], ["85877.8", "0.00428552", "0", "4"], ["85878.4", "0.00582167", "0", "1"], ["85888.4", "0.13430253", "0", "2"], ["85904.4", "0.00129001", "0", "2"], ["85905.9", "0.23287119", "0", "1"], ["85909.6", "0", "0", "0"], ["85909.9", "0", "0", "0"], ["85910.4", "0.0008", "0", "2"], ["85911.2", "0.0004", "0", "1"]], "bids": [["85849.2", "0", "0", "0"], ["85848.3", "0.23287119", "0", "1"], ["85837.6", "0", "0", "0"], ["85836.8", "0.00079892", "0", "2"], ["85836", "0.00039893", "0", "1"], ["85824.3", "0", "0", "0"], ["85796.1", "0.03443319", "0", "3"], ["85712.6", "0.0814", "0", "1"]], "ts": "1742458822703", "checksum": 192470033, "seqId": 49818453820, "prevSeqId": 49818453778}], "record_time": 1742458823.181013}
{"arg": {"channel": "books", "instId": "BTC-USDT"}, "action": "update", "data": [{"asks": [["85876.4", "0.0005", "0", "1"], ["85876.5", "0.0005", "0", "1"], ["85877.8", "0.00642829", "0", "6"], ["85884.5", "0.02935655", "0", "1"], ["85884.6", "0.00007591", "0", "2"], ["85905.9", "0", "0", "0"], ["85909.9", "0.23286629", "0", "1"], ["86011.1", "0", "0", "0"]], "bids": [["85875.9", "0.41183704", "0", "11"], ["85849.2", "0.23286629", "0", "1"], ["85848.3", "0", "0", "0"]], "ts": "1742458822803", "checksum": -1314817503, "seqId": 49818453839, "prevSeqId": 49818453820}], "record_time": 1742458823.277873}
{"arg": {"channel": "books", "instId": "BTC-USDT"}, "action": "update", "data": [{"asks": [["85876", "0.83477375", "0", "10"], ["85877.4", "0.05695617", "0", "2"], ["85888.4", "0.00403253", "0", "1"], ["85904.4", "0.00001501", "0", "1"], ["85909.6", "0.0008", "0", "2"], ["85910.4", "0.0004", "0", "1"], ["85911.2", "0", "0", "0"]], "bids": [["85875.9", "0.55559213", "0", "12"], ["85872.9", "0.11643719", "0", "1"], ["85871.8", "0", "0", "0"], ["85871.5", "0.0005", "0", "1"], ["85870.6", "0.0377998", "0", "1"], ["85870.5", "0", "0", "0"], ["85837.6", "0.0008", "0", "2"], ["85836.8", "0.00039892", "0", "1"], ["85836", "0", "0", "0"]], "ts": "1742458822903", "checksum": 1485948840, "seqId": 49818453893, "prevSeqId": 49818453839}], "record_time": 1742458823.376412}
{"arg": {"channel": "books", "instId": "BTC-USDT"}, "action": "update", "data": [{"asks": [["85876", "0.81877375", "0", "9"], ["85877.3", "0.00582166", "0", "1"], ["85878.2", "0", "0", "0"], ["85878.4", "0", "0", "0"], ["85880.9", "0.01200467", "0", "2"], ["85884.5", "0.08643698", "0", "2"], ["85884.6", "0.20257591", "0", "3"], ["85888.6", "0.19807764", "0", "3"], ["85909.6", "0", "0", "0"], ["85910.4", "0.0008", "0", "2"], ["85911.2", "0.0004", "0", "1"], ["86011.1", "0.00006532", "0", "1"]], "bids": [["85875.9", "0.55557113", "0", "11"], ["85872.9", "0", "0", "0"], ["85872", "0.0567", "0", "1"], ["85871.9", "0.0005", "0", "1"], ["85871.5", "0", "0", "0"], ["85871.2", "0.0005", "0", "1"], ["85870.6", "0", "0", "0"], ["85870", "0.17314105", "0", "2"], ["85867.5", "0.01184", "0", "1"], ["85864.9", "0.28116874", "0", "1"], ["85864.8", "0", "0", "0"], ["85864.2", "0", "0", "0"], ["85862.8", "0.52402", "0", "2"], ["85862.3", "0.18677758", "0", "2"], ["85858.7", "0.2025", "0", "1"], ["85849.1", "0", "0", "0"], ["85846.8", "0.11017586", "0", "2"], ["85837.6", "0", "0", "0"], ["85836.8", "0.00079892", "0", "2"], ["85836", "0.00039893", "0", "1"], ["85819.1", "0.30658949", "0", "1"], ["85816.8", "0", "0", "0"], ["85712.2", "0.00003896", "0", "1"], ["85712.1", "0.00011161", "0", "1"], ["85711.2", "0.01064", "0", "1"]], "ts": "1742458823003", "checksum": -1338695359, "seqId": 49818453957, "prevSeqId": 49818453893}], "record_time": 1742458823.477236}
{"arg": {"channel": "books", "instId": "BTC-USDT"}, "action": "update", "data": [{"asks": [["85876.4", "0", "0", "0"], ["85876.6", "0.0005", "0", "1"], ["85903.9", "0.0043665", "0", "1"], ["85909.8", "0.30164966", "0", "1"], ["85916", "0", "0", "0"], ["85916.8", "0.07999999", "0", "2"], ["85917.6", "0.03999999", "0", "1"], ["86010.5", "0", "0", "0"], ["86011.1", "0", "0", "0"]], "bids": [["85875.9", "0.55692163", "0", "13"], ["85872.1", "0.00160711", "0", "2"], ["85871.9", "0", "0", "0"], ["85871.7", "0.0005", "0", "1"], ["85871.2", "0", "0", "0"], ["85870.1", "0.07628411", "0", "1"], ["85849.4", "1.61233983", "0", "1"], ["85848.3", "0.47621878", "0", "1"], ["85847.1", "0", "0", "0"], ["85843", "1", "0", "1"], ["85828.6", "0", "0", "0"], ["85828", "0", "0", "0"], ["85827.2", "0.12929981", "0", "5"], ["85826.4", "0.053", "0", "2"], ["85824.3", "0.02327492", "0", "2"], ["85822.8", "0.49540065", "0", "1"], ["85819.4", "2.97385142", "0", "1"], ["85797.8", "0.1869152", "0", "2"], ["85796.1", "0.01115851", "0", "1"], ["85768.3", "1.0632027", "0", "3"], ["85712.1", "0", "0", "0"], ["85711.2", "0", "0", "0"]], "ts": "1742458823103", "checksum": -579463245, "seqId": 49818454016, "prevSeqId": 49818453957}], "record_time": 1742458823.577135}
{"arg": {"channel": "books", "instId": "BTC-USDT"}, "action": "update", "data": [{"asks": [["85876.5", "0", "0", "0"], ["85876.6", "0.001", "0", "2"], ["85877.3", "0", "0", "0"], ["85877.7", "0.0058217", "0", "1"], ["85884.5", "0.02935655", "0", "1"], ["85884.6", "0.00007591", "0", "2"], ["85903.9", "0", "0", "0"], ["85915", "1", "0", "1"], ["85916", "0.08", "0", "2"], ["85916.8", "0.03999999", "0", "1"], ["85917.6", "0", "0", "0"], ["86010.5", "0.03", "0", "1"]], "bids": [["85872.1", "0.00210711", "0", "3"], ["85871.7", "0", "0", "0"], ["85864.2", "0.34924351", "0", "1"], ["85840", "0.10082147", "0", "3"], ["85828", "0.026", "0", "2"], ["85827.2", "0.11629981", "0", "4"], ["85826.4", "0.04", "0", "1"], ["85824.3", "0", "0", "0"], ["85796.1", "0.03443319", "0", "3"]], "ts": "1742458823203", "checksum": -30609779, "seqId": 49818454046, "prevSeqId": 49818454016}], "record_time": 1742458823.67654}
{"arg": {"channel": "books", "instId": "BTC-USDT"}, "action": "update", "data": [{"asks": [["85876.5", "0.001", "0", "2"], ["85876.6", "0", "0", "0"], ["85884.6", "0.20257591", "0", "3"], ["85905.9", "0.003831", "0", "1"], ["85909.7", "0.23286208", "0", "1"], ["85909.9", "0", "0", "0"], ["85911", "0.2", "0", "1"], ["85915", "0", "0", "0"], ["86010.5", "0", "0", "0"]], "bids": [["85872.1", "0.00160711", "0", "2"], ["85870.5", "0.0005", "0", "1"], ["85849.5", "0.23286497", "0", "1"], ["85849.2", "0", "0", "0"], ["85843", "0", "0", "0"], ["85840", "0.00082147", "0", "2"]], "ts": "1742458823303", "checksum": 859254884, "seqId": 49818454090, "prevSeqId": 49818454046}], "record_time": 1742458823.778312}
{"arg": {"channel": "books", "instId": "BTC-USDT"}, "action": "update", "data": [{"asks": [["85876.4", "0.001", "0", "2"], ["85876.5", "0", "0", "0"], ["85884.6", "0.00007591", "0", "2"]], "bids": [["85840.7", "0.01749891", "0", "1"], ["85768.3", "1.04570379", "0", "2"], ["85712.2", "0", "0", "0"]], "ts": "1742458823403", "checksum": -1003026351, "seqId": 49818454124, "prevSeqId": 49818454090}], "record_time": 1742458823.877353}
{"arg": {"channel": "books", "instId": "BTC-USDT"}, "action": "update", "data": [{"asks": [["85877.3", "0.00582165", "0", "1"], ["85877.7", "0", "0", "0"], ["85884.5", "0.08643698", "0", "2"], ["85884.6", "0.20257591", "0", "3"], ["85887.6", "0.07406675", "0", "5"], ["85905.9", "0", "0", "0"], ["85909.6", "0.0008", "0", "2"], ["85910.4", "0.0004", "0", "1"], ["85911.2", "0", "0", "0"], ["85948.7", "0", "0", "0"], ["86010.5", "0.03", "0", "1"], ["86011.1", "0.00006532", "0", "1"]], "bids": [["85875.9", "0.55568113", "0", "12"], ["85872.1", "0.00210711", "0", "3"], ["85870.5", "0", "0", "0"], ["85853.1", "0.17042613", "0", "1"], ["85837.6", "0.0008", "0", "2"], ["85836.8", "0.00039892", "0", "1"], ["85836", "0", "0", "0"], ["85780.2", "0", "0", "0"], ["85712.2", "0.00003896", "0", "1"], ["85712.1", "0.00011161", "0", "1"]], "ts": "1742458823503", "checksum": -986345945, "seqId": 49818454191, "prevSeqId": 49818454124}], "record_time": 1742458823.976188}
{"arg": {"channel": "books", "instId": "BTC-USDT"}, "action": "update", "data": [{"asks": [["85887.6", "0.07639537", "0", "6"], ["85897.6", "0", "0", "0"], ["85927.6", "0", "0", "0"], ["85941.6", "0", "0", "0"], ["86011.2", "0.00200313", "0", "2"], ["86012.1", "0.00001172", "0", "1"], ["86012.5", "0.1755432", "0", "1"]], "bids": [["85875.9", "0.55569113", "0", "13"], ["85853.1", "0.17275568", "0", "2"], ["85849.4", "0", "0", "0"], ["85819.4", "0", "0", "0"], ["85773.1", "0", "0", "0"], ["85711.2", "0.01064", "0", "1"], ["85711", "0.116533", "0", "1"], ["85710.3", "0.34924351", "0", "1"]], "ts": "1742458823603", "checksum": 1465838218, "seqId": 49818454230, "prevSeqId": 49818454191}], "record_time": 1742458824.076389}
{"arg": {"channel": "books", "instId": "BTC-USDT"}, "action": "update", "data": [{"asks": [["85876", "0.82459375", "0", "10"], ["85876.4", "0", "0", "0"], ["85876.6", "0.001", "0", "2"], ["85897.5", "0.05956232", "0", "1"], ["85900", "2.02911514", "0", "12"], ["85927.4", "0.20583189", "0", "2"], ["85930", "2.87198008", "0", "3"], ["85954.6", "0.07179676", "0", "6"]], "bids": [["85872.1", "0.00110711", "0", "1"], ["85872", "0.0572", "0", "2"], ["85870.3", "0.0005", "0", "1"], ["85849.4", "1.54235775", "0", "1"], ["85840.7", "0", "0", "0"], ["85819.4", "2.83726196", "0", "1"], ["85786.1", "0.27244136", "0", "2"], ["85768.4", "0.01749891", "0", "1"], ["85711.2", "0", "0", "0"], ["85711", "0", "0", "0"], ["85710.3", "0", "0", "0"]], "ts": "1742458823703", "checksum": -1302296645, "seqId": 49818454265, "prevSeqId": 49818454230}], "record_time": 1742458824.175927}
{"arg": {"channel": "books", "instId": "BTC-USDT"}, "action": "update", "data": [{"asks": [["85903.9", "0.0010455", "0", "1"], ["85911", "0", "0", "0"]], "bids": [["85875.9", "0.55978313", "0", "14"], ["85872.1", "0.00210711", "0", "3"], ["85872", "0.0567", "0", "1"], ["85870.3", "0", "0", "0"], ["85711.2", "0.01064", "0", "1"]], "ts": "1742458823803", "checksum": -612101811, "seqId": 49818454293, "prevSeqId": 49818454265}], "record_time": 1742458824.275911}
{"arg": {"channel": "books", "instId": "BTC-USDT"}, "action": "update", "data": [{"asks": [["85954.5", "0.11876907", "0", "2"], ["85954.6", "0.14160109", "0", "7"], ["85954.8", "0", "0", "0"], ["86013.4", "0.0000412", "0", "3"]], "bids": [["85840.7", "0.01749891", "0", "1"], ["85824.3", "0.02327492", "0", "2"], ["85796.1", "0.01115851", "0", "1"], ["85786.1", "0.34238272", "0", "3"], ["85768.4", "0", "0", "0"], ["85711.2", "0", "0", "0"]], "ts": "1742458823903", "checksum": -612101811, "seqId": 49818454317, "prevSeqId": 49818454293}], "record_time": 1742458824.461872}
{"arg": {"channel": "books", "instId": "BTC-USDT"}, "action": "update", "data": [{"asks": [["85876.5", "0.001", "0", "2"], ["85876.6", "0", "0", "0"], ["85884.5", "0.0857384", "0", "2"], ["85898.6", "0.80256953", "0", "1"], ["85909.7", "0.23286554", "0", "1"], ["85927.4", "1.18003079", "0", "3"], ["85932", "0", "0", "0"], ["85932.1", "0.00002919", "0", "1"], ["85938", "0", "0", "0"], ["85941", "0.00883419", "0", "1"], ["85941.9", "0", "0", "0"], ["85954.6", "0.07179676", "0", "6"]], "bids": [["85872.1", "0.00160711", "0", "2"], ["85871.7", "0.0005", "0", "1"], ["85849.6", "0.23297715", "0", "2"], ["85849.5", "0.9389261", "0", "1"], ["85848.3", "0", "0", "0"], ["85822.9", "0", "0", "0"], ["85822.8", "1.3311811", "0", "2"], ["85822.1", "0.01793059", "0", "1"], ["85791.3", "0.12545875", "0", "2"], ["85786.1", "0.27244136", "0", "2"], ["85768.3", "0.02673767", "0", "1"], ["85766.8", "0.06853613", "0", "2"], ["85750", "0", "0", "0"], ["85748.4", "0.17930592", "0", "1"]], "ts": "1742458824103", "checksum": 138722695, "seqId": 49818454398, "prevSeqId": 49818454317}], "record_time": 1742458824.577277}
{"arg": {"channel": "books", "instId": "BTC-USDT"}, "action": "update", "data": [{"asks": [["85876", "0.82109894", "0", "9"], ["85899.9", "0.01840789", "0", "3"], ["85905.6", "0.003492", "0", "1"], ["85938", "0.00005937", "0", "1"], ["85954.6", "0.14160109", "0", "7"], ["86012.5", "0", "0", "0"], ["86013.4", "0", "0", "0"]], "bids": [["85872.1", "0.00210711", "0", "3"], ["85871.7", "0", "0", "0"], ["85824.3", "0", "0", "0"], ["85796.1", "0.03443319", "0", "3"], ["85786.1", "0.34238272", "0", "3"], ["85711.2", "0.01064", "0", "1"], ["85711", "0.116533", "0", "1"]], "ts": "1742458824203", "checksum": 301171230, "seqId": 49818454431, "prevSeqId": 49818454398}], "record_time": 1742458824.680385}
