{"arg": {"channel": "books", "instId": "BTC-USDT"}, "action": "update", "data": [{"asks": [], "bids": [["84023", "0", "0", "0"], ["83921.3", "0.0016853", "0", "2"]], "ts": "1742555177704", "checksum": -1180262457, "seqId": 49927501902, "prevSeqId": 49927501899}], "record_time": 1742555177.705352, "EXCHANGE": "OKX"}
{"arg": {"channel": "books", "instId": "BTC-USDT"}, "action": "update", "data": [{"asks": [["84084.3", "0.53124069", "0", "1"], ["84087.7", "1", "0", "1"], ["84088.4", "0.25379035", "0", "1"], ["84089.4", "0", "0", "0"]], "bids": [], "ts": "1742555177804", "checksum": -1180262457, "seqId": 49927501910, "prevSeqId": 49927501902}], "record_time": 1742555177.806558, "EXCHANGE": "OKX"}
{"arg": {"channel": "books", "instId": "BTC-USDT"}, "action": "update", "data": [{"asks": [["84084.3", "0.27054554", "0", "1"], ["84087.7", "0", "0", "0"], ["84088.4", "0.54343251", "0", "2"], ["84089", "1", "0", "1"], ["84157.4", "0.0001965", "0", "1"], ["84166", "0", "0", "0"], ["84175.6", "0.001965", "0", "1"], ["84191.8", "0", "0", "0"]], "bids": [["84070", "0.33809551", "0", "7"]], "ts": "1742555177904", "checksum": 1832261471, "seqId": 49927501922, "prevSeqId": 49927501910}], "record_time": 1742555177.905785, "EXCHANGE": "OKX"}
{"arg": {"channel": "books", "instId": "BTC-USDT"}, "action": "update", "data": [{"asks": [["84080.8", "0.005", "0", "1"], ["84090.8", "0.005", "0", "1"], ["84242.5", "0", "0", "0"], ["84242.6", "0", "0", "0"]], "bids": [["84068.2", "0.005", "0", "1"], ["84058.1", "0.005", "0", "1"], ["84035.1", "0.23801212", "0", "1"], ["84033.7", "0", "0", "0"], ["83921.7", "0", "0", "0"], ["83921.3", "0", "0", "0"]], "ts": "1742555178004", "checksum": 1564697413, "seqId": 49927501928, "prevSeqId": 49927501922}], "record_time": 1742555178.006377, "EXCHANGE": "OKX"}
{"arg": {"channel": "books", "instId": "BTC-USDT"}, "action": "update", "data": [{"asks": [["84086.8", "0", "0", "0"], ["84096.8", "0.83725821", "0", "1"], ["84123", "0.42478133", "0", "1"]], "bids": [["84066.5", "0.011901", "0", "1"], ["84035.1", "0", "0", "0"], ["84033.7", "0.23801286", "0", "1"], ["84032.6", "0.12427043", "0", "1"], ["84021.4", "0.01188695", "0", "1"], ["84021.1", "0.01832693", "0", "1"], ["83922.4", "0", "0", "0"], ["83922", "0", "0", "0"]], "ts": "1742555178104", "checksum": -1441658285, "seqId": 49927501938, "prevSeqId": 49927501928}], "record_time": 1742555178.106025, "EXCHANGE": "OKX"}
{"arg": {"channel": "books", "instId": "BTC-USDT"}, "action": "update", "data": [{"asks": [["84110", "2.44", "0", "3"]], "bids": [["84057", "0.005", "0", "2"], ["84033", "1", "0", "1"], ["83923", "0", "0", "0"]], "ts": "1742555178204", "checksum": -1441658285, "seqId": 49927501943, "prevSeqId": 49927501938}], "record_time": 1742555178.204256, "EXCHANGE": "OKX"}
{"arg": {"channel": "books", "instId": "BTC-USDT"}, "action": "update", "data": [{"asks": [], "bids": [["84033.8", "0.2422225", "0", "2"], ["84033.7", "0", "0", "0"], ["83923", "0.00001987", "0", "1"]], "ts": "1742555178304", "checksum": -1441658285, "seqId": 49927501958, "prevSeqId": 49927501943}], "record_time": 1742555178.304956, "EXCHANGE": "OKX"}
{"arg": {"channel": "books", "instId": "BTC-USDT"}, "action": "update", "data": [{"asks": [["84092.3", "0.23801145", "0", "1"], ["84092.5", "0.37181968", "0", "6"], ["84150.7", "0.07130066", "0", "1"], ["84232", "0.00172464", "0", "3"]], "bids": [["84070", "0.34330586", "0", "8"], ["84058.8", "0.52850581", "0", "2"], ["84053.3", "0.04", "0", "1"], ["84035.1", "0.23801145", "0", "1"], ["84033.8", "0.00420994", "0", "1"], ["83985.8", "0.07147328", "0", "2"], ["83923", "0", "0", "0"]], "ts": "1742555178404", "checksum": -2104911286, "seqId": 49927501990, "prevSeqId": 49927501958}], "record_time": 1742555178.405196, "EXCHANGE": "OKX"}
{"arg": {"channel": "books", "instId": "BTC-USDT"}, "action": "update", "data": [{"asks": [["84080.8", "0.01", "0", "2"], ["84090.8", "0.01", "0", "2"], ["84112.8", "0.08", "0", "2"], ["84113.6", "0.21821721", "0", "2"], ["84114.4", "0.52861", "0", "1"], ["84150.7", "0.14260132", "0", "2"], ["84242.4", "0", "0", "0"]], "bids": [["84068.2", "0.01", "0", "2"], ["84058.2", "0.005", "0", "1"], ["83985.8", "0.14291391", "0", "3"], ["83924.2", "0", "0", "0"]], "ts": "1742555178504", "checksum": -341928059, "seqId": 49927502008, "prevSeqId": 49927501990}], "record_time": 1742555178.505169, "EXCHANGE": "OKX"}
{"arg": {"channel": "books", "instId": "BTC-USDT"}, "action": "update", "data": [{"asks": [], "bids": [["84033", "0", "0", "0"], ["83924.2", "0.000015", "0", "1"]], "ts": "1742555178604", "checksum": -341928059, "seqId": 49927502009, "prevSeqId": 49927502008}], "record_time": 1742555178.605308, "EXCHANGE": "OKX"}
{"arg": {"channel": "books", "instId": "BTC-USDT"}, "action": "update", "data": [{"asks": [], "bids": [["84070", "0.42755129", "0", "9"], ["84051.1", "0", "0", "0"], ["83923", "0.00001987", "0", "1"]], "ts": "1742555178704", "checksum": 1296384292, "seqId": 49927502014, "prevSeqId": 49927502009}], "record_time": 1742555178.704852, "EXCHANGE": "OKX"}
{"arg": {"channel": "books", "instId": "BTC-USDT"}, "action": "update", "data": [{"asks": [], "bids": [["84060.1", "0", "0", "0"], ["84004.1", "0", "0", "0"], ["83995.8", "0", "0", "0"], ["83980.6", "0.00001197", "0", "1"], ["83952.7", "0.00001065", "0", "1"], ["83922.4", "0.03", "0", "1"], ["83922", "0.00001197", "0", "1"], ["83921.7", "0.0535785", "0", "1"]], "ts": "1742555178804", "checksum": 965767205, "seqId": 49927502025, "prevSeqId": 49927502014}], "record_time": 1742555178.805618, "EXCHANGE": "OKX"}
{"arg": {"channel": "books", "instId": "BTC-USDT"}, "action": "update", "data": [{"asks": [], "bids": [["84070", "0.42231129", "0", "8"], ["83980.6", "0.00017445", "0", "2"]], "ts": "1742555178904", "checksum": -128372100, "seqId": 49927502031, "prevSeqId": 49927502025}], "record_time": 1742555178.905331, "EXCHANGE": "OKX"}
{"arg": {"channel": "books", "instId": "BTC-USDT"}, "action": "update", "data": [{"asks": [], "bids": [["84041.8", "0.17842", "0", "1"], ["84004.5", "0.0023564", "0", "1"], ["83995.3", "0.01902248", "0", "1"], ["83952.4", "0.00358994", "0", "1"], ["83923", "0", "0", "0"], ["83922.4", "0", "0", "0"], ["83922", "0", "0", "0"], ["83921.7", "0", "0", "0"]], "ts": "1742555179004", "checksum": -128372100, "seqId": 49927502037, "prevSeqId": 49927502031}], "record_time": 1742555179.005216, "EXCHANGE": "OKX"}
{"arg": {"channel": "books", "instId": "BTC-USDT"}, "action": "update", "data": [{"asks": [["84120.3", "0.07450232", "0", "1"], ["84242", "0", "0", "0"]], "bids": [["84060.5", "0.005661", "0", "1"], ["84035.1", "0", "0", "0"], ["84033.7", "0.23801247", "0", "1"], ["84020.4", "0.26724268", "0", "2"], ["83924.2", "0", "0", "0"]], "ts": "1742555179104", "checksum": -798377100, "seqId": 49927502042, "prevSeqId": 49927502037}], "record_time": 1742555179.112549, "EXCHANGE": "OKX"}
{"arg": {"channel": "books", "instId": "BTC-USDT"}, "action": "update", "data": [{"asks": [["84070.5", "0.5", "0", "1"], ["84241", "0", "0", "0"]], "bids": [["84060.5", "0", "0", "0"], ["83924.2", "0.000015", "0", "1"]], "ts": "1742555179304", "checksum": -497876864, "seqId": 49927502047, "prevSeqId": 49927502042}], "record_time": 1742555179.304716, "EXCHANGE": "OKX"}
{"arg": {"channel": "books", "instId": "BTC-USDT"}, "action": "update", "data": [{"asks": [["84070.4", "0.20119615", "0", "1"], ["84071.9", "0", "0", "0"], ["84109.2", "0.47358537", "0", "1"], ["84110", "1.24", "0", "1"]], "bids": [["84070", "0.34294586", "0", "8"], ["84060.3", "0.0090105", "0", "2"]], "ts": "1742555179404", "checksum": 723447069, "seqId": 49927502066, "prevSeqId": 49927502047}], "record_time": 1742555179.406964, "EXCHANGE": "OKX"}
{"arg": {"channel": "books", "instId": "BTC-USDT"}, "action": "update", "data": [{"asks": [["84087.1", "0", "0", "0"], ["84241", "0.00001501", "0", "1"]], "bids": [["84041.8", "0", "0", "0"], ["83923", "0.00001987", "0", "1"]], "ts": "1742555179504", "checksum": 723447069, "seqId": 49927502068, "prevSeqId": 49927502066}], "record_time": 1742555179.507738, "EXCHANGE": "OKX"}
{"arg": {"channel": "books", "instId": "BTC-USDT"}, "action": "update", "data": [{"asks": [["84102.9", "0.00424784", "0", "1"], ["84112.8", "0", "0", "0"], ["84113.6", "0.25821721", "0", "3"], ["84114.4", "0.56860999", "0", "2"], ["84142.2", "0", "0", "0"], ["84177.6", "0.1", "0", "1"]], "bids": [["84037.6", "0.33020846", "0", "2"], ["84036.8", "0.106", "0", "4"], ["84036", "0.054784", "0", "3"], ["83936.8", "0.01189901", "0", "2"]], "ts": "1742555179604", "checksum": 723447069, "seqId": 49927502088, "prevSeqId": 49927502068}], "record_time": 1742555179.608809, "EXCHANGE": "OKX"}
{"arg": {"channel": "books", "instId": "BTC-USDT"}, "action": "update", "data": [{"asks": [["84096.8", "0", "0", "0"], ["84096.9", "0", "0", "0"], ["84126.2", "0", "0", "0"], ["84126.3", "0", "0", "0"], ["84177.6", "0.23960232", "0", "2"], ["84178.1", "0.1", "0", "1"], ["84178.2", "0", "0", "0"], ["84242", "0.0000185", "0", "1"], ["84242.4", "0.00469113", "0", "3"], ["84242.5", "0.00011938", "0", "1"], ["84242.6", "0.00419183", "0", "1"], ["84242.8", "0.03", "0", "1"]], "bids": [["84044.8", "0.23663805", "0", "2"], ["84044.7", "0", "0", "0"], ["84016.6", "0.74707063", "0", "2"], ["84015.3", "0", "0", "0"], ["83992.6", "0.67430932", "0", "1"], ["83922.4", "0.03", "0", "1"]], "ts": "1742555179704", "checksum": 723447069, "seqId": 49927502104, "prevSeqId": 49927502088}], "record_time": 1742555179.704935, "EXCHANGE": "OKX"}
{"arg": {"channel": "books", "instId": "BTC-USDT"}, "action": "update", "data": [{"asks": [["84086.5", "0.0000315", "0", "1"], ["84097.2", "1.7057673", "0", "2"], ["84105.6", "0", "0", "0"], ["84126.7", "2.89619427", "0", "1"], ["84130.4", "0.01774536", "0", "1"], ["84242.6", "0", "0", "0"], ["84242.8", "0", "0", "0"]], "bids": [["84044.8", "1.8389454", "0", "2"], ["84040.7", "0.01774536", "0", "1"], ["84037.6", "0.41020846", "0", "4"], ["84036.8", "0.066", "0", "3"], ["84036", "0.014784", "0", "2"], ["84015.3", "2.8993699", "0", "1"], ["83976.5", "0", "0", "0"], ["83922.4", "0", "0", "0"]], "ts": "1742555179804", "checksum": 723447069, "seqId": 49927502123, "prevSeqId": 49927502104}], "record_time": 1742555179.806238, "EXCHANGE": "OKX"}
{"arg": {"channel": "books", "instId": "BTC-USDT"}, "action": "update", "data": [{"asks": [["84070.1", "1.58811647", "0", "18"], ["84072", "0.0146", "0", "1"], ["84073.1", "0", "0", "0"], ["84073.6", "0.02530935", "0", "1"], ["84077", "0", "0", "0"], ["84078.6", "0.08991011", "0", "1"], ["84079.9", "0.05508771", "0", "2"], ["84082.5", "0.03124226", "0", "1"], ["84083", "0.03165901", "0", "1"], ["84083.1", "0.03100897", "0", "1"], ["84083.2", "0.03155056", "0", "1"], ["84083.3", "0", "0", "0"], ["84083.7", "0", "0", "0"], ["84083.9", "0", "0", "0"], ["84085.9", "0.04", "0", "1"], ["84086.8", "0.0118986", "0", "1"], ["84088.3", "1.1249", "0", "2"], ["84088.4", "0.25379035", "0", "1"], ["84089", "0", "0", "0"], ["84089.4", "0.23801759", "0", "1"], ["84089.5", "0.06745555", "0", "2"], ["84090.2", "0", "0", "0"], ["84090.3", "0", "0", "0"], ["84091.8", "0.03609622", "0", "2"], ["84091.9", "0.03488717", "0", "1"], ["84092.3", "0", "0", "0"], ["84092.4", "0", "0", "0"], ["84092.5", "0.33827236", "0", "5"], ["84093", "0", "0", "0"], ["84096.5", "0.15396772", "0", "2"], ["84097.3", "0", "0", "0"], ["84097.7", "0", "0", "0"], ["84098.5", "0.06610138", "0", "1"], ["84099", "0.06945505", "0", "1"], ["84099.1", "0", "0", "0"], ["84099.7", "0", "0", "0"], ["84100.5", "0.06454669", "0", "1"], ["84101.2", "0", "0", "0"], ["84125.7", "0.0118877", "0", "1"], ["84132.1", "0.01188767", "0", "1"], ["84156.3", "0.01608782", "0", "2"], ["84159.2", "0.04188754", "0", "2"], ["84160.8", "0.02629911", "0", "3"], ["84162", "0.01188753", "0", "1"], ["84178.4", "0.01188745", "0", "1"], ["84234.2", "0", "0", "0"], ["84238.3", "0", "0", "0"]], "bids": [["84070", "0.12142326", "0", "6"], ["84067.7", "0", "0", "0"], ["84065.6", "0", "0", "0"], ["84061", "0.11901832", "0", "1"], ["84059.7", "0", "0", "0"], ["84058.8", "0.23885768", "0", "1"], ["84058.4", "0", "0", "0"], ["84056.6", "0.0134", "0", "1"], ["84056", "0", "0", "0"], ["84055.8", "0.04006", "0", "2"], ["84055.7", "0.00001197", "0", "1"], ["84055.6", "0.138", "0", "3"], ["84055.2", "0.03460477", "0", "1"], ["84055", "0.03407311", "0", "1"], ["84054.5", "0", "0", "0"], ["84054.4", "0.03162825", "0", "1"], ["84053.8", "0.03254499", "0", "1"], ["84050.1", "0.04021", "0", "1"], ["84050", "0.01818629", "0", "4"], ["84049", "0", "0", "0"], ["84048.2", "0.0350349", "0", "1"], ["84047.5", "0.03405918", "0", "1"], ["84046.9", "0", "0", "0"], ["84046.3", "0.03494825", "0", "1"], ["84045.7", "0.08820213", "0", "2"], ["84044.3", "0.35579296", "0", "1"], ["84042", "0.11235012", "0", "2"], ["84041.2", "0.06967476", "0", "1"], ["84039.6", "0", "0", "0"], ["84039", "0.06236597", "0", "1"], ["84038.8", "0", "0", "0"], ["84038.2", "0.0214248", "0", "1"], ["84038.1", "0.06841542", "0", "1"], ["84037.5", "0.12099829", "0", "2"], ["84033.7", "0.23801759", "0", "1"], ["84022.1", "0", "0", "0"], ["84021.5", "0.11890903", "0", "1"], ["84021.4", "0", "0", "0"], ["84021.3", "0", "0", "0"], ["84020.5", "0", "0", "0"], ["84020.3", "0.2025", "0", "1"], ["84014", "0.34182", "0", "2"], ["84012.2", "0.17821722", "0", "1"], ["84008.9", "0.000015", "0", "1"], ["84000.6", "0", "0", "0"], ["83995.1", "0", "0", "0"], ["83988.2", "0", "0", "0"], ["83981.8", "0", "0", "0"], ["83980.5", "0", "0", "0"], ["83979.7", "0.11878326", "0", "1"], ["83977.6", "0.03", "0", "1"], ["83975.2", "0", "0", "0"], ["83963.3", "0.0116003", "0", "2"], ["83955.8", "0.02377394", "0", "2"], ["83948.2", "0.01188745", "0", "1"], ["83936.1", "0.01814076", "0", "3"], ["83931.4", "0.01188712", "0", "1"], ["83922.4", "0.04188747", "0", "2"], ["83922", "0.00001197", "0", "1"], ["83921.7", "0.0535785", "0", "1"], ["83921.3", "0.0016853", "0", "2"], ["83921", "0.00001002", "0", "1"], ["83920", "0.00001096", "0", "1"], ["83919.2", "0.00003545", "0", "1"], ["83918.9", "0.00001197", "0", "1"], ["83917.6", "0.00005114", "0", "1"]], "ts": "1742555179904", "checksum": 870916447, "seqId": 49927502283, "prevSeqId": 49927502123}], "record_time": 1742555179.905134, "EXCHANGE": "OKX"}
{"arg": {"channel": "books", "instId": "BTC-USDT"}, "action": "update", "data": [{"asks": [["84070.1", "1.46078095", "0", "18"], ["84079.9", "0.01651368", "0", "1"], ["84081.4", "0.03407443", "0", "2"], ["84082.2", "0.03369576", "0", "1"], ["84082.3", "0.03187945", "0", "1"], ["84082.4", "0.03136304", "0", "1"], ["84082.5", "0", "0", "0"], ["84083", "0", "0", "0"], ["84083.1", "0", "0", "0"], ["84083.2", "0", "0", "0"], ["84088.2", "0.62619073", "0", "1"], ["84088.4", "0.03164173", "0", "1"], ["84088.5", "0.39103317", "0", "2"], ["84089.4", "0", "0", "0"], ["84089.5", "0", "0", "0"], ["84091.1", "0.06540071", "0", "2"], ["84091.8", "0.00420676", "0", "1"], ["84091.9", "0", "0", "0"], ["84092.4", "0.23801454", "0", "1"], ["84095.4", "0.0638467", "0", "1"], ["84096.5", "0.08991011", "0", "1"], ["84097.8", "0.06393517", "0", "1"], ["84098", "0.0618831", "0", "1"], ["84098.5", "0", "0", "0"], ["84099", "0", "0", "0"], ["84099.8", "0.06448299", "0", "1"], ["84100.5", "0", "0", "0"], ["84105.6", "0.01774536", "0", "1"], ["84120.4", "0.10600126", "0", "3"], ["84125.7", "0.0237754", "0", "2"], ["84130.4", "0", "0", "0"], ["84144.4", "0.01188761", "0", "1"], ["84147.5", "0.0118876", "0", "1"], ["84156.3", "0.00420026", "0", "1"], ["84159.2", "0.03", "0", "1"], ["84162", "0", "0", "0"], ["84178.4", "0", "0", "0"]], "bids": [["84067.5", "0", "0", "0"], ["84058.8", "0.59045458", "0", "2"], ["84058.7", "0.00351178", "0", "1"], ["84055.7", "1.00001197", "0", "2"], ["84055.2", "0", "0", "0"], ["84055", "0", "0", "0"], ["84054.6", "0.2383603", "0", "1"], ["84054.4", "0", "0", "0"], ["84054.3", "0.03129943", "0", "1"], ["84054.1", "0.03301154", "0", "1"], ["84053.8", "0", "0", "0"], ["84053.7", "0.03144733", "0", "1"], ["84052.8", "0.0313193", "0", "1"], ["84050.2", "0.00871968", "0", "1"], ["84048.2", "0", "0", "0"], ["84047.5", "0", "0", "0"], ["84047.1", "0.2397632", "0", "2"], ["84046.5", "0.03491021", "0", "1"], ["84046.3", "0", "0", "0"], ["84045.9", "0.01774536", "0", "1"], ["84045.7", "0.05427", "0", "1"], ["84044.9", "0.03474147", "0", "1"], ["84041.2", "0", "0", "0"], ["84040.7", "0", "0", "0"], ["84040.1", "0.0693284", "0", "2"], ["84039", "0", "0", "0"], ["84038.3", "0.06188442", "0", "1"], ["84038.1", "0", "0", "0"], ["84037.6", "0.33020846", "0", "2"], ["84037.5", "0.05952577", "0", "1"], ["84037.1", "0.06249688", "0", "1"], ["84036.8", "0.106", "0", "4"], ["84036", "0.054784", "0", "3"], ["84035.1", "0.23801454", "0", "1"], ["84033.7", "0", "0", "0"], ["84021.1", "0", "0", "0"], ["84020.5", "0.01832723", "0", "1"], ["83948.3", "0.18327233", "0", "1"], ["83947.7", "0", "0", "0"], ["83918.3", "0.2025", "0", "1"], ["83917.5", "0.11890903", "0", "1"]], "ts": "1742555180004", "checksum": -761149306, "seqId": 49927502376, "prevSeqId": 49927502283}], "record_time": 1742555180.005106, "EXCHANGE": "OKX"}
{"arg": {"channel": "books", "instId": "BTC-USDT"}, "action": "update", "data": [{"asks": [["84079.9", "0.05674877", "0", "2"], ["84097.1", "0.82772326", "0", "1"], ["84121.7", "0.01188754", "0", "1"], ["84125.4", "0", "0", "0"], ["84126.6", "0.86886487", "0", "1"], ["84205.9", "0.01188754", "0", "1"], ["84209.6", "0", "0", "0"], ["84242.4", "0", "0", "0"], ["84242.5", "0", "0", "0"]], "bids": [["84045.6", "0.03473106", "0", "1"], ["84044.3", "0.53421296", "0", "2"], ["84036.8", "0.17213047", "0", "5"], ["84035.1", "0.23801219", "0", "1"], ["84033.6", "0", "0", "0"], ["84032.8", "0.1", "0", "2"], ["84032", "0.05", "0", "1"], ["84020.9", "0", "0", "0"], ["84016.6", "1.51844085", "0", "3"], ["84015.5", "0.01783319", "0", "2"]], "ts": "1742555180104", "checksum": -1885627012, "seqId": 49927502413, "prevSeqId": 49927502376}], "record_time": 1742555180.104805, "EXCHANGE": "OKX"}
{"arg": {"channel": "books", "instId": "BTC-USDT"}, "action": "update", "data": [{"asks": [["84112.8", "0.08", "0", "2"], ["84113.6", "0.21821721", "0", "2"], ["84114.4", "0.52861", "0", "1"], ["84242", "0", "0", "0"]], "bids": [["84070", "0.12157325", "0", "7"], ["84054.6", "0.35369309", "0", "2"], ["84054.5", "0.35685", "0", "1"], ["84052.3", "0.04620804", "0", "2"], ["84021.7", "0.03", "0", "1"], ["83986.4", "0", "0", "0"], ["83980.6", "0.00001197", "0", "1"], ["83980.1", "0.00016248", "0", "1"], ["83917.6", "0", "0", "0"], ["83917.5", "0", "0", "0"]], "ts": "1742555180204", "checksum": 346980042, "seqId": 49927502436, "prevSeqId": 49927502413}], "record_time": 1742555180.20763, "EXCHANGE": "OKX"}
{"arg": {"channel": "books", "instId": "BTC-USDT"}, "action": "update", "data": [{"asks": [["84070.1", "1.46065883", "0", "18"], ["84092.4", "0", "0", "0"], ["84093.1", "0.23801109", "0", "1"], ["84112.8", "0", "0", "0"], ["84113.6", "0.25821721", "0", "3"], ["84114.4", "0.56860999", "0", "2"], ["84242", "0.0000185", "0", "1"]], "bids": [["84057.1", "1", "0", "1"], ["84055.7", "0.00001197", "0", "1"], ["84037.6", "0.41020846", "0", "4"], ["84036.8", "0.13213047", "0", "4"], ["84036", "0.014784", "0", "2"], ["84035.1", "0.23801147", "0", "1"], ["84033.6", "0.1", "0", "2"], ["84033.2", "0", "0", "0"], ["84032.8", "0.05", "0", "1"], ["84032", "0", "0", "0"]], "ts": "1742555180304", "checksum": 921362707, "seqId": 49927502467, "prevSeqId": 49927502436}], "record_time": 1742555180.305312, "EXCHANGE": "OKX"}
{"arg": {"channel": "books", "instId": "BTC-USDT"}, "action": "update", "data": [{"asks": [["84079.9", "0.05497413", "0", "2"], ["84082.2", "0.03457071", "0", "1"], ["84082.3", "0.03365675", "0", "1"], ["84088.5", "0.39107705", "0", "2"], ["84091.1", "0.03109267", "0", "1"], ["84091.2", "0.03385317", "0", "1"], ["84093.1", "0", "0", "0"], ["84094.3", "0.23800944", "0", "1"], ["84099.8", "0.07023233", "0", "1"], ["84106", "1", "0", "1"], ["84107", "0.2", "0", "1"], ["84112.8", "0.08", "0", "2"], ["84113.6", "0.21821721", "0", "2"], ["84114.4", "0.52861", "0", "1"], ["84240", "0", "0", "0"], ["84240.1", "0", "0", "0"], ["84241", "0", "0", "0"], ["84242", "0", "0", "0"]], "bids": [["84070", "0.12329959", "0", "3"], ["84054.3", "0.03410683", "0", "1"], ["84052.8", "0.03328948", "0", "1"], ["84046.5", "0.03284294", "0", "1"], ["84045", "0.09473284", "0", "3"], ["84044.9", "0", "0", "0"], ["84036.8", "0.1274983", "0", "4"], ["84035.9", "0.2380214", "0", "2"], ["84035.1", "0", "0", "0"], ["83917.6", "0.00005114", "0", "1"], ["83917.5", "0.11890903", "0", "1"]], "ts": "1742555180404", "checksum": -145559101, "seqId": 49927502549, "prevSeqId": 49927502467}], "record_time": 1742555180.40551, "EXCHANGE": "OKX"}
{"arg": {"channel": "books", "instId": "BTC-USDT"}, "action": "update", "data": [{"asks": [["84093.1", "0.23801134", "0", "1"], ["84094.3", "0", "0", "0"], ["84192.2", "0.03", "0", "1"], ["84194.2", "0.183208", "0", "1"], ["84206.1", "0.13327598", "0", "1"], ["84207.3", "0", "0", "0"]], "bids": [["84035.9", "0.00001196", "0", "1"], ["84035.1", "0.23801145", "0", "1"], ["83963.3", "0.02319998", "0", "4"], ["83917.5", "0", "0", "0"]], "ts": "1742555180504", "checksum": -145559101, "seqId": 49927502577, "prevSeqId": 49927502549}], "record_time": 1742555180.504647, "EXCHANGE": "OKX"}
{"arg": {"channel": "books", "instId": "BTC-USDT"}, "action": "update", "data": [{"asks": [], "bids": [["84033", "1", "0", "1"], ["83917.6", "0", "0", "0"]], "ts": "1742555180604", "checksum": -145559101, "seqId": 49927502589, "prevSeqId": 49927502577}], "record_time": 1742555180.606348, "EXCHANGE": "OKX"}
{"arg": {"channel": "books", "instId": "BTC-USDT"}, "action": "update", "data": [{"asks": [["84120.4", "0.11788899", "0", "4"], ["84147.5", "0", "0", "0"], ["84192.2", "0", "0", "0"], ["84240", "0.00039685", "0", "3"], ["84240.1", "0.00001005", "0", "1"]], "bids": [["84024", "0.2", "0", "1"], ["83918.3", "0", "0", "0"]], "ts": "1742555180704", "checksum": -145559101, "seqId": 49927502603, "prevSeqId": 49927502589}], "record_time": 1742555180.70694, "EXCHANGE": "OKX"}
{"arg": {"channel": "books", "instId": "BTC-USDT"}, "action": "update", "data": [{"asks": [["84093.1", "0", "0", "0"], ["84094.3", "0.23800959", "0", "1"], ["84120.4", "0.10600126", "0", "3"], ["84147.5", "0.0118876", "0", "1"], ["84150.7", "0.07130066", "0", "1"], ["84240.1", "0", "0", "0"]], "bids": [["84035.9", "0.23802155", "0", "2"], ["84035.1", "0", "0", "0"], ["83985.8", "0.07147328", "0", "2"], ["83918.3", "0.2025", "0", "1"]], "ts": "1742555180804", "checksum": -145559101, "seqId": 49927502632, "prevSeqId": 49927502603}], "record_time": 1742555180.804979, "EXCHANGE": "OKX"}
{"arg": {"channel": "books", "instId": "BTC-USDT"}, "action": "update", "data": [{"asks": [["84092.4", "0.23801216", "0", "1"], ["84094.3", "0", "0", "0"], ["84120.4", "0.11788899", "0", "4"], ["84147", "0.08352541", "0", "2"], ["84147.5", "0", "0", "0"], ["84240.1", "0.00001005", "0", "1"]], "bids": [["84058.4", "1", "0", "1"], ["84057.1", "0", "0", "0"], ["84035.9", "0.00001196", "0", "1"], ["84033.7", "0.23801373", "0", "1"], ["83918.3", "0", "0", "0"]], "ts": "1742555180904", "checksum": -145559101, "seqId": 49927502665, "prevSeqId": 49927502632}], "record_time": 1742555180.905156, "EXCHANGE": "OKX"}
{"arg": {"channel": "books", "instId": "BTC-USDT"}, "action": "update", "data": [{"asks": [["84070.1", "1.36065883", "0", "17"], ["84079.9", "0.05673849", "0", "2"], ["84081.4", "0.000015", "0", "1"], ["84082.2", "0", "0", "0"], ["84082.3", "0", "0", "0"], ["84082.4", "0", "0", "0"], ["84083.3", "0.03108485", "0", "1"], ["84083.7", "0.06543073", "0", "2"], ["84083.9", "0.03502459", "0", "1"], ["84088.4", "0", "0", "0"], ["84088.5", "0.35641581", "0", "1"], ["84090.2", "0.03453908", "0", "1"], ["84090.3", "0.03384149", "0", "1"], ["84091.1", "0", "0", "0"], ["84091.2", "0", "0", "0"], ["84092.4", "0.27213376", "0", "2"], ["84092.5", "0.37015728", "0", "6"], ["84095.4", "0", "0", "0"], ["84097.3", "0.06857552", "0", "1"], ["84097.8", "0", "0", "0"], ["84098", "0", "0", "0"], ["84099.1", "0.07076057", "0", "1"], ["84099.7", "0.06480487", "0", "1"], ["84099.8", "0", "0", "0"], ["84101.2", "0.06123441", "0", "1"], ["84241", "0.00001501", "0", "1"]], "bids": [["84070", "0.34078479", "0", "5"], ["84056", "0.03102982", "0", "1"], ["84055.7", "0.03379084", "0", "2"], ["84055", "0.03471192", "0", "1"], ["84054.5", "0.39139759", "0", "2"], ["84054.3", "0", "0", "0"], ["84054.1", "0", "0", "0"], ["84053.7", "0", "0", "0"], ["84052.8", "0", "0", "0"], ["84049", "0.03288759", "0", "1"], ["84048.2", "0.03210513", "0", "1"], ["84047.1", "0.20908", "0", "1"], ["84046.9", "0.0315068", "0", "1"], ["84046.5", "0", "0", "0"], ["84046.3", "0.03092004", "0", "1"], ["84045.6", "0", "0", "0"], ["84045", "0.05945451", "0", "2"], ["84042", "0.17693074", "0", "3"], ["84040.1", "0.00357", "0", "1"], ["84039.6", "0.06364018", "0", "1"], ["84038.8", "0.07006564", "0", "1"], ["84038.3", "0", "0", "0"], ["84038.2", "0.08887314", "0", "2"], ["84037.1", "0", "0", "0"], ["84036.8", "0.066", "0", "3"], ["84033", "0", "0", "0"], ["84024", "0", "0", "0"], ["83918.3", "0.2025", "0", "1"], ["83917.6", "0.00005114", "0", "1"]], "ts": "1742555181004", "checksum": 13122557, "seqId": 49927502736, "prevSeqId": 49927502665}], "record_time": 1742555181.004607, "EXCHANGE": "OKX"}
{"arg": {"channel": "books", "instId": "BTC-USDT"}, "action": "update", "data": [{"asks": [["84105.7", "0.66806969", "0", "2"], ["84120.4", "0.10600126", "0", "3"], ["84147", "0.12893042", "0", "3"], ["84147.5", "0.0118876", "0", "1"], ["84150.7", "0.14260132", "0", "2"], ["84241", "0", "0", "0"]], "bids": [["84045.9", "0", "0", "0"], ["84044.9", "0.72255786", "0", "2"], ["84044.8", "1.62005271", "0", "1"], ["84035.9", "0.23802274", "0", "2"], ["84033.7", "0", "0", "0"], ["84016.5", "0.918569", "0", "1"], ["83992.6", "0", "0", "0"], ["83985.8", "0.14291391", "0", "3"], ["83917.5", "0.11890903", "0", "1"], ["83917.4", "0.17821722", "0", "1"]], "ts": "1742555181104", "checksum": 13122557, "seqId": 49927502763, "prevSeqId": 49927502736}], "record_time": 1742555181.10521, "EXCHANGE": "OKX"}
{"arg": {"channel": "books", "instId": "BTC-USDT"}, "action": "update", "data": [{"asks": [["84092.4", "0.0341216", "0", "1"], ["84094.3", "0.23800902", "0", "1"], ["84224.4", "0.00001197", "0", "1"], ["84240.1", "0", "0", "0"]], "bids": [["84025.1", "0.03", "0", "1"], ["83917.4", "0", "0", "0"]], "ts": "1742555181204", "checksum": 13122557, "seqId": 49927502772, "prevSeqId": 49927502763}], "record_time": 1742555181.204804, "EXCHANGE": "OKX"}
{"arg": {"channel": "books", "instId": "BTC-USDT"}, "action": "update", "data": [{"asks": [["84150.7", "0.07130066", "0", "1"], ["84223.5", "0", "0", "0"], ["84240.1", "0.00001005", "0", "1"]], "bids": [["83985.8", "0.07147328", "0", "2"]], "ts": "1742555181304", "checksum": 13122557, "seqId": 49927502787, "prevSeqId": 49927502772}], "record_time": 1742555181.30527, "EXCHANGE": "OKX"}
{"arg": {"channel": "books", "instId": "BTC-USDT"}, "action": "update", "data": [{"asks": [["84120.4", "0.11788899", "0", "4"], ["84147.5", "0", "0", "0"], ["84150.7", "0.14260132", "0", "2"], ["84225.5", "0", "0", "0"], ["84241", "0.00001501", "0", "1"], ["84242", "0.0000185", "0", "1"]], "bids": [["84070", "0.33653479", "0", "4"], ["84050.2", "0", "0", "0"], ["83985.8", "0.14291391", "0", "3"], ["83917.4", "0.17821722", "0", "1"]], "ts": "1742555181404", "checksum": 1880431354, "seqId": 49927502809, "prevSeqId": 49927502787}], "record_time": 1742555181.404366, "EXCHANGE": "OKX"}
{"arg": {"channel": "books", "instId": "BTC-USDT"}, "action": "update", "data": [{"asks": [["84120.4", "0.10600126", "0", "3"], ["84147.5", "0.0118876", "0", "1"], ["84238.6", "0.03", "0", "1"], ["84241", "0", "0", "0"], ["84242", "0", "0", "0"]], "bids": [], "ts": "1742555181504", "checksum": 1880431354, "seqId": 49927502820, "prevSeqId": 49927502809}], "record_time": 1742555181.504275, "EXCHANGE": "OKX"}
{"arg": {"channel": "books", "instId": "BTC-USDT"}, "action": "update", "data": [{"asks": [["84120.4", "0.11788899", "0", "4"], ["84147.5", "0", "0", "0"], ["84150.7", "0.07130066", "0", "1"], ["84176.1", "0.3025", "0", "2"], ["84178.1", "0", "0", "0"], ["84241", "0.00001501", "0", "1"], ["84242", "0.0000185", "0", "1"]], "bids": [["83987.7", "0.00603797", "0", "2"], ["83985.8", "0.07147328", "0", "2"], ["83982.1", "0.00579984", "0", "1"], ["83975.2", "0.00579984", "0", "1"], ["83969.5", "0.00579984", "0", "1"], ["83963.3", "0.02899982", "0", "5"], ["83917.6", "0", "0", "0"], ["83917.5", "0", "0", "0"], ["83917.4", "0", "0", "0"]], "ts": "1742555181604", "checksum": 1880431354, "seqId": 49927502842, "prevSeqId": 49927502820}], "record_time": 1742555181.605933, "EXCHANGE": "OKX"}
{"arg": {"channel": "books", "instId": "BTC-USDT"}, "action": "update", "data": [{"asks": [["84147", "0.08352541", "0", "2"]], "bids": [], "ts": "1742555181704", "checksum": 1880431354, "seqId": 49927502864, "prevSeqId": 49927502842}], "record_time": 1742555181.705233, "EXCHANGE": "OKX"}
{"arg": {"channel": "books", "instId": "BTC-USDT"}, "action": "update", "data": [{"asks": [["84150.7", "0", "0", "0"], ["84242.4", "0.00469113", "0", "3"]], "bids": [["84070", "0.34025479", "0", "5"], ["83985.8", "0.00003265", "0", "1"], ["83980.1", "0", "0", "0"], ["83917.6", "0.00005114", "0", "1"]], "ts": "1742555181804", "checksum": -671985591, "seqId": 49927502878, "prevSeqId": 49927502864}], "record_time": 1742555181.805344, "EXCHANGE": "OKX"}
{"arg": {"channel": "books", "instId": "BTC-USDT"}, "action": "update", "data": [{"asks": [["84070.1", "1.36055654", "0", "17"], ["84150.7", "0.14260132", "0", "2"], ["84242.4", "0", "0", "0"]], "bids": [["84064.7", "0.0966243", "0", "1"], ["84064.6", "0.202", "0", "2"], ["84037.6", "0.33020846", "0", "2"], ["84036.8", "0.106", "0", "4"], ["84036", "0.054784", "0", "3"], ["83985.8", "0.14291391", "0", "3"], ["83980.1", "0.00016248", "0", "1"], ["83918.3", "0", "0", "0"], ["83917.6", "0", "0", "0"]], "ts": "1742555181904", "checksum": 2101790701, "seqId": 49927502906, "prevSeqId": 49927502878}], "record_time": 1742555181.904945, "EXCHANGE": "OKX"}
{"arg": {"channel": "books", "instId": "BTC-USDT"}, "action": "update", "data": [{"asks": [["84078.6", "0", "0", "0"], ["84088.3", "0.1249", "0", "1"], ["84089.6", "1", "0", "1"], ["84120.4", "0.10600126", "0", "3"], ["84147.5", "0.0118876", "0", "1"], ["84242", "0", "0", "0"]], "bids": [["84036.1", "0.23800831", "0", "1"], ["84035.9", "0.00001196", "0", "1"], ["84034", "1", "0", "1"], ["84023", "0.2", "0", "1"], ["83920", "0", "0", "0"], ["83919.2", "0", "0", "0"], ["83918.9", "0", "0", "0"]], "ts": "1742555182004", "checksum": -945857153, "seqId": 49927502930, "prevSeqId": 49927502906}], "record_time": 1742555182.004452, "EXCHANGE": "OKX"}
{"arg": {"channel": "books", "instId": "BTC-USDT"}, "action": "update", "data": [{"asks": [["84070.1", "1.24155108", "0", "16"], ["84071.9", "0.11900291", "0", "1"], ["84084.3", "0.55069972", "0", "2"], ["84088.1", "1", "0", "1"], ["84088.2", "0.24526645", "0", "1"], ["84089.6", "0", "0", "0"], ["84093.1", "0.23800906", "0", "1"], ["84094.3", "0", "0", "0"], ["84120.4", "0.11788899", "0", "4"], ["84147", "0.12536414", "0", "3"], ["84147.5", "0", "0", "0"]], "bids": [["84070", "0.33998127", "0", "5"], ["84064.7", "0.0366243", "0", "1"], ["84064.6", "0.002", "0", "1"], ["84037.6", "0.63779935", "0", "1"], ["84036.1", "0", "0", "0"], ["84035.9", "0.23802066", "0", "2"], ["84000.1", "0.40718646", "0", "1"], ["83920", "0.00001096", "0", "1"]], "ts": "1742555182104", "checksum": 1970196119, "seqId": 49927502970, "prevSeqId": 49927502930}], "record_time": 1742555182.105744, "EXCHANGE": "OKX"}
{"arg": {"channel": "books", "instId": "BTC-USDT"}, "action": "update", "data": [{"asks": [["84070.1", "1.24369208", "0", "17"], ["84093.1", "0.23800974", "0", "1"], ["84117", "0", "0", "0"], ["84242", "0.0000185", "0", "1"]], "bids": [["84037.6", "0", "0", "0"], ["84035.9", "0.00001196", "0", "1"], ["84035.1", "0.23800974", "0", "1"], ["84034", "0", "0", "0"], ["84023", "0.1", "0", "1"], ["84000.1", "0.98624812", "0", "2"], ["83919.2", "0.00003545", "0", "1"]], "ts": "1742555182204", "checksum": 1125800262, "seqId": 49927503000, "prevSeqId": 49927502970}], "record_time": 1742555182.20463, "EXCHANGE": "OKX"}
{"arg": {"channel": "books", "instId": "BTC-USDT"}, "action": "update", "data": [{"asks": [["84093.1", "0.23800884", "0", "1"]], "bids": [["84070", "0.33626127", "0", "4"], ["84037.6", "0.08", "0", "2"], ["84036.8", "0.066", "0", "3"], ["84036", "0.014784", "0", "2"], ["84035.9", "0.2380208", "0", "2"], ["84035.1", "0", "0", "0"]], "ts": "1742555182304", "checksum": 1397091211, "seqId": 49927503034, "prevSeqId": 49927503000}], "record_time": 1742555182.306377, "EXCHANGE": "OKX"}
{"arg": {"channel": "books", "instId": "BTC-USDT"}, "action": "update", "data": [{"asks": [["84093.1", "0", "0", "0"], ["84094.3", "0.23800865", "0", "1"], ["84120.4", "0.10600126", "0", "3"], ["84147.5", "0.0118876", "0", "1"], ["84242", "0", "0", "0"]], "bids": [["84037.6", "0", "0", "0"], ["84036.8", "0.08", "0", "2"], ["84036.1", "0.23800865", "0", "1"], ["84036", "0.067784", "0", "4"], ["84035.9", "0.00001196", "0", "1"], ["84035.2", "0.013", "0", "1"], ["84033.6", "0", "0", "0"], ["84032.8", "0.1", "0", "2"], ["84032", "0.05", "0", "1"], ["83919.2", "0", "0", "0"]], "ts": "1742555182404", "checksum": 1397091211, "seqId": 49927503056, "prevSeqId": 49927503034}], "record_time": 1742555182.404907, "EXCHANGE": "OKX"}
{"arg": {"channel": "books", "instId": "BTC-USDT"}, "action": "update", "data": [{"asks": [["84100", "0.0066249", "0", "2"], ["84200", "5.34096099", "0", "33"]], "bids": [["84033.6", "0.1", "0", "2"], ["84032.8", "0.05", "0", "1"], ["84032", "0", "0", "0"]], "ts": "1742555182504", "checksum": 1397091211, "seqId": 49927503066, "prevSeqId": 49927503056}], "record_time": 1742555182.50606, "EXCHANGE": "OKX"}
{"arg": {"channel": "books", "instId": "BTC-USDT"}, "action": "update", "data": [{"asks": [["84150.7", "0.07130066", "0", "1"]], "bids": [["84023", "0", "0", "0"], ["83985.8", "0.07147328", "0", "2"], ["83919.2", "0.00003545", "0", "1"]], "ts": "1742555182604", "checksum": 1397091211, "seqId": 49927503087, "prevSeqId": 49927503066}], "record_time": 1742555182.609686, "EXCHANGE": "OKX"}
{"arg": {"channel": "books", "instId": "BTC-USDT"}, "action": "update", "data": [{"asks": [["84093.1", "0.23800982", "0", "1"], ["84094.3", "0", "0", "0"], ["84097.1", "0.3576374", "0", "1"], ["84097.2", "0.11890903", "0", "1"], ["84120.4", "0.11788899", "0", "4"], ["84126.6", "0", "0", "0"], ["84126.7", "0", "0", "0"], ["84147", "0.08352541", "0", "2"], ["84147.5", "0", "0", "0"], ["84242", "0.0000185", "0", "1"], ["84242.4", "0.00469113", "0", "3"], ["84242.5", "0.00011938", "0", "1"]], "bids": [["84044.9", "0.01774536", "0", "1"], ["84044.8", "0", "0", "0"], ["84036.9", "0.2380103", "0", "1"], ["84036.1", "0", "0", "0"], ["84016.6", "0.74707063", "0", "2"], ["84015.3", "0", "0", "0"], ["83977.9", "0.29226206", "0", "2"], ["83918.9", "0.00001197", "0", "1"], ["83918.3", "0.2025", "0", "1"]], "ts": "1742555182704", "checksum": 1397091211, "seqId": 49927503131, "prevSeqId": 49927503087}], "record_time": 1742555182.706616, "EXCHANGE": "OKX"}
{"arg": {"channel": "books", "instId": "BTC-USDT"}, "action": "update", "data": [{"asks": [["84096.2", "1.71344438", "0", "2"], ["84120.4", "0.10600126", "0", "3"], ["84123", "1.24962562", "0", "2"], ["84125.6", "2.91458479", "0", "1"], ["84147.5", "0.0118876", "0", "1"], ["84177.6", "0.31215203", "0", "3"], ["84177.8", "0.4", "0", "1"], ["84242", "0", "0", "0"], ["84242.4", "0", "0", "0"], ["84242.5", "0", "0", "0"]], "bids": [["84070", "0.33900127", "0", "5"], ["84059.6", "0", "0", "0"], ["84044.9", "0", "0", "0"], ["84043.8", "1.52819304", "0", "1"], ["84040.7", "0.01774536", "0", "1"], ["84036.9", "0", "0", "0"], ["84036.8", "0.106", "0", "4"], ["84036.1", "0.23800952", "0", "1"], ["84036", "0.054784", "0", "3"], ["84035.2", "0", "0", "0"], ["84014.4", "2.75911565", "0", "1"], ["83918.3", "0", "0", "0"], ["83917.6", "0.00005114", "0", "1"]], "ts": "1742555182804", "checksum": -731760788, "seqId": 49927503170, "prevSeqId": 49927503131}], "record_time": 1742555182.805155, "EXCHANGE": "OKX"}
{"arg": {"channel": "books", "instId": "BTC-USDT"}, "action": "update", "data": [{"asks": [["84120.4", "0.11788899", "0", "4"], ["84147.5", "0", "0", "0"], ["84150.7", "0.14260132", "0", "2"], ["84242", "0.0000185", "0", "1"]], "bids": [["84056.5", "0.133608", "0", "1"], ["83985.8", "0.14291391", "0", "3"], ["83917.6", "0", "0", "0"]], "ts": "1742555182904", "checksum": -731760788, "seqId": 49927503188, "prevSeqId": 49927503170}], "record_time": 1742555182.911124, "EXCHANGE": "OKX"}
{"arg": {"channel": "books", "instId": "BTC-USDT"}, "action": "update", "data": [{"asks": [["84093.1", "0", "0", "0"], ["84094.3", "0.23800833", "0", "1"], ["84120.4", "0.10600126", "0", "3"], ["84147.5", "0.0118876", "0", "1"], ["84242", "0", "0", "0"]], "bids": [["84070", "0.33881227", "0", "5"], ["84044.4", "0.01774536", "0", "1"], ["84040.7", "0", "0", "0"], ["84036.9", "0.23800833", "0", "1"], ["84036.1", "0", "0", "0"]], "ts": "1742555183004", "checksum": -844464582, "seqId": 49927503200, "prevSeqId": 49927503188}], "record_time": 1742555183.004178, "EXCHANGE": "OKX"}
{"arg": {"channel": "books", "instId": "BTC-USDT"}, "action": "update", "data": [{"asks": [["84092.4", "0.27213144", "0", "2"], ["84094.3", "0", "0", "0"], ["84101.5", "0", "0", "0"], ["84111.5", "0", "0", "0"], ["84147", "0.12893042", "0", "3"], ["84242", "0.0000185", "0", "1"], ["84242.4", "0.00469113", "0", "3"], ["84242.5", "0.00011938", "0", "1"]], "bids": [["84064.6", "0", "0", "0"], ["84044.4", "0.69499996", "0", "2"], ["84036.9", "0", "0", "0"], ["84036.1", "0.23800984", "0", "1"], ["84016.6", "1.47093084", "0", "3"], ["83918.3", "0.2025", "0", "1"]], "ts": "1742555183104", "checksum": 823862615, "seqId": 49927503221, "prevSeqId": 49927503200}], "record_time": 1742555183.115268, "EXCHANGE": "OKX"}
{"arg": {"channel": "books", "instId": "BTC-USDT"}, "action": "update", "data": [{"asks": [], "bids": [["84034", "1", "0", "1"], ["83918.3", "0", "0", "0"]], "ts": "1742555183204", "checksum": 823862615, "seqId": 49927503227, "prevSeqId": 49927503221}], "record_time": 1742555183.204541, "EXCHANGE": "OKX"}
{"arg": {"channel": "books", "instId": "BTC-USDT"}, "action": "update", "data": [{"asks": [["84070.1", "1.24155108", "0", "16"], ["84092.4", "0.0341216", "0", "1"], ["84094.3", "0.23800828", "0", "1"], ["84102.8", "0.15629457", "0", "1"], ["84102.9", "0", "0", "0"], ["84113.3", "0.002141", "0", "1"], ["84242.4", "0", "0", "0"], ["84242.5", "0", "0", "0"]], "bids": [["84070", "0.33882227", "0", "6"], ["84036.1", "0.23800828", "0", "1"]], "ts": "1742555183304", "checksum": 885580106, "seqId": 49927503253, "prevSeqId": 49927503227}], "record_time": 1742555183.304428, "EXCHANGE": "OKX"}
{"arg": {"channel": "books", "instId": "BTC-USDT"}, "action": "update", "data": [{"asks": [], "bids": [["84034", "0", "0", "0"], ["83918.3", "0.2025", "0", "1"]], "ts": "1742555183404", "checksum": 885580106, "seqId": 49927503273, "prevSeqId": 49927503253}], "record_time": 1742555183.40534, "EXCHANGE": "OKX"}
{"arg": {"channel": "books", "instId": "BTC-USDT"}, "action": "update", "data": [{"asks": [["84078.9", "0.03115443", "0", "2"], ["84088.9", "0.002", "0", "1"], ["84150.7", "0.07130066", "0", "1"], ["84242", "0", "0", "0"]], "bids": [["84068.1", "0.002", "0", "1"], ["84058", "0.0045", "0", "2"], ["83985.8", "0.07147328", "0", "2"], ["83918.3", "0", "0", "0"]], "ts": "1742555183604", "checksum": 2090108759, "seqId": 49927503296, "prevSeqId": 49927503273}], "record_time": 1742555183.605629, "EXCHANGE": "OKX"}
{"arg": {"channel": "books", "instId": "BTC-USDT"}, "action": "update", "data": [{"asks": [["84092.3", "0.23801221", "0", "1"], ["84094.3", "0", "0", "0"], ["84150.7", "0.14260132", "0", "2"]], "bids": [["84064.7", "0.01917178", "0", "1"], ["84063", "0.29507322", "0", "2"], ["84058.4", "0", "0", "0"], ["84056", "1.03102982", "0", "2"], ["84036.1", "0", "0", "0"], ["84033.7", "0.23801221", "0", "1"], ["84023", "0.2", "0", "2"], ["83985.8", "0.14291391", "0", "3"]], "ts": "1742555183704", "checksum": -634043744, "seqId": 49927503323, "prevSeqId": 49927503296}], "record_time": 1742555183.704598, "EXCHANGE": "OKX"}
{"arg": {"channel": "books", "instId": "BTC-USDT"}, "action": "update", "data": [{"asks": [["84070.1", "1.24092962", "0", "16"], ["84079.9", "0.0369615", "0", "1"], ["84081.4", "0.03089669", "0", "2"], ["84082.3", "0.06610718", "0", "2"], ["84082.4", "0.03357585", "0", "1"], ["84083.3", "0", "0", "0"], ["84083.7", "0", "0", "0"], ["84083.9", "0", "0", "0"], ["84088.4", "0.03112659", "0", "1"], ["84088.6", "0.03523273", "0", "1"], ["84090.2", "0", "0", "0"], ["84090.3", "0", "0", "0"], ["84091.1", "0.03246158", "0", "1"], ["84091.2", "0.0316222", "0", "1"], ["84092.4", "0", "0", "0"], ["84092.5", "0.33827236", "0", "5"], ["84095.4", "0.06684597", "0", "1"], ["84097.3", "0", "0", "0"], ["84097.8", "0.06510297", "0", "1"], ["84098", "0.06491569", "0", "1"], ["84099.1", "0", "0", "0"], ["84099.7", "0", "0", "0"], ["84099.8", "0.06175941", "0", "1"], ["84101.2", "0", "0", "0"], ["84120.4", "0.11788899", "0", "4"], ["84147.5", "0", "0", "0"], ["84242", "0.0000185", "0", "1"]], "bids": [["84070", "0.11858707", "0", "2"], ["84062", "0", "0", "0"], ["84057.4", "1", "0", "1"], ["84056", "0", "0", "0"], ["84055.7", "0.00001197", "0", "1"], ["84055", "0", "0", "0"], ["84054.5", "0.35685", "0", "1"], ["84054.3", "0.03492447", "0", "1"], ["84054.1", "0.03233117", "0", "1"], ["84053.7", "0.033425", "0", "1"], ["84052.9", "0.39159173", "0", "2"], ["84052.8", "0.01190341", "0", "1"], ["84049", "0", "0", "0"], ["84048.2", "0", "0", "0"], ["84047.1", "0.24367144", "0", "2"], ["84046.9", "0", "0", "0"], ["84046.6", "0.03364644", "0", "2"], ["84046.3", "0", "0", "0"], ["84045.6", "0.03376591", "0", "1"], ["84045", "0.09308558", "0", "3"], ["84042", "0.11235012", "0", "2"], ["84040.1", "0.06718915", "0", "2"], ["84039.6", "0", "0", "0"], ["84038.8", "0", "0", "0"], ["84038.3", "0.06546875", "0", "1"], ["84038.2", "0.0214248", "0", "1"], ["84037.1", "0.07016456", "0", "1"], ["84036.8", "0.17615318", "0", "5"], ["84023", "0.1", "0", "1"], ["84015.5", "0.01188754", "0", "1"], ["83918.3", "0.2025", "0", "1"]], "ts": "1742555183804", "checksum": -1077887244, "seqId": 49927503407, "prevSeqId": 49927503323}], "record_time": 1742555183.806791, "EXCHANGE": "OKX"}
{"arg": {"channel": "books", "instId": "BTC-USDT"}, "action": "update", "data": [{"asks": [["84070.1", "1.24030813", "0", "16"], ["84079.9", "0.07889826", "0", "1"], ["84082.8", "0.08991011", "0", "1"], ["84242", "0", "0", "0"]], "bids": [["84036.8", "0.15015318", "0", "3"], ["84036", "0.067784", "0", "4"], ["84035.2", "0.013", "0", "1"], ["84023", "0", "0", "0"]], "ts": "1742555183904", "checksum": -1610400185, "seqId": 49927503437, "prevSeqId": 49927503407}], "record_time": 1742555183.906489, "EXCHANGE": "OKX"}
{"arg": {"channel": "books", "instId": "BTC-USDT"}, "action": "update", "data": [{"asks": [["84070.1", "1.24244913", "0", "17"], ["84113.3", "0", "0", "0"], ["84242", "0.0000185", "0", "1"]], "bids": [], "ts": "1742555184004", "checksum": 1716249792, "seqId": 49927503448, "prevSeqId": 49927503437}], "record_time": 1742555184.005196, "EXCHANGE": "OKX"}
{"arg": {"channel": "books", "instId": "BTC-USDT"}, "action": "update", "data": [{"asks": [["84092.3", "0", "0", "0"], ["84092.4", "0.23801059", "0", "1"]], "bids": [["84035.1", "0.23801195", "0", "1"], ["84033.7", "0", "0", "0"], ["84004.5", "0", "0", "0"], ["83995.3", "0", "0", "0"], ["83917.6", "0.00005114", "0", "1"], ["83917.5", "0.11890903", "0", "1"]], "ts": "1742555184104", "checksum": 1716249792, "seqId": 49927503490, "prevSeqId": 49927503448}], "record_time": 1742555184.108766, "EXCHANGE": "OKX"}
{"arg": {"channel": "books", "instId": "BTC-USDT"}, "action": "update", "data": [{"asks": [["84068.3", "1.70764413", "0", "23"], ["84069.6", "0.1", "0", "1"], ["84069.9", "0.18492342", "0", "1"], ["84070", "0.0146", "0", "1"], ["84070.1", "0.16881387", "0", "7"], ["84070.4", "0", "0", "0"], ["84070.8", "0.08991011", "0", "1"], ["84071.9", "0", "0", "0"], ["84072.3", "0.01910134", "0", "1"], ["84073.5", "0.01388459", "0", "1"], ["84073.6", "0", "0", "0"], ["84073.9", "0", "0", "0"], ["84074.6", "0.03167", "0", "1"], ["84075.5", "0.00001197", "0", "1"], ["84076.5", "0.20491216", "0", "2"], ["84076.7", "0.05506443", "0", "3"], ["84077", "0.04", "0", "1"], ["84077.9", "0.11890903", "0", "1"], ["84078.5", "0.29542585", "0", "6"], ["84079", "0.06809204", "0", "2"], ["84079.2", "0.03445138", "0", "1"], ["84079.4", "0", "0", "0"], ["84079.8", "0.12820284", "0", "1"], ["84079.9", "0", "0", "0"], ["84080.8", "0.02055", "0", "3"], ["84081.4", "0.000015", "0", "1"], ["84082.3", "0", "0", "0"], ["84082.4", "0", "0", "0"], ["84083.7", "0.23803097", "0", "1"], ["84083.8", "0.02380316", "0", "1"], ["84084", "0.42054301", "0", "2"], ["84084.1", "0", "0", "0"], ["84084.2", "1", "0", "1"], ["84084.3", "0", "0", "0"], ["84084.7", "0.03", "0", "1"], ["84085.2", "0", "0", "0"], ["84085.5", "0.06567423", "0", "2"], ["84085.8", "0", "0", "0"], ["84086", "0.0146", "0", "1"], ["84086.5", "0", "0", "0"], ["84087.7", "0.03185117", "0", "1"], ["84087.8", "0.03429131", "0", "1"], ["84088.1", "0", "0", "0"], ["84088.2", "0", "0", "0"], ["84088.3", "0", "0", "0"], ["84088.4", "0", "0", "0"], ["84088.6", "0", "0", "0"], ["84088.7", "0.11890903", "0", "1"], ["84091.1", "0", "0", "0"], ["84091.2", "0", "0", "0"], ["84092", "0", "0", "0"], ["84092.4", "0", "0", "0"], ["84092.5", "0.78159873", "0", "4"], ["84094", "0.0054", "0", "1"], ["84094.4", "0.17834113", "0", "3"], ["84094.9", "0.06537635", "0", "1"], ["84095.4", "0", "0", "0"], ["84096.5", "0.15188517", "0", "2"], ["84097.8", "0", "0", "0"], ["84098", "0", "0", "0"], ["84099", "0.14043766", "0", "1"], ["84099.3", "0.05557", "0", "3"], ["84099.8", "0", "0", "0"], ["84102.4", "0", "0", "0"], ["84105.7", "0.42029712", "0", "1"], ["84105.8", "0.48245", "0", "2"], ["84106", "0", "0", "0"], ["84106.6", "0.00001501", "0", "1"], ["84107", "0", "0", "0"], ["84109.2", "0", "0", "0"], ["84109.3", "0", "0", "0"], ["84110", "0.35685", "0", "1"], ["84112", "0.19890902", "0", "3"], ["84112.8", "0.03999999", "0", "1"], ["84113.6", "0.17821722", "0", "1"], ["84114.6", "0", "0", "0"], ["84117.3", "0.01917563", "0", "1"], ["84117.9", "0", "0", "0"], ["84118.4", "0", "0", "0"], ["84120.3", "0.0395036", "0", "1"], ["84120.4", "0.09411353", "0", "2"], ["84121.6", "0", "0", "0"], ["84125.7", "0.05991", "0", "1"], ["84127.1", "0.917363", "0", "1"], ["84131.2", "0", "0", "0"], ["84131.3", "0", "0", "0"], ["84131.8", "0.000015", "0", "1"], ["84132.1", "0", "0", "0"], ["84138.7", "0.00579996", "0", "1"], ["84144.4", "0", "0", "0"], ["84145.1", "0.00579996", "0", "1"], ["84151.3", "0.0117475", "0", "2"], ["84158.8", "0.00579996", "0", "1"], ["84161.7", "0.47825996", "0", "2"], ["84164.2", "0.63655981", "0", "3"], ["84165.8", "1.38729876", "0", "2"], ["84167.3", "0.00609996", "0", "1"], ["84171.2", "0.00579996", "0", "1"], ["84171.3", "0.01188773", "0", "1"], ["84171.5", "0.00579996", "0", "1"], ["84173.1", "0.00609996", "0", "1"], ["84192", "0.01188761", "0", "1"], ["84194.4", "0.0118876", "0", "1"], ["84196.9", "0.01188759", "0", "1"], ["84210.9", "0.0118875", "0", "1"], ["84211.5", "0.00594742", "0", "1"], ["84221", "0.00593983", "0", "1"], ["84222", "0", "0", "0"], ["84228.3", "0.01784265", "0", "3"], ["84238.8", "0", "0", "0"], ["84239", "0", "0", "0"], ["84242.4", "0.00469113", "0", "3"]], "bids": [["84070", "0", "0", "0"], ["84066.5", "0", "0", "0"], ["84065.9", "0", "0", "0"], ["84065.2", "0", "0", "0"], ["84064.7", "0", "0", "0"], ["84064.5", "0", "0", "0"], ["84063.4", "0.00773181", "0", "1"], ["84063", "0.05617506", "0", "1"], ["84061.5", "0.14720495", "0", "1"], ["84061", "0", "0", "0"], ["84060.3", "0.009", "0", "1"], ["84059.2", "0", "0", "0"], ["84058.8", "0.23885768", "0", "1"], ["84057.5", "0.00007494", "0", "1"], ["84057.4", "0", "0", "0"], ["84056.6", "0", "0", "0"], ["84056.5", "0", "0", "0"], ["84056.3", "0", "0", "0"], ["84054.8", "0.2159", "0", "2"], ["84054.6", "0.2383603", "0", "1"], ["84054.5", "0.00773181", "0", "1"], ["84054.3", "0", "0", "0"], ["84054.1", "0", "0", "0"], ["84053.7", "0", "0", "0"], ["84053.3", "0", "0", "0"], ["84053.2", "0.0134", "0", "1"], ["84052.9", "0.3568907", "0", "1"], ["84051.5", "0.18043766", "0", "2"], ["84051.3", "0", "0", "0"], ["84051.2", "0.03127098", "0", "1"], ["84051", "0.03105852", "0", "1"], ["84050.3", "0.03412498", "0", "1"], ["84049.8", "0.03130554", "0", "1"], ["84049.4", "0.45952614", "0", "2"], ["84048.2", "1", "0", "1"], ["84048.1", "0.11903657", "0", "1"], ["84047.1", "0.20908", "0", "1"], ["84047", "0", "0", "0"], ["84046.6", "0.00009543", "0", "1"], ["84046.2", "0", "0", "0"], ["84045.7", "0.00713897", "0", "1"], ["84045.6", "0", "0", "0"], ["84045", "0.00001", "0", "1"], ["84044.3", "0.35579296", "0", "1"], ["84044.2", "0.05275101", "0", "2"], ["84043.5", "0.03329518", "0", "1"], ["84042.2", "0.03438504", "0", "1"], ["84041.6", "0.03466283", "0", "1"], ["84040.6", "0", "0", "0"], ["84040.1", "0.00357", "0", "1"], ["84039.3", "0.51668", "0", "1"], ["84038.3", "0", "0", "0"], ["84037.5", "0", "0", "0"], ["84037.2", "0.06241691", "0", "1"], ["84037.1", "0", "0", "0"], ["84036.8", "0", "0", "0"], ["84036", "0.001784", "0", "1"], ["84035.9", "0.14044962", "0", "2"], ["84035.6", "0", "0", "0"], ["84035.2", "0", "0", "0"], ["84035.1", "0", "0", "0"], ["84035", "0", "0", "0"], ["84034.9", "0.06160616", "0", "1"], ["84034", "0.06563761", "0", "1"], ["84033.6", "0", "0", "0"], ["84033.5", "0.07014287", "0", "1"], ["84032.8", "0.08", "0", "2"], ["84032", "0.066", "0", "3"], ["84031.2", "0.013", "0", "1"], ["84029", "0.23803097", "0", "1"], ["84028.9", "0.30234296", "0", "1"], ["84028.8", "0.3025", "0", "3"], ["84028", "0.05", "0", "1"], ["84027.3", "0.35579296", "0", "1"], ["84025.2", "0.00100367", "0", "1"], ["84025", "0.05423719", "0", "2"], ["84021.7", "0.38685", "0", "2"], ["84021.3", "0.0238149", "0", "1"], ["84020.9", "0.05617506", "0", "1"], ["84020.2", "0", "0", "0"], ["84018.7", "0.3736554", "0", "2"], ["84014", "0", "0", "0"], ["84013.3", "0", "0", "0"], ["84012.4", "0", "0", "0"], ["84010.4", "0.56662709", "0", "1"], ["84009.7", "0", "0", "0"], ["84005.3", "0.01189946", "0", "2"], ["84000.1", "1.56190935", "0", "1"], ["83991.7", "0.00594754", "0", "1"], ["83991.6", "1.52477582", "0", "4"], ["83991", "0.05955872", "0", "1"], ["83987.8", "0.00602062", "0", "2"], ["83987", "0.01188759", "0", "1"], ["83980.1", "0", "0", "0"], ["83976.6", "0", "0", "0"], ["83969.7", "0.21703", "0", "1"], ["83969.4", "0.30335734", "0", "2"], ["83967.8", "0.00609955", "0", "1"], ["83958.6", "0", "0", "0"], ["83948.2", "0", "0", "0"], ["83947.5", "0.06274742", "0", "5"], ["83942.1", "0.00001", "0", "1"], ["83941.8", "0.00001197", "0", "1"], ["83935.9", "0.0054", "0", "1"], ["83930.7", "0.01786072", "0", "4"], ["83922.4", "0.03", "0", "1"], ["83917.4", "0.17821722", "0", "1"], ["83917.3", "0.08991011", "0", "1"], ["83917.2", "0.35579296", "0", "1"], ["83916.6", "0.00106624", "0", "4"], ["83916.5", "3.54678207", "0", "3"], ["83916.3", "0.03074456", "0", "2"], ["83915.9", "0.00014559", "0", "1"], ["83914.2", "0.03486546", "0", "1"], ["83914.1", "0.00001066", "0", "1"], ["83913", "0.00002243", "0", "1"]], "ts": "1742555184204", "checksum": 1018760872, "seqId": 49927504023, "prevSeqId": 49927503490}], "record_time": 1742555184.205291, "EXCHANGE": "OKX"}
{"arg": {"channel": "books", "instId": "BTC-USDT"}, "action": "update", "data": [{"asks": [["84068.3", "1.31517511", "0", "20"], ["84070.1", "0.07960502", "0", "5"], ["84077.8", "0.000012", "0", "1"], ["84079", "0.03281609", "0", "1"], ["84079.1", "0.03517438", "0", "1"], ["84079.8", "0.07479266", "0", "1"], ["84081.3", "0.06", "0", "2"], ["84083.7", "0", "0", "0"], ["84084.7", "0.09", "0", "3"], ["84088.4", "0.23802097", "0", "1"], ["84092.5", "0.75159873", "0", "3"], ["84094.4", "0.11235012", "0", "2"], ["84094.5", "0.06730755", "0", "1"], ["84105.6", "0", "0", "0"], ["84106.8", "0.25755", "0", "1"], ["84112.8", "0.13999999", "0", "2"], ["84122.6", "0.01774536", "0", "1"], ["84130.5", "0", "0", "0"], ["84131.3", "0.01128925", "0", "1"], ["84138.8", "0", "0", "0"], ["84140.4", "0.47216", "0", "1"], ["84144.5", "0.2498", "0", "1"], ["84159.8", "0.05875204", "0", "2"], ["84161.7", "0.00609996", "0", "1"], ["84207.7", "1.91586179", "0", "3"], ["84239.8", "0", "0", "0"], ["84240", "0", "0", "0"], ["84240.1", "0", "0", "0"], ["84241", "0", "0", "0"], ["84242", "0", "0", "0"], ["84242.4", "0", "0", "0"]], "bids": [["84068.2", "0.01114", "0", "3"], ["84058.8", "0.1776474", "0", "1"], ["84058.7", "0", "0", "0"], ["84057.2", "0", "0", "0"], ["84056.9", "0", "0", "0"], ["84055.2", "0.133607", "0", "1"], ["84054.2", "0.000015", "0", "1"], ["84051.2", "0.06745687", "0", "2"], ["84050.9", "0.02981207", "0", "2"], ["84050.4", "0.03405688", "0", "1"], ["84050.3", "0", "0", "0"], ["84048.2", "0", "0", "0"], ["84047.1", "0", "0", "0"], ["84046.9", "1", "0", "1"], ["84039.9", "0.05944451", "0", "1"], ["84038.2", "0", "0", "0"], ["84035", "0.0624964", "0", "1"], ["84034.9", "0", "0", "0"], ["84032.9", "0.23802097", "0", "1"], ["84029", "0", "0", "0"], ["84027.5", "0.0214248", "0", "1"], ["84026.1", "0.21329091", "0", "2"], ["84020.5", "0", "0", "0"], ["84019.6", "0", "0", "0"], ["84018.4", "0.1", "0", "1"], ["84014.5", "0.01832778", "0", "1"], ["84013.4", "0", "0", "0"], ["84007.5", "0", "0", "0"], ["84005.9", "0.00285318", "0", "1"], ["84003.9", "0", "0", "0"], ["84002", "0.00105313", "0", "1"], ["83997.3", "0.2498", "0", "1"], ["83995.7", "0.00235665", "0", "1"], ["83992.5", "1.33976296", "0", "2"], ["83991.6", "0.04100582", "0", "3"], ["83985.6", "0.01902468", "0", "1"], ["83980.1", "0.00016248", "0", "1"], ["83958.9", "1.48377", "0", "1"], ["83948.3", "0", "0", "0"], ["83943.2", "0.18327786", "0", "1"], ["83939.6", "0", "0", "0"], ["83937.8", "0.00201854", "0", "1"], ["83914.2", "0", "0", "0"], ["83914.1", "0", "0", "0"], ["83913", "0", "0", "0"]], "ts": "1742555184304", "checksum": -799185894, "seqId": 49927504140, "prevSeqId": 49927504023}], "record_time": 1742555184.305011, "EXCHANGE": "OKX"}
{"arg": {"channel": "books", "instId": "BTC-USDT"}, "action": "update", "data": [{"asks": [["84068.3", "1.26743757", "0", "19"], ["84080.2", "0.0103941", "0", "1"], ["84084.1", "0.17843", "0", "1"], ["84084.6", "0.03", "0", "1"], ["84086.4", "0.03", "0", "1"], ["84088.4", "0", "0", "0"], ["84089.7", "0.23801938", "0", "1"], ["84089.8", "0.030015", "0", "2"], ["84096.3", "0.01190002", "0", "1"], ["84115.6", "0.03", "0", "1"], ["84122.6", "0.01778848", "0", "2"], ["84123.1", "0.2025", "0", "1"], ["84124.9", "0", "0", "0"], ["84238.6", "0", "0", "0"], ["84239.2", "0", "0", "0"], ["84239.3", "0", "0", "0"], ["84239.7", "0", "0", "0"]], "bids": [["84057.5", "0.02538429", "0", "2"], ["84054.2", "0", "0", "0"], ["84051.3", "0.17843", "0", "1"], ["84033.6", "0.23801938", "0", "1"], ["84032.9", "0", "0", "0"], ["84025", "1.05423719", "0", "3"], ["84011.5", "0.17843", "0", "1"], ["83981.2", "0.02377547", "0", "2"], ["83980.1", "0", "0", "0"], ["83978.4", "0.00016248", "0", "1"], ["83955.8", "0.01188698", "0", "1"], ["83936.1", "0.00625367", "0", "2"], ["83916.3", "0", "0", "0"], ["83915.9", "0", "0", "0"]], "ts": "1742555184404", "checksum": 1117988703, "seqId": 49927504181, "prevSeqId": 49927504140}], "record_time": 1742555184.406947, "EXCHANGE": "OKX"}
{"arg": {"channel": "books", "instId": "BTC-USDT"}, "action": "update", "data": [{"asks": [["84068.3", "1.27783167", "0", "20"], ["84072.2", "0.02277999", "0", "1"], ["84073.5", "0", "0", "0"], ["84073.6", "0.01055", "0", "1"], ["84078.9", "0.06443361", "0", "3"], ["84079", "0.03201845", "0", "1"], ["84079.1", "0.03427831", "0", "1"], ["84079.2", "0", "0", "0"], ["84079.8", "0.43680496", "0", "2"], ["84080.2", "0", "0", "0"], ["84080.8", "0.01", "0", "2"], ["84082.9", "1", "0", "1"], ["84084", "0.33108486", "0", "3"], ["84084.2", "0", "0", "0"], ["84085.4", "0.03478755", "0", "2"], ["84085.5", "0.03184011", "0", "1"], ["84086.4", "0", "0", "0"], ["84086.9", "0.23802396", "0", "1"], ["84088.3", "0.1249", "0", "1"], ["84089.7", "0", "0", "0"], ["84089.8", "0.000015", "0", "1"], ["84092.5", "0.72159873", "0", "2"], ["84094.4", "0.17485335", "0", "3"], ["84094.5", "0", "0", "0"], ["84096.4", "0.06251598", "0", "1"], ["84096.5", "0.08991011", "0", "1"], ["84109.3", "0.1249", "0", "1"], ["84112.2", "0.06", "0", "2"], ["84115.6", "0.06", "0", "2"], ["84134.5", "0", "0", "0"], ["84136.5", "0.05617506", "0", "1"]], "bids": [["84061.5", "0", "0", "0"], ["84054.8", "0.2025", "0", "1"], ["84054.2", "0.000015", "0", "1"], ["84051", "0", "0", "0"], ["84050.9", "0.06158668", "0", "3"], ["84050.4", "0", "0", "0"], ["84050.3", "0.03328905", "0", "1"], ["84049.8", "0", "0", "0"], ["84049.7", "0.03321279", "0", "1"], ["84049.4", "0.47400311", "0", "2"], ["84047.7", "0.0134", "0", "1"], ["84046.9", "0", "0", "0"], ["84046.5", "1", "0", "1"], ["84046.2", "0.1249", "0", "1"], ["84043.5", "0", "0", "0"], ["84043.4", "0.03394145", "0", "1"], ["84035", "0", "0", "0"], ["84034.9", "0.06372517", "0", "1"], ["84033.6", "0", "0", "0"], ["84033.5", "0", "0", "0"], ["84033.4", "0.06473927", "0", "1"], ["84032.8", "0", "0", "0"], ["84032", "0", "0", "0"], ["84031.6", "0.23802396", "0", "1"], ["84031.2", "0", "0", "0"], ["84029.6", "0.08", "0", "2"], ["84028.8", "0.2685", "0", "4"], ["84028", "0.013", "0", "1"], ["84025.6", "0.1", "0", "2"], ["84025.4", "0", "0", "0"], ["84025.2", "0.12590367", "0", "2"], ["84025", "0.05423719", "0", "2"], ["84024.8", "0.05", "0", "1"], ["84017.9", "0", "0", "0"], ["84013.4", "0.0054", "0", "1"], ["84010.4", "0", "0", "0"], ["84001.9", "0", "0", "0"], ["83996.7", "0.00714313", "0", "1"], ["83989.9", "0.0054", "0", "1"]], "ts": "1742555184504", "checksum": -1888618693, "seqId": 49927504292, "prevSeqId": 49927504181}], "record_time": 1742555184.505353, "EXCHANGE": "OKX"}
{"arg": {"channel": "books", "instId": "BTC-USDT"}, "action": "update", "data": [{"asks": [["84076.7", "0.05489552", "0", "2"], ["84085.8", "0.23802643", "0", "1"], ["84086.9", "0", "0", "0"], ["84096", "0.01774536", "0", "1"], ["84104.8", "0.25821722", "0", "3"], ["84105.6", "0.03999999", "0", "1"], ["84112", "0.11890903", "0", "1"], ["84112.8", "0.1", "0", "1"], ["84122.6", "0.00004312", "0", "1"], ["84237.8", "0", "0", "0"], ["84238.1", "0", "0", "0"]], "bids": [["84068.2", "0.01125654", "0", "4"], ["84058.9", "0", "0", "0"], ["84055.6", "0", "0", "0"], ["84052.3", "0.00420804", "0", "1"], ["84047.3", "0.087", "0", "2"], ["84031.6", "0", "0", "0"], ["84029.7", "0.23802643", "0", "1"], ["84008.5", "0.01188774", "0", "1"], ["84002", "0", "0", "0"], ["84001.6", "0.00105314", "0", "1"], ["83993", "0.1249", "0", "1"], ["83981.2", "0.01188786", "0", "1"], ["83972", "0.13069982", "0", "2"], ["83916.5", "0", "0", "0"]], "ts": "1742555184604", "checksum": 1151719512, "seqId": 49927504330, "prevSeqId": 49927504292}], "record_time": 1742555184.605134, "EXCHANGE": "OKX"}
{"arg": {"channel": "books", "instId": "BTC-USDT"}, "action": "update", "data": [{"asks": [["84076.5", "0.31398087", "0", "1"], ["84077.2", "0.03364772", "0", "1"], ["84077.7", "0.03248238", "0", "1"], ["84077.8", "0.39141486", "0", "3"], ["84077.9", "0.15248987", "0", "2"], ["84078.5", "0.26282487", "0", "5"], ["84078.9", "0.03115443", "0", "2"], ["84079", "0", "0", "0"], ["84079.1", "0", "0", "0"], ["84084.2", "0.06558012", "0", "2"], ["84085.4", "0.00001197", "0", "1"], ["84085.5", "0", "0", "0"], ["84085.8", "0", "0", "0"], ["84086.4", "0.03425966", "0", "1"], ["84086.5", "0.03377721", "0", "1"], ["84087.1", "0.23802442", "0", "1"], ["84087.7", "0", "0", "0"], ["84087.8", "0", "0", "0"], ["84091.2", "0.06205533", "0", "1"], ["84092.5", "0.65940771", "0", "1"], ["84093.2", "0.20060408", "0", "3"], ["84093.6", "0.06194408", "0", "1"], ["84094.4", "0.11235012", "0", "2"], ["84094.9", "0", "0", "0"], ["84095.2", "0.07619268", "0", "2"], ["84096.4", "0", "0", "0"]], "bids": [["84063", "0", "0", "0"], ["84061.4", "0", "0", "0"], ["84051.2", "0.03618589", "0", "1"], ["84050.9", "0.02981207", "0", "2"], ["84050.7", "0.102", "0", "2"], ["84050.3", "0", "0", "0"], ["84049.9", "0.03148885", "0", "2"], ["84049.7", "0.03064517", "0", "1"], ["84049.1", "0.09317092", "0", "2"], ["84048.5", "0.03501538", "0", "1"], ["84047.3", "0.18", "0", "4"], ["84044.2", "0.01804", "0", "1"], ["84043.4", "0", "0", "0"], ["84042.9", "0.030701", "0", "1"], ["84042.2", "0.03258653", "0", "1"], ["84041.6", "0", "0", "0"], ["84040.9", "0.03271147", "0", "1"], ["84040.3", "0.03202374", "0", "1"], ["84037.2", "0", "0", "0"], ["84035.9", "0.77444875", "0", "4"], ["84034.9", "0", "0", "0"], ["84034", "0", "0", "0"], ["84033.7", "0.0618864", "0", "1"], ["84033.4", "0", "0", "0"], ["84032.7", "0.06276686", "0", "1"], ["84032.2", "0.06142639", "0", "1"], ["84031.6", "0.23802442", "0", "1"], ["84029.7", "0", "0", "0"], ["84020.9", "0.11235012", "0", "2"], ["84005.3", "0.0237872", "0", "3"], ["83975.5", "0.01194246", "0", "2"], ["83955.8", "0", "0", "0"], ["83931.4", "0", "0", "0"], ["83916.5", "3.54678207", "0", "3"], ["83916.3", "0.03074456", "0", "2"], ["83915.9", "0.00014559", "0", "1"]], "ts": "1742555184704", "checksum": 1848006083, "seqId": 49927504421, "prevSeqId": 49927504330}], "record_time": 1742555184.704522, "EXCHANGE": "OKX"}
{"arg": {"channel": "books", "instId": "BTC-USDT"}, "action": "update", "data": [{"asks": [["84070.8", "0", "0", "0"], ["84073.1", "0.01910134", "0", "1"], ["84077.8", "0.42405006", "0", "3"], ["84077.9", "0.11890903", "0", "1"], ["84079.8", "0.14733586", "0", "2"], ["84082.9", "0", "0", "0"], ["84084", "0.61460915", "0", "2"], ["84084.1", "0.20960075", "0", "2"], ["84084.2", "0.03467748", "0", "1"], ["84084.7", "1.09", "0", "4"], ["84087.1", "0", "0", "0"], ["84091.1", "0.23801965", "0", "1"], ["84198.6", "0.00594421", "0", "1"], ["84200.5", "0", "0", "0"], ["84237.8", "0.00007018", "0", "2"], ["84238.1", "0.00006534", "0", "2"]], "bids": [["84068.2", "0.01011654", "0", "3"], ["84054.6", "0.58022246", "0", "2"], ["84053.2", "1.0134", "0", "2"], ["84049.4", "0.25186481", "0", "1"], ["84048.5", "0", "0", "0"], ["84048.4", "0.03544095", "0", "1"], ["84046.5", "0", "0", "0"], ["84042.2", "0", "0", "0"], ["84042.1", "0.03091371", "0", "1"], ["84033.8", "0.24222959", "0", "2"], ["84031.6", "0", "0", "0"], ["84025.2", "0.1249", "0", "1"], ["84022.6", "0.00002208", "0", "1"], ["84021.7", "0.03", "0", "1"], ["84014.1", "0.00694935", "0", "2"], ["84013.2", "0", "0", "0"], ["84011.6", "0.00099883", "0", "1"], ["84011.5", "0", "0", "0"], ["84008.5", "0", "0", "0"], ["83981.2", "0.02377547", "0", "2"], ["83976.2", "0.2498", "0", "1"], ["83914.2", "0.03486546", "0", "1"], ["83914.1", "0.00001066", "0", "1"], ["83913", "0.00002243", "0", "1"]], "ts": "1742555184804", "checksum": -1681798383, "seqId": 49927504480, "prevSeqId": 49927504421}], "record_time": 1742555184.804598, "EXCHANGE": "OKX"}
{"arg": {"channel": "books", "instId": "BTC-USDT"}, "action": "update", "data": [{"asks": [["84068.3", "1.39683968", "0", "21"], ["84077.2", "0", "0", "0"], ["84077.7", "0", "0", "0"], ["84077.8", "0.35641581", "0", "1"], ["84079.2", "0.000021", "0", "1"], ["84084.1", "0.17843", "0", "1"], ["84084.2", "0", "0", "0"], ["84086.4", "0", "0", "0"], ["84086.5", "0", "0", "0"], ["84091.2", "0", "0", "0"], ["84093.2", "0.13420468", "0", "2"], ["84093.6", "0", "0", "0"], ["84095.2", "0.009071", "0", "1"], ["84110", "0", "0", "0"], ["84144.5", "0", "0", "0"], ["84205.9", "0.07188754", "0", "3"], ["84238.6", "0.03", "0", "1"], ["84239.3", "0.00011161", "0", "1"], ["84239.7", "0.01652", "0", "1"], ["84239.8", "0.35579296", "0", "1"], ["84240", "0.00039685", "0", "3"], ["84240.1", "0.00001005", "0", "1"], ["84241", "0.00001501", "0", "1"], ["84242", "0.0000185", "0", "1"]], "bids": [["84062.8", "0.11901575", "0", "1"], ["84053.6", "0.00357711", "0", "1"], ["84049.9", "0.00060645", "0", "1"], ["84049.7", "0", "0", "0"], ["84049.1", "0.06205459", "0", "1"], ["84048.4", "0", "0", "0"], ["84042.9", "0", "0", "0"], ["84042.4", "0.11905663", "0", "2"], ["84042.1", "0", "0", "0"], ["84040.9", "0", "0", "0"], ["84040.3", "0", "0", "0"], ["84039.2", "0.17843", "0", "1"], ["84035.9", "0.70734584", "0", "3"], ["84033.7", "0", "0", "0"], ["84032.7", "0", "0", "0"], ["84032.2", "0", "0", "0"], ["84016.4", "0.06", "0", "2"], ["83997.3", "0", "0", "0"], ["83993", "0", "0", "0"], ["83976.2", "0", "0", "0"], ["83972", "0.00579982", "0", "1"], ["83912.6", "0.00013227", "0", "2"], ["83912.5", "0.00016336", "0", "3"], ["83912", "0.00001198", "0", "1"], ["83910", "0.0000128", "0", "1"], ["83909", "0.17828186", "0", "3"], ["83908.6", "0.35687932", "0", "2"], ["83908.3", "0.00422253", "0", "1"], ["83907", "0.00005223", "0", "1"]], "ts": "1742555184904", "checksum": -699692967, "seqId": 49927504535, "prevSeqId": 49927504480}], "record_time": 1742555184.905965, "EXCHANGE": "OKX"}
{"arg": {"channel": "books", "instId": "BTC-USDT"}, "action": "update", "data": [{"asks": [["84077.9", "0.14967377", "0", "2"], ["84078.6", "0.03507138", "0", "1"], ["84078.7", "0.06276919", "0", "2"], ["84084.7", "1.44685", "0", "5"], ["84084.9", "0.03304333", "0", "1"], ["84085", "0.03253826", "0", "1"], ["84087.4", "0.03454147", "0", "1"], ["84087.5", "0.03440065", "0", "1"], ["84091.9", "0.06216563", "0", "1"], ["84094.1", "0.06393166", "0", "1"], ["84094.4", "0.18097499", "0", "3"], ["84096", "0", "0", "0"], ["84096.1", "0.24650032", "0", "2"], ["84104.8", "0.17821722", "0", "1"], ["84105.6", "0.07999999", "0", "2"], ["84106.4", "0.03999999", "0", "1"], ["84122.6", "0.01778848", "0", "2"], ["84238.6", "0", "0", "0"], ["84239.3", "0", "0", "0"], ["84239.7", "0", "0", "0"], ["84239.8", "0", "0", "0"], ["84240", "0", "0", "0"], ["84240.1", "0", "0", "0"], ["84241", "0", "0", "0"], ["84242", "0", "0", "0"]], "bids": [["84050.6", "0.06277183", "0", "2"], ["84050", "0.04921403", "0", "5"], ["84049.4", "0.60871481", "0", "2"], ["84049.3", "0.03313351", "0", "1"], ["84043.6", "0.03073176", "0", "1"], ["84043", "0.03522186", "0", "2"], ["84041.9", "0.03129279", "0", "1"], ["84041.3", "0.03180187", "0", "1"], ["84039.2", "0", "0", "0"], ["84036.6", "0.06500864", "0", "1"], ["84034.6", "0.06580897", "0", "1"], ["84033.5", "0.06216919", "0", "1"], ["84033.1", "0.06724715", "0", "1"], ["84008.5", "0.01188774", "0", "1"], ["83981.2", "0.01188786", "0", "1"], ["83913", "0", "0", "0"], ["83912.6", "0", "0", "0"], ["83912.5", "0", "0", "0"], ["83912", "0", "0", "0"], ["83910", "0", "0", "0"], ["83909", "0", "0", "0"], ["83908.6", "0", "0", "0"], ["83908.3", "0", "0", "0"], ["83907", "0", "0", "0"]], "ts": "1742555185004", "checksum": -1333600394, "seqId": 49927504583, "prevSeqId": 49927504535}], "record_time": 1742555185.005499, "EXCHANGE": "OKX"}
{"arg": {"channel": "books", "instId": "BTC-USDT"}, "action": "update", "data": [{"asks": [["84068.3", "1.39689295", "0", "22"], ["84070.1", "0.07746402", "0", "4"], ["84079.8", "0.07479266", "0", "1"], ["84087.7", "0.4808", "0", "1"], ["84105.7", "0", "0", "0"], ["84105.8", "0.0054", "0", "1"], ["84113.1", "0.002141", "0", "1"], ["84219.3", "3.20041814", "0", "2"], ["84238.1", "0", "0", "0"]], "bids": [["84049.4", "0.25186481", "0", "1"], ["84040.5", "0", "0", "0"], ["84039.3", "0", "0", "0"], ["84035", "0.1249", "0", "1"], ["84024.7", "0.5253413", "0", "2"], ["84024.5", "0.49196", "0", "1"], ["84014", "0.1249", "0", "1"], ["84008.5", "0", "0", "0"], ["83985.6", "0.04902468", "0", "2"], ["83981.2", "0.02377547", "0", "2"], ["83936.8", "0.00001197", "0", "1"], ["83931.3", "0.01189953", "0", "2"]], "ts": "1742555185104", "checksum": 1821562698, "seqId": 49927504609, "prevSeqId": 49927504583}], "record_time": 1742555185.105554, "EXCHANGE": "OKX"}
{"arg": {"channel": "books", "instId": "BTC-USDT"}, "action": "update", "data": [{"asks": [["84104", "1.2", "0", "2"], ["84106.7", "0.29313233", "0", "1"], ["84116.4", "0.35641581", "0", "1"], ["84172.2", "0.1", "0", "1"], ["84237.6", "0", "0", "0"], ["84237.7", "0", "0", "0"], ["84237.8", "0", "0", "0"]], "bids": [["84049.1", "0", "0", "0"], ["84036", "0.45061171", "0", "2"], ["83913", "0.00002243", "0", "1"]], "ts": "1742555185204", "checksum": 1821562698, "seqId": 49927504622, "prevSeqId": 49927504609}], "record_time": 1742555185.206075, "EXCHANGE": "OKX"}
{"arg": {"channel": "books", "instId": "BTC-USDT"}, "action": "update", "data": [{"asks": [["84072.3", "0", "0", "0"], ["84078.6", "0", "0", "0"], ["84078.7", "0.09708909", "0", "3"], ["84096", "0.01774536", "0", "1"], ["84096.1", "0.17821722", "0", "1"], ["84096.2", "1.78107744", "0", "3"], ["84102.4", "0.2498", "0", "1"], ["84104.8", "0.25821722", "0", "3"], ["84105.6", "0.03999999", "0", "1"], ["84106.4", "0", "0", "0"], ["84109", "0.471116", "0", "1"], ["84112.1", "0.0615901", "0", "2"], ["84122.6", "0.00004312", "0", "1"], ["84123.2", "0", "0", "0"], ["84177.7", "0", "0", "0"], ["84237.6", "0.0142", "0", "1"], ["84237.7", "0.071", "0", "5"]], "bids": [["84068.2", "0.01087654", "0", "4"], ["84050.7", "0.1346365", "0", "3"], ["84050.6", "0.03089604", "0", "1"], ["84049.4", "0.60871481", "0", "2"], ["84044.7", "0.06108808", "0", "1"], ["84039.3", "0.2498", "0", "1"], ["84033.2", "0.06956032", "0", "1"], ["84033.1", "0", "0", "0"], ["83914.1", "0", "0", "0"], ["83913", "0", "0", "0"]], "ts": "1742555185304", "checksum": 369122702, "seqId": 49927504665, "prevSeqId": 49927504622}], "record_time": 1742555185.304944, "EXCHANGE": "OKX"}
{"arg": {"channel": "books", "instId": "BTC-USDT"}, "action": "update", "data": [{"asks": [], "bids": [["84049.4", "0.25186481", "0", "1"], ["84036.7", "0.17843", "0", "1"], ["84008.5", "0.01188774", "0", "1"], ["83981.2", "0.01188786", "0", "1"], ["83915.9", "0", "0", "0"], ["83914.2", "0", "0", "0"]], "ts": "1742555185404", "checksum": 369122702, "seqId": 49927504673, "prevSeqId": 49927504665}], "record_time": 1742555185.405715, "EXCHANGE": "OKX"}
{"arg": {"channel": "books", "instId": "BTC-USDT"}, "action": "update", "data": [{"asks": [["84071.1", "0.08991011", "0", "1"], ["84079.8", "0.16933358", "0", "2"], ["84082.2", "0.35685", "0", "1"], ["84084.7", "1.09", "0", "4"], ["84237.6", "0", "0", "0"], ["84237.7", "0", "0", "0"]], "bids": [["84053.6", "0", "0", "0"], ["84049.4", "0.60871481", "0", "2"], ["84036.7", "0", "0", "0"], ["84008.5", "0", "0", "0"], ["83981.2", "0.02377547", "0", "2"], ["83978.4", "0", "0", "0"], ["83915.9", "0.00014559", "0", "1"], ["83914.2", "0.03486546", "0", "1"], ["83914.1", "0.00001066", "0", "1"], ["83913", "0.00002243", "0", "1"]], "ts": "1742555185504", "checksum": 1195613222, "seqId": 49927504695, "prevSeqId": 49927504673}], "record_time": 1742555185.504854, "EXCHANGE": "OKX"}
{"arg": {"channel": "books", "instId": "BTC-USDT"}, "action": "update", "data": [{"asks": [["84081.5", "0.17843", "0", "1"], ["84084.1", "0", "0", "0"], ["84092.5", "0", "0", "0"], ["84096.2", "0.18660166", "0", "2"], ["84121.6", "0.01188756", "0", "1"], ["84121.7", "0", "0", "0"], ["84123", "0", "0", "0"], ["84125.6", "0", "0", "0"], ["84182.5", "0", "0", "0"], ["84190.9", "0.27607157", "0", "1"], ["84199.3", "0", "0", "0"], ["84205.8", "0.01188756", "0", "1"], ["84205.9", "0.06", "0", "2"], ["84207.7", "1.90391514", "0", "2"], ["84216.1", "0", "0", "0"], ["84223.8", "0.17896554", "0", "3"], ["84237.6", "0.0142", "0", "1"], ["84237.7", "0.071", "0", "5"], ["84237.8", "0.00007018", "0", "2"], ["84238.1", "0.00006534", "0", "2"], ["84238.6", "0.03", "0", "1"]], "bids": [["84044.4", "0.21910786", "0", "2"], ["84043.8", "0", "0", "0"], ["84035.6", "0.01", "0", "1"], ["84016.6", "0.00060645", "0", "1"], ["84015.5", "0", "0", "0"], ["84015.4", "0.01188756", "0", "1"], ["84014.4", "0", "0", "0"], ["83979", "0.00579982", "0", "1"], ["83978.4", "0.00016248", "0", "1"], ["83964", "0", "0", "0"], ["83955.1", "0", "0", "0"], ["83946.7", "0.00002763", "0", "2"], ["83937.7", "0", "0", "0"], ["83912.6", "0.00013227", "0", "2"], ["83912.5", "0.00016336", "0", "3"], ["83912", "0.00001198", "0", "1"]], "ts": "1742555185604", "checksum": 1195613222, "seqId": 49927504736, "prevSeqId": 49927504695}], "record_time": 1742555185.606014, "EXCHANGE": "OKX"}
{"arg": {"channel": "books", "instId": "BTC-USDT"}, "action": "update", "data": [{"asks": [["84076.5", "0.44473566", "0", "2"], ["84077.7", "0.17821722", "0", "1"], ["84078.6", "0.03276811", "0", "1"], ["84078.7", "0.06276919", "0", "2"], ["84079.8", "0.51104496", "0", "1"], ["84083", "1", "0", "1"], ["84084", "0.37374545", "0", "2"], ["84084.7", "0.09", "0", "3"], ["84092.2", "1.55638389", "0", "1"], ["84096", "0", "0", "0"], ["84096.1", "0.24806654", "0", "2"], ["84096.2", "0.1189686", "0", "1"], ["84102", "1.052", "0", "3"], ["84104", "1", "0", "1"], ["84121.6", "2.8855273", "0", "2"], ["84138.8", "0.01774536", "0", "1"], ["84237.7", "0", "0", "0"], ["84237.8", "0", "0", "0"], ["84238.1", "0", "0", "0"], ["84238.6", "0", "0", "0"]], "bids": [["84068.2", "0.01057979", "0", "4"], ["84050.7", "0.102", "0", "2"], ["84050.6", "0.06580999", "0", "2"], ["84044.4", "0.2013625", "0", "1"], ["84038.6", "1.60760802", "0", "1"], ["84036.7", "0.17843", "0", "1"], ["84036.1", "0.01774536", "0", "1"], ["84033.2", "0", "0", "0"], ["84033.1", "0.06912888", "0", "1"], ["84009.2", "2.82939759", "0", "1"], ["83963.4", "0.00609995", "0", "1"], ["83937.8", "0", "0", "0"], ["83937", "0.0020187", "0", "1"], ["83914.1", "0", "0", "0"], ["83913", "0", "0", "0"], ["83912.6", "0", "0", "0"], ["83912.5", "0", "0", "0"], ["83912", "0", "0", "0"]], "ts": "1742555185704", "checksum": 1099224584, "seqId": 49927504777, "prevSeqId": 49927504736}], "record_time": 1742555185.704324, "EXCHANGE": "OKX"}
{"arg": {"channel": "books", "instId": "BTC-USDT"}, "action": "update", "data": [{"asks": [["84068.3", "1.41599429", "0", "23"], ["84071.1", "0", "0", "0"], ["84083.9", "0.05617506", "0", "1"], ["84104.8", "0.17821722", "0", "1"], ["84105.6", "0.07999999", "0", "2"], ["84106.4", "0.03999999", "0", "1"], ["84237.6", "0", "0", "0"]], "bids": [["84068.2", "0.00981979", "0", "3"], ["84036.7", "0", "0", "0"], ["84008.5", "0.01188774", "0", "1"], ["83981.2", "0.01188786", "0", "1"]], "ts": "1742555185804", "checksum": 1931786944, "seqId": 49927504793, "prevSeqId": 49927504777}], "record_time": 1742555185.804538, "EXCHANGE": "OKX"}
{"arg": {"channel": "books", "instId": "BTC-USDT"}, "action": "update", "data": [{"asks": [["84068.3", "1.40560019", "0", "22"], ["84080.1", "0.0103941", "0", "1"], ["84092.1", "0.01774536", "0", "1"], ["84138.8", "0", "0", "0"], ["84237.3", "0", "0", "0"]], "bids": [["84039.2", "0.17843", "0", "1"], ["84038.7", "0.01774536", "0", "1"], ["84036.1", "0", "0", "0"], ["84013", "0.2", "0", "1"], ["84008.5", "0", "0", "0"], ["83981.2", "0.02377547", "0", "2"], ["83914.2", "0", "0", "0"]], "ts": "1742555185904", "checksum": -1672094379, "seqId": 49927504810, "prevSeqId": 49927504793}], "record_time": 1742555185.904942, "EXCHANGE": "OKX"}
{"arg": {"channel": "books", "instId": "BTC-USDT"}, "action": "update", "data": [{"asks": [], "bids": [["84054.5", "1.00773181", "0", "2"], ["84054.2", "0", "0", "0"], ["84053.2", "0.0134", "0", "1"], ["84013", "0", "0", "0"], ["84008.5", "0.01188774", "0", "1"], ["83981.2", "0.01188786", "0", "1"], ["83914.2", "0.03486546", "0", "1"]], "ts": "1742555186004", "checksum": -1672094379, "seqId": 49927504820, "prevSeqId": 49927504810}], "record_time": 1742555186.005042, "EXCHANGE": "OKX"}
{"arg": {"channel": "books", "instId": "BTC-USDT"}, "action": "update", "data": [{"asks": [["84079.2", "0", "0", "0"], ["84091.1", "0", "0", "0"], ["84091.8", "0.24222629", "0", "2"], ["84102", "0.052", "0", "2"], ["84197.1", "0", "0", "0"], ["84237.3", "0.0142", "0", "1"], ["84237.6", "0.0142", "0", "1"], ["84237.7", "0.071", "0", "5"]], "bids": [["84054.5", "1.00827781", "0", "3"], ["84033.8", "0.00420994", "0", "1"], ["84033.6", "0.23801962", "0", "1"], ["84014.5", "0", "0", "0"], ["84013.1", "0.01832753", "0", "1"], ["84008.5", "0", "0", "0"], ["83981.2", "0.02377547", "0", "2"], ["83943.2", "0", "0", "0"], ["83941.6", "0.18327539", "0", "1"]], "ts": "1742555186104", "checksum": -1672094379, "seqId": 49927504864, "prevSeqId": 49927504820}], "record_time": 1742555186.111335, "EXCHANGE": "OKX"}
{"arg": {"channel": "books", "instId": "BTC-USDT"}, "action": "update", "data": [{"asks": [["84068.3", "1.41599429", "0", "23"], ["84080.1", "0", "0", "0"], ["84088.6", "0.60751715", "0", "1"], ["84091.7", "0.01774536", "0", "1"], ["84092.1", "0", "0", "0"], ["84120.3", "0.89309126", "0", "2"]], "bids": [["84039.4", "0.61607501", "0", "1"], ["84000.1", "3.17204302", "0", "2"], ["83969.4", "0.01189648", "0", "1"], ["83914.2", "0", "0", "0"]], "ts": "1742555186204", "checksum": 1931786944, "seqId": 49927504877, "prevSeqId": 49927504864}], "record_time": 1742555186.215921, "EXCHANGE": "OKX"}
{"arg": {"channel": "books", "instId": "BTC-USDT"}, "action": "update", "data": [{"asks": [["84068.3", "1.55238254", "0", "24"], ["84077.8", "0.35927631", "0", "2"], ["84077.9", "0.15229485", "0", "2"], ["84078.7", "0.06400836", "0", "2"], ["84079.7", "0.35685", "0", "1"], ["84079.8", "0.5311934", "0", "2"], ["84080.6", "0.04", "0", "1"], ["84082.3", "0.0042075", "0", "1"], ["84083", "0", "0", "0"], ["84083.7", "1", "0", "1"], ["84084.9", "0.03314782", "0", "1"], ["84085", "0.03248376", "0", "1"], ["84085.9", "0", "0", "0"], ["84091.8", "0.00420676", "0", "1"], ["84091.9", "0.0613698", "0", "1"], ["84092.1", "0.23801914", "0", "1"], ["84104.8", "0.25821722", "0", "3"], ["84105.6", "0.03999999", "0", "1"], ["84106.4", "0", "0", "0"], ["84115.3", "0.01188845", "0", "1"], ["84115.5", "0.01188842", "0", "1"], ["84116.3", "0.01556656", "0", "2"], ["84116.4", "0.3683041", "0", "2"], ["84116.5", "0.02100489", "0", "2"], ["84117.1", "0.01188819", "0", "1"], ["84160.8", "0.02389911", "0", "2"], ["84165.8", "1.375411", "0", "1"], ["84171.3", "0", "0", "0"], ["84192", "0", "0", "0"], ["84194.4", "0", "0", "0"], ["84196.9", "0", "0", "0"], ["84202.5", "0.03", "0", "1"], ["84210.9", "0", "0", "0"], ["84237.7", "0", "0", "0"]], "bids": [["84068.2", "0.01021698", "0", "5"], ["84060.2", "0", "0", "0"], ["84058.8", "0.1202274", "0", "1"], ["84057.5", "0.00007494", "0", "1"], ["84055.8", "0.00006", "0", "1"], ["84055.2", "0", "0", "0"], ["84054.6", "0.55967446", "0", "2"], ["84054.5", "0.00773181", "0", "1"], ["84051.4", "1", "0", "1"], ["84051.3", "0", "0", "0"], ["84051", "0.04", "0", "1"], ["84050.6", "0.06833844", "0", "2"], ["84050", "0.03136403", "0", "4"], ["84049.4", "0.25186481", "0", "1"], ["84049.3", "0.03416989", "0", "1"], ["84046.9", "0.35685", "0", "1"], ["84045.1", "0.01790207", "0", "2"], ["84043.8", "0.00475942", "0", "1"], ["84043.6", "0.03137929", "0", "1"], ["84043", "0.03476897", "0", "2"], ["84039.2", "0", "0", "0"], ["84036.6", "0.06454903", "0", "1"], ["84036", "0.001784", "0", "1"], ["84035.9", "0.14044962", "0", "2"], ["84035", "0", "0", "0"], ["84033.6", "0.23801963", "0", "1"], ["84023", "0.554742", "0", "1"], ["84005.3", "0.00001196", "0", "1"], ["84000.5", "0.00001501", "0", "1"], ["83987", "0", "0", "0"], ["83983.4", "0.12726671", "0", "3"], ["83981.2", "0", "0", "0"], ["83979", "0", "0", "0"], ["83977.9", "0.28646195", "0", "1"], ["83975.5", "0.00005458", "0", "1"], ["83972", "0", "0", "0"], ["83971.6", "0", "0", "0"], ["83971.5", "0.07103511", "0", "2"], ["83969.8", "0.36187575", "0", "1"], ["83960.9", "0.00579962", "0", "1"], ["83954.8", "0.00579962", "0", "1"], ["83954.7", "0.00579962", "0", "1"], ["83952.4", "0", "0", "0"], ["83951.7", "0", "0", "0"], ["83950.7", "0", "0", "0"], ["83941.2", "0.01784691", "0", "1"], ["83940.2", "0.01786089", "0", "1"], ["83933", "0", "0", "0"], ["83923.5", "0.01774462", "0", "1"], ["83920.6", "0.01188752", "0", "1"], ["83914.2", "0.03486546", "0", "1"]], "ts": "1742555186304", "checksum": -1208444992, "seqId": 49927505042, "prevSeqId": 49927504877}], "record_time": 1742555186.304572, "EXCHANGE": "OKX"}
{"arg": {"channel": "books", "instId": "BTC-USDT"}, "action": "update", "data": [{"asks": [["84077.8", "0.35641581", "0", "1"], ["84082.2", "0", "0", "0"], ["84088.2", "0.23802592", "0", "1"], ["84091.7", "0", "0", "0"], ["84092", "0.01774536", "0", "1"], ["84092.1", "0", "0", "0"], ["84237.7", "0.071", "0", "5"]], "bids": [["84053.2", "0.147005", "0", "2"], ["84052.7", "1", "0", "1"], ["84051.7", "0.0005925", "0", "1"], ["84051.4", "0", "0", "0"], ["84048.8", "0.17843", "0", "1"], ["84046.9", "0", "0", "0"], ["84033.6", "0", "0", "0"], ["84031.6", "0.23802592", "0", "1"], ["83961", "0.00579962", "0", "1"], ["83954.9", "0.00579962", "0", "1"], ["83945.4", "0.12249895", "0", "2"], ["83916.3", "0", "0", "0"], ["83915.9", "0", "0", "0"], ["83914.2", "0", "0", "0"]], "ts": "1742555186404", "checksum": -986308438, "seqId": 49927505062, "prevSeqId": 49927505042}], "record_time": 1742555186.406378, "EXCHANGE": "OKX"}
{"arg": {"channel": "books", "instId": "BTC-USDT"}, "action": "update", "data": [{"asks": [["84062.9", "0.76062708", "0", "6"], ["84063", "1.12916944", "0", "10"], ["84063.5", "1.66515006", "0", "19"], ["84063.8", "0.38471766", "0", "1"], ["84063.9", "0.35964043", "0", "1"], ["84064", "0.0146", "0", "1"], ["84066", "0.0146", "0", "1"], ["84067.2", "0.01055", "0", "1"], ["84068", "0.0146", "0", "1"], ["84068.1", "1.05050144", "0", "2"], ["84068.2", "0.5880441", "0", "4"], ["84068.3", "0.34038204", "0", "9"], ["84068.8", "0.00773225", "0", "1"], ["84069.6", "0", "0", "0"], ["84069.9", "0", "0", "0"], ["84072.2", "0.05193442", "0", "2"], ["84073", "0.000015", "0", "1"], ["84074.6", "0", "0", "0"], ["84075.7", "0", "0", "0"], ["84076.7", "0.016", "0", "1"], ["84077.8", "0.35643981", "0", "2"], ["84077.9", "0.11890903", "0", "1"], ["84078.6", "0", "0", "0"], ["84078.7", "0", "0", "0"], ["84078.9", "1.002", "0", "2"], ["84079.7", "0", "0", "0"], ["84079.8", "0.10174243", "0", "1"], ["84081.5", "0", "0", "0"], ["84081.7", "0", "0", "0"], ["84083.3", "0.00060645", "0", "1"], ["84083.7", "0", "0", "0"], ["84083.8", "0.26184189", "0", "2"], ["84084.9", "0", "0", "0"], ["84085", "0", "0", "0"], ["84086", "0", "0", "0"], ["84087.4", "0", "0", "0"], ["84087.5", "0", "0", "0"], ["84088", "0", "0", "0"], ["84088.2", "0", "0", "0"], ["84088.3", "0", "0", "0"], ["84090", "0.001", "0", "1"], ["84091.9", "0", "0", "0"], ["84094.1", "0", "0", "0"], ["84094.4", "0.11235012", "0", "2"], ["84096.1", "0.17821722", "0", "1"], ["84096.2", "0", "0", "0"], ["84099.9", "0.00101534", "0", "2"], ["84102.4", "0", "0", "0"], ["84107.8", "0.11846252", "0", "1"], ["84109.3", "0", "0", "0"], ["84112.1", "0.00367825", "0", "1"], ["84113.1", "0", "0", "0"], ["84115.5", "0", "0", "0"], ["84116.3", "0.00367825", "0", "1"], ["84116.4", "0.35641581", "0", "1"], ["84116.5", "0.00911661", "0", "1"], ["84117.1", "0", "0", "0"], ["84131.4", "0.17821722", "0", "1"], ["84133.3", "0.00504382", "0", "4"], ["84133.6", "0", "0", "0"], ["84155.5", "0.0024", "0", "1"], ["84163.8", "0.01188842", "0", "1"], ["84167.2", "0.0060996", "0", "1"], ["84169.3", "0", "0", "0"], ["84173.4", "0.71313968", "0", "1"], ["84184.8", "0.01188831", "0", "1"], ["84187.2", "0.01188829", "0", "1"], ["84189.7", "0.01188828", "0", "1"], ["84203.9", "0.01188819", "0", "1"], ["84215.4", "0.84031699", "0", "2"], ["84237.8", "0.00007018", "0", "2"], ["84238.1", "0.00006534", "0", "2"], ["84238.6", "0.03", "0", "1"], ["84239.3", "0.00011161", "0", "1"], ["84239.7", "0.01652", "0", "1"]], "bids": [["84068.2", "0", "0", "0"], ["84068.1", "0", "0", "0"], ["84067.1", "0", "0", "0"], ["84066.6", "0", "0", "0"], ["84065.7", "0", "0", "0"], ["84063.4", "0", "0", "0"], ["84062.9", "0", "0", "0"], ["84062.8", "0", "0", "0"], ["84060.7", "0", "0", "0"], ["84059.6", "0.02530935", "0", "1"], ["84059.3", "0", "0", "0"], ["84058.8", "0", "0", "0"], ["84055.2", "0.01190254", "0", "1"], ["84054.9", "0.2025", "0", "1"], ["84054.8", "0", "0", "0"], ["84054.6", "0.2383603", "0", "1"], ["84053.2", "0", "0", "0"], ["84052.7", "0", "0", "0"], ["84051.7", "0", "0", "0"], ["84051.5", "0.14043766", "0", "1"], ["84050.6", "0", "0", "0"], ["84050.1", "0", "0", "0"], ["84050", "0.00033629", "0", "3"], ["84049.3", "0", "0", "0"], ["84048.8", "0", "0", "0"], ["84048.4", "0.0134", "0", "1"], ["84046.2", "0", "0", "0"], ["84045.7", "0", "0", "0"], ["84044.7", "0", "0", "0"], ["84043.6", "0", "0", "0"], ["84043", "0.00011161", "0", "1"], ["84042.7", "0.00876252", "0", "1"], ["84042.1", "0.04021", "0", "1"], ["84041.9", "0", "0", "0"], ["84041.5", "1", "0", "1"], ["84041.4", "0.06940334", "0", "1"], ["84041.3", "0", "0", "0"], ["84040.1", "0", "0", "0"], ["84039.9", "0", "0", "0"], ["84039.4", "0", "0", "0"], ["84039.3", "0", "0", "0"], ["84038.6", "0", "0", "0"], ["84036.6", "0", "0", "0"], ["84034.6", "0", "0", "0"], ["84033.5", "0", "0", "0"], ["84033.1", "0", "0", "0"], ["84032.5", "0", "0", "0"], ["84031.6", "0", "0", "0"], ["84029.6", "0", "0", "0"], ["84029", "0.23803873", "0", "1"], ["84028.8", "0.2025", "0", "1"], ["84028", "0.106", "0", "4"], ["84027.2", "0.053", "0", "2"], ["84027", "1", "0", "1"], ["84025.6", "0", "0", "0"], ["84025.2", "0", "0", "0"], ["84024.8", "0", "0", "0"], ["84024", "0.1", "0", "2"], ["84023.2", "0.05", "0", "1"], ["84023", "0", "0", "0"], ["84014.1", "0.00100367", "0", "1"], ["84014", "0", "0", "0"], ["84012.7", "0.71855168", "0", "2"], ["84012.3", "0.34676624", "0", "2"], ["84010.3", "0", "0", "0"], ["84009.2", "0", "0", "0"], ["83975.3", "0.000015", "0", "1"], ["83972", "0.0060996", "0", "1"], ["83970.7", "0.71890549", "0", "3"], ["83966.7", "0.18431682", "0", "2"], ["83961.1", "0.0060996", "0", "1"], ["83954.9", "0.01159924", "0", "2"], ["83939", "0.04188842", "0", "2"], ["83933.2", "0", "0", "0"], ["83916.3", "0.03074456", "0", "2"], ["83915.9", "0.00014559", "0", "1"], ["83914.2", "0.03486546", "0", "1"], ["83914.1", "0.00001066", "0", "1"], ["83913", "0.00002243", "0", "1"], ["83912.6", "0.00013227", "0", "2"], ["83912.5", "0.00016336", "0", "3"], ["83912", "0.00001198", "0", "1"], ["83910", "0.0000128", "0", "1"], ["83909.8", "0.2025", "0", "1"], ["83909", "0.17828186", "0", "3"], ["83908.6", "0.35687932", "0", "2"], ["83908.3", "0.00422253", "0", "1"], ["83907", "0.00005223", "0", "1"], ["83906.6", "0.00001026", "0", "1"], ["83906", "0.00377005", "0", "1"], ["83905.5", "0.00023819", "0", "2"], ["83905", "0.00083264", "0", "2"], ["83904.9", "0.00001038", "0", "1"], ["83904.7", "0.00005672", "0", "1"], ["83904", "0.00037866", "0", "1"], ["83903.9", "0.00001958", "0", "1"], ["83903.6", "0.0238195", "0", "4"], ["83903.4", "0.00001931", "0", "1"], ["83902.9", "0.0007442", "0", "1"], ["83902.7", "0.04361002", "0", "3"], ["83902.3", "0.03001053", "0", "2"], ["83902.1", "0.000012", "0", "1"], ["83901.6", "0.00265136", "0", "6"]], "ts": "1742555186504", "checksum": -528593051, "seqId": 49927505502, "prevSeqId": 49927505062}], "record_time": 1742555186.506936, "EXCHANGE": "OKX"}
{"arg": {"channel": "books", "instId": "BTC-USDT"}, "action": "update", "data": [{"asks": [["84060.1", "0.98305962", "0", "11"], ["84060.3", "0.03629389", "0", "1"], ["84060.4", "0.052", "0", "2"], ["84062", "0.0146", "0", "1"], ["84062.9", "0.052", "0", "2"], ["84063", "0", "0", "0"], ["84063.1", "0.02530935", "0", "1"], ["84063.5", "0.052", "0", "2"], ["84063.8", "0.12776679", "0", "1"], ["84067.1", "0.00111919", "0", "1"], ["84068", "0.28308779", "0", "2"], ["84068.1", "0.03167", "0", "1"], ["84068.2", "0.2025", "0", "1"], ["84068.3", "0.24879357", "0", "6"], ["84070", "0.04945532", "0", "2"], ["84070.1", "0.052", "0", "2"], ["84070.4", "0.03454664", "0", "1"], ["84070.5", "0.53505503", "0", "3"], ["84070.7", "0.03279645", "0", "1"], ["84072.1", "0.31927609", "0", "2"], ["84072.2", "0.02915443", "0", "1"], ["84075.6", "1", "0", "1"], ["84076.5", "0.43034324", "0", "1"], ["84077", "0.10511707", "0", "3"], ["84077.5", "0.03", "0", "1"], ["84077.6", "0.03", "0", "1"], ["84077.8", "0.35641581", "0", "1"], ["84078.5", "0.255094", "0", "4"], ["84078.9", "0.002", "0", "1"], ["84079.2", "0.03502563", "0", "1"], ["84079.3", "0.03481982", "0", "1"], ["84079.8", "0.15829892", "0", "2"], ["84081.5", "0.17844", "0", "1"], ["84081.7", "0.11898911", "0", "1"], ["84082.3", "0.00431911", "0", "2"], ["84082.7", "0.23804033", "0", "1"], ["84083.8", "0", "0", "0"], ["84083.9", "0.11235012", "0", "2"], ["84084", "0.42150478", "0", "2"], ["84085.9", "0.06169", "0", "1"], ["84086.4", "0.06829926", "0", "1"], ["84087.9", "0.06505415", "0", "1"], ["84089", "0.0512652", "0", "1"], ["84089.8", "0.02381054", "0", "2"], ["84092", "0", "0", "0"], ["84093.1", "0.30321059", "0", "2"], ["84094.4", "0.64962012", "0", "3"], ["84102.3", "0.4611428", "0", "2"], ["84103", "0.016", "0", "1"], ["84103.3", "0.05793548", "0", "1"], ["84104.8", "0.25821721", "0", "3"], ["84105.8", "0.02324395", "0", "2"], ["84106.7", "0.43336434", "0", "2"], ["84108", "0.1", "0", "1"], ["84111.9", "0.06191291", "0", "1"], ["84112.8", "0", "0", "0"], ["84114.3", "0.18608224", "0", "1"], ["84114.4", "0", "0", "0"], ["84115", "0.054715", "0", "2"], ["84115.3", "0", "0", "0"], ["84120.2", "0.01774536", "0", "1"], ["84122.7", "0.5081818", "0", "2"], ["84125.7", "0", "0", "0"], ["84126.4", "0", "0", "0"], ["84127.1", "0", "0", "0"], ["84130.3", "0.00713179", "0", "1"], ["84131.3", "0.27619018", "0", "2"], ["84134.5", "0.02697662", "0", "1"], ["84136.5", "0", "0", "0"], ["84140.3", "0.08754", "0", "1"], ["84142.8", "0.15903203", "0", "1"], ["84145.2", "0", "0", "0"], ["84151.4", "0", "0", "0"], ["84163.8", "0", "0", "0"], ["84164.2", "0.21608002", "0", "2"], ["84165.8", "0", "0", "0"], ["84167.4", "0.00594549", "0", "1"], ["84173", "0.00298666", "0", "1"], ["84181.4", "0.00597332", "0", "1"], ["84184.8", "0", "0", "0"], ["84187.2", "0", "0", "0"], ["84189.7", "0", "0", "0"], ["84189.8", "0.00895999", "0", "1"], ["84191.8", "0.21861", "0", "1"], ["84198.2", "0.01194665", "0", "1"], ["84201", "0.03", "0", "1"], ["84203.9", "0", "0", "0"], ["84206.6", "0.01493332", "0", "1"], ["84234", "0", "0", "0"], ["84234.4", "0", "0", "0"], ["84235", "0", "0", "0"], ["84235.2", "0", "0", "0"], ["84235.7", "0", "0", "0"], ["84236", "0", "0", "0"], ["84236.6", "0", "0", "0"], ["84236.8", "0", "0", "0"], ["84237", "0", "0", "0"], ["84237.2", "0", "0", "0"], ["84237.3", "0", "0", "0"], ["84237.6", "0", "0", "0"], ["84237.7", "0", "0", "0"], ["84237.8", "0", "0", "0"], ["84238.1", "0", "0", "0"], ["84238.6", "0", "0", "0"], ["84239.3", "0", "0", "0"], ["84239.7", "0", "0", "0"]], "bids": [["84062.6", "0", "0", "0"], ["84061.2", "0", "0", "0"], ["84060.3", "0", "0", "0"], ["84060", "0.04247886", "0", "3"], ["84059.6", "0", "0", "0"], ["84058.5", "0.00055974", "0", "1"], ["84055.8", "0", "0", "0"], ["84055.2", "0", "0", "0"], ["84054.9", "0", "0", "0"], ["84054.6", "0", "0", "0"], ["84053.1", "0.02530935", "0", "1"], ["84051.2", "0", "0", "0"], ["84050.9", "0.000015", "0", "1"], ["84049.4", "0", "0", "0"], ["84048.4", "0", "0", "0"], ["84048.1", "0", "0", "0"], ["84046.1", "0.00006", "0", "1"], ["84045", "0", "0", "0"], ["84044.8", "0.0015135", "0", "1"], ["84044.7", "0.03618589", "0", "1"], ["84044.4", "0", "0", "0"], ["84043.8", "0", "0", "0"], ["84043.6", "0.00475943", "0", "1"], ["84043.5", "0.04", "0", "1"], ["84042.7", "0.03104493", "0", "1"], ["84042.4", "1.15337513", "0", "4"], ["84041.8", "0.03176486", "0", "1"], ["84041.5", "0", "0", "0"], ["84041.4", "0", "0", "0"], ["84041.3", "0.03165595", "0", "1"], ["84038.7", "0.17844", "0", "1"], ["84037.5", "0.00713967", "0", "1"], ["84037.4", "0.24191038", "0", "1"], ["84035.9", "0.19932663", "0", "3"], ["84035.7", "0.03300763", "0", "1"], ["84035.1", "0.05944451", "0", "1"], ["84035", "0.03316493", "0", "1"], ["84033.7", "0.15198551", "0", "2"], ["84033.1", "0.03150461", "0", "1"], ["84032.6", "0", "0", "0"], ["84031.6", "0.11353345", "0", "1"], ["84029.6", "0.25578569", "0", "2"], ["84029.3", "0.00353141", "0", "1"], ["84029", "0", "0", "0"], ["84028.9", "0", "0", "0"], ["84028.7", "0.06412307", "0", "1"], ["84028.6", "0", "0", "0"], ["84028", "0", "0", "0"], ["84027.2", "0", "0", "0"], ["84027", "0", "0", "0"], ["84026.4", "0.14651845", "0", "3"], ["84025.6", "0.066", "0", "3"], ["84025.5", "0.06864027", "0", "1"], ["84024.9", "0.06250348", "0", "1"], ["84024.8", "0.54210201", "0", "2"], ["84024", "0", "0", "0"], ["84023.2", "0", "0", "0"], ["84022.4", "0.1", "0", "2"], ["84021.6", "0.05", "0", "1"], ["84020.4", "0.17438074", "0", "1"], ["84018.4", "0", "0", "0"], ["84018.3", "0", "0", "0"], ["84017.8", "0.02817312", "0", "1"], ["84016.5", "0", "0", "0"], ["84013.6", "0.1", "0", "1"], ["84012.8", "0.10142232", "0", "1"], ["84012", "0.01188822", "0", "1"], ["84010.5", "0", "0", "0"], ["84010.4", "0.01188821", "0", "1"], ["84010.3", "0.01188821", "0", "1"], ["84005.9", "0", "0", "0"], ["84001.6", "0", "0", "0"], ["84000.1", "0", "0", "0"], ["84000", "20.47588537", "0", "34"], ["83997.2", "0.01188807", "0", "1"], ["83996.8", "0.0028533", "0", "1"], ["83996.2", "0", "0", "0"], ["83994.1", "0.01188832", "0", "1"], ["83994", "0.00105332", "0", "1"], ["83993", "0.12491", "0", "1"], ["83991.6", "0.0120477", "0", "2"], ["83990.4", "0", "0", "0"], ["83978.4", "0.00016245", "0", "1"], ["83977.9", "0", "0", "0"], ["83977.6", "0.05379224", "0", "2"], ["83972", "0.1310096", "0", "2"], ["83969.8", "0", "0", "0"], ["83968.2", "0.00298666", "0", "1"], ["83964.7", "0.01188824", "0", "1"], ["83955.8", "0.00597332", "0", "1"], ["83955", "0.00610018", "0", "1"], ["83947.1", "0.00895999", "0", "1"], ["83939", "0.03", "0", "1"], ["83938.7", "0.01194665", "0", "1"], ["83937", "0", "0", "0"], ["83936.1", "0.0000442", "0", "1"], ["83935.4", "0.00201966", "0", "1"], ["83930.1", "0.01493332", "0", "1"], ["83920.6", "0", "0", "0"], ["83906.6", "0.00002224", "0", "2"], ["83903.6", "0.00004426", "0", "2"], ["83902.9", "0", "0", "0"], ["83902.7", "0", "0", "0"], ["83902.3", "0", "0", "0"], ["83902.1", "0", "0", "0"], ["83901.6", "0", "0", "0"]], "ts": "1742555186604", "checksum": 366600014, "seqId": 49927506272, "prevSeqId": 49927505502}], "record_time": 1742555186.606779, "EXCHANGE": "OKX"}
{"arg": {"channel": "books", "instId": "BTC-USDT"}, "action": "update", "data": [{"asks": [["84060.1", "0.34146062", "0", "5"], ["84060.3", "0", "0", "0"], ["84060.4", "0", "0", "0"], ["84062.9", "0", "0", "0"], ["84063", "0.01668856", "0", "1"], ["84063.5", "0", "0", "0"], ["84063.8", "0", "0", "0"], ["84063.9", "0", "0", "0"], ["84067.2", "0", "0", "0"], ["84068", "0.18690327", "0", "2"], ["84068.1", "0", "0", "0"], ["84068.2", "0", "0", "0"], ["84068.3", "0.07640532", "0", "4"], ["84068.6", "0.01055", "0", "1"], ["84070", "0.0146", "0", "1"], ["84070.1", "0.016", "0", "1"], ["84070.4", "0", "0", "0"], ["84070.5", "0.50001197", "0", "2"], ["84070.7", "0", "0", "0"], ["84072.1", "0.06454073", "0", "2"], ["84073.4", "0.03241296", "0", "1"], ["84073.7", "0.06882149", "0", "2"], ["84073.9", "0.03452246", "0", "1"], ["84074.1", "0.03", "0", "1"], ["84074.3", "0.03", "0", "1"], ["84074.8", "0.03167", "0", "1"], ["84075.6", "0", "0", "0"], ["84076.8", "0.0103941", "0", "1"], ["84077", "0.04", "0", "1"], ["84077.7", "0.23821722", "0", "3"], ["84079.2", "0", "0", "0"], ["84079.3", "0", "0", "0"], ["84079.8", "0.46303059", "0", "2"], ["84080", "1.0146", "0", "2"], ["84080.2", "0.03514699", "0", "1"], ["84080.4", "0.03429051", "0", "2"], ["84081.5", "0", "0", "0"], ["84082.4", "0.03498124", "0", "1"], ["84082.5", "0.03242901", "0", "1"], ["84082.7", "0", "0", "0"], ["84084", "0.35914545", "0", "1"], ["84084.6", "0", "0", "0"], ["84084.7", "0.06", "0", "2"], ["84085.9", "0", "0", "0"], ["84086.4", "0", "0", "0"], ["84086.7", "0.08376", "0", "1"], ["84087.4", "0.06536701", "0", "1"], ["84087.9", "0", "0", "0"], ["84088.4", "0.23802357", "0", "1"], ["84089.1", "0.07013598", "0", "1"], ["84089.7", "0.06397071", "0", "1"], ["84091.2", "0.06176888", "0", "1"], ["84097.6", "0.5564676", "0", "1"], ["84117.3", "0.07909163", "0", "2"], ["84119.1", "0.91745", "0", "1"], ["84139", "0", "0", "0"], ["84151.9", "0.089838", "0", "1"], ["84152.6", "0.57526325", "0", "2"], ["84152.8", "1.375623", "0", "1"], ["84233.9", "0", "0", "0"]], "bids": [["84060", "0.50740896", "0", "8"], ["84055.1", "0.0134", "0", "1"], ["84053", "0.23144113", "0", "1"], ["84048.8", "0.20789886", "0", "2"], ["84046.7", "0.133604", "0", "1"], ["84046.1", "0.03102622", "0", "2"], ["84045.7", "0.03270551", "0", "1"], ["84045.6", "0.5460969", "0", "1"], ["84045.5", "1", "0", "1"], ["84045", "0.03184158", "0", "1"], ["84044.8", "0", "0", "0"], ["84044.5", "0.03230062", "0", "1"], ["84044.4", "0.02979707", "0", "1"], ["84044.2", "0", "0", "0"], ["84042.7", "0", "0", "0"], ["84042.4", "0.11905663", "0", "2"], ["84042.1", "0", "0", "0"], ["84041.8", "0", "0", "0"], ["84041.3", "0", "0", "0"], ["84039.9", "0.06318613", "0", "1"], ["84039.1", "0.03186717", "0", "1"], ["84038.7", "0", "0", "0"], ["84038.2", "0.03393714", "0", "1"], ["84037.4", "0.8071176", "0", "2"], ["84036.9", "0.03109438", "0", "1"], ["84036.3", "0.03388485", "0", "1"], ["84035.7", "0", "0", "0"], ["84035", "0", "0", "0"], ["84034.7", "1.53605522", "0", "1"], ["84033.8", "0.24223351", "0", "2"], ["84033.7", "0.11905693", "0", "1"], ["84033.1", "0", "0", "0"], ["84032.1", "0.06830863", "0", "1"], ["84031.8", "0.3315906", "0", "2"], ["84031.6", "0.56097409", "0", "1"], ["84029.6", "0.08766893", "0", "2"], ["84028.8", "0.27324657", "0", "2"], ["84028.7", "0", "0", "0"], ["84028.2", "0.07026945", "0", "1"], ["84027.4", "0.45005645", "0", "1"], ["84026.4", "0.08", "0", "2"], ["84025.5", "0", "0", "0"], ["84024.9", "0", "0", "0"], ["84013.6", "0", "0", "0"], ["84012.8", "0.20288771", "0", "2"], ["84012.3", "0.59810591", "0", "1"], ["84010.2", "0.45579296", "0", "2"], ["84009.9", "0.03934099", "0", "2"], ["84009", "0.918652", "0", "1"], ["84007.4", "1.7403131", "0", "2"], ["84006.4", "0.17844", "0", "1"], ["84005.3", "2.73617588", "0", "2"], ["84002.3", "0.059998", "0", "1"], ["84000.1", "3.6074072", "0", "1"], ["83978.7", "0.01148933", "0", "1"], ["83972.7", "0", "0", "0"], ["83964.8", "0.00007199", "0", "1"], ["83964.7", "0", "0", "0"], ["83935.4", "0", "0", "0"], ["83928.6", "0.00201972", "0", "1"], ["83922.1", "0.00621039", "0", "1"], ["83908.3", "0", "0", "0"], ["83907", "0", "0", "0"], ["83906.6", "0", "0", "0"], ["83906", "0", "0", "0"], ["83905.5", "0", "0", "0"], ["83905", "0", "0", "0"], ["83904.9", "0", "0", "0"], ["83904.7", "0", "0", "0"], ["83904", "0", "0", "0"], ["83903.9", "0", "0", "0"], ["83903.6", "0", "0", "0"], ["83903.4", "0", "0", "0"]], "ts": "1742555186704", "checksum": 92462716, "seqId": 49927506643, "prevSeqId": 49927506272}], "record_time": 1742555186.705377, "EXCHANGE": "OKX"}
{"arg": {"channel": "books", "instId": "BTC-USDT"}, "action": "update", "data": [{"asks": [["84060.1", "0.09168988", "0", "3"], ["84063", "0", "0", "0"], ["84063.1", "0", "0", "0"], ["84063.9", "0.01668856", "0", "1"], ["84066.8", "0.02530935", "0", "1"], ["84068.3", "0.05826432", "0", "2"], ["84068.6", "0", "0", "0"], ["84073.4", "0", "0", "0"], ["84073.7", "0", "0", "0"], ["84073.9", "0", "0", "0"], ["84074.8", "0", "0", "0"], ["84075.5", "0.03512701", "0", "2"], ["84080", "0.0146", "0", "1"], ["84080.2", "0", "0", "0"], ["84080.4", "0.00001197", "0", "1"], ["84081.3", "0.03", "0", "1"], ["84081.4", "1.000015", "0", "2"], ["84082.4", "0", "0", "0"], ["84082.5", "0", "0", "0"], ["84082.8", "0", "0", "0"], ["84083.9", "0.13615356", "0", "3"], ["84084.7", "0.03", "0", "1"], ["84087.4", "0", "0", "0"], ["84088.4", "0", "0", "0"], ["84089.1", "0", "0", "0"], ["84089.7", "0.23802071", "0", "1"], ["84091.2", "0", "0", "0"], ["84092.1", "0.01774536", "0", "1"], ["84093", "0.06376182", "0", "1"], ["84097.1", "0.56902268", "0", "2"], ["84099.9", "0.35790534", "0", "3"], ["84104.6", "0.1", "0", "1"], ["84108", "0", "0", "0"], ["84109.6", "0.03", "0", "1"], ["84110.5", "0.002141", "0", "1"], ["84116.2", "0.00004312", "0", "1"], ["84117.3", "0.059916", "0", "1"], ["84120.2", "0", "0", "0"], ["84122.6", "0", "0", "0"], ["84144.5", "0.24982", "0", "1"], ["84233.9", "0.00419323", "0", "1"], ["84234", "0.00036", "0", "1"], ["84234.4", "0.00001197", "0", "1"], ["84235", "0.00025", "0", "1"], ["84235.2", "0.00002902", "0", "1"], ["84235.7", "0.03", "0", "1"], ["84236", "0.00036", "0", "1"], ["84236.6", "0.00593", "0", "1"], ["84236.8", "0.00001738", "0", "1"]], "bids": [["84060", "0.80741896", "0", "11"], ["84059.9", "0.04945877", "0", "1"], ["84059.8", "0.11902001", "0", "1"], ["84058.3", "0.01190205", "0", "1"], ["84056.3", "0.02530935", "0", "1"], ["84053.2", "0.008", "0", "1"], ["84053.1", "0", "0", "0"], ["84051.8", "0.00351428", "0", "1"], ["84051.4", "0.0027735", "0", "1"], ["84048.8", "0.56554088", "0", "3"], ["84047", "1", "0", "1"], ["84046.1", "0.00006", "0", "1"], ["84045.7", "0", "0", "0"], ["84045.6", "0.22193227", "0", "1"], ["84045.5", "0", "0", "0"], ["84045", "0.02380344", "0", "1"], ["84044.5", "0", "0", "0"], ["84039.1", "0", "0", "0"], ["84038.2", "0", "0", "0"], ["84037.5", "0.02488503", "0", "2"], ["84036.9", "0", "0", "0"], ["84036.3", "0", "0", "0"], ["84036", "0.23980471", "0", "2"], ["84033.8", "0.00420994", "0", "1"], ["84032.1", "0", "0", "0"], ["84030", "0.07012745", "0", "2"], ["84029.6", "0.08991011", "0", "1"], ["84028.8", "0.2025", "0", "1"], ["84028.2", "0", "0", "0"], ["84026.4", "0.0903941", "0", "3"], ["84023.7", "0.027995", "0", "2"], ["84016.7", "0.35180007", "0", "1"], ["84016.6", "0.35749645", "0", "2"], ["84012.8", "0", "0", "0"], ["84000.1", "1.65197753", "0", "1"], ["83997.3", "0.24982", "0", "1"], ["83978.4", "0", "0", "0"], ["83976.2", "0.24982", "0", "1"], ["83972.1", "0.00016246", "0", "1"], ["83909.8", "0", "0", "0"], ["83908.3", "0.00422253", "0", "1"]], "ts": "1742555186804", "checksum": -512358041, "seqId": 49927506868, "prevSeqId": 49927506643}], "record_time": 1742555186.805236, "EXCHANGE": "OKX"}
{"arg": {"channel": "books", "instId": "BTC-USDT"}, "action": "update", "data": [{"asks": [["84060.1", "0.14512624", "0", "5"], ["84063.5", "0.052393", "0", "1"], ["84063.6", "0.11901478", "0", "1"], ["84063.9", "0", "0", "0"], ["84072.1", "0.1145423", "0", "1"], ["84072.9", "0.01055", "0", "1"], ["84074", "0.19304", "0", "2"], ["84074.3", "0.09650086", "0", "3"], ["84074.4", "0.0353512", "0", "1"], ["84074.8", "0.03356574", "0", "1"], ["84075.5", "0.00001197", "0", "1"], ["84079.2", "0.03166", "0", "1"], ["84081.1", "0.03287791", "0", "1"], ["84081.3", "0.03479256", "0", "1"], ["84083.1", "0.03087481", "0", "1"], ["84083.2", "0.03211514", "0", "1"], ["84084.7", "0", "0", "0"], ["84088.3", "0.0651449", "0", "1"], ["84088.4", "0.23802135", "0", "1"], ["84089.7", "0", "0", "0"], ["84089.8", "0.08551512", "0", "3"], ["84091.8", "0.06942806", "0", "2"], ["84093", "0", "0", "0"], ["84109.8", "0.03", "0", "1"], ["84234", "0", "0", "0"], ["84234.4", "0", "0", "0"], ["84235", "0", "0", "0"], ["84235.2", "0", "0", "0"], ["84235.7", "0", "0", "0"], ["84236", "0", "0", "0"], ["84236.6", "0", "0", "0"], ["84236.8", "0", "0", "0"]], "bids": [["84059.6", "0.0134", "0", "1"], ["84055.1", "0", "0", "0"], ["84051.3", "0.17844", "0", "1"], ["84048.8", "0.52533088", "0", "2"], ["84047", "1.03500649", "0", "2"], ["84046.3", "0.03341979", "0", "1"], ["84045.7", "0.03330637", "0", "1"], ["84045.4", "0.03288793", "0", "1"], ["84040", "0.03100819", "0", "2"], ["84037.6", "0.03122685", "0", "1"], ["84037", "0.03347475", "0", "1"], ["84036", "0.001784", "0", "1"], ["84035.7", "0.00357", "0", "1"], ["84033.8", "0.24223129", "0", "2"], ["84033", "0.06565081", "0", "1"], ["84030.3", "0.06310288", "0", "1"], ["84030", "0.00001196", "0", "1"], ["84028.8", "0.26683389", "0", "2"], ["84021.7", "0", "0", "0"], ["83913", "0", "0", "0"], ["83912.6", "0", "0", "0"], ["83912.5", "0", "0", "0"], ["83912", "0", "0", "0"], ["83910", "0", "0", "0"], ["83909", "0", "0", "0"], ["83908.6", "0", "0", "0"], ["83908.3", "0", "0", "0"]], "ts": "1742555186904", "checksum": 415989695, "seqId": 49927507077, "prevSeqId": 49927506868}], "record_time": 1742555186.90532, "EXCHANGE": "OKX"}
{"arg": {"channel": "books", "instId": "BTC-USDT"}, "action": "update", "data": [{"asks": [["84060.1", "0.10802624", "0", "4"], ["84063.5", "0", "0", "0"], ["84063.6", "0", "0", "0"], ["84065.5", "0.00773256", "0", "1"], ["84074.3", "0.06280823", "0", "2"], ["84080.1", "1", "0", "1"], ["84080.5", "0.0044625", "0", "1"], ["84081.3", "0", "0", "0"], ["84081.4", "0.000015", "0", "1"], ["84088.3", "0.12491", "0", "1"], ["84109.2", "0.1287028", "0", "1"], ["84109.3", "0.12491", "0", "1"], ["84111.9", "0", "0", "0"], ["84233.9", "0", "0", "0"]], "bids": [["84060", "0.60741896", "0", "10"], ["84055.2", "0.00773256", "0", "1"], ["84053.2", "0.04821", "0", "2"], ["84048.8", "0.24480984", "0", "2"], ["84047", "0", "0", "0"], ["84046.2", "0.12491", "0", "1"], ["84045.6", "0.50405711", "0", "2"], ["84045.5", "1", "0", "1"], ["84040", "0.00001", "0", "1"], ["84039.1", "0.03388331", "0", "1"], ["84033", "0", "0", "0"], ["84025.2", "0.12491", "0", "1"], ["84025.1", "0", "0", "0"], ["84011.8", "0.2325", "0", "2"], ["84006", "0.2", "0", "1"], ["83915.9", "0", "0", "0"], ["83914.2", "0", "0", "0"], ["83914.1", "0", "0", "0"]], "ts": "1742555187004", "checksum": 1360806315, "seqId": 49927507123, "prevSeqId": 49927507077}], "record_time": 1742555187.009528, "EXCHANGE": "OKX"}
{"arg": {"channel": "books", "instId": "BTC-USDT"}, "action": "update", "data": [{"asks": [["84060.1", "0.34456062", "0", "6"], ["84063.4", "0.01190238", "0", "1"], ["84065.5", "0.05574467", "0", "2"], ["84065.6", "0.11901183", "0", "1"], ["84066.8", "0", "0", "0"], ["84068.5", "0.01055", "0", "1"], ["84068.6", "0.2025", "0", "1"], ["84070.3", "0.02530935", "0", "1"], ["84072.9", "0", "0", "0"], ["84073.3", "0.03077948", "0", "1"], ["84073.7", "0.06543368", "0", "2"], ["84073.9", "0.03208845", "0", "1"], ["84074.3", "0.03", "0", "1"], ["84074.4", "0", "0", "0"], ["84074.8", "0.03167", "0", "1"], ["84076.3", "0.18725022", "0", "1"], ["84076.5", "0.62549246", "0", "2"], ["84079.2", "0", "0", "0"], ["84079.7", "1", "0", "1"], ["84079.8", "0.10283489", "0", "1"], ["84080.1", "0", "0", "0"], ["84080.2", "0.03405952", "0", "1"], ["84080.3", "0.03060479", "0", "1"], ["84080.5", "0", "0", "0"], ["84081.1", "0", "0", "0"], ["84082.4", "0.03186892", "0", "1"], ["84082.5", "0.03225539", "0", "1"], ["84083.1", "0", "0", "0"], ["84083.2", "0", "0", "0"], ["84086.6", "0.23802763", "0", "1"], ["84087.3", "0.06675756", "0", "1"], ["84088.4", "0", "0", "0"], ["84089.1", "0.06722713", "0", "1"], ["84089.7", "0.06624534", "0", "1"], ["84089.8", "0.02381054", "0", "2"], ["84091.2", "0.0627405", "0", "1"], ["84091.8", "0.00420676", "0", "1"], ["84097.9", "0.2025", "0", "1"], ["84100.9", "0.83695485", "0", "1"], ["84101", "1", "0", "1"], ["84102.3", "0", "0", "0"], ["84166.7", "0.1", "0", "1"], ["84230.6", "0", "0", "0"], ["84230.9", "0", "0", "0"], ["84231.1", "0", "0", "0"], ["84232", "0", "0", "0"], ["84232.3", "0", "0", "0"], ["84232.6", "0", "0", "0"], ["84232.9", "0", "0", "0"], ["84233", "0", "0", "0"], ["84233.3", "0", "0", "0"], ["84233.5", "0", "0", "0"], ["84233.8", "0", "0", "0"]], "bids": [["84060", "0.47050896", "0", "7"], ["84059.6", "0", "0", "0"], ["84059.2", "0.02530935", "0", "1"], ["84058.3", "0", "0", "0"], ["84056.3", "0.0045285", "0", "1"], ["84056", "0.01190238", "0", "1"], ["84053.2", "0.008", "0", "1"], ["84051.4", "0", "0", "0"], ["84048.8", "0.18902864", "0", "1"], ["84048", "0", "0", "0"], ["84046.7", "0", "0", "0"], ["84046.3", "0", "0", "0"], ["84046.2", "0.70887633", "0", "2"], ["84046.1", "1.00006", "0", "2"], ["84046", "0.03110101", "0", "1"], ["84045.7", "0.03364052", "0", "1"], ["84045.6", "0", "0", "0"], ["84045.5", "0", "0", "0"], ["84045.4", "0", "0", "0"], ["84045", "0.05582033", "0", "2"], ["84044.5", "0.03094865", "0", "1"], ["84039.9", "0.10174197", "0", "2"], ["84039.1", "0", "0", "0"], ["84039", "0.03471515", "0", "1"], ["84038.2", "0.03496799", "0", "1"], ["84037.9", "0.18725022", "0", "1"], ["84037.6", "0", "0", "0"], ["84037", "0", "0", "0"], ["84036.9", "0.0328192", "0", "1"], ["84036.3", "0.03105433", "0", "1"], ["84035.1", "0", "0", "0"], ["84033.8", "0.00420994", "0", "1"], ["84033.2", "0.05944451", "0", "1"], ["84032", "0.06480136", "0", "1"], ["84030.7", "0.23802763", "0", "1"], ["84030.3", "0", "0", "0"], ["84029.6", "0.15168247", "0", "2"], ["84028.8", "0.2657578", "0", "2"], ["84028.2", "0.0696628", "0", "1"], ["84015.2", "0.03", "0", "1"], ["84006", "0", "0", "0"], ["83915.9", "0.00014559", "0", "1"]], "ts": "1742555187104", "checksum": -518351369, "seqId": 49927507346, "prevSeqId": 49927507123}], "record_time": 1742555187.105872, "EXCHANGE": "OKX"}
{"arg": {"channel": "books", "instId": "BTC-USDT"}, "action": "update", "data": [{"asks": [["84063.3", "0.04881729", "0", "2"], ["84063.8", "0.11901445", "0", "1"], ["84065.5", "0.00773256", "0", "1"], ["84065.6", "0", "0", "0"], ["84068.6", "0", "0", "0"], ["84077.8", "0.35643831", "0", "2"], ["84092.8", "0.01", "0", "1"], ["84093.1", "0.65759921", "0", "1"], ["84093.8", "1.24", "0", "1"], ["84118", "0.01", "0", "1"], ["84121.8", "0", "0", "0"], ["84147", "0.11893042", "0", "2"], ["84177.6", "0.21215203", "0", "2"], ["84230.1", "0", "0", "0"], ["84230.7", "0", "0", "0"]], "bids": [["84056", "0", "0", "0"], ["84055.5", "0.00244579", "0", "3"], ["84055.1", "0.0134", "0", "1"], ["84048.8", "0.40767864", "0", "3"], ["84047.2", "0.133608", "0", "1"], ["84038", "0.01774536", "0", "1"], ["84037.5", "0.00713967", "0", "1"], ["84033.9", "0.01", "0", "1"], ["83954.4", "0.36159313", "0", "2"], ["83916.5", "0", "0", "0"], ["83916.3", "0", "0", "0"], ["83915.9", "0", "0", "0"]], "ts": "1742555187204", "checksum": 534529871, "seqId": 49927507378, "prevSeqId": 49927507346}], "record_time": 1742555187.205826, "EXCHANGE": "OKX"}
{"arg": {"channel": "books", "instId": "BTC-USDT"}, "action": "update", "data": [{"asks": [["84063.4", "0", "0", "0"], ["84066.5", "0.01190194", "0", "1"], ["84072.1", "0.23430252", "0", "2"], ["84074.7", "0.35689", "0", "1"], ["84079.8", "0.20356311", "0", "2"], ["84081.4", "0.249835", "0", "2"], ["84086.6", "0", "0", "0"], ["84089.6", "0.23802342", "0", "1"], ["84099.9", "0.00101534", "0", "2"], ["84102.4", "0.24982", "0", "1"], ["84228.5", "0", "0", "0"], ["84228.9", "0", "0", "0"]], "bids": [["84060", "0.47059896", "0", "8"], ["84056.3", "0", "0", "0"], ["84055.8", "0.0008655", "0", "1"], ["84055.5", "0.00347175", "0", "4"], ["84049.5", "0.34499684", "0", "1"], ["84049.4", "0.35689", "0", "1"], ["84048.8", "0.21865", "0", "2"], ["84032.1", "0.23802342", "0", "1"], ["84030.7", "0", "0", "0"], ["84016.7", "0.25373307", "0", "1"], ["84016.6", "0.00060645", "0", "1"], ["84006.4", "0", "0", "0"], ["83993", "0", "0", "0"], ["83972", "0.0060996", "0", "1"]], "ts": "1742555187304", "checksum": 328811260, "seqId": 49927507403, "prevSeqId": 49927507378}], "record_time": 1742555187.305938, "EXCHANGE": "OKX"}
{"arg": {"channel": "books", "instId": "BTC-USDT"}, "action": "update", "data": [{"asks": [["84122.7", "0.4152778", "0", "2"], ["84123.4", "0.000015", "0", "1"], ["84144.5", "0", "0", "0"], ["84228.5", "0.00002372", "0", "1"]], "bids": [["84060", "0.47098725", "0", "9"], ["84055.8", "0", "0", "0"], ["83997.3", "0", "0", "0"], ["83976.2", "0", "0", "0"], ["83916.5", "3.54678207", "0", "3"], ["83916.3", "0.03074456", "0", "2"], ["83915.9", "0.00014559", "0", "1"]], "ts": "1742555187404", "checksum": 996771730, "seqId": 49927507411, "prevSeqId": 49927507403}], "record_time": 1742555187.407568, "EXCHANGE": "OKX"}
{"arg": {"channel": "books", "instId": "BTC-USDT"}, "action": "update", "data": [{"asks": [["84078.4", "1", "0", "1"], ["84079.7", "0", "0", "0"], ["84096.7", "0", "0", "0"], ["84102.4", "0.32982", "0", "3"], ["84103.2", "0.03999999", "0", "1"], ["84104.8", "0.17821722", "0", "1"], ["84105.6", "0", "0", "0"], ["84228.9", "0.00008", "0", "1"]], "bids": [["84055.8", "0.000039", "0", "1"], ["84055.5", "0.00449771", "0", "5"], ["84039.9", "0.17668304", "0", "1"], ["84039.2", "0.17844", "0", "1"], ["83972.1", "0", "0", "0"], ["83970.6", "0.00016246", "0", "1"], ["83916.3", "0", "0", "0"], ["83915.9", "0", "0", "0"]], "ts": "1742555187504", "checksum": 1466205059, "seqId": 49927507431, "prevSeqId": 49927507411}], "record_time": 1742555187.504943, "EXCHANGE": "OKX"}
{"arg": {"channel": "books", "instId": "BTC-USDT"}, "action": "update", "data": [{"asks": [["84068.6", "0.2025", "0", "1"], ["84077.8", "0.35641581", "0", "1"], ["84105", "0.00001", "0", "1"], ["84127", "0", "0", "0"], ["84228.9", "0", "0", "0"]], "bids": [["84055.5", "0.00654963", "0", "7"], ["84035", "0.12491", "0", "1"], ["84029.1", "0.60055158", "0", "1"], ["84027.4", "0", "0", "0"], ["84021", "0.17823918", "0", "3"], ["84014", "0.12491", "0", "1"], ["84000.1", "1.09137754", "0", "1"], ["83916.6", "0", "0", "0"], ["83916.5", "0", "0", "0"]], "ts": "1742555187604", "checksum": -1488990934, "seqId": 49927507454, "prevSeqId": 49927507431}], "record_time": 1742555187.605694, "EXCHANGE": "OKX"}
{"arg": {"channel": "books", "instId": "BTC-USDT"}, "action": "update", "data": [{"asks": [["84102", "0.252", "0", "3"], ["84219.7", "0.00011161", "0", "1"]], "bids": [["84046.1", "0.00006", "0", "1"], ["84044.7", "1.03618589", "0", "2"], ["83970.6", "0", "0", "0"], ["83916.6", "0.00106624", "0", "4"]], "ts": "1742555187704", "checksum": -1488990934, "seqId": 49927507480, "prevSeqId": 49927507454}], "record_time": 1742555187.7148, "EXCHANGE": "OKX"}
{"arg": {"channel": "books", "instId": "BTC-USDT"}, "action": "update", "data": [{"asks": [["84068.6", "0", "0", "0"], ["84077.8", "0.35643981", "0", "2"], ["84088.2", "0.23802517", "0", "1"], ["84089.6", "0", "0", "0"], ["84228.9", "0.00008", "0", "1"]], "bids": [["84060", "0.46395639", "0", "8"], ["84039.3", "0.24982", "0", "1"], ["84032.1", "0", "0", "0"], ["84029.7", "0.23802517", "0", "1"], ["84018.3", "0.24982", "0", "1"], ["83970.6", "0.00016243", "0", "1"], ["83917.3", "0", "0", "0"], ["83917.2", "0", "0", "0"], ["83916.6", "0", "0", "0"]], "ts": "1742555187804", "checksum": 351820728, "seqId": 49927507515, "prevSeqId": 49927507480}], "record_time": 1742555187.804522, "EXCHANGE": "OKX"}
{"arg": {"channel": "books", "instId": "BTC-USDT"}, "action": "update", "data": [{"asks": [["84060.1", "0.34146062", "0", "5"]], "bids": [["83959", "0.00083", "0", "1"], ["83917.4", "0", "0", "0"]], "ts": "1742555187904", "checksum": -1412728335, "seqId": 49927507518, "prevSeqId": 49927507515}], "record_time": 1742555187.905196, "EXCHANGE": "OKX"}
{"arg": {"channel": "books", "instId": "BTC-USDT"}, "action": "update", "data": [{"asks": [["84073.3", "0", "0", "0"], ["84073.4", "0.03419364", "0", "1"], ["84080.3", "0", "0", "0"], ["84080.4", "0.03302227", "0", "2"], ["84087.3", "0", "0", "0"], ["84087.4", "0.06252254", "0", "1"], ["84088.2", "0", "0", "0"], ["84091.1", "0.2380223", "0", "1"], ["84102.4", "0.24982", "0", "1"], ["84103.2", "0.07999999", "0", "2"], ["84104", "1.03999999", "0", "2"], ["84230.1", "0.000548", "0", "2"]], "bids": [["84046.1", "0.03397766", "0", "2"], ["84046", "0", "0", "0"], ["84039.1", "0.0323944", "0", "1"], ["84039", "0", "0", "0"], ["84032.2", "0.2380223", "0", "1"], ["84032.1", "0.06247697", "0", "1"], ["84032", "0", "0", "0"], ["84029.7", "0", "0", "0"], ["83917.4", "0.17821722", "0", "1"]], "ts": "1742555188004", "checksum": 946841597, "seqId": 49927507544, "prevSeqId": 49927507518}], "record_time": 1742555188.004288, "EXCHANGE": "OKX"}
{"arg": {"channel": "books", "instId": "BTC-USDT"}, "action": "update", "data": [{"asks": [["84080.8", "0.005", "0", "1"], ["84089.6", "0.23802374", "0", "1"], ["84090.8", "0.005", "0", "1"], ["84091.1", "0", "0", "0"], ["84130.2", "0.01129679", "0", "1"], ["84131.3", "0.26490093", "0", "1"], ["84230.1", "0", "0", "0"]], "bids": [["84058.1", "0", "0", "0"], ["84035.7", "0", "0", "0"], ["84032.2", "0.23802374", "0", "1"], ["84020.9", "0.11592046", "0", "3"], ["84020.4", "0.26712402", "0", "2"], ["84013.1", "0", "0", "0"], ["84012.4", "0.01832763", "0", "1"], ["83997.3", "0.00285313", "0", "1"], ["83996.8", "0", "0", "0"], ["83941.6", "0", "0", "0"], ["83941.2", "0.2011233", "0", "2"], ["83917.3", "0.08991011", "0", "1"], ["83917.2", "0.35579296", "0", "1"], ["83916.6", "0.00106624", "0", "4"]], "ts": "1742555188104", "checksum": 1052566528, "seqId": 49927507594, "prevSeqId": 49927507544}], "record_time": 1742555188.105601, "EXCHANGE": "OKX"}
{"arg": {"channel": "books", "instId": "BTC-USDT"}, "action": "update", "data": [{"asks": [["84060.1", "0.09168988", "0", "3"], ["84068.5", "0", "0", "0"], ["84071.5", "0.01055", "0", "1"], ["84073.4", "0", "0", "0"], ["84073.7", "0", "0", "0"], ["84073.9", "0", "0", "0"], ["84074.7", "0.38900206", "0", "2"], ["84074.8", "0.03512264", "0", "1"], ["84074.9", "0.03311652", "0", "1"], ["84075.2", "0.03375982", "0", "1"], ["84079.1", "0.03166", "0", "1"], ["84080.2", "0", "0", "0"], ["84080.4", "0.00001197", "0", "1"], ["84081.5", "0.03110089", "0", "1"], ["84081.9", "0.03364691", "0", "1"], ["84082.4", "0", "0", "0"], ["84082.5", "0", "0", "0"], ["84083.5", "0.03111421", "0", "1"], ["84083.6", "0.03485841", "0", "1"], ["84087.4", "0", "0", "0"], ["84088.2", "0.2380242", "0", "1"], ["84088.9", "0.06397732", "0", "2"], ["84089.1", "0", "0", "0"], ["84089.6", "0", "0", "0"], ["84089.7", "0", "0", "0"], ["84090.2", "0.06814852", "0", "1"], ["84090.9", "0.06804633", "0", "1"], ["84091.2", "0", "0", "0"], ["84092.2", "1.62339506", "0", "2"], ["84230.1", "0.000548", "0", "2"]], "bids": [["84060", "0.58186846", "0", "11"], ["84058.1", "0.0134", "0", "1"], ["84055.1", "0", "0", "0"], ["84053.1", "0.04021", "0", "1"], ["84048.8", "0.17844", "0", "1"], ["84047.6", "0.03077051", "0", "1"], ["84046.7", "0.03259227", "0", "1"], ["84046.1", "0.03188174", "0", "2"], ["84045.8", "0.24094166", "0", "4"], ["84045.7", "0", "0", "0"], ["84045", "0.02380344", "0", "1"], ["84044.5", "0", "0", "0"], ["84040.6", "0.03091609", "0", "1"], ["84039.5", "0.03220028", "0", "1"], ["84039.1", "0", "0", "0"], ["84038.2", "0", "0", "0"], ["84038", "0.04972964", "0", "2"], ["84037.4", "0.84008852", "0", "3"], ["84036.9", "0", "0", "0"], ["84036.3", "0", "0", "0"], ["84033.6", "0.06532604", "0", "1"], ["84032.1", "0", "0", "0"], ["84030.7", "0.06546515", "0", "1"], ["84030", "0.06663139", "0", "2"], ["84029.6", "0.08991011", "0", "1"], ["84029.2", "0.06811331", "0", "1"], ["84028.8", "0.2025", "0", "1"], ["84028.2", "0", "0", "0"]], "ts": "1742555188204", "checksum": 1111108850, "seqId": 49927507719, "prevSeqId": 49927507594}], "record_time": 1742555188.204895, "EXCHANGE": "OKX"}
{"arg": {"channel": "books", "instId": "BTC-USDT"}, "action": "update", "data": [{"asks": [["84060.1", "0.12878988", "0", "4"], ["84074.5", "0.10124943", "0", "3"], ["84074.7", "0.35689", "0", "1"], ["84074.8", "0", "0", "0"], ["84074.9", "0.03197711", "0", "1"], ["84075.2", "0", "0", "0"], ["84081.2", "0.0345807", "0", "1"], ["84081.5", "0.03113575", "0", "1"], ["84081.9", "0", "0", "0"], ["84083.2", "0.03474996", "0", "1"], ["84083.3", "0.03262977", "0", "2"], ["84083.5", "0", "0", "0"], ["84083.6", "0", "0", "0"], ["84088.2", "0.23802505", "0", "1"], ["84088.5", "0.42415333", "0", "2"], ["84088.9", "0.002", "0", "1"], ["84089.9", "0.06286077", "0", "1"], ["84090.2", "0", "0", "0"], ["84090.7", "0.07011217", "0", "1"], ["84090.9", "0", "0", "0"], ["84092", "0.0685301", "0", "1"], ["84092.2", "1.55638389", "0", "1"], ["84230.7", "0.2025", "0", "1"]], "bids": [["84047.6", "0", "0", "0"], ["84047.2", "0.16593287", "0", "2"], ["84046.7", "0", "0", "0"], ["84046.5", "0.0334598", "0", "1"], ["84046.1", "0.00006", "0", "1"], ["84045.8", "0.23913408", "0", "4"], ["84045.5", "0.03485764", "0", "1"], ["84040.6", "0", "0", "0"], ["84040.2", "0.0313298", "0", "1"], ["84039.5", "0", "0", "0"], ["84039.2", "0.21203412", "0", "2"], ["84038", "0.01774536", "0", "1"], ["84037.7", "0.03118221", "0", "1"], ["84037.4", "0.8071176", "0", "2"], ["84037.1", "0.03441364", "0", "1"], ["84033.6", "0", "0", "0"], ["84033.2", "0.12205284", "0", "2"], ["84032.2", "0", "0", "0"], ["84030.7", "0", "0", "0"], ["84030.5", "0.23802505", "0", "1"], ["84030.4", "0.06889051", "0", "1"], ["84030", "0.00001196", "0", "1"], ["84029.8", "0.06844776", "0", "1"], ["84029.2", "0", "0", "0"], ["84029", "0.06899757", "0", "1"], ["83916.6", "0", "0", "0"]], "ts": "1742555188304", "checksum": 1670305469, "seqId": 49927507780, "prevSeqId": 49927507719}], "record_time": 1742555188.305693, "EXCHANGE": "OKX"}
{"arg": {"channel": "books", "instId": "BTC-USDT"}, "action": "update", "data": [{"asks": [["84066.5", "0", "0", "0"], ["84068.9", "0.01190168", "0", "1"], ["84088.2", "0", "0", "0"], ["84089.7", "0.2380231", "0", "1"], ["84091.9", "0.01774536", "0", "1"], ["84092.1", "0", "0", "0"]], "bids": [["84031.9", "0.2380231", "0", "1"], ["84030.5", "0", "0", "0"], ["83970.6", "0.00016242", "0", "1"]], "ts": "1742555188404", "checksum": -925544446, "seqId": 49927507793, "prevSeqId": 49927507780}], "record_time": 1742555188.405953, "EXCHANGE": "OKX"}
{"arg": {"channel": "books", "instId": "BTC-USDT"}, "action": "update", "data": [{"asks": [["84087.6", "0.23802511", "0", "1"], ["84089.7", "0", "0", "0"]], "bids": [["84031.9", "0", "0", "0"], ["84030.5", "0.23802511", "0", "1"]], "ts": "1742555188504", "checksum": -925544446, "seqId": 49927507799, "prevSeqId": 49927507793}], "record_time": 1742555188.505846, "EXCHANGE": "OKX"}
{"arg": {"channel": "books", "instId": "BTC-USDT"}, "action": "update", "data": [{"asks": [["84068.3", "0.03916298", "0", "1"], ["84087.6", "0", "0", "0"], ["84088.4", "0.25488157", "0", "1"], ["84088.6", "0", "0", "0"], ["84089.7", "0.23802285", "0", "1"], ["84092.2", "0", "0", "0"], ["84119", "0.30817588", "0", "1"], ["84120.3", "0", "0", "0"], ["84121.6", "0.01188756", "0", "1"], ["84230.9", "0.35582144", "0", "2"]], "bids": [["84037.4", "0.35977079", "0", "2"], ["84034.7", "0", "0", "0"], ["84033.8", "0.24223279", "0", "2"], ["84031.8", "0.65502317", "0", "1"], ["84030.5", "0", "0", "0"], ["84030", "1.00001196", "0", "2"], ["84007.4", "0.91613799", "0", "1"], ["84005.3", "0.00001196", "0", "1"], ["84000.1", "2.38801659", "0", "2"], ["83916.6", "0.00106624", "0", "4"], ["83916.5", "3.54678207", "0", "3"]], "ts": "1742555188604", "checksum": 1915527050, "seqId": 49927507831, "prevSeqId": 49927507799}], "record_time": 1742555188.605271, "EXCHANGE": "OKX"}
{"arg": {"channel": "books", "instId": "BTC-USDT"}, "action": "update", "data": [{"asks": [["84063.6", "0.01910366", "0", "1"], ["84074.4", "0.03326669", "0", "1"], ["84074.5", "0.06969836", "0", "2"], ["84074.9", "0.03502222", "0", "1"], ["84081.2", "0.03320604", "0", "1"], ["84081.4", "0.28092726", "0", "3"], ["84081.5", "0", "0", "0"], ["84083.2", "0.03158924", "0", "1"], ["84083.3", "0.03497528", "0", "2"], ["84084", "0.71091717", "0", "2"], ["84086.6", "1.56218005", "0", "1"], ["84088.4", "0.32348327", "0", "2"], ["84088.5", "0.35641581", "0", "1"], ["84089.7", "0", "0", "0"], ["84089.9", "0.06331458", "0", "1"], ["84090.6", "0.23802339", "0", "1"], ["84090.7", "0.06723478", "0", "1"], ["84091.9", "0", "0", "0"], ["84092", "0", "0", "0"], ["84093", "0.01774536", "0", "1"], ["84114.3", "1.00920285", "0", "2"], ["84116", "2.78048614", "0", "1"], ["84230.7", "0", "0", "0"], ["84230.9", "0", "0", "0"]], "bids": [["84047.2", "0.133608", "0", "1"], ["84047.1", "0.0342801", "0", "1"], ["84046.5", "0.03148803", "0", "1"], ["84045.8", "0.24127723", "0", "4"], ["84045.5", "0.03199127", "0", "1"], ["84040.2", "0", "0", "0"], ["84040.1", "0.03363132", "0", "1"], ["84039.2", "0.2116507", "0", "2"], ["84038", "0", "0", "0"], ["84037.7", "0", "0", "0"], ["84037.4", "0.82776217", "0", "1"], ["84037.1", "0.03354283", "0", "1"], ["84036.2", "1.60907976", "0", "1"], ["84033.8", "0.00420994", "0", "1"], ["84033.2", "0.05944451", "0", "1"], ["84033.1", "0.06914629", "0", "1"], ["84031.9", "0.25576875", "0", "2"], ["84030.4", "0.06616203", "0", "1"], ["84029.8", "0.06192369", "0", "1"], ["84029", "0", "0", "0"], ["84007.4", "1.75807549", "0", "2"], ["84006.8", "2.97381186", "0", "1"], ["84000.1", "0.63679473", "0", "1"], ["83916.6", "0", "0", "0"], ["83916.5", "0", "0", "0"]], "ts": "1742555188704", "checksum": 1561774018, "seqId": 49927507904, "prevSeqId": 49927507831}], "record_time": 1742555188.705935, "EXCHANGE": "OKX"}
{"arg": {"channel": "books", "instId": "BTC-USDT"}, "action": "update", "data": [{"asks": [["84073.6", "0.01118528", "0", "2"], ["84074.4", "0", "0", "0"], ["84074.5", "0", "0", "0"], ["84074.9", "0", "0", "0"], ["84081.2", "0", "0", "0"], ["84081.4", "0.249835", "0", "2"], ["84083.2", "0", "0", "0"], ["84083.3", "0.00060645", "0", "1"], ["84088.4", "0.25488157", "0", "1"], ["84089.9", "0", "0", "0"], ["84090.7", "0", "0", "0"], ["84114.2", "0.00004312", "0", "1"], ["84116.2", "0", "0", "0"], ["84230.9", "0.35582144", "0", "2"], ["84232", "0.00172464", "0", "3"], ["84232.3", "0.29700048", "0", "2"], ["84232.6", "0.00001501", "0", "1"], ["84232.9", "0.08747", "0", "1"], ["84233", "0.06012728", "0", "2"], ["84233.3", "0.00101534", "0", "2"]], "bids": [["84060", "0.78186846", "0", "12"], ["84047.1", "0", "0", "0"], ["84046.5", "0", "0", "0"], ["84045.8", "0.20672021", "0", "3"], ["84045.5", "0", "0", "0"], ["84040.1", "0", "0", "0"], ["84039.2", "0.17844", "0", "1"], ["84037.1", "0", "0", "0"], ["84033.1", "0", "0", "0"], ["84030.4", "0", "0", "0"], ["84029.8", "0", "0", "0"], ["83916.6", "0.00106624", "0", "4"], ["83916.5", "3.54678207", "0", "3"], ["83916.3", "0.03074456", "0", "2"], ["83915.9", "0.00014559", "0", "1"], ["83914.2", "0.03486546", "0", "1"], ["83914.1", "0.00001066", "0", "1"], ["83913", "0.00002243", "0", "1"], ["83912.6", "0.00013227", "0", "2"]], "ts": "1742555188804", "checksum": -1542239919, "seqId": 49927507941, "prevSeqId": 49927507904}], "record_time": 1742555188.805796, "EXCHANGE": "OKX"}
{"arg": {"channel": "books", "instId": "BTC-USDT"}, "action": "update", "data": [{"asks": [["84060.1", "0.09168988", "0", "3"], ["84074.7", "0.38963955", "0", "2"], ["84074.8", "0.06788139", "0", "2"], ["84075.1", "0.03327281", "0", "1"], ["84081.4", "0.28466836", "0", "3"], ["84081.8", "0.03203255", "0", "1"], ["84083.5", "0.03118073", "0", "1"], ["84083.6", "0.03280756", "0", "1"], ["84088.8", "0.06741017", "0", "1"], ["84090.2", "0.06765278", "0", "1"], ["84090.4", "0.23803542", "0", "2"], ["84090.6", "0", "0", "0"], ["84090.9", "0.06872389", "0", "1"], ["84092.2", "0.06327213", "0", "1"], ["84102.4", "0.32982", "0", "3"], ["84103.2", "0.03999999", "0", "1"], ["84104", "1", "0", "1"], ["84230.1", "0", "0", "0"], ["84230.9", "0", "0", "0"], ["84232", "0", "0", "0"], ["84232.3", "0", "0", "0"], ["84232.6", "0", "0", "0"], ["84232.9", "0", "0", "0"], ["84233", "0", "0", "0"], ["84233.3", "0", "0", "0"]], "bids": [["84047.5", "0.03506004", "0", "1"], ["84046.7", "0.03427854", "0", "1"], ["84046.1", "0.03143912", "0", "2"], ["84045.7", "0.03501791", "0", "1"], ["84040.5", "0.03268971", "0", "1"], ["84039.4", "0.03130706", "0", "1"], ["84038", "0.04847973", "0", "2"], ["84037.4", "0.86213826", "0", "2"], ["84033.5", "0.06468749", "0", "1"], ["84031.9", "0.23802339", "0", "1"], ["84030.7", "0.06961255", "0", "1"], ["84030", "1.0637931", "0", "3"], ["84029.2", "0.06282192", "0", "1"], ["83995.7", "0", "0", "0"], ["83985.6", "0.03", "0", "1"], ["83945.4", "0.11890903", "0", "1"], ["83916.6", "0", "0", "0"], ["83916.5", "0", "0", "0"], ["83916.3", "0", "0", "0"], ["83915.9", "0", "0", "0"], ["83914.2", "0", "0", "0"], ["83914.1", "0", "0", "0"], ["83913", "0", "0", "0"], ["83912.6", "0", "0", "0"]], "ts": "1742555188904", "checksum": -749129691, "seqId": 49927508041, "prevSeqId": 49927507941}], "record_time": 1742555188.905275, "EXCHANGE": "OKX"}
{"arg": {"channel": "books", "instId": "BTC-USDT"}, "action": "update", "data": [{"asks": [["84072.4", "0.005", "0", "1"], ["84082.4", "0.005", "0", "1"], ["84228.5", "0", "0", "0"], ["84228.9", "0", "0", "0"]], "bids": [["84058.2", "0.01", "0", "2"], ["84048.1", "0.005", "0", "1"], ["83997.6", "0.00235657", "0", "1"], ["83945.5", "0.00358991", "0", "1"], ["83917.4", "0", "0", "0"], ["83917.3", "0", "0", "0"], ["83917.2", "0", "0", "0"]], "ts": "1742555189004", "checksum": 1010709164, "seqId": 49927508050, "prevSeqId": 49927508041}], "record_time": 1742555189.013311, "EXCHANGE": "OKX"}
{"arg": {"channel": "books", "instId": "BTC-USDT"}, "action": "update", "data": [{"asks": [["84063.3", "0", "0", "0"], ["84074.7", "0.35689", "0", "1"], ["84074.8", "0.03098985", "0", "1"], ["84074.9", "0.03480324", "0", "1"], ["84075.1", "0.03375286", "0", "1"], ["84075.4", "0.0333832", "0", "1"], ["84077.7", "0.06", "0", "2"], ["84077.8", "0.000024", "0", "1"], ["84080.8", "0", "0", "0"], ["84081.4", "0.249835", "0", "2"], ["84081.7", "0.15199864", "0", "2"], ["84081.8", "0", "0", "0"], ["84082.1", "0.03259672", "0", "1"], ["84088.8", "0", "0", "0"], ["84089.1", "0.06766769", "0", "1"], ["84090.2", "0", "0", "0"], ["84090.3", "0.06392368", "0", "1"], ["84090.4", "0.00001197", "0", "1"], ["84090.8", "0", "0", "0"], ["84090.9", "0", "0", "0"], ["84091.1", "0.06965134", "0", "1"], ["84092.1", "0.23802089", "0", "1"], ["84092.2", "0", "0", "0"], ["84092.3", "0.06128537", "0", "1"], ["84116.5", "0", "0", "0"], ["84149.8", "0.0001965", "0", "1"], ["84157.4", "0", "0", "0"], ["84228.5", "0.00002372", "0", "1"]], "bids": [["84058.2", "0.005", "0", "1"], ["84048.8", "0", "0", "0"], ["84047.8", "0.03490656", "0", "1"], ["84047.5", "0", "0", "0"], ["84046.8", "0.03461159", "0", "1"], ["84046.7", "0", "0", "0"], ["84046.2", "0.74244312", "0", "3"], ["84046.1", "0.00006", "0", "1"], ["84046", "0.03196763", "0", "1"], ["84045.7", "0", "0", "0"], ["84040.8", "0.03206362", "0", "1"], ["84040.5", "0", "0", "0"], ["84039.7", "0.03141047", "0", "1"], ["84039.6", "0.00875806", "0", "1"], ["84039.4", "0", "0", "0"], ["84033.8", "0.0696934", "0", "2"], ["84033.5", "0", "0", "0"], ["84031.8", "0.32388109", "0", "1"], ["84030.8", "0.06199165", "0", "1"], ["84030.7", "0", "0", "0"], ["84030.2", "0.06246222", "0", "1"], ["84030", "0.00001196", "0", "1"], ["84029.3", "0.06596962", "0", "2"], ["84029.2", "0", "0", "0"], ["84014", "0.22491", "0", "2"], ["84000.1", "0.96793681", "0", "2"], ["83917.4", "0.17821722", "0", "1"]], "ts": "1742555189104", "checksum": 1728122081, "seqId": 49927508160, "prevSeqId": 49927508050}], "record_time": 1742555189.115795, "EXCHANGE": "OKX"}
{"arg": {"channel": "books", "instId": "BTC-USDT"}, "action": "update", "data": [{"asks": [["84063.7", "0.04711986", "0", "1"], ["84074.8", "0.09733512", "0", "3"], ["84074.9", "0", "0", "0"], ["84075.1", "0", "0", "0"], ["84075.2", "0.0312829", "0", "1"], ["84075.4", "0", "0", "0"], ["84076.5", "0.66326275", "0", "1"], ["84079.7", "0.35641581", "0", "1"], ["84079.8", "0.21584076", "0", "1"], ["84081.5", "0.03514786", "0", "1"], ["84081.7", "0.11898911", "0", "1"], ["84081.8", "0.03273011", "0", "1"], ["84082.1", "0", "0", "0"], ["84088.8", "0.06235766", "0", "1"], ["84089.1", "0", "0", "0"], ["84090.2", "0.06169551", "0", "1"], ["84090.3", "0", "0", "0"], ["84090.9", "0.06740843", "0", "1"], ["84091.1", "0", "0", "0"], ["84228.5", "0", "0", "0"]], "bids": [["84060", "0.78365246", "0", "13"], ["84047.8", "0", "0", "0"], ["84047.5", "0.03223927", "0", "1"], ["84046.2", "0.70887633", "0", "2"], ["84046.1", "0.03396066", "0", "2"], ["84046", "0", "0", "0"], ["84045.8", "0.24027744", "0", "4"], ["84040.8", "0", "0", "0"], ["84040.5", "0.0311028", "0", "1"], ["84039.7", "0", "0", "0"], ["84039.5", "0.03085532", "0", "1"], ["84036", "0", "0", "0"], ["84033.8", "0.00420994", "0", "1"], ["84033.5", "0.06908149", "0", "1"], ["84030.8", "0", "0", "0"], ["84030.7", "0.06256429", "0", "1"], ["84030.2", "0", "0", "0"], ["84030", "0.0652417", "0", "2"], ["84014", "0.12491", "0", "1"], ["83917.3", "0.08991011", "0", "1"], ["83917.2", "0.35579296", "0", "1"]], "ts": "1742555189204", "checksum": 1358386233, "seqId": 49927508213, "prevSeqId": 49927508160}], "record_time": 1742555189.261194, "EXCHANGE": "OKX"}
{"arg": {"channel": "books", "instId": "BTC-USDT"}, "action": "update", "data": [{"asks": [["84078.3", "0.17821722", "0", "1"], ["84228.4", "0", "0", "0"]], "bids": [["83984.2", "0.01902386", "0", "1"], ["83917.2", "0", "0", "0"]], "ts": "1742555189304", "checksum": 1358386233, "seqId": 49927508216, "prevSeqId": 49927508213}], "record_time": 1742555189.305259, "EXCHANGE": "OKX"}
{"arg": {"channel": "books", "instId": "BTC-USDT"}, "action": "update", "data": [{"asks": [["84070", "0.01521127", "0", "2"]], "bids": [], "ts": "1742555189404", "checksum": 340999646, "seqId": 49927508217, "prevSeqId": 49927508216}], "record_time": 1742555189.405762, "EXCHANGE": "OKX"}
{"arg": {"channel": "books", "instId": "BTC-USDT"}, "action": "update", "data": [{"asks": [["84060.1", "0.12862919", "0", "4"], ["84072.4", "0.01", "0", "2"], ["84074.5", "0.06571995", "0", "2"], ["84074.6", "0.03143279", "0", "1"], ["84074.8", "0", "0", "0"], ["84074.9", "0.03272862", "0", "1"], ["84075.2", "0", "0", "0"], ["84081.2", "0.03350247", "0", "1"], ["84081.5", "0.03151216", "0", "1"], ["84081.8", "0", "0", "0"], ["84082.4", "0.01", "0", "2"], ["84083.2", "0.0327837", "0", "1"], ["84083.3", "0.03588999", "0", "2"], ["84083.5", "0", "0", "0"], ["84083.6", "0", "0", "0"], ["84088.5", "0.42066154", "0", "2"], ["84088.8", "0", "0", "0"], ["84089.7", "0.23802572", "0", "1"], ["84090", "0.06685142", "0", "2"], ["84090.2", "0", "0", "0"], ["84090.7", "0.0658141", "0", "1"], ["84090.9", "0", "0", "0"], ["84092", "0.06428212", "0", "1"], ["84092.1", "0", "0", "0"], ["84092.3", "0", "0", "0"], ["84228.4", "0.00010514", "0", "1"], ["84228.5", "0.00002372", "0", "1"]], "bids": [["84060", "0.58365246", "0", "12"], ["84058.2", "0.01", "0", "2"], ["84048.2", "0.005", "0", "1"], ["84047.5", "0", "0", "0"], ["84047.2", "0.16665846", "0", "2"], ["84046.8", "0", "0", "0"], ["84046.5", "0.03434856", "0", "1"], ["84046.1", "0.00006", "0", "1"], ["84045.9", "0.03338873", "0", "1"], ["84045.8", "0.20672021", "0", "3"], ["84045.5", "0.03536843", "0", "1"], ["84040.5", "0", "0", "0"], ["84040.2", "0.03430797", "0", "1"], ["84039.5", "0", "0", "0"], ["84039.2", "0.21057232", "0", "2"], ["84038", "0.01774536", "0", "1"], ["84037.7", "0.03390077", "0", "1"], ["84037.4", "0.82776217", "0", "1"], ["84037.1", "0.03122098", "0", "1"], ["84033.5", "0", "0", "0"], ["84033.2", "0.12201597", "0", "2"], ["84031.9", "0", "0", "0"], ["84030.7", "0", "0", "0"], ["84030.5", "0.06496331", "0", "1"], ["84030", "0.00001196", "0", "1"], ["84029.8", "0.06862614", "0", "1"], ["84029.7", "0.23802558", "0", "1"], ["84029.3", "0.00353141", "0", "1"], ["84029", "0.06486248", "0", "1"], ["83917.6", "0", "0", "0"], ["83917.5", "0", "0", "0"], ["83917.4", "0", "0", "0"], ["83917.3", "0", "0", "0"]], "ts": "1742555189504", "checksum": 245290012, "seqId": 49927508291, "prevSeqId": 49927508217}], "record_time": 1742555189.530451, "EXCHANGE": "OKX"}
{"arg": {"channel": "books", "instId": "BTC-USDT"}, "action": "update", "data": [{"asks": [["84073.3", "0.00906686", "0", "1"], ["84228.5", "0", "0", "0"]], "bids": [], "ts": "1742555189604", "checksum": 515313538, "seqId": 49927508294, "prevSeqId": 49927508291}], "record_time": 1742555189.608538, "EXCHANGE": "OKX"}
{"arg": {"channel": "books", "instId": "BTC-USDT"}, "action": "update", "data": [{"asks": [["84060.1", "0.09152919", "0", "3"], ["84074.5", "0", "0", "0"], ["84074.6", "0", "0", "0"], ["84074.8", "0.09623218", "0", "3"], ["84074.9", "0", "0", "0"], ["84075.2", "0.03108755", "0", "1"], ["84081.2", "0", "0", "0"], ["84081.5", "0.03320705", "0", "1"], ["84081.8", "0.03259664", "0", "1"], ["84083.2", "0", "0", "0"], ["84083.3", "0.00060645", "0", "1"], ["84083.5", "0.03415762", "0", "1"], ["84083.6", "0.0322961", "0", "1"], ["84088.5", "0.35641581", "0", "1"], ["84088.8", "0.06487996", "0", "1"], ["84090", "0.001", "0", "1"], ["84090.2", "0.06514021", "0", "1"], ["84090.7", "0", "0", "0"], ["84090.9", "0.06705115", "0", "1"], ["84092", "0", "0", "0"], ["84092.3", "0.06186624", "0", "1"], ["84228.3", "0", "0", "0"], ["84228.4", "0", "0", "0"]], "bids": [["84048.8", "0.17844", "0", "1"], ["84047.5", "0.03470803", "0", "1"], ["84047.2", "0.133608", "0", "1"], ["84046.8", "0.03427731", "0", "1"], ["84046.5", "0", "0", "0"], ["84046.1", "0.03094681", "0", "2"], ["84045.9", "0.00357", "0", "1"], ["84045.8", "0.23800517", "0", "4"], ["84045.5", "0", "0", "0"], ["84040.5", "0.03069693", "0", "1"], ["84040.2", "0", "0", "0"], ["84039.9", "0.24398741", "0", "2"], ["84039.5", "0.0324678", "0", "1"], ["84039.2", "0.17844", "0", "1"], ["84038", "0.051956", "0", "2"], ["84037.7", "0", "0", "0"], ["84037.4", "0.85920068", "0", "2"], ["84037.1", "0", "0", "0"], ["84033.5", "0.06884276", "0", "1"], ["84033.2", "0.05944451", "0", "1"], ["84030.7", "0.06755629", "0", "1"], ["84030.5", "0", "0", "0"], ["84030", "0.06590533", "0", "2"], ["84029.8", "0", "0", "0"], ["84029.3", "0.07138355", "0", "2"], ["84029", "0", "0", "0"], ["84020.9", "0.11235012", "0", "2"], ["83917.6", "0.00005114", "0", "1"]], "ts": "1742555189704", "checksum": -2087009607, "seqId": 49927508352, "prevSeqId": 49927508294}], "record_time": 1742555189.718451, "EXCHANGE": "OKX"}
{"arg": {"channel": "books", "instId": "BTC-USDT"}, "action": "update", "data": [{"asks": [["84073.6", "0.01055", "0", "1"], ["84078.5", "0.2545", "0", "3"]], "bids": [["84060", "0.79129246", "0", "14"]], "ts": "1742555189804", "checksum": 1636821050, "seqId": 49927508358, "prevSeqId": 49927508352}], "record_time": 1742555189.805863, "EXCHANGE": "OKX"}
{"arg": {"channel": "books", "instId": "BTC-USDT"}, "action": "update", "data": [{"asks": [], "bids": [["84048.8", "0", "0", "0"], ["83917.5", "0.11890903", "0", "1"]], "ts": "1742555189904", "checksum": 1636821050, "seqId": 49927508362, "prevSeqId": 49927508358}], "record_time": 1742555189.904498, "EXCHANGE": "OKX"}
{"arg": {"channel": "books", "instId": "BTC-USDT"}, "action": "update", "data": [{"asks": [["84060.1", "0.12862919", "0", "4"], ["84066", "0.01523777", "0", "2"], ["84089.7", "0", "0", "0"], ["84090.1", "0.23802368", "0", "1"]], "bids": [["84060", "0.59129246", "0", "13"], ["84031.9", "0.23802368", "0", "1"], ["84029.7", "0", "0", "0"]], "ts": "1742555190004", "checksum": -469128915, "seqId": 49927508372, "prevSeqId": 49927508362}], "record_time": 1742555190.050747, "EXCHANGE": "OKX"}
{"arg": {"channel": "books", "instId": "BTC-USDT"}, "action": "update", "data": [{"asks": [["84060.1", "0.09152919", "0", "3"], ["84074.8", "0.10089341", "0", "3"], ["84075.2", "0.03474989", "0", "1"], ["84081.5", "0.03323751", "0", "1"], ["84081.8", "0.03494988", "0", "1"], ["84083.5", "0.03457231", "0", "1"], ["84083.6", "0.03148996", "0", "1"], ["84088.8", "0.06587853", "0", "1"], ["84090.1", "0.23802316", "0", "1"], ["84090.2", "0.06674605", "0", "1"], ["84090.9", "0.06432529", "0", "1"], ["84092.3", "0.06454919", "0", "1"]], "bids": [["84060", "0.58950846", "0", "12"], ["84047.5", "0.03250945", "0", "1"], ["84046.8", "0.03358398", "0", "1"], ["84046.1", "0.03342089", "0", "2"], ["84045.8", "0.24042157", "0", "4"], ["84040.5", "0.03419689", "0", "1"], ["84039.5", "0.03128234", "0", "1"], ["84038", "0.04882216", "0", "2"], ["84037.4", "0.85947213", "0", "2"], ["84033.5", "0.06946183", "0", "1"], ["84031.9", "0.23802266", "0", "1"], ["84030.7", "0.06467075", "0", "1"], ["84030", "1.06248554", "0", "3"], ["84029.3", "0.07274327", "0", "2"], ["84029.1", "0.4193538", "0", "1"], ["84026.5", "0", "0", "0"], ["84017.7", "0.00143896", "0", "2"], ["84014.7", "0.471153", "0", "1"], ["84000.1", "1.10289762", "0", "1"], ["83997.7", "0.00285316", "0", "1"], ["83997.3", "0", "0", "0"]], "ts": "1742555190104", "checksum": 1486545856, "seqId": 49927508469, "prevSeqId": 49927508372}], "record_time": 1742555190.104875, "EXCHANGE": "OKX"}
{"arg": {"channel": "books", "instId": "BTC-USDT"}, "action": "update", "data": [{"asks": [["84074.8", "0.10009672", "0", "3"], ["84090.1", "0", "0", "0"], ["84090.8", "0.23802313", "0", "1"], ["84092.3", "0.06574565", "0", "1"]], "bids": [["84046.8", "0.03313863", "0", "1"], ["84029.3", "0.06701806", "0", "2"]], "ts": "1742555190204", "checksum": 1486545856, "seqId": 49927508495, "prevSeqId": 49927508469}], "record_time": 1742555190.243388, "EXCHANGE": "OKX"}
{"arg": {"channel": "books", "instId": "BTC-USDT"}, "action": "update", "data": [{"asks": [["84060.1", "0.12862919", "0", "4"], ["84074.5", "0.03337998", "0", "1"], ["84074.6", "0.0320713", "0", "1"], ["84074.8", "0", "0", "0"], ["84074.9", "0.03115347", "0", "1"], ["84075.2", "0", "0", "0"], ["84081.2", "0.03136192", "0", "1"], ["84081.5", "0.03378653", "0", "1"], ["84081.8", "0", "0", "0"], ["84083.2", "0.03476751", "0", "1"], ["84083.3", "0.03310996", "0", "2"], ["84083.5", "0", "0", "0"], ["84083.6", "0", "0", "0"], ["84088.5", "0.4177463", "0", "2"], ["84088.8", "0", "0", "0"], ["84089.7", "0.23802413", "0", "1"], ["84090", "0.064647", "0", "2"], ["84090.2", "0", "0", "0"], ["84090.7", "0.06343755", "0", "1"], ["84090.8", "0", "0", "0"], ["84090.9", "0", "0", "0"], ["84092.3", "0", "0", "0"], ["84228.3", "0.01784265", "0", "3"], ["84228.4", "0.00010514", "0", "1"], ["84228.5", "0.00002372", "0", "1"]], "bids": [["84060", "0.59093546", "0", "13"], ["84057", "0.0025", "0", "1"], ["84047.5", "0", "0", "0"], ["84047.2", "0.16704197", "0", "2"], ["84046.8", "0", "0", "0"], ["84046.1", "0.00006", "0", "1"], ["84045.9", "0.03612666", "0", "2"], ["84045.8", "0.20672021", "0", "3"], ["84045.5", "0.03501883", "0", "1"], ["84040.5", "0", "0", "0"], ["84040.2", "0.03464704", "0", "1"], ["84039.5", "0", "0", "0"], ["84039.2", "0.20979276", "0", "2"], ["84038", "0.01774536", "0", "1"], ["84037.7", "0.03272038", "0", "1"], ["84037.4", "0.82776217", "0", "1"], ["84037.1", "0.03180032", "0", "1"], ["84033.5", "0", "0", "0"], ["84033.2", "0.1257102", "0", "2"], ["84030.7", "0", "0", "0"], ["84030.5", "0.06375881", "0", "1"], ["84030", "1.00001196", "0", "2"], ["84029.8", "0.06472548", "0", "1"], ["84029.3", "0.00353141", "0", "1"], ["84017.7", "0.00001196", "0", "1"]], "ts": "1742555190304", "checksum": -138702581, "seqId": 49927508547, "prevSeqId": 49927508495}], "record_time": 1742555190.311361, "EXCHANGE": "OKX"}
{"arg": {"channel": "books", "instId": "BTC-USDT"}, "action": "update", "data": [{"asks": [["84060.1", "0.09152919", "0", "3"], ["84074.5", "0", "0", "0"], ["84074.6", "0", "0", "0"], ["84074.8", "0.10080666", "0", "3"], ["84074.9", "0", "0", "0"], ["84075.2", "0.03329388", "0", "1"], ["84081.2", "0", "0", "0"], ["84081.5", "0.03129386", "0", "1"], ["84081.8", "0.03308367", "0", "1"], ["84083.2", "0", "0", "0"], ["84083.3", "0.00060645", "0", "1"], ["84083.5", "0.03154525", "0", "1"], ["84083.6", "0.0317772", "0", "1"], ["84088.5", "0.35641581", "0", "1"], ["84088.8", "0.06257863", "0", "1"], ["84089.7", "0", "0", "0"], ["84090", "0.001", "0", "1"], ["84090.1", "0.23802339", "0", "1"], ["84090.2", "0.06221037", "0", "1"], ["84090.7", "0", "0", "0"], ["84090.9", "0.07058426", "0", "1"], ["84092.3", "0.06159053", "0", "1"], ["84228.3", "0", "0", "0"], ["84228.4", "0", "0", "0"], ["84228.5", "0", "0", "0"]], "bids": [["84047.5", "0.03091349", "0", "1"], ["84047.2", "0.133608", "0", "1"], ["84046.8", "0.03357808", "0", "1"], ["84046.1", "0.03269729", "0", "2"], ["84045.9", "0.00357", "0", "1"], ["84045.8", "0.2403087", "0", "4"], ["84045.5", "0", "0", "0"], ["84040.5", "0.03354136", "0", "1"], ["84040.2", "0", "0", "0"], ["84039.5", "0.03387803", "0", "1"], ["84039.2", "0.17844", "0", "1"], ["84038", "0.05108679", "0", "2"], ["84037.7", "0", "0", "0"], ["84037.4", "0.86186863", "0", "2"], ["84037.1", "0", "0", "0"], ["84033.5", "0.06301052", "0", "1"], ["84033.2", "0.05944451", "0", "1"], ["84030.7", "0.06963022", "0", "1"], ["84030.5", "0", "0", "0"], ["84030", "1.0644127", "0", "3"], ["84029.8", "0", "0", "0"], ["84029.3", "0.0662176", "0", "2"]], "ts": "1742555190404", "checksum": 1360465827, "seqId": 49927508607, "prevSeqId": 49927508547}], "record_time": 1742555190.406016, "EXCHANGE": "OKX"}
{"arg": {"channel": "books", "instId": "BTC-USDT"}, "action": "update", "data": [{"asks": [["84070.1", "0", "0", "0"], ["84090.1", "0", "0", "0"], ["84090.8", "0.23802292", "0", "1"], ["84114.2", "0", "0", "0"], ["84228.3", "0.01784265", "0", "3"], ["84228.4", "0.00010514", "0", "1"]], "bids": [["84045.9", "0", "0", "0"], ["84009.6", "0.00357", "0", "1"]], "ts": "1742555190504", "checksum": 695977165, "seqId": 49927508616, "prevSeqId": 49927508607}], "record_time": 1742555190.573554, "EXCHANGE": "OKX"}
{"arg": {"channel": "books", "instId": "BTC-USDT"}, "action": "update", "data": [{"asks": [["84087.7", "0", "0", "0"], ["84094.4", "0.11235012", "0", "2"], ["84100.1", "0.4808", "0", "1"], ["84109.2", "0.27379595", "0", "2"], ["84111.3", "0.53727", "0", "1"], ["84114.2", "0.00004312", "0", "1"], ["84228.3", "0", "0", "0"], ["84228.4", "0", "0", "0"]], "bids": [["84046", "1", "0", "1"], ["84044.7", "0.03618589", "0", "1"], ["83931.3", "0.00001197", "0", "1"], ["83927.2", "0.01188839", "0", "1"], ["83917.6", "0", "0", "0"], ["83917.5", "0", "0", "0"]], "ts": "1742555190604", "checksum": 695977165, "seqId": 49927508629, "prevSeqId": 49927508616}], "record_time": 1742555190.605387, "EXCHANGE": "OKX"}
{"arg": {"channel": "books", "instId": "BTC-USDT"}, "action": "update", "data": [{"asks": [["84089", "0", "0", "0"], ["84195.9", "0.0118887", "0", "1"]], "bids": [["84012.4", "0", "0", "0"], ["84010.1", "0.01832779", "0", "1"], ["83941.2", "0.01784691", "0", "1"], ["83938.3", "0.18327795", "0", "1"], ["83918.3", "0", "0", "0"]], "ts": "1742555190704", "checksum": 695977165, "seqId": 49927508652, "prevSeqId": 49927508629}], "record_time": 1742555190.763726, "EXCHANGE": "OKX"}
{"arg": {"channel": "books", "instId": "BTC-USDT"}, "action": "update", "data": [{"asks": [], "bids": [["84060", "0.58329546", "0", "12"], ["84046", "0", "0", "0"], ["84044.6", "1", "0", "1"]], "ts": "1742555190804", "checksum": -472632345, "seqId": 49927508659, "prevSeqId": 49927508652}], "record_time": 1742555190.805098, "EXCHANGE": "OKX"}
{"arg": {"channel": "books", "instId": "BTC-USDT"}, "action": "update", "data": [{"asks": [["84078.4", "0", "0", "0"], ["84079.8", "1.21584076", "0", "2"], ["84228.3", "0.01784265", "0", "3"]], "bids": [], "ts": "1742555190904", "checksum": -472632345, "seqId": 49927508668, "prevSeqId": 49927508659}], "record_time": 1742555190.905925, "EXCHANGE": "OKX"}
{"arg": {"channel": "books", "instId": "BTC-USDT"}, "action": "update", "data": [{"asks": [["84078.4", "1", "0", "1"], ["84079.8", "0.21584076", "0", "1"], ["84116.6", "0.01249471", "0", "2"], ["84121.6", "0", "0", "0"], ["84200.8", "0.01188826", "0", "1"], ["84205.8", "0", "0", "0"]], "bids": [["84046.4", "0.00357", "0", "1"], ["84015.4", "0", "0", "0"], ["84010.4", "0.02377647", "0", "2"], ["84009.6", "0", "0", "0"], ["83918.3", "0.2025", "0", "1"]], "ts": "1742555191104", "checksum": -472632345, "seqId": 49927508685, "prevSeqId": 49927508668}], "record_time": 1742555191.113119, "EXCHANGE": "OKX"}
{"arg": {"channel": "books", "instId": "BTC-USDT"}, "action": "update", "data": [{"asks": [["84076.8", "1.0103941", "0", "2"], ["84078.4", "0", "0", "0"], ["84228.4", "0.00010514", "0", "1"]], "bids": [["84044.6", "0", "0", "0"], ["84043.5", "1.04", "0", "2"], ["84031.8", "0.58358714", "0", "2"], ["83917.6", "0.00005114", "0", "1"]], "ts": "1742555191204", "checksum": -472632345, "seqId": 49927508697, "prevSeqId": 49927508685}], "record_time": 1742555191.288439, "EXCHANGE": "OKX"}
{"arg": {"channel": "books", "instId": "BTC-USDT"}, "action": "update", "data": [{"asks": [["84076.8", "0.0103941", "0", "1"], ["84078.1", "1", "0", "1"], ["84228.4", "0", "0", "0"]], "bids": [["84060", "0.59039546", "0", "13"], ["84045", "1.02380344", "0", "2"], ["84043.5", "0.04", "0", "1"]], "ts": "1742555191304", "checksum": 1779939909, "seqId": 49927508712, "prevSeqId": 49927508697}], "record_time": 1742555191.30522, "EXCHANGE": "OKX"}
{"arg": {"channel": "books", "instId": "BTC-USDT"}, "action": "update", "data": [{"asks": [["84084", "0.14291634", "0", "1"], ["84086.6", "0", "0", "0"], ["84088.2", "0.23802281", "0", "1"], ["84090.8", "0", "0", "0"], ["84114.3", "0.18608224", "0", "1"], ["84116", "0", "0", "0"], ["84228.4", "0.00010514", "0", "1"], ["84228.5", "0.00002372", "0", "1"]], "bids": [["84037.4", "0.03410646", "0", "1"], ["84036.2", "0", "0", "0"], ["84033.8", "0.24223275", "0", "2"], ["84031.9", "0", "0", "0"], ["84006.8", "0", "0", "0"], ["84000.1", "1.67095374", "0", "2"], ["83917.5", "0.11890903", "0", "1"], ["83917.4", "0.17821722", "0", "1"], ["83917.3", "0.08991011", "0", "1"]], "ts": "1742555191404", "checksum": 1779939909, "seqId": 49927508733, "prevSeqId": 49927508712}], "record_time": 1742555191.405981, "EXCHANGE": "OKX"}
{"arg": {"channel": "books", "instId": "BTC-USDT"}, "action": "update", "data": [{"asks": [["84086.6", "1.60184472", "0", "1"], ["84088.2", "0", "0", "0"], ["84089.7", "0.23802363", "0", "1"], ["84116", "2.89212193", "0", "1"], ["84228.4", "0", "0", "0"], ["84228.5", "0", "0", "0"]], "bids": [["84038", "0.03334143", "0", "1"], ["84036.6", "1.61715455", "0", "1"], ["84033.8", "0.00420994", "0", "1"], ["84031.9", "0.25576899", "0", "2"], ["84012.7", "0.11890903", "0", "1"], ["84007.4", "0.91613799", "0", "1"], ["84006.3", "0.59964265", "0", "1"], ["83977.9", "0.29198412", "0", "1"], ["83970.7", "0.12458302", "0", "2"], ["83964.3", "0.59432247", "0", "1"], ["83918.3", "0", "0", "0"], ["83917.6", "0", "0", "0"], ["83917.5", "0", "0", "0"], ["83917.4", "0", "0", "0"], ["83917.3", "0", "0", "0"]], "ts": "1742555191504", "checksum": 1779939909, "seqId": 49927508752, "prevSeqId": 49927508733}], "record_time": 1742555191.505441, "EXCHANGE": "OKX"}
{"arg": {"channel": "books", "instId": "BTC-USDT"}, "action": "update", "data": [{"asks": [], "bids": [["84046.4", "0", "0", "0"], ["84030.8", "0.00357", "0", "1"], ["84007.1", "2.82680936", "0", "1"], ["83918.9", "0", "0", "0"]], "ts": "1742555191604", "checksum": 1779939909, "seqId": 49927508755, "prevSeqId": 49927508752}], "record_time": 1742555191.623269, "EXCHANGE": "OKX"}
{"arg": {"channel": "books", "instId": "BTC-USDT"}, "action": "update", "data": [{"asks": [], "bids": [["84036.7", "0.01774536", "0", "1"], ["84031.9", "0.23802363", "0", "1"], ["83919.2", "0", "0", "0"]], "ts": "1742555191704", "checksum": 1779939909, "seqId": 49927508758, "prevSeqId": 49927508755}], "record_time": 1742555191.704959, "EXCHANGE": "OKX"}
{"arg": {"channel": "books", "instId": "BTC-USDT"}, "action": "update", "data": [{"asks": [["84067.9", "0.2", "0", "1"], ["84074.8", "0.0994499", "0", "3"], ["84075.2", "0.03213354", "0", "1"], ["84081.5", "0.03134121", "0", "1"], ["84081.8", "0.03115636", "0", "1"], ["84083.5", "0.0313513", "0", "1"], ["84083.6", "0.03478962", "0", "1"], ["84088.8", "0.06966617", "0", "1"], ["84090.2", "0.06670959", "0", "1"], ["84090.9", "0.06596281", "0", "1"], ["84092.3", "0", "0", "0"], ["84150.7", "0.07130066", "0", "1"]], "bids": [["84047.5", "0.03453685", "0", "1"], ["84046.8", "0.03065006", "0", "1"], ["84046.1", "0.03221528", "0", "2"], ["84045.8", "0.24204965", "0", "4"], ["84040.5", "0.03462763", "0", "1"], ["84039.5", "0.03442125", "0", "1"], ["84038", "0", "0", "0"], ["84037.4", "0.03279243", "0", "1"], ["84033.5", "0.06399782", "0", "1"], ["84030.7", "0.0663225", "0", "1"], ["84030", "1.06634887", "0", "3"], ["84029.3", "0.00353141", "0", "1"], ["83985.8", "0.07147328", "0", "2"], ["83919.2", "0.00003545", "0", "1"]], "ts": "1742555191804", "checksum": 865731056, "seqId": 49927508876, "prevSeqId": 49927508758}], "record_time": 1742555191.813072, "EXCHANGE": "OKX"}
{"arg": {"channel": "books", "instId": "BTC-USDT"}, "action": "update", "data": [{"asks": [["84092.3", "0.06322658", "0", "1"], ["84147", "0.07352541", "0", "1"], ["84150.7", "0", "0", "0"]], "bids": [["84038", "0.03091813", "0", "1"], ["84029.3", "0.06765952", "0", "2"], ["83985.8", "0.00003265", "0", "1"], ["83919.2", "0", "0", "0"]], "ts": "1742555191904", "checksum": 865731056, "seqId": 49927508889, "prevSeqId": 49927508876}], "record_time": 1742555191.910442, "EXCHANGE": "OKX"}
{"arg": {"channel": "books", "instId": "BTC-USDT"}, "action": "update", "data": [{"asks": [["84067.9", "0", "0", "0"], ["84102.4", "0.24982", "0", "1"], ["84103.2", "0.07999999", "0", "2"], ["84104", "1.03999999", "0", "2"], ["84143.7", "0.0713066", "0", "1"]], "bids": [["83978.8", "0.07144658", "0", "1"], ["83920", "0", "0", "0"]], "ts": "1742555192004", "checksum": 1779939909, "seqId": 49927508903, "prevSeqId": 49927508889}], "record_time": 1742555192.005524, "EXCHANGE": "OKX"}
{"arg": {"channel": "books", "instId": "BTC-USDT"}, "action": "update", "data": [{"asks": [], "bids": [["84011.9", "0.0183278", "0", "1"], ["84010.1", "0", "0", "0"], ["83940.3", "0.18327801", "0", "1"], ["83938.3", "0", "0", "0"]], "ts": "1742555192104", "checksum": 1779939909, "seqId": 49927508910, "prevSeqId": 49927508903}], "record_time": 1742555192.193231, "EXCHANGE": "OKX"}
{"arg": {"channel": "books", "instId": "BTC-USDT"}, "action": "update", "data": [{"asks": [["84089.7", "0", "0", "0"], ["84090.1", "0.23802135", "0", "1"]], "bids": [["84060", "0.58329546", "0", "12"], ["84039.6", "0", "0", "0"], ["84033.3", "0.23903665", "0", "3"], ["84031.9", "0", "0", "0"], ["84014", "0.22491", "0", "2"], ["83920", "0.00001096", "0", "1"], ["83919.2", "0.00003545", "0", "1"]], "ts": "1742555192204", "checksum": -472632345, "seqId": 49927508933, "prevSeqId": 49927508910}], "record_time": 1742555192.204483, "EXCHANGE": "OKX"}
{"arg": {"channel": "books", "instId": "BTC-USDT"}, "action": "update", "data": [{"asks": [["84090.1", "0.23802196", "0", "1"], ["84114.3", "1.04351214", "0", "2"]], "bids": [["84036.7", "0.74988517", "0", "2"], ["84033.3", "0.00101534", "0", "2"], ["84031.9", "0.23802348", "0", "1"], ["84014", "0.12491", "0", "1"], ["83919.2", "0", "0", "0"]], "ts": "1742555192304", "checksum": -472632345, "seqId": 49927508957, "prevSeqId": 49927508933}], "record_time": 1742555192.401455, "EXCHANGE": "OKX"}
{"arg": {"channel": "books", "instId": "BTC-USDT"}, "action": "update", "data": [{"asks": [["84074.8", "0.10083402", "0", "3"], ["84075.2", "0.03200665", "0", "1"], ["84081.5", "0.03156792", "0", "1"], ["84081.8", "0.03381478", "0", "1"], ["84083.5", "0.0348842", "0", "1"], ["84083.6", "0.03339378", "0", "1"], ["84088.8", "0.06241695", "0", "1"], ["84090.2", "0.06403185", "0", "1"], ["84090.9", "0.06675381", "0", "1"], ["84092.3", "0", "0", "0"], ["84143.7", "0.1426132", "0", "2"], ["84228.4", "0.00010514", "0", "1"]], "bids": [["84047.5", "0.03425574", "0", "1"], ["84046.8", "0.03257121", "0", "1"], ["84046.1", "0.03405772", "0", "2"], ["84045.8", "0.2393303", "0", "4"], ["84040.5", "0.03446395", "0", "1"], ["84039.5", "0.03495051", "0", "1"], ["84038", "0.03073741", "0", "1"], ["84037.4", "0.03081016", "0", "1"], ["84033.5", "0.0681392", "0", "1"], ["84030.7", "0.06449167", "0", "1"], ["84030", "1.06609083", "0", "3"], ["84029.3", "0.00353141", "0", "1"], ["83978.8", "0.14289316", "0", "2"]], "ts": "1742555192404", "checksum": -472632345, "seqId": 49927509019, "prevSeqId": 49927508957}], "record_time": 1742555192.40564, "EXCHANGE": "OKX"}
{"arg": {"channel": "books", "instId": "BTC-USDT"}, "action": "update", "data": [{"asks": [["84060.1", "0.55234743", "0", "7"], ["84061.6", "0.04008521", "0", "1"], ["84061.7", "0.11901738", "0", "1"], ["84063.5", "0.01733795", "0", "1"], ["84063.7", "0", "0", "0"], ["84063.8", "0", "0", "0"], ["84067.1", "0.01166919", "0", "2"], ["84067.9", "0.11890903", "0", "1"], ["84068.3", "0", "0", "0"], ["84068.6", "0.2025", "0", "1"], ["84071.5", "0", "0", "0"], ["84073.3", "0.04108083", "0", "2"], ["84073.4", "0.07083298", "0", "2"], ["84073.7", "0.06832504", "0", "2"], ["84073.9", "0.03374779", "0", "1"], ["84074.8", "0", "0", "0"], ["84075.2", "0", "0", "0"], ["84076.3", "0.86636458", "0", "2"], ["84076.4", "1", "0", "1"], ["84076.5", "0", "0", "0"], ["84078.1", "0", "0", "0"], ["84079.1", "0", "0", "0"], ["84080.2", "0.03420984", "0", "1"], ["84080.3", "0.0327963", "0", "1"], ["84081.5", "0", "0", "0"], ["84081.8", "0", "0", "0"], ["84082.4", "0.04455638", "0", "3"], ["84082.5", "0.03200394", "0", "1"], ["84083.5", "0", "0", "0"], ["84083.6", "0", "0", "0"], ["84087.3", "0.06592987", "0", "1"], ["84088.8", "0", "0", "0"], ["84089.1", "0.06494575", "0", "1"], ["84089.7", "0.30140561", "0", "2"], ["84090.1", "0", "0", "0"], ["84090.2", "0", "0", "0"], ["84090.9", "0", "0", "0"], ["84091.2", "0.06538776", "0", "1"], ["84228.5", "0.00002372", "0", "1"]], "bids": [["84060", "0.48186846", "0", "10"], ["84058.1", "0", "0", "0"], ["84053.8", "0.0134", "0", "1"], ["84053.1", "0", "0", "0"], ["84052.5", "0.05617506", "0", "1"], ["84051.8", "0", "0", "0"], ["84048.8", "0.17844", "0", "1"], ["84047.5", "0.04021", "0", "1"], ["84046.8", "0", "0", "0"], ["84046.1", "0.00006", "0", "1"], ["84046", "0.03398745", "0", "1"], ["84045.8", "0.20672021", "0", "3"], ["84045.7", "0.032755", "0", "1"], ["84045", "0.05783128", "0", "2"], ["84044.5", "0.03367088", "0", "1"], ["84043.9", "1", "0", "1"], ["84040.5", "0", "0", "0"], ["84039.5", "0", "0", "0"], ["84039", "0.03183126", "0", "1"], ["84038.2", "0.03444494", "0", "1"], ["84038", "0", "0", "0"], ["84037.4", "0", "0", "0"], ["84036.9", "0.03223233", "0", "1"], ["84036.3", "0.03106708", "0", "1"], ["84033.5", "0", "0", "0"], ["84032", "0.06703466", "0", "1"], ["84031.9", "0", "0", "0"], ["84031.8", "0.32388109", "0", "1"], ["84030.7", "0", "0", "0"], ["84030", "0.00001196", "0", "1"], ["84029.7", "0.23802542", "0", "1"], ["84029.6", "0.16008534", "0", "2"], ["84028.8", "0.26791024", "0", "2"], ["84028.2", "0.06834884", "0", "1"], ["84016.5", "0.001427", "0", "1"], ["83997.6", "0", "0", "0"], ["83945.5", "0", "0", "0"], ["83920", "0", "0", "0"]], "ts": "1742555192504", "checksum": -1768389625, "seqId": 49927509181, "prevSeqId": 49927509019}], "record_time": 1742555192.50739, "EXCHANGE": "OKX"}
{"arg": {"channel": "books", "instId": "BTC-USDT"}, "action": "update", "data": [{"asks": [["84068.6", "0", "0", "0"], ["84228.9", "0.00008", "0", "1"]], "bids": [["84060", "0.46402546", "0", "9"], ["83998.3", "0.00235648", "0", "1"], ["83997.7", "0", "0", "0"], ["83997.3", "0.00285316", "0", "1"], ["83943.8", "0.20608998", "0", "2"], ["83921", "0", "0", "0"]], "ts": "1742555192604", "checksum": -16302944, "seqId": 49927509188, "prevSeqId": 49927509181}], "record_time": 1742555192.671482, "EXCHANGE": "OKX"}
{"arg": {"channel": "books", "instId": "BTC-USDT"}, "action": "update", "data": [{"asks": [], "bids": [["84060", "0.47061546", "0", "10"]], "ts": "1742555192704", "checksum": -1469577069, "seqId": 49927509189, "prevSeqId": 49927509188}], "record_time": 1742555192.708699, "EXCHANGE": "OKX"}
{"arg": {"channel": "books", "instId": "BTC-USDT"}, "action": "update", "data": [{"asks": [["84088.2", "0.23802755", "0", "1"], ["84089.7", "0.0633812", "0", "1"], ["84143.7", "0.0713066", "0", "1"], ["84228.9", "0", "0", "0"]], "bids": [["84060", "0.46181546", "0", "9"], ["84051.4", "0.00351318", "0", "1"], ["83978.8", "0.07144658", "0", "1"], ["83943.8", "0.2025", "0", "1"], ["83921.3", "0", "0", "0"]], "ts": "1742555193004", "checksum": -239441219, "seqId": 49927509212, "prevSeqId": 49927509189}], "record_time": 1742555193.004821, "EXCHANGE": "OKX"}
{"arg": {"channel": "books", "instId": "BTC-USDT"}, "action": "update", "data": [{"asks": [["84143.7", "0", "0", "0"], ["84228.9", "0.00008", "0", "1"]], "bids": [["83998.3", "0", "0", "0"], ["83978.8", "0", "0", "0"], ["83921.3", "0.0016853", "0", "2"], ["83921", "0.00001002", "0", "1"]], "ts": "1742555193104", "checksum": -239441219, "seqId": 49927509222, "prevSeqId": 49927509212}], "record_time": 1742555193.105283, "EXCHANGE": "OKX"}
{"arg": {"channel": "books", "instId": "BTC-USDT"}, "action": "update", "data": [{"asks": [["84068.6", "0.2025", "0", "1"], ["84143.7", "0.1426132", "0", "2"], ["84228.5", "0", "0", "0"], ["84228.9", "0", "0", "0"]], "bids": [["84060", "0.47965946", "0", "10"], ["83978.8", "0.14289316", "0", "2"], ["83921", "0", "0", "0"]], "ts": "1742555193204", "checksum": 782434449, "seqId": 49927509235, "prevSeqId": 49927509222}], "record_time": 1742555193.204502, "EXCHANGE": "OKX"}
{"arg": {"channel": "books", "instId": "BTC-USDT"}, "action": "update", "data": [{"asks": [["84084", "0.69679244", "0", "2"], ["84100.4", "0", "0", "0"], ["84143.7", "0.0713066", "0", "1"], ["84228.5", "0.00002372", "0", "1"]], "bids": [["84000.1", "2.04045748", "0", "1"], ["83992", "0.00235666", "0", "1"], ["83978.8", "0.07144658", "0", "1"], ["83939.9", "0.00359015", "0", "1"], ["83921.7", "0", "0", "0"], ["83921.3", "0", "0", "0"]], "ts": "1742555193304", "checksum": 782434449, "seqId": 49927509250, "prevSeqId": 49927509235}], "record_time": 1742555193.386271, "EXCHANGE": "OKX"}
{"arg": {"channel": "books", "instId": "BTC-USDT"}, "action": "update", "data": [{"asks": [["84084.2", "0.05944451", "0", "1"], ["84093.2", "0.00059468", "0", "1"], ["84228.5", "0", "0", "0"]], "bids": [["84014", "0.22491", "0", "2"]], "ts": "1742555193404", "checksum": 782434449, "seqId": 49927509257, "prevSeqId": 49927509250}], "record_time": 1742555193.404833, "EXCHANGE": "OKX"}
{"arg": {"channel": "books", "instId": "BTC-USDT"}, "action": "update", "data": [{"asks": [["84068.6", "0", "0", "0"], ["84082.8", "0.133611", "0", "1"], ["84143.7", "0.1426132", "0", "2"]], "bids": [["84045.1", "1.01790207", "0", "3"], ["84043.9", "0", "0", "0"], ["84014", "0.12491", "0", "1"], ["83978.8", "0.14289316", "0", "2"], ["83921.7", "0.0535785", "0", "1"]], "ts": "1742555193504", "checksum": 630530717, "seqId": 49927509273, "prevSeqId": 49927509257}], "record_time": 1742555193.508495, "EXCHANGE": "OKX"}
{"arg": {"channel": "books", "instId": "BTC-USDT"}, "action": "update", "data": [{"asks": [["84068.6", "0.2025", "0", "1"], ["84228.4", "0", "0", "0"]], "bids": [["84030.8", "0", "0", "0"], ["84011.6", "0.00456883", "0", "2"], ["83921.3", "0.0016853", "0", "2"]], "ts": "1742555193604", "checksum": 782434449, "seqId": 49927509276, "prevSeqId": 49927509273}], "record_time": 1742555193.615217, "EXCHANGE": "OKX"}
{"arg": {"channel": "books", "instId": "BTC-USDT"}, "action": "update", "data": [{"asks": [["84068.6", "0", "0", "0"], ["84228.4", "0.00010514", "0", "1"]], "bids": [["84060", "0.47306946", "0", "9"]], "ts": "1742555193704", "checksum": 1752159217, "seqId": 49927509278, "prevSeqId": 49927509276}], "record_time": 1742555193.720858, "EXCHANGE": "OKX"}
{"arg": {"channel": "books", "instId": "BTC-USDT"}, "action": "update", "data": [{"asks": [["84060.1", "0.51214743", "0", "5"], ["84088.2", "0", "0", "0"], ["84091.1", "0.23802385", "0", "1"]], "bids": [["84051.4", "0", "0", "0"], ["84032.1", "0.23802385", "0", "1"], ["84029.7", "0", "0", "0"], ["84011.6", "0.00099883", "0", "1"], ["83987.4", "0.00357", "0", "1"]], "ts": "1742555193804", "checksum": -86291411, "seqId": 49927509290, "prevSeqId": 49927509278}], "record_time": 1742555193.819406, "EXCHANGE": "OKX"}
{"arg": {"channel": "books", "instId": "BTC-USDT"}, "action": "update", "data": [{"asks": [], "bids": [["84060", "0.48906946", "0", "10"], ["84048.8", "0", "0", "0"], ["84025.9", "0.00357", "0", "1"], ["83987.4", "0", "0", "0"], ["83921", "0.00001002", "0", "1"]], "ts": "1742555193904", "checksum": 1771054322, "seqId": 49927509295, "prevSeqId": 49927509290}], "record_time": 1742555193.913913, "EXCHANGE": "OKX"}
{"arg": {"channel": "books", "instId": "BTC-USDT"}, "action": "update", "data": [{"asks": [["84076.4", "0", "0", "0"], ["84077.7", "1.06", "0", "3"], ["84084", "0.14291634", "0", "1"], ["84086.6", "0", "0", "0"], ["84089.7", "0.30140186", "0", "2"], ["84091.1", "0", "0", "0"], ["84114.3", "0.18608224", "0", "1"], ["84116", "0", "0", "0"], ["84228.5", "0.00002372", "0", "1"], ["84228.9", "0.00008", "0", "1"], ["84230.1", "0.000548", "0", "2"], ["84230.9", "0.35582144", "0", "2"]], "bids": [["84060", "0.49049746", "0", "11"], ["84051.4", "0.00349033", "0", "1"], ["84033.3", "0.239036", "0", "3"], ["84032.1", "0", "0", "0"], ["84026.4", "0.0103941", "0", "1"], ["84025.6", "0.106", "0", "4"], ["84024.8", "0.58210201", "0", "3"], ["84022.4", "0", "0", "0"], ["84021.6", "0.1", "0", "2"], ["84020.8", "0.05", "0", "1"], ["84016.5", "0", "0", "0"], ["84011.9", "0", "0", "0"], ["84011.7", "0.01832762", "0", "1"], ["83920", "0.00001096", "0", "1"]], "ts": "1742555194004", "checksum": -343298878, "seqId": 49927509322, "prevSeqId": 49927509295}], "record_time": 1742555194.007437, "EXCHANGE": "OKX"}
{"arg": {"channel": "books", "instId": "BTC-USDT"}, "action": "update", "data": [{"asks": [["84060.1", "0.51231634", "0", "6"], ["84078.9", "0", "0", "0"], ["84088.9", "0", "0", "0"], ["84089.7", "0.0633812", "0", "1"], ["84091.1", "0.2380202", "0", "1"], ["84230.7", "0.2025", "0", "1"]], "bids": [["84058", "0.0025", "0", "1"], ["84033.3", "0.23903554", "0", "3"]], "ts": "1742555194104", "checksum": -1378555601, "seqId": 49927509345, "prevSeqId": 49927509322}], "record_time": 1742555194.106239, "EXCHANGE": "OKX"}
{"arg": {"channel": "books", "instId": "BTC-USDT"}, "action": "update", "data": [{"asks": [["84077.7", "0.06", "0", "2"], ["84080.3", "1.0327963", "0", "2"], ["84089.7", "0.30140171", "0", "2"], ["84091.1", "0", "0", "0"], ["84100.9", "0", "0", "0"], ["84101", "0", "0", "0"], ["84102", "0.052", "0", "2"], ["84104", "0.03999999", "0", "1"], ["84232", "0.00172464", "0", "3"], ["84232.3", "0.29700048", "0", "2"], ["84232.6", "0.00001501", "0", "1"]], "bids": [["84060", "0.49708746", "0", "12"], ["84047.1", "1", "0", "1"], ["84045.1", "0.01790207", "0", "2"], ["83920", "0", "0", "0"]], "ts": "1742555194204", "checksum": -643969500, "seqId": 49927509360, "prevSeqId": 49927509345}], "record_time": 1742555194.248142, "EXCHANGE": "OKX"}
{"arg": {"channel": "books", "instId": "BTC-USDT"}, "action": "update", "data": [{"asks": [["84060.1", "0.0916981", "0", "4"], ["84067.1", "0.00111919", "0", "1"], ["84072.5", "0.01055", "0", "1"], ["84073.3", "0.00906686", "0", "1"], ["84073.4", "0.03916298", "0", "1"], ["84073.7", "0", "0", "0"], ["84073.9", "0", "0", "0"], ["84074.2", "0.06367679", "0", "2"], ["84074.3", "0.06446709", "0", "2"], ["84074.6", "0.03481747", "0", "1"], ["84076.3", "0.81013954", "0", "3"], ["84078.8", "0.03166", "0", "1"], ["84078.9", "1", "0", "1"], ["84080.2", "0", "0", "0"], ["84080.3", "0", "0", "0"], ["84080.9", "0.0313504", "0", "1"], ["84081.3", "0.03447308", "0", "1"], ["84082.4", "0.01", "0", "2"], ["84082.5", "0", "0", "0"], ["84082.9", "0.03166948", "0", "1"], ["84083", "0.03431046", "0", "1"], ["84084", "0.62328692", "0", "2"], ["84086.6", "1.53540937", "0", "1"], ["84087.3", "0", "0", "0"], ["84088.3", "0.19235033", "0", "2"], ["84088.4", "0", "0", "0"], ["84089.1", "0", "0", "0"], ["84089.6", "0.06625806", "0", "1"], ["84089.7", "0", "0", "0"], ["84090.4", "0.06805663", "0", "2"], ["84091.2", "0", "0", "0"], ["84091.7", "0.0613992", "0", "1"], ["84093", "0.23801908", "0", "1"], ["84114.3", "1.0072672", "0", "2"], ["84116", "2.77130546", "0", "1"], ["84138.8", "0.01774536", "0", "1"], ["84230.9", "0", "0", "0"], ["84232", "0", "0", "0"], ["84232.3", "0", "0", "0"], ["84232.6", "0", "0", "0"]], "bids": [["84060", "0.59708746", "0", "13"], ["84059.1", "0.0134", "0", "1"], ["84058", "0", "0", "0"], ["84053.8", "0", "0", "0"], ["84052.8", "0.05211341", "0", "2"], ["84047.5", "0", "0", "0"], ["84047.1", "0", "0", "0"], ["84047", "0.0311665", "0", "1"], ["84046.2", "0.74075257", "0", "4"], ["84046", "0", "0", "0"], ["84045.7", "0", "0", "0"], ["84045.6", "1", "0", "1"], ["84045.5", "0.03118298", "0", "1"], ["84045.2", "0.03542613", "0", "1"], ["84045", "0.02380344", "0", "1"], ["84044.5", "0", "0", "0"], ["84040", "0.03351079", "0", "2"], ["84039", "0", "0", "0"], ["84038.9", "0.03335103", "0", "1"], ["84038.2", "0", "0", "0"], ["84037.4", "0.03496974", "0", "1"], ["84036.9", "0", "0", "0"], ["84036.8", "0.03351586", "0", "1"], ["84036.3", "0", "0", "0"], ["84033.8", "0.24222902", "0", "2"], ["84033.3", "0.00101534", "0", "2"], ["84033", "0.06962199", "0", "1"], ["84032", "0", "0", "0"], ["84030.1", "0.06990736", "0", "1"], ["84029.6", "0.08991011", "0", "1"], ["84029.5", "0.24235392", "0", "2"], ["84028.8", "0.2025", "0", "1"], ["84028.7", "0.06783307", "0", "1"], ["84028.2", "0", "0", "0"], ["84007.4", "1.89386753", "0", "2"], ["84000.1", "0", "0", "0"], ["83982.1", "0.45868919", "0", "2"], ["83977.9", "0", "0", "0"], ["83920", "0.00001096", "0", "1"], ["83919.2", "0.00003545", "0", "1"], ["83918.9", "0.00001197", "0", "1"], ["83918.3", "0.2025", "0", "1"]], "ts": "1742555194304", "checksum": 1100921686, "seqId": 49927509470, "prevSeqId": 49927509360}], "record_time": 1742555194.305683, "EXCHANGE": "OKX"}
{"arg": {"channel": "books", "instId": "BTC-USDT"}, "action": "update", "data": [{"asks": [["84067.1", "0.00113041", "0", "2"], ["84090.3", "0.23802075", "0", "1"], ["84093", "0", "0", "0"]], "bids": [["84055", "0.0025", "0", "1"], ["84038", "0.01774536", "0", "1"], ["84036.7", "0.73213981", "0", "1"], ["84033.8", "0.00420994", "0", "1"], ["84031.9", "0.23802081", "0", "1"], ["83919.2", "0", "0", "0"], ["83918.9", "0", "0", "0"], ["83918.3", "0", "0", "0"]], "ts": "1742555194404", "checksum": 26684954, "seqId": 49927509492, "prevSeqId": 49927509470}], "record_time": 1742555194.435389, "EXCHANGE": "OKX"}
{"arg": {"channel": "books", "instId": "BTC-USDT"}, "action": "update", "data": [{"asks": [["84083.3", "0.14104411", "0", "2"], ["84109.1", "0", "0", "0"], ["84230.9", "0.35582144", "0", "2"]], "bids": [["84051.5", "0", "0", "0"], ["84038.8", "0.14043766", "0", "1"], ["84030", "1.00001196", "0", "2"], ["84022.4", "0.1", "0", "2"], ["84021.6", "0.05", "0", "1"], ["84020.8", "0", "0", "0"]], "ts": "1742555194504", "checksum": 1615335182, "seqId": 49927509510, "prevSeqId": 49927509492}], "record_time": 1742555194.5049, "EXCHANGE": "OKX"}
{"arg": {"channel": "books", "instId": "BTC-USDT"}, "action": "update", "data": [{"asks": [["84072.3", "0.002", "0", "1"], ["84082.3", "0.00631911", "0", "3"], ["84093", "0.01774536", "0", "1"], ["84138.8", "0", "0", "0"], ["84230.9", "0", "0", "0"]], "bids": [["84058.1", "0.002", "0", "1"], ["84048", "0.002", "0", "1"], ["84039.1", "0.00897487", "0", "1"], ["83921.3", "0", "0", "0"], ["83921", "0", "0", "0"], ["83920", "0", "0", "0"]], "ts": "1742555194604", "checksum": 422229212, "seqId": 49927509523, "prevSeqId": 49927509510}], "record_time": 1742555194.604219, "EXCHANGE": "OKX"}
{"arg": {"channel": "books", "instId": "BTC-USDT"}, "action": "update", "data": [{"asks": [["84060.1", "0.1318981", "0", "6"], ["84074", "0.26148678", "0", "4"], ["84074.1", "0.06142074", "0", "2"], ["84074.2", "0", "0", "0"], ["84074.3", "0.03", "0", "1"], ["84074.4", "0.03274225", "0", "1"], ["84074.6", "0", "0", "0"], ["84080.7", "0.03209195", "0", "1"], ["84080.9", "0", "0", "0"], ["84081", "0.03384168", "0", "1"], ["84081.3", "0", "0", "0"], ["84082.8", "0.16875522", "0", "2"], ["84082.9", "0.03502606", "0", "1"], ["84083", "0", "0", "0"], ["84088", "0.06885791", "0", "1"], ["84088.3", "0.12491", "0", "1"], ["84089.5", "0.3026964", "0", "2"], ["84089.6", "0", "0", "0"], ["84090.1", "0.06755678", "0", "1"], ["84090.3", "0", "0", "0"], ["84090.4", "0.00001197", "0", "1"], ["84091.5", "0.06238591", "0", "1"], ["84091.7", "0", "0", "0"], ["84230.9", "0.35582144", "0", "2"]], "bids": [["84060", "0.59559039", "0", "11"], ["84051.4", "0", "0", "0"], ["84047", "0", "0", "0"], ["84046.7", "0.03500807", "0", "1"], ["84046.2", "0.70867135", "0", "3"], ["84046", "0.03262841", "0", "1"], ["84045.5", "0", "0", "0"], ["84045.4", "0.03196088", "0", "1"], ["84045.2", "0", "0", "0"], ["84045", "0.05823561", "0", "2"], ["84040", "0.00001", "0", "1"], ["84039.7", "0.03391912", "0", "1"], ["84038.9", "0", "0", "0"], ["84038.7", "0.03430282", "0", "1"], ["84037.4", "0", "0", "0"], ["84037.3", "0.23520612", "0", "2"], ["84036.8", "0", "0", "0"], ["84036.7", "0.76436228", "0", "2"], ["84033", "0", "0", "0"], ["84032.7", "0.06761065", "0", "1"], ["84031.9", "0", "0", "0"], ["84030.2", "0.23802522", "0", "1"], ["84030.1", "0", "0", "0"], ["84030", "0.06260509", "0", "2"], ["84029.5", "0.17821722", "0", "1"], ["84029.2", "0.06580348", "0", "1"], ["84028.7", "0", "0", "0"], ["84028.5", "0.06545814", "0", "1"], ["84026.4", "0.0903941", "0", "3"], ["84025.6", "0.066", "0", "3"], ["84024.8", "0.54210201", "0", "2"], ["84017.1", "0.001427", "0", "1"], ["83921.3", "0.0016853", "0", "2"]], "ts": "1742555194704", "checksum": 1335048889, "seqId": 49927509605, "prevSeqId": 49927509523}], "record_time": 1742555194.769362, "EXCHANGE": "OKX"}
{"arg": {"channel": "books", "instId": "BTC-USDT"}, "action": "update", "data": [{"asks": [["84060.1", "0.30376884", "0", "5"], ["84066", "0.0146", "0", "1"], ["84067.1", "0.00111919", "0", "1"], ["84069", "0.01055", "0", "1"], ["84072.5", "0", "0", "0"], ["84073.7", "0.06606127", "0", "2"], ["84073.9", "0.03276673", "0", "1"], ["84074", "0.19304", "0", "2"], ["84074.1", "0.03", "0", "1"], ["84074.4", "0.03167", "0", "1"], ["84078.8", "0", "0", "0"], ["84080.2", "0.03470403", "0", "1"], ["84080.7", "0", "0", "0"], ["84081", "0", "0", "0"], ["84082.4", "0.04497062", "0", "3"], ["84082.5", "0.03539037", "0", "1"], ["84082.8", "0.133611", "0", "1"], ["84082.9", "0", "0", "0"], ["84088", "0", "0", "0"], ["84089.1", "0.06945366", "0", "1"], ["84089.5", "0.23802522", "0", "1"], ["84089.7", "0.06981463", "0", "1"], ["84090.1", "0", "0", "0"], ["84091.2", "0.06354538", "0", "1"], ["84091.5", "0", "0", "0"], ["84230.7", "0", "0", "0"], ["84232", "0.00172464", "0", "3"]], "bids": [["84060", "0.47774639", "0", "9"], ["84059.1", "0", "0", "0"], ["84055.8", "0", "0", "0"], ["84055.7", "0.01341197", "0", "2"], ["84052.8", "0.01190341", "0", "1"], ["84051.3", "0.18196139", "0", "2"], ["84048.5", "0.04021", "0", "1"], ["84046.7", "0", "0", "0"], ["84046", "0", "0", "0"], ["84045.7", "0.03065619", "0", "1"], ["84045.4", "0", "0", "0"], ["84045", "0.05744222", "0", "2"], ["84044.5", "0.03457634", "0", "1"], ["84039.7", "0", "0", "0"], ["84038.7", "0", "0", "0"], ["84038.2", "0.03221712", "0", "1"], ["84038", "0", "0", "0"], ["84037.4", "0.01774536", "0", "1"], ["84037.3", "0.2025", "0", "1"], ["84036.9", "0.03414226", "0", "1"], ["84036.7", "0.73213981", "0", "1"], ["84036.3", "0.03116881", "0", "1"], ["84032.7", "0", "0", "0"], ["84030", "0.00001196", "0", "1"], ["84029.6", "0.15397836", "0", "2"], ["84029.2", "0", "0", "0"], ["84028.8", "0.26786407", "0", "2"], ["84028.5", "0", "0", "0"], ["84028.2", "0.06727148", "0", "1"], ["84026.3", "0.0054", "0", "1"], ["84014.5", "0.0054", "0", "1"], ["84013.4", "0", "0", "0"], ["83989.9", "0", "0", "0"], ["83985.1", "0.0054", "0", "1"], ["83935.9", "0", "0", "0"], ["83921", "0.00001002", "0", "1"], ["83920", "0.00001096", "0", "1"], ["83919.2", "0.00003545", "0", "1"]], "ts": "1742555194804", "checksum": -655563289, "seqId": 49927509692, "prevSeqId": 49927509605}], "record_time": 1742555194.805676, "EXCHANGE": "OKX"}
{"arg": {"channel": "books", "instId": "BTC-USDT"}, "action": "update", "data": [{"asks": [["84065.5", "0.00838155", "0", "2"], ["84073.4", "0.07047743", "0", "2"], ["84076.3", "0.55626658", "0", "2"], ["84078.9", "0", "0", "0"], ["84080.4", "0.03118068", "0", "2"], ["84080.5", "1", "0", "1"], ["84087.4", "0.06701391", "0", "1"], ["84089.5", "0", "0", "0"], ["84093", "0.25576388", "0", "2"], ["84230.7", "0.2025", "0", "1"], ["84232", "0", "0", "0"]], "bids": [["84060", "0.49559039", "0", "10"], ["84056", "0.000015", "0", "1"], ["84049.5", "0.56867459", "0", "2"], ["84046.9", "1", "0", "1"], ["84046.2", "0.44920868", "0", "2"], ["84046.1", "0.03314438", "0", "2"], ["84045.6", "0", "0", "0"], ["84039.1", "0.04213764", "0", "2"], ["84033.8", "0.24222846", "0", "2"], ["84032.1", "0.06381551", "0", "1"], ["84030.2", "0", "0", "0"], ["83943.1", "0", "0", "0"], ["83931.8", "0.183232", "0", "1"], ["83919.2", "0", "0", "0"]], "ts": "1742555194904", "checksum": -1254709976, "seqId": 49927509722, "prevSeqId": 49927509692}], "record_time": 1742555194.958187, "EXCHANGE": "OKX"}
{"arg": {"channel": "books", "instId": "BTC-USDT"}, "action": "update", "data": [{"asks": [["84060.1", "0.0916981", "0", "4"], ["84061.6", "0", "0", "0"], ["84061.7", "0", "0", "0"], ["84063.5", "0.05087843", "0", "2"], ["84063.7", "0.11901452", "0", "1"], ["84069", "0", "0", "0"], ["84072.6", "0.01055", "0", "1"], ["84073.4", "0.03916298", "0", "1"], ["84073.7", "0", "0", "0"], ["84073.9", "0", "0", "0"], ["84074.4", "0", "0", "0"], ["84074.7", "0.38843892", "0", "2"], ["84074.8", "0.06767745", "0", "2"], ["84075.1", "0.03095026", "0", "1"], ["84078.9", "0.03166", "0", "1"], ["84080.2", "0", "0", "0"], ["84080.4", "0.00001197", "0", "1"], ["84080.5", "0", "0", "0"], ["84081.4", "1.28460228", "0", "4"], ["84081.8", "0.03078516", "0", "1"], ["84082.4", "0.01", "0", "2"], ["84082.5", "0", "0", "0"], ["84083.5", "0.0322812", "0", "1"], ["84083.6", "0.03132831", "0", "1"], ["84087.4", "0", "0", "0"], ["84088.8", "0.0692301", "0", "1"], ["84089.1", "0", "0", "0"], ["84089.7", "0", "0", "0"], ["84090.1", "0.23802094", "0", "1"], ["84090.2", "0.07021719", "0", "1"], ["84090.9", "0.06894405", "0", "1"], ["84091.2", "0", "0", "0"], ["84092.2", "0.06375577", "0", "1"], ["84093", "0.01774536", "0", "1"]], "bids": [["84060", "0.59559039", "0", "11"], ["84059.2", "0.03870935", "0", "2"], ["84055.7", "0.00001197", "0", "1"], ["84052.9", "0.3971007", "0", "2"], ["84048.5", "0", "0", "0"], ["84047.5", "0.03199082", "0", "1"], ["84046.9", "0", "0", "0"], ["84046.7", "0.0342172", "0", "1"], ["84046.1", "0.034111", "0", "2"], ["84045.7", "0.03415034", "0", "1"], ["84045.1", "1.01790207", "0", "3"], ["84045", "0.02380344", "0", "1"], ["84044.5", "0", "0", "0"], ["84040.5", "0.03293046", "0", "1"], ["84039.4", "0.03103682", "0", "1"], ["84039.1", "0.00897487", "0", "1"], ["84038.2", "0", "0", "0"], ["84038", "0.03237348", "0", "1"], ["84037.4", "0.05100656", "0", "2"], ["84036.9", "0", "0", "0"], ["84036.3", "0", "0", "0"], ["84033.8", "0.00420994", "0", "1"], ["84033.5", "0.06495999", "0", "1"], ["84032.1", "0", "0", "0"], ["84031.9", "0.23802094", "0", "1"], ["84030.7", "0.06395415", "0", "1"], ["84030", "0.06944797", "0", "2"], ["84029.6", "0.08991011", "0", "1"], ["84029.2", "0.06963487", "0", "1"], ["84028.8", "0.2025", "0", "1"], ["84028.2", "0", "0", "0"], ["83920", "0", "0", "0"]], "ts": "1742555195004", "checksum": 122123156, "seqId": 49927509823, "prevSeqId": 49927509722}], "record_time": 1742555195.006455, "EXCHANGE": "OKX"}
{"arg": {"channel": "books", "instId": "BTC-USDT"}, "action": "update", "data": [{"asks": [], "bids": [["84049.5", "0.34499684", "0", "1"], ["84046.2", "0.6887994", "0", "3"]], "ts": "1742555195104", "checksum": 122123156, "seqId": 49927509827, "prevSeqId": 49927509823}], "record_time": 1742555195.107127, "EXCHANGE": "OKX"}
{"arg": {"channel": "books", "instId": "BTC-USDT"}, "action": "update", "data": [{"asks": [["84080", "1.0146", "0", "2"], ["84081.4", "0.28460228", "0", "3"], ["84090.1", "0", "0", "0"], ["84090.8", "0.23802007", "0", "1"], ["84101", "1", "0", "1"], ["84102", "0.252", "0", "3"], ["84230.9", "0", "0", "0"]], "bids": [["84060", "0.58900039", "0", "10"], ["84031.9", "0.23802007", "0", "1"]], "ts": "1742555195204", "checksum": 1735106739, "seqId": 49927509840, "prevSeqId": 49927509827}], "record_time": 1742555195.293033, "EXCHANGE": "OKX"}
{"arg": {"channel": "books", "instId": "BTC-USDT"}, "action": "update", "data": [{"asks": [["84063.7", "0", "0", "0"], ["84079.8", "0.57236397", "0", "2"], ["84143.7", "0.0713066", "0", "1"], ["84230.9", "0.35582144", "0", "2"]], "bids": [["84014", "0.22491", "0", "2"], ["84000.1", "1.08280487", "0", "1"], ["83978.8", "0.07144658", "0", "1"], ["83921", "0", "0", "0"]], "ts": "1742555195504", "checksum": -280084202, "seqId": 49927509852, "prevSeqId": 49927509840}], "record_time": 1742555195.506349, "EXCHANGE": "OKX"}
{"arg": {"channel": "books", "instId": "BTC-USDT"}, "action": "update", "data": [{"asks": [["84060.1", "0.14513504", "0", "6"], ["84061.3", "0.04008536", "0", "1"], ["84061.4", "0.11901788", "0", "1"], ["84063.5", "0.01733795", "0", "1"], ["84073.8", "0.03139993", "0", "1"], ["84073.9", "0.03302812", "0", "1"], ["84074", "0.22667063", "0", "3"], ["84074.3", "0.0647094", "0", "2"], ["84074.7", "0.35689", "0", "1"], ["84074.8", "0", "0", "0"], ["84075.1", "0", "0", "0"], ["84080.6", "0.07490561", "0", "2"], ["84080.8", "0.03133163", "0", "1"], ["84081.4", "0.249835", "0", "2"], ["84081.8", "0", "0", "0"], ["84082.7", "0.03122147", "0", "1"], ["84082.8", "0.16560216", "0", "2"], ["84083.5", "0", "0", "0"], ["84083.6", "0", "0", "0"], ["84087.8", "0.0636727", "0", "1"], ["84088.8", "0", "0", "0"], ["84089.4", "0.0670842", "0", "1"], ["84090", "0.06519406", "0", "2"], ["84090.2", "0", "0", "0"], ["84090.8", "0", "0", "0"], ["84090.9", "0", "0", "0"], ["84091.4", "0.0688437", "0", "1"], ["84092.2", "0", "0", "0"], ["84093", "0.25576619", "0", "2"], ["84143.7", "0.1426132", "0", "2"], ["84232", "0.00172464", "0", "3"]], "bids": [["84060", "0.57115639", "0", "9"], ["84047.5", "0", "0", "0"], ["84046.7", "0", "0", "0"], ["84046.5", "0.03283887", "0", "1"], ["84046.1", "0.00006", "0", "1"], ["84045.9", "0.03369742", "0", "1"], ["84045.7", "0", "0", "0"], ["84045.3", "0.03529091", "0", "1"], ["84044.9", "0.03322541", "0", "1"], ["84040.5", "0", "0", "0"], ["84039.5", "0.03134118", "0", "1"], ["84039.4", "0", "0", "0"], ["84038.6", "0.03515851", "0", "1"], ["84038", "0", "0", "0"], ["84037.4", "0.01774536", "0", "1"], ["84037.2", "0.03175859", "0", "1"], ["84036.6", "1.65233167", "0", "2"], ["84035.9", "0.14044962", "0", "2"], ["84033.5", "0", "0", "0"], ["84032.5", "0.06787203", "0", "1"], ["84030.7", "0", "0", "0"], ["84030", "0.00001196", "0", "1"], ["84029.9", "0.06855801", "0", "1"], ["84029.2", "0", "0", "0"], ["84029.1", "0.48138778", "0", "2"], ["84028.4", "0.06472473", "0", "1"], ["84014", "0.12491", "0", "1"], ["83978.8", "0.14289316", "0", "2"], ["83921.3", "0", "0", "0"]], "ts": "1742555195604", "checksum": 38610757, "seqId": 49927510023, "prevSeqId": 49927509852}], "record_time": 1742555195.609643, "EXCHANGE": "OKX"}
{"arg": {"channel": "books", "instId": "BTC-USDT"}, "action": "update", "data": [{"asks": [["84076.3", "0.81963754", "0", "3"], ["84078.6", "1", "0", "1"], ["84079.8", "0.21584076", "0", "1"], ["84080", "0.0146", "0", "1"], ["84091.3", "0.23802162", "0", "1"], ["84093", "0.01774536", "0", "1"], ["84230.9", "0", "0", "0"], ["84232", "0", "0", "0"]], "bids": [["84060", "0.57774639", "0", "10"], ["84045.1", "0.01790207", "0", "2"], ["84043.7", "1", "0", "1"], ["84040.1", "0.06171342", "0", "1"], ["84032.6", "0.23802162", "0", "1"], ["84031.9", "0", "0", "0"], ["84029.1", "0.75107698", "0", "3"], ["84029", "1", "0", "1"], ["83982.1", "0.00579984", "0", "1"], ["83922.1", "0", "0", "0"], ["83922", "0", "0", "0"], ["83921.7", "0", "0", "0"]], "ts": "1742555195704", "checksum": 530936096, "seqId": 49927510041, "prevSeqId": 49927510023}], "record_time": 1742555195.704926, "EXCHANGE": "OKX"}
{"arg": {"channel": "books", "instId": "BTC-USDT"}, "action": "update", "data": [{"asks": [["84060.1", "0.35680578", "0", "7"], ["84068.7", "0.01055", "0", "1"], ["84072.6", "0", "0", "0"], ["84073.3", "0.04365525", "0", "2"], ["84073.7", "0.06610383", "0", "2"], ["84073.8", "0", "0", "0"], ["84073.9", "0.03433645", "0", "1"], ["84074", "0.19304", "0", "2"], ["84074.3", "0.03", "0", "1"], ["84074.6", "0.03167", "0", "1"], ["84077.3", "1", "0", "1"], ["84078.6", "0", "0", "0"], ["84078.9", "0", "0", "0"], ["84080.2", "0.032708", "0", "1"], ["84080.3", "0.03344065", "0", "1"], ["84080.6", "0.04", "0", "1"], ["84080.8", "0", "0", "0"], ["84082.5", "0.03276748", "0", "1"], ["84082.7", "0", "0", "0"], ["84082.8", "0.133611", "0", "1"], ["84087.3", "0.06599068", "0", "1"], ["84087.8", "0", "0", "0"], ["84089.1", "0.06470071", "0", "1"], ["84089.4", "0", "0", "0"], ["84089.7", "0.06790525", "0", "1"], ["84090", "0.001", "0", "1"], ["84091.4", "0", "0", "0"], ["84230.7", "0", "0", "0"]], "bids": [["84060", "0.47774639", "0", "9"], ["84059.2", "0.02530935", "0", "1"], ["84055.4", "0.0134", "0", "1"], ["84048.8", "0.17844", "0", "1"], ["84046.5", "0", "0", "0"], ["84046", "0.03411594", "0", "1"], ["84045.9", "0", "0", "0"], ["84045.7", "0.03415507", "0", "1"], ["84045.3", "0", "0", "0"], ["84045", "0.05661346", "0", "2"], ["84044.9", "0", "0", "0"], ["84044.5", "0.03146529", "0", "1"], ["84039.5", "0", "0", "0"], ["84039", "0.03278198", "0", "1"], ["84038.6", "0", "0", "0"], ["84038.2", "0.03435897", "0", "1"], ["84037.2", "0", "0", "0"], ["84036.9", "0.03396677", "0", "1"], ["84036.6", "1.61715455", "0", "1"], ["84036.3", "0.03138315", "0", "1"], ["84032.5", "0", "0", "0"], ["84032", "0.0624466", "0", "1"], ["84029.9", "0", "0", "0"], ["84029.6", "0.15491994", "0", "2"], ["84029.1", "0.689043", "0", "2"], ["84028.8", "0.27157329", "0", "2"], ["84028.4", "0", "0", "0"]], "ts": "1742555195804", "checksum": 2017203725, "seqId": 49927510098, "prevSeqId": 49927510041}], "record_time": 1742555195.814706, "EXCHANGE": "OKX"}
{"arg": {"channel": "books", "instId": "BTC-USDT"}, "action": "update", "data": [{"asks": [["84077.3", "0", "0", "0"], ["84079.5", "1", "0", "1"], ["84082.4", "0.04393897", "0", "3"], ["84091.2", "0.06543302", "0", "1"], ["84091.3", "0", "0", "0"], ["84093", "0.25576736", "0", "2"]], "bids": [["84032.6", "0", "0", "0"], ["84032.1", "0.238022", "0", "1"], ["84029.1", "0.4193538", "0", "1"], ["84029", "0", "0", "0"], ["84028.2", "0.0676255", "0", "1"]], "ts": "1742555195904", "checksum": 2017203725, "seqId": 49927510110, "prevSeqId": 49927510098}], "record_time": 1742555195.905802, "EXCHANGE": "OKX"}
{"arg": {"channel": "books", "instId": "BTC-USDT"}, "action": "update", "data": [{"asks": [["84077.3", "1", "0", "1"], ["84079.5", "0", "0", "0"], ["84091.1", "0.23802131", "0", "1"], ["84093", "0.01774536", "0", "1"], ["84102.4", "0.32982", "0", "3"], ["84103.2", "0.03999999", "0", "1"], ["84104", "0", "0", "0"]], "bids": [["84045", "1.05661346", "0", "3"], ["84043.7", "0", "0", "0"], ["84032.1", "0.23802131", "0", "1"], ["83922.1", "0.00621039", "0", "1"]], "ts": "1742555196004", "checksum": 2017203725, "seqId": 49927510126, "prevSeqId": 49927510110}], "record_time": 1742555196.007789, "EXCHANGE": "OKX"}
{"arg": {"channel": "books", "instId": "BTC-USDT"}, "action": "update", "data": [{"asks": [["84089.6", "0.23802384", "0", "1"], ["84091.1", "0", "0", "0"], ["84102.4", "0.24982", "0", "1"], ["84103.2", "0.07999999", "0", "2"], ["84104", "0.03999999", "0", "1"], ["84230.1", "0", "0", "0"]], "bids": [["84045", "0.05661346", "0", "2"], ["84043.5", "1.04", "0", "2"], ["84032.1", "0", "0", "0"], ["84029.7", "0.23802384", "0", "1"]], "ts": "1742555196104", "checksum": 2017203725, "seqId": 49927510142, "prevSeqId": 49927510126}], "record_time": 1742555196.110774, "EXCHANGE": "OKX"}
{"arg": {"channel": "books", "instId": "BTC-USDT"}, "action": "update", "data": [{"asks": [["84089", "0.23802465", "0", "1"], ["84089.6", "0", "0", "0"]], "bids": [], "ts": "1742555196304", "checksum": 2017203725, "seqId": 49927510152, "prevSeqId": 49927510142}], "record_time": 1742555196.366712, "EXCHANGE": "OKX"}
{"arg": {"channel": "books", "instId": "BTC-USDT"}, "action": "update", "data": [{"asks": [], "bids": [["84060", "0.49559039", "0", "10"], ["84052.9", "0.3568907", "0", "1"], ["84048.5", "0.04021", "0", "1"], ["83922.1", "0", "0", "0"]], "ts": "1742555196404", "checksum": -69313184, "seqId": 49927510158, "prevSeqId": 49927510152}], "record_time": 1742555196.404473, "EXCHANGE": "OKX"}
{"arg": {"channel": "books", "instId": "BTC-USDT"}, "action": "update", "data": [{"asks": [["84060.1", "0.63654131", "0", "11"], ["84065", "0.01055", "0", "1"], ["84065.8", "0.0119021", "0", "1"], ["84068.6", "0.2025", "0", "1"], ["84068.7", "0", "0", "0"], ["84068.9", "0", "0", "0"], ["84072.1", "0.53941956", "0", "1"], ["84073.8", "1", "0", "1"], ["84076.3", "0.55626658", "0", "2"], ["84077.3", "0", "0", "0"], ["84078.2", "0.08991011", "0", "1"], ["84082.7", "0.23803719", "0", "1"], ["84089", "0", "0", "0"], ["84228.5", "0", "0", "0"], ["84228.9", "0", "0", "0"]], "bids": [["84060", "0.23256489", "0", "7"], ["84059.9", "0", "0", "0"], ["84056", "0", "0", "0"], ["84055.4", "0", "0", "0"], ["84051.7", "0.0134", "0", "1"], ["84043.5", "0.04", "0", "1"], ["84042.3", "1", "0", "1"], ["84031.8", "0", "0", "0"], ["84031.6", "0", "0", "0"], ["84029.7", "0", "0", "0"], ["84029.6", "0.06500983", "0", "1"], ["84026.4", "0.08", "0", "2"], ["84025.7", "0.23805219", "0", "2"], ["84016.2", "0.55561096", "0", "1"], ["84000.1", "1.45614473", "0", "2"], ["83922.1", "0.00621039", "0", "1"], ["83922", "0.00001197", "0", "1"], ["83921.7", "0.0535785", "0", "1"]], "ts": "1742555196504", "checksum": -1518354898, "seqId": 49927510222, "prevSeqId": 49927510158}], "record_time": 1742555196.530428, "EXCHANGE": "OKX"}
{"arg": {"channel": "books", "instId": "BTC-USDT"}, "action": "update", "data": [{"asks": [["84063.6", "0", "0", "0"], ["84068.6", "0", "0", "0"], ["84070.2", "0.03167", "0", "1"], ["84074.6", "0", "0", "0"], ["84082.7", "0", "0", "0"], ["84086.5", "0.23803261", "0", "1"], ["84102.4", "0.32982", "0", "3"], ["84103.2", "0.03999999", "0", "1"], ["84104", "0", "0", "0"], ["84115.7", "0.01188839", "0", "1"], ["84116.6", "0.00060645", "0", "1"], ["84199.9", "0.20046812", "0", "9"], ["84200.8", "0", "0", "0"], ["84228.5", "0.00002372", "0", "1"], ["84228.9", "0.00008", "0", "1"], ["84230.1", "0.000548", "0", "2"]], "bids": [["84060", "0.51721382", "0", "8"], ["84049.9", "0.00506895", "0", "2"], ["84027.4", "0.23803261", "0", "1"], ["84025.7", "0.000015", "0", "1"], ["84011.3", "0.01188839", "0", "1"], ["84010.4", "0.01188821", "0", "1"], ["83922", "0", "0", "0"], ["83921.7", "0", "0", "0"]], "ts": "1742555196604", "checksum": -2130831484, "seqId": 49927510271, "prevSeqId": 49927510222}], "record_time": 1742555196.605385, "EXCHANGE": "OKX"}
{"arg": {"channel": "books", "instId": "BTC-USDT"}, "action": "update", "data": [{"asks": [["84063.1", "0.01910392", "0", "1"], ["84065.5", "0.00773256", "0", "1"], ["84102.4", "0.24982", "0", "1"], ["84103.2", "0.07999999", "0", "2"], ["84104", "0.03999999", "0", "1"], ["84228.9", "0", "0", "0"], ["84230.1", "0", "0", "0"]], "bids": [["84060", "0.64989782", "0", "9"], ["84049.9", "0.00060645", "0", "1"]], "ts": "1742555196704", "checksum": 1432890903, "seqId": 49927510287, "prevSeqId": 49927510271}], "record_time": 1742555196.709213, "EXCHANGE": "OKX"}
{"arg": {"channel": "books", "instId": "BTC-USDT"}, "action": "update", "data": [{"asks": [["84060.1", "0.10803504", "0", "5"], ["84061.3", "0", "0", "0"], ["84061.4", "0", "0", "0"], ["84063.4", "0.05088682", "0", "1"], ["84063.5", "0.11901491", "0", "1"], ["84065", "0.00065397", "0", "1"], ["84065.8", "0", "0", "0"], ["84067.9", "0", "0", "0"], ["84069.8", "0.01055", "0", "1"], ["84070.2", "0", "0", "0"], ["84072.1", "0.25920638", "0", "1"], ["84073.3", "0.00906686", "0", "1"], ["84073.7", "0", "0", "0"], ["84073.8", "0", "0", "0"], ["84073.9", "0", "0", "0"], ["84074.5", "0.0326301", "0", "1"], ["84074.6", "0.06264786", "0", "2"], ["84075", "0.03163969", "0", "1"], ["84076.1", "0.03166", "0", "1"], ["84076.3", "0.81013954", "0", "3"], ["84078.2", "0", "0", "0"], ["84078.3", "0", "0", "0"], ["84079.7", "1", "0", "1"], ["84080.2", "0", "0", "0"], ["84080.3", "0", "0", "0"], ["84081.3", "0.03185762", "0", "1"], ["84081.5", "0.03095012", "0", "1"], ["84082.4", "0.01", "0", "2"], ["84082.5", "0", "0", "0"], ["84083.3", "0.17365152", "0", "3"], ["84083.4", "0.03474594", "0", "1"], ["84084", "0.14291634", "0", "1"], ["84086.5", "0", "0", "0"], ["84086.6", "0", "0", "0"], ["84087.3", "0", "0", "0"], ["84088.5", "0.42641462", "0", "2"], ["84089.1", "0", "0", "0"], ["84089.7", "0.23802336", "0", "1"], ["84090", "0.06823352", "0", "2"], ["84090.7", "0.06608848", "0", "1"], ["84091.2", "0", "0", "0"], ["84092.1", "0.06642726", "0", "1"], ["84114.3", "0.18608224", "0", "1"], ["84116", "0", "0", "0"], ["84228.9", "0.00008", "0", "1"], ["84230.1", "0.000548", "0", "2"], ["84230.7", "0.2025", "0", "1"], ["84230.9", "0.35582144", "0", "2"], ["84232", "0.00172464", "0", "3"], ["84232.3", "0.29700048", "0", "2"], ["84232.6", "0.00001501", "0", "1"], ["84232.9", "0.08747", "0", "1"]], "bids": [["84060", "0.74841743", "0", "10"], ["84059.9", "0.05287746", "0", "1"], ["84056.5", "0.0134", "0", "1"], ["84051.7", "0", "0", "0"], ["84051.1", "0.000015", "0", "1"], ["84049.5", "0.62220659", "0", "2"], ["84047.2", "0.16579917", "0", "2"], ["84046.9", "1", "0", "1"], ["84046.6", "0.03120081", "0", "2"], ["84046.2", "0.44920868", "0", "2"], ["84046", "0", "0", "0"], ["84045.9", "0.03318575", "0", "1"], ["84045.7", "0", "0", "0"], ["84045.6", "0.03443703", "0", "1"], ["84045", "0.02380344", "0", "1"], ["84044.5", "0", "0", "0"], ["84042.3", "0", "0", "0"], ["84040.2", "0.03419605", "0", "1"], ["84039.3", "0.28335392", "0", "2"], ["84039", "0", "0", "0"], ["84038.2", "0", "0", "0"], ["84037.8", "0.03122425", "0", "1"], ["84037.2", "0.03444744", "0", "1"], ["84036.9", "0", "0", "0"], ["84036.3", "0", "0", "0"], ["84033.2", "0.12152069", "0", "2"], ["84032", "0", "0", "0"], ["84031.6", "0.23802336", "0", "1"], ["84030.5", "0.0688157", "0", "1"], ["84029.8", "0.06915836", "0", "1"], ["84029.6", "0", "0", "0"], ["84029.1", "0.48292507", "0", "2"], ["84028.8", "0.2025", "0", "1"], ["84028.2", "0", "0", "0"], ["84027.4", "0", "0", "0"], ["84026.4", "0.0903941", "0", "3"], ["83922", "0.00001197", "0", "1"]], "ts": "1742555196804", "checksum": -1690468446, "seqId": 49927510463, "prevSeqId": 49927510287}], "record_time": 1742555196.863722, "EXCHANGE": "OKX"}
{"arg": {"channel": "books", "instId": "BTC-USDT"}, "action": "update", "data": [{"asks": [["84060.1", "0.10800995", "0", "5"], ["84069.8", "0", "0", "0"], ["84076.3", "0.44112318", "0", "2"], ["84079.7", "0.35641581", "0", "1"], ["84079.8", "0.57266372", "0", "2"], ["84081.7", "1.11898911", "0", "2"], ["84093", "0", "0", "0"], ["84101", "0", "0", "0"], ["84102", "0.052", "0", "2"], ["84138.8", "0.01774536", "0", "1"], ["84233", "0.06012728", "0", "2"], ["84233.3", "0.00101534", "0", "2"]], "bids": [["84060", "0.94841743", "0", "11"], ["84053.3", "0.04021", "0", "1"], ["84048.5", "0", "0", "0"], ["84038", "0.01774536", "0", "1"], ["84037.4", "0", "0", "0"], ["84030", "1.00001196", "0", "2"], ["84026.4", "0.0103941", "0", "1"], ["84025.6", "0.106", "0", "4"], ["84024.8", "0.58210201", "0", "3"], ["84022.4", "0", "0", "0"], ["84021.6", "0.1", "0", "2"], ["84020.8", "0.05", "0", "1"]], "ts": "1742555196904", "checksum": -1208804984, "seqId": 49927510494, "prevSeqId": 49927510463}], "record_time": 1742555196.905159, "EXCHANGE": "OKX"}
{"arg": {"channel": "books", "instId": "BTC-USDT"}, "action": "update", "data": [{"asks": [["84065", "0", "0", "0"], ["84065.5", "0.00838778", "0", "2"], ["84073.2", "0.01055", "0", "1"], ["84074.5", "0", "0", "0"], ["84074.6", "0.0975513", "0", "3"], ["84081.5", "0", "0", "0"], ["84081.6", "0.03345275", "0", "1"], ["84086.6", "1.550972", "0", "1"], ["84088.5", "0.35641581", "0", "1"], ["84088.6", "0.06775071", "0", "1"], ["84089.7", "0", "0", "0"], ["84090.6", "0.23801976", "0", "1"], ["84114.3", "1.02943348", "0", "2"], ["84116", "2.84519293", "0", "1"], ["84233", "0", "0", "0"], ["84233.3", "0", "0", "0"]], "bids": [["84059.9", "0.06627746", "0", "2"], ["84056.5", "0", "0", "0"], ["84047.3", "0.21175802", "0", "5"], ["84047.2", "0.133608", "0", "1"], ["84040.3", "0.03404157", "0", "1"], ["84040.2", "0", "0", "0"], ["84033.3", "0.06612411", "0", "3"], ["84033.2", "0.05944451", "0", "1"], ["84031.6", "0.23801976", "0", "1"], ["83921.7", "0.0535785", "0", "1"]], "ts": "1742555197004", "checksum": -1794836776, "seqId": 49927510525, "prevSeqId": 49927510494}], "record_time": 1742555197.065991, "EXCHANGE": "OKX"}
{"arg": {"channel": "books", "instId": "BTC-USDT"}, "action": "update", "data": [{"asks": [["84063.1", "0", "0", "0"], ["84074.6", "0.03085097", "0", "1"], ["84074.7", "0.4195578", "0", "3"], ["84077.8", "0.17824122", "0", "2"], ["84081.6", "0", "0", "0"], ["84081.7", "1.14979229", "0", "3"], ["84088.6", "0", "0", "0"], ["84088.7", "0.1863312", "0", "2"], ["84090", "0.001", "0", "1"], ["84090.1", "0.06776235", "0", "1"], ["84090.6", "0", "0", "0"], ["84092", "0.23801711", "0", "1"], ["84233", "0.06012728", "0", "2"], ["84233.3", "0.00101534", "0", "2"]], "bids": [["84048.8", "0", "0", "0"], ["84047.4", "0.0321413", "0", "1"], ["84047.3", "0.18", "0", "4"], ["84046", "0.03334226", "0", "1"], ["84045.9", "0", "0", "0"], ["84040.4", "0.0319482", "0", "1"], ["84040.3", "0", "0", "0"], ["84033.8", "0.24222705", "0", "2"], ["84033.4", "0.07009878", "0", "1"], ["84033.3", "0.00101534", "0", "2"], ["84031.6", "0", "0", "0"], ["84030.6", "0.0694689", "0", "1"], ["84030.5", "0", "0", "0"]], "ts": "1742555197104", "checksum": -96343595, "seqId": 49927510565, "prevSeqId": 49927510525}], "record_time": 1742555197.114637, "EXCHANGE": "OKX"}
{"arg": {"channel": "books", "instId": "BTC-USDT"}, "action": "update", "data": [{"asks": [["84060.1", "0.09167301", "0", "4"], ["84063.4", "0.06605128", "0", "2"], ["84074.6", "0", "0", "0"], ["84074.7", "0.38847766", "0", "2"], ["84074.8", "0.06939715", "0", "2"], ["84075", "0", "0", "0"], ["84075.1", "0.03243622", "0", "1"], ["84080.4", "1.00001197", "0", "2"], ["84081.3", "0", "0", "0"], ["84081.4", "0.2832926", "0", "3"], ["84081.7", "0.11898911", "0", "1"], ["84081.8", "0.03493526", "0", "1"], ["84083.3", "0.14104411", "0", "2"], ["84083.4", "0.03456523", "0", "1"], ["84083.5", "0.0328627", "0", "1"], ["84088.7", "0.11890903", "0", "1"], ["84088.8", "0.0684759", "0", "1"], ["84090.1", "0", "0", "0"], ["84090.2", "0.06649376", "0", "1"], ["84090.6", "0.23801876", "0", "1"], ["84090.7", "0", "0", "0"], ["84090.8", "0.06643211", "0", "1"], ["84092", "0", "0", "0"], ["84092.1", "0", "0", "0"], ["84092.2", "0.06448078", "0", "1"], ["84093", "0.01774536", "0", "1"], ["84116", "0", "0", "0"], ["84138.8", "0", "0", "0"], ["84233.3", "0", "0", "0"]], "bids": [["84060", "0.95445743", "0", "12"], ["84051.1", "0", "0", "0"], ["84049.5", "0.34499684", "0", "1"], ["84047.5", "0.03270213", "0", "1"], ["84047.4", "0", "0", "0"], ["84046.9", "0", "0", "0"], ["84046.7", "0.03318662", "0", "1"], ["84046.6", "0.00009543", "0", "1"], ["84046.2", "0.68867278", "0", "3"], ["84046.1", "0.03101316", "0", "2"], ["84046", "0", "0", "0"], ["84045.7", "0.03119777", "0", "1"], ["84045.6", "0", "0", "0"], ["84045.5", "1", "0", "1"], ["84040.5", "0.03375346", "0", "1"], ["84040.4", "0", "0", "0"], ["84039.4", "0.03265005", "0", "1"], ["84039.3", "0.24982", "0", "1"], ["84037.9", "0.22145243", "0", "2"], ["84037.8", "0", "0", "0"], ["84037.3", "0.23467249", "0", "2"], ["84037.2", "0", "0", "0"], ["84033.8", "0.00420994", "0", "1"], ["84033.5", "0.06618869", "0", "1"], ["84033.4", "0", "0", "0"], ["84031.6", "0.23801876", "0", "1"], ["84030.7", "0.06476198", "0", "1"], ["84030.6", "0", "0", "0"], ["84029.9", "0.0620029", "0", "1"], ["84029.8", "0", "0", "0"], ["84029.2", "0.06543475", "0", "1"], ["84029.1", "0.4193538", "0", "1"]], "ts": "1742555197204", "checksum": -205319890, "seqId": 49927510634, "prevSeqId": 49927510565}], "record_time": 1742555197.207915, "EXCHANGE": "OKX"}
