{"arg": {"channel": "books", "instId": "BTC-USDT"}, "action": "update", "data": [{"asks": [["83964.1", "1.07757783", "0", "16"]], "bids": [], "ts": "1742576919700", "checksum": 1545204515, "seqId": 49944904511, "prevSeqId": 49944904507}], "record_time": 1742576919.873648, "EXCHANGE": "OKX"}
{"arg": {"channel": "books", "instId": "BTC-USDT"}, "action": "update", "data": [{"asks": [["83994", "1", "0", "1"], ["84133.5", "0", "0", "0"]], "bids": [["83964", "0.2117106", "0", "3"], ["83963.1", "0", "0", "0"], ["83963", "0.0605", "0", "1"]], "ts": "1742576919800", "checksum": -94751629, "seqId": 49944904522, "prevSeqId": 49944904511}], "record_time": 1742576919.973511, "EXCHANGE": "OKX"}
{"arg": {"channel": "books", "instId": "BTC-USDT"}, "action": "update", "data": [{"asks": [], "bids": [["83964", "0.1263657", "0", "2"], ["83950.6", "0", "0", "0"], ["83925.6", "0.026", "0", "2"], ["83924.8", "0.013", "0", "1"], ["83909.6", "0", "0", "0"], ["83908.8", "0", "0", "0"], ["83817.4", "0.2025", "0", "1"]], "ts": "1742576919900", "checksum": 493472311, "seqId": 49944904537, "prevSeqId": 49944904522}], "record_time": 1742576920.07361, "EXCHANGE": "OKX"}
{"arg": {"channel": "books", "instId": "BTC-USDT"}, "action": "update", "data": [{"asks": [["84032.4", "0.01130976", "0", "1"], ["84032.6", "0.000015", "0", "1"], ["84040.4", "0", "0", "0"], ["84040.5", "0.00197262", "0", "1"], ["84103.7", "0.1130976", "0", "1"], ["84106.9", "0", "0", "0"], ["84133.3", "0", "0", "0"]], "bids": [["83964", "0.2160657", "0", "4"], ["83936", "1.00018", "0", "2"], ["83931.3", "0.23832918", "0", "1"], ["83924", "0", "0", "0"], ["83920.7", "0.01190621", "0", "1"], ["83897", "0", "0", "0"], ["83896.9", "0.0010067", "0", "1"], ["83895.7", "0.00145249", "0", "1"], ["83895.5", "0", "0", "0"]], "ts": "1742576920100", "checksum": -1281364286, "seqId": 49944904566, "prevSeqId": 49944904537}], "record_time": 1742576920.27505, "EXCHANGE": "OKX"}
{"arg": {"channel": "books", "instId": "BTC-USDT"}, "action": "update", "data": [{"asks": [["83964.1", "1.07936483", "0", "17"], ["83993", "0.35780328", "0", "2"], ["84039.4", "0", "0", "0"], ["84039.5", "0", "0", "0"], ["84040.4", "0.00152682", "0", "1"], ["84133.3", "0.00517228", "0", "9"]], "bids": [["83964", "0.2129657", "0", "3"], ["83936.5", "0.55500027", "0", "2"], ["83931.3", "0.23832822", "0", "1"], ["83895.8", "0.00218657", "0", "1"], ["83895.6", "0", "0", "0"], ["83868.4", "0.00595708", "0", "1"]], "ts": "1742576920200", "checksum": -502838609, "seqId": 49944904581, "prevSeqId": 49944904566}], "record_time": 1742576920.374342, "EXCHANGE": "OKX"}
{"arg": {"channel": "books", "instId": "BTC-USDT"}, "action": "update", "data": [{"asks": [["83964.1", "1.07908345", "0", "17"]], "bids": [["83964", "0.2189206", "0", "4"], ["83958.8", "0.39150008", "0", "2"], ["83958.7", "1", "0", "1"], ["83957.9", "0.13241298", "0", "1"], ["83957.4", "0", "0", "0"]], "ts": "1742576920300", "checksum": -2077885233, "seqId": 49944904588, "prevSeqId": 49944904581}], "record_time": 1742576920.473786, "EXCHANGE": "OKX"}
{"arg": {"channel": "books", "instId": "BTC-USDT"}, "action": "update", "data": [{"asks": [["83988.5", "0", "0", "0"], ["83989.1", "0", "0", "0"], ["84021.4", "0.18691857", "0", "1"], ["84022.7", "0", "0", "0"], ["84133.5", "0.00001277", "0", "1"], ["84134.5", "0.0000103", "0", "1"], ["84134.6", "0.00003392", "0", "1"]], "bids": [["83964", "0.2189306", "0", "5"], ["83932.4", "0.21275926", "0", "1"], ["83931.3", "0.23832851", "0", "1"], ["83930.4", "0.00357", "0", "1"], ["83898.7", "0.35853614", "0", "1"], ["83896.8", "0", "0", "0"], ["83859.8", "0.20185452", "0", "1"]], "ts": "1742576920400", "checksum": 1871000783, "seqId": 49944904604, "prevSeqId": 49944904588}], "record_time": 1742576920.574297, "EXCHANGE": "OKX"}
{"arg": {"channel": "books", "instId": "BTC-USDT"}, "action": "update", "data": [{"asks": [["83964.1", "1.08247239", "0", "18"], ["83965.9", "0", "0", "0"], ["83988.1", "0", "0", "0"], ["83988.9", "1.7227094", "0", "1"], ["84040.3", "0.00197262", "0", "1"], ["84040.5", "0", "0", "0"], ["84061.8", "0.01774536", "0", "1"]], "bids": [["83964", "0.1263757", "0", "3"], ["83958.8", "0.09150008", "0", "1"], ["83958.7", "0", "0", "0"], ["83957.9", "0.41167036", "0", "2"], ["83957.4", "1", "0", "1"], ["83937", "0.1129966", "0", "3"], ["83931.3", "0", "0", "0"], ["83930.7", "1.71623749", "0", "1"], ["83928.8", "0.23833042", "0", "1"], ["83928", "0.08", "0", "2"], ["83927.2", "0.0408", "0", "3"], ["83926.4", "0.00039983", "0", "1"], ["83897.1", "3.01411766", "0", "1"], ["83896.9", "0", "0", "0"], ["83895.9", "0.0010067", "0", "1"], ["83818.1", "0", "0", "0"], ["83818", "0", "0", "0"], ["83817.4", "0", "0", "0"]], "ts": "1742576920500", "checksum": 646038836, "seqId": 49944904633, "prevSeqId": 49944904604}], "record_time": 1742576920.679124, "EXCHANGE": "OKX"}
{"arg": {"channel": "books", "instId": "BTC-USDT"}, "action": "update", "data": [{"asks": [["83988.2", "0.23832853", "0", "1"], ["84021.4", "1.09051723", "0", "2"], ["84022.6", "3.0881347", "0", "1"], ["84134.6", "0", "0", "0"]], "bids": [["83931.3", "0.23832853", "0", "1"], ["83928.8", "0", "0", "0"], ["83897.2", "0.0010187", "0", "2"], ["83895.9", "0", "0", "0"], ["83818.1", "0.00006813", "0", "3"]], "ts": "1742576920600", "checksum": 646038836, "seqId": 49944904647, "prevSeqId": 49944904633}], "record_time": 1742576920.786115, "EXCHANGE": "OKX"}
{"arg": {"channel": "books", "instId": "BTC-USDT"}, "action": "update", "data": [{"asks": [["83964.1", "1.07908345", "0", "17"], ["83964.4", "0.00339031", "0", "1"], ["83988.1", "0.01774536", "0", "1"], ["84003", "0", "0", "0"], ["84061.8", "0", "0", "0"]], "bids": [["83964", "0.2129757", "0", "4"], ["83957.4", "0", "0", "0"], ["83957.3", "1.00774136", "0", "2"], ["83950.5", "0.00351177", "0", "1"]], "ts": "1742576920700", "checksum": 645312498, "seqId": 49944904664, "prevSeqId": 49944904647}], "record_time": 1742576920.873547, "EXCHANGE": "OKX"}
{"arg": {"channel": "books", "instId": "BTC-USDT"}, "action": "update", "data": [{"asks": [], "bids": [["83964", "0.21893062", "0", "5"], ["83958.9", "1", "0", "1"], ["83957.9", "0.13241298", "0", "1"], ["83957.3", "0.00774136", "0", "1"], ["83818.1", "0", "0", "0"]], "ts": "1742576920800", "checksum": 76974813, "seqId": 49944904670, "prevSeqId": 49944904664}], "record_time": 1742576920.973894, "EXCHANGE": "OKX"}
{"arg": {"channel": "books", "instId": "BTC-USDT"}, "action": "update", "data": [{"asks": [["84002.3", "0.11889794", "0", "1"]], "bids": [["83964", "0.23686062", "0", "6"], ["83931.3", "0.23833002", "0", "1"], ["83928", "0", "0", "0"], ["83927.2", "0.0808", "0", "4"], ["83926.4", "0.04039983", "0", "2"], ["83818.1", "0.00006813", "0", "3"]], "ts": "1742576920900", "checksum": 371157989, "seqId": 49944904691, "prevSeqId": 49944904670}], "record_time": 1742576921.073304, "EXCHANGE": "OKX"}
{"arg": {"channel": "books", "instId": "BTC-USDT"}, "action": "update", "data": [{"asks": [], "bids": [["83964", "0.2309057", "0", "5"], ["83958.9", "0", "0", "0"], ["83957.9", "0.41167036", "0", "2"], ["83957.5", "1", "0", "1"]], "ts": "1742576921000", "checksum": 797316166, "seqId": 49944904705, "prevSeqId": 49944904691}], "record_time": 1742576921.173371, "EXCHANGE": "OKX"}
{"arg": {"channel": "books", "instId": "BTC-USDT"}, "action": "update", "data": [{"asks": [["83973.4", "0", "0", "0"], ["83983.5", "0.33223924", "0", "1"], ["84134.6", "0.00003392", "0", "1"]], "bids": [["83946.1", "0", "0", "0"], ["83936.1", "0", "0", "0"], ["83935", "0", "0", "0"], ["83928", "0.08", "0", "2"], ["83927.2", "0.0408", "0", "3"], ["83926.4", "0.00039983", "0", "1"], ["83925", "0", "0", "0"], ["83922.4", "0.1", "0", "2"], ["83921.6", "0.30011", "0", "2"], ["83920.8", "0", "0", "0"], ["83818", "0.00001199", "0", "1"], ["83817.4", "0.2025", "0", "1"], ["83817.1", "0.00001501", "0", "1"]], "ts": "1742576921100", "checksum": 1952966652, "seqId": 49944904726, "prevSeqId": 49944904705}], "record_time": 1742576921.273578, "EXCHANGE": "OKX"}
{"arg": {"channel": "books", "instId": "BTC-USDT"}, "action": "update", "data": [{"asks": [["83964.4", "0", "0", "0"], ["83965.9", "0.00339002", "0", "1"], ["83988.5", "0.74886645", "0", "1"], ["84134.6", "0", "0", "0"]], "bids": [["83932.4", "0.77253461", "0", "2"], ["83931.3", "0.23832835", "0", "1"], ["83922.4", "0", "0", "0"], ["83921.6", "0.35011", "0", "3"], ["83920.8", "0.05", "0", "1"], ["83898.7", "1.19777158", "0", "2"], ["83859.8", "0", "0", "0"], ["83834.1", "0", "0", "0"], ["83816.9", "0.00126817", "0", "1"], ["83816.6", "0.00060645", "0", "1"]], "ts": "1742576921200", "checksum": -1466618012, "seqId": 49944904749, "prevSeqId": 49944904726}], "record_time": 1742576921.372586, "EXCHANGE": "OKX"}
{"arg": {"channel": "books", "instId": "BTC-USDT"}, "action": "update", "data": [{"asks": [["83983.5", "0.33423924", "0", "2"], ["83993.6", "0.002", "0", "1"], ["84134.5", "0", "0", "0"]], "bids": [["83962.1", "0.002", "0", "1"], ["83952.1", "0.002", "0", "1"], ["83931.3", "0.23832845", "0", "1"], ["83816.9", "0", "0", "0"], ["83816.6", "0", "0", "0"]], "ts": "1742576921300", "checksum": 1885315898, "seqId": 49944904761, "prevSeqId": 49944904749}], "record_time": 1742576921.473917, "EXCHANGE": "OKX"}
{"arg": {"channel": "books", "instId": "BTC-USDT"}, "action": "update", "data": [{"asks": [["83985.7", "0.00909134", "0", "1"], ["84133.5", "0", "0", "0"]], "bids": [["83964", "0.23097486", "0", "6"], ["83931.3", "0.23832872", "0", "1"]], "ts": "1742576921400", "checksum": 1767579393, "seqId": 49944904773, "prevSeqId": 49944904761}], "record_time": 1742576921.573408, "EXCHANGE": "OKX"}
{"arg": {"channel": "books", "instId": "BTC-USDT"}, "action": "update", "data": [{"asks": [], "bids": [["83936", "1.20018", "0", "3"]], "ts": "1742576921500", "checksum": 1767579393, "seqId": 49944904778, "prevSeqId": 49944904773}], "record_time": 1742576921.674367, "EXCHANGE": "OKX"}
{"arg": {"channel": "books", "instId": "BTC-USDT"}, "action": "update", "data": [{"asks": [["83964.5", "0.22625672", "0", "10"], ["84045.1", "0.07139025", "0", "1"]], "bids": [["83962", "0.0439", "0", "1"], ["83959.5", "1", "0", "1"], ["83957.5", "0", "0", "0"], ["83880.4", "0.0715304", "0", "1"], ["83817.1", "0", "0", "0"]], "ts": "1742576921600", "checksum": 1986211605, "seqId": 49944904790, "prevSeqId": 49944904778}], "record_time": 1742576921.773472, "EXCHANGE": "OKX"}
{"arg": {"channel": "books", "instId": "BTC-USDT"}, "action": "update", "data": [{"asks": [["83964.1", "1.06121745", "0", "16"], ["83964.3", "0.08212599", "0", "1"], ["84003", "0.2", "0", "1"], ["84133.3", "0", "0", "0"]], "bids": [["83957.9", "0.13241298", "0", "1"], ["83923.6", "0.471837", "0", "1"], ["83898.5", "0.00595606", "0", "1"], ["83817.4", "0", "0", "0"]], "ts": "1742576921700", "checksum": 1525727463, "seqId": 49944904823, "prevSeqId": 49944904790}], "record_time": 1742576921.87368, "EXCHANGE": "OKX"}
{"arg": {"channel": "books", "instId": "BTC-USDT"}, "action": "update", "data": [{"asks": [["83964.1", "0.61438889", "0", "10"], ["83964.2", "0", "0", "0"], ["83964.3", "0", "0", "0"], ["83964.5", "0.01360672", "0", "8"], ["83965.9", "0", "0", "0"], ["83967.8", "0.00339306", "0", "1"], ["83971", "0", "0", "0"], ["83972", "0.05404", "0", "2"], ["83973.2", "0.01191493", "0", "1"], ["83978.3", "0.03544", "0", "2"], ["83983.4", "0", "0", "0"], ["83984.3", "0.01190699", "0", "1"], ["83988.2", "0", "0", "0"], ["83991.2", "0.23832953", "0", "2"], ["83994", "0", "0", "0"], ["83995.2", "0", "0", "0"], ["83996", "0.0008", "0", "2"], ["83996.8", "0.0004", "0", "1"], ["84003.2", "0", "0", "0"], ["84004", "0.07999999", "0", "2"], ["84004.8", "0.03999999", "0", "1"], ["84011.7", "0", "0", "0"], ["84014.3", "0", "0", "0"], ["84045.1", "0.1427805", "0", "2"], ["84133.3", "0.00517228", "0", "9"], ["84133.5", "0.00001277", "0", "1"], ["84134.5", "0.0000103", "0", "1"], ["84134.6", "0.00003392", "0", "1"], ["84135", "0.00001199", "0", "1"], ["84135.7", "0.0000221", "0", "1"], ["84135.8", "0.00007302", "0", "1"]], "bids": [["83964", "1.03868202", "0", "11"], ["83959.6", "0.32745002", "0", "1"], ["83958.5", "0.01397", "0", "1"], ["83952.2", "0.04193", "0", "1"], ["83950", "0.0439", "0", "1"], ["83944.9", "0", "0", "0"], ["83936", "1.00018", "0", "2"], ["83935.3", "0.23831754", "0", "1"], ["83932.5", "0.11889794", "0", "1"], ["83931.3", "0", "0", "0"], ["83881.4", "0", "0", "0"], ["83880.4", "0.1430608", "0", "2"], ["83818.1", "0", "0", "0"], ["83818", "0", "0", "0"]], "ts": "1742576921800", "checksum": 1953770804, "seqId": 49944904892, "prevSeqId": 49944904823}], "record_time": 1742576921.974163, "EXCHANGE": "OKX"}
{"arg": {"channel": "books", "instId": "BTC-USDT"}, "action": "update", "data": [{"asks": [["83964.1", "0.8725331", "0", "6"], ["83967.8", "0", "0", "0"], ["83967.9", "0", "0", "0"], ["83968.3", "0", "0", "0"], ["83969.9", "0.00338559", "0", "1"], ["83970.6", "0.0772844", "0", "1"], ["83970.8", "0.00774136", "0", "1"], ["83970.9", "0.01191616", "0", "1"], ["83971.3", "0.04084853", "0", "1"], ["83971.7", "0", "0", "0"], ["83972", "0.0439", "0", "1"], ["83972.1", "0", "0", "0"], ["83973.2", "0.13105784", "0", "2"], ["83973.9", "0", "0", "0"], ["83974.5", "0", "0", "0"], ["83974.7", "0.000357", "0", "1"], ["83975.1", "0.05226004", "0", "2"], ["83977.2", "0.04293364", "0", "1"], ["83979.4", "0.18386829", "0", "2"], ["83979.5", "0", "0", "0"], ["83979.9", "0.04", "0", "1"], ["83982.5", "0", "0", "0"], ["83982.9", "0", "0", "0"], ["83983.5", "0.23336958", "0", "2"], ["83983.7", "0", "0", "0"], ["83984.3", "0", "0", "0"], ["83984.8", "0.01190692", "0", "1"], ["83988.1", "0", "0", "0"], ["83988.2", "0.01774536", "0", "1"], ["83988.5", "0.2050806", "0", "1"], ["83988.9", "0", "0", "0"], ["83990.6", "0.0119211", "0", "2"], ["83991.2", "0.23832485", "0", "2"], ["83993", "0.05359983", "0", "1"], ["83994.1", "0", "0", "0"], ["83996", "0", "0", "0"], ["83996.8", "0", "0", "0"], ["83997.2", "0.05959609", "0", "1"], ["83999.2", "0.0008", "0", "2"], ["84000", "0.18813756", "0", "5"], ["84004", "0", "0", "0"], ["84004.8", "0", "0", "0"], ["84007.2", "0.07999999", "0", "2"], ["84008", "0.03999999", "0", "1"], ["84014.7", "0.000715", "0", "1"], ["84021.4", "0.18691857", "0", "1"], ["84022.6", "0", "0", "0"], ["84136", "0.3565323", "0", "1"], ["84136.7", "0.00004748", "0", "1"], ["84137.1", "0.00001501", "0", "1"], ["84137.2", "3.88291", "0", "1"], ["84137.7", "0.5999", "0", "1"], ["84138.8", "0.06044981", "0", "3"], ["84140", "0.00031221", "0", "2"]], "bids": [["83964", "1.97245694", "0", "13"], ["83961.4", "0.05769412", "0", "1"], ["83959.8", "0.01191616", "0", "1"], ["83959.6", "0", "0", "0"], ["83959.5", "0", "0", "0"], ["83959.4", "0.04293364", "0", "1"], ["83956.6", "0.00001199", "0", "1"], ["83955.7", "0", "0", "0"], ["83944.3", "0.31524298", "0", "2"], ["83944", "0.08991011", "0", "1"], ["83939.6", "0", "0", "0"], ["83938.3", "0.23831286", "0", "1"], ["83935.3", "0", "0", "0"], ["83928", "0", "0", "0"], ["83927.2", "0", "0", "0"], ["83926.4", "0", "0", "0"], ["83925.6", "0.08079983", "0", "4"], ["83924.8", "0.04039984", "0", "2"], ["83924", "0.013", "0", "1"], ["83921.6", "0.25011", "0", "1"], ["83920.8", "0", "0", "0"], ["83920", "0.10037", "0", "4"], ["83919.2", "0.05", "0", "1"], ["83915.8", "0.02635121", "0", "1"], ["83914.9", "0.0249433", "0", "1"], ["83873.5", "0.04741289", "0", "1"], ["83818.9", "0", "0", "0"]], "ts": "1742576921900", "checksum": 577565247, "seqId": 49944905076, "prevSeqId": 49944904892}], "record_time": 1742576922.073463, "EXCHANGE": "OKX"}
{"arg": {"channel": "books", "instId": "BTC-USDT"}, "action": "update", "data": [{"asks": [["83964.1", "0.8885331", "0", "7"], ["83964.4", "0.01731399", "0", "1"], ["83967.8", "0.00338843", "0", "1"], ["83967.9", "0.04224936", "0", "1"], ["83969", "0.01014", "0", "1"], ["83969.9", "0", "0", "0"], ["83974.7", "0", "0", "0"], ["83979.2", "0.11889794", "0", "1"], ["83979.3", "0.23898725", "0", "3"], ["83979.4", "0.36778989", "0", "2"], ["83979.5", "0.3573", "0", "1"], ["83982.9", "0.3565323", "0", "1"], ["83988.2", "0.25606365", "0", "2"], ["83989.9", "1.69542117", "0", "1"], ["83991.2", "0.00001199", "0", "1"], ["84003", "0", "0", "0"], ["84023.6", "3.04707515", "0", "1"], ["84136.7", "0", "0", "0"], ["84137.1", "0", "0", "0"], ["84137.2", "0", "0", "0"], ["84137.7", "0", "0", "0"], ["84138.8", "0", "0", "0"], ["84140", "0", "0", "0"]], "bids": [["83964", "0.5657355", "0", "9"], ["83962.2", "0.37503896", "0", "1"], ["83962.1", "1.002", "0", "2"], ["83961.4", "0", "0", "0"], ["83958.5", "0", "0", "0"], ["83955.6", "0.01397", "0", "1"], ["83941.7", "0.3573", "0", "1"], ["83939.2", "0", "0", "0"], ["83938.3", "0", "0", "0"], ["83936.5", "0.29142888", "0", "1"], ["83936", "0.00018", "0", "1"], ["83935.6", "0.23831829", "0", "1"]], "ts": "1742576922000", "checksum": 537213076, "seqId": 49944905118, "prevSeqId": 49944905076}], "record_time": 1742576922.174787, "EXCHANGE": "OKX"}
{"arg": {"channel": "books", "instId": "BTC-USDT"}, "action": "update", "data": [{"asks": [["83964.1", "0.9888931", "0", "8"], ["83964.3", "0.00339352", "0", "1"], ["83967.8", "0", "0", "0"], ["83970.6", "0.18955886", "0", "2"], ["83970.9", "0.13106234", "0", "2"], ["83973.2", "0.01191493", "0", "1"], ["83973.6", "0.03044", "0", "1"], ["83974.3", "0.3565323", "0", "1"], ["83978.3", "0.005", "0", "1"], ["83979.9", "0.21865", "0", "2"], ["83988.2", "0.23831829", "0", "1"], ["84040.2", "0.0015268", "0", "1"], ["84040.4", "0", "0", "0"], ["84061.8", "0.01774536", "0", "1"], ["84135.7", "0", "0", "0"], ["84135.8", "0", "0", "0"], ["84136", "0", "0", "0"]], "bids": [["83964", "0.02521916", "0", "4"], ["83962.2", "0", "0", "0"], ["83962.1", "0.002", "0", "1"], ["83962", "0", "0", "0"], ["83961.6", "0.11915912", "0", "1"], ["83958", "0.41595792", "0", "1"], ["83957.9", "0", "0", "0"], ["83956.4", "1", "0", "1"], ["83955.6", "0", "0", "0"], ["83952.2", "0", "0", "0"], ["83947.5", "0.33355385", "0", "4"], ["83944", "0", "0", "0"], ["83942.1", "0.17865", "0", "1"], ["83935.6", "0", "0", "0"], ["83932.6", "0.23832726", "0", "1"], ["83915.8", "0", "0", "0"], ["83914.9", "0", "0", "0"], ["83895.9", "0.00145248", "0", "1"], ["83895.7", "0", "0", "0"], ["83818.9", "0.00006774", "0", "2"], ["83818.1", "0.00006813", "0", "3"], ["83818", "0.00001199", "0", "1"], ["83817.4", "0.2025", "0", "1"]], "ts": "1742576922100", "checksum": -578340071, "seqId": 49944905183, "prevSeqId": 49944905118}], "record_time": 1742576922.274426, "EXCHANGE": "OKX"}
{"arg": {"channel": "books", "instId": "BTC-USDT"}, "action": "update", "data": [{"asks": [["83964.1", "1.03994753", "0", "11"], ["83964.3", "0.00339346", "0", "1"], ["83969", "0", "0", "0"], ["83971.3", "0", "0", "0"], ["83973.3", "0.04293364", "0", "1"], ["83975.1", "0.03456909", "0", "1"], ["83977.2", "0", "0", "0"], ["83979.2", "0.64999664", "0", "2"], ["83979.4", "0.03", "0", "1"], ["83983.5", "0.002", "0", "1"], ["83984", "0", "0", "0"], ["83988.5", "0.68807187", "0", "2"], ["84021.4", "1.07819936", "0", "2"], ["84040.3", "0", "0", "0"], ["84040.5", "0.00197261", "0", "1"], ["84135.7", "0.0000221", "0", "1"], ["84135.8", "0.00007302", "0", "1"], ["84136", "0.3565323", "0", "1"]], "bids": [["83964", "0.11181916", "0", "5"], ["83949.4", "0.01397", "0", "1"], ["83947.5", "0.29162385", "0", "3"], ["83939.2", "0.3573", "0", "1"], ["83932.6", "0", "0", "0"], ["83931.3", "0.23832871", "0", "1"], ["83923.7", "0.51414971", "0", "2"], ["83923.4", "0", "0", "0"], ["83817.4", "0", "0", "0"]], "ts": "1742576922200", "checksum": 1673861489, "seqId": 49944905218, "prevSeqId": 49944905183}], "record_time": 1742576922.374214, "EXCHANGE": "OKX"}
{"arg": {"channel": "books", "instId": "BTC-USDT"}, "action": "update", "data": [{"asks": [["83969.2", "0.03044", "0", "1"], ["83969.9", "0.010386", "0", "1"], ["83973.6", "0", "0", "0"], ["83988.2", "0.23832636", "0", "1"], ["84136", "0", "0", "0"]], "bids": [["83964", "0.02521916", "0", "4"], ["83943.7", "0.04193", "0", "1"], ["83939.6", "0.17865", "0", "1"], ["83932.6", "0.23832636", "0", "1"], ["83931.3", "0", "0", "0"], ["83818.1", "0", "0", "0"], ["83818", "0", "0", "0"]], "ts": "1742576922300", "checksum": 1671395730, "seqId": 49944905239, "prevSeqId": 49944905218}], "record_time": 1742576922.473426, "EXCHANGE": "OKX"}
{"arg": {"channel": "books", "instId": "BTC-USDT"}, "action": "update", "data": [{"asks": [["83964.1", "1.05781353", "0", "12"], ["83964.3", "0", "0", "0"], ["83964.4", "0.02070738", "0", "2"], ["83969.9", "0", "0", "0"], ["83984.4", "0.23832914", "0", "1"], ["83988.2", "0", "0", "0"], ["84136", "0.3565323", "0", "1"], ["84136.7", "0.00004748", "0", "1"]], "bids": [["83932.6", "0", "0", "0"], ["83928.8", "0.23833001", "0", "1"]], "ts": "1742576922400", "checksum": 740166411, "seqId": 49944905252, "prevSeqId": 49944905239}], "record_time": 1742576922.573393, "EXCHANGE": "OKX"}
{"arg": {"channel": "books", "instId": "BTC-USDT"}, "action": "update", "data": [{"asks": [["83964.4", "0.02070732", "0", "2"], ["83969.9", "0.000021", "0", "1"], ["83984.4", "0", "0", "0"], ["83988.2", "0.23832871", "0", "1"], ["84136.7", "0", "0", "0"]], "bids": [["83931.3", "0.23832913", "0", "1"], ["83928.8", "0", "0", "0"]], "ts": "1742576922500", "checksum": -486554777, "seqId": 49944905263, "prevSeqId": 49944905252}], "record_time": 1742576922.673941, "EXCHANGE": "OKX"}
{"arg": {"channel": "books", "instId": "BTC-USDT"}, "action": "update", "data": [{"asks": [["83964.4", "0.01731399", "0", "1"], ["83965.9", "0.00339356", "0", "1"], ["83984.4", "0.23832928", "0", "1"], ["83988.2", "0", "0", "0"], ["84136", "0", "0", "0"]], "bids": [["83931.3", "0", "0", "0"], ["83928.8", "0.23833068", "0", "1"]], "ts": "1742576922600", "checksum": -2117244607, "seqId": 49944905271, "prevSeqId": 49944905263}], "record_time": 1742576922.773218, "EXCHANGE": "OKX"}
{"arg": {"channel": "books", "instId": "BTC-USDT"}, "action": "update", "data": [{"asks": [["83984.4", "0", "0", "0"], ["83988.2", "0.23832878", "0", "1"], ["84045.1", "0.07139025", "0", "1"]], "bids": [["83964", "0.11491916", "0", "6"], ["83962", "0.0439", "0", "1"], ["83931.3", "0.23832878", "0", "1"], ["83928.8", "0", "0", "0"], ["83880.4", "0.0715304", "0", "1"], ["83818.9", "0", "0", "0"]], "ts": "1742576922700", "checksum": 467239449, "seqId": 49944905285, "prevSeqId": 49944905271}], "record_time": 1742576922.873897, "EXCHANGE": "OKX"}
{"arg": {"channel": "books", "instId": "BTC-USDT"}, "action": "update", "data": [{"asks": [["83964.1", "1.26120681", "0", "14"], ["83965.9", "0", "0", "0"], ["83984.4", "0.23833007", "0", "1"], ["83988.2", "0", "0", "0"], ["83998", "1", "0", "1"], ["84023.4", "0.0119154", "0", "1"], ["84045.1", "0.1427805", "0", "2"], ["84051.4", "0", "0", "0"]], "bids": [["83964", "0.11181916", "0", "5"], ["83934", "0.37865", "0", "2"], ["83931.3", "0", "0", "0"], ["83928.8", "0.23833007", "0", "1"], ["83880.4", "0.1430608", "0", "2"]], "ts": "1742576922800", "checksum": 1564447712, "seqId": 49944905311, "prevSeqId": 49944905285}], "record_time": 1742576922.974225, "EXCHANGE": "OKX"}
{"arg": {"channel": "books", "instId": "BTC-USDT"}, "action": "update", "data": [{"asks": [["83964.1", "1.25781353", "0", "13"], ["83965.9", "0.0033935", "0", "1"], ["83988.2", "0.01774536", "0", "1"], ["84061.8", "0", "0", "0"], ["84135.8", "0", "0", "0"]], "bids": [["83934", "0.17865", "0", "1"]], "ts": "1742576922900", "checksum": -406232061, "seqId": 49944905317, "prevSeqId": 49944905311}], "record_time": 1742576923.073776, "EXCHANGE": "OKX"}
{"arg": {"channel": "books", "instId": "BTC-USDT"}, "action": "update", "data": [{"asks": [["83964.1", "1.05781353", "0", "12"], ["83984.4", "0", "0", "0"], ["83988.2", "0.25607478", "0", "2"], ["84002", "0.2", "0", "1"], ["84021.2", "0.24991495", "0", "2"]], "bids": [["83964", "0.11491916", "0", "6"], ["83957.8", "1", "0", "1"], ["83956.4", "0", "0", "0"], ["83937.3", "0.25011", "0", "1"], ["83934", "1.17865", "0", "2"], ["83932.6", "0.23832667", "0", "1"], ["83928.8", "0", "0", "0"], ["83819.2", "0", "0", "0"]], "ts": "1742576923000", "checksum": -867865440, "seqId": 49944905330, "prevSeqId": 49944905317}], "record_time": 1742576923.172936, "EXCHANGE": "OKX"}
{"arg": {"channel": "books", "instId": "BTC-USDT"}, "action": "update", "data": [{"asks": [["84033.1", "0", "0", "0"], ["84038.3", "0.00589875", "0", "1"], ["84086.6", "0", "0", "0"], ["84135.8", "0.00007302", "0", "1"], ["84136", "0.3565323", "0", "1"]], "bids": [["83959.8", "0", "0", "0"], ["83957.6", "0.01191651", "0", "1"], ["83939.6", "0", "0", "0"], ["83934", "0.17865", "0", "1"], ["83932.6", "0", "0", "0"], ["83931.3", "0.23832613", "0", "1"], ["83872.6", "0", "0", "0"], ["83869.6", "0", "0", "0"], ["83819.2", "0.00001297", "0", "1"], ["83818.9", "0.00006774", "0", "2"], ["83818.1", "0.00006813", "0", "3"]], "ts": "1742576923100", "checksum": 478899951, "seqId": 49944905347, "prevSeqId": 49944905330}], "record_time": 1742576923.273232, "EXCHANGE": "OKX"}
{"arg": {"channel": "books", "instId": "BTC-USDT"}, "action": "update", "data": [{"asks": [["83964.3", "0.00339304", "0", "1"], ["83965.9", "0", "0", "0"], ["83968.8", "0.01191651", "0", "1"], ["83970.9", "0.11914618", "0", "1"], ["83981.9", "0", "0", "0"], ["83984.4", "0.23833057", "0", "1"], ["83988.2", "0.01774536", "0", "1"], ["83997.8", "0.53762831", "0", "2"], ["84002", "0", "0", "0"], ["84086.5", "0.69461361", "0", "2"]], "bids": [["83964", "0.11777408", "0", "6"], ["83963.8", "0.11915609", "0", "1"], ["83961.6", "0", "0", "0"], ["83959.3", "1", "0", "1"], ["83958", "0.11534187", "0", "1"], ["83957.8", "0", "0", "0"], ["83931.3", "0", "0", "0"], ["83928.8", "0.23833057", "0", "1"], ["83928.6", "0.67713903", "0", "3"]], "ts": "1742576923200", "checksum": 1020737365, "seqId": 49944905370, "prevSeqId": 49944905347}], "record_time": 1742576923.373775, "EXCHANGE": "OKX"}
{"arg": {"channel": "books", "instId": "BTC-USDT"}, "action": "update", "data": [{"asks": [["83964.3", "0", "0", "0"], ["83965.9", "0.00339337", "0", "1"], ["83981.4", "0.135092", "0", "1"], ["83984.4", "0.23832956", "0", "1"], ["83988.5", "0.2050806", "0", "1"], ["83989.9", "0", "0", "0"], ["84021.4", "0.18691857", "0", "1"], ["84023.6", "0", "0", "0"], ["84032.9", "0.00119", "0", "1"], ["84038.1", "0.01427923", "0", "1"], ["84136", "0", "0", "0"]], "bids": [["83964", "0.09984408", "0", "5"], ["83959.3", "0", "0", "0"], ["83957.9", "1", "0", "1"], ["83932.4", "0.21275926", "0", "1"], ["83931.3", "0.23832956", "0", "1"], ["83930.7", "0", "0", "0"], ["83928.8", "0", "0", "0"], ["83898.7", "0", "0", "0"], ["83897.1", "0", "0", "0"], ["83881.4", "0.5085168", "0", "1"], ["83875.3", "0.00215372", "0", "2"], ["83872.2", "0.01510833", "0", "1"], ["83818", "0.00001199", "0", "1"]], "ts": "1742576923300", "checksum": -2104886780, "seqId": 49944905403, "prevSeqId": 49944905370}], "record_time": 1742576923.474536, "EXCHANGE": "OKX"}
{"arg": {"channel": "books", "instId": "BTC-USDT"}, "action": "update", "data": [{"asks": [["83984.4", "0.23832952", "0", "1"], ["83988.2", "0", "0", "0"], ["83989.1", "1.74443171", "0", "1"], ["84021.4", "1.08780947", "0", "2"], ["84022.8", "3.06719344", "0", "1"], ["84061.8", "0.01774536", "0", "1"], ["84135.7", "0", "0", "0"], ["84135.8", "0", "0", "0"]], "bids": [["83958", "0.40092414", "0", "2"], ["83957.9", "0", "0", "0"], ["83956.6", "1.00001199", "0", "2"], ["83939.6", "0.17865", "0", "1"], ["83931.6", "1.68503917", "0", "1"], ["83931.3", "0", "0", "0"], ["83928.8", "0.23832951", "0", "1"], ["83922.4", "0.1", "0", "2"], ["83921.6", "0.30011", "0", "2"], ["83920", "0.00037", "0", "2"], ["83919.2", "0", "0", "0"], ["83898", "3.05984874", "0", "1"], ["83897.2", "0.000012", "0", "1"], ["83896", "0.00100675", "0", "1"], ["83818.9", "0", "0", "0"], ["83818.1", "0", "0", "0"], ["83818", "0", "0", "0"]], "ts": "1742576923400", "checksum": -1896269302, "seqId": 49944905430, "prevSeqId": 49944905403}], "record_time": 1742576923.57593, "EXCHANGE": "OKX"}
{"arg": {"channel": "books", "instId": "BTC-USDT"}, "action": "update", "data": [{"asks": [["84003.2", "0.08", "0", "2"], ["84004", "0.03999999", "0", "1"], ["84007.2", "0", "0", "0"], ["84008", "0", "0", "0"]], "bids": [["83964", "0.00728916", "0", "3"], ["83928", "0.08", "0", "2"], ["83927.2", "0.04", "0", "1"], ["83925.6", "0.00079983", "0", "2"], ["83924.8", "0.00039984", "0", "1"], ["83819.4", "0", "0", "0"], ["83819.2", "0", "0", "0"]], "ts": "1742576923500", "checksum": 1306138131, "seqId": 49944905444, "prevSeqId": 49944905430}], "record_time": 1742576923.673666, "EXCHANGE": "OKX"}
{"arg": {"channel": "books", "instId": "BTC-USDT"}, "action": "update", "data": [{"asks": [["83984.4", "0.23832901", "0", "1"], ["83995.2", "0.0008", "0", "2"], ["83996", "0.0004", "0", "1"], ["83999.2", "0", "0", "0"], ["84000", "0.18773756", "0", "4"], ["84135", "0", "0", "0"]], "bids": [["83928", "0.0808", "0", "4"], ["83927.2", "0.04039982", "0", "2"], ["83925.6", "0", "0", "0"], ["83924.8", "0", "0", "0"], ["83819.4", "0.00014808", "0", "2"], ["83819.2", "0.00001297", "0", "1"]], "ts": "1742576923600", "checksum": 1306138131, "seqId": 49944905460, "prevSeqId": 49944905444}], "record_time": 1742576923.773485, "EXCHANGE": "OKX"}
{"arg": {"channel": "books", "instId": "BTC-USDT"}, "action": "update", "data": [{"asks": [["83984.4", "0", "0", "0"], ["83985.7", "0", "0", "0"], ["83988.2", "0.25607153", "0", "2"], ["84061.8", "0", "0", "0"], ["84135", "0.00001199", "0", "1"], ["84135.7", "0.0000221", "0", "1"]], "bids": [["83964", "0.10294408", "0", "6"], ["83957.9", "1", "0", "1"], ["83956.6", "0.00001199", "0", "1"], ["83938.8", "0", "0", "0"], ["83932.6", "0.23832617", "0", "1"], ["83928.8", "0", "0", "0"], ["83917", "0.00596643", "0", "2"]], "ts": "1742576923700", "checksum": -1751189112, "seqId": 49944905477, "prevSeqId": 49944905460}], "record_time": 1742576923.874125, "EXCHANGE": "OKX"}
{"arg": {"channel": "books", "instId": "BTC-USDT"}, "action": "update", "data": [{"asks": [["83964.1", "1.04766353", "0", "11"], ["83966.8", "0.01014", "0", "1"], ["84135.7", "0", "0", "0"]], "bids": [["83964", "0.40169022", "0", "8"], ["83961", "1", "0", "1"], ["83958", "0.11534187", "0", "1"], ["83957.9", "0", "0", "0"], ["83953.4", "0.01397", "0", "1"], ["83949.4", "0", "0", "0"]], "ts": "1742576923800", "checksum": 763566005, "seqId": 49944905490, "prevSeqId": 49944905477}], "record_time": 1742576923.974673, "EXCHANGE": "OKX"}
{"arg": {"channel": "books", "instId": "BTC-USDT"}, "action": "update", "data": [{"asks": [["83964.1", "1.05366353", "0", "12"], ["83965.9", "0", "0", "0"], ["83967.8", "0.00340757", "0", "1"], ["83969.9", "0", "0", "0"], ["83971.8", "0", "0", "0"], ["84135.7", "0.0000221", "0", "1"], ["84135.8", "0.00007302", "0", "1"]], "bids": [["83962.4", "1", "0", "1"], ["83961", "0", "0", "0"], ["83939.6", "0", "0", "0"], ["83928", "0.08", "0", "2"], ["83927.2", "0.04079982", "0", "3"], ["83926.4", "0.00039983", "0", "1"]], "ts": "1742576923900", "checksum": 2049228964, "seqId": 49944905508, "prevSeqId": 49944905490}], "record_time": 1742576924.072863, "EXCHANGE": "OKX"}
{"arg": {"channel": "books", "instId": "BTC-USDT"}, "action": "update", "data": [{"asks": [["83964.1", "1.01979753", "0", "10"], ["83967.8", "0", "0", "0"], ["83968.6", "0.00340539", "0", "1"], ["83969.2", "0", "0", "0"], ["83973.9", "0.000039", "0", "1"], ["83974.5", "0.03044", "0", "1"], ["83995.2", "0", "0", "0"], ["83996", "0.0008", "0", "2"], ["83996.8", "0.0004", "0", "1"], ["83997.8", "0.27116379", "0", "1"], ["83998", "0", "0", "0"]], "bids": [["83964", "0.55375166", "0", "9"], ["83948.4", "0.0559", "0", "2"], ["83943.7", "0", "0", "0"], ["83939.2", "0", "0", "0"], ["83818.9", "0.00006774", "0", "2"], ["83818.1", "0.00006813", "0", "3"]], "ts": "1742576924000", "checksum": -740392036, "seqId": 49944905558, "prevSeqId": 49944905508}], "record_time": 1742576924.173592, "EXCHANGE": "OKX"}
{"arg": {"channel": "books", "instId": "BTC-USDT"}, "action": "update", "data": [{"asks": [["83964.1", "0.878589", "0", "8"], ["83968.6", "0", "0", "0"], ["83970.5", "0.00340537", "0", "1"], ["83970.7", "0.04084853", "0", "1"], ["83970.9", "0", "0", "0"], ["83973.2", "0.13105778", "0", "2"], ["83979.2", "0.4604164", "0", "2"], ["83979.5", "0", "0", "0"], ["83979.9", "0.04", "0", "1"], ["83988.2", "0", "0", "0"], ["83991.2", "0.23832599", "0", "2"], ["84015.7", "0.01774536", "0", "1"], ["84040.2", "0", "0", "0"], ["84040.4", "0.0015268", "0", "1"], ["84136", "0.3565323", "0", "1"]], "bids": [["83964", "0.58865738", "0", "10"], ["83938.3", "0.23831376", "0", "1"], ["83938", "1", "0", "1"], ["83932.6", "0", "0", "0"], ["83916.1", "0", "0", "0"], ["83915.8", "0.01835075", "0", "1"], ["83914.8", "0.0249433", "0", "1"], ["83896.2", "0.00100671", "0", "1"], ["83896.1", "0.00363903", "0", "2"], ["83896", "0", "0", "0"], ["83895.9", "0", "0", "0"], ["83895.8", "0", "0", "0"], ["83844.7", "0.00005731", "0", "1"], ["83844.6", "1.87888546", "0", "3"], ["83818.1", "0", "0", "0"]], "ts": "1742576924100", "checksum": -996453641, "seqId": 49944905602, "prevSeqId": 49944905558}], "record_time": 1742576924.273835, "EXCHANGE": "OKX"}
{"arg": {"channel": "books", "instId": "BTC-USDT"}, "action": "update", "data": [{"asks": [["83966.8", "0", "0", "0"], ["83969.2", "0.01014", "0", "1"], ["83969.9", "0.00340524", "0", "1"], ["83970.5", "0", "0", "0"], ["83988.2", "0.23831652", "0", "1"], ["83988.5", "0.77426987", "0", "2"], ["83991.2", "0.00001199", "0", "1"], ["84136", "0", "0", "0"]], "bids": [["83964", "0.60465738", "0", "11"], ["83955.8", "0.01397", "0", "1"], ["83953.4", "0", "0", "0"], ["83938.3", "0", "0", "0"], ["83934.1", "0.23831919", "0", "1"], ["83932.4", "0.69167611", "0", "2"]], "ts": "1742576924200", "checksum": -1577740945, "seqId": 49944905649, "prevSeqId": 49944905602}], "record_time": 1742576924.372944, "EXCHANGE": "OKX"}
{"arg": {"channel": "books", "instId": "BTC-USDT"}, "action": "update", "data": [{"asks": [["83968.7", "0.02340297", "0", "2"], ["83969.9", "0", "0", "0"], ["83982.6", "0.26424136", "0", "2"], ["83988.1", "0.01774536", "0", "1"], ["84003.2", "0", "0", "0"], ["84004", "0.07999999", "0", "2"], ["84004.8", "0.03999999", "0", "1"], ["84015.7", "0", "0", "0"], ["84136", "0.3565323", "0", "1"]], "bids": [["83964", "0.64855738", "0", "12"], ["83963", "0", "0", "0"], ["83962.5", "0.36727312", "0", "1"], ["83939.8", "0.3573", "0", "1"], ["83922.4", "0", "0", "0"], ["83921.6", "0.35011", "0", "3"], ["83920.8", "0.05", "0", "1"], ["83818.9", "0", "0", "0"]], "ts": "1742576924300", "checksum": -728262372, "seqId": 49944905688, "prevSeqId": 49944905649}], "record_time": 1742576924.473727, "EXCHANGE": "OKX"}
{"arg": {"channel": "books", "instId": "BTC-USDT"}, "action": "update", "data": [{"asks": [["83967.8", "0.00340285", "0", "1"], ["83968.7", "0.02", "0", "1"], ["83994.2", "0.12505", "0", "1"], ["84015.1", "0.12505", "0", "1"], ["84032.4", "0", "0", "0"], ["84034.7", "0.01130015", "0", "1"], ["84103.7", "0", "0", "0"], ["84106.9", "0.1130015", "0", "1"], ["84135.7", "0", "0", "0"], ["84135.8", "0", "0", "0"], ["84136", "0", "0", "0"]], "bids": [["83964", "0.69305738", "0", "12"], ["83962.5", "0", "0", "0"], ["83962.4", "0", "0", "0"], ["83961.1", "0.35350312", "0", "1"], ["83961", "1", "0", "1"], ["83934.1", "0", "0", "0"], ["83932.6", "0.23832232", "0", "1"], ["83928", "0", "0", "0"], ["83927.2", "0.08079982", "0", "4"], ["83926.4", "0.04039983", "0", "2"], ["83917.3", "0.01835048", "0", "1"], ["83915.8", "0", "0", "0"], ["83844.7", "0.1835622", "0", "2"], ["83844.6", "1.69537794", "0", "2"], ["83818.9", "0.00006774", "0", "2"]], "ts": "1742576924400", "checksum": 1921843691, "seqId": 49944905720, "prevSeqId": 49944905688}], "record_time": 1742576924.573356, "EXCHANGE": "OKX"}
{"arg": {"channel": "books", "instId": "BTC-USDT"}, "action": "update", "data": [{"asks": [["83980.1", "0.2965", "0", "2"], ["83982.6", "0.00774136", "0", "1"]], "bids": [["83938", "0", "0", "0"], ["83818.1", "0.00006813", "0", "3"]], "ts": "1742576924500", "checksum": 1921843691, "seqId": 49944905728, "prevSeqId": 49944905720}], "record_time": 1742576924.675852, "EXCHANGE": "OKX"}
{"arg": {"channel": "books", "instId": "BTC-USDT"}, "action": "update", "data": [{"asks": [["83964.1", "0.896455", "0", "9"], ["83988.9", "0.01190634", "0", "1"], ["83990.6", "0.000015", "0", "1"], ["83993.1", "0.01190574", "0", "1"], ["83993.6", "0.01390567", "0", "2"], ["83993.9", "0", "0", "0"], ["83994.5", "0", "0", "0"], ["83996", "0", "0", "0"], ["83996.8", "0.0008", "0", "2"], ["83997.6", "0.0004", "0", "1"]], "bids": [["83924.6", "0.01190567", "0", "1"], ["83924", "0.02490574", "0", "2"], ["83923.7", "0.50224416", "0", "1"], ["83923.2", "0.01190587", "0", "1"], ["83818.1", "0", "0", "0"]], "ts": "1742576924600", "checksum": -1876063158, "seqId": 49944905747, "prevSeqId": 49944905728}], "record_time": 1742576924.774896, "EXCHANGE": "OKX"}
{"arg": {"channel": "books", "instId": "BTC-USDT"}, "action": "update", "data": [{"asks": [["83967.8", "0", "0", "0"], ["83969.1", "0.00340375", "0", "1"], ["83980.1", "0.04", "0", "1"], ["83988.2", "0", "0", "0"], ["83992.9", "0.23831432", "0", "1"]], "bids": [["83964", "0.67676738", "0", "11"], ["83938", "0.23831432", "0", "1"], ["83932.6", "0", "0", "0"]], "ts": "1742576924800", "checksum": 905114592, "seqId": 49944905768, "prevSeqId": 49944905747}], "record_time": 1742576924.973726, "EXCHANGE": "OKX"}
{"arg": {"channel": "books", "instId": "BTC-USDT"}, "action": "snapshot", "data": [{"asks": [["83986.6", "2.02273125", "0", "20"], ["83988", "0.0439", "0", "1"], ["83988.4", "0.04197871", "0", "1"], ["83988.5", "0.0639133", "0", "3"], ["83989.7", "0.00773933", "0", "1"], ["83990", "0.0439", "0", "1"], ["83990.2", "0.000021", "0", "1"], ["83990.6", "0.0428883", "0", "1"], ["83990.9", "0.00111973", "0", "1"], ["83991", "0.052", "0", "2"], ["83991.7", "0.03062", "0", "1"], ["83992", "0.0439", "0", "1"], ["83993.5", "0.09354649", "0", "1"], ["83993.6", "0.02958248", "0", "1"], ["83994.1", "0.052", "0", "2"], ["83994.9", "0.00773916", "0", "1"], ["83995.5", "0.036", "0", "1"], ["83995.6", "0.2385", "0", "3"], ["83996", "0.0439", "0", "1"], ["83996.1", "0.016", "0", "1"], ["83996.2", "0.00001199", "0", "1"], ["83997.7", "0.002", "0", "1"], ["83998", "0.0439", "0", "1"], ["83998.3", "0.14865044", "0", "1"], ["83999", "0.000015", "0", "1"], ["83999.2", "0.02382749", "0", "1"], ["83999.6", "0.35697351", "0", "1"], ["84000", "0.0439", "0", "1"], ["84000.2", "0.25850428", "0", "2"], ["84000.3", "0.17898725", "0", "1"], ["84000.5", "0.1786", "0", "1"], ["84000.6", "0.14011011", "0", "3"], ["84001.1", "0.00001199", "0", "1"], ["84001.4", "0.0015", "0", "1"], ["84002", "0.133958", "0", "6"], ["84003", "0.134841", "0", "1"], ["84003.9", "0.11889794", "0", "1"], ["84004", "0.0439", "0", "1"], ["84004.4", "0.052", "0", "2"], ["84005.4", "0.23904446", "0", "2"], ["84005.6", "0.17909685", "0", "3"], ["84005.7", "0.04", "0", "1"], ["84005.8", "0.03", "0", "1"], ["84006", "0.0439", "0", "1"], ["84006.1", "0.00001198", "0", "1"], ["84006.2", "0.052", "0", "2"], ["84007.1", "0.00360407", "0", "1"], ["84007.4", "0.00001501", "0", "1"], ["84007.8", "0.002", "0", "1"], ["84008", "0.05581011", "0", "2"], ["84008.2", "0.2545", "0", "3"], ["84008.6", "0.98707501", "0", "1"], ["84008.7", "1", "0", "1"], ["84008.9", "0.03", "0", "1"], ["84009", "0.03", "0", "1"], ["84009.8", "0.03", "0", "1"], ["84010.3", "0.35697351", "0", "1"], ["84011", "0.00001198", "0", "1"], ["84011.3", "0.17898725", "0", "1"], ["84011.9", "1.56837728", "0", "1"], ["84012.1", "0.052", "0", "2"], ["84012.6", "0.15630145", "0", "1"], ["84013.1", "0.016", "0", "1"], ["84013.2", "0.18761632", "0", "1"], ["84015.8", "0.00001501", "0", "1"], ["84016", "0.00001198", "0", "1"], ["84016.5", "0.23826078", "0", "1"], ["84016.6", "0.12325839", "0", "3"], ["84017.7", "0.28756719", "0", "1"], ["84018", "1.08991011", "0", "2"], ["84018.3", "0.01", "0", "2"], ["84018.5", "0.14071224", "0", "1"], ["84019.1", "0.11889794", "0", "1"], ["84019.2", "0.01190205", "0", "1"], ["84019.4", "0.35697351", "0", "1"], ["84019.7", "0.35719", "0", "1"], ["84020.5", "0.01190186", "0", "1"], ["84020.8", "0.11256978", "0", "2"], ["84020.9", "0.00001198", "0", "1"], ["84021", "0.01", "0", "1"], ["84021.3", "0.21238952", "0", "1"], ["84021.6", "0.2025", "0", "1"], ["84023.3", "0.00011161", "0", "1"], ["84024.2", "0.000015", "0", "1"], ["84024.3", "0.05988", "0", "1"], ["84024.4", "0.25002", "0", "1"], ["84025.1", "0.17898725", "0", "1"], ["84025.6", "0.24136306", "0", "1"], ["84025.9", "0.00001198", "0", "1"], ["84026.6", "0.26238", "0", "1"], ["84027", "0.02976121", "0", "1"], ["84027.9", "0.35697351", "0", "1"], ["84028", "0.11889794", "0", "1"], ["84028.1", "0.08991011", "0", "1"], ["84028.3", "0.005", "0", "1"], ["84028.4", "0.005", "0", "1"], ["84029.3", "0.02381266", "0", "1"], ["84030.8", "0.00001198", "0", "1"], ["84030.9", "0.11221571", "0", "1"], ["84031", "0.2025", "0", "1"], ["84031.1", "0.1", "0", "1"], ["84031.4", "0.11256978", "0", "2"], ["84032.1", "0.00595224", "0", "1"], ["84032.6", "0.000015", "0", "1"], ["84033.1", "0.01962952", "0", "1"], ["84033.3", "0.00101534", "0", "2"], ["84033.4", "0.052", "0", "2"], ["84033.7", "0.17898725", "0", "1"], ["84033.9", "0.96619191", "0", "1"], ["84034", "1.62238533", "0", "3"], ["84034.1", "0.5912964", "0", "1"], ["84034.8", "0.00589954", "0", "1"], ["84034.9", "0.052", "0", "2"], ["84035.8", "0.00001198", "0", "1"], ["84037.3", "0.05956073", "0", "1"], ["84037.4", "0.35697351", "0", "1"], ["84037.8", "0.52893", "0", "2"], ["84038.5", "0.17418962", "0", "1"], ["84038.6", "0.11889794", "0", "1"], ["84039.2", "0.052", "0", "2"], ["84039.8", "0.00195733", "0", "1"], ["84039.9", "0.2545", "0", "3"], ["84040", "0.00004", "0", "1"], ["84040.3", "0.02283169", "0", "1"], ["84040.8", "0.00001198", "0", "1"], ["84041", "0.000025", "0", "2"], ["84041.8", "0.00589954", "0", "1"], ["84041.9", "0.11256978", "0", "2"], ["84042", "0.01189882", "0", "1"], ["84042.5", "0.016", "0", "1"], ["84042.9", "0.14071224", "0", "1"], ["84043", "0.00011161", "0", "1"], ["84043.3", "0.00589954", "0", "1"], ["84043.4", "0.39741072", "0", "1"], ["84043.9", "0.00002157", "0", "1"], ["84044", "0.10260864", "0", "4"], ["84044.3", "0.00103317", "0", "1"], ["84044.6", "0.01189845", "0", "1"], ["84044.8", "0.0004", "0", "1"], ["84045", "0.17898725", "0", "1"], ["84045.1", "0.824761", "0", "1"], ["84045.4", "0.24999", "0", "1"], ["84045.5", "0.03566075", "0", "2"], ["84045.7", "0.00001198", "0", "1"], ["84046.6", "0.00009539", "0", "1"], ["84046.9", "0.00589954", "0", "1"], ["84047", "0.23290086", "0", "1"], ["84047.1", "0.35697351", "0", "1"], ["84048", "0.0015", "0", "1"], ["84048.5", "0.0115492", "0", "1"], ["84049", "0.01368", "0", "1"], ["84049.1", "0.01189781", "0", "1"], ["84049.4", "0.00105092", "0", "2"], ["84049.5", "0.20845319", "0", "2"], ["84049.8", "0.04762613", "0", "1"], ["84049.9", "0.00060645", "0", "1"], ["84050", "0.00018518", "0", "2"], ["84050.4", "0.35425148", "0", "1"], ["84050.5", "0.11889794", "0", "1"], ["84050.7", "0.000012", "0", "1"], ["84050.8", "0.001786", "0", "1"], ["84051.2", "0.08595318", "0", "3"], ["84051.4", "0.01124703", "0", "1"], ["84051.5", "0.02970591", "0", "2"], ["84051.9", "0.01785571", "0", "1"], ["84052", "0.04149999", "0", "2"], ["84052.4", "0.11256978", "0", "2"], ["84052.6", "0.00001738", "0", "1"], ["84052.7", "0.0057746", "0", "1"], ["84053.1", "0.56957501", "0", "2"], ["84053.3", "0.01189722", "0", "1"], ["84053.4", "0.0119088", "0", "1"], ["84053.6", "0.17898725", "0", "1"], ["84054.4", "0.0001721", "0", "1"], ["84055", "0.179784", "0", "1"], ["84055.6", "0.3565443", "0", "2"], ["84056.3", "0.04497", "0", "1"], ["84056.9", "0.0057746", "0", "1"], ["84057", "0.01", "0", "1"], ["84057.1", "0.00007544", "0", "2"], ["84057.3", "0.03", "0", "1"], ["84057.4", "0.00009384", "0", "1"], ["84057.8", "0.000015", "0", "1"], ["84057.9", "0.20252241", "0", "2"], ["84058.8", "0.16922965", "0", "4"], ["84060", "0.00004", "0", "1"], ["84060.2", "0.43692", "0", "1"], ["84060.6", "0.000012", "0", "1"], ["84062.1", "0.00002296", "0", "1"], ["84062.4", "0.00010514", "0", "1"], ["84062.6", "0.00011161", "0", "1"], ["84062.9", "0.11256978", "0", "2"], ["84063.7", "0.65996116", "0", "3"], ["84063.8", "0.17190794", "0", "2"], ["84063.9", "0.00713742", "0", "1"], ["84064.5", "0.35772186", "0", "2"], ["84065.2", "0.00008584", "0", "1"], ["84065.6", "0.47156999", "0", "2"], ["84066.2", "0.00591454", "0", "2"], ["84066.3", "0.2025", "0", "1"], ["84066.6", "0.00504382", "0", "4"], ["84067", "0.000012", "0", "1"], ["84067.7", "0.06414777", "0", "1"], ["84067.8", "0.05952242", "0", "1"], ["84068.7", "0.10418414", "0", "2"], ["84069.7", "0.00011444", "0", "1"], ["84071", "0.001721", "0", "1"], ["84071.4", "0.00001362", "0", "1"], ["84072.2", "0.00002016", "0", "1"], ["84072.6", "0.00007814", "0", "1"], ["84072.8", "0.11889794", "0", "1"], ["84072.9", "0.22340873", "0", "1"], ["84073", "0.3565323", "0", "1"], ["84073.2", "0.17898725", "0", "1"], ["84073.9", "0.00589954", "0", "1"], ["84074", "0.00595164", "0", "1"], ["84074.1", "0.14273138", "0", "2"], ["84074.6", "0.000015", "0", "1"], ["84074.7", "0.2025", "0", "1"], ["84075", "0.00004433", "0", "1"], ["84075.5", "0.00001199", "0", "1"], ["84076.1", "0.03413857", "0", "1"], ["84076.2", "0.05949841", "0", "1"], ["84076.5", "0.00010284", "0", "1"], ["84076.8", "0.00001957", "0", "1"], ["84076.9", "0.03009125", "0", "2"], ["84077", "0.00008", "0", "1"], ["84078.4", "0.02380922", "0", "1"], ["84079.3", "0.00001199", "0", "1"], ["84079.4", "0.00018194", "0", "1"], ["84079.9", "0.00001026", "0", "1"], ["84080", "0.01785492", "0", "3"], ["84080.8", "0.2798112", "0", "1"], ["84081.4", "0.00593318", "0", "2"], ["84081.5", "0.02381132", "0", "1"], ["84081.6", "0.00212326", "0", "1"], ["84081.7", "0.03", "0", "1"], ["84081.9", "0.02124", "0", "1"], ["84082.1", "0.00579941", "0", "1"], ["84082.2", "0.17898725", "0", "1"], ["84082.3", "0.00011161", "0", "1"], ["84082.6", "0.00001984", "0", "1"], ["84083", "0.00001501", "0", "1"], ["84083.1", "0.2025", "0", "1"], ["84083.3", "0.00422986", "0", "3"], ["84083.4", "0.11764", "0", "2"], ["84083.8", "0.3565323", "0", "1"], ["84084.6", "0.05732575", "0", "1"], ["84085.1", "0.42018233", "0", "1"], ["84085.2", "1.21477", "0", "1"], ["84085.4", "0.00001199", "0", "1"], ["84085.6", "0.07165719", "0", "1"], ["84085.7", "0.00068775", "0", "1"], ["84086.7", "0.03", "0", "1"], ["84087.5", "0.07166249", "0", "1"], ["84088.1", "0.00589954", "0", "1"], ["84088.2", "0.00591879", "0", "2"], ["84088.3", "0.196399", "0", "1"], ["84088.5", "0.00003542", "0", "1"], ["84088.6", "0.01736", "0", "1"], ["84089.1", "0.00002215", "0", "1"], ["84089.6", "0.11889794", "0", "1"], ["84089.7", "0.0015", "0", "1"], ["84090", "0.067428", "0", "1"], ["84090.2", "0.00074396", "0", "1"], ["84090.4", "0.00002339", "0", "2"], ["84090.5", "0.0054", "0", "1"], ["84090.8", "0.00376703", "0", "1"], ["84090.9", "0.00003887", "0", "1"], ["84091.1", "0.17898725", "0", "1"], ["84091.2", "0.00001297", "0", "1"], ["84091.4", "0.00001501", "0", "1"], ["84091.5", "0.2025", "0", "1"], ["84091.6", "0.00595105", "0", "1"], ["84091.7", "0.00001199", "0", "1"], ["84092.7", "1.36840454", "0", "3"], ["84093.2", "0.3565323", "0", "1"], ["84093.8", "0.61647", "0", "1"], ["84094.2", "0.0357113", "0", "1"], ["84094.5", "0.31997186", "0", "1"], ["84095.1", "0.000015", "0", "1"], ["84095.8", "3.4627", "0", "1"], ["84096", "0.00006328", "0", "1"], ["84097.5", "0.1", "0", "1"], ["84098.1", "0.0428", "0", "2"], ["84098.2", "0.0214", "0", "1"], ["84098.3", "0.0428", "0", "2"], ["84099.3", "0.00298666", "0", "1"], ["84099.6", "0.4", "0", "1"], ["84099.8", "0.000015", "0", "1"], ["84099.9", "1.826165", "0", "5"], ["84100", "5.01249374", "0", "6"], ["84100.3", "0.00001199", "0", "1"], ["84100.9", "0.00595025", "0", "1"], ["84101", "0.03", "0", "1"], ["84101.2", "0.23400215", "0", "1"], ["84101.3", "0.17898725", "0", "1"], ["84101.7", "0.3565323", "0", "1"], ["84101.9", "0.00011161", "0", "1"], ["84103.5", "0.00589966", "0", "1"], ["84103.6", "0.00590056", "0", "1"], ["84103.8", "0.00595025", "0", "1"], ["84104.1", "0.00001199", "0", "1"], ["84104.2", "0.1", "0", "1"], ["84104.9", "0.03", "0", "1"], ["84105.2", "0.00001053", "0", "1"], ["84106.6", "0.00001008", "0", "1"], ["84106.8", "0.00590049", "0", "1"], ["84106.9", "0.01180112", "0", "2"], ["84107", "0.00120451", "0", "3"], ["84107.6", "0.00001881", "0", "1"], ["84107.7", "0.01191332", "0", "2"], ["84108.2", "0.000015", "0", "1"], ["84108.3", "0.2025", "0", "1"], ["84109", "0.08994305", "0", "2"], ["84110", "0.00589966", "0", "1"], ["84110.1", "0.01232", "0", "1"], ["84110.2", "0.00001199", "0", "1"], ["84110.3", "0.00579971", "0", "1"], ["84110.4", "0.16542114", "0", "1"], ["84110.5", "0.3565323", "0", "1"], ["84111.1", "0.00003344", "0", "1"], ["84111.2", "0.00004855", "0", "1"], ["84111.6", "0.0015", "0", "1"], ["84112.6", "0.00003552", "0", "1"], ["84113.3", "0.17898725", "0", "1"], ["84113.5", "0.00003103", "0", "1"], ["84113.6", "0.15231037", "0", "1"], ["84114", "0.00014547", "0", "1"], ["84115.1", "0.1", "0", "1"], ["84115.2", "0.00001199", "0", "1"], ["84115.6", "0.00579971", "0", "1"], ["84115.7", "0.00103744", "0", "1"], ["84116.1", "0.00895999", "0", "1"], ["84116.4", "0.00001199", "0", "1"], ["84116.5", "0.00580002", "0", "1"], ["84116.6", "0.00657466", "0", "3"], ["84116.7", "0.11889794", "0", "1"], ["84117.3", "0.214308", "0", "1"], ["84117.6", "0.00001805", "0", "1"], ["84118", "0.00251795", "0", "1"], ["84118.9", "0.15480832", "0", "1"], ["84119", "0.35658448", "0", "2"], ["84119.4", "0.08761", "0", "1"], ["84120", "0.00006444", "0", "2"], ["84121.5", "0.00011161", "0", "1"], ["84122.1", "1.24675239", "0", "2"], ["84122.2", "0.17898725", "0", "1"], ["84123.2", "0.0426", "0", "3"], ["84123.3", "3.82107", "0", "1"], ["84123.4", "0.0426", "0", "3"], ["84123.5", "0.0142", "0", "1"], ["84123.6", "0.00126715", "0", "1"], ["84123.7", "0.00005514", "0", "1"], ["84124.5", "0.01194665", "0", "1"], ["84124.9", "0.10292533", "0", "1"], ["84125", "0.00010765", "0", "2"], ["84125.1", "0.00015069", "0", "2"], ["84125.3", "0.00001956", "0", "1"], ["84125.9", "0.00594", "0", "1"], ["84126.2", "0.00001805", "0", "1"], ["84126.6", "0.00002004", "0", "1"], ["84127", "0.11892505", "0", "1"], ["84127.4", "0.12846203", "0", "1"], ["84127.5", "0.3565323", "0", "1"], ["84129.2", "0.002382", "0", "1"], ["84130.1", "0.00001199", "0", "1"], ["84130.5", "0.11889794", "0", "1"], ["84131.1", "0.00008649", "0", "2"], ["84131.2", "0.03", "0", "1"], ["84132.5", "0.17898725", "0", "1"], ["84132.6", "0.0000434", "0", "1"], ["84132.8", "0.00002013", "0", "1"], ["84132.9", "0.01493332", "0", "1"], ["84133.1", "0.08991011", "0", "1"], ["84133.3", "0.00517228", "0", "9"], ["84133.4", "0.0059532", "0", "1"], ["84133.5", "0.00001277", "0", "1"], ["84134.1", "0.21119", "0", "1"], ["84134.2", "0.0119064", "0", "2"], ["84134.5", "0.0000103", "0", "1"], ["84134.6", "0.00003392", "0", "1"], ["84134.9", "0.33943407", "0", "1"], ["84135", "0.72698412", "0", "2"], ["84135.7", "0.0000221", "0", "1"], ["84135.8", "1.64332302", "0", "2"], ["84136", "0.3565323", "0", "1"], ["84136.2", "0.08356695", "0", "2"], ["84136.7", "0.00004748", "0", "1"], ["84136.8", "0.00005963", "0", "1"], ["84137.1", "0.00001501", "0", "1"], ["84138.8", "0.00044981", "0", "1"], ["84140", "0.0003242", "0", "3"], ["84141.1", "0.00005109", "0", "1"], ["84141.2", "0.00011161", "0", "1"], ["84141.3", "0.00083", "0", "1"], ["84141.4", "0.08762", "0", "1"], ["84141.9", "0.00085329", "0", "2"], ["84142", "0.183468", "0", "1"], ["84142.1", "0.00083", "0", "1"]], "bids": [["83986.5", "0.002", "0", "1"], ["83984.1", "0.00011161", "0", "1"], ["83983.9", "0.005", "0", "1"], ["83983.3", "0.00060645", "0", "1"], ["83982.3", "0.00056051", "0", "1"], ["83982", "0.0439", "0", "1"], ["83981.8", "0.11913048", "0", "1"], ["83980", "0.00001", "0", "1"], ["83979.1", "0.03377093", "0", "1"], ["83979", "0.11256978", "0", "2"], ["83977.5", "0.4464255", "0", "2"], ["83976.7", "0.000015", "0", "1"], ["83976.5", "0.002", "0", "1"], ["83976.4", "0.00001199", "0", "1"], ["83975.8", "0.17898725", "0", "1"], ["83975.7", "0.2185", "0", "2"], ["83975.4", "1", "0", "1"], ["83975.2", "0.01191364", "0", "1"], ["83974.7", "0.2204915", "0", "2"], ["83974.6", "0.35697351", "0", "1"], ["83974.1", "0.00773916", "0", "1"], ["83974", "0.01388", "0", "1"], ["83973.6", "0.016", "0", "1"], ["83973.2", "0.01189853", "0", "1"], ["83973.1", "0.069", "0", "2"], ["83972.9", "0.01", "0", "1"], ["83972.3", "0.0429483", "0", "2"], ["83971.5", "0.00001199", "0", "1"], ["83971.4", "0.05389", "0", "2"], ["83970.4", "0.23251263", "0", "1"], ["83970.3", "0.1786", "0", "1"], ["83969.9", "0.05956073", "0", "1"], ["83969.7", "0.34061632", "0", "5"], ["83969.5", "0.04", "0", "1"], ["83968.8", "0.001785", "0", "1"], ["83968.7", "0.04167", "0", "1"], ["83968.6", "0.0119157", "0", "1"], ["83968.5", "0.11256978", "0", "2"], ["83968.3", "0.00001501", "0", "1"], ["83968", "0.00357", "0", "1"], ["83966.6", "0.00101534", "0", "2"], ["83966.5", "0.04329013", "0", "2"], ["83966.3", "0.44130596", "0", "2"], ["83966.2", "0.3565323", "0", "1"], ["83966.1", "0.17898725", "0", "1"], ["83965.9", "0.2025", "0", "1"], ["83965", "0.11915438", "0", "1"], ["83964.6", "0.00477891", "0", "2"], ["83964.4", "0.00011161", "0", "1"], ["83963.1", "0.11915709", "0", "1"], ["83962.7", "0.02382661", "0", "1"], ["83962.6", "0.0000595", "0", "1"], ["83961.9", "0.08611", "0", "1"], ["83961.6", "0.00001199", "0", "1"], ["83961.5", "0.45386518", "0", "2"], ["83961.2", "0.31931224", "0", "2"], ["83960.7", "0.02831988", "0", "1"], ["83960", "0.00001", "0", "1"], ["83959.9", "0.00001501", "0", "1"], ["83959.5", "0.00001501", "0", "1"], ["83959", "0.02687256", "0", "3"], ["83958.8", "0.01190057", "0", "1"], ["83958.6", "0.01774536", "0", "1"], ["83958.5", "0.23826078", "0", "1"], ["83958.4", "0.5600595", "0", "2"], ["83958.3", "0.471533", "0", "1"], ["83958", "0.11506978", "0", "3"], ["83957.7", "0.36355587", "0", "2"], ["83957.6", "0.17898725", "0", "1"], ["83957.5", "0.14071224", "0", "1"], ["83957", "0.12502", "0", "1"], ["83956.6", "0.05166199", "0", "2"], ["83956.4", "0.01190115", "0", "1"], ["83956.2", "0.3565323", "0", "1"], ["83956", "0.05841208", "0", "2"], ["83954.3", "0.5776526", "0", "1"], ["83954.2", "0.0000595", "0", "1"], ["83953.3", "0.61578169", "0", "1"], ["83953.2", "1.5521176", "0", "1"], ["83952.8", "0.08", "0", "2"], ["83952.2", "0.01787692", "0", "1"], ["83952", "0.04", "0", "1"], ["83951.7", "0.00001199", "0", "1"], ["83951.6", "0.0000559", "0", "1"], ["83951.5", "0.202515", "0", "2"], ["83951.4", "0.01190186", "0", "1"], ["83950.8", "0.01190196", "0", "1"], ["83950.1", "0.58749072", "0", "1"], ["83950", "0.01672", "0", "1"], ["83949.9", "0.00060645", "0", "1"], ["83949.8", "0.11889794", "0", "1"], ["83949.3", "0.01190193", "0", "1"], ["83949.2", "0.35719", "0", "1"], ["83948.2", "0.47569972", "0", "1"], ["83948.1", "0.17898725", "0", "1"], ["83948", "0.51886", "0", "1"], ["83947.5", "0.46910208", "0", "3"], ["83947.3", "0.00103791", "0", "1"], ["83947.2", "0.1", "0", "2"], ["83946.9", "0.045028", "0", "1"], ["83946.7", "0.00001199", "0", "1"], ["83946.4", "0.05", "0", "1"], ["83946.3", "0.55976", "0", "1"], ["83945.4", "0.17043797", "0", "1"], ["83944.8", "0.00011161", "0", "1"], ["83943.1", "0.24660501", "0", "2"], ["83941.8", "0.00001199", "0", "1"], ["83941.4", "0.11889794", "0", "1"], ["83941.3", "0.2025", "0", "1"], ["83940.5", "0.24999", "0", "1"], ["83940", "0.00001", "0", "1"], ["83939.5", "0.2128046", "0", "1"], ["83939.1", "0.3565323", "0", "1"], ["83938.8", "0.08935", "0", "1"], ["83938.3", "0.17898725", "0", "1"], ["83938", "0.00667544", "0", "3"], ["83937.1", "0.00946978", "0", "2"], ["83936.8", "0.00151199", "0", "2"], ["83936.7", "0.02383891", "0", "1"], ["83936.6", "0.00579952", "0", "1"], ["83936.1", "0.13547322", "0", "1"], ["83936", "0.12501", "0", "1"], ["83935.7", "0.00579972", "0", "1"], ["83935.4", "0.00579993", "0", "1"], ["83935.3", "0.00589951", "0", "1"], ["83934.7", "0.00001501", "0", "1"], ["83933.8", "0.01834601", "0", "1"], ["83933.7", "0.00579978", "0", "1"], ["83933.6", "0.00579952", "0", "1"], ["83933.3", "0.00504382", "0", "4"], ["83933.2", "0.08991011", "0", "1"], ["83932.9", "0.2025", "0", "1"], ["83932.1", "0.82587", "0", "1"], ["83931.9", "0.00001199", "0", "1"], ["83931.2", "0.00595319", "0", "1"], ["83931.1", "1.40955827", "0", "1"], ["83931", "3.33744268", "0", "2"], ["83930.9", "0.00589951", "0", "1"], ["83930.8", "0.00589978", "0", "1"], ["83930.7", "0.00579974", "0", "1"], ["83930.6", "0.3565323", "0", "1"], ["83930.1", "0.00595319", "0", "1"], ["83930", "0.20792", "0", "1"], ["83929.9", "0.00589974", "0", "1"], ["83929.6", "0.01185254", "0", "2"], ["83929.4", "0.17898725", "0", "1"], ["83929.3", "0.00579975", "0", "1"], ["83928.2", "0.00595319", "0", "1"], ["83928.1", "0.01189954", "0", "1"], ["83927.3", "0.0059528", "0", "1"], ["83927.2", "0.06417768", "0", "1"], ["83927", "0.04761845", "0", "1"], ["83926.9", "0.00596518", "0", "2"], ["83926.7", "0.01169927", "0", "2"], ["83926.3", "0.000015", "0", "1"], ["83925.7", "0.0059528", "0", "1"], ["83925.6", "0.11889794", "0", "1"], ["83925.2", "0.00011161", "0", "1"], ["83925", "0.0118528", "0", "2"], ["83924.9", "0.00579962", "0", "1"], ["83924.2", "0.00595302", "0", "1"], ["83924.1", "0.00589961", "0", "1"], ["83924", "0.00036", "0", "1"], ["83923.5", "1.02240445", "0", "1"], ["83923.2", "2.74032102", "0", "1"], ["83922.3", "0.01785957", "0", "3"], ["83922.2", "0.3565323", "0", "1"], ["83922", "0.00001199", "0", "1"], ["83921.6", "0.2025", "0", "1"], ["83920.2", "0.18478707", "0", "2"], ["83917.9", "0.00001501", "0", "1"], ["83917.4", "0.0046598", "0", "4"], ["83917.3", "0.05407121", "0", "1"], ["83917.2", "0.05961109", "0", "1"], ["83917", "0.00073199", "0", "2"], ["83916.7", "0.11889794", "0", "1"], ["83916.6", "0.00063636", "0", "2"], ["83916", "0.00036", "0", "1"], ["83914.4", "0.0058995", "0", "1"], ["83914.3", "0.0119079", "0", "2"], ["83914", "0.09045011", "0", "2"], ["83913.4", "0.06757", "0", "1"], ["83913.3", "0.37639802", "0", "2"], ["83913.2", "0.4", "0", "1"], ["83913", "0.36248681", "0", "2"], ["83912.3", "0.58226341", "0", "1"], ["83912.1", "0.00595451", "0", "1"], ["83912", "0.00001199", "0", "1"], ["83911.3", "0.0894", "0", "1"], ["83911.2", "0.50551914", "0", "2"], ["83911.1", "0.17898725", "0", "1"], ["83910.7", "0.10616225", "0", "1"], ["83910.6", "0.00579995", "0", "1"], ["83910.4", "0.00595451", "0", "1"], ["83910.2", "0.2123", "0", "2"], ["83910", "0.0000597", "0", "1"], ["83909.7", "0.00715054", "0", "1"], ["83909.5", "0.902485", "0", "2"], ["83909.2", "0.14301158", "0", "2"], ["83909", "0.00039889", "0", "2"], ["83908.1", "0.12479744", "0", "2"], ["83908", "0.00072", "0", "2"], ["83907.1", "0.000012", "0", "1"], ["83905.5", "0.00071491", "0", "3"], ["83905.3", "0.03575594", "0", "1"], ["83904.8", "0.38704093", "0", "2"], ["83904.4", "0.07963956", "0", "1"], ["83904.1", "0.00589951", "0", "1"], ["83904", "0.00036", "0", "1"], ["83903.9", "1.217394", "0", "1"], ["83903.7", "0.0057995", "0", "1"], ["83903.6", "0.08359223", "0", "1"], ["83903.5", "0.3565323", "0", "1"], ["83902.7", "0.02381132", "0", "1"], ["83902.1", "0.000012", "0", "1"], ["83901.9", "0.17843417", "0", "1"], ["83901.8", "0.2025", "0", "1"], ["83901.6", "0.00232244", "0", "1"], ["83901.1", "0.01192607", "0", "2"], ["83901", "0.00036", "0", "1"], ["83900.6", "0.00608323", "0", "2"], ["83900.5", "0.17898725", "0", "1"], ["83900", "0.00121483", "0", "4"], ["83899.9", "0.00101534", "0", "2"], ["83899.7", "0.11889794", "0", "1"], ["83899", "0.00036", "0", "1"], ["83898.3", "0.0057995", "0", "1"], ["83898.2", "0.00579995", "0", "1"], ["83898.1", "0.03", "0", "1"], ["83897.7", "0.06154772", "0", "2"], ["83897.6", "0.03", "0", "1"], ["83897.5", "0.183371", "0", "1"], ["83897.2", "0.000012", "0", "1"], ["83896", "0.00888617", "0", "2"], ["83894.4", "0.30589553", "0", "1"], ["83894.3", "0.35654428", "0", "2"], ["83893.9", "0.00213883", "0", "1"], ["83892.7", "0.00001501", "0", "1"], ["83892", "0.011699", "0", "2"], ["83891.9", "0.00579995", "0", "1"], ["83891.8", "0.17898725", "0", "1"], ["83891.7", "0.2025", "0", "1"], ["83891.5", "0.02381047", "0", "1"], ["83891.3", "0.11925902", "0", "1"], ["83890.9", "0.11889794", "0", "1"], ["83890.3", "0.00589948", "0", "1"], ["83890.2", "0.04681856", "0", "3"], ["83890.1", "0.03", "0", "1"], ["83889.1", "0.00579952", "0", "1"], ["83888.8", "0.00007596", "0", "1"], ["83888.3", "0.0007582", "0", "1"], ["83888", "0.00025", "0", "1"], ["83887.9", "0.01510585", "0", "1"], ["83887.7", "0.00005849", "0", "1"], ["83887.6", "0.00597332", "0", "1"], ["83887.3", "0.00001198", "0", "1"], ["83887", "0.08942", "0", "1"], ["83886.5", "0.22948164", "0", "1"], ["83886", "0.00928245", "0", "1"], ["83885.9", "0.00011161", "0", "1"], ["83885.6", "0.05300526", "0", "1"], ["83885.5", "3.71558", "0", "1"], ["83884.5", "0.3565323", "0", "1"], ["83884.3", "0.00001501", "0", "1"], ["83883.9", "0.05952007", "0", "2"], ["83883.3", "0.00060645", "0", "1"], ["83882.5", "0.17898725", "0", "1"], ["83882.4", "0.00001198", "0", "1"], ["83882", "0.00036", "0", "1"], ["83881.9", "0.03001198", "0", "2"], ["83880.5", "0.06", "0", "2"], ["83880.3", "0.00001072", "0", "1"], ["83880", "0.0000366", "0", "1"], ["83879.9", "0.2025", "0", "1"], ["83879.2", "0.00895999", "0", "1"], ["83877.4", "0.00017505", "0", "1"], ["83876.4", "0.00589928", "0", "1"], ["83876.2", "0.48621051", "0", "2"], ["83876.1", "0.3565323", "0", "1"], ["83875.9", "1.576495", "0", "2"], ["83875.8", "0.07166249", "0", "1"], ["83875.3", "0.000015", "0", "1"], ["83874.5", "0.05732575", "0", "1"], ["83874.1", "0.07165719", "0", "1"], ["83873.6", "0.00579953", "0", "1"], ["83873.4", "0.17898725", "0", "1"], ["83872.9", "0.214272", "0", "1"], ["83872.5", "0.00001198", "0", "1"], ["83870.8", "0.01194665", "0", "1"], ["83870.6", "0.08991011", "0", "1"], ["83869.6", "0.00001198", "0", "1"], ["83869.5", "0.0182", "0", "1"], ["83868.3", "0.2025", "0", "1"], ["83867.5", "0.000015", "0", "1"], ["83867.4", "0.3565323", "0", "1"], ["83866.7", "0.00005728", "0", "1"], ["83866.6", "0.12924617", "0", "11"], ["83866.2", "0.00011161", "0", "1"], ["83864.9", "0.17898725", "0", "1"], ["83864", "0.00002125", "0", "1"], ["83863.3", "0.00004163", "0", "1"], ["83863.2", "0.18346011", "0", "1"], ["83863.1", "0.00103791", "0", "1"], ["83862.6", "0.00001198", "0", "1"], ["83862.4", "0.01494332", "0", "2"], ["83860", "0.00036", "0", "1"], ["83859.8", "0.2025", "0", "1"], ["83859.2", "0.04468045", "0", "2"], ["83858.6", "0.00020004", "0", "1"], ["83858.3", "0.3565323", "0", "1"], ["83858.2", "0.00595302", "0", "1"], ["83858", "0.00036", "0", "1"], ["83857.6", "0.00001198", "0", "1"], ["83857.5", "0.00004084", "0", "1"], ["83857.3", "0.00001198", "0", "1"], ["83857.1", "0.00091322", "0", "4"], ["83857", "0.00036", "0", "1"], ["83856.6", "0.03", "0", "1"], ["83855.1", "0.17898725", "0", "1"], ["83854.7", "0.00168677", "0", "1"], ["83853.4", "0.00010118", "0", "1"], ["83853.3", "0.11889794", "0", "1"], ["83852.9", "0.08991011", "0", "1"], ["83852.8", "0.03", "0", "1"], ["83852.5", "0.00001059", "0", "1"], ["83852", "0.00036", "0", "1"], ["83851.3", "0.2025", "0", "1"], ["83851", "0.00044214", "0", "2"], ["83850.4", "0.00001302", "0", "1"], ["83850.2", "0.002382", "0", "1"], ["83850.1", "0.00002208", "0", "1"], ["83850", "0.0009247", "0", "5"], ["83849.9", "0.00419995", "0", "2"], ["83849.6", "0.36324874", "0", "3"], ["83849", "0.00017035", "0", "1"], ["83848.9", "1.72317698", "0", "2"], ["83848.4", "0.00017177", "0", "1"], ["83847.8", "0.00001319", "0", "1"], ["83847.7", "0.00001199", "0", "1"], ["83846.8", "0.00001004", "0", "1"], ["83846.7", "0.17898725", "0", "1"], ["83846.6", "0.00011161", "0", "1"], ["83846.1", "0.00002549", "0", "1"], ["83845", "0.00001198", "0", "1"], ["83844.8", "0.00005594", "0", "1"], ["83844.7", "0.00005731", "0", "1"], ["83844.6", "0.11889794", "0", "1"], ["83843.2", "0.00596", "0", "1"], ["83843", "0.00604583", "0", "2"], ["83842.9", "0.00001008", "0", "1"], ["83842.8", "0.2025", "0", "1"], ["83842.4", "0.00003928", "0", "2"], ["83842.1", "0.03006538", "0", "2"], ["83842", "0.00018", "0", "1"], ["83841.9", "0.0008232", "0", "1"], ["83841.4", "0.01797745", "0", "6"], ["83840.7", "0.35776874", "0", "1"], ["83840", "0.00029869", "0", "2"], ["83839.9", "0.00007308", "0", "1"], ["83839", "0.00001308", "0", "1"], ["83838.8", "0.00002989", "0", "1"], ["83838.3", "0.17998725", "0", "2"], ["83838", "0.0015", "0", "1"], ["83837.8", "0.00001199", "0", "1"], ["83837.5", "0.06", "0", "2"], ["83837.2", "0.00003224", "0", "1"], ["83836.6", "0.00003296", "0", "1"], ["83836.5", "0.00012802", "0", "1"], ["83835.4", "0.00103978", "0", "1"], ["83834.6", "3.22865", "0", "1"], ["83834.5", "0.11889794", "0", "1"], ["83834.4", "0.2025", "0", "1"], ["83834", "0.00013099", "0", "1"], ["83833.6", "0.0284", "0", "2"], ["83833.5", "0.0142", "0", "1"], ["83833.3", "0.0359514", "0", "12"], ["83833.2", "0.000015", "0", "1"], ["83832.9", "0.00001756", "0", "1"], ["83832.1", "0.35776874", "0", "1"], ["83831", "0.00004167", "0", "1"], ["83830.6", "0.0142", "0", "1"], ["83830", "0.00005835", "0", "2"], ["83829.9", "0.17901312", "0", "2"], ["83828.7", "0.01148", "0", "1"], ["83827.7", "0.10411011", "0", "2"], ["83827.5", "0.04971356", "0", "1"], ["83827", "0.00011161", "0", "1"], ["83826.5", "0.00040898", "0", "2"], ["83826.3", "0.07157653", "0", "1"], ["83826.1", "0.00015468", "0", "1"], ["83826", "0.2025", "0", "1"], ["83825.9", "0.00001586", "0", "1"], ["83825.4", "0.00001365", "0", "1"], ["83825.1", "0.0166188", "0", "1"], ["83825", "0.00008012", "0", "2"], ["83824.2", "0.20833794", "0", "2"], ["83823.6", "0.35776874", "0", "1"], ["83823.5", "0.00039533", "0", "1"], ["83823.4", "6.63755725", "0", "1"], ["83823", "0.00001199", "0", "1"]], "ts": "1742577042900", "checksum": 46565047, "seqId": 49944983280, "prevSeqId": -1}], "record_time": 1742577043.074777, "EXCHANGE": "OKX"}
{"arg": {"channel": "books", "instId": "BTC-USDT"}, "action": "update", "data": [{"asks": [["83982.1", "0.75087832", "0", "10"], ["83982.3", "0.754962", "0", "5"], ["83982.4", "1.44613734", "0", "7"], ["83984", "0.0439", "0", "1"], ["83984.2", "0.07493", "0", "1"], ["83985.1", "0.0102", "0", "1"], ["83986", "0.0439", "0", "1"], ["83986.1", "0.1", "0", "1"], ["83986.6", "0.4224477", "0", "6"], ["83987.3", "0.03062", "0", "1"], ["83990.9", "0", "0", "0"], ["83991.7", "0", "0", "0"], ["83999.9", "0.00060645", "0", "1"], ["84003.7", "0.00011161", "0", "1"], ["84006", "0", "0", "0"], ["84008", "0.01191011", "0", "1"], ["84008.7", "0", "0", "0"], ["84012.6", "0.09807051", "0", "1"], ["84016.5", "0.23826314", "0", "1"], ["84017.7", "0.63007494", "0", "2"], ["84140", "0.00031221", "0", "2"], ["84141.1", "0", "0", "0"], ["84141.2", "0", "0", "0"], ["84141.3", "0", "0", "0"], ["84141.4", "0", "0", "0"], ["84141.9", "0", "0", "0"], ["84142", "0", "0", "0"], ["84142.1", "0", "0", "0"]], "bids": [["83986.5", "0", "0", "0"], ["83984.1", "0", "0", "0"], ["83983.9", "0", "0", "0"], ["83983.3", "0", "0", "0"], ["83982.3", "0", "0", "0"], ["83982", "0.0932", "0", "2"], ["83975.8", "0.22187555", "0", "2"], ["83972.3", "0.00006", "0", "1"], ["83971.4", "0.04", "0", "1"], ["83968.7", "0", "0", "0"], ["83967", "0.01389", "0", "1"], ["83961.9", "0.21113", "0", "2"], ["83960.7", "0.06998988", "0", "2"], ["83959.8", "0.00714628", "0", "1"], ["83958.5", "0", "0", "0"], ["83956.3", "0.23826314", "0", "1"], ["83952.8", "0", "0", "0"], ["83952", "0.08", "0", "2"], ["83951.2", "0.04", "0", "1"], ["83947.2", "0", "0", "0"], ["83946.4", "0.1", "0", "2"], ["83945.6", "0.05", "0", "1"], ["83941", "0.12502", "0", "1"], ["83913.5", "0.00595363", "0", "1"], ["83841.9", "0", "0", "0"], ["83828.6", "0.0008232", "0", "1"], ["83822.5", "0.00003465", "0", "2"], ["83822.4", "0.00001007", "0", "1"]], "ts": "1742577043000", "checksum": 1489299042, "seqId": 49944983486, "prevSeqId": 49944983280}], "record_time": 1742577043.172313, "EXCHANGE": "OKX"}
{"arg": {"channel": "books", "instId": "BTC-USDT"}, "action": "update", "data": [{"asks": [["83982.1", "0.28941483", "0", "8"], ["83982.2", "0.11848161", "0", "1"], ["83982.3", "0.00111979", "0", "1"], ["83982.4", "0", "0", "0"], ["83984.1", "0.01191377", "0", "1"], ["83984.2", "0", "0", "0"], ["83985.1", "0", "0", "0"], ["83987.3", "0", "0", "0"], ["83988.4", "0.05789574", "0", "2"], ["83988.5", "0.052", "0", "2"], ["83990.6", "0.0429033", "0", "2"], ["84005.4", "0.17373781", "0", "1"], ["84008.6", "0.67390501", "0", "1"], ["84009.4", "0.01190343", "0", "1"], ["84011.2", "0.23826264", "0", "1"], ["84016.5", "0", "0", "0"], ["84026.9", "0.1", "0", "1"], ["84030.8", "0.00104515", "0", "2"], ["84031.1", "0", "0", "0"], ["84037.4", "0.35800958", "0", "2"], ["84042", "0", "0", "0"], ["84044.3", "0", "0", "0"], ["84049.4", "0.000015", "0", "1"], ["84094.6", "0.1", "0", "1"], ["84113.6", "0", "0", "0"], ["84115.1", "0", "0", "0"], ["84141.1", "0.00005109", "0", "1"], ["84141.2", "0.00011161", "0", "1"], ["84141.3", "0.00083", "0", "1"], ["84141.4", "0.08762", "0", "1"]], "bids": [["83982", "0.39792161", "0", "6"], ["83976.6", "1", "0", "1"], ["83975.4", "0", "0", "0"], ["83973.7", "0.00056059", "0", "1"], ["83959.8", "0", "0", "0"], ["83951.2", "0.0408", "0", "3"], ["83950.4", "0.0004", "0", "1"], ["83946.4", "0", "0", "0"], ["83945.6", "0.1", "0", "2"], ["83944.8", "0.05011161", "0", "2"], ["83917.4", "0.13128758", "0", "3"], ["83917.3", "0.25005", "0", "1"], ["83914.5", "0.00695979", "0", "2"], ["83914.4", "0.00735173", "0", "2"], ["83913.5", "0.01190728", "0", "2"], ["83832.6", "0.00001199", "0", "1"], ["83822.5", "0", "0", "0"], ["83822.4", "0", "0", "0"]], "ts": "1742577043100", "checksum": 1199465162, "seqId": 49944983586, "prevSeqId": 49944983486}], "record_time": 1742577043.272536, "EXCHANGE": "OKX"}
{"arg": {"channel": "books", "instId": "BTC-USDT"}, "action": "update", "data": [{"asks": [["83982.1", "0.41655841", "0", "8"], ["83989.4", "0.0102", "0", "1"], ["83995.7", "0.03062", "0", "1"], ["84019.7", "0", "0", "0"], ["84026.4", "0.08", "0", "2"], ["84026.6", "0.36238", "0", "2"], ["84026.9", "0", "0", "0"], ["84027.2", "0.03999999", "0", "1"], ["84051.2", "0.00595319", "0", "1"], ["84052", "0.0015", "0", "1"], ["84141.3", "0", "0", "0"], ["84141.4", "0", "0", "0"]], "bids": [["83982", "0.44386519", "0", "8"], ["83981.9", "0.06951308", "0", "1"], ["83979.1", "0", "0", "0"], ["83975.4", "0.01388", "0", "1"], ["83974.8", "0.00773974", "0", "1"], ["83967", "0", "0", "0"], ["83960.7", "0.02831988", "0", "1"], ["83958.6", "0", "0", "0"], ["83958.5", "0.01774536", "0", "1"], ["83958.4", "0.0000595", "0", "1"], ["83949.2", "0", "0", "0"], ["83917.4", "0.05408621", "0", "2"], ["83917.3", "0", "0", "0"], ["83914.5", "0.0091461", "0", "3"], ["83832.9", "0.00002955", "0", "2"], ["83822.5", "0.00003465", "0", "2"]], "ts": "1742577043200", "checksum": 1977441636, "seqId": 49944983623, "prevSeqId": 49944983586}], "record_time": 1742577043.377798, "EXCHANGE": "OKX"}
{"arg": {"channel": "books", "instId": "BTC-USDT"}, "action": "update", "data": [{"asks": [["83982.1", "0.42535841", "0", "10"], ["83982.2", "0.17217418", "0", "2"], ["84002.1", "0.35722", "0", "1"], ["84009.4", "0", "0", "0"], ["84010.2", "0.01190332", "0", "1"], ["84026.4", "0.07999999", "0", "2"], ["84039.7", "0.00002157", "0", "1"], ["84043.9", "0", "0", "0"], ["84141.2", "0", "0", "0"]], "bids": [["83982", "0.10805319", "0", "4"], ["83980", "0.04391", "0", "2"], ["83975.4", "0", "0", "0"], ["83970.4", "0.32848432", "0", "2"], ["83969.3", "0.35722", "0", "1"], ["83969.1", "0.04167", "0", "1"], ["83967.8", "0.17861", "0", "1"], ["83966.3", "0.30646496", "0", "1"], ["83961.5", "0.26546878", "0", "1"], ["83953.3", "1.01541619", "0", "2"], ["83952", "0", "0", "0"], ["83951.2", "0.0808", "0", "4"], ["83950.4", "0.0404", "0", "2"], ["83900.6", "0.0058995", "0", "1"], ["83896.1", "0.00018373", "0", "1"], ["83885.6", "0.20605102", "0", "2"], ["83876.2", "0.11889794", "0", "1"], ["83823", "0", "0", "0"], ["83822.5", "0", "0", "0"]], "ts": "1742577043300", "checksum": 1560708219, "seqId": 49944983663, "prevSeqId": 49944983623}], "record_time": 1742577043.472888, "EXCHANGE": "OKX"}
{"arg": {"channel": "books", "instId": "BTC-USDT"}, "action": "update", "data": [{"asks": [["83982.1", "0.44258979", "0", "9"], ["83986.6", "0.41091532", "0", "5"], ["83993.1", "0.01153238", "0", "1"], ["84000.6", "0.0502", "0", "2"], ["84141.1", "0", "0", "0"]], "bids": [["83982", "0.31239717", "0", "6"], ["83973.8", "0.01389", "0", "1"], ["83966.1", "0.31382725", "0", "2"], ["83958.5", "0", "0", "0"], ["83958.4", "0.01780486", "0", "2"], ["83827.3", "0.00621597", "0", "1"], ["83823.4", "0", "0", "0"]], "ts": "1742577043400", "checksum": 564606895, "seqId": 49944983680, "prevSeqId": 49944983663}], "record_time": 1742577043.575459, "EXCHANGE": "OKX"}
{"arg": {"channel": "books", "instId": "BTC-USDT"}, "action": "update", "data": [{"asks": [["83982.1", "0.64258979", "0", "10"], ["83982.2", "0.11848161", "0", "1"], ["83984.6", "0.11912674", "0", "1"], ["83986.3", "0.0102", "0", "1"], ["83986.6", "0.09179155", "0", "3"], ["83989.4", "0", "0", "0"], ["83991", "0.08262", "0", "3"], ["83995.7", "0", "0", "0"]], "bids": [["83982", "0.30359717", "0", "5"], ["83978", "0.0439", "0", "1"], ["83975.7", "0.016", "0", "1"], ["83973.8", "0", "0", "0"], ["83969.1", "0", "0", "0"], ["83964.4", "0.04178161", "0", "2"], ["83823.4", "6.63755725", "0", "1"]], "ts": "1742577043500", "checksum": -225136608, "seqId": 49944983720, "prevSeqId": 49944983680}], "record_time": 1742577043.672997, "EXCHANGE": "OKX"}
{"arg": {"channel": "books", "instId": "BTC-USDT"}, "action": "update", "data": [{"asks": [["83982.1", "0.84508979", "0", "11"], ["83991.2", "0.00001199", "0", "1"], ["84008.6", "0.27844161", "0", "1"], ["84011.9", "0", "0", "0"], ["84033.9", "0.49431247", "0", "1"], ["84034", "0.052", "0", "2"]], "bids": [["83982", "0.10002875", "0", "4"], ["83970.2", "0.00352117", "0", "1"], ["83968.7", "0.01389", "0", "1"], ["83959.3", "0.25005", "0", "1"], ["83953.3", "0.61578169", "0", "1"], ["83953.2", "0", "0", "0"], ["83950.2", "0.56", "0", "1"], ["83930.8", "0.01589978", "0", "2"], ["83924.9", "0.06579962", "0", "3"], ["83923.5", "0.22850728", "0", "1"], ["83923.2", "0", "0", "0"], ["83885.6", "0.9039765", "0", "1"], ["83823.5", "0", "0", "0"], ["83823.4", "0", "0", "0"]], "ts": "1742577043600", "checksum": -1063295407, "seqId": 49944983744, "prevSeqId": 49944983720}], "record_time": 1742577043.772651, "EXCHANGE": "OKX"}
{"arg": {"channel": "books", "instId": "BTC-USDT"}, "action": "update", "data": [{"asks": [["83983.6", "0.0102", "0", "1"], ["83986.3", "0", "0", "0"], ["84008.6", "0.732974", "0", "2"], ["84009.6", "1.63112531", "0", "1"], ["84018.4", "0.0008", "0", "2"], ["84019.2", "0.01230205", "0", "2"], ["84038.5", "1.05536046", "0", "2"], ["84039.6", "3.02169239", "0", "1"], ["84044", "0.10180864", "0", "2"], ["84044.8", "0", "0", "0"], ["84138.8", "0", "0", "0"], ["84140", "0", "0", "0"]], "bids": [["83958.4", "0.0000595", "0", "1"], ["83953.3", "0.90191726", "0", "2"], ["83953.2", "1.61378784", "0", "1"], ["83923.5", "1.04960902", "0", "2"], ["83923.2", "2.83221718", "0", "1"], ["83911.2", "0.40551914", "0", "1"], ["83885.6", "0", "0", "0"], ["83823.6", "0", "0", "0"]], "ts": "1742577043700", "checksum": -671249001, "seqId": 49944983776, "prevSeqId": 49944983744}], "record_time": 1742577043.872057, "EXCHANGE": "OKX"}
{"arg": {"channel": "books", "instId": "BTC-USDT"}, "action": "update", "data": [{"asks": [["83982.1", "0.64258979", "0", "10"]], "bids": [["83982", "0.18662875", "0", "5"]], "ts": "1742577043800", "checksum": -1448679758, "seqId": 49944983779, "prevSeqId": 49944983776}], "record_time": 1742577043.972139, "EXCHANGE": "OKX"}
{"arg": {"channel": "books", "instId": "BTC-USDT"}, "action": "update", "data": [{"asks": [], "bids": [["83982", "0.10002875", "0", "4"], ["83962.6", "0", "0", "0"], ["83958.4", "0.01774536", "0", "1"], ["83954.2", "0", "0", "0"], ["83823.6", "0.35776874", "0", "1"], ["83823.5", "0.00039533", "0", "1"]], "ts": "1742577043900", "checksum": 116791266, "seqId": 49944983786, "prevSeqId": 49944983779}], "record_time": 1742577044.072277, "EXCHANGE": "OKX"}
{"arg": {"channel": "books", "instId": "BTC-USDT"}, "action": "update", "data": [{"asks": [["83982.1", "0.64508979", "0", "10"], ["83983.6", "0", "0", "0"], ["83986.1", "0.1102", "0", "2"], ["84010.3", "0.4132584", "0", "2"], ["84062.9", "0.05628489", "0", "1"], ["84138.8", "0.00044981", "0", "1"]], "bids": [["83968.7", "0", "0", "0"], ["83946", "0.01155008", "0", "1"], ["83941.8", "0.00578703", "0", "2"], ["83937.6", "0.00577504", "0", "1"], ["83823.5", "0", "0", "0"]], "ts": "1742577044000", "checksum": 1565340907, "seqId": 49944983820, "prevSeqId": 49944983786}], "record_time": 1742577044.173581, "EXCHANGE": "OKX"}
{"arg": {"channel": "books", "instId": "BTC-USDT"}, "action": "update", "data": [{"asks": [["83982.1", "0.47787979", "0", "10"], ["84011.2", "0", "0", "0"], ["84012.5", "0.23826083", "0", "1"], ["84037.2", "0.00002157", "0", "1"], ["84039.7", "0", "0", "0"], ["84051.4", "0", "0", "0"], ["84054.3", "0.01125183", "0", "1"]], "bids": [["83982", "0.18662875", "0", "5"], ["83967.8", "0", "0", "0"], ["83957.1", "0.23826093", "0", "1"], ["83956.3", "0", "0", "0"], ["83937.2", "0.01834609", "0", "1"], ["83933.8", "0", "0", "0"], ["83914.4", "0.0058995", "0", "1"], ["83914.1", "0.00145211", "0", "1"], ["83898.2", "0.02652452", "0", "2"], ["83897.7", "0", "0", "0"], ["83897.5", "0", "0", "0"], ["83896.1", "0", "0", "0"], ["83894", "0.00018364", "0", "1"], ["83865", "0.18346099", "0", "1"], ["83864.9", "0.36236025", "0", "2"], ["83863.2", "0", "0", "0"], ["83823.5", "0.00039533", "0", "1"], ["83823.4", "6.63755725", "0", "1"]], "ts": "1742577044100", "checksum": 797041258, "seqId": 49944983873, "prevSeqId": 49944983820}], "record_time": 1742577044.272633, "EXCHANGE": "OKX"}
{"arg": {"channel": "books", "instId": "BTC-USDT"}, "action": "update", "data": [{"asks": [["83982.1", "0.43528079", "0", "8"], ["83982.2", "0.08004753", "0", "1"], ["83984.1", "0", "0", "0"], ["83984.6", "0", "0", "0"], ["83986.1", "0.1", "0", "1"], ["83986.4", "0.01191342", "0", "1"], ["83986.6", "0.05579155", "0", "2"], ["83987.9", "0.08192869", "0", "1"], ["83988.4", "0", "0", "0"], ["83988.6", "0.0102", "0", "1"], ["84012.5", "0", "0", "0"], ["84012.6", "0.15728954", "0", "2"], ["84013.1", "0.25425949", "0", "2"], ["84018.4", "0", "0", "0"], ["84019.2", "0.01270205", "0", "3"], ["84020", "0.0004", "0", "1"], ["84140", "0.00031221", "0", "2"]], "bids": [["83982", "0.45234075", "0", "8"], ["83978.1", "0.39103678", "0", "1"], ["83978", "1.0439", "0", "2"], ["83977.5", "0", "0", "0"], ["83976.6", "0", "0", "0"], ["83974.6", "0.37086351", "0", "2"], ["83961.5", "0.41054727", "0", "2"], ["83958.4", "0.25600485", "0", "2"], ["83957.1", "0", "0", "0"], ["83882.9", "0.07165719", "0", "1"], ["83874.1", "0", "0", "0"], ["83823", "0.00001199", "0", "1"], ["83822.5", "0.00003465", "0", "2"]], "ts": "1742577044200", "checksum": -726379683, "seqId": 49944983915, "prevSeqId": 49944983873}], "record_time": 1742577044.378226, "EXCHANGE": "OKX"}
{"arg": {"channel": "books", "instId": "BTC-USDT"}, "action": "update", "data": [{"asks": [["84026.4", "0", "0", "0"], ["84027.2", "0.07999999", "0", "2"], ["84028", "0.15889793", "0", "2"], ["84141.1", "0.00005109", "0", "1"]], "bids": [["83957.7", "0.7648194", "0", "1"], ["83955", "0.2", "0", "1"], ["83954", "1", "0", "1"], ["83950.2", "0", "0", "0"], ["83913.2", "0", "0", "0"], ["83894.4", "0", "0", "0"], ["83822.4", "0.00001007", "0", "1"]], "ts": "1742577044300", "checksum": -726379683, "seqId": 49944983932, "prevSeqId": 49944983915}], "record_time": 1742577044.472427, "EXCHANGE": "OKX"}
{"arg": {"channel": "books", "instId": "BTC-USDT"}, "action": "update", "data": [{"asks": [["83988.2", "0.11912158", "0", "1"], ["84002", "0.119758", "0", "5"], ["84012.5", "0.23826016", "0", "1"], ["84012.6", "0.09807051", "0", "1"], ["84013.1", "0.016", "0", "1"], ["84134.1", "0.24119", "0", "2"], ["84140", "0", "0", "0"], ["84141.1", "0", "0", "0"]], "bids": [["83978", "0.0439", "0", "1"], ["83976.3", "1", "0", "1"], ["83958.4", "0.01774536", "0", "1"], ["83957.1", "0.23826016", "0", "1"], ["83822.5", "0", "0", "0"], ["83822.4", "0", "0", "0"]], "ts": "1742577044400", "checksum": 669202661, "seqId": 49944983945, "prevSeqId": 49944983932}], "record_time": 1742577044.579619, "EXCHANGE": "OKX"}
{"arg": {"channel": "books", "instId": "BTC-USDT"}, "action": "update", "data": [{"asks": [["83982.1", "0.80228079", "0", "12"], ["83982.2", "0.05004743", "0", "1"], ["83983.7", "0.0102", "0", "1"], ["83986.1", "0.11912451", "0", "1"], ["83986.4", "0", "0", "0"], ["83988.2", "0", "0", "0"], ["83988.6", "0", "0", "0"], ["83993.5", "0.13312256", "0", "2"], ["83995.4", "0.11889794", "0", "1"], ["83998.4", "0.01191148", "0", "1"], ["84000.2", "0.39437829", "0", "1"], ["84005.5", "0.03", "0", "1"], ["84008", "0", "0", "0"], ["84008.1", "0.23826811", "0", "1"], ["84009.8", "0", "0", "0"], ["84012.5", "0", "0", "0"], ["84017.7", "0.28756719", "0", "1"], ["84018", "0.08991011", "0", "1"], ["84026.4", "0.08", "0", "2"], ["84027.2", "0.03999999", "0", "1"], ["84028", "0.11889794", "0", "1"], ["84065.6", "0.4953846", "0", "3"], ["84074.1", "0.07136569", "0", "1"], ["84078.4", "0", "0", "0"], ["84140", "0.00031221", "0", "2"]], "bids": [["83982", "0.00682921", "0", "2"], ["83981.9", "0", "0", "0"], ["83981.8", "0", "0", "0"], ["83980.1", "0.06204124", "0", "2"], ["83979.6", "0.1191336", "0", "1"], ["83979", "0.05628489", "0", "1"], ["83978.1", "0.08623678", "0", "1"], ["83976.3", "0", "0", "0"], ["83975.7", "0", "0", "0"], ["83974.7", "0.42340749", "0", "2"], ["83974.6", "0.35697351", "0", "1"], ["83973.9", "1", "0", "1"], ["83973.6", "0", "0", "0"], ["83971.4", "0", "0", "0"], ["83970.3", "0", "0", "0"], ["83969.3", "0", "0", "0"], ["83966.8", "0.04", "0", "1"], ["83964.6", "0.000015", "0", "1"], ["83961.5", "0.41531136", "0", "3"], ["83961.2", "0.14071224", "0", "1"], ["83957.8", "0.31", "0", "1"], ["83957.1", "0", "0", "0"], ["83957", "0", "0", "0"], ["83951.6", "0.23832401", "0", "2"], ["83937", "0.05628489", "0", "1"], ["83935.4", "0", "0", "0"], ["83909.2", "0.07150579", "0", "1"], ["83894", "0", "0", "0"], ["83882.9", "0", "0", "0"], ["83879.3", "0.00579996", "0", "1"], ["83822.5", "0.00003465", "0", "2"], ["83822.4", "0.00001007", "0", "1"], ["83822.2", "0.00299792", "0", "1"], ["83822", "0.00001994", "0", "1"], ["83821.8", "0.00033901", "0", "2"], ["83821.5", "0.17898725", "0", "1"]], "ts": "1742577044500", "checksum": -594338337, "seqId": 49944984077, "prevSeqId": 49944983945}], "record_time": 1742577044.673523, "EXCHANGE": "OKX"}
{"arg": {"channel": "books", "instId": "BTC-USDT"}, "action": "update", "data": [{"asks": [["83982.1", "0.59978079", "0", "11"], ["83982.2", "0.07595483", "0", "2"], ["83984", "0.05581376", "0", "2"], ["83986.9", "0.0428883", "0", "1"], ["83990.6", "0.000015", "0", "1"], ["83992.5", "0.02", "0", "1"], ["83995.6", "0.2185", "0", "2"], ["84000.2", "0.24804234", "0", "1"], ["84000.5", "0", "0", "0"], ["84002.1", "0", "0", "0"], ["84008.1", "0.23827008", "0", "1"], ["84074.1", "0.14273138", "0", "2"]], "bids": [["83982", "0.05612921", "0", "3"], ["83970.4", "0.23251263", "0", "1"], ["83970.2", "0", "0", "0"], ["83966.3", "0.42189615", "0", "2"], ["83965.3", "0.17861", "0", "1"], ["83951.6", "0.23832598", "0", "2"], ["83951.5", "0.21441876", "0", "3"], ["83951.2", "0.08", "0", "2"], ["83950.4", "0.0408", "0", "3"], ["83949.6", "0.0004", "0", "1"], ["83946", "0", "0", "0"], ["83945.6", "0", "0", "0"], ["83944.8", "0.10011161", "0", "3"], ["83944", "0.05", "0", "1"], ["83941.8", "0.00001199", "0", "1"], ["83937.6", "0", "0", "0"], ["83928.1", "0", "0", "0"], ["83909.2", "0.14301158", "0", "2"], ["83894", "0.00018361", "0", "1"], ["83820.2", "0.00083", "0", "1"]], "ts": "1742577044600", "checksum": -1669030293, "seqId": 49944984145, "prevSeqId": 49944984077}], "record_time": 1742577044.772569, "EXCHANGE": "OKX"}
{"arg": {"channel": "books", "instId": "BTC-USDT"}, "action": "update", "data": [{"asks": [["83982.1", "0.60998079", "0", "12"], ["83983.7", "0", "0", "0"], ["84008.1", "0", "0", "0"], ["84011.2", "0.23826473", "0", "1"], ["84016.5", "0.00035881", "0", "1"], ["84019.3", "0.01190203", "0", "1"], ["84045.4", "0", "0", "0"], ["84048.5", "0", "0", "0"], ["84053.3", "0", "0", "0"], ["84141.1", "0.00005109", "0", "1"], ["84141.2", "0.00011161", "0", "1"]], "bids": [["83975.8", "0.17898725", "0", "1"], ["83972.3", "0.0429483", "0", "2"], ["83967.8", "0.01389", "0", "1"], ["83955.1", "0.23826473", "0", "1"], ["83951.6", "0.0000559", "0", "1"], ["83951.2", "0", "0", "0"], ["83950.4", "0.0808", "0", "4"], ["83949.6", "0.0404", "0", "2"], ["83945.9", "0.00005952", "0", "1"], ["83941.7", "0.00005952", "0", "1"], ["83937.5", "0.00005952", "0", "1"], ["83843", "0.00596352", "0", "1"], ["83836.1", "0.00008231", "0", "1"], ["83822.2", "0", "0", "0"], ["83822", "0", "0", "0"], ["83821.8", "0", "0", "0"], ["83821.5", "0", "0", "0"], ["83820.2", "0", "0", "0"]], "ts": "1742577044700", "checksum": 529253420, "seqId": 49944984175, "prevSeqId": 49944984145}], "record_time": 1742577044.873861, "EXCHANGE": "OKX"}
{"arg": {"channel": "books", "instId": "BTC-USDT"}, "action": "update", "data": [{"asks": [["83982.1", "0.81248079", "0", "13"], ["83996.9", "0.25210618", "0", "1"], ["83997", "0.35722", "0", "1"], ["83998.3", "0", "0", "0"], ["84042.6", "0.01155008", "0", "1"], ["84141.1", "0", "0", "0"], ["84141.2", "0", "0", "0"]], "bids": [["83978.1", "0.36259069", "0", "2"], ["83975.3", "1", "0", "1"], ["83974.7", "0.14103713", "0", "1"], ["83973.9", "0", "0", "0"], ["83964.3", "0.35722", "0", "1"], ["83915", "0.12503", "0", "1"], ["83822.5", "0", "0", "0"], ["83822.4", "0", "0", "0"]], "ts": "1742577044800", "checksum": 882535417, "seqId": 49944984192, "prevSeqId": 49944984175}], "record_time": 1742577044.977045, "EXCHANGE": "OKX"}
{"arg": {"channel": "books", "instId": "BTC-USDT"}, "action": "update", "data": [{"asks": [["83998", "0.22251", "0", "2"], ["84008.1", "0.23826963", "0", "1"], ["84011.2", "0", "0", "0"], ["84064.4", "0.0184002", "0", "1"], ["84065.6", "0.47156999", "0", "2"], ["84089.9", "0.1", "0", "1"], ["84138.8", "0", "0", "0"], ["84140", "0", "0", "0"]], "bids": [["83982", "0.00682921", "0", "2"], ["83980.1", "0", "0", "0"], ["83980", "0.00001", "0", "1"], ["83978.1", "0.08623678", "0", "1"], ["83975.3", "0", "0", "0"], ["83974.7", "0.43627398", "0", "2"], ["83973.7", "1.00056059", "0", "2"], ["83969.9", "0", "0", "0"], ["83963.4", "0.05956073", "0", "1"], ["83955.1", "0", "0", "0"], ["83953.7", "0.17861", "0", "1"], ["83951.6", "0.23832553", "0", "2"], ["83915.1", "0.00100616", "0", "1"], ["83914.5", "0.00813996", "0", "2"], ["83877", "0.1", "0", "1"]], "ts": "1742577044900", "checksum": 762767923, "seqId": 49944984226, "prevSeqId": 49944984192}], "record_time": 1742577045.07258, "EXCHANGE": "OKX"}
{"arg": {"channel": "books", "instId": "BTC-USDT"}, "action": "update", "data": [{"asks": [["83982.1", "0.60998079", "0", "12"], ["83993.1", "0", "0", "0"], ["84017.6", "0.01190227", "0", "1"], ["84026.4", "0.07999999", "0", "2"], ["84049.1", "0", "0", "0"], ["84101.2", "0", "0", "0"], ["84104.2", "0", "0", "0"], ["84138.8", "0.00044981", "0", "1"], ["84140", "0.00031221", "0", "2"], ["84141.1", "0.00005109", "0", "1"]], "bids": [["83982", "0.14517398", "0", "5"], ["83980", "0.04391", "0", "2"], ["83978.1", "0.36259069", "0", "2"], ["83975", "1", "0", "1"], ["83974.7", "0.14103713", "0", "1"], ["83973.7", "0.00056059", "0", "1"], ["83964.3", "0", "0", "0"], ["83920.1", "0.09158922", "0", "1"], ["83920", "0.12503", "0", "1"], ["83917.4", "0.000015", "0", "1"], ["83823.4", "0", "0", "0"], ["83823", "0", "0", "0"]], "ts": "1742577045000", "checksum": -1630625530, "seqId": 49944984249, "prevSeqId": 49944984226}], "record_time": 1742577045.173708, "EXCHANGE": "OKX"}
{"arg": {"channel": "books", "instId": "BTC-USDT"}, "action": "update", "data": [{"asks": [["83982.1", "0.81248079", "0", "13"], ["83998", "0.23404238", "0", "3"], ["84001.2", "0.17839", "0", "1"], ["84008.1", "0", "0", "0"], ["84010.2", "0.25016923", "0", "2"], ["84018.5", "0.15261439", "0", "2"], ["84019.1", "0.1308", "0", "2"], ["84044", "0.08991011", "0", "1"], ["84044.6", "0", "0", "0"], ["84141.2", "0.00011161", "0", "1"]], "bids": [["83982", "0.06024655", "0", "5"], ["83973.2", "0", "0", "0"], ["83964.3", "0.35722", "0", "1"], ["83955.1", "0.23826591", "0", "1"], ["83951.6", "0.0000559", "0", "1"], ["83951.5", "0.21450389", "0", "4"], ["83947.7", "0.01190215", "0", "1"], ["83823.6", "0", "0", "0"], ["83823.5", "0", "0", "0"]], "ts": "1742577045100", "checksum": 731607238, "seqId": 49944984269, "prevSeqId": 49944984249}], "record_time": 1742577045.272823, "EXCHANGE": "OKX"}
{"arg": {"channel": "books", "instId": "BTC-USDT"}, "action": "update", "data": [{"asks": [["84010.2", "0.01190332", "0", "1"], ["84011.2", "0.23826608", "0", "1"], ["84141.2", "0", "0", "0"]], "bids": [["83975.5", "1", "0", "1"], ["83975", "0", "0", "0"], ["83964.3", "0", "0", "0"], ["83955.1", "0.23826608", "0", "1"], ["83953.7", "0", "0", "0"], ["83924.7", "0.03", "0", "1"], ["83823.6", "0.35776874", "0", "1"]], "ts": "1742577045200", "checksum": -625068126, "seqId": 49944984292, "prevSeqId": 49944984269}], "record_time": 1742577045.371899, "EXCHANGE": "OKX"}
{"arg": {"channel": "books", "instId": "BTC-USDT"}, "action": "update", "data": [{"asks": [["83982.1", "0.57732417", "0", "10"], ["83991", "0.052", "0", "2"], ["83995.5", "0.06662", "0", "2"], ["84011.2", "0", "0", "0"], ["84016.5", "0.238618", "0", "2"], ["84024.3", "0", "0", "0"], ["84031.9", "0.06155339", "0", "1"], ["84141.2", "0.00011161", "0", "1"]], "bids": [["83982", "0.58487641", "0", "9"], ["83981.7", "0.11913065", "0", "1"], ["83979.6", "0", "0", "0"], ["83976.9", "1", "0", "1"], ["83975.5", "0", "0", "0"], ["83970", "0.01389", "0", "1"], ["83969.3", "0.00363264", "0", "1"], ["83968.9", "0.04167", "0", "1"], ["83967.8", "0", "0", "0"], ["83964.4", "0.00011161", "0", "1"], ["83964.3", "0.35722", "0", "1"], ["83959.1", "0.23825988", "0", "1"], ["83955.1", "0", "0", "0"], ["83953.3", "0.61578169", "0", "1"], ["83950.4", "0", "0", "0"], ["83950.1", "0", "0", "0"], ["83949.6", "0", "0", "0"], ["83948.8", "0.0808", "0", "4"], ["83948", "0.55926", "0", "3"], ["83944.8", "0.00011161", "0", "1"], ["83944", "0", "0", "0"], ["83943.2", "0.1", "0", "2"], ["83942.4", "0.05", "0", "1"], ["83931.9", "0.57761466", "0", "2"], ["83894.4", "0.08399522", "0", "1"], ["83825", "0", "0", "0"], ["83824.2", "0", "0", "0"], ["83823.6", "0", "0", "0"]], "ts": "1742577045300", "checksum": 971798103, "seqId": 49944984350, "prevSeqId": 49944984292}], "record_time": 1742577045.473668, "EXCHANGE": "OKX"}
{"arg": {"channel": "books", "instId": "BTC-USDT"}, "action": "update", "data": [{"asks": [["83982.1", "0.50348328", "0", "10"], ["83987.9", "0.0598762", "0", "1"], ["83999", "0.060015", "0", "3"], ["84002.4", "0.06", "0", "2"], ["84005.6", "0.14909685", "0", "2"], ["84012.5", "0.23826106", "0", "1"], ["84016.5", "0.00035881", "0", "1"], ["84021", "0.21", "0", "2"], ["84040.3", "0", "0", "0"], ["84141.2", "0", "0", "0"]], "bids": [["83982", "0.40523339", "0", "11"], ["83964.3", "0", "0", "0"], ["83959.1", "0", "0", "0"], ["83956.7", "0.23826106", "0", "1"], ["83956.2", "0.5351423", "0", "2"], ["83920.1", "0", "0", "0"], ["83920", "0", "0", "0"], ["83883", "0.07165719", "0", "1"], ["83825", "0.00008012", "0", "2"], ["83824.2", "0.20833794", "0", "2"]], "ts": "1742577045400", "checksum": 1441165412, "seqId": 49944984383, "prevSeqId": 49944984350}], "record_time": 1742577045.572251, "EXCHANGE": "OKX"}
{"arg": {"channel": "books", "instId": "BTC-USDT"}, "action": "update", "data": [{"asks": [["83986.1", "0", "0", "0"], ["83987.9", "0.08812814", "0", "2"], ["83988.1", "0.0102", "0", "1"], ["83988.2", "0.11912156", "0", "1"], ["84005.6", "0.11909685", "0", "1"], ["84008.9", "0", "0", "0"], ["84009", "0", "0", "0"], ["84015", "1", "0", "1"]], "bids": [["83974.1", "0.02162916", "0", "2"], ["83970", "0", "0", "0"], ["83948.4", "0.01153238", "0", "1"]], "ts": "1742577045500", "checksum": -1924545853, "seqId": 49944984394, "prevSeqId": 49944984383}], "record_time": 1742577045.672907, "EXCHANGE": "OKX"}
{"arg": {"channel": "books", "instId": "BTC-USDT"}, "action": "update", "data": [{"asks": [["83982.1", "0.27501358", "0", "5"], ["83982.2", "0", "0", "0"], ["83983.9", "0.06058998", "0", "1"], ["83986.6", "0.03979155", "0", "1"], ["83987.9", "0.0598762", "0", "1"], ["83988.2", "0", "0", "0"], ["83988.5", "0.016", "0", "1"], ["83990.6", "0.004315", "0", "2"], ["83991.2", "0.11912925", "0", "2"], ["84012.5", "0", "0", "0"], ["84015", "0", "0", "0"], ["84016.5", "0.23861415", "0", "2"], ["84016.6", "0.11968782", "0", "2"], ["84018.1", "0.003573", "0", "1"], ["84021", "0.01", "0", "1"], ["84040.1", "0.03", "0", "1"], ["84043.5", "0.03", "0", "1"]], "bids": [["83982", "0.65263055", "0", "17"], ["83981.8", "0.06579766", "0", "1"], ["83979", "1.05628489", "0", "2"], ["83976.9", "0", "0", "0"], ["83966.8", "0.39722", "0", "2"], ["83959.4", "0.23825534", "0", "1"], ["83956.7", "0", "0", "0"], ["83955", "0", "0", "0"], ["83954", "0", "0", "0"], ["83823.6", "0.35776874", "0", "1"], ["83823.5", "0.00039533", "0", "1"]], "ts": "1742577045600", "checksum": -1980332447, "seqId": 49944984448, "prevSeqId": 49944984394}], "record_time": 1742577045.773463, "EXCHANGE": "OKX"}
{"arg": {"channel": "books", "instId": "BTC-USDT"}, "action": "update", "data": [{"asks": [["83982.1", "0.73930923", "0", "16"], ["83985.3", "0.0188", "0", "1"], ["83988.1", "0", "0", "0"], ["83989.3", "0.11912005", "0", "1"], ["83991.1", "0.0102", "0", "1"], ["83991.2", "0.00001199", "0", "1"], ["84012", "0.23826309", "0", "1"], ["84016.5", "0.00035881", "0", "1"], ["84025.6", "0.32136305", "0", "3"], ["84026.4", "0.03999999", "0", "1"], ["84027.2", "0", "0", "0"], ["84062.9", "0", "0", "0"], ["84141.1", "0", "0", "0"]], "bids": [["83982", "0.40419655", "0", "11"], ["83981.8", "0.0489122", "0", "1"], ["83979", "0", "0", "0"], ["83976.3", "1", "0", "1"], ["83974.1", "0.00773916", "0", "1"], ["83966.8", "0.04", "0", "1"], ["83965.3", "0", "0", "0"], ["83959.4", "0", "0", "0"], ["83957.7", "0.46634088", "0", "1"], ["83956.7", "0.23826309", "0", "1"], ["83956.2", "0.3565323", "0", "1"], ["83915", "0", "0", "0"], ["83823.4", "6.63755725", "0", "1"], ["83823", "0.00001199", "0", "1"]], "ts": "1742577045700", "checksum": -404086258, "seqId": 49944984501, "prevSeqId": 49944984448}], "record_time": 1742577045.87304, "EXCHANGE": "OKX"}
{"arg": {"channel": "books", "instId": "BTC-USDT"}, "action": "update", "data": [{"asks": [["84016.8", "0.0008", "0", "2"], ["84017.6", "0.01230227", "0", "2"], ["84019.2", "0.01190205", "0", "1"], ["84020", "0", "0", "0"], ["84024.8", "0.08", "0", "2"], ["84025.6", "0.28136305", "0", "2"], ["84026.4", "0", "0", "0"]], "bids": [["83982", "0.38569655", "0", "9"], ["83976.3", "0", "0", "0"], ["83974.9", "1", "0", "1"], ["83969.3", "0.36085264", "0", "2"], ["83957", "0.12503", "0", "1"], ["83949.6", "0.08", "0", "2"], ["83948.8", "0.0408", "0", "3"], ["83948", "0.51926", "0", "2"], ["83943.2", "0.66", "0", "3"], ["83941.8", "0.40001199", "0", "2"], ["83915.1", "0", "0", "0"], ["83914.6", "0.0010061", "0", "1"], ["83823.4", "0", "0", "0"], ["83823", "0", "0", "0"]], "ts": "1742577045800", "checksum": 765885520, "seqId": 49944984527, "prevSeqId": 49944984501}], "record_time": 1742577045.972595, "EXCHANGE": "OKX"}
{"arg": {"channel": "books", "instId": "BTC-USDT"}, "action": "update", "data": [{"asks": [["83986.4", "0.0102", "0", "1"], ["83991.1", "0", "0", "0"]], "bids": [["83972.4", "0.01389", "0", "1"], ["83969.3", "0.00363264", "0", "1"], ["83965.3", "0.17861", "0", "1"], ["83956.2", "0.5351423", "0", "2"], ["83883", "0", "0", "0"], ["83823.5", "0", "0", "0"]], "ts": "1742577045900", "checksum": 749104579, "seqId": 49944984545, "prevSeqId": 49944984527}], "record_time": 1742577046.073694, "EXCHANGE": "OKX"}
{"arg": {"channel": "books", "instId": "BTC-USDT"}, "action": "update", "data": [{"asks": [["84016.8", "0", "0", "0"], ["84017.6", "0.01270227", "0", "3"], ["84018.4", "0.0004", "0", "1"]], "bids": [["83982", "0.40666497", "0", "10"], ["83976.5", "0.00418336", "0", "3"], ["83965.3", "0", "0", "0"], ["83956.2", "0.3565323", "0", "1"], ["83949.6", "0", "0", "0"], ["83948.8", "0.0808", "0", "4"], ["83948", "0.55926", "0", "3"], ["83884.2", "0.07165719", "0", "1"], ["83823.5", "0.00039533", "0", "1"]], "ts": "1742577046000", "checksum": 1905083157, "seqId": 49944984563, "prevSeqId": 49944984545}], "record_time": 1742577046.172761, "EXCHANGE": "OKX"}
{"arg": {"channel": "books", "instId": "BTC-USDT"}, "action": "update", "data": [{"asks": [["83984", "0.0439", "0", "1"], ["83986.1", "0.01191345", "0", "1"], ["84012", "0", "0", "0"], ["84012.5", "0.23826182", "0", "1"], ["84140", "0", "0", "0"]], "bids": [["83982", "0.38569655", "0", "9"], ["83970.4", "0.3237089", "0", "2"], ["83969.3", "0.36085264", "0", "2"], ["83967.8", "0.17861", "0", "1"], ["83958.4", "0.2560068", "0", "2"], ["83956.7", "0", "0", "0"], ["83937.6", "0.01834607", "0", "1"], ["83937.2", "0", "0", "0"], ["83914.7", "0.00100609", "0", "1"], ["83914.6", "0.00218618", "0", "1"], ["83914.5", "0.00595365", "0", "1"], ["83880.5", "0.03", "0", "1"], ["83823.5", "0", "0", "0"]], "ts": "1742577046100", "checksum": -879264017, "seqId": 49944984612, "prevSeqId": 49944984563}], "record_time": 1742577046.272076, "EXCHANGE": "OKX"}
{"arg": {"channel": "books", "instId": "BTC-USDT"}, "action": "update", "data": [{"asks": [["84011.2", "0.23826502", "0", "1"], ["84012.5", "0", "0", "0"]], "bids": [["83982", "0.41675522", "0", "11"], ["83977.8", "0.04467434", "0", "1"], ["83969.3", "0.00363264", "0", "1"], ["83958.4", "0.01774536", "0", "1"], ["83954.4", "0.23826502", "0", "1"], ["83949.6", "0.08", "0", "2"], ["83948.8", "0.0408", "0", "3"], ["83948", "0.51926", "0", "2"], ["83825", "0", "0", "0"], ["83824.2", "0", "0", "0"], ["83823.6", "0", "0", "0"]], "ts": "1742577046200", "checksum": 121395416, "seqId": 49944984633, "prevSeqId": 49944984612}], "record_time": 1742577046.3741, "EXCHANGE": "OKX"}
{"arg": {"channel": "books", "instId": "BTC-USDT"}, "action": "update", "data": [{"asks": [["84011.2", "0", "0", "0"], ["84012", "0.23826375", "0", "1"], ["84037.8", "0.64490977", "0", "3"], ["84063.7", "0.54398139", "0", "2"], ["84085.1", "0.58575117", "0", "2"], ["84087.1", "0.72697213", "0", "1"], ["84135", "0.00001199", "0", "1"], ["84138.8", "0", "0", "0"]], "bids": [["83976.5", "1.00418336", "0", "4"], ["83974.9", "0", "0", "0"], ["83966.8", "0.39722", "0", "2"], ["83957.7", "0", "0", "0"], ["83956.7", "0.23826375", "0", "1"], ["83954.4", "0", "0", "0"], ["83954.3", "0", "0", "0"], ["83945.3", "0.5776526", "0", "1"], ["83915", "0.12503", "0", "1"], ["83913.3", "0.14586203", "0", "1"], ["83912.3", "0", "0", "0"], ["83903.3", "0.58226341", "0", "1"], ["83884.2", "0", "0", "0"], ["83883", "0.07165719", "0", "1"], ["83825", "0.00008012", "0", "2"]], "ts": "1742577046300", "checksum": -196798181, "seqId": 49944984659, "prevSeqId": 49944984633}], "record_time": 1742577046.472674, "EXCHANGE": "OKX"}
{"arg": {"channel": "books", "instId": "BTC-USDT"}, "action": "update", "data": [{"asks": [["84012", "0", "0", "0"], ["84013.1", "0.2542611", "0", "2"], ["84138.8", "0.00044981", "0", "1"]], "bids": [["83966.8", "0.04", "0", "1"], ["83961.2", "0.31932224", "0", "2"], ["83958.4", "0.25600646", "0", "2"], ["83956.7", "0", "0", "0"], ["83880.5", "0", "0", "0"], ["83824.2", "0.20833794", "0", "2"], ["83823.6", "0.35776874", "0", "1"]], "ts": "1742577046400", "checksum": -196798181, "seqId": 49944984671, "prevSeqId": 49944984659}], "record_time": 1742577046.571989, "EXCHANGE": "OKX"}
{"arg": {"channel": "books", "instId": "BTC-USDT"}, "action": "update", "data": [{"asks": [["84013.1", "0.016", "0", "1"], ["84016.5", "0.23861774", "0", "2"], ["84019.4", "0.35714561", "0", "2"], ["84035.9", "0.001721", "0", "1"], ["84054.4", "0", "0", "0"], ["84071", "0", "0", "0"], ["84140", "0.00031221", "0", "2"]], "bids": [["83959.4", "0.23825893", "0", "1"], ["83958.4", "0.01774536", "0", "1"], ["83915", "0", "0", "0"]], "ts": "1742577046500", "checksum": -196798181, "seqId": 49944984690, "prevSeqId": 49944984671}], "record_time": 1742577046.699708, "EXCHANGE": "OKX"}
{"arg": {"channel": "books", "instId": "BTC-USDT"}, "action": "update", "data": [{"asks": [["83982.1", "0.63902491", "0", "13"], ["84008.6", "0", "0", "0"], ["84009.6", "0", "0", "0"], ["84010.2", "0.20518061", "0", "2"], ["84013.1", "0.25425571", "0", "2"], ["84016.5", "0.00035881", "0", "1"], ["84017", "1", "0", "1"], ["84024.8", "0", "0", "0"], ["84025.6", "0.32136305", "0", "3"], ["84026.4", "0.03999999", "0", "1"], ["84038.5", "0.17418962", "0", "1"], ["84039.6", "0", "0", "0"], ["84141.1", "0.00005109", "0", "1"], ["84141.2", "0.00011161", "0", "1"]], "bids": [["83982", "0.43275522", "0", "12"], ["83977.8", "1.04467434", "0", "2"], ["83976.5", "0.00418336", "0", "3"], ["83970.3", "0.17861", "0", "1"], ["83969.3", "0.36085264", "0", "2"], ["83967.8", "0", "0", "0"], ["83955", "1.2", "0", "2"], ["83953.3", "0", "0", "0"], ["83953.2", "0", "0", "0"], ["83949.6", "0", "0", "0"], ["83948.8", "0.0808", "0", "4"], ["83948", "0.55926", "0", "3"], ["83923.5", "0.22850728", "0", "1"], ["83923.2", "0", "0", "0"], ["83903.4", "0.33876303", "0", "1"], ["83901.9", "0", "0", "0"], ["83876.2", "0.7375071", "0", "2"], ["83823.5", "0.00039533", "0", "1"], ["83823.4", "6.63755725", "0", "1"], ["83823", "0.00001199", "0", "1"]], "ts": "1742577046600", "checksum": -1006425142, "seqId": 49944984732, "prevSeqId": 49944984690}], "record_time": 1742577046.772235, "EXCHANGE": "OKX"}
{"arg": {"channel": "books", "instId": "BTC-USDT"}, "action": "update", "data": [{"asks": [["83982.1", "0.41532239", "0", "8"], ["83986.4", "0", "0", "0"], ["83989.1", "0.0102", "0", "1"], ["84009.2", "1.55098673", "0", "1"], ["84013.1", "0.016", "0", "1"], ["84016.5", "0.23861428", "0", "2"], ["84017", "0", "0", "0"], ["84018.1", "0", "0", "0"], ["84037.9", "0.003573", "0", "1"], ["84038.5", "0.99015809", "0", "2"], ["84039.2", "2.8492044", "0", "3"]], "bids": [["83982", "0.48269451", "0", "14"], ["83975.1", "0.01388", "0", "1"], ["83972.4", "0", "0", "0"], ["83958.4", "0", "0", "0"], ["83955", "1", "0", "1"], ["83954.6", "1.5815575", "0", "1"], ["83927.2", "0.95551661", "0", "2"], ["83924.6", "2.9138834", "0", "1"], ["83834.7", "0.01774536", "0", "1"], ["83823.4", "0", "0", "0"], ["83823", "0", "0", "0"]], "ts": "1742577046700", "checksum": -112599963, "seqId": 49944984761, "prevSeqId": 49944984732}], "record_time": 1742577046.876588, "EXCHANGE": "OKX"}
{"arg": {"channel": "books", "instId": "BTC-USDT"}, "action": "update", "data": [{"asks": [["84084.6", "0.15732575", "0", "2"]], "bids": [], "ts": "1742577046800", "checksum": -112599963, "seqId": 49944984767, "prevSeqId": 49944984761}], "record_time": 1742577046.975716, "EXCHANGE": "OKX"}
{"arg": {"channel": "books", "instId": "BTC-USDT"}, "action": "update", "data": [{"asks": [["83984", "0", "0", "0"], ["83986.9", "0", "0", "0"], ["83987.9", "0.09453788", "0", "2"], ["83988.5", "0", "0", "0"], ["83989.3", "0", "0", "0"], ["83990.2", "0", "0", "0"], ["83990.6", "0.0472033", "0", "3"], ["83991", "0.016", "0", "1"], ["83992", "0.16301612", "0", "2"], ["84016.5", "0.23861617", "0", "2"], ["84097.5", "0", "0", "0"], ["84141.3", "0.00083", "0", "1"], ["84141.4", "0.08762", "0", "1"], ["84141.9", "0.00085329", "0", "2"], ["84142", "0.183468", "0", "1"], ["84142.1", "0.00083", "0", "1"], ["84142.2", "0.17898725", "0", "1"]], "bids": [["83982", "0.68519451", "0", "15"], ["83964.6", "0", "0", "0"], ["83957.9", "0.01774536", "0", "1"], ["83834.7", "0", "0", "0"], ["83823", "0.00001199", "0", "1"]], "ts": "1742577046900", "checksum": 1664058838, "seqId": 49944984785, "prevSeqId": 49944984767}], "record_time": 1742577047.076242, "EXCHANGE": "OKX"}
{"arg": {"channel": "books", "instId": "BTC-USDT"}, "action": "update", "data": [{"asks": [["83983.9", "0", "0", "0"], ["83985.9", "0.0286815", "0", "1"], ["83987.9", "0.0598762", "0", "1"], ["83991.9", "0.20290671", "0", "1"], ["83993.5", "0", "0", "0"], ["83995.8", "0.004935", "0", "1"], ["83998.7", "0.003573", "0", "1"], ["84037.9", "0", "0", "0"], ["84142.2", "0", "0", "0"]], "bids": [["83977.9", "0.01191327", "0", "1"], ["83976.7", "0.0429033", "0", "2"], ["83975.2", "0", "0", "0"], ["83972.3", "0.00006", "0", "1"], ["83968.5", "0.11260878", "0", "3"]], "ts": "1742577047000", "checksum": 563878845, "seqId": 49944984806, "prevSeqId": 49944984785}], "record_time": 1742577047.172515, "EXCHANGE": "OKX"}
{"arg": {"channel": "books", "instId": "BTC-USDT"}, "action": "update", "data": [{"asks": [["84018.3", "0.005", "0", "1"], ["84028.4", "0", "0", "0"], ["84142.2", "0.17898725", "0", "1"]], "bids": [["83959.4", "0.23825567", "0", "1"], ["83958.8", "0", "0", "0"], ["83948.3", "0.01190206", "0", "1"]], "ts": "1742577047100", "checksum": 563878845, "seqId": 49944984816, "prevSeqId": 49944984806}], "record_time": 1742577047.273054, "EXCHANGE": "OKX"}
{"arg": {"channel": "books", "instId": "BTC-USDT"}, "action": "update", "data": [{"asks": [["83982.1", "0.10147881", "0", "3"], ["83985.9", "0.01674404", "0", "1"], ["83986.6", "0", "0", "0"], ["83992.4", "0.03979155", "0", "1"], ["83998.7", "0", "0", "0"], ["84013.1", "0.25425805", "0", "2"], ["84016.5", "0.00035881", "0", "1"], ["84028.7", "0.003573", "0", "1"]], "bids": [], "ts": "1742577047200", "checksum": -1380048808, "seqId": 49944984831, "prevSeqId": 49944984816}], "record_time": 1742577047.372318, "EXCHANGE": "OKX"}
{"arg": {"channel": "books", "instId": "BTC-USDT"}, "action": "update", "data": [{"asks": [["83982.1", "0", "0", "0"], ["83982.3", "0", "0", "0"], ["83985.9", "0", "0", "0"], ["83986", "0", "0", "0"], ["83986.1", "0", "0", "0"], ["83987.9", "0", "0", "0"], ["83988", "0", "0", "0"], ["83989.1", "0", "0", "0"], ["83989.7", "0", "0", "0"], ["83989.9", "0.01821006", "0", "1"], ["83990.6", "0.004315", "0", "2"], ["83990.9", "0.00056049", "0", "1"], ["83991", "0", "0", "0"], ["83991.3", "0.01191271", "0", "1"], ["83991.8", "0.00773945", "0", "1"], ["83991.9", "0.09063334", "0", "1"], ["83992", "0.0439", "0", "1"], ["83994.1", "0", "0", "0"], ["83994.6", "0.0428883", "0", "1"], ["83995.5", "0", "0", "0"], ["83995.6", "0.016", "0", "1"], ["83995.8", "0", "0", "0"], ["83996.9", "0.21214266", "0", "2"], ["83997", "0", "0", "0"], ["83998", "0.05543238", "0", "2"], ["83998.8", "0.35697351", "0", "1"], ["83998.9", "0.2025", "0", "1"], ["83999.2", "0", "0", "0"], ["83999.6", "0", "0", "0"], ["84000.6", "0.0102", "0", "1"], ["84001.2", "0", "0", "0"], ["84001.4", "0.001857", "0", "2"], ["84002.2", "0.04", "0", "1"], ["84007.7", "0.02382495", "0", "1"], ["84010.2", "0.19327729", "0", "1"], ["84013.1", "0.016", "0", "1"], ["84013.6", "0.01190284", "0", "1"], ["84017.6", "0.01190227", "0", "1"], ["84018", "0", "0", "0"], ["84018.4", "0.0008", "0", "2"], ["84019.2", "0.01230205", "0", "2"], ["84020.7", "0.23823735", "0", "1"], ["84025.6", "0.24136306", "0", "1"], ["84026.4", "0.07999999", "0", "2"], ["84027.2", "0.03999999", "0", "1"], ["84142.8", "0.02898561", "0", "3"], ["84143.8", "0.00001314", "0", "1"], ["84144.1", "0.0000568", "0", "1"], ["84144.5", "0.00001211", "0", "1"], ["84145.1", "0.00039405", "0", "2"], ["84145.2", "0.00167282", "0", "19"]], "bids": [["83985.2", "1.44101791", "0", "16"], ["83985", "0.11785105", "0", "1"], ["83984", "0.40087351", "0", "2"], ["83983.5", "0.01191247", "0", "1"], ["83982.3", "0.46144845", "0", "1"], ["83982", "0.33566024", "0", "11"], ["83981.8", "0", "0", "0"], ["83981.7", "0", "0", "0"], ["83981.3", "0.01388", "0", "1"], ["83980.6", "0.0428883", "0", "1"], ["83979.6", "1", "0", "1"], ["83979.4", "0.08991011", "0", "1"], ["83978.1", "0.08623678", "0", "1"], ["83977.9", "0", "0", "0"], ["83977.8", "0.04467434", "0", "1"], ["83976.7", "0.000015", "0", "1"], ["83975.1", "0", "0", "0"], ["83975", "0.04166", "0", "1"], ["83973.7", "0", "0", "0"], ["83970.7", "0.08991011", "0", "1"], ["83968.9", "0", "0", "0"], ["83968.8", "0", "0", "0"], ["83966.9", "0.23823735", "0", "1"], ["83962.7", "0.03097264", "0", "2"], ["83959.4", "0", "0", "0"], ["83956.5", "0.08991011", "0", "1"], ["83956", "0.00001", "0", "1"], ["83955", "0", "0", "0"], ["83947.2", "0.026", "0", "2"], ["83946.9", "0", "0", "0"], ["83946.4", "0.013", "0", "1"], ["83945.4", "0.73043797", "0", "2"], ["83943.2", "0.1", "0", "2"], ["83939.2", "0.001786", "0", "1"], ["83933.1", "0.02466532", "0", "1"], ["83876.2", "0.11889794", "0", "1"], ["83832.6", "0", "0", "0"], ["83825.1", "0", "0", "0"], ["83825", "0", "0", "0"], ["83824.2", "0", "0", "0"], ["83823.6", "0", "0", "0"], ["83823.5", "0", "0", "0"], ["83823", "0", "0", "0"]], "ts": "1742577047300", "checksum": 1024347752, "seqId": 49944985072, "prevSeqId": 49944984831}], "record_time": 1742577047.472257, "EXCHANGE": "OKX"}
{"arg": {"channel": "books", "instId": "BTC-USDT"}, "action": "update", "data": [{"asks": [["83985.3", "0.1054", "0", "2"], ["83986", "0.0439", "0", "1"], ["83988", "0.0439", "0", "1"], ["83989.9", "0", "0", "0"], ["83990.6", "0.0043", "0", "1"], ["83991.3", "0", "0", "0"], ["83991.6", "0.1616649", "0", "1"], ["83991.7", "0.2", "0", "1"], ["83991.9", "0", "0", "0"], ["83992.4", "0", "0", "0"], ["83992.5", "0", "0", "0"], ["83994.3", "0.01191228", "0", "1"], ["83994.6", "0", "0", "0"], ["83995.2", "0.11911168", "0", "1"], ["83995.6", "0", "0", "0"], ["83996.9", "0.21433866", "0", "2"], ["83998", "0.0439", "0", "1"], ["83998.4", "0.01192648", "0", "2"], ["83998.7", "0.02", "0", "1"], ["83999", "0.000015", "0", "1"], ["83999.1", "0.0428883", "0", "1"], ["83999.3", "0.03979155", "0", "1"], ["84000.2", "0.17211714", "0", "1"], ["84001.4", "0.0015", "0", "1"], ["84002.2", "0", "0", "0"], ["84002.4", "0", "0", "0"], ["84002.9", "0.01153238", "0", "1"], ["84003", "0", "0", "0"], ["84003.1", "0.1786", "0", "1"], ["84003.6", "0.03", "0", "1"], ["84004.5", "0.26167886", "0", "1"], ["84004.6", "0.35721", "0", "1"], ["84004.9", "0.04", "0", "1"], ["84005.4", "0", "0", "0"], ["84005.7", "0", "0", "0"], ["84008.5", "0.04", "0", "1"], ["84009.1", "0.65857331", "0", "1"], ["84010.2", "0", "0", "0"], ["84013.6", "0", "0", "0"], ["84015.8", "0.01191754", "0", "2"], ["84017.6", "0.25014646", "0", "2"], ["84018.4", "0", "0", "0"], ["84019.2", "0.01190205", "0", "1"], ["84020", "0.0008", "0", "2"], ["84020.7", "0", "0", "0"], ["84020.8", "0.11296978", "0", "3"], ["84026.4", "0", "0", "0"], ["84026.6", "0.26238", "0", "1"], ["84027.2", "0", "0", "0"], ["84028", "0.19889793", "0", "3"], ["84028.8", "0.03999999", "0", "1"], ["84029.8", "0.1", "0", "1"], ["84031.9", "0", "0", "0"], ["84043.4", "0", "0", "0"], ["84045.1", "0", "0", "0"], ["84056.3", "0", "0", "0"], ["84085.6", "0", "0", "0"], ["84112.6", "0.07169271", "0", "2"], ["84145.5", "0.3565323", "0", "1"], ["84145.6", "0.00238839", "0", "1"], ["84145.9", "0.00007383", "0", "2"]], "bids": [["83985.2", "1.19846771", "0", "14"], ["83985", "0", "0", "0"], ["83982.3", "0.46256828", "0", "2"], ["83982", "0.33445157", "0", "9"], ["83981.4", "1", "0", "1"], ["83979.6", "0", "0", "0"], ["83976", "0.04327814", "0", "1"], ["83972.1", "0.04", "0", "1"], ["83968.5", "0.11256978", "0", "2"], ["83966.9", "0", "0", "0"], ["83966.8", "0", "0", "0"], ["83966.5", "0.00001199", "0", "1"], ["83963.5", "0.23824419", "0", "1"], ["83961.5", "0.41054727", "0", "2"], ["83961", "0.05801378", "0", "1"], ["83933.1", "0", "0", "0"], ["83932.1", "0", "0", "0"], ["83917.3", "0.00464379", "0", "3"], ["83914.7", "0", "0", "0"], ["83914.6", "0", "0", "0"], ["83914.1", "0", "0", "0"], ["83911.4", "0.10616608", "0", "1"], ["83910.7", "0", "0", "0"], ["83825.1", "0.0166188", "0", "1"], ["83825", "0.00008012", "0", "2"], ["83824.2", "0.20833794", "0", "2"]], "ts": "1742577047400", "checksum": 593753912, "seqId": 49944985236, "prevSeqId": 49944985072}], "record_time": 1742577047.577312, "EXCHANGE": "OKX"}
{"arg": {"channel": "books", "instId": "BTC-USDT"}, "action": "update", "data": [{"asks": [["83985.3", "0.0188", "0", "1"], ["83998.7", "0", "0", "0"], ["83999.4", "0.02", "0", "1"], ["83999.5", "0.0102", "0", "1"], ["84005.8", "0.06061", "0", "2"], ["84005.9", "0.134846", "0", "1"], ["84024.9", "0.12502", "0", "1"], ["84028.7", "0", "0", "0"], ["84036.9", "0.05934752", "0", "1"], ["84045.9", "0.0232", "0", "1"], ["84048.1", "0.03", "0", "1"], ["84052.2", "0.824691", "0", "1"], ["84063.7", "0.58894739", "0", "3"], ["84144.5", "0", "0", "0"], ["84145.1", "0", "0", "0"], ["84145.2", "0", "0", "0"], ["84145.5", "0", "0", "0"], ["84145.6", "0", "0", "0"], ["84145.9", "0", "0", "0"]], "bids": [["83985.2", "1.21241746", "0", "16"], ["83982.8", "1", "0", "1"], ["83981.4", "0", "0", "0"], ["83981.3", "0", "0", "0"], ["83979.3", "0.04166", "0", "1"], ["83975", "0", "0", "0"], ["83971", "0.0015225", "0", "1"], ["83970.4", "0.23251263", "0", "1"], ["83969.3", "0.00363264", "0", "1"], ["83963.8", "0.1786", "0", "1"], ["83961.2", "0.14071224", "0", "1"], ["83957.9", "0", "0", "0"], ["83954.3", "0.045024", "0", "1"], ["83939.3", "0.8258", "0", "1"], ["83825", "0", "0", "0"], ["83824.2", "0", "0", "0"]], "ts": "1742577047500", "checksum": 383656963, "seqId": 49944985273, "prevSeqId": 49944985236}], "record_time": 1742577047.672348, "EXCHANGE": "OKX"}
{"arg": {"channel": "books", "instId": "BTC-USDT"}, "action": "update", "data": [{"asks": [["83986", "0", "0", "0"], ["83993.2", "0.11911454", "0", "1"], ["83995.2", "0", "0", "0"], ["84004.3", "0.03", "0", "1"], ["84007.7", "0.08382495", "0", "3"], ["84012.6", "0.15989423", "0", "2"], ["84016.5", "0.23860981", "0", "2"], ["84017.6", "0.01190227", "0", "1"], ["84020.4", "0.01190188", "0", "1"], ["84020.5", "0", "0", "0"], ["84035", "0.1", "0", "1"], ["84043.2", "0.25004", "0", "1"], ["84143.8", "0", "0", "0"], ["84144.1", "0", "0", "0"]], "bids": [["83984.1", "0.58968179", "0", "1"], ["83982.8", "0", "0", "0"], ["83982.3", "0.00111983", "0", "1"], ["83981", "1", "0", "1"], ["83974.7", "0.26626254", "0", "2"], ["83971.9", "0.35721", "0", "1"], ["83963.5", "0", "0", "0"], ["83960.8", "0.238251", "0", "1"], ["83958", "0.11756978", "0", "4"], ["83957.6", "0.89968904", "0", "2"], ["83951.4", "0", "0", "0"], ["83951.3", "0.01190188", "0", "1"], ["83917.3", "0.058715", "0", "4"], ["83894.4", "0.19023389", "0", "2"], ["83825.4", "0", "0", "0"], ["83825.1", "0", "0", "0"]], "ts": "1742577047600", "checksum": -99708829, "seqId": 49944985309, "prevSeqId": 49944985273}], "record_time": 1742577047.773643, "EXCHANGE": "OKX"}
{"arg": {"channel": "books", "instId": "BTC-USDT"}, "action": "update", "data": [{"asks": [["84012.6", "0.09807051", "0", "1"], ["84016.5", "0.00035881", "0", "1"], ["84018.4", "0.23824524", "0", "1"], ["84025", "1", "0", "1"], ["84035", "0", "0", "0"], ["84142.8", "0", "0", "0"]], "bids": [["83983.1", "1", "0", "1"], ["83981", "0", "0", "0"], ["83966", "0.2", "0", "1"], ["83963.5", "0.23824524", "0", "1"], ["83960.8", "0", "0", "0"], ["83956.4", "0", "0", "0"], ["83955.5", "0.01190105", "0", "1"], ["83825.9", "0", "0", "0"]], "ts": "1742577047700", "checksum": -270488217, "seqId": 49944985324, "prevSeqId": 49944985309}], "record_time": 1742577047.872702, "EXCHANGE": "OKX"}
{"arg": {"channel": "books", "instId": "BTC-USDT"}, "action": "update", "data": [{"asks": [["83996", "0.0489", "0", "2"], ["84006.1", "0.00501198", "0", "2"]], "bids": [["83983.4", "0.005", "0", "1"], ["83973.3", "0.005", "0", "1"], ["83957.9", "0.01774536", "0", "1"], ["83826.3", "0", "0", "0"], ["83826.1", "0", "0", "0"], ["83826", "0", "0", "0"]], "ts": "1742577047800", "checksum": -1802110235, "seqId": 49944985332, "prevSeqId": 49944985324}], "record_time": 1742577047.973981, "EXCHANGE": "OKX"}
{"arg": {"channel": "books", "instId": "BTC-USDT"}, "action": "update", "data": [{"asks": [["84019.2", "0", "0", "0"], ["84023.8", "0.01190139", "0", "1"]], "bids": [["83953.1", "0.01190139", "0", "1"], ["83949.3", "0", "0", "0"]], "ts": "1742577047900", "checksum": -1802110235, "seqId": 49944985340, "prevSeqId": 49944985332}], "record_time": 1742577048.072389, "EXCHANGE": "OKX"}
{"arg": {"channel": "books", "instId": "BTC-USDT"}, "action": "update", "data": [{"asks": [["83991.6", "0.10166576", "0", "1"], ["83991.7", "0", "0", "0"], ["83996.9", "0.21740316", "0", "2"], ["83998.7", "0.35697351", "0", "1"], ["83998.8", "0", "0", "0"], ["84142.8", "0.02898561", "0", "3"]], "bids": [["83982.1", "0.01427915", "0", "1"], ["83954.6", "1.59345892", "0", "2"], ["83950.8", "0", "0", "0"]], "ts": "1742577048000", "checksum": 412846131, "seqId": 49944985352, "prevSeqId": 49944985340}], "record_time": 1742577048.171754, "EXCHANGE": "OKX"}
{"arg": {"channel": "books", "instId": "BTC-USDT"}, "action": "update", "data": [{"asks": [["83988", "0", "0", "0"], ["83996.1", "0", "0", "0"], ["84018.4", "0.23824344", "0", "1"], ["84037.2", "0", "0", "0"], ["84041.7", "0.00002157", "0", "1"], ["84054.3", "0", "0", "0"], ["84055.5", "0.01127217", "0", "1"], ["84143.8", "0.00001314", "0", "1"], ["84144.1", "0.0000568", "0", "1"]], "bids": [["83963.9", "0.23824301", "0", "1"], ["83963.5", "0", "0", "0"], ["83938.9", "0.01834465", "0", "1"], ["83937.6", "0", "0", "0"], ["83917.4", "0.00465854", "0", "4"], ["83917.3", "0.05407121", "0", "1"], ["83896.1", "0.00018359", "0", "1"], ["83894", "0", "0", "0"], ["83867.5", "0.18346156", "0", "2"], ["83865", "0", "0", "0"], ["83826.3", "0.07157653", "0", "1"]], "ts": "1742577048100", "checksum": 991649486, "seqId": 49944985388, "prevSeqId": 49944985352}], "record_time": 1742577048.27236, "EXCHANGE": "OKX"}
{"arg": {"channel": "books", "instId": "BTC-USDT"}, "action": "update", "data": [{"asks": [["83987", "0.005", "0", "1"], ["83991.6", "0.09342343", "0", "2"], ["83993.2", "0", "0", "0"], ["83995.3", "0.11911152", "0", "1"], ["83997", "0.005", "0", "1"], ["84018.3", "0", "0", "0"], ["84018.4", "0", "0", "0"], ["84019", "0.23824289", "0", "1"], ["84028.3", "0", "0", "0"]], "bids": [["83985.2", "1.23027646", "0", "17"], ["83984.1", "0.5603263", "0", "2"], ["83983.4", "0.01", "0", "2"], ["83983.2", "1", "0", "1"], ["83983.1", "0", "0", "0"], ["83976.5", "0.00309168", "0", "2"], ["83973.4", "0.005", "0", "1"], ["83963.9", "0.23824445", "0", "1"], ["83826.3", "0", "0", "0"]], "ts": "1742577048200", "checksum": 1317172305, "seqId": 49944985425, "prevSeqId": 49944985388}], "record_time": 1742577048.37206, "EXCHANGE": "OKX"}
{"arg": {"channel": "books", "instId": "BTC-USDT"}, "action": "update", "data": [{"asks": [["84017.6", "0.25014894", "0", "2"], ["84019", "0", "0", "0"], ["84019.4", "0.35697351", "0", "1"], ["84026.5", "0.0001722", "0", "1"]], "bids": [["83976.5", "0.002", "0", "1"], ["83966.3", "0.72138778", "0", "1"], ["83966", "1.2", "0", "2"], ["83963.9", "0", "0", "0"], ["83962", "0.23824665", "0", "1"]], "ts": "1742577048300", "checksum": -1477776263, "seqId": 49944985439, "prevSeqId": 49944985425}], "record_time": 1742577048.472533, "EXCHANGE": "OKX"}
{"arg": {"channel": "books", "instId": "BTC-USDT"}, "action": "update", "data": [{"asks": [["83988", "0.0439", "0", "1"], ["83991.5", "0.2", "0", "1"], ["84143.8", "0", "0", "0"], ["84144.1", "0", "0", "0"]], "bids": [], "ts": "1742577048400", "checksum": -799384974, "seqId": 49944985444, "prevSeqId": 49944985439}], "record_time": 1742577048.573571, "EXCHANGE": "OKX"}
{"arg": {"channel": "books", "instId": "BTC-USDT"}, "action": "update", "data": [{"asks": [["83991.5", "0", "0", "0"], ["84027.2", "0.08", "0", "2"], ["84028", "0.15889793", "0", "2"], ["84028.8", "0", "0", "0"], ["84143.8", "0.00001314", "0", "1"]], "bids": [["83949.6", "0.08", "0", "2"], ["83948.8", "0.0408", "0", "3"], ["83948", "0.51926", "0", "2"], ["83826.5", "0", "0", "0"]], "ts": "1742577048500", "checksum": 1310318281, "seqId": 49944985455, "prevSeqId": 49944985444}], "record_time": 1742577048.676085, "EXCHANGE": "OKX"}
{"arg": {"channel": "books", "instId": "BTC-USDT"}, "action": "update", "data": [{"asks": [["84019.2", "0.0008", "0", "2"], ["84020", "0.0004", "0", "1"], ["84020.8", "0.11256978", "0", "2"], ["84025", "0", "0", "0"], ["84026.4", "0.08", "0", "2"], ["84027.2", "0.03999999", "0", "1"], ["84028", "0.11889794", "0", "1"], ["84042.8", "0.22636004", "0", "1"], ["84142.8", "0", "0", "0"], ["84143.8", "0", "0", "0"]], "bids": [["83983.2", "0", "0", "0"], ["83981.7", "1", "0", "1"], ["83971", "0", "0", "0"], ["83945.4", "1.04744685", "0", "3"], ["83944", "0.1", "0", "2"], ["83943.2", "0.05", "0", "1"], ["83942.4", "0", "0", "0"], ["83894.4", "0", "0", "0"], ["83826.5", "0.00040898", "0", "2"], ["83826.3", "0.07157653", "0", "1"]], "ts": "1742577048600", "checksum": -862671420, "seqId": 49944985504, "prevSeqId": 49944985455}], "record_time": 1742577048.778622, "EXCHANGE": "OKX"}
{"arg": {"channel": "books", "instId": "BTC-USDT"}, "action": "update", "data": [{"asks": [["83988", "0", "0", "0"], ["84026.4", "0", "0", "0"], ["84027.2", "0.07999999", "0", "2"], ["84028", "0.15889793", "0", "2"], ["84038", "0.2", "0", "1"], ["84142.8", "0.02898561", "0", "3"]], "bids": [["83973.9", "0.003285", "0", "1"], ["83944", "0", "0", "0"], ["83943.2", "0.1", "0", "2"], ["83942.4", "0.05", "0", "1"], ["83938.9", "0", "0", "0"], ["83938.4", "0.0183449", "0", "1"], ["83867.5", "0.000015", "0", "1"], ["83866.7", "0.18350628", "0", "2"], ["83826.3", "0", "0", "0"]], "ts": "1742577048700", "checksum": -441075073, "seqId": 49944985519, "prevSeqId": 49944985504}], "record_time": 1742577048.872168, "EXCHANGE": "OKX"}
{"arg": {"channel": "books", "instId": "BTC-USDT"}, "action": "update", "data": [{"asks": [["84038", "0", "0", "0"], ["84143.8", "0.00001314", "0", "1"]], "bids": [["83964.6", "0.00357286", "0", "1"], ["83826.5", "0", "0", "0"]], "ts": "1742577048800", "checksum": -441075073, "seqId": 49944985522, "prevSeqId": 49944985519}], "record_time": 1742577048.97204, "EXCHANGE": "OKX"}
{"arg": {"channel": "books", "instId": "BTC-USDT"}, "action": "update", "data": [{"asks": [["83985.3", "0.1085", "0", "3"], ["83986", "0.0439", "0", "1"], ["83988", "0.0439", "0", "1"], ["83991.6", "0.09342441", "0", "2"], ["83991.8", "0.01965209", "0", "2"], ["83993.2", "0.11911445", "0", "1"], ["83994.3", "0", "0", "0"], ["83995.3", "0", "0", "0"], ["84016.5", "0.23860724", "0", "2"], ["84017.6", "0.01190227", "0", "1"], ["84026.4", "0.08", "0", "2"], ["84027.2", "0.03999999", "0", "1"], ["84028", "0.11889794", "0", "1"], ["84036.9", "0", "0", "0"], ["84038.4", "0.471595", "0", "1"], ["84063.7", "0.22395325", "0", "2"], ["84065.6", "0.00001199", "0", "1"], ["84142.8", "0", "0", "0"], ["84143.8", "0", "0", "0"]], "bids": [["83985.2", "1.10900136", "0", "16"], ["83979.4", "0", "0", "0"], ["83973.9", "0", "0", "0"], ["83969.5", "0.047245", "0", "2"], ["83964.6", "0", "0", "0"], ["83962", "0", "0", "0"], ["83959.4", "0.23824986", "0", "1"], ["83949.7", "0.00357286", "0", "1"], ["83944", "0.1", "0", "2"], ["83943.2", "0.05", "0", "1"], ["83942.4", "0", "0", "0"], ["83826.5", "0.00040898", "0", "2"], ["83826.3", "0.07157653", "0", "1"]], "ts": "1742577048900", "checksum": -333397975, "seqId": 49944985566, "prevSeqId": 49944985522}], "record_time": 1742577049.072854, "EXCHANGE": "OKX"}
{"arg": {"channel": "books", "instId": "BTC-USDT"}, "action": "update", "data": [{"asks": [["83985.3", "0.11898299", "0", "4"], ["84026.4", "0", "0", "0"], ["84027.2", "0.07999999", "0", "2"], ["84028", "0.15889793", "0", "2"], ["84032.3", "0.05774899", "0", "1"]], "bids": [["83985.2", "0.62745529", "0", "12"], ["83984.1", "0.1632364", "0", "1"], ["83984", "0.0439", "0", "1"], ["83981.7", "0", "0", "0"], ["83970.4", "0.47852296", "0", "2"], ["83969.5", "0.04", "0", "1"], ["83967", "1", "0", "1"], ["83966.3", "0.4741248", "0", "1"], ["83966", "0.2", "0", "1"], ["83961.3", "0.23825221", "0", "1"], ["83959.4", "0", "0", "0"]], "ts": "1742577049000", "checksum": 701737711, "seqId": 49944985596, "prevSeqId": 49944985566}], "record_time": 1742577049.172931, "EXCHANGE": "OKX"}
{"arg": {"channel": "books", "instId": "BTC-USDT"}, "action": "update", "data": [{"asks": [["83985.3", "0.1085", "0", "3"]], "bids": [["83984.1", "0.44283185", "0", "2"], ["83983.5", "0", "0", "0"], ["83981.2", "0.0119128", "0", "1"], ["83980.8", "1", "0", "1"], ["83970.4", "0.23251263", "0", "1"], ["83967", "0", "0", "0"], ["83917.5", "0.00100583", "0", "1"], ["83917.4", "0.00365272", "0", "3"], ["83894.4", "0.09955961", "0", "1"], ["83826.5", "0", "0", "0"], ["83826.3", "0", "0", "0"]], "ts": "1742577049100", "checksum": 568548098, "seqId": 49944985616, "prevSeqId": 49944985596}], "record_time": 1742577049.272255, "EXCHANGE": "OKX"}
{"arg": {"channel": "books", "instId": "BTC-USDT"}, "action": "update", "data": [{"asks": [["83985.3", "0.0219", "0", "2"], ["84026.4", "0.08", "0", "2"], ["84027.2", "0.03999999", "0", "1"], ["84028", "0.11889794", "0", "1"], ["84142.2", "0", "0", "0"]], "bids": [["83985.2", "0.62924129", "0", "13"], ["83984.3", "0.35697351", "0", "1"], ["83984.2", "0.17898725", "0", "1"], ["83949.6", "0.0808", "0", "4"], ["83948.8", "0.0404", "0", "2"], ["83948", "0.51886", "0", "1"], ["83945.5", "0.56", "0", "1"], ["83945.4", "0.48744685", "0", "2"], ["83939.2", "0", "0", "0"], ["83827.3", "0", "0", "0"], ["83827", "0", "0", "0"]], "ts": "1742577049200", "checksum": -670518801, "seqId": 49944985637, "prevSeqId": 49944985616}], "record_time": 1742577049.375299, "EXCHANGE": "OKX"}
{"arg": {"channel": "books", "instId": "BTC-USDT"}, "action": "update", "data": [{"asks": [["84016.5", "0.00035881", "0", "1"], ["84017.6", "0.25015042", "0", "2"]], "bids": [["83962.8", "0.23824815", "0", "1"], ["83961.3", "0", "0", "0"]], "ts": "1742577049300", "checksum": -670518801, "seqId": 49944985643, "prevSeqId": 49944985637}], "record_time": 1742577049.472359, "EXCHANGE": "OKX"}
{"arg": {"channel": "books", "instId": "BTC-USDT"}, "action": "update", "data": [{"asks": [["83986", "0", "0", "0"], ["83989.9", "0.07463174", "0", "1"], ["83991.5", "0.2", "0", "1"], ["84017.6", "0.25015067", "0", "2"], ["84026.4", "0", "0", "0"], ["84027.2", "0.07999999", "0", "2"], ["84028", "0.15889793", "0", "2"]], "bids": [["83985.2", "0.64710129", "0", "14"], ["83982.1", "1.01427915", "0", "2"], ["83980.8", "0", "0", "0"], ["83969.6", "0.0049575", "0", "1"], ["83962.8", "0", "0", "0"], ["83962", "0.2382484", "0", "1"]], "ts": "1742577049400", "checksum": -1393078015, "seqId": 49944985666, "prevSeqId": 49944985643}], "record_time": 1742577049.573407, "EXCHANGE": "OKX"}
{"arg": {"channel": "books", "instId": "BTC-USDT"}, "action": "update", "data": [{"asks": [["84009.1", "0", "0", "0"], ["84009.2", "0", "0", "0"], ["84038.5", "0.17418962", "0", "1"], ["84039.2", "0.052", "0", "2"], ["84142.2", "0.17898725", "0", "1"], ["84142.8", "0.02898561", "0", "3"]], "bids": [["83957.6", "0.17898725", "0", "1"], ["83954.6", "0.01190142", "0", "1"], ["83949.7", "0", "0", "0"], ["83927.2", "0.06417768", "0", "1"], ["83924.6", "0", "0", "0"], ["83827.3", "0.00621597", "0", "1"], ["83827", "0.00011161", "0", "1"]], "ts": "1742577049500", "checksum": -1393078015, "seqId": 49944985678, "prevSeqId": 49944985666}], "record_time": 1742577049.673636, "EXCHANGE": "OKX"}
{"arg": {"channel": "books", "instId": "BTC-USDT"}, "action": "update", "data": [{"asks": [["84013.5", "1.59838861", "0", "1"], ["84022", "1", "0", "1"], ["84043.6", "2.81904321", "0", "1"], ["84074.1", "0.07136569", "0", "1"], ["84142.1", "0", "0", "0"], ["84142.2", "0", "0", "0"], ["84142.8", "0", "0", "0"]], "bids": [["83958.3", "2.0752038", "0", "2"], ["83957.9", "0", "0", "0"], ["83928.3", "2.92669703", "0", "1"], ["83909.2", "0.07150579", "0", "1"]], "ts": "1742577049600", "checksum": -1393078015, "seqId": 49944985696, "prevSeqId": 49944985678}], "record_time": 1742577049.772056, "EXCHANGE": "OKX"}
{"arg": {"channel": "books", "instId": "BTC-USDT"}, "action": "update", "data": [{"asks": [["84012.6", "0.56793551", "0", "2"], ["84026.4", "0.08", "0", "2"], ["84027.2", "0.03999999", "0", "1"], ["84028", "0.11889794", "0", "1"], ["84042.8", "1.043778", "0", "2"], ["84074.1", "0", "0", "0"]], "bids": [["83961.5", "0.75771621", "0", "1"], ["83928.4", "0.97095471", "0", "1"], ["83927.2", "0", "0", "0"], ["83909.2", "0", "0", "0"], ["83826.5", "0.00040898", "0", "2"]], "ts": "1742577049700", "checksum": -1393078015, "seqId": 49944985716, "prevSeqId": 49944985696}], "record_time": 1742577049.872268, "EXCHANGE": "OKX"}
{"arg": {"channel": "books", "instId": "BTC-USDT"}, "action": "update", "data": [{"asks": [["84026.4", "0", "0", "0"], ["84027.2", "0.07999999", "0", "2"], ["84028", "0.15889793", "0", "2"], ["84033", "0.2", "0", "1"], ["84074.1", "0.07136569", "0", "1"], ["84142", "0", "0", "0"]], "bids": [["83948.3", "0.02964742", "0", "2"], ["83909.2", "0.07150579", "0", "1"], ["83826.5", "0", "0", "0"]], "ts": "1742577049800", "checksum": -1393078015, "seqId": 49944985749, "prevSeqId": 49944985716}], "record_time": 1742577049.972712, "EXCHANGE": "OKX"}
{"arg": {"channel": "books", "instId": "BTC-USDT"}, "action": "update", "data": [{"asks": [["84016.5", "0.23861077", "0", "2"], ["84017.6", "0.01190227", "0", "1"], ["84033", "0", "0", "0"], ["84074.1", "0.14273138", "0", "2"], ["84142", "0.183468", "0", "1"]], "bids": [["83962", "0", "0", "0"], ["83959.4", "0.23825196", "0", "1"], ["83909.2", "0.14301158", "0", "2"]], "ts": "1742577049900", "checksum": -1393078015, "seqId": 49944985769, "prevSeqId": 49944985749}], "record_time": 1742577050.072814, "EXCHANGE": "OKX"}
{"arg": {"channel": "books", "instId": "BTC-USDT"}, "action": "update", "data": [{"asks": [], "bids": [["83966.3", "0.7148592", "0", "2"], ["83965", "1.11915438", "0", "2"], ["83960.8", "0.23824951", "0", "1"], ["83959.4", "0", "0", "0"]], "ts": "1742577050000", "checksum": -1393078015, "seqId": 49944985777, "prevSeqId": 49944985769}], "record_time": 1742577050.172357, "EXCHANGE": "OKX"}
{"arg": {"channel": "books", "instId": "BTC-USDT"}, "action": "update", "data": [{"asks": [["84054.9", "0.01127613", "0", "1"], ["84055.5", "0", "0", "0"], ["84074.1", "0.07136569", "0", "1"]], "bids": [["83960.8", "0.23824977", "0", "1"], ["83959.2", "0.0119029", "0", "1"], ["83951.5", "0.20260013", "0", "3"], ["83917.7", "0.00100585", "0", "1"], ["83917.6", "0.00218593", "0", "1"], ["83917.5", "0", "0", "0"], ["83917.4", "0.0014668", "0", "2"], ["83909.2", "0.07150579", "0", "1"], ["83827.3", "0", "0", "0"], ["83827", "0", "0", "0"]], "ts": "1742577050100", "checksum": -1393078015, "seqId": 49944985796, "prevSeqId": 49944985777}], "record_time": 1742577050.273037, "EXCHANGE": "OKX"}
{"arg": {"channel": "books", "instId": "BTC-USDT"}, "action": "update", "data": [{"asks": [["84019.3", "0", "0", "0"], ["84025.4", "0.01190117", "0", "1"], ["84026.4", "0.08", "0", "2"], ["84027.2", "0.03999999", "0", "1"], ["84028", "0.11889794", "0", "1"], ["84142", "0", "0", "0"]], "bids": [["83960.8", "0.23824969", "0", "1"]], "ts": "1742577050200", "checksum": -1393078015, "seqId": 49944985815, "prevSeqId": 49944985796}], "record_time": 1742577050.371785, "EXCHANGE": "OKX"}
{"arg": {"channel": "books", "instId": "BTC-USDT"}, "action": "update", "data": [{"asks": [["84026.4", "0", "0", "0"], ["84027.2", "0.07999999", "0", "2"], ["84028", "0.15889793", "0", "2"], ["84142", "0.183468", "0", "1"]], "bids": [], "ts": "1742577050300", "checksum": -1393078015, "seqId": 49944985819, "prevSeqId": 49944985815}], "record_time": 1742577050.472827, "EXCHANGE": "OKX"}
{"arg": {"channel": "books", "instId": "BTC-USDT"}, "action": "update", "data": [{"asks": [["84026.4", "0.08", "0", "2"], ["84027.2", "0.03999999", "0", "1"], ["84028", "0.11889794", "0", "1"], ["84142", "0", "0", "0"]], "bids": [["83961.6", "0.23826123", "0", "2"], ["83960.8", "0", "0", "0"], ["83827.3", "0.00621597", "0", "1"]], "ts": "1742577050400", "checksum": -1393078015, "seqId": 49944985847, "prevSeqId": 49944985819}], "record_time": 1742577050.573358, "EXCHANGE": "OKX"}
{"arg": {"channel": "books", "instId": "BTC-USDT"}, "action": "update", "data": [{"asks": [["84017.6", "0", "0", "0"], ["84023.6", "0.01190142", "0", "1"], ["84074.1", "0", "0", "0"], ["84142", "0.183468", "0", "1"]], "bids": [["83961.6", "0.23826108", "0", "2"], ["83909.2", "0", "0", "0"], ["83827", "0.00011161", "0", "1"]], "ts": "1742577050500", "checksum": -1393078015, "seqId": 49944985862, "prevSeqId": 49944985847}], "record_time": 1742577050.681278, "EXCHANGE": "OKX"}
{"arg": {"channel": "books", "instId": "BTC-USDT"}, "action": "update", "data": [{"asks": [["83985.3", "0.1085", "0", "3"], ["84016.5", "0.00035881", "0", "1"], ["84017.6", "0.23824883", "0", "1"], ["84018.5", "0.14071224", "0", "1"], ["84019.1", "0.11889794", "0", "1"], ["84024.5", "0.0119013", "0", "1"], ["84026", "0.01190108", "0", "1"], ["84141.4", "0", "0", "0"], ["84141.9", "0", "0", "0"], ["84142", "0", "0", "0"]], "bids": [["83955.5", "0.02380235", "0", "2"], ["83947.7", "0", "0", "0"], ["83826.5", "0.00040898", "0", "2"]], "ts": "1742577050600", "checksum": -1533552900, "seqId": 49944985871, "prevSeqId": 49944985862}], "record_time": 1742577050.772145, "EXCHANGE": "OKX"}
{"arg": {"channel": "books", "instId": "BTC-USDT"}, "action": "update", "data": [{"asks": [["83985.3", "0.70268355", "0", "6"], ["83986", "0.0439", "0", "1"], ["83991.9", "0.0102", "0", "1"], ["83998.2", "0.03061", "0", "1"], ["83999.5", "0", "0", "0"], ["84004.6", "0", "0", "0"], ["84005.8", "0.03", "0", "1"], ["84017.6", "0.23824976", "0", "1"], ["84021.3", "0.5111587", "0", "2"], ["84063.6", "0.29780666", "0", "1"], ["84074.1", "0.14273138", "0", "2"], ["84141.1", "0", "0", "0"], ["84141.2", "0", "0", "0"], ["84141.3", "0", "0", "0"]], "bids": [["83985.2", "0.72057691", "0", "11"], ["83984.3", "0", "0", "0"], ["83982.1", "0.01427915", "0", "1"], ["83982", "0.29845157", "0", "8"], ["83980.7", "1", "0", "1"], ["83979.3", "0", "0", "0"], ["83978", "0.05778", "0", "2"], ["83971.7", "0.04167", "0", "1"], ["83970.7", "0", "0", "0"], ["83966.3", "0.4741248", "0", "1"], ["83965", "0.11915438", "0", "1"], ["83961.6", "0.23826175", "0", "2"], ["83957.9", "0.4000715", "0", "1"], ["83909.2", "0.14301158", "0", "2"], ["83826.5", "0", "0", "0"]], "ts": "1742577050700", "checksum": 427006573, "seqId": 49944985942, "prevSeqId": 49944985871}], "record_time": 1742577050.872192, "EXCHANGE": "OKX"}
{"arg": {"channel": "books", "instId": "BTC-USDT"}, "action": "update", "data": [{"asks": [["83989.1", "0.113941", "0", "1"], ["83989.2", "0.01191299", "0", "1"], ["83989.9", "0", "0", "0"], ["83990.8", "0.11911785", "0", "1"], ["83991.6", "0.06593139", "0", "1"], ["83991.8", "0.00773945", "0", "1"], ["83993.2", "0", "0", "0"], ["83994.9", "0.01267416", "0", "2"], ["83998.4", "0.01191148", "0", "1"], ["84016.5", "0.23861468", "0", "2"], ["84017.6", "0", "0", "0"]], "bids": [["83985.2", "0.53141625", "0", "9"], ["83982", "0.07995157", "0", "6"], ["83978.1", "0.15031634", "0", "2"], ["83976.8", "0.2025", "0", "1"], ["83970.3", "0.178625", "0", "2"], ["83969.6", "0", "0", "0"], ["83961.6", "0.00001199", "0", "1"], ["83959.4", "0.23825382", "0", "1"], ["83959.2", "0", "0", "0"], ["83958.4", "0.01190278", "0", "1"], ["83946.4", "0.573", "0", "2"], ["83945.5", "0", "0", "0"], ["83842.7", "0.00008234", "0", "1"], ["83836.1", "0", "0", "0"]], "ts": "1742577050800", "checksum": 597633408, "seqId": 49944985999, "prevSeqId": 49944985942}], "record_time": 1742577050.97233, "EXCHANGE": "OKX"}
{"arg": {"channel": "books", "instId": "BTC-USDT"}, "action": "update", "data": [{"asks": [["83994.6", "0.0428883", "0", "1"], ["83994.9", "0.00773916", "0", "1"], ["83999.1", "0", "0", "0"], ["84000.2", "0.24011811", "0", "2"], ["84002.1", "0.35721", "0", "1"], ["84003.1", "0", "0", "0"], ["84012", "0.23825749", "0", "1"], ["84016.5", "0.00035881", "0", "1"], ["84140", "0", "0", "0"]], "bids": [["83985.2", "0.43105625", "0", "8"], ["83984.3", "0.40894698", "0", "2"], ["83984.1", "0", "0", "0"], ["83981.2", "0", "0", "0"], ["83980.7", "0", "0", "0"], ["83979.3", "1", "0", "1"], ["83978.7", "0.01191316", "0", "1"], ["83966", "0.1", "0", "1"], ["83959.4", "0", "0", "0"], ["83958.4", "0.25016027", "0", "2"], ["83826.5", "0.00040898", "0", "2"]], "ts": "1742577050900", "checksum": -1691452479, "seqId": 49944986028, "prevSeqId": 49944985999}], "record_time": 1742577051.07143, "EXCHANGE": "OKX"}
{"arg": {"channel": "books", "instId": "BTC-USDT"}, "action": "update", "data": [{"asks": [["84012", "0", "0", "0"], ["84016.5", "0.23861495", "0", "2"], ["84018.4", "0.0008", "0", "2"], ["84019.2", "0.0004", "0", "1"], ["84020", "0", "0", "0"], ["84140", "0.00031221", "0", "2"]], "bids": [["83959.4", "0.23825614", "0", "1"], ["83958.4", "0.01190278", "0", "1"], ["83826.5", "0", "0", "0"]], "ts": "1742577051000", "checksum": -1691452479, "seqId": 49944986036, "prevSeqId": 49944986028}], "record_time": 1742577051.172151, "EXCHANGE": "OKX"}
{"arg": {"channel": "books", "instId": "BTC-USDT"}, "action": "update", "data": [{"asks": [["83985.3", "1.05400355", "0", "9"], ["83986.9", "0.01191332", "0", "1"], ["83989.2", "0", "0", "0"], ["83989.3", "0.0102", "0", "1"], ["83990.1", "0.000072", "0", "1"], ["83991.9", "0", "0", "0"], ["83993.7", "0.03062", "0", "1"], ["83998.2", "0", "0", "0"], ["84008.2", "0.258073", "0", "4"], ["84013.1", "0.25425805", "0", "2"], ["84016.5", "0.00035881", "0", "1"], ["84115.6", "0", "0", "0"], ["84116.5", "0", "0", "0"], ["84141.1", "0.00005109", "0", "1"]], "bids": [["83985.2", "0.12098151", "0", "3"], ["83984.3", "0", "0", "0"], ["83984.2", "0", "0", "0"], ["83979.3", "0", "0", "0"], ["83978.1", "0.4423064", "0", "1"], ["83978", "0.0439", "0", "1"], ["83975.5", "1", "0", "1"], ["83971.7", "0", "0", "0"], ["83970.3", "0.17861", "0", "1"], ["83967.2", "0.04167", "0", "1"], ["83967", "0.004467", "0", "1"], ["83966", "0", "0", "0"], ["83959.4", "0.23825805", "0", "1"], ["83894.4", "0.16714712", "0", "2"], ["83826.5", "0.00040898", "0", "2"], ["83826.1", "0.00015468", "0", "1"]], "ts": "1742577051100", "checksum": 1924370739, "seqId": 49944986082, "prevSeqId": 49944986036}], "record_time": 1742577051.272246, "EXCHANGE": "OKX"}
{"arg": {"channel": "books", "instId": "BTC-USDT"}, "action": "update", "data": [{"asks": [["83985.3", "0.75150355", "0", "7"], ["84018.4", "0", "0", "0"], ["84019.2", "0.0008", "0", "2"], ["84020", "0.0004", "0", "1"]], "bids": [["83985.2", "0.21353493", "0", "5"], ["83967", "0", "0", "0"], ["83826", "0.2025", "0", "1"]], "ts": "1742577051200", "checksum": 2101311357, "seqId": 49944986093, "prevSeqId": 49944986082}], "record_time": 1742577051.372886, "EXCHANGE": "OKX"}
{"arg": {"channel": "books", "instId": "BTC-USDT"}, "action": "update", "data": [{"asks": [["84018.4", "0.0008", "0", "2"], ["84019.2", "0.0004", "0", "1"], ["84020", "0", "0", "0"]], "bids": [["83976.8", "1.2025", "0", "2"], ["83976", "0", "0", "0"], ["83975.5", "0", "0", "0"], ["83973.3", "0.01889", "0", "2"], ["83970.7", "0.04327814", "0", "1"], ["83965.9", "0.21440684", "0", "2"], ["83825.9", "0.00001586", "0", "1"]], "ts": "1742577051300", "checksum": 267340134, "seqId": 49944986106, "prevSeqId": 49944986093}], "record_time": 1742577051.472654, "EXCHANGE": "OKX"}
{"arg": {"channel": "books", "instId": "BTC-USDT"}, "action": "update", "data": [{"asks": [["83989.1", "0.0534487", "0", "1"], ["83991.5", "0", "0", "0"], ["84008.2", "0.2545", "0", "3"], ["84022.6", "0.003573", "0", "1"], ["84042", "0.01154964", "0", "1"], ["84042.6", "0", "0", "0"]], "bids": [["83983.5", "0.05764466", "0", "1"], ["83965.9", "0.2025", "0", "1"], ["83948", "0.54486", "0", "3"], ["83947.2", "0.013", "0", "1"], ["83946.4", "0.56", "0", "1"], ["83825.9", "0", "0", "0"]], "ts": "1742577051400", "checksum": -249970628, "seqId": 49944986128, "prevSeqId": 49944986106}], "record_time": 1742577051.576207, "EXCHANGE": "OKX"}
{"arg": {"channel": "books", "instId": "BTC-USDT"}, "action": "update", "data": [{"asks": [["84002", "0.113758", "0", "4"]], "bids": [["83965.9", "0.21440684", "0", "2"]], "ts": "1742577051500", "checksum": -249970628, "seqId": 49944986133, "prevSeqId": 49944986128}], "record_time": 1742577051.671974, "EXCHANGE": "OKX"}
{"arg": {"channel": "books", "instId": "BTC-USDT"}, "action": "update", "data": [{"asks": [["84042", "0", "0", "0"], ["84074.1", "0.07136569", "0", "1"], ["84141.2", "0.00011161", "0", "1"]], "bids": [["83985.2", "0.38419637", "0", "6"], ["83978.3", "0.4439485", "0", "1"], ["83978.2", "1", "0", "1"], ["83978.1", "0", "0", "0"], ["83976.8", "0.2025", "0", "1"], ["83975.6", "0.01388", "0", "1"], ["83973.3", "0.005", "0", "1"], ["83909.2", "0.07150579", "0", "1"], ["83826.1", "0", "0", "0"], ["83826", "0", "0", "0"]], "ts": "1742577051600", "checksum": -273033938, "seqId": 49944986154, "prevSeqId": 49944986133}], "record_time": 1742577051.773019, "EXCHANGE": "OKX"}
{"arg": {"channel": "books", "instId": "BTC-USDT"}, "action": "update", "data": [{"asks": [["84010.2", "0.19327729", "0", "1"], ["84013.1", "0.016", "0", "1"], ["84016.5", "0.2386144", "0", "2"], ["84018.4", "0", "0", "0"], ["84019.2", "0.0008", "0", "2"], ["84020", "0.0004", "0", "1"], ["84026.4", "0", "0", "0"], ["84027.2", "0.07999999", "0", "2"], ["84028", "0.15889793", "0", "2"], ["84032.3", "0", "0", "0"], ["84038.3", "0.31425544", "0", "1"], ["84038.5", "0", "0", "0"], ["84064.5", "0.3565323", "0", "1"], ["84067.7", "0.04486818", "0", "1"], ["84068.7", "0.08991011", "0", "1"], ["84071.5", "0.0713679", "0", "1"], ["84074.1", "0", "0", "0"], ["84118", "0", "0", "0"], ["84141.3", "0.00083", "0", "1"], ["84141.4", "0.08762", "0", "1"]], "bids": [["83966.3", "0.65843125", "0", "2"], ["83964", "1", "0", "1"], ["83951.6", "0.12951382", "0", "2"], ["83948", "0.51886", "0", "1"], ["83947.2", "0.026", "0", "2"], ["83946.4", "0.573", "0", "2"], ["83909.2", "0", "0", "0"], ["83906.6", "0.071508", "0", "1"], ["83893.9", "0", "0", "0"]], "ts": "1742577051700", "checksum": -273033938, "seqId": 49944986206, "prevSeqId": 49944986154}], "record_time": 1742577051.883732, "EXCHANGE": "OKX"}
{"arg": {"channel": "books", "instId": "BTC-USDT"}, "action": "update", "data": [{"asks": [["84016.5", "0.23861316", "0", "2"], ["84025.2", "0.05833468", "0", "1"], ["84026.4", "0.08", "0", "2"], ["84027.2", "0.03999999", "0", "1"], ["84028", "0.11889794", "0", "1"], ["84042", "0.01154964", "0", "1"], ["84071.5", "0.1427358", "0", "2"], ["84141.2", "0", "0", "0"], ["84141.3", "0", "0", "0"], ["84141.4", "0", "0", "0"]], "bids": [["83965.9", "0.2025", "0", "1"], ["83965.8", "0.00495", "0", "1"], ["83959.4", "0.23825435", "0", "1"], ["83906.6", "0.143016", "0", "2"], ["83826.5", "0", "0", "0"]], "ts": "1742577051800", "checksum": -273033938, "seqId": 49944986243, "prevSeqId": 49944986206}], "record_time": 1742577051.972782, "EXCHANGE": "OKX"}
{"arg": {"channel": "books", "instId": "BTC-USDT"}, "action": "update", "data": [{"asks": [["84013.1", "0.25425722", "0", "2"], ["84016.5", "0.00035881", "0", "1"], ["84018.4", "0.0008", "0", "2"], ["84019.2", "0.0004", "0", "1"], ["84020", "0", "0", "0"], ["84030", "0.2", "0", "1"], ["84141.1", "0", "0", "0"]], "bids": [["83959.4", "0", "0", "0"], ["83958.4", "0.25016", "0", "2"], ["83826.5", "0.00040898", "0", "2"]], "ts": "1742577051900", "checksum": -273033938, "seqId": 49944986254, "prevSeqId": 49944986243}], "record_time": 1742577052.071822, "EXCHANGE": "OKX"}
{"arg": {"channel": "books", "instId": "BTC-USDT"}, "action": "update", "data": [{"asks": [["84012", "0.23825811", "0", "1"], ["84013.1", "0.016", "0", "1"], ["84018.4", "0", "0", "0"], ["84019.2", "0.0008", "0", "2"], ["84020", "0.0004", "0", "1"], ["84026.4", "0", "0", "0"], ["84027.2", "0.07999999", "0", "2"], ["84028", "0.15889793", "0", "2"], ["84071.5", "0.0713679", "0", "1"]], "bids": [["83958.4", "0.25016089", "0", "2"], ["83906.6", "0.071508", "0", "1"]], "ts": "1742577052000", "checksum": -273033938, "seqId": 49944986278, "prevSeqId": 49944986254}], "record_time": 1742577052.172151, "EXCHANGE": "OKX"}
{"arg": {"channel": "books", "instId": "BTC-USDT"}, "action": "update", "data": [{"asks": [["84012", "0", "0", "0"], ["84016.5", "0.23861428", "0", "2"], ["84018.4", "0.0008", "0", "2"], ["84019.2", "0.0004", "0", "1"], ["84020", "0", "0", "0"], ["84026.4", "0.08", "0", "2"], ["84027.2", "0.03999999", "0", "1"], ["84028", "0.11889794", "0", "1"], ["84071.5", "0", "0", "0"], ["84141.1", "0.00005109", "0", "1"]], "bids": [["83966", "0.1", "0", "1"], ["83959.4", "0.23825547", "0", "1"], ["83958.4", "0.01190278", "0", "1"], ["83938.4", "0", "0", "0"], ["83938.1", "0.01834564", "0", "1"], ["83917.9", "0.00102099", "0", "2"], ["83917.8", "0.00218609", "0", "1"], ["83917.7", "0", "0", "0"], ["83917.6", "0", "0", "0"], ["83906.6", "0", "0", "0"]], "ts": "1742577052100", "checksum": -273033938, "seqId": 49944986307, "prevSeqId": 49944986278}], "record_time": 1742577052.271757, "EXCHANGE": "OKX"}
{"arg": {"channel": "books", "instId": "BTC-USDT"}, "action": "update", "data": [{"asks": [["83998", "0.047473", "0", "2"], ["84022.6", "0", "0", "0"], ["84071.5", "0.1427358", "0", "2"]], "bids": [["83965.8", "0", "0", "0"], ["83945.8", "0.5776526", "0", "1"], ["83945.4", "0.17043797", "0", "1"], ["83945.3", "0", "0", "0"], ["83917.8", "0", "0", "0"], ["83917.5", "0.00218609", "0", "1"], ["83906.6", "0.143016", "0", "2"], ["83903.8", "0.58226341", "0", "1"], ["83903.4", "0", "0", "0"], ["83903.3", "0", "0", "0"], ["83826.1", "0.00015468", "0", "1"]], "ts": "1742577052200", "checksum": -273033938, "seqId": 49944986333, "prevSeqId": 49944986307}], "record_time": 1742577052.372848, "EXCHANGE": "OKX"}
{"arg": {"channel": "books", "instId": "BTC-USDT"}, "action": "update", "data": [{"asks": [["83998", "0.0439", "0", "1"], ["84010.6", "0.003573", "0", "1"], ["84018.4", "0", "0", "0"], ["84019.2", "0.0008", "0", "2"], ["84020", "0.0004", "0", "1"], ["84026.4", "0", "0", "0"], ["84027.2", "0.07999999", "0", "2"], ["84028", "0.15889793", "0", "2"]], "bids": [["83985.2", "0.40916479", "0", "7"], ["83966", "0.204935", "0", "3"], ["83948.3", "0.01190206", "0", "1"]], "ts": "1742577052300", "checksum": 1359501496, "seqId": 49944986349, "prevSeqId": 49944986333}], "record_time": 1742577052.475192, "EXCHANGE": "OKX"}
{"arg": {"channel": "books", "instId": "BTC-USDT"}, "action": "update", "data": [{"asks": [["84030", "0", "0", "0"], ["84058.9", "0.00118964", "0", "1"], ["84063.9", "0.02141227", "0", "2"], ["84112.2", "0.00251767", "0", "1"], ["84141.1", "0", "0", "0"]], "bids": [["83985.2", "0.40828479", "0", "7"], ["83983.5", "0.35043907", "0", "2"], ["83979.5", "1", "0", "1"], ["83978.3", "0.1481125", "0", "1"], ["83978.2", "0", "0", "0"], ["83959.4", "0", "0", "0"], ["83959.1", "0.23825575", "0", "1"], ["83897.9", "0.00213845", "0", "1"], ["83826.1", "0", "0", "0"]], "ts": "1742577052400", "checksum": -2031950414, "seqId": 49944986365, "prevSeqId": 49944986349}], "record_time": 1742577052.576416, "EXCHANGE": "OKX"}
{"arg": {"channel": "books", "instId": "BTC-USDT"}, "action": "update", "data": [{"asks": [["84014", "0.01190278", "0", "1"], ["84015.8", "0.00001501", "0", "1"], ["84140", "0", "0", "0"]], "bids": [["83955.2", "0.01190108", "0", "1"], ["83948.3", "0", "0", "0"]], "ts": "1742577052600", "checksum": -2031950414, "seqId": 49944986374, "prevSeqId": 49944986365}], "record_time": 1742577052.77301, "EXCHANGE": "OKX"}
{"arg": {"channel": "books", "instId": "BTC-USDT"}, "action": "update", "data": [{"asks": [["84010.6", "0", "0", "0"], ["84023.8", "0.01547439", "0", "2"], ["84050.4", "0.51948894", "0", "2"], ["84071.5", "0.0713679", "0", "1"], ["84140", "0.00031221", "0", "2"]], "bids": [["83985.2", "0.40990764", "0", "8"], ["83948.2", "0.81187894", "0", "2"], ["83906.6", "0.071508", "0", "1"], ["83904.8", "0.52449577", "0", "3"]], "ts": "1742577052700", "checksum": -1667297378, "seqId": 49944986392, "prevSeqId": 49944986374}], "record_time": 1742577052.872817, "EXCHANGE": "OKX"}
{"arg": {"channel": "books", "instId": "BTC-USDT"}, "action": "update", "data": [{"asks": [["84071.5", "0.1427358", "0", "2"]], "bids": [["83948.3", "0.01774536", "0", "1"], ["83906.6", "0.143016", "0", "2"], ["83826.5", "0", "0", "0"]], "ts": "1742577052800", "checksum": -1667297378, "seqId": 49944986401, "prevSeqId": 49944986392}], "record_time": 1742577052.973389, "EXCHANGE": "OKX"}
{"arg": {"channel": "books", "instId": "BTC-USDT"}, "action": "update", "data": [{"asks": [["83985.3", "0.85150355", "0", "8"], ["83986.8", "0.07169352", "0", "1"], ["83986.9", "0.02211332", "0", "2"], ["83988.9", "0.11912059", "0", "1"], ["83989.1", "0", "0", "0"], ["83989.3", "0", "0", "0"], ["83990.8", "0", "0", "0"], ["84012", "0.23825924", "0", "1"], ["84016.5", "0.00035881", "0", "1"], ["84018.4", "0.0008", "0", "2"], ["84019.2", "0.0004", "0", "1"], ["84020", "0", "0", "0"], ["84021.3", "0.21238952", "0", "1"], ["84022", "0", "0", "0"], ["84026.4", "0.08", "0", "2"], ["84027.2", "0.03999999", "0", "1"], ["84028", "0.11889794", "0", "1"]], "bids": [["83985.2", "0.00764602", "0", "3"], ["83984", "0", "0", "0"], ["83983.5", "0", "0", "0"], ["83983", "0.11912875", "0", "1"], ["83979.5", "0", "0", "0"], ["83978.3", "0.0831985", "0", "1"], ["83976.8", "0", "0", "0"], ["83975.6", "0", "0", "0"], ["83974.3", "1", "0", "1"], ["83966.3", "0.93182089", "0", "1"], ["83966", "0", "0", "0"], ["83964", "0", "0", "0"], ["83959.1", "0.23825924", "0", "1"], ["83940.8", "0.001786", "0", "1"], ["83826.5", "0.00040898", "0", "2"], ["83826.1", "0.00015468", "0", "1"], ["83826", "0.2025", "0", "1"], ["83825.9", "0.00001586", "0", "1"]], "ts": "1742577052900", "checksum": 802625631, "seqId": 49944986472, "prevSeqId": 49944986401}], "record_time": 1742577053.072347, "EXCHANGE": "OKX"}
{"arg": {"channel": "books", "instId": "BTC-USDT"}, "action": "update", "data": [{"asks": [["83983.5", "1.28736227", "0", "15"], ["83984", "0.0439", "0", "1"], ["83984.1", "0.157654", "0", "1"], ["83984.2", "0.2025", "0", "1"], ["83985.2", "0.2", "0", "1"], ["83985.3", "0.052", "0", "2"], ["83986.8", "0", "0", "0"], ["83987.9", "0.02782334", "0", "1"], ["83988.5", "0.03062", "0", "1"], ["83988.9", "0", "0", "0"], ["83991.8", "0", "0", "0"], ["83993.7", "0", "0", "0"], ["83994", "0.00773962", "0", "1"], ["84012", "0", "0", "0"], ["84012.5", "0.23826121", "0", "1"], ["84025.6", "0.32136305", "0", "3"], ["84026.4", "0.03999999", "0", "1"], ["84027.2", "0", "0", "0"], ["84029.8", "0", "0", "0"], ["84138.8", "0", "0", "0"], ["84140", "0", "0", "0"]], "bids": [["83985.2", "0", "0", "0"], ["83983.4", "0.08908275", "0", "4"], ["83982", "0.05016868", "0", "5"], ["83980.6", "0", "0", "0"], ["83978.3", "0.13354868", "0", "2"], ["83975.8", "0.22187555", "0", "2"], ["83975", "0.2025", "0", "1"], ["83974.7", "0.53916302", "0", "1"], ["83969.3", "0.36084264", "0", "2"], ["83968.4", "0.0047637", "0", "1"], ["83967.2", "0", "0", "0"], ["83966.3", "0.4141248", "0", "1"], ["83962.7", "0.02382661", "0", "1"], ["83962.4", "0.004467", "0", "1"], ["83962", "0.04167", "0", "1"], ["83959.1", "0", "0", "0"], ["83954.4", "0.23826121", "0", "1"], ["83947.6", "0.56", "0", "1"], ["83946.4", "0.013", "0", "1"], ["83917.9", "0.00001501", "0", "1"], ["83917.4", "0.000015", "0", "1"], ["83916.7", "0.11990395", "0", "2"], ["83914.6", "0.00145196", "0", "1"], ["83826.1", "0", "0", "0"], ["83826", "0", "0", "0"], ["83825.9", "0", "0", "0"]], "ts": "1742577053000", "checksum": 945262639, "seqId": 49944986608, "prevSeqId": 49944986472}], "record_time": 1742577053.172552, "EXCHANGE": "OKX"}
{"arg": {"channel": "books", "instId": "BTC-USDT"}, "action": "update", "data": [{"asks": [["83983.5", "1.30909465", "0", "17"], ["83984.1", "0.16956773", "0", "2"], ["83984.9", "0.1191263", "0", "1"], ["83986.6", "0.08991011", "0", "1"], ["83986.9", "0", "0", "0"], ["83987.9", "0.05940728", "0", "2"], ["83988.5", "0.0735083", "0", "2"], ["83989.4", "0.03979155", "0", "1"], ["83994.6", "0", "0", "0"], ["83997.4", "0.02382802", "0", "1"], ["83997.7", "0", "0", "0"], ["83998.9", "0.29241011", "0", "2"], ["83999.3", "0", "0", "0"], ["84002.9", "0", "0", "0"], ["84003.3", "0.23828432", "0", "1"], ["84003.4", "0.04", "0", "1"], ["84004.5", "0.50451932", "0", "2"], ["84007.1", "1.00360407", "0", "2"], ["84007.7", "0.06", "0", "2"], ["84007.8", "0", "0", "0"], ["84008.1", "0.05969", "0", "1"], ["84008.5", "0", "0", "0"], ["84010", "0.003573", "0", "1"], ["84012.5", "0", "0", "0"], ["84012.7", "0.27953218", "0", "1"], ["84012.9", "0.01190294", "0", "1"], ["84018.2", "0.06212194", "0", "1"], ["84020.4", "0", "0", "0"], ["84023.8", "0.01190139", "0", "1"], ["84025.2", "0", "0", "0"], ["84028", "0.21889794", "0", "2"], ["84050.4", "0.35425148", "0", "1"], ["84052.2", "0", "0", "0"], ["84063.7", "0.17898725", "0", "1"], ["84080.9", "0.07165719", "0", "1"], ["84081.2", "0.107", "0", "5"], ["84098.1", "0", "0", "0"], ["84098.2", "0", "0", "0"], ["84098.3", "0", "0", "0"], ["84105.9", "0.0426", "0", "3"], ["84106.4", "0.0568", "0", "4"], ["84112.6", "0.00003552", "0", "1"], ["84123.2", "0", "0", "0"], ["84123.4", "0", "0", "0"], ["84123.5", "0", "0", "0"], ["84138.8", "0.00044981", "0", "1"], ["84140", "0.00031221", "0", "2"]], "bids": [["83983.4", "0.03978275", "0", "3"], ["83983", "0", "0", "0"], ["83982", "0.00626868", "0", "4"], ["83980", "0.00001", "0", "1"], ["83978.7", "0", "0", "0"], ["83978.3", "0", "0", "0"], ["83976.5", "0", "0", "0"], ["83975.8", "0.17898725", "0", "1"], ["83975", "0", "0", "0"], ["83974.7", "0.51848087", "0", "2"], ["83974.3", "0", "0", "0"], ["83972.7", "0.01191401", "0", "1"], ["83972.1", "0", "0", "0"], ["83971.8", "1", "0", "1"], ["83970.7", "0", "0", "0"], ["83969.3", "0.35721", "0", "1"], ["83968.8", "0.01389", "0", "1"], ["83968.4", "0", "0", "0"], ["83966.1", "0.17898725", "0", "1"], ["83965.4", "0.04", "0", "1"], ["83962.4", "0", "0", "0"], ["83961.9", "0.12502", "0", "1"], ["83961.5", "0.31052924", "0", "1"], ["83961", "0", "0", "0"], ["83958.4", "0", "0", "0"], ["83958.3", "0.471533", "0", "1"], ["83956.8", "0.08608", "0", "1"], ["83956.5", "0", "0", "0"], ["83954.4", "0", "0", "0"], ["83954.3", "0", "0", "0"], ["83952.2", "0", "0", "0"], ["83951.6", "0.0000559", "0", "1"], ["83951.3", "0", "0", "0"], ["83950.9", "0.06154573", "0", "1"], ["83949.8", "0", "0", "0"], ["83949.6", "0.08", "0", "2"], ["83948.9", "0.23828432", "0", "1"], ["83948.8", "0.0408", "0", "3"], ["83948.4", "0", "0", "0"], ["83948", "0.51926", "0", "2"], ["83944", "0", "0", "0"], ["83943.2", "0.1", "0", "2"], ["83942.4", "0.05", "0", "1"], ["83942.2", "0.01190294", "0", "1"], ["83939.6", "0.01190356", "0", "1"], ["83939.3", "0", "0", "0"], ["83934.2", "0.01788075", "0", "1"], ["83910.6", "0", "0", "0"], ["83904.8", "0.51869582", "0", "2"], ["83898.2", "0.02072457", "0", "1"], ["83894.5", "0.00579957", "0", "1"], ["83891.9", "0", "0", "0"], ["83889.2", "0.00579957", "0", "1"], ["83884", "0.00579957", "0", "1"], ["83883.9", "0.00589928", "0", "1"], ["83880", "0.06521459", "0", "2"], ["83877.1", "0.00579957", "0", "1"], ["83850.3", "0.05364228", "0", "1"], ["83833.6", "0", "0", "0"], ["83833.5", "0", "0", "0"], ["83833.3", "0.0075514", "0", "10"], ["83830.6", "0", "0", "0"], ["83826.1", "0.00015468", "0", "1"], ["83826", "0.2025", "0", "1"], ["83825.9", "0.00001586", "0", "1"], ["83825.4", "0.00001365", "0", "1"], ["83825.1", "0.0166188", "0", "1"], ["83825", "0.00008012", "0", "2"], ["83824.2", "0.20833794", "0", "2"], ["83823.6", "0.35776874", "0", "1"], ["83823.5", "0.00039533", "0", "1"], ["83823", "0.00001199", "0", "1"]], "ts": "1742577053100", "checksum": -1031363644, "seqId": 49944986823, "prevSeqId": 49944986608}], "record_time": 1742577053.27352, "EXCHANGE": "OKX"}
{"arg": {"channel": "books", "instId": "BTC-USDT"}, "action": "update", "data": [{"asks": [["83983.5", "1.3488862", "0", "18"], ["83989.4", "0", "0", "0"], ["83991.1", "0.02", "0", "1"], ["83996.9", "0.33155098", "0", "1"], ["83997", "0.36221", "0", "2"], ["83998.8", "0.06", "0", "2"], ["83999.4", "0", "0", "0"], ["84000.2", "0.17211714", "0", "1"], ["84002.1", "0.03", "0", "1"], ["84002.2", "0.03", "0", "1"], ["84003.3", "0", "0", "0"], ["84004.3", "0", "0", "0"], ["84007.6", "0.23827463", "0", "1"], ["84044.2", "0.82477", "0", "1"], ["84045.9", "0", "0", "0"], ["84047.9", "0.01127711", "0", "1"], ["84054.9", "0", "0", "0"], ["84055.2", "0.04497", "0", "1"], ["84140", "0", "0", "0"]], "bids": [["83983.4", "0.01", "0", "2"], ["83973.1", "0", "0", "0"], ["83971.9", "0", "0", "0"], ["83970.4", "0.11118124", "0", "1"], ["83970.3", "0", "0", "0"], ["83969.7", "0.18761632", "0", "1"], ["83969.3", "0", "0", "0"], ["83968.5", "0.18156978", "0", "4"], ["83965.4", "0.174853", "0", "2"], ["83965.2", "0.036", "0", "1"], ["83965", "0.16243252", "0", "2"], ["83964.3", "0.35721", "0", "1"], ["83963.8", "0", "0", "0"], ["83958.7", "0.0036", "0", "1"], ["83957", "0", "0", "0"], ["83955.5", "0.0119013", "0", "1"], ["83951.6", "0.23833378", "0", "2"], ["83949", "0.01774536", "0", "1"], ["83948.9", "0", "0", "0"], ["83948.3", "0", "0", "0"], ["83947.2", "0.03790223", "0", "3"], ["83945.8", "0.6226816", "0", "2"], ["83944", "0.1", "0", "2"], ["83943.2", "0.05", "0", "1"], ["83942.4", "0", "0", "0"], ["83938.1", "0", "0", "0"], ["83931.3", "0.84422531", "0", "2"], ["83866.7", "0.00005728", "0", "1"], ["83860.1", "0.1834731", "0", "1"], ["83822.5", "0.00003465", "0", "2"], ["83822.4", "0.00001007", "0", "1"], ["83822.2", "0.00299792", "0", "1"]], "ts": "1742577053200", "checksum": 47973660, "seqId": 49944986892, "prevSeqId": 49944986823}], "record_time": 1742577053.373295, "EXCHANGE": "OKX"}
{"arg": {"channel": "books", "instId": "BTC-USDT"}, "action": "update", "data": [{"asks": [["84007.6", "0", "0", "0"], ["84007.7", "0.03", "0", "1"], ["84010.1", "0.2382728", "0", "1"], ["84043.2", "0", "0", "0"], ["84140", "0.00031221", "0", "2"]], "bids": [["83971.7", "0.0428883", "0", "1"], ["83965.2", "0.12", "0", "3"], ["83962.8", "0.17861", "0", "1"], ["83958.7", "0", "0", "0"], ["83953.7", "0.17861", "0", "1"], ["83948", "2.06718364", "0", "3"], ["83822.4", "0", "0", "0"], ["83822.2", "0", "0", "0"]], "ts": "1742577053300", "checksum": -202138890, "seqId": 49944986906, "prevSeqId": 49944986892}], "record_time": 1742577053.472274, "EXCHANGE": "OKX"}
{"arg": {"channel": "books", "instId": "BTC-USDT"}, "action": "update", "data": [{"asks": [["83985.2", "0", "0", "0"], ["83990.6", "0.0063", "0", "2"], ["84000.7", "0.002", "0", "1"], ["84003.6", "0", "0", "0"], ["84007.7", "0", "0", "0"], ["84014.7", "0.01190268", "0", "1"], ["84020", "0.2", "0", "1"], ["84023.8", "0", "0", "0"], ["84141.1", "0.00005109", "0", "1"]], "bids": [["83981.5", "0.002", "0", "1"], ["83973.1", "1", "0", "1"], ["83971.8", "0", "0", "0"], ["83971.5", "0.00201199", "0", "2"], ["83967.7", "0.00359599", "0", "1"], ["83965.2", "0.153", "0", "4"], ["83953.1", "0", "0", "0"], ["83945.6", "0.01190268", "0", "1"], ["83915", "0.12502", "0", "1"], ["83823.5", "0", "0", "0"], ["83823", "0", "0", "0"], ["83822.5", "0", "0", "0"]], "ts": "1742577053400", "checksum": 693054854, "seqId": 49944986928, "prevSeqId": 49944986906}], "record_time": 1742577053.572802, "EXCHANGE": "OKX"}
{"arg": {"channel": "books", "instId": "BTC-USDT"}, "action": "update", "data": [{"asks": [["83983.5", "1.35245927", "0", "19"], ["84010", "0", "0", "0"], ["84141.2", "0.00011161", "0", "1"]], "bids": [["83964.3", "0", "0", "0"], ["83961.8", "0.35721", "0", "1"], ["83957.7", "0.004935", "0", "1"], ["83954.6", "0", "0", "0"], ["83949", "0", "0", "0"], ["83948.3", "0.01774536", "0", "1"], ["83945.4", "0.18234044", "0", "2"]], "ts": "1742577053500", "checksum": 623479427, "seqId": 49944986943, "prevSeqId": 49944986928}], "record_time": 1742577053.671979, "EXCHANGE": "OKX"}
{"arg": {"channel": "books", "instId": "BTC-USDT"}, "action": "update", "data": [{"asks": [["84020", "0", "0", "0"], ["84024", "0.08", "0", "2"], ["84024.8", "0.03999999", "0", "1"], ["84025.6", "0.24136306", "0", "1"], ["84026.4", "0", "0", "0"]], "bids": [["83951.2", "0.17861", "0", "1"], ["83924.2", "0.13097302", "0", "2"], ["83917.3", "0.30412121", "0", "2"], ["83823.6", "0", "0", "0"]], "ts": "1742577053600", "checksum": 623479427, "seqId": 49944986955, "prevSeqId": 49944986943}], "record_time": 1742577053.772522, "EXCHANGE": "OKX"}
{"arg": {"channel": "books", "instId": "BTC-USDT"}, "action": "update", "data": [{"asks": [["83986.6", "0", "0", "0"], ["84117.6", "0.18342405", "0", "2"], ["84141.3", "0.00083", "0", "1"]], "bids": [["83980", "0.04391", "0", "2"], ["83964.3", "0.35721", "0", "1"], ["83962.8", "0", "0", "0"], ["83961.8", "0", "0", "0"], ["83951.2", "0", "0", "0"], ["83948.2", "1.25857454", "0", "1"], ["83917.3", "0", "0", "0"], ["83885.6", "0.43950542", "0", "1"], ["83823.6", "0.35776874", "0", "1"], ["83823.5", "0.00039533", "0", "1"]], "ts": "1742577053700", "checksum": -1750563482, "seqId": 49944986973, "prevSeqId": 49944986955}], "record_time": 1742577053.872165, "EXCHANGE": "OKX"}
{"arg": {"channel": "books", "instId": "BTC-USDT"}, "action": "update", "data": [{"asks": [["84006.1", "0.24328791", "0", "3"], ["84010.1", "0", "0", "0"], ["84141.4", "0.08762", "0", "1"]], "bids": [["83974.4", "1", "0", "1"], ["83973.1", "0", "0", "0"], ["83965.3", "0.17861", "0", "1"], ["83823.5", "0", "0", "0"]], "ts": "1742577053800", "checksum": 107186740, "seqId": 49944986980, "prevSeqId": 49944986973}], "record_time": 1742577053.97234, "EXCHANGE": "OKX"}
{"arg": {"channel": "books", "instId": "BTC-USDT"}, "action": "update", "data": [{"asks": [["84014", "1.01190278", "0", "2"]], "bids": [["83949", "0.2", "0", "1"], ["83948", "3.06718364", "0", "4"], ["83823.6", "0", "0", "0"]], "ts": "1742577053900", "checksum": 107186740, "seqId": 49944986987, "prevSeqId": 49944986980}], "record_time": 1742577054.075558, "EXCHANGE": "OKX"}
{"arg": {"channel": "books", "instId": "BTC-USDT"}, "action": "update", "data": [{"asks": [], "bids": [["83965.4", "0.04", "0", "1"]], "ts": "1742577054000", "checksum": 107186740, "seqId": 49944986989, "prevSeqId": 49944986987}], "record_time": 1742577054.175107, "EXCHANGE": "OKX"}
{"arg": {"channel": "books", "instId": "BTC-USDT"}, "action": "update", "data": [{"asks": [["84005.8", "0.26827679", "0", "2"], ["84006.1", "0.00501198", "0", "2"], ["84038.5", "0.00002157", "0", "1"], ["84041.7", "0", "0", "0"], ["84046.5", "0.01127711", "0", "1"], ["84047.9", "0", "0", "0"], ["84081.4", "0.10593318", "0", "3"]], "bids": [["83980", "0.00001", "0", "1"], ["83975.6", "0.04467633", "0", "1"], ["83964.4", "0.13496361", "0", "2"], ["83948", "2.06718364", "0", "3"], ["83931.3", "0.825878", "0", "1"], ["83930.2", "0.01834727", "0", "1"], ["83917.5", "0", "0", "0"], ["83915.1", "0.00363837", "0", "2"], ["83914.6", "0", "0", "0"], ["83896.1", "0", "0", "0"], ["83894.6", "0.0001836", "0", "1"], ["83860.1", "0", "0", "0"], ["83858.7", "0.18347279", "0", "1"], ["83824.2", "0", "0", "0"]], "ts": "1742577054100", "checksum": 564668855, "seqId": 49944987026, "prevSeqId": 49944986989}], "record_time": 1742577054.272333, "EXCHANGE": "OKX"}
{"arg": {"channel": "books", "instId": "BTC-USDT"}, "action": "update", "data": [{"asks": [["84094.6", "0", "0", "0"], ["84141.9", "0.00085329", "0", "2"]], "bids": [], "ts": "1742577054200", "checksum": 564668855, "seqId": 49944987028, "prevSeqId": 49944987026}], "record_time": 1742577054.374076, "EXCHANGE": "OKX"}
{"arg": {"channel": "books", "instId": "BTC-USDT"}, "action": "update", "data": [{"asks": [["83983.5", "1.15245927", "0", "18"], ["84058.9", "0", "0", "0"], ["84063.9", "0.00713742", "0", "1"], ["84112.2", "0", "0", "0"], ["84142.1", "0.00083", "0", "1"], ["84142.2", "0.17898725", "0", "1"]], "bids": [["83975.9", "0.17651305", "0", "1"], ["83974.8", "0.36471325", "0", "2"], ["83974.7", "0.26044584", "0", "1"], ["83974.6", "0", "0", "0"], ["83897.9", "0", "0", "0"], ["83887.9", "0", "0", "0"], ["83824.2", "0.20833794", "0", "2"], ["83823.6", "0.35776874", "0", "1"]], "ts": "1742577054400", "checksum": -589934491, "seqId": 49944987048, "prevSeqId": 49944987028}], "record_time": 1742577054.573243, "EXCHANGE": "OKX"}
{"arg": {"channel": "books", "instId": "BTC-USDT"}, "action": "update", "data": [{"asks": [["83983.5", "1.14092689", "0", "17"], ["84038.5", "0", "0", "0"], ["84142.8", "0.02898561", "0", "3"]], "bids": [], "ts": "1742577054500", "checksum": 2075924321, "seqId": 49944987051, "prevSeqId": 49944987048}], "record_time": 1742577054.672824, "EXCHANGE": "OKX"}
{"arg": {"channel": "books", "instId": "BTC-USDT"}, "action": "update", "data": [{"asks": [["83992.7", "0.01153238", "0", "1"], ["84005.8", "0.03", "0", "1"], ["84007", "0.23827535", "0", "1"], ["84020", "0.2", "0", "1"], ["84038.5", "0.00002157", "0", "1"], ["84052.9", "0.00118972", "0", "1"], ["84057.9", "0.21679828", "0", "3"], ["84106.3", "0.00251788", "0", "1"], ["84141.3", "0", "0", "0"], ["84141.4", "0", "0", "0"], ["84141.9", "0", "0", "0"], ["84142.1", "0", "0", "0"], ["84142.2", "0", "0", "0"], ["84142.8", "0", "0", "0"]], "bids": [["83980", "0.04391", "0", "2"], ["83964.3", "0", "0", "0"], ["83956.2", "0.5351423", "0", "2"], ["83953.7", "0", "0", "0"], ["83951.6", "0.23832941", "0", "2"], ["83893.4", "0.00213853", "0", "1"], ["83890.4", "0.01510524", "0", "1"]], "ts": "1742577054600", "checksum": 341826289, "seqId": 49944987083, "prevSeqId": 49944987051}], "record_time": 1742577054.772302, "EXCHANGE": "OKX"}
{"arg": {"channel": "books", "instId": "BTC-USDT"}, "action": "update", "data": [{"asks": [["83983.9", "0.07687418", "0", "2"], ["83984.1", "0.01191373", "0", "1"], ["83984.2", "0", "0", "0"], ["83984.9", "0", "0", "0"], ["83985.3", "0.036", "0", "1"], ["83987.4", "0.11912275", "0", "1"], ["83998.9", "0.2025", "0", "1"], ["84004.5", "0.26167886", "0", "1"], ["84007", "0", "0", "0"], ["84007.1", "0.00360407", "0", "1"], ["84008.5", "1", "0", "1"], ["84010.1", "0.23827053", "0", "1"], ["84012.6", "0", "0", "0"], ["84014", "0.01190278", "0", "1"], ["84016.8", "0.0008", "0", "2"], ["84017.6", "0.0004", "0", "1"], ["84018.4", "0", "0", "0"], ["84019.2", "0", "0", "0"], ["84020", "0", "0", "0"], ["84024", "0", "0", "0"], ["84024.8", "0.07999999", "0", "2"], ["84025.6", "0.28136305", "0", "2"], ["84141.3", "0.00083", "0", "1"], ["84141.4", "0.08762", "0", "1"]], "bids": [["83983.4", "0.29241486", "0", "5"], ["83982.8", "0.11912913", "0", "1"], ["83982", "0.05016868", "0", "5"], ["83975.9", "0.51519892", "0", "2"], ["83975.7", "1", "0", "1"], ["83975", "0.2025", "0", "1"], ["83974.7", "0.02954804", "0", "1"], ["83974.4", "0", "0", "0"], ["83971.1", "0.01389", "0", "1"], ["83969.3", "0.35721", "0", "1"], ["83968.8", "0", "0", "0"], ["83951.8", "0.23827053", "0", "1"], ["83951.6", "0.0000559", "0", "1"], ["83950.9", "0", "0", "0"], ["83949.6", "0.0808", "0", "4"], ["83949", "0", "0", "0"], ["83948.8", "0.0404", "0", "2"], ["83948", "2.06678364", "0", "2"], ["83917.3", "0.05437302", "0", "1"], ["83894.4", "0.28326206", "0", "1"], ["83825", "0", "0", "0"], ["83824.2", "0", "0", "0"], ["83823.6", "0", "0", "0"]], "ts": "1742577054700", "checksum": -1772915777, "seqId": 49944987144, "prevSeqId": 49944987083}], "record_time": 1742577054.872832, "EXCHANGE": "OKX"}
{"arg": {"channel": "books", "instId": "BTC-USDT"}, "action": "update", "data": [{"asks": [["83983.5", "1.12715382", "0", "15"], ["83985.7", "0.0102", "0", "1"], ["84010.1", "0.23826853", "0", "1"], ["84013", "0.003573", "0", "1"], ["84018.2", "0", "0", "0"], ["84046.5", "0", "0", "0"], ["84048.9", "0.01128686", "0", "1"], ["84141.4", "0", "0", "0"]], "bids": [["83983.4", "0.20581486", "0", "4"], ["83970.4", "0.22205838", "0", "2"], ["83965.3", "0", "0", "0"], ["83961.2", "0.31932224", "0", "2"], ["83956.2", "0.3565323", "0", "1"], ["83955.2", "0.25016835", "0", "2"], ["83955.1", "0.05707126", "0", "1"], ["83951.8", "0", "0", "0"], ["83951.5", "0.202515", "0", "2"], ["83936.3", "0.00008513", "0", "1"], ["83932", "0.01834644", "0", "1"], ["83930.2", "0", "0", "0"], ["83860.1", "0.18346447", "0", "1"], ["83858.7", "0", "0", "0"]], "ts": "1742577054800", "checksum": 1616059295, "seqId": 49944987175, "prevSeqId": 49944987144}], "record_time": 1742577054.99925, "EXCHANGE": "OKX"}
{"arg": {"channel": "books", "instId": "BTC-USDT"}, "action": "update", "data": [{"asks": [["84022.6", "0.06040458", "0", "1"], ["84141.3", "0", "0", "0"]], "bids": [["83967.8", "0.17861", "0", "1"], ["83957", "0.12502", "0", "1"], ["83955.2", "0.01190108", "0", "1"], ["83951.6", "0.23832391", "0", "2"], ["83915", "0", "0", "0"], ["83825.1", "0", "0", "0"]], "ts": "1742577054900", "checksum": 1616059295, "seqId": 49944987189, "prevSeqId": 49944987175}], "record_time": 1742577055.072417, "EXCHANGE": "OKX"}
{"arg": {"channel": "books", "instId": "BTC-USDT"}, "action": "update", "data": [{"asks": [["84006.9", "1", "0", "1"], ["84008.5", "0", "0", "0"], ["84016.8", "0", "0", "0"], ["84017.6", "0.0008", "0", "2"], ["84018.4", "0.0004", "0", "1"]], "bids": [["83967.8", "0", "0", "0"], ["83949.6", "0.08", "0", "2"], ["83948.8", "0.0408", "0", "3"], ["83948", "2.06718364", "0", "3"], ["83944", "0", "0", "0"], ["83943.2", "0.1", "0", "2"], ["83942.4", "0.05", "0", "1"], ["83825.1", "0.0166188", "0", "1"]], "ts": "1742577055000", "checksum": 1616059295, "seqId": 49944987205, "prevSeqId": 49944987189}], "record_time": 1742577055.17448, "EXCHANGE": "OKX"}
{"arg": {"channel": "books", "instId": "BTC-USDT"}, "action": "update", "data": [{"asks": [["84006.9", "0", "0", "0"], ["84007", "1", "0", "1"], ["84010.1", "0.23827053", "0", "1"], ["84016.8", "0.0008", "0", "2"], ["84017.6", "0.0004", "0", "1"], ["84018.4", "0", "0", "0"], ["84024", "0.08", "0", "2"], ["84024.8", "0.03999999", "0", "1"], ["84025.6", "0.24136306", "0", "1"], ["84141.2", "0", "0", "0"]], "bids": [["83982", "0.00626868", "0", "4"], ["83975.9", "0.17651305", "0", "1"], ["83975.7", "0", "0", "0"], ["83974.7", "0.33002153", "0", "2"], ["83973.7", "1", "0", "1"], ["83967.8", "0.17861", "0", "1"], ["83951.6", "0.23832638", "0", "2"], ["83950", "1.01672", "0", "2"], ["83949.6", "0.0808", "0", "4"], ["83948.8", "0.0404", "0", "2"], ["83948", "2.06678364", "0", "2"], ["83944", "0.1", "0", "2"], ["83943.2", "0.05", "0", "1"], ["83942.4", "0", "0", "0"], ["83825.1", "0", "0", "0"]], "ts": "1742577055100", "checksum": -1702105735, "seqId": 49944987260, "prevSeqId": 49944987205}], "record_time": 1742577055.272603, "EXCHANGE": "OKX"}
{"arg": {"channel": "books", "instId": "BTC-USDT"}, "action": "update", "data": [{"asks": [["83983.5", "1.13735382", "0", "16"], ["83985.7", "0", "0", "0"], ["84005.7", "0.23827485", "0", "1"], ["84010.1", "0", "0", "0"], ["84141.2", "0.00011161", "0", "1"]], "bids": [["83983.4", "0.01", "0", "2"], ["83975", "0", "0", "0"], ["83971.1", "0", "0", "0"], ["83969.3", "0", "0", "0"], ["83968.3", "0.01390501", "0", "2"], ["83961.2", "0.14071224", "0", "1"], ["83957.7", "0", "0", "0"], ["83950.1", "0.01774536", "0", "1"], ["83950", "0.01672", "0", "1"], ["83948.3", "0", "0", "0"], ["83947.6", "0", "0", "0"], ["83825.1", "0.0166188", "0", "1"], ["83825", "0.00008012", "0", "2"], ["83824.2", "0.20833794", "0", "2"], ["83823.6", "0.35776874", "0", "1"], ["83823.5", "0.00039533", "0", "1"]], "ts": "1742577055200", "checksum": -1389046660, "seqId": 49944987283, "prevSeqId": 49944987260}], "record_time": 1742577055.376383, "EXCHANGE": "OKX"}
{"arg": {"channel": "books", "instId": "BTC-USDT"}, "action": "update", "data": [{"asks": [["83983.5", "1.33735382", "0", "17"]], "bids": [["83966.8", "0.35721", "0", "1"], ["83957", "0", "0", "0"], ["83941.9", "0.56", "0", "1"], ["83883", "0", "0", "0"]], "ts": "1742577055300", "checksum": -651451457, "seqId": 49944987290, "prevSeqId": 49944987283}], "record_time": 1742577055.472687, "EXCHANGE": "OKX"}
{"arg": {"channel": "books", "instId": "BTC-USDT"}, "action": "update", "data": [{"asks": [["84005.7", "0", "0", "0"], ["84008", "0.23827427", "0", "1"], ["84013.5", "0", "0", "0"], ["84042.8", "0.36352404", "0", "1"], ["84043.6", "0", "0", "0"], ["84141.3", "0.00083", "0", "1"], ["84141.4", "0.08762", "0", "1"]], "bids": [["83965.3", "0.17861", "0", "1"], ["83957.7", "0.0000135", "0", "1"], ["83956.2", "0.5351423", "0", "2"], ["83950.1", "0", "0", "0"], ["83948.3", "0.01774536", "0", "1"], ["83948.2", "0", "0", "0"], ["83948", "0.51886", "0", "1"], ["83928.4", "0", "0", "0"], ["83928.3", "0", "0", "0"], ["83915", "0.12502", "0", "1"]], "ts": "1742577055400", "checksum": -651451457, "seqId": 49944987309, "prevSeqId": 49944987290}], "record_time": 1742577055.571967, "EXCHANGE": "OKX"}
{"arg": {"channel": "books", "instId": "BTC-USDT"}, "action": "update", "data": [{"asks": [["84006.4", "1.62329617", "0", "1"], ["84008", "0", "0", "0"], ["84010.1", "0.23827284", "0", "1"], ["84036.4", "3.0037895", "0", "1"], ["84141.3", "0", "0", "0"], ["84141.4", "0", "0", "0"]], "bids": [["83952", "0.23827284", "0", "1"], ["83951.9", "1.55022009", "0", "1"], ["83951.6", "0.0000559", "0", "1"], ["83921.9", "2.79750071", "0", "1"], ["83824.2", "0", "0", "0"], ["83823.6", "0", "0", "0"], ["83823.5", "0", "0", "0"]], "ts": "1742577055500", "checksum": -651451457, "seqId": 49944987317, "prevSeqId": 49944987309}], "record_time": 1742577055.681013, "EXCHANGE": "OKX"}
{"arg": {"channel": "books", "instId": "BTC-USDT"}, "action": "update", "data": [{"asks": [["84071.5", "0.0713679", "0", "1"]], "bids": [["83906.6", "0.071508", "0", "1"]], "ts": "1742577055600", "checksum": -651451457, "seqId": 49944987325, "prevSeqId": 49944987317}], "record_time": 1742577055.77477, "EXCHANGE": "OKX"}
{"arg": {"channel": "books", "instId": "BTC-USDT"}, "action": "update", "data": [{"asks": [["83983.5", "1.13735382", "0", "16"], ["84004.5", "0.97290817", "0", "2"], ["84014", "1.01190278", "0", "2"], ["84017.1", "0.01190234", "0", "1"], ["84020", "0.2", "0", "1"], ["84025.4", "0", "0", "0"], ["84033.9", "1.36897049", "0", "2"], ["84060.3", "0.07137733", "0", "1"], ["84071.5", "0", "0", "0"], ["84141.2", "0", "0", "0"]], "bids": [["83983.4", "0.28636144", "0", "4"], ["83982", "0.05016868", "0", "5"], ["83952.1", "0.01774536", "0", "1"], ["83950", "0.21672", "0", "2"], ["83948.3", "0", "0", "0"], ["83948.1", "0.85285339", "0", "2"], ["83923.5", "1.03919408", "0", "2"], ["83906.6", "0", "0", "0"], ["83895.6", "0.07151745", "0", "1"], ["83885.6", "1.09852694", "0", "2"]], "ts": "1742577055700", "checksum": 574382285, "seqId": 49944987357, "prevSeqId": 49944987325}], "record_time": 1742577055.875895, "EXCHANGE": "OKX"}
{"arg": {"channel": "books", "instId": "BTC-USDT"}, "action": "update", "data": [{"asks": [["83983.5", "0.90732514", "0", "13"], ["83985.8", "0.0102", "0", "1"], ["84004.5", "0.26167886", "0", "1"], ["84007", "0", "0", "0"], ["84007.4", "1.00001501", "0", "2"], ["84010.1", "0.23826902", "0", "1"], ["84060.3", "0.14275466", "0", "2"]], "bids": [["83983.4", "0.20571499", "0", "4"], ["83975.9", "0.51519892", "0", "2"], ["83975", "1.2025", "0", "2"], ["83974.7", "0.02954804", "0", "1"], ["83973.7", "0", "0", "0"], ["83971.5", "0.01590199", "0", "3"], ["83970.4", "0.11118124", "0", "1"], ["83968.3", "0.00001501", "0", "1"], ["83967.8", "0", "0", "0"], ["83966.8", "0", "0", "0"], ["83965.3", "0", "0", "0"], ["83955.2", "0.25016955", "0", "2"], ["83952", "0", "0", "0"], ["83895.6", "0.1430349", "0", "2"], ["83883.7", "0.07165719", "0", "1"], ["83824.2", "0.20833794", "0", "2"], ["83823.6", "0.35776874", "0", "1"], ["83823.5", "0.00039533", "0", "1"]], "ts": "1742577055800", "checksum": 26697527, "seqId": 49944987414, "prevSeqId": 49944987357}], "record_time": 1742577055.972073, "EXCHANGE": "OKX"}
{"arg": {"channel": "books", "instId": "BTC-USDT"}, "action": "update", "data": [{"asks": [["83983.5", "1.00732514", "0", "14"]], "bids": [["83970.4", "0.16847838", "0", "2"], ["83958", "0.13531514", "0", "5"], ["83957", "0.12502", "0", "1"], ["83956.2", "0.3565323", "0", "1"], ["83955.2", "0.01190108", "0", "1"], ["83952.1", "0", "0", "0"], ["83952", "0.23826942", "0", "1"], ["83924.2", "0.00595302", "0", "1"], ["83915", "0", "0", "0"], ["83883", "0.6", "0", "1"], ["83823.5", "0", "0", "0"]], "ts": "1742577055900", "checksum": 1692662720, "seqId": 49944987430, "prevSeqId": 49944987414}], "record_time": 1742577056.071953, "EXCHANGE": "OKX"}
{"arg": {"channel": "books", "instId": "BTC-USDT"}, "action": "update", "data": [{"asks": [["84014.5", "0.01190271", "0", "1"], ["84023.6", "0", "0", "0"]], "bids": [["83966.8", "0.35721", "0", "1"], ["83883.7", "0", "0", "0"]], "ts": "1742577056000", "checksum": 1692662720, "seqId": 49944987436, "prevSeqId": 49944987430}], "record_time": 1742577056.173394, "EXCHANGE": "OKX"}
{"arg": {"channel": "books", "instId": "BTC-USDT"}, "action": "update", "data": [{"asks": [["84016.2", "0.01190247", "0", "1"], ["84018.5", "0.15261439", "0", "2"], ["84024.5", "0", "0", "0"], ["84026", "0", "0", "0"], ["84141.2", "0.00011161", "0", "1"]], "bids": [["83965.3", "0.17861", "0", "1"], ["83956.2", "0.5351423", "0", "2"], ["83955.5", "0", "0", "0"], ["83947.2", "0.0498047", "0", "4"], ["83924.2", "0.13097302", "0", "2"], ["83915.2", "0.00363802", "0", "2"], ["83915.1", "0", "0", "0"], ["83901.6", "0", "0", "0"], ["83823.5", "0.00039533", "0", "1"]], "ts": "1742577056100", "checksum": 1692662720, "seqId": 49944987461, "prevSeqId": 49944987436}], "record_time": 1742577056.272144, "EXCHANGE": "OKX"}
{"arg": {"channel": "books", "instId": "BTC-USDT"}, "action": "update", "data": [{"asks": [["83983.5", "1.01752514", "0", "15"], ["83985.8", "0", "0", "0"], ["84007.4", "0.00001501", "0", "1"], ["84020", "0", "0", "0"], ["84141.3", "0.00083", "0", "1"], ["84141.4", "0.08762", "0", "1"]], "bids": [["83983.4", "0.01", "0", "2"], ["83982", "0.00626868", "0", "4"], ["83975.9", "0.17651305", "0", "1"], ["83975", "0", "0", "0"], ["83971.5", "0.00201199", "0", "2"], ["83968.8", "0.01389", "0", "1"], ["83965.3", "0", "0", "0"], ["83959.6", "1", "0", "1"], ["83957", "0", "0", "0"], ["83883", "0.67165719", "0", "2"], ["83823", "0.00001199", "0", "1"]], "ts": "1742577056200", "checksum": 1636750378, "seqId": 49944987488, "prevSeqId": 49944987461}], "record_time": 1742577056.372652, "EXCHANGE": "OKX"}
{"arg": {"channel": "books", "instId": "BTC-USDT"}, "action": "update", "data": [{"asks": [["83983.5", "1.21752514", "0", "16"], ["84010.1", "0.23827184", "0", "1"], ["84047.9", "0.0112846", "0", "1"], ["84048.9", "0", "0", "0"], ["84097", "0.6", "0", "1"], ["84141.4", "0", "0", "0"]], "bids": [["83975.9", "0.51519892", "0", "2"], ["83975.1", "1", "0", "1"], ["83975", "0.2025", "0", "1"], ["83959.6", "0", "0", "0"], ["83958", "0.11756978", "0", "4"], ["83952.1", "0.01774536", "0", "1"], ["83950", "0.01672", "0", "1"], ["83932", "0", "0", "0"], ["83931.4", "0.01834684", "0", "1"], ["83823.5", "0", "0", "0"], ["83823", "0", "0", "0"]], "ts": "1742577056300", "checksum": 1777966664, "seqId": 49944987506, "prevSeqId": 49944987488}], "record_time": 1742577056.472582, "EXCHANGE": "OKX"}
{"arg": {"channel": "books", "instId": "BTC-USDT"}, "action": "update", "data": [{"asks": [["83987.4", "0", "0", "0"], ["84007.4", "1.00001501", "0", "2"], ["84010.1", "0.23827259", "0", "1"], ["84141.4", "0.08762", "0", "1"]], "bids": [["83980", "0.00001", "0", "1"], ["83975.9", "0.45444892", "0", "2"], ["83975.1", "0", "0", "0"], ["83975", "1", "0", "1"], ["83967.7", "0", "0", "0"], ["83965.3", "0.17861", "0", "1"], ["83964.4", "0.00011161", "0", "1"], ["83957.7", "0", "0", "0"], ["83915", "0.12502", "0", "1"], ["83894.6", "0", "0", "0"], ["83883", "0.6", "0", "1"], ["83881.3", "0.07165719", "0", "1"], ["83823.5", "0.00039533", "0", "1"]], "ts": "1742577056400", "checksum": 2112999902, "seqId": 49944987534, "prevSeqId": 49944987506}], "record_time": 1742577056.572524, "EXCHANGE": "OKX"}
{"arg": {"channel": "books", "instId": "BTC-USDT"}, "action": "update", "data": [{"asks": [["83983.9", "0.07207509", "0", "2"], ["83985.2", "0.11912578", "0", "1"], ["84016", "0.00081198", "0", "3"], ["84016.8", "0.0004", "0", "1"], ["84017.6", "0", "0", "0"]], "bids": [["83964.3", "0.35721", "0", "1"], ["83964", "0.134854", "0", "1"], ["83957.3", "0.000357", "0", "1"], ["83952.1", "0.25601529", "0", "2"], ["83952", "0", "0", "0"], ["83943.2", "0.61", "0", "2"], ["83941.9", "0", "0", "0"], ["83894.6", "0.00018359", "0", "1"], ["83823.6", "0", "0", "0"], ["83823.5", "0", "0", "0"]], "ts": "1742577056500", "checksum": 240180476, "seqId": 49944987570, "prevSeqId": 49944987534}], "record_time": 1742577056.672846, "EXCHANGE": "OKX"}
{"arg": {"channel": "books", "instId": "BTC-USDT"}, "action": "update", "data": [{"asks": [["84006.3", "0.23827426", "0", "1"], ["84010.1", "0", "0", "0"], ["84042", "0", "0", "0"], ["84141.9", "0.00085329", "0", "2"]], "bids": [["83952.1", "0.01774536", "0", "1"], ["83952", "0.23827426", "0", "1"], ["83824.2", "0", "0", "0"]], "ts": "1742577056600", "checksum": 240180476, "seqId": 49944987576, "prevSeqId": 49944987570}], "record_time": 1742577056.772717, "EXCHANGE": "OKX"}
{"arg": {"channel": "books", "instId": "BTC-USDT"}, "action": "update", "data": [{"asks": [["84004.5", "1.04439044", "0", "2"], ["84006.3", "0", "0", "0"], ["84010.1", "0.23827475", "0", "1"], ["84099.3", "0", "0", "0"], ["84107.7", "0.00594", "0", "1"], ["84116.1", "0", "0", "0"], ["84124.5", "0", "0", "0"], ["84132.9", "0", "0", "0"], ["84142.1", "0.00083", "0", "1"], ["84142.2", "0.17898725", "0", "1"], ["84142.8", "0.02898561", "0", "3"], ["84143.8", "0.00001314", "0", "1"]], "bids": [["83952.1", "0.25602011", "0", "2"], ["83952", "0.55527883", "0", "1"], ["83927", "0.12270672", "0", "2"], ["83901.9", "0.15624028", "0", "1"], ["83896", "0.00589951", "0", "1"], ["83887.6", "0", "0", "0"], ["83885.6", "0.43950542", "0", "1"], ["83879.2", "0", "0", "0"], ["83870.8", "0", "0", "0"], ["83862.4", "0.00001", "0", "1"], ["83824.2", "0.20833794", "0", "2"], ["83823.6", "0.35776874", "0", "1"]], "ts": "1742577056700", "checksum": 240180476, "seqId": 49944987595, "prevSeqId": 49944987576}], "record_time": 1742577056.872313, "EXCHANGE": "OKX"}
{"arg": {"channel": "books", "instId": "BTC-USDT"}, "action": "update", "data": [{"asks": [["84008", "0.2382759", "0", "1"], ["84010.1", "0", "0", "0"], ["84041.8", "0.01332454", "0", "2"], ["84084.2", "0.00298666", "0", "1"], ["84092.6", "0.00597332", "0", "1"], ["84101", "0.03895999", "0", "2"], ["84109.4", "0.01194665", "0", "1"], ["84117.8", "0.01493332", "0", "1"], ["84142.1", "0", "0", "0"], ["84142.2", "0", "0", "0"], ["84142.8", "0", "0", "0"], ["84143.8", "0", "0", "0"]], "bids": [["83975.1", "1", "0", "1"], ["83975", "0", "0", "0"], ["83883.4", "0.00298666", "0", "1"], ["83875", "0.00597332", "0", "1"], ["83866.6", "0.13820616", "0", "12"], ["83858.2", "0.01789967", "0", "2"], ["83846.9", "0.01493332", "0", "1"], ["83825", "0", "0", "0"], ["83824.2", "0", "0", "0"], ["83823.6", "0", "0", "0"]], "ts": "1742577056800", "checksum": 844768764, "seqId": 49944987620, "prevSeqId": 49944987595}], "record_time": 1742577056.972406, "EXCHANGE": "OKX"}
{"arg": {"channel": "books", "instId": "BTC-USDT"}, "action": "update", "data": [{"asks": [["84016", "0.00001198", "0", "1"], ["84016.8", "0.0008", "0", "2"], ["84017.6", "0.0004", "0", "1"], ["84060.3", "0.07137733", "0", "1"], ["84141.9", "0", "0", "0"]], "bids": [["83975.9", "0.17651305", "0", "1"], ["83975.1", "0", "0", "0"], ["83961.5", "0.57171309", "0", "2"], ["83959.2", "1", "0", "1"], ["83895.6", "0.07151745", "0", "1"]], "ts": "1742577057000", "checksum": 1713457716, "seqId": 49944987639, "prevSeqId": 49944987620}], "record_time": 1742577057.172149, "EXCHANGE": "OKX"}
{"arg": {"channel": "books", "instId": "BTC-USDT"}, "action": "update", "data": [{"asks": [["83984.2", "0.0104925", "0", "1"], ["83990.1", "0", "0", "0"], ["84004.4", "0.29027788", "0", "3"], ["84008", "0", "0", "0"], ["84060.3", "0.14275466", "0", "2"], ["84141.9", "0.00085329", "0", "2"]], "bids": [["83975.9", "0.45444892", "0", "2"], ["83974.9", "1", "0", "1"], ["83961.5", "0.31052924", "0", "1"], ["83959.2", "0", "0", "0"], ["83957.3", "0", "0", "0"], ["83955.8", "0.0001785", "0", "1"], ["83952.1", "0.01774536", "0", "1"], ["83949.7", "0.23827788", "0", "1"], ["83915.3", "0.00145202", "0", "1"], ["83915.2", "0.00218603", "0", "1"], ["83895.6", "0.1430349", "0", "2"], ["83859.4", "0.0023222", "0", "1"], ["83825.9", "0", "0", "0"], ["83825.4", "0", "0", "0"], ["83825.1", "0", "0", "0"]], "ts": "1742577057100", "checksum": -683974811, "seqId": 49944987677, "prevSeqId": 49944987639}], "record_time": 1742577057.272703, "EXCHANGE": "OKX"}
{"arg": {"channel": "books", "instId": "BTC-USDT"}, "action": "update", "data": [{"asks": [["83984.2", "0", "0", "0"], ["84004.4", "0.052", "0", "2"], ["84005.5", "0.26827727", "0", "2"], ["84018", "0.1", "0", "1"]], "bids": [["83975.9", "0.17651305", "0", "1"], ["83974.9", "0", "0", "0"], ["83974.7", "0.32585453", "0", "2"], ["83973.2", "1", "0", "1"], ["83952.1", "0.25602263", "0", "2"], ["83949.7", "0", "0", "0"], ["83949", "1", "0", "1"]], "ts": "1742577057200", "checksum": 874369169, "seqId": 49944987698, "prevSeqId": 49944987677}], "record_time": 1742577057.372342, "EXCHANGE": "OKX"}
{"arg": {"channel": "books", "instId": "BTC-USDT"}, "action": "update", "data": [{"asks": [["83983.7", "0.004956", "0", "1"], ["83998.4", "0", "0", "0"], ["84005.5", "0.26827745", "0", "2"]], "bids": [["83968.6", "0", "0", "0"], ["83967.5", "0.00365583", "0", "1"], ["83952.1", "0.25602281", "0", "2"], ["83949", "0", "0", "0"], ["83946", "0.2", "0", "1"], ["83826", "0", "0", "0"], ["83825.9", "0.00001586", "0", "1"]], "ts": "1742577057300", "checksum": -1883645042, "seqId": 49944987734, "prevSeqId": 49944987698}], "record_time": 1742577057.472456, "EXCHANGE": "OKX"}
{"arg": {"channel": "books", "instId": "BTC-USDT"}, "action": "update", "data": [{"asks": [["83983.7", "0", "0", "0"], ["83983.9", "0.07207433", "0", "2"], ["83985.2", "0", "0", "0"], ["83987", "0.12412326", "0", "2"], ["84142.1", "0.00083", "0", "1"], ["84142.2", "0.17898725", "0", "1"]], "bids": [["83946", "0", "0", "0"], ["83826", "0.2025", "0", "1"]], "ts": "1742577057400", "checksum": -547256679, "seqId": 49944987751, "prevSeqId": 49944987734}], "record_time": 1742577057.572527, "EXCHANGE": "OKX"}
{"arg": {"channel": "books", "instId": "BTC-USDT"}, "action": "update", "data": [{"asks": [["83983.9", "0.07274483", "0", "3"], ["84005.5", "0.03", "0", "1"], ["84010.1", "0.2382749", "0", "1"], ["84142.2", "0", "0", "0"]], "bids": [["83974.8", "0.59650493", "0", "3"], ["83974.7", "1", "0", "1"], ["83973.2", "0", "0", "0"], ["83955.8", "0", "0", "0"], ["83825.4", "0.00001365", "0", "1"], ["83825.1", "0.0166188", "0", "1"]], "ts": "1742577057500", "checksum": -132862799, "seqId": 49944987772, "prevSeqId": 49944987751}], "record_time": 1742577057.672117, "EXCHANGE": "OKX"}
{"arg": {"channel": "books", "instId": "BTC-USDT"}, "action": "update", "data": [{"asks": [["84016", "0.00081198", "0", "3"], ["84016.8", "0.0004", "0", "1"], ["84017.6", "0", "0", "0"], ["84018", "0", "0", "0"], ["84142.2", "0.17898725", "0", "1"], ["84142.8", "0.02898561", "0", "3"]], "bids": [["83980", "0.04391", "0", "2"], ["83957.2", "0.004935", "0", "1"], ["83825.1", "0", "0", "0"]], "ts": "1742577057600", "checksum": 846588577, "seqId": 49944987780, "prevSeqId": 49944987772}], "record_time": 1742577057.77296, "EXCHANGE": "OKX"}
{"arg": {"channel": "books", "instId": "BTC-USDT"}, "action": "update", "data": [{"asks": [["84006.3", "0.23827615", "0", "1"], ["84010.1", "0", "0", "0"], ["84013.1", "0.42295017", "0", "2"], ["84016", "0.00001198", "0", "1"], ["84016.8", "0.0008", "0", "2"], ["84017.6", "0.0004", "0", "1"], ["84142.8", "0", "0", "0"]], "bids": [["83945.4", "0.49762443", "0", "3"], ["83898.2", "0.06009335", "0", "2"]], "ts": "1742577057700", "checksum": 846588577, "seqId": 49944987796, "prevSeqId": 49944987780}], "record_time": 1742577057.874511, "EXCHANGE": "OKX"}
{"arg": {"channel": "books", "instId": "BTC-USDT"}, "action": "update", "data": [{"asks": [["84006.3", "0", "0", "0"], ["84010.1", "0.23827535", "0", "1"], ["84024", "0", "0", "0"], ["84024.8", "0.07999999", "0", "2"], ["84025.6", "0.28136305", "0", "2"], ["84142.8", "0.02898561", "0", "3"]], "bids": [["83949.6", "0.08", "0", "2"], ["83948.8", "0.0408", "0", "3"], ["83948", "0.51926", "0", "2"]], "ts": "1742577057800", "checksum": 846588577, "seqId": 49944987816, "prevSeqId": 49944987796}], "record_time": 1742577057.97193, "EXCHANGE": "OKX"}
{"arg": {"channel": "books", "instId": "BTC-USDT"}, "action": "update", "data": [{"asks": [["84010.1", "0.23827558", "0", "1"], ["84060.3", "0.07137733", "0", "1"]], "bids": [["83975.9", "0.11583996", "0", "1"], ["83974.8", "0.39426129", "0", "3"], ["83974.7", "0", "0", "0"], ["83961.5", "0.57171309", "0", "2"], ["83958.8", "1", "0", "1"], ["83898.2", "0.02072457", "0", "1"], ["83895.6", "0.07151745", "0", "1"]], "ts": "1742577057900", "checksum": -578666750, "seqId": 49944987835, "prevSeqId": 49944987816}], "record_time": 1742577058.072435, "EXCHANGE": "OKX"}
{"arg": {"channel": "books", "instId": "BTC-USDT"}, "action": "update", "data": [{"asks": [["84060.3", "0.14275466", "0", "2"], ["84141.9", "0.00002329", "0", "1"]], "bids": [["83975.9", "0.40135996", "0", "2"], ["83975.2", "1", "0", "1"], ["83961.5", "0.31052924", "0", "1"], ["83958.8", "0", "0", "0"], ["83895.6", "0.1430349", "0", "2"]], "ts": "1742577058000", "checksum": 1648955144, "seqId": 49944987864, "prevSeqId": 49944987835}], "record_time": 1742577058.171962, "EXCHANGE": "OKX"}
{"arg": {"channel": "books", "instId": "BTC-USDT"}, "action": "update", "data": [{"asks": [["83982.9", "1.30138585", "0", "18"], ["83983", "0.1", "0", "1"], ["83983.3", "0.64298652", "0", "1"], ["83983.4", "0.2", "0", "1"], ["83983.5", "0.28599155", "0", "4"], ["83983.9", "0.0006705", "0", "1"], ["83996", "0.0439", "0", "1"], ["84004.9", "0.05190407", "0", "2"], ["84006.1", "0.00001198", "0", "1"], ["84014", "1", "0", "1"], ["84024", "0.08", "0", "2"], ["84024.8", "0.03999999", "0", "1"], ["84025.6", "0.24136306", "0", "1"], ["84141.4", "0", "0", "0"], ["84141.9", "0", "0", "0"], ["84142.1", "0", "0", "0"], ["84142.2", "0", "0", "0"], ["84142.8", "0", "0", "0"]], "bids": [["83983.4", "0", "0", "0"], ["83973.3", "0", "0", "0"], ["83960.3", "0.00714623", "0", "1"], ["83960.1", "0.00476417", "0", "1"], ["83957.2", "0", "0", "0"], ["83955.2", "0", "0", "0"], ["83947.8", "0.01190239", "0", "1"], ["83945.8", "0.045029", "0", "1"], ["83945.3", "0.5776526", "0", "1"], ["83931.4", "0", "0", "0"], ["83931.2", "0.02430034", "0", "2"], ["83915.5", "0.00145204", "0", "1"], ["83915.4", "0.00218609", "0", "1"], ["83915.3", "0", "0", "0"], ["83915.2", "0", "0", "0"], ["83903.8", "0", "0", "0"], ["83903.3", "0.58226341", "0", "1"], ["83860.1", "0", "0", "0"], ["83859.5", "0.18347154", "0", "1"], ["83825.1", "0.0166188", "0", "1"]], "ts": "1742577058100", "checksum": 975234980, "seqId": 49944987982, "prevSeqId": 49944987864}], "record_time": 1742577058.272839, "EXCHANGE": "OKX"}
{"arg": {"channel": "books", "instId": "BTC-USDT"}, "action": "update", "data": [{"asks": [["83982.9", "1.34381432", "0", "19"], ["83983.3", "0.16583139", "0", "1"], ["83983.5", "0.2462", "0", "3"], ["83984.3", "0.02893196", "0", "1"], ["83993.6", "0", "0", "0"], ["84004.9", "0.04", "0", "1"], ["84005.4", "0.23827934", "0", "1"], ["84005.7", "0.01190396", "0", "1"], ["84010.1", "0", "0", "0"], ["84016", "0.00081198", "0", "3"], ["84016.8", "0.0004", "0", "1"], ["84017.6", "0", "0", "0"], ["84027.4", "0.1", "0", "1"], ["84028", "0.11889794", "0", "1"], ["84052.9", "0", "0", "0"], ["84057.9", "0.20252241", "0", "2"], ["84106.3", "0", "0", "0"], ["84141.4", "0.08762", "0", "1"]], "bids": [["83957.6", "0.18394475", "0", "2"], ["83952.1", "0.01774536", "0", "1"], ["83949.7", "0.23827934", "0", "1"], ["83916.7", "0.11889794", "0", "1"], ["83916.1", "0.00100611", "0", "1"], ["83915.5", "0", "0", "0"], ["83914.6", "0.00145204", "0", "1"], ["83894.6", "0", "0", "0"], ["83893.4", "0", "0", "0"], ["83890.4", "0", "0", "0"], ["83825", "0.00008012", "0", "2"]], "ts": "1742577058200", "checksum": 1885972496, "seqId": 49944988027, "prevSeqId": 49944987982}], "record_time": 1742577058.373209, "EXCHANGE": "OKX"}
{"arg": {"channel": "books", "instId": "BTC-USDT"}, "action": "update", "data": [{"asks": [["83983.3", "0.08663069", "0", "1"], ["83983.4", "0", "0", "0"], ["83983.5", "0.0462", "0", "2"], ["84003.8", "0.11909948", "0", "1"], ["84005.4", "0", "0", "0"], ["84006", "0.23827766", "0", "1"], ["84016.6", "0.00060645", "0", "1"], ["84055.2", "0.04615969", "0", "2"], ["84060.2", "0.45119548", "0", "2"], ["84108.6", "0.00251778", "0", "1"], ["84141.4", "0", "0", "0"]], "bids": [["83952.1", "0.25602301", "0", "2"], ["83949.7", "0", "0", "0"], ["83947", "1", "0", "1"], ["83894.6", "0.00018359", "0", "1"], ["83891.6", "0.00213848", "0", "1"], ["83888.5", "0.01510555", "0", "1"], ["83825.4", "0", "0", "0"], ["83825.1", "0", "0", "0"], ["83825", "0", "0", "0"]], "ts": "1742577058300", "checksum": -820545663, "seqId": 49944988058, "prevSeqId": 49944988027}], "record_time": 1742577058.472296, "EXCHANGE": "OKX"}
{"arg": {"channel": "books", "instId": "BTC-USDT"}, "action": "update", "data": [{"asks": [["84006", "0", "0", "0"], ["84006.1", "0.23828964", "0", "2"], ["84016", "0.00001198", "0", "1"], ["84016.8", "0.0008", "0", "2"], ["84017.6", "0.0004", "0", "1"]], "bids": [["83980", "0.00001", "0", "1"], ["83952.1", "0.01774536", "0", "1"], ["83949.7", "0.23827764", "0", "1"], ["83948", "0.71926", "0", "3"], ["83944", "0", "0", "0"], ["83943.2", "0.66", "0", "3"], ["83942.4", "0.05", "0", "1"], ["83825.9", "0", "0", "0"]], "ts": "1742577058400", "checksum": -847312230, "seqId": 49944988080, "prevSeqId": 49944988058}], "record_time": 1742577058.571845, "EXCHANGE": "OKX"}
{"arg": {"channel": "books", "instId": "BTC-USDT"}, "action": "update", "data": [{"asks": [["83983.9", "0", "0", "0"], ["83986.3", "0.005022", "0", "1"], ["84016", "0.00081198", "0", "3"], ["84016.8", "0.0004", "0", "1"], ["84017.6", "0", "0", "0"], ["84141.4", "0.08762", "0", "1"]], "bids": [["83982.8", "0.13337913", "0", "2"], ["83974.8", "0.44981778", "0", "4"], ["83974.4", "0.2025", "0", "1"], ["83961.5", "0.17264246", "0", "1"], ["83958.3", "0", "0", "0"], ["83957.6", "0.17898725", "0", "1"], ["83957.4", "0.004935", "0", "1"], ["83945.4", "0.96926443", "0", "4"], ["83944", "0.1", "0", "2"], ["83943.2", "0.61", "0", "2"], ["83942.4", "0", "0", "0"], ["83826", "0", "0", "0"]], "ts": "1742577058500", "checksum": 426592515, "seqId": 49944988118, "prevSeqId": 49944988080}], "record_time": 1742577058.672113, "EXCHANGE": "OKX"}
{"arg": {"channel": "books", "instId": "BTC-USDT"}, "action": "update", "data": [{"asks": [["83986.3", "0", "0", "0"], ["84006.1", "0.00001198", "0", "1"], ["84010.1", "0.23827526", "0", "1"], ["84011.2", "0.01190318", "0", "1"], ["84012.9", "0", "0", "0"]], "bids": [["83957.4", "0", "0", "0"], ["83952.1", "0.25602062", "0", "2"], ["83951", "0.01190407", "0", "1"], ["83949.7", "0", "0", "0"], ["83944", "0", "0", "0"], ["83943.8", "0.01190318", "0", "1"], ["83943.2", "0.66", "0", "3"], ["83942.4", "0.05", "0", "1"], ["83942.2", "0", "0", "0"], ["83939.6", "0", "0", "0"], ["83826", "0.2025", "0", "1"], ["83825.9", "0.00001586", "0", "1"]], "ts": "1742577058600", "checksum": -495489902, "seqId": 49944988149, "prevSeqId": 49944988118}], "record_time": 1742577058.776235, "EXCHANGE": "OKX"}
{"arg": {"channel": "books", "instId": "BTC-USDT"}, "action": "update", "data": [{"asks": [["83983.3", "0.09244416", "0", "2"], ["83985", "0.11912605", "0", "1"], ["83987", "0.005", "0", "1"], ["83987.2", "0.0001785", "0", "1"], ["84005.4", "0.23827826", "0", "1"], ["84010.1", "0", "0", "0"], ["84141.3", "0", "0", "0"], ["84141.4", "0", "0", "0"]], "bids": [["83974.8", "0.39426129", "0", "3"], ["83974.4", "0", "0", "0"], ["83967.5", "0", "0", "0"], ["83958.6", "0.0016395", "0", "1"], ["83948", "0.73116234", "0", "4"], ["83947.2", "0.03790247", "0", "3"], ["83944", "0.1", "0", "2"], ["83943.2", "0.61", "0", "2"], ["83942.4", "0", "0", "0"], ["83910.2", "0.2025", "0", "1"], ["83903.4", "0.3380663", "0", "1"], ["83901.9", "0", "0", "0"], ["83825.4", "0.00001365", "0", "1"]], "ts": "1742577058700", "checksum": 1166050531, "seqId": 49944988175, "prevSeqId": 49944988149}], "record_time": 1742577058.872178, "EXCHANGE": "OKX"}
{"arg": {"channel": "books", "instId": "BTC-USDT"}, "action": "update", "data": [{"asks": [["83996", "0.0489", "0", "2"], ["84005.4", "0", "0", "0"], ["84006.1", "0.00501198", "0", "2"], ["84010.1", "0.23827596", "0", "1"], ["84016", "0.00001198", "0", "1"], ["84016.8", "0.0008", "0", "2"], ["84017.6", "0.0004", "0", "1"], ["84141.2", "0", "0", "0"]], "bids": [["83981", "0.005", "0", "1"], ["83975.9", "0.16203305", "0", "1"], ["83975.2", "0", "0", "0"], ["83974.8", "0.69056778", "0", "4"], ["83973.8", "1", "0", "1"], ["83970.9", "0.005", "0", "1"], ["83902.7", "0", "0", "0"], ["83890.1", "0.05381444", "0", "2"], ["83825.4", "0", "0", "0"]], "ts": "1742577058800", "checksum": -1224171731, "seqId": 49944988194, "prevSeqId": 49944988175}], "record_time": 1742577058.972647, "EXCHANGE": "OKX"}
{"arg": {"channel": "books", "instId": "BTC-USDT"}, "action": "update", "data": [{"asks": [["84000.2", "0.25650932", "0", "2"], ["84006.1", "0.2432898", "0", "3"], ["84010.1", "0", "0", "0"], ["84013.8", "0.01190281", "0", "1"], ["84014.7", "0", "0", "0"], ["84141.2", "0.00011161", "0", "1"]], "bids": [["83975.9", "0.45625892", "0", "2"], ["83975.4", "1", "0", "1"], ["83974.8", "0.39426129", "0", "3"], ["83973.8", "0", "0", "0"], ["83958.6", "0", "0", "0"], ["83952.1", "0.25602318", "0", "2"], ["83948.1", "1.27207788", "0", "3"], ["83946.5", "0.01190281", "0", "1"], ["83945.6", "0", "0", "0"], ["83945.5", "0.56", "0", "1"], ["83943.2", "0.05", "0", "1"]], "ts": "1742577058900", "checksum": 6184935, "seqId": 49944988238, "prevSeqId": 49944988194}], "record_time": 1742577059.072829, "EXCHANGE": "OKX"}
{"arg": {"channel": "books", "instId": "BTC-USDT"}, "action": "update", "data": [{"asks": [["84005.8", "0.26827804", "0", "2"], ["84006.1", "0.00501198", "0", "2"], ["84016", "0.00081198", "0", "3"], ["84016.8", "0.0004", "0", "1"], ["84017.6", "0", "0", "0"], ["84141.3", "0.00083", "0", "1"]], "bids": [["83957.1", "0.004935", "0", "1"], ["83949.6", "0.0808", "0", "4"], ["83948.8", "0.0404", "0", "2"], ["83948", "0.73076234", "0", "3"], ["83947.1", "0.01190271", "0", "1"], ["83945.4", "0.95736196", "0", "3"], ["83885.6", "0", "0", "0"], ["83825.9", "0", "0", "0"]], "ts": "1742577059000", "checksum": 6184935, "seqId": 49944988258, "prevSeqId": 49944988238}], "record_time": 1742577059.173386, "EXCHANGE": "OKX"}
{"arg": {"channel": "books", "instId": "BTC-USDT"}, "action": "update", "data": [{"asks": [["83982.9", "1.14131432", "0", "18"], ["83983.3", "0.09094317", "0", "2"], ["83985", "0", "0", "0"], ["83987", "0", "0", "0"], ["83987.2", "0", "0", "0"], ["83987.4", "0.11912273", "0", "1"], ["83997", "0.35721", "0", "1"], ["84004.5", "0.67647935", "0", "1"], ["84005.8", "0.03", "0", "1"], ["84007.4", "0.00001501", "0", "1"], ["84008", "0.23827575", "0", "1"], ["84013", "0", "0", "0"], ["84020.5", "0.00357302", "0", "1"], ["84141.4", "0.08762", "0", "1"]], "bids": [["83982", "0.05016868", "0", "5"], ["83980", "0.04391", "0", "2"], ["83976.8", "0.47652115", "0", "1"], ["83976.7", "1.000015", "0", "2"], ["83975.9", "0", "0", "0"], ["83975.4", "0", "0", "0"], ["83974.8", "0.45131778", "0", "4"], ["83974.4", "0.2025", "0", "1"], ["83973.4", "0", "0", "0"], ["83957.1", "0", "0", "0"], ["83951", "0", "0", "0"], ["83950.1", "0.01190396", "0", "1"], ["83948.1", "0.85285339", "0", "2"], ["83948", "0.53076234", "0", "2"], ["83947", "0", "0", "0"], ["83825.9", "0.00001586", "0", "1"], ["83825.4", "0.00001365", "0", "1"], ["83825.1", "0.0166188", "0", "1"]], "ts": "1742577059100", "checksum": 172709382, "seqId": 49944988305, "prevSeqId": 49944988258}], "record_time": 1742577059.273546, "EXCHANGE": "OKX"}
