{"arg": {"channel": "books", "instId": "BTC-USDT"}, "action": "update", "data": [{"asks": [["84070.5", "0.00001197", "0", "1"], ["84086.6", "0", "0", "0"], ["84114.3", "0.18608224", "0", "1"], ["84233.3", "0.00101534", "0", "2"]], "bids": [["84053.4", "0.008", "0", "1"], ["84053.2", "0", "0", "0"], ["84053", "0.23501113", "0", "2"], ["84036.7", "0", "0", "0"], ["84036.6", "0", "0", "0"], ["84025.9", "0", "0", "0"], ["84007.4", "0.91613799", "0", "1"], ["84007.1", "0", "0", "0"], ["83977.9", "0.29198412", "0", "1"], ["83921.3", "0.0016853", "0", "2"], ["83921", "0.00001002", "0", "1"], ["83920", "0.00001096", "0", "1"]], "ts": "1742555197304", "checksum": 1574255227, "seqId": 49927510651, "prevSeqId": 49927510634}], "record_time": 1742555197.389791, "EXCHANGE": "OKX"}
{"arg": {"channel": "books", "instId": "BTC-USDT"}, "action": "update", "data": [{"asks": [["84068", "0.02907945", "0", "2"], ["84086.6", "1.55492682", "0", "1"], ["84093", "0", "0", "0"], ["84116", "2.87582744", "0", "1"], ["84138.8", "0.01774536", "0", "1"], ["84233", "0", "0", "0"], ["84233.3", "0", "0", "0"]], "bids": [["84053.4", "0", "0", "0"], ["84038", "0", "0", "0"], ["84032.7", "1.58369726", "0", "1"], ["84030.1", "0.01774536", "0", "1"], ["84003.3", "2.98401866", "0", "2"]], "ts": "1742555197404", "checksum": -1287610882, "seqId": 49927510663, "prevSeqId": 49927510651}], "record_time": 1742555197.404092, "EXCHANGE": "OKX"}
{"arg": {"channel": "books", "instId": "BTC-USDT"}, "action": "update", "data": [{"asks": [["84084", "0.60936319", "0", "2"], ["84102.4", "0.32982", "0", "3"], ["84103.2", "0.03999999", "0", "1"], ["84104", "0", "0", "0"], ["84143.7", "0.0713066", "0", "1"], ["84233", "0.06012728", "0", "2"]], "bids": [["84032.8", "0.9784656", "0", "1"], ["84026.4", "0.0903941", "0", "3"], ["84025.6", "0.066", "0", "3"], ["84024.8", "0.54210201", "0", "2"], ["84022.4", "0.1", "0", "2"], ["84021.6", "0.05", "0", "1"], ["84020.8", "0", "0", "0"], ["84000.1", "2.13479764", "0", "1"], ["83978.8", "0.07144658", "0", "1"], ["83920", "0", "0", "0"]], "ts": "1742555197504", "checksum": -1287610882, "seqId": 49927510686, "prevSeqId": 49927510663}], "record_time": 1742555197.586193, "EXCHANGE": "OKX"}
{"arg": {"channel": "books", "instId": "BTC-USDT"}, "action": "update", "data": [{"asks": [["84143.7", "0.1426132", "0", "2"]], "bids": [["83978.8", "0.14289316", "0", "2"]], "ts": "1742555197604", "checksum": -1287610882, "seqId": 49927510694, "prevSeqId": 49927510686}], "record_time": 1742555197.605806, "EXCHANGE": "OKX"}
{"arg": {"channel": "books", "instId": "BTC-USDT"}, "action": "update", "data": [{"asks": [["84093", "0.01774536", "0", "1"], ["84138.8", "0", "0", "0"]], "bids": [["84032.9", "0.01774536", "0", "1"], ["84030.1", "0", "0", "0"]], "ts": "1742555197704", "checksum": -1287610882, "seqId": 49927510702, "prevSeqId": 49927510694}], "record_time": 1742555197.725993, "EXCHANGE": "OKX"}
{"arg": {"channel": "books", "instId": "BTC-USDT"}, "action": "update", "data": [{"asks": [["84076.3", "0.82453246", "0", "3"], ["84079", "1", "0", "1"], ["84079.8", "0.21584076", "0", "1"], ["84080.4", "0.00001197", "0", "1"], ["84090.6", "0", "0", "0"], ["84090.7", "0.2380187", "0", "1"], ["84233", "0", "0", "0"]], "bids": [["84055.8", "0.000024", "0", "1"], ["84045.5", "0", "0", "0"], ["84044.1", "1", "0", "1"], ["84033.8", "0.24222864", "0", "2"], ["84031.6", "0", "0", "0"]], "ts": "1742555197804", "checksum": 1607819651, "seqId": 49927510719, "prevSeqId": 49927510702}], "record_time": 1742555197.804878, "EXCHANGE": "OKX"}
{"arg": {"channel": "books", "instId": "BTC-USDT"}, "action": "update", "data": [{"asks": [["84107", "0.2", "0", "1"], ["84232.9", "0", "0", "0"]], "bids": [["84033.9", "0.02774536", "0", "2"], ["84032.9", "0", "0", "0"], ["83920", "0.00001096", "0", "1"]], "ts": "1742555197904", "checksum": 1607819651, "seqId": 49927510724, "prevSeqId": 49927510719}], "record_time": 1742555197.911813, "EXCHANGE": "OKX"}
{"arg": {"channel": "books", "instId": "BTC-USDT"}, "action": "update", "data": [{"asks": [["84090.1", "0.23801892", "0", "1"], ["84090.7", "0", "0", "0"], ["84107", "0", "0", "0"], ["84232.9", "0.08747", "0", "1"]], "bids": [["84060", "0.95588443", "0", "13"], ["84051", "0.18111", "0", "2"], ["84034", "0.23801892", "0", "1"], ["84033.8", "0.00420994", "0", "1"], ["84017.1", "0", "0", "0"]], "ts": "1742555198004", "checksum": 1262346097, "seqId": 49927510732, "prevSeqId": 49927510724}], "record_time": 1742555198.004773, "EXCHANGE": "OKX"}
{"arg": {"channel": "books", "instId": "BTC-USDT"}, "action": "update", "data": [{"asks": [["84062", "0", "0", "0"], ["84074.8", "0.03502911", "0", "1"], ["84074.9", "0.03433127", "0", "1"], ["84075.1", "0", "0", "0"], ["84075.2", "0.03519464", "0", "1"], ["84076.3", "0.44112318", "0", "2"], ["84077.8", "0.17821722", "0", "1"], ["84079", "0", "0", "0"], ["84079.8", "0.57382062", "0", "2"], ["84080.4", "1.00001197", "0", "2"], ["84081.4", "0.249835", "0", "2"], ["84081.5", "0.03449684", "0", "1"], ["84081.7", "0.12345161", "0", "2"], ["84081.8", "0", "0", "0"], ["84081.9", "0.03354008", "0", "1"], ["84083.4", "0", "0", "0"], ["84083.5", "0.03447257", "0", "1"], ["84083.6", "0.03150794", "0", "1"], ["84088.8", "0", "0", "0"], ["84088.9", "0.06546124", "0", "1"], ["84090.1", "0", "0", "0"], ["84090.8", "0.23801702", "0", "1"], ["84090.9", "0.06476242", "0", "1"]], "bids": [["84060", "0.95445743", "0", "12"], ["84047.6", "0.03207084", "0", "1"], ["84047.5", "0", "0", "0"], ["84045.8", "0.23958958", "0", "4"], ["84045.7", "0", "0", "0"], ["84040.6", "0.03455886", "0", "1"], ["84040.5", "0", "0", "0"], ["84039.5", "0.03308191", "0", "1"], ["84039.4", "0", "0", "0"], ["84038", "0.03101138", "0", "1"], ["84037.9", "0.18725022", "0", "1"], ["84037.4", "0.03311674", "0", "1"], ["84037.3", "0.2025", "0", "1"], ["84034.1", "0.01776037", "0", "2"], ["84034", "0", "0", "0"], ["84033.9", "0.01", "0", "1"], ["84033.8", "0.24222774", "0", "2"], ["84033.6", "0.06847993", "0", "1"], ["84033.5", "0", "0", "0"], ["84030", "1.064115", "0", "3"], ["84029.9", "0", "0", "0"], ["84016.3", "0.001427", "0", "1"]], "ts": "1742555198104", "checksum": -1405489054, "seqId": 49927510793, "prevSeqId": 49927510732}], "record_time": 1742555198.106636, "EXCHANGE": "OKX"}
{"arg": {"channel": "books", "instId": "BTC-USDT"}, "action": "update", "data": [{"asks": [["84090.8", "0.23801748", "0", "1"]], "bids": [["84060", "0.94841743", "0", "11"], ["84033.8", "0.24222742", "0", "2"]], "ts": "1742555198204", "checksum": -1258549494, "seqId": 49927510807, "prevSeqId": 49927510793}], "record_time": 1742555198.206072, "EXCHANGE": "OKX"}
{"arg": {"channel": "books", "instId": "BTC-USDT"}, "action": "update", "data": [{"asks": [["84076.3", "0.82452526", "0", "3"], ["84078.9", "1", "0", "1"], ["84079.8", "0.21584076", "0", "1"], ["84080.4", "0.00001197", "0", "1"], ["84232.9", "0", "0", "0"]], "bids": [["84055", "0.005", "0", "2"], ["84048.8", "0.17844", "0", "1"], ["83920", "0", "0", "0"]], "ts": "1742555198304", "checksum": 412441180, "seqId": 49927510816, "prevSeqId": 49927510807}], "record_time": 1742555198.449728, "EXCHANGE": "OKX"}
{"arg": {"channel": "books", "instId": "BTC-USDT"}, "action": "update", "data": [{"asks": [], "bids": [["84034.1", "0.00001501", "0", "1"], ["84033.9", "0.02774536", "0", "2"]], "ts": "1742555198404", "checksum": 412441180, "seqId": 49927510820, "prevSeqId": 49927510816}], "record_time": 1742555198.451497, "EXCHANGE": "OKX"}
{"arg": {"channel": "books", "instId": "BTC-USDT"}, "action": "update", "data": [{"asks": [["84081.7", "0.11898911", "0", "1"]], "bids": [], "ts": "1742555198504", "checksum": 412441180, "seqId": 49927510821, "prevSeqId": 49927510820}], "record_time": 1742555198.663666, "EXCHANGE": "OKX"}
{"arg": {"channel": "books", "instId": "BTC-USDT"}, "action": "update", "data": [{"asks": [["84102.3", "0.30827036", "0", "1"], ["84143.7", "0.0713066", "0", "1"], ["84168.1", "0.37093207", "0", "1"], ["84172", "0.64996", "0", "1"], ["84194.6", "0.00001196", "0", "1"], ["84195.4", "0", "0", "0"], ["84232.6", "0", "0", "0"]], "bids": [["84036", "0.32660317", "0", "1"], ["84015", "0.2", "0", "1"], ["83978.8", "0.07144658", "0", "1"], ["83977.9", "0", "0", "0"], ["83921", "0", "0", "0"]], "ts": "1742555198604", "checksum": 412441180, "seqId": 49927510839, "prevSeqId": 49927510821}], "record_time": 1742555198.665018, "EXCHANGE": "OKX"}
{"arg": {"channel": "books", "instId": "BTC-USDT"}, "action": "update", "data": [{"asks": [["84068", "0.08726952", "0", "3"], ["84069.9", "0.2", "0", "1"], ["84079.7", "0.36087831", "0", "2"], ["84143.7", "0", "0", "0"]], "bids": [["84060", "0.95445743", "0", "12"], ["84036.1", "0.01774536", "0", "1"], ["84033.9", "0.01", "0", "1"], ["84015", "0", "0", "0"], ["83978.8", "0", "0", "0"], ["83921", "0.00001002", "0", "1"]], "ts": "1742555198704", "checksum": -1660805871, "seqId": 49927510853, "prevSeqId": 49927510839}], "record_time": 1742555198.706423, "EXCHANGE": "OKX"}
{"arg": {"channel": "books", "instId": "BTC-USDT"}, "action": "update", "data": [{"asks": [["84060.1", "0.03593707", "0", "4"], ["84068", "0.02907945", "0", "2"], ["84069.9", "0", "0", "0"], ["84074.7", "0.35689", "0", "1"], ["84074.8", "0", "0", "0"], ["84074.9", "0", "0", "0"], ["84075.2", "0", "0", "0"], ["84076.1", "0", "0", "0"], ["84079.7", "0.35641581", "0", "1"], ["84079.9", "0.0044625", "0", "1"], ["84080.8", "0.03166", "0", "1"], ["84081.5", "0", "0", "0"], ["84081.9", "0", "0", "0"], ["84083.5", "0", "0", "0"], ["84083.6", "0", "0", "0"], ["84088.9", "0", "0", "0"], ["84090.2", "0", "0", "0"], ["84090.9", "0", "0", "0"], ["84092.2", "0", "0", "0"], ["84143.7", "0.1426132", "0", "2"], ["84232.6", "0.00001501", "0", "1"], ["84232.9", "0.08747", "0", "1"], ["84233", "0.06012728", "0", "2"], ["84233.3", "0.00101534", "0", "2"], ["84233.5", "0.00002296", "0", "1"], ["84233.8", "0.00003542", "0", "1"], ["84233.9", "0.00419323", "0", "1"], ["84234", "0.00036", "0", "1"], ["84234.4", "0.00001197", "0", "1"], ["84235", "0.00025", "0", "1"]], "bids": [["84047.6", "0", "0", "0"], ["84046.7", "0", "0", "0"], ["84046.1", "0.00006", "0", "1"], ["84045.8", "0.20672021", "0", "3"], ["84040.6", "0", "0", "0"], ["84039.5", "0", "0", "0"], ["84038", "0", "0", "0"], ["84037.4", "0", "0", "0"], ["84033.6", "0", "0", "0"], ["84030.7", "0", "0", "0"], ["84030", "1.00001196", "0", "2"], ["84029.2", "0", "0", "0"], ["83978.8", "0.14289316", "0", "2"], ["83920", "0.00001096", "0", "1"], ["83919.2", "0.00003545", "0", "1"], ["83918.9", "0.00001197", "0", "1"], ["83917.6", "0.00005114", "0", "1"], ["83917.5", "0.11890903", "0", "1"], ["83917.4", "0.17821722", "0", "1"], ["83917.3", "0.08991011", "0", "1"], ["83917.2", "0.35579296", "0", "1"]], "ts": "1742555198804", "checksum": 1831732099, "seqId": 49927510907, "prevSeqId": 49927510853}], "record_time": 1742555198.804774, "EXCHANGE": "OKX"}
{"arg": {"channel": "books", "instId": "BTC-USDT"}, "action": "update", "data": [{"asks": [["84062", "0.0146", "0", "1"], ["84075.1", "0.03212163", "0", "1"], ["84075.2", "0.03317588", "0", "1"], ["84075.5", "0.03261886", "0", "2"], ["84075.7", "0.03370602", "0", "1"], ["84082", "0.04558761", "0", "2"], ["84082.5", "0.03106305", "0", "1"], ["84083.8", "0.03096667", "0", "1"], ["84083.9", "0.17102976", "0", "4"], ["84089.4", "0.23802243", "0", "1"], ["84089.5", "0.06457983", "0", "1"], ["84090.6", "0.06854674", "0", "1"], ["84090.8", "0", "0", "0"], ["84091.4", "0.07011936", "0", "1"], ["84092.6", "0.06440861", "0", "1"], ["84232.6", "0", "0", "0"], ["84232.9", "0", "0", "0"], ["84233", "0", "0", "0"], ["84233.3", "0", "0", "0"], ["84233.5", "0", "0", "0"], ["84233.8", "0", "0", "0"], ["84233.9", "0", "0", "0"], ["84234", "0", "0", "0"], ["84234.4", "0", "0", "0"], ["84235", "0", "0", "0"]], "bids": [["84048.2", "0.03849548", "0", "2"], ["84047.1", "0.03149086", "0", "1"], ["84046.5", "0.0308829", "0", "1"], ["84046.3", "0.03176672", "0", "1"], ["84041.2", "0.03146309", "0", "1"], ["84040", "0.03120299", "0", "2"], ["84038.3", "0.03298433", "0", "1"], ["84037.7", "0.03428708", "0", "1"], ["84036", "0", "0", "0"], ["84034.2", "0.06509332", "0", "1"], ["84033.8", "0.00420994", "0", "1"], ["84031.2", "0.23802243", "0", "1"], ["84031.1", "0.0664619", "0", "1"], ["84030.5", "0.06957578", "0", "1"], ["84029.6", "0.06664476", "0", "1"], ["83921.3", "0", "0", "0"], ["83921", "0", "0", "0"], ["83920", "0", "0", "0"], ["83919.2", "0", "0", "0"], ["83918.9", "0", "0", "0"], ["83917.6", "0", "0", "0"], ["83917.5", "0", "0", "0"], ["83917.4", "0", "0", "0"], ["83917.3", "0", "0", "0"], ["83917.2", "0", "0", "0"]], "ts": "1742555198904", "checksum": 914209659, "seqId": 49927511002, "prevSeqId": 49927510907}], "record_time": 1742555198.966748, "EXCHANGE": "OKX"}
{"arg": {"channel": "books", "instId": "BTC-USDT"}, "action": "update", "data": [{"asks": [["84079.9", "0", "0", "0"], ["84089.4", "0.2380224", "0", "1"], ["84107", "0.2", "0", "1"]], "bids": [["84036.1", "0", "0", "0"], ["84032.9", "0.25576779", "0", "2"], ["84031.2", "0", "0", "0"], ["83921.3", "0.0016853", "0", "2"]], "ts": "1742555199004", "checksum": 914209659, "seqId": 49927511013, "prevSeqId": 49927511002}], "record_time": 1742555199.005476, "EXCHANGE": "OKX"}
{"arg": {"channel": "books", "instId": "BTC-USDT"}, "action": "update", "data": [{"asks": [["84072.4", "0.005", "0", "1"], ["84082.4", "0.005", "0", "1"], ["84088.2", "0.23802281", "0", "1"], ["84089.4", "0", "0", "0"], ["84102.4", "0.24982", "0", "1"], ["84103.2", "0.07999999", "0", "2"], ["84104", "0.03999999", "0", "1"], ["84232.3", "0", "0", "0"]], "bids": [["84060", "1.01528745", "0", "13"], ["84058.2", "0.005", "0", "1"], ["84048.1", "0", "0", "0"], ["84032.9", "0.01774536", "0", "1"], ["84031.2", "0.23802281", "0", "1"]], "ts": "1742555199104", "checksum": 874210736, "seqId": 49927511029, "prevSeqId": 49927511013}], "record_time": 1742555199.152954, "EXCHANGE": "OKX"}
{"arg": {"channel": "books", "instId": "BTC-USDT"}, "action": "update", "data": [{"asks": [["84081", "0.0044625", "0", "1"], ["84088.2", "0.23802354", "0", "1"], ["84107", "0", "0", "0"]], "bids": [["84031.2", "0", "0", "0"], ["84030.6", "0.23802354", "0", "1"]], "ts": "1742555199204", "checksum": 874210736, "seqId": 49927511039, "prevSeqId": 49927511029}], "record_time": 1742555199.204415, "EXCHANGE": "OKX"}
{"arg": {"channel": "books", "instId": "BTC-USDT"}, "action": "update", "data": [{"asks": [["84081", "0", "0", "0"], ["84232.3", "0.29700048", "0", "2"]], "bids": [], "ts": "1742555199304", "checksum": 874210736, "seqId": 49927511041, "prevSeqId": 49927511039}], "record_time": 1742555199.30566, "EXCHANGE": "OKX"}
{"arg": {"channel": "books", "instId": "BTC-USDT"}, "action": "update", "data": [{"asks": [["84080.9", "0.00564", "0", "1"], ["84143.7", "0.0713066", "0", "1"], ["84232.3", "0", "0", "0"]], "bids": [["83978.8", "0.07144658", "0", "1"]], "ts": "1742555199404", "checksum": 874210736, "seqId": 49927511051, "prevSeqId": 49927511041}], "record_time": 1742555199.502114, "EXCHANGE": "OKX"}
{"arg": {"channel": "books", "instId": "BTC-USDT"}, "action": "update", "data": [{"asks": [["84088.2", "0", "0", "0"], ["84089.4", "0.23802224", "0", "1"], ["84143.7", "0", "0", "0"], ["84232.3", "0.29700048", "0", "2"]], "bids": [["84031.2", "0.23802224", "0", "1"], ["84030.6", "0", "0", "0"], ["83978.8", "0", "0", "0"], ["83921", "0.00001002", "0", "1"]], "ts": "1742555199504", "checksum": 874210736, "seqId": 49927511061, "prevSeqId": 49927511051}], "record_time": 1742555199.505446, "EXCHANGE": "OKX"}
{"arg": {"channel": "books", "instId": "BTC-USDT"}, "action": "update", "data": [{"asks": [["84077.5", "1.03", "0", "2"], ["84078.9", "0", "0", "0"], ["84080.9", "0", "0", "0"], ["84088.2", "0.23802469", "0", "1"], ["84089.4", "0", "0", "0"], ["84114.3", "1.03862383", "0", "2"], ["84143.7", "0.1426132", "0", "2"], ["84232.6", "0.00001501", "0", "1"]], "bids": [["84060", "0.81528745", "0", "12"], ["84046.2", "0.668339", "0", "3"], ["84044.1", "0", "0", "0"], ["84043.3", "1", "0", "1"], ["84037.4", "0.30960833", "0", "1"], ["84031.2", "0", "0", "0"], ["84030.6", "0.23802417", "0", "1"], ["84016.3", "0", "0", "0"], ["84015.9", "0.001428", "0", "1"], ["83978.8", "0.14289316", "0", "2"], ["83921.3", "0", "0", "0"], ["83921", "0", "0", "0"]], "ts": "1742555199604", "checksum": -972338523, "seqId": 49927511103, "prevSeqId": 49927511061}], "record_time": 1742555199.67829, "EXCHANGE": "OKX"}
{"arg": {"channel": "books", "instId": "BTC-USDT"}, "action": "update", "data": [{"asks": [["84060.1", "0.05537401", "0", "6"], ["84068", "0.11566847", "0", "2"], ["84068.6", "0.11890903", "0", "1"], ["84068.7", "0.2", "0", "1"], ["84075.1", "0", "0", "0"], ["84075.2", "0", "0", "0"], ["84075.5", "0.00001197", "0", "1"], ["84075.7", "0", "0", "0"], ["84082", "0.0146", "0", "1"], ["84082.5", "0", "0", "0"], ["84083.8", "0", "0", "0"], ["84083.9", "0.13615356", "0", "3"], ["84088.2", "0", "0", "0"], ["84089.5", "0", "0", "0"], ["84089.7", "0.23802269", "0", "1"], ["84090.6", "0", "0", "0"], ["84091.4", "0", "0", "0"], ["84092.6", "0", "0", "0"], ["84184.9", "0.183239", "0", "1"], ["84194.2", "0", "0", "0"], ["84232.9", "0.08747", "0", "1"], ["84233", "0.06012728", "0", "2"], ["84233.3", "0.00101534", "0", "2"], ["84233.5", "0.00002296", "0", "1"], ["84233.8", "0.00003542", "0", "1"], ["84233.9", "0.00419323", "0", "1"], ["84234", "0.00036", "0", "1"]], "bids": [["84060", "0.79140345", "0", "10"], ["84048.2", "0.005", "0", "1"], ["84047.1", "0", "0", "0"], ["84046.5", "0", "0", "0"], ["84046.3", "0", "0", "0"], ["84041.2", "0", "0", "0"], ["84040", "0.00001", "0", "1"], ["84038.3", "0", "0", "0"], ["84037.7", "0", "0", "0"], ["84034.2", "0", "0", "0"], ["84031.2", "0.23802269", "0", "1"], ["84031.1", "0", "0", "0"], ["84030.6", "0", "0", "0"], ["84030.5", "0", "0", "0"], ["84029.6", "0", "0", "0"], ["84018", "0.1", "0", "1"], ["83921.3", "0.0016853", "0", "2"], ["83921", "0.00001002", "0", "1"], ["83920", "0.00001096", "0", "1"], ["83919.2", "0.00003545", "0", "1"], ["83918.9", "0.00001197", "0", "1"], ["83917.6", "0.00005114", "0", "1"], ["83917.5", "0.11890903", "0", "1"], ["83917.4", "0.17821722", "0", "1"], ["83917.3", "0.08991011", "0", "1"]], "ts": "1742555199704", "checksum": 593774353, "seqId": 49927511160, "prevSeqId": 49927511103}], "record_time": 1742555199.716855, "EXCHANGE": "OKX"}
{"arg": {"channel": "books", "instId": "BTC-USDT"}, "action": "update", "data": [{"asks": [["84060.1", "0.09247401", "0", "7"]], "bids": [["84018", "0", "0", "0"], ["83917.2", "0.35579296", "0", "1"]], "ts": "1742555199804", "checksum": -390683914, "seqId": 49927511214, "prevSeqId": 49927511160}], "record_time": 1742555199.808772, "EXCHANGE": "OKX"}
{"arg": {"channel": "books", "instId": "BTC-USDT"}, "action": "update", "data": [{"asks": [["84065.5", "0.00773256", "0", "1"], ["84074.7", "0.39020639", "0", "2"], ["84074.8", "0.06809319", "0", "2"], ["84075.1", "0.03091027", "0", "1"], ["84077.8", "0.17824122", "0", "2"], ["84081.4", "0.28138503", "0", "3"], ["84081.8", "0.03195161", "0", "1"], ["84083.4", "0.03300434", "0", "1"], ["84083.5", "0.03132532", "0", "1"], ["84088.8", "0.06924517", "0", "1"], ["84090.2", "0.0677834", "0", "1"], ["84090.8", "0.06291714", "0", "1"], ["84092.2", "0.0613182", "0", "1"], ["84101", "1", "0", "1"], ["84102.4", "0.32982", "0", "3"], ["84103.2", "0.03999999", "0", "1"], ["84104", "0", "0", "0"], ["84232.3", "0", "0", "0"], ["84232.6", "0", "0", "0"], ["84232.9", "0", "0", "0"], ["84233", "0", "0", "0"], ["84233.3", "0", "0", "0"], ["84233.5", "0", "0", "0"], ["84233.8", "0", "0", "0"], ["84233.9", "0", "0", "0"], ["84234", "0", "0", "0"]], "bids": [["84047.5", "0.03229737", "0", "1"], ["84046.7", "0.03276999", "0", "1"], ["84046.1", "0.03142712", "0", "2"], ["84045.7", "0.0322946", "0", "1"], ["84040.5", "0.03257548", "0", "1"], ["84039.4", "0.03387649", "0", "1"], ["84037.9", "0.21922907", "0", "2"], ["84037.3", "0.23478965", "0", "2"], ["84033.5", "0.06555827", "0", "1"], ["84030.7", "0.06970605", "0", "1"], ["84029.9", "0.06837868", "0", "1"], ["84029.2", "0.06746452", "0", "1"], ["83921", "0", "0", "0"], ["83920", "0", "0", "0"], ["83919.2", "0", "0", "0"], ["83918.9", "0", "0", "0"], ["83917.6", "0", "0", "0"], ["83917.5", "0", "0", "0"], ["83917.4", "0", "0", "0"], ["83917.3", "0", "0", "0"], ["83917.2", "0", "0", "0"]], "ts": "1742555199904", "checksum": 1941693313, "seqId": 49927511251, "prevSeqId": 49927511214}], "record_time": 1742555199.904462, "EXCHANGE": "OKX"}
{"arg": {"channel": "books", "instId": "BTC-USDT"}, "action": "update", "data": [{"asks": [["84063.4", "0.06671397", "0", "3"], ["84088.2", "0.2380246", "0", "1"], ["84089.7", "0", "0", "0"], ["84102.4", "0.24982", "0", "1"], ["84103.2", "0.07999999", "0", "2"], ["84104", "0.03999999", "0", "1"], ["84232", "0", "0", "0"]], "bids": [["84060", "0.80924645", "0", "11"], ["84031.2", "0", "0", "0"], ["84029.3", "0.24155714", "0", "2"], ["84026.4", "0.0103941", "0", "1"], ["84025.6", "0.106", "0", "4"], ["84024.8", "0.58210201", "0", "3"], ["83921", "0.00001002", "0", "1"]], "ts": "1742555200004", "checksum": -1063726605, "seqId": 49927511270, "prevSeqId": 49927511251}], "record_time": 1742555200.015386, "EXCHANGE": "OKX"}
{"arg": {"channel": "books", "instId": "BTC-USDT"}, "action": "update", "data": [{"asks": [["84060.1", "0.90903141", "0", "13"], ["84066.3", "0.01055", "0", "1"], ["84068", "0.1728686", "0", "3"], ["84068.6", "0.32140903", "0", "2"], ["84072.4", "0.01", "0", "2"], ["84072.6", "0.03167", "0", "1"], ["84073.2", "0", "0", "0"], ["84073.3", "0.04223398", "0", "2"], ["84073.7", "0.06633915", "0", "2"], ["84073.9", "0.0325873", "0", "1"], ["84074.7", "0.35689", "0", "1"], ["84074.8", "0", "0", "0"], ["84075.1", "0", "0", "0"], ["84075.7", "0.72957143", "0", "1"], ["84075.8", "1", "0", "1"], ["84076.3", "0.18725022", "0", "1"], ["84077.5", "0.03", "0", "1"], ["84080.2", "0.03501712", "0", "1"], ["84080.3", "0.03271333", "0", "1"], ["84080.8", "0", "0", "0"], ["84081.4", "0.249835", "0", "2"], ["84081.8", "0", "0", "0"], ["84082.4", "0.04256522", "0", "3"], ["84082.5", "0.03222634", "0", "1"], ["84083.4", "0", "0", "0"], ["84083.5", "0", "0", "0"], ["84087.3", "0.06465873", "0", "1"], ["84088.2", "0.23802716", "0", "1"], ["84088.8", "0", "0", "0"], ["84089.1", "0.06499479", "0", "1"], ["84089.7", "0.06273985", "0", "1"], ["84090.2", "0", "0", "0"], ["84090.8", "0", "0", "0"], ["84091.2", "0.06335035", "0", "1"], ["84092.2", "0", "0", "0"], ["84230.7", "0", "0", "0"], ["84230.9", "0", "0", "0"]], "bids": [["84060", "0.69140345", "0", "9"], ["84059.9", "0.05287746", "0", "1"], ["84058.2", "0.01", "0", "2"], ["84053.3", "0", "0", "0"], ["84053", "0.24841113", "0", "3"], ["84048.1", "0.005", "0", "1"], ["84047.5", "0", "0", "0"], ["84046.7", "0.04021", "0", "1"], ["84046.1", "0.00006", "0", "1"], ["84046", "0.03114633", "0", "1"], ["84045.7", "0.0323691", "0", "1"], ["84045", "0.05536064", "0", "2"], ["84044.5", "0.03531657", "0", "1"], ["84040.5", "0", "0", "0"], ["84039.4", "0", "0", "0"], ["84039", "0.03259958", "0", "1"], ["84038.2", "0.0324487", "0", "1"], ["84037.9", "0.18725022", "0", "1"], ["84037.3", "0.2025", "0", "1"], ["84036.9", "0.03063342", "0", "1"], ["84036.3", "0.03421174", "0", "1"], ["84033.5", "0", "0", "0"], ["84032", "0.06589797", "0", "1"], ["84030.7", "0", "0", "0"], ["84029.9", "0", "0", "0"], ["84029.6", "0.064631", "0", "1"], ["84029.3", "0.00353141", "0", "1"], ["84029.2", "0", "0", "0"], ["84028.8", "0.26892356", "0", "2"], ["84028.2", "0.06179575", "0", "1"], ["84027.4", "0.23802716", "0", "1"], ["84011.7", "0", "0", "0"], ["84010.8", "0.018328", "0", "1"], ["83940.3", "0", "0", "0"], ["83939.1", "0.18328006", "0", "1"], ["83921.7", "0", "0", "0"], ["83921.3", "0", "0", "0"], ["83921", "0", "0", "0"]], "ts": "1742555200104", "checksum": -1421797351, "seqId": 49927511378, "prevSeqId": 49927511270}], "record_time": 1742555200.108504, "EXCHANGE": "OKX"}
{"arg": {"channel": "books", "instId": "BTC-USDT"}, "action": "update", "data": [{"asks": [["84061.6", "0.04008523", "0", "1"], ["84061.7", "0.11901742", "0", "1"], ["84063.4", "0.03040768", "0", "3"], ["84063.5", "0", "0", "0"], ["84072.1", "0.53392605", "0", "2"], ["84072.4", "0.005", "0", "1"], ["84074.5", "1", "0", "1"], ["84075.7", "0.37339636", "0", "1"], ["84075.8", "0", "0", "0"], ["84082.4", "0.03756522", "0", "2"], ["84084", "0.14291634", "0", "1"], ["84086.6", "0.23802668", "0", "1"], ["84088.2", "0", "0", "0"], ["84097", "1", "0", "1"], ["84114.3", "0.18608224", "0", "1"], ["84116", "0", "0", "0"]], "bids": [["84060", "0.49494345", "0", "9"], ["84059.9", "0", "0", "0"], ["84058.2", "0.005", "0", "1"], ["84055.8", "0", "0", "0"], ["84048.2", "0", "0", "0"], ["84032.8", "0", "0", "0"], ["84032.7", "0", "0", "0"], ["84030.1", "0.23802678", "0", "1"], ["84027.4", "0", "0", "0"], ["84003.3", "0.2025", "0", "1"], ["84000.1", "2.82398869", "0", "2"], ["83921.7", "0.0535785", "0", "1"], ["83921.3", "0.0016853", "0", "2"], ["83921", "0.00001002", "0", "1"], ["83920", "0.00001096", "0", "1"], ["83919.2", "0.00003545", "0", "1"]], "ts": "1742555200204", "checksum": 1557071736, "seqId": 49927511414, "prevSeqId": 49927511378}], "record_time": 1742555200.20772, "EXCHANGE": "OKX"}
{"arg": {"channel": "books", "instId": "BTC-USDT"}, "action": "update", "data": [{"asks": [["84086.6", "1.53602464", "0", "1"], ["84086.9", "0.23802785", "0", "1"], ["84116", "2.78183541", "0", "1"], ["84228.9", "0", "0", "0"], ["84230.1", "0", "0", "0"]], "bids": [["84060", "0.69744345", "0", "10"], ["84049.8", "0.00027", "0", "1"], ["84034.4", "1.59004019", "0", "1"], ["84032.9", "0", "0", "0"], ["84030.2", "0.01774536", "0", "1"], ["84030.1", "0", "0", "0"], ["84028.9", "0.23802785", "0", "1"], ["84005", "2.81553668", "0", "1"], ["83977.9", "0.05287746", "0", "1"], ["83921.3", "0", "0", "0"], ["83921", "0", "0", "0"], ["83920", "0", "0", "0"], ["83919.2", "0", "0", "0"]], "ts": "1742555200304", "checksum": 185721018, "seqId": 49927511428, "prevSeqId": 49927511414}], "record_time": 1742555200.309674, "EXCHANGE": "OKX"}
{"arg": {"channel": "books", "instId": "BTC-USDT"}, "action": "update", "data": [{"asks": [["84086.9", "0", "0", "0"], ["84088.2", "0.23802683", "0", "1"]], "bids": [["84030.1", "0.23802683", "0", "1"], ["84028.9", "0", "0", "0"]], "ts": "1742555200404", "checksum": 185721018, "seqId": 49927511434, "prevSeqId": 49927511428}], "record_time": 1742555200.405849, "EXCHANGE": "OKX"}
{"arg": {"channel": "books", "instId": "BTC-USDT"}, "action": "update", "data": [{"asks": [["84072.4", "0.01", "0", "2"], ["84082.4", "0.04256522", "0", "3"], ["84088.2", "0", "0", "0"], ["84089", "0.23802375", "0", "1"]], "bids": [["84058.2", "0.01", "0", "2"], ["84048.2", "0.005", "0", "1"], ["84044.7", "1.03618589", "0", "2"], ["84043.3", "0", "0", "0"], ["84022.4", "0", "0", "0"], ["84021.6", "0.1", "0", "2"], ["84020.8", "0.05", "0", "1"]], "ts": "1742555200504", "checksum": 261771725, "seqId": 49927511448, "prevSeqId": 49927511434}], "record_time": 1742555200.542783, "EXCHANGE": "OKX"}
{"arg": {"channel": "books", "instId": "BTC-USDT"}, "action": "update", "data": [{"asks": [], "bids": [["84053", "0.24484113", "0", "2"], ["84038", "0.01774536", "0", "1"], ["84030.2", "0", "0", "0"], ["84023.5", "0.00357", "0", "1"], ["83921.7", "0", "0", "0"]], "ts": "1742555200604", "checksum": -1905006956, "seqId": 49927511455, "prevSeqId": 49927511448}], "record_time": 1742555200.612022, "EXCHANGE": "OKX"}
{"arg": {"channel": "books", "instId": "BTC-USDT"}, "action": "update", "data": [{"asks": [["84068", "0.06475216", "0", "2"], ["84068.7", "0", "0", "0"], ["84084", "0.62309016", "0", "2"], ["84097", "0", "0", "0"], ["84101", "0", "0", "0"], ["84114.3", "1.01042622", "0", "2"], ["84228.9", "0.00008", "0", "1"], ["84230.1", "0.000548", "0", "2"], ["84230.7", "0.2025", "0", "1"]], "bids": [["84030.2", "0.4442661", "0", "1"], ["83922", "0", "0", "0"]], "ts": "1742555200704", "checksum": -1862218115, "seqId": 49927511468, "prevSeqId": 49927511455}], "record_time": 1742555200.734619, "EXCHANGE": "OKX"}
{"arg": {"channel": "books", "instId": "BTC-USDT"}, "action": "update", "data": [{"asks": [["84060.1", "0.90887673", "0", "12"], ["84068", "0.11923314", "0", "3"]], "bids": [["84049.8", "0", "0", "0"], ["84022.4", "0.1", "0", "2"], ["84021.6", "0.05", "0", "1"], ["84020.8", "0", "0", "0"], ["84013", "0.1", "0", "1"]], "ts": "1742555200804", "checksum": 1367192598, "seqId": 49927511481, "prevSeqId": 49927511468}], "record_time": 1742555200.805873, "EXCHANGE": "OKX"}
{"arg": {"channel": "books", "instId": "BTC-USDT"}, "action": "update", "data": [{"asks": [["84068", "0.06475216", "0", "2"], ["84068.6", "0.11890903", "0", "1"]], "bids": [["84060", "0.71528645", "0", "11"], ["84050.6", "0.000534", "0", "1"], ["84022.4", "0", "0", "0"], ["84021.6", "0.1", "0", "2"], ["84020.8", "0.05", "0", "1"], ["84013", "0", "0", "0"]], "ts": "1742555200904", "checksum": 1903615957, "seqId": 49927511497, "prevSeqId": 49927511481}], "record_time": 1742555200.913911, "EXCHANGE": "OKX"}
{"arg": {"channel": "books", "instId": "BTC-USDT"}, "action": "update", "data": [{"asks": [["84143.7", "0.0713066", "0", "1"]], "bids": [["83978.8", "0.07144658", "0", "1"]], "ts": "1742555201004", "checksum": 1903615957, "seqId": 49927511513, "prevSeqId": 49927511497}], "record_time": 1742555201.06331, "EXCHANGE": "OKX"}
{"arg": {"channel": "books", "instId": "BTC-USDT"}, "action": "update", "data": [{"asks": [["84063.4", "0.01582715", "0", "2"], ["84063.9", "0.02217333", "0", "1"], ["84067.2", "0.02530935", "0", "1"], ["84068", "0.11923314", "0", "3"], ["84068.6", "0.32140903", "0", "2"], ["84070.3", "0", "0", "0"], ["84074.7", "0.36879031", "0", "2"], ["84086.8", "0", "0", "0"], ["84202.8", "0.00597054", "0", "2"], ["84211.5", "0", "0", "0"], ["84219.6", "0.01784439", "0", "3"], ["84228.3", "0", "0", "0"], ["84230.9", "0.35582144", "0", "2"]], "bids": [["84060", "0.39495052", "0", "8"], ["84059.2", "0", "0", "0"], ["84051.3", "0.17844", "0", "1"], ["84023.5", "0", "0", "0"], ["84022.4", "0.1", "0", "2"], ["84021.6", "0.05", "0", "1"], ["84020.8", "0", "0", "0"], ["83958.4", "0", "0", "0"], ["83931", "0.21412", "0", "1"], ["83922", "0.00001197", "0", "1"], ["83921.7", "0.0535785", "0", "1"]], "ts": "1742555201104", "checksum": -1854009358, "seqId": 49927511558, "prevSeqId": 49927511513}], "record_time": 1742555201.104785, "EXCHANGE": "OKX"}
{"arg": {"channel": "books", "instId": "BTC-USDT"}, "action": "update", "data": [{"asks": [["84063.3", "0.01055", "0", "1"], ["84066.3", "0", "0", "0"], ["84100", "0.1066249", "0", "3"], ["84143.7", "0.1426132", "0", "2"]], "bids": [["84060", "0.43145802", "0", "8"], ["84057.8", "0.02530935", "0", "1"], ["84053", "0.23144113", "0", "1"], ["84050", "0.01373629", "0", "4"], ["84004.2", "0.12491", "0", "1"], ["83978.8", "0.14289316", "0", "2"], ["83922", "0", "0", "0"], ["83921.7", "0", "0", "0"]], "ts": "1742555201204", "checksum": 1472480535, "seqId": 49927511576, "prevSeqId": 49927511558}], "record_time": 1742555201.252113, "EXCHANGE": "OKX"}
{"arg": {"channel": "books", "instId": "BTC-USDT"}, "action": "update", "data": [{"asks": [["84063.4", "0.01516446", "0", "1"]], "bids": [], "ts": "1742555201304", "checksum": -1879066387, "seqId": 49927511580, "prevSeqId": 49927511576}], "record_time": 1742555201.305269, "EXCHANGE": "OKX"}
{"arg": {"channel": "books", "instId": "BTC-USDT"}, "action": "update", "data": [{"asks": [["84063.3", "0.01121642", "0", "2"]], "bids": [], "ts": "1742555201404", "checksum": 1774698493, "seqId": 49927511582, "prevSeqId": 49927511580}], "record_time": 1742555201.404662, "EXCHANGE": "OKX"}
{"arg": {"channel": "books", "instId": "BTC-USDT"}, "action": "update", "data": [{"asks": [["84102.4", "0.32982", "0", "3"], ["84103.2", "0.03999999", "0", "1"], ["84104", "0", "0", "0"], ["84232", "0.00172464", "0", "3"]], "bids": [["84060", "0.42945802", "0", "8"], ["84050.6", "0", "0", "0"], ["84030.3", "0.23802337", "0", "1"], ["84030.1", "0", "0", "0"], ["84026.4", "0.0903941", "0", "3"], ["84025.6", "0.066", "0", "3"], ["84024.8", "0.54210201", "0", "2"], ["83922", "0.00001197", "0", "1"]], "ts": "1742555201504", "checksum": 1286655802, "seqId": 49927511602, "prevSeqId": 49927511582}], "record_time": 1742555201.5865, "EXCHANGE": "OKX"}
{"arg": {"channel": "books", "instId": "BTC-USDT"}, "action": "update", "data": [{"asks": [["84074.5", "0", "0", "0"], ["84075.9", "1", "0", "1"], ["84089", "0", "0", "0"], ["84089.6", "0.23802189", "0", "1"], ["84173", "0", "0", "0"], ["84181.4", "0", "0", "0"], ["84189.8", "0", "0", "0"], ["84198.2", "0", "0", "0"], ["84206.6", "0", "0", "0"], ["84232.3", "0.29700048", "0", "2"], ["84232.6", "0.00001501", "0", "1"], ["84232.9", "0.08747", "0", "1"], ["84233", "0.06012728", "0", "2"], ["84233.3", "0.00101534", "0", "2"]], "bids": [["84060", "0.434404", "0", "11"], ["84032.1", "0.23802189", "0", "1"], ["84030.3", "0", "0", "0"], ["83968.2", "0", "0", "0"], ["83955.8", "0", "0", "0"], ["83947.1", "0", "0", "0"], ["83938.7", "0", "0", "0"], ["83930.1", "0", "0", "0"], ["83921.7", "0.0535785", "0", "1"], ["83921.3", "0.0016853", "0", "2"], ["83921", "0.00001002", "0", "1"], ["83920", "0.00001096", "0", "1"], ["83919.2", "0.00003545", "0", "1"]], "ts": "1742555201604", "checksum": -296345424, "seqId": 49927511624, "prevSeqId": 49927511602}], "record_time": 1742555201.60517, "EXCHANGE": "OKX"}
{"arg": {"channel": "books", "instId": "BTC-USDT"}, "action": "update", "data": [{"asks": [["84072.1", "0.25920638", "0", "1"], ["84075.7", "0.68289688", "0", "2"], ["84097.1", "0.8357641", "0", "1"], ["84100", "1.1066249", "0", "4"]], "bids": [["84060", "0.652248", "0", "13"], ["84058.3", "0.2", "0", "1"], ["84051.5", "0.000561", "0", "1"], ["84046", "1.03114633", "0", "2"], ["84044.7", "0.03618589", "0", "1"], ["84037.4", "0.7478449", "0", "2"], ["84032.1", "0", "0", "0"], ["84030.3", "0.23802212", "0", "1"], ["84007.4", "1.92795873", "0", "2"], ["84000.1", "0", "0", "0"], ["83982.1", "0.45868919", "0", "2"], ["83977.9", "0", "0", "0"]], "ts": "1742555201704", "checksum": -1333262276, "seqId": 49927511645, "prevSeqId": 49927511624}], "record_time": 1742555201.77577, "EXCHANGE": "OKX"}
{"arg": {"channel": "books", "instId": "BTC-USDT"}, "action": "update", "data": [{"asks": [["84060.1", "0.90577673", "0", "11"], ["84068", "0.06475216", "0", "2"], ["84068.6", "0.11890903", "0", "1"], ["84075.9", "0", "0", "0"], ["84077.4", "1", "0", "1"], ["84097.1", "0", "0", "0"], ["84100", "0.0066249", "0", "2"], ["84233.5", "0.00002296", "0", "1"]], "bids": [["84059.9", "0.11362746", "0", "1"], ["84051.5", "0", "0", "0"]], "ts": "1742555201804", "checksum": -293545160, "seqId": 49927511655, "prevSeqId": 49927511645}], "record_time": 1742555201.804492, "EXCHANGE": "OKX"}
{"arg": {"channel": "books", "instId": "BTC-USDT"}, "action": "update", "data": [{"asks": [], "bids": [["84051.5", "0.000021", "0", "1"], ["84015", "0.2", "0", "1"], ["83920", "0", "0", "0"], ["83919.2", "0", "0", "0"]], "ts": "1742555201904", "checksum": 1454751642, "seqId": 49927511660, "prevSeqId": 49927511655}], "record_time": 1742555201.907129, "EXCHANGE": "OKX"}
{"arg": {"channel": "books", "instId": "BTC-USDT"}, "action": "update", "data": [{"asks": [["84068", "0.11164034", "0", "3"], ["84068.6", "0.32140903", "0", "2"]], "bids": [["84060", "0.44990586", "0", "8"], ["84055.5", "0.00757559", "0", "8"], ["84050.8", "0.00349671", "0", "2"]], "ts": "1742555202004", "checksum": -1530275238, "seqId": 49927511680, "prevSeqId": 49927511660}], "record_time": 1742555202.006466, "EXCHANGE": "OKX"}
{"arg": {"channel": "books", "instId": "BTC-USDT"}, "action": "update", "data": [{"asks": [["84060.1", "0.90593061", "0", "12"], ["84068", "0.06475216", "0", "2"], ["84068.6", "0.11890903", "0", "1"], ["84089.5", "0.23802282", "0", "1"], ["84089.6", "0", "0", "0"], ["84115.7", "0", "0", "0"], ["84116.6", "0.01249471", "0", "2"], ["84199.9", "0.18857973", "0", "8"], ["84200.8", "0.01188826", "0", "1"]], "bids": [["84060", "0.44997586", "0", "9"], ["84050.8", "0.00001197", "0", "1"], ["84011.3", "0", "0", "0"], ["84010.4", "0.02377647", "0", "2"], ["83920", "0.00001096", "0", "1"]], "ts": "1742555202104", "checksum": 718454248, "seqId": 49927511699, "prevSeqId": 49927511680}], "record_time": 1742555202.111741, "EXCHANGE": "OKX"}
{"arg": {"channel": "books", "instId": "BTC-USDT"}, "action": "update", "data": [{"asks": [["84068", "0.11164034", "0", "3"], ["84068.6", "0.32140903", "0", "2"]], "bids": [], "ts": "1742555202204", "checksum": -41080534, "seqId": 49927511702, "prevSeqId": 49927511699}], "record_time": 1742555202.204476, "EXCHANGE": "OKX"}
{"arg": {"channel": "books", "instId": "BTC-USDT"}, "action": "update", "data": [{"asks": [["84140", "0.00041388", "0", "4"]], "bids": [["84059.9", "0.05468525", "0", "1"], ["84058.3", "0", "0", "0"], ["84058", "0.0025", "0", "1"], ["83970.6", "0", "0", "0"], ["83919.2", "0.00003545", "0", "1"]], "ts": "1742555202304", "checksum": -1332735465, "seqId": 49927511709, "prevSeqId": 49927511702}], "record_time": 1742555202.304269, "EXCHANGE": "OKX"}
{"arg": {"channel": "books", "instId": "BTC-USDT"}, "action": "update", "data": [{"asks": [["84068", "0.06475216", "0", "2"]], "bids": [["83970.6", "0.00016244", "0", "1"], ["83919.2", "0", "0", "0"]], "ts": "1742555202404", "checksum": -417100352, "seqId": 49927511715, "prevSeqId": 49927511709}], "record_time": 1742555202.406427, "EXCHANGE": "OKX"}
{"arg": {"channel": "books", "instId": "BTC-USDT"}, "action": "update", "data": [{"asks": [["84068", "0.11164034", "0", "3"], ["84089.5", "0", "0", "0"], ["84089.6", "0.23802233", "0", "1"], ["84169.6", "0.00298666", "0", "1"], ["84178", "0.00597332", "0", "1"], ["84186.4", "0.00895999", "0", "1"], ["84194.8", "0.01194665", "0", "1"], ["84203.2", "0.01493332", "0", "1"], ["84232.6", "0", "0", "0"], ["84232.9", "0", "0", "0"], ["84233", "0", "0", "0"], ["84233.3", "0", "0", "0"], ["84233.5", "0", "0", "0"]], "bids": [["84031.6", "0.23802233", "0", "1"], ["84030.3", "0", "0", "0"], ["84015", "0", "0", "0"], ["83959.1", "0.00299675", "0", "2"], ["83950.7", "0.00597332", "0", "1"], ["83942.3", "0.00895999", "0", "1"], ["83933.9", "0.01194665", "0", "1"], ["83925.5", "0.01493332", "0", "1"], ["83921.3", "0", "0", "0"], ["83921", "0", "0", "0"], ["83920", "0", "0", "0"]], "ts": "1742555202504", "checksum": -1332735465, "seqId": 49927511731, "prevSeqId": 49927511715}], "record_time": 1742555202.508166, "EXCHANGE": "OKX"}
{"arg": {"channel": "books", "instId": "BTC-USDT"}, "action": "update", "data": [{"asks": [["84068", "0.06475216", "0", "2"], ["84068.6", "0.11890903", "0", "1"], ["84089.6", "0", "0", "0"], ["84091.1", "0.23802077", "0", "1"]], "bids": [["84060", "0.44998586", "0", "10"], ["84032.1", "0.23802077", "0", "1"], ["84031.6", "0", "0", "0"]], "ts": "1742555202604", "checksum": -1795300718, "seqId": 49927511740, "prevSeqId": 49927511731}], "record_time": 1742555202.635353, "EXCHANGE": "OKX"}
{"arg": {"channel": "books", "instId": "BTC-USDT"}, "action": "update", "data": [{"asks": [["84089.7", "0.30076048", "0", "2"], ["84091.1", "0", "0", "0"], ["84097.5", "0.54121923", "0", "1"]], "bids": [["84000.1", "0.92785749", "0", "1"], ["83921.7", "0", "0", "0"]], "ts": "1742555202704", "checksum": -1795300718, "seqId": 49927511744, "prevSeqId": 49927511740}], "record_time": 1742555202.705013, "EXCHANGE": "OKX"}
{"arg": {"channel": "books", "instId": "BTC-USDT"}, "action": "update", "data": [{"asks": [["84068", "0.11164034", "0", "3"], ["84068.6", "0.32140903", "0", "2"], ["84077.4", "0", "0", "0"], ["84078.7", "1", "0", "1"], ["84089.7", "0.06273985", "0", "1"], ["84091.1", "0.23801793", "0", "1"], ["84101", "1", "0", "1"], ["84130.2", "0.01130537", "0", "1"], ["84232", "0", "0", "0"], ["84232.3", "0", "0", "0"]], "bids": [["84049.5", "0.62220659", "0", "2"], ["84047.2", "1.133608", "0", "2"], ["84046.2", "0.44920868", "0", "2"], ["84046", "0.03114633", "0", "1"], ["84010.8", "0", "0", "0"], ["84010.1", "0.01832752", "0", "1"], ["83939.1", "0", "0", "0"], ["83938.3", "0.18327521", "0", "1"]], "ts": "1742555202804", "checksum": 1134720592, "seqId": 49927511791, "prevSeqId": 49927511744}], "record_time": 1742555202.825535, "EXCHANGE": "OKX"}
{"arg": {"channel": "books", "instId": "BTC-USDT"}, "action": "update", "data": [{"asks": [["84068", "0.06475216", "0", "2"], ["84068.6", "0.11890903", "0", "1"], ["84089", "0.23802262", "0", "1"], ["84091.1", "0", "0", "0"]], "bids": [["84049.5", "0.34499684", "0", "1"], ["84047.2", "0.133608", "0", "1"], ["84046.2", "0.70745576", "0", "3"], ["84045.9", "1", "0", "1"], ["84032.1", "0", "0", "0"], ["84030.3", "0.23802262", "0", "1"], ["83922", "0", "0", "0"]], "ts": "1742555202904", "checksum": -1795300718, "seqId": 49927511808, "prevSeqId": 49927511791}], "record_time": 1742555202.90862, "EXCHANGE": "OKX"}
{"arg": {"channel": "books", "instId": "BTC-USDT"}, "action": "update", "data": [{"asks": [["84068", "0.11164034", "0", "3"], ["84068.2", "0.03167", "0", "1"], ["84068.6", "0.32140903", "0", "2"], ["84072.6", "0", "0", "0"], ["84076", "1.0146", "0", "2"], ["84078.7", "0", "0", "0"], ["84087.1", "0.23802682", "0", "1"], ["84089", "0", "0", "0"], ["84101", "0", "0", "0"], ["84130.2", "0.01130563", "0", "1"], ["84232", "0.00172464", "0", "3"], ["84232.3", "0.29700048", "0", "2"]], "bids": [["84060", "0.24748586", "0", "9"], ["84059.9", "0", "0", "0"], ["84046.7", "0", "0", "0"], ["84045.9", "0", "0", "0"], ["84044", "1", "0", "1"], ["84042.3", "0.04021", "0", "1"], ["84040.6", "0.17844", "0", "1"], ["84030.3", "0", "0", "0"], ["84028.3", "0.23802682", "0", "1"], ["84010.1", "0.01832784", "0", "1"], ["84005", "0", "0", "0"], ["83938.3", "0.18327848", "0", "1"], ["83922", "0.00001197", "0", "1"]], "ts": "1742555203004", "checksum": 573594881, "seqId": 49927511853, "prevSeqId": 49927511808}], "record_time": 1742555203.008701, "EXCHANGE": "OKX"}
{"arg": {"channel": "books", "instId": "BTC-USDT"}, "action": "update", "data": [{"asks": [["84066.1", "0.01190204", "0", "1"], ["84072.1", "0.52949514", "0", "2"], ["84074.6", "1", "0", "1"], ["84075.7", "0.37339636", "0", "1"], ["84076", "0.0146", "0", "1"], ["84084", "0.14291634", "0", "1"], ["84086.3", "1.6165195", "0", "1"], ["84086.6", "0", "0", "0"], ["84114.3", "0.18608224", "0", "1"], ["84115.8", "2.91842498", "0", "1"], ["84116", "0", "0", "0"], ["84232", "0", "0", "0"], ["84232.3", "0", "0", "0"]], "bids": [["84060", "0.42766186", "0", "6"], ["84037.4", "0.30960833", "0", "1"], ["84034.4", "1.58279811", "0", "1"], ["84030.3", "0.23802699", "0", "1"], ["84028.3", "0", "0", "0"], ["84007.4", "0.91613799", "0", "1"], ["84005", "2.82166655", "0", "1"], ["83977.9", "0.29198412", "0", "1"], ["83922.1", "0", "0", "0"], ["83922", "0", "0", "0"]], "ts": "1742555203104", "checksum": 1062221377, "seqId": 49927511880, "prevSeqId": 49927511853}], "record_time": 1742555203.156414, "EXCHANGE": "OKX"}
{"arg": {"channel": "books", "instId": "BTC-USDT"}, "action": "update", "data": [{"asks": [["84087.1", "0", "0", "0"], ["84088.2", "0.23802594", "0", "1"], ["84130.2", "0.01130576", "0", "1"]], "bids": [["84060", "0.44550486", "0", "7"], ["84037.4", "0.74567228", "0", "2"], ["84030.3", "0", "0", "0"], ["84028.9", "0.23802594", "0", "1"], ["84010.1", "0", "0", "0"], ["84010", "0.0184719", "0", "2"], ["83938.3", "0.18328015", "0", "1"], ["83922.1", "0.00621039", "0", "1"]], "ts": "1742555203204", "checksum": -1318426887, "seqId": 49927511904, "prevSeqId": 49927511880}], "record_time": 1742555203.206765, "EXCHANGE": "OKX"}
{"arg": {"channel": "books", "instId": "BTC-USDT"}, "action": "update", "data": [{"asks": [], "bids": [["84060", "0.44495888", "0", "5"], ["84046.2", "0.44920868", "0", "2"], ["84044", "0", "0", "0"], ["84031.6", "0.23802355", "0", "1"], ["84028.9", "0", "0", "0"], ["83922", "0.00001197", "0", "1"]], "ts": "1742555203404", "checksum": -163772459, "seqId": 49927511912, "prevSeqId": 49927511904}], "record_time": 1742555203.407172, "EXCHANGE": "OKX"}
{"arg": {"channel": "books", "instId": "BTC-USDT"}, "action": "update", "data": [{"asks": [["84143.7", "0.0713066", "0", "1"]], "bids": [["84060", "0.24245888", "0", "4"], ["84051", "0.04", "0", "1"], ["84046.2", "0.71951876", "0", "3"], ["84044.2", "1", "0", "1"], ["84031.6", "0", "0", "0"], ["84030.3", "0.23802528", "0", "1"], ["84030.2", "0", "0", "0"], ["84030", "0.00001196", "0", "1"], ["84008", "0.1", "0", "1"], ["83978.8", "0.07144658", "0", "1"], ["83922", "0", "0", "0"]], "ts": "1742555203504", "checksum": 1506821348, "seqId": 49927511927, "prevSeqId": 49927511912}], "record_time": 1742555203.515333, "EXCHANGE": "OKX"}
{"arg": {"channel": "books", "instId": "BTC-USDT"}, "action": "update", "data": [{"asks": [["84086.2", "0.23802749", "0", "1"], ["84088.2", "0", "0", "0"], ["84143.7", "0.1426132", "0", "2"]], "bids": [["84060", "0.10754752", "0", "3"], ["84030.3", "0", "0", "0"], ["84027.4", "0.23802988", "0", "1"], ["84008", "0", "0", "0"], ["83978.8", "0.14289316", "0", "2"], ["83922", "0.00001197", "0", "1"]], "ts": "1742555203604", "checksum": 868568269, "seqId": 49927511947, "prevSeqId": 49927511927}], "record_time": 1742555203.686046, "EXCHANGE": "OKX"}
{"arg": {"channel": "books", "instId": "BTC-USDT"}, "action": "update", "data": [{"asks": [["84060.9", "0.01055", "0", "1"], ["84063.3", "0.00066642", "0", "1"], ["84072.4", "0.04386352", "0", "3"], ["84073.3", "0.00906686", "0", "1"], ["84073.5", "0.06420958", "0", "2"], ["84073.6", "0.04158543", "0", "2"], ["84073.7", "0", "0", "0"], ["84073.9", "0", "0", "0"], ["84079.4", "0.03226308", "0", "1"], ["84079.8", "0.24684265", "0", "2"], ["84080.2", "0", "0", "0"], ["84080.3", "0", "0", "0"], ["84082.3", "0.04085703", "0", "4"], ["84082.4", "0.04212196", "0", "3"], ["84082.5", "0", "0", "0"], ["84083.8", "0.23803128", "0", "1"], ["84086.2", "0", "0", "0"], ["84086.4", "0.06851238", "0", "1"], ["84087.3", "0", "0", "0"], ["84089", "0.06344177", "0", "1"], ["84089.1", "0", "0", "0"], ["84089.2", "0.06977033", "0", "1"], ["84089.7", "0", "0", "0"], ["84091", "0.06837897", "0", "1"], ["84091.2", "0", "0", "0"], ["84232", "0.00172464", "0", "3"], ["84232.3", "0.29700048", "0", "2"]], "bids": [["84050", "0.00033629", "0", "3"], ["84047.6", "0.0134", "0", "1"], ["84046", "0", "0", "0"], ["84045.7", "0", "0", "0"], ["84045.5", "0.03199299", "0", "1"], ["84045.1", "0.05015032", "0", "3"], ["84045", "0.02380344", "0", "1"], ["84044.9", "0.03364178", "0", "1"], ["84044.5", "0", "0", "0"], ["84044.1", "0.03189749", "0", "1"], ["84039", "0", "0", "0"], ["84038.2", "0", "0", "0"], ["84038.1", "0.03377533", "0", "1"], ["84037.8", "0.03416467", "0", "1"], ["84036.9", "0", "0", "0"], ["84036.8", "0.03157041", "0", "1"], ["84036.3", "0", "0", "0"], ["84036.2", "0.03525389", "0", "1"], ["84032", "0", "0", "0"], ["84031.1", "0.06684651", "0", "1"], ["84029.6", "0", "0", "0"], ["84029.5", "0.2408995", "0", "2"], ["84028.8", "0.2025", "0", "1"], ["84028.3", "0.06909805", "0", "1"], ["84028.2", "0", "0", "0"], ["84028", "0.06886133", "0", "1"], ["83977.7", "0", "0", "0"], ["83951.3", "0.05700028", "0", "1"], ["83922", "0", "0", "0"]], "ts": "1742555203704", "checksum": 146495339, "seqId": 49927512006, "prevSeqId": 49927511947}], "record_time": 1742555203.705584, "EXCHANGE": "OKX"}
{"arg": {"channel": "books", "instId": "BTC-USDT"}, "action": "update", "data": [{"asks": [["84063.3", "0", "0", "0"], ["84076.6", "0", "0", "0"], ["84084", "0.64482513", "0", "2"], ["84097", "0.2", "0", "1"], ["84114.3", "1.05140306", "0", "2"], ["84232.6", "0.00001501", "0", "1"]], "bids": [["84050.4", "0.00351473", "0", "1"], ["84000.1", "2.38962244", "0", "2"], ["83977.9", "0", "0", "0"]], "ts": "1742555203804", "checksum": -314325154, "seqId": 49927512014, "prevSeqId": 49927512006}], "record_time": 1742555203.870652, "EXCHANGE": "OKX"}
{"arg": {"channel": "books", "instId": "BTC-USDT"}, "action": "update", "data": [{"asks": [["84063.4", "0.01583711", "0", "2"], ["84072.4", "0.01", "0", "2"], ["84072.6", "0.03198898", "0", "1"], ["84073.5", "0", "0", "0"], ["84073.6", "0.04192503", "0", "2"], ["84073.7", "0.0671054", "0", "2"], ["84079.4", "0", "0", "0"], ["84079.6", "0.03477828", "0", "1"], ["84079.8", "0.21584076", "0", "1"], ["84080", "0.04585158", "0", "2"], ["84083.8", "0", "0", "0"], ["84086.2", "0.23803109", "0", "1"], ["84086.4", "0", "0", "0"], ["84086.6", "0.06650258", "0", "1"], ["84089", "0", "0", "0"], ["84089.1", "0.06685045", "0", "1"], ["84089.2", "0", "0", "0"], ["84089.4", "0.06263363", "0", "1"], ["84091", "0", "0", "0"], ["84091.1", "0.06704561", "0", "1"], ["84232.6", "0", "0", "0"]], "bids": [["84060", "0.12539152", "0", "4"], ["84045.6", "0.03350005", "0", "1"], ["84045.5", "0", "0", "0"], ["84045.3", "0.03462969", "0", "1"], ["84045.1", "0.01790207", "0", "2"], ["84045", "0.0546826", "0", "2"], ["84044.9", "0", "0", "0"], ["84044.3", "0.38945961", "0", "2"], ["84044.1", "0", "0", "0"], ["84038.3", "0.03092235", "0", "1"], ["84038.1", "0", "0", "0"], ["84038", "0.0526888", "0", "2"], ["84037.8", "0", "0", "0"], ["84031.3", "0.06757183", "0", "1"], ["84031.1", "0", "0", "0"], ["84029.6", "0.06740175", "0", "1"], ["84029.5", "0.17821722", "0", "1"], ["84028.5", "0.06750768", "0", "1"], ["84028.3", "0", "0", "0"], ["84028.1", "0.06383396", "0", "1"], ["84028", "0", "0", "0"], ["83958.5", "0", "0", "0"], ["83922", "0.00001197", "0", "1"], ["83921.7", "0.0535785", "0", "1"]], "ts": "1742555203904", "checksum": -1333037077, "seqId": 49927512063, "prevSeqId": 49927512014}], "record_time": 1742555203.905011, "EXCHANGE": "OKX"}
{"arg": {"channel": "books", "instId": "BTC-USDT"}, "action": "update", "data": [{"asks": [["84063.9", "0.03407567", "0", "2"], ["84066.1", "0", "0", "0"], ["84072.4", "0.04457332", "0", "3"], ["84072.6", "0", "0", "0"], ["84073.5", "0.06557024", "0", "2"], ["84073.6", "0.04398684", "0", "2"], ["84073.7", "0", "0", "0"], ["84079.4", "0.03321184", "0", "1"], ["84079.6", "0", "0", "0"], ["84079.8", "0.24822979", "0", "2"], ["84080", "0.0146", "0", "1"], ["84086.4", "0.06645383", "0", "1"], ["84086.6", "0", "0", "0"], ["84089", "0.06492606", "0", "1"], ["84089.1", "0", "0", "0"], ["84089.2", "0.06239802", "0", "1"], ["84089.4", "0", "0", "0"], ["84091", "0.0692068", "0", "1"], ["84091.1", "0", "0", "0"], ["84097", "1.2", "0", "2"], ["84232.6", "0.00001501", "0", "1"], ["84232.9", "0.08747", "0", "1"]], "bids": [["84060", "0.10754752", "0", "3"], ["84045.6", "0", "0", "0"], ["84045.5", "0.0329899", "0", "1"], ["84045.3", "0", "0", "0"], ["84045.1", "0.0496579", "0", "3"], ["84045", "0.02380344", "0", "1"], ["84044.9", "0.03470991", "0", "1"], ["84044.3", "0.35579296", "0", "1"], ["84044.1", "0.03289278", "0", "1"], ["84038.3", "0", "0", "0"], ["84038.1", "0.03145074", "0", "1"], ["84038", "0.01774536", "0", "1"], ["84037.8", "0.0317052", "0", "1"], ["84031.3", "0", "0", "0"], ["84031.1", "0.06453653", "0", "1"], ["84029.6", "0", "0", "0"], ["84029.5", "0.24131624", "0", "2"], ["84028.5", "0", "0", "0"], ["84028.3", "0.06372715", "0", "1"], ["84028.1", "0.23803026", "0", "1"], ["84028", "0.06931924", "0", "1"], ["84027.4", "0", "0", "0"], ["83984.2", "0", "0", "0"]], "ts": "1742555204004", "checksum": -1557750967, "seqId": 49927512113, "prevSeqId": 49927512063}], "record_time": 1742555204.014861, "EXCHANGE": "OKX"}
{"arg": {"channel": "books", "instId": "BTC-USDT"}, "action": "update", "data": [{"asks": [["84072.2", "0.06271895", "0", "2"], ["84072.4", "0.01", "0", "2"], ["84073.2", "0.03209408", "0", "1"], ["84073.4", "0.0732279", "0", "2"], ["84073.5", "0.03359797", "0", "1"], ["84073.6", "0.01055", "0", "1"], ["84079.2", "0.03063093", "0", "1"], ["84079.4", "0", "0", "0"], ["84079.5", "0.03456416", "0", "1"], ["84079.8", "0.21584076", "0", "1"], ["84082.1", "0.03135481", "0", "1"], ["84082.2", "0.03384555", "0", "1"], ["84082.3", "0.00631911", "0", "3"], ["84082.4", "0.01", "0", "2"], ["84086.2", "0.30371344", "0", "2"], ["84086.4", "0", "0", "0"], ["84088.9", "0.06799696", "0", "1"], ["84089", "0.06906278", "0", "1"], ["84089.2", "0", "0", "0"], ["84090.9", "0.06501705", "0", "1"], ["84091", "0", "0", "0"], ["84124.9", "0.01130836", "0", "1"], ["84130.2", "0", "0", "0"], ["84232.3", "0", "0", "0"], ["84232.6", "0", "0", "0"], ["84232.9", "0", "0", "0"]], "bids": [["84060", "0.08314402", "0", "4"], ["84045.5", "0", "0", "0"], ["84045.4", "0.03367153", "0", "1"], ["84045.1", "0.01790207", "0", "2"], ["84044.9", "0.03347177", "0", "1"], ["84044.8", "0.0316761", "0", "1"], ["84044.1", "0", "0", "0"], ["84043.8", "0.0345071", "0", "1"], ["84038.1", "0", "0", "0"], ["84037.9", "0.21996175", "0", "2"], ["84037.8", "0", "0", "0"], ["84037.5", "0.0408015", "0", "2"], ["84036.8", "0", "0", "0"], ["84036.6", "0.03190992", "0", "1"], ["84036.2", "0", "0", "0"], ["84036", "0.03447296", "0", "1"], ["84031.1", "0", "0", "0"], ["84030.9", "0.06805926", "0", "2"], ["84029.5", "0.17821722", "0", "1"], ["84029.4", "0.06542368", "0", "1"], ["84028.3", "0", "0", "0"], ["84028.1", "0.06497529", "0", "1"], ["84028", "0", "0", "0"], ["84027.9", "0.07199036", "0", "2"], ["84027.4", "0.2380301", "0", "1"], ["84010", "0.00014389", "0", "1"], ["84007.5", "0.01832832", "0", "1"], ["83982.3", "0.01902428", "0", "1"], ["83938.3", "0", "0", "0"], ["83937", "0.1832835", "0", "1"]], "ts": "1742555204104", "checksum": 153145681, "seqId": 49927512186, "prevSeqId": 49927512113}], "record_time": 1742555204.11544, "EXCHANGE": "OKX"}
{"arg": {"channel": "books", "instId": "BTC-USDT"}, "action": "update", "data": [{"asks": [["84083.8", "0.23803181", "0", "1"], ["84086.2", "0.06568235", "0", "1"], ["84232", "0", "0", "0"]], "bids": [], "ts": "1742555204204", "checksum": 153145681, "seqId": 49927512190, "prevSeqId": 49927512186}], "record_time": 1742555204.207696, "EXCHANGE": "OKX"}
{"arg": {"channel": "books", "instId": "BTC-USDT"}, "action": "update", "data": [{"asks": [["84083.8", "0", "0", "0"], ["84086.1", "0.23803123", "0", "1"]], "bids": [["84027.4", "0.23803129", "0", "1"]], "ts": "1742555204304", "checksum": 153145681, "seqId": 49927512212, "prevSeqId": 49927512190}], "record_time": 1742555204.305067, "EXCHANGE": "OKX"}
{"arg": {"channel": "books", "instId": "BTC-USDT"}, "action": "update", "data": [{"asks": [["84070", "0.0146", "0", "1"], ["84086.1", "0.23803082", "0", "1"], ["84143.7", "0.0713066", "0", "1"]], "bids": [["84045.5", "1", "0", "1"], ["84044.2", "0", "0", "0"], ["84028", "0.23803082", "0", "1"], ["84027.4", "0", "0", "0"], ["83978.8", "0.07144658", "0", "1"]], "ts": "1742555204404", "checksum": -464605699, "seqId": 49927512230, "prevSeqId": 49927512212}], "record_time": 1742555204.411961, "EXCHANGE": "OKX"}
{"arg": {"channel": "books", "instId": "BTC-USDT"}, "action": "update", "data": [{"asks": [["84072", "0.04951459", "0", "2"], ["84072.1", "0.25920638", "0", "1"], ["84072.2", "0.02915443", "0", "1"], ["84073", "0.03456576", "0", "2"], ["84073.2", "0.03424756", "0", "1"], ["84073.3", "0.04218168", "0", "2"], ["84073.4", "0.03916298", "0", "1"], ["84073.5", "0", "0", "0"], ["84074.6", "0", "0", "0"], ["84075.7", "0.70266363", "0", "2"], ["84076", "1.0146", "0", "2"], ["84079", "0.03477368", "0", "1"], ["84079.2", "0", "0", "0"], ["84079.3", "0.03311548", "0", "1"], ["84079.5", "0", "0", "0"], ["84082", "0.08068582", "0", "3"], ["84082.1", "0", "0", "0"], ["84082.2", "0", "0", "0"], ["84082.8", "0", "0", "0"], ["84086", "0.06769551", "0", "1"], ["84086.2", "0", "0", "0"], ["84088.7", "0.25168226", "0", "3"], ["84088.9", "0", "0", "0"], ["84089", "0", "0", "0"], ["84090.7", "0.06916089", "0", "1"], ["84090.9", "0", "0", "0"], ["84100.4", "0.471192", "0", "1"], ["84106.7", "0.29313233", "0", "1"], ["84109", "0", "0", "0"], ["84143.7", "0.1426132", "0", "2"], ["84232", "0.00172464", "0", "3"], ["84232.3", "0.29700048", "0", "2"], ["84232.6", "0.00001501", "0", "1"], ["84232.9", "0.08747", "0", "1"], ["84233", "0.06012728", "0", "2"], ["84233.3", "0.00101534", "0", "2"], ["84233.5", "0.00002296", "0", "1"]], "bids": [["84060", "0.06530002", "0", "3"], ["84049.5", "0.61416359", "0", "2"], ["84046.9", "1", "0", "1"], ["84046.2", "0.44920868", "0", "2"], ["84045.5", "0", "0", "0"], ["84045.4", "0", "0", "0"], ["84045.2", "0.03120394", "0", "1"], ["84044.9", "0", "0", "0"], ["84044.8", "0", "0", "0"], ["84044.7", "0.06693308", "0", "2"], ["84044.6", "0.03290947", "0", "1"], ["84043.8", "0", "0", "0"], ["84043.6", "0.04013449", "0", "2"], ["84037.9", "0.18725022", "0", "1"], ["84037.7", "0.03065578", "0", "1"], ["84037.5", "0.00713967", "0", "1"], ["84037.3", "0.23760297", "0", "2"], ["84036.6", "0", "0", "0"], ["84036.5", "0.03140719", "0", "1"], ["84036", "0", "0", "0"], ["84035.8", "0.39109788", "0", "2"], ["84030.9", "0.00001196", "0", "1"], ["84030.7", "0.06601591", "0", "1"], ["84029.4", "0", "0", "0"], ["84029.2", "0.06279721", "0", "1"], ["84028.1", "0", "0", "0"], ["84027.9", "0.009425", "0", "1"], ["84027.8", "0.06375274", "0", "1"], ["84027.7", "0.06194881", "0", "2"], ["84023", "1", "0", "1"], ["83978.8", "0.14289316", "0", "2"]], "ts": "1742555204504", "checksum": 188216421, "seqId": 49927512307, "prevSeqId": 49927512230}], "record_time": 1742555204.505878, "EXCHANGE": "OKX"}
{"arg": {"channel": "books", "instId": "BTC-USDT"}, "action": "update", "data": [{"asks": [["84082.6", "0.13709275", "0", "2"]], "bids": [["84013", "0.2", "0", "1"], ["83921.7", "0", "0", "0"]], "ts": "1742555204604", "checksum": 188216421, "seqId": 49927512310, "prevSeqId": 49927512307}], "record_time": 1742555204.615745, "EXCHANGE": "OKX"}
{"arg": {"channel": "books", "instId": "BTC-USDT"}, "action": "update", "data": [{"asks": [["84083.2", "0.23803419", "0", "1"], ["84086.1", "0", "0", "0"], ["84101.6", "0.08", "0", "2"], ["84102.4", "0.28981999", "0", "2"], ["84103.2", "0", "0", "0"]], "bids": [["84049.5", "0.34499684", "0", "1"], ["84046.9", "0", "0", "0"], ["84046.2", "0.7194727", "0", "3"], ["84046.1", "1.00006", "0", "2"], ["84028", "0", "0", "0"], ["84027.4", "0.23803419", "0", "1"], ["84023", "0", "0", "0"], ["84013", "0", "0", "0"], ["83921.7", "0.0535785", "0", "1"], ["83921.3", "0.0016853", "0", "2"], ["83921", "0.00001002", "0", "1"]], "ts": "1742555204704", "checksum": 188216421, "seqId": 49927512328, "prevSeqId": 49927512310}], "record_time": 1742555204.744181, "EXCHANGE": "OKX"}
{"arg": {"channel": "books", "instId": "BTC-USDT"}, "action": "update", "data": [{"asks": [["84072.1", "0.52044101", "0", "2"], ["84074.2", "1", "0", "1"], ["84075.7", "0.37339636", "0", "1"], ["84076", "0.0146", "0", "1"], ["84096.9", "1.07824954", "0", "1"], ["84097.5", "0", "0", "0"], ["84233.5", "0", "0", "0"]], "bids": [["84046.1", "0.00006", "0", "1"], ["84045.6", "1", "0", "1"], ["84031.6", "0.1084025", "0", "1"], ["84007.4", "1.92979769", "0", "2"], ["84000.1", "0.92785749", "0", "1"], ["83982.1", "0.34554865", "0", "2"], ["83921.3", "0", "0", "0"], ["83921", "0", "0", "0"]], "ts": "1742555204804", "checksum": -245849156, "seqId": 49927512350, "prevSeqId": 49927512328}], "record_time": 1742555204.805172, "EXCHANGE": "OKX"}
{"arg": {"channel": "books", "instId": "BTC-USDT"}, "action": "update", "data": [{"asks": [["84074.2", "0", "0", "0"], ["84075.6", "1", "0", "1"], ["84101.6", "0", "0", "0"], ["84102.4", "0.32981999", "0", "3"], ["84103.2", "0.03999999", "0", "1"]], "bids": [["83978.3", "0.04769993", "0", "2"], ["83977.6", "0.03", "0", "1"]], "ts": "1742555204904", "checksum": -245849156, "seqId": 49927512361, "prevSeqId": 49927512350}], "record_time": 1742555204.94587, "EXCHANGE": "OKX"}
{"arg": {"channel": "books", "instId": "BTC-USDT"}, "action": "update", "data": [{"asks": [["84101.6", "0.08", "0", "2"], ["84102.4", "0.28981999", "0", "2"], ["84103.2", "0", "0", "0"]], "bids": [["84060", "0.06483002", "0", "3"], ["84027.4", "0", "0", "0"], ["84026.5", "0.23803361", "0", "1"]], "ts": "1742555205004", "checksum": -1651964414, "seqId": 49927512374, "prevSeqId": 49927512361}], "record_time": 1742555205.014916, "EXCHANGE": "OKX"}
{"arg": {"channel": "books", "instId": "BTC-USDT"}, "action": "update", "data": [{"asks": [["84072", "0.0146", "0", "1"], ["84072.1", "0.55551813", "0", "3"], ["84073", "0.000015", "0", "1"], ["84073.1", "0.05138403", "0", "2"], ["84073.2", "0", "0", "0"], ["84073.3", "0.0421142", "0", "2"], ["84073.4", "0.07068388", "0", "2"], ["84079", "0", "0", "0"], ["84079.1", "0.03243552", "0", "1"], ["84079.3", "0", "0", "0"], ["84079.4", "0.03419828", "0", "1"], ["84082", "0.04938415", "0", "2"], ["84082.1", "0.03120231", "0", "1"], ["84086", "0", "0", "0"], ["84086.1", "0.06214334", "0", "1"], ["84088.7", "0.11890903", "0", "1"], ["84088.8", "0.13262498", "0", "2"], ["84090.7", "0", "0", "0"], ["84090.8", "0.06725843", "0", "1"], ["84101.6", "0", "0", "0"], ["84102.4", "0.32981999", "0", "3"], ["84103.2", "0.03999999", "0", "1"], ["84233.3", "0", "0", "0"]], "bids": [["84060", "0.07251002", "0", "4"], ["84045.3", "0.03304081", "0", "1"], ["84045.2", "0", "0", "0"], ["84044.8", "0.03195883", "0", "1"], ["84044.7", "0.06731688", "0", "2"], ["84044.6", "0", "0", "0"], ["84043.7", "0.03357631", "0", "1"], ["84043.6", "0.00475943", "0", "1"], ["84037.8", "0.03327466", "0", "1"], ["84037.7", "0", "0", "0"], ["84037.4", "0.77673472", "0", "3"], ["84037.3", "0.2025", "0", "1"], ["84035.9", "0.17546984", "0", "3"], ["84035.8", "0.35579296", "0", "1"], ["84030.8", "0.06584308", "0", "1"], ["84030.7", "0", "0", "0"], ["84029.3", "0.06952767", "0", "2"], ["84029.2", "0", "0", "0"], ["84027.9", "0.07206512", "0", "2"], ["84027.8", "0.06286209", "0", "1"], ["84027.7", "0.00007596", "0", "1"], ["84026.3", "0", "0", "0"], ["84014.5", "0", "0", "0"], ["84008.6", "0.0354", "0", "2"], ["83926.3", "0.0054", "0", "1"], ["83921.3", "0.0016853", "0", "2"]], "ts": "1742555205104", "checksum": -1547442285, "seqId": 49927512433, "prevSeqId": 49927512374}], "record_time": 1742555205.104523, "EXCHANGE": "OKX"}
{"arg": {"channel": "books", "instId": "BTC-USDT"}, "action": "update", "data": [{"asks": [["84072.3", "0", "0", "0"], ["84082.3", "0.00431911", "0", "2"], ["84101.6", "0.08", "0", "2"], ["84102.4", "0.28981999", "0", "2"], ["84103.2", "0", "0", "0"], ["84233.3", "0.00101534", "0", "2"]], "bids": [["84058.1", "0", "0", "0"], ["84048", "0", "0", "0"], ["83921", "0.00001002", "0", "1"], ["83920", "0.00001096", "0", "1"]], "ts": "1742555205404", "checksum": 1015065781, "seqId": 49927512447, "prevSeqId": 49927512433}], "record_time": 1742555205.445498, "EXCHANGE": "OKX"}
{"arg": {"channel": "books", "instId": "BTC-USDT"}, "action": "update", "data": [{"asks": [["84083.2", "0", "0", "0"], ["84083.9", "0.3741844", "0", "4"], ["84233.5", "0.00002296", "0", "1"]], "bids": [["84027.9", "0.31009596", "0", "3"], ["84026.5", "0", "0", "0"], ["83919.2", "0.00003545", "0", "1"]], "ts": "1742555205504", "checksum": 1015065781, "seqId": 49927512467, "prevSeqId": 49927512447}], "record_time": 1742555205.508159, "EXCHANGE": "OKX"}
{"arg": {"channel": "books", "instId": "BTC-USDT"}, "action": "update", "data": [{"asks": [["84072", "0.04641491", "0", "2"], ["84072.1", "0.52044101", "0", "2"], ["84072.3", "0.002", "0", "1"], ["84073", "0.03414828", "0", "2"], ["84073.1", "0.01910134", "0", "1"], ["84073.2", "0.03398823", "0", "1"], ["84073.3", "0.0404603", "0", "2"], ["84073.4", "0.03916298", "0", "1"], ["84079", "0.03511703", "0", "1"], ["84079.1", "0", "0", "0"], ["84079.3", "0.03419803", "0", "1"], ["84079.4", "0", "0", "0"], ["84082", "0.08266917", "0", "3"], ["84082.1", "0", "0", "0"], ["84082.3", "0.00631911", "0", "3"], ["84083.9", "0.13615356", "0", "3"], ["84085.9", "0.23802904", "0", "1"], ["84086", "0.06722575", "0", "1"], ["84086.1", "0", "0", "0"], ["84088.7", "0.24840318", "0", "3"], ["84088.8", "0", "0", "0"], ["84090.7", "0.06141666", "0", "1"], ["84090.8", "0", "0", "0"], ["84143.7", "0.0713066", "0", "1"], ["84233.5", "0", "0", "0"]], "bids": [["84060", "0.06483002", "0", "3"], ["84058.1", "0.002", "0", "1"], ["84048", "0.002", "0", "1"], ["84045.3", "0", "0", "0"], ["84045.2", "0.03426222", "0", "1"], ["84044.8", "0", "0", "0"], ["84044.7", "0.06900658", "0", "2"], ["84044.6", "0.03536263", "0", "1"], ["84043.7", "0", "0", "0"], ["84043.6", "0.04016394", "0", "2"], ["84037.8", "0", "0", "0"], ["84037.7", "0.03128986", "0", "1"], ["84037.4", "0.74567228", "0", "2"], ["84037.3", "0.23644133", "0", "2"], ["84036.5", "0.03412284", "0", "1"], ["84035.9", "0.14044962", "0", "2"], ["84035.8", "0.38973536", "0", "2"], ["84030.8", "0", "0", "0"], ["84030.7", "0.07019632", "0", "1"], ["84029.3", "0.00353141", "0", "1"], ["84029.2", "0.06988191", "0", "1"], ["84027.9", "0.24745584", "0", "2"], ["84027.8", "0.06360909", "0", "1"], ["84027.7", "0.06637269", "0", "2"], ["83978.8", "0.07144658", "0", "1"], ["83920", "0", "0", "0"], ["83919.2", "0", "0", "0"]], "ts": "1742555205604", "checksum": 1614717411, "seqId": 49927512537, "prevSeqId": 49927512467}], "record_time": 1742555205.605466, "EXCHANGE": "OKX"}
{"arg": {"channel": "books", "instId": "BTC-USDT"}, "action": "update", "data": [{"asks": [["84083.8", "0.23803152", "0", "1"], ["84085.9", "0", "0", "0"], ["84143.7", "0", "0", "0"], ["84233.5", "0.00002296", "0", "1"]], "bids": [["84027.9", "0.009425", "0", "1"], ["84027.4", "0.23803152", "0", "1"], ["84023", "1", "0", "1"], ["84013", "0.2", "0", "1"], ["83978.8", "0", "0", "0"], ["83921.3", "0", "0", "0"], ["83921", "0", "0", "0"]], "ts": "1742555205704", "checksum": 1614717411, "seqId": 49927512550, "prevSeqId": 49927512537}], "record_time": 1742555205.777957, "EXCHANGE": "OKX"}
{"arg": {"channel": "books", "instId": "BTC-USDT"}, "action": "update", "data": [{"asks": [["84084", "0.14291634", "0", "1"], ["84086.3", "0", "0", "0"], ["84088.4", "0.20857948", "0", "1"], ["84114.3", "0.18608224", "0", "1"], ["84115.8", "0", "0", "0"], ["84143.7", "0.1426132", "0", "2"]], "bids": [["84037.4", "0.30960833", "0", "1"], ["84034.4", "0", "0", "0"], ["84023", "0", "0", "0"], ["84013", "0.1", "0", "1"], ["84007.4", "0.91613799", "0", "1"], ["84005", "0", "0", "0"], ["84000.1", "1.2676063", "0", "2"], ["83978.8", "0.14289316", "0", "2"], ["83978.1", "0.27674637", "0", "1"], ["83921.3", "0.0016853", "0", "2"]], "ts": "1742555205904", "checksum": 1614717411, "seqId": 49927512580, "prevSeqId": 49927512550}], "record_time": 1742555205.967112, "EXCHANGE": "OKX"}
{"arg": {"channel": "books", "instId": "BTC-USDT"}, "action": "update", "data": [{"asks": [["84086.3", "1.52961791", "0", "1"], ["84114.3", "0.99027801", "0", "2"], ["84115.7", "2.71467484", "0", "1"], ["84143.7", "0.0713066", "0", "1"], ["84233.3", "0", "0", "0"], ["84233.5", "0", "0", "0"]], "bids": [["84038", "0", "0", "0"], ["84037.4", "0.76447649", "0", "2"], ["84033.6", "1.6083174", "0", "1"], ["84029.6", "0.01774536", "0", "1"], ["84004.2", "2.9721884", "0", "2"], ["83978.8", "0.07144658", "0", "1"], ["83921.3", "0", "0", "0"]], "ts": "1742555206004", "checksum": 1614717411, "seqId": 49927512596, "prevSeqId": 49927512580}], "record_time": 1742555206.006424, "EXCHANGE": "OKX"}
{"arg": {"channel": "books", "instId": "BTC-USDT"}, "action": "update", "data": [{"asks": [["84072", "0.0146", "0", "1"], ["84072.1", "0.55379977", "0", "3"], ["84073", "0.000015", "0", "1"], ["84073.1", "0.05247636", "0", "2"], ["84073.2", "0", "0", "0"], ["84073.3", "0.04414958", "0", "2"], ["84073.4", "0.07419131", "0", "2"], ["84079", "0", "0", "0"], ["84079.1", "0.0333769", "0", "1"], ["84079.3", "0", "0", "0"], ["84079.4", "0.03229349", "0", "1"], ["84082", "0.04937648", "0", "2"], ["84082.1", "0.03192959", "0", "1"], ["84083.8", "0.23803185", "0", "1"], ["84086", "0", "0", "0"], ["84086.1", "0.06835415", "0", "1"], ["84088.4", "0", "0", "0"], ["84088.7", "0.11890903", "0", "1"], ["84088.8", "0.13173654", "0", "2"], ["84090.7", "0", "0", "0"], ["84090.8", "0.06964778", "0", "1"]], "bids": [["84060", "0.07079002", "0", "4"], ["84045.3", "0.03233833", "0", "1"], ["84045.2", "0", "0", "0"], ["84044.8", "0.0317075", "0", "1"], ["84044.7", "0.06808529", "0", "2"], ["84044.6", "0", "0", "0"], ["84043.7", "0.03156338", "0", "1"], ["84043.6", "0.00475943", "0", "1"], ["84037.8", "0.03433018", "0", "1"], ["84037.7", "0", "0", "0"], ["84037.4", "0.79637791", "0", "3"], ["84037.3", "0.2025", "0", "1"], ["84035.9", "0.17582973", "0", "3"], ["84035.8", "0.35579296", "0", "1"], ["84030.8", "0.06456857", "0", "1"], ["84030.7", "0", "0", "0"], ["84029.3", "0.06660093", "0", "2"], ["84029.2", "0", "0", "0"], ["84027.9", "0.07944427", "0", "2"], ["84027.8", "0.06535703", "0", "1"], ["84027.7", "0.00007596", "0", "1"], ["84027.4", "0.23803184", "0", "1"], ["83970.6", "0", "0", "0"], ["83921.3", "0.0016853", "0", "2"]], "ts": "1742555206104", "checksum": -1750156429, "seqId": 49927512668, "prevSeqId": 49927512596}], "record_time": 1742555206.104418, "EXCHANGE": "OKX"}
{"arg": {"channel": "books", "instId": "BTC-USDT"}, "action": "update", "data": [{"asks": [["84072.1", "0.29256514", "0", "2"], ["84075.6", "0", "0", "0"], ["84075.7", "0.701998", "0", "2"], ["84076.6", "1", "0", "1"], ["84143.7", "0.1426132", "0", "2"]], "bids": [["84049.5", "0.61416359", "0", "2"], ["84047.7", "1.0134", "0", "2"], ["84046.2", "0.44920868", "0", "2"], ["84045.6", "0", "0", "0"], ["84038", "0.01774536", "0", "1"], ["84029.6", "0", "0", "0"], ["83978.8", "0.14289316", "0", "2"], ["83970.6", "0.00016244", "0", "1"]], "ts": "1742555206204", "checksum": 2045546562, "seqId": 49927512689, "prevSeqId": 49927512668}], "record_time": 1742555206.204715, "EXCHANGE": "OKX"}
{"arg": {"channel": "books", "instId": "BTC-USDT"}, "action": "update", "data": [{"asks": [["84060.1", "0.91941061", "0", "13"], ["84074", "0.0146", "0", "1"], ["84083.2", "0.23803264", "0", "1"], ["84083.8", "0", "0", "0"]], "bids": [["84047.7", "0.0134", "0", "1"], ["84046.3", "1", "0", "1"], ["84027.4", "0", "0", "0"], ["84026.5", "0.23803264", "0", "1"], ["84026.4", "0.08", "0", "2"], ["83970.6", "0", "0", "0"]], "ts": "1742555206304", "checksum": 690953237, "seqId": 49927512714, "prevSeqId": 49927512689}], "record_time": 1742555206.304508, "EXCHANGE": "OKX"}
{"arg": {"channel": "books", "instId": "BTC-USDT"}, "action": "update", "data": [{"asks": [["84063.8", "0.03432793", "0", "1"], ["84063.9", "0.01190234", "0", "1"], ["84066.1", "0.03916298", "0", "1"], ["84072.1", "0.22139155", "0", "2"], ["84073.4", "0.03502833", "0", "1"], ["84077.8", "0.17821722", "0", "1"], ["84078.2", "0.08991011", "0", "1"], ["84083.2", "0", "0", "0"], ["84083.8", "0.23803186", "0", "1"], ["84232.6", "0", "0", "0"], ["84232.9", "0", "0", "0"], ["84233", "0", "0", "0"]], "bids": [["84051.5", "0", "0", "0"], ["84050.4", "0", "0", "0"], ["84049.5", "0.34499684", "0", "1"], ["84046.3", "0", "0", "0"], ["84046.2", "0.71865458", "0", "3"], ["84044.8", "1.0317075", "0", "2"], ["84027", "0.23803186", "0", "1"], ["84026.5", "0", "0", "0"], ["84026.4", "0", "0", "0"], ["84025.6", "0.08", "0", "2"], ["84024.8", "0.59510201", "0", "4"], ["84024", "0.013", "0", "1"], ["84022.4", "0", "0", "0"], ["84021.6", "0.1", "0", "2"], ["84020.8", "0.05", "0", "1"], ["83970.6", "0.00016244", "0", "1"], ["83921", "0.00001002", "0", "1"], ["83920", "0.00001096", "0", "1"]], "ts": "1742555206404", "checksum": -531243447, "seqId": 49927512757, "prevSeqId": 49927512714}], "record_time": 1742555206.405542, "EXCHANGE": "OKX"}
{"arg": {"channel": "books", "instId": "BTC-USDT"}, "action": "update", "data": [{"asks": [["84068", "0.31527323", "0", "3"], ["84068.9", "0.17844", "0", "1"], ["84071", "0.35641581", "0", "1"], ["84071.1", "0.35689", "0", "1"], ["84072.1", "0.11601655", "0", "2"], ["84072.4", "0.01564", "0", "3"], ["84074.7", "0.01190031", "0", "1"], ["84082.5", "0.23803562", "0", "1"], ["84083.8", "0", "0", "0"], ["84230.9", "0", "0", "0"], ["84232", "0", "0", "0"], ["84232.3", "0", "0", "0"]], "bids": [["84046.2", "0.44920868", "0", "2"], ["84044.8", "0.0317075", "0", "1"], ["84027", "0", "0", "0"], ["84025.6", "0", "0", "0"], ["84025.3", "0.23803562", "0", "1"], ["84024.8", "0.60910201", "0", "3"], ["84024", "0.066", "0", "3"], ["84023.2", "0.013", "0", "1"], ["84021.6", "0", "0", "0"], ["84020.8", "0.1", "0", "2"], ["84020", "0.05001", "0", "2"], ["84013", "0", "0", "0"], ["83919.2", "0.00003545", "0", "1"], ["83918.9", "0.00001197", "0", "1"]], "ts": "1742555206504", "checksum": 357574921, "seqId": 49927512795, "prevSeqId": 49927512757}], "record_time": 1742555206.504315, "EXCHANGE": "OKX"}
{"arg": {"channel": "books", "instId": "BTC-USDT"}, "action": "update", "data": [{"asks": [["84072", "0.04769589", "0", "2"], ["84072.1", "0.07473931", "0", "2"], ["84073", "0.03146716", "0", "2"], ["84073.1", "0.01910134", "0", "1"], ["84073.2", "0.03334504", "0", "1"], ["84073.3", "0.04286578", "0", "2"], ["84073.4", "0", "0", "0"], ["84079", "0.03311539", "0", "1"], ["84079.1", "0", "0", "0"], ["84079.3", "0.03111335", "0", "1"], ["84079.4", "0", "0", "0"], ["84081.3", "0.23803764", "0", "1"], ["84082", "0.08293723", "0", "3"], ["84082.1", "0", "0", "0"], ["84082.5", "0", "0", "0"], ["84086", "0.06736831", "0", "1"], ["84086.1", "0", "0", "0"], ["84088.7", "0.24682291", "0", "3"], ["84088.8", "0", "0", "0"], ["84090.7", "0.064488", "0", "1"], ["84090.8", "0.00357", "0", "1"], ["84101.6", "0", "0", "0"], ["84102.4", "0.32981999", "0", "3"], ["84103.2", "0.03999999", "0", "1"], ["84109.5", "0", "0", "0"], ["84230.9", "0.35582144", "0", "2"], ["84232", "0.00172464", "0", "3"]], "bids": [["84060", "0.06483002", "0", "3"], ["84046.2", "0.71865458", "0", "3"], ["84045.3", "0", "0", "0"], ["84045.2", "0.03279034", "0", "1"], ["84044.8", "0", "0", "0"], ["84044.7", "1.0682269", "0", "3"], ["84044.6", "0.03326797", "0", "1"], ["84043.7", "0", "0", "0"], ["84043.6", "0.03986699", "0", "2"], ["84037.8", "0", "0", "0"], ["84037.7", "0.03310669", "0", "1"], ["84037.4", "0.76447649", "0", "2"], ["84037.3", "0.23555253", "0", "2"], ["84035.9", "0.14044962", "0", "2"], ["84035.8", "0.3872897", "0", "2"], ["84030.8", "0", "0", "0"], ["84030.7", "0.0614943", "0", "1"], ["84029.3", "0.00353141", "0", "1"], ["84029.2", "0.0629251", "0", "1"], ["84027.9", "0.009425", "0", "1"], ["84027.8", "0.06852104", "0", "1"], ["84027.7", "0.06845718", "0", "2"], ["84025.3", "0", "0", "0"], ["84024.8", "0.52910201", "0", "1"], ["84024", "0.08", "0", "2"], ["84023.8", "0.23803764", "0", "1"], ["84023.2", "0.066", "0", "3"], ["84022.4", "0.013", "0", "1"], ["84020.8", "0", "0", "0"], ["84020", "0.10001", "0", "3"], ["84019.2", "0.05", "0", "1"], ["83918.9", "0", "0", "0"]], "ts": "1742555206604", "checksum": 768847865, "seqId": 49927512875, "prevSeqId": 49927512795}], "record_time": 1742555206.605257, "EXCHANGE": "OKX"}
{"arg": {"channel": "books", "instId": "BTC-USDT"}, "action": "update", "data": [{"asks": [], "bids": [["84024", "0", "0", "0"], ["84023.2", "0.106", "0", "4"], ["84022.4", "0.053", "0", "2"], ["83918.9", "0.00001197", "0", "1"]], "ts": "1742555206704", "checksum": 768847865, "seqId": 49927512879, "prevSeqId": 49927512875}], "record_time": 1742555206.708371, "EXCHANGE": "OKX"}
{"arg": {"channel": "books", "instId": "BTC-USDT"}, "action": "update", "data": [{"asks": [], "bids": [["84046", "1", "0", "1"], ["84044.7", "0.0682269", "0", "2"], ["83918.9", "0", "0", "0"]], "ts": "1742555206804", "checksum": 768847865, "seqId": 49927512896, "prevSeqId": 49927512879}], "record_time": 1742555206.826734, "EXCHANGE": "OKX"}
{"arg": {"channel": "books", "instId": "BTC-USDT"}, "action": "update", "data": [{"asks": [["84072.4", "0.01", "0", "2"], ["84084", "0.61841143", "0", "2"]], "bids": [["84046", "1.00564", "0", "2"], ["84024", "0.08", "0", "2"], ["84023.2", "0.066", "0", "3"], ["84022.4", "0.013", "0", "1"], ["84020", "1.10001", "0", "4"], ["84000.1", "2.26327991", "0", "1"], ["83978.1", "0", "0", "0"]], "ts": "1742555206904", "checksum": 768847865, "seqId": 49927512915, "prevSeqId": 49927512896}], "record_time": 1742555206.90609, "EXCHANGE": "OKX"}
{"arg": {"channel": "books", "instId": "BTC-USDT"}, "action": "update", "data": [{"asks": [["84065.4", "0.00364912", "0", "1"], ["84070", "0.0151355", "0", "2"], ["84072", "0.0146", "0", "1"], ["84072.1", "0.10986502", "0", "3"], ["84079", "0", "0", "0"], ["84079.1", "0.0339918", "0", "1"], ["84082", "0.04937648", "0", "2"], ["84082.1", "0.03439816", "0", "1"], ["84086", "0", "0", "0"], ["84086.1", "0.06188418", "0", "1"], ["84088.7", "0.1827992", "0", "2"], ["84088.8", "0.06612399", "0", "1"], ["84159.8", "0.08865786", "0", "3"], ["84161.1", "0.1", "0", "1"], ["84230.1", "0", "0", "0"], ["84230.7", "0", "0", "0"], ["84230.9", "0", "0", "0"], ["84232", "0", "0", "0"]], "bids": [["84055.9", "0.01190248", "0", "1"], ["84048.7", "0.18183813", "0", "2"], ["84046", "1", "0", "1"], ["84044.8", "0.03178607", "0", "1"], ["84044.7", "0.03618589", "0", "1"], ["84037.8", "0.03133221", "0", "1"], ["84037.7", "0", "0", "0"], ["84035.9", "0.1754999", "0", "3"], ["84035.8", "0.35579296", "0", "1"], ["84030.8", "0.06879257", "0", "1"], ["84030.7", "0", "0", "0"], ["84027.9", "0.07334647", "0", "2"], ["84027.8", "0", "0", "0"], ["84024", "0", "0", "0"], ["84023.2", "0.106", "0", "4"], ["84022.4", "0.053", "0", "2"], ["84020", "0.10001", "0", "3"]], "ts": "1742555207004", "checksum": -2011751207, "seqId": 49927512949, "prevSeqId": 49927512915}], "record_time": 1742555207.01779, "EXCHANGE": "OKX"}
{"arg": {"channel": "books", "instId": "BTC-USDT"}, "action": "update", "data": [{"asks": [["84072.1", "0.10948988", "0", "3"], ["84073", "0.000015", "0", "1"], ["84073.1", "0.05372625", "0", "2"], ["84073.2", "0", "0", "0"], ["84073.3", "0.04225562", "0", "2"], ["84073.4", "0.03517196", "0", "1"], ["84079.3", "0", "0", "0"], ["84079.4", "0.03240135", "0", "1"], ["84088.7", "0.11890903", "0", "1"], ["84088.8", "0.06636494", "0", "1"], ["84088.9", "0.06862101", "0", "1"], ["84090.7", "0", "0", "0"], ["84090.8", "0.06762421", "0", "2"], ["84176.1", "0.2025", "0", "1"]], "bids": [["84060", "0.06932002", "0", "4"], ["84046", "1.0056625", "0", "2"], ["84045.3", "0.03140922", "0", "1"], ["84045.2", "0", "0", "0"], ["84044.7", "0.07103647", "0", "2"], ["84044.6", "0", "0", "0"], ["84043.7", "0.0339977", "0", "1"], ["84043.6", "0.00475943", "0", "1"], ["84037.4", "0.79965785", "0", "3"], ["84037.3", "0.2025", "0", "1"], ["84029.3", "0.07326618", "0", "2"], ["84029.2", "0", "0", "0"], ["84028", "0.06363385", "0", "1"], ["84027.9", "0.009425", "0", "1"], ["84027.8", "0.0648513", "0", "1"], ["84027.7", "0.00007596", "0", "1"], ["84024", "0.08", "0", "2"], ["84023.2", "0.066", "0", "3"], ["84022.4", "0.013", "0", "1"], ["83927.2", "0", "0", "0"], ["83926.3", "0.01728826", "0", "2"], ["83919.2", "0", "0", "0"]], "ts": "1742555207104", "checksum": 1549816411, "seqId": 49927513002, "prevSeqId": 49927512949}], "record_time": 1742555207.110865, "EXCHANGE": "OKX"}
{"arg": {"channel": "books", "instId": "BTC-USDT"}, "action": "update", "data": [{"asks": [["84081.3", "0", "0", "0"], ["84082.5", "0.23803568", "0", "1"], ["84143.7", "0.0713066", "0", "1"]], "bids": [["84025.3", "0.23803568", "0", "1"], ["84023.8", "0", "0", "0"], ["83978.8", "0.07144658", "0", "1"]], "ts": "1742555207304", "checksum": 1549816411, "seqId": 49927513024, "prevSeqId": 49927513002}], "record_time": 1742555207.349062, "EXCHANGE": "OKX"}
{"arg": {"channel": "books", "instId": "BTC-USDT"}, "action": "update", "data": [{"asks": [["84065.4", "0", "0", "0"], ["84070", "0.0146", "0", "1"], ["84072.4", "0.015661", "0", "3"], ["84143.7", "0.1426132", "0", "2"], ["84230.1", "0.000548", "0", "2"]], "bids": [["84046", "1", "0", "1"], ["83978.8", "0.14289316", "0", "2"]], "ts": "1742555207404", "checksum": -5109780, "seqId": 49927513036, "prevSeqId": 49927513024}], "record_time": 1742555207.406499, "EXCHANGE": "OKX"}
{"arg": {"channel": "books", "instId": "BTC-USDT"}, "action": "update", "data": [{"asks": [["84060.1", "0.9192417", "0", "12"]], "bids": [["84046.4", "0.000021", "0", "1"], ["84012", "0.21188822", "0", "2"], ["83920", "0", "0", "0"]], "ts": "1742555207504", "checksum": 990605230, "seqId": 49927513040, "prevSeqId": 49927513036}], "record_time": 1742555207.542196, "EXCHANGE": "OKX"}
{"arg": {"channel": "books", "instId": "BTC-USDT"}, "action": "update", "data": [{"asks": [["84081.3", "0.23803768", "0", "1"], ["84082.5", "0", "0", "0"], ["84115.7", "2.72656323", "0", "2"], ["84116.6", "0.00060645", "0", "1"], ["84199.9", "0.20046812", "0", "9"], ["84200.8", "0", "0", "0"], ["84230.7", "0.2025", "0", "1"]], "bids": [["84025.3", "0", "0", "0"], ["84023.8", "0.23803768", "0", "1"], ["84012", "0.01188822", "0", "1"], ["84011.3", "0.01188839", "0", "1"], ["84010.4", "0.01188821", "0", "1"], ["83921", "0", "0", "0"]], "ts": "1742555207604", "checksum": 990605230, "seqId": 49927513055, "prevSeqId": 49927513040}], "record_time": 1742555207.606522, "EXCHANGE": "OKX"}
{"arg": {"channel": "books", "instId": "BTC-USDT"}, "action": "update", "data": [{"asks": [["84072.4", "0.01", "0", "2"]], "bids": [["84060", "0.06929037", "0", "4"]], "ts": "1742555207704", "checksum": 2145929825, "seqId": 49927513068, "prevSeqId": 49927513055}], "record_time": 1742555207.709386, "EXCHANGE": "OKX"}
{"arg": {"channel": "books", "instId": "BTC-USDT"}, "action": "update", "data": [{"asks": [["84069.9", "0.00564", "0", "1"], ["84080.5", "0.23804115", "0", "1"], ["84081.3", "0", "0", "0"], ["84143.7", "0.0713066", "0", "1"], ["84230.7", "0", "0", "0"]], "bids": [["84047.3", "0.1844625", "0", "5"], ["84046.4", "0", "0", "0"], ["84023.8", "0", "0", "0"], ["84021.6", "0.23804115", "0", "1"], ["83978.8", "0.07144658", "0", "1"], ["83921", "0.00001002", "0", "1"]], "ts": "1742555207804", "checksum": -267393929, "seqId": 49927513090, "prevSeqId": 49927513068}], "record_time": 1742555207.871725, "EXCHANGE": "OKX"}
{"arg": {"channel": "books", "instId": "BTC-USDT"}, "action": "update", "data": [{"asks": [["84088.4", "0.21208928", "0", "1"], ["84143.7", "0.1426132", "0", "2"], ["84230.1", "0", "0", "0"]], "bids": [["84047.3", "0.18", "0", "4"], ["84007.4", "1.93748124", "0", "2"], ["83982.1", "0.00579984", "0", "1"], ["83978.8", "0.14289316", "0", "2"]], "ts": "1742555207904", "checksum": -267393929, "seqId": 49927513108, "prevSeqId": 49927513090}], "record_time": 1742555207.906195, "EXCHANGE": "OKX"}
{"arg": {"channel": "books", "instId": "BTC-USDT"}, "action": "update", "data": [{"asks": [], "bids": [["84045.8", "0.20674271", "0", "4"], ["84024", "0", "0", "0"], ["84023.2", "0.106", "0", "4"], ["84022.5", "0.23804006", "0", "1"], ["84022.4", "0.053", "0", "2"], ["84021.6", "0", "0", "0"], ["84021", "1.17823918", "0", "4"], ["84000.1", "0", "0", "0"], ["83982.1", "0.45868919", "0", "2"], ["83920", "0.00001096", "0", "1"], ["83919.2", "0.00003545", "0", "1"]], "ts": "1742555208004", "checksum": -267393929, "seqId": 49927513120, "prevSeqId": 49927513108}], "record_time": 1742555208.221532, "EXCHANGE": "OKX"}
{"arg": {"channel": "books", "instId": "BTC-USDT"}, "action": "update", "data": [{"asks": [["84072.1", "0.1086262", "0", "3"], ["84073", "0.03166084", "0", "2"], ["84073.1", "0.01910134", "0", "1"], ["84073.2", "0.03511709", "0", "1"], ["84073.3", "0.04241063", "0", "2"], ["84073.4", "0", "0", "0"], ["84079.3", "0.03186566", "0", "1"], ["84079.4", "0", "0", "0"], ["84080.5", "0.2380411", "0", "1"], ["84088.4", "0", "0", "0"], ["84088.7", "0.18649191", "0", "2"], ["84088.8", "0.06893205", "0", "1"], ["84088.9", "0", "0", "0"], ["84090.7", "0.06675527", "0", "1"], ["84090.8", "0.00357", "0", "1"], ["84101.6", "0.08", "0", "2"], ["84102.4", "0.28981999", "0", "2"], ["84103.2", "0", "0", "0"], ["84230.1", "0.000548", "0", "2"]], "bids": [["84060", "0.06480037", "0", "3"], ["84045.3", "0", "0", "0"], ["84045.2", "0.03461732", "0", "1"], ["84044.7", "0.03618589", "0", "1"], ["84044.6", "0.03520431", "0", "1"], ["84043.7", "0", "0", "0"], ["84043.6", "0.03951915", "0", "2"], ["84037.4", "0.76447649", "0", "2"], ["84037.3", "0.23469988", "0", "2"], ["84029.3", "0.00353141", "0", "1"], ["84029.2", "0.06493781", "0", "1"], ["84028", "0", "0", "0"], ["84027.9", "0.07310542", "0", "2"], ["84027.8", "0", "0", "0"], ["84027.7", "0.06967983", "0", "2"], ["84024", "0.08", "0", "2"], ["84023.2", "0.066", "0", "3"], ["84022.5", "0", "0", "0"], ["84022.4", "0.013", "0", "1"], ["84021.6", "0.2380412", "0", "1"], ["84021", "0.17823918", "0", "3"], ["83947.5", "0.0568", "0", "4"], ["83938.1", "0.00594813", "0", "1"], ["83937", "0", "0", "0"], ["83935.4", "0.18329104", "0", "1"], ["83930.7", "0.00001807", "0", "1"], ["83921.3", "0.01952969", "0", "5"], ["83919.2", "0", "0", "0"]], "ts": "1742555208104", "checksum": -506154723, "seqId": 49927513212, "prevSeqId": 49927513120}], "record_time": 1742555208.223102, "EXCHANGE": "OKX"}
{"arg": {"channel": "books", "instId": "BTC-USDT"}, "action": "update", "data": [{"asks": [["84060.1", "0.9057617", "0", "11"], ["84069.9", "0", "0", "0"], ["84072.1", "0.1067579", "0", "3"], ["84073", "0.000015", "0", "1"], ["84073.1", "0.05258409", "0", "2"], ["84073.2", "0", "0", "0"], ["84073.3", "0.04322406", "0", "2"], ["84073.4", "0.03381674", "0", "1"], ["84079.1", "0.03192809", "0", "1"], ["84079.3", "0", "0", "0"], ["84079.4", "0.03405388", "0", "1"], ["84080.5", "0", "0", "0"], ["84081.6", "0.2380365", "0", "1"], ["84082", "0.0146", "0", "1"], ["84082.1", "0.06931203", "0", "2"], ["84086.1", "0.06153327", "0", "1"], ["84088.7", "0.11890903", "0", "1"], ["84088.8", "0.06955357", "0", "1"], ["84088.9", "0.06888282", "0", "1"], ["84090.7", "0", "0", "0"], ["84090.8", "0.0685827", "0", "2"], ["84097.6", "0", "0", "0"], ["84112.4", "0.57159173", "0", "1"], ["84230.7", "0.2025", "0", "1"]], "bids": [["84059.1", "0.01190202", "0", "1"], ["84055.9", "0", "0", "0"], ["84045.3", "0.03263706", "0", "1"], ["84045.2", "0", "0", "0"], ["84044.8", "0.031329", "0", "1"], ["84044.7", "0.06735407", "0", "2"], ["84044.6", "0", "0", "0"], ["84043.7", "0.03448683", "0", "1"], ["84043.6", "0.00475943", "0", "1"], ["84037.8", "0.03405559", "0", "1"], ["84037.4", "0.79993689", "0", "3"], ["84037.3", "0.2025", "0", "1"], ["84036.6", "0.03220395", "0", "1"], ["84036.5", "0", "0", "0"], ["84035.9", "0.17559011", "0", "3"], ["84030.8", "0.06813718", "0", "1"], ["84029.3", "0.065461", "0", "2"], ["84029.2", "0", "0", "0"], ["84028", "0.06868357", "0", "1"], ["84027.9", "0.009425", "0", "1"], ["84027.8", "0.06387427", "0", "1"], ["84027.7", "0.00007596", "0", "1"], ["84025.3", "0.23803438", "0", "1"], ["84021.6", "0", "0", "0"], ["83920", "0", "0", "0"]], "ts": "1742555208204", "checksum": -393854378, "seqId": 49927513283, "prevSeqId": 49927513212}], "record_time": 1742555208.262403, "EXCHANGE": "OKX"}
{"arg": {"channel": "books", "instId": "BTC-USDT"}, "action": "update", "data": [{"asks": [["84060.1", "1.0083417", "0", "12"], ["84063.8", "0.03433915", "0", "2"], ["84067.5", "0.00349166", "0", "1"], ["84072.1", "0.1123394", "0", "4"], ["84082.1", "0.03500502", "0", "1"], ["84088.9", "0", "0", "0"]], "bids": [["84060", "0.06299477", "0", "3"], ["84036.6", "0", "0", "0"], ["84028", "0", "0", "0"], ["84025.3", "0", "0", "0"], ["84024.1", "0.23803722", "0", "1"], ["83920", "0.00001096", "0", "1"], ["83919.2", "0.00003545", "0", "1"]], "ts": "1742555208304", "checksum": -2068364799, "seqId": 49927513297, "prevSeqId": 49927513283}], "record_time": 1742555208.450109, "EXCHANGE": "OKX"}
{"arg": {"channel": "books", "instId": "BTC-USDT"}, "action": "update", "data": [{"asks": [["84072", "0.04544255", "0", "2"], ["84072.1", "0.05719347", "0", "2"], ["84073", "0.03375346", "0", "2"], ["84073.1", "0.01910134", "0", "1"], ["84073.2", "0.03254452", "0", "1"], ["84073.3", "0.04069605", "0", "2"], ["84073.4", "0", "0", "0"], ["84079", "0.03374143", "0", "1"], ["84079.1", "0", "0", "0"], ["84079.3", "0.03143511", "0", "1"], ["84079.4", "0", "0", "0"], ["84081.3", "0.23803873", "0", "1"], ["84081.6", "0", "0", "0"], ["84082", "0.04654391", "0", "2"], ["84082.1", "0", "0", "0"], ["84086", "0.06783878", "0", "1"], ["84086.1", "0", "0", "0"], ["84088.7", "0.25551896", "0", "3"], ["84088.8", "0", "0", "0"], ["84090.7", "0.06287708", "0", "1"], ["84090.8", "0.00357", "0", "1"], ["84230.9", "0.35582144", "0", "2"]], "bids": [["84059.1", "0", "0", "0"], ["84045.3", "0", "0", "0"], ["84045.2", "0.03368168", "0", "1"], ["84044.8", "0", "0", "0"], ["84044.7", "0.07044778", "0", "2"], ["84044.6", "0.03218344", "0", "1"], ["84043.7", "0", "0", "0"], ["84043.6", "0.03762715", "0", "2"], ["84037.8", "0", "0", "0"], ["84037.7", "0.03435355", "0", "1"], ["84037.4", "0.76447649", "0", "2"], ["84037.3", "0.23674814", "0", "2"], ["84035.9", "0.14044962", "0", "2"], ["84035.8", "0.38992966", "0", "2"], ["84030.8", "0", "0", "0"], ["84030.7", "0.067215", "0", "1"], ["84029.3", "0.00353141", "0", "1"], ["84029.2", "0.06510551", "0", "1"], ["84027.8", "0.07042476", "0", "1"], ["84027.7", "0.06349032", "0", "2"], ["84024.1", "0", "0", "0"], ["84023.3", "0.23815034", "0", "2"], ["83918.9", "0.00001197", "0", "1"], ["83918.3", "0.2025", "0", "1"]], "ts": "1742555208404", "checksum": 418046075, "seqId": 49927513356, "prevSeqId": 49927513297}], "record_time": 1742555208.454287, "EXCHANGE": "OKX"}
{"arg": {"channel": "books", "instId": "BTC-USDT"}, "action": "update", "data": [{"asks": [["84072.1", "0.07284213", "0", "2"], ["84081.2", "0.23803944", "0", "1"], ["84081.3", "0", "0", "0"], ["84081.9", "0.03471957", "0", "1"], ["84230.9", "0", "0", "0"]], "bids": [["84036.4", "0.0341995", "0", "1"], ["84023.3", "0.00011161", "0", "1"], ["84021.6", "0.23803944", "0", "1"], ["83918.9", "0", "0", "0"], ["83918.3", "0", "0", "0"]], "ts": "1742555208504", "checksum": 418046075, "seqId": 49927513377, "prevSeqId": 49927513356}], "record_time": 1742555208.504974, "EXCHANGE": "OKX"}
{"arg": {"channel": "books", "instId": "BTC-USDT"}, "action": "update", "data": [{"asks": [["84072", "0.05108255", "0", "3"], ["84081.2", "0", "0", "0"], ["84081.3", "0.23803831", "0", "1"], ["84081.9", "0", "0", "0"], ["84082", "0.07771846", "0", "3"], ["84101.6", "0", "0", "0"], ["84102.4", "0.32981999", "0", "3"], ["84103.2", "0.03999999", "0", "1"], ["84143.7", "0.0713066", "0", "1"], ["84230.9", "0.35582144", "0", "2"]], "bids": [["84060", "0.06520477", "0", "4"], ["84046.2", "0.72030717", "0", "3"], ["84046", "0", "0", "0"], ["84045.5", "1", "0", "1"], ["84036.5", "0.03383263", "0", "1"], ["84036.4", "0", "0", "0"], ["84024", "0", "0", "0"], ["84023.3", "0.23815066", "0", "2"], ["84023.2", "0.106", "0", "4"], ["84022.4", "0.053", "0", "2"], ["84021.6", "0", "0", "0"], ["84012", "0.21188822", "0", "2"], ["83978.8", "0.07144658", "0", "1"], ["83918.9", "0.00001197", "0", "1"], ["83918.3", "0.2025", "0", "1"]], "ts": "1742555208604", "checksum": 303839147, "seqId": 49927513409, "prevSeqId": 49927513377}], "record_time": 1742555208.605267, "EXCHANGE": "OKX"}
{"arg": {"channel": "books", "instId": "BTC-USDT"}, "action": "update", "data": [{"asks": [["84101.6", "0.08", "0", "2"], ["84102.4", "0.28981999", "0", "2"], ["84103.2", "0", "0", "0"]], "bids": [["84024", "0.08", "0", "2"], ["84023.2", "0.066", "0", "3"], ["84022.4", "0.013", "0", "1"], ["84012", "0.01188822", "0", "1"], ["83918.3", "0", "0", "0"]], "ts": "1742555208704", "checksum": 303839147, "seqId": 49927513452, "prevSeqId": 49927513409}], "record_time": 1742555208.706203, "EXCHANGE": "OKX"}
{"arg": {"channel": "books", "instId": "BTC-USDT"}, "action": "update", "data": [{"asks": [["84079.6", "0.23804149", "0", "1"], ["84081.3", "0", "0", "0"], ["84143.7", "0.1426132", "0", "2"]], "bids": [["84023.3", "0.00011161", "0", "1"], ["84021.6", "0.23804149", "0", "1"], ["83978.8", "0.14289316", "0", "2"], ["83918.9", "0", "0", "0"]], "ts": "1742555208804", "checksum": 303839147, "seqId": 49927513468, "prevSeqId": 49927513452}], "record_time": 1742555208.804141, "EXCHANGE": "OKX"}
{"arg": {"channel": "books", "instId": "BTC-USDT"}, "action": "update", "data": [{"asks": [["84079.6", "0", "0", "0"], ["84080.5", "0.23803967", "0", "1"], ["84101.6", "0", "0", "0"], ["84102.4", "0.32981999", "0", "3"], ["84103.2", "0.03999999", "0", "1"], ["84143.7", "0.0713066", "0", "1"]], "bids": [["84024", "0", "0", "0"], ["84023.2", "0.106", "0", "4"], ["84022.4", "0.053", "0", "2"], ["84021.6", "0.23803967", "0", "1"], ["83978.8", "0.07144658", "0", "1"], ["83918.9", "0.00001197", "0", "1"]], "ts": "1742555208904", "checksum": 303839147, "seqId": 49927513492, "prevSeqId": 49927513468}], "record_time": 1742555208.924758, "EXCHANGE": "OKX"}
{"arg": {"channel": "books", "instId": "BTC-USDT"}, "action": "update", "data": [{"asks": [["84072", "0.04544255", "0", "2"], ["84088.4", "0.21222334", "0", "1"], ["84230.9", "0", "0", "0"]], "bids": [["84000.1", "1.24028407", "0", "1"], ["83918.9", "0", "0", "0"]], "ts": "1742555209004", "checksum": -1867749519, "seqId": 49927513508, "prevSeqId": 49927513492}], "record_time": 1742555209.009221, "EXCHANGE": "OKX"}
{"arg": {"channel": "books", "instId": "BTC-USDT"}, "action": "update", "data": [{"asks": [["84071.7", "0.000399", "0", "1"], ["84112.8", "0.05992", "0", "1"], ["84117.3", "0", "0", "0"], ["84230.7", "0", "0", "0"]], "bids": [["84021", "1.17823918", "0", "4"]], "ts": "1742555209104", "checksum": -1481834376, "seqId": 49927513526, "prevSeqId": 49927513508}], "record_time": 1742555209.119159, "EXCHANGE": "OKX"}
{"arg": {"channel": "books", "instId": "BTC-USDT"}, "action": "update", "data": [{"asks": [["84070.1", "0.0007", "0", "1"], ["84143.7", "0.1426132", "0", "2"], ["84230.1", "0", "0", "0"]], "bids": [["83978.8", "0.14289316", "0", "2"]], "ts": "1742555209204", "checksum": 2047547856, "seqId": 49927513533, "prevSeqId": 49927513526}], "record_time": 1742555209.205916, "EXCHANGE": "OKX"}
{"arg": {"channel": "books", "instId": "BTC-USDT"}, "action": "update", "data": [{"asks": [["84182.7", "0.183246", "0", "1"], ["84184.9", "0", "0", "0"]], "bids": [], "ts": "1742555209304", "checksum": 2047547856, "seqId": 49927513536, "prevSeqId": 49927513533}], "record_time": 1742555209.305594, "EXCHANGE": "OKX"}
{"arg": {"channel": "books", "instId": "BTC-USDT"}, "action": "update", "data": [{"asks": [["84143.7", "0.0713066", "0", "1"]], "bids": [["83978.8", "0.07144658", "0", "1"]], "ts": "1742555209404", "checksum": 2047547856, "seqId": 49927513545, "prevSeqId": 49927513536}], "record_time": 1742555209.488223, "EXCHANGE": "OKX"}
{"arg": {"channel": "books", "instId": "BTC-USDT"}, "action": "update", "data": [{"asks": [["84081.9", "0.03227123", "0", "1"], ["84082", "0.04654391", "0", "2"], ["84143.7", "0.1426132", "0", "2"], ["84228.9", "0", "0", "0"]], "bids": [["84060", "0.06298474", "0", "3"], ["84036.5", "0", "0", "0"], ["84036.4", "0.03380586", "0", "1"], ["83978.8", "0.14289316", "0", "2"]], "ts": "1742555209604", "checksum": 1811512458, "seqId": 49927513569, "prevSeqId": 49927513545}], "record_time": 1742555209.649373, "EXCHANGE": "OKX"}
{"arg": {"channel": "books", "instId": "BTC-USDT"}, "action": "snapshot", "data": [{"asks": [["84071.4", "0.60546512", "0", "6"], ["84071.8", "0.002", "0", "1"], ["84071.9", "0.01766839", "0", "1"], ["84072", "0.0146", "0", "1"], ["84072.5", "0.005", "0", "1"], ["84073", "0.000015", "0", "1"], ["84074", "0.0234", "0", "1"], ["84075.2", "0.005", "0", "1"], ["84075.6", "0.01087964", "0", "2"], ["84076.1", "0.0471678", "0", "1"], ["84076.2", "0.0017", "0", "1"], ["84076.4", "0.01190006", "0", "1"], ["84076.5", "0.00193096", "0", "1"], ["84078.6", "0.11890903", "0", "1"], ["84079.8", "0.29200536", "0", "2"], ["84079.9", "0.03097", "0", "1"], ["84080.4", "0.04001197", "0", "2"], ["84080.9", "0.11899026", "0", "1"], ["84081.4", "0.02532435", "0", "2"], ["84081.8", "0.062", "0", "3"], ["84082.3", "0.00011161", "0", "1"], ["84082.4", "0.2060891", "0", "2"], ["84082.5", "0.005", "0", "1"], ["84083.3", "0.01520774", "0", "3"], ["84083.7", "0.11898634", "0", "1"], ["84083.9", "0.11235012", "0", "2"], ["84084.4", "0.59916699", "0", "2"], ["84084.6", "0.02380302", "0", "1"], ["84084.7", "0.03062642", "0", "1"], ["84084.8", "0.03906251", "0", "1"], ["84084.9", "0.016", "0", "1"], ["84085", "0.0358193", "0", "3"], ["84085.1", "0.03287288", "0", "1"], ["84085.2", "0.125", "0", "5"], ["84085.3", "0.03274909", "0", "1"], ["84085.4", "0.04001197", "0", "2"], ["84085.6", "0.14043766", "0", "1"], ["84085.8", "0.02843448", "0", "1"], ["84086.4", "0.01774536", "0", "1"], ["84086.5", "1", "0", "1"], ["84087.5", "0.05944451", "0", "1"], ["84087.6", "0.0054", "0", "1"], ["84087.7", "0.17821722", "0", "1"], ["84087.8", "0.30615925", "0", "2"], ["84088.9", "1.05170735", "0", "2"], ["84089.1", "0.17842", "0", "1"], ["84089.8", "0.000015", "0", "1"], ["84089.9", "0.133456", "0", "1"], ["84090.2", "0.35641581", "0", "1"], ["84090.4", "0.00001197", "0", "1"], ["84090.9", "0.2025", "0", "1"], ["84091.2", "1.57066965", "0", "1"], ["84091.3", "0.25402691", "0", "2"], ["84091.5", "0.14043766", "0", "1"], ["84091.6", "0.03394737", "0", "1"], ["84091.7", "0.03170118", "0", "1"], ["84092.5", "0.01", "0", "1"], ["84092.7", "0.08297", "0", "1"], ["84093.7", "0.03371343", "0", "1"], ["84093.8", "0.05460239", "0", "2"], ["84094.4", "0.11235012", "0", "2"], ["84095.2", "0.46009", "0", "1"], ["84095.3", "0.00001197", "0", "1"], ["84096.3", "0.17821722", "0", "1"], ["84096.6", "0.00001533", "0", "1"], ["84096.8", "0.00357", "0", "1"], ["84097.2", "0.11890903", "0", "1"], ["84097.9", "0.00001501", "0", "1"], ["84098.2", "0.000015", "0", "1"], ["84098.3", "0.00161601", "0", "1"], ["84098.7", "0.06676283", "0", "1"], ["84098.8", "0.35641581", "0", "1"], ["84099.4", "0.2079", "0", "2"], ["84099.5", "0.56492759", "0", "2"], ["84099.9", "0.00101534", "0", "2"], ["84100", "0.0066649", "0", "3"], ["84100.3", "0.00001197", "0", "1"], ["84100.4", "0.23800049", "0", "1"], ["84100.5", "0.06794164", "0", "1"], ["84101.1", "0.06534156", "0", "1"], ["84101.9", "0.00011161", "0", "1"], ["84102", "0.052", "0", "2"], ["84102.1", "0.04284161", "0", "1"], ["84102.5", "0.0671434", "0", "1"], ["84103", "0.016", "0", "1"], ["84103.6", "0.40120182", "0", "1"], ["84103.7", "0.471219", "0", "1"], ["84104.7", "0.25755", "0", "1"], ["84104.8", "0.17821722", "0", "1"], ["84104.9", "0.11235012", "0", "2"], ["84105", "0.00001", "0", "1"], ["84105.2", "0.00001197", "0", "1"], ["84105.4", "0.01784403", "0", "1"], ["84105.6", "0.07999999", "0", "2"], ["84106.4", "0.03999999", "0", "1"], ["84106.6", "0.00001501", "0", "1"], ["84106.9", "0.11846252", "0", "1"], ["84107.2", "0.00420428", "0", "1"], ["84107.4", "0.35641581", "0", "1"], ["84107.5", "0.016", "0", "1"], ["84107.7", "0.01190002", "0", "1"], ["84107.9", "0.2025", "0", "1"], ["84108.2", "0.12491", "0", "1"], ["84109", "0.001784", "0", "1"], ["84109.1", "0.061247", "0", "1"], ["84109.4", "0.38705683", "0", "2"], ["84109.5", "0.54039", "0", "1"], ["84110.2", "0.00001197", "0", "1"], ["84111.2", "0.10591011", "0", "2"], ["84112", "0.11890903", "0", "1"], ["84112.3", "0.24981", "0", "1"], ["84113.4", "0.018", "0", "1"], ["84113.5", "0.27973717", "0", "2"], ["84113.6", "0.17821722", "0", "1"], ["84115", "0.02380338", "0", "2"], ["84115.2", "0.00001197", "0", "1"], ["84115.4", "0.11235012", "0", "2"], ["84115.9", "0.1", "0", "1"], ["84116.4", "0.55891581", "0", "2"], ["84116.6", "0.00060645", "0", "1"], ["84116.8", "0.00420428", "0", "1"], ["84117.6", "0.87447758", "0", "2"], ["84117.7", "0.01", "0", "1"], ["84119.2", "0.03", "0", "1"], ["84120", "0.00004", "0", "1"], ["84120.1", "0.00001197", "0", "1"], ["84120.4", "0.00420342", "0", "1"], ["84120.6", "2.86086963", "0", "1"], ["84120.9", "0.01188766", "0", "1"], ["84121", "0.01188764", "0", "1"], ["84121.4", "0.01188759", "0", "1"], ["84121.5", "0.00011161", "0", "1"], ["84121.6", "0.02377512", "0", "2"], ["84122.5", "0.06", "0", "2"], ["84122.6", "0.25789171", "0", "1"], ["84122.7", "0.17821722", "0", "1"], ["84122.8", "0.11890903", "0", "1"], ["84123.4", "0.000015", "0", "1"], ["84123.9", "0.00357", "0", "1"], ["84124.9", "0.20254312", "0", "2"], ["84125", "0.35641581", "0", "1"], ["84125.1", "0.00001197", "0", "1"], ["84130.1", "0.00001197", "0", "1"], ["84130.3", "0.00713179", "0", "1"], ["84131", "0.37959093", "0", "1"], ["84131.4", "0.17821722", "0", "1"], ["84131.8", "0.917326", "0", "2"], ["84132.4", "0.11890903", "0", "1"], ["84133.3", "0.00504382", "0", "4"], ["84133.4", "0.2025", "0", "1"], ["84133.9", "0.01130888", "0", "1"], ["84134", "0.40420221", "0", "2"], ["84134.3", "0.35641581", "0", "1"], ["84134.5", "0.21009693", "0", "2"], ["84134.6", "0.08991011", "0", "1"], ["84135", "0.00001197", "0", "1"], ["84135.1", "0.01188767", "0", "1"], ["84135.4", "0.16488944", "0", "1"], ["84138.1", "0.00594812", "0", "1"], ["84138.2", "0.00594631", "0", "1"], ["84138.3", "0.47216", "0", "1"], ["84138.6", "1.06358526", "0", "2"], ["84140", "0.00037388", "0", "3"], ["84140.2", "0.14263415", "0", "3"], ["84140.3", "0.05484", "0", "1"], ["84140.5", "0.0599", "0", "1"], ["84140.9", "0.08752", "0", "1"], ["84141.2", "0.00011161", "0", "1"], ["84141.3", "0.01188764", "0", "1"], ["84141.7", "3.14434136", "0", "2"], ["84141.9", "0.2025", "0", "1"], ["84142.7", "0.17821722", "0", "1"], ["84142.8", "0.15903203", "0", "1"], ["84144.6", "0.01148", "0", "1"], ["84145", "0.00001197", "0", "1"], ["84145.8", "0.03", "0", "1"], ["84146.6", "0.35641581", "0", "1"], ["84146.7", "0.11890903", "0", "1"], ["84146.9", "0.03", "0", "1"], ["84147", "0.12011478", "0", "3"], ["84147.5", "0.02379271", "0", "1"], ["84148.4", "0.0019221", "0", "1"], ["84148.5", "0.05944734", "0", "1"], ["84148.6", "0.00001501", "0", "1"], ["84148.8", "0.02379128", "0", "1"], ["84149.9", "0.00061841", "0", "2"], ["84150.2", "0.00420106", "0", "1"], ["84150.4", "0.2025", "0", "1"], ["84151.3", "0.00594754", "0", "1"], ["84152.5", "0.00012217", "0", "1"], ["84152.6", "0.19832148", "0", "1"], ["84152.7", "0.17821722", "0", "1"], ["84153.3", "0.0054", "0", "1"], ["84154.9", "0.00001196", "0", "1"], ["84155.1", "0.08991011", "0", "1"], ["84155.3", "0.35641581", "0", "1"], ["84155.8", "0.56105893", "0", "2"], ["84155.9", "0.11890903", "0", "1"], ["84156.3", "0.00420026", "0", "1"], ["84157", "0.00001501", "0", "1"], ["84157.6", "1.475545", "0", "2"], ["84157.9", "0.1", "0", "1"], ["84158.5", "0.01425881", "0", "1"], ["84158.6", "0.00580051", "0", "1"], ["84158.7", "0.00594727", "0", "1"], ["84158.9", "0.2025", "0", "1"], ["84159.2", "0.1", "0", "1"], ["84159.5", "0.0001965", "0", "1"], ["84159.6", "0.10841323", "0", "1"], ["84159.8", "0.00001196", "0", "1"], ["84160.4", "0.0011882", "0", "1"], ["84160.8", "0.00011161", "0", "1"], ["84162.5", "0.089826", "0", "1"], ["84162.8", "0.17821722", "0", "1"], ["84163.6", "0.09727321", "0", "5"], ["84164.2", "0.21028006", "0", "1"], ["84164.3", "0.35641581", "0", "1"], ["84164.5", "0.02071925", "0", "2"], ["84164.8", "0.00001196", "0", "1"], ["84164.9", "0.12470954", "0", "2"], ["84165.4", "0.000015", "0", "1"], ["84166.3", "0.0356801", "0", "1"], ["84166.5", "0.08349046", "0", "1"], ["84166.6", "0.00104525", "0", "3"], ["84167.4", "0.2025", "0", "1"], ["84168.1", "1.38863302", "0", "2"], ["84168.7", "0.00580041", "0", "1"], ["84168.8", "0.00579972", "0", "1"], ["84169.2", "0.001965", "0", "1"], ["84169.8", "0.00001196", "0", "1"], ["84170", "3.7106", "0", "2"], ["84170.2", "0.2271431", "0", "1"], ["84171.6", "0.17821722", "0", "1"], ["84171.9", "0.00580051", "0", "1"], ["84172", "0.64996", "0", "1"], ["84173.1", "0.47529737", "0", "3"], ["84173.2", "0.35641581", "0", "1"], ["84173.4", "0.71313968", "0", "1"], ["84173.6", "0.11890903", "0", "1"], ["84173.8", "0.000015", "0", "1"], ["84174.7", "0.00001196", "0", "1"], ["84175.1", "0.00579972", "0", "1"], ["84175.7", "0.00580041", "0", "1"], ["84175.8", "0.00419826", "0", "1"], ["84175.9", "0.2025", "0", "1"], ["84177.6", "0.13960232", "0", "1"], ["84178.9", "0.00580051", "0", "1"], ["84179.1", "0.05700028", "0", "1"], ["84179.7", "0.00001196", "0", "1"], ["84179.8", "0.11885048", "0", "1"], ["84180.4", "0.00011161", "0", "1"], ["84180.5", "0.17821722", "0", "1"], ["84181.1", "0.26333467", "0", "1"], ["84181.8", "0.00003887", "0", "1"], ["84181.9", "0.00579972", "0", "1"], ["84182.1", "0.000015", "0", "1"], ["84182.2", "0.11892404", "0", "2"], ["84182.6", "0.35641581", "0", "1"], ["84182.8", "0.00597332", "0", "1"], ["84182.9", "0.00023777", "0", "1"], ["84183.3", "0.00060645", "0", "1"], ["84184.2", "0.00419766", "0", "1"], ["84184.4", "0.2025", "0", "1"], ["84184.7", "0.00001196", "0", "1"], ["84185.1", "0.10275197", "0", "1"], ["84185.4", "0.09571062", "0", "2"], ["84186.6", "0.03", "0", "1"], ["84186.7", "0.183251", "0", "1"], ["84188.6", "0.00579972", "0", "1"], ["84188.9", "0.05252859", "0", "2"], ["84189.6", "0.03001196", "0", "2"], ["84190", "0.00001057", "0", "1"], ["84190.5", "0.07125036", "0", "1"], ["84190.6", "0.00001501", "0", "1"], ["84190.9", "0.27607157", "0", "1"], ["84191", "0.17821722", "0", "1"], ["84191.1", "0.35641581", "0", "1"], ["84191.3", "0.11890903", "0", "1"], ["84191.5", "0.07998313", "0", "2"], ["84191.8", "0.21861", "0", "1"], ["84192.6", "0.0041965", "0", "1"], ["84192.9", "0.2025", "0", "1"], ["84194.4", "0.00039355", "0", "1"], ["84194.6", "0.02876826", "0", "2"], ["84194.7", "0.08991011", "0", "1"], ["84199", "0.00251501", "0", "2"], ["84199.6", "0.00001196", "0", "1"], ["84199.7", "0.35641581", "0", "1"], ["84199.8", "0.11890903", "0", "1"], ["84199.9", "0.20052638", "0", "9"], ["84200", "6.19730597", "0", "36"], ["84200.1", "0.00011161", "0", "1"], ["84200.4", "0.01483565", "0", "2"], ["84200.6", "0.08749", "0", "1"], ["84201", "0.03", "0", "1"], ["84201.4", "0.2025", "0", "1"], ["84202", "0.00005073", "0", "1"], ["84202.5", "0.03", "0", "1"], ["84202.8", "0.00002241", "0", "1"], ["84203", "0.00001198", "0", "1"], ["84203.7", "0.01188786", "0", "1"], ["84204.5", "0.00031886", "0", "2"], ["84204.6", "0.00594775", "0", "1"], ["84205", "0.00181735", "0", "1"], ["84205.9", "0.06", "0", "2"], ["84206.1", "0.67965387", "0", "2"], ["84207.4", "0.000015", "0", "1"], ["84207.5", "0.214069", "0", "1"], ["84207.7", "1.90391514", "0", "2"], ["84208.3", "0.01493332", "0", "1"], ["84208.5", "0.00040805", "0", "13"], ["84208.7", "0.00001096", "0", "1"], ["84209.3", "0.00011444", "0", "1"], ["84209.5", "0.00001197", "0", "1"], ["84210.5", "0.05365541", "0", "3"], ["84210.6", "0.21299237", "0", "1"], ["84211.1", "0.00002037", "0", "1"], ["84211.7", "0.00003107", "0", "2"], ["84212", "0.0000594", "0", "1"], ["84212.1", "0.00001023", "0", "1"], ["84212.5", "0.00001995", "0", "1"], ["84212.6", "0.01511839", "0", "1"], ["84213.1", "0.18059522", "0", "2"], ["84213.5", "0.35641581", "0", "1"], ["84214.2", "0.00001575", "0", "1"], ["84214.5", "0.00001197", "0", "1"], ["84214.8", "0.00032751", "0", "1"], ["84215.3", "0.06946337", "0", "1"], ["84215.4", "0.84032896", "0", "3"], ["84215.8", "0.00001501", "0", "1"], ["84216", "0.00001565", "0", "1"], ["84216.6", "0.00060645", "0", "1"], ["84216.9", "0.08991011", "0", "1"], ["84217.9", "0.00419368", "0", "1"], ["84218", "0.00016867", "0", "1"], ["84218.1", "0.00001045", "0", "1"], ["84219.3", "0.00007814", "0", "1"], ["84219.4", "0.00001503", "0", "1"], ["84219.7", "0.00011161", "0", "1"], ["84220.9", "0.01299784", "0", "1"], ["84221.3", "0.00037549", "0", "1"], ["84221.4", "0.01784325", "0", "3"], ["84222.3", "0.35641581", "0", "1"], ["84222.7", "0.10708", "0", "1"], ["84223.7", "0.0004", "0", "1"], ["84223.8", "0.17846554", "0", "2"], ["84224", "0.00118464", "0", "1"], ["84224.2", "0.00003002", "0", "2"], ["84224.4", "0.00001197", "0", "1"], ["84225", "0.00017601", "0", "1"], ["84225.2", "0.00593955", "0", "1"], ["84225.9", "0.00419367", "0", "1"], ["84226.5", "0.00002974", "0", "1"], ["84226.6", "0.00001653", "0", "1"], ["84228.4", "0.00010514", "0", "1"], ["84228.5", "0.00002372", "0", "1"], ["84228.9", "0.00008", "0", "1"], ["84230.1", "0.000548", "0", "2"], ["84230.9", "0.35582144", "0", "2"], ["84232", "0.00036", "0", "1"], ["84232.3", "0.31120048", "0", "3"], ["84232.9", "0.08747", "0", "1"], ["84233", "0.07468728", "0", "4"], ["84233.3", "0.01521534", "0", "3"], ["84233.5", "0.01422296", "0", "2"], ["84233.7", "0.0142", "0", "1"], ["84233.8", "0.00003542", "0", "1"], ["84233.9", "0.00419323", "0", "1"], ["84234", "0.0142", "0", "1"], ["84234.2", "0.0142", "0", "1"], ["84234.4", "0.00001197", "0", "1"], ["84235.2", "0.00002902", "0", "1"], ["84235.6", "0.03", "0", "1"], ["84236.6", "0.00593", "0", "1"], ["84236.8", "0.00001738", "0", "1"], ["84236.9", "0.03", "0", "1"], ["84237.2", "0.00001115", "0", "1"], ["84237.8", "0.00007018", "0", "2"], ["84238.1", "0.00006534", "0", "2"], ["84238.6", "0.03", "0", "1"], ["84239.3", "0.00011161", "0", "1"], ["84239.7", "0.01652", "0", "1"], ["84239.8", "0.35579296", "0", "1"], ["84240", "0.00003685", "0", "2"], ["84240.1", "0.00001005", "0", "1"], ["84241.1", "0.14244836", "0", "2"], ["84242", "0.0000185", "0", "1"], ["84242.4", "0.00469113", "0", "3"], ["84242.5", "0.00011938", "0", "1"], ["84242.6", "0.00419183", "0", "1"], ["84244.1", "0.00083", "0", "1"], ["84244.3", "0.00605088", "0", "2"], ["84244.6", "0.5999", "0", "1"], ["84245.2", "0.00003034", "0", "1"], ["84245.5", "0.00009384", "0", "1"], ["84245.8", "0.00040029", "0", "4"], ["84246.3", "0.00083", "0", "1"], ["84246.5", "0.00120691", "0", "2"], ["84247.2", "0.00153761", "0", "2"], ["84247.3", "0.08991011", "0", "1"]], "bids": [["84071.3", "0.43481004", "0", "8"], ["84070.1", "0.09407761", "0", "2"], ["84070", "0.0234", "0", "1"], ["84068", "0.0234", "0", "1"], ["84067.8", "0.2", "0", "1"], ["84067.7", "0.02788553", "0", "1"], ["84067", "0.2371486", "0", "2"], ["84066.9", "0.2025", "0", "1"], ["84066.7", "0.35641581", "0", "1"], ["84066.3", "0.02530935", "0", "1"], ["84066", "0.0234", "0", "1"], ["84065.9", "0.052", "0", "2"], ["84063.6", "0.10629359", "0", "4"], ["84062.5", "0.02214679", "0", "1"], ["84062", "0.03945328", "0", "3"], ["84060.7", "0.00001197", "0", "1"], ["84060.2", "0.0168865", "0", "3"], ["84060", "0.01461", "0", "2"], ["84059.8", "0.002", "0", "1"], ["84059.5", "0.00773238", "0", "1"], ["84059.3", "0.000015", "0", "1"], ["84058.6", "0.00773208", "0", "1"], ["84058.2", "0.47532114", "0", "1"], ["84058", "1.0146", "0", "2"], ["84057.4", "0.21192759", "0", "2"], ["84057.1", "0.0137", "0", "1"], ["84057", "0.03220471", "0", "1"], ["84056.8", "0.2025", "0", "1"], ["84056.4", "0.03449453", "0", "1"], ["84056", "0.0146", "0", "1"], ["84055.9", "0.03184273", "0", "1"], ["84055.7", "0.00001197", "0", "1"], ["84054.9", "0.04", "0", "1"], ["84054.6", "0.31980033", "0", "1"], ["84054.5", "0.016", "0", "1"], ["84054", "0.0146", "0", "1"], ["84053.9", "0.016", "0", "1"], ["84053.8", "0.17842", "0", "1"], ["84053.7", "0.04", "0", "1"], ["84053.5", "0.35684", "0", "1"], ["84052.8", "0.35641581", "0", "1"], ["84052.6", "0.13345", "0", "1"], ["84052.5", "0.05617506", "0", "1"], ["84052.3", "0.00420806", "0", "1"], ["84052", "0.0146", "0", "1"], ["84051.2", "0.00006777", "0", "1"], ["84050.9", "0.000015", "0", "1"], ["84050.8", "0.00001198", "0", "1"], ["84050.7", "0.16014293", "0", "2"], ["84050.4", "0.03265881", "0", "1"], ["84050.2", "0.005", "0", "1"], ["84050.1", "0.005", "0", "1"], ["84050", "0.01493629", "0", "4"], ["84049.9", "0.01251027", "0", "2"], ["84049.8", "0.1237", "0", "4"], ["84049.6", "0.03090738", "0", "1"], ["84049.4", "0.21161483", "0", "1"], ["84049.3", "0.24979", "0", "1"], ["84048.7", "0.17827722", "0", "2"], ["84048.6", "0.00475915", "0", "1"], ["84048.3", "0.2025", "0", "1"], ["84048.2", "0.03425567", "0", "1"], ["84047.6", "0.03461359", "0", "1"], ["84046.6", "0.00009543", "0", "1"], ["84046.5", "0.08991011", "0", "1"], ["84046.4", "0.18", "0", "4"], ["84046.1", "0.2567382", "0", "1"], ["84045.9", "0.17842", "0", "1"], ["84045.8", "0.00001198", "0", "1"], ["84045.1", "0.12496207", "0", "2"], ["84044.5", "0.11904157", "0", "1"], ["84044.3", "0.35579296", "0", "1"], ["84044.2", "0.00350877", "0", "1"], ["84043.4", "0.06410332", "0", "1"], ["84043.1", "0.0042087", "0", "1"], ["84043", "0.00011161", "0", "1"], ["84042.5", "0.00001501", "0", "1"], ["84042.4", "0.00001196", "0", "1"], ["84042.2", "0.23800163", "0", "1"], ["84042", "0.11235012", "0", "2"], ["84041.9", "0.71353939", "0", "2"], ["84041.8", "0.05902086", "0", "1"], ["84041.1", "0.18725022", "0", "1"], ["84041", "0.06721641", "0", "1"], ["84040.2", "0.06731187", "0", "1"], ["84040", "0.00001", "0", "1"], ["84039.8", "0.38071722", "0", "2"], ["84039.5", "0.06691842", "0", "1"], ["84039", "1.6159405", "0", "1"], ["84037.5", "0.02745264", "0", "1"], ["84036.2", "0.52842", "0", "1"], ["84035.9", "0.00001196", "0", "1"], ["84035.8", "0.35579296", "0", "1"], ["84035.3", "0.14043766", "0", "1"], ["84034.5", "0.02817312", "0", "1"], ["84034.1", "0.00001501", "0", "1"], ["84033.8", "0.00420994", "0", "1"], ["84033.5", "0.01", "0", "1"], ["84033.3", "0.12592534", "0", "3"], ["84032", "0.00357", "0", "1"], ["84031.6", "0.01774536", "0", "1"], ["84031.5", "0.11338803", "0", "3"], ["84031.4", "0.00012658", "0", "1"], ["84031.3", "0.20606993", "0", "2"], ["84031.1", "0.01785", "0", "1"], ["84031", "0.059978", "0", "1"], ["84030.9", "0.00001196", "0", "1"], ["84030.8", "0.08991011", "0", "1"], ["84030.6", "0.48051", "0", "1"], ["84030", "0.00001196", "0", "1"], ["84029.5", "0.17821722", "0", "1"], ["84029.1", "0.05444", "0", "1"], ["84029", "0.0103941", "0", "1"], ["84028.4", "0.00100367", "0", "1"], ["84028.3", "0.24982", "0", "1"], ["84027.9", "0.40926913", "0", "2"], ["84027.8", "0.27920304", "0", "1"], ["84027.7", "0.00007596", "0", "1"], ["84027.5", "0.00099943", "0", "1"], ["84027.3", "0.35579296", "0", "1"], ["84026.9", "0.05944451", "0", "1"], ["84026.6", "0.00017505", "0", "1"], ["84026.3", "0.57885102", "0", "1"], ["84026.2", "0.02381352", "0", "1"], ["84026.1", "0.00421091", "0", "1"], ["84025.7", "0.000015", "0", "1"], ["84025.6", "0.08", "0", "2"], ["84025.1", "0.11890903", "0", "1"], ["84025", "0.00001719", "0", "1"], ["84024.8", "0.04", "0", "1"], ["84024.7", "0.0000313", "0", "1"], ["84024.2", "0.29277776", "0", "2"], ["84024.1", "0.12491", "0", "1"], ["84023.7", "0.02412024", "0", "2"], ["84023.3", "0.00011161", "0", "1"], ["84023.2", "0.026", "0", "2"], ["84022.8", "0.2025", "0", "1"], ["84022.6", "0.00002208", "0", "1"], ["84022.4", "0.013", "0", "1"], ["84022.3", "0.918505", "0", "1"], ["84022.2", "0.35308766", "0", "3"], ["84022", "0.00001", "0", "1"], ["84021.6", "0.1", "0", "2"], ["84021.5", "0.1", "0", "1"], ["84021", "0.17822918", "0", "2"], ["84020.9", "0.11235012", "0", "2"], ["84020.8", "0.05", "0", "1"], ["84020", "0.00001", "0", "1"], ["84019.5", "0.00080024", "0", "1"], ["84018.8", "0.25837394", "0", "1"], ["84018.7", "0.35579296", "0", "1"], ["84018.5", "0.471215", "0", "1"], ["84017.7", "0.00001196", "0", "1"], ["84017.3", "0.00001501", "0", "1"], ["84017", "0.01832613", "0", "1"], ["84016.9", "0.00421155", "0", "1"], ["84016.7", "0.0214248", "0", "1"], ["84016.6", "0.00060645", "0", "1"], ["84016.4", "0.03", "0", "1"], ["84014.3", "0.2125", "0", "2"], ["84013.7", "0.006471", "0", "2"], ["84013.4", "0.01188786", "0", "1"], ["84012.7", "0.11890903", "0", "1"], ["84012.3", "2.08958745", "0", "3"], ["84012.2", "0.17821722", "0", "1"], ["84011.1", "0.00001196", "0", "1"], ["84010.7", "0.00005963", "0", "1"], ["84010.4", "0.11235012", "0", "2"], ["84010.2", "3.30950296", "0", "2"], ["84010", "0.00014389", "0", "1"], ["84009.6", "2.86331148", "0", "1"], ["84009.3", "0.59964265", "0", "1"], ["84008.9", "0.00286806", "0", "2"], ["84008.8", "0.00421282", "0", "1"], ["84008.4", "0.00001501", "0", "1"], ["84008.3", "0.00001365", "0", "1"], ["84006.2", "0.00001196", "0", "1"], ["84005.8", "0.20607", "0", "2"], ["84005.7", "0.01", "0", "1"], ["84005.4", "0.0238194", "0", "1"], ["84005.3", "0.00001196", "0", "1"], ["84005.1", "0.00105321", "0", "1"], ["84005", "0.00235619", "0", "1"], ["84003.7", "0.26823894", "0", "3"], ["84002.8", "0.4", "0", "1"], ["84001.6", "0.01786609", "0", "1"], ["84001.5", "0.35579296", "0", "1"], ["84001.1", "0.00008", "0", "1"], ["84000.5", "0.00001501", "0", "1"], ["84000.4", "0.00421334", "0", "1"], ["84000.2", "0.03", "0", "1"], ["84000.1", "2.70955733", "0", "2"], ["84000", "20.47588537", "0", "34"], ["83999.9", "0.00517179", "0", "8"], ["83998.6", "3.44638", "0", "1"], ["83997.3", "0.2025", "0", "1"], ["83996.4", "0.03", "0", "1"], ["83996.3", "0.01903314", "0", "2"], ["83995.9", "0.0071432", "0", "1"], ["83995.6", "0.00595", "0", "1"], ["83994.3", "0.17821722", "0", "1"], ["83993.9", "0.00421443", "0", "1"], ["83992.5", "1.42905296", "0", "3"], ["83992.4", "0.49202759", "0", "3"], ["83992.1", "0.00001501", "0", "1"], ["83991.5", "0.11878326", "0", "1"], ["83991.3", "0.00001196", "0", "1"], ["83991.1", "0.0166188", "0", "1"], ["83991", "0.05955872", "0", "1"], ["83990.3", "0.00009235", "0", "1"], ["83990.2", "0.0054", "0", "1"], ["83988.8", "0.2025", "0", "1"], ["83988.3", "0.0000469", "0", "1"], ["83988", "0.00005334", "0", "1"], ["83987.8", "0.00007308", "0", "1"], ["83987.7", "0.00023813", "0", "1"], ["83987.4", "0.04757931", "0", "1"], ["83986.7", "0.01652", "0", "1"], ["83986.6", "0.11912367", "0", "1"], ["83986.3", "0.00001197", "0", "1"], ["83986.1", "0.2094027", "0", "1"], ["83985.8", "0.0796718", "0", "2"], ["83985.7", "0.00001677", "0", "1"], ["83985.6", "0.03", "0", "1"], ["83985.1", "0.00594785", "0", "1"], ["83985", "0.0988158", "0", "2"], ["83984.9", "1.378372", "0", "1"], ["83984.3", "0.03", "0", "1"], ["83984.1", "0.02390126", "0", "2"], ["83983.7", "0.00001501", "0", "1"], ["83983.6", "0.17821722", "0", "1"], ["83983.5", "0.35579296", "0", "1"], ["83983.4", "0.00004752", "0", "1"], ["83983.3", "0.00482138", "0", "2"], ["83982", "0.00016245", "0", "1"], ["83981.9", "0.0000492", "0", "1"], ["83981.5", "0.00005685", "0", "1"], ["83981.4", "0.00001197", "0", "1"], ["83981", "0.03", "0", "1"], ["83980.6", "0.00001197", "0", "1"], ["83980.4", "0.09815424", "0", "1"], ["83980.3", "0.2025", "0", "1"], ["83980", "0.00005457", "0", "1"], ["83979.8", "0.00579952", "0", "1"], ["83979.7", "0.11878326", "0", "1"], ["83979.5", "0.00004344", "0", "1"], ["83978.7", "0.01148933", "0", "1"], ["83978.2", "0.00421569", "0", "1"], ["83977.9", "0.03", "0", "1"], ["83977.2", "0.00005459", "0", "1"], ["83975.7", "0.01174817", "0", "2"], ["83975.5", "0.00005458", "0", "1"], ["83975.3", "0.14291412", "0", "3"], ["83975.1", "0.17821722", "0", "1"], ["83975", "0.35581966", "0", "2"], ["83974.8", "0.1", "0", "1"], ["83974.6", "0.00003456", "0", "1"], ["83974.3", "0.00003395", "0", "1"], ["83972.8", "0.00594865", "0", "1"], ["83971.8", "0.2025", "0", "1"], ["83971.5", "0.00001197", "0", "1"], ["83971.4", "0.00068806", "0", "1"], ["83971.1", "0.08991011", "0", "1"], ["83971", "0.00594865", "0", "1"], ["83970.9", "0.00002851", "0", "1"], ["83970.7", "0.11878326", "0", "1"], ["83969.9", "0.014", "0", "1"], ["83969.8", "0.00007199", "0", "1"], ["83969.7", "0.21703", "0", "1"], ["83969.3", "0.00579952", "0", "1"], ["83969", "0.00005519", "0", "1"], ["83968.3", "0.00001197", "0", "1"], ["83967.8", "0.39800926", "0", "1"], ["83967.7", "0.10004003", "0", "2"], ["83967.4", "0.00013882", "0", "1"], ["83967.3", "0.59432247", "0", "1"], ["83967.2", "0.00001508", "0", "1"], ["83967", "0.08933", "0", "1"], ["83966.9", "0.000015", "0", "1"], ["83966.8", "0.0042171", "0", "1"], ["83966.7", "0.17821722", "0", "1"], ["83966.6", "0.3604018", "0", "4"], ["83966.3", "0.00001501", "0", "1"], ["83964.4", "0.00011161", "0", "1"], ["83963.7", "0.006", "0", "1"], ["83963.3", "0.2025", "0", "1"], ["83962.9", "0.00930276", "0", "2"], ["83962.3", "0.11878326", "0", "1"], ["83961.6", "0.00001197", "0", "1"], ["83961", "0.00298666", "0", "1"], ["83960.4", "0.02979085", "0", "2"], ["83960", "0.00612357", "0", "3"], ["83959.9", "0.00600998", "0", "2"], ["83959.8", "0.00421771", "0", "1"], ["83959.7", "0.00072", "0", "1"], ["83959.6", "0.03573218", "0", "1"], ["83959.1", "0.00001009", "0", "1"], ["83959", "0.00682987", "0", "2"], ["83958.9", "1.48377", "0", "1"], ["83958.8", "0.00005335", "0", "1"], ["83958.3", "0.00006061", "0", "1"], ["83957.6", "0.006", "0", "1"], ["83957.5", "0.00609975", "0", "1"], ["83957.4", "0.00651964", "0", "2"], ["83957.2", "0.01219978", "0", "2"], ["83957.1", "0.00609984", "0", "1"], ["83956.9", "0.00268856", "0", "1"], ["83956.8", "0.00579952", "0", "1"], ["83956.6", "0.00001197", "0", "1"], ["83955.9", "0.00001197", "0", "1"], ["83955.3", "0.00579976", "0", "1"], ["83954.8", "0.2025", "0", "1"], ["83954.6", "0.00083", "0", "1"], ["83954.5", "0.17821722", "0", "1"], ["83954.4", "0.36159313", "0", "2"], ["83954.1", "0.01189968", "0", "2"], ["83954", "0.02319942", "0", "4"], ["83953.6", "0.00579986", "0", "1"], ["83953.4", "0.00358947", "0", "1"], ["83953", "0.00609975", "0", "1"], ["83952.9", "0.08991011", "0", "1"], ["83952.7", "0.00001065", "0", "1"], ["83952.6", "0.00597332", "0", "1"], ["83951.9", "0.07102314", "0", "1"], ["83951.6", "0.0770502", "0", "2"], ["83951.5", "0.03", "0", "1"], ["83951.3", "0.05700028", "0", "1"], ["83950.3", "3.25523952", "0", "2"], ["83950", "0.00013403", "0", "2"], ["83949.9", "0.01062478", "0", "3"], ["83948.7", "0.03", "0", "1"], ["83948.1", "0.03", "0", "1"], ["83947.6", "0.00579976", "0", "1"], ["83947.3", "0.00103791", "0", "1"], ["83946.9", "0.01190094", "0", "1"], ["83946.7", "0.00002763", "0", "2"], ["83946.3", "0.2025", "0", "1"], ["83946.1", "0.17821722", "0", "1"], ["83946", "0.38579296", "0", "2"], ["83945.5", "0.18326132", "0", "1"], ["83945.4", "0.11890903", "0", "1"], ["83945", "0.00579981", "0", "1"], ["83944.9", "0.00579981", "0", "1"], ["83944.8", "0.00011161", "0", "1"], ["83944.6", "0.00421935", "0", "1"], ["83944.1", "0.02315999", "0", "2"], ["83943.9", "0.0142", "0", "1"], ["83943.8", "0.00594775", "0", "1"], ["83943.6", "0.0142", "0", "1"], ["83943.4", "0.0142", "0", "1"], ["83943.2", "0.0142", "0", "1"], ["83942.2", "0.0142", "0", "1"], ["83942.1", "0.03001", "0", "2"], ["83942", "0.00007352", "0", "1"], ["83941.8", "0.00001197", "0", "1"], ["83941.1", "0.00001807", "0", "1"], ["83940.4", "0.00002279", "0", "1"], ["83940", "0.00201886", "0", "1"], ["83939.8", "0.08991011", "0", "1"], ["83939.5", "0.00007329", "0", "1"], ["83938.4", "0.00001883", "0", "1"], ["83938.2", "0.0001735", "0", "1"], ["83937.8", "0.2025", "0", "1"], ["83937.1", "1.2020045", "0", "1"], ["83936.9", "0.03", "0", "1"], ["83936.8", "0.00001197", "0", "1"], ["83936.1", "0.0000442", "0", "1"], ["83935.7", "0.01194665", "0", "1"], ["83935.6", "0.00001925", "0", "1"], ["83935.2", "0.183254", "0", "1"], ["83934.9", "0.17821722", "0", "1"], ["83934.2", "0.35579296", "0", "1"], ["83934.1", "0.00422012", "0", "1"], ["83933.8", "0.00011948", "0", "1"], ["83933.3", "0.00525171", "0", "7"], ["83932.9", "0.00001845", "0", "1"], ["83932.8", "0.014", "0", "1"], ["83931.9", "0.00001197", "0", "1"], ["83931.4", "0.0054", "0", "1"], ["83931.3", "0.00001197", "0", "1"], ["83931", "0.21412", "0", "1"], ["83930.7", "0.00001807", "0", "1"], ["83930.5", "0.00001316", "0", "1"], ["83930.2", "0.00606454", "0", "2"], ["83929.9", "0.00007149", "0", "1"], ["83929.3", "0.2025", "0", "1"], ["83928.5", "0.14848165", "0", "4"], ["83927.9", "0.00199404", "0", "5"], ["83927.4", "0.01784918", "0", "1"], ["83927.3", "0.01493332", "0", "1"], ["83927", "0.01784325", "0", "3"], ["83926.8", "0.01188752", "0", "1"], ["83926.3", "0.01786316", "0", "1"], ["83926.1", "0.00007821", "0", "1"], ["83925.9", "0.00001002", "0", "1"], ["83925.8", "0.17821722", "0", "1"], ["83925.6", "0.35579296", "0", "1"], ["83925.3", "0.00008", "0", "1"], ["83925.2", "0.00011161", "0", "1"], ["83925", "0.00027367", "0", "1"]], "ts": "1742555346309", "checksum": 1700262961, "seqId": 49927596017, "prevSeqId": -1}], "record_time": 1742555346.318826, "EXCHANGE": "OKX"}
{"arg": {"channel": "books", "instId": "BTC-USDT"}, "action": "update", "data": [{"asks": [["84071.4", "0.3642803", "0", "4"], ["84071.9", "0", "0", "0"], ["84076", "0.0234", "0", "1"], ["84079.1", "0.01032", "0", "1"], ["84079.8", "0.21014472", "0", "1"], ["84079.9", "0", "0", "0"], ["84082.4", "0.2025", "0", "1"], ["84085.4", "0.03098197", "0", "2"], ["84088.9", "0.70994511", "0", "1"], ["84089.1", "0", "0", "0"], ["84089.5", "0.04", "0", "1"], ["84089.9", "0", "0", "0"], ["84091.3", "0.36104691", "0", "2"], ["84105.6", "0", "0", "0"], ["84106.4", "0.07999999", "0", "2"], ["84107.2", "0.04420427", "0", "2"], ["84108", "0.2", "0", "1"], ["84109", "1.001784", "0", "2"], ["84120.9", "0", "0", "0"], ["84121.4", "0", "0", "0"], ["84121.6", "0", "0", "0"], ["84133.3", "0.25483382", "0", "5"], ["84160.4", "0.01307556", "0", "2"], ["84161.4", "0.0048", "0", "1"], ["84163.3", "0.01188735", "0", "1"], ["84166.1", "0.01188733", "0", "1"], ["84182.3", "0.01188725", "0", "1"]], "bids": [["84071.3", "0.53481004", "0", "9"], ["84062.6", "0.0137", "0", "1"], ["84060.2", "0.01", "0", "2"], ["84058", "0.0146", "0", "1"], ["84057.1", "0", "0", "0"], ["84056.6", "1", "0", "1"], ["84056.3", "0.04111", "0", "1"], ["84053.8", "0", "0", "0"], ["84052.5", "0.11235012", "0", "2"], ["84050.7", "0.11903293", "0", "1"], ["84048.6", "0", "0", "0"]], "ts": "1742555346409", "checksum": 992931750, "seqId": 49927596065, "prevSeqId": 49927596017}], "record_time": 1742555346.413908, "EXCHANGE": "OKX"}
{"arg": {"channel": "books", "instId": "BTC-USDT"}, "action": "update", "data": [{"asks": [["84091.6", "0.21236737", "0", "2"], ["84093.1", "0.133445", "0", "1"], ["84108", "0", "0", "0"], ["84109", "0.001784", "0", "1"], ["84112.1", "0.00199062", "0", "1"], ["84116.3", "0.00199062", "0", "1"], ["84120.5", "0.00199062", "0", "1"], ["84121.4", "0.01188759", "0", "1"], ["84121.5", "0.01199918", "0", "2"], ["84121.6", "0.01188756", "0", "1"], ["84133.6", "0.12489", "0", "1"], ["84136.5", "0.01188747", "0", "1"], ["84160.4", "0.0011882", "0", "1"], ["84163.3", "0", "0", "0"], ["84166.1", "0", "0", "0"], ["84182.3", "0", "0", "0"], ["84246.3", "0", "0", "0"], ["84246.5", "0", "0", "0"], ["84247.2", "0", "0", "0"], ["84247.3", "0", "0", "0"]], "bids": [["84060.4", "0.00564", "0", "1"], ["84056.3", "0.21953", "0", "2"], ["83973.1", "0.01188747", "0", "1"], ["83954.5", "0.19010479", "0", "2"], ["83952", "0.01188759", "0", "1"], ["83926.8", "0", "0", "0"], ["83925.2", "0", "0", "0"], ["83925", "0", "0", "0"]], "ts": "1742555346509", "checksum": -90968885, "seqId": 49927596092, "prevSeqId": 49927596065}], "record_time": 1742555346.513466, "EXCHANGE": "OKX"}
{"arg": {"channel": "books", "instId": "BTC-USDT"}, "action": "update", "data": [{"asks": [["84121", "0", "0", "0"], ["84121.8", "0.01188753", "0", "1"]], "bids": [], "ts": "1742555346609", "checksum": -90968885, "seqId": 49927596102, "prevSeqId": 49927596092}], "record_time": 1742555346.61349, "EXCHANGE": "OKX"}
{"arg": {"channel": "books", "instId": "BTC-USDT"}, "action": "update", "data": [{"asks": [["84071.4", "0.48328392", "0", "5"], ["84098.5", "0.4528938", "0", "1"], ["84098.6", "0.23800593", "0", "1"], ["84100.4", "0", "0", "0"], ["84131", "0.72313202", "0", "2"], ["84140.2", "0.07132458", "0", "2"], ["84163.6", "0.07587321", "0", "4"], ["84241.1", "0.07122418", "0", "1"], ["84245.8", "0", "0", "0"]], "bids": [["84071.3", "0.43481004", "0", "8"], ["84069.9", "0.11900574", "0", "1"], ["84042.2", "0", "0", "0"], ["84041.2", "0.23800587", "0", "1"], ["84036.3", "0.73602723", "0", "2"], ["84036", "1", "0", "1"], ["84025", "0.20001719", "0", "2"], ["84024.8", "0.066", "0", "3"], ["84024", "0.013", "0", "1"], ["84023.2", "0", "0", "0"], ["84022.4", "0", "0", "0"], ["84005.9", "0.07299323", "0", "1"], ["83975.3", "0.07146456", "0", "2"], ["83968.6", "0.0214", "0", "1"], ["83925.9", "0", "0", "0"], ["83925.8", "0", "0", "0"], ["83925.6", "0", "0", "0"], ["83925.3", "0", "0", "0"]], "ts": "1742555346809", "checksum": 605483610, "seqId": 49927596141, "prevSeqId": 49927596102}], "record_time": 1742555346.816125, "EXCHANGE": "OKX"}
{"arg": {"channel": "books", "instId": "BTC-USDT"}, "action": "update", "data": [{"asks": [["84082.5", "0.00863051", "0", "2"], ["84098.4", "0.2380029", "0", "1"], ["84098.6", "0", "0", "0"], ["84121.4", "0", "0", "0"], ["84121.5", "0.00011161", "0", "1"], ["84121.6", "0", "0", "0"], ["84136.5", "0", "0", "0"], ["84140.2", "0.00001501", "0", "1"], ["84143.2", "0.07130702", "0", "1"], ["84160.4", "0.02496292", "0", "3"], ["84163.6", "0.05447321", "0", "3"], ["84166.1", "0.01188733", "0", "1"], ["84182.3", "0.01188725", "0", "1"], ["84241.1", "0", "0", "0"], ["84244.1", "0.07205164", "0", "2"], ["84245.8", "0.00040029", "0", "4"]], "bids": [["84060.4", "0", "0", "0"], ["84058.1", "1", "0", "1"], ["84056.6", "0", "0", "0"], ["84042.1", "0.2380029", "0", "1"], ["84041.2", "0", "0", "0"], ["84025", "0.00001719", "0", "1"], ["83982", "0", "0", "0"], ["83978.3", "0.07144701", "0", "1"], ["83975.3", "0.000015", "0", "1"], ["83968.7", "0.0214", "0", "1"], ["83967.8", "0", "0", "0"], ["83925.9", "0.00001002", "0", "1"]], "ts": "1742555346909", "checksum": -22329465, "seqId": 49927596186, "prevSeqId": 49927596141}], "record_time": 1742555346.914301, "EXCHANGE": "OKX"}
{"arg": {"channel": "books", "instId": "BTC-USDT"}, "action": "update", "data": [{"asks": [["84098.4", "0", "0", "0"], ["84100.4", "0.23800045", "0", "1"], ["84143.2", "0.14261404", "0", "2"], ["84163.6", "0.03307321", "0", "2"], ["84244.1", "0.14327328", "0", "3"]], "bids": [["84071.3", "0.67434068", "0", "10"], ["84061", "0.00564", "0", "1"], ["84058.1", "0", "0", "0"], ["84056.1", "1", "0", "1"], ["84042.1", "0.23800114", "0", "1"], ["83982", "0.00016245", "0", "1"], ["83978.3", "0.14289402", "0", "2"], ["83968.8", "0.0214", "0", "1"], ["83926.3", "0", "0", "0"], ["83926.1", "0", "0", "0"], ["83925.9", "0", "0", "0"]], "ts": "1742555347009", "checksum": -258581452, "seqId": 49927596217, "prevSeqId": 49927596186}], "record_time": 1742555347.017507, "EXCHANGE": "OKX"}
{"arg": {"channel": "books", "instId": "BTC-USDT"}, "action": "update", "data": [{"asks": [["84163.6", "0.0214", "0", "1"]], "bids": [["83968.9", "0.0214", "0", "1"], ["83932.5", "0.01188729", "0", "1"], ["83927.3", "0", "0", "0"], ["83927", "0", "0", "0"]], "ts": "1742555347109", "checksum": -258581452, "seqId": 49927596224, "prevSeqId": 49927596217}], "record_time": 1742555347.116616, "EXCHANGE": "OKX"}
{"arg": {"channel": "books", "instId": "BTC-USDT"}, "action": "update", "data": [{"asks": [["84093.8", "0.41144239", "0", "3"], ["84133.3", "0.2786088", "0", "7"], ["84160.4", "0.0011882", "0", "1"], ["84163.3", "0.01188735", "0", "1"], ["84166.1", "0", "0", "0"]], "bids": [], "ts": "1742555347209", "checksum": -258581452, "seqId": 49927596237, "prevSeqId": 49927596224}], "record_time": 1742555347.292735, "EXCHANGE": "OKX"}
{"arg": {"channel": "books", "instId": "BTC-USDT"}, "action": "update", "data": [{"asks": [["84093.8", "0.05460239", "0", "2"], ["84133.3", "0.26672131", "0", "6"], ["84160.4", "0.01307556", "0", "2"], ["84163.6", "0", "0", "0"], ["84246.3", "0.00083", "0", "1"]], "bids": [["83969", "0.02145519", "0", "2"]], "ts": "1742555347309", "checksum": -258581452, "seqId": 49927596248, "prevSeqId": 49927596237}], "record_time": 1742555347.353061, "EXCHANGE": "OKX"}
{"arg": {"channel": "books", "instId": "BTC-USDT"}, "action": "update", "data": [{"asks": [["84133.3", "0.2786088", "0", "7"], ["84160.4", "0.0011882", "0", "1"], ["84200", "6.19613161", "0", "35"]], "bids": [["84071.3", "0.53434068", "0", "9"], ["84061.1", "0.0000225", "0", "1"], ["84061", "0", "0", "0"], ["84058", "1.0146", "0", "2"], ["84056.1", "0", "0", "0"], ["83927.3", "0.01493332", "0", "1"]], "ts": "1742555347409", "checksum": 301196491, "seqId": 49927596260, "prevSeqId": 49927596248}], "record_time": 1742555347.4142, "EXCHANGE": "OKX"}
{"arg": {"channel": "books", "instId": "BTC-USDT"}, "action": "update", "data": [{"asks": [["84115", "1.02380338", "0", "3"], ["84117", "0.2", "0", "1"], ["84246.3", "0", "0", "0"]], "bids": [["84053.8", "0.17842", "0", "1"], ["83927.3", "0", "0", "0"]], "ts": "1742555347509", "checksum": 301196491, "seqId": 49927596270, "prevSeqId": 49927596260}], "record_time": 1742555347.514255, "EXCHANGE": "OKX"}
{"arg": {"channel": "books", "instId": "BTC-USDT"}, "action": "update", "data": [{"asks": [["84115", "0.02380338", "0", "2"], ["84117", "0", "0", "0"], ["84246.3", "0.00083", "0", "1"]], "bids": [["84071.3", "0.43434068", "0", "8"]], "ts": "1742555347609", "checksum": -95212341, "seqId": 49927596273, "prevSeqId": 49927596270}], "record_time": 1742555347.613166, "EXCHANGE": "OKX"}
{"arg": {"channel": "books", "instId": "BTC-USDT"}, "action": "update", "data": [{"asks": [["84133.3", "0.26672131", "0", "6"], ["84160.4", "0.01307556", "0", "2"]], "bids": [], "ts": "1742555347709", "checksum": -95212341, "seqId": 49927596279, "prevSeqId": 49927596273}], "record_time": 1742555347.713318, "EXCHANGE": "OKX"}
{"arg": {"channel": "books", "instId": "BTC-USDT"}, "action": "update", "data": [{"asks": [["84143.2", "0.07130702", "0", "1"], ["84244.1", "0.07205164", "0", "2"]], "bids": [["84071.3", "0.41834068", "0", "7"], ["83978.3", "0.07144701", "0", "1"]], "ts": "1742555347809", "checksum": 1616188321, "seqId": 49927596290, "prevSeqId": 49927596279}], "record_time": 1742555347.813887, "EXCHANGE": "OKX"}
{"arg": {"channel": "books", "instId": "BTC-USDT"}, "action": "update", "data": [{"asks": [["84071.4", "0.48329925", "0", "6"], ["84071.9", "0.01766839", "0", "1"], ["84076.7", "0.01032", "0", "1"], ["84079.1", "0", "0", "0"], ["84084.6", "0.05523436", "0", "2"], ["84084.7", "0", "0", "0"], ["84085.3", "1.03274909", "0", "2"], ["84086.5", "0", "0", "0"], ["84091.3", "0.25399691", "0", "2"], ["84091.6", "0.06566366", "0", "2"], ["84091.7", "0", "0", "0"], ["84093", "0.29173364", "0", "1"], ["84096.2", "0.23801101", "0", "1"], ["84096.6", "0", "0", "0"], ["84098.6", "0.06626475", "0", "1"], ["84098.7", "0", "0", "0"], ["84100.4", "0", "0", "0"], ["84246.5", "0.00120691", "0", "2"], ["84247.2", "0.00153761", "0", "2"]], "bids": [["84071.3", "0.33263668", "0", "4"], ["84070.1", "0.05530753", "0", "2"], ["84069.9", "0", "0", "0"], ["84067.8", "0.11900861", "0", "1"], ["84062.6", "0", "0", "0"], ["84060.2", "0.0237", "0", "3"], ["84058", "0.0146", "0", "1"], ["84057.4", "0.17821722", "0", "1"], ["84057.3", "0.03126592", "0", "1"], ["84056.6", "1", "0", "1"], ["84050.4", "0", "0", "0"], ["84050.3", "0.03304955", "0", "1"], ["84046.5", "0", "0", "0"], ["84043.4", "0", "0", "0"], ["84043.3", "0.06460448", "0", "1"], ["84042.1", "0", "0", "0"], ["84037.6", "0.23801101", "0", "1"], ["84037.5", "0", "0", "0"], ["84031.6", "0.3615675", "0", "2"], ["84028", "0.2", "0", "1"], ["84021.7", "0.02745264", "0", "1"], ["84000.1", "2.04826163", "0", "1"], ["83966.9", "0.600015", "0", "2"]], "ts": "1742555347909", "checksum": 1363976248, "seqId": 49927596361, "prevSeqId": 49927596290}], "record_time": 1742555347.913479, "EXCHANGE": "OKX"}
{"arg": {"channel": "books", "instId": "BTC-USDT"}, "action": "update", "data": [{"asks": [["84075.9", "0.46359169", "0", "2"], ["84076.1", "0", "0", "0"], ["84078.5", "0.17821722", "0", "1"], ["84079", "0.17842", "0", "1"], ["84079.8", "0.6753428", "0", "1"], ["84080.8", "0.35641581", "0", "1"], ["84081", "0.03097", "0", "1"], ["84081.2", "0.35684", "0", "1"], ["84083.7", "1.11898634", "0", "2"], ["84084.2", "0.03246565", "0", "1"], ["84084.4", "0.35301933", "0", "1"], ["84084.6", "0.02380302", "0", "1"], ["84084.9", "0.05040823", "0", "2"], ["84085", "0.03459203", "0", "3"], ["84085.1", "0.03314276", "0", "1"], ["84085.3", "0", "0", "0"], ["84085.4", "0.00001197", "0", "1"], ["84086.4", "0", "0", "0"], ["84087.6", "0.02314536", "0", "2"], ["84088.7", "0.08991011", "0", "1"], ["84091.2", "1.60405504", "0", "2"], ["84091.4", "0.03277014", "0", "1"], ["84091.6", "0.12489", "0", "1"], ["84093.6", "0.03272093", "0", "1"], ["84093.7", "0.03209846", "0", "1"], ["84093.8", "0.0237944", "0", "1"], ["84095.1", "0.23801457", "0", "1"], ["84096.2", "0", "0", "0"], ["84098.2", "0.06970326", "0", "2"], ["84098.6", "0", "0", "0"], ["84100.4", "0.06549602", "0", "1"], ["84100.5", "0", "0", "0"], ["84100.8", "0.0634818", "0", "1"], ["84101.1", "0", "0", "0"], ["84102.4", "0.06278583", "0", "1"], ["84102.5", "0", "0", "0"], ["84121.5", "0.01199918", "0", "2"], ["84121.6", "0.01188756", "0", "1"], ["84133.3", "0.01693131", "0", "5"], ["84136.5", "0.01188747", "0", "1"], ["84143.2", "0.14261404", "0", "2"], ["84160.4", "0.0011882", "0", "1"], ["84163.3", "0", "0", "0"], ["84182.3", "0", "0", "0"], ["84244.1", "0.14327328", "0", "3"], ["84245.2", "0", "0", "0"], ["84245.5", "0", "0", "0"], ["84245.8", "0", "0", "0"], ["84246.3", "0", "0", "0"], ["84246.5", "0", "0", "0"], ["84247.2", "0", "0", "0"]], "bids": [["84071.3", "0.21120668", "0", "3"], ["84067", "0.15454487", "0", "2"], ["84066.9", "0", "0", "0"], ["84065.9", "0", "0", "0"], ["84058.2", "0.23978012", "0", "1"], ["84057.3", "0", "0", "0"], ["84057", "0", "0", "0"], ["84056.9", "0.06565844", "0", "2"], ["84056.6", "0", "0", "0"], ["84056.4", "0", "0", "0"], ["84056.3", "0.21119634", "0", "2"], ["84055.9", "0", "0", "0"], ["84055.7", "0.03440617", "0", "2"], ["84054.6", "0.66862846", "0", "2"], ["84053.9", "1.016", "0", "2"], ["84051.9", "0.04111", "0", "1"], ["84050.3", "0", "0", "0"], ["84049.9", "0.04328332", "0", "3"], ["84049.6", "0", "0", "0"], ["84049.4", "0.24654242", "0", "2"], ["84048.2", "0", "0", "0"], ["84048.1", "0.03299236", "0", "1"], ["84047.6", "0", "0", "0"], ["84047.5", "0.03267012", "0", "1"], ["84043.3", "0", "0", "0"], ["84042.9", "0.06449686", "0", "1"], ["84041", "0", "0", "0"], ["84040.9", "0.0700967", "0", "1"], ["84040.2", "0", "0", "0"], ["84039.9", "0.06903853", "0", "1"], ["84039.5", "0", "0", "0"], ["84039.4", "0.06502633", "0", "1"], ["84037.6", "0", "0", "0"], ["84036.4", "0.23801457", "0", "1"], ["84028", "0", "0", "0"], ["83978.3", "0.14289402", "0", "2"], ["83927.3", "0.01493332", "0", "1"], ["83927", "0.01784325", "0", "3"], ["83926.3", "0.01786316", "0", "1"], ["83926.1", "0.00007821", "0", "1"], ["83925.9", "0.00001002", "0", "1"], ["83925.8", "0.17821722", "0", "1"], ["83925.6", "0.35579296", "0", "1"], ["83925.3", "0.00008", "0", "1"]], "ts": "1742555348009", "checksum": -1868707887, "seqId": 49927596470, "prevSeqId": 49927596361}], "record_time": 1742555348.013714, "EXCHANGE": "OKX"}
{"arg": {"channel": "books", "instId": "BTC-USDT"}, "action": "update", "data": [{"asks": [["84071.8", "0", "0", "0"], ["84077.7", "0.02530935", "0", "1"], ["84081.4", "0.000015", "0", "1"], ["84081.8", "0.06", "0", "2"], ["84095.1", "0", "0", "0"], ["84096.2", "0.23801433", "0", "1"], ["84133.6", "0", "0", "0"], ["84245.2", "0.00003034", "0", "1"]], "bids": [["84059.8", "0", "0", "0"], ["84049.8", "0.1217", "0", "3"], ["84017.7", "0.59965461", "0", "2"], ["84009.3", "0", "0", "0"], ["83975.7", "0.60607064", "0", "3"], ["83967.3", "0", "0", "0"], ["83940", "0", "0", "0"], ["83939.9", "0.0020189", "0", "1"], ["83925.2", "0.00011161", "0", "1"], ["83925", "0.00027367", "0", "1"], ["83924.8", "0.00422077", "0", "1"]], "ts": "1742555348109", "checksum": 867799550, "seqId": 49927596493, "prevSeqId": 49927596470}], "record_time": 1742555348.116179, "EXCHANGE": "OKX"}
{"arg": {"channel": "books", "instId": "BTC-USDT"}, "action": "update", "data": [{"asks": [["84071.4", "0.68579925", "0", "7"], ["84073.5", "0.01032", "0", "1"], ["84076.7", "0", "0", "0"], ["84084.2", "0", "0", "0"], ["84084.9", "0.016", "0", "1"], ["84085", "0.00194596", "0", "2"], ["84085.1", "0", "0", "0"], ["84091.2", "1.57066965", "0", "1"], ["84091.4", "0", "0", "0"], ["84093.6", "0", "0", "0"], ["84093.7", "0", "0", "0"], ["84098.2", "0.000015", "0", "1"], ["84100.4", "0", "0", "0"], ["84100.8", "0", "0", "0"], ["84102.4", "0", "0", "0"], ["84105.6", "0.08", "0", "2"], ["84106.4", "0.03999999", "0", "1"], ["84107.2", "0.00420428", "0", "1"], ["84245.5", "0.00009384", "0", "1"], ["84245.8", "0.00040029", "0", "4"], ["84246.3", "0.00083", "0", "1"], ["84246.5", "0.00120691", "0", "2"], ["84247.2", "0.00153761", "0", "2"], ["84247.3", "0.08991011", "0", "1"], ["84247.5", "0.00001525", "0", "1"]], "bids": [["84071.3", "0.00602186", "0", "2"], ["84070.1", "0", "0", "0"], ["84070", "0", "0", "0"], ["84068.1", "0.01538566", "0", "1"], ["84067.8", "0", "0", "0"], ["84066.7", "0", "0", "0"], ["84066", "0.14241126", "0", "2"], ["84063.6", "0.09029359", "0", "3"], ["84062", "0.02345328", "0", "2"], ["84061.1", "0", "0", "0"], ["84060.2", "0.01", "0", "2"], ["84057", "0.0137", "0", "1"], ["84056.9", "0", "0", "0"], ["84056.3", "0.17842", "0", "1"], ["84055.7", "0.00001197", "0", "1"], ["84053.9", "0.016", "0", "1"], ["84049.9", "0.01251027", "0", "2"], ["84049.4", "0.21161483", "0", "1"], ["84048.1", "0", "0", "0"], ["84047.5", "0", "0", "0"], ["84042.9", "0", "0", "0"], ["84040.9", "0", "0", "0"], ["84039.9", "0", "0", "0"], ["84039.4", "0", "0", "0"], ["84031.3", "0.2025", "0", "1"], ["83924.6", "0.00004441", "0", "2"], ["83924.2", "0.000015", "0", "1"], ["83923", "0.00001987", "0", "1"], ["83922", "0.00001197", "0", "1"], ["83921.7", "0.0535785", "0", "1"], ["83921.3", "0.0016853", "0", "2"], ["83921", "0.00001002", "0", "1"], ["83920", "0.00001096", "0", "1"], ["83919.7", "0.002379", "0", "1"], ["83919.2", "0.00003545", "0", "1"]], "ts": "1742555348209", "checksum": -2071659319, "seqId": 49927596544, "prevSeqId": 49927596493}], "record_time": 1742555348.216839, "EXCHANGE": "OKX"}
{"arg": {"channel": "books", "instId": "BTC-USDT"}, "action": "update", "data": [{"asks": [["84068.1", "1.27737607", "0", "16"], ["84070", "0.0234", "0", "1"], ["84071.2", "0.1156046", "0", "2"], ["84071.4", "0.05201533", "0", "3"], ["84073.2", "0.03290096", "0", "2"], ["84075.5", "0.00001197", "0", "1"], ["84075.7", "0.08991011", "0", "1"], ["84075.9", "0.36505422", "0", "2"], ["84078.7", "0.0103941", "0", "1"], ["84081", "0", "0", "0"], ["84083.3", "0.00481364", "0", "2"], ["84083.7", "0.11898634", "0", "1"], ["84084", "1", "0", "1"], ["84085", "0.000015", "0", "1"], ["84092.3", "0.23802286", "0", "1"], ["84096.2", "0", "0", "0"], ["84104", "0.08", "0", "2"], ["84104.8", "0.21821721", "0", "2"], ["84105.6", "0", "0", "0"], ["84106.4", "0", "0", "0"], ["84115.9", "0", "0", "0"], ["84121.5", "0.00011161", "0", "1"], ["84121.6", "0", "0", "0"], ["84133.3", "0.00504382", "0", "4"], ["84135.1", "0", "0", "0"], ["84136.5", "0", "0", "0"], ["84141.3", "0", "0", "0"], ["84145.7", "0.00192209", "0", "1"], ["84148.4", "0", "0", "0"], ["84148.7", "0.00012217", "0", "1"], ["84152.5", "0", "0", "0"], ["84199.1", "0.0118876", "0", "1"], ["84203.8", "0.01188757", "0", "1"], ["84221.8", "0.02377492", "0", "2"], ["84223.9", "0.01188745", "0", "1"], ["84236.3", "0.01188736", "0", "1"], ["84245.8", "0", "0", "0"], ["84246.3", "0", "0", "0"], ["84246.5", "0", "0", "0"], ["84247.2", "0", "0", "0"], ["84247.3", "0", "0", "0"], ["84247.5", "0", "0", "0"]], "bids": [["84071.3", "0", "0", "0"], ["84068.1", "0", "0", "0"], ["84068", "0", "0", "0"], ["84067.7", "0", "0", "0"], ["84067", "0.00111924", "0", "1"], ["84066.3", "0", "0", "0"], ["84066", "0.0234", "0", "1"], ["84063.6", "0.05429359", "0", "2"], ["84063", "0.02530935", "0", "1"], ["84057", "0", "0", "0"], ["84056.6", "0.0004335", "0", "1"], ["84054.6", "0.31980033", "0", "1"], ["84051.9", "0", "0", "0"], ["84049.6", "0.00475909", "0", "1"], ["84049.4", "0.54661102", "0", "2"], ["84047.4", "0.04111", "0", "1"], ["84046.3", "1", "0", "1"], ["84045.9", "0", "0", "0"], ["84045.5", "0.00713899", "0", "1"], ["84041.8", "0", "0", "0"], ["84036.4", "0", "0", "0"], ["84036.3", "0.11890903", "0", "1"], ["84036", "0", "0", "0"], ["84034.5", "0", "0", "0"], ["84034.3", "0.23802286", "0", "1"], ["84023.3", "0.02828473", "0", "2"], ["84021.5", "0", "0", "0"], ["84018.6", "0.01188736", "0", "1"], ["84018", "0.01188745", "0", "1"], ["84017.9", "0.01188746", "0", "1"], ["84017.8", "0.01188746", "0", "1"], ["84017.7", "0.61154234", "0", "3"], ["84008.9", "0.000015", "0", "1"], ["84005.5", "0.00285321", "0", "1"], ["84005.1", "0", "0", "0"], ["84001.7", "0.00105331", "0", "1"], ["83995.8", "0.01188757", "0", "1"], ["83975.8", "0.29129154", "0", "1"], ["83973.1", "0", "0", "0"], ["83954.5", "0.17821722", "0", "1"], ["83952", "0", "0", "0"], ["83918.9", "0.00001197", "0", "1"]], "ts": "1742555348309", "checksum": -1994348739, "seqId": 49927596967, "prevSeqId": 49927596544}], "record_time": 1742555348.315141, "EXCHANGE": "OKX"}
{"arg": {"channel": "books", "instId": "BTC-USDT"}, "action": "update", "data": [{"asks": [["84066.1", "1.32907507", "0", "18"], ["84066.7", "0.07977116", "0", "1"], ["84066.8", "0.11901017", "0", "1"], ["84067.1", "0.016", "0", "1"], ["84068", "0.0234", "0", "1"], ["84068.1", "0.016", "0", "1"], ["84071.2", "0.1", "0", "1"], ["84071.9", "0.03527535", "0", "2"], ["84073.2", "0.03097", "0", "1"], ["84073.5", "0", "0", "0"], ["84073.8", "0.02530935", "0", "1"], ["84075.6", "0.01032", "0", "1"], ["84077.7", "0", "0", "0"], ["84078.2", "0.0333155", "0", "1"], ["84078.7", "0", "0", "0"], ["84078.8", "0.03186412", "0", "1"], ["84078.9", "0.03438693", "0", "1"], ["84079", "0.03326993", "0", "1"], ["84085", "0", "0", "0"], ["84085.2", "0.15631252", "0", "6"], ["84085.3", "0.03359801", "0", "1"], ["84087.5", "0.09295073", "0", "2"], ["84087.6", "0.05471109", "0", "3"], ["84088.6", "0.23802822", "0", "1"], ["84092.2", "0.06981656", "0", "1"], ["84092.3", "0", "0", "0"], ["84094.3", "0.07002812", "0", "1"], ["84094.8", "0.06689261", "0", "1"], ["84096.3", "0.24786681", "0", "2"], ["84103.2", "0.08", "0", "2"], ["84104", "0.03999999", "0", "1"], ["84104.8", "0.17821722", "0", "1"], ["84112.6", "0.1", "0", "1"], ["84132.3", "0.01130979", "0", "1"], ["84133.9", "0", "0", "0"], ["84144.5", "0.00192209", "0", "1"], ["84145.7", "0", "0", "0"], ["84146.8", "0.00012217", "0", "1"], ["84148.7", "0", "0", "0"], ["84203.8", "0", "0", "0"], ["84221.8", "0.01188746", "0", "1"], ["84240.1", "0", "0", "0"], ["84242", "0", "0", "0"], ["84242.4", "0", "0", "0"], ["84242.5", "0", "0", "0"], ["84242.6", "0", "0", "0"], ["84244.1", "0", "0", "0"], ["84244.3", "0", "0", "0"], ["84244.6", "0", "0", "0"], ["84245.2", "0", "0", "0"], ["84245.5", "0", "0", "0"]], "bids": [["84067", "0", "0", "0"], ["84064.1", "0.06274248", "0", "2"], ["84064", "0.14241401", "0", "2"], ["84063", "0", "0", "0"], ["84061.3", "0.02788553", "0", "1"], ["84058.7", "0.02530935", "0", "1"], ["84058.4", "0.0005597", "0", "1"], ["84058.2", "0.13510881", "0", "1"], ["84056.6", "0", "0", "0"], ["84056.3", "0", "0", "0"], ["84053.8", "0", "0", "0"], ["84053.5", "0", "0", "0"], ["84051.3", "0.0137", "0", "1"], ["84050.9", "0.03311562", "0", "2"], ["84050.8", "0.0327205", "0", "2"], ["84050.2", "0.03589662", "0", "2"], ["84049.6", "0.03744866", "0", "2"], ["84049.4", "0.21161483", "0", "1"], ["84049.3", "0", "0", "0"], ["84046.3", "0", "0", "0"], ["84045.5", "0", "0", "0"], ["84044.7", "1", "0", "1"], ["84043.9", "0.03201335", "0", "1"], ["84043.3", "0.03238705", "0", "1"], ["84042", "0.14593974", "0", "3"], ["84041.4", "0.03248709", "0", "1"], ["84037.5", "0.06178273", "0", "1"], ["84036.9", "0.0660249", "0", "1"], ["84034.8", "0.07057002", "0", "1"], ["84034.3", "0", "0", "0"], ["84033.9", "0.06204452", "0", "1"], ["84033.3", "0.19578015", "0", "4"], ["84031.7", "0.23802697", "0", "1"], ["84017", "0", "0", "0"], ["84014.4", "0.01832788", "0", "1"], ["84007.3", "0.2498", "0", "1"], ["84005.5", "0", "0", "0"], ["84002.9", "0.00285322", "0", "1"], ["84001.7", "0", "0", "0"], ["84000.5", "0.00106832", "0", "2"], ["83945.5", "0", "0", "0"], ["83944.2", "0.18327883", "0", "1"], ["83921", "0", "0", "0"], ["83920", "0", "0", "0"], ["83919.7", "0", "0", "0"], ["83919.2", "0", "0", "0"], ["83918.9", "0", "0", "0"]], "ts": "1742555348409", "checksum": 929532164, "seqId": 49927597327, "prevSeqId": 49927596967}], "record_time": 1742555348.415995, "EXCHANGE": "OKX"}
{"arg": {"channel": "books", "instId": "BTC-USDT"}, "action": "update", "data": [{"asks": [["84064.2", "0.114", "0", "3"], ["84066", "0.0234", "0", "1"], ["84066.1", "0", "0", "0"], ["84066.7", "0", "0", "0"], ["84066.8", "0", "0", "0"], ["84067", "0.00111924", "0", "1"], ["84067.1", "0", "0", "0"], ["84067.9", "0.01884819", "0", "1"], ["84068.1", "0", "0", "0"], ["84070.5", "0.00001197", "0", "1"], ["84071.2", "0", "0", "0"], ["84071.4", "0.01601533", "0", "2"], ["84071.9", "0.09072848", "0", "1"], ["84072.7", "0.2025", "0", "1"], ["84073.2", "0", "0", "0"], ["84075.7", "0", "0", "0"], ["84075.9", "0.43425344", "0", "3"], ["84076.2", "0.35857", "0", "2"], ["84078.2", "0", "0", "0"], ["84078.8", "0", "0", "0"], ["84078.9", "0", "0", "0"], ["84079", "0.17844", "0", "1"], ["84079.7", "0.0000105", "0", "1"], ["84079.8", "0.30684758", "0", "1"], ["84080", "0.03411249", "0", "1"], ["84080.5", "0.03097", "0", "1"], ["84081.2", "0", "0", "0"], ["84081.8", "0.0703941", "0", "3"], ["84084", "0", "0", "0"], ["84085.2", "0.125", "0", "5"], ["84085.3", "0", "0", "0"], ["84086.8", "1", "0", "1"], ["84087", "0.03412665", "0", "1"], ["84087.4", "0.01774536", "0", "1"], ["84087.5", "0.05944451", "0", "1"], ["84087.6", "0.0054", "0", "1"], ["84088.6", "0", "0", "0"], ["84088.7", "0", "0", "0"], ["84092.2", "0", "0", "0"], ["84094", "0.06565279", "0", "1"], ["84094.3", "0", "0", "0"], ["84094.8", "0", "0", "0"], ["84095.1", "0.2380157", "0", "1"], ["84096.1", "0.06336731", "0", "1"], ["84096.3", "0.17821722", "0", "1"], ["84097.2", "0.18193548", "0", "2"], ["84103.2", "0.07999999", "0", "2"], ["84104.8", "0.23734648", "0", "2"], ["84109.1", "0", "0", "0"], ["84110.6", "0.1", "0", "1"], ["84112.6", "0", "0", "0"], ["84121.7", "0.00004312", "0", "1"], ["84124.9", "0.2025", "0", "1"], ["84141.6", "0.00192209", "0", "1"], ["84144.5", "0", "0", "0"], ["84145.7", "0.00012217", "0", "1"], ["84146.8", "0", "0", "0"], ["84199.1", "0", "0", "0"], ["84215.4", "0.84031699", "0", "2"], ["84221.8", "0", "0", "0"], ["84223.9", "0", "0", "0"], ["84236.3", "0", "0", "0"], ["84240.1", "0.00001005", "0", "1"], ["84242", "0.0000185", "0", "1"], ["84242.4", "0.00469113", "0", "3"], ["84242.5", "0.00011938", "0", "1"], ["84242.6", "0.00419183", "0", "1"], ["84244.1", "0.15516085", "0", "4"], ["84244.3", "0.00605088", "0", "2"], ["84244.6", "0.5999", "0", "1"]], "bids": [["84066", "0", "0", "0"], ["84064.1", "1.11128516", "0", "9"], ["84063.7", "0.03604763", "0", "1"], ["84063.6", "0.03645059", "0", "1"], ["84062.5", "0", "0", "0"], ["84054.7", "0.04111", "0", "1"], ["84053.8", "0.17844", "0", "1"], ["84052.7", "0.03275062", "0", "1"], ["84050.9", "0.000015", "0", "1"], ["84050.8", "0.00001198", "0", "1"], ["84050.2", "0.005", "0", "1"], ["84049.6", "0.00475909", "0", "1"], ["84049.4", "0.47389309", "0", "2"], ["84047.7", "1", "0", "1"], ["84047.4", "0", "0", "0"], ["84045.9", "0.53531", "0", "2"], ["84045.7", "0.03119934", "0", "1"], ["84044.7", "0", "0", "0"], ["84043.9", "0", "0", "0"], ["84043.3", "0", "0", "0"], ["84043", "0.03382866", "0", "2"], ["84042", "0.11235012", "0", "2"], ["84041.6", "0.00713932", "0", "1"], ["84041.4", "0", "0", "0"], ["84038.7", "0.06309542", "0", "1"], ["84036.9", "0", "0", "0"], ["84036.4", "0.2380157", "0", "1"], ["84035.2", "0.06279019", "0", "1"], ["84034.8", "0", "0", "0"], ["84034.2", "0.06726573", "0", "1"], ["84033.9", "0", "0", "0"], ["84033.3", "0.12592534", "0", "3"], ["84031.8", "0.01774536", "0", "1"], ["84031.7", "0", "0", "0"], ["84031.6", "0.34382214", "0", "1"], ["84025.6", "0", "0", "0"], ["84024.8", "0.106", "0", "4"], ["84024", "0.053", "0", "2"], ["84021.6", "0", "0", "0"], ["84020.8", "0.1", "0", "2"], ["84020", "0.05001", "0", "2"], ["84016.2", "0.1", "0", "1"], ["84007.5", "0.1249", "0", "1"], ["84002.9", "0", "0", "0"], ["84001.7", "0.00285324", "0", "1"], ["84000.5", "0.00001501", "0", "1"], ["83997.4", "0.00105333", "0", "1"], ["83982", "0", "0", "0"], ["83978.4", "0.00016246", "0", "1"], ["83922", "0", "0", "0"], ["83921.7", "0", "0", "0"], ["83921.3", "0", "0", "0"]], "ts": "1742555348509", "checksum": -1084737834, "seqId": 49927597672, "prevSeqId": 49927597327}], "record_time": 1742555348.514587, "EXCHANGE": "OKX"}
{"arg": {"channel": "books", "instId": "BTC-USDT"}, "action": "update", "data": [{"asks": [["84064.2", "0.18193873", "0", "3"], ["84076.7", "0.01032", "0", "1"], ["84078.2", "0.03287669", "0", "1"], ["84078.3", "0.0314299", "0", "1"], ["84078.8", "0.03126383", "0", "1"], ["84079", "0.21034111", "0", "2"], ["84080", "0", "0", "0"], ["84085.3", "0.03122016", "0", "1"], ["84085.8", "0.06241264", "0", "2"], ["84087", "0.03274167", "0", "1"], ["84092.8", "0.06150958", "0", "1"], ["84093.7", "0.06692227", "0", "1"], ["84094", "0", "0", "0"], ["84094.3", "0.23801791", "0", "1"], ["84094.8", "0.0673617", "0", "1"], ["84095.1", "0", "0", "0"], ["84095.7", "0.06942215", "0", "1"], ["84096.1", "0", "0", "0"], ["84097.2", "0.11890903", "0", "1"], ["84108.7", "0.1", "0", "1"], ["84110.6", "0", "0", "0"], ["84120.3", "0.00004312", "0", "1"], ["84121.7", "0", "0", "0"], ["84242.4", "0", "0", "0"], ["84242.5", "0", "0", "0"], ["84242.6", "0", "0", "0"], ["84244.1", "0", "0", "0"], ["84244.3", "0", "0", "0"], ["84244.6", "0", "0", "0"]], "bids": [["84064.1", "1.16613609", "0", "12"], ["84063.7", "0.02511245", "0", "1"], ["84063.6", "0", "0", "0"], ["84063.5", "0.0137", "0", "1"], ["84054.6", "0.56569246", "0", "2"], ["84052.7", "0", "0", "0"], ["84051.5", "0.03295421", "0", "1"], ["84051.3", "0", "0", "0"], ["84051.2", "1.00006777", "0", "2"], ["84050", "0.22488889", "0", "5"], ["84049.6", "0.07323992", "0", "3"], ["84049.4", "0", "0", "0"], ["84047.7", "0", "0", "0"], ["84045.9", "0.17844", "0", "1"], ["84045.7", "0", "0", "0"], ["84044.5", "0.15246323", "0", "2"], ["84043.3", "0.03400569", "0", "1"], ["84043", "0.00011161", "0", "1"], ["84041.5", "0.0342197", "0", "1"], ["84040.8", "0.0325735", "0", "1"], ["84038.7", "0", "0", "0"], ["84037.5", "0.13108335", "0", "2"], ["84036.4", "0.23801791", "0", "1"], ["84035.2", "0", "0", "0"], ["84034.2", "0.06940141", "0", "1"], ["84033.9", "0.06417553", "0", "1"], ["84032.7", "0.06823803", "0", "1"], ["84024.8", "0.08", "0", "2"], ["84024", "0.066", "0", "3"], ["84023.2", "0.013", "0", "1"], ["84016.2", "0", "0", "0"], ["84014.3", "0.3125", "0", "3"], ["84007.3", "0", "0", "0"], ["83978.4", "0", "0", "0"], ["83975.9", "0.00016246", "0", "1"], ["83922", "0.00001197", "0", "1"], ["83921.7", "0.0535785", "0", "1"]], "ts": "1742555348609", "checksum": 497319583, "seqId": 49927597853, "prevSeqId": 49927597672}], "record_time": 1742555348.614066, "EXCHANGE": "OKX"}
{"arg": {"channel": "books", "instId": "BTC-USDT"}, "action": "update", "data": [{"asks": [["84087", "0.06612212", "0", "2"], ["84103.2", "0", "0", "0"], ["84104", "0.07999999", "0", "2"], ["84104.8", "0.27734647", "0", "3"], ["84242.4", "0.00469113", "0", "3"]], "bids": [["84050.2", "0.03810355", "0", "2"], ["84007.5", "0", "0", "0"], ["83921.3", "0.0016853", "0", "2"]], "ts": "1742555348709", "checksum": 497319583, "seqId": 49927597861, "prevSeqId": 49927597853}], "record_time": 1742555348.715636, "EXCHANGE": "OKX"}
{"arg": {"channel": "books", "instId": "BTC-USDT"}, "action": "update", "data": [{"asks": [["84066", "0.0254", "0", "2"], ["84076", "0.0254", "0", "2"], ["84077", "0.00193097", "0", "1"], ["84086.7", "0.01774536", "0", "1"], ["84086.9", "0.03333208", "0", "1"], ["84087", "0.03274167", "0", "1"], ["84087.4", "0", "0", "0"], ["84092.6", "0.2380196", "0", "1"], ["84094.3", "0", "0", "0"], ["84094.7", "0.06416334", "0", "1"], ["84094.8", "0", "0", "0"], ["84242", "0", "0", "0"], ["84242.4", "0", "0", "0"]], "bids": [["84062.2", "0.002", "0", "1"], ["84057.4", "0.17943822", "0", "2"], ["84053.5", "0.35687", "0", "1"], ["84052.7", "1", "0", "1"], ["84052.1", "0.002", "0", "1"], ["84051.2", "0.00006777", "0", "1"], ["84041.5", "0", "0", "0"], ["84041.4", "0.0344154", "0", "1"], ["84036.4", "0", "0", "0"], ["84034.3", "0.2380196", "0", "1"], ["84033.9", "0", "0", "0"], ["84033.8", "0.06856312", "0", "2"], ["84031.8", "0", "0", "0"], ["84031.7", "0.01774536", "0", "1"], ["83922", "0", "0", "0"], ["83921.7", "0", "0", "0"], ["83921.3", "0", "0", "0"]], "ts": "1742555348809", "checksum": -2026838687, "seqId": 49927597894, "prevSeqId": 49927597861}], "record_time": 1742555348.814338, "EXCHANGE": "OKX"}
{"arg": {"channel": "books", "instId": "BTC-USDT"}, "action": "update", "data": [{"asks": [["84084.4", "0.577169", "0", "2"], ["84098.5", "1.6928938", "0", "2"], ["84103.2", "0.07999999", "0", "2"], ["84104", "0.03999999", "0", "1"], ["84104.8", "0.23734648", "0", "2"], ["84240.1", "0", "0", "0"]], "bids": [["84054.6", "0.31980033", "0", "1"], ["84052.7", "0", "0", "0"], ["84050", "0.51918907", "0", "6"], ["84049.8", "1.1217", "0", "4"], ["84049.3", "0.24981", "0", "1"], ["84036.3", "0.53910755", "0", "2"], ["84000.1", "2.43080148", "0", "2"]], "ts": "1742555348909", "checksum": 1465410547, "seqId": 49927597917, "prevSeqId": 49927597894}], "record_time": 1742555348.91353, "EXCHANGE": "OKX"}
{"arg": {"channel": "books", "instId": "BTC-USDT"}, "action": "update", "data": [{"asks": [["84064.2", "0.0769", "0", "2"], ["84066.4", "0.03603894", "0", "1"], ["84066.5", "0.11901056", "0", "1"], ["84075.9", "0.23425344", "0", "2"], ["84078.2", "0", "0", "0"], ["84078.3", "0", "0", "0"], ["84078.5", "0.21044751", "0", "2"], ["84078.6", "0.15008776", "0", "2"], ["84078.7", "0.0347891", "0", "1"], ["84078.8", "0", "0", "0"], ["84079", "0.21348721", "0", "2"], ["84085.3", "0.03251129", "0", "1"], ["84085.7", "0.03238059", "0", "1"], ["84085.8", "0.02843448", "0", "1"], ["84086.9", "0", "0", "0"], ["84087", "0", "0", "0"], ["84087.3", "0.03387462", "0", "1"], ["84087.4", "0.03370226", "0", "1"], ["84092.6", "0", "0", "0"], ["84092.7", "0.15322316", "0", "2"], ["84092.8", "0", "0", "0"], ["84093.7", "0", "0", "0"], ["84094", "0.06706163", "0", "1"], ["84094.3", "0.2380162", "0", "1"], ["84094.7", "0", "0", "0"], ["84094.8", "0.06658934", "0", "1"], ["84095.7", "0", "0", "0"], ["84096", "0.06413715", "0", "1"], ["84103.2", "0", "0", "0"], ["84104", "0.07999999", "0", "2"], ["84104.8", "0.27734647", "0", "3"], ["84240.1", "0.00001005", "0", "1"]], "bids": [["84054.6", "0.67912972", "0", "2"], ["84052.1", "1.002", "0", "2"], ["84051.5", "0", "0", "0"], ["84051.4", "0.03065263", "0", "1"], ["84050.9", "0.08992511", "0", "2"], ["84050.5", "0.03462809", "0", "1"], ["84050.2", "0.005", "0", "1"], ["84050", "0.22488889", "0", "5"], ["84049.9", "0.04499148", "0", "3"], ["84049.8", "0.1217", "0", "3"], ["84049.6", "0.03589387", "0", "2"], ["84044.5", "0.11904157", "0", "1"], ["84044.4", "0.03372176", "0", "1"], ["84043.3", "0.03328705", "0", "1"], ["84041.8", "0.03197304", "0", "1"], ["84041.4", "0", "0", "0"], ["84041.2", "0.03087774", "0", "1"], ["84040.8", "0", "0", "0"], ["84037.5", "0.06178273", "0", "1"], ["84037.4", "0.06692294", "0", "1"], ["84036.4", "0.2380162", "0", "1"], ["84036.3", "0.11890903", "0", "1"], ["84034.5", "0.06490078", "0", "1"], ["84034.3", "0", "0", "0"], ["84034.2", "0", "0", "0"], ["84033.9", "0.07064679", "0", "1"], ["84033.8", "0.00420994", "0", "1"], ["84033", "0.06386293", "0", "1"], ["84032.7", "0", "0", "0"], ["84020", "0.15001", "0", "3"], ["83924.8", "0", "0", "0"], ["83924.6", "0", "0", "0"], ["83924.2", "0", "0", "0"], ["83923", "0", "0", "0"]], "ts": "1742555349009", "checksum": 33007893, "seqId": 49927597991, "prevSeqId": 49927597917}], "record_time": 1742555349.019799, "EXCHANGE": "OKX"}
{"arg": {"channel": "books", "instId": "BTC-USDT"}, "action": "update", "data": [{"asks": [["84094.3", "0", "0", "0"], ["84095.9", "0.23801405", "0", "1"]], "bids": [["84037.6", "0.23801405", "0", "1"], ["84036.4", "0", "0", "0"], ["84020", "0.05001", "0", "2"]], "ts": "1742555349109", "checksum": 33007893, "seqId": 49927597996, "prevSeqId": 49927597991}], "record_time": 1742555349.116474, "EXCHANGE": "OKX"}
{"arg": {"channel": "books", "instId": "BTC-USDT"}, "action": "update", "data": [{"asks": [], "bids": [["84053.6", "1", "0", "1"], ["84052.1", "0.002", "0", "1"], ["83925", "0", "0", "0"]], "ts": "1742555349209", "checksum": 33007893, "seqId": 49927598002, "prevSeqId": 49927597996}], "record_time": 1742555349.215822, "EXCHANGE": "OKX"}
{"arg": {"channel": "books", "instId": "BTC-USDT"}, "action": "update", "data": [{"asks": [["84064.2", "0.04", "0", "1"], ["84078.5", "0.17821722", "0", "1"], ["84078.6", "0.11890903", "0", "1"], ["84078.7", "0", "0", "0"], ["84078.8", "0.03119094", "0", "1"], ["84078.9", "0.03190811", "0", "1"], ["84079", "0.17844", "0", "1"], ["84079.1", "0.03252472", "0", "1"], ["84079.4", "0.03267274", "0", "1"], ["84080.5", "0", "0", "0"], ["84084.9", "0.04697", "0", "2"], ["84085.3", "0", "0", "0"], ["84085.7", "0.03439097", "0", "1"], ["84086.1", "0.03288913", "0", "1"], ["84087.3", "0", "0", "0"], ["84087.4", "0", "0", "0"], ["84087.5", "0.09267691", "0", "2"], ["84087.6", "0.04042804", "0", "2"], ["84092.7", "0.08297", "0", "1"], ["84093.1", "0.20345963", "0", "2"], ["84094", "0", "0", "0"], ["84094.3", "0.06333337", "0", "1"], ["84094.8", "0", "0", "0"], ["84096", "0", "0", "0"], ["84096.3", "0.24356586", "0", "2"], ["84185.1", "0", "0", "0"], ["84185.3", "0.05521168", "0", "1"], ["84186.7", "0", "0", "0"], ["84192.7", "0.18325", "0", "1"], ["84242", "0.0000185", "0", "1"], ["84242.4", "0.00469113", "0", "3"]], "bids": [["84063.7", "0.03901639", "0", "2"], ["84059.1", "0.04111", "0", "1"], ["84054.7", "0", "0", "0"], ["84051.8", "0.03211363", "0", "1"], ["84051.4", "0", "0", "0"], ["84050.8", "0.03469063", "0", "2"], ["84050.5", "0", "0", "0"], ["84050.2", "0.03804095", "0", "2"], ["84050", "0.25837447", "0", "6"], ["84049.9", "0.01251027", "0", "2"], ["84049.6", "0.00475909", "0", "1"], ["84044.8", "0.03291434", "0", "1"], ["84044.4", "0", "0", "0"], ["84043.7", "0.03167106", "0", "1"], ["84043.3", "0", "0", "0"], ["84042", "0.14543461", "0", "3"], ["84041.8", "0", "0", "0"], ["84041.4", "0.0325253", "0", "1"], ["84041.2", "0", "0", "0"], ["84037.8", "0.06228873", "0", "1"], ["84037.4", "0", "0", "0"], ["84034.8", "0.06356013", "0", "1"], ["84034.5", "0", "0", "0"], ["84033.9", "0", "0", "0"], ["84033.4", "0.0054", "0", "1"], ["84033.3", "0.19312956", "0", "4"], ["84033", "0", "0", "0"], ["84021.6", "0.0054", "0", "1"], ["84013.7", "0.001071", "0", "1"], ["83992.2", "0.0054", "0", "1"], ["83990.2", "0", "0", "0"], ["83931.4", "0", "0", "0"], ["83925", "0.00027367", "0", "1"], ["83924.8", "0.00422077", "0", "1"], ["83924.6", "0.00004441", "0", "2"]], "ts": "1742555349309", "checksum": 1850906852, "seqId": 49927598079, "prevSeqId": 49927598002}], "record_time": 1742555349.314753, "EXCHANGE": "OKX"}
{"arg": {"channel": "books", "instId": "BTC-USDT"}, "action": "update", "data": [{"asks": [["84064.2", "0.0769", "0", "2"], ["84078.5", "0.21129537", "0", "2"], ["84078.6", "0.15141618", "0", "2"], ["84078.7", "0.03295804", "0", "1"], ["84078.8", "0", "0", "0"], ["84078.9", "0", "0", "0"], ["84079", "0.21082953", "0", "2"], ["84079.1", "0", "0", "0"], ["84079.4", "0", "0", "0"], ["84085.3", "0.03111766", "0", "1"], ["84085.7", "0.03361488", "0", "1"], ["84086.1", "0", "0", "0"], ["84087.3", "0.03243226", "0", "1"], ["84087.4", "0.03464808", "0", "1"], ["84087.5", "0.05944451", "0", "1"], ["84087.6", "0.0054", "0", "1"], ["84092.7", "0.14945448", "0", "2"], ["84093.1", "0.133445", "0", "1"], ["84094", "0.0647367", "0", "1"], ["84094.3", "0", "0", "0"], ["84094.8", "0.06886372", "0", "1"], ["84096", "0.06865715", "0", "1"], ["84096.3", "0.17821722", "0", "1"], ["84242.4", "0", "0", "0"]], "bids": [["84053.6", "0", "0", "0"], ["84051.8", "0", "0", "0"], ["84051.4", "0.03245125", "0", "1"], ["84051.3", "1", "0", "1"], ["84050.8", "0.00001198", "0", "1"], ["84050.5", "0.03466198", "0", "1"], ["84050.2", "0.005", "0", "1"], ["84050", "0.22488889", "0", "5"], ["84049.9", "0.04366722", "0", "3"], ["84049.6", "0.03637885", "0", "2"], ["84044.8", "0", "0", "0"], ["84044.4", "0.03425221", "0", "1"], ["84043.7", "0", "0", "0"], ["84043.3", "0.0335615", "0", "1"], ["84042", "0.11235012", "0", "2"], ["84041.8", "0.03205635", "0", "1"], ["84041.4", "0", "0", "0"], ["84041.2", "0.03438516", "0", "1"], ["84037.8", "0", "0", "0"], ["84037.4", "0.06330368", "0", "1"], ["84034.8", "0", "0", "0"], ["84034.5", "0.06723794", "0", "1"], ["84033.9", "0.06716062", "0", "1"], ["84033.3", "0.12592534", "0", "3"], ["84033", "0.06911986", "0", "1"], ["83925.2", "0", "0", "0"], ["83925", "0", "0", "0"], ["83924.8", "0", "0", "0"], ["83924.6", "0", "0", "0"]], "ts": "1742555349409", "checksum": -772024851, "seqId": 49927598133, "prevSeqId": 49927598079}], "record_time": 1742555349.414843, "EXCHANGE": "OKX"}
{"arg": {"channel": "books", "instId": "BTC-USDT"}, "action": "update", "data": [{"asks": [["84143.2", "0.07130702", "0", "1"]], "bids": [["83978.3", "0.07144701", "0", "1"]], "ts": "1742555349509", "checksum": -772024851, "seqId": 49927598142, "prevSeqId": 49927598133}], "record_time": 1742555349.514, "EXCHANGE": "OKX"}
{"arg": {"channel": "books", "instId": "BTC-USDT"}, "action": "update", "data": [{"asks": [["84085.5", "1", "0", "1"], ["84086.8", "0", "0", "0"], ["84106", "0.2", "0", "1"], ["84107", "1", "0", "1"], ["84240.1", "0", "0", "0"], ["84242", "0", "0", "0"]], "bids": [], "ts": "1742555349609", "checksum": -772024851, "seqId": 49927598159, "prevSeqId": 49927598142}], "record_time": 1742555349.617204, "EXCHANGE": "OKX"}
{"arg": {"channel": "books", "instId": "BTC-USDT"}, "action": "update", "data": [{"asks": [["84086.7", "0", "0", "0"], ["84087.6", "0.02314536", "0", "2"], ["84240.1", "0.00001005", "0", "1"]], "bids": [["84064.1", "1.16792009", "0", "13"], ["84053", "1", "0", "1"], ["84051.3", "0", "0", "0"], ["84013.7", "0", "0", "0"], ["83925.2", "0.00011161", "0", "1"]], "ts": "1742555349709", "checksum": 441247277, "seqId": 49927598179, "prevSeqId": 49927598159}], "record_time": 1742555349.717138, "EXCHANGE": "OKX"}
{"arg": {"channel": "books", "instId": "BTC-USDT"}, "action": "update", "data": [{"asks": [["84143.2", "0.14261404", "0", "2"]], "bids": [["83978.3", "0.14289402", "0", "2"]], "ts": "1742555349809", "checksum": 441247277, "seqId": 49927598185, "prevSeqId": 49927598179}], "record_time": 1742555349.814637, "EXCHANGE": "OKX"}
{"arg": {"channel": "books", "instId": "BTC-USDT"}, "action": "update", "data": [{"asks": [["84064.2", "0.08", "0", "3"], ["84078.5", "0.17821722", "0", "1"], ["84078.6", "0.11890903", "0", "1"], ["84078.7", "0", "0", "0"], ["84079", "0.17844", "0", "1"], ["84085.3", "0", "0", "0"], ["84085.7", "0", "0", "0"], ["84087.3", "0", "0", "0"], ["84087.4", "0", "0", "0"], ["84092.7", "0.08297", "0", "1"], ["84093.9", "0.23801713", "0", "1"], ["84094", "0", "0", "0"], ["84094.8", "0", "0", "0"], ["84095.9", "0", "0", "0"], ["84096", "0", "0", "0"], ["84098.4", "0.71308068", "0", "1"], ["84098.5", "1.24", "0", "1"], ["84102.4", "0.08", "0", "2"], ["84103.2", "0.03999999", "0", "1"], ["84104", "0", "0", "0"], ["84104.8", "0.23734648", "0", "2"], ["84242", "0.0000185", "0", "1"], ["84242.4", "0.00469113", "0", "3"], ["84242.5", "0.00011938", "0", "1"], ["84242.6", "0.00419183", "0", "1"], ["84244.1", "0.15516085", "0", "4"], ["84244.3", "0.00605088", "0", "2"]], "bids": [["84053", "0", "0", "0"], ["84051.4", "0", "0", "0"], ["84050.5", "0", "0", "0"], ["84050.4", "1", "0", "1"], ["84049.9", "0.01251027", "0", "2"], ["84049.6", "0.00475909", "0", "1"], ["84044.4", "0", "0", "0"], ["84043.3", "0", "0", "0"], ["84041.8", "0", "0", "0"], ["84041.2", "0", "0", "0"], ["84037.6", "0", "0", "0"], ["84037.5", "0.46543237", "0", "2"], ["84037.4", "0", "0", "0"], ["84035.9", "0.23802909", "0", "2"], ["84034.5", "0", "0", "0"], ["84033.9", "0", "0", "0"], ["84033", "0", "0", "0"], ["83925", "0.00027367", "0", "1"], ["83924.8", "0.00422077", "0", "1"], ["83924.6", "0.00004441", "0", "2"], ["83924.2", "0.000015", "0", "1"], ["83923", "0.00001987", "0", "1"], ["83922", "0.00001197", "0", "1"], ["83921.7", "0.0535785", "0", "1"], ["83921.3", "0.0016853", "0", "2"], ["83921", "0.00001002", "0", "1"], ["83920", "0.00001096", "0", "1"], ["83919.7", "0.002379", "0", "1"]], "ts": "1742555349909", "checksum": -145063199, "seqId": 49927598229, "prevSeqId": 49927598185}], "record_time": 1742555349.914049, "EXCHANGE": "OKX"}
{"arg": {"channel": "books", "instId": "BTC-USDT"}, "action": "update", "data": [{"asks": [["84064.2", "0.0769", "0", "2"], ["84067.9", "0.07649217", "0", "2"], ["84071.3", "0.2", "0", "1"], ["84078.5", "0.24260183", "0", "3"], ["84078.6", "0.15165019", "0", "2"], ["84079", "0.2116924", "0", "2"], ["84085.3", "0.03151351", "0", "1"], ["84085.5", "1.03394461", "0", "2"], ["84087.3", "0.03086748", "0", "1"], ["84087.4", "0.03436886", "0", "1"], ["84092.5", "0.07845953", "0", "2"], ["84093.9", "0", "0", "0"], ["84094", "0.07020581", "0", "1"], ["84094.7", "0.23801606", "0", "1"], ["84094.8", "0.0624879", "0", "1"], ["84096", "0.06972443", "0", "1"], ["84102.4", "0", "0", "0"], ["84103.2", "0.07999999", "0", "2"], ["84104", "0.03999999", "0", "1"], ["84130.2", "0.01130823", "0", "1"], ["84132.3", "0", "0", "0"], ["84240.1", "0", "0", "0"], ["84242", "0", "0", "0"], ["84242.4", "0", "0", "0"], ["84242.5", "0", "0", "0"], ["84242.6", "0", "0", "0"], ["84244.1", "0", "0", "0"], ["84244.3", "0", "0", "0"]], "bids": [["84051.2", "0.03420207", "0", "2"], ["84050.5", "0.03438672", "0", "1"], ["84049.9", "0.04509126", "0", "3"], ["84049.6", "0.03668396", "0", "2"], ["84044.2", "0.03663529", "0", "2"], ["84043.3", "0.03411956", "0", "1"], ["84041.8", "0.03184716", "0", "1"], ["84041.2", "0.03447546", "0", "1"], ["84037.2", "0.06174695", "0", "1"], ["84036.4", "0.23801606", "0", "1"], ["84035.9", "0.00001196", "0", "1"], ["84034.5", "0.06883987", "0", "1"], ["84033.9", "0.06771268", "0", "1"], ["84033", "0.06235071", "0", "1"], ["84014.4", "0", "0", "0"], ["84013.5", "0.01832724", "0", "1"], ["83944.2", "0", "0", "0"], ["83942.3", "0.18327244", "0", "1"], ["83924.6", "0", "0", "0"], ["83924.2", "0", "0", "0"], ["83923", "0", "0", "0"], ["83922", "0", "0", "0"], ["83921.7", "0", "0", "0"], ["83921.3", "0", "0", "0"], ["83921", "0", "0", "0"], ["83920", "0", "0", "0"], ["83919.7", "0", "0", "0"]], "ts": "1742555350009", "checksum": -1705429666, "seqId": 49927598297, "prevSeqId": 49927598229}], "record_time": 1742555350.013823, "EXCHANGE": "OKX"}
{"arg": {"channel": "books", "instId": "BTC-USDT"}, "action": "update", "data": [{"asks": [["84064.2", "0.08", "0", "3"], ["84067.9", "0.01884819", "0", "1"], ["84071.3", "0", "0", "0"], ["84078.5", "0.21057705", "0", "2"], ["84078.7", "0.03060099", "0", "1"], ["84085.5", "1", "0", "1"], ["84085.7", "0.03318208", "0", "1"], ["84092.5", "0.01", "0", "1"], ["84092.7", "0.14611486", "0", "2"], ["84094.3", "0.23801592", "0", "1"], ["84094.7", "0", "0", "0"], ["84119.1", "0.00004312", "0", "1"], ["84120.3", "0", "0", "0"], ["84203.7", "0", "0", "0"], ["84206.9", "0.0118874", "0", "1"], ["84240", "0", "0", "0"]], "bids": [["84051.4", "0.03271834", "0", "1"], ["84051.2", "0.00006777", "0", "1"], ["84044.4", "0.03424025", "0", "1"], ["84044.2", "0.00350877", "0", "1"], ["84037.4", "0.0685242", "0", "1"], ["84037.2", "0", "0", "0"], ["84016.6", "0.01249385", "0", "2"], ["84013.5", "0", "0", "0"], ["84013.4", "0", "0", "0"], ["84012.8", "0.0183272", "0", "1"], ["84008.5", "0.01", "0", "1"], ["83975.9", "0", "0", "0"], ["83974.7", "0.00016248", "0", "1"], ["83939.9", "0", "0", "0"], ["83933.9", "0.0020193", "0", "1"], ["83925", "0", "0", "0"], ["83924.8", "0", "0", "0"]], "ts": "1742555350109", "checksum": -145063199, "seqId": 49927598340, "prevSeqId": 49927598297}], "record_time": 1742555350.114949, "EXCHANGE": "OKX"}
{"arg": {"channel": "books", "instId": "BTC-USDT"}, "action": "update", "data": [{"asks": [["84064.2", "0.1171", "0", "4"], ["84078.3", "0.03423176", "0", "1"], ["84078.4", "0.03136696", "0", "1"], ["84078.5", "0.21245357", "0", "2"], ["84078.6", "0.11890903", "0", "1"], ["84078.7", "0", "0", "0"], ["84078.8", "0.03323847", "0", "1"], ["84079", "0.17844", "0", "1"], ["84085.1", "0.03197507", "0", "1"], ["84085.3", "0.03429808", "0", "1"], ["84085.7", "0", "0", "0"], ["84087.1", "0.03289693", "0", "1"], ["84087.2", "0.03339062", "0", "1"], ["84087.3", "0", "0", "0"], ["84087.4", "0", "0", "0"], ["84092.3", "0.0629679", "0", "1"], ["84092.7", "0.08297", "0", "1"], ["84093.9", "0.07005525", "0", "1"], ["84094", "0", "0", "0"], ["84094.3", "0.23801701", "0", "1"], ["84094.5", "0.06835897", "0", "1"], ["84094.8", "0", "0", "0"], ["84095.9", "0.0670422", "0", "1"], ["84096", "0", "0", "0"], ["84106", "0", "0", "0"], ["84239.7", "0", "0", "0"], ["84239.8", "0", "0", "0"]], "bids": [["84057.4", "0.17821722", "0", "1"], ["84051.4", "0", "0", "0"], ["84051", "0.03147645", "0", "1"], ["84050.5", "0", "0", "0"], ["84050.4", "1.03118085", "0", "2"], ["84049.9", "0.01251027", "0", "2"], ["84049.8", "0.15502877", "0", "4"], ["84049.6", "0.00475909", "0", "1"], ["84049.4", "0.03210994", "0", "1"], ["84044.4", "0", "0", "0"], ["84044", "0.03281689", "0", "1"], ["84043.3", "0", "0", "0"], ["84043.1", "0.03607849", "0", "2"], ["84041.8", "0", "0", "0"], ["84041.6", "0.04159811", "0", "2"], ["84041.2", "0", "0", "0"], ["84041", "0.03358803", "0", "1"], ["84037.4", "0", "0", "0"], ["84037", "0.06508814", "0", "1"], ["84036.4", "0", "0", "0"], ["84035.9", "0.2380293", "0", "2"], ["84034.5", "0", "0", "0"], ["84034.4", "0.06217873", "0", "1"], ["84033.9", "0", "0", "0"], ["84033.6", "0.06283568", "0", "1"], ["84033", "0", "0", "0"], ["84032.9", "0.06192581", "0", "1"], ["84005", "0", "0", "0"], ["83996.3", "0.00001196", "0", "1"], ["83953.4", "0", "0", "0"], ["83925", "0.00027367", "0", "1"], ["83924.8", "0.00422077", "0", "1"], ["83924.6", "0.00004441", "0", "2"], ["83924.2", "0.000015", "0", "1"], ["83923", "0.00001987", "0", "1"]], "ts": "1742555350209", "checksum": 1502689280, "seqId": 49927598406, "prevSeqId": 49927598340}], "record_time": 1742555350.213907, "EXCHANGE": "OKX"}
{"arg": {"channel": "books", "instId": "BTC-USDT"}, "action": "update", "data": [{"asks": [["84102.4", "0.08", "0", "2"], ["84103.2", "0.03999999", "0", "1"], ["84104", "0", "0", "0"]], "bids": [["84034", "1", "0", "1"], ["83923", "0", "0", "0"]], "ts": "1742555350309", "checksum": 1502689280, "seqId": 49927598412, "prevSeqId": 49927598406}], "record_time": 1742555350.313173, "EXCHANGE": "OKX"}
{"arg": {"channel": "books", "instId": "BTC-USDT"}, "action": "update", "data": [{"asks": [["84084.4", "0.58684659", "0", "2"], ["84084.9", "1.04697", "0", "3"], ["84085.5", "0", "0", "0"], ["84094.3", "0.2380173", "0", "1"], ["84102.4", "0", "0", "0"], ["84103.2", "0.07999999", "0", "2"], ["84104", "0.03999999", "0", "1"], ["84143.2", "0.07130702", "0", "1"], ["84239.7", "0.01652", "0", "1"]], "bids": [["84054.6", "0.31980033", "0", "1"], ["84050.4", "0.03118085", "0", "1"], ["84050", "0.59321943", "0", "6"], ["84049.1", "1", "0", "1"], ["84035.9", "0.23802926", "0", "2"], ["84034.1", "0.01776037", "0", "2"], ["84034", "0", "0", "0"], ["84031.7", "0", "0", "0"], ["83978.3", "0.07144701", "0", "1"], ["83923", "0.00001987", "0", "1"]], "ts": "1742555350409", "checksum": -708786188, "seqId": 49927598455, "prevSeqId": 49927598412}], "record_time": 1742555350.413593, "EXCHANGE": "OKX"}
{"arg": {"channel": "books", "instId": "BTC-USDT"}, "action": "update", "data": [{"asks": [["84094.3", "0", "0", "0"], ["84095.1", "0.23801506", "0", "1"], ["84143.2", "0.14261404", "0", "2"]], "bids": [["84057.9", "0.00564", "0", "1"], ["84036.4", "0.23801506", "0", "1"], ["84035.9", "0.00001196", "0", "1"], ["83978.3", "0.14289402", "0", "2"], ["83924.2", "0", "0", "0"], ["83923", "0", "0", "0"]], "ts": "1742555350509", "checksum": -330238695, "seqId": 49927598482, "prevSeqId": 49927598455}], "record_time": 1742555350.513111, "EXCHANGE": "OKX"}
{"arg": {"channel": "books", "instId": "BTC-USDT"}, "action": "update", "data": [{"asks": [["84095.1", "0", "0", "0"], ["84095.8", "0.2380143", "0", "1"]], "bids": [["84054.6", "0.71501368", "0", "2"], ["84050.8", "1.00001198", "0", "2"], ["84050", "0.22488889", "0", "5"], ["84049.1", "0", "0", "0"], ["84037.1", "0.2380143", "0", "1"], ["84036.4", "0", "0", "0"], ["83924.2", "0.000015", "0", "1"]], "ts": "1742555350609", "checksum": -1779425177, "seqId": 49927598503, "prevSeqId": 49927598482}], "record_time": 1742555350.613618, "EXCHANGE": "OKX"}
{"arg": {"channel": "books", "instId": "BTC-USDT"}, "action": "update", "data": [{"asks": [["84064.2", "0.08", "0", "3"], ["84078.3", "0", "0", "0"], ["84078.4", "0", "0", "0"], ["84078.5", "0.20946", "0", "2"], ["84078.6", "0.15109367", "0", "2"], ["84078.7", "0.03279678", "0", "1"], ["84078.8", "0", "0", "0"], ["84079", "0.21058483", "0", "2"], ["84085.1", "0", "0", "0"], ["84085.3", "0.03120122", "0", "1"], ["84085.7", "0.03238278", "0", "1"], ["84087.1", "0", "0", "0"], ["84087.2", "0", "0", "0"], ["84087.3", "0.03191083", "0", "1"], ["84087.4", "0.03277736", "0", "1"], ["84092.3", "0", "0", "0"], ["84092.7", "0.15144377", "0", "2"], ["84093.9", "0", "0", "0"], ["84094", "0.06376085", "0", "1"], ["84094.5", "0", "0", "0"], ["84094.8", "0.07000194", "0", "1"], ["84095.9", "0", "0", "0"], ["84096", "0.06508785", "0", "1"], ["84107", "0", "0", "0"], ["84239.8", "0.35579296", "0", "1"], ["84240", "0.00003685", "0", "2"], ["84240.1", "0.00001005", "0", "1"], ["84242", "0.0000185", "0", "1"]], "bids": [["84054.6", "0.31980033", "0", "1"], ["84052.4", "1", "0", "1"], ["84051.4", "0.03114515", "0", "1"], ["84051", "0", "0", "0"], ["84050.8", "0.00001198", "0", "1"], ["84050.5", "0.03511234", "0", "1"], ["84050.4", "0", "0", "0"], ["84049.9", "0.04746147", "0", "3"], ["84049.8", "0.1217", "0", "3"], ["84049.6", "0.03913026", "0", "2"], ["84049.4", "0", "0", "0"], ["84044.4", "0.03098215", "0", "1"], ["84044", "0", "0", "0"], ["84043.3", "0.03463941", "0", "1"], ["84043.1", "0.0042087", "0", "1"], ["84041.8", "0.03414549", "0", "1"], ["84041.6", "0.00713932", "0", "1"], ["84041.2", "0.03106315", "0", "1"], ["84041", "0", "0", "0"], ["84037.4", "0.0636374", "0", "1"], ["84037", "0", "0", "0"], ["84034.5", "0.0657903", "0", "1"], ["84034.4", "0", "0", "0"], ["84034.1", "0.00001501", "0", "1"], ["84033.9", "0.06784523", "0", "1"], ["84033.6", "0", "0", "0"], ["84033", "0.06624145", "0", "1"], ["84032.9", "0", "0", "0"], ["84031.7", "0.01774536", "0", "1"], ["84000.1", "2.723401", "0", "1"], ["83988.4", "0.00235659", "0", "1"], ["83946", "0.35579296", "0", "1"], ["83936.2", "0.00359029", "0", "1"], ["83925.2", "0", "0", "0"], ["83925", "0", "0", "0"], ["83924.8", "0", "0", "0"], ["83924.6", "0", "0", "0"], ["83924.2", "0", "0", "0"]], "ts": "1742555350709", "checksum": -273918487, "seqId": 49927598578, "prevSeqId": 49927598503}], "record_time": 1742555350.714102, "EXCHANGE": "OKX"}
{"arg": {"channel": "books", "instId": "BTC-USDT"}, "action": "update", "data": [{"asks": [["84064.2", "0.1171", "0", "4"], ["84078.3", "0.03455049", "0", "1"], ["84078.4", "0.03507863", "0", "1"], ["84078.5", "0.20958787", "0", "2"], ["84078.6", "0.11890903", "0", "1"], ["84078.7", "0", "0", "0"], ["84078.8", "0.03200619", "0", "1"], ["84079", "0.17844", "0", "1"], ["84085.1", "0.03524226", "0", "1"], ["84085.3", "0.03256442", "0", "1"], ["84085.7", "0", "0", "0"], ["84087.1", "0.03337085", "0", "1"], ["84087.2", "0.03172214", "0", "1"], ["84087.3", "0", "0", "0"], ["84087.4", "0", "0", "0"], ["84092.3", "0.0617769", "0", "1"], ["84092.7", "0.08297", "0", "1"], ["84093.9", "0.06785175", "0", "1"], ["84094", "0", "0", "0"], ["84094.5", "0.06845601", "0", "1"], ["84094.8", "0", "0", "0"], ["84095.9", "0.06233685", "0", "1"], ["84096", "0", "0", "0"], ["84240", "0", "0", "0"], ["84240.1", "0", "0", "0"], ["84242", "0", "0", "0"]], "bids": [["84054.6", "0.71609374", "0", "2"], ["84051.4", "0", "0", "0"], ["84051", "0.03390991", "0", "1"], ["84050.5", "0", "0", "0"], ["84050.4", "0.03460128", "0", "1"], ["84049.9", "0.01251027", "0", "2"], ["84049.8", "0.15399792", "0", "4"], ["84049.6", "0.00475909", "0", "1"], ["84049.4", "0.03501561", "0", "1"], ["84044.4", "0", "0", "0"], ["84044", "0.03394097", "0", "1"], ["84043.3", "0", "0", "0"], ["84043.1", "0.03721348", "0", "2"], ["84041.8", "0", "0", "0"], ["84041.6", "0.04024714", "0", "2"], ["84041.2", "0", "0", "0"], ["84041", "0.03169516", "0", "1"], ["84037.4", "0", "0", "0"], ["84037", "0.06238892", "0", "1"], ["84034.5", "0", "0", "0"], ["84034.4", "0.06323635", "0", "1"], ["84033.9", "0", "0", "0"], ["84033.6", "0.0681834", "0", "1"], ["84033", "0", "0", "0"], ["84032.9", "0.0700765", "0", "1"], ["83980.4", "0", "0", "0"], ["83979", "0.01902508", "0", "1"], ["83975.8", "0", "0", "0"], ["83925.2", "0.00011161", "0", "1"], ["83925", "0.00027367", "0", "1"]], "ts": "1742555350809", "checksum": -330798233, "seqId": 49927598659, "prevSeqId": 49927598578}], "record_time": 1742555350.814951, "EXCHANGE": "OKX"}
{"arg": {"channel": "books", "instId": "BTC-USDT"}, "action": "update", "data": [{"asks": [["84064.2", "0.0769", "0", "2"], ["84067.9", "0.07649217", "0", "2"], ["84071.3", "0.2", "0", "1"], ["84078.3", "0", "0", "0"], ["84078.4", "0", "0", "0"], ["84078.5", "0.24380625", "0", "3"], ["84078.6", "0.1518621", "0", "2"], ["84078.8", "0", "0", "0"], ["84079", "0.21015022", "0", "2"], ["84085.1", "0", "0", "0"], ["84085.3", "0.03405815", "0", "1"], ["84085.5", "0.03479862", "0", "1"], ["84087.1", "0", "0", "0"], ["84087.2", "0", "0", "0"], ["84087.3", "0.03507248", "0", "1"], ["84087.4", "0.03112631", "0", "1"], ["84092.3", "0", "0", "0"], ["84092.5", "0.07233791", "0", "2"], ["84093.9", "0", "0", "0"], ["84094", "0.06471248", "0", "1"], ["84094.5", "0", "0", "0"], ["84094.8", "0.06321809", "0", "1"], ["84095.9", "0", "0", "0"], ["84096", "0.06843681", "0", "1"], ["84107.3", "0.24405295", "0", "1"], ["84158.5", "0", "0", "0"], ["84160.4", "0", "0", "0"], ["84240", "0.00003685", "0", "2"], ["84240.1", "0.00001005", "0", "1"], ["84242", "0.0000185", "0", "1"], ["84242.4", "0.00469113", "0", "3"]], "bids": [["84058.3", "0.0007395", "0", "1"], ["84057.9", "0", "0", "0"], ["84052.4", "0", "0", "0"], ["84051.2", "0.03300572", "0", "2"], ["84051", "0", "0", "0"], ["84050.5", "1.03447882", "0", "2"], ["84050.4", "0", "0", "0"], ["84049.9", "0.04616399", "0", "3"], ["84049.8", "0.1217", "0", "3"], ["84049.6", "0.03669151", "0", "2"], ["84049.4", "0", "0", "0"], ["84044.2", "0.03517359", "0", "2"], ["84044", "0", "0", "0"], ["84043.3", "0.03137007", "0", "1"], ["84043.1", "0.0042087", "0", "1"], ["84041.8", "0.0309811", "0", "1"], ["84041.6", "0.00713932", "0", "1"], ["84041.2", "0.03514009", "0", "1"], ["84041", "0", "0", "0"], ["84037.2", "0.0651565", "0", "1"], ["84037", "0", "0", "0"], ["84034.5", "0.06812841", "0", "1"], ["84034.4", "0", "0", "0"], ["84033.9", "0.06833504", "0", "1"], ["84033.6", "0", "0", "0"], ["84033", "0.0676502", "0", "1"], ["84032.9", "0", "0", "0"], ["84024.2", "0.54873984", "0", "3"], ["84000.1", "0", "0", "0"], ["83975.8", "0.37205313", "0", "1"], ["83947.6", "0.03579976", "0", "2"], ["83924.8", "0.00422077", "0", "1"], ["83924.6", "0.00004441", "0", "2"]], "ts": "1742555350909", "checksum": -2110025986, "seqId": 49927598739, "prevSeqId": 49927598659}], "record_time": 1742555350.913985, "EXCHANGE": "OKX"}
{"arg": {"channel": "books", "instId": "BTC-USDT"}, "action": "update", "data": [{"asks": [["84093.1", "0", "0", "0"], ["84242.5", "0.00011938", "0", "1"]], "bids": [["83963.4", "0.00600032", "0", "1"], ["83924.6", "0", "0", "0"]], "ts": "1742555351009", "checksum": -2110025986, "seqId": 49927598750, "prevSeqId": 49927598739}], "record_time": 1742555351.014037, "EXCHANGE": "OKX"}
{"arg": {"channel": "books", "instId": "BTC-USDT"}, "action": "update", "data": [{"asks": [["84091.9", "0.133438", "0", "1"], ["84242.5", "0", "0", "0"]], "bids": [["84018", "0.21188745", "0", "2"]], "ts": "1742555351109", "checksum": -2110025986, "seqId": 49927598755, "prevSeqId": 49927598750}], "record_time": 1742555351.113476, "EXCHANGE": "OKX"}
{"arg": {"channel": "books", "instId": "BTC-USDT"}, "action": "update", "data": [{"asks": [["84064.2", "0.08", "0", "3"], ["84088.9", "0", "0", "0"], ["84091.2", "0", "0", "0"], ["84093.9", "0.23801842", "0", "1"], ["84095.8", "0", "0", "0"], ["84106", "0.2", "0", "1"], ["84117.6", "0.0144576", "0", "1"], ["84120.6", "0", "0", "0"], ["84141.6", "0", "0", "0"], ["84156.5", "0.01425914", "0", "1"], ["84159.3", "0.00118822", "0", "1"], ["84242.5", "0.00011938", "0", "1"]], "bids": [["84041.9", "0.14310487", "0", "1"], ["84039", "0", "0", "0"], ["84037.6", "0.23801583", "0", "1"], ["84037.1", "0", "0", "0"], ["84018", "0.01188745", "0", "1"], ["84012.3", "1.36944896", "0", "2"], ["84009.6", "0", "0", "0"], ["83997.4", "0", "0", "0"], ["83996.5", "0.00105329", "0", "1"], ["83924.6", "0.00004441", "0", "2"], ["83924.2", "0.000015", "0", "1"]], "ts": "1742555351209", "checksum": 129732692, "seqId": 49927598781, "prevSeqId": 49927598755}], "record_time": 1742555351.213623, "EXCHANGE": "OKX"}
{"arg": {"channel": "books", "instId": "BTC-USDT"}, "action": "update", "data": [{"asks": [["84087.6", "0.0054", "0", "1"], ["84094", "1.66842873", "0", "2"], ["84123.4", "2.88675684", "0", "2"], ["84130.9", "0.01774536", "0", "1"], ["84142.6", "0.0019221", "0", "1"], ["84242.4", "0", "0", "0"], ["84242.5", "0", "0", "0"]], "bids": [["84040.7", "1.58200259", "0", "1"], ["84037.6", "0", "0", "0"], ["84036.4", "0.23801619", "0", "1"], ["84011.3", "2.81810066", "0", "1"], ["83924.6", "0", "0", "0"], ["83924.2", "0", "0", "0"]], "ts": "1742555351309", "checksum": 129732692, "seqId": 49927598792, "prevSeqId": 49927598781}], "record_time": 1742555351.313628, "EXCHANGE": "OKX"}
{"arg": {"channel": "books", "instId": "BTC-USDT"}, "action": "update", "data": [{"asks": [["84093.9", "0", "0", "0"], ["84095.9", "0.23801272", "0", "1"], ["84143.2", "0.07130702", "0", "1"], ["84145.7", "0", "0", "0"], ["84145.8", "0", "0", "0"], ["84146.5", "0.00012217", "0", "1"], ["84242.4", "0.00469113", "0", "3"]], "bids": [["84037.6", "0.23801272", "0", "1"], ["84036.4", "0", "0", "0"], ["84034", "1", "0", "1"], ["83997.4", "0.00105327", "0", "1"], ["83996.5", "0", "0", "0"], ["83978.3", "0.07144701", "0", "1"], ["83924.8", "0", "0", "0"]], "ts": "1742555351409", "checksum": 129732692, "seqId": 49927598814, "prevSeqId": 49927598792}], "record_time": 1742555351.413132, "EXCHANGE": "OKX"}
{"arg": {"channel": "books", "instId": "BTC-USDT"}, "action": "update", "data": [{"asks": [["84090.1", "0.01774536", "0", "1"], ["84116.4", "0.58891581", "0", "3"], ["84130.9", "0", "0", "0"], ["84143.2", "0", "0", "0"], ["84149.8", "0.03", "0", "1"], ["84173.1", "0.47231071", "0", "2"], ["84182.8", "0", "0", "0"], ["84191.5", "0.07102314", "0", "1"], ["84199.9", "0.18857973", "0", "8"], ["84208.3", "0", "0", "0"], ["84242.5", "0.00011938", "0", "1"], ["84242.6", "0.00419183", "0", "1"]], "bids": [["84034.1", "0.01776037", "0", "2"], ["84034", "0", "0", "0"], ["84031.7", "0", "0", "0"], ["83978.3", "0", "0", "0"], ["83961", "0", "0", "0"], ["83952.6", "0", "0", "0"], ["83944.1", "0.0142", "0", "1"], ["83935.7", "0", "0", "0"], ["83927.3", "0", "0", "0"], ["83924.8", "0.00422077", "0", "1"], ["83924.6", "0.00004441", "0", "2"], ["83924.2", "0.000015", "0", "1"], ["83923", "0.00001987", "0", "1"], ["83922", "0.00001197", "0", "1"], ["83921.7", "0.0535785", "0", "1"], ["83921.3", "0.0016853", "0", "2"]], "ts": "1742555351509", "checksum": 129732692, "seqId": 49927598839, "prevSeqId": 49927598814}], "record_time": 1742555351.513409, "EXCHANGE": "OKX"}
{"arg": {"channel": "books", "instId": "BTC-USDT"}, "action": "update", "data": [{"asks": [["84064.2", "0.08001533", "0", "4"], ["84071.4", "0.016", "0", "1"], ["84092.6", "0.23801676", "0", "1"], ["84095.9", "0", "0", "0"], ["84143.2", "0.07130702", "0", "1"], ["84242.6", "0", "0", "0"]], "bids": [["84054.6", "0.31980033", "0", "1"], ["84050.5", "0.03447882", "0", "1"], ["84050", "0.59326366", "0", "6"], ["84049.2", "1", "0", "1"], ["84037.6", "0", "0", "0"], ["84036.4", "0.23801676", "0", "1"], ["83978.3", "0.07144701", "0", "1"], ["83921.7", "0", "0", "0"], ["83921.3", "0", "0", "0"]], "ts": "1742555351609", "checksum": -1111787447, "seqId": 49927598858, "prevSeqId": 49927598839}], "record_time": 1742555351.613474, "EXCHANGE": "OKX"}
{"arg": {"channel": "books", "instId": "BTC-USDT"}, "action": "update", "data": [{"asks": [["84092.6", "0", "0", "0"], ["84093.9", "0.23801447", "0", "1"], ["84106", "0", "0", "0"], ["84107", "1", "0", "1"], ["84143.2", "0.14261404", "0", "2"]], "bids": [["84037.6", "0.23801447", "0", "1"], ["84036.4", "0", "0", "0"], ["84034.1", "0.00001501", "0", "1"], ["84031.7", "0.01774536", "0", "1"], ["83978.3", "0.14289402", "0", "2"], ["83922", "0", "0", "0"]], "ts": "1742555351709", "checksum": -1111787447, "seqId": 49927598874, "prevSeqId": 49927598858}], "record_time": 1742555351.713409, "EXCHANGE": "OKX"}
{"arg": {"channel": "books", "instId": "BTC-USDT"}, "action": "update", "data": [{"asks": [["84107", "0", "0", "0"], ["84242.6", "0.00419183", "0", "1"]], "bids": [["84037.6", "0", "0", "0"], ["84036.4", "0.2380156", "0", "1"]], "ts": "1742555351809", "checksum": -1111787447, "seqId": 49927598879, "prevSeqId": 49927598874}], "record_time": 1742555351.813514, "EXCHANGE": "OKX"}
{"arg": {"channel": "books", "instId": "BTC-USDT"}, "action": "update", "data": [{"asks": [["84093", "0.80730184", "0", "2"], ["84103.2", "0", "0", "0"], ["84104", "0.07999999", "0", "2"], ["84104.8", "0.27734647", "0", "3"], ["84122.6", "1.0916778", "0", "2"], ["84143.2", "0.07130702", "0", "1"], ["84244.1", "0.08393921", "0", "3"]], "bids": [["84054.6", "0.71644152", "0", "2"], ["84050.5", "1.03447882", "0", "2"], ["84050", "0.22488889", "0", "5"], ["84049.2", "0", "0", "0"], ["84041.9", "0.64908405", "0", "2"], ["84000.1", "2.87290178", "0", "1"], ["83978.3", "0.07144701", "0", "1"]], "ts": "1742555351909", "checksum": 25437473, "seqId": 49927598898, "prevSeqId": 49927598879}], "record_time": 1742555351.916228, "EXCHANGE": "OKX"}
{"arg": {"channel": "books", "instId": "BTC-USDT"}, "action": "update", "data": [{"asks": [["84064.2", "0.11711533", "0", "5"], ["84076.4", "0.01190007", "0", "1"], ["84078.3", "0.03303751", "0", "1"], ["84078.4", "0.03477905", "0", "1"], ["84078.5", "0.20971542", "0", "2"], ["84078.6", "0.11890903", "0", "1"], ["84078.8", "0.03168153", "0", "1"], ["84079", "0.17844", "0", "1"], ["84084.9", "0.04697", "0", "2"], ["84085.1", "0.03540993", "0", "1"], ["84085.3", "0.03250349", "0", "1"], ["84085.5", "0", "0", "0"], ["84086.8", "1", "0", "1"], ["84087.1", "0.03491939", "0", "1"], ["84087.2", "0.0322989", "0", "1"], ["84087.3", "0", "0", "0"], ["84087.4", "0", "0", "0"], ["84092.3", "0.06897341", "0", "1"], ["84092.5", "0.01", "0", "1"], ["84092.6", "0.23801717", "0", "1"], ["84093.9", "0.06890965", "0", "1"], ["84094", "1.60371625", "0", "1"], ["84094.5", "0.07044544", "0", "1"], ["84094.8", "0", "0", "0"], ["84095.9", "0.06208259", "0", "1"], ["84096", "0", "0", "0"], ["84130.2", "0", "0", "0"], ["84131.3", "0.01130836", "0", "1"], ["84143.2", "0.14261404", "0", "2"], ["84225.2", "0", "0", "0"], ["84242", "0", "0", "0"], ["84242.4", "0", "0", "0"], ["84242.5", "0", "0", "0"], ["84242.6", "0", "0", "0"], ["84244.1", "0", "0", "0"]], "bids": [["84054.6", "0.31980033", "0", "1"], ["84051.2", "0.00006777", "0", "1"], ["84051", "0.03261213", "0", "1"], ["84050.9", "0.000015", "0", "1"], ["84050.5", "0", "0", "0"], ["84050.4", "0.03421799", "0", "1"], ["84050", "0.59378831", "0", "6"], ["84049.9", "0.01251027", "0", "2"], ["84049.8", "0.15666918", "0", "4"], ["84049.6", "0.00475909", "0", "1"], ["84049.4", "0.0323658", "0", "1"], ["84049.2", "1", "0", "1"], ["84044.2", "0.00350877", "0", "1"], ["84044", "0.032725", "0", "1"], ["84043.3", "0", "0", "0"], ["84043.1", "0.03961572", "0", "2"], ["84041.8", "0", "0", "0"], ["84041.6", "0.04083498", "0", "2"], ["84041.2", "0", "0", "0"], ["84041", "0.03440253", "0", "1"], ["84037.2", "0", "0", "0"], ["84037", "0.06590579", "0", "1"], ["84036.4", "0.2380165", "0", "1"], ["84034.5", "0", "0", "0"], ["84034.4", "0.07059423", "0", "1"], ["84033.9", "0", "0", "0"], ["84033.6", "0.07003543", "0", "1"], ["84033", "0", "0", "0"], ["84032.9", "0.06553029", "0", "1"], ["84014.4", "0.01832719", "0", "1"], ["84012.8", "0", "0", "0"], ["83978.3", "0.14289402", "0", "2"], ["83943.3", "0.18327198", "0", "1"], ["83942.3", "0", "0", "0"], ["83924.2", "0", "0", "0"], ["83923", "0", "0", "0"]], "ts": "1742555352009", "checksum": -130729300, "seqId": 49927598987, "prevSeqId": 49927598898}], "record_time": 1742555352.013774, "EXCHANGE": "OKX"}
{"arg": {"channel": "books", "instId": "BTC-USDT"}, "action": "update", "data": [{"asks": [["84064.2", "0.45619199", "0", "9"], ["84064.5", "0.04365975", "0", "1"], ["84064.6", "0.11901326", "0", "1"], ["84066.4", "0", "0", "0"], ["84066.5", "0", "0", "0"], ["84074.5", "0.01032", "0", "1"], ["84076.7", "0", "0", "0"], ["84077.5", "0.03301604", "0", "1"], ["84077.8", "0.03418208", "0", "1"], ["84077.9", "0.03462104", "0", "1"], ["84078.1", "0.03207744", "0", "1"], ["84078.3", "0", "0", "0"], ["84078.4", "0", "0", "0"], ["84078.5", "0.17821722", "0", "1"], ["84078.8", "0", "0", "0"], ["84080.5", "0.03097", "0", "1"], ["84084.4", "0.38621306", "0", "2"], ["84084.5", "0.03245045", "0", "1"], ["84084.9", "0.016", "0", "1"], ["84085.1", "0", "0", "0"], ["84085.3", "1", "0", "1"], ["84086.5", "0.03117479", "0", "1"], ["84086.6", "0.03110678", "0", "1"], ["84086.7", "0.01774536", "0", "1"], ["84086.8", "0", "0", "0"], ["84087.1", "0", "0", "0"], ["84087.2", "0", "0", "0"], ["84090.1", "0", "0", "0"], ["84091.5", "0.20681313", "0", "2"], ["84092.3", "0", "0", "0"], ["84092.6", "0.23801669", "0", "1"], ["84093.3", "0.068247", "0", "1"], ["84093.9", "0.06651374", "0", "1"], ["84094.5", "0", "0", "0"], ["84095.3", "0.063842", "0", "2"], ["84095.9", "0", "0", "0"], ["84103.2", "0.08", "0", "2"], ["84104", "0.03999999", "0", "1"], ["84104.8", "0.23734648", "0", "2"], ["84141.6", "0.0019221", "0", "1"], ["84142.6", "0", "0", "0"], ["84156.5", "0", "0", "0"], ["84157.4", "0.00118824", "0", "1"], ["84159.3", "0", "0", "0"], ["84242", "0.0000185", "0", "1"]], "bids": [["84064.1", "1.06792009", "0", "12"], ["84063.5", "0", "0", "0"], ["84061.2", "0.0137", "0", "1"], ["84059.1", "0", "0", "0"], ["84058.3", "0", "0", "0"], ["84054.6", "0.36091033", "0", "2"], ["84051", "0", "0", "0"], ["84050.4", "0", "0", "0"], ["84050.2", "0.03621027", "0", "2"], ["84050", "0.22488889", "0", "5"], ["84049.8", "0.15290129", "0", "4"], ["84049.4", "0", "0", "0"], ["84049.2", "0.03170977", "0", "1"], ["84048.7", "0.2101526", "0", "3"], ["84047.1", "1", "0", "1"], ["84046.1", "0.55815483", "0", "2"], ["84044", "0", "0", "0"], ["84043.2", "0.03437034", "0", "1"], ["84043.1", "0.0042087", "0", "1"], ["84042.4", "0.03467722", "0", "2"], ["84041.6", "0.00713932", "0", "1"], ["84041", "0.03480758", "0", "1"], ["84040.4", "0.03418126", "0", "1"], ["84037", "0", "0", "0"], ["84036.4", "0", "0", "0"], ["84036.2", "0.59687564", "0", "2"], ["84034.4", "0", "0", "0"], ["84033.9", "0.2380192", "0", "1"], ["84033.8", "0.07066628", "0", "2"], ["84033.6", "0", "0", "0"], ["84033", "0.07046583", "0", "1"], ["84032.9", "0", "0", "0"], ["84032.3", "0.06412243", "0", "1"], ["83988.4", "0", "0", "0"], ["83979", "0", "0", "0"], ["83936.2", "0", "0", "0"], ["83924.2", "0.000015", "0", "1"], ["83923", "0.00001987", "0", "1"], ["83922", "0.00001197", "0", "1"], ["83921.7", "0.0535785", "0", "1"], ["83921.3", "0.0016853", "0", "2"], ["83921", "0.00001002", "0", "1"], ["83920.8", "0.2025", "0", "1"], ["83920", "0.00001096", "0", "1"]], "ts": "1742555352109", "checksum": -1203382123, "seqId": 49927599110, "prevSeqId": 49927598987}], "record_time": 1742555352.114151, "EXCHANGE": "OKX"}
{"arg": {"channel": "books", "instId": "BTC-USDT"}, "action": "update", "data": [{"asks": [["84085.3", "0", "0", "0"], ["84085.6", "1.14043766", "0", "2"], ["84090.8", "0.23802053", "0", "1"], ["84092.6", "0", "0", "0"], ["84102.4", "0.08", "0", "2"], ["84103.2", "0.03999999", "0", "1"], ["84104", "0", "0", "0"], ["84130.2", "0.01130849", "0", "1"], ["84131.3", "0", "0", "0"], ["84157.4", "0.01544723", "0", "2"], ["84242.4", "0.01062947", "0", "4"]], "bids": [["84064.1", "0.92864809", "0", "10"], ["84055.8", "0.0000165", "0", "1"], ["84050", "0.60202375", "0", "6"], ["84046.1", "0.2567382", "0", "1"], ["84018", "0.21188745", "0", "2"], ["84014.4", "0", "0", "0"], ["84012.8", "0.01832781", "0", "1"], ["83997", "0.00235641", "0", "1"], ["83984.9", "1.39739591", "0", "2"], ["83944.9", "0.00938973", "0", "2"], ["83943.3", "0", "0", "0"], ["83942.3", "0.18327812", "0", "1"], ["83920.8", "0", "0", "0"], ["83920", "0", "0", "0"]], "ts": "1742555352209", "checksum": -1959992307, "seqId": 49927599143, "prevSeqId": 49927599110}], "record_time": 1742555352.214476, "EXCHANGE": "OKX"}
{"arg": {"channel": "books", "instId": "BTC-USDT"}, "action": "update", "data": [{"asks": [["84064.2", "0.45500362", "0", "9"], ["84086.7", "0", "0", "0"], ["84090.1", "0.01774536", "0", "1"], ["84102.4", "0", "0", "0"], ["84103.2", "0.07999999", "0", "2"], ["84104", "0.03999999", "0", "1"]], "bids": [["84064.1", "0.87149009", "0", "10"], ["84049.8", "1.15290129", "0", "5"], ["84047.1", "0", "0", "0"], ["84018", "0.01188745", "0", "1"], ["83920.8", "0.2025", "0", "1"]], "ts": "1742555352309", "checksum": -372935175, "seqId": 49927599160, "prevSeqId": 49927599143}], "record_time": 1742555352.313325, "EXCHANGE": "OKX"}
{"arg": {"channel": "books", "instId": "BTC-USDT"}, "action": "update", "data": [{"asks": [["84064.2", "0.52034362", "0", "10"], ["84072.3", "0.01032", "0", "1"], ["84074.5", "0", "0", "0"], ["84087.4", "0.23802966", "0", "1"], ["84090.8", "0", "0", "0"], ["84102.4", "0.08", "0", "2"], ["84103.2", "0.03999999", "0", "1"], ["84104", "0", "0", "0"], ["84173.1", "0.47529737", "0", "3"], ["84182.7", "0.00597332", "0", "1"], ["84191.2", "0.00895999", "0", "1"], ["84199.6", "0.01195861", "0", "2"], ["84208", "0.01493332", "0", "1"], ["84240.1", "0", "0", "0"], ["84242", "0", "0", "0"], ["84242.4", "0", "0", "0"]], "bids": [["84064.1", "0.66091673", "0", "9"], ["84061.2", "0", "0", "0"], ["84058.8", "0.0137", "0", "1"], ["84053.8", "0", "0", "0"], ["84053.5", "0", "0", "0"], ["84050", "0.22488889", "0", "5"], ["84049.8", "0.15290129", "0", "4"], ["84049.3", "0", "0", "0"], ["84046.1", "0.50462283", "0", "2"], ["84046", "1", "0", "1"], ["84045.9", "0", "0", "0"], ["84033.9", "0", "0", "0"], ["84031.1", "0.25587966", "0", "2"], ["84007.3", "0.24981", "0", "1"], ["83960.7", "0.00298666", "0", "1"], ["83952.3", "0.00597332", "0", "1"], ["83943.8", "0.01490774", "0", "2"], ["83935.4", "0.01194665", "0", "1"], ["83927", "0.03277657", "0", "4"]], "ts": "1742555352409", "checksum": 155158907, "seqId": 49927599197, "prevSeqId": 49927599160}], "record_time": 1742555352.416222, "EXCHANGE": "OKX"}
{"arg": {"channel": "books", "instId": "BTC-USDT"}, "action": "update", "data": [{"asks": [], "bids": [["84064.1", "0.64307473", "0", "8"], ["84050", "0.52708075", "0", "6"], ["84047.3", "1", "0", "1"], ["84046.1", "0.2567382", "0", "1"], ["84046", "0", "0", "0"], ["84022", "1.00001", "0", "2"], ["84007.5", "0.1249", "0", "1"], ["83920.8", "0", "0", "0"]], "ts": "1742555352509", "checksum": 1973644245, "seqId": 49927599206, "prevSeqId": 49927599197}], "record_time": 1742555352.513897, "EXCHANGE": "OKX"}
{"arg": {"channel": "books", "instId": "BTC-USDT"}, "action": "update", "data": [{"asks": [], "bids": [["84048.7", "0.3885926", "0", "4"], ["84045.9", "0.35687", "0", "1"], ["84036.3", "0", "0", "0"], ["84033.3", "0.30436534", "0", "4"], ["84022", "0.00001", "0", "1"], ["83933.2", "0.01188753", "0", "1"], ["83932.5", "0", "0", "0"]], "ts": "1742555352609", "checksum": 1973644245, "seqId": 49927599215, "prevSeqId": 49927599206}], "record_time": 1742555352.613979, "EXCHANGE": "OKX"}
