{"arg": {"channel": "books", "instId": "BTC-USDT"}, "action": "update", "data": [{"asks": [["88538", "0.49804936", "0", "12"], ["88539.7", "0", "0", "0"], ["88539.9", "0.01246809", "0", "3"], ["88540.2", "0.00007853", "0", "1"], ["88540.6", "0.01353", "0", "1"], ["88540.8", "0.0001", "0", "1"], ["88541.2", "0.0001", "0", "1"], ["88544", "0.04994726", "0", "3"], ["88545.4", "0.02932442", "0", "5"], ["88545.6", "0.02922347", "0", "1"], ["88545.8", "0.02594604", "0", "1"], ["88546.1", "0.02590603", "0", "1"], ["88546.2", "0.20540139", "0", "1"], ["88546.3", "0.06036982", "0", "3"], ["88546.5", "0.00001", "0", "1"], ["88546.8", "0.00019039", "0", "1"], ["88546.9", "0.00112749", "0", "1"], ["88547.7", "0.01161485", "0", "2"], ["88548.6", "0.10082306", "0", "3"], ["88549.1", "0.08895554", "0", "1"], ["88549.7", "0.08940485", "0", "1"], ["88549.8", "0.07767138", "0", "1"], ["88550.2", "0.11685302", "0", "2"], ["88550.3", "0.08675596", "0", "1"], ["88551.5", "0", "0", "0"], ["88551.9", "0.012102", "0", "1"], ["88552.1", "0.00137118", "0", "1"], ["88552.8", "0.13154012", "0", "2"], ["88553.3", "0.14682508", "0", "1"], ["88554.8", "0.14537778", "0", "2"], ["88555.4", "0.00225374", "0", "1"], ["88555.9", "0.14988527", "0", "1"], ["88567.2", "0.000015", "0", "1"], ["88569.6", "0.22589402", "0", "1"], ["88576.8", "0.77611035", "0", "3"], ["88579.9", "1.67872257", "0", "3"], ["88604", "0.00001042", "0", "1"], ["88604.8", "0.01739331", "0", "1"], ["88625.1", "0", "0", "0"], ["88625.5", "0", "0", "0"], ["88625.6", "0", "0", "0"], ["88625.9", "0", "0", "0"], ["88626", "0", "0", "0"], ["88626.1", "0", "0", "0"], ["88626.2", "0", "0", "0"], ["88626.3", "0", "0", "0"]], "bids": [["88537.9", "0.17238155", "0", "6"], ["88534.7", "0.01357284", "0", "1"], ["88533", "0.0001", "0", "1"], ["88532.8", "0.0001", "0", "1"], ["88532.6", "0", "0", "0"], ["88532.5", "0.00145491", "0", "1"], ["88528.2", "0.02718266", "0", "1"], ["88528.1", "0.06772765", "0", "2"], ["88528", "0.32951878", "0", "4"], ["88527.7", "0.05520178", "0", "2"], ["88527.4", "0", "0", "0"], ["88527.1", "0.0194028", "0", "1"], ["88526.5", "0", "0", "0"], ["88525.5", "0.00942", "0", "1"], ["88524.4", "0.0848818", "0", "2"], ["88524.2", "0.07334352", "0", "1"], ["88523.7", "0", "0", "0"], ["88523.6", "0.38233482", "0", "3"], ["88522.8", "0", "0", "0"], ["88522", "0.0163", "0", "1"], ["88521.2", "0.12177268", "0", "1"], ["88520.6", "0.36757724", "0", "2"], ["88520.3", "0.13594519", "0", "1"], ["88519.2", "0.10742966", "0", "2"], ["88519.1", "0.14185744", "0", "2"], ["88517.4", "0.14228414", "0", "1"], ["88516.8", "0.000168", "0", "1"], ["88512.6", "1.67086511", "0", "1"], ["88510.4", "0.11064436", "0", "2"], ["88509.9", "0.22589362", "0", "1"], ["88509.8", "0.02698183", "0", "1"], ["88506.4", "0.00029911", "0", "1"], ["88481.8", "0.01739331", "0", "1"], ["88480.7", "0", "0", "0"], ["88456.5", "0.34795575", "0", "3"], ["88405.5", "0.17394451", "0", "2"], ["88293.4", "0", "0", "0"], ["88292.4", "0", "0", "0"], ["88292.3", "0", "0", "0"], ["88292", "0", "0", "0"], ["88291", "0", "0", "0"], ["88290", "0", "0", "0"]], "ts": "1741338240305", "checksum": -1110300031, "seqId": 48070594043, "prevSeqId": 48070593776}]}
{"arg": {"channel": "books", "instId": "BTC-USDT"}, "action": "update", "data": [{"asks": [["88538", "0.47864936", "0", "11"], ["88540.8", "0.000021", "0", "1"], ["88541.2", "0.0002", "0", "2"], ["88545.4", "0.00013356", "0", "4"], ["88545.5", "0.02983108", "0", "2"], ["88546.1", "0", "0", "0"], ["88546.2", "0.23491617", "0", "2"], ["88546.8", "0.00023539", "0", "2"], ["88547.7", "0.00738035", "0", "1"], ["88549.1", "0", "0", "0"], ["88549.2", "0.08784398", "0", "1"], ["88549.7", "0", "0", "0"], ["88549.8", "0.15767452", "0", "2"], ["88551.8", "0.01211297", "0", "2"], ["88551.9", "0", "0", "0"], ["88554.8", "0.015", "0", "1"], ["88554.9", "0.14158564", "0", "1"], ["88555.9", "0", "0", "0"], ["88556", "0.13843128", "0", "2"], ["88569.6", "0", "0", "0"], ["88571.5", "0.22614935", "0", "4"], ["88602", "0.11739348", "0", "2"], ["88604.8", "0", "0", "0"], ["88625.1", "0.0003639", "0", "1"], ["88625.5", "0.03920011", "0", "1"], ["88625.6", "0.00570108", "0", "1"], ["88625.9", "0.11344277", "0", "2"], ["88626", "0.00570108", "0", "1"]], "bids": [["88533.3", "0.0002", "0", "2"], ["88533", "0", "0", "0"], ["88532.8", "0", "0", "0"], ["88528.2", "0.05718621", "0", "2"], ["88528.1", "0.04", "0", "1"], ["88527.8", "0.0538835", "0", "2"], ["88527.7", "0", "0", "0"], ["88525.5", "0.03640183", "0", "2"], ["88519.2", "0.21193028", "0", "1"], ["88517.5", "0.14631362", "0", "1"], ["88517.4", "0", "0", "0"], ["88514.8", "0.24239369", "0", "2"], ["88510.4", "0.03975045", "0", "1"], ["88509.9", "0", "0", "0"], ["88509.8", "0", "0", "0"], ["88481.8", "0", "0", "0"], ["88478.9", "0.01739348", "0", "1"], ["88405.5", "0.00001139", "0", "1"], ["88403.5", "0.17393483", "0", "1"], ["88307.6", "0.00282425", "0", "1"], ["88293.4", "0.04093218", "0", "1"]], "ts": "1741338240405", "checksum": -1569769233, "seqId": 48070594115, "prevSeqId": 48070594043}]}
{"arg": {"channel": "books", "instId": "BTC-USDT"}, "action": "update", "data": [{"asks": [["88547.4", "0.0000135", "0", "1"], ["88551", "0.01213651", "0", "3"], ["88551.8", "0.00001097", "0", "1"], ["88571.5", "0.22614936", "0", "4"], ["88575.1", "0.00363681", "0", "2"], ["88581.7", "0.00019458", "0", "5"], ["88626", "0", "0", "0"]], "bids": [["88533.3", "0", "0", "0"], ["88533.2", "0.0002", "0", "2"], ["88521.2", "0.12178381", "0", "2"], ["88519.2", "0.15759208", "0", "1"], ["88514.8", "0.24239308", "0", "2"]], "ts": "1741338240505", "checksum": 1261652729, "seqId": 48070594145, "prevSeqId": 48070594115}]}
{"arg": {"channel": "books", "instId": "BTC-USDT"}, "action": "update", "data": [{"asks": [["88550.9", "0.012102", "0", "1"], ["88551", "0.00003451", "0", "2"], ["88625.9", "0", "0", "0"]], "bids": [["88537.9", "0.17239155", "0", "7"]], "ts": "1741338240605", "checksum": -479282201, "seqId": 48070594158, "prevSeqId": 48070594145}]}
{"arg": {"channel": "books", "instId": "BTC-USDT"}, "action": "update", "data": [{"asks": [["88538", "0.51157936", "0", "13"], ["88539.9", "0.00086598", "0", "2"], ["88540.4", "0.0002", "0", "2"], ["88540.6", "0", "0", "0"], ["88541.2", "0", "0", "0"], ["88543.2", "0.07738481", "0", "1"], ["88544", "0.00084248", "0", "2"], ["88544.1", "0.10089972", "0", "4"], ["88545.5", "0.00001035", "0", "1"], ["88545.6", "0", "0", "0"], ["88545.8", "0", "0", "0"], ["88546.2", "0.20540139", "0", "1"], ["88546.9", "0.20812749", "0", "2"], ["88548.6", "0", "0", "0"], ["88549.2", "0", "0", "0"], ["88549.8", "0", "0", "0"], ["88550.2", "0", "0", "0"], ["88550.3", "0", "0", "0"], ["88550.4", "0.15890717", "0", "2"], ["88550.7", "0.01213858", "0", "2"], ["88550.9", "0", "0", "0"], ["88552.8", "0.00001007", "0", "1"], ["88553.3", "0", "0", "0"], ["88554.9", "0", "0", "0"], ["88556", "0.00001349", "0", "1"], ["88564", "0.42121111", "0", "2"], ["88564.1", "1", "0", "1"], ["88565.4", "0", "0", "0"], ["88565.9", "0.03619784", "0", "2"], ["88571.5", "0.22614983", "0", "4"], ["88573.6", "0", "0", "0"], ["88585.2", "0.21195151", "0", "2"], ["88587.4", "0.49752432", "0", "6"], ["88589.9", "0.40581415", "0", "1"], ["88590.6", "0.497796", "0", "1"], ["88593.5", "0", "0", "0"], ["88596.7", "0.00001016", "0", "1"], ["88605.3", "0.00569815", "0", "1"], ["88606.1", "0.01128591", "0", "1"], ["88625.9", "0.11344277", "0", "2"], ["88626", "0.00570108", "0", "1"], ["88626.1", "0.03", "0", "1"], ["88626.2", "0.03", "0", "1"], ["88626.3", "0.36929724", "0", "2"], ["88626.4", "0.0399405", "0", "1"], ["88626.5", "0.01358534", "0", "2"], ["88626.6", "0.74641525", "0", "2"], ["88626.9", "0.00013978", "0", "2"]], "bids": [["88537.9", "0.04246244", "0", "5"], ["88537.3", "0", "0", "0"], ["88536", "0", "0", "0"], ["88533.5", "0.11294929", "0", "1"], ["88533.2", "0", "0", "0"], ["88532.5", "0", "0", "0"], ["88532.4", "0", "0", "0"], ["88530.2", "0.00145491", "0", "1"], ["88530.1", "0.03623509", "0", "2"], ["88528.8", "0", "0", "0"], ["88528.2", "0", "0", "0"], ["88528", "0.05687557", "0", "4"], ["88527.9", "0.00744165", "0", "2"], ["88527.8", "0", "0", "0"], ["88527.2", "0", "0", "0"], ["88527", "0", "0", "0"], ["88526.8", "0.0001", "0", "1"], ["88525.5", "0", "0", "0"], ["88525.2", "0", "0", "0"], ["88524.4", "0.00001138", "0", "1"], ["88524.2", "0", "0", "0"], ["88523.6", "0.20790314", "0", "1"], ["88522.8", "0.00942", "0", "1"], ["88521.2", "0.00001113", "0", "1"], ["88521.1", "0", "0", "0"], ["88520.6", "0.33929724", "0", "1"], ["88520.3", "0", "0", "0"], ["88519.2", "0.29714381", "0", "2"], ["88519.1", "0.00851121", "0", "1"], ["88517.5", "0", "0", "0"], ["88517.1", "0.22588954", "0", "1"], ["88516.8", "0", "0", "0"], ["88516.1", "0.02828", "0", "1"], ["88514.8", "0.01650401", "0", "1"], ["88506.1", "0.02698183", "0", "1"], ["88503.7", "0", "0", "0"], ["88503.2", "0", "0", "0"], ["88502.7", "0", "0", "0"], ["88501.6", "0.24023527", "0", "2"], ["88500.3", "0.04517915", "0", "1"], ["88497.5", "0.02671259", "0", "1"], ["88497.2", "0.498321", "0", "1"], ["88494.9", "0.03521033", "0", "1"], ["88490.1", "0", "0", "0"], ["88484.5", "0", "0", "0"], ["88483.6", "0.36174135", "0", "2"], ["88483.5", "0.49797", "0", "1"], ["88482.9", "0", "0", "0"], ["88482", "0.01128591", "0", "1"], ["88452.1", "0.30659113", "0", "2"], ["88292.4", "0.00001139", "0", "1"], ["88292.3", "0.00002159", "0", "1"], ["88292", "0.0025", "0", "1"], ["88291", "0.005", "0", "2"], ["88290", "0.00001172", "0", "1"], ["88289.4", "0.03", "0", "1"], ["88287.1", "0.03", "0", "1"], ["88287", "0.03", "0", "1"], ["88286.3", "0.03", "0", "1"], ["88284.9", "0.08542891", "0", "1"]], "ts": "1741338240705", "checksum": 778508760, "seqId": 48070594421, "prevSeqId": 48070594158}]}
{"arg": {"channel": "books", "instId": "BTC-USDT"}, "action": "update", "data": [{"asks": [["88525.9", "0.45428978", "0", "13"], ["88526", "0.16128496", "0", "4"], ["88526.5", "0.08542891", "0", "1"], ["88529.7", "0.0002", "0", "2"], ["88530.1", "0.01129587", "0", "1"], ["88531.9", "0.06023306", "0", "2"], ["88532", "0.0171", "0", "1"], ["88532.6", "0.20231246", "0", "1"], ["88533.2", "0.00559818", "0", "1"], ["88533.3", "0.00057148", "0", "1"], ["88533.4", "0.47012258", "0", "1"], ["88533.6", "0.90244663", "0", "1"], ["88533.7", "0.012102", "0", "1"], ["88534", "0.0171", "0", "1"], ["88534.7", "0.00004771", "0", "1"], ["88534.8", "0.29112", "0", "2"], ["88535.7", "0.00001138", "0", "1"], ["88536", "0.0171", "0", "1"], ["88536.7", "0.33929724", "0", "1"], ["88537.8", "0.476958", "0", "2"], ["88537.9", "0.01888533", "0", "1"], ["88538", "0.78835053", "0", "8"], ["88538.1", "0.00007794", "0", "3"], ["88540.4", "0", "0", "0"], ["88540.6", "1", "0", "1"], ["88540.8", "0.00001501", "0", "1"], ["88540.9", "0.00006", "0", "1"], ["88541.3", "0.00001138", "0", "1"], ["88541.4", "0.24173492", "0", "1"], ["88541.5", "0.26597785", "0", "3"], ["88542", "0.16591186", "0", "2"], ["88543.1", "0.11474824", "0", "2"], ["88543.2", "0", "0", "0"], ["88543.4", "0.12925845", "0", "3"], ["88543.7", "0.00735281", "0", "2"], ["88543.9", "0.01365817", "0", "2"], ["88544.1", "0.04066666", "0", "2"], ["88544.5", "0.02030917", "0", "2"], ["88545", "0", "0", "0"], ["88545.1", "0.00001083", "0", "1"], ["88545.4", "0.08556247", "0", "5"], ["88546", "0.53149365", "0", "4"], ["88546.1", "0.90244663", "0", "1"], ["88546.2", "0", "0", "0"], ["88546.3", "0.00013676", "0", "1"], ["88546.5", "0.11294282", "0", "2"], ["88546.8", "0.00019039", "0", "1"], ["88546.9", "0.207", "0", "1"], ["88547.3", "0", "0", "0"], ["88547.4", "0", "0", "0"], ["88547.8", "0.01358574", "0", "2"], ["88548.4", "0.11295778", "0", "3"], ["88550", "0.01549307", "0", "10"], ["88550.1", "0.04", "0", "1"], ["88550.4", "0", "0", "0"], ["88550.7", "0.00003658", "0", "1"], ["88551.7", "0", "0", "0"], ["88554.4", "0.28773947", "0", "2"], ["88555.4", "0", "0", "0"], ["88558.2", "0.00574872", "0", "2"], ["88558.4", "0.02259853", "0", "2"], ["88558.5", "0", "0", "0"], ["88559.6", "0.90244663", "0", "1"], ["88560.4", "0.08574532", "0", "3"], ["88560.6", "0.147132", "0", "2"], ["88560.8", "0", "0", "0"], ["88561.7", "0", "0", "0"], ["88564", "0.06857764", "0", "2"], ["88564.1", "0", "0", "0"], ["88565.5", "0.0000112", "0", "1"], ["88565.9", "0.0000114", "0", "1"], ["88566.1", "0", "0", "0"], ["88567.3", "0", "0", "0"], ["88571.5", "0.00026029", "0", "3"], ["88579", "0.12276168", "0", "8"], ["88580", "0.03", "0", "1"], ["88581", "0.00017534", "0", "2"], ["88584", "0.11403045", "0", "3"], ["88584.8", "0.000315", "0", "2"], ["88585.6", "0", "0", "0"], ["88587.4", "0.00013832", "0", "5"], ["88589", "0.06805171", "0", "2"], ["88590", "0.00001453", "0", "1"], ["88590.6", "0", "0", "0"], ["88596.6", "0", "0", "0"], ["88597.2", "0.01128704", "0", "1"], ["88597.7", "0.0225786", "0", "2"], ["88599.5", "0.06666822", "0", "1"], ["88602", "0.01739348", "0", "1"], ["88604.9", "0", "0", "0"], ["88605.9", "0.04518421", "0", "1"], ["88606.1", "0", "0", "0"], ["88606.9", "0.00052479", "0", "1"], ["88613.1", "0.0225921", "0", "1"], ["88623.9", "0", "0", "0"], ["88624.2", "0.01134044", "0", "5"], ["88625.5", "0", "0", "0"], ["88625.6", "0", "0", "0"], ["88625.9", "0", "0", "0"], ["88626", "0", "0", "0"], ["88626.1", "0", "0", "0"], ["88626.2", "0", "0", "0"], ["88626.3", "0", "0", "0"], ["88626.4", "0", "0", "0"], ["88626.5", "0", "0", "0"], ["88626.6", "0", "0", "0"], ["88626.9", "0", "0", "0"]], "bids": [["88537.9", "0", "0", "0"], ["88534.7", "0", "0", "0"], ["88534", "0", "0", "0"], ["88533.5", "0", "0", "0"], ["88532.2", "0", "0", "0"], ["88532", "0", "0", "0"], ["88530.2", "0", "0", "0"], ["88530.1", "0", "0", "0"], ["88530", "0", "0", "0"], ["88529.5", "0", "0", "0"], ["88529.1", "0", "0", "0"], ["88528.9", "0", "0", "0"], ["88528.7", "0", "0", "0"], ["88528.1", "0", "0", "0"], ["88528", "0", "0", "0"], ["88527.9", "0", "0", "0"], ["88527.1", "0", "0", "0"], ["88526.8", "0", "0", "0"], ["88526", "0", "0", "0"], ["88525.8", "0.04171616", "0", "3"], ["88525.7", "0.00001979", "0", "1"], ["88524.4", "0", "0", "0"], ["88524", "0.0171", "0", "1"], ["88523.6", "0", "0", "0"], ["88522.8", "0", "0", "0"], ["88522", "0.0171", "0", "1"], ["88521.6", "0", "0", "0"], ["88521.2", "0", "0", "0"], ["88520.9", "0", "0", "0"], ["88520.8", "0", "0", "0"], ["88520.6", "0", "0", "0"], ["88520", "0.0171", "0", "1"], ["88519.8", "0", "0", "0"], ["88519.2", "0", "0", "0"], ["88519.1", "0", "0", "0"], ["88518.8", "0", "0", "0"], ["88518.4", "0", "0", "0"], ["88518.1", "0", "0", "0"], ["88518", "0.0171", "0", "1"], ["88517.1", "0.0001", "0", "1"], ["88517", "0", "0", "0"], ["88516.9", "0", "0", "0"], ["88516.6", "0", "0", "0"], ["88516.1", "0.000072", "0", "1"], ["88516", "0.0171", "0", "1"], ["88515.3", "0.0001", "0", "1"], ["88515.2", "0", "0", "0"], ["88514.8", "0", "0", "0"], ["88514.7", "0", "0", "0"], ["88514", "0", "0", "0"], ["88513.7", "0", "0", "0"], ["88513.5", "0", "0", "0"], ["88513.4", "0", "0", "0"], ["88512.6", "0", "0", "0"], ["88512.3", "0.01129814", "0", "1"], ["88511.5", "0", "0", "0"], ["88510.9", "0.0284997", "0", "1"], ["88510.4", "0", "0", "0"], ["88508.2", "0", "0", "0"], ["88507.7", "0.09034959", "0", "3"], ["88507.6", "0.03011653", "0", "1"], ["88507.4", "0.03012791", "0", "2"], ["88507.2", "0", "0", "0"], ["88506.4", "0.015", "0", "1"], ["88506.3", "0", "0", "0"], ["88506.2", "0.33929724", "0", "1"], ["88506.1", "0", "0", "0"], ["88506", "0.08653785", "0", "1"], ["88503.5", "0.13454179", "0", "1"], ["88503.3", "0", "0", "0"], ["88502.4", "0.14635249", "0", "1"], ["88502.2", "0", "0", "0"], ["88502.1", "0", "0", "0"], ["88501.6", "0.09751889", "0", "1"], ["88500.9", "0.04", "0", "1"], ["88500.4", "0.04853488", "0", "2"], ["88500.3", "0", "0", "0"], ["88499.1", "0.207", "0", "1"], ["88497.6", "0.0006", "0", "2"], ["88497.5", "0", "0", "0"], ["88497.4", "0", "0", "0"], ["88497.2", "0", "0", "0"], ["88496.9", "0", "0", "0"], ["88496.8", "0.06029926", "0", "3"], ["88496.7", "0.1129962", "0", "1"], ["88495.1", "0.00341464", "0", "1"], ["88494.9", "0", "0", "0"], ["88494.5", "0.90244663", "0", "1"], ["88494.4", "0.33929724", "0", "1"], ["88494.3", "0.147132", "0", "2"], ["88494", "0", "0", "0"], ["88493", "0", "0", "0"], ["88492.7", "0.38388018", "0", "1"], ["88492.6", "0", "0", "0"], ["88492", "0", "0", "0"], ["88491.7", "0", "0", "0"], ["88491.5", "0", "0", "0"], ["88491.1", "0", "0", "0"], ["88490.2", "0.207", "0", "1"], ["88484.8", "0.00344138", "0", "2"], ["88484", "0.12", "0", "4"], ["88483.7", "0.01650401", "0", "1"], ["88483.6", "0.24458586", "0", "1"], ["88483.5", "0", "0", "0"], ["88483", "0.03", "0", "1"], ["88482", "0", "0", "0"], ["88480", "0.07139383", "0", "3"], ["88478.9", "0", "0", "0"], ["88478.8", "0", "0", "0"], ["88478.7", "0", "0", "0"], ["88478.6", "0", "0", "0"], ["88475.2", "0", "0", "0"], ["88475.1", "0.64644062", "0", "1"], ["88473.9", "0.04084968", "0", "1"], ["88473.5", "0", "0", "0"], ["88472.6", "0", "0", "0"], ["88471.1", "0.207", "0", "1"], ["88470.9", "0", "0", "0"], ["88469", "0.0112889", "0", "1"], ["88468", "0", "0", "0"], ["88466.2", "0", "0", "0"], ["88462", "0", "0", "0"], ["88461.3", "0.002", "0", "1"], ["88460.8", "0.02260842", "0", "1"], ["88458.7", "0", "0", "0"], ["88456.5", "0.51451069", "0", "2"], ["88452.1", "1.57325811", "0", "3"], ["88449.7", "2.12624221", "0", "1"], ["88447.4", "0.011286", "0", "1"], ["88443", "0.01316", "0", "1"], ["88441", "0.01128879", "0", "1"], ["88435.9", "0.65377096", "0", "2"], ["88430", "0", "0", "0"], ["88420.4", "0", "0", "0"], ["88420", "0", "0", "0"], ["88405.4", "0", "0", "0"], ["88403.5", "0", "0", "0"], ["88401.9", "0.173984", "0", "1"], ["88394.4", "0", "0", "0"], ["88388.1", "0", "0", "0"], ["88387.4", "0", "0", "0"], ["88385.6", "0.00564806", "0", "1"], ["88378.2", "0.06666822", "0", "1"], ["88378.1", "0.06804094", "0", "1"], ["88376.2", "0.01128888", "0", "1"], ["88373.5", "0.01694266", "0", "3"], ["88365.9", "0", "0", "0"], ["88358.9", "0.011286", "0", "1"], ["88312", "0.207", "0", "1"], ["88307.6", "0", "0", "0"], ["88303.1", "0.207", "0", "1"], ["88283.5", "0.11343045", "0", "1"], ["88283.3", "0.00416498", "0", "2"], ["88283", "0.00001722", "0", "1"], ["88281.2", "0.00006263", "0", "1"], ["88281.1", "0.34078752", "0", "2"], ["88280.5", "0.00002567", "0", "1"], ["88279.9", "0.00001655", "0", "1"], ["88276.1", "0.00007", "0", "1"], ["88275.5", "0.00001139", "0", "1"], ["88275", "0.00009665", "0", "2"], ["88274.6", "0.00001339", "0", "1"], ["88274.4", "0.000015", "0", "1"], ["88274.2", "0.00002298", "0", "1"], ["88274.1", "0.03", "0", "1"], ["88274", "0.06797011", "0", "1"], ["88273.4", "0.01785714", "0", "1"], ["88272.7", "0.00003889", "0", "1"], ["88272.2", "0.00282458", "0", "1"], ["88272", "0.0025", "0", "1"], ["88271.5", "0.01148", "0", "1"], ["88271.3", "0.00002208", "0", "1"], ["88270.8", "0.00001148", "0", "1"], ["88270.7", "0.00003554", "0", "1"], ["88270", "0.00004066", "0", "1"], ["88269.4", "0.11343045", "0", "1"], ["88269.3", "0.34056098", "0", "1"], ["88269.2", "0.08542891", "0", "1"], ["88268.6", "0.00282509", "0", "1"], ["88267.2", "0.00002851", "0", "1"], ["88266.6", "0.0128608", "0", "15"], ["88265.3", "0.00004344", "0", "1"], ["88264.7", "0.00004446", "0", "3"], ["88264.4", "0.00024852", "0", "1"], ["88264.2", "0.00001139", "0", "1"], ["88262.9", "0.00168511", "0", "2"], ["88261.8", "0.00074456", "0", "1"], ["88260.8", "0.00010584", "0", "1"], ["88260", "0.00002148", "0", "1"], ["88259.2", "0.00005974", "0", "1"], ["88259.1", "0.00011181", "0", "1"], ["88258.7", "0.00282652", "0", "1"], ["88257.9", "0.00020125", "0", "2"], ["88257.6", "0.00003493", "0", "1"], ["88256.9", "0.34056098", "0", "1"], ["88256.4", "0.0000172", "0", "1"], ["88255.8", "0.00003183", "0", "1"], ["88255.6", "0.12221196", "0", "1"], ["88255", "0.01785714", "0", "1"], ["88254.3", "0.00012967", "0", "2"], ["88253.7", "0.00608886", "0", "2"], ["88253", "0.00001297", "0", "1"], ["88252", "0.00002018", "0", "1"], ["88251.8", "0.00001302", "0", "1"], ["88250.7", "0.11343045", "0", "1"], ["88250", "0.11322175", "0", "21"], ["88249.9", "0.00060139", "0", "2"]], "ts": "1741338240805", "checksum": -1873571907, "seqId": 48070595726, "prevSeqId": 48070594421}]}
{"arg": {"channel": "books", "instId": "BTC-USDT"}, "action": "update", "data": [{"asks": [["88522.1", "0.55251162", "0", "17"], ["88524", "0.0171", "0", "1"], ["88525.7", "0.21123615", "0", "1"], ["88525.8", "0.06498", "0", "1"], ["88525.9", "0.0482743", "0", "3"], ["88526", "0.0171", "0", "1"], ["88526.2", "0.0001", "0", "1"], ["88526.5", "0", "0", "0"], ["88528.6", "0.04399127", "0", "1"], ["88529.7", "0.0001", "0", "1"], ["88530.1", "0.09208779", "0", "2"], ["88530.6", "0.0017535", "0", "1"], ["88530.7", "0.07650139", "0", "1"], ["88531.8", "0.00209084", "0", "1"], ["88532", "0.01711501", "0", "2"], ["88532.6", "0.04093", "0", "1"], ["88533.7", "0", "0", "0"], ["88533.9", "0.012102", "0", "1"], ["88534.2", "0.1421846", "0", "1"], ["88534.7", "0", "0", "0"], ["88536", "0.1502443", "0", "2"], ["88537.8", "0.48053314", "0", "2"], ["88538", "0.63601419", "0", "6"], ["88538.2", "0.02207271", "0", "1"], ["88540", "1.02213926", "0", "6"], ["88540.6", "0", "0", "0"], ["88541.4", "0.12956561", "0", "1"], ["88541.5", "0.04001152", "0", "2"], ["88543.1", "0.16274824", "0", "3"], ["88543.4", "0.00111045", "0", "2"], ["88544.1", "0.00007666", "0", "1"], ["88544.5", "0.00111578", "0", "1"], ["88550", "0.08010149", "0", "11"], ["88553.4", "0.02510254", "0", "1"], ["88554.3", "0.22594155", "0", "1"], ["88554.8", "0", "0", "0"], ["88557.9", "0.00338693", "0", "1"], ["88575.1", "0.00024988", "0", "1"], ["88583.3", "0.01942868", "0", "10"], ["88585.2", "0.07169795", "0", "1"], ["88590", "0.10001453", "0", "2"], ["88597.7", "0", "0", "0"], ["88602", "0", "0", "0"], ["88605.9", "0", "0", "0"], ["88606", "0.04565056", "0", "4"], ["88611.9", "0.00759848", "0", "3"], ["88619.5", "0.00167644", "0", "1"], ["88621.8", "0", "0", "0"], ["88624.1", "0", "0", "0"], ["88624.2", "0.00005126", "0", "4"], ["88624.4", "0", "0", "0"], ["88624.5", "0", "0", "0"], ["88624.6", "0", "0", "0"], ["88624.9", "0", "0", "0"], ["88625", "0", "0", "0"], ["88625.1", "0", "0", "0"]], "bids": [["88525.8", "0", "0", "0"], ["88525.7", "0", "0", "0"], ["88524", "0", "0", "0"], ["88522", "0.0785", "0", "3"], ["88519.5", "0.0001", "0", "1"], ["88518.4", "0.0001", "0", "1"], ["88517.1", "0", "0", "0"], ["88516.1", "0.06023306", "0", "2"], ["88515.3", "0", "0", "0"], ["88513.2", "0.04978482", "0", "1"], ["88513.1", "0.06024444", "0", "3"], ["88512.8", "0.04001501", "0", "2"], ["88510.9", "0", "0", "0"], ["88508.9", "0.02693918", "0", "1"], ["88508.1", "0.07563837", "0", "1"], ["88507.7", "0", "0", "0"], ["88507.6", "0", "0", "0"], ["88507.4", "0.00001138", "0", "1"], ["88506.5", "0.03011653", "0", "1"], ["88506.2", "0", "0", "0"], ["88506", "0.11908029", "0", "2"], ["88505.4", "0.07937333", "0", "1"], ["88505.2", "0.07795003", "0", "1"], ["88504.8", "0.0873779", "0", "1"], ["88502.4", "0", "0", "0"], ["88501.2", "0.14040582", "0", "1"], ["88501.1", "0.03", "0", "1"], ["88500.9", "0", "0", "0"], ["88500.3", "0.13880023", "0", "1"], ["88498.8", "0.00451984", "0", "1"], ["88497.6", "0.03", "0", "1"], ["88496.8", "0.06", "0", "2"], ["88495.2", "0.21835042", "0", "3"], ["88494.8", "0.00343", "0", "1"], ["88494.6", "0.22594155", "0", "1"], ["88494.5", "0", "0", "0"], ["88494.4", "0.33989651", "0", "3"], ["88493.7", "0.11300012", "0", "1"], ["88493.6", "0.00029927", "0", "1"], ["88492", "0.04", "0", "1"], ["88491.3", "0.128148", "0", "1"], ["88488.4", "0.30919096", "0", "1"], ["88485.5", "0.01650401", "0", "1"], ["88485.4", "0", "0", "0"], ["88484.8", "0.00001138", "0", "1"], ["88484", "0", "0", "0"], ["88483.7", "0", "0", "0"], ["88483", "0.06", "0", "2"], ["88480", "0.13139383", "0", "5"], ["88479", "0.03", "0", "1"], ["88476.7", "0.0112", "0", "1"], ["88475.2", "0.11343045", "0", "1"], ["88474.1", "0", "0", "0"], ["88472.6", "0.0112889", "0", "1"], ["88470.2", "0.01128899", "0", "1"], ["88469.6", "0", "0", "0"], ["88462.1", "0.00103822", "0", "2"], ["88462", "0.00019395", "0", "1"], ["88461.3", "0.15978249", "0", "2"], ["88458.4", "0.01739754", "0", "1"], ["88456.5", "1.33200507", "0", "3"], ["88455.9", "0.00098678", "0", "1"], ["88455.1", "0.00343", "0", "1"], ["88453.9", "2.9383692", "0", "1"], ["88450.2", "0", "0", "0"], ["88447", "0.15920507", "0", "1"], ["88441.4", "0.10517581", "0", "1"], ["88441", "0", "0", "0"], ["88434", "0.16048423", "0", "1"], ["88430.2", "0.01968989", "0", "2"], ["88429.4", "0", "0", "0"], ["88414.8", "0.25000851", "0", "2"], ["88414.3", "0", "0", "0"], ["88402.2", "0.00212229", "0", "1"], ["88384.1", "0.17397542", "0", "1"], ["88376.2", "0", "0", "0"], ["88303.1", "0", "0", "0"], ["88256.4", "0", "0", "0"], ["88255.8", "0", "0", "0"], ["88255.6", "0", "0", "0"], ["88255", "0", "0", "0"], ["88254.3", "0", "0", "0"], ["88253.7", "0", "0", "0"], ["88253", "0", "0", "0"], ["88252", "0", "0", "0"], ["88251.8", "0", "0", "0"], ["88250.7", "0", "0", "0"], ["88250", "0", "0", "0"], ["88249.9", "0", "0", "0"]], "ts": "1741338240905", "checksum": 898037547, "seqId": 48070596347, "prevSeqId": 48070595726}]}
{"arg": {"channel": "books", "instId": "BTC-USDT"}, "action": "update", "data": [{"asks": [["88522.1", "0.35019897", "0", "10"], ["88525.3", "0.0001", "0", "1"], ["88525.4", "0.0001", "0", "1"], ["88525.7", "0.0151888", "0", "1"], ["88525.8", "0.00224251", "0", "1"], ["88526.2", "0", "0", "0"], ["88528.5", "0.07358633", "0", "2"], ["88528.6", "0.02832094", "0", "1"], ["88529.7", "0", "0", "0"], ["88530.1", "0.01129587", "0", "1"], ["88530.7", "0", "0", "0"], ["88531", "0.00002293", "0", "1"], ["88532.3", "0.07998475", "0", "1"], ["88532.5", "0.012102", "0", "1"], ["88533.9", "0", "0", "0"], ["88534.2", "0", "0", "0"], ["88536", "0.0171", "0", "1"], ["88536.3", "0.128148", "0", "1"], ["88536.4", "0.14751002", "0", "1"], ["88537.8", "0.14305879", "0", "1"], ["88538", "0.29429857", "0", "5"], ["88538.2", "0", "0", "0"], ["88540", "0.02213926", "0", "5"], ["88541.4", "0.42776991", "0", "2"], ["88543.1", "0.21074824", "0", "4"], ["88545.1", "1.00001083", "0", "2"], ["88546.6", "0.13501512", "0", "4"], ["88553.4", "0", "0", "0"], ["88554.3", "0.22593784", "0", "1"], ["88558.3", "0.0450114", "0", "2"], ["88561.9", "0.31291502", "0", "4"], ["88569.4", "0.50040856", "0", "2"], ["88572", "0.20881256", "0", "2"], ["88572.6", "0.497897", "0", "1"], ["88582.2", "0.0000474", "0", "3"], ["88585.8", "0.0567942", "0", "3"], ["88590", "0.00001453", "0", "1"], ["88597.2", "0", "0", "0"], ["88608.1", "0.745265", "0", "1"], ["88608.5", "0.00183734", "0", "1"], ["88609.5", "0.746535", "0", "1"], ["88611.9", "0.00576114", "0", "2"], ["88615.1", "0.00167645", "0", "1"], ["88619.5", "0", "0", "0"], ["88623.6", "0", "0", "0"], ["88623.7", "0", "0", "0"], ["88623.8", "0", "0", "0"], ["88624.2", "0", "0", "0"]], "bids": [["88522", "0.14098577", "0", "4"], ["88521.9", "0.00004532", "0", "1"], ["88520.3", "0.0001", "0", "1"], ["88519.8", "0.0001", "0", "1"], ["88519.5", "0", "0", "0"], ["88518.4", "0", "0", "0"], ["88516.8", "0.00112792", "0", "1"], ["88515.1", "0.00935", "0", "1"], ["88513.4", "0.06826656", "0", "1"], ["88513.3", "0.06023306", "0", "2"], ["88513.2", "0", "0", "0"], ["88513.1", "0.00001138", "0", "1"], ["88512.2", "0.00007275", "0", "1"], ["88511.3", "0.02933945", "0", "1"], ["88509", "0.1450922", "0", "2"], ["88508.9", "0", "0", "0"], ["88508.1", "0", "0", "0"], ["88507.6", "0.085896", "0", "1"], ["88506.6", "0.009", "0", "1"], ["88506.5", "0.33929724", "0", "1"], ["88506", "0.15599106", "0", "2"], ["88505.4", "0", "0", "0"], ["88505.2", "0", "0", "0"], ["88504.8", "0", "0", "0"], ["88503.4", "0.14882311", "0", "1"], ["88501.6", "0.20598274", "0", "3"], ["88501.2", "0", "0", "0"], ["88500.3", "0", "0", "0"], ["88498.2", "0.22593784", "0", "1"], ["88497.6", "0.06", "0", "2"], ["88495.2", "0.59026725", "0", "3"], ["88494.6", "0", "0", "0"], ["88494.5", "0.90244663", "0", "1"], ["88494.4", "0.33929724", "0", "1"], ["88493.6", "0.00059927", "0", "2"], ["88493", "0.54782762", "0", "1"], ["88492.8", "0.00029927", "0", "1"], ["88488.4", "1.00120168", "0", "1"], ["88487.5", "1.70179274", "0", "1"], ["88485.5", "0", "0", "0"], ["88485", "0.90244663", "0", "1"], ["88483.6", "0.38727528", "0", "2"], ["88483", "0", "0", "0"], ["88481.8", "0.01650401", "0", "1"], ["88481", "0.06", "0", "2"], ["88480", "0.05194673", "0", "2"], ["88479.8", "0.498418", "0", "1"], ["88479.1", "0.06949113", "0", "2"], ["88479", "0.06", "0", "2"], ["88478", "0.03", "0", "1"], ["88472.9", "0.01936", "0", "1"], ["88465.8", "0.49807", "0", "1"], ["88462.1", "0.00001138", "0", "1"], ["88462", "0", "0", "0"], ["88458.4", "0.01842439", "0", "2"], ["88457.4", "0.03096528", "0", "1"], ["88455.9", "0", "0", "0"], ["88452.1", "1.5742449", "0", "4"], ["88447.4", "0", "0", "0"], ["88447", "0", "0", "0"], ["88443", "0.761099", "0", "2"], ["88435.9", "0.005", "0", "1"], ["88434", "0", "0", "0"], ["88431.3", "0.00114976", "0", "1"], ["88430.2", "0.0045196", "0", "1"], ["88427.2", "0.746789", "0", "1"], ["88425.4", "0.00019403", "0", "1"], ["88414.8", "0.00565", "0", "1"], ["88409.5", "0", "0", "0"], ["88402.2", "0", "0", "0"], ["88400.3", "0.00212214", "0", "1"], ["88379.4", "0.203292", "0", "1"], ["88358.9", "0", "0", "0"], ["88262.9", "0", "0", "0"], ["88261.8", "0", "0", "0"], ["88260.8", "0", "0", "0"], ["88260", "0", "0", "0"], ["88259.2", "0", "0", "0"], ["88259.1", "0", "0", "0"], ["88258.7", "0", "0", "0"], ["88257.9", "0", "0", "0"], ["88257.6", "0", "0", "0"], ["88256.9", "0", "0", "0"]], "ts": "1741338241005", "checksum": -980397105, "seqId": 48070596779, "prevSeqId": 48070596347}]}
{"arg": {"channel": "books", "instId": "BTC-USDT"}, "action": "update", "data": [{"asks": [["88520.3", "0.21738232", "0", "6"], ["88520.4", "0.0001", "0", "1"], ["88521.4", "0.04436198", "0", "1"], ["88521.5", "0.06498", "0", "1"], ["88522", "0.0331", "0", "2"], ["88522.1", "0.01364", "0", "1"], ["88522.4", "0.0001", "0", "1"], ["88525.2", "0.03329756", "0", "1"], ["88525.3", "0.06023306", "0", "2"], ["88525.4", "0", "0", "0"], ["88525.7", "0", "0", "0"], ["88525.9", "0.0346343", "0", "2"], ["88527", "0.04094", "0", "1"], ["88527.3", "0.02932371", "0", "1"], ["88528.1", "0.09727774", "0", "3"], ["88528.2", "0.06023306", "0", "2"], ["88528.5", "0", "0", "0"], ["88528.6", "0", "0", "0"], ["88528.8", "0.02808008", "0", "1"], ["88530.6", "0", "0", "0"], ["88531", "0.13994626", "0", "3"], ["88531.8", "0", "0", "0"], ["88531.9", "0", "0", "0"], ["88532.3", "0.08073349", "0", "1"], ["88532.5", "0", "0", "0"], ["88532.6", "0", "0", "0"], ["88533.1", "0.09577859", "0", "2"], ["88533.4", "0.20118865", "0", "2"], ["88533.6", "0", "0", "0"], ["88535.1", "0.13563628", "0", "1"], ["88535.4", "0.13819808", "0", "1"], ["88536.4", "0", "0", "0"], ["88536.7", "0", "0", "0"], ["88537.7", "0.01091165", "0", "1"], ["88537.8", "0.10357316", "0", "1"], ["88537.9", "0.15238588", "0", "2"], ["88541.4", "0.12956561", "0", "1"], ["88545.1", "0.00001083", "0", "1"], ["88546", "0.78426397", "0", "5"], ["88546.6", "0.17401512", "0", "5"], ["88546.7", "1", "0", "1"], ["88550", "0.24143496", "0", "11"], ["88554.3", "0", "0", "0"], ["88561.6", "1.77689473", "0", "2"], ["88561.9", "0.26491502", "0", "3"], ["88622.6", "0", "0", "0"], ["88622.7", "0", "0", "0"], ["88622.9", "0", "0", "0"], ["88623.3", "0", "0", "0"]], "bids": [["88522", "0", "0", "0"], ["88521.9", "0", "0", "0"], ["88520.3", "0", "0", "0"], ["88520.2", "0.13062911", "0", "3"], ["88520.1", "0.00005202", "0", "1"], ["88519.8", "0", "0", "0"], ["88519.6", "0.11296696", "0", "1"], ["88518.1", "0.0001", "0", "1"], ["88516.1", "0", "0", "0"], ["88515.4", "0.00005466", "0", "1"], ["88513.4", "0.01541918", "0", "1"], ["88513.3", "0", "0", "0"], ["88512.2", "0", "0", "0"], ["88511.3", "0", "0", "0"], ["88510.4", "0.00007275", "0", "1"], ["88510", "0.0279021", "0", "1"], ["88509.6", "0.02628888", "0", "1"], ["88509.4", "0.0289652", "0", "1"], ["88509.1", "0.15022909", "0", "1"], ["88509", "0", "0", "0"], ["88507.6", "0", "0", "0"], ["88507.1", "0.00828329", "0", "1"], ["88506.6", "0", "0", "0"], ["88506.2", "0.09669275", "0", "2"], ["88506", "0.1807031", "0", "2"], ["88505.4", "0.07652498", "0", "1"], ["88505.1", "0.08867236", "0", "1"], ["88503.4", "0", "0", "0"], ["88502.2", "0.13519074", "0", "1"], ["88502.1", "0.14498522", "0", "1"], ["88501.6", "0.20174674", "0", "2"], ["88500.3", "0.13826125", "0", "1"], ["88499.6", "0.02805", "0", "1"], ["88498.2", "0", "0", "0"], ["88495.3", "0.22594189", "0", "1"], ["88493.6", "0", "0", "0"], ["88493", "0", "0", "0"], ["88492.8", "0.00059927", "0", "2"], ["88492", "0.04029928", "0", "2"], ["88488.5", "0.01650401", "0", "1"], ["88481.8", "0", "0", "0"], ["88481", "0", "0", "0"], ["88480", "0.11194673", "0", "4"], ["88475.2", "0.21343045", "0", "2"], ["88470.3", "0.01441274", "0", "1"], ["88468.9", "0.0194471", "0", "1"], ["88466.1", "0.58270049", "0", "2"], ["88462.5", "0.55483407", "0", "1"], ["88452.1", "0.98080054", "0", "3"], ["88441.4", "0", "0", "0"], ["88413.4", "0.00170674", "0", "1"], ["88400.3", "0", "0", "0"], ["88397.8", "0.00212215", "0", "1"], ["88304.7", "3.25058437", "0", "2"], ["88267.2", "0", "0", "0"], ["88266.6", "0", "0", "0"], ["88265.3", "0", "0", "0"], ["88264.7", "0", "0", "0"], ["88264.4", "0", "0", "0"], ["88264.2", "0", "0", "0"]], "ts": "1741338241105", "checksum": -739943391, "seqId": 48070597180, "prevSeqId": 48070596779}]}
{"arg": {"channel": "books", "instId": "BTC-USDT"}, "action": "update", "data": [{"asks": [["88520.3", "0.17231232", "0", "4"], ["88520.4", "0", "0", "0"], ["88521.4", "0.029454", "0", "1"], ["88521.8", "0.0001", "0", "1"], ["88522.1", "0", "0", "0"], ["88522.4", "0", "0", "0"], ["88522.8", "0.0001", "0", "1"], ["88525.2", "0.02220142", "0", "1"], ["88527", "0", "0", "0"], ["88527.3", "0", "0", "0"], ["88528", "0.10705883", "0", "3"], ["88528.1", "0", "0", "0"], ["88528.8", "0.02725909", "0", "1"], ["88529", "0.02760646", "0", "1"], ["88530.9", "0.00209084", "0", "1"], ["88531", "0.06023306", "0", "2"], ["88531.6", "0.001482", "0", "1"], ["88531.7", "0.08228042", "0", "1"], ["88532.3", "0", "0", "0"], ["88532.8", "0.012102", "0", "1"], ["88532.9", "0.0739622", "0", "1"], ["88533.1", "0", "0", "0"], ["88533.4", "0.55170744", "0", "2"], ["88535.1", "0", "0", "0"], ["88535.4", "0", "0", "0"], ["88535.7", "0.90245801", "0", "2"], ["88535.8", "0.144404", "0", "1"], ["88536.1", "0.13520732", "0", "1"], ["88537.6", "0.25056306", "0", "1"], ["88537.7", "0.35020889", "0", "2"], ["88537.8", "0", "0", "0"], ["88537.9", "0.01888533", "0", "1"], ["88538.1", "0.14009432", "0", "4"], ["88550", "0.08010046", "0", "11"], ["88554.3", "0.2259381", "0", "1"], ["88558.3", "0.0000114", "0", "1"], ["88559.5", "0.94382777", "0", "5"], ["88561.9", "0.22291502", "0", "2"], ["88589.9", "0.50581415", "0", "2"], ["88607.4", "0.00183734", "0", "1"], ["88608.5", "0", "0", "0"], ["88608.7", "0.0399405", "0", "1"], ["88622.2", "0", "0", "0"], ["88622.3", "0", "0", "0"], ["88622.5", "0", "0", "0"]], "bids": [["88520.2", "0.17242827", "0", "6"], ["88519.3", "0.00015466", "0", "2"], ["88518.1", "0", "0", "0"], ["88515.4", "0", "0", "0"], ["88513.7", "0.07802703", "0", "1"], ["88513.6", "0.06023584", "0", "2"], ["88513.4", "0", "0", "0"], ["88510.6", "0.02798604", "0", "1"], ["88510.5", "0.000072", "0", "1"], ["88510.4", "0.06023584", "0", "2"], ["88510.3", "0.02525868", "0", "1"], ["88510", "0", "0", "0"], ["88509.7", "0.02617592", "0", "1"], ["88509.6", "0", "0", "0"], ["88509.4", "0", "0", "0"], ["88507.4", "0.05101508", "0", "3"], ["88507.2", "0.00545735", "0", "1"], ["88506.9", "0.08743346", "0", "1"], ["88506.6", "0.06023584", "0", "2"], ["88506.2", "0.00935", "0", "1"], ["88506.1", "0.07596288", "0", "1"], ["88506", "0.17733471", "0", "2"], ["88505.4", "0", "0", "0"], ["88505.3", "0.2331224", "0", "3"], ["88505.1", "0", "0", "0"], ["88502.9", "0.12344486", "0", "1"], ["88502.8", "0.13603769", "0", "1"], ["88502.2", "0", "0", "0"], ["88502.1", "0", "0", "0"], ["88501", "0.004236", "0", "1"], ["88500.6", "0.14028685", "0", "1"], ["88500.3", "0", "0", "0"], ["88497.7", "0.2259381", "0", "1"], ["88495.3", "0", "0", "0"], ["88493.9", "0.0109147", "0", "1"], ["88491.9", "0.03250401", "0", "2"], ["88491.3", "0", "0", "0"], ["88488.5", "0", "0", "0"], ["88479", "0", "0", "0"], ["88478", "0.06", "0", "2"], ["88477", "0.03", "0", "1"], ["88452.1", "1.073979", "0", "3"], ["88450.2", "0.00098683", "0", "1"], ["88446.5", "0.30754406", "0", "1"], ["88435.9", "0", "0", "0"], ["88425.4", "0", "0", "0"], ["88421.3", "0.00019404", "0", "1"], ["88397.8", "0", "0", "0"], ["88393.3", "0.00212249", "0", "1"], ["88269.3", "0", "0", "0"], ["88269.2", "0", "0", "0"], ["88268.6", "0", "0", "0"]], "ts": "1741338241205", "checksum": 314357135, "seqId": 48070597442, "prevSeqId": 48070597180}]}
{"arg": {"channel": "books", "instId": "BTC-USDT"}, "action": "update", "data": [{"asks": [["88521.8", "0", "0", "0"], ["88522.8", "0", "0", "0"], ["88525.2", "0.04044297", "0", "2"], ["88527.8", "0.00209084", "0", "1"], ["88527.9", "0.0002", "0", "2"], ["88528", "0.07487385", "0", "2"], ["88528.5", "0.01364", "0", "1"], ["88528.8", "0.02494705", "0", "1"], ["88529", "0", "0", "0"], ["88529.1", "0.0264695", "0", "2"], ["88530.1", "0.01863882", "0", "2"], ["88530.9", "0", "0", "0"], ["88531.6", "0", "0", "0"], ["88531.7", "0.08489787", "0", "1"], ["88531.9", "0.012102", "0", "1"], ["88532.8", "0", "0", "0"], ["88532.9", "0", "0", "0"], ["88533", "0.08246349", "0", "1"], ["88533.1", "0.00209084", "0", "1"], ["88533.4", "0.54417819", "0", "2"], ["88535.1", "0.04093", "0", "1"], ["88538.1", "0.00007794", "0", "3"], ["88538.2", "0.13581552", "0", "1"], ["88542", "0.0171", "0", "1"], ["88551.4", "0.03768876", "0", "1"], ["88561.9", "0.18391502", "0", "1"], ["88581.3", "0.10004102", "0", "2"], ["88589.9", "0.40581415", "0", "1"], ["88621.6", "0", "0", "0"], ["88621.9", "0", "0", "0"], ["88622", "0", "0", "0"]], "bids": [["88519.3", "0.0001", "0", "1"], ["88519.1", "0.00005466", "0", "1"], ["88513.7", "0.05156046", "0", "1"], ["88512.5", "0.00935", "0", "1"], ["88511.7", "0.00734295", "0", "1"], ["88510.7", "0.02939844", "0", "1"], ["88510.6", "0", "0", "0"], ["88510.3", "0.02598774", "0", "1"], ["88509.7", "0.0295253", "0", "1"], ["88506.2", "0", "0", "0"], ["88506.1", "0", "0", "0"], ["88506", "0.11959005", "0", "1"], ["88505.9", "0.02805", "0", "1"], ["88505.4", "0.08422238", "0", "1"], ["88505.3", "0.147132", "0", "2"], ["88503.5", "0", "0", "0"], ["88501", "0", "0", "0"], ["88500.6", "0.1343507", "0", "1"], ["88499.6", "0", "0", "0"], ["88496.7", "0.2411432", "0", "2"], ["88495.4", "0.00734295", "0", "1"], ["88491.9", "0.016", "0", "1"], ["88487.2", "0.01650401", "0", "1"], ["88480.5", "0.03719397", "0", "1"], ["88475.2", "0.11343045", "0", "1"], ["88473.4", "0.10001138", "0", "2"], ["88360.3", "0.00001138", "0", "1"], ["88354.6", "0.00001138", "0", "1"], ["88271.3", "0", "0", "0"], ["88270.8", "0", "0", "0"], ["88270.7", "0", "0", "0"], ["88270", "0", "0", "0"], ["88269.4", "0", "0", "0"]], "ts": "1741338241305", "checksum": 1285411523, "seqId": 48070597593, "prevSeqId": 48070597442}]}
{"arg": {"channel": "books", "instId": "BTC-USDT"}, "action": "update", "data": [{"asks": [["88520.3", "0.19172591", "0", "7"], ["88521.4", "0", "0", "0"], ["88521.5", "0", "0", "0"], ["88522.7", "0.0001", "0", "1"], ["88522.8", "0.0001", "0", "1"], ["88525", "0.07312256", "0", "2"], ["88525.1", "0.06023584", "0", "2"], ["88525.2", "0", "0", "0"], ["88527.8", "0", "0", "0"], ["88527.9", "0.00209084", "0", "1"], ["88528", "0.08755105", "0", "2"], ["88528.1", "0.02955667", "0", "1"], ["88528.5", "0", "0", "0"], ["88528.8", "0", "0", "0"], ["88528.9", "0.0263583", "0", "1"], ["88529", "0.02642394", "0", "1"], ["88529.1", "0", "0", "0"], ["88531.2", "0.000015", "0", "1"], ["88531.7", "0", "0", "0"], ["88531.8", "0.08647283", "0", "1"], ["88533", "0", "0", "0"], ["88533.1", "0.07403539", "0", "1"], ["88533.3", "0.08549955", "0", "2"], ["88533.4", "0.46529598", "0", "1"], ["88535.8", "0", "0", "0"], ["88535.9", "0.13141887", "0", "1"], ["88536.1", "0", "0", "0"], ["88536.3", "0.25334595", "0", "2"], ["88538.1", "0.14696498", "0", "4"], ["88538.2", "0", "0", "0"], ["88541.4", "0.39754861", "0", "2"], ["88545.3", "1", "0", "1"], ["88546", "0.53149365", "0", "4"], ["88546.7", "0", "0", "0"], ["88550", "0.01549307", "0", "10"], ["88554.3", "0", "0", "0"], ["88557.7", "0.22592809", "0", "1"], ["88579.3", "0.1", "0", "1"], ["88581.3", "0.00004102", "0", "1"], ["88585.8", "0.02258678", "0", "2"], ["88590.6", "0.02936579", "0", "1"]], "bids": [["88520.2", "0.16612827", "0", "6"], ["88519.3", "0", "0", "0"], ["88519.1", "0", "0", "0"], ["88518.8", "0.0001", "0", "1"], ["88518.6", "0.00005466", "0", "1"], ["88510.8", "0.02854455", "0", "1"], ["88510.7", "0", "0", "0"], ["88510.4", "0.08756508", "0", "3"], ["88510.3", "0", "0", "0"], ["88509.7", "0.02694268", "0", "1"], ["88507.1", "0.08913969", "0", "1"], ["88506.9", "0", "0", "0"], ["88506.6", "0", "0", "0"], ["88506.2", "0.0743182", "0", "1"], ["88506", "0.2060692", "0", "2"], ["88505.4", "0", "0", "0"], ["88505.3", "0.22579724", "0", "3"], ["88503", "0.12464128", "0", "1"], ["88502.9", "0.14316637", "0", "1"], ["88502.8", "0", "0", "0"], ["88502.3", "0.003855", "0", "1"], ["88501.7", "0.22592809", "0", "1"], ["88500.6", "0", "0", "0"], ["88500.5", "0.14754245", "0", "1"], ["88497.7", "0", "0", "0"], ["88462.2", "0.02972082", "0", "1"], ["88457.4", "0", "0", "0"], ["88452.1", "1.13575179", "0", "2"], ["88421.3", "0", "0", "0"], ["88418.5", "0.00019405", "0", "1"], ["88271.3", "0.00002208", "0", "1"], ["88270.8", "0.00001148", "0", "1"]], "ts": "1741338241405", "checksum": -1049559329, "seqId": 48070597795, "prevSeqId": 48070597593}]}
{"arg": {"channel": "books", "instId": "BTC-USDT"}, "action": "update", "data": [{"asks": [["88520.3", "0.15829352", "0", "7"], ["88522.7", "0", "0", "0"], ["88522.8", "0", "0", "0"], ["88523.3", "0.0002", "0", "2"], ["88525", "0.0383558", "0", "1"], ["88525.3", "0", "0", "0"], ["88527.3", "0.01364", "0", "1"], ["88528.1", "0", "0", "0"], ["88528.4", "0.02835034", "0", "1"], ["88528.9", "0", "0", "0"], ["88529", "0", "0", "0"], ["88529.1", "0.02680448", "0", "2"], ["88529.2", "0.02598739", "0", "1"], ["88531.8", "0", "0", "0"], ["88532.1", "0.08295296", "0", "1"], ["88533.1", "0", "0", "0"], ["88533.3", "0.08288813", "0", "2"], ["88533.5", "0.08087867", "0", "1"], ["88535.9", "0", "0", "0"], ["88536.2", "0.13093471", "0", "1"], ["88536.3", "0.128148", "0", "1"], ["88536.5", "0.13232905", "0", "1"], ["88538.1", "0.00007794", "0", "3"], ["88538.2", "0.14132076", "0", "1"], ["88550", "0.09140499", "0", "11"], ["88554.3", "0.2259311", "0", "1"], ["88557.7", "0", "0", "0"], ["88613.2", "0.00167646", "0", "1"], ["88615.1", "0", "0", "0"], ["88621.1", "0", "0", "0"]], "bids": [["88520.2", "0.15988827", "0", "5"], ["88519", "0.00005466", "0", "1"], ["88518.6", "0", "0", "0"], ["88511", "0.02992654", "0", "1"], ["88510.8", "0", "0", "0"], ["88510.7", "0.02571596", "0", "1"], ["88510.4", "0.06023584", "0", "2"], ["88509.8", "0.02731706", "0", "1"], ["88509.7", "0", "0", "0"], ["88509.1", "0.25517463", "0", "2"], ["88508.8", "0.33895", "0", "1"], ["88507.3", "0.08220635", "0", "1"], ["88507.1", "0", "0", "0"], ["88507", "0.33896", "0", "1"], ["88506.5", "0.4137183", "0", "2"], ["88506.2", "0", "0", "0"], ["88505.4", "0.07893566", "0", "1"], ["88505.3", "0.486092", "0", "3"], ["88503.3", "0.12864481", "0", "1"], ["88503.2", "0.14870677", "0", "1"], ["88503", "0", "0", "0"], ["88502.9", "0", "0", "0"], ["88502.3", "0", "0", "0"], ["88501.7", "0", "0", "0"], ["88500.7", "0.13746578", "0", "1"], ["88500.5", "0", "0", "0"], ["88499.2", "0.2259311", "0", "1"], ["88487.2", "0", "0", "0"], ["88485.1", "0.01650401", "0", "1"], ["88458.4", "0.01739754", "0", "1"], ["88456.6", "0.00102687", "0", "1"], ["88271.5", "0", "0", "0"], ["88271.3", "0", "0", "0"], ["88270.8", "0", "0", "0"]], "ts": "1741338241505", "checksum": 1866167537, "seqId": 48070597912, "prevSeqId": 48070597795}]}
{"arg": {"channel": "books", "instId": "BTC-USDT"}, "action": "update", "data": [{"asks": [["88520.3", "0.24127405", "0", "9"], ["88521.4", "0.04387941", "0", "1"], ["88521.5", "0.1129647", "0", "1"], ["88523.3", "0", "0", "0"], ["88523.4", "0.0002", "0", "2"], ["88524.9", "0.05776817", "0", "1"], ["88525", "0", "0", "0"], ["88527.6", "0.02635212", "0", "1"], ["88527.9", "0", "0", "0"], ["88528", "0.08751873", "0", "2"], ["88528.3", "0.02524657", "0", "1"], ["88528.4", "0", "0", "0"], ["88528.9", "0.02734382", "0", "1"], ["88529.1", "0", "0", "0"], ["88529.2", "0", "0", "0"], ["88530", "0.00209084", "0", "1"], ["88531.2", "0.08967343", "0", "2"], ["88532.1", "0", "0", "0"], ["88533.3", "0.00057148", "0", "1"], ["88533.5", "0", "0", "0"], ["88535.5", "0.1485059", "0", "1"], ["88536.2", "0", "0", "0"], ["88536.5", "0", "0", "0"], ["88538.2", "0", "0", "0"], ["88550", "0.01549307", "0", "10"], ["88554.3", "0", "0", "0"], ["88557.7", "0.22592649", "0", "1"], ["88567", "0.06", "0", "2"], ["88568", "0.09", "0", "3"], ["88579", "0.00276168", "0", "4"], ["88580", "0", "0", "0"], ["88620.9", "0", "0", "0"], ["88621.1", "0.00002626", "0", "1"], ["88621.6", "0.00015113", "0", "1"]], "bids": [["88519.6", "0", "0", "0"], ["88519", "0", "0", "0"], ["88518.8", "0", "0", "0"], ["88518.7", "0.00015466", "0", "2"], ["88517.2", "0.11297003", "0", "1"], ["88513.9", "0.08656835", "0", "1"], ["88513.8", "0.1", "0", "1"], ["88513.7", "0", "0", "0"], ["88511", "0", "0", "0"], ["88510.7", "0", "0", "0"], ["88510.3", "0.02994618", "0", "1"], ["88509.8", "0", "0", "0"], ["88507.4", "0.00001138", "0", "1"], ["88507.3", "0", "0", "0"], ["88506.6", "0.0784527", "0", "1"], ["88506.5", "0.33929724", "0", "1"], ["88506", "0.32072671", "0", "2"], ["88505.4", "0", "0", "0"], ["88503.3", "0", "0", "0"], ["88503.2", "0", "0", "0"], ["88502.3", "0.1313731", "0", "1"], ["88501.3", "0.0000225", "0", "1"], ["88500.7", "0", "0", "0"], ["88499.2", "0.22592852", "0", "1"], ["88487.6", "0.01650401", "0", "1"], ["88485.1", "0", "0", "0"], ["88481", "0.06", "0", "2"], ["88479", "0.03", "0", "1"], ["88478", "0", "0", "0"], ["88477", "0", "0", "0"], ["88464.5", "0.33912", "0", "1"], ["88271.5", "0.01148", "0", "1"], ["88271.3", "0.00002208", "0", "1"], ["88270.8", "0.00001148", "0", "1"]], "ts": "1741338241605", "checksum": 1163617490, "seqId": 48070598097, "prevSeqId": 48070597912}]}
{"arg": {"channel": "books", "instId": "BTC-USDT"}, "action": "update", "data": [{"asks": [["88523.4", "0", "0", "0"], ["88523.5", "0.0002", "0", "2"], ["88529.2", "0.00001623", "0", "1"], ["88530", "0", "0", "0"], ["88530.9", "0.00209084", "0", "1"], ["88532.6", "0.08014935", "0", "1"], ["88533.3", "0.08853144", "0", "2"], ["88535.8", "0.13917316", "0", "1"], ["88538.1", "0.13835744", "0", "4"], ["88570", "0.15408136", "0", "1"], ["88607.8", "0.33858009", "0", "2"], ["88620.8", "0", "0", "0"], ["88621", "0", "0", "0"], ["88621.1", "0", "0", "0"], ["88621.6", "0", "0", "0"]], "bids": [["88518.7", "0", "0", "0"], ["88518.6", "0.00015466", "0", "2"], ["88509.7", "0.02761122", "0", "1"], ["88509.4", "0.02844785", "0", "1"], ["88506", "0.22202846", "0", "1"], ["88505.5", "0.08306848", "0", "1"], ["88505.1", "0.08009079", "0", "1"], ["88502.3", "0.26266802", "0", "2"], ["88500.3", "0.13940765", "0", "1"], ["88488.5", "0.01650401", "0", "1"], ["88487.6", "0", "0", "0"], ["88480", "0.05194673", "0", "2"], ["88479.1", "0.05149113", "0", "2"], ["88479", "0.06", "0", "2"], ["88478", "0.03", "0", "1"], ["88467.5", "0.03406696", "0", "1"], ["88462.2", "0", "0", "0"], ["88272.7", "0", "0", "0"], ["88272.2", "0", "0", "0"], ["88272", "0", "0", "0"], ["88271.5", "0", "0", "0"], ["88271.3", "0", "0", "0"], ["88270.8", "0", "0", "0"]], "ts": "1741338241705", "checksum": 830386403, "seqId": 48070598176, "prevSeqId": 48070598097}]}
{"arg": {"channel": "books", "instId": "BTC-USDT"}, "action": "update", "data": [{"asks": [["88523.5", "0", "0", "0"], ["88524.9", "0.0384158", "0", "1"], ["88525.4", "0.0002", "0", "2"], ["88527.5", "0.02951904", "0", "1"], ["88527.6", "0", "0", "0"], ["88529.2", "0", "0", "0"], ["88530", "0.00001138", "0", "1"], ["88535.3", "0.13538352", "0", "1"], ["88535.5", "0", "0", "0"], ["88543.8", "1", "0", "1"], ["88545.3", "0", "0", "0"]], "bids": [["88518.6", "0", "0", "0"], ["88518.5", "0.00015466", "0", "2"], ["88510.3", "0", "0", "0"], ["88510.2", "0.0283856", "0", "1"], ["88506.6", "0", "0", "0"], ["88506.4", "0.09965165", "0", "2"], ["88491", "0.10001", "0", "2"], ["88272.7", "0.00003889", "0", "1"]], "ts": "1741338241805", "checksum": 1750257011, "seqId": 48070598218, "prevSeqId": 48070598176}]}
{"arg": {"channel": "books", "instId": "BTC-USDT"}, "action": "update", "data": [{"asks": [["88520.3", "0.22527405", "0", "8"], ["88522.1", "0.005", "0", "1"], ["88525.4", "0", "0", "0"], ["88525.8", "0.00244251", "0", "3"], ["88528.3", "0", "0", "0"], ["88528.4", "0.02567773", "0", "1"], ["88530", "0.00210222", "0", "2"], ["88530.9", "0", "0", "0"], ["88532.7", "0.005", "0", "1"], ["88535.3", "0", "0", "0"], ["88535.4", "0.13387619", "0", "1"], ["88543.5", "1.00001124", "0", "2"], ["88543.8", "0", "0", "0"], ["88551.4", "0", "0", "0"], ["88556.1", "0.03763734", "0", "1"], ["88563", "1.00237119", "0", "2"], ["88572", "0.20941256", "0", "4"], ["88572.8", "0.0003", "0", "1"], ["88584", "0.11343045", "0", "1"], ["88584.8", "0.000015", "0", "1"]], "bids": [["88518.6", "0.00015466", "0", "2"], ["88518.5", "0", "0", "0"], ["88509.8", "0.02522452", "0", "1"], ["88509.7", "0", "0", "0"], ["88506.5", "0.42185791", "0", "2"], ["88506.4", "0.015", "0", "1"], ["88502.4", "0.1491991", "0", "1"], ["88502.3", "0.13129492", "0", "1"], ["88493.6", "0.0006", "0", "2"], ["88492.8", "0.00029927", "0", "1"], ["88492", "0.04", "0", "1"], ["88485.1", "0.03576303", "0", "1"], ["88480.5", "0", "0", "0"], ["88464", "0.005", "0", "1"], ["88453.4", "0.005", "0", "1"], ["88274.1", "0", "0", "0"], ["88274", "0", "0", "0"], ["88273.4", "0", "0", "0"], ["88272.7", "0", "0", "0"]], "ts": "1741338241905", "checksum": 1727922900, "seqId": 48070598290, "prevSeqId": 48070598218}]}
{"arg": {"channel": "books", "instId": "BTC-USDT"}, "action": "update", "data": [{"asks": [["88520.3", "0.104", "0", "4"], ["88521.4", "0", "0", "0"], ["88521.5", "0", "0", "0"], ["88522", "0.0171", "0", "1"], ["88524.9", "0", "0", "0"], ["88525.1", "0", "0", "0"], ["88525.8", "0.00224251", "0", "1"], ["88525.9", "0.0186343", "0", "1"], ["88527.3", "0", "0", "0"], ["88527.5", "0", "0", "0"], ["88528", "0.066211", "0", "2"], ["88528.4", "0", "0", "0"], ["88528.9", "0.0001", "0", "1"], ["88529.2", "0.00001623", "0", "1"], ["88529.6", "0.0001", "0", "1"], ["88530", "0.00001138", "0", "1"], ["88530.1", "0.04834991", "0", "3"], ["88530.8", "0.02722932", "0", "1"], ["88530.9", "0.02435828", "0", "1"], ["88531.2", "0.000015", "0", "1"], ["88531.3", "0.01364", "0", "1"], ["88531.9", "0", "0", "0"], ["88532.6", "0.012102", "0", "1"], ["88533.3", "0.00057148", "0", "1"], ["88533.4", "0.08622281", "0", "1"], ["88533.8", "0.08460629", "0", "1"], ["88534.8", "0", "0", "0"], ["88535.1", "0.07359532", "0", "1"], ["88535.2", "0.08322565", "0", "1"], ["88535.4", "0", "0", "0"], ["88535.7", "0.00001138", "0", "1"], ["88535.8", "0", "0", "0"], ["88537.6", "0.21929961", "0", "2"], ["88537.7", "0.01091165", "0", "1"], ["88537.9", "0.16565784", "0", "2"], ["88538", "0.08729857", "0", "4"], ["88538.1", "0.00007794", "0", "3"], ["88539.7", "0.33929724", "0", "1"], ["88539.9", "0.04179598", "0", "3"], ["88540", "0.15569843", "0", "6"], ["88541.4", "0.07611563", "0", "1"], ["88541.5", "0.00001152", "0", "1"], ["88543.5", "0.00001124", "0", "1"], ["88545.4", "0.00013356", "0", "4"], ["88556.1", "0", "0", "0"], ["88557.9", "0", "0", "0"], ["88561.6", "0.11343045", "0", "1"], ["88563", "0.00237119", "0", "1"], ["88569.4", "0.00292156", "0", "1"], ["88570", "0", "0", "0"], ["88572", "0.080795", "0", "3"], ["88572.6", "0", "0", "0"], ["88576.8", "0.339112", "0", "2"], ["88578.1", "0.00348313", "0", "4"], ["88579.9", "0.0004693", "0", "2"], ["88589", "0.00001077", "0", "1"], ["88590.6", "0", "0", "0"], ["88595.3", "0.03306977", "0", "1"], ["88606", "0.00046406", "0", "3"], ["88608.3", "0.04518699", "0", "1"], ["88618.1", "0.06804094", "0", "1"], ["88620.8", "0.00011317", "0", "1"], ["88620.9", "0.207", "0", "1"], ["88621", "0.00027554", "0", "1"], ["88621.1", "0.00002626", "0", "1"], ["88621.6", "0.00015113", "0", "1"]], "bids": [["88520.2", "0.18900954", "0", "7"], ["88520.1", "0.09535972", "0", "2"], ["88519.4", "0.11296728", "0", "1"], ["88519.3", "0.00005466", "0", "1"], ["88519.1", "0.0001", "0", "1"], ["88518.6", "0", "0", "0"], ["88517.4", "0.0510037", "0", "2"], ["88517.2", "0", "0", "0"], ["88516.1", "0.06023584", "0", "2"], ["88515.4", "0.00935", "0", "1"], ["88514", "0.03011792", "0", "1"], ["88513.6", "0.03011792", "0", "1"], ["88512.7", "0.02924564", "0", "1"], ["88512.5", "0", "0", "0"], ["88512.3", "0.03810445", "0", "2"], ["88511.4", "0.028654", "0", "1"], ["88510.7", "0.02805", "0", "1"], ["88510.5", "0.00007275", "0", "1"], ["88510.2", "0", "0", "0"], ["88509.8", "0", "0", "0"], ["88509.4", "0", "0", "0"], ["88509.1", "0.39836088", "0", "1"], ["88509", "0.08062458", "0", "1"], ["88507", "0.42774925", "0", "2"], ["88506.5", "0.33929724", "0", "1"], ["88506", "0.39723095", "0", "2"], ["88505.9", "0", "0", "0"], ["88505.5", "0.03", "0", "1"], ["88505.4", "0.90244663", "0", "1"], ["88505.1", "0", "0", "0"], ["88504.9", "0.26604846", "0", "2"], ["88502.4", "0", "0", "0"], ["88502.3", "0", "0", "0"], ["88502.2", "0.13803377", "0", "1"], ["88502", "0.06", "0", "2"], ["88501.7", "0.22591928", "0", "1"], ["88500.3", "0", "0", "0"], ["88499.2", "0", "0", "0"], ["88498.2", "0.01650401", "0", "1"], ["88496.8", "0.03", "0", "1"], ["88493.6", "0.00059927", "0", "2"], ["88492.6", "0.03499187", "0", "1"], ["88491.2", "0.08542891", "0", "1"], ["88488.5", "0", "0", "0"], ["88488.4", "0", "0", "0"], ["88487.5", "0", "0", "0"], ["88485.1", "0", "0", "0"], ["88483.6", "0.24458586", "0", "1"], ["88479.8", "0", "0", "0"], ["88473.9", "0", "0", "0"], ["88473", "0.03018034", "0", "1"], ["88467.5", "0", "0", "0"], ["88453.9", "0", "0", "0"], ["88452.1", "0.005", "0", "1"], ["88414.8", "0.57442021", "0", "2"]], "ts": "1741338242005", "checksum": 936000468, "seqId": 48070598639, "prevSeqId": 48070598290}]}
{"arg": {"channel": "books", "instId": "BTC-USDT"}, "action": "update", "data": [{"asks": [["88520.3", "0.1538", "0", "7"], ["88525.7", "0.02387351", "0", "1"], ["88525.9", "0", "0", "0"], ["88527.7", "0.0001", "0", "1"], ["88527.8", "0.0001", "0", "1"], ["88527.9", "0.06023584", "0", "2"], ["88528.2", "0", "0", "0"], ["88528.7", "0.02631379", "0", "1"], ["88528.9", "0", "0", "0"], ["88529.2", "0", "0", "0"], ["88529.4", "0.02873608", "0", "1"], ["88529.5", "0.02562643", "0", "1"], ["88529.6", "0", "0", "0"], ["88530.1", "0.01863882", "0", "2"], ["88530.8", "0", "0", "0"], ["88530.9", "0", "0", "0"], ["88532.4", "0.08811224", "0", "2"], ["88532.5", "0.07233784", "0", "3"], ["88532.6", "0", "0", "0"], ["88533.2", "0.19022203", "0", "3"], ["88533.3", "0.06080732", "0", "3"], ["88533.4", "0", "0", "0"], ["88533.8", "0.08413162", "0", "1"], ["88534.7", "0.0186343", "0", "1"], ["88535.1", "0", "0", "0"], ["88535.2", "0", "0", "0"], ["88535.7", "0.06024722", "0", "3"], ["88535.9", "0.06023584", "0", "2"], ["88536.5", "0.14965121", "0", "1"], ["88537.6", "0.14851167", "0", "1"], ["88537.9", "0.01888533", "0", "1"], ["88538.4", "0.00028414", "0", "4"], ["88538.6", "0.1481073", "0", "1"], ["88540", "0.02213926", "0", "5"], ["88544.2", "0.04", "0", "1"], ["88554.3", "0.22592462", "0", "1"], ["88557.7", "0", "0", "0"], ["88559.5", "0.00343073", "0", "4"], ["88561.6", "1.7323567", "0", "2"], ["88567", "0.12", "0", "4"], ["88568", "0.03", "0", "1"], ["88583.3", "0.00203114", "0", "9"], ["88586", "0.01739591", "0", "1"], ["88595.6", "2.90563122", "0", "1"], ["88606.8", "0.00183733", "0", "1"], ["88607.4", "0", "0", "0"], ["88620.8", "0", "0", "0"], ["88620.9", "0", "0", "0"], ["88621", "0", "0", "0"], ["88621.1", "0", "0", "0"], ["88621.6", "0", "0", "0"]], "bids": [["88520.2", "0.17299911", "0", "5"], ["88520.1", "0.00005202", "0", "1"], ["88519.3", "0.00015466", "0", "2"], ["88519.1", "0", "0", "0"], ["88513.9", "0.0531432", "0", "1"], ["88513.8", "0", "0", "0"], ["88512.7", "0", "0", "0"], ["88512.3", "0.01129814", "0", "1"], ["88511.4", "0", "0", "0"], ["88510.9", "0.02436882", "0", "1"], ["88510.5", "0.000072", "0", "1"], ["88509.9", "0.02591678", "0", "1"], ["88509", "0", "0", "0"], ["88507", "0.33896", "0", "1"], ["88506.7", "0.08034538", "0", "1"], ["88506", "0.58291609", "0", "1"], ["88504.9", "0", "0", "0"], ["88503.5", "0.27668497", "0", "2"], ["88502.2", "0", "0", "0"], ["88501.7", "0", "0", "0"], ["88498.2", "0.22592966", "0", "1"], ["88496.8", "0", "0", "0"], ["88494.6", "0.01650401", "0", "1"], ["88492.6", "0", "0", "0"], ["88491", "0.00001", "0", "1"], ["88490.6", "1.68336292", "0", "1"], ["88486.1", "0.0372521", "0", "1"], ["88482", "0.06", "0", "2"], ["88480", "0.08194673", "0", "3"], ["88479", "0", "0", "0"], ["88478", "0", "0", "0"], ["88462", "0.01739591", "0", "1"], ["88458.4", "0", "0", "0"], ["88456.6", "2.96520676", "0", "2"], ["88456.5", "0.51451069", "0", "2"], ["88452.1", "0", "0", "0"], ["88441.5", "0", "0", "0"], ["88386.8", "0.17395912", "0", "1"], ["88384.1", "0", "0", "0"], ["88274.1", "0.03", "0", "1"], ["88274", "0.06797011", "0", "1"], ["88273.4", "0.01785714", "0", "1"], ["88272.7", "0.00003889", "0", "1"], ["88272.2", "0.00282458", "0", "1"], ["88272", "0.0025", "0", "1"]], "ts": "1741338242105", "checksum": 367712570, "seqId": 48070598940, "prevSeqId": 48070598639}]}
{"arg": {"channel": "books", "instId": "BTC-USDT"}, "action": "update", "data": [{"asks": [["88520.3", "0.26839192", "0", "9"], ["88526.3", "0.0001", "0", "1"], ["88526.4", "0.0001", "0", "1"], ["88527.7", "0", "0", "0"], ["88527.8", "0", "0", "0"], ["88528.6", "0.02830344", "0", "1"], ["88528.7", "0", "0", "0"], ["88530.9", "0.00146135", "0", "1"], ["88532.4", "0.08616913", "0", "1"], ["88533.3", "0.00057148", "0", "1"], ["88533.7", "0.17056292", "0", "2"], ["88533.8", "0", "0", "0"], ["88536.9", "0.13244352", "0", "1"], ["88538.5", "0.13787215", "0", "1"], ["88538.6", "0", "0", "0"], ["88541.4", "0.37860118", "0", "2"], ["88545.5", "1.00001035", "0", "2"], ["88554.3", "0", "0", "0"], ["88554.9", "0.22592694", "0", "1"], ["88571.2", "0.0006", "0", "2"], ["88572", "0.080495", "0", "2"], ["88572.8", "0", "0", "0"], ["88577.3", "1.39988963", "0", "2"], ["88580.5", "0.49754073", "0", "2"], ["88584.8", "0.01741092", "0", "2"], ["88586", "0", "0", "0"], ["88620.7", "0", "0", "0"]], "bids": [["88519.3", "0.0001", "0", "1"], ["88519.2", "0.00005466", "0", "1"], ["88511.3", "0.02641603", "0", "1"], ["88507.6", "0.0861425", "0", "1"], ["88505.5", "0.10816581", "0", "2"], ["88500.7", "0.13856522", "0", "1"], ["88500.4", "0.01853488", "0", "1"], ["88499.2", "0.22592694", "0", "1"], ["88498.2", "0", "0", "0"], ["88495.3", "0.01650401", "0", "1"], ["88494.6", "0", "0", "0"], ["88494.4", "0.33989651", "0", "3"], ["88493.6", "0.00029927", "0", "1"], ["88492.8", "0", "0", "0"], ["88484.8", "0.49805938", "0", "2"], ["88462", "0", "0", "0"], ["88460.9", "0.01739592", "0", "1"], ["88391.1", "0.18952577", "0", "1"], ["88386.8", "0", "0", "0"], ["88384.7", "0.17395923", "0", "1"], ["88273.4", "0", "0", "0"], ["88272.7", "0", "0", "0"], ["88272.2", "0", "0", "0"], ["88272", "0", "0", "0"]], "ts": "1741338242205", "checksum": 1842060158, "seqId": 48070599052, "prevSeqId": 48070598940}]}
{"arg": {"channel": "books", "instId": "BTC-USDT"}, "action": "update", "data": [{"asks": [["88525.7", "0.0396506", "0", "2"], ["88525.8", "0.00244251", "0", "3"], ["88526.3", "0", "0", "0"], ["88526.4", "0", "0", "0"], ["88526.9", "0.01364", "0", "1"], ["88527.8", "0.027142", "0", "1"], ["88528", "0.0635657", "0", "1"], ["88528.6", "0.02639717", "0", "1"], ["88529", "0.02633817", "0", "1"], ["88529.2", "0.00001623", "0", "1"], ["88529.4", "0", "0", "0"], ["88529.5", "0", "0", "0"], ["88530.9", "0.0011707", "0", "1"], ["88531.3", "0", "0", "0"], ["88531.5", "0.08062578", "0", "1"], ["88532.4", "0", "0", "0"], ["88532.8", "0.07298044", "0", "1"], ["88533.2", "0.18602539", "0", "3"], ["88533.4", "0.08304522", "0", "1"], ["88533.5", "0.04093", "0", "1"], ["88533.7", "0", "0", "0"], ["88535.6", "0.14246327", "0", "1"], ["88535.9", "0", "0", "0"], ["88536", "0.14298517", "0", "2"], ["88536.5", "0", "0", "0"], ["88536.9", "0", "0", "0"], ["88538.2", "0.13335318", "0", "1"], ["88538.5", "0", "0", "0"], ["88539.9", "0.00086598", "0", "2"], ["88554.9", "0", "0", "0"], ["88557.7", "0.22592612", "0", "1"], ["88576.8", "0.56613687", "0", "3"], ["88620.7", "0.00001139", "0", "1"]], "bids": [["88519.3", "0.00015466", "0", "2"], ["88519.2", "0", "0", "0"], ["88515.4", "0", "0", "0"], ["88511.3", "0", "0", "0"], ["88511", "0.00935", "0", "1"], ["88510.9", "0", "0", "0"], ["88510.7", "0", "0", "0"], ["88510.5", "0.02707032", "0", "2"], ["88510", "0.0266477", "0", "1"], ["88509.9", "0", "0", "0"], ["88509.6", "0.02756421", "0", "1"], ["88507.6", "0", "0", "0"], ["88506.7", "0.08625144", "0", "1"], ["88505.8", "0.07992195", "0", "1"], ["88505.5", "0.03", "0", "1"], ["88505.2", "0.08142473", "0", "1"], ["88504.3", "0.02805", "0", "1"], ["88503.5", "0", "0", "0"], ["88502.6", "0.28429535", "0", "2"], ["88500.7", "0", "0", "0"], ["88500.4", "0.15437624", "0", "2"], ["88499.2", "0.22592612", "0", "1"], ["88460.9", "0", "0", "0"], ["88458.4", "0.01739602", "0", "1"], ["88364.1", "0.12177848", "0", "1"], ["88273.4", "0.01785714", "0", "1"]], "ts": "1741338242305", "checksum": 1835940244, "seqId": 48070599159, "prevSeqId": 48070599052}]}
{"arg": {"channel": "books", "instId": "BTC-USDT"}, "action": "update", "data": [{"asks": [["88512.4", "0.32570203", "0", "8"], ["88512.7", "0.0001", "0", "1"], ["88512.8", "0.0001", "0", "1"], ["88514", "0.0171", "0", "1"], ["88516.7", "0.05139018", "0", "1"], ["88516.9", "0.05205327", "0", "2"], ["88518", "0.0171", "0", "1"], ["88519.2", "0.10204733", "0", "1"], ["88519.4", "0.05205327", "0", "2"], ["88520", "0.0171", "0", "1"], ["88520.3", "0.05367901", "0", "3"], ["88521.1", "0.0039", "0", "1"], ["88522", "0.0453455", "0", "2"], ["88522.1", "0.08711039", "0", "2"], ["88522.9", "0.00209084", "0", "1"], ["88523", "0.08542891", "0", "1"], ["88523.2", "0.07956854", "0", "2"], ["88523.8", "0.07112036", "0", "2"], ["88524.1", "0.02616231", "0", "1"], ["88524.3", "0.00001138", "0", "1"], ["88524.9", "0.14148951", "0", "1"], ["88525.6", "0.06023584", "0", "2"], ["88525.7", "0", "0", "0"], ["88525.8", "0.00224251", "0", "1"], ["88526.8", "0.06023584", "0", "2"], ["88527.8", "0", "0", "0"], ["88527.9", "0", "0", "0"], ["88528", "0.18474377", "0", "1"], ["88528.6", "0", "0", "0"], ["88529", "0", "0", "0"], ["88529.2", "0.207", "0", "1"], ["88530.6", "0.33929724", "0", "1"], ["88530.9", "0", "0", "0"], ["88531", "0", "0", "0"], ["88531.2", "0", "0", "0"], ["88531.5", "0", "0", "0"], ["88531.9", "0.00006", "0", "1"], ["88532.5", "0", "0", "0"], ["88532.8", "0", "0", "0"], ["88533.2", "0.79948129", "0", "4"], ["88533.3", "1.00057148", "0", "2"], ["88533.4", "0", "0", "0"], ["88535.5", "0.90244663", "0", "1"], ["88535.6", "0", "0", "0"], ["88535.7", "0.00001138", "0", "1"], ["88536", "0", "0", "0"], ["88536.5", "0.30754406", "0", "1"], ["88536.6", "0.048", "0", "1"], ["88536.8", "0.02721284", "0", "2"], ["88537", "0.20508657", "0", "2"], ["88537.6", "0", "0", "0"], ["88537.7", "0", "0", "0"], ["88537.9", "0.00338767", "0", "1"], ["88538", "0.05205327", "0", "2"], ["88538.2", "0", "0", "0"], ["88540", "0.00503926", "0", "4"], ["88540.1", "0.08703293", "0", "3"], ["88540.9", "0", "0", "0"], ["88541.2", "0.09089705", "0", "1"], ["88541.4", "0", "0", "0"], ["88542", "0", "0", "0"], ["88543", "0.22603316", "0", "3"], ["88543.9", "0.00001817", "0", "1"], ["88544.5", "0.04111578", "0", "2"], ["88545.5", "0.00001035", "0", "1"], ["88546.6", "0.12901512", "0", "4"], ["88547.8", "0.0000129", "0", "1"], ["88548.4", "0.00002745", "0", "2"], ["88550", "0.00109016", "0", "9"], ["88550.1", "0", "0", "0"], ["88557.7", "0", "0", "0"], ["88559.5", "0.98397774", "0", "5"], ["88560.9", "0.0255798", "0", "13"], ["88565", "0.06", "0", "2"], ["88567", "0.06", "0", "2"], ["88571.2", "0", "0", "0"], ["88572", "0.080795", "0", "3"], ["88572.8", "0.0003", "0", "1"], ["88576.8", "0.339112", "0", "2"], ["88577.3", "0.90244663", "0", "1"], ["88578.1", "0.00009546", "0", "3"], ["88579.3", "0", "0", "0"], ["88580.5", "0.00002973", "0", "1"], ["88581.4", "0.01693395", "0", "1"], ["88583.2", "0.0174075", "0", "2"], ["88584.8", "0.000015", "0", "1"], ["88588.8", "0.03396582", "0", "2"], ["88595.3", "0", "0", "0"], ["88603", "0.00001028", "0", "1"], ["88606.8", "0", "0", "0"], ["88611", "0.00168673", "0", "2"], ["88611.2", "0.02260989", "0", "2"], ["88613.2", "0", "0", "0"], ["88620", "0", "0", "0"], ["88620.2", "0", "0", "0"], ["88620.6", "0", "0", "0"], ["88620.7", "0", "0", "0"]], "bids": [["88520.2", "0", "0", "0"], ["88520.1", "0", "0", "0"], ["88520", "0", "0", "0"], ["88519.4", "0", "0", "0"], ["88519.3", "0", "0", "0"], ["88518", "0", "0", "0"], ["88517.4", "0", "0", "0"], ["88516.8", "0", "0", "0"], ["88516.1", "0", "0", "0"], ["88516", "0", "0", "0"], ["88515.1", "0", "0", "0"], ["88514", "0", "0", "0"], ["88513.9", "0", "0", "0"], ["88513.6", "0", "0", "0"], ["88513.1", "0", "0", "0"], ["88512.8", "0", "0", "0"], ["88512.3", "0.06499814", "0", "3"], ["88512.2", "0.00009301", "0", "1"], ["88511.7", "0", "0", "0"], ["88511", "0", "0", "0"], ["88510.5", "0", "0", "0"], ["88510.4", "0", "0", "0"], ["88510", "0.0171", "0", "1"], ["88509.6", "0", "0", "0"], ["88509.1", "0", "0", "0"], ["88508.8", "0.0001", "0", "1"], ["88508.7", "0.00935", "0", "1"], ["88508.2", "0.00734323", "0", "1"], ["88508", "0.0171", "0", "1"], ["88507.2", "0", "0", "0"], ["88507", "0", "0", "0"], ["88506.7", "0", "0", "0"], ["88506.5", "0", "0", "0"], ["88506.4", "0", "0", "0"], ["88506", "0", "0", "0"], ["88505.8", "0", "0", "0"], ["88505.5", "0", "0", "0"], ["88505.4", "0.01212974", "0", "2"], ["88505.3", "0", "0", "0"], ["88505.2", "0", "0", "0"], ["88504.3", "0", "0", "0"], ["88503.9", "0.04", "0", "1"], ["88502.6", "0", "0", "0"], ["88502.5", "0.00007275", "0", "1"], ["88502", "0", "0", "0"], ["88501.6", "0.112639", "0", "2"], ["88501.3", "0", "0", "0"], ["88500.4", "0.01853488", "0", "1"], ["88499.7", "0.03", "0", "1"], ["88499.3", "0.05129366", "0", "2"], ["88499.2", "0", "0", "0"], ["88499.1", "0", "0", "0"], ["88498.8", "0", "0", "0"], ["88496.7", "0", "0", "0"], ["88496.1", "0.03001138", "0", "2"], ["88496", "0.08132106", "0", "1"], ["88495.3", "0", "0", "0"], ["88495.2", "0.39072036", "0", "2"], ["88495", "0.08833034", "0", "1"], ["88494.8", "0", "0", "0"], ["88494.4", "0.33929724", "0", "1"], ["88493.9", "0", "0", "0"], ["88493.7", "0", "0", "0"], ["88493.6", "0", "0", "0"], ["88492.7", "0.78261834", "0", "2"], ["88492.2", "0", "0", "0"], ["88492", "0", "0", "0"], ["88491.9", "0.16593876", "0", "2"], ["88491.2", "0", "0", "0"], ["88490.2", "0", "0", "0"], ["88488.7", "0.000168", "0", "1"], ["88487.1", "0.55938403", "0", "1"], ["88486.4", "0.000615", "0", "3"], ["88486.1", "0", "0", "0"], ["88485.6", "0.0002993", "0", "1"], ["88485.1", "0.22595897", "0", "1"], ["88484.8", "0.00001138", "0", "1"], ["88484.5", "0.00343", "0", "1"], ["88482", "0", "0", "0"], ["88481", "0", "0", "0"], ["88480.5", "0.11301686", "0", "1"], ["88480", "0.05194673", "0", "2"], ["88476.7", "0", "0", "0"], ["88476.5", "0.03613105", "0", "1"], ["88473.4", "0.00001138", "0", "1"], ["88473.1", "0.44341", "0", "1"], ["88473", "0.09018034", "0", "3"], ["88472", "0.06", "0", "2"], ["88471", "0.36929724", "0", "2"], ["88470.2", "0", "0", "0"], ["88467.8", "0.01121138", "0", "2"], ["88466.2", "0.01650401", "0", "1"], ["88464.5", "0", "0", "0"], ["88461.3", "0.17107262", "0", "3"], ["88458.4", "0.01739744", "0", "1"], ["88458.3", "0.02260905", "0", "1"], ["88456.7", "1.40659375", "0", "1"], ["88456.6", "2.96417989", "0", "1"], ["88456.5", "0.00001138", "0", "1"], ["88455.2", "0.00102706", "0", "1"], ["88453", "1.6079432", "0", "1"], ["88452.9", "2.12624221", "0", "1"], ["88450.2", "0", "0", "0"], ["88449.7", "0", "0", "0"], ["88449.5", "0.01688841", "0", "1"], ["88447.3", "0.00098704", "0", "1"], ["88447.2", "0", "0", "0"], ["88447", "0.14538332", "0", "2"], ["88443.1", "0.04442961", "0", "2"], ["88431.6", "0.02259394", "0", "1"], ["88424.4", "0.21123262", "0", "2"], ["88423.5", "0", "0", "0"], ["88418.4", "0", "0", "0"], ["88414.8", "0.00565", "0", "1"], ["88409.7", "0.01655265", "0", "1"], ["88404", "0.02259489", "0", "1"], ["88384.7", "0", "0", "0"], ["88384.1", "0.17397441", "0", "1"], ["88364.1", "0", "0", "0"], ["88349", "0.00001138", "0", "1"], ["88303.1", "0.207", "0", "1"], ["88294.2", "0.207", "0", "1"], ["88272.7", "0.00003889", "0", "1"], ["88272.2", "0.00282458", "0", "1"], ["88272", "0.0025", "0", "1"], ["88271.5", "0.01148", "0", "1"], ["88271.3", "0.00002208", "0", "1"], ["88270.8", "0.00001148", "0", "1"], ["88270.7", "0.00003554", "0", "1"], ["88270", "0.00004066", "0", "1"], ["88269.4", "0.11343045", "0", "1"], ["88269.3", "0.34056098", "0", "1"], ["88269.2", "0.08542891", "0", "1"], ["88268.6", "0.00282509", "0", "1"], ["88267.4", "0.00011329", "0", "1"], ["88267.2", "0.00002851", "0", "1"], ["88266.6", "0.0128608", "0", "15"], ["88265.3", "0.00004344", "0", "1"], ["88264.7", "0.00004446", "0", "3"], ["88264.4", "0.00024852", "0", "1"], ["88264.2", "0.00001139", "0", "1"], ["88262.9", "0.00168511", "0", "2"], ["88261.8", "0.00074456", "0", "1"], ["88260.8", "0.00010584", "0", "1"], ["88260", "0.00002148", "0", "1"], ["88259.2", "0.00005974", "0", "1"], ["88259.1", "0.00011181", "0", "1"], ["88258.7", "0.00282652", "0", "1"], ["88257.9", "0.00020125", "0", "2"], ["88257.6", "0.00003493", "0", "1"], ["88256.9", "0.34056098", "0", "1"]], "ts": "1741338242405", "checksum": 1281779120, "seqId": 48070600126, "prevSeqId": 48070599159}]}
{"arg": {"channel": "books", "instId": "BTC-USDT"}, "action": "update", "data": [{"asks": [["88512.4", "0.3627716", "0", "7"], ["88512.7", "0", "0", "0"], ["88512.8", "0", "0", "0"], ["88514.1", "0.005", "0", "1"], ["88515", "0.0001", "0", "1"], ["88516.7", "0", "0", "0"], ["88516.9", "0.016", "0", "1"], ["88517.8", "0.0001", "0", "1"], ["88519.2", "0.05180219", "0", "1"], ["88519.4", "0.016", "0", "1"], ["88519.5", "0.02707334", "0", "1"], ["88520.3", "0.04350471", "0", "3"], ["88521.1", "0", "0", "0"], ["88521.9", "0.00209084", "0", "1"], ["88522", "0.0862855", "0", "3"], ["88522.1", "0.005", "0", "1"], ["88522.3", "0.0073436", "0", "1"], ["88522.9", "0", "0", "0"], ["88523", "0", "0", "0"], ["88523.1", "0.01888533", "0", "1"], ["88523.2", "0.1021964", "0", "3"], ["88523.8", "0.03413752", "0", "1"], ["88524.1", "0", "0", "0"], ["88524.5", "0.07736374", "0", "1"], ["88524.8", "0.005", "0", "1"], ["88524.9", "0", "0", "0"], ["88525.4", "0.08087682", "0", "1"], ["88525.6", "0", "0", "0"], ["88526.9", "0", "0", "0"], ["88527.3", "0.13986173", "0", "1"], ["88528", "0.45154376", "0", "2"], ["88532.9", "1.4427493", "0", "2"], ["88533.2", "0.11854797", "0", "2"], ["88533.3", "0.00057148", "0", "1"], ["88533.5", "0", "0", "0"], ["88535.9", "0.02616231", "0", "1"], ["88537", "0.14172635", "0", "1"], ["88538.1", "0.03907794", "0", "4"], ["88540.1", "0.13503293", "0", "4"], ["88541.1", "0.22596049", "0", "1"], ["88543", "0.00007419", "0", "2"], ["88543.7", "0.00001033", "0", "1"], ["88546.6", "0.08101512", "0", "3"], ["88555.9", "0.0373002", "0", "1"], ["88560", "0.06474113", "0", "8"], ["88560.9", "0.0005061", "0", "12"], ["88561", "0.03", "0", "1"], ["88564.5", "0.0250737", "0", "1"], ["88567", "0", "0", "0"], ["88568", "0", "0", "0"], ["88571.3", "0.497477", "0", "1"], ["88572", "0.20939636", "0", "4"], ["88574.7", "0.497543", "0", "1"], ["88574.9", "0.01739914", "0", "1"], ["88578.4", "0.1", "0", "1"], ["88583.2", "0.00001006", "0", "1"], ["88602.4", "0.242775", "0", "2"], ["88607.4", "0.00167656", "0", "1"], ["88611", "0.00001016", "0", "1"], ["88618.2", "0", "0", "0"], ["88618.5", "0", "0", "0"], ["88618.7", "0", "0", "0"], ["88618.8", "0", "0", "0"], ["88618.9", "0", "0", "0"], ["88619.2", "0", "0", "0"], ["88619.6", "0", "0", "0"], ["88619.8", "0", "0", "0"], ["88619.9", "0", "0", "0"]], "bids": [["88512.3", "0.16589725", "0", "5"], ["88512", "0.0171", "0", "1"], ["88511.8", "0.0001", "0", "1"], ["88508.9", "0.0001", "0", "1"], ["88508.8", "0", "0", "0"], ["88508.2", "0", "0", "0"], ["88507.4", "0.05990008", "0", "3"], ["88505.4", "0", "0", "0"], ["88504.1", "0.12622343", "0", "3"], ["88502.6", "0.000072", "0", "1"], ["88502.5", "0.0598887", "0", "2"], ["88501.7", "0.02767887", "0", "1"], ["88501.6", "0.26319467", "0", "2"], ["88500.3", "0.33898", "0", "1"], ["88499.3", "0", "0", "0"], ["88498.9", "0.00935", "0", "1"], ["88498.5", "0.33899", "0", "1"], ["88497.2", "0.07993862", "0", "1"], ["88496.6", "0.128135", "0", "1"], ["88496.2", "0.03", "0", "1"], ["88496", "0", "0", "0"], ["88495.2", "0.5469121", "0", "3"], ["88495.1", "0", "0", "0"], ["88495", "0", "0", "0"], ["88494.5", "1.10944663", "0", "2"], ["88494.3", "0.29462908", "0", "3"], ["88493.3", "0.11300064", "0", "1"], ["88492.8", "0.015", "0", "1"], ["88492.7", "0.53747017", "0", "1"], ["88492.4", "0.14807275", "0", "1"], ["88492.3", "0.02806", "0", "1"], ["88491.9", "0.016", "0", "1"], ["88491.8", "0", "0", "0"], ["88491", "0", "0", "0"], ["88488.7", "0", "0", "0"], ["88486.4", "0.000015", "0", "1"], ["88485.8", "0.04", "0", "1"], ["88485.6", "0.0005993", "0", "2"], ["88485.1", "0", "0", "0"], ["88485", "0.93929783", "0", "2"], ["88484.8", "0.00031068", "0", "2"], ["88481.8", "0.22596049", "0", "1"], ["88479.1", "0.24794291", "0", "2"], ["88478.8", "0.498082", "0", "1"], ["88477.8", "0.20567", "0", "1"], ["88470.6", "0.005", "0", "1"], ["88469.1", "0.01650401", "0", "1"], ["88466.2", "0", "0", "0"], ["88460", "0.005015", "0", "2"], ["88458.4", "0", "0", "0"], ["88455.2", "0", "0", "0"], ["88451.3", "0.01739914", "0", "1"], ["88449.6", "0.00102705", "0", "1"], ["88447.3", "0", "0", "0"], ["88443.1", "0.23583693", "0", "3"], ["88443", "0.747939", "0", "1"], ["88441.4", "0.00098703", "0", "1"], ["88438.6", "0", "0", "0"], ["88424.4", "0.00451934", "0", "1"], ["88393.3", "0", "0", "0"], ["88391.1", "0", "0", "0"], ["88386.8", "0.00212362", "0", "1"], ["88384.1", "0", "0", "0"], ["88376", "0.17399143", "0", "1"], ["88260.8", "0", "0", "0"], ["88260", "0", "0", "0"], ["88259.2", "0", "0", "0"], ["88259.1", "0", "0", "0"], ["88258.7", "0", "0", "0"], ["88257.9", "0", "0", "0"], ["88257.6", "0", "0", "0"], ["88256.9", "0", "0", "0"]], "ts": "1741338242505", "checksum": -1842158514, "seqId": 48070600533, "prevSeqId": 48070600126}]}
{"arg": {"channel": "books", "instId": "BTC-USDT"}, "action": "update", "data": [{"asks": [["88512.4", "0.3720616", "0", "9"], ["88514.9", "0.0002", "0", "2"], ["88515", "0", "0", "0"], ["88517.1", "0.03917528", "0", "1"], ["88517.8", "0.02941008", "0", "1"], ["88518.6", "0.0247862", "0", "1"], ["88518.8", "0.0009375", "0", "1"], ["88519.1", "0.0598887", "0", "2"], ["88519.2", "0.10122493", "0", "2"], ["88519.5", "0", "0", "0"], ["88520.3", "0.01762574", "0", "2"], ["88521.4", "0.00209084", "0", "1"], ["88521.5", "0.08489148", "0", "1"], ["88521.9", "0", "0", "0"], ["88522", "0.1049198", "0", "4"], ["88522.8", "0.07657794", "0", "1"], ["88523.2", "0.012117", "0", "2"], ["88523.8", "0.11895963", "0", "2"], ["88524.5", "0", "0", "0"], ["88525.4", "0", "0", "0"], ["88525.6", "0.14445271", "0", "1"], ["88526", "0.14773097", "0", "2"], ["88527.3", "0", "0", "0"], ["88528", "0.18474377", "0", "1"], ["88528.6", "0.13451792", "0", "1"], ["88532.6", "0.7586493", "0", "1"], ["88532.7", "1.005", "0", "2"], ["88532.9", "0", "0", "0"], ["88534.5", "0.048", "0", "1"], ["88534.7", "0", "0", "0"], ["88537", "0.2236638", "0", "2"], ["88537.9", "0", "0", "0"], ["88541.1", "0", "0", "0"], ["88541.2", "0.12019569", "0", "2"], ["88543", "0.22603476", "0", "3"], ["88543.1", "0.11474824", "0", "2"], ["88546.6", "0.03901512", "0", "2"], ["88564.5", "0", "0", "0"], ["88571.4", "0.11558794", "0", "22"], ["88578.4", "0", "0", "0"], ["88600.1", "0", "0", "0"], ["88618.2", "0.0000551", "0", "1"]], "bids": [["88512.3", "0.06499814", "0", "3"], ["88511.8", "0", "0", "0"], ["88509.8", "0.0001", "0", "1"], ["88509.5", "0.0001", "0", "1"], ["88508.9", "0", "0", "0"], ["88504.2", "0.04994337", "0", "2"], ["88504.1", "0.06633473", "0", "1"], ["88501.7", "0", "0", "0"], ["88501.6", "0.32343944", "0", "2"], ["88500.4", "0.02772748", "0", "1"], ["88500", "0.02757552", "0", "1"], ["88499.9", "0.02853739", "0", "2"], ["88497.2", "0", "0", "0"], ["88496.7", "0.41799008", "0", "2"], ["88495.8", "0.07954817", "0", "1"], ["88495.6", "0.08479428", "0", "1"], ["88494.5", "0.90244663", "0", "1"], ["88494.3", "0.147132", "0", "2"], ["88493.4", "0.015", "0", "1"], ["88492.8", "0", "0", "0"], ["88492.6", "0.27002595", "0", "2"], ["88492.4", "0", "0", "0"], ["88490.8", "0.13681531", "0", "1"], ["88488.9", "0.003855", "0", "1"], ["88481.8", "0.22596077", "0", "1"], ["88472", "0", "0", "0"], ["88471", "0.39929724", "0", "3"], ["88470.3", "0", "0", "0"], ["88470.1", "0.02338604", "0", "1"], ["88470", "0.03", "0", "1"], ["88469.1", "0", "0", "0"], ["88466.2", "0.01650401", "0", "1"], ["88465.5", "0.1", "0", "1"], ["88456", "0.33915", "0", "1"], ["88443.1", "0.04442961", "0", "2"], ["88417.3", "0.01903351", "0", "1"], ["88267.2", "0", "0", "0"], ["88266.6", "0", "0", "0"], ["88265.3", "0", "0", "0"], ["88264.7", "0", "0", "0"], ["88264.4", "0", "0", "0"], ["88264.2", "0", "0", "0"], ["88262.9", "0", "0", "0"], ["88261.8", "0", "0", "0"]], "ts": "1741338242605", "checksum": -1979757497, "seqId": 48070600761, "prevSeqId": 48070600533}]}
{"arg": {"channel": "books", "instId": "BTC-USDT"}, "action": "update", "data": [{"asks": [["88512.4", "0.3873059", "0", "9"], ["88514.2", "0.01364", "0", "1"], ["88515.7", "0.02818685", "0", "1"], ["88515.9", "0.03692056", "0", "1"], ["88516.6", "0.02553621", "0", "1"], ["88517.1", "0", "0", "0"], ["88517.2", "0.02788416", "0", "1"], ["88517.8", "0", "0", "0"], ["88518.6", "0", "0", "0"], ["88519.2", "0.19020496", "0", "1"], ["88519.4", "0.10074796", "0", "2"], ["88520.8", "0.07685154", "0", "1"], ["88521.4", "0", "0", "0"], ["88521.5", "0.08545092", "0", "1"], ["88521.6", "0.00209084", "0", "1"], ["88521.7", "0.33929724", "0", "1"], ["88522", "0.05804", "0", "2"], ["88522.8", "0", "0", "0"], ["88523.2", "0.000015", "0", "1"], ["88523.6", "0.13321863", "0", "1"], ["88523.8", "0.0903216", "0", "1"], ["88524", "0.15443782", "0", "2"], ["88525.6", "0", "0", "0"], ["88526", "0.0171", "0", "1"], ["88526.3", "0.14303664", "0", "1"], ["88526.8", "0", "0", "0"], ["88528", "0.45563576", "0", "2"], ["88528.3", "1", "0", "1"], ["88528.6", "0", "0", "0"], ["88529.3", "0.01364", "0", "1"], ["88532.6", "0.44111832", "0", "1"], ["88532.7", "0.005", "0", "1"], ["88533.7", "0.04", "0", "1"], ["88535.9", "0", "0", "0"], ["88536.8", "0.01357284", "0", "1"], ["88539.6", "0.22628557", "0", "3"], ["88541.2", "0.0598943", "0", "1"], ["88542.3", "0.00344413", "0", "2"], ["88543", "0.00007419", "0", "2"], ["88544.1", "0.02623897", "0", "2"], ["88544.2", "0", "0", "0"], ["88546.6", "0.00001512", "0", "1"], ["88557", "0.06", "0", "2"], ["88565", "0", "0", "0"], ["88583.4", "0.03555632", "0", "2"], ["88588.8", "0.00011082", "0", "1"], ["88593.8", "0.07357739", "0", "2"], ["88597.1", "0.00002384", "0", "1"], ["88617.9", "0", "0", "0"], ["88618.1", "0", "0", "0"], ["88618.2", "0", "0", "0"]], "bids": [["88512.3", "0.01129814", "0", "1"], ["88512", "0", "0", "0"], ["88510", "0", "0", "0"], ["88509.8", "0", "0", "0"], ["88509.5", "0", "0", "0"], ["88508.7", "0", "0", "0"], ["88508.4", "0.0001", "0", "1"], ["88508", "0", "0", "0"], ["88507.4", "0.00001138", "0", "1"], ["88507.1", "0.0001", "0", "1"], ["88504.2", "0", "0", "0"], ["88504.1", "0", "0", "0"], ["88504", "0", "0", "0"], ["88501.6", "0", "0", "0"], ["88501.3", "0.00935", "0", "1"], ["88501.1", "0", "0", "0"], ["88500.4", "0", "0", "0"], ["88500", "0", "0", "0"], ["88499.9", "0.00057148", "0", "1"], ["88499.7", "0", "0", "0"], ["88498.9", "0", "0", "0"], ["88498.4", "0.02906155", "0", "1"], ["88498", "0.02700055", "0", "1"], ["88497.7", "0.02725873", "0", "1"], ["88497.6", "0", "0", "0"], ["88496.7", "0.339", "0", "1"], ["88496.2", "0", "0", "0"], ["88496.1", "0.00001138", "0", "1"], ["88495.8", "0", "0", "0"], ["88495.6", "0", "0", "0"], ["88494.7", "0.0878333", "0", "1"], ["88494.6", "0.00935", "0", "1"], ["88493.7", "0.081936", "0", "1"], ["88493.3", "0.19509009", "0", "2"], ["88492.6", "0", "0", "0"], ["88492.3", "0", "0", "0"], ["88490.8", "0", "0", "0"], ["88490.6", "0.14006706", "0", "1"], ["88490.5", "0.12869056", "0", "1"], ["88488.9", "0", "0", "0"], ["88488.5", "0.13915215", "0", "1"], ["88488", "0.02806", "0", "1"], ["88485.8", "0", "0", "0"], ["88485.6", "0", "0", "0"], ["88484.8", "0.00061068", "0", "3"], ["88484", "0.0002993", "0", "1"], ["88481.8", "0", "0", "0"], ["88479.3", "0.21717968", "0", "1"], ["88479.2", "0.22596796", "0", "1"], ["88479.1", "0.00001138", "0", "1"], ["88478.8", "0", "0", "0"], ["88478.2", "0", "0", "0"], ["88476.5", "0", "0", "0"], ["88474.8", "0.03725685", "0", "1"], ["88473", "0", "0", "0"], ["88472", "0.06", "0", "2"], ["88470.2", "0.01650401", "0", "1"], ["88467", "0.03311363", "0", "1"], ["88466.2", "0", "0", "0"], ["88466.1", "0.39951597", "0", "1"], ["88465.8", "0", "0", "0"], ["88462.5", "0", "0", "0"], ["88457.4", "0.01695768", "0", "1"], ["88456.6", "0", "0", "0"], ["88418.5", "0", "0", "0"], ["88411.4", "0.00019407", "0", "1"], ["88267.2", "0.00002851", "0", "1"], ["88266.6", "0.0128608", "0", "15"], ["88265.3", "0.00004344", "0", "1"], ["88264.7", "0.00004446", "0", "3"], ["88264.4", "0.00024852", "0", "1"], ["88264.2", "0.00001139", "0", "1"], ["88262.9", "0.00168511", "0", "2"], ["88261.8", "0.00074456", "0", "1"], ["88260.8", "0.00010584", "0", "1"], ["88260", "0.00002148", "0", "1"], ["88259.2", "0.00005974", "0", "1"], ["88259.1", "0.00011181", "0", "1"], ["88258.7", "0.00282652", "0", "1"], ["88257.9", "0.00020125", "0", "2"]], "ts": "1741338242705", "checksum": -1724675127, "seqId": 48070601017, "prevSeqId": 48070600761}]}
{"arg": {"channel": "books", "instId": "BTC-USDT"}, "action": "update", "data": [{"asks": [["88506.1", "0.17766305", "0", "4"], ["88508", "0.0171", "0", "1"], ["88508.4", "0.0001", "0", "1"], ["88508.6", "0.0001", "0", "1"], ["88510", "0.0171", "0", "1"], ["88511.6", "0.03348861", "0", "1"], ["88511.7", "0.0598887", "0", "2"], ["88512.3", "0.016", "0", "1"], ["88512.4", "0.0186343", "0", "1"], ["88514.3", "0.02782264", "0", "1"], ["88514.9", "0", "0", "0"], ["88515.7", "0", "0", "0"], ["88515.9", "0.11705019", "0", "1"], ["88516.3", "0.012102", "0", "1"], ["88516.4", "0.207", "0", "1"], ["88516.6", "0", "0", "0"], ["88517.2", "0", "0", "0"], ["88518", "0.0991279", "0", "2"], ["88519.1", "0.00068752", "0", "1"], ["88519.2", "0.2443634", "0", "2"], ["88519.4", "0.016", "0", "1"], ["88520.8", "0", "0", "0"], ["88521.5", "0", "0", "0"], ["88521.6", "0", "0", "0"], ["88522", "0.0171", "0", "1"], ["88522.1", "0.14080795", "0", "2"], ["88522.5", "0.00006", "0", "1"], ["88523.6", "0", "0", "0"], ["88523.8", "0.3462248", "0", "2"], ["88524", "0.0171", "0", "1"], ["88526.3", "0", "0", "0"], ["88526.9", "1", "0", "1"], ["88527.7", "0.048", "0", "1"], ["88528", "0.18474377", "0", "1"], ["88528.3", "0", "0", "0"], ["88530", "0.11296519", "0", "2"], ["88530.1", "0.06663882", "0", "3"], ["88531.2", "0.087", "0", "2"], ["88531.9", "0", "0", "0"], ["88532", "0.00001501", "0", "1"], ["88534", "0", "0", "0"], ["88534.5", "0", "0", "0"], ["88537.9", "0.22597352", "0", "1"], ["88539.6", "0.00031761", "0", "2"], ["88540.1", "0.09003293", "0", "3"], ["88546.5", "0.00001", "0", "1"], ["88549.5", "0.073566", "0", "1"], ["88555.9", "0", "0", "0"], ["88557", "0", "0", "0"], ["88557.7", "0.0250737", "0", "1"], ["88558", "0.26704957", "0", "6"], ["88564", "0.19048476", "0", "3"], ["88566.2", "0.45239", "0", "1"], ["88569.4", "0.10292156", "0", "2"], ["88569.6", "0.01739984", "0", "1"], ["88570.3", "0.00461", "0", "2"], ["88570.6", "0.00112904", "0", "1"], ["88570.7", "0.00112904", "0", "1"], ["88571.3", "0", "0", "0"], ["88571.4", "0.01558794", "0", "21"], ["88572", "0.080795", "0", "3"], ["88574.7", "0", "0", "0"], ["88574.9", "0", "0", "0"], ["88577.6", "0.06396084", "0", "5"], ["88583.4", "0.0048", "0", "1"], ["88589.9", "0", "0", "0"], ["88590.8", "0", "0", "0"], ["88599.5", "0.08021231", "0", "2"], ["88599.8", "0.00167663", "0", "1"], ["88607.4", "0", "0", "0"], ["88607.5", "0", "0", "0"], ["88617.6", "0", "0", "0"]], "bids": [["88512.3", "0", "0", "0"], ["88512.2", "0", "0", "0"], ["88508.4", "0", "0", "0"], ["88507.4", "0", "0", "0"], ["88507.1", "0", "0", "0"], ["88506", "0.2771", "0", "5"], ["88505.9", "0.00011626", "0", "1"], ["88505.5", "0.0001", "0", "1"], ["88505.2", "0.0001", "0", "1"], ["88504", "0.0171", "0", "1"], ["88503", "0.1", "0", "1"], ["88502.6", "0", "0", "0"], ["88502.5", "0", "0", "0"], ["88502", "0.0171", "0", "1"], ["88501.8", "0", "0", "0"], ["88500.4", "0.2069747", "0", "1"], ["88498.4", "0", "0", "0"], ["88498.3", "0.01129993", "0", "1"], ["88498.1", "0", "0", "0"], ["88498", "0", "0", "0"], ["88497.7", "0", "0", "0"], ["88497", "0.02698479", "0", "1"], ["88496.8", "0.25227689", "0", "1"], ["88496.6", "0", "0", "0"], ["88496.2", "0.00007275", "0", "1"], ["88495.3", "0.02736068", "0", "1"], ["88495.2", "0.00001501", "0", "1"], ["88494.7", "0", "0", "0"], ["88494.6", "0", "0", "0"], ["88494.5", "0", "0", "0"], ["88494.4", "0", "0", "0"], ["88493.7", "0", "0", "0"], ["88493.3", "0.19495772", "0", "2"], ["88492.7", "0.24191968", "0", "2"], ["88490.9", "0.07853941", "0", "1"], ["88490.6", "0", "0", "0"], ["88490.5", "0", "0", "0"], ["88490.2", "0.33929724", "0", "1"], ["88489.9", "0.00452029", "0", "1"], ["88489.2", "0.0034726", "0", "1"], ["88489.1", "0.19484302", "0", "3"], ["88488.8", "0.12363443", "0", "1"], ["88488.5", "0", "0", "0"], ["88487.1", "0.40643024", "0", "1"], ["88487", "0", "0", "0"], ["88486", "0.131458", "0", "1"], ["88485.6", "0.06", "0", "2"], ["88485", "0.90244663", "0", "1"], ["88484.8", "0.00001138", "0", "1"], ["88484.5", "0", "0", "0"], ["88484", "0", "0", "0"], ["88480.7", "0.22597352", "0", "1"], ["88480", "0.09254605", "0", "5"], ["88479.3", "0.09573464", "0", "1"], ["88479.2", "0.00029932", "0", "1"], ["88474.9", "0.00343", "0", "1"], ["88473.3", "0.18391502", "0", "1"], ["88472.9", "0", "0", "0"], ["88472", "0", "0", "0"], ["88471", "0.33929724", "0", "1"], ["88470.2", "0", "0", "0"], ["88470.1", "0.03238604", "0", "1"], ["88470", "0", "0", "0"], ["88468", "0.06", "0", "2"], ["88467", "0", "0", "0"], ["88466", "0.06", "0", "2"], ["88465.5", "0", "0", "0"], ["88465", "0.03", "0", "1"], ["88464.6", "0.47714", "0", "1"], ["88463.9", "0", "0", "0"], ["88463.5", "0.1", "0", "1"], ["88461.2", "0.35580125", "0", "2"], ["88456.7", "0.61877672", "0", "1"], ["88454.5", "0", "0", "0"], ["88451.3", "0", "0", "0"], ["88450.1", "0", "0", "0"], ["88449.6", "0", "0", "0"], ["88445.8", "0.01739984", "0", "1"], ["88445.7", "0", "0", "0"], ["88443.9", "0", "0", "0"], ["88443.2", "0.00102724", "0", "1"], ["88443.1", "0.10289178", "0", "3"], ["88443", "0", "0", "0"], ["88441.4", "0", "0", "0"], ["88436.3", "0.00098721", "0", "1"], ["88435.9", "0.64877096", "0", "1"], ["88434", "0.20256341", "0", "1"], ["88431.6", "0", "0", "0"], ["88431.3", "0", "0", "0"], ["88430.2", "0.06150749", "0", "2"], ["88427.2", "0", "0", "0"], ["88424.5", "0.20129104", "0", "1"], ["88422.3", "0.01590128", "0", "1"], ["88421.9", "0.02727908", "0", "1"], ["88419", "0.00093027", "0", "1"], ["88414.8", "0.53680819", "0", "3"], ["88413.4", "0", "0", "0"], ["88403.4", "0", "0", "0"], ["88376", "0", "0", "0"], ["88371.3", "0.20792586", "0", "2"], ["88370.6", "0.17399842", "0", "1"], ["88347.1", "0", "0", "0"], ["88337.7", "0", "0", "0"], ["88307.5", "0", "0", "0"], ["88289.8", "0.00566329", "0", "1"], ["88257.6", "0.00003493", "0", "1"], ["88256.9", "0.34056098", "0", "1"], ["88256.4", "0.0000172", "0", "1"], ["88255.8", "0.00003183", "0", "1"], ["88255.6", "0.12221196", "0", "1"], ["88255", "0.01785714", "0", "1"], ["88254.3", "0.00012967", "0", "2"], ["88253.7", "0.00608886", "0", "2"]], "ts": "1741338242805", "checksum": -429999051, "seqId": 48070601699, "prevSeqId": 48070601017}]}
{"arg": {"channel": "books", "instId": "BTC-USDT"}, "action": "update", "data": [{"asks": [["88507", "0.04421493", "0", "1"], ["88507.1", "0.11298309", "0", "1"], ["88508.4", "0", "0", "0"], ["88508.6", "0.0002", "0", "2"], ["88513.8", "0.02863812", "0", "1"], ["88514.3", "0", "0", "0"], ["88514.8", "0.02609574", "0", "1"], ["88515.1", "0.02617708", "0", "1"], ["88515.8", "0.00012275", "0", "1"], ["88515.9", "0.11564984", "0", "2"], ["88517.1", "0.0000225", "0", "1"], ["88517.5", "0.08932645", "0", "1"], ["88518", "0.0171", "0", "1"], ["88518.8", "0", "0", "0"], ["88519.1", "0.07494251", "0", "1"], ["88519.2", "0.21622434", "0", "2"], ["88519.5", "0.07921839", "0", "1"], ["88521.7", "0.47191289", "0", "2"], ["88522.1", "0.005", "0", "1"], ["88522.4", "0.12705682", "0", "1"], ["88524.4", "0.14442415", "0", "1"], ["88531.2", "0.174", "0", "4"], ["88540.1", "0.04203293", "0", "2"], ["88561.3", "0.497533", "0", "1"], ["88564", "0.32452607", "0", "2"], ["88564.9", "0.49761526", "0", "2"], ["88576.2", "0.03269151", "0", "1"], ["88593.8", "0.00001139", "0", "1"], ["88615.2", "0", "0", "0"], ["88615.3", "0", "0", "0"], ["88615.4", "0", "0", "0"], ["88615.9", "0", "0", "0"], ["88616", "0", "0", "0"], ["88616.1", "0", "0", "0"], ["88616.2", "0", "0", "0"], ["88616.6", "0", "0", "0"], ["88616.7", "0", "0", "0"], ["88616.8", "0", "0", "0"]], "bids": [["88505.5", "0", "0", "0"], ["88505.3", "0.0002", "0", "2"], ["88505.2", "0", "0", "0"], ["88503.4", "0.11298766", "0", "1"], ["88500.7", "0.00935", "0", "1"], ["88497.5", "0.00734413", "0", "1"], ["88497", "0", "0", "0"], ["88496.8", "0.18646792", "0", "1"], ["88496.5", "0.02660034", "0", "1"], ["88495.9", "0.02436838", "0", "1"], ["88495.3", "0.02799521", "0", "1"], ["88493.3", "0.11300064", "0", "1"], ["88492.8", "0.08913813", "0", "1"], ["88491.6", "0.26257406", "0", "2"], ["88490.9", "0", "0", "0"], ["88490.8", "0.08423266", "0", "1"], ["88489.1", "0.06", "0", "2"], ["88488.8", "0", "0", "0"], ["88488.7", "0.14481742", "0", "1"], ["88488.3", "0.1386135", "0", "1"], ["88488.1", "0.0194028", "0", "1"], ["88488", "0", "0", "0"], ["88486.3", "0.0000525", "0", "1"], ["88486", "0", "0", "0"], ["88485.9", "0.1295168", "0", "1"], ["88485.6", "0.12", "0", "4"], ["88474.7", "0.53763122", "0", "1"], ["88470.1", "0.17778069", "0", "2"], ["88468.1", "0.498143", "0", "1"], ["88463.5", "0", "0", "0"], ["88462.7", "0.03460816", "0", "1"], ["88461.4", "0.01650401", "0", "1"], ["88461.2", "0.33929724", "0", "1"], ["88459.2", "0.1", "0", "1"], ["88453.8", "0.61156745", "0", "2"], ["88451.8", "0.35601724", "0", "2"], ["88448.4", "0.00289125", "0", "1"], ["88444", "0.00289125", "0", "1"], ["88439.6", "0.00289125", "0", "1"], ["88430.8", "0.28244887", "0", "1"], ["88430.7", "0.747017", "0", "1"], ["88430.2", "0.0045196", "0", "1"], ["88422.6", "0", "0", "0"], ["88415.3", "0.00114996", "0", "1"], ["88414.6", "0.746895", "0", "1"], ["88405.3", "0.0007203", "0", "1"], ["88386.8", "0", "0", "0"], ["88381.8", "0.00212486", "0", "1"], ["88343.3", "0.00001138", "0", "1"], ["88326.7", "0.00001138", "0", "1"], ["88264.7", "0", "0", "0"], ["88264.4", "0", "0", "0"], ["88264.2", "0", "0", "0"], ["88262.9", "0", "0", "0"], ["88261.8", "0", "0", "0"], ["88260.8", "0", "0", "0"], ["88260", "0", "0", "0"], ["88259.2", "0", "0", "0"], ["88259.1", "0", "0", "0"], ["88258.7", "0", "0", "0"], ["88257.9", "0", "0", "0"], ["88257.6", "0", "0", "0"], ["88256.9", "0", "0", "0"], ["88256.4", "0", "0", "0"], ["88255.8", "0", "0", "0"], ["88255.6", "0", "0", "0"], ["88255", "0", "0", "0"], ["88254.3", "0", "0", "0"], ["88253.7", "0", "0", "0"]], "ts": "1741338242905", "checksum": 1568447617, "seqId": 48070601863, "prevSeqId": 48070601699}]}
{"arg": {"channel": "books", "instId": "BTC-USDT"}, "action": "update", "data": [{"asks": [["88508.6", "0", "0", "0"], ["88508.7", "0.0002", "0", "2"], ["88515.8", "0", "0", "0"], ["88516.3", "0", "0", "0"], ["88516.7", "0.012102", "0", "1"], ["88516.8", "0.00066019", "0", "1"], ["88522.1", "0.04593", "0", "2"], ["88536.6", "0", "0", "0"], ["88540.1", "0.00003293", "0", "1"], ["88546.3", "0.03629008", "0", "2"], ["88548.8", "0.01001", "0", "2"], ["88565.1", "0.1", "0", "1"], ["88569.4", "0.00292156", "0", "1"], ["88575.4", "0.01", "0", "1"], ["88579.7", "0", "0", "0"], ["88603.7", "0.00001139", "0", "1"]], "bids": [["88494.1", "0.02806", "0", "1"], ["88487.3", "0.128135", "0", "1"], ["88479.3", "0.59567563", "0", "2"], ["88478.5", "1.7060601", "0", "1"], ["88475.4", "0.03746439", "0", "1"], ["88465.2", "0.01650401", "0", "1"], ["88461.4", "0", "0", "0"], ["88447", "1.04415399", "0", "1"], ["88444.6", "3.00348489", "0", "1"], ["88434", "0", "0", "0"], ["88430.8", "0", "0", "0"], ["88424.5", "0", "0", "0"], ["88421.9", "0", "0", "0"], ["88414.8", "0.00565", "0", "1"], ["88411.4", "0", "0", "0"], ["88404.1", "0.00019401", "0", "1"], ["88316.5", "0", "0", "0"]], "ts": "1741338243005", "checksum": 1106665470, "seqId": 48070601931, "prevSeqId": 48070601863}]}
{"arg": {"channel": "books", "instId": "BTC-USDT"}, "action": "update", "data": [{"asks": [["88508.7", "0", "0", "0"], ["88509.6", "0.0001", "0", "1"], ["88509.8", "0.0001", "0", "1"], ["88511.6", "0.04651298", "0", "2"], ["88513.8", "0.02867124", "0", "1"], ["88514.8", "0.0255677", "0", "1"], ["88515.9", "0.11466149", "0", "2"], ["88516.8", "0.00224259", "0", "1"], ["88517.5", "0.07946005", "0", "1"], ["88519.1", "0.07927767", "0", "1"], ["88519.5", "0.07966179", "0", "1"], ["88523.8", "0.36288712", "0", "2"], ["88524.4", "0.1437606", "0", "1"], ["88525.8", "0", "0", "0"], ["88526.9", "0", "0", "0"], ["88528.8", "1", "0", "1"], ["88538.1", "0.00007794", "0", "3"], ["88552.9", "0.04527901", "0", "1"], ["88553", "0.12", "0", "4"], ["88554", "0.030035", "0", "2"], ["88558", "0.20704957", "0", "4"], ["88560", "0.00474113", "0", "6"], ["88561", "0", "0", "0"], ["88564.8", "0.1", "0", "1"], ["88565.1", "0", "0", "0"], ["88615", "0", "0", "0"]], "bids": [["88506", "0.2784538", "0", "6"], ["88490.8", "0.07898408", "0", "1"], ["88488.3", "0.12609648", "0", "1"], ["88485.9", "0.13124364", "0", "1"], ["88467", "0.06", "0", "2"], ["88466.2", "0.01650401", "0", "1"], ["88466", "0.03", "0", "1"], ["88465.2", "0", "0", "0"], ["88465", "0", "0", "0"]], "ts": "1741338243105", "checksum": -1436843587, "seqId": 48070602007, "prevSeqId": 48070601931}]}
{"arg": {"channel": "books", "instId": "BTC-USDT"}, "action": "update", "data": [{"asks": [["88506.1", "0.24264305", "0", "5"], ["88509.6", "0", "0", "0"], ["88509.8", "0", "0", "0"], ["88512.2", "0.0002", "0", "2"], ["88513.6", "0.02932884", "0", "1"], ["88513.7", "0.02767091", "0", "1"], ["88513.8", "0", "0", "0"], ["88514.6", "0.02478398", "0", "1"], ["88514.8", "0", "0", "0"], ["88515", "0.02689829", "0", "1"], ["88515.1", "0", "0", "0"], ["88515.9", "0.1152736", "0", "2"], ["88517.3", "0.082015", "0", "1"], ["88517.5", "0", "0", "0"], ["88517.8", "0.07874209", "0", "1"], ["88518.9", "0.07876309", "0", "1"], ["88519.1", "0", "0", "0"], ["88521.4", "0.13474631", "0", "1"], ["88521.7", "0.33929724", "0", "1"], ["88522.1", "0.18027515", "0", "3"], ["88522.4", "0", "0", "0"], ["88523.8", "0.6015632", "0", "1"], ["88524", "0.16179487", "0", "2"], ["88525.5", "0.90244663", "0", "1"], ["88525.6", "1", "0", "1"], ["88527.7", "0.07418522", "0", "2"], ["88528.8", "0", "0", "0"], ["88535.4", "0.22597457", "0", "1"], ["88537", "0.14172635", "0", "1"], ["88537.9", "0", "0", "0"], ["88544.1", "0.00007666", "0", "1"], ["88555", "0.45950865", "0", "6"], ["88557.6", "0.0006", "0", "2"], ["88558.4", "0.02289853", "0", "3"], ["88572", "0.080195", "0", "1"], ["88572.8", "0", "0", "0"], ["88595.6", "0", "0", "0"], ["88614.4", "0", "0", "0"]], "bids": [["88506", "0.2184538", "0", "4"], ["88505.3", "0", "0", "0"], ["88505.2", "0.0002", "0", "2"], ["88503.4", "0", "0", "0"], ["88496.5", "0", "0", "0"], ["88496.3", "0.000072", "0", "1"], ["88496.2", "0.02818365", "0", "1"], ["88495.9", "0", "0", "0"], ["88495.8", "0.02856892", "0", "1"], ["88495.6", "0.02734379", "0", "1"], ["88495.3", "0", "0", "0"], ["88495.2", "0.02741949", "0", "2"], ["88493.3", "0", "0", "0"], ["88492.8", "0", "0", "0"], ["88492.5", "0.08414956", "0", "1"], ["88491.7", "0.08456718", "0", "1"], ["88491.6", "0.183915", "0", "1"], ["88491.3", "0.07475645", "0", "1"], ["88488.7", "0", "0", "0"], ["88488.4", "0.1439258", "0", "1"], ["88488.3", "0", "0", "0"], ["88488.1", "0.15222142", "0", "2"], ["88485.5", "0.14848487", "0", "1"], ["88480.7", "0", "0", "0"], ["88477.4", "0.11302093", "0", "1"], ["88475.5", "0.22597457", "0", "1"], ["88467", "0", "0", "0"], ["88466.2", "0", "0", "0"], ["88466", "0.06", "0", "2"], ["88465.2", "0.01650401", "0", "1"], ["88465", "0.03", "0", "1"], ["88302.7", "6.25604919", "0", "1"], ["88266.6", "0", "0", "0"], ["88265.3", "0", "0", "0"]], "ts": "1741338243205", "checksum": -1192331111, "seqId": 48070602128, "prevSeqId": 48070602007}]}
{"arg": {"channel": "books", "instId": "BTC-USDT"}, "action": "update", "data": [{"asks": [["88506.1", "0.29026456", "0", "7"], ["88511.3", "0.0002", "0", "2"], ["88512.2", "0", "0", "0"], ["88513.5", "0.02825155", "0", "1"], ["88513.6", "0", "0", "0"], ["88515.8", "0.00152121", "0", "1"], ["88516.3", "0.012102", "0", "1"], ["88516.7", "0", "0", "0"], ["88517.1", "0", "0", "0"], ["88517.2", "0.08803872", "0", "1"], ["88517.3", "0", "0", "0"], ["88518.8", "0.0740737", "0", "1"], ["88518.9", "0", "0", "0"], ["88546", "0.89977222", "0", "5"], ["88546.6", "1.63975928", "0", "2"], ["88551.9", "0.04599758", "0", "1"], ["88552", "0.06101398", "0", "5"], ["88552.9", "0", "0", "0"], ["88553", "0.09", "0", "3"], ["88554", "0.000035", "0", "1"]], "bids": [["88506", "0.21553846", "0", "5"], ["88505.2", "0", "0", "0"], ["88502.3", "0.0002", "0", "2"], ["88500.7", "0", "0", "0"], ["88500.4", "0", "0", "0"], ["88497.4", "0.00935", "0", "1"], ["88467", "0.06", "0", "2"], ["88466", "0.03", "0", "1"], ["88465.2", "0", "0", "0"], ["88465", "0", "0", "0"], ["88462.8", "0.01650401", "0", "1"], ["88393.3", "0.00170709", "0", "1"], ["88287.1", "0.03063", "0", "2"]], "ts": "1741338243305", "checksum": 263487345, "seqId": 48070602189, "prevSeqId": 48070602128}]}
{"arg": {"channel": "books", "instId": "BTC-USDT"}, "action": "update", "data": [{"asks": [["88506.1", "0.2961875", "0", "8"], ["88511.3", "0.06009404", "0", "4"], ["88511.9", "0.01364", "0", "1"], ["88513", "0.00001138", "0", "1"], ["88513.5", "0", "0", "0"], ["88513.7", "0", "0", "0"], ["88514.2", "0", "0", "0"], ["88514.6", "0", "0", "0"], ["88515", "0", "0", "0"], ["88517.2", "0", "0", "0"], ["88517.8", "0", "0", "0"], ["88518.2", "0.01184588", "0", "1"], ["88518.7", "0.00001138", "0", "1"], ["88518.8", "0", "0", "0"], ["88520", "0.10252891", "0", "2"], ["88521.1", "1", "0", "1"], ["88521.4", "0", "0", "0"], ["88522", "0.14053275", "0", "2"], ["88522.1", "0.04593", "0", "2"], ["88523.1", "0.03252533", "0", "2"], ["88523.6", "0.22599771", "0", "1"], ["88523.7", "0.04", "0", "1"], ["88523.8", "0.42430491", "0", "1"], ["88524", "0.0171", "0", "1"], ["88525.4", "0.11343045", "0", "1"], ["88525.6", "0", "0", "0"], ["88529.3", "0", "0", "0"], ["88533.7", "0", "0", "0"], ["88533.9", "0.04", "0", "1"], ["88535.4", "0", "0", "0"], ["88542.1", "0.02520543", "0", "2"], ["88544.5", "0.00111578", "0", "1"], ["88549.5", "0.147132", "0", "2"], ["88552", "0.00101398", "0", "3"], ["88553", "0.12", "0", "4"], ["88554", "0.030035", "0", "2"], ["88555", "0.2967477", "0", "5"], ["88557.7", "0", "0", "0"], ["88598.2", "0.02278247", "0", "2"], ["88609.3", "0.65101286", "0", "5"], ["88613.1", "0", "0", "0"], ["88614.4", "0.00003119", "0", "3"], ["88615", "0.00001139", "0", "1"], ["88615.2", "0.0036953", "0", "1"], ["88615.3", "0.00001787", "0", "1"], ["88615.4", "0.00002919", "0", "1"], ["88615.9", "0.00001023", "0", "1"]], "bids": [["88506", "0.10146952", "0", "3"], ["88505.9", "0.00008176", "0", "1"], ["88504", "0", "0", "0"], ["88503.9", "0", "0", "0"], ["88503", "0", "0", "0"], ["88502.3", "0.0001", "0", "1"], ["88502.2", "0.0001", "0", "1"], ["88502", "0", "0", "0"], ["88501.3", "0", "0", "0"], ["88500.3", "0", "0", "0"], ["88498.5", "0", "0", "0"], ["88496.8", "0", "0", "0"], ["88496.7", "0", "0", "0"], ["88496.2", "0", "0", "0"], ["88495.8", "0", "0", "0"], ["88495.6", "0", "0", "0"], ["88495.5", "0.04", "0", "1"], ["88495.1", "0.00935", "0", "1"], ["88494.3", "0.073566", "0", "1"], ["88493.7", "0.11300004", "0", "1"], ["88493.4", "0", "0", "0"], ["88492.5", "0", "0", "0"], ["88491.9", "0", "0", "0"], ["88491.7", "0", "0", "0"], ["88491.3", "0", "0", "0"], ["88490.2", "0", "0", "0"], ["88489.9", "0", "0", "0"], ["88489.2", "0", "0", "0"], ["88488.4", "0", "0", "0"], ["88488.1", "0.0194028", "0", "1"], ["88486.3", "0", "0", "0"], ["88485.5", "0", "0", "0"], ["88480", "0.05194673", "0", "2"], ["88479.2", "0", "0", "0"], ["88478.4", "0.00059932", "0", "2"], ["88477.6", "0.00031432", "0", "2"], ["88475.5", "0", "0", "0"], ["88475.3", "0.04", "0", "1"], ["88475.2", "0", "0", "0"], ["88474.8", "0", "0", "0"], ["88474.7", "0", "0", "0"], ["88469", "0", "0", "0"], ["88468", "0", "0", "0"], ["88467.8", "0.00001138", "0", "1"], ["88467", "0", "0", "0"], ["88466.4", "0.22599771", "0", "1"], ["88466.3", "0.03407579", "0", "1"], ["88466", "0.06", "0", "2"], ["88464", "0.065", "0", "3"], ["88463", "0.03", "0", "1"], ["88462.8", "0", "0", "0"], ["88461.3", "0.15978249", "0", "2"], ["88459.3", "0.01650401", "0", "1"], ["88456", "0", "0", "0"], ["88452.1", "0.56875287", "0", "1"], ["88449.5", "0", "0", "0"], ["88425.3", "0", "0", "0"], ["88415.9", "0.01657745", "0", "1"], ["88409.7", "0", "0", "0"], ["88382.6", "0.01129097", "0", "1"], ["88377.5", "0.01129054", "0", "1"], ["88373.5", "0.01129536", "0", "2"], ["88351.1", "0.00564933", "0", "1"], ["88348.3", "0", "0", "0"], ["88330.4", "0.09892891", "0", "2"], ["88330.1", "0.22843211", "0", "3"], ["88329.8", "0", "0", "0"], ["88311.8", "0.13373045", "0", "2"], ["88266.6", "0.0128608", "0", "15"], ["88265.3", "0.00004344", "0", "1"], ["88264.7", "0.00004446", "0", "3"], ["88264.4", "0.00024852", "0", "1"], ["88264.2", "0.00001139", "0", "1"], ["88262.9", "0.00168511", "0", "2"], ["88261.8", "0.00074456", "0", "1"], ["88260.8", "0.00010584", "0", "1"], ["88260", "0.00002148", "0", "1"], ["88259.2", "0.00005974", "0", "1"], ["88259.1", "0.00011181", "0", "1"], ["88258.7", "0.00282652", "0", "1"], ["88257.9", "0.00020125", "0", "2"], ["88257.6", "0.00003493", "0", "1"], ["88256.9", "0.34056098", "0", "1"], ["88256.4", "0.0000172", "0", "1"], ["88255.8", "0.00003183", "0", "1"], ["88255.6", "0.12221196", "0", "1"], ["88255", "0.01785714", "0", "1"], ["88254.3", "0.00012967", "0", "2"], ["88253.7", "0.00326441", "0", "1"], ["88253", "0.00001297", "0", "1"], ["88252", "0.00002018", "0", "1"]], "ts": "1741338243405", "checksum": -1954951363, "seqId": 48070602392, "prevSeqId": 48070602189}]}
{"arg": {"channel": "books", "instId": "BTC-USDT"}, "action": "update", "data": [{"asks": [["88498.4", "0.4765657", "0", "12"], ["88498.7", "0.0001", "0", "1"], ["88498.8", "0.0001", "0", "1"], ["88500", "0.0171", "0", "1"], ["88501.9", "0.01539", "0", "1"], ["88502", "0.0171", "0", "1"], ["88504", "0.0171", "0", "1"], ["88504.4", "0.004236", "0", "1"], ["88505.6", "0.02901929", "0", "1"], ["88505.8", "0.0284358", "0", "1"], ["88506", "0.0171", "0", "1"], ["88506.1", "0.11629584", "0", "4"], ["88506.7", "0.0251791", "0", "1"], ["88507", "0", "0", "0"], ["88507.3", "0.02750553", "0", "1"], ["88509.1", "0.00209084", "0", "1"], ["88509.9", "0.05989404", "0", "2"], ["88510.6", "0.012102", "0", "1"], ["88510.7", "0.00734477", "0", "1"], ["88511.3", "0", "0", "0"], ["88511.6", "0.04249423", "0", "1"], ["88511.7", "0.14271372", "0", "3"], ["88513.1", "0.01129804", "0", "1"], ["88513.4", "0.00006", "0", "1"], ["88513.5", "0.13340283", "0", "1"], ["88514.4", "0.00001501", "0", "1"], ["88514.9", "0.11211518", "0", "1"], ["88515.8", "0.04094", "0", "1"], ["88515.9", "0", "0", "0"], ["88516.3", "0", "0", "0"], ["88516.6", "0.14165897", "0", "2"], ["88516.8", "0", "0", "0"], ["88519.2", "0.50185847", "0", "2"], ["88519.5", "0", "0", "0"], ["88519.8", "1", "0", "1"], ["88521.1", "0", "0", "0"], ["88522", "0", "0", "0"], ["88522.1", "0.005", "0", "1"], ["88522.5", "0", "0", "0"], ["88523.4", "0.02510254", "0", "1"], ["88523.6", "0", "0", "0"], ["88524", "0", "0", "0"], ["88524.4", "0", "0", "0"], ["88525.1", "0.039", "0", "1"], ["88526", "0", "0", "0"], ["88527.6", "0.22599525", "0", "1"], ["88530.1", "0.048", "0", "1"], ["88530.8", "0.02259057", "0", "1"], ["88533.2", "0.00559818", "0", "1"], ["88536.3", "0.312063", "0", "2"], ["88539", "0.00826549", "0", "1"], ["88539.5", "0.18391502", "0", "1"], ["88541.2", "0.04444207", "0", "1"], ["88542.1", "0.00010289", "0", "1"], ["88551.9", "0.10535988", "0", "2"], ["88553.8", "0.21704", "0", "1"], ["88559.9", "0.00570014", "0", "1"], ["88561.2", "0", "0", "0"], ["88561.9", "0", "0", "0"], ["88564.3", "0.01129124", "0", "1"], ["88564.8", "0.01740112", "0", "1"], ["88566.2", "0.45809014", "0", "2"], ["88569.6", "0", "0", "0"], ["88569.7", "0.15318778", "0", "1"], ["88569.8", "0", "0", "0"], ["88581.3", "0.00574116", "0", "2"], ["88582.6", "0.63068237", "0", "1"], ["88585.1", "0.00570014", "0", "1"], ["88585.8", "0.00001023", "0", "1"], ["88587.6", "0.04519444", "0", "1"], ["88590", "0.11306453", "0", "2"], ["88591.3", "0.0016767", "0", "1"], ["88594.1", "0.00588851", "0", "8"], ["88599.8", "0", "0", "0"], ["88599.9", "0.01045417", "0", "8"], ["88607.8", "0.00001009", "0", "1"], ["88607.9", "0.00571153", "0", "2"], ["88608.3", "0", "0", "0"], ["88609.3", "0.04063049", "0", "5"], ["88609.4", "0.04207212", "0", "4"], ["88609.5", "0.766835", "0", "2"], ["88611.2", "0", "0", "0"], ["88611.4", "0", "0", "0"], ["88611.6", "0", "0", "0"], ["88611.8", "0", "0", "0"], ["88611.9", "0", "0", "0"], ["88612", "0", "0", "0"], ["88612.4", "0", "0", "0"], ["88612.5", "0", "0", "0"], ["88612.6", "0", "0", "0"], ["88613", "0", "0", "0"], ["88613.3", "0", "0", "0"], ["88614", "0", "0", "0"], ["88614.4", "0", "0", "0"], ["88615", "0", "0", "0"], ["88615.2", "0", "0", "0"], ["88615.3", "0", "0", "0"], ["88615.4", "0", "0", "0"], ["88615.9", "0", "0", "0"]], "bids": [["88506", "0", "0", "0"], ["88505.9", "0", "0", "0"], ["88502.3", "0", "0", "0"], ["88502.2", "0", "0", "0"], ["88499.9", "0", "0", "0"], ["88498.3", "0.16639993", "0", "4"], ["88498.2", "0.00011832", "0", "1"], ["88497.5", "0", "0", "0"], ["88497.4", "0", "0", "0"], ["88497", "0.00112831", "0", "1"], ["88496.3", "0", "0", "0"], ["88496", "0.0171", "0", "1"], ["88495.9", "0.0001", "0", "1"], ["88495.7", "0.0001", "0", "1"], ["88495.4", "0", "0", "0"], ["88495.2", "0.00001501", "0", "1"], ["88494.3", "0", "0", "0"], ["88494.1", "0", "0", "0"], ["88494", "0.0171", "0", "1"], ["88493.9", "0.1", "0", "1"], ["88493.7", "0", "0", "0"], ["88492.7", "0.01800341", "0", "1"], ["88492.3", "0.00734477", "0", "1"], ["88491.6", "0", "0", "0"], ["88491.2", "0.33902", "0", "1"], ["88490.8", "0", "0", "0"], ["88488.5", "0.00007275", "0", "1"], ["88488.3", "0.02839855", "0", "1"], ["88487.9", "0.02832828", "0", "1"], ["88487.7", "0.02668974", "0", "1"], ["88487.4", "0.02588405", "0", "1"], ["88485.9", "0", "0", "0"], ["88485.7", "0", "0", "0"], ["88483.2", "0.156482", "0", "3"], ["88481.8", "0.015", "0", "1"], ["88481", "0.00452074", "0", "1"], ["88480.6", "0", "0", "0"], ["88480.5", "0.25487356", "0", "2"], ["88478.4", "0", "0", "0"], ["88478.3", "0.000024", "0", "1"], ["88477.8", "0", "0", "0"], ["88477.6", "0.14753372", "0", "2"], ["88476", "0.00734477", "0", "1"], ["88475.4", "0", "0", "0"], ["88475.3", "0", "0", "0"], ["88472.6", "0.0512889", "0", "2"], ["88472", "0.0006", "0", "2"], ["88471.2", "0.00029935", "0", "1"], ["88470.8", "0.03744909", "0", "1"], ["88470.1", "0.25158503", "0", "1"], ["88470", "0.183915", "0", "1"], ["88468.9", "0", "0", "0"], ["88468.2", "0.22599525", "0", "1"], ["88468", "0.00001", "0", "1"], ["88467.9", "0", "0", "0"], ["88466.4", "0", "0", "0"], ["88466.3", "0", "0", "0"], ["88466", "0", "0", "0"], ["88464.9", "0", "0", "0"], ["88464", "0.005", "0", "1"], ["88463", "0", "0", "0"], ["88461.3", "0.23519403", "0", "3"], ["88461.1", "0.19232644", "0", "3"], ["88460", "0.065015", "0", "4"], ["88459.3", "0", "0", "0"], ["88459.2", "0", "0", "0"], ["88458.9", "0.0112", "0", "1"], ["88458", "0.06", "0", "2"], ["88457.4", "0.22262768", "0", "2"], ["88457", "0.03", "0", "1"], ["88456.7", "0.63822382", "0", "2"], ["88456.4", "0", "0", "0"], ["88454", "0.01129106", "0", "1"], ["88453", "0", "0", "0"], ["88452.9", "0", "0", "0"], ["88452.6", "0.01129124", "0", "1"], ["88452.2", "0.27766577", "0", "1"], ["88452", "0.00016958", "0", "1"], ["88450.1", "0.01650401", "0", "1"], ["88450", "0.073566", "0", "1"], ["88448.4", "0", "0", "0"], ["88445.8", "0", "0", "0"], ["88444", "0", "0", "0"], ["88443.2", "0", "0", "0"], ["88440", "0.01740112", "0", "1"], ["88439.6", "0", "0", "0"], ["88439.1", "0.07108744", "0", "1"], ["88436.3", "0", "0", "0"], ["88435.9", "0.01689095", "0", "1"], ["88435.8", "0", "0", "0"], ["88435.6", "0.00102744", "0", "1"], ["88434.9", "0.88231128", "0", "1"], ["88434.8", "2.12624221", "0", "1"], ["88433.9", "0.00564951", "0", "1"], ["88433.1", "0.06335", "0", "1"], ["88432.9", "0.01129126", "0", "1"], ["88430.8", "0.28244887", "0", "1"], ["88426.8", "0.00098743", "0", "1"], ["88424.4", "0.20423842", "0", "2"], ["88422.7", "0", "0", "0"], ["88422.1", "0.15762008", "0", "1"], ["88422", "0.43447", "0", "1"], ["88414.8", "0.62165898", "0", "2"], ["88410.5", "0.00007202", "0", "1"], ["88408", "2.95765", "0", "1"], ["88405.9", "0.03391816", "0", "1"], ["88404.1", "0", "0", "0"], ["88402.6", "2.16256986", "0", "1"], ["88396.1", "0.01655514", "0", "1"], ["88385.6", "0", "0", "0"], ["88382.6", "0", "0", "0"], ["88377.5", "0", "0", "0"], ["88373.5", "0", "0", "0"], ["88370.6", "0", "0", "0"], ["88368", "0.00564933", "0", "1"], ["88366.3", "0", "0", "0"], ["88365.8", "0.17401121", "0", "1"], ["88364.1", "0.01129124", "0", "1"], ["88351.1", "0.01694799", "0", "3"], ["88348.7", "0", "0", "0"], ["88348.6", "0", "0", "0"], ["88348.5", "0", "0", "0"], ["88347.4", "0", "0", "0"], ["88347.3", "0.11343045", "0", "1"], ["88330.5", "0.0705", "0", "4"], ["88330.1", "0.20813211", "0", "2"], ["88329.9", "0", "0", "0"], ["88328.8", "0", "0", "0"], ["88328.5", "0.0135", "0", "1"], ["88328.3", "0.6134", "0", "2"], ["88328.1", "0.0135", "0", "1"], ["88311.9", "0.0406", "0", "2"], ["88311.8", "0.15403045", "0", "3"], ["88309.6", "0.0203", "0", "1"], ["88285.3", "0.207", "0", "1"], ["88253", "0", "0", "0"], ["88252", "0", "0", "0"]], "ts": "1741338243505", "checksum": 268703450, "seqId": 48070603162, "prevSeqId": 48070602392}]}
{"arg": {"channel": "books", "instId": "BTC-USDT"}, "action": "update", "data": [{"asks": [["88498.4", "0.47995624", "0", "13"], ["88498.7", "0", "0", "0"], ["88498.8", "0", "0", "0"], ["88500.7", "0.0001", "0", "1"], ["88501.6", "0.01364", "0", "1"], ["88501.9", "0.03540184", "0", "2"], ["88505", "0.02884494", "0", "1"], ["88505.1", "0.02846064", "0", "1"], ["88505.6", "0", "0", "0"], ["88505.8", "0", "0", "0"], ["88505.9", "0.05989404", "0", "2"], ["88506", "0.0453244", "0", "3"], ["88506.1", "0.19390347", "0", "5"], ["88506.7", "0.02615047", "0", "1"], ["88507.3", "0", "0", "0"], ["88508.7", "0.08943243", "0", "1"], ["88509.1", "0", "0", "0"], ["88509.2", "0.0832709", "0", "1"], ["88509.8", "0.00209084", "0", "1"], ["88510.3", "0.0955194", "0", "2"], ["88510.6", "0", "0", "0"], ["88511.1", "0.08509896", "0", "1"], ["88511.6", "0.12629664", "0", "1"], ["88511.7", "0", "0", "0"], ["88511.9", "0", "0", "0"], ["88512", "0.01357284", "0", "1"], ["88512.8", "0.47324302", "0", "2"], ["88513.5", "0", "0", "0"], ["88513.6", "0.13160337", "0", "1"], ["88514.9", "0.49957217", "0", "2"], ["88515.4", "0.14367255", "0", "1"], ["88516", "0.14259344", "0", "1"], ["88516.6", "0.00057148", "0", "1"], ["88517.7", "0.128135", "0", "1"], ["88518.7", "1.00001138", "0", "2"], ["88519.2", "0.17236591", "0", "1"], ["88519.8", "0.048", "0", "1"], ["88521.6", "0.048", "0", "1"], ["88523.1", "0.01364", "0", "1"], ["88523.4", "0.11210254", "0", "3"], ["88530.1", "0", "0", "0"], ["88531.2", "0.129", "0", "3"], ["88536.3", "0.183915", "0", "1"], ["88536.8", "0", "0", "0"], ["88542.3", "0.00005413", "0", "1"], ["88543.1", "0.11343045", "0", "1"], ["88546.3", "0.00013676", "0", "1"], ["88547.6", "0", "0", "0"], ["88552", "0.00023792", "0", "2"], ["88557.1", "0.1", "0", "1"], ["88564", "0.20598592", "0", "2"], ["88564.3", "0", "0", "0"], ["88564.9", "0.00001626", "0", "1"], ["88571.7", "0.0299716", "0", "1"], ["88576.2", "0", "0", "0"], ["88577.6", "0.07525038", "0", "6"], ["88586.7", "0.03995189", "0", "2"], ["88608.7", "0", "0", "0"], ["88610.7", "0", "0", "0"], ["88611", "0", "0", "0"], ["88611.1", "0", "0", "0"]], "bids": [["88498.3", "0.11129993", "0", "2"], ["88496.1", "0.00011138", "0", "2"], ["88496", "0.0172", "0", "2"], ["88495.9", "0", "0", "0"], ["88495.7", "0", "0", "0"], ["88495.2", "0", "0", "0"], ["88492.7", "0", "0", "0"], ["88492.3", "0", "0", "0"], ["88491.3", "0.22143724", "0", "1"], ["88489.4", "0.33902", "0", "1"], ["88488.3", "0", "0", "0"], ["88488.1", "0", "0", "0"], ["88487.9", "0", "0", "0"], ["88487.8", "0.06544841", "0", "1"], ["88487.7", "0.02733913", "0", "1"], ["88487.4", "0", "0", "0"], ["88487.2", "0.0269836", "0", "1"], ["88487.1", "0.0256915", "0", "1"], ["88486.8", "0.02793309", "0", "1"], ["88485.6", "0.09", "0", "3"], ["88485", "0", "0", "0"], ["88484.9", "0", "0", "0"], ["88484", "0.08231125", "0", "1"], ["88483.1", "0.08607066", "0", "1"], ["88482.8", "0.07311815", "0", "1"], ["88482.4", "0.0777791", "0", "1"], ["88480.5", "0.11301686", "0", "1"], ["88480.3", "0.03", "0", "1"], ["88479.8", "0.14335817", "0", "1"], ["88479.5", "0.13188774", "0", "1"], ["88477.6", "0.000015", "0", "1"], ["88477.5", "0.13967623", "0", "1"], ["88476.9", "0.14382012", "0", "1"], ["88470.1", "0.12436398", "0", "1"], ["88468.1", "0", "0", "0"], ["88460", "0.005015", "0", "2"], ["88459", "0.06", "0", "2"], ["88456.7", "0.40781398", "0", "2"], ["88453.8", "0.11343045", "0", "1"], ["88452.6", "0.47092556", "0", "1"], ["88452.5", "0.447346", "0", "1"], ["88452.2", "0", "0", "0"], ["88451.6", "0.1", "0", "1"], ["88450.1", "0", "0", "0"], ["88450", "0.147132", "0", "2"], ["88447.1", "0.01650401", "0", "1"], ["88446.7", "0.33919", "0", "1"], ["88440", "0.02294412", "0", "2"], ["88439.3", "0.01128954", "0", "1"], ["88439.1", "0.04109951", "0", "1"], ["88439", "0", "0", "0"], ["88435.6", "0.00650776", "0", "2"], ["88434.8", "0", "0", "0"], ["88433.2", "2.12624221", "0", "1"], ["88431.1", "0.00548032", "0", "1"], ["88414.8", "0.74237726", "0", "3"], ["88405.4", "0.000194", "0", "1"], ["88381.8", "0", "0", "0"], ["88372.8", "0.0021263", "0", "1"], ["88306", "0.01936138", "0", "1"], ["88293.4", "0", "0", "0"], ["88256.9", "0", "0", "0"], ["88256.4", "0", "0", "0"], ["88255.8", "0", "0", "0"], ["88255.6", "0", "0", "0"], ["88255", "0", "0", "0"], ["88254.3", "0", "0", "0"], ["88253.7", "0", "0", "0"]], "ts": "1741338243605", "checksum": 560963233, "seqId": 48070603514, "prevSeqId": 48070603162}]}
{"arg": {"channel": "books", "instId": "BTC-USDT"}, "action": "update", "data": [{"asks": [["88500.7", "0", "0", "0"], ["88500.8", "0.0002", "0", "2"], ["88501.9", "0.05651766", "0", "2"], ["88504.4", "0", "0", "0"], ["88504.9", "0.02911787", "0", "1"], ["88505", "0.02946583", "0", "1"], ["88505.1", "0", "0", "0"], ["88505.9", "0.08663886", "0", "3"], ["88506", "0.01956416", "0", "3"], ["88506.1", "0.25414765", "0", "4"], ["88506.6", "0.02768145", "0", "1"], ["88506.7", "0", "0", "0"], ["88506.8", "0.01888533", "0", "1"], ["88507.3", "0.207", "0", "1"], ["88508.2", "0.04094", "0", "1"], ["88508.6", "0.07901006", "0", "1"], ["88508.7", "0", "0", "0"], ["88509.1", "0.08358034", "0", "1"], ["88509.2", "0", "0", "0"], ["88509.8", "0", "0", "0"], ["88509.9", "0", "0", "0"], ["88510.2", "0.08359149", "0", "1"], ["88510.3", "0", "0", "0"], ["88510.6", "0.012102", "0", "1"], ["88511", "0.08326529", "0", "1"], ["88511.1", "0", "0", "0"], ["88511.6", "0.45292359", "0", "1"], ["88512.7", "0.13629256", "0", "1"], ["88512.8", "0.33929724", "0", "1"], ["88513.5", "0.13379418", "0", "1"], ["88513.6", "0", "0", "0"], ["88514.8", "0.90244663", "0", "1"], ["88514.9", "0.18606452", "0", "1"], ["88515.3", "0.14756846", "0", "1"], ["88515.4", "0", "0", "0"], ["88515.8", "0", "0", "0"], ["88515.9", "0.1319241", "0", "1"], ["88516", "0", "0", "0"], ["88518.7", "0.00001138", "0", "1"], ["88519.2", "0.50572017", "0", "2"], ["88519.8", "1.048", "0", "2"], ["88523.4", "0.16010254", "0", "4"], ["88531.2", "0.042", "0", "1"], ["88533", "0.00548032", "0", "1"], ["88537.4", "0.00548032", "0", "1"], ["88538.4", "0.07385014", "0", "5"], ["88547.1", "0.5538329", "0", "1"], ["88551.9", "0.24700418", "0", "1"], ["88554.2", "0.49836466", "0", "3"], ["88559.5", "0.98062749", "0", "4"], ["88561.3", "0", "0", "0"], ["88563.9", "0.01740159", "0", "1"], ["88564.8", "0", "0", "0"], ["88566.2", "0.49286927", "0", "3"], ["88567", "0.01129089", "0", "1"], ["88571.7", "0", "0", "0"], ["88577.6", "0.06396084", "0", "5"], ["88582.7", "0.073566", "0", "1"], ["88591.6", "0.745661", "0", "1"], ["88592.4", "0", "0", "0"], ["88608.1", "0", "0", "0"], ["88608.9", "0.00570112", "0", "1"], ["88609.5", "0.0203", "0", "1"], ["88610.4", "0", "0", "0"], ["88610.5", "0", "0", "0"], ["88610.6", "0", "0", "0"]], "bids": [["88498.2", "0.00009282", "0", "1"], ["88496.1", "0.00001138", "0", "1"], ["88496", "0.0001", "0", "1"], ["88495.1", "0", "0", "0"], ["88494.7", "0.0001", "0", "1"], ["88491.3", "0", "0", "0"], ["88490.6", "0.00935", "0", "1"], ["88489.1", "0", "0", "0"], ["88487.7", "0", "0", "0"], ["88487.6", "0.0283789", "0", "1"], ["88487.2", "0", "0", "0"], ["88487.1", "0.02979", "0", "1"], ["88487", "0.02716173", "0", "1"], ["88486.8", "0", "0", "0"], ["88486.7", "0.02915275", "0", "1"], ["88485.8", "0.00935", "0", "1"], ["88485.6", "0", "0", "0"], ["88484", "0", "0", "0"], ["88483.9", "0.08136594", "0", "1"], ["88483.2", "0.147132", "0", "2"], ["88483.1", "0", "0", "0"], ["88483", "0.08531742", "0", "1"], ["88482.8", "0", "0", "0"], ["88482.7", "0.08863155", "0", "2"], ["88482.4", "0", "0", "0"], ["88482.3", "0.0888865", "0", "1"], ["88480.5", "0", "0", "0"], ["88480.3", "0", "0", "0"], ["88479.8", "0", "0", "0"], ["88479.7", "0.1430262", "0", "1"], ["88479.6", "0.16031949", "0", "1"], ["88479.5", "0", "0", "0"], ["88479.4", "0.12338152", "0", "1"], ["88479.3", "0", "0", "0"], ["88479.2", "0.02807", "0", "1"], ["88478.5", "0", "0", "0"], ["88478.3", "0", "0", "0"], ["88477.5", "0", "0", "0"], ["88477.4", "0.25889398", "0", "2"], ["88476.9", "0", "0", "0"], ["88476.8", "0.13250541", "0", "1"], ["88475.3", "0.0194028", "0", "1"], ["88475.2", "0.000093", "0", "1"], ["88474.8", "0.03", "0", "1"], ["88472.6", "0.0112889", "0", "1"], ["88472", "0", "0", "0"], ["88471.2", "0", "0", "0"], ["88470.8", "0", "0", "0"], ["88470.4", "0.00059935", "0", "2"], ["88469.6", "0.00029935", "0", "1"], ["88468.8", "0.04001501", "0", "2"], ["88464", "0.118038", "0", "2"], ["88462.7", "0", "0", "0"], ["88459", "0", "0", "0"], ["88458", "0", "0", "0"], ["88457.6", "0.63161578", "0", "1"], ["88457.5", "0.498202", "0", "1"], ["88457", "0.06", "0", "2"], ["88456.7", "0.0194471", "0", "1"], ["88456", "0.06", "0", "2"], ["88455", "0.03", "0", "1"], ["88449.9", "0.01186237", "0", "2"], ["88447.1", "0", "0", "0"], ["88447", "0.25781849", "0", "1"], ["88446.8", "0.01650401", "0", "1"], ["88444.6", "0", "0", "0"], ["88440.1", "0.01740159", "0", "1"], ["88440", "0.005543", "0", "1"], ["88439.3", "0", "0", "0"], ["88434.7", "0", "0", "0"], ["88414.8", "1.09979359", "0", "2"], ["88411.4", "0.42968687", "0", "1"], ["88408.1", "0.34363898", "0", "1"], ["88405.4", "0", "0", "0"], ["88397.8", "0.00019401", "0", "1"], ["88365.8", "0", "0", "0"], ["88364.2", "0.17401597", "0", "1"], ["88364.1", "0", "0", "0"], ["88361.4", "0.01129089", "0", "1"], ["88256.9", "0.34056098", "0", "1"], ["88256.4", "0.0000172", "0", "1"]], "ts": "1741338243705", "checksum": -2108894572, "seqId": 48070603786, "prevSeqId": 48070603514}]}
{"arg": {"channel": "books", "instId": "BTC-USDT"}, "action": "update", "data": [{"asks": [["88498.4", "0.47798559", "0", "13"], ["88504.4", "0.000021", "0", "1"], ["88507", "0.012102", "0", "1"], ["88510.6", "0", "0", "0"], ["88516.7", "0.01364", "0", "1"], ["88522", "0.00017709", "0", "1"], ["88523.1", "0", "0", "0"], ["88527.7", "0.02618522", "0", "1"], ["88528.6", "0.01096065", "0", "1"], ["88531.2", "0", "0", "0"], ["88541.2", "0.16415111", "0", "2"], ["88541.6", "0.4478057", "0", "3"], ["88551", "0.45198929", "0", "3"], ["88551.1", "0.49759", "0", "1"], ["88551.9", "0", "0", "0"], ["88556.6", "0.01740167", "0", "1"], ["88563.9", "0", "0", "0"], ["88582.1", "0", "0", "0"], ["88590.4", "0.745414", "0", "1"], ["88610", "0", "0", "0"], ["88610.1", "0", "0", "0"]], "bids": [["88498.3", "0.10803792", "0", "2"], ["88496.3", "0.0001", "0", "1"], ["88496.1", "0.00011138", "0", "2"], ["88496", "0", "0", "0"], ["88494.7", "0", "0", "0"], ["88487.8", "0.03715793", "0", "1"], ["88487.3", "0", "0", "0"], ["88482.7", "0.07997036", "0", "1"], ["88478.4", "0.06", "0", "2"], ["88476.7", "0.128135", "0", "1"], ["88474.8", "0.09", "0", "3"], ["88472.5", "0.01853488", "0", "1"], ["88470.4", "0", "0", "0"], ["88469.6", "0.00059935", "0", "2"], ["88468.8", "0.04031436", "0", "3"], ["88466.1", "0.92103722", "0", "2"], ["88465.7", "1.65352413", "0", "1"], ["88456", "0", "0", "0"], ["88455", "0.06", "0", "2"], ["88454", "0.04129106", "0", "2"], ["88453.8", "0.14754125", "0", "2"], ["88446.8", "0", "0", "0"], ["88443.2", "0.01650401", "0", "1"], ["88443.1", "0.25163098", "0", "2"], ["88442.8", "0.498199", "0", "1"], ["88440.1", "0", "0", "0"], ["88434.9", "1.61735711", "0", "2"], ["88433", "0.01740167", "0", "1"], ["88431.8", "2.91778247", "0", "1"], ["88414.8", "0.49610364", "0", "3"], ["88408.1", "0", "0", "0"], ["88364.2", "0", "0", "0"], ["88351.2", "0.17401673", "0", "1"], ["88306", "0", "0", "0"]], "ts": "1741338243805", "checksum": -1053044683, "seqId": 48070603878, "prevSeqId": 48070603786}]}
{"arg": {"channel": "books", "instId": "BTC-USDT"}, "action": "update", "data": [{"asks": [["88498.4", "0.45858559", "0", "12"], ["88499.4", "0.0002", "0", "2"], ["88500.8", "0", "0", "0"], ["88501.9", "0.03530184", "0", "1"], ["88504.9", "0", "0", "0"], ["88505", "0.00201673", "0", "1"], ["88505.9", "0.05989404", "0", "2"], ["88506", "0.01934275", "0", "2"], ["88506.1", "0.24302594", "0", "5"], ["88506.6", "0", "0", "0"], ["88507", "0", "0", "0"], ["88507.3", "0.00001138", "0", "1"], ["88508.6", "0", "0", "0"], ["88509.1", "0", "0", "0"], ["88510.2", "0", "0", "0"], ["88511", "0", "0", "0"], ["88512.7", "0", "0", "0"], ["88513.5", "0", "0", "0"], ["88514.9", "0.18780031", "0", "2"], ["88515.3", "0", "0", "0"], ["88515.9", "0", "0", "0"], ["88537.9", "0.00083", "0", "1"], ["88556.6", "0", "0", "0"], ["88563.9", "0.01740155", "0", "1"], ["88610", "0.00004062", "0", "1"], ["88610.1", "0.11285173", "0", "1"], ["88610.4", "0.00001013", "0", "1"], ["88610.5", "0.00003079", "0", "2"], ["88610.6", "0.1370973", "0", "2"], ["88610.7", "0.00151215", "0", "1"], ["88611", "0.00001016", "0", "1"], ["88611.1", "0.00028247", "0", "7"], ["88611.2", "0.03381017", "0", "4"], ["88611.4", "0.01417453", "0", "2"]], "bids": [["88498.3", "0.18726703", "0", "5"], ["88498", "0.0171", "0", "1"], ["88496.3", "0", "0", "0"], ["88496.1", "0.00001138", "0", "1"], ["88496", "0.0171", "0", "1"], ["88494.7", "0.0001", "0", "1"], ["88494.1", "0.0001", "0", "1"], ["88493.4", "0.11300047", "0", "1"], ["88491.3", "0.20624224", "0", "1"], ["88487.8", "0", "0", "0"], ["88487.6", "0", "0", "0"], ["88487.5", "0.04471111", "0", "1"], ["88487.1", "0", "0", "0"], ["88487", "0", "0", "0"], ["88486.7", "0", "0", "0"], ["88483.9", "0", "0", "0"], ["88483.6", "0.25750058", "0", "2"], ["88483", "0", "0", "0"], ["88482.7", "0", "0", "0"], ["88482.3", "0", "0", "0"], ["88480.5", "0.207", "0", "1"], ["88479.7", "0", "0", "0"], ["88479.6", "0.17515306", "0", "2"], ["88479.4", "0", "0", "0"], ["88477.8", "0.00340372", "0", "1"], ["88477.4", "0.11302093", "0", "1"], ["88476.8", "0", "0", "0"], ["88474.8", "0.12", "0", "4"], ["88447.1", "0.01650401", "0", "1"], ["88443.2", "0", "0", "0"], ["88440", "0.02294455", "0", "2"], ["88433", "0", "0", "0"], ["88414.8", "0.65001561", "0", "3"], ["88411.4", "0", "0", "0"], ["88364.1", "0.17401559", "0", "1"], ["88351.2", "0", "0", "0"], ["88332", "0.00001138", "0", "1"], ["88255.8", "0.00003183", "0", "1"], ["88255.6", "0.12221196", "0", "1"], ["88255", "0.01785714", "0", "1"], ["88254.3", "0.00012967", "0", "2"], ["88253.7", "0.00326441", "0", "1"]], "ts": "1741338243905", "checksum": 1095815590, "seqId": 48070604066, "prevSeqId": 48070603878}]}
{"arg": {"channel": "books", "instId": "BTC-USDT"}, "action": "update", "data": [{"asks": [["88498.4", "0.47798559", "0", "13"], ["88499.4", "0", "0", "0"], ["88500.9", "0.0001", "0", "1"], ["88503.1", "0.0001", "0", "1"], ["88505", "0", "0", "0"], ["88505.4", "0.02720173", "0", "1"], ["88505.8", "0.00201673", "0", "1"], ["88506.1", "0.15011982", "0", "5"], ["88507.9", "0.012102", "0", "1"], ["88509", "0.08641175", "0", "1"], ["88511.4", "0.08676926", "0", "1"], ["88513.1", "0.15852974", "0", "2"], ["88514.9", "0.11829112", "0", "1"], ["88516.3", "0.12996376", "0", "1"], ["88519.8", "0.048", "0", "1"], ["88521.8", "1", "0", "1"], ["88527.6", "0", "0", "0"], ["88529.9", "0.22599194", "0", "1"], ["88537", "0.4842764", "0", "2"], ["88538.3", "0.00124659", "0", "9"], ["88539", "1.00826549", "0", "2"], ["88610.5", "0", "0", "0"], ["88610.6", "0", "0", "0"], ["88610.7", "0", "0", "0"], ["88611", "0", "0", "0"], ["88611.1", "0", "0", "0"], ["88611.2", "0", "0", "0"], ["88611.4", "0", "0", "0"]], "bids": [["88494.9", "0.0001", "0", "1"], ["88494.7", "0", "0", "0"], ["88494.6", "0.0001", "0", "1"], ["88494.1", "0", "0", "0"], ["88493.4", "0", "0", "0"], ["88489.8", "0.00734477", "0", "1"], ["88487.9", "0.02786153", "0", "1"], ["88487.5", "0.02640219", "0", "1"], ["88487.1", "0.02707878", "0", "1"], ["88484.2", "0.08359153", "0", "1"], ["88484", "0.67273621", "0", "1"], ["88483.9", "0.90244663", "0", "1"], ["88483.6", "0", "0", "0"], ["88483.4", "0.0818372", "0", "1"], ["88479.6", "0.10682786", "0", "1"], ["88477.8", "0.1426824", "0", "2"], ["88473.4", "0.22600398", "0", "2"], ["88470.1", "0.06883502", "0", "1"], ["88468.2", "0", "0", "0"], ["88459.8", "0.03715077", "0", "1"], ["88452.7", "0.01650401", "0", "1"], ["88447.1", "0", "0", "0"], ["88414.8", "0.14092923", "0", "2"], ["88255.8", "0", "0", "0"], ["88255.6", "0", "0", "0"], ["88255", "0", "0", "0"], ["88254.3", "0", "0", "0"], ["88253.7", "0", "0", "0"]], "ts": "1741338244005", "checksum": 199553448, "seqId": 48070604190, "prevSeqId": 48070604066}]}
{"arg": {"channel": "books", "instId": "BTC-USDT"}, "action": "update", "data": [{"asks": [["88498.4", "0.45858559", "0", "12"], ["88500.9", "0", "0", "0"], ["88503.1", "0", "0", "0"], ["88503.7", "0.0002", "0", "2"], ["88505.4", "0", "0", "0"], ["88505.7", "0.0275951", "0", "1"], ["88505.8", "0.02918477", "0", "1"], ["88506", "0.02046295", "0", "3"], ["88506.8", "0.04639371", "0", "2"], ["88507.4", "0.02964421", "0", "1"], ["88509", "0", "0", "0"], ["88509.4", "0.08517997", "0", "1"], ["88510", "0.10260312", "0", "2"], ["88511.1", "0.08248119", "0", "1"], ["88511.4", "0", "0", "0"], ["88511.8", "0.08201425", "0", "1"], ["88513.1", "0.01129804", "0", "1"], ["88513.6", "0.14567237", "0", "1"], ["88514.3", "0.13707722", "0", "1"], ["88514.9", "0.18746253", "0", "2"], ["88516.2", "0.14574399", "0", "1"], ["88516.3", "0", "0", "0"], ["88516.7", "0.14775532", "0", "2"], ["88529.9", "0", "0", "0"], ["88532.5", "0.22598943", "0", "1"], ["88563.9", "0.01740098", "0", "1"], ["88610", "0", "0", "0"], ["88610.1", "0", "0", "0"], ["88610.4", "0", "0", "0"]], "bids": [["88494.9", "0", "0", "0"], ["88494.7", "0.0002", "0", "2"], ["88494.6", "0", "0", "0"], ["88492.1", "0.00004575", "0", "1"], ["88491.3", "0.29255812", "0", "2"], ["88489.5", "0.33929724", "0", "1"], ["88488.5", "0.000027", "0", "1"], ["88488.4", "0.02705761", "0", "1"], ["88488", "0.02909242", "0", "1"], ["88487.9", "0", "0", "0"], ["88487.8", "0.02508331", "0", "1"], ["88487.6", "0.09564608", "0", "2"], ["88487.5", "0.02626234", "0", "1"], ["88487.1", "0", "0", "0"], ["88486.9", "0.32775", "0", "1"], ["88484.7", "0.08265665", "0", "1"], ["88484.2", "0", "0", "0"], ["88483.8", "0.081596", "0", "1"], ["88483.5", "0.07864622", "0", "1"], ["88483.4", "0", "0", "0"], ["88483", "0.08173865", "0", "1"], ["88480.6", "0.13237647", "0", "1"], ["88480.2", "0.47760654", "0", "2"], ["88479.6", "0.20724191", "0", "2"], ["88478.1", "0.1392375", "0", "1"], ["88477.8", "0.00340372", "0", "1"], ["88477.7", "0.14983193", "0", "1"], ["88473.4", "0.00001138", "0", "1"], ["88471.2", "0.22599099", "0", "1"], ["88454.1", "0.01650401", "0", "1"], ["88452.7", "0", "0", "0"], ["88440.1", "0.01740098", "0", "1"], ["88440", "0.005543", "0", "1"], ["88435.7", "0.00102741", "0", "1"], ["88435.6", "0.00548032", "0", "1"], ["88410.5", "0", "0", "0"], ["88405.3", "0", "0", "0"], ["88402.8", "0.00572237", "0", "2"], ["88391.5", "0.0007203", "0", "1"], ["88364.1", "0.17400971", "0", "1"], ["88262.9", "0", "0", "0"], ["88261.8", "0", "0", "0"], ["88260.8", "0", "0", "0"], ["88260", "0", "0", "0"], ["88259.2", "0", "0", "0"], ["88259.1", "0", "0", "0"], ["88258.7", "0", "0", "0"], ["88257.9", "0", "0", "0"], ["88257.6", "0", "0", "0"], ["88256.9", "0", "0", "0"], ["88256.4", "0", "0", "0"]], "ts": "1741338244105", "checksum": 1525788046, "seqId": 48070604311, "prevSeqId": 48070604190}]}
{"arg": {"channel": "books", "instId": "BTC-USDT"}, "action": "update", "data": [{"asks": [["88502.9", "0.0001", "0", "1"], ["88503.1", "0.0001", "0", "1"], ["88503.7", "0", "0", "0"], ["88532.5", "0", "0", "0"], ["88533.8", "0.2259872", "0", "1"], ["88537.1", "0.03649299", "0", "1"], ["88563.9", "0", "0", "0"], ["88565.1", "0.01740073", "0", "1"], ["88609.5", "0", "0", "0"], ["88609.7", "0", "0", "0"]], "bids": [["88494.7", "0.0001", "0", "1"], ["88494.6", "0.0001", "0", "1"], ["88491.3", "0.20624224", "0", "1"], ["88489.5", "0", "0", "0"], ["88475.2", "0.22608086", "0", "2"], ["88471.2", "0", "0", "0"], ["88365.8", "0.17400738", "0", "1"], ["88364.1", "0", "0", "0"], ["88262.9", "0.00168511", "0", "2"]], "ts": "1741338244205", "checksum": -934029573, "seqId": 48070604347, "prevSeqId": 48070604311}]}
{"arg": {"channel": "books", "instId": "BTC-USDT"}, "action": "update", "data": [{"asks": [["88498.4", "0.45859505", "0", "11"], ["88502.9", "0", "0", "0"], ["88503.1", "0", "0", "0"], ["88503.5", "0.0002", "0", "2"], ["88519.2", "0.17236591", "0", "1"], ["88521.8", "0", "0", "0"], ["88523.4", "0.135", "0", "3"], ["88523.7", "1.04", "0", "2"], ["88529.2", "0.21039054", "0", "2"], ["88533.8", "0.22598303", "0", "1"], ["88534.8", "0.02510254", "0", "1"], ["88544", "0.06084248", "0", "4"], ["88545", "0.09", "0", "3"], ["88553", "0", "0", "0"], ["88554", "0.000035", "0", "1"], ["88609.5", "0.0203", "0", "1"]], "bids": [["88498.3", "0.16786703", "0", "4"], ["88494.8", "0.0002", "0", "2"], ["88494.7", "0", "0", "0"], ["88494.6", "0", "0", "0"], ["88482.9", "0.0000225", "0", "1"], ["88476.8", "0.22598303", "0", "1"], ["88475.2", "0", "0", "0"], ["88458", "0.06", "0", "2"], ["88456.1", "0.91895064", "0", "2"], ["88456", "0.03", "0", "1"], ["88455", "0", "0", "0"], ["88454.1", "0", "0", "0"], ["88454", "0.01129106", "0", "1"]], "ts": "1741338244305", "checksum": -1042769782, "seqId": 48070604417, "prevSeqId": 48070604347}]}
{"arg": {"channel": "books", "instId": "BTC-USDT"}, "action": "update", "data": [{"asks": [["88505.5", "0.00192247", "0", "1"], ["88505.6", "0.02820215", "0", "1"], ["88505.7", "0.02775328", "0", "1"], ["88505.8", "0", "0", "0"], ["88506", "0.01934275", "0", "2"], ["88506.7", "0.0259975", "0", "1"], ["88506.8", "0.01888533", "0", "1"], ["88507.3", "0.02694011", "0", "2"], ["88507.4", "0", "0", "0"], ["88507.9", "0", "0", "0"], ["88509.3", "0.08311312", "0", "1"], ["88509.4", "0", "0", "0"], ["88509.8", "0.08770611", "0", "1"], ["88510", "0.0171", "0", "1"], ["88511", "0.0820112", "0", "1"], ["88511.1", "0", "0", "0"], ["88511.7", "0.08379138", "0", "1"], ["88511.8", "0", "0", "0"], ["88513.4", "0.13773063", "0", "2"], ["88513.6", "0", "0", "0"], ["88514.2", "0.12539287", "0", "1"], ["88514.3", "0", "0", "0"], ["88514.9", "0.18673679", "0", "2"], ["88516", "0.13272303", "0", "1"], ["88516.2", "0", "0", "0"], ["88516.6", "0.14528864", "0", "2"], ["88516.7", "0.01364", "0", "1"], ["88519.2", "0.49415054", "0", "2"], ["88519.8", "0.05143796", "0", "2"], ["88520.3", "0.016", "0", "1"], ["88520.8", "1", "0", "1"], ["88523.6", "0.3378221", "0", "1"], ["88523.7", "0.04", "0", "1"], ["88523.8", "0", "0", "0"], ["88533.8", "0.22598647", "0", "1"], ["88565.1", "0.01740051", "0", "1"], ["88609.5", "0", "0", "0"]], "bids": [["88498.3", "0.12726703", "0", "3"], ["88494.8", "0", "0", "0"], ["88494.6", "0.0001", "0", "1"], ["88494.5", "0.0001", "0", "1"], ["88488.4", "0", "0", "0"], ["88488.3", "0.02993963", "0", "1"], ["88488", "0", "0", "0"], ["88487.8", "0.02644858", "0", "1"], ["88487.7", "0.02635737", "0", "1"], ["88487.5", "0", "0", "0"], ["88487.4", "0.02801778", "0", "1"], ["88484.7", "0", "0", "0"], ["88484.6", "0.08615588", "0", "1"], ["88483.8", "0", "0", "0"], ["88483.7", "0.07935143", "0", "1"], ["88483.5", "0", "0", "0"], ["88483.4", "0.07598898", "0", "1"], ["88483", "0", "0", "0"], ["88482.9", "0.08320383", "0", "1"], ["88480.6", "0", "0", "0"], ["88480.4", "0.14866739", "0", "1"], ["88480.2", "0.33929724", "0", "1"], ["88480.1", "0.13327798", "0", "2"], ["88478.1", "0", "0", "0"], ["88478", "0.14775773", "0", "1"], ["88477.7", "0", "0", "0"], ["88477.5", "0.1415385", "0", "1"], ["88476.8", "0", "0", "0"], ["88475.2", "0.22598664", "0", "1"], ["88457", "0", "0", "0"], ["88456.2", "0.01650401", "0", "1"], ["88456.1", "0.90244663", "0", "1"], ["88456", "0.06", "0", "2"], ["88455", "0.03", "0", "1"], ["88440.1", "0.01740051", "0", "1"], ["88365.8", "0.17400517", "0", "1"], ["88262.9", "0", "0", "0"]], "ts": "1741338244405", "checksum": 313127702, "seqId": 48070604532, "prevSeqId": 48070604417}]}
{"arg": {"channel": "books", "instId": "BTC-USDT"}, "action": "update", "data": [{"asks": [["88501.1", "0.0001", "0", "1"], ["88503.5", "0.0001", "0", "1"], ["88505.2", "0.02952574", "0", "1"], ["88505.4", "0.02656507", "0", "1"], ["88505.5", "0", "0", "0"], ["88505.6", "0", "0", "0"], ["88505.7", "0", "0", "0"], ["88505.8", "0.00114586", "0", "1"], ["88506.1", "0.156775", "0", "5"], ["88506.3", "0.02667156", "0", "1"], ["88506.7", "0", "0", "0"], ["88507", "0.02864886", "0", "1"], ["88507.3", "0.00001138", "0", "1"], ["88508.9", "0.012102", "0", "1"], ["88509", "0.08505328", "0", "1"], ["88509.3", "0", "0", "0"], ["88509.5", "0.07872591", "0", "1"], ["88509.8", "0", "0", "0"], ["88510.6", "0.07657399", "0", "1"], ["88511", "0", "0", "0"], ["88511.4", "0.08284544", "0", "1"], ["88511.7", "0", "0", "0"], ["88513.1", "0.15812379", "0", "2"], ["88513.4", "0.00006", "0", "1"], ["88513.9", "0.13178095", "0", "1"], ["88514.2", "0", "0", "0"], ["88514.9", "0.1890433", "0", "2"], ["88515.7", "0.13865935", "0", "1"], ["88516", "0", "0", "0"], ["88516.3", "0.14646921", "0", "1"], ["88516.6", "0.00057148", "0", "1"], ["88519.4", "1.016", "0", "2"], ["88520.8", "0", "0", "0"], ["88532.5", "0.22598766", "0", "1"], ["88533.8", "0", "0", "0"], ["88543", "0.00008419", "0", "3"], ["88565.1", "0.0174007", "0", "1"], ["88566", "0", "0", "0"], ["88609.3", "0", "0", "0"], ["88609.4", "0", "0", "0"]], "bids": [["88494.6", "0", "0", "0"], ["88494.5", "0", "0", "0"], ["88494.4", "0.0001", "0", "1"], ["88494.3", "0.0001", "0", "1"], ["88488.3", "0", "0", "0"], ["88487.9", "0.02670499", "0", "1"], ["88487.8", "0", "0", "0"], ["88487.7", "0", "0", "0"], ["88487.6", "0.13955375", "0", "1"], ["88487.5", "0.02885026", "0", "1"], ["88487.4", "0", "0", "0"], ["88487.3", "0.02437917", "0", "1"], ["88487.1", "0.02600071", "0", "1"], ["88484.6", "0", "0", "0"], ["88484.2", "0.08867517", "0", "1"], ["88483.7", "0", "0", "0"], ["88483.4", "0.08210115", "0", "1"], ["88483", "0.07621413", "0", "1"], ["88482.9", "0", "0", "0"], ["88482.7", "0.07911734", "0", "1"], ["88480.4", "0", "0", "0"], ["88480.1", "0.14311269", "0", "2"], ["88479.7", "0.13860144", "0", "1"], ["88478", "0", "0", "0"], ["88477.8", "0.13714118", "0", "2"], ["88477.5", "0", "0", "0"], ["88477.2", "0.14235534", "0", "1"], ["88476", "0.01119977", "0", "2"], ["88475.2", "0", "0", "0"], ["88473.4", "0.22599904", "0", "2"], ["88459.9", "0.01650401", "0", "1"], ["88458", "0", "0", "0"], ["88457", "0.06", "0", "2"], ["88456.2", "0", "0", "0"], ["88440.1", "0.0174007", "0", "1"], ["88365.8", "0.17400702", "0", "1"], ["88262.9", "0.00168511", "0", "2"], ["88261.8", "0.00074456", "0", "1"]], "ts": "1741338244505", "checksum": 271307130, "seqId": 48070604656, "prevSeqId": 48070604532}]}
{"arg": {"channel": "books", "instId": "BTC-USDT"}, "action": "update", "data": [{"asks": [["88519.4", "0.016", "0", "1"], ["88530.5", "0.22599164", "0", "1"], ["88532.5", "0", "0", "0"], ["88548.8", "0.01061", "0", "4"], ["88549.6", "0.00031501", "0", "2"], ["88557.6", "0", "0", "0"], ["88558.4", "0.02259853", "0", "2"], ["88609.3", "0.04063049", "0", "5"]], "bids": [["88494.6", "0.0002", "0", "2"], ["88494.4", "0", "0", "0"], ["88494.3", "0", "0", "0"], ["88473.4", "0.00001138", "0", "1"], ["88471.2", "0.22599164", "0", "1"]], "ts": "1741338244605", "checksum": 2021342693, "seqId": 48070604684, "prevSeqId": 48070604656}]}
{"arg": {"channel": "books", "instId": "BTC-USDT"}, "action": "update", "data": [{"asks": [["88503.5", "0", "0", "0"], ["88503.6", "0.0001", "0", "1"], ["88505.1", "0.02755532", "0", "1"], ["88505.2", "0.0270177", "0", "1"], ["88505.4", "0", "0", "0"], ["88506.1", "0.28772834", "0", "6"], ["88506.3", "0", "0", "0"], ["88506.8", "0.04783546", "0", "2"], ["88507", "0", "0", "0"], ["88507.3", "0.20701138", "0", "2"], ["88508.7", "0.012102", "0", "1"], ["88508.8", "0.08143747", "0", "1"], ["88508.9", "0", "0", "0"], ["88509", "0", "0", "0"], ["88509.3", "0.08336424", "0", "1"], ["88509.5", "0", "0", "0"], ["88510.4", "0.07839444", "0", "1"], ["88510.6", "0", "0", "0"], ["88511.3", "0.08883361", "0", "1"], ["88511.4", "0", "0", "0"], ["88512.9", "0.13299785", "0", "1"], ["88513.1", "0.01129804", "0", "1"], ["88513.7", "0.12978624", "0", "1"], ["88513.9", "0", "0", "0"], ["88514.8", "1.15314015", "0", "2"], ["88514.9", "0", "0", "0"], ["88515.5", "0.15018533", "0", "1"], ["88515.7", "0", "0", "0"], ["88516.1", "0.14808147", "0", "1"], ["88516.3", "0", "0", "0"], ["88519.2", "0.4946942", "0", "2"], ["88520.5", "1", "0", "1"], ["88530.5", "0", "0", "0"], ["88532.5", "0.22599135", "0", "1"], ["88544", "0.12084248", "0", "6"], ["88545", "0.03", "0", "1"], ["88609.4", "0.04207212", "0", "4"]], "bids": [["88498.3", "0.10803792", "0", "2"], ["88498", "0", "0", "0"], ["88496", "0", "0", "0"], ["88494.6", "0", "0", "0"], ["88493.8", "0.0001", "0", "1"], ["88493.7", "0.0001", "0", "1"], ["88487.9", "0", "0", "0"], ["88487.8", "0.02780024", "0", "1"], ["88487.6", "0.10113791", "0", "1"], ["88487.5", "0", "0", "0"], ["88487.3", "0.02918993", "0", "1"], ["88487.1", "0.02652425", "0", "1"], ["88486.9", "0.35469613", "0", "2"], ["88484.2", "0", "0", "0"], ["88484", "0.75274327", "0", "2"], ["88483.4", "0", "0", "0"], ["88483.2", "0.23724634", "0", "3"], ["88483", "0", "0", "0"], ["88482.8", "0.07803468", "0", "1"], ["88482.7", "0", "0", "0"], ["88482.5", "0.08295914", "0", "1"], ["88480.5", "0", "0", "0"], ["88480.1", "0.00056509", "0", "1"], ["88479.9", "0.1494548", "0", "1"], ["88479.7", "0", "0", "0"], ["88479.6", "0.30664805", "0", "3"], ["88477.8", "0.00340372", "0", "1"], ["88477.6", "0.14794348", "0", "2"], ["88477.2", "0", "0", "0"], ["88477", "0.1444768", "0", "1"], ["88459", "0.06", "0", "2"], ["88457", "0", "0", "0"], ["88260.8", "0.00010584", "0", "1"], ["88260", "0.00002148", "0", "1"], ["88259.2", "0.00005974", "0", "1"], ["88259.1", "0.00011181", "0", "1"], ["88258.7", "0.00282652", "0", "1"]], "ts": "1741338244705", "checksum": -644275195, "seqId": 48070604799, "prevSeqId": 48070604684}]}
{"arg": {"channel": "books", "instId": "BTC-USDT"}, "action": "update", "data": [{"asks": [["88491.8", "0.6251034", "0", "13"], ["88491.9", "0.0002", "0", "2"], ["88492", "0.0171", "0", "1"], ["88493.9", "0.0214226", "0", "1"], ["88494", "0.0171", "0", "1"], ["88497", "0.00224285", "0", "1"], ["88497.1", "0.05205327", "0", "2"], ["88498", "0.0171", "0", "1"], ["88498.2", "0.01305379", "0", "1"], ["88498.3", "0.03996345", "0", "2"], ["88498.4", "0.07982811", "0", "3"], ["88499.3", "0.0252571", "0", "1"], ["88500.1", "0.0290664", "0", "1"], ["88501", "0.00209084", "0", "1"], ["88501.1", "0", "0", "0"], ["88501.6", "0", "0", "0"], ["88501.7", "0.00001138", "0", "1"], ["88501.9", "0.06705383", "0", "1"], ["88502", "0.09842486", "0", "2"], ["88502.5", "0.08401973", "0", "1"], ["88503.5", "0.04094", "0", "1"], ["88503.6", "0", "0", "0"], ["88504", "0.02444532", "0", "2"], ["88504.4", "0", "0", "0"], ["88504.6", "0.08352072", "0", "1"], ["88505", "0.05989404", "0", "2"], ["88505.1", "0", "0", "0"], ["88505.2", "0", "0", "0"], ["88505.6", "0.000015", "0", "1"], ["88505.8", "0", "0", "0"], ["88505.9", "0", "0", "0"], ["88506", "0.0171", "0", "1"], ["88506.1", "0.42387762", "0", "6"], ["88506.8", "0.01888533", "0", "1"], ["88507.9", "0.012102", "0", "1"], ["88508.2", "0", "0", "0"], ["88508.7", "0", "0", "0"], ["88508.8", "0", "0", "0"], ["88509.3", "0", "0", "0"], ["88510.4", "0", "0", "0"], ["88511.3", "0", "0", "0"], ["88512.9", "0", "0", "0"], ["88513.7", "0", "0", "0"], ["88514", "0", "0", "0"], ["88514.8", "1.28940106", "0", "3"], ["88515.5", "0", "0", "0"], ["88516.1", "1", "0", "1"], ["88518", "0", "0", "0"], ["88519.2", "0.26936903", "0", "2"], ["88520", "0.08542891", "0", "1"], ["88520.5", "0", "0", "0"], ["88521.5", "0.22601281", "0", "1"], ["88522.3", "0", "0", "0"], ["88523.3", "0.04", "0", "1"], ["88532.5", "0", "0", "0"], ["88533.9", "0", "0", "0"], ["88538.4", "0.14741614", "0", "6"], ["88541.2", "0.16416611", "0", "3"], ["88550.6", "0.00071315", "0", "1"], ["88557.1", "0", "0", "0"], ["88560.8", "0.01740292", "0", "1"], ["88563.3", "0.01693741", "0", "1"], ["88565.1", "0", "0", "0"], ["88569.7", "0.28306431", "0", "2"], ["88570", "0.49675", "0", "1"], ["88581.4", "0", "0", "0"], ["88582.7", "0", "0", "0"], ["88587.3", "0.00167685", "0", "1"], ["88590.4", "0.76801362", "0", "2"], ["88591.3", "0", "0", "0"], ["88598.5", "0", "0", "0"], ["88601.5", "0.65121071", "0", "1"], ["88609.5", "0.0203", "0", "1"]], "bids": [["88498.3", "0", "0", "0"], ["88498.2", "0", "0", "0"], ["88497", "0", "0", "0"], ["88496.1", "0", "0", "0"], ["88495.5", "0", "0", "0"], ["88494", "0", "0", "0"], ["88493.9", "0", "0", "0"], ["88493.8", "0", "0", "0"], ["88493.7", "0", "0", "0"], ["88492.1", "0", "0", "0"], ["88491.7", "0.14522988", "0", "4"], ["88491.3", "0", "0", "0"], ["88491.2", "0", "0", "0"], ["88490.8", "0.00004575", "0", "1"], ["88490.6", "0", "0", "0"], ["88490.4", "0", "0", "0"], ["88490", "0.0171", "0", "1"], ["88489.8", "0", "0", "0"], ["88489.4", "0", "0", "0"], ["88488.6", "0.0001", "0", "1"], ["88488.5", "0", "0", "0"], ["88488.1", "0.02255316", "0", "1"], ["88488", "0.01822851", "0", "2"], ["88487.8", "0", "0", "0"], ["88487.7", "0.0001", "0", "1"], ["88487.6", "0", "0", "0"], ["88487.3", "0", "0", "0"], ["88487.2", "0.000027", "0", "1"], ["88487.1", "0", "0", "0"], ["88486.9", "0", "0", "0"], ["88486.7", "0.04", "0", "1"], ["88485.8", "0", "0", "0"], ["88485.6", "0.00734532", "0", "1"], ["88485", "0.00935", "0", "1"], ["88484", "0.181299", "0", "1"], ["88483.9", "0", "0", "0"], ["88483.2", "0.147132", "0", "2"], ["88482.8", "0", "0", "0"], ["88482.5", "0", "0", "0"], ["88481.7", "0", "0", "0"], ["88481", "0", "0", "0"], ["88480.3", "0.02444725", "0", "1"], ["88480.2", "0.36559936", "0", "2"], ["88480", "0.03594673", "0", "1"], ["88479.9", "0", "0", "0"], ["88479.6", "0.16106167", "0", "2"], ["88479.2", "0", "0", "0"], ["88479", "0.0062197", "0", "1"], ["88477.8", "0", "0", "0"], ["88477.6", "0.000015", "0", "1"], ["88477", "0", "0", "0"], ["88476.4", "0.08456245", "0", "1"], ["88476", "0.00734477", "0", "1"], ["88474.9", "0", "0", "0"], ["88473.1", "0.13364235", "0", "1"], ["88472.7", "0.00452117", "0", "1"], ["88472.6", "0", "0", "0"], ["88472.5", "0.01868488", "0", "2"], ["88471.2", "0", "0", "0"], ["88471.1", "0", "0", "0"], ["88470.2", "0.13389524", "0", "1"], ["88469.6", "0", "0", "0"], ["88468.8", "0.04001501", "0", "2"], ["88466.4", "0.00059936", "0", "2"], ["88466.2", "0.22601265", "0", "1"], ["88465.7", "1.65695413", "0", "2"], ["88465.6", "0.00029937", "0", "1"], ["88465.1", "0.90244663", "0", "1"], ["88465", "0.207", "0", "1"], ["88461.3", "0.15978249", "0", "2"], ["88461.1", "0.147132", "0", "2"], ["88459.9", "0", "0", "0"], ["88459", "0", "0", "0"], ["88458.9", "0", "0", "0"], ["88457.4", "0.20567", "0", "1"], ["88456.3", "0.0349506", "0", "1"], ["88456", "0", "0", "0"], ["88455.1", "0", "0", "0"], ["88455", "0", "0", "0"], ["88454", "0.06", "0", "2"], ["88453", "0.06", "0", "2"], ["88452", "0.03016958", "0", "2"], ["88451.6", "0", "0", "0"], ["88451.1", "0.01650401", "0", "1"], ["88451", "0.44341", "0", "1"], ["88450.6", "0.0112", "0", "1"], ["88449.9", "0.00057148", "0", "1"], ["88447", "0.16114191", "0", "1"], ["88446.7", "0", "0", "0"], ["88445.7", "0.02258424", "0", "2"], ["88445.3", "0", "0", "0"], ["88443.1", "0.24598147", "0", "1"], ["88440.3", "0.01129127", "0", "1"], ["88440.1", "0", "0", "0"], ["88439.9", "0", "0", "0"], ["88438.1", "0.01696138", "0", "1"], ["88438", "0", "0", "0"], ["88436.3", "0.01740292", "0", "1"], ["88435.9", "0", "0", "0"], ["88435.7", "0", "0", "0"], ["88434.9", "0.88231128", "0", "1"], ["88433.9", "0", "0", "0"], ["88433.2", "0", "0", "0"], ["88432.9", "0", "0", "0"], ["88432.2", "0", "0", "0"], ["88431.9", "0.00102754", "0", "1"], ["88430.8", "0.88259997", "0", "2"], ["88430.2", "2.12624221", "0", "1"], ["88429.5", "0", "0", "0"], ["88428.4", "0.00343", "0", "1"], ["88426.8", "0", "0", "0"], ["88426.7", "0", "0", "0"], ["88424.5", "0.0009876", "0", "1"], ["88424.4", "0.2166115", "0", "2"], ["88423.1", "0", "0", "0"], ["88422.3", "0", "0", "0"], ["88417.7", "0.01129221", "0", "1"], ["88415.9", "0", "0", "0"], ["88414.8", "1.07978628", "0", "2"], ["88408.7", "0.02259925", "0", "1"], ["88404.4", "0.0165789", "0", "1"], ["88404", "0", "0", "0"], ["88402.9", "0.00451992", "0", "1"], ["88396.1", "0", "0", "0"], ["88386.7", "0", "0", "0"], ["88385.9", "0.02259925", "0", "1"], ["88384.5", "0.01655658", "0", "1"], ["88365.8", "0", "0", "0"], ["88361.6", "0.1740292", "0", "1"], ["88349.7", "0.05088414", "0", "1"], ["88326.4", "0.03", "0", "1"], ["88289.8", "0", "0", "0"], ["88271.9", "0.00566444", "0", "1"], ["88268.6", "0", "0", "0"], ["88257.9", "0.00020125", "0", "2"], ["88257.6", "0.00003493", "0", "1"], ["88256.9", "0.34056098", "0", "1"], ["88256.4", "0.0000172", "0", "1"], ["88255.8", "0.00003183", "0", "1"], ["88255.6", "0.12221196", "0", "1"], ["88255", "0.01785714", "0", "1"], ["88254.3", "0.00012967", "0", "2"], ["88253.7", "0.00326441", "0", "1"], ["88253", "0.00001297", "0", "1"], ["88252", "0.00002018", "0", "1"], ["88251.8", "0.00001302", "0", "1"], ["88250.7", "0.11343045", "0", "1"], ["88250", "0.11322175", "0", "21"], ["88249.9", "0.00060139", "0", "2"], ["88248.9", "0.03", "0", "1"], ["88247.9", "0.0001", "0", "1"], ["88247.3", "0.00001139", "0", "1"], ["88246.9", "0.03", "0", "1"], ["88246.8", "0.00560182", "0", "1"], ["88246.7", "0.00840315", "0", "1"], ["88246.4", "0.34056098", "0", "1"], ["88244.9", "0.00001267", "0", "1"], ["88244.2", "0.03", "0", "1"], ["88243.5", "0.03", "0", "1"], ["88243.4", "0.00001628", "0", "1"]], "ts": "1741338244805", "checksum": 2093552324, "seqId": 48070605644, "prevSeqId": 48070604799}]}
{"arg": {"channel": "books", "instId": "BTC-USDT"}, "action": "update", "data": [{"asks": [["88491.8", "0.5409834", "0", "12"], ["88491.9", "0", "0", "0"], ["88495.4", "0.0001", "0", "1"], ["88495.6", "0.0001", "0", "1"], ["88497.9", "0.03643021", "0", "2"], ["88498.2", "0", "0", "0"], ["88498.3", "0.01364", "0", "1"], ["88498.4", "0.05205327", "0", "2"], ["88499.3", "0", "0", "0"], ["88500.1", "0", "0", "0"], ["88501", "0", "0", "0"], ["88501.9", "0.11382539", "0", "2"], ["88502", "0.0171", "0", "1"], ["88502.5", "0", "0", "0"], ["88504.3", "0.08112528", "0", "1"], ["88504.6", "0", "0", "0"], ["88504.7", "0.00209084", "0", "1"], ["88506.1", "0.31774264", "0", "5"], ["88518", "0.039", "0", "1"], ["88521.5", "0.22601248", "0", "1"], ["88555.8", "0.1", "0", "1"], ["88584.8", "0.00169185", "0", "2"], ["88587.3", "0", "0", "0"], ["88609.7", "0.01692", "0", "1"]], "bids": [["88491.7", "0.08522988", "0", "2"], ["88488.7", "0.0001", "0", "1"], ["88488.4", "0.11300686", "0", "1"], ["88487.7", "0", "0", "0"], ["88486", "0.0171", "0", "1"], ["88484", "0.26581689", "0", "2"], ["88482.7", "0.33905", "0", "1"], ["88480.9", "0.33906", "0", "1"], ["88480.3", "0", "0", "0"], ["88480.2", "0.33929724", "0", "1"], ["88479.6", "0.16020197", "0", "2"], ["88476.4", "0", "0", "0"], ["88475.6", "0.08193197", "0", "1"], ["88473.5", "0.00337762", "0", "1"], ["88473.1", "0", "0", "0"], ["88470.7", "0.13387629", "0", "1"], ["88470.6", "0.10669431", "0", "3"], ["88470.2", "0", "0", "0"], ["88470.1", "0", "0", "0"], ["88466.2", "0", "0", "0"], ["88462", "0.22601248", "0", "1"], ["88445", "0.1", "0", "1"], ["88431.9", "0", "0", "0"], ["88428.6", "0.00102754", "0", "1"], ["88424.5", "0", "0", "0"], ["88421.9", "0.0009876", "0", "1"], ["88417.3", "0", "0", "0"], ["88312.7", "0.00001138", "0", "1"], ["88244.2", "0", "0", "0"], ["88243.5", "0", "0", "0"], ["88243.4", "0", "0", "0"]], "ts": "1741338244905", "checksum": -1585868321, "seqId": 48070605926, "prevSeqId": 48070605644}]}
{"arg": {"channel": "books", "instId": "BTC-USDT"}, "action": "update", "data": [{"asks": [["88494.2", "0.0002", "0", "2"], ["88495.1", "0.01364", "0", "1"], ["88495.4", "0", "0", "0"], ["88495.6", "0", "0", "0"], ["88497.9", "0.04012707", "0", "2"], ["88498.3", "0.02843488", "0", "1"], ["88498.4", "0.0786698", "0", "3"], ["88499.3", "0.02655905", "0", "1"], ["88499.9", "0.02822788", "0", "1"], ["88500.5", "0.0039", "0", "1"], ["88501.8", "0.00209084", "0", "1"], ["88501.9", "0.1407514", "0", "2"], ["88502", "0.10643445", "0", "2"], ["88502.5", "0.08612628", "0", "1"], ["88503.6", "0.08089195", "0", "1"], ["88504.7", "0", "0", "0"], ["88506.1", "0.45170765", "0", "5"], ["88506.9", "0.12744334", "0", "1"], ["88508.7", "0.13499946", "0", "1"], ["88509.2", "0.13902755", "0", "1"], ["88514.5", "0.096", "0", "2"], ["88518", "0.126", "0", "3"], ["88521.6", "0", "0", "0"], ["88536.4", "0.00564739", "0", "1"], ["88540", "0.06503926", "0", "6"], ["88541", "0.09004407", "0", "6"], ["88542.9", "0.00071315", "0", "1"], ["88544", "0.00084248", "0", "2"], ["88545", "0", "0", "0"], ["88546", "0.53149365", "0", "4"], ["88546.6", "0.00001512", "0", "1"], ["88550.5", "0.1", "0", "1"], ["88550.6", "0", "0", "0"], ["88555.8", "0", "0", "0"], ["88556.4", "0.01740272", "0", "1"], ["88560.8", "0", "0", "0"], ["88608.6", "0", "0", "0"], ["88608.9", "0", "0", "0"], ["88609", "0", "0", "0"], ["88609.2", "0", "0", "0"], ["88609.3", "0", "0", "0"], ["88609.4", "0", "0", "0"], ["88609.5", "0", "0", "0"], ["88609.7", "0", "0", "0"]], "bids": [["88488.7", "0", "0", "0"], ["88488.6", "0", "0", "0"], ["88488.1", "0", "0", "0"], ["88487.4", "0.0002", "0", "2"], ["88487.3", "0.02215461", "0", "1"], ["88481", "0.0290789", "0", "1"], ["88480.5", "0.02679418", "0", "1"], ["88480.3", "0.02622445", "0", "1"], ["88480", "0.06333716", "0", "2"], ["88478.1", "0.00935", "0", "1"], ["88477.3", "0.08373003", "0", "1"], ["88476.4", "0.08605781", "0", "1"], ["88476", "0.09078822", "0", "2"], ["88473.1", "0.14481628", "0", "1"], ["88472.8", "0.13281168", "0", "1"], ["88471.5", "0.02807", "0", "1"], ["88470.8", "0.1089081", "0", "1"], ["88470.6", "0.005", "0", "1"], ["88470.2", "0.13936553", "0", "1"], ["88458.6", "0.0323093", "0", "1"], ["88453.8", "0.11343045", "0", "1"], ["88452.1", "0.58525688", "0", "2"], ["88451.1", "0", "0", "0"], ["88445", "0.11129243", "0", "2"], ["88436.3", "0", "0", "0"], ["88432.2", "0.01740272", "0", "1"], ["88417.7", "0", "0", "0"], ["88397.8", "0", "0", "0"], ["88396.5", "0.01903617", "0", "1"], ["88393.4", "0.00019401", "0", "1"], ["88361.6", "0", "0", "0"], ["88351.2", "0.17402722", "0", "1"], ["88250", "0", "0", "0"], ["88249.9", "0", "0", "0"], ["88248.9", "0", "0", "0"], ["88247.9", "0", "0", "0"], ["88247.3", "0", "0", "0"], ["88246.9", "0", "0", "0"], ["88246.8", "0", "0", "0"], ["88246.7", "0", "0", "0"], ["88246.4", "0", "0", "0"], ["88244.9", "0", "0", "0"]], "ts": "1741338245005", "checksum": 510608164, "seqId": 48070606076, "prevSeqId": 48070605926}]}
{"arg": {"channel": "books", "instId": "BTC-USDT"}, "action": "update", "data": [{"asks": [["88491.8", "0.50490538", "0", "10"], ["88491.9", "0.03069921", "0", "2"], ["88493.9", "0", "0", "0"], ["88494.2", "0", "0", "0"], ["88495.5", "0.00627993", "0", "1"], ["88496", "0.0001", "0", "1"], ["88496.1", "0.0001", "0", "1"], ["88497.9", "0", "0", "0"], ["88498.3", "0.05008872", "0", "1"], ["88498.4", "0.05205327", "0", "2"], ["88498.7", "0.0271527", "0", "1"], ["88498.9", "0.02864152", "0", "1"], ["88499.3", "0", "0", "0"], ["88499.8", "0.02522505", "0", "1"], ["88499.9", "0", "0", "0"], ["88500.4", "0.02785435", "0", "1"], ["88501.6", "0.0014576", "0", "1"], ["88501.8", "0", "0", "0"], ["88501.9", "0.13911034", "0", "1"], ["88502", "0.0171", "0", "1"], ["88502.5", "0.09002768", "0", "1"], ["88503", "0.07864672", "0", "1"], ["88503.6", "0", "0", "0"], ["88503.9", "0.012102", "0", "1"], ["88504.1", "0.08296012", "0", "1"], ["88504.3", "0", "0", "0"], ["88504.8", "0.07965503", "0", "1"], ["88506.1", "0.31820183", "0", "4"], ["88506.6", "0.13609583", "0", "1"], ["88506.9", "0", "0", "0"], ["88507.4", "0.13619893", "0", "1"], ["88507.9", "0", "0", "0"], ["88508.7", "0.01255986", "0", "1"], ["88509.2", "0.14245575", "0", "1"], ["88509.7", "0.13497667", "0", "1"], ["88511.6", "0.66817718", "0", "2"], ["88512", "0.02721284", "0", "2"], ["88514.6", "1", "0", "1"], ["88514.8", "1.03870754", "0", "2"], ["88516.1", "0", "0", "0"], ["88516.7", "0", "0", "0"], ["88518", "0.174", "0", "4"], ["88518.2", "0", "0", "0"], ["88519.2", "0.17236591", "0", "1"], ["88521.5", "0", "0", "0"], ["88523.4", "0.042", "0", "1"], ["88525.1", "0", "0", "0"], ["88525.3", "0.22600584", "0", "1"], ["88532.6", "0.86571202", "0", "2"], ["88534.2", "1.62818905", "0", "1"], ["88540", "0.12503926", "0", "8"], ["88541", "0.03004407", "0", "4"], ["88544", "0.00144248", "0", "4"], ["88544.8", "0.00031536", "0", "2"], ["88548.8", "0.01001", "0", "2"], ["88549.6", "0.00001501", "0", "1"], ["88606.9", "0", "0", "0"], ["88607.8", "0", "0", "0"], ["88607.9", "0", "0", "0"], ["88608", "0", "0", "0"]], "bids": [["88491.7", "0.14522988", "0", "4"], ["88490.7", "0.0001", "0", "1"], ["88490.6", "0.0001", "0", "1"], ["88487.4", "0", "0", "0"], ["88487.3", "0", "0", "0"], ["88486.8", "0.02214651", "0", "1"], ["88481.8", "0", "0", "0"], ["88481.4", "0.02647686", "0", "1"], ["88481", "0.02967478", "0", "1"], ["88480.8", "0.02554997", "0", "1"], ["88480.5", "0.02882061", "0", "1"], ["88480.3", "0", "0", "0"], ["88480", "0.03594673", "0", "1"], ["88479.6", "0.1652332", "0", "2"], ["88477.7", "0.08291383", "0", "1"], ["88477.3", "0", "0", "0"], ["88476.9", "0.08995682", "0", "1"], ["88476.7", "0", "0", "0"], ["88476.5", "0.07635922", "0", "1"], ["88476.4", "0", "0", "0"], ["88476.1", "0.07891872", "0", "1"], ["88476", "0.00734477", "0", "1"], ["88475.6", "0", "0", "0"], ["88473.9", "0.207", "0", "1"], ["88473.6", "0.13142241", "0", "1"], ["88473.2", "0.13739766", "0", "1"], ["88473.1", "0", "0", "0"], ["88472.9", "0.015", "0", "1"], ["88472.8", "0", "0", "0"], ["88471.2", "0.13483929", "0", "1"], ["88470.8", "0.20108014", "0", "1"], ["88470.7", "0.14604116", "0", "1"], ["88470.2", "0", "0", "0"], ["88467.2", "0.22660584", "0", "3"], ["88467.1", "0.128138", "0", "1"], ["88466.4", "0.00029936", "0", "1"], ["88465.6", "0", "0", "0"], ["88462", "0", "0", "0"], ["88461.3", "0.22077317", "0", "3"], ["88459.8", "0", "0", "0"], ["88454.7", "0.03521284", "0", "1"], ["88452.1", "0.56875287", "0", "1"], ["88447.1", "0.01650401", "0", "1"], ["88253", "0", "0", "0"], ["88252", "0", "0", "0"], ["88251.8", "0", "0", "0"], ["88250.7", "0", "0", "0"]], "ts": "1741338245105", "checksum": 1320670849, "seqId": 48070606254, "prevSeqId": 48070606076}]}
{"arg": {"channel": "books", "instId": "BTC-USDT"}, "action": "update", "data": [{"asks": [["88491.8", "0.52430538", "0", "11"], ["88493.7", "0.0001", "0", "1"], ["88496", "0", "0", "0"], ["88496.1", "0", "0", "0"], ["88496.2", "0.0001", "0", "1"], ["88498.3", "0.07205473", "0", "3"], ["88498.4", "0.08168439", "0", "3"], ["88498.7", "0", "0", "0"], ["88498.9", "0", "0", "0"], ["88499.8", "0", "0", "0"], ["88499.9", "0.02698156", "0", "1"], ["88500.4", "0", "0", "0"], ["88500.5", "0", "0", "0"], ["88501.6", "0", "0", "0"], ["88501.9", "0.12147867", "0", "2"], ["88502", "0.10516982", "0", "2"], ["88502.5", "0.08210464", "0", "1"], ["88503", "0", "0", "0"], ["88503.4", "0.00209084", "0", "1"], ["88504.1", "0", "0", "0"], ["88504.8", "0", "0", "0"], ["88506.1", "0.42641271", "0", "5"], ["88506.6", "0", "0", "0"], ["88507.4", "0", "0", "0"], ["88508.7", "0.16090126", "0", "2"], ["88509.2", "0", "0", "0"], ["88509.7", "0", "0", "0"], ["88512.6", "0.04", "0", "1"], ["88514.6", "0", "0", "0"], ["88514.8", "1.11093396", "0", "3"], ["88519.8", "0.00343796", "0", "1"], ["88521.6", "0.2260145", "0", "1"], ["88523.4", "0", "0", "0"], ["88523.7", "0", "0", "0"], ["88525.3", "0", "0", "0"], ["88539", "1.06826549", "0", "4"], ["88540", "0.06503926", "0", "6"], ["88540.5", "0.00072792", "0", "3"], ["88606.9", "0.00052479", "0", "1"], ["88607.8", "0.00001009", "0", "1"], ["88607.9", "0.00571153", "0", "2"], ["88608", "0.0305953", "0", "2"], ["88608.6", "0.00007393", "0", "1"], ["88608.9", "0.00570112", "0", "1"], ["88609", "0.1", "0", "1"], ["88609.2", "0.00572586", "0", "2"], ["88609.3", "0.04063049", "0", "5"], ["88609.4", "0.04207212", "0", "4"], ["88609.5", "0.0203", "0", "1"], ["88609.7", "0.01692", "0", "1"], ["88610", "0.00004062", "0", "1"]], "bids": [["88491.7", "0.01130077", "0", "1"], ["88490.7", "0", "0", "0"], ["88490.6", "0", "0", "0"], ["88490.3", "0.0001", "0", "1"], ["88490.2", "0.0001", "0", "1"], ["88490", "0", "0", "0"], ["88488", "0.00112851", "0", "1"], ["88486.8", "0", "0", "0"], ["88486.4", "0", "0", "0"], ["88486", "0", "0", "0"], ["88484", "0", "0", "0"], ["88481.4", "0", "0", "0"], ["88481", "0.02872847", "0", "1"], ["88480.8", "0", "0", "0"], ["88480.5", "0.02782457", "0", "1"], ["88480.3", "0.02428774", "0", "1"], ["88480.2", "0", "0", "0"], ["88480", "0.02700513", "0", "1"], ["88479.6", "0.24001855", "0", "2"], ["88479.2", "0.32764", "0", "1"], ["88477.7", "0", "0", "0"], ["88477.2", "0.08204821", "0", "1"], ["88476.9", "0", "0", "0"], ["88476.5", "0", "0", "0"], ["88476.4", "0.08083776", "0", "1"], ["88476.1", "0", "0", "0"], ["88476", "0.08745568", "0", "2"], ["88473.9", "0", "0", "0"], ["88473.6", "0", "0", "0"], ["88473.2", "0", "0", "0"], ["88473.1", "0.13894251", "0", "1"], ["88471.9", "0", "0", "0"], ["88471.2", "0", "0", "0"], ["88470.8", "0.17657145", "0", "2"], ["88470.7", "0", "0", "0"], ["88470.2", "0.13987487", "0", "1"], ["88468.8", "0.00001501", "0", "1"], ["88467.2", "0", "0", "0"], ["88467.1", "0", "0", "0"], ["88466.4", "0.00059936", "0", "2"], ["88465.6", "0.00029937", "0", "1"], ["88461.3", "0.21877317", "0", "2"], ["88458.7", "0.22601527", "0", "1"], ["88457.5", "0", "0", "0"], ["88452.5", "0", "0", "0"], ["88430.7", "0", "0", "0"], ["88414.6", "0", "0", "0"], ["88253", "0.00001297", "0", "1"], ["88252", "0.00002018", "0", "1"], ["88251.8", "0.00001302", "0", "1"], ["88250.7", "0.11343045", "0", "1"], ["88250", "0.11322175", "0", "21"], ["88249.9", "0.00060139", "0", "2"], ["88248.9", "0.03", "0", "1"], ["88247.9", "0.0001", "0", "1"], ["88247.3", "0.00001139", "0", "1"], ["88246.9", "0.03", "0", "1"], ["88246.8", "0.00560182", "0", "1"], ["88246.7", "0.00840315", "0", "1"], ["88246.4", "0.34056098", "0", "1"], ["88244.9", "0.00001267", "0", "1"], ["88244.2", "0.03", "0", "1"], ["88243.5", "0.03", "0", "1"]], "ts": "1741338245205", "checksum": -255082072, "seqId": 48070606456, "prevSeqId": 48070606254}]}
{"arg": {"channel": "books", "instId": "BTC-USDT"}, "action": "update", "data": [{"asks": [["88491.8", "0.54133567", "0", "13"], ["88493.7", "0.0002", "0", "2"], ["88495.1", "0", "0", "0"], ["88496.2", "0", "0", "0"], ["88497.2", "0.02956909", "0", "1"], ["88497.3", "0.02663238", "0", "1"], ["88497.4", "0.09068993", "0", "2"], ["88497.5", "0.04094", "0", "1"], ["88498.3", "0.027296", "0", "1"], ["88498.4", "0.05205327", "0", "2"], ["88499.1", "0.02812045", "0", "1"], ["88499.9", "0", "0", "0"], ["88500.8", "0.00185315", "0", "1"], ["88500.9", "0.08413946", "0", "1"], ["88501.4", "0.08281715", "0", "1"], ["88501.9", "0.21398103", "0", "2"], ["88502", "0.0171", "0", "1"], ["88502.5", "0", "0", "0"], ["88502.6", "0.08347633", "0", "1"], ["88503.4", "0", "0", "0"], ["88503.5", "0", "0", "0"], ["88503.6", "0.08122885", "0", "1"], ["88503.7", "0.012102", "0", "1"], ["88503.8", "0.33929724", "0", "1"], ["88503.9", "0", "0", "0"], ["88505", "0.13900362", "0", "1"], ["88505.9", "0.13155432", "0", "1"], ["88506.1", "0.49376132", "0", "4"], ["88507.6", "0.13686355", "0", "1"], ["88508.5", "0.13445498", "0", "1"], ["88508.7", "0.01255986", "0", "1"], ["88510.1", "1", "0", "1"], ["88511.6", "0.45292359", "0", "1"], ["88521.6", "0.22601464", "0", "1"], ["88528", "0.49709143", "0", "2"], ["88529.2", "0.207", "0", "1"], ["88531", "1", "0", "1"], ["88532.1", "0.03772882", "0", "1"], ["88537", "0.5442764", "0", "4"], ["88537.1", "0", "0", "0"], ["88538", "0.14205327", "0", "5"], ["88539", "1.00826549", "0", "2"], ["88540", "0.00503926", "0", "4"], ["88541", "0.00004407", "0", "3"], ["88551", "0.0659216", "0", "3"], ["88551.1", "0", "0", "0"], ["88551.3", "0.00521204", "0", "2"], ["88554.2", "0.00070666", "0", "2"], ["88559.5", "1.01180945", "0", "5"], ["88566.2", "0.45809014", "0", "2"], ["88577.1", "0", "0", "0"], ["88588.3", "0.01568", "0", "1"], ["88599.8", "0.0226", "0", "1"], ["88602.4", "0.2429521", "0", "3"], ["88608", "0", "0", "0"], ["88608.6", "0", "0", "0"], ["88608.9", "0", "0", "0"], ["88609", "0", "0", "0"], ["88609.2", "0", "0", "0"], ["88609.3", "0", "0", "0"], ["88609.4", "0", "0", "0"], ["88609.5", "0", "0", "0"], ["88609.7", "0", "0", "0"], ["88610", "0", "0", "0"]], "bids": [["88491.7", "0.08542988", "0", "2"], ["88490.3", "0", "0", "0"], ["88490.2", "0", "0", "0"], ["88489.4", "0.0001", "0", "1"], ["88489.3", "0.0001", "0", "1"], ["88488.4", "0", "0", "0"], ["88488", "0.01822851", "0", "2"], ["88486", "0.0171", "0", "1"], ["88485.6", "0", "0", "0"], ["88483.3", "0.06046552", "0", "3"], ["88483.2", "0.073566", "0", "1"], ["88483.1", "0.00734531", "0", "1"], ["88482.8", "0.2359563", "0", "1"], ["88481", "0", "0", "0"], ["88480.5", "0", "0", "0"], ["88480.3", "0", "0", "0"], ["88480", "0", "0", "0"], ["88479.9", "0.02778463", "0", "1"], ["88479.6", "0.1555847", "0", "2"], ["88479.4", "0.02705372", "0", "1"], ["88479.2", "0.38121974", "0", "3"], ["88478.4", "0", "0", "0"], ["88477.4", "0", "0", "0"], ["88477.2", "0", "0", "0"], ["88476.4", "0", "0", "0"], ["88476.1", "0.07857826", "0", "1"], ["88476", "0.00734477", "0", "1"], ["88475.3", "0.1090349", "0", "2"], ["88474.9", "0.08071764", "0", "1"], ["88474.8", "0", "0", "0"], ["88474.7", "0.08687225", "0", "1"], ["88473.5", "0", "0", "0"], ["88473.1", "0", "0", "0"], ["88472.5", "0.01853488", "0", "1"], ["88472", "0.13261577", "0", "1"], ["88471.6", "0.12404227", "0", "1"], ["88470.8", "0.14420687", "0", "2"], ["88470.2", "0", "0", "0"], ["88469.8", "0.14293863", "0", "1"], ["88469.2", "0.03", "0", "1"], ["88469.1", "0.13846841", "0", "1"], ["88467.9", "0.128138", "0", "1"], ["88466.4", "0", "0", "0"], ["88465.6", "0", "0", "0"], ["88464.8", "0.0006", "0", "2"], ["88464", "0.11833737", "0", "3"], ["88463.8", "0.04", "0", "1"], ["88461.4", "0.22601464", "0", "1"], ["88460.8", "0", "0", "0"], ["88460.2", "0.11304289", "0", "1"], ["88458.7", "0", "0", "0"], ["88458.6", "0", "0", "0"], ["88458.3", "0", "0", "0"], ["88457.6", "0.46040422", "0", "1"], ["88456.3", "0", "0", "0"], ["88454.7", "0", "0", "0"], ["88454", "0", "0", "0"], ["88453.4", "0.03472845", "0", "2"], ["88453", "0", "0", "0"], ["88452.2", "0.04520215", "0", "1"], ["88452", "0.06016958", "0", "3"], ["88451", "0.50341", "0", "3"], ["88450", "0.177132", "0", "3"], ["88447.1", "0", "0", "0"], ["88446.6", "0.01650401", "0", "1"], ["88443.2", "0.447358", "0", "1"], ["88443.1", "0", "0", "0"], ["88442.8", "0", "0", "0"], ["88441.4", "0.10683945", "0", "1"], ["88439.1", "0.3063582", "0", "2"], ["88439", "0.073566", "0", "1"], ["88438.4", "0.90244663", "0", "1"], ["88434.2", "0.02261521", "0", "1"], ["88428.5", "0", "0", "0"], ["88415.3", "0", "0", "0"], ["88402.8", "0.00565035", "0", "1"], ["88391.5", "0", "0", "0"], ["88391.4", "0.00007202", "0", "1"], ["88391.3", "0.0007203", "0", "1"], ["88243.4", "0.00001628", "0", "1"], ["88243.2", "0.00015126", "0", "1"], ["88243.1", "0.03", "0", "1"]], "ts": "1741338245305", "checksum": 951230993, "seqId": 48070606782, "prevSeqId": 48070606456}]}
{"arg": {"channel": "books", "instId": "BTC-USDT"}, "action": "update", "data": [{"asks": [["88491.9", "0.0511148", "0", "1"], ["88493.7", "0", "0", "0"], ["88494", "0.0173", "0", "3"], ["88495.7", "0.03293108", "0", "2"], ["88495.8", "0.02777877", "0", "1"], ["88496.8", "0.02748812", "0", "1"], ["88497.2", "0", "0", "0"], ["88497.3", "0.02588634", "0", "1"], ["88497.4", "0.0851305", "0", "2"], ["88498.3", "0", "0", "0"], ["88499", "0.01371001", "0", "2"], ["88499.1", "0.0186343", "0", "1"], ["88499.4", "0.08297324", "0", "1"], ["88499.9", "0.08064592", "0", "1"], ["88500.8", "0", "0", "0"], ["88500.9", "0", "0", "0"], ["88501.1", "0.07715665", "0", "1"], ["88501.4", "0", "0", "0"], ["88501.8", "0.07921145", "0", "1"], ["88501.9", "0.36337363", "0", "1"], ["88502.6", "0", "0", "0"], ["88503.5", "0.13389677", "0", "1"], ["88503.6", "0", "0", "0"], ["88503.7", "0", "0", "0"], ["88504.4", "0.12989911", "0", "1"], ["88505", "0", "0", "0"], ["88505.2", "0.08542891", "0", "1"], ["88505.8", "0.90244663", "0", "1"], ["88505.9", "0", "0", "0"], ["88506.1", "0.62981", "0", "5"], ["88506.7", "0.13563589", "0", "1"], ["88507.2", "0.01364", "0", "1"], ["88507.3", "1.20701138", "0", "3"], ["88507.6", "0", "0", "0"], ["88508.5", "0", "0", "0"], ["88510.1", "0", "0", "0"], ["88512", "0.01357284", "0", "1"], ["88512.4", "0", "0", "0"], ["88521.6", "0.22601712", "0", "1"], ["88535", "0.06", "0", "2"], ["88536", "0.03", "0", "1"], ["88537", "0.4842764", "0", "2"], ["88537.8", "0.21704", "0", "1"], ["88538", "0.11205327", "0", "4"], ["88550.4", "0.03234606", "0", "1"], ["88551", "0.00003451", "0", "2"], ["88551.2", "0.01740327", "0", "1"], ["88553.8", "0", "0", "0"], ["88556.4", "0", "0", "0"], ["88572", "0.13527146", "0", "2"], ["88573.2", "0.24276", "0", "1"], ["88595", "0.00005751", "0", "2"], ["88595.1", "0.05807858", "0", "2"], ["88602.4", "0.0001921", "0", "2"], ["88606.9", "0", "0", "0"], ["88607.8", "0", "0", "0"], ["88607.9", "0", "0", "0"]], "bids": [["88491.7", "0.01130077", "0", "1"], ["88489.4", "0", "0", "0"], ["88489.3", "0", "0", "0"], ["88488", "0.00112851", "0", "1"], ["88486.7", "0.0402", "0", "3"], ["88485", "0", "0", "0"], ["88482.8", "0", "0", "0"], ["88479.9", "0", "0", "0"], ["88479.6", "0.11035545", "0", "1"], ["88479.4", "0", "0", "0"], ["88479.2", "0.32764", "0", "1"], ["88479.1", "0.00936138", "0", "2"], ["88478.4", "0.02970732", "0", "1"], ["88477.9", "0.02849477", "0", "1"], ["88477.7", "0.02472467", "0", "1"], ["88477.3", "0.0277199", "0", "1"], ["88476.1", "0", "0", "0"], ["88475.3", "0.0194028", "0", "1"], ["88474.9", "0", "0", "0"], ["88474.7", "0.08443975", "0", "1"], ["88473.8", "0.08422816", "0", "1"], ["88473.4", "0.07551486", "0", "2"], ["88472.9", "0.10258345", "0", "2"], ["88472.7", "0.06452117", "0", "3"], ["88472", "0", "0", "0"], ["88471.6", "0", "0", "0"], ["88470.8", "0.22543159", "0", "1"], ["88470.5", "0.14268832", "0", "1"], ["88470.1", "0.13714322", "0", "1"], ["88469.8", "0", "0", "0"], ["88469.2", "0.09", "0", "3"], ["88469.1", "0", "0", "0"], ["88468", "0.1405317", "0", "2"], ["88467.9", "0", "0", "0"], ["88467.6", "0.14750997", "0", "1"], ["88467", "0.003855", "0", "1"], ["88465", "0.30374692", "0", "2"], ["88464.8", "0", "0", "0"], ["88464", "0.11863737", "0", "4"], ["88463.2", "0.00029937", "0", "1"], ["88461.4", "0", "0", "0"], ["88460.3", "0.22601712", "0", "1"], ["88457.4", "0", "0", "0"], ["88451", "0.44341", "0", "1"], ["88450", "0.207132", "0", "4"], ["88449.1", "0.20567", "0", "1"], ["88449", "0.03", "0", "1"], ["88446.6", "0", "0", "0"], ["88443.3", "0.25755536", "0", "2"], ["88441.4", "0", "0", "0"], ["88432.2", "0", "0", "0"], ["88426.7", "0.01740327", "0", "1"], ["88409.9", "0", "0", "0"], ["88387.5", "0.1", "0", "1"], ["88378.3", "2.89243248", "0", "2"], ["88328", "0", "0", "0"], ["88242.1", "0.00001638", "0", "1"], ["88242", "0.00059306", "0", "1"], ["88241.7", "0.00001364", "0", "1"], ["88241.6", "0.00001139", "0", "1"], ["88240.8", "0.00001008", "0", "1"]], "ts": "1741338245405", "checksum": 755774402, "seqId": 48070606969, "prevSeqId": 48070606782}]}
{"arg": {"channel": "books", "instId": "BTC-USDT"}, "action": "update", "data": [{"asks": [["88491.9", "0.04147815", "0", "2"], ["88493.7", "0.0001", "0", "1"], ["88494", "0.0172", "0", "2"], ["88495.7", "0.0000225", "0", "1"], ["88495.8", "0", "0", "0"], ["88495.9", "0.02817258", "0", "1"], ["88496", "0.02816042", "0", "1"], ["88496.8", "0", "0", "0"], ["88497", "0.02920422", "0", "2"], ["88497.3", "0", "0", "0"], ["88497.4", "0.09336454", "0", "2"], ["88497.6", "0.02704202", "0", "1"], ["88499", "0.012102", "0", "1"], ["88499.4", "0", "0", "0"], ["88499.6", "0.08669269", "0", "1"], ["88499.9", "0", "0", "0"], ["88500.1", "0.08573896", "0", "1"], ["88501.1", "0", "0", "0"], ["88501.3", "0.0790176", "0", "1"], ["88501.6", "0.00182357", "0", "1"], ["88501.8", "0.00209084", "0", "1"], ["88502", "0.0963525", "0", "2"], ["88503.5", "0", "0", "0"], ["88503.7", "0.14611246", "0", "1"], ["88504.4", "0", "0", "0"], ["88504.6", "0.12412681", "0", "1"], ["88505.2", "0", "0", "0"], ["88506.1", "0.49376132", "0", "4"], ["88506.3", "0.14005362", "0", "1"], ["88506.7", "0", "0", "0"], ["88506.9", "0.13071572", "0", "1"], ["88535", "0.12", "0", "4"], ["88538", "0.05205327", "0", "2"], ["88546", "1.23175241", "0", "6"], ["88549.2", "0.497687", "0", "1"], ["88550.4", "0", "0", "0"], ["88550.5", "0", "0", "0"], ["88606", "0", "0", "0"]], "bids": [["88491.7", "0.01350695", "0", "3"], ["88488.4", "0.0001", "0", "1"], ["88488", "0.01822851", "0", "2"], ["88487.8", "0.0001", "0", "1"], ["88486.7", "0.04", "0", "1"], ["88482.8", "0.20360253", "0", "1"], ["88478.6", "0.02711864", "0", "1"], ["88478.4", "0", "0", "0"], ["88478.1", "0.03580329", "0", "2"], ["88477.9", "0.02505664", "0", "1"], ["88477.7", "0", "0", "0"], ["88477.6", "0.02594272", "0", "2"], ["88477.3", "0", "0", "0"], ["88474.9", "0.08308434", "0", "1"], ["88474.7", "0", "0", "0"], ["88474", "0.07907793", "0", "1"], ["88473.8", "0", "0", "0"], ["88473.6", "0.08152192", "0", "1"], ["88473.4", "0.00001138", "0", "1"], ["88473.1", "0.08037208", "0", "1"], ["88472.9", "0.015", "0", "1"], ["88470.8", "0.13366331", "0", "1"], ["88470.7", "0.1410293", "0", "1"], ["88470.5", "0", "0", "0"], ["88470.3", "0.12555125", "0", "1"], ["88470.1", "0", "0", "0"], ["88469.3", "0.00335796", "0", "1"], ["88469.2", "0.12", "0", "4"], ["88468.2", "0.14649068", "0", "1"], ["88468", "0.00001", "0", "1"], ["88467.8", "0.14156935", "0", "2"], ["88467.6", "0", "0", "0"], ["88467.1", "0.128138", "0", "1"], ["88465", "0.207", "0", "1"], ["88456.7", "0", "0", "0"], ["88452.6", "0.67108861", "0", "2"], ["88452.4", "0.498231", "0", "1"], ["88452", "0.00016958", "0", "1"], ["88451", "0.50341", "0", "3"], ["88445", "0.13073953", "0", "3"], ["88439.1", "0.44473846", "0", "1"], ["88438", "0.498226", "0", "1"], ["88430.5", "0.02261615", "0", "1"], ["88415", "0.747149", "0", "1"], ["88414.8", "0.57550994", "0", "3"], ["88398.7", "0.747029", "0", "1"], ["88394.2", "0.00116162", "0", "2"], ["88243.5", "0", "0", "0"], ["88243.4", "0", "0", "0"], ["88243.2", "0", "0", "0"], ["88243.1", "0", "0", "0"], ["88242.1", "0", "0", "0"], ["88242", "0", "0", "0"], ["88241.7", "0", "0", "0"], ["88241.6", "0", "0", "0"], ["88240.8", "0", "0", "0"]], "ts": "1741338245505", "checksum": -1196656721, "seqId": 48070607175, "prevSeqId": 48070606969}]}
{"arg": {"channel": "books", "instId": "BTC-USDT"}, "action": "update", "data": [{"asks": [["88493.6", "0.002", "0", "1"], ["88493.7", "0", "0", "0"], ["88494", "0.0173", "0", "3"], ["88499.5", "0.00141757", "0", "1"], ["88500.1", "0", "0", "0"], ["88500.2", "0.0839056", "0", "1"], ["88501.6", "0", "0", "0"], ["88501.8", "0", "0", "0"], ["88503.7", "0", "0", "0"], ["88503.8", "0.47942384", "0", "2"], ["88506.3", "0", "0", "0"], ["88506.4", "0.14666253", "0", "1"], ["88506.9", "0", "0", "0"], ["88507", "0.13121773", "0", "1"], ["88534", "0.06", "0", "2"], ["88535", "0.09", "0", "3"], ["88536", "0", "0", "0"], ["88538.9", "0.00071317", "0", "1"], ["88539.2", "0.0006", "0", "2"], ["88540", "0.00533926", "0", "5"], ["88542.9", "0", "0", "0"], ["88544", "0.00084248", "0", "2"], ["88544.8", "0.00001536", "0", "1"], ["88550.3", "0.03756704", "0", "1"], ["88550.4", "0.1", "0", "1"], ["88583.4", "0", "0", "0"], ["88583.5", "0.00832769", "0", "2"], ["88583.7", "0", "0", "0"], ["88606", "0.00046406", "0", "3"]], "bids": [["88491.7", "0.01461004", "0", "4"], ["88488.4", "0", "0", "0"], ["88487.7", "0.0001", "0", "1"], ["88482.5", "0.002", "0", "1"], ["88478.2", "0.02631677", "0", "1"], ["88478.1", "0.00935", "0", "1"], ["88471.9", "0.002", "0", "1"], ["88470.8", "0.42524563", "0", "3"], ["88470.7", "0", "0", "0"], ["88467.9", "0.13342053", "0", "1"], ["88467.8", "0.00001138", "0", "1"], ["88452", "0.06016958", "0", "3"], ["88451", "0.44341", "0", "1"], ["88393.4", "0", "0", "0"], ["88378.2", "0", "0", "0"], ["88294", "0.0058", "0", "2"], ["88244.2", "0", "0", "0"]], "ts": "1741338245605", "checksum": 79429833, "seqId": 48070607251, "prevSeqId": 48070607175}]}
{"arg": {"channel": "books", "instId": "BTC-USDT"}, "action": "update", "data": [{"asks": [["88491.9", "0.04246729", "0", "2"], ["88495.9", "0", "0", "0"], ["88496", "0", "0", "0"], ["88496.4", "0.02867324", "0", "1"], ["88496.5", "0.02775786", "0", "1"], ["88497", "0.00224285", "0", "1"], ["88497.4", "0.08255828", "0", "2"], ["88497.5", "0.06822307", "0", "2"], ["88497.6", "0", "0", "0"], ["88498.1", "0.02831947", "0", "1"], ["88499.5", "0", "0", "0"], ["88499.6", "0", "0", "0"], ["88499.9", "0.00061642", "0", "1"], ["88500.1", "0.08080824", "0", "1"], ["88500.2", "0", "0", "0"], ["88500.6", "0.08210607", "0", "1"], ["88501.3", "0", "0", "0"], ["88501.8", "0.07474854", "0", "1"], ["88502", "0.0171", "0", "1"], ["88502.6", "0.0811124", "0", "1"], ["88503.8", "0.33929724", "0", "1"], ["88504.2", "0.1428544", "0", "1"], ["88504.3", "0.002", "0", "1"], ["88504.6", "0", "0", "0"], ["88505.1", "0.1374561", "0", "1"], ["88506.4", "0", "0", "0"], ["88506.8", "0.16813281", "0", "2"], ["88507", "0", "0", "0"], ["88507.5", "0.13641744", "0", "1"], ["88605.6", "0", "0", "0"], ["88606", "0", "0", "0"]], "bids": [["88488.3", "0.0001", "0", "1"], ["88488", "0.01832851", "0", "3"], ["88487.8", "0", "0", "0"], ["88487.7", "0", "0", "0"], ["88485.1", "0.11301104", "0", "1"], ["88479.6", "0.15586719", "0", "2"], ["88479", "0.03584008", "0", "2"], ["88478.6", "0.02673714", "0", "1"], ["88478.4", "0.02455772", "0", "1"], ["88478.2", "0", "0", "0"], ["88478.1", "0.0352974", "0", "2"], ["88477.9", "0", "0", "0"], ["88477.6", "0.000015", "0", "1"], ["88475.3", "0.09874526", "0", "2"], ["88474.9", "0", "0", "0"], ["88474.5", "0.08891664", "0", "1"], ["88474.1", "0.07853584", "0", "1"], ["88474", "0", "0", "0"], ["88473.7", "0.08752441", "0", "1"], ["88473.6", "0", "0", "0"], ["88473.1", "0", "0", "0"], ["88471.2", "0.13832972", "0", "1"], ["88470.8", "0.33674796", "0", "3"], ["88470.3", "0", "0", "0"], ["88468.7", "0.14695571", "0", "1"], ["88468.3", "0.13397586", "0", "1"], ["88468.2", "0", "0", "0"], ["88467.9", "0", "0", "0"], ["88445.1", "0.0165154", "0", "2"], ["88443.3", "0.24105135", "0", "1"], ["88442.4", "0.03680011", "0", "2"], ["88391.5", "0.00019396", "0", "1"], ["88244.2", "0.03", "0", "1"]], "ts": "1741338245705", "checksum": 1501643380, "seqId": 48070607354, "prevSeqId": 48070607251}]}
{"arg": {"channel": "books", "instId": "BTC-USDT"}, "action": "update", "data": [{"asks": [["88493.8", "0.0002", "0", "2"], ["88494", "0.0171", "0", "1"], ["88499.9", "0.00130491", "0", "1"], ["88600.7", "0.00311789", "0", "1"], ["88605.2", "0", "0", "0"], ["88605.3", "0", "0", "0"]], "bids": [["88491.6", "0.0000804", "0", "1"], ["88490.8", "0", "0", "0"], ["88489.2", "0.0001", "0", "1"], ["88489.1", "0.0001", "0", "1"], ["88488.3", "0", "0", "0"], ["88488", "0.01822851", "0", "2"], ["88487.2", "0", "0", "0"], ["88485.5", "0.00004575", "0", "1"], ["88481.9", "0.000027", "0", "1"], ["88445.8", "0.01650401", "0", "1"], ["88445.1", "0.00001139", "0", "1"], ["88403.4", "0.00311789", "0", "1"], ["88390.9", "0.00623578", "0", "1"], ["88372.6", "0.00935368", "0", "1"], ["88372.1", "0.06666822", "0", "1"], ["88247.3", "0", "0", "0"], ["88246.9", "0", "0", "0"], ["88246.8", "0", "0", "0"], ["88246.7", "0", "0", "0"], ["88246.4", "0", "0", "0"], ["88244.9", "0", "0", "0"], ["88244.2", "0", "0", "0"]], "ts": "1741338245805", "checksum": -1353936222, "seqId": 48070607394, "prevSeqId": 48070607354}]}
{"arg": {"channel": "books", "instId": "BTC-USDT"}, "action": "update", "data": [{"asks": [["88491.8", "0.43873163", "0", "9"], ["88493.8", "0", "0", "0"], ["88494", "0.0172", "0", "2"], ["88494.5", "0.0001", "0", "1"], ["88495.6", "0.01364", "0", "1"], ["88495.7", "0", "0", "0"], ["88496.4", "0", "0", "0"], ["88496.5", "0", "0", "0"], ["88497.1", "0.016", "0", "1"], ["88497.4", "0.06334649", "0", "2"], ["88497.5", "0", "0", "0"], ["88498.1", "0", "0", "0"], ["88498.4", "0.016", "0", "1"], ["88499", "0", "0", "0"], ["88499.3", "0.02774789", "0", "1"], ["88499.4", "0.02638105", "0", "1"], ["88499.9", "0.012102", "0", "1"], ["88500.1", "0", "0", "0"], ["88500.4", "0.02636125", "0", "1"], ["88500.6", "0", "0", "0"], ["88500.8", "0.02892838", "0", "1"], ["88501.8", "0", "0", "0"], ["88502.2", "0.04094", "0", "1"], ["88502.6", "0", "0", "0"], ["88503", "0.08970769", "0", "1"], ["88503.5", "0.08630335", "0", "1"], ["88504.2", "0", "0", "0"], ["88504.7", "0.07645306", "0", "1"], ["88505.1", "0", "0", "0"], ["88505.3", "0.08647301", "0", "1"], ["88506.1", "0.32308859", "0", "4"], ["88506.8", "0.01888533", "0", "1"], ["88507.1", "0.25927414", "0", "2"], ["88507.3", "0.20701138", "0", "2"], ["88507.5", "0", "0", "0"], ["88508", "0.15117896", "0", "2"], ["88509.7", "0.14139598", "0", "1"], ["88510.2", "0.13061038", "0", "1"], ["88511.6", "0.67049489", "0", "2"], ["88513.8", "1", "0", "1"], ["88532.5", "0.05713349", "0", "1"], ["88535", "0.25302365", "0", "4"], ["88538.9", "0", "0", "0"]], "bids": [["88491.7", "0.20278345", "0", "8"], ["88490.7", "0.0001", "0", "1"], ["88490.4", "0.0001", "0", "1"], ["88490.3", "0.11300446", "0", "1"], ["88490", "0.0171", "0", "1"], ["88489.2", "0", "0", "0"], ["88489.1", "0", "0", "0"], ["88485.1", "0", "0", "0"], ["88482", "0.02812908", "0", "1"], ["88481.5", "0.02811027", "0", "1"], ["88481.3", "0.02470947", "0", "1"], ["88480.8", "0.02643743", "0", "1"], ["88480.7", "0.00935", "0", "1"], ["88479.6", "0.17255173", "0", "2"], ["88479", "0.0062197", "0", "1"], ["88478.6", "0", "0", "0"], ["88478.4", "0", "0", "0"], ["88478.3", "0.08552459", "0", "1"], ["88478.1", "0", "0", "0"], ["88477.4", "0.07998347", "0", "1"], ["88477", "0.07961385", "0", "1"], ["88476.4", "0.08603178", "0", "1"], ["88475.3", "0.0194028", "0", "1"], ["88474.5", "0", "0", "0"], ["88474.1", "0.13686224", "0", "1"], ["88473.9", "0.207", "0", "1"], ["88473.7", "0.12744487", "0", "1"], ["88471.5", "0.17611271", "0", "2"], ["88471.2", "0.15056347", "0", "1"], ["88470.8", "0.13366331", "0", "1"], ["88468.7", "0", "0", "0"], ["88468.3", "0", "0", "0"], ["88467", "0", "0", "0"], ["88450.1", "0.01650401", "0", "1"], ["88445.8", "0", "0", "0"], ["88391.5", "0", "0", "0"], ["88375.5", "0.06666822", "0", "1"], ["88372.1", "0", "0", "0"], ["88249.9", "0", "0", "0"], ["88248.9", "0", "0", "0"], ["88247.9", "0", "0", "0"]], "ts": "1741338245905", "checksum": -1030978679, "seqId": 48070607533, "prevSeqId": 48070607394}]}
{"arg": {"channel": "books", "instId": "BTC-USDT"}, "action": "update", "data": [{"asks": [["88491.8", "0.41933163", "0", "8"], ["88491.9", "0.02849282", "0", "1"], ["88493.9", "0.0001", "0", "1"], ["88494.5", "0", "0", "0"], ["88497.4", "0.05171247", "0", "2"], ["88499.3", "0.02707024", "0", "1"], ["88500.3", "0.02437523", "0", "1"], ["88500.4", "0", "0", "0"], ["88501.8", "0.33929724", "0", "1"], ["88502.7", "0.003855", "0", "1"], ["88503.8", "0", "0", "0"], ["88505.8", "0", "0", "0"], ["88507.9", "0.13519524", "0", "1"], ["88508", "0.0171", "0", "1"], ["88512.1", "1", "0", "1"], ["88513.8", "0", "0", "0"], ["88521.6", "0", "0", "0"], ["88525.3", "0.22600925", "0", "1"], ["88535", "0.25302273", "0", "4"], ["88604.3", "0", "0", "0"]], "bids": [["88491.7", "0.22426858", "0", "10"], ["88490.8", "0.0001", "0", "1"], ["88490.4", "0", "0", "0"], ["88482.9", "0.33929724", "0", "1"], ["88482", "0.00002625", "0", "1"], ["88481.9", "0.02787255", "0", "1"], ["88478.3", "0", "0", "0"], ["88478.2", "0.08497245", "0", "1"], ["88477", "0", "0", "0"], ["88476.9", "0.07572944", "0", "1"], ["88475.1", "0.65035562", "0", "2"], ["88467.2", "0.22600717", "0", "1"], ["88460.3", "0", "0", "0"], ["88450.9", "0.01650401", "0", "1"], ["88450.1", "0", "0", "0"], ["88391.5", "0.00019394", "0", "1"], ["88250.7", "0", "0", "0"], ["88250", "0", "0", "0"]], "ts": "1741338246005", "checksum": -1335633644, "seqId": 48070607600, "prevSeqId": 48070607533}]}
{"arg": {"channel": "books", "instId": "BTC-USDT"}, "action": "update", "data": [{"asks": [["88491.8", "0.43873163", "0", "9"], ["88493.9", "0", "0", "0"], ["88494", "0.0171", "0", "1"], ["88496.2", "0.0002", "0", "2"], ["88500.3", "0.02604399", "0", "1"], ["88501.7", "0.23511828", "0", "2"], ["88501.9", "0", "0", "0"], ["88507.9", "0.12890556", "0", "1"], ["88523.2", "0.22602353", "0", "2"], ["88525.3", "0", "0", "0"], ["88529.9", "0.00071319", "0", "1"], ["88532.5", "0", "0", "0"], ["88534", "0", "0", "0"], ["88535", "0.12", "0", "4"], ["88536", "0.03", "0", "1"], ["88551.2", "0", "0", "0"], ["88554.3", "0.01740221", "0", "1"], ["88604.3", "0.00001362", "0", "1"], ["88605.2", "0.0000166", "0", "1"]], "bids": [["88491.7", "0.20486858", "0", "9"], ["88490.8", "0.0002", "0", "2"], ["88490.7", "0", "0", "0"], ["88483", "0.23079278", "0", "1"], ["88482.9", "0", "0", "0"], ["88482.8", "0", "0", "0"], ["88482", "0", "0", "0"], ["88481.9", "0.0266988", "0", "2"], ["88478.2", "0.0823616", "0", "1"], ["88476.9", "0.07334273", "0", "1"], ["88467.2", "0", "0", "0"], ["88466.2", "0.22600882", "0", "1"], ["88452", "0.00016958", "0", "1"], ["88451.1", "0.01650401", "0", "1"], ["88451", "0.50341", "0", "3"], ["88450.9", "0", "0", "0"], ["88430.6", "0.01740221", "0", "1"], ["88428.6", "0", "0", "0"], ["88428.5", "0.00102751", "0", "1"], ["88426.7", "0", "0", "0"], ["88372.8", "0", "0", "0"], ["88368.3", "0.00212783", "0", "1"], ["88250.7", "0.11343045", "0", "1"], ["88250", "0.11322175", "0", "21"], ["88249.9", "0.00060139", "0", "2"]], "ts": "1741338246105", "checksum": 1232296556, "seqId": 48070607716, "prevSeqId": 48070607600}]}
{"arg": {"channel": "books", "instId": "BTC-USDT"}, "action": "update", "data": [{"asks": [["88491.8", "0.44556163", "0", "10"], ["88494.5", "0.0001", "0", "1"], ["88496.1", "0.0001", "0", "1"], ["88496.2", "0", "0", "0"], ["88497.4", "0", "0", "0"], ["88497.9", "0.05327705", "0", "1"], ["88499.3", "0", "0", "0"], ["88499.4", "0", "0", "0"], ["88500.2", "0.02514928", "0", "1"], ["88500.3", "0", "0", "0"], ["88500.8", "0", "0", "0"], ["88501.7", "0.21673377", "0", "3"], ["88503", "0", "0", "0"], ["88503.5", "0", "0", "0"], ["88504.7", "0", "0", "0"], ["88505.3", "0", "0", "0"], ["88506.1", "0.32001557", "0", "4"], ["88507.1", "0.11298309", "0", "1"], ["88507.8", "0.12495449", "0", "1"], ["88507.9", "0", "0", "0"], ["88509.7", "0", "0", "0"], ["88510.2", "0", "0", "0"], ["88523.2", "0.22602537", "0", "2"], ["88605.3", "0.00569815", "0", "1"], ["88605.6", "0.30754406", "0", "1"], ["88606", "0.00046406", "0", "3"], ["88606.9", "0.00052479", "0", "1"], ["88607.8", "0.00001009", "0", "1"], ["88607.9", "0.00571153", "0", "2"], ["88608", "0.0305953", "0", "2"], ["88608.6", "0.32547393", "0", "2"]], "bids": [["88491.7", "0.20695371", "0", "10"], ["88490.8", "0", "0", "0"], ["88490.5", "0.0001", "0", "1"], ["88490.3", "0", "0", "0"], ["88490.1", "0.0001", "0", "1"], ["88488", "0.1312359", "0", "3"], ["88481.9", "0.000027", "0", "1"], ["88481.8", "0.02764209", "0", "1"], ["88481.5", "0", "0", "0"], ["88481.3", "0", "0", "0"], ["88480.8", "0", "0", "0"], ["88479.6", "0.19495602", "0", "2"], ["88478.2", "0", "0", "0"], ["88477.4", "0", "0", "0"], ["88476.9", "0", "0", "0"], ["88476.4", "0", "0", "0"], ["88475.1", "0.64644062", "0", "1"], ["88474.1", "0", "0", "0"], ["88473.7", "0", "0", "0"], ["88471.9", "0.005855", "0", "2"], ["88471.5", "0.02807", "0", "1"], ["88471.2", "0", "0", "0"], ["88466.2", "0", "0", "0"], ["88463.2", "0.0002989", "0", "1"], ["88462", "0.22601037", "0", "1"], ["88451.9", "0.01650401", "0", "1"], ["88451.1", "0", "0", "0"], ["88248.9", "0.03", "0", "1"], ["88247.9", "0.0001", "0", "1"], ["88247.3", "0.00001139", "0", "1"], ["88246.9", "0.03", "0", "1"], ["88246.8", "0.00560182", "0", "1"], ["88246.7", "0.00840315", "0", "1"], ["88246.4", "0.34056098", "0", "1"], ["88244.9", "0.00001267", "0", "1"], ["88244.2", "0.03", "0", "1"]], "ts": "1741338246205", "checksum": -508941679, "seqId": 48070607874, "prevSeqId": 48070607716}]}
{"arg": {"channel": "books", "instId": "BTC-USDT"}, "action": "update", "data": [{"asks": [["88491.8", "0.44217134", "0", "9"], ["88494.5", "0", "0", "0"], ["88496.1", "0", "0", "0"], ["88496.2", "0.0001", "0", "1"], ["88496.3", "0.0001", "0", "1"], ["88497.9", "0.05403107", "0", "2"], ["88498.9", "0.0296067", "0", "1"], ["88499", "0.02962245", "0", "1"], ["88500", "0.04445951", "0", "2"], ["88500.2", "0", "0", "0"], ["88500.7", "0.02583929", "0", "1"], ["88501.7", "0.216864", "0", "3"], ["88502.6", "0.08980669", "0", "1"], ["88503.1", "0.08748611", "0", "1"], ["88504.3", "0.07616249", "0", "2"], ["88505.1", "0.08222828", "0", "1"], ["88506.1", "0.24414638", "0", "4"], ["88506.7", "0.14200499", "0", "1"], ["88507.6", "0.12770937", "0", "1"], ["88507.8", "0", "0", "0"], ["88509.3", "0.14893567", "0", "1"], ["88510.1", "0.14055023", "0", "1"], ["88510.6", "1", "0", "1"], ["88512.1", "0", "0", "0"], ["88518.5", "0.00339025", "0", "1"], ["88521.6", "0.22601518", "0", "1"], ["88523.2", "0.000015", "0", "1"], ["88553.9", "0.01741262", "0", "2"], ["88554.3", "0", "0", "0"], ["88571.6", "0.07360581", "0", "2"], ["88605.2", "0", "0", "0"], ["88605.3", "0", "0", "0"], ["88605.6", "0", "0", "0"], ["88606", "0", "0", "0"], ["88606.9", "0", "0", "0"], ["88607.8", "0", "0", "0"], ["88607.9", "0", "0", "0"], ["88608", "0", "0", "0"], ["88608.6", "0", "0", "0"]], "bids": [["88491.7", "0.17473885", "0", "10"], ["88490.7", "0.0001", "0", "1"], ["88490.1", "0", "0", "0"], ["88483.4", "0.05617985", "0", "1"], ["88483.2", "0", "0", "0"], ["88483", "0", "0", "0"], ["88482.7", "0", "0", "0"], ["88481.8", "0", "0", "0"], ["88481.6", "0.02644524", "0", "1"], ["88481.1", "0.02798242", "0", "1"], ["88480.9", "0.02635823", "0", "1"], ["88480.7", "0.03607736", "0", "2"], ["88479.6", "0.11035545", "0", "1"], ["88479.2", "0", "0", "0"], ["88477.9", "0.08914435", "0", "1"], ["88477", "0.0792693", "0", "1"], ["88476.6", "0.07705202", "0", "1"], ["88476.2", "0.0813761", "0", "1"], ["88473.7", "0.13863545", "0", "1"], ["88473.3", "0.3212366", "0", "2"], ["88471.3", "0.13673228", "0", "1"], ["88470.8", "0.28054652", "0", "2"], ["88462", "0", "0", "0"], ["88460.3", "0.22601518", "0", "1"], ["88452.5", "0.01650401", "0", "1"], ["88452", "0.06016958", "0", "3"], ["88451.9", "0", "0", "0"], ["88451", "0.44341", "0", "1"], ["88450.6", "0", "0", "0"], ["88430.6", "0", "0", "0"], ["88428.6", "0.01740248", "0", "1"], ["88414.8", "0.64092256", "0", "2"], ["88246.4", "0", "0", "0"], ["88244.9", "0", "0", "0"], ["88244.2", "0", "0", "0"]], "ts": "1741338246305", "checksum": 1170878726, "seqId": 48070608064, "prevSeqId": 48070607874}]}
{"arg": {"channel": "books", "instId": "BTC-USDT"}, "action": "update", "data": [{"asks": [["88493.9", "0.0001", "0", "1"], ["88494", "0.0172", "0", "2"], ["88496.2", "0", "0", "0"], ["88496.3", "0", "0", "0"], ["88497.9", "0.04524249", "0", "2"], ["88498.9", "0", "0", "0"], ["88499", "0", "0", "0"], ["88499.3", "0.02906277", "0", "1"], ["88499.4", "0.02770889", "0", "1"], ["88500", "0.0171", "0", "1"], ["88500.3", "0.02790396", "0", "1"], ["88500.7", "0", "0", "0"], ["88500.8", "0.02899747", "0", "1"], ["88501.7", "0.18754994", "0", "3"], ["88502.6", "0", "0", "0"], ["88502.7", "0", "0", "0"], ["88503", "0.08286915", "0", "1"], ["88503.1", "0", "0", "0"], ["88503.5", "0.08175492", "0", "1"], ["88504.3", "0.002", "0", "1"], ["88504.7", "0.07828789", "0", "1"], ["88505.1", "0", "0", "0"], ["88505.3", "0.078668", "0", "1"], ["88506.1", "0.27736424", "0", "4"], ["88506.7", "0", "0", "0"], ["88507.1", "0.24435975", "0", "2"], ["88507.6", "0", "0", "0"], ["88507.9", "0.12280425", "0", "1"], ["88509.3", "0", "0", "0"], ["88509.7", "0.14048931", "0", "1"], ["88510.1", "0", "0", "0"], ["88510.2", "0.14748596", "0", "1"], ["88510.5", "0.72931377", "0", "1"], ["88511.6", "0", "0", "0"], ["88527.4", "0.073566", "0", "1"]], "bids": [["88491.7", "0.20903885", "0", "11"], ["88490.7", "0", "0", "0"], ["88490.5", "0", "0", "0"], ["88490.3", "0.11310439", "0", "2"], ["88490.1", "0.0001", "0", "1"], ["88488", "0.01822851", "0", "2"], ["88483.4", "0.04645359", "0", "2"], ["88482", "0.00002625", "0", "1"], ["88481.9", "0.02847392", "0", "1"], ["88481.6", "0", "0", "0"], ["88481.5", "0.02965905", "0", "1"], ["88481.3", "0.02594964", "0", "1"], ["88481.1", "0", "0", "0"], ["88480.9", "0.33906", "0", "1"], ["88480.8", "0.02902184", "0", "1"], ["88480.7", "0.00935", "0", "1"], ["88479.6", "0.12718541", "0", "2"], ["88478.2", "0.08446314", "0", "1"], ["88477.9", "0", "0", "0"], ["88477.4", "0.07912607", "0", "1"], ["88477", "0.07458599", "0", "1"], ["88476.6", "0", "0", "0"], ["88476.4", "0.07771455", "0", "1"], ["88476.2", "0", "0", "0"], ["88476.1", "0.05989404", "0", "2"], ["88474.1", "0.14287753", "0", "1"], ["88473.7", "0.1320879", "0", "1"], ["88473.3", "0.18391502", "0", "1"], ["88471.5", "0.15982127", "0", "2"], ["88471.3", "0", "0", "0"], ["88471.2", "0.14851463", "0", "1"], ["88470.8", "0.13366331", "0", "1"], ["88462", "0.22601214", "0", "1"], ["88460.3", "0", "0", "0"], ["88452.7", "0.01650401", "0", "1"], ["88452.5", "0", "0", "0"], ["88439", "0.147132", "0", "2"], ["88414.8", "0.77082888", "0", "3"], ["88247.3", "0", "0", "0"], ["88246.9", "0", "0", "0"], ["88246.8", "0", "0", "0"], ["88246.7", "0", "0", "0"]], "ts": "1741338246405", "checksum": -1144697554, "seqId": 48070608210, "prevSeqId": 48070608064}]}
{"arg": {"channel": "books", "instId": "BTC-USDT"}, "action": "update", "data": [{"asks": [["88493.9", "0", "0", "0"], ["88494.3", "0.0001", "0", "1"], ["88497.9", "0.03182567", "0", "1"], ["88498.8", "0.0024495", "0", "1"], ["88498.9", "0.02654825", "0", "1"], ["88499", "0.02955023", "0", "1"], ["88499.3", "0", "0", "0"], ["88499.4", "0", "0", "0"], ["88500", "0.04405429", "0", "2"], ["88500.3", "0", "0", "0"], ["88500.7", "0.02846785", "0", "1"], ["88500.8", "0", "0", "0"], ["88501.7", "0.19129912", "0", "3"], ["88502.6", "0.08972957", "0", "1"], ["88503", "0", "0", "0"], ["88503.1", "0.08317932", "0", "1"], ["88503.5", "0", "0", "0"], ["88504.3", "0.08191689", "0", "2"], ["88504.7", "0", "0", "0"], ["88505.1", "0.08267584", "0", "1"], ["88505.3", "0", "0", "0"], ["88506.1", "0.23997953", "0", "4"], ["88506.7", "0.13522295", "0", "1"], ["88507.1", "0.11298309", "0", "1"], ["88507.6", "0.13606754", "0", "1"], ["88507.9", "0", "0", "0"], ["88509.3", "0.14416946", "0", "1"], ["88509.7", "0", "0", "0"], ["88510.1", "0.14182821", "0", "1"], ["88510.2", "0", "0", "0"]], "bids": [["88491.7", "0.17473885", "0", "10"], ["88490.7", "0.0001", "0", "1"], ["88490.6", "0.0001", "0", "1"], ["88490.3", "0", "0", "0"], ["88490.1", "0", "0", "0"], ["88487.8", "0.11300766", "0", "1"], ["88483.4", "0.24214312", "0", "2"], ["88482", "0", "0", "0"], ["88481.9", "0.000027", "0", "1"], ["88481.6", "0.02696183", "0", "1"], ["88481.5", "0", "0", "0"], ["88481.3", "0", "0", "0"], ["88481.1", "0.02840193", "0", "1"], ["88481", "0.33929724", "0", "1"], ["88480.9", "0.36610695", "0", "2"], ["88480.8", "0", "0", "0"], ["88480.7", "0.03541848", "0", "2"], ["88479.6", "0.1144211", "0", "1"], ["88479.1", "0.34842138", "0", "3"], ["88478.2", "0", "0", "0"], ["88477.8", "0.08771805", "0", "1"], ["88477.4", "0", "0", "0"], ["88477", "0.08028687", "0", "1"], ["88476.6", "0.08064536", "0", "1"], ["88476.4", "0", "0", "0"], ["88476.2", "0.08246624", "0", "1"], ["88476.1", "0", "0", "0"], ["88474.1", "0", "0", "0"], ["88473.7", "0.1319236", "0", "1"], ["88473.3", "0.32003656", "0", "2"], ["88471.5", "0.02807", "0", "1"], ["88471.3", "0.13197059", "0", "1"], ["88471.2", "0", "0", "0"], ["88470.8", "0.27524038", "0", "2"], ["88453.5", "0.01650401", "0", "1"], ["88452.7", "0", "0", "0"], ["88247.3", "0.00001139", "0", "1"], ["88246.9", "0.03", "0", "1"]], "ts": "1741338246505", "checksum": 1463428128, "seqId": 48070608305, "prevSeqId": 48070608210}]}
{"arg": {"channel": "books", "instId": "BTC-USDT"}, "action": "update", "data": [{"asks": [["88497.9", "0.05449372", "0", "2"], ["88498.8", "0", "0", "0"], ["88506.1", "0.31553283", "0", "3"], ["88521.6", "0", "0", "0"], ["88523.2", "0.22602491", "0", "2"], ["88540", "0.16829722", "0", "6"], ["88590", "0.00001453", "0", "1"], ["88605.2", "0.0000166", "0", "1"], ["88605.3", "0.00569815", "0", "1"]], "bids": [["88490.7", "0", "0", "0"], ["88490.6", "0.0002", "0", "2"], ["88479.6", "0.29054537", "0", "1"], ["88477.3", "0.33907", "0", "1"], ["88453.9", "0.01650401", "0", "1"], ["88453.5", "0", "0", "0"]], "ts": "1741338246605", "checksum": 454638849, "seqId": 48070608339, "prevSeqId": 48070608305}]}
{"arg": {"channel": "books", "instId": "BTC-USDT"}, "action": "update", "data": [{"asks": [["88493.9", "0.0002", "0", "2"], ["88494", "0.0171", "0", "1"], ["88494.3", "0", "0", "0"], ["88498.3", "0.003855", "0", "1"], ["88605.3", "0", "0", "0"]], "bids": [["88452", "0.00016958", "0", "1"], ["88451", "0.50341", "0", "3"]], "ts": "1741338246705", "checksum": 948633515, "seqId": 48070608351, "prevSeqId": 48070608339}]}
{"arg": {"channel": "books", "instId": "BTC-USDT"}, "action": "update", "data": [{"asks": [["88493.9", "0", "0", "0"], ["88494", "0.0173", "0", "3"], ["88497.9", "0.0445003", "0", "2"], ["88498.3", "0", "0", "0"], ["88498.9", "0", "0", "0"], ["88499", "0", "0", "0"], ["88499.2", "0.02763118", "0", "1"], ["88499.4", "0.02965038", "0", "1"], ["88500", "0.0171", "0", "1"], ["88500.3", "0.02517389", "0", "1"], ["88500.7", "0", "0", "0"], ["88500.8", "0.02718119", "0", "1"], ["88501.7", "0.18970678", "0", "3"], ["88502.6", "0", "0", "0"], ["88503", "0.08046142", "0", "1"], ["88503.1", "0", "0", "0"], ["88503.5", "0.08607238", "0", "1"], ["88504.3", "0.002", "0", "1"], ["88504.6", "0.08313953", "0", "1"], ["88505.1", "0", "0", "0"], ["88505.3", "0.08635941", "0", "1"], ["88506.1", "0.24264576", "0", "4"], ["88506.7", "0", "0", "0"], ["88507.1", "0.25311481", "0", "2"], ["88507.6", "0", "0", "0"], ["88507.9", "0.12458366", "0", "1"], ["88509.3", "0", "0", "0"], ["88509.7", "0.13826206", "0", "1"], ["88510.1", "0", "0", "0"], ["88510.2", "0.14101131", "0", "1"], ["88525.8", "0.00427177", "0", "1"], ["88554.5", "0.03463433", "0", "1"], ["88559.5", "0.98062749", "0", "4"], ["88605.2", "0", "0", "0"]], "bids": [["88491.7", "0.20903885", "0", "11"], ["88490.8", "0.0001", "0", "1"], ["88490.7", "0.0001", "0", "1"], ["88490.6", "0", "0", "0"], ["88490", "0.1301048", "0", "2"], ["88487.8", "0", "0", "0"], ["88482", "0.00002625", "0", "1"], ["88481.9", "0.02940412", "0", "1"], ["88481.6", "0", "0", "0"], ["88481.5", "0.02905617", "0", "1"], ["88481.3", "0.02481873", "0", "1"], ["88481.1", "0", "0", "0"], ["88480.9", "0.33906", "0", "1"], ["88480.8", "0.02756876", "0", "1"], ["88480.7", "0.00935", "0", "1"], ["88479.6", "0.2161421", "0", "1"], ["88478.2", "0.08013537", "0", "1"], ["88477.8", "0", "0", "0"], ["88477.4", "0.08982985", "0", "1"], ["88477", "0", "0", "0"], ["88476.9", "0.08046961", "0", "1"], ["88476.6", "0", "0", "0"], ["88476.4", "0.08904277", "0", "1"], ["88476.2", "0", "0", "0"], ["88474.1", "0.14921611", "0", "1"], ["88473.7", "0.1363544", "0", "1"], ["88473.3", "0.18391502", "0", "1"], ["88471.5", "0.15996641", "0", "2"], ["88471.3", "0", "0", "0"], ["88471.2", "0.13959347", "0", "1"], ["88470.8", "0.13366331", "0", "1"], ["88465", "0.30380344", "0", "2"], ["88462", "0.22600858", "0", "1"], ["88459", "1", "0", "1"], ["88436.5", "0.33923", "0", "1"], ["88249.9", "0", "0", "0"], ["88248.9", "0", "0", "0"], ["88247.9", "0", "0", "0"], ["88247.3", "0", "0", "0"], ["88246.9", "0", "0", "0"]], "ts": "1741338246805", "checksum": 285378153, "seqId": 48070608481, "prevSeqId": 48070608351}]}
