{"arg": {"channel": "books", "instId": "BTC-USDT"}, "action": "update", "data": [{"asks": [["84110.1", "3.07679749", "0", "25"], ["84154.4", "0.002497", "0", "1"], ["84266.6", "0", "0", "0"]], "bids": [["84105.1", "0.07328791", "0", "3"]], "ts": "1742584897306", "checksum": 406887757, "seqId": 49948782415, "prevSeqId": 49948782410}], "record_time": 1742584897.390677, "EXCHANGE": "OKX"}
{"arg": {"channel": "books", "instId": "BTC-USDT"}, "action": "update", "data": [{"asks": [["84143.6", "0.2378923", "0", "1"], ["84146.9", "0", "0", "0"], ["84182.9", "0.07127345", "0", "1"]], "bids": [["84104.1", "0.09441592", "0", "2"], ["84101.5", "0.2025", "0", "1"], ["84090.1", "0", "0", "0"], ["84088.4", "0.23789228", "0", "1"], ["84017.8", "0.07141336", "0", "1"], ["83947.2", "0", "0", "0"]], "ts": "1742584897406", "checksum": -1123558405, "seqId": 49948782448, "prevSeqId": 49948782415}], "record_time": 1742584897.492184, "EXCHANGE": "OKX"}
{"arg": {"channel": "books", "instId": "BTC-USDT"}, "action": "update", "data": [{"asks": [["84123.1", "0.27244217", "0", "1"], ["84124.9", "0", "0", "0"], ["84151.6", "0.60774614", "0", "2"], ["84154.7", "0.1", "0", "1"], ["84182.9", "0", "0", "0"], ["84266.6", "0.0121482", "0", "12"], ["84266.9", "0.0000201", "0", "1"]], "bids": [["84071", "0.2302277", "0", "1"], ["84070.7", "0", "0", "0"], ["84068.2", "0", "0", "0"], ["84039.8", "0.03034222", "0", "1"], ["84038.4", "0", "0", "0"], ["84017.8", "0", "0", "0"], ["83947.2", "0.00030759", "0", "1"], ["83946.7", "0.00002763", "0", "2"], ["83946.4", "0.17898725", "0", "1"]], "ts": "1742584897506", "checksum": -1123558405, "seqId": 49948782467, "prevSeqId": 49948782448}], "record_time": 1742584897.591192, "EXCHANGE": "OKX"}
{"arg": {"channel": "books", "instId": "BTC-USDT"}, "action": "update", "data": [{"asks": [["84130.7", "0.57687872", "0", "1"], ["84130.8", "1.54690898", "0", "1"], ["84131", "0", "0", "0"], ["84143.6", "0.23789221", "0", "1"], ["84159.8", "1.09174005", "0", "3"], ["84160.6", "2.86291834", "0", "1"], ["84266.6", "0", "0", "0"], ["84266.9", "0", "0", "0"]], "bids": [["84078.7", "0.2666657", "0", "2"], ["84075.7", "0.11890769", "0", "1"], ["84075.6", "1.23663473", "0", "2"], ["84075.2", "1.62577187", "0", "2"], ["84045.5", "1.19241257", "0", "1"], ["84045.4", "2.87541705", "0", "1"], ["84044.3", "0", "0", "0"], ["84025.9", "0.01774536", "0", "1"], ["83946.7", "0", "0", "0"], ["83946.4", "0", "0", "0"]], "ts": "1742584897606", "checksum": -1123558405, "seqId": 49948782487, "prevSeqId": 49948782467}], "record_time": 1742584897.691321, "EXCHANGE": "OKX"}
{"arg": {"channel": "books", "instId": "BTC-USDT"}, "action": "update", "data": [{"asks": [["84143.6", "0", "0", "0"], ["84146.9", "0.23789017", "0", "1"], ["84182.9", "0.1425469", "0", "2"], ["84265.8", "0", "0", "0"]], "bids": [["84090.4", "0.23789017", "0", "1"], ["84088.4", "0", "0", "0"], ["84017.8", "0.14282672", "0", "2"], ["83991.3", "0", "0", "0"], ["83977", "0.5823469", "0", "2"], ["83965.8", "0.0008349", "0", "1"], ["83947.2", "0", "0", "0"]], "ts": "1742584897706", "checksum": -1123558405, "seqId": 49948782516, "prevSeqId": 49948782487}], "record_time": 1742584897.791588, "EXCHANGE": "OKX"}
{"arg": {"channel": "books", "instId": "BTC-USDT"}, "action": "update", "data": [{"asks": [["84143.1", "0.23789302", "0", "1"], ["84146.9", "0", "0", "0"]], "bids": [["84090.4", "0", "0", "0"], ["84088.4", "0.23789302", "0", "1"], ["83978.7", "0.183208", "0", "1"], ["83947.3", "0", "0", "0"]], "ts": "1742584897806", "checksum": -1123558405, "seqId": 49948782532, "prevSeqId": 49948782516}], "record_time": 1742584897.891186, "EXCHANGE": "OKX"}
{"arg": {"channel": "books", "instId": "BTC-USDT"}, "action": "update", "data": [{"asks": [["84110.1", "3.09620284", "0", "27"]], "bids": [["84104.1", "0.03847534", "0", "1"], ["84101.5", "0", "0", "0"], ["84078.7", "0.09772495", "0", "1"], ["84075.8", "0.01774536", "0", "1"], ["84025.9", "0", "0", "0"], ["83988.2", "0.11256246", "0", "1"]], "ts": "1742584897906", "checksum": -156785647, "seqId": 49948782543, "prevSeqId": 49948782532}], "record_time": 1742584897.991449, "EXCHANGE": "OKX"}
{"arg": {"channel": "books", "instId": "BTC-USDT"}, "action": "update", "data": [{"asks": [["84143.1", "0", "0", "0"], ["84143.4", "0.23789265", "0", "1"]], "bids": [["84104.1", "0.09441592", "0", "2"], ["84101.5", "0.2025", "0", "1"], ["83948.1", "0", "0", "0"]], "ts": "1742584898006", "checksum": 101717467, "seqId": 49948782548, "prevSeqId": 49948782543}], "record_time": 1742584898.091227, "EXCHANGE": "OKX"}
{"arg": {"channel": "books", "instId": "BTC-USDT"}, "action": "update", "data": [{"asks": [["84123", "0.2", "0", "2"], ["84125.4", "0", "0", "0"], ["84126", "0.21819367", "0", "1"], ["84127", "0", "0", "0"], ["84143.1", "0.2378931", "0", "1"], ["84143.4", "0", "0", "0"], ["84173.6", "0.04113685", "0", "2"], ["84174.5", "0", "0", "0"], ["84182.9", "0.07127345", "0", "1"], ["84265.8", "0.03", "0", "1"], ["84266.6", "0.0121482", "0", "12"], ["84266.9", "0.0000201", "0", "1"]], "bids": [["84108.1", "0", "0", "0"], ["84106.1", "0.05450639", "0", "1"], ["84104.1", "0.03847534", "0", "1"], ["84101.5", "0", "0", "0"], ["84097.6", "0", "0", "0"], ["84076.8", "0.01188624", "0", "1"], ["84073.1", "0.01188439", "0", "1"], ["84039.7", "0", "0", "0"], ["84030.1", "0", "0", "0"], ["84017.8", "0.07141336", "0", "1"], ["83948.1", "0.08991011", "0", "1"], ["83947.3", "0.00117469", "0", "3"]], "ts": "1742584898106", "checksum": 880201987, "seqId": 49948782582, "prevSeqId": 49948782548}], "record_time": 1742584898.190843, "EXCHANGE": "OKX"}
{"arg": {"channel": "books", "instId": "BTC-USDT"}, "action": "update", "data": [{"asks": [["84122.3", "0.00135", "0", "1"], ["84266.9", "0", "0", "0"]], "bids": [["84108", "0", "0", "0"], ["84098.1", "0.004935", "0", "1"], ["84080.3", "0.2025", "0", "1"]], "ts": "1742584898206", "checksum": -364333117, "seqId": 49948782592, "prevSeqId": 49948782582}], "record_time": 1742584898.291839, "EXCHANGE": "OKX"}
{"arg": {"channel": "books", "instId": "BTC-USDT"}, "action": "update", "data": [{"asks": [["84112.2", "0", "0", "0"], ["84122.3", "0", "0", "0"], ["84133.2", "0.01284959", "0", "1"], ["84143.1", "0.23789507", "0", "1"], ["84182.9", "0.1425469", "0", "2"], ["84266.9", "0.0000201", "0", "1"]], "bids": [["84017.8", "0.14282672", "0", "2"]], "ts": "1742584898306", "checksum": 796719073, "seqId": 49948782606, "prevSeqId": 49948782592}], "record_time": 1742584898.391328, "EXCHANGE": "OKX"}
{"arg": {"channel": "books", "instId": "BTC-USDT"}, "action": "update", "data": [{"asks": [["84110.1", "3.01167209", "0", "26"], ["84123", "0.01", "0", "1"], ["84125.1", "0.00299226", "0", "3"], ["84130.6", "0.0128496", "0", "1"], ["84133.2", "0", "0", "0"], ["84143.1", "0.23789478", "0", "1"]], "bids": [["84108", "0.0439", "0", "1"], ["84104.1", "0.09441592", "0", "2"], ["84101.5", "0.2025", "0", "1"], ["84098.1", "0", "0", "0"], ["84088.4", "0.23789478", "0", "1"], ["83947.3", "0", "0", "0"]], "ts": "1742584898406", "checksum": -299459011, "seqId": 49948782628, "prevSeqId": 49948782606}], "record_time": 1742584898.497016, "EXCHANGE": "OKX"}
{"arg": {"channel": "books", "instId": "BTC-USDT"}, "action": "update", "data": [{"asks": [["84110.1", "2.99382909", "0", "25"], ["84143", "0.26166313", "0", "3"], ["84143.1", "0", "0", "0"], ["84267.5", "0.002379", "0", "1"]], "bids": [], "ts": "1742584898506", "checksum": -983450325, "seqId": 49948782637, "prevSeqId": 49948782628}], "record_time": 1742584898.591987, "EXCHANGE": "OKX"}
{"arg": {"channel": "books", "instId": "BTC-USDT"}, "action": "update", "data": [{"asks": [["84110.1", "2.99632609", "0", "26"], ["84154.4", "0", "0", "0"], ["84268.1", "0.01182404", "0", "1"]], "bids": [["84100.1", "0.0042075", "0", "1"], ["83948.1", "0", "0", "0"]], "ts": "1742584898606", "checksum": 206675380, "seqId": 49948782642, "prevSeqId": 49948782637}], "record_time": 1742584898.690642, "EXCHANGE": "OKX"}
{"arg": {"channel": "books", "instId": "BTC-USDT"}, "action": "update", "data": [{"asks": [["84143", "0.02376906", "0", "2"], ["84143.6", "0.23789002", "0", "1"], ["84268.1", "0", "0", "0"]], "bids": [["84090.4", "0.23789002", "0", "1"], ["84088.4", "0", "0", "0"], ["83956.2", "0.00620699", "0", "1"], ["83948.4", "0", "0", "0"]], "ts": "1742584898706", "checksum": 206675380, "seqId": 49948782649, "prevSeqId": 49948782642}], "record_time": 1742584898.79089, "EXCHANGE": "OKX"}
{"arg": {"channel": "books", "instId": "BTC-USDT"}, "action": "update", "data": [{"asks": [["84125.1", "0.00263226", "0", "2"], ["84143.1", "0.23789255", "0", "1"], ["84143.6", "0", "0", "0"]], "bids": [["84090.4", "0", "0", "0"], ["84088.4", "0.23789255", "0", "1"]], "ts": "1742584898806", "checksum": 206675380, "seqId": 49948782654, "prevSeqId": 49948782649}], "record_time": 1742584898.891007, "EXCHANGE": "OKX"}
{"arg": {"channel": "books", "instId": "BTC-USDT"}, "action": "update", "data": [{"asks": [["84125", "0.00495", "0", "2"]], "bids": [["84008.7", "0", "0", "0"], ["83948.4", "0.20290063", "0", "5"]], "ts": "1742584898906", "checksum": 206675380, "seqId": 49948782666, "prevSeqId": 49948782654}], "record_time": 1742584898.991404, "EXCHANGE": "OKX"}
{"arg": {"channel": "books", "instId": "BTC-USDT"}, "action": "update", "data": [{"asks": [["84110.1", "3.01416109", "0", "27"], ["84125", "0.000015", "0", "1"]], "bids": [["84104.1", "0.03847534", "0", "1"], ["84101.5", "0", "0", "0"], ["83948.1", "0.08991011", "0", "1"]], "ts": "1742584899006", "checksum": 254244913, "seqId": 49948782671, "prevSeqId": 49948782666}], "record_time": 1742584899.094198, "EXCHANGE": "OKX"}
{"arg": {"channel": "books", "instId": "BTC-USDT"}, "action": "update", "data": [{"asks": [["84110.1", "3.01166409", "0", "26"], ["84122.6", "0.0300105", "0", "2"], ["84143.1", "0.23789298", "0", "1"], ["84154.9", "0.00250896", "0", "2"]], "bids": [["84110", "0.16168179", "0", "3"], ["84104.1", "0.09441592", "0", "2"], ["84101.5", "0.2025", "0", "1"], ["84100.1", "0", "0", "0"], ["84088.4", "0.23789298", "0", "1"]], "ts": "1742584899106", "checksum": 1317760313, "seqId": 49948782703, "prevSeqId": 49948782671}], "record_time": 1742584899.197912, "EXCHANGE": "OKX"}
{"arg": {"channel": "books", "instId": "BTC-USDT"}, "action": "update", "data": [{"asks": [], "bids": [["84110", "0.11778179", "0", "2"], ["84099.2", "0.003675", "0", "1"], ["84071", "0.49844923", "0", "2"], ["84070", "0", "0", "0"], ["84068", "1.04", "0", "2"], ["84059.9", "0.05940567", "0", "1"], ["84057", "0.2", "0", "1"], ["84021.5", "1.60233686", "0", "3"], ["83948.1", "0", "0", "0"]], "ts": "1742584899206", "checksum": -1357070858, "seqId": 49948782715, "prevSeqId": 49948782703}], "record_time": 1742584899.291549, "EXCHANGE": "OKX"}
{"arg": {"channel": "books", "instId": "BTC-USDT"}, "action": "update", "data": [{"asks": [["84110.1", "2.99382909", "0", "25"], ["84111.8", "0.005", "0", "1"], ["84121.9", "0.005", "0", "1"], ["84143.1", "0", "0", "0"], ["84146.9", "0.23788882", "0", "1"], ["84266.9", "0", "0", "0"], ["84267.5", "0", "0", "0"]], "bids": [["84103.9", "0.005", "0", "1"], ["84093.9", "0.005", "0", "1"], ["84091.8", "0.23788882", "0", "1"], ["84088.4", "0", "0", "0"], ["83948.6", "0", "0", "0"], ["83948.4", "0", "0", "0"]], "ts": "1742584899306", "checksum": 318891210, "seqId": 49948782735, "prevSeqId": 49948782715}], "record_time": 1742584899.391882, "EXCHANGE": "OKX"}
{"arg": {"channel": "books", "instId": "BTC-USDT"}, "action": "update", "data": [{"asks": [], "bids": [["84091.8", "0", "0", "0"], ["84090.4", "0.23788945", "0", "1"], ["84071", "0.2302277", "0", "1"], ["84068", "0.04", "0", "1"], ["84057", "0", "0", "0"], ["83948.6", "0.00063143", "0", "3"]], "ts": "1742584899406", "checksum": 318891210, "seqId": 49948782742, "prevSeqId": 49948782735}], "record_time": 1742584899.49148, "EXCHANGE": "OKX"}
{"arg": {"channel": "books", "instId": "BTC-USDT"}, "action": "update", "data": [{"asks": [["84110.1", "3.01166409", "0", "26"], ["84143.6", "0.23788988", "0", "1"], ["84146.9", "0", "0", "0"]], "bids": [], "ts": "1742584899506", "checksum": -324845414, "seqId": 49948782764, "prevSeqId": 49948782742}], "record_time": 1742584899.591284, "EXCHANGE": "OKX"}
{"arg": {"channel": "books", "instId": "BTC-USDT"}, "action": "update", "data": [{"asks": [["84143.1", "0.23789097", "0", "1"], ["84143.6", "0", "0", "0"]], "bids": [["84090.4", "0", "0", "0"], ["84088.4", "0.23789097", "0", "1"]], "ts": "1742584899606", "checksum": -324845414, "seqId": 49948782768, "prevSeqId": 49948782764}], "record_time": 1742584899.69151, "EXCHANGE": "OKX"}
{"arg": {"channel": "books", "instId": "BTC-USDT"}, "action": "update", "data": [{"asks": [["84111.8", "0.01", "0", "2"], ["84121.9", "0.01", "0", "2"]], "bids": [["84104.1", "0.03847534", "0", "1"], ["84103.9", "0.01", "0", "2"], ["84102.1", "0.02799005", "0", "1"], ["84101.5", "0", "0", "0"], ["84099.6", "0.01189564", "0", "1"], ["84099.2", "0", "0", "0"], ["84093.9", "0.01", "0", "2"], ["83948.4", "0.00040063", "0", "4"]], "ts": "1742584899706", "checksum": 1617073035, "seqId": 49948782780, "prevSeqId": 49948782768}], "record_time": 1742584899.791322, "EXCHANGE": "OKX"}
{"arg": {"channel": "books", "instId": "BTC-USDT"}, "action": "update", "data": [{"asks": [], "bids": [["84101.5", "0.2025", "0", "1"], ["84098.8", "0.0002025", "0", "1"], ["83948.6", "0", "0", "0"], ["83948.4", "0", "0", "0"]], "ts": "1742584899806", "checksum": -616719937, "seqId": 49948782788, "prevSeqId": 49948782780}], "record_time": 1742584899.891592, "EXCHANGE": "OKX"}
{"arg": {"channel": "books", "instId": "BTC-USDT"}, "action": "update", "data": [{"asks": [], "bids": [["84104.1", "0.09384733", "0", "2"]], "ts": "1742584899906", "checksum": 553859116, "seqId": 49948782790, "prevSeqId": 49948782788}], "record_time": 1742584899.990771, "EXCHANGE": "OKX"}
{"arg": {"channel": "books", "instId": "BTC-USDT"}, "action": "update", "data": [{"asks": [["84110.9", "0.003567", "0", "1"], ["84122.6", "0.03", "0", "1"], ["84123.1", "0.57362153", "0", "2"], ["84124.6", "0.0044595", "0", "1"], ["84126", "1.21819367", "0", "2"], ["84130.9", "0.01188624", "0", "1"], ["84132.2", "0", "0", "0"], ["84133.5", "0", "0", "0"], ["84133.8", "0", "0", "0"], ["84141.2", "0.23801063", "0", "2"], ["84143.1", "0", "0", "0"], ["84144", "0.01188439", "0", "1"]], "bids": [["84110", "0.00011498", "0", "1"], ["84108", "0", "0", "0"], ["84104.1", "0.03847534", "0", "1"], ["84101.5", "0", "0", "0"], ["84099.8", "0.15505102", "0", "2"], ["84088.4", "0", "0", "0"], ["84084.2", "0.23789902", "0", "1"], ["83988.2", "0.15267237", "0", "2"], ["83948.6", "0.00063143", "0", "3"], ["83948.4", "0.20290063", "0", "5"]], "ts": "1742584900106", "checksum": -262651581, "seqId": 49948782840, "prevSeqId": 49948782790}], "record_time": 1742584900.19173, "EXCHANGE": "OKX"}
{"arg": {"channel": "books", "instId": "BTC-USDT"}, "action": "update", "data": [{"asks": [["84106.2", "1.47980322", "0", "18"], ["84106.6", "0.11895389", "0", "1"], ["84107.5", "0.40669417", "0", "1"], ["84107.6", "1", "0", "1"], ["84108.2", "0.35564723", "0", "1"], ["84108.8", "0.01189564", "0", "1"], ["84109.6", "0.1", "0", "1"], ["84109.9", "0.1550749", "0", "1"], ["84110.1", "0.23265631", "0", "7"], ["84111.2", "0", "0", "0"], ["84111.3", "0.02533", "0", "1"], ["84112", "0.00262029", "0", "1"], ["84115.2", "0.00001197", "0", "1"], ["84117.5", "0", "0", "0"], ["84125.1", "0.00001197", "0", "1"], ["84130.9", "0", "0", "0"], ["84131.7", "0.01188613", "0", "1"], ["84136.3", "0", "0", "0"], ["84139.2", "0.0008", "0", "2"], ["84140", "0.00045196", "0", "3"], ["84140.8", "0", "0", "0"], ["84141.1", "0.23790066", "0", "1"], ["84141.2", "0.00011161", "0", "1"], ["84143", "0.03565359", "0", "3"], ["84146.4", "0.07999999", "0", "2"], ["84147.2", "0.28966999", "0", "2"], ["84148", "0", "0", "0"], ["84154.7", "0", "0", "0"], ["84262.4", "0", "0", "0"], ["84263.1", "0", "0", "0"], ["84263.8", "0", "0", "0"], ["84263.9", "0", "0", "0"], ["84264", "0", "0", "0"], ["84264.9", "0", "0", "0"], ["84265.8", "0", "0", "0"], ["84266.6", "0", "0", "0"]], "bids": [["84110", "0", "0", "0"], ["84106.1", "0.36553935", "0", "3"], ["84105.2", "0.07924314", "0", "1"], ["84105.1", "0.06556011", "0", "2"], ["84104.1", "0", "0", "0"], ["84101.5", "0.00772833", "0", "1"], ["84097.4", "0", "0", "0"], ["84092.1", "0.33021255", "0", "1"], ["84091.1", "0.04052964", "0", "2"], ["84087.6", "0", "0", "0"], ["84084.9", "0.05022", "0", "1"], ["84084.2", "0", "0", "0"], ["84082.2", "0.23790066", "0", "1"], ["84076.8", "0", "0", "0"], ["84070.4", "0.01188453", "0", "1"], ["84069.6", "0", "0", "0"], ["84068.8", "0.00079848", "0", "2"], ["84068", "0.08039848", "0", "3"], ["84067.2", "0.04", "0", "1"], ["84066.5", "0", "0", "0"], ["84065.6", "0.27711", "0", "1"], ["84065.4", "0", "0", "0"], ["84064.8", "0.1", "0", "2"], ["84064", "0.05", "0", "1"], ["84061.5", "0.01188613", "0", "1"], ["84034", "0", "0", "0"], ["84029.4", "0.00100229", "0", "1"], ["84023.4", "0", "0", "0"], ["84017.9", "0.00144907", "0", "1"], ["83948.1", "0.08991011", "0", "1"]], "ts": "1742584900206", "checksum": 876494659, "seqId": 49948783030, "prevSeqId": 49948782840}], "record_time": 1742584900.301777, "EXCHANGE": "OKX"}
{"arg": {"channel": "books", "instId": "BTC-USDT"}, "action": "update", "data": [{"asks": [["84106.2", "1.23117247", "0", "16"], ["84110.1", "0.23146631", "0", "6"], ["84124.6", "0", "0", "0"], ["84130", "0.0128496", "0", "1"], ["84130.6", "0", "0", "0"], ["84150.8", "0.1", "0", "1"]], "bids": [["84061.5", "0.11188613", "0", "2"]], "ts": "1742584900306", "checksum": 1560694392, "seqId": 49948783048, "prevSeqId": 49948783030}], "record_time": 1742584900.391575, "EXCHANGE": "OKX"}
