{"arg": {"channel": "books", "instId": "BTC-USDT"}, "action": "snapshot", "data": [{"asks": [["83937.1", "2.23706805", "0", "16"], ["83937.9", "0.04312196", "0", "1"], ["83938", "0.0799", "0", "2"], ["83938.7", "0.00608985", "0", "6"], ["83939.8", "0.002", "0", "1"], ["83939.9", "0.01181", "0", "2"], ["83940", "0.04394", "0", "2"], ["83941.5", "0.01", "0", "2"], ["83941.7", "0.00001199", "0", "1"], ["83943.2", "0.1202998", "0", "2"], ["83944.5", "0.3565323", "0", "1"], ["83944.7", "0.04296377", "0", "1"], ["83944.8", "0.00011161", "0", "1"], ["83945.2", "0.00774407", "0", "1"], ["83945.5", "0.123807", "0", "2"], ["83945.6", "0.00056093", "0", "1"], ["83945.9", "0.004458", "0", "1"], ["83946.6", "0.00001199", "0", "1"], ["83947.4", "0.11250022", "0", "2"], ["83947.7", "0.02", "0", "1"], ["83948.2", "0.00774441", "0", "1"], ["83948.3", "0.03094", "0", "1"], ["83948.6", "0.04475367", "0", "2"], ["83949.2", "0.11889794", "0", "1"], ["83949.6", "0.01031", "0", "1"], ["83949.9", "0.34399478", "0", "3"], ["83950", "0.2025", "0", "1"], ["83950.1", "0.0015", "0", "1"], ["83950.2", "0.08991011", "0", "1"], ["83951.6", "0.00001199", "0", "1"], ["83952", "0.01", "0", "1"], ["83952.1", "0.016", "0", "1"], ["83952.2", "0.01191791", "0", "1"], ["83952.4", "0.02384091", "0", "1"], ["83952.9", "0.3565323", "0", "1"], ["83953.1", "0.35741", "0", "1"], ["83953.5", "0.11917083", "0", "1"], ["83953.6", "0.03981539", "0", "1"], ["83953.7", "0.17898725", "0", "1"], ["83953.9", "0.0119113", "0", "1"], ["83954", "0.2813949", "0", "1"], ["83954.2", "0.052", "0", "2"], ["83954.3", "0.00351238", "0", "1"], ["83954.5", "0.18079576", "0", "2"], ["83955.3", "0.06", "0", "2"], ["83956.1", "0.016", "0", "1"], ["83956.5", "0.00001199", "0", "1"], ["83957", "0.2384351", "0", "2"], ["83957.1", "0.135416", "0", "1"], ["83957.9", "0.1141366", "0", "3"], ["83958", "0.04", "0", "1"], ["83958.1", "0.016", "0", "1"], ["83958.5", "0.14079576", "0", "1"], ["83958.7", "0.12", "0", "4"], ["83959.5", "0.76626113", "0", "1"], ["83959.6", "1.6098534", "0", "1"], ["83960.1", "0.016", "0", "1"], ["83960.4", "1", "0", "1"], ["83961.3", "0.3565323", "0", "1"], ["83961.5", "0.11890993", "0", "2"], ["83962", "0.00001", "0", "1"], ["83962.7", "0.30088779", "0", "1"], ["83963", "0.08991011", "0", "1"], ["83963.8", "0.17898725", "0", "1"], ["83963.9", "0.50218", "0", "1"], ["83964.4", "0.00011161", "0", "1"], ["83964.5", "0.2025", "0", "1"], ["83965.4", "0.000015", "0", "1"], ["83965.7", "0.11915345", "0", "1"], ["83966.4", "0.00001199", "0", "1"], ["83966.6", "0.21895", "0", "4"], ["83967.4", "0.2502", "0", "1"], ["83967.9", "0.07150541", "0", "2"], ["83968.1", "0.01190929", "0", "1"], ["83968.4", "0.1126366", "0", "2"], ["83968.5", "0.18772768", "0", "1"], ["83969.1", "0.000015", "0", "1"], ["83969.3", "0.01190912", "0", "1"], ["83969.4", "0.01190911", "0", "1"], ["83970.4", "0.0008", "0", "2"], ["83970.9", "0.47483612", "0", "1"], ["83971", "0.3565323", "0", "1"], ["83971.2", "0.02323169", "0", "2"], ["83971.4", "0.00001199", "0", "1"], ["83971.7", "0.472134", "0", "1"], ["83973.1", "0.17898725", "0", "1"], ["83973.2", "0.02382856", "0", "1"], ["83973.5", "0.11889794", "0", "1"], ["83973.8", "0.20401501", "0", "3"], ["83974", "0.1251", "0", "1"], ["83974.6", "0.0001723", "0", "1"], ["83975.1", "0.02382801", "0", "1"], ["83976.3", "0.00001199", "0", "1"], ["83976.4", "0.34731788", "0", "2"], ["83977.6", "0.05719634", "0", "1"], ["83977.9", "0.57753742", "0", "1"], ["83978.2", "0.01274631", "0", "2"], ["83978.6", "0.11597977", "0", "1"], ["83978.9", "0.1126366", "0", "2"], ["83979.2", "0.07999999", "0", "2"], ["83979.3", "0.31188773", "0", "1"], ["83979.6", "0.3565323", "0", "1"], ["83980", "0.04005735", "0", "2"], ["83981.3", "0.00715643", "0", "2"], ["83981.9", "0.29788519", "0", "2"], ["83982.2", "0.202515", "0", "2"], ["83982.4", "0.02180771", "0", "2"], ["83983.3", "0.00060645", "0", "1"], ["83983.7", "0.11936814", "0", "1"], ["83983.8", "0.26238", "0", "1"], ["83984.1", "0.00011161", "0", "1"], ["83985.2", "0.08991011", "0", "1"], ["83986.2", "0.00001199", "0", "1"], ["83986.6", "0.00083845", "0", "1"], ["83987.2", "0.001723", "0", "1"], ["83988", "0.002145", "0", "1"], ["83988.1", "0.02288178", "0", "1"], ["83988.3", "0.42712865", "0", "2"], ["83988.4", "0.2502", "0", "1"], ["83989.3", "0.59025", "0", "1"], ["83989.4", "0.3565323", "0", "1"], ["83990.4", "0.00595793", "0", "1"], ["83990.5", "0.11889794", "0", "1"], ["83990.6", "0.202515", "0", "2"], ["83990.8", "0.00103317", "0", "1"], ["83991.2", "0.00001199", "0", "1"], ["83991.3", "0.01", "0", "1"], ["83992.2", "0.94837093", "0", "1"], ["83992.3", "2.95746099", "0", "1"], ["83994.6", "0.01865386", "0", "1"], ["83995", "0.1251", "0", "1"], ["83995.9", "0.17898725", "0", "1"], ["83996.2", "0.00001199", "0", "1"], ["83997.5", "0.4", "0", "1"], ["83997.9", "0.00002157", "0", "1"], ["83998", "0.00103582", "0", "1"], ["83998.9", "0.00595724", "0", "1"], ["83999", "0.60934285", "0", "2"], ["83999.1", "0.32139794", "0", "2"], ["83999.4", "0.878599", "0", "2"], ["83999.7", "0.3565323", "0", "1"], ["83999.9", "0.0051126", "0", "6"], ["84000", "0.18773756", "0", "4"], ["84000.8", "0.04630347", "0", "1"], ["84000.9", "0.1428557", "0", "2"], ["84001.1", "0.00001198", "0", "1"], ["84002.4", "0.01786635", "0", "1"], ["84003.7", "0.00011161", "0", "1"], ["84004.2", "0.32205415", "0", "1"], ["84005.2", "0.0011904", "0", "1"], ["84005.4", "0.08991011", "0", "1"], ["84005.6", "0.03", "0", "1"], ["84006.1", "0.00001198", "0", "1"], ["84006.5", "0.01135925", "0", "1"], ["84006.6", "0.04765592", "0", "1"], ["84006.8", "0.00595711", "0", "1"], ["84006.9", "0.17898725", "0", "1"], ["84007.4", "0.000015", "0", "1"], ["84007.5", "0.2025", "0", "1"], ["84008", "0.11889794", "0", "1"], ["84008.1", "0.3565323", "0", "1"], ["84009.1", "0.00595711", "0", "1"], ["84009.2", "0.03942251", "0", "2"], ["84009.4", "0.01192016", "0", "1"], ["84010.5", "0.01428393", "0", "1"], ["84010.7", "0.05954482", "0", "1"], ["84011", "0.00001198", "0", "1"], ["84011.1", "0.00001501", "0", "1"], ["84011.8", "0.044994", "0", "1"], ["84013.9", "0.00580014", "0", "1"], ["84015.8", "0.1146467", "0", "2"], ["84015.9", "0.2025", "0", "1"], ["84016", "0.17899923", "0", "2"], ["84016.6", "0.00060645", "0", "1"], ["84016.8", "0.32548263", "0", "2"], ["84017", "0.01719982", "0", "1"], ["84017.2", "0.3565323", "0", "1"], ["84017.4", "0.43692", "0", "1"], ["84017.6", "0.000012", "0", "1"], ["84019.4", "0.00580014", "0", "1"], ["84019.5", "0.1", "0", "1"], ["84020.5", "0.21889794", "0", "2"], ["84021.5", "0.08771", "0", "1"], ["84021.6", "0.01190945", "0", "1"], ["84022", "0.16795279", "0", "1"], ["84022.5", "0.02099926", "0", "1"], ["84022.8", "0.0214", "0", "1"], ["84023.1", "0.0428", "0", "2"], ["84023.3", "0.00011161", "0", "1"], ["84023.7", "0.08991011", "0", "1"], ["84023.9", "0.00298666", "0", "1"], ["84024.2", "0.000015", "0", "1"], ["84024.3", "0.2025", "0", "1"], ["84025.1", "0.18478739", "0", "2"], ["84025.8", "0.0015", "0", "1"], ["84025.9", "0.000012", "0", "1"], ["84026", "0.00579977", "0", "1"], ["84026.1", "0.13289296", "0", "1"], ["84026.4", "0.3565323", "0", "1"], ["84026.6", "0.0001749", "0", "1"], ["84027.7", "0.00007589", "0", "1"], ["84029.6", "0.03", "0", "1"], ["84029.9", "0.000012", "0", "1"], ["84030", "0.0325", "0", "2"], ["84031", "0.00830014", "0", "2"], ["84031.3", "0.2944742", "0", "2"], ["84031.4", "0.11902446", "0", "2"], ["84031.5", "0.00683721", "0", "2"], ["84032.5", "0.00075763", "0", "1"], ["84032.6", "0.000015", "0", "1"], ["84032.7", "0.81897", "0", "2"], ["84032.9", "0.0214", "0", "1"], ["84033", "0.005", "0", "2"], ["84033.3", "0.00101534", "0", "2"], ["84033.4", "0.03", "0", "1"], ["84035.2", "0.00590014", "0", "1"], ["84035.3", "0.02364535", "0", "2"], ["84035.4", "0.56446912", "0", "3"], ["84035.5", "0.17898725", "0", "1"], ["84035.8", "0.000012", "0", "1"], ["84036", "0.3565323", "0", "1"], ["84037.2", "0.00580014", "0", "1"], ["84037.3", "0.06747", "0", "1"], ["84037.5", "1.22079785", "0", "2"], ["84037.6", "0.10489442", "0", "2"], ["84039.8", "0.00590014", "0", "1"], ["84039.9", "0.01160003", "0", "2"], ["84040.4", "0.00590014", "0", "1"], ["84040.5", "0.09714238", "0", "1"], ["84040.6", "0.11889794", "0", "1"], ["84040.8", "0.000012", "0", "1"], ["84041", "0.000015", "0", "1"], ["84041.1", "0.2025", "0", "1"], ["84041.3", "0.05732575", "0", "1"], ["84041.5", "0.00580014", "0", "1"], ["84042.3", "0.000012", "0", "1"], ["84042.5", "0.00589988", "0", "1"], ["84042.6", "0.07165719", "0", "1"], ["84042.7", "0.01652", "0", "1"], ["84043", "0.00011161", "0", "1"], ["84043.8", "0.07166249", "0", "1"], ["84044.2", "0.01485984", "0", "2"], ["84044.4", "0.0357327", "0", "1"], ["84044.7", "0.00590014", "0", "1"], ["84044.8", "0.18941448", "0", "1"], ["84044.9", "0.17898725", "0", "1"], ["84045.2", "0.00595193", "0", "1"], ["84045.6", "0.08991011", "0", "1"], ["84046", "0.3565323", "0", "1"], ["84046.6", "1.25402088", "0", "2"], ["84046.7", "3.93236", "0", "1"], ["84048", "0.0015", "0", "1"], ["84048.2", "0.0142", "0", "1"], ["84048.3", "0.0284", "0", "2"], ["84049.5", "0.2025", "0", "1"], ["84049.9", "0.00060645", "0", "1"], ["84050", "0.00018518", "0", "2"], ["84050.5", "0.11889794", "0", "1"], ["84050.7", "0.000012", "0", "1"], ["84051.3", "0.19493", "0", "2"], ["84052", "0.0015", "0", "1"], ["84052.6", "0.01196403", "0", "2"], ["84053.1", "0.00001501", "0", "1"], ["84053.6", "0.17898725", "0", "1"], ["84054", "1.03689", "0", "1"], ["84054.1", "3.4563", "0", "1"], ["84055.4", "0.2501256", "0", "1"], ["84055.5", "0.214487", "0", "1"], ["84055.6", "0.3565443", "0", "2"], ["84057.1", "0.00007544", "0", "2"], ["84057.4", "0.00009384", "0", "1"], ["84057.5", "0.06", "0", "2"], ["84057.9", "0.20252241", "0", "2"], ["84058.1", "0.0142", "0", "1"], ["84058.2", "0.183598", "0", "1"], ["84058.8", "0.00254713", "0", "2"], ["84060.6", "0.000012", "0", "1"], ["84061.9", "0.01733191", "0", "1"], ["84062", "0.01493332", "0", "1"], ["84062.1", "0.00002296", "0", "1"], ["84062.4", "0.00010514", "0", "1"], ["84062.6", "0.00011161", "0", "1"], ["84062.7", "0.0142", "0", "1"], ["84062.8", "0.0284", "0", "2"], ["84063.7", "0.17898725", "0", "1"], ["84063.8", "0.11889794", "0", "1"], ["84064.5", "0.3565323", "0", "1"], ["84065.1", "0.00594", "0", "1"], ["84065.2", "0.00008584", "0", "1"], ["84065.6", "0.000012", "0", "1"], ["84065.9", "0.00595724", "0", "1"], ["84066.3", "1.84575", "0", "2"], ["84066.6", "0.00504382", "0", "4"], ["84067", "0.002395", "0", "2"], ["84067.4", "0.21414", "0", "1"], ["84068.4", "0.05361054", "0", "1"], ["84068.5", "0.5999", "0", "1"], ["84069.1", "0.11900691", "0", "1"], ["84069.7", "0.00011444", "0", "1"], ["84071.4", "0.00001362", "0", "1"], ["84072.2", "0.00002016", "0", "1"], ["84072.6", "0.08998825", "0", "2"], ["84072.8", "0.11889794", "0", "1"], ["84073", "0.3565323", "0", "1"], ["84073.2", "0.17898725", "0", "1"], ["84075", "0.00004433", "0", "1"], ["84075.5", "0.00001199", "0", "1"], ["84076.5", "0.00010284", "0", "1"], ["84076.8", "0.00001957", "0", "1"], ["84076.9", "0.00009125", "0", "1"], ["84077", "0.00008", "0", "1"], ["84079", "0.00594", "0", "1"], ["84079.3", "0.00001199", "0", "1"], ["84079.4", "0.00018194", "0", "1"], ["84079.9", "0.00001026", "0", "1"], ["84081.4", "0.00003364", "0", "1"], ["84081.6", "0.00212326", "0", "1"], ["84082.2", "0.17898725", "0", "1"], ["84082.3", "0.00011161", "0", "1"], ["84082.6", "0.00001984", "0", "1"], ["84082.7", "0.01787159", "0", "3"], ["84083.3", "0.00422986", "0", "3"], ["84083.8", "0.3565323", "0", "1"], ["84083.9", "0.08767", "0", "1"], ["84084.2", "0.01064", "0", "1"], ["84085.1", "0.0054", "0", "1"], ["84085.4", "0.00001199", "0", "1"], ["84085.7", "0.00068775", "0", "1"], ["84087.5", "0.72697213", "0", "1"], ["84088.2", "0.00011938", "0", "1"], ["84088.5", "0.00003542", "0", "1"], ["84089.1", "0.00002215", "0", "1"], ["84089.7", "0.0315", "0", "2"], ["84090.2", "0.00074396", "0", "1"], ["84090.4", "0.0000114", "0", "1"], ["84090.8", "0.00376703", "0", "1"], ["84090.9", "0.00003887", "0", "1"], ["84091.1", "0.17898725", "0", "1"], ["84091.2", "0.00001297", "0", "1"], ["84091.7", "0.00001199", "0", "1"], ["84093.2", "0.3565323", "0", "1"], ["84094.5", "0.31997186", "0", "1"], ["84095.1", "0.000015", "0", "1"], ["84095.3", "0.00001197", "0", "1"], ["84095.5", "0.00351192", "0", "1"], ["84096", "0.00006328", "0", "1"], ["84097.7", "0.03", "0", "1"], ["84099.9", "0.00101534", "0", "2"], ["84100", "5.01249374", "0", "6"], ["84101.1", "0.06", "0", "2"], ["84101.3", "0.17898725", "0", "1"], ["84101.6", "0.14268464", "0", "2"], ["84101.7", "0.3565323", "0", "1"], ["84101.9", "0.00011161", "0", "1"], ["84105.2", "0.0000225", "0", "2"], ["84105.5", "6.65454647", "0", "1"], ["84106.6", "0.00001008", "0", "1"], ["84107", "0.00120451", "0", "3"], ["84107.6", "0.00001881", "0", "1"], ["84109", "0.08994305", "0", "2"], ["84110", "0.01232", "0", "1"], ["84110.5", "0.3565323", "0", "1"], ["84111.1", "0.00003344", "0", "1"], ["84111.2", "0.00004855", "0", "1"], ["84111.6", "0.0015", "0", "1"], ["84111.8", "0.00006401", "0", "1"], ["84112.6", "0.00003552", "0", "1"], ["84113.3", "0.17898725", "0", "1"], ["84113.5", "0.00003103", "0", "1"], ["84114", "0.00014547", "0", "1"], ["84115.7", "0.00103744", "0", "1"], ["84116.6", "0.00060645", "0", "1"], ["84116.8", "0.00594739", "0", "1"], ["84117.6", "0.00001805", "0", "1"], ["84118.6", "3.72", "0", "1"], ["84118.9", "0.08764", "0", "1"], ["84119", "0.35658448", "0", "2"], ["84120", "0.00006444", "0", "2"], ["84120.1", "0.00001197", "0", "1"], ["84121.5", "0.00011161", "0", "1"], ["84122.2", "0.17898725", "0", "1"], ["84123.6", "0.00126715", "0", "1"], ["84123.7", "0.00005514", "0", "1"], ["84125", "0.00009264", "0", "1"], ["84125.1", "0.0001387", "0", "1"], ["84125.3", "0.00001956", "0", "1"], ["84126.2", "0.00001805", "0", "1"], ["84126.6", "0.00002004", "0", "1"], ["84127.5", "0.3565323", "0", "1"], ["84130.6", "3.37684", "0", "1"], ["84131.1", "0.00008649", "0", "2"], ["84131.6", "0.017875", "0", "1"], ["84132.5", "0.17898725", "0", "1"], ["84132.6", "0.0000434", "0", "1"], ["84132.8", "0.00002013", "0", "1"], ["84133.1", "0.08991011", "0", "1"], ["84133.3", "0.00517228", "0", "9"], ["84133.5", "0.00001277", "0", "1"], ["84134.5", "0.0000103", "0", "1"], ["84134.6", "0.00003392", "0", "1"]], "bids": [["83937", "0.00112015", "0", "1"], ["83932.6", "0.03404579", "0", "1"], ["83932", "0.0439", "0", "1"], ["83931.9", "0.00001199", "0", "1"], ["83931.3", "0.016", "0", "1"], ["83930.5", "0.00195414", "0", "1"], ["83930.2", "0.00771984", "0", "1"], ["83930", "0.0439", "0", "1"], ["83928.5", "0.0918299", "0", "1"], ["83928", "0.0439", "0", "1"], ["83927.9", "0.016", "0", "1"], ["83927.1", "0.0119166", "0", "1"], ["83927", "0.04296377", "0", "1"], ["83926.9", "0.00001199", "0", "1"], ["83926.4", "0.0447025", "0", "1"], ["83926.3", "0.00001501", "0", "1"], ["83926.1", "0.01192162", "0", "1"], ["83926", "0.0439", "0", "1"], ["83925.9", "0.052", "0", "2"], ["83924.5", "0.052", "0", "2"], ["83924.3", "0.2314527", "0", "1"], ["83924", "0.0439", "0", "1"], ["83923.6", "0.016", "0", "1"], ["83923.5", "0.01376", "0", "1"], ["83922.8", "0.00771984", "0", "1"], ["83922.7", "0.04262488", "0", "1"], ["83922", "0.04391199", "0", "2"], ["83921.9", "0.063", "0", "2"], ["83921.7", "0.052", "0", "2"], ["83921.3", "0.00006", "0", "1"], ["83920.5", "0.3565323", "0", "1"], ["83920.4", "0.40941", "0", "3"], ["83920.2", "0.04", "0", "1"], ["83920.1", "0.17898725", "0", "1"], ["83920", "0.61575669", "0", "3"], ["83919.8", "0.135416", "0", "1"], ["83919.7", "0.052", "0", "2"], ["83919.5", "0.1787", "0", "1"], ["83918.6", "0.141", "0", "4"], ["83918", "0.0439", "0", "1"], ["83917.9", "0.00001501", "0", "1"], ["83917.8", "0.04", "0", "1"], ["83917.2", "1", "0", "1"], ["83917", "0.00001199", "0", "1"], ["83916.8", "0.20726663", "0", "2"], ["83916.6", "0.00060645", "0", "1"], ["83916.4", "0.1192234", "0", "1"], ["83916", "0.20671616", "0", "6"], ["83915.5", "0.28249715", "0", "1"], ["83914.8", "0.0238398", "0", "1"], ["83914.7", "0.00357", "0", "1"], ["83914.5", "0.19487781", "0", "2"], ["83913.4", "0.14079576", "0", "1"], ["83912.7", "0.11922862", "0", "1"], ["83912.1", "0.3565323", "0", "1"], ["83912", "0.00001199", "0", "1"], ["83911.8", "0.32724512", "0", "2"], ["83911.6", "0.016", "0", "1"], ["83911.4", "0.08684", "0", "1"], ["83911.3", "0.17898725", "0", "1"], ["83911.1", "0.1411", "0", "2"], ["83910.4", "0.05988903", "0", "1"], ["83909.9", "0.016", "0", "1"], ["83909.5", "0.000015", "0", "1"], ["83908", "0.00036", "0", "1"], ["83907.6", "0.23002338", "0", "1"], ["83907.1", "0.00001199", "0", "1"], ["83907", "0.005", "0", "1"], ["83906.2", "0.005", "0", "1"], ["83905.5", "0.11322493", "0", "4"], ["83904.5", "0.50758", "0", "2"], ["83903.4", "0.85780817", "0", "3"], ["83903.3", "0.49732806", "0", "2"], ["83902.5", "0.045052", "0", "1"], ["83902.1", "0.00143562", "0", "2"], ["83901.9", "0.24042009", "0", "2"], ["83901.8", "1.54132205", "0", "1"], ["83901.6", "0.08", "0", "2"], ["83901.5", "0.2025", "0", "1"], ["83901.1", "0.000015", "0", "1"], ["83901", "0.01226997", "0", "2"], ["83900.8", "0.04", "0", "1"], ["83900.5", "0.17898725", "0", "1"], ["83900.1", "0.07150522", "0", "2"], ["83900", "0.00001", "0", "1"], ["83899.9", "0.00101534", "0", "2"], ["83899.8", "0.052", "0", "2"], ["83898.4", "0.1251", "0", "1"], ["83898.3", "0.41899051", "0", "2"], ["83898.2", "0.036", "0", "1"], ["83897.8", "0.016", "0", "1"], ["83897.2", "0.000012", "0", "1"], ["83896.9", "0.5826526", "0", "2"], ["83896.8", "0.1", "0", "2"], ["83896.1", "0.005", "0", "1"], ["83896", "0.05", "0", "1"], ["83895.9", "0.47202", "0", "1"], ["83895.4", "0.08991011", "0", "1"], ["83895", "0.7065054", "0", "4"], ["83894.8", "0.11889794", "0", "1"], ["83894.3", "0.3565323", "0", "1"], ["83894.2", "0.00294862", "0", "1"], ["83893.9", "0.02385105", "0", "1"], ["83893.8", "0.052", "0", "2"], ["83893.1", "0.01", "0", "1"], ["83892.7", "0.00001501", "0", "1"], ["83892.2", "0.000012", "0", "1"], ["83892.1", "0.01672", "0", "1"], ["83891.8", "0.18098725", "0", "2"], ["83891.7", "0.2545", "0", "3"], ["83891.5", "0.58617", "0", "1"], ["83890.9", "0.00579988", "0", "1"], ["83890.8", "0.2630465", "0", "1"], ["83890.3", "0.05213", "0", "1"], ["83890.2", "0.01835673", "0", "1"], ["83890.1", "0.13090014", "0", "2"], ["83890", "0.00294862", "0", "1"], ["83889.7", "0.00590014", "0", "1"], ["83889.5", "0.52547", "0", "1"], ["83888.2", "0.036", "0", "1"], ["83888", "0.00025", "0", "1"], ["83887.8", "0.016", "0", "1"], ["83887.5", "0.01191069", "0", "1"], ["83887.3", "0.000012", "0", "1"], ["83887", "0.052", "0", "2"], ["83886.6", "0.62593897", "0", "1"], ["83886.5", "0.826129", "0", "1"], ["83886.4", "0.02679925", "0", "4"], ["83886", "0.00928245", "0", "1"], ["83885.9", "0.00011161", "0", "1"], ["83885.8", "0.00294862", "0", "1"], ["83885.6", "0.01339925", "0", "2"], ["83884.6", "0.11889794", "0", "1"], ["83884.5", "0.4128506", "0", "2"], ["83884.3", "0.00001501", "0", "1"], ["83883.5", "0.25027", "0", "1"], ["83883.3", "0.01251775", "0", "2"], ["83883.2", "0.0119113", "0", "1"], ["83882.5", "0.19089865", "0", "2"], ["83882.4", "0.01192343", "0", "2"], ["83882.1", "0.01", "0", "1"], ["83882", "0.00036", "0", "1"], ["83881", "0.08602316", "0", "3"], ["83880", "0.0000466", "0", "2"], ["83879.9", "0.2025", "0", "1"], ["83879.2", "0.01789259", "0", "1"], ["83878.1", "0.21297967", "0", "1"], ["83877.9", "0.00590014", "0", "1"], ["83877.4", "0.125112", "0", "2"], ["83877", "0.00001", "0", "1"], ["83876.2", "0.11889794", "0", "1"], ["83876.1", "0.3565323", "0", "1"], ["83875.9", "0.000015", "0", "1"], ["83875.3", "0.000015", "0", "1"], ["83874.2", "0.04395824", "0", "1"], ["83874", "0.0057997", "0", "1"], ["83873.5", "0.93693569", "0", "2"], ["83873.4", "0.17898725", "0", "1"], ["83872.5", "2.85175377", "0", "2"], ["83872.4", "0.067603", "0", "1"], ["83870.9", "0.90247", "0", "1"], ["83870.7", "0.00595711", "0", "1"], ["83870.6", "0.09209687", "0", "2"], ["83870.5", "0.02385773", "0", "1"], ["83870.4", "0.00579995", "0", "1"], ["83869.9", "0.00246001", "0", "2"], ["83869.8", "0.0057997", "0", "1"], ["83868.4", "0.42824222", "0", "2"], ["83868.3", "0.2025", "0", "1"], ["83867.8", "0.03", "0", "1"], ["83867.5", "0.000027", "0", "2"], ["83867.4", "0.3565323", "0", "1"], ["83866.7", "0.00005728", "0", "1"], ["83866.6", "0.12924617", "0", "11"], ["83866.4", "0.57914207", "0", "1"], ["83866.2", "0.00011161", "0", "1"], ["83865.1", "0.00589995", "0", "1"], ["83865", "0.08402611", "0", "1"], ["83864.9", "0.17898725", "0", "1"], ["83864.6", "0.08944", "0", "1"], ["83864", "0.00002125", "0", "1"], ["83863.3", "0.00004163", "0", "1"], ["83863.2", "0.0071545", "0", "1"], ["83863.1", "0.00103791", "0", "1"], ["83862.6", "0.00001198", "0", "1"], ["83861.4", "0.0058997", "0", "1"], ["83861.3", "0.22439328", "0", "1"], ["83860", "0.00037", "0", "2"], ["83859.7", "0.22531873", "0", "3"], ["83859.2", "0.04468045", "0", "2"], ["83859.1", "0.00001501", "0", "1"], ["83858.6", "0.00020004", "0", "1"], ["83858.3", "0.3565323", "0", "1"], ["83858", "0.00036", "0", "1"], ["83857.6", "0.00001198", "0", "1"], ["83857.5", "0.00004084", "0", "1"], ["83857.4", "0.01736", "0", "1"], ["83857.3", "0.00001198", "0", "1"], ["83857.1", "0.00091322", "0", "4"], ["83857", "0.00036", "0", "1"], ["83856.9", "0.62361728", "0", "1"], ["83856.2", "1.217523", "0", "1"], ["83855.6", "0.01511099", "0", "1"], ["83855.1", "0.17898725", "0", "1"], ["83854.9", "0.58226341", "0", "1"], ["83854.8", "0.09", "0", "3"], ["83854.7", "0.00168677", "0", "1"], ["83853.4", "0.00605986", "0", "2"], ["83853.3", "0.11889794", "0", "1"], ["83853", "0.19882548", "0", "1"], ["83852.9", "0.08991011", "0", "1"], ["83852.5", "0.00001059", "0", "1"], ["83852", "0.00036", "0", "1"], ["83851", "0.20294214", "0", "3"], ["83850.7", "0.000015", "0", "1"], ["83850.4", "0.00001302", "0", "1"], ["83850.1", "0.00598038", "0", "2"], ["83850", "0.02475342", "0", "6"], ["83849.9", "0.00419995", "0", "2"], ["83849.6", "0.35784874", "0", "2"], ["83848.9", "0.00054698", "0", "1"], ["83848.4", "0.00017177", "0", "1"], ["83848.2", "0.00018326", "0", "1"], ["83848.1", "0.18205019", "0", "1"], ["83847.8", "0.00001319", "0", "1"], ["83847.7", "0.00001199", "0", "1"], ["83847.2", "0.20864", "0", "1"], ["83846.8", "0.00001004", "0", "1"], ["83846.7", "0.23864845", "0", "2"], ["83846.6", "0.00011161", "0", "1"], ["83846.1", "0.00002549", "0", "1"], ["83845.9", "0.0777093", "0", "1"], ["83845", "0.00001198", "0", "1"], ["83844.7", "0.00005731", "0", "1"], ["83844.6", "0.11889794", "0", "1"], ["83844.5", "0.06", "0", "2"], ["83843.8", "0.0357824", "0", "1"], ["83843.1", "0.07166249", "0", "1"], ["83843", "0.00596352", "0", "1"], ["83842.9", "0.00001008", "0", "1"], ["83842.7", "0.17928995", "0", "1"], ["83842.6", "0.2025", "0", "1"], ["83842.4", "0.00003928", "0", "2"], ["83842.3", "0.00001501", "0", "1"], ["83842.1", "0.00006538", "0", "1"], ["83842", "0.00018", "0", "1"], ["83841.7", "0.00595948", "0", "1"], ["83841.4", "0.00011803", "0", "3"], ["83840.7", "0.35776874", "0", "1"], ["83840.1", "0.00595948", "0", "1"], ["83840", "0.00029869", "0", "2"], ["83839.9", "0.00007308", "0", "1"], ["83839", "0.00001308", "0", "1"], ["83838.8", "0.08948989", "0", "2"], ["83838.3", "0.17998725", "0", "2"], ["83838", "0.0015", "0", "1"], ["83837.8", "0.00001199", "0", "1"], ["83837.7", "0.07165719", "0", "1"], ["83837.5", "0.51768277", "0", "1"], ["83837.4", "1.57648", "0", "1"], ["83837.2", "0.00003224", "0", "1"], ["83836.6", "0.00003296", "0", "1"], ["83836.5", "0.00012802", "0", "1"], ["83836.3", "0.00579988", "0", "1"], ["83836.2", "0.14313614", "0", "2"], ["83835.4", "0.00103978", "0", "1"], ["83834.6", "0.30065955", "0", "2"], ["83834.5", "0.51889794", "0", "2"], ["83834.2", "0.2025", "0", "1"], ["83834", "0.00013099", "0", "1"], ["83833.9", "0.00001501", "0", "1"], ["83833.3", "0.0015914", "0", "9"], ["83833.2", "0.000015", "0", "1"], ["83832.9", "0.00002955", "0", "2"], ["83832.6", "0.00001199", "0", "1"], ["83832.1", "0.35776874", "0", "1"], ["83831.6", "0.19530534", "0", "3"], ["83831.4", "0.05732575", "0", "1"], ["83831", "0.00004167", "0", "1"], ["83830.1", "0.00595991", "0", "1"], ["83830", "0.00005835", "0", "2"], ["83829.9", "0.17901312", "0", "2"], ["83828.9", "0.02068", "0", "1"], ["83828.7", "0.01148", "0", "1"], ["83828", "0.00589976", "0", "1"], ["83827.7", "0.08991011", "0", "1"], ["83827.5", "0.04971356", "0", "1"], ["83827", "0.00011161", "0", "1"], ["83826.8", "0.00589976", "0", "1"], ["83826.5", "0.00040898", "0", "2"], ["83826.1", "0.00015468", "0", "1"], ["83825.9", "0.00001586", "0", "1"], ["83825.8", "0.2025", "0", "1"], ["83825.5", "0.000015", "0", "1"], ["83825.4", "0.00001365", "0", "1"], ["83825.1", "0.0166188", "0", "1"], ["83825", "0.00008012", "0", "2"], ["83824.2", "0.11889794", "0", "1"], ["83824.1", "0.00589976", "0", "1"], ["83823.6", "0.35776874", "0", "1"], ["83823.5", "0.00039533", "0", "1"], ["83823.1", "3.93999", "0", "1"], ["83823", "0.10001199", "0", "2"], ["83822.9", "0.00298666", "0", "1"], ["83822.5", "0.00003465", "0", "2"], ["83822.4", "0.00001007", "0", "1"], ["83822.2", "0.00889801", "0", "2"], ["83822", "0.00001994", "0", "1"], ["83821.8", "0.00033901", "0", "2"], ["83821.6", "0.00083", "0", "1"], ["83821.5", "0.17898725", "0", "1"], ["83820.8", "0.01159908", "0", "2"], ["83820.3", "0.00589976", "0", "1"], ["83820.2", "0.00083", "0", "1"], ["83820", "0.00021617", "0", "3"], ["83819.9", "0.00012246", "0", "2"], ["83819.7", "0.00580009", "0", "1"], ["83819.6", "0.1", "0", "1"], ["83819.5", "0.01788468", "0", "3"], ["83819.4", "0.00014808", "0", "2"], ["83819.2", "0.01193609", "0", "3"], ["83819.1", "0.00596073", "0", "1"], ["83818.9", "0.00006774", "0", "2"], ["83818.1", "0.00006813", "0", "3"], ["83818", "0.00001199", "0", "1"], ["83817.7", "0.18356731", "0", "1"], ["83817.6", "0.02384342", "0", "3"], ["83817.5", "0.00589976", "0", "1"], ["83817.4", "0.20846073", "0", "2"], ["83817.1", "0.00001501", "0", "1"], ["83817", "0.00579954", "0", "1"], ["83816.9", "0.00126817", "0", "1"], ["83816.6", "0.01252957", "0", "3"], ["83815.9", "0.00004266", "0", "1"], ["83815.3", "0.0060847", "0", "2"], ["83815.2", "0.00596073", "0", "1"], ["83815.1", "0.09536976", "0", "2"], ["83815", "3.87122186", "0", "4"], ["83814.9", "0.0073937", "0", "2"], ["83814.7", "0.00580009", "0", "1"], ["83814.6", "0.00596073", "0", "1"], ["83814.5", "0.11676658", "0", "2"], ["83814.4", "0.00595495", "0", "2"], ["83814.1", "0.00003395", "0", "1"], ["83813.5", "0.00598187", "0", "2"], ["83813.4", "0.00596156", "0", "1"], ["83813.1", "0.00581153", "0", "2"], ["83812.5", "0.00667459", "0", "3"], ["83812", "0.01192152", "0", "2"], ["83811.9", "0.0010552", "0", "1"], ["83811.5", "0.01192312", "0", "2"], ["83811.3", "0.00074812", "0", "1"], ["83810.1", "0.00001655", "0", "1"], ["83809.9", "0.0054", "0", "1"], ["83809.8", "0.00013882", "0", "1"], ["83809.7", "0.00001075", "0", "1"], ["83809.6", "0.00596089", "0", "1"], ["83809.5", "0.00579954", "0", "1"], ["83809.4", "0.01778243", "0", "4"], ["83809.3", "0.00589976", "0", "1"], ["83809", "0.2025", "0", "1"], ["83808.7", "0.00001501", "0", "1"], ["83808.2", "0.00001199", "0", "1"], ["83808", "0.00015274", "0", "2"], ["83807.9", "0.00001018", "0", "1"], ["83807.6", "0.04192312", "0", "3"], ["83807.4", "0.23827629", "0", "2"], ["83807.3", "0.00011161", "0", "1"], ["83807.1", "0.00001527", "0", "1"], ["83806.6", "0.00001217", "0", "1"], ["83806.1", "0.00895999", "0", "1"], ["83805.6", "0.00001394", "0", "1"], ["83805.5", "0.00599165", "0", "2"], ["83805.4", "1.15105906", "0", "2"], ["83805.2", "0.00001069", "0", "1"], ["83805", "0.17920146", "0", "2"], ["83804.9", "0.35776874", "0", "1"], ["83804.7", "0.08991011", "0", "1"], ["83804.4", "0.00579954", "0", "1"], ["83803.2", "0.00597692", "0", "2"], ["83803.1", "0.00589953", "0", "1"], ["83802.6", "0.00024991", "0", "1"], ["83801.7", "0.00003263", "0", "1"], ["83800.9", "0.00589976", "0", "1"], ["83800.6", "0.2025", "0", "1"], ["83800.5", "0.00004114", "0", "2"], ["83800.3", "0.000015", "0", "1"], ["83800", "0.4943161", "0", "57"], ["83799.9", "0.00496882", "0", "7"], ["83799.3", "0.21457", "0", "1"], ["83798.5", "0.00002012", "0", "1"], ["83798.3", "0.00001199", "0", "1"], ["83798", "0.183573", "0", "1"], ["83797.7", "0.01194665", "0", "1"], ["83797.6", "0.00595724", "0", "1"], ["83796.5", "0.00011447", "0", "2"], ["83795.8", "0.01169907", "0", "2"], ["83795.7", "0.35776874", "0", "1"], ["83795.4", "0.00002996", "0", "1"], ["83794.7", "0.00028726", "0", "3"]], "ts": "1742576770201", "checksum": 1640188354, "seqId": 49944833368, "prevSeqId": -1}], "record_time": 1742576770.37948, "EXCHANGE": "OKX"}
{"arg": {"channel": "books", "instId": "BTC-USDT"}, "action": "update", "data": [{"asks": [["83937.1", "2.02303567", "0", "14"], ["83937.9", "0.07348886", "0", "2"], ["83939.6", "0.1191905", "0", "1"], ["83941.7", "0.03095199", "0", "2"], ["83948.3", "0", "0", "0"], ["83949.9", "0.31521246", "0", "2"], ["83951", "0.01153238", "0", "1"], ["83953", "0.12509", "0", "1"], ["83953.1", "0", "0", "0"], ["83954", "0.18056632", "0", "1"], ["83957", "0.00001501", "0", "1"], ["83959.5", "0.44743567", "0", "1"], ["83959.6", "0", "0", "0"], ["83960.4", "0", "0", "0"], ["83961.2", "0.23840815", "0", "1"], ["83961.5", "1.11890993", "0", "3"], ["83981.6", "0.1", "0", "1"], ["83995", "0", "0", "0"], ["83997.9", "0", "0", "0"], ["83998.8", "0.00002157", "0", "1"]], "bids": [["83936.5", "0.11919479", "0", "1"], ["83934", "0.0439", "0", "1"], ["83932.6", "0", "0", "0"], ["83930.3", "0.07623595", "0", "1"], ["83928.6", "0.2025", "0", "1"], ["83924.3", "0.60187212", "0", "2"], ["83921.9", "0.07676", "0", "3"], ["83920.5", "1.3565323", "0", "2"], ["83920", "0.39032947", "0", "3"], ["83917.8", "0.06973194", "0", "2"], ["83917.2", "0", "0", "0"], ["83916.3", "0.000144", "0", "1"], ["83915.6", "0.04128", "0", "1"], ["83905.6", "0.23841238", "0", "1"], ["83901.9", "0.002", "0", "1"], ["83870.6", "0.08991011", "0", "1"], ["83869.9", "0.00100722", "0", "1"], ["83868.5", "0.00363995", "0", "2"], ["83849", "0.00018325", "0", "1"], ["83848.2", "0", "0", "0"], ["83842.9", "0.01192882", "0", "2"], ["83817.6", "0.01192312", "0", "2"], ["83797.6", "0", "0", "0"], ["83796.5", "0", "0", "0"], ["83795.8", "0", "0", "0"], ["83795.7", "0", "0", "0"], ["83795.4", "0", "0", "0"], ["83794.7", "0", "0", "0"]], "ts": "1742576770301", "checksum": 1975479206, "seqId": 49944833444, "prevSeqId": 49944833368}], "record_time": 1742576770.477024, "EXCHANGE": "OKX"}
{"arg": {"channel": "books", "instId": "BTC-USDT"}, "action": "update", "data": [{"asks": [["83936.6", "0.96744718", "0", "12"], ["83936.8", "0.07887911", "0", "1"], ["83937", "0.00112014", "0", "1"], ["83937.1", "0.01031", "0", "1"], ["83937.9", "0", "0", "0"], ["83939.9", "0.0015", "0", "1"], ["83940.3", "0.02878232", "0", "1"], ["83945.6", "0", "0", "0"], ["83945.9", "0", "0", "0"], ["83949.7", "0.17871", "0", "1"], ["83961.2", "0", "0", "0"], ["83961.5", "1.12248269", "0", "4"], ["83962.6", "0.23840348", "0", "1"], ["83981.6", "0", "0", "0"], ["84134.6", "0", "0", "0"]], "bids": [["83937", "0", "0", "0"], ["83936.5", "0.21485174", "0", "4"], ["83932.1", "0.08348624", "0", "2"], ["83930.3", "0", "0", "0"], ["83928.6", "0.17898725", "0", "1"], ["83928.5", "0.14523901", "0", "2"], ["83928.4", "0.00056101", "0", "1"], ["83928.1", "0.2025", "0", "1"], ["83922.1", "0.04", "0", "1"], ["83917.8", "0.02973194", "0", "1"], ["83914.5", "0.18772768", "0", "1"], ["83907.7", "0.23840428", "0", "1"], ["83905.6", "0", "0", "0"], ["83887.7", "0.00005849", "0", "1"], ["83798.3", "0", "0", "0"], ["83798", "0", "0", "0"], ["83797.7", "0", "0", "0"]], "ts": "1742576770401", "checksum": 770404885, "seqId": 49944833577, "prevSeqId": 49944833444}], "record_time": 1742576770.57703, "EXCHANGE": "OKX"}
{"arg": {"channel": "books", "instId": "BTC-USDT"}, "action": "update", "data": [{"asks": [["83936.6", "0.97897956", "0", "13"], ["83945.6", "0.002715", "0", "1"], ["83950.6", "0.35741", "0", "1"], ["83951", "0", "0", "0"], ["83962.6", "0", "0", "0"], ["83962.7", "0.75176674", "0", "2"], ["83962.9", "1.53838962", "0", "1"], ["83965.6", "0.23840193", "0", "1"], ["83977.6", "0.13719634", "0", "3"], ["83978.4", "0.03999999", "0", "1"], ["83979.2", "0", "0", "0"], ["83980", "0.00005736", "0", "1"], ["83981.1", "0.1", "0", "1"], ["84133.3", "0", "0", "0"], ["84133.5", "0", "0", "0"], ["84134.5", "0", "0", "0"]], "bids": [["83936.5", "0.12522207", "0", "3"], ["83926", "0.04743241", "0", "2"], ["83922.4", "1", "0", "1"], ["83921.7", "0.05203868", "0", "3"], ["83920.5", "0.3565323", "0", "1"], ["83905.9", "0.31", "0", "1"], ["83902.4", "0.08", "0", "2"], ["83901.6", "0.04", "0", "1"], ["83900.8", "0", "0", "0"], ["83799.3", "0", "0", "0"], ["83798.5", "0", "0", "0"]], "ts": "1742576770501", "checksum": -287563013, "seqId": 49944833608, "prevSeqId": 49944833577}], "record_time": 1742576770.677138, "EXCHANGE": "OKX"}
{"arg": {"channel": "books", "instId": "BTC-USDT"}, "action": "update", "data": [{"asks": [["83936.8", "0.04899969", "0", "1"], ["83939.6", "0", "0", "0"], ["83942", "0.11918717", "0", "1"], ["83958.4", "0.49840295", "0", "2"], ["83959.5", "0", "0", "0"], ["83962.6", "0.01774536", "0", "1"], ["83962.9", "0", "0", "0"], ["83968", "0.2", "0", "1"], ["83971.2", "0.0004", "0", "1"], ["83980.3", "0.02283169", "0", "1"], ["83992.3", "0", "0", "0"], ["84035.3", "0.00589999", "0", "1"], ["84133.1", "0", "0", "0"]], "bids": [["83936.5", "0.21182207", "0", "4"], ["83932.1", "0.08774197", "0", "1"], ["83928.5", "0.14936701", "0", "2"], ["83926", "0.0439", "0", "1"], ["83924.4", "0.01376", "0", "1"], ["83921.9", "0.063", "0", "2"], ["83916.3", "0", "0", "0"], ["83901.8", "0", "0", "0"], ["83872.5", "0.000012", "0", "1"], ["83799.3", "0.21457", "0", "1"]], "ts": "1742576770601", "checksum": -1762091271, "seqId": 49944833643, "prevSeqId": 49944833608}], "record_time": 1742576770.778311, "EXCHANGE": "OKX"}
{"arg": {"channel": "books", "instId": "BTC-USDT"}, "action": "update", "data": [{"asks": [["83938.7", "0.00710483", "0", "7"], ["83958.2", "1.53758582", "0", "1"], ["83958.4", "0.22674623", "0", "1"], ["83961.5", "0.12248269", "0", "3"], ["83962.7", "0.30088779", "0", "1"], ["83965.6", "0", "0", "0"], ["83966.5", "0.23839618", "0", "1"], ["83968", "0", "0", "0"], ["83968.8", "0.0008", "0", "2"], ["83969.6", "0.0004", "0", "1"], ["83970.4", "0", "0", "0"], ["83971.2", "0", "0", "0"], ["83987.6", "2.73077164", "0", "1"], ["83992.2", "0", "0", "0"], ["84104", "0.00118464", "0", "1"], ["84132.8", "0", "0", "0"]], "bids": [["83936.5", "0.12522207", "0", "3"], ["83928.5", "0.0918299", "0", "1"], ["83928.1", "0", "0", "0"], ["83918.8", "0.0044685", "0", "1"], ["83911.9", "0.23839618", "0", "1"], ["83911.8", "0.44142178", "0", "3"], ["83909", "0.2", "0", "1"], ["83907.7", "0", "0", "0"], ["83907.6", "0.57936715", "0", "2"], ["83907", "1.005", "0", "2"], ["83903.8", "1.60131412", "0", "1"], ["83903.4", "0.42004748", "0", "2"], ["83901.6", "0.0408", "0", "3"], ["83900.8", "0.00039918", "0", "1"], ["83886.4", "0.026", "0", "2"], ["83885.6", "0.013", "0", "1"], ["83874.4", "2.84848997", "0", "1"], ["83873.5", "0.37279077", "0", "1"], ["83859.7", "0.22318", "0", "2"], ["83800.3", "0", "0", "0"], ["83800", "0", "0", "0"], ["83799.9", "0", "0", "0"], ["83799.3", "0", "0", "0"]], "ts": "1742576770701", "checksum": 1927711884, "seqId": 49944833690, "prevSeqId": 49944833643}], "record_time": 1742576770.876925, "EXCHANGE": "OKX"}
{"arg": {"channel": "books", "instId": "BTC-USDT"}, "action": "update", "data": [{"asks": [["83936.6", "0.97872095", "0", "13"], ["83958.1", "0.70402197", "0", "2"], ["83958.4", "0", "0", "0"], ["83962.6", "0", "0", "0"], ["83965.6", "0.23839898", "0", "1"], ["83966.5", "0", "0", "0"], ["83987.5", "1.28735903", "0", "1"], ["83988.3", "0", "0", "0"], ["84035.3", "0.02364535", "0", "2"], ["84132.8", "0.00002013", "0", "1"], ["84133.1", "0.08991011", "0", "1"]], "bids": [["83928.5", "0.14936701", "0", "2"], ["83928.1", "0.2025", "0", "1"], ["83911.9", "0", "0", "0"], ["83911.8", "0.55816599", "0", "2"], ["83909.1", "0.23839898", "0", "1"], ["83907.6", "1.01609342", "0", "1"], ["83878.1", "1.02479663", "0", "2"], ["83848.2", "0.0021389", "0", "1"], ["83800.6", "0", "0", "0"], ["83800.5", "0", "0", "0"]], "ts": "1742576770801", "checksum": 667234898, "seqId": 49944833723, "prevSeqId": 49944833690}], "record_time": 1742576770.981089, "EXCHANGE": "OKX"}
{"arg": {"channel": "books", "instId": "BTC-USDT"}, "action": "snapshot", "data": [{"asks": [["83951.6", "0.53040714", "0", "8"], ["83952", "0.0439", "0", "1"], ["83952.9", "0.00507319", "0", "5"], ["83953.9", "0.10796527", "0", "2"], ["83954", "0.0439", "0", "1"], ["83954.2", "0.00056084", "0", "1"], ["83956", "0.0439", "0", "1"], ["83956.5", "0.00001199", "0", "1"], ["83957", "0.11918083", "0", "2"], ["83957.1", "0.0119175", "0", "1"], ["83957.2", "0.00774241", "0", "1"], ["83957.4", "0.02964377", "0", "1"], ["83957.5", "0.002", "0", "1"], ["83957.6", "0.04084853", "0", "1"], ["83957.7", "0.02", "0", "1"], ["83957.9", "0.1245066", "0", "4"], ["83959.1", "0.01037", "0", "1"], ["83959.2", "0.17215733", "0", "1"], ["83959.7", "0.04293364", "0", "1"], ["83961.3", "0.3565323", "0", "1"], ["83961.5", "0.11890993", "0", "2"], ["83961.6", "0.01", "0", "2"], ["83962.2", "0.24049994", "0", "2"], ["83962.4", "0.00353378", "0", "1"], ["83962.5", "0.02344883", "0", "2"], ["83963.4", "0.04", "0", "1"], ["83963.8", "0.17898725", "0", "1"], ["83964", "0.0000105", "0", "1"], ["83964.4", "0.35746161", "0", "2"], ["83964.5", "0.2025", "0", "1"], ["83964.8", "0.17867", "0", "1"], ["83965.4", "0.000015", "0", "1"], ["83965.8", "0.00774271", "0", "1"], ["83966.1", "0.06", "0", "2"], ["83966.4", "0.00001199", "0", "1"], ["83966.6", "0.00101534", "0", "2"], ["83966.7", "0.07111", "0", "2"], ["83966.8", "0.15635134", "0", "2"], ["83968.4", "0.1126366", "0", "2"], ["83968.6", "0.135151", "0", "1"], ["83969.1", "0.000015", "0", "1"], ["83969.5", "0.12", "0", "4"], ["83969.6", "0.14079576", "0", "1"], ["83970.2", "0.11914709", "0", "1"], ["83970.9", "0.76486069", "0", "2"], ["83971", "0.3565323", "0", "1"], ["83971.4", "0.00001199", "0", "1"], ["83971.6", "1.57621258", "0", "1"], ["83973.1", "0.17898725", "0", "1"], ["83973.2", "0.12507", "0", "1"], ["83973.4", "0.01774536", "0", "1"], ["83973.5", "0.14273212", "0", "2"], ["83973.8", "0.20401501", "0", "3"], ["83974", "0.19963613", "0", "2"], ["83974.6", "1", "0", "1"], ["83975.5", "0.01190824", "0", "1"], ["83976.3", "0.00001199", "0", "1"], ["83976.4", "0.02159369", "0", "1"], ["83976.6", "0.01", "0", "1"], ["83976.8", "0.52183", "0", "1"], ["83978.3", "0.14079576", "0", "1"], ["83978.9", "0.17223269", "0", "3"], ["83979.1", "0.001787", "0", "1"], ["83979.5", "0.2672229", "0", "1"], ["83979.6", "0.3565323", "0", "1"], ["83979.9", "0.00872587", "0", "1"], ["83980", "0.00005736", "0", "1"], ["83980.3", "0.01190756", "0", "1"], ["83980.6", "0.11913234", "0", "1"], ["83981.3", "0.00001199", "0", "1"], ["83981.6", "0.0008", "0", "2"], ["83981.9", "0.29788519", "0", "2"], ["83982.2", "0.202515", "0", "2"], ["83982.4", "0.48425626", "0", "3"], ["83982.9", "0.01190719", "0", "1"], ["83983", "0.01190718", "0", "1"], ["83983.3", "0.00060645", "0", "1"], ["83984.1", "0.01201863", "0", "2"], ["83984.2", "0.23834288", "0", "1"], ["83984.3", "0.31616659", "0", "1"], ["83984.5", "0.25014", "0", "1"], ["83984.6", "0.0000595", "0", "1"], ["83984.8", "0.56532021", "0", "1"], ["83986.2", "0.00001199", "0", "1"], ["83987", "0.00001", "0", "1"], ["83989.2", "0.50694336", "0", "1"], ["83989.3", "0.9718266", "0", "4"], ["83989.4", "0.3565323", "0", "1"], ["83989.6", "0.08357299", "0", "3"], ["83990.4", "0.03999999", "0", "1"], ["83990.5", "0.11889794", "0", "1"], ["83990.6", "0.202515", "0", "2"], ["83991.1", "0.00002737", "0", "1"], ["83991.2", "0.00001199", "0", "1"], ["83992", "0.0001723", "0", "1"], ["83992.3", "0.02096926", "0", "1"], ["83992.6", "0.01915497", "0", "1"], ["83992.9", "0.00103317", "0", "1"], ["83994.2", "0.12507", "0", "1"], ["83994.5", "0.02382253", "0", "1"], ["83994.9", "0.08957793", "0", "2"], ["83995.1", "0.01", "0", "1"], ["83995.3", "0.00002737", "0", "1"], ["83995.9", "0.17898725", "0", "1"], ["83996.1", "0.1", "0", "1"], ["83996.2", "0.00001199", "0", "1"], ["83997.1", "0.00083261", "0", "1"], ["83997.4", "0.41040515", "0", "1"], ["83997.5", "0.4", "0", "1"], ["83997.7", "0.001723", "0", "1"], ["83998.3", "0.03", "0", "1"], ["83998.4", "0.07740141", "0", "2"], ["83999", "0.00001501", "0", "1"], ["83999.1", "0.32139794", "0", "2"], ["83999.6", "0.00589969", "0", "1"], ["83999.7", "0.3565323", "0", "1"], ["83999.9", "0.0051126", "0", "6"], ["84000", "0.38773756", "0", "5"], ["84001", "2.88750639", "0", "1"], ["84001.1", "0.00001198", "0", "1"], ["84001.4", "0.11597977", "0", "1"], ["84003.1", "0.01786613", "0", "1"], ["84003.7", "0.00011161", "0", "1"], ["84004.2", "0.32919665", "0", "2"], ["84005.3", "0.00589969", "0", "1"], ["84005.4", "0.08991011", "0", "1"], ["84005.5", "0.25015", "0", "1"], ["84005.6", "0.06", "0", "2"], ["84005.7", "0.03", "0", "1"], ["84006.1", "0.00001198", "0", "1"], ["84006.8", "0.00595711", "0", "1"], ["84006.9", "0.17898725", "0", "1"], ["84007.4", "0.000015", "0", "1"], ["84007.5", "0.2025", "0", "1"], ["84008", "0.11889794", "0", "1"], ["84008.1", "0.3565323", "0", "1"], ["84008.7", "0.03499749", "0", "2"], ["84008.8", "0.04765399", "0", "1"], ["84009.1", "0.00595711", "0", "1"], ["84010.6", "0.00002157", "0", "1"], ["84010.7", "0.05954482", "0", "1"], ["84011", "0.00001198", "0", "1"], ["84011.1", "0.00001501", "0", "1"], ["84013.6", "0.00589969", "0", "1"], ["84013.7", "0.00595626", "0", "1"], ["84015.8", "0.1146467", "0", "2"], ["84015.9", "0.2025", "0", "1"], ["84016", "0.17899923", "0", "2"], ["84016.5", "0.00595626", "0", "1"], ["84016.6", "0.00060645", "0", "1"], ["84016.8", "0.20679367", "0", "1"], ["84016.9", "0.1", "0", "1"], ["84017.2", "0.3565323", "0", "1"], ["84017.6", "0.000012", "0", "1"], ["84018.7", "0.82515", "0", "1"], ["84019.3", "0.01133662", "0", "1"], ["84019.4", "0.00589969", "0", "1"], ["84019.5", "0.1", "0", "1"], ["84020.5", "0.21889794", "0", "2"], ["84021.1", "0.14282132", "0", "2"], ["84021.4", "1.1845592", "0", "1"], ["84021.5", "3.46232", "0", "2"], ["84022.9", "0.43692", "0", "1"], ["84023.3", "0.00011161", "0", "1"], ["84023.4", "0.01484", "0", "1"], ["84023.7", "0.08991011", "0", "1"], ["84023.8", "0.0238282", "0", "1"], ["84024.2", "0.000015", "0", "1"], ["84024.3", "0.2025", "0", "1"], ["84024.6", "0.02382581", "0", "1"], ["84025.1", "0.17898725", "0", "1"], ["84025.8", "0.0015", "0", "1"], ["84025.9", "0.000012", "0", "1"], ["84026.1", "0.13289296", "0", "1"], ["84026.4", "0.3565323", "0", "1"], ["84026.6", "0.0001749", "0", "1"], ["84026.7", "0.00589969", "0", "1"], ["84027.7", "0.00007589", "0", "1"], ["84027.9", "0.01191838", "0", "1"], ["84029.3", "0.00590009", "0", "1"], ["84029.4", "0.00119005", "0", "1"], ["84029.6", "0.03", "0", "1"], ["84029.9", "0.000012", "0", "1"], ["84030", "0.0325", "0", "2"], ["84031", "0.0025", "0", "1"], ["84031.3", "0.11489508", "0", "1"], ["84031.4", "0.11902446", "0", "2"], ["84031.5", "0.00103744", "0", "1"], ["84031.8", "0.044983", "0", "1"], ["84032", "0.00298666", "0", "1"], ["84032.5", "0.00075763", "0", "1"], ["84032.6", "0.000015", "0", "1"], ["84032.7", "0.2025", "0", "1"], ["84033", "0.005", "0", "2"], ["84033.3", "0.00101534", "0", "2"], ["84033.4", "0.03", "0", "1"], ["84034.2", "0.00589969", "0", "1"], ["84034.3", "0.01169929", "0", "2"], ["84035", "0.01427975", "0", "1"], ["84035.4", "0.16065947", "0", "1"], ["84035.5", "0.17898725", "0", "1"], ["84035.8", "0.000012", "0", "1"], ["84035.9", "0.0000597", "0", "1"], ["84036", "0.3565323", "0", "1"], ["84037", "0.0214", "0", "1"], ["84037.6", "0.08349442", "0", "1"], ["84038.4", "0.00580002", "0", "1"], ["84038.6", "0.00590006", "0", "1"], ["84038.7", "0.0054", "0", "1"], ["84039", "0.67687556", "0", "2"], ["84039.1", "0.72697213", "0", "1"], ["84039.2", "0.0428", "0", "2"], ["84039.3", "0.0214", "0", "1"], ["84039.4", "0.00579972", "0", "1"], ["84040.6", "0.11889794", "0", "1"], ["84040.8", "1.22178032", "0", "3"], ["84040.9", "0.00589969", "0", "1"], ["84041", "0.005815", "0", "2"], ["84041.1", "0.2025", "0", "1"], ["84041.3", "0.05732575", "0", "1"], ["84042.3", "0.000012", "0", "1"], ["84042.4", "0.23192292", "0", "1"], ["84042.7", "0.01652", "0", "1"], ["84042.8", "0.00589981", "0", "1"], ["84043", "0.00011161", "0", "1"], ["84043.9", "0.03573289", "0", "1"], ["84044.9", "0.17898725", "0", "1"], ["84045.2", "0.07760912", "0", "2"], ["84045.6", "0.08991011", "0", "1"], ["84046", "0.3837323", "0", "3"], ["84046.4", "0.07166249", "0", "1"], ["84046.6", "1.25402088", "0", "2"], ["84046.7", "3.93236", "0", "1"], ["84048", "0.0015", "0", "1"], ["84049.2", "0.00895999", "0", "1"], ["84049.5", "0.2025", "0", "1"], ["84049.9", "0.00060645", "0", "1"], ["84050", "0.00018518", "0", "2"], ["84050.4", "0.34361149", "0", "2"], ["84050.5", "0.11889794", "0", "1"], ["84050.7", "0.000012", "0", "1"], ["84051.3", "0.08767", "0", "1"], ["84051.7", "0.61647", "0", "1"], ["84052", "0.0015", "0", "1"], ["84052.6", "0.00001738", "0", "1"], ["84053.1", "0.00001501", "0", "1"], ["84053.6", "0.17898725", "0", "1"], ["84053.9", "0.03", "0", "1"], ["84055.5", "0.20791571", "0", "1"], ["84055.6", "0.3565443", "0", "2"], ["84057.1", "0.00007544", "0", "2"], ["84057.4", "0.00009384", "0", "1"], ["84057.5", "0.06", "0", "2"], ["84057.6", "0.01194665", "0", "1"], ["84057.9", "0.20252241", "0", "2"], ["84058.8", "0.00002902", "0", "1"], ["84060.6", "0.000012", "0", "1"], ["84062.1", "0.19126236", "0", "3"], ["84062.2", "0.6142", "0", "2"], ["84062.4", "0.02850514", "0", "3"], ["84062.6", "0.00011161", "0", "1"], ["84063.7", "0.17898725", "0", "1"], ["84063.8", "0.11889794", "0", "1"], ["84064.4", "0.70769468", "0", "3"], ["84064.5", "0.3707323", "0", "2"], ["84065.1", "0.00594", "0", "1"], ["84065.2", "0.00008584", "0", "1"], ["84065.4", "0.067448", "0", "1"], ["84065.6", "0.00001199", "0", "1"], ["84065.8", "0.03", "0", "1"], ["84066", "0.01493332", "0", "1"], ["84066.3", "1.84575", "0", "2"], ["84066.6", "0.00504382", "0", "4"], ["84067", "0.002395", "0", "2"], ["84067.3", "0.30051565", "0", "1"], ["84067.4", "0.21414", "0", "1"], ["84068.4", "0.05361054", "0", "1"], ["84068.5", "0.5999", "0", "1"], ["84069.1", "0.11900691", "0", "1"], ["84069.7", "0.00011444", "0", "1"], ["84071.2", "0.0142", "0", "1"], ["84071.4", "0.00001362", "0", "1"], ["84072.2", "0.00002016", "0", "1"], ["84072.6", "0.08998825", "0", "2"], ["84072.7", "0.25709214", "0", "1"], ["84072.8", "0.11889794", "0", "1"], ["84073", "0.3565323", "0", "1"], ["84073.2", "0.17898725", "0", "1"], ["84074.7", "0.2025", "0", "1"], ["84075", "0.00004433", "0", "1"], ["84075.5", "0.00001199", "0", "1"], ["84076.5", "0.00010284", "0", "1"], ["84076.8", "0.00001957", "0", "1"], ["84076.9", "0.00009125", "0", "1"], ["84077", "0.00008", "0", "1"], ["84078.1", "0.183523", "0", "1"], ["84079", "0.00594", "0", "1"], ["84079.3", "0.00596796", "0", "2"], ["84079.4", "0.00018194", "0", "1"], ["84079.9", "0.00001026", "0", "1"], ["84081.4", "0.00003364", "0", "1"], ["84081.6", "0.00212326", "0", "1"], ["84082.2", "0.17898725", "0", "1"], ["84082.3", "0.00011161", "0", "1"], ["84082.6", "0.00001984", "0", "1"], ["84083", "0.214407", "0", "1"], ["84083.3", "0.00422986", "0", "3"], ["84083.8", "0.3565323", "0", "1"], ["84083.9", "0.08767", "0", "1"], ["84084.2", "0.04064", "0", "2"], ["84085.4", "0.00001199", "0", "1"], ["84085.6", "0.00251777", "0", "1"], ["84085.7", "0.00068775", "0", "1"], ["84086.5", "0.69209544", "0", "1"], ["84087.2", "0.03", "0", "1"], ["84088.2", "0.00011938", "0", "1"], ["84088.5", "0.00003542", "0", "1"], ["84088.8", "0.03", "0", "1"], ["84089.1", "0.00002215", "0", "1"], ["84089.7", "0.0015", "0", "1"], ["84090.2", "0.00074396", "0", "1"], ["84090.4", "0.00002339", "0", "2"], ["84090.8", "0.00376703", "0", "1"], ["84090.9", "0.00003887", "0", "1"], ["84091.1", "0.17898725", "0", "1"], ["84091.2", "0.00001297", "0", "1"], ["84091.7", "0.00001199", "0", "1"], ["84092.9", "0.03", "0", "1"], ["84093.2", "0.3565323", "0", "1"], ["84094.5", "0.31997186", "0", "1"], ["84095.1", "0.000015", "0", "1"], ["84095.5", "0.00351192", "0", "1"], ["84096", "0.00006328", "0", "1"], ["84096.1", "0.01786872", "0", "3"], ["84099.9", "0.00101534", "0", "2"], ["84100", "5.01249374", "0", "6"], ["84100.3", "0.00001199", "0", "1"], ["84101.3", "0.17898725", "0", "1"], ["84101.7", "0.3565323", "0", "1"], ["84101.9", "0.00011161", "0", "1"], ["84103.8", "0.03", "0", "1"], ["84104.1", "0.00001199", "0", "1"], ["84104.2", "0.00594821", "0", "1"], ["84105.2", "0.0000225", "0", "2"], ["84106.6", "0.00001008", "0", "1"], ["84107", "0.00120451", "0", "3"], ["84107.6", "0.00001881", "0", "1"], ["84109", "0.08994305", "0", "2"], ["84110", "0.01232", "0", "1"], ["84110.4", "0.10721", "0", "1"], ["84110.5", "0.3565323", "0", "1"], ["84111.1", "0.00003344", "0", "1"], ["84111.2", "0.00004855", "0", "1"], ["84111.6", "0.0015", "0", "1"], ["84112", "0.00118464", "0", "1"], ["84112.6", "0.00003552", "0", "1"], ["84113.3", "0.17898725", "0", "1"], ["84113.5", "0.00003103", "0", "1"], ["84114", "0.00014547", "0", "1"], ["84115.7", "0.00103744", "0", "1"], ["84116.6", "0.00060645", "0", "1"], ["84117.6", "0.00001805", "0", "1"], ["84118.1", "3.72", "0", "1"], ["84118.2", "0.03", "0", "1"], ["84119", "0.35658448", "0", "2"], ["84119.4", "0.08761", "0", "1"], ["84120", "0.00006444", "0", "2"], ["84120.1", "0.00001197", "0", "1"], ["84121.5", "0.00011161", "0", "1"], ["84121.8", "0.14265032", "0", "2"], ["84122.2", "0.17898725", "0", "1"], ["84123.6", "0.00126715", "0", "1"], ["84123.7", "0.00005514", "0", "1"], ["84125", "0.00009264", "0", "1"], ["84125.1", "0.0001387", "0", "1"], ["84125.3", "0.00001956", "0", "1"], ["84126.1", "6.59525189", "0", "1"], ["84126.2", "0.00001805", "0", "1"], ["84126.6", "0.00002004", "0", "1"], ["84127.5", "0.3565323", "0", "1"], ["84130.6", "3.37684", "0", "1"], ["84130.9", "0.03", "0", "1"], ["84131.1", "0.00008649", "0", "2"], ["84132.5", "0.17898725", "0", "1"], ["84132.6", "0.0000434", "0", "1"], ["84132.8", "0.00002013", "0", "1"], ["84133.1", "0.08997412", "0", "2"], ["84133.3", "0.00517228", "0", "9"], ["84133.5", "0.00001277", "0", "1"], ["84134.5", "0.0000103", "0", "1"], ["84134.6", "0.00003392", "0", "1"], ["84135", "0.00001199", "0", "1"], ["84135.7", "0.0000221", "0", "1"], ["84135.8", "0.00007302", "0", "1"], ["84136", "0.3565323", "0", "1"], ["84136.7", "0.00004748", "0", "1"], ["84137.1", "0.00001501", "0", "1"], ["84137.2", "3.88291", "0", "1"], ["84138.8", "0.06044981", "0", "3"], ["84140", "0.00031221", "0", "2"]], "bids": [["83951.5", "0.62450064", "0", "13"], ["83950.3", "0.15606714", "0", "1"], ["83950", "0.0439", "0", "1"], ["83949.8", "0.17317621", "0", "2"], ["83948", "0.0439", "0", "1"], ["83946.9", "0.01367", "0", "1"], ["83946.6", "0.0119175", "0", "1"], ["83946", "0.0439", "0", "1"], ["83945.6", "0.08212042", "0", "2"], ["83945", "0.40088336", "0", "2"], ["83944", "0.0439", "0", "1"], ["83943.9", "0.04293364", "0", "1"], ["83943.1", "0.000015", "0", "1"], ["83942.2", "0.04103", "0", "1"], ["83942", "0.0439", "0", "1"], ["83941.8", "0.20251199", "0", "2"], ["83941.3", "1", "0", "1"], ["83940.4", "0.20153885", "0", "1"], ["83940", "0.04391", "0", "2"], ["83939.6", "0.04", "0", "1"], ["83938.8", "0.00884966", "0", "1"], ["83938.4", "0.00385992", "0", "1"], ["83938.2", "0.17898725", "0", "1"], ["83938", "0.0439", "0", "1"], ["83937.7", "0.03960671", "0", "1"], ["83937.3", "0.03251695", "0", "2"], ["83937.1", "0.3565323", "0", "1"], ["83937", "0.20630407", "0", "2"], ["83936.9", "0.036", "0", "1"], ["83936.8", "0.00001199", "0", "1"], ["83936.6", "0.000039", "0", "1"], ["83936", "0.0439", "0", "1"], ["83935.6", "0.00006", "0", "1"], ["83935.5", "0.11919626", "0", "1"], ["83935.1", "0.005", "0", "1"], ["83935", "0.002", "0", "1"], ["83934.7", "0.000015", "0", "1"], ["83934", "0.2439", "0", "3"], ["83933.9", "0.00385992", "0", "1"], ["83933.4", "0.2025", "0", "1"], ["83933.3", "0.00060645", "0", "1"], ["83932.8", "0.97104325", "0", "2"], ["83932.2", "0.01192075", "0", "1"], ["83932.1", "0.17867", "0", "1"], ["83932", "0.0439", "0", "1"], ["83931.9", "0.14883599", "0", "3"], ["83931.6", "0.38118507", "0", "2"], ["83931.4", "0.063", "0", "2"], ["83931.1", "0.11920246", "0", "1"], ["83931", "1", "0", "1"], ["83930.4", "0.00357", "0", "1"], ["83930.1", "0.05959609", "0", "1"], ["83929.7", "0.04", "0", "1"], ["83928.7", "0.3565323", "0", "1"], ["83928.6", "0.17898725", "0", "1"], ["83928.1", "0.11633073", "0", "1"], ["83928", "0.141", "0", "4"], ["83927.6", "0.05756563", "0", "1"], ["83927.2", "0.005", "0", "1"], ["83926.9", "0.00001199", "0", "1"], ["83926.5", "0.1126366", "0", "2"], ["83926.3", "0.000015", "0", "1"], ["83925.2", "0.00011161", "0", "1"], ["83925", "0.007", "0", "2"], ["83924.4", "0.23834574", "0", "1"], ["83924.3", "0.33696469", "0", "2"], ["83923.3", "0.28969", "0", "2"], ["83922.5", "0.045042", "0", "1"], ["83922.3", "0.08991011", "0", "1"], ["83922", "0.00037199", "0", "2"], ["83921.6", "0.25014", "0", "1"], ["83921.4", "0.17868", "0", "1"], ["83920.3", "0.3565323", "0", "1"], ["83920.2", "0.17898725", "0", "1"], ["83920", "0.00001", "0", "1"], ["83917.9", "0.51919785", "0", "2"], ["83917.8", "1.58442331", "0", "2"], ["83917.7", "0.0238443", "0", "1"], ["83917", "0.0090988", "0", "2"], ["83916.6", "0.00060645", "0", "1"], ["83916", "0.1126366", "0", "2"], ["83914.6", "0.20042398", "0", "1"], ["83914.5", "0.14079576", "0", "1"], ["83914.4", "0.08", "0", "2"], ["83914", "0.00054", "0", "1"], ["83913.9", "0.009", "0", "1"], ["83913.8", "0.12507", "0", "1"], ["83913.7", "0.5776526", "0", "1"], ["83913.6", "0.04079943", "0", "3"], ["83913.4", "0.01190726", "0", "1"], ["83912.8", "0.02639943", "0", "3"], ["83912", "0.02491944", "0", "3"], ["83911.9", "0.38034679", "0", "3"], ["83911.7", "0.24659", "0", "1"], ["83911.4", "0.55008918", "0", "2"], ["83911.1", "0.17898725", "0", "1"], ["83910.5", "0.11889794", "0", "1"], ["83910.3", "0.12507", "0", "1"], ["83910.2", "0.2299139", "0", "3"], ["83910", "1", "0", "1"], ["83909.5", "0.000015", "0", "1"], ["83909", "0.00036", "0", "1"], ["83908.8", "0.1", "0", "2"], ["83908.2", "0.01190756", "0", "1"], ["83908", "0.05072", "0", "3"], ["83907.1", "0.000012", "0", "1"], ["83906.7", "0.05246", "0", "1"], ["83906.6", "0.58057091", "0", "1"], ["83906.5", "0.59271", "0", "1"], ["83906.3", "0.01155427", "0", "1"], ["83905.9", "0.826259", "0", "1"], ["83905.5", "0.11322493", "0", "4"], ["83904.8", "0.01190824", "0", "1"], ["83904", "0.02116927", "0", "2"], ["83903.6", "0.00190026", "0", "1"], ["83903.5", "0.3565323", "0", "1"], ["83903.4", "0.01153238", "0", "1"], ["83902.5", "0.01835305", "0", "1"], ["83902.4", "0.02488967", "0", "1"], ["83902.1", "0.000012", "0", "1"], ["83902", "0.00001", "0", "1"], ["83901.9", "0.46787841", "0", "1"], ["83901.8", "0.29241011", "0", "2"], ["83901.1", "0.000015", "0", "1"], ["83901", "0.00036", "0", "1"], ["83900.6", "0.78615", "0", "2"], ["83900.5", "0.17898725", "0", "1"], ["83900.3", "0.0249433", "0", "1"], ["83900", "0.00001", "0", "1"], ["83899.9", "0.1418111", "0", "3"], ["83899.8", "0.016", "0", "1"], ["83899.3", "0.11889794", "0", "1"], ["83899", "0.00036", "0", "1"], ["83898.6", "0.57581275", "0", "2"], ["83898.5", "0.471951", "0", "1"], ["83897.8", "0.016", "0", "1"], ["83897.5", "0.01788861", "0", "1"], ["83897.2", "0.000012", "0", "1"], ["83896.7", "0.00357", "0", "1"], ["83895.5", "0.01190928", "0", "1"], ["83895", "0.11001021", "0", "2"], ["83894.9", "0.02385078", "0", "1"], ["83894.4", "0.31014702", "0", "2"], ["83894.3", "0.3565323", "0", "1"], ["83893.8", "0.052", "0", "2"], ["83893.4", "0.001787", "0", "1"], ["83892.8", "0.12507", "0", "1"], ["83892.7", "0.00001501", "0", "1"], ["83892.2", "0.000012", "0", "1"], ["83891.8", "0.17898725", "0", "1"], ["83891.7", "0.2545", "0", "3"], ["83890.9", "0.11889794", "0", "1"], ["83890", "0.00595662", "0", "1"], ["83889.6", "0.92540613", "0", "2"], ["83889.5", "0.08941", "0", "1"], ["83889.3", "0.12507", "0", "1"], ["83888.9", "0.067589", "0", "1"], ["83888.5", "0.00595662", "0", "1"], ["83888.4", "2.80051589", "0", "1"], ["83888.2", "0.036", "0", "1"], ["83888", "0.00025", "0", "1"], ["83887.8", "0.016", "0", "1"], ["83887.7", "0.00005849", "0", "1"], ["83887.3", "0.000012", "0", "1"], ["83887", "0.052", "0", "2"], ["83886.5", "0.22948164", "0", "1"], ["83886.1", "0.00595662", "0", "1"], ["83886", "0.00928245", "0", "1"], ["83885.9", "0.00011161", "0", "1"], ["83885.7", "0.4086792", "0", "1"], ["83884.9", "0.00100684", "0", "1"], ["83884.8", "0.56595662", "0", "2"], ["83884.5", "0.3565323", "0", "1"], ["83884.3", "0.00001501", "0", "1"], ["83883.5", "0.00145251", "0", "1"], ["83883.4", "0.00595662", "0", "1"], ["83883.3", "0.00060645", "0", "1"], ["83882.5", "0.17898725", "0", "1"], ["83882.4", "0.000012", "0", "1"], ["83882.2", "0.00218672", "0", "1"], ["83882", "0.00036", "0", "1"], ["83881.9", "0.01", "0", "1"], ["83880.6", "0.00595662", "0", "1"], ["83880.5", "0.06", "0", "2"], ["83880.3", "0.00001072", "0", "1"], ["83880", "0.06437037", "0", "3"], ["83879.9", "0.20845662", "0", "2"], ["83878.2", "0.58103726", "0", "2"], ["83878.1", "0.90247", "0", "1"], ["83877.4", "0.000012", "0", "1"], ["83877.3", "0.05963948", "0", "1"], ["83876.3", "0.00595632", "0", "1"], ["83876.2", "0.11889794", "0", "1"], ["83876.1", "0.3565323", "0", "1"], ["83875.9", "0.000015", "0", "1"], ["83875.3", "0.000015", "0", "1"], ["83874", "0.4057997", "0", "2"], ["83873.6", "0.08241272", "0", "1"], ["83873.4", "0.17898725", "0", "1"], ["83872.5", "0.000012", "0", "1"], ["83871.7", "0.58226341", "0", "1"], ["83870.6", "0.08991011", "0", "1"], ["83869.8", "0.0057997", "0", "1"], ["83869.6", "0.24407231", "0", "1"], ["83869.5", "0.043961", "0", "1"], ["83868.4", "0.00595708", "0", "1"], ["83868.3", "0.2025", "0", "1"], ["83868.2", "0.0182", "0", "1"], ["83868", "0.06", "0", "2"], ["83867.6", "0.158368", "0", "1"], ["83867.5", "0.000027", "0", "2"], ["83867.4", "0.3565323", "0", "1"], ["83866.7", "0.00721149", "0", "2"], ["83866.6", "0.12924617", "0", "11"], ["83866.2", "0.00011161", "0", "1"], ["83865.8", "0.07594092", "0", "1"], ["83865", "1.26152551", "0", "2"], ["83864.9", "0.17898725", "0", "1"], ["83864.6", "0.08944", "0", "1"], ["83864", "0.00002125", "0", "1"], ["83863.7", "0.0058995", "0", "1"], ["83863.4", "0.00018338", "0", "1"], ["83863.3", "0.00004163", "0", "1"], ["83863.1", "0.00103791", "0", "1"], ["83862.6", "3.95371198", "0", "2"], ["83861.7", "0.0058995", "0", "1"], ["83861.5", "0.00595815", "0", "1"], ["83860", "0.00036", "0", "1"], ["83859.8", "0.01789986", "0", "1"], ["83859.7", "0.22913815", "0", "3"], ["83859.6", "1.218421", "0", "1"], ["83859.2", "0.04468045", "0", "2"], ["83859.1", "0.00001501", "0", "1"], ["83859", "0.03", "0", "1"], ["83858.6", "0.00020004", "0", "1"], ["83858.3", "0.3565323", "0", "1"], ["83858", "0.00036", "0", "1"], ["83857.6", "0.00001198", "0", "1"], ["83857.5", "0.00594034", "0", "2"], ["83857.4", "0.00595815", "0", "1"], ["83857.3", "0.00001198", "0", "1"], ["83857.1", "0.00091322", "0", "4"], ["83857", "0.00631815", "0", "2"], ["83856.4", "0.1431017", "0", "2"], ["83855.3", "0.07165719", "0", "1"], ["83855.1", "0.17898725", "0", "1"], ["83854.8", "0.03", "0", "1"], ["83854.7", "0.00764492", "0", "2"], ["83853.4", "0.00605986", "0", "2"], ["83853.3", "0.11889794", "0", "1"], ["83853", "3.50636", "0", "1"], ["83852.9", "0.08991011", "0", "1"], ["83852.5", "0.00001059", "0", "1"], ["83852", "0.00036", "0", "1"], ["83851.9", "0.01511174", "0", "1"], ["83851.1", "0.06106469", "0", "1"], ["83851", "0.20294214", "0", "3"], ["83850.9", "0.0021391", "0", "1"], ["83850.7", "0.000015", "0", "1"], ["83850.4", "0.00001302", "0", "1"], ["83850.2", "0.0058995", "0", "1"], ["83850.1", "0.00598038", "0", "2"], ["83850", "0.0009247", "0", "5"], ["83849.9", "0.00419995", "0", "2"], ["83849.6", "0.35784874", "0", "2"], ["83848.9", "0.00054698", "0", "1"], ["83848.7", "0.01191774", "0", "1"], ["83848.4", "0.00017177", "0", "1"], ["83847.8", "0.00001319", "0", "1"], ["83847.7", "0.00001199", "0", "1"], ["83847.2", "0.20864", "0", "1"], ["83846.8", "0.00001004", "0", "1"], ["83846.7", "0.17898725", "0", "1"], ["83846.6", "0.00011161", "0", "1"], ["83846.1", "0.00002549", "0", "1"], ["83845", "0.00001198", "0", "1"], ["83844.7", "0.00005731", "0", "1"], ["83844.6", "1.69537794", "0", "2"], ["83844.5", "0.06", "0", "2"], ["83843.8", "0.0357824", "0", "1"], ["83843.6", "0.00579947", "0", "1"], ["83843.1", "0.0058995", "0", "1"], ["83843", "0.00596352", "0", "1"], ["83842.9", "0.00001008", "0", "1"], ["83842.6", "0.2025", "0", "1"], ["83842.4", "0.00003928", "0", "2"], ["83842.3", "0.00001501", "0", "1"], ["83842.1", "0.00006538", "0", "1"], ["83842", "0.00018", "0", "1"], ["83841.7", "0.00595948", "0", "1"], ["83841.4", "0.00011803", "0", "3"], ["83841.2", "0.0836995", "0", "1"], ["83840.9", "0.1", "0", "1"], ["83840.7", "0.35776874", "0", "1"], ["83840.2", "0.00589983", "0", "1"], ["83840.1", "0.00595948", "0", "1"], ["83840", "0.00029869", "0", "2"], ["83839.9", "0.00007308", "0", "1"], ["83839", "0.00001308", "0", "1"], ["83838.8", "0.08948989", "0", "2"], ["83838.3", "0.17998725", "0", "2"], ["83838", "0.0015", "0", "1"], ["83837.8", "0.00001199", "0", "1"], ["83837.2", "0.00003224", "0", "1"], ["83836.7", "0.00579947", "0", "1"], ["83836.6", "0.00003296", "0", "1"], ["83836.5", "0.05745377", "0", "2"], ["83836.4", "0.6", "0", "1"], ["83835.6", "0.00579961", "0", "1"], ["83835.5", "0.0058995", "0", "1"], ["83835.4", "0.00103978", "0", "1"], ["83834.5", "0.12479762", "0", "2"], ["83834.2", "0.2025", "0", "1"], ["83834", "0.00013099", "0", "1"], ["83833.9", "0.00001501", "0", "1"], ["83833.3", "0.0015914", "0", "9"], ["83833.2", "0.00591458", "0", "2"], ["83832.9", "0.00002955", "0", "2"], ["83832.6", "0.00591182", "0", "2"], ["83832.5", "0.00579939", "0", "1"], ["83832.4", "0.1", "0", "1"], ["83832.3", "0.00298666", "0", "1"], ["83832.2", "0.00579947", "0", "1"], ["83832.1", "0.35776874", "0", "1"], ["83831.7", "0.0054", "0", "1"], ["83831.6", "0.12382814", "0", "2"], ["83831", "0.00004167", "0", "1"], ["83830.3", "0.18353263", "0", "1"], ["83830.2", "0.00579961", "0", "1"], ["83830.1", "0.00595991", "0", "1"], ["83830", "0.00585758", "0", "3"], ["83829.9", "0.17901312", "0", "2"], ["83829.4", "0.07166249", "0", "1"], ["83829", "0.00579966", "0", "1"], ["83828.9", "0.02068", "0", "1"], ["83828.7", "0.01148", "0", "1"], ["83828.2", "0.0058995", "0", "1"], ["83828.1", "0.01179955", "0", "2"], ["83827.7", "0.09580979", "0", "2"], ["83827.5", "0.04971356", "0", "1"], ["83827", "0.00011161", "0", "1"], ["83826.9", "0.00579947", "0", "1"], ["83826.8", "0.03", "0", "1"], ["83826.5", "0.00040898", "0", "2"], ["83826.1", "0.00015468", "0", "1"], ["83825.9", "0.00591569", "0", "2"], ["83825.8", "0.2025", "0", "1"], ["83825.5", "0.000015", "0", "1"], ["83825.4", "0.00001365", "0", "1"], ["83825.3", "0.00579961", "0", "1"], ["83825.2", "0.00579951", "0", "1"], ["83825.1", "0.0166188", "0", "1"], ["83825", "0.00008012", "0", "2"], ["83824.2", "0.11889794", "0", "1"], ["83823.9", "0.00597332", "0", "1"], ["83823.6", "0.35776874", "0", "1"], ["83823.5", "0.00039533", "0", "1"], ["83823", "0.00001199", "0", "1"], ["83822.5", "0.00003465", "0", "2"], ["83822.4", "0.00001007", "0", "1"], ["83822.3", "0.01169963", "0", "2"], ["83822.2", "0.00889801", "0", "2"], ["83822", "0.00001994", "0", "1"], ["83821.8", "0.00033901", "0", "2"], ["83821.6", "0.00083", "0", "1"], ["83821.5", "0.19078615", "0", "3"], ["83821.4", "0.00083", "0", "1"], ["83820.5", "0.00579941", "0", "1"], ["83820.4", "0.00579951", "0", "1"], ["83820.2", "0.00083", "0", "1"], ["83820", "0.00021617", "0", "3"], ["83819.9", "0.00012246", "0", "2"], ["83819.7", "0.00580009", "0", "1"], ["83819.4", "0.00014808", "0", "2"], ["83819.2", "0.00001297", "0", "1"], ["83818.9", "0.00006774", "0", "2"], ["83818.1", "0.00006813", "0", "3"], ["83818", "0.00001199", "0", "1"], ["83817.4", "0.2025", "0", "1"], ["83817.1", "0.00001501", "0", "1"], ["83816.9", "0.00126817", "0", "1"], ["83816.7", "0.00579987", "0", "1"], ["83816.6", "0.00060645", "0", "1"], ["83815.9", "0.00594228", "0", "2"], ["83815.8", "0.05366466", "0", "1"], ["83815.5", "0.00895999", "0", "1"], ["83815.3", "0.00018461", "0", "1"], ["83815.1", "0.08947", "0", "1"], ["83815", "0.36356854", "0", "2"], ["83814.9", "0.0073937", "0", "2"], ["83814.7", "0.03", "0", "1"], ["83814.4", "0.00005519", "0", "1"], ["83814.1", "0.00003395", "0", "1"], ["83813.5", "0.00002031", "0", "1"], ["83813.1", "0.00001199", "0", "1"], ["83812.5", "0.00667459", "0", "3"], ["83811.9", "0.0010552", "0", "1"], ["83811.6", "0.00595655", "0", "1"], ["83811.3", "0.00074812", "0", "1"], ["83811.2", "0.183534", "0", "1"]], "ts": "1742576907600", "checksum": -1155931191, "seqId": 49944898247, "prevSeqId": -1}], "record_time": 1742576907.778087, "EXCHANGE": "OKX"}
{"arg": {"channel": "books", "instId": "BTC-USDT"}, "action": "update", "data": [{"asks": [["83973.3", "1", "0", "1"], ["83974.6", "0", "0", "0"]], "bids": [], "ts": "1742576907700", "checksum": -1155931191, "seqId": 49944898249, "prevSeqId": 49944898247}], "record_time": 1742576907.87384, "EXCHANGE": "OKX"}
{"arg": {"channel": "books", "instId": "BTC-USDT"}, "action": "update", "data": [{"asks": [["83973.4", "0", "0", "0"], ["83989", "1", "0", "1"], ["83989.1", "0.01774536", "0", "1"], ["84140", "0", "0", "0"]], "bids": [["83934", "0.1439", "0", "2"]], "ts": "1742576907800", "checksum": -1155931191, "seqId": 49944898253, "prevSeqId": 49944898249}], "record_time": 1742576907.974454, "EXCHANGE": "OKX"}
{"arg": {"channel": "books", "instId": "BTC-USDT"}, "action": "update", "data": [{"asks": [["84023.8", "0", "0", "0"], ["84040.9", "0.02972306", "0", "2"], ["84140", "0.00031221", "0", "2"]], "bids": [["83945", "0.0911946", "0", "1"], ["83941.3", "0", "0", "0"], ["83940.4", "0.49925648", "0", "2"], ["83939.9", "1", "0", "1"], ["83932.8", "0.66334765", "0", "2"], ["83931", "0", "0", "0"], ["83810.9", "1.72263", "0", "1"]], "ts": "1742576907900", "checksum": -1034872808, "seqId": 49944898265, "prevSeqId": 49944898253}], "record_time": 1742576908.073531, "EXCHANGE": "OKX"}
{"arg": {"channel": "books", "instId": "BTC-USDT"}, "action": "update", "data": [{"asks": [["83981.8", "0.01774536", "0", "1"], ["83989.1", "0", "0", "0"]], "bids": [["83951.5", "0.55198064", "0", "12"], ["83940.4", "0.20153885", "0", "1"], ["83939.9", "0", "0", "0"], ["83937", "0.44133858", "0", "1"], ["83936.9", "1.036", "0", "2"], ["83810.1", "0.00001655", "0", "1"]], "ts": "1742576908000", "checksum": -100410115, "seqId": 49944898276, "prevSeqId": 49944898265}], "record_time": 1742576908.173094, "EXCHANGE": "OKX"}
{"arg": {"channel": "books", "instId": "BTC-USDT"}, "action": "update", "data": [{"asks": [["83954.6", "0.01191787", "0", "1"], ["83957.1", "0", "0", "0"], ["83982.1", "0.23834798", "0", "1"], ["83984.2", "0", "0", "0"], ["83988.9", "0.83201525", "0", "1"], ["83989.2", "0", "0", "0"], ["84016.8", "0.45949936", "0", "2"], ["84029.4", "0", "0", "0"], ["84035", "0", "0", "0"], ["84085.6", "0", "0", "0"], ["84140.7", "0.03", "0", "1"], ["84141.1", "0.00005109", "0", "1"], ["84141.2", "0.00011161", "0", "1"]], "bids": [["83951.5", "0.57368814", "0", "13"], ["83946.6", "0", "0", "0"], ["83943.8", "0.01191787", "0", "1"], ["83926.6", "0.23834686", "0", "1"], ["83924.4", "0", "0", "0"], ["83914.6", "0.40017622", "0", "2"], ["83902.4", "0", "0", "0"], ["83883.7", "0.00145257", "0", "1"], ["83883.6", "0.00218669", "0", "1"], ["83883.5", "0", "0", "0"], ["83882.2", "0", "0", "0"], ["83873.6", "0.24679015", "0", "2"], ["83809.8", "0.00013882", "0", "1"]], "ts": "1742576908100", "checksum": -204216935, "seqId": 49944898309, "prevSeqId": 49944898276}], "record_time": 1742576908.273912, "EXCHANGE": "OKX"}
{"arg": {"channel": "books", "instId": "BTC-USDT"}, "action": "update", "data": [{"asks": [["83982.1", "0", "0", "0"], ["83984", "0.23834777", "0", "1"], ["84002", "0.02288178", "0", "1"], ["84021.1", "0.07141066", "0", "1"], ["84121.8", "0.07132516", "0", "1"], ["84141.2", "0", "0", "0"]], "bids": [["83856.4", "0.07155085", "0", "1"], ["83851.9", "0", "0", "0"], ["83809.7", "0.00001075", "0", "1"]], "ts": "1742576908200", "checksum": -204216935, "seqId": 49944898323, "prevSeqId": 49944898309}], "record_time": 1742576908.373596, "EXCHANGE": "OKX"}
{"arg": {"channel": "books", "instId": "BTC-USDT"}, "action": "update", "data": [{"asks": [["83951.6", "0.55146328", "0", "10"], ["83981.8", "0.25609382", "0", "2"], ["83984", "0", "0", "0"], ["83988.9", "0", "0", "0"], ["83989", "0", "0", "0"], ["83990.6", "0.26240563", "0", "3"], ["83994.9", "0.03", "0", "1"], ["84141.2", "0.00011161", "0", "1"], ["84141.7", "0.03", "0", "1"], ["84141.9", "0.00002329", "0", "1"]], "bids": [["83951.5", "0.49668814", "0", "12"], ["83950.3", "0.11609899", "0", "1"], ["83946.9", "0", "0", "0"], ["83944.6", "0.01367", "0", "1"], ["83942.9", "0.0036246", "0", "1"], ["83936.6", "0", "0", "0"], ["83927.6", "0", "0", "0"], ["83923.4", "0.06210308", "0", "1"]], "ts": "1742576908300", "checksum": 1851430854, "seqId": 49944898355, "prevSeqId": 49944898323}], "record_time": 1742576908.47386, "EXCHANGE": "OKX"}
{"arg": {"channel": "books", "instId": "BTC-USDT"}, "action": "update", "data": [{"asks": [["83981.8", "0", "0", "0"], ["83982.1", "0.23834815", "0", "1"], ["83997.3", "0.01774536", "0", "1"], ["84000", "0.18773756", "0", "4"], ["84021.1", "0.14282132", "0", "2"], ["84026.1", "0.13408306", "0", "2"], ["84031.3", "0.12917547", "0", "2"], ["84079.8", "0.00251808", "0", "1"], ["84121.8", "0.14265032", "0", "2"], ["84141.7", "0", "0", "0"], ["84141.9", "0", "0", "0"]], "bids": [["83936.9", "0.036", "0", "1"], ["83936.1", "0.004935", "0", "1"], ["83935.5", "1.11919626", "0", "2"], ["83862.9", "0.01511048", "0", "1"], ["83856.4", "0.1431017", "0", "2"], ["83809.8", "0", "0", "0"], ["83809.7", "0", "0", "0"]], "ts": "1742576908400", "checksum": 1851430854, "seqId": 49944898380, "prevSeqId": 49944898355}], "record_time": 1742576908.573258, "EXCHANGE": "OKX"}
{"arg": {"channel": "books", "instId": "BTC-USDT"}, "action": "update", "data": [{"asks": [["83981.8", "0.23834904", "0", "1"], ["83982.1", "0", "0", "0"]], "bids": [["83926.6", "0", "0", "0"], ["83924.4", "0.23834906", "0", "1"]], "ts": "1742576908500", "checksum": 1851430854, "seqId": 49944898392, "prevSeqId": 49944898380}], "record_time": 1742576908.675755, "EXCHANGE": "OKX"}
{"arg": {"channel": "books", "instId": "BTC-USDT"}, "action": "update", "data": [{"asks": [["83972", "0.01190874", "0", "1"], ["83974", "0.18772768", "0", "1"], ["83975.5", "0", "0", "0"], ["83978.3", "0.1527036", "0", "2"], ["83980.3", "0", "0", "0"], ["83983.8", "0.01190706", "0", "1"]], "bids": [["83936.9", "1.036", "0", "2"], ["83936.1", "0", "0", "0"], ["83935.5", "0.11919626", "0", "1"], ["83918.1", "0.01190874", "0", "1"], ["83913.1", "0.01190706", "0", "1"], ["83911", "0.01190784", "0", "1"], ["83908.2", "0", "0", "0"], ["83904.8", "0", "0", "0"], ["83895.5", "0", "0", "0"], ["83809.8", "0.00013882", "0", "1"]], "ts": "1742576908600", "checksum": 1851430854, "seqId": 49944898413, "prevSeqId": 49944898392}], "record_time": 1742576908.773378, "EXCHANGE": "OKX"}
{"arg": {"channel": "books", "instId": "BTC-USDT"}, "action": "update", "data": [{"asks": [["83982.8", "0.01190721", "0", "1"], ["83984.1", "0.00011161", "0", "1"], ["84021.1", "0.07141066", "0", "1"], ["84121.8", "0.07132516", "0", "1"], ["84141.2", "0", "0", "0"]], "bids": [["83938.2", "0.17901725", "0", "2"], ["83913.8", "0.13697721", "0", "2"], ["83911.9", "0.36843977", "0", "2"], ["83856.4", "0.07155085", "0", "1"]], "ts": "1742576908700", "checksum": 1226705648, "seqId": 49944898426, "prevSeqId": 49944898413}], "record_time": 1742576908.874675, "EXCHANGE": "OKX"}
{"arg": {"channel": "books", "instId": "BTC-USDT"}, "action": "update", "data": [{"asks": [["83951.6", "0.80920028", "0", "13"], ["83952.1", "0.01191822", "0", "1"], ["83954.4", "0.01037", "0", "1"], ["83954.6", "0", "0", "0"], ["83954.8", "0.11916897", "0", "1"], ["83957", "0.00001501", "0", "1"], ["83959.1", "0", "0", "0"], ["83960.7", "0.03111", "0", "1"], ["83966.7", "0.04", "0", "1"], ["83971.6", "0", "0", "0"], ["83972", "1.01190874", "0", "2"], ["83973.3", "0", "0", "0"], ["83978.8", "0.23835329", "0", "1"], ["83979.1", "0", "0", "0"], ["83981", "0.08991011", "0", "1"], ["83981.8", "0", "0", "0"], ["83987.8", "0.003573", "0", "1"], ["83989.6", "0.08", "0", "2"], ["84001", "0", "0", "0"], ["84021.1", "0.14282132", "0", "2"], ["84121.8", "0.14265032", "0", "2"]], "bids": [["83951.5", "0.15765709", "0", "6"], ["83950.3", "0", "0", "0"], ["83944.6", "0", "0", "0"], ["83943.8", "0", "0", "0"], ["83942.9", "0", "0", "0"], ["83942.2", "0", "0", "0"], ["83941.5", "0.01191822", "0", "1"], ["83941", "0.01367", "0", "1"], ["83937", "0.26574219", "0", "1"], ["83936.9", "0.036", "0", "1"], ["83934.7", "0.041045", "0", "2"], ["83934", "0.2439", "0", "3"], ["83932.8", "0.90389516", "0", "3"], ["83930.8", "1", "0", "1"], ["83922.3", "0", "0", "0"], ["83917.9", "0.00001501", "0", "1"], ["83917.8", "0.01", "0", "1"], ["83889.6", "0.09743013", "0", "1"], ["83888.4", "0", "0", "0"], ["83856.4", "0.1431017", "0", "2"], ["83844.7", "0.50867069", "0", "2"], ["83809.7", "0.00001075", "0", "1"], ["83809.5", "0.00008239", "0", "1"], ["83809.4", "0.00005977", "0", "1"], ["83808.7", "0.00001501", "0", "1"]], "ts": "1742576908800", "checksum": -2085547155, "seqId": 49944898493, "prevSeqId": 49944898426}], "record_time": 1742576908.973562, "EXCHANGE": "OKX"}
{"arg": {"channel": "books", "instId": "BTC-USDT"}, "action": "update", "data": [{"asks": [["83971.9", "1.54138136", "0", "1"], ["83972", "1", "0", "1"], ["83972.9", "0.01190861", "0", "1"], ["83978.2", "0.2383583", "0", "1"], ["83978.8", "0", "0", "0"], ["83988.8", "0.08", "0", "2"], ["83989.6", "0.03999999", "0", "1"], ["83990.4", "0", "0", "0"], ["83997.3", "0", "0", "0"], ["84001.3", "2.79805171", "0", "1"], ["84015.7", "0.01774536", "0", "1"], ["84140", "0", "0", "0"], ["84140.7", "0", "0", "0"], ["84141.1", "0", "0", "0"]], "bids": [["83937", "0.53252442", "0", "2"], ["83934", "1.2439", "0", "4"], ["83931.7", "1", "0", "1"], ["83930.8", "0", "0", "0"], ["83928.1", "0", "0", "0"], ["83924.4", "0", "0", "0"], ["83922.6", "0.2383583", "0", "1"], ["83921.1", "1.53270009", "0", "1"], ["83918.1", "0", "0", "0"], ["83913.1", "0.02381435", "0", "2"], ["83912", "0.01301199", "0", "2"], ["83895.3", "0.01190861", "0", "1"], ["83891.8", "3.01573967", "0", "2"], ["83809", "0.2025", "0", "1"], ["83808.7", "0", "0", "0"]], "ts": "1742576908900", "checksum": -1410571870, "seqId": 49944898528, "prevSeqId": 49944898493}], "record_time": 1742576909.073597, "EXCHANGE": "OKX"}
{"arg": {"channel": "books", "instId": "BTC-USDT"}, "action": "update", "data": [{"asks": [["83951.8", "0.01037", "0", "1"], ["83954.4", "0", "0", "0"], ["83988.8", "0", "0", "0"], ["83989.6", "0.07999999", "0", "2"], ["83990.4", "0.03999999", "0", "1"]], "bids": [["83951.5", "0.10835709", "0", "5"], ["83941", "0", "0", "0"], ["83938.4", "0.01752992", "0", "2"], ["83938.2", "0.17898725", "0", "1"], ["83934.7", "0.041069", "0", "3"], ["83808.7", "0.00001501", "0", "1"]], "ts": "1742576909000", "checksum": 1088848908, "seqId": 49944898541, "prevSeqId": 49944898528}], "record_time": 1742576909.176447, "EXCHANGE": "OKX"}
{"arg": {"channel": "books", "instId": "BTC-USDT"}, "action": "update", "data": [{"asks": [["83989.2", "0.54891054", "0", "1"], ["83997", "0.02343907", "0", "1"], ["83997.1", "0", "0", "0"], ["84126.1", "0", "0", "0"]], "bids": [["83937", "0.79918384", "0", "1"], ["83934.7", "0.041045", "0", "2"], ["83933", "1", "0", "1"], ["83932.8", "0.66334765", "0", "2"], ["83931.7", "0", "0", "0"], ["83924.3", "0.89766111", "0", "1"], ["83922.6", "0", "0", "0"], ["83921.7", "0.23835893", "0", "1"], ["83894.4", "1.13873842", "0", "3"], ["83844.7", "0.00005731", "0", "1"]], "ts": "1742576909100", "checksum": 2105267139, "seqId": 49944898561, "prevSeqId": 49944898541}], "record_time": 1742576909.273703, "EXCHANGE": "OKX"}
{"arg": {"channel": "books", "instId": "BTC-USDT"}, "action": "update", "data": [{"asks": [["83972", "0", "0", "0"], ["83975.3", "1", "0", "1"], ["83978.2", "0", "0", "0"], ["83979.4", "0.23835552", "0", "1"], ["83989.1", "0.01774536", "0", "1"], ["83989.6", "0", "0", "0"], ["83990.4", "0.07999999", "0", "2"], ["83991.2", "0.04001198", "0", "2"], ["84015.7", "0", "0", "0"], ["84140", "0.00031221", "0", "2"]], "bids": [["83951.5", "0.15765709", "0", "6"], ["83950", "0", "0", "0"], ["83949.8", "0.11917599", "0", "1"], ["83941.8", "0.00001199", "0", "1"], ["83940.4", "0.28335531", "0", "2"], ["83937", "0.47984228", "0", "2"], ["83935.5", "1.11919626", "0", "2"], ["83934", "0.0439", "0", "1"], ["83933", "0", "0", "0"], ["83922.6", "0.23835552", "0", "1"], ["83921.7", "0", "0", "0"], ["83859.7", "0.71502621", "0", "4"], ["83808.2", "0.00001199", "0", "1"], ["83808", "0.00015274", "0", "2"]], "ts": "1742576909200", "checksum": -1961049423, "seqId": 49944898616, "prevSeqId": 49944898561}], "record_time": 1742576909.39213, "EXCHANGE": "OKX"}
{"arg": {"channel": "books", "instId": "BTC-USDT"}, "action": "update", "data": [{"asks": [["83951.6", "0.97945319", "0", "17"], ["83952.4", "0.11917235", "0", "1"], ["83953.5", "0.08991011", "0", "1"], ["83954.8", "0", "0", "0"], ["83955.8", "0.04293364", "0", "1"], ["83957.6", "0", "0", "0"], ["83959.7", "0", "0", "0"], ["83962.5", "0.10182656", "0", "2"], ["83964", "0", "0", "0"], ["83964.7", "0.03", "0", "1"], ["83964.8", "0.20250712", "0", "2"], ["83966.6", "0.23939538", "0", "3"], ["83966.8", "0.54029217", "0", "1"], ["83969.3", "1", "0", "1"], ["83973.5", "0.11889794", "0", "1"], ["83975.3", "0", "0", "0"], ["83979.4", "0", "0", "0"], ["83983", "1.01190718", "0", "2"], ["83990.6", "0.202515", "0", "2"], ["84001.9", "0.02283169", "0", "1"], ["84016.8", "0.20679367", "0", "1"], ["84018.7", "0", "0", "0"], ["84031.8", "0", "0", "0"], ["84134.5", "6.48485452", "0", "2"], ["84140.7", "0.03", "0", "1"], ["84141.1", "0.00005109", "0", "1"]], "bids": [["83951.5", "0.01580116", "0", "3"], ["83949.8", "0", "0", "0"], ["83948", "0", "0", "0"], ["83947.2", "0.11917961", "0", "1"], ["83945", "0", "0", "0"], ["83944.3", "0.08025", "0", "1"], ["83943.9", "0", "0", "0"], ["83941.5", "0", "0", "0"], ["83940.4", "0.20153885", "0", "1"], ["83939.6", "0", "0", "0"], ["83938.8", "0", "0", "0"], ["83937.7", "0", "0", "0"], ["83937.3", "0.005", "0", "1"], ["83937.1", "0.36845116", "0", "2"], ["83937", "0.20719929", "0", "1"], ["83936.9", "0", "0", "0"], ["83935.5", "0.11919626", "0", "1"], ["83931.6", "0.35735", "0", "1"], ["83931.2", "0.0000105", "0", "1"], ["83929.4", "0.03960671", "0", "1"], ["83928.1", "0.36976599", "0", "2"], ["83927.9", "1", "0", "1"], ["83927.8", "0.02751695", "0", "1"], ["83923.4", "0.31", "0", "1"], ["83923", "0.02383742", "0", "1"], ["83922.6", "0", "0", "0"], ["83922.5", "0", "0", "0"], ["83912.9", "0.23838004", "0", "1"], ["83906.6", "0", "0", "0"], ["83905.9", "0", "0", "0"], ["83900.3", "0", "0", "0"], ["83807.9", "0.00001018", "0", "1"], ["83807.6", "0.03", "0", "1"], ["83807.4", "0.23827629", "0", "2"], ["83807.3", "0.00011161", "0", "1"], ["83807.1", "0.01196192", "0", "2"]], "ts": "1742576909300", "checksum": -1908317728, "seqId": 49944898715, "prevSeqId": 49944898616}], "record_time": 1742576909.473841, "EXCHANGE": "OKX"}
{"arg": {"channel": "books", "instId": "BTC-USDT"}, "action": "update", "data": [{"asks": [["83951.6", "0.98302619", "0", "18"], ["83952.3", "0.17604028", "0", "2"], ["83952.6", "0.0005025", "0", "1"], ["83953.9", "0", "0", "0"], ["83956.4", "0.03112", "0", "1"], ["83960.7", "0", "0", "0"], ["83961.3", "0.4165323", "0", "3"], ["83962.2", "0.3319905", "0", "1"], ["83964.7", "0.09", "0", "3"], ["83965.8", "0", "0", "0"], ["83966.6", "0.00101534", "0", "2"], ["83967.8", "1", "0", "1"], ["83968.6", "0", "0", "0"], ["83969.3", "0", "0", "0"], ["83969.5", "0.09", "0", "3"], ["83970.1", "0.23837492", "0", "1"], ["83979.4", "0.01774536", "0", "1"], ["83983", "0.01190718", "0", "1"], ["83984.7", "0.05880354", "0", "1"], ["83985", "0.2", "0", "1"], ["83987.8", "0", "0", "0"], ["83989.1", "0", "0", "0"], ["84141.1", "0", "0", "0"]], "bids": [["83947.5", "0.11917917", "0", "1"], ["83947.2", "0", "0", "0"], ["83938.1", "0.04293364", "0", "1"], ["83937", "0.15150539", "0", "1"], ["83934.7", "0.000015", "0", "1"], ["83933.1", "0.04", "0", "1"], ["83932.8", "0.5195883", "0", "2"], ["83932.1", "0", "0", "0"], ["83931.6", "0", "0", "0"], ["83930.4", "0.04461", "0", "2"], ["83928.1", "0.37802108", "0", "2"], ["83927.9", "0", "0", "0"], ["83927.1", "1", "0", "1"], ["83921.4", "0", "0", "0"], ["83917.5", "0.05915992", "0", "1"], ["83914.7", "0.23837535", "0", "1"], ["83912.9", "0", "0", "0"]], "ts": "1742576909400", "checksum": 1843743664, "seqId": 49944898779, "prevSeqId": 49944898715}], "record_time": 1742576909.574231, "EXCHANGE": "OKX"}
{"arg": {"channel": "books", "instId": "BTC-USDT"}, "action": "update", "data": [{"asks": [["83948.1", "1.85508699", "0", "23"], ["83949.6", "0.37466622", "0", "1"], ["83949.7", "0.3565323", "0", "1"], ["83950", "0.0439", "0", "1"], ["83951", "0.11917437", "0", "1"], ["83951.5", "0.39051963", "0", "3"], ["83951.6", "0.2897879", "0", "10"], ["83951.8", "0", "0", "0"], ["83952.1", "0", "0", "0"], ["83952.3", "0.00774256", "0", "1"], ["83952.4", "0", "0", "0"], ["83952.6", "0", "0", "0"], ["83953.5", "0", "0", "0"], ["83955.7", "0.09056203", "0", "1"], ["83964.7", "0.12", "0", "4"], ["83966.1", "0.03", "0", "1"], ["83966.7", "0.175139", "0", "2"], ["83970.1", "0", "0", "0"], ["83976.7", "0.23837418", "0", "1"], ["83988.8", "0.07999999", "0", "2"], ["83989.6", "0.03999999", "0", "1"], ["83990.4", "0", "0", "0"], ["83991.2", "0.00001199", "0", "1"], ["84011.1", "0.82524001", "0", "2"], ["84023.6", "0.044987", "0", "1"], ["84101", "0.03", "0", "1"], ["84104.1", "0", "0", "0"], ["84137.2", "0", "0", "0"], ["84138.8", "0", "0", "0"], ["84140", "0", "0", "0"], ["84140.7", "0", "0", "0"]], "bids": [["83951.5", "0", "0", "0"], ["83948", "0.14319864", "0", "3"], ["83944.3", "0", "0", "0"], ["83938.4", "0.00385992", "0", "1"], ["83934.8", "0.00354486", "0", "1"], ["83934", "0.05757", "0", "2"], ["83932.8", "0.88531072", "0", "3"], ["83929.1", "0.35735", "0", "1"], ["83928.9", "1", "0", "1"], ["83928.1", "0.07973256", "0", "1"], ["83927.1", "0", "0", "0"], ["83926.7", "0.00476606", "0", "1"], ["83925.5", "0.0071492", "0", "1"], ["83916.1", "0.23837034", "0", "1"], ["83914.7", "0", "0", "0"], ["83914.3", "0.045046", "0", "1"], ["83898.3", "0.826334", "0", "1"], ["83807.9", "0", "0", "0"], ["83807.6", "0", "0", "0"], ["83807.4", "0", "0", "0"], ["83807.3", "0", "0", "0"], ["83807.1", "0", "0", "0"]], "ts": "1742576909500", "checksum": -368895028, "seqId": 49944898904, "prevSeqId": 49944898779}], "record_time": 1742576909.674291, "EXCHANGE": "OKX"}
{"arg": {"channel": "books", "instId": "BTC-USDT"}, "action": "update", "data": [{"asks": [["83948.1", "1.16796963", "0", "18"], ["83949.3", "0.11917683", "0", "1"], ["83949.6", "0.27829714", "0", "1"], ["83951", "0", "0", "0"], ["83951.5", "0.19051963", "0", "2"], ["83951.6", "0.287732", "0", "8"], ["83954.3", "0.0000195", "0", "1"], ["83966.1", "0", "0", "0"], ["83967.7", "0.11915059", "0", "1"], ["83969.5", "0", "0", "0"], ["83976.6", "0.02774536", "0", "2"], ["83979.4", "0", "0", "0"], ["83980.6", "0", "0", "0"], ["83982.4", "0.472349", "0", "2"], ["83984.3", "0.32807358", "0", "2"], ["83985", "0", "0", "0"], ["83986.4", "0.08", "0", "2"], ["83987.2", "0.03999999", "0", "1"], ["83988.8", "0", "0", "0"], ["83989.6", "0", "0", "0"], ["83992.6", "0.11915497", "0", "2"], ["83996.1", "0", "0", "0"], ["84137.2", "3.88291", "0", "1"], ["84138.8", "0.06044981", "0", "3"], ["84140", "0.00031221", "0", "2"], ["84140.7", "0.03", "0", "1"]], "bids": [["83948", "0.42421059", "0", "5"], ["83943.1", "0", "0", "0"], ["83940.4", "0", "0", "0"], ["83929.5", "0.17868", "0", "1"], ["83921.4", "0.17868", "0", "1"], ["83913.4", "0", "0", "0"], ["83912.1", "0.01190699", "0", "1"], ["83884.9", "0", "0", "0"], ["83883.7", "0", "0", "0"], ["83883.6", "0", "0", "0"], ["83880.7", "0.00319407", "0", "2"], ["83880.1", "0.00145282", "0", "1"], ["83807.9", "0.00001018", "0", "1"]], "ts": "1742576909600", "checksum": -1690461188, "seqId": 49944898990, "prevSeqId": 49944898904}], "record_time": 1742576909.776571, "EXCHANGE": "OKX"}
{"arg": {"channel": "books", "instId": "BTC-USDT"}, "action": "update", "data": [{"asks": [["83948.1", "0.76007327", "0", "12"], ["83949.6", "0.11058745", "0", "1"], ["83949.7", "0", "0", "0"], ["83950.8", "0.01037", "0", "1"], ["83951.6", "0.06736", "0", "6"], ["83962.5", "0.01191645", "0", "1"], ["83966.8", "0.14752351", "0", "1"], ["83967.8", "0", "0", "0"], ["83971.1", "1", "0", "1"], ["83976.7", "0", "0", "0"], ["83978.8", "0.23835919", "0", "1"], ["83986.4", "0", "0", "0"], ["83987.2", "0.07999999", "0", "2"], ["83988", "0.03999999", "0", "1"]], "bids": [["83944.1", "0.0263436", "0", "1"], ["83938.3", "0.19178162", "0", "1"], ["83937.4", "0.01367", "0", "1"], ["83937", "0.43363067", "0", "2"], ["83934.1", "1", "0", "1"], ["83934", "0.0439", "0", "1"], ["83932.8", "0.5195883", "0", "2"], ["83928.9", "0", "0", "0"], ["83921.7", "0.23835919", "0", "1"], ["83916.1", "0", "0", "0"], ["83808.2", "0", "0", "0"], ["83808", "0", "0", "0"], ["83807.9", "0", "0", "0"]], "ts": "1742576909700", "checksum": -2045829720, "seqId": 49944899038, "prevSeqId": 49944898990}], "record_time": 1742576909.876134, "EXCHANGE": "OKX"}
{"arg": {"channel": "books", "instId": "BTC-USDT"}, "action": "update", "data": [{"asks": [["83948.1", "0.50453438", "0", "11"], ["83949.3", "0", "0", "0"], ["83950.8", "0", "0", "0"], ["83951.1", "0.11917418", "0", "1"], ["83954.1", "0.04084853", "0", "1"], ["83966.8", "0.42908307", "0", "2"], ["83969.8", "1", "0", "1"], ["83971.1", "0", "0", "0"], ["83976.6", "0.01", "0", "1"], ["83997.3", "0.01774536", "0", "1"], ["84057.5", "0", "0", "0"]], "bids": [["83948", "0.37071195", "0", "4"], ["83935.5", "1.11919626", "0", "2"], ["83934.1", "0", "0", "0"], ["83808.2", "0.00001199", "0", "1"]], "ts": "1742576909800", "checksum": -437667915, "seqId": 49944899060, "prevSeqId": 49944899038}], "record_time": 1742576909.97731, "EXCHANGE": "OKX"}
{"arg": {"channel": "books", "instId": "BTC-USDT"}, "action": "update", "data": [{"asks": [["83948.1", "0.72841167", "0", "17"], ["83953.5", "0.01037", "0", "1"], ["83976.7", "0.23836238", "0", "1"], ["83978.8", "0", "0", "0"], ["84140.7", "0", "0", "0"]], "bids": [["83948", "0.13955581", "0", "4"], ["83937.4", "0", "0", "0"], ["83921.7", "0", "0", "0"], ["83917.8", "0.24836238", "0", "2"], ["83808", "0.00015274", "0", "2"], ["83807.9", "0.00001018", "0", "1"]], "ts": "1742576909900", "checksum": -2002312738, "seqId": 49944899083, "prevSeqId": 49944899060}], "record_time": 1742576910.073629, "EXCHANGE": "OKX"}
{"arg": {"channel": "books", "instId": "BTC-USDT"}, "action": "update", "data": [{"asks": [["83968.5", "1", "0", "1"], ["83969.8", "0", "0", "0"], ["83979.2", "0.0008", "0", "2"], ["83980", "0.00045736", "0", "2"], ["83981.6", "0", "0", "0"], ["83982.4", "0.471949", "0", "1"], ["84066.9", "0.03", "0", "1"], ["84140", "0", "0", "0"]], "bids": [["83948", "0.14951581", "0", "5"], ["83935.5", "0.11919626", "0", "1"], ["83934.2", "1", "0", "1"], ["83914.4", "0.0808", "0", "4"], ["83913.6", "0.04039943", "0", "2"], ["83912.8", "0.026", "0", "2"], ["83807.9", "0", "0", "0"]], "ts": "1742576910000", "checksum": 1807373450, "seqId": 49944899104, "prevSeqId": 49944899083}], "record_time": 1742576910.173673, "EXCHANGE": "OKX"}
{"arg": {"channel": "books", "instId": "BTC-USDT"}, "action": "update", "data": [{"asks": [["83949.2", "0.01037", "0", "1"], ["83953.5", "0", "0", "0"], ["83976.6", "0.3355386", "0", "2"], ["84001.2", "0.89545956", "0", "1"], ["84006.7", "0.00002157", "0", "1"], ["84010.6", "0", "0", "0"], ["84015.8", "0.12597766", "0", "3"], ["84019.3", "0", "0", "0"]], "bids": [["83935.8", "0.01367", "0", "1"], ["83917.9", "0.13612755", "0", "2"], ["83902.5", "0", "0", "0"], ["83899.9", "0.16016531", "0", "4"], ["83880.8", "0.00100711", "0", "1"], ["83880.7", "0.00218694", "0", "1"], ["83863.4", "0", "0", "0"], ["83860.1", "0.00018339", "0", "1"], ["83844.7", "0.38461806", "0", "2"], ["83830.3", "0", "0", "0"], ["83828.3", "0.18354215", "0", "1"], ["83808", "0", "0", "0"]], "ts": "1742576910100", "checksum": 1064038012, "seqId": 49944899131, "prevSeqId": 49944899104}], "record_time": 1742576910.273758, "EXCHANGE": "OKX"}
{"arg": {"channel": "books", "instId": "BTC-USDT"}, "action": "update", "data": [{"asks": [["83948.1", "1.03091167", "0", "19"], ["83967.2", "1", "0", "1"], ["83968.5", "0", "0", "0"], ["83973.7", "0.23837148", "0", "1"], ["83976.5", "0.01774536", "0", "1"], ["83976.7", "0", "0", "0"], ["83983.5", "0.002", "0", "1"], ["83997.3", "0", "0", "0"], ["84138.8", "0", "0", "0"]], "bids": [["83948", "0.01591581", "0", "2"], ["83946.1", "0.002", "0", "1"], ["83937", "0.15150539", "0", "1"], ["83936.1", "0.002", "0", "1"], ["83935.8", "0", "0", "0"], ["83934.2", "0", "0", "0"], ["83932.8", "0.93891472", "0", "3"], ["83929.6", "1", "0", "1"], ["83928.1", "0.44159565", "0", "2"], ["83927", "0.2", "0", "1"], ["83925", "1.007", "0", "3"], ["83920", "0.00037", "0", "2"], ["83917.9", "0.00001501", "0", "1"], ["83917.8", "0.01", "0", "1"], ["83916.1", "0.23837148", "0", "1"], ["83809", "0", "0", "0"], ["83808.7", "0", "0", "0"], ["83808.2", "0", "0", "0"]], "ts": "1742576910200", "checksum": -205961372, "seqId": 49944899179, "prevSeqId": 49944899131}], "record_time": 1742576910.376503, "EXCHANGE": "OKX"}
{"arg": {"channel": "books", "instId": "BTC-USDT"}, "action": "update", "data": [{"asks": [["83948.1", "0.89116258", "0", "21"], ["83949.2", "0", "0", "0"], ["83949.4", "0.11917669", "0", "1"], ["83951.1", "0", "0", "0"], ["83951.5", "0.17898725", "0", "1"], ["83954.1", "0", "0", "0"], ["83973.4", "0.24037191", "0", "2"], ["83973.7", "0", "0", "0"], ["84138.8", "0.06044981", "0", "3"], ["84140", "0.00031221", "0", "2"]], "bids": [["83948", "0.15961586", "0", "5"], ["83944.1", "0", "0", "0"], ["83933.3", "0.01427645", "0", "2"], ["83916.1", "0", "0", "0"], ["83914.7", "0.23837182", "0", "1"], ["83831.7", "0", "0", "0"], ["83809", "0.2025", "0", "1"], ["83808.7", "0.00001501", "0", "1"]], "ts": "1742576910300", "checksum": -1953608351, "seqId": 49944899220, "prevSeqId": 49944899179}], "record_time": 1742576910.478271, "EXCHANGE": "OKX"}
{"arg": {"channel": "books", "instId": "BTC-USDT"}, "action": "update", "data": [{"asks": [["83973.4", "0.002", "0", "1"], ["83976.5", "0.23836919", "0", "1"], ["83981", "1.08991011", "0", "2"], ["83997.3", "0.01774536", "0", "1"], ["84140", "0", "0", "0"]], "bids": [["83916.1", "0.23836919", "0", "1"], ["83914.7", "0", "0", "0"]], "ts": "1742576910400", "checksum": -1953608351, "seqId": 49944899238, "prevSeqId": 49944899220}], "record_time": 1742576910.574847, "EXCHANGE": "OKX"}
{"arg": {"channel": "books", "instId": "BTC-USDT"}, "action": "update", "data": [{"asks": [["83976.5", "0.2383691", "0", "1"], ["83981", "0.08991011", "0", "1"]], "bids": [["83948", "0.06397005", "0", "3"], ["83946", "0", "0", "0"], ["83932.8", "0.5195883", "0", "2"], ["83930.1", "0", "0", "0"], ["83929.6", "0", "0", "0"], ["83928.2", "0.29256222", "0", "1"], ["83928.1", "1", "0", "1"], ["83927", "0", "0", "0"], ["83925", "0.007", "0", "2"], ["83923.3", "0.34928609", "0", "3"], ["83917.8", "0.2483691", "0", "2"], ["83916.1", "0", "0", "0"], ["83911.9", "0.3565323", "0", "1"], ["83911.8", "0.01190732", "0", "1"], ["83808.2", "0.00001199", "0", "1"], ["83808", "0.00015274", "0", "2"], ["83807.9", "0.00001018", "0", "1"]], "ts": "1742576910500", "checksum": 1657283240, "seqId": 49944899267, "prevSeqId": 49944899238}], "record_time": 1742576910.673297, "EXCHANGE": "OKX"}
{"arg": {"channel": "books", "instId": "BTC-USDT"}, "action": "update", "data": [{"asks": [["83976.4", "0.03933905", "0", "2"], ["83985", "0.2", "0", "1"], ["83997.3", "0", "0", "0"]], "bids": [["83947.5", "0", "0", "0"], ["83945.5", "0.119182", "0", "1"], ["83938.3", "0.08482193", "0", "1"], ["83937.1", "0.01191886", "0", "1"], ["83921.4", "0", "0", "0"], ["83807.6", "0.03", "0", "1"]], "ts": "1742576910600", "checksum": -733306859, "seqId": 49944899277, "prevSeqId": 49944899267}], "record_time": 1742576910.773819, "EXCHANGE": "OKX"}
{"arg": {"channel": "books", "instId": "BTC-USDT"}, "action": "update", "data": [{"asks": [["83948.1", "0.8796302", "0", "20"], ["83951.9", "0.01153238", "0", "1"], ["83976.3", "0.23838243", "0", "2"], ["83976.5", "0", "0", "0"], ["83982.4", "0", "0", "0"], ["83994.7", "0.471898", "0", "1"], ["84006.7", "0", "0", "0"], ["84140", "0.00031221", "0", "2"]], "bids": [["83947.4", "0.11917936", "0", "1"], ["83945.5", "0", "0", "0"], ["83938.4", "0.16355363", "0", "2"], ["83938.3", "0.3565323", "0", "1"], ["83926.6", "0.35736", "0", "1"], ["83918.9", "0.17868", "0", "1"], ["83917.8", "0.01", "0", "1"], ["83916.1", "0.23837016", "0", "1"], ["83808", "0", "0", "0"], ["83807.9", "0", "0", "0"], ["83807.6", "0", "0", "0"]], "ts": "1742576910700", "checksum": -481765290, "seqId": 49944899298, "prevSeqId": 49944899277}], "record_time": 1742576910.873876, "EXCHANGE": "OKX"}
{"arg": {"channel": "books", "instId": "BTC-USDT"}, "action": "update", "data": [{"asks": [["83948.1", "0.89116258", "0", "21"], ["83951.9", "0", "0", "0"], ["83976.3", "0.23838223", "0", "2"], ["83976.4", "0.02159369", "0", "1"], ["83985", "0", "0", "0"], ["83989.1", "0.01774536", "0", "1"], ["84006.7", "0.00002157", "0", "1"]], "bids": [["83948", "0.15962611", "0", "6"], ["83927", "0.17868", "0", "1"], ["83808.2", "0", "0", "0"]], "ts": "1742576910800", "checksum": 98106679, "seqId": 49944899320, "prevSeqId": 49944899298}], "record_time": 1742576910.97661, "EXCHANGE": "OKX"}
{"arg": {"channel": "books", "instId": "BTC-USDT"}, "action": "update", "data": [{"asks": [], "bids": [["83932.8", "0.92103589", "0", "3"], ["83929.5", "1.17868", "0", "2"], ["83928.2", "0.14516622", "0", "1"], ["83928.1", "0", "0", "0"], ["83926.6", "0", "0", "0"], ["83921.4", "0.17868", "0", "1"], ["83808.2", "0.00001199", "0", "1"]], "ts": "1742576910900", "checksum": 98106679, "seqId": 49944899330, "prevSeqId": 49944899320}], "record_time": 1742576911.075364, "EXCHANGE": "OKX"}
{"arg": {"channel": "books", "instId": "BTC-USDT"}, "action": "update", "data": [{"asks": [["83948.1", "1.09116258", "0", "22"], ["83967.2", "0", "0", "0"], ["83968.6", "1", "0", "1"], ["84062.2", "0.0142", "0", "1"]], "bids": [["83948", "0.14965611", "0", "4"], ["83931", "1", "0", "1"], ["83929.5", "0.17868", "0", "1"], ["83928.2", "0.09156222", "0", "1"], ["83927", "0", "0", "0"], ["83918.9", "0", "0", "0"], ["83836.4", "0", "0", "0"], ["83808", "0.00015274", "0", "2"], ["83807.9", "0.00001018", "0", "1"]], "ts": "1742576911000", "checksum": -1653729583, "seqId": 49944899346, "prevSeqId": 49944899330}], "record_time": 1742576911.175796, "EXCHANGE": "OKX"}
{"arg": {"channel": "books", "instId": "BTC-USDT"}, "action": "update", "data": [{"asks": [["84008.7", "0.27831336", "0", "3"], ["84062.1", "0.01286799", "0", "2"]], "bids": [["83948", "0.05710005", "0", "2"], ["83906.6", "0.33258702", "0", "1"], ["83853.1", "0.1764305", "0", "1"], ["83808", "0", "0", "0"], ["83807.9", "0", "0", "0"]], "ts": "1742576911100", "checksum": -2001238407, "seqId": 49944899355, "prevSeqId": 49944899346}], "record_time": 1742576911.273177, "EXCHANGE": "OKX"}
{"arg": {"channel": "books", "instId": "BTC-USDT"}, "action": "update", "data": [{"asks": [["83948.1", "0.8796302", "0", "20"], ["83958.8", "0.01153238", "0", "1"], ["83976.3", "0.00001199", "0", "1"], ["83978.2", "0.2383629", "0", "1"], ["84021.1", "0.07141066", "0", "1"], ["84121.8", "0.07132516", "0", "1"], ["84138.8", "0", "0", "0"], ["84140", "0", "0", "0"]], "bids": [["83948", "0.14965611", "0", "4"], ["83921.7", "0.2383629", "0", "1"], ["83916.1", "0", "0", "0"], ["83862.9", "0", "0", "0"], ["83856.4", "0.07155085", "0", "1"], ["83851.3", "0.01511215", "0", "1"]], "ts": "1742576911200", "checksum": -791918512, "seqId": 49944899373, "prevSeqId": 49944899355}], "record_time": 1742576911.374245, "EXCHANGE": "OKX"}
{"arg": {"channel": "books", "instId": "BTC-USDT"}, "action": "update", "data": [{"asks": [["83979.2", "0", "0", "0"], ["83980", "0.00085736", "0", "3"], ["83980.8", "0.0004", "0", "1"], ["83987.2", "0", "0", "0"], ["83988", "0.07999999", "0", "2"], ["83988.8", "0.03999999", "0", "1"]], "bids": [["83946", "0.0439", "0", "1"], ["83921.7", "0", "0", "0"], ["83917.8", "0.24836328", "0", "2"], ["83914.4", "0.08", "0", "2"], ["83913.6", "0.04079943", "0", "3"], ["83912.8", "0.02639943", "0", "3"]], "ts": "1742576911300", "checksum": -1739376524, "seqId": 49944899403, "prevSeqId": 49944899373}], "record_time": 1742576911.47429, "EXCHANGE": "OKX"}
{"arg": {"channel": "books", "instId": "BTC-USDT"}, "action": "update", "data": [{"asks": [["83948.1", "0.89716258", "0", "22"], ["83949.4", "0", "0", "0"], ["83951.4", "0.04293364", "0", "1"], ["83951.6", "0.065573", "0", "5"], ["83955.8", "0", "0", "0"], ["83956.7", "0.04", "0", "1"], ["83958.8", "0", "0", "0"], ["83962.2", "0.23731896", "0", "1"], ["83962.4", "0", "0", "0"], ["83963.4", "0", "0", "0"], ["83963.5", "0.25015", "0", "1"], ["83964.4", "0.00011161", "0", "1"], ["83964.8", "0.02383712", "0", "1"], ["83976.5", "0.23836928", "0", "1"], ["83978.2", "0", "0", "0"], ["83994.7", "0.473685", "0", "2"], ["84001.9", "0", "0", "0"], ["84005.5", "0", "0", "0"], ["84021.1", "0.14282132", "0", "2"], ["84121.8", "0.14265032", "0", "2"], ["84138.8", "0.06044981", "0", "3"], ["84140", "0.00031221", "0", "2"], ["84140.7", "0.03", "0", "1"], ["84141.1", "0.00005109", "0", "1"]], "bids": [["83948", "1.00440653", "0", "8"], ["83932", "1.0439", "0", "2"], ["83931", "0", "0", "0"], ["83929.7", "0", "0", "0"], ["83926.7", "0", "0", "0"], ["83926.3", "0.040015", "0", "2"], ["83921.4", "0", "0", "0"], ["83918.9", "0.17868", "0", "1"], ["83917.8", "0.24836928", "0", "2"], ["83856.4", "0.1431017", "0", "2"], ["83808", "0.00015274", "0", "2"], ["83807.9", "0.00001018", "0", "1"], ["83807.6", "0.03", "0", "1"]], "ts": "1742576911400", "checksum": -1745751543, "seqId": 49944899474, "prevSeqId": 49944899403}], "record_time": 1742576911.573863, "EXCHANGE": "OKX"}
{"arg": {"channel": "books", "instId": "BTC-USDT"}, "action": "update", "data": [{"asks": [["83948.1", "0.80594405", "0", "19"], ["83951.3", "0.11917395", "0", "1"], ["83951.6", "0.029573", "0", "4"], ["83951.9", "0.02", "0", "1"], ["83953.2", "0.04084853", "0", "1"], ["83954.3", "0", "0", "0"], ["83956.4", "0", "0", "0"], ["83957.7", "0", "0", "0"], ["83958.7", "0.0045705", "0", "1"], ["83959.2", "0.258654", "0", "2"], ["83960.9", "0.03111", "0", "1"], ["83967.1", "1", "0", "1"], ["83968.6", "0", "0", "0"], ["83969.5", "0.2383761", "0", "1"], ["83976.5", "0", "0", "0"], ["84140.7", "0", "0", "0"], ["84141.1", "0", "0", "0"]], "bids": [["83948", "0.06767611", "0", "3"], ["83946", "0", "0", "0"], ["83938.5", "0.01367", "0", "1"], ["83934.9", "0.04103", "0", "1"], ["83933.3", "0.00060645", "0", "1"], ["83932.8", "0.5195883", "0", "2"], ["83932", "0.0439", "0", "1"], ["83930.4", "0.00357", "0", "1"], ["83928.9", "1", "0", "1"], ["83918.9", "0", "0", "0"], ["83917.8", "0.01", "0", "1"], ["83916.1", "0.23837025", "0", "1"], ["83893.3", "0.03", "0", "1"], ["83844.7", "0.00005731", "0", "1"], ["83808", "0", "0", "0"], ["83807.9", "0", "0", "0"], ["83807.6", "0", "0", "0"]], "ts": "1742576911500", "checksum": 1688358865, "seqId": 49944899573, "prevSeqId": 49944899474}], "record_time": 1742576911.673609, "EXCHANGE": "OKX"}
{"arg": {"channel": "books", "instId": "BTC-USDT"}, "action": "update", "data": [{"asks": [["83948.1", "0.84679258", "0", "20"], ["83951.8", "0.004575", "0", "1"], ["83953.2", "0", "0", "0"], ["83957.2", "0.18642241", "0", "2"], ["83958.7", "0", "0", "0"], ["83959.2", "0.17215733", "0", "1"], ["83962.4", "0.00355257", "0", "1"], ["83979.2", "0.0008", "0", "2"], ["83980", "0.00045736", "0", "2"], ["83980.8", "0", "0", "0"], ["83987.2", "0.08", "0", "2"], ["83988", "0.03999999", "0", "1"], ["83988.8", "0", "0", "0"]], "bids": [["83948", "0.07077611", "0", "4"], ["83938.5", "0", "0", "0"], ["83934.9", "0", "0", "0"], ["83932.8", "0.89672389", "0", "3"], ["83928.2", "0.14429113", "0", "2"], ["83927", "0.17868", "0", "1"], ["83914.4", "0.0808", "0", "4"], ["83913.6", "0.04039943", "0", "2"], ["83912.8", "0.026", "0", "2"], ["83893.3", "0.06", "0", "2"], ["83808", "0.00015274", "0", "2"]], "ts": "1742576911600", "checksum": -200811630, "seqId": 49944899599, "prevSeqId": 49944899573}], "record_time": 1742576911.819224, "EXCHANGE": "OKX"}
{"arg": {"channel": "books", "instId": "BTC-USDT"}, "action": "update", "data": [{"asks": [["83948.1", "0.85716258", "0", "21"], ["83953.9", "0.03112", "0", "1"], ["83956.8", "0.35736", "0", "1"], ["83960.9", "0", "0", "0"], ["83970.9", "0.39244611", "0", "1"], ["83971.9", "0", "0", "0"], ["84001.2", "0", "0", "0"], ["84001.3", "0", "0", "0"], ["84140.7", "0.03", "0", "1"], ["84141.1", "0.00005109", "0", "1"]], "bids": [["83948", "0.06767611", "0", "3"], ["83934.3", "0.01367", "0", "1"], ["83927.9", "0.04104", "0", "1"], ["83927", "0", "0", "0"], ["83924.3", "0", "0", "0"], ["83921.1", "0", "0", "0"], ["83918.9", "0.17868", "0", "1"], ["83894.4", "0.31014702", "0", "2"], ["83891.8", "0.17898725", "0", "1"]], "ts": "1742576911700", "checksum": 264278157, "seqId": 49944899616, "prevSeqId": 49944899599}], "record_time": 1742576911.873348, "EXCHANGE": "OKX"}
{"arg": {"channel": "books", "instId": "BTC-USDT"}, "action": "update", "data": [{"asks": [["83955.7", "0.22383768", "0", "2"], ["83966.8", "0.92761547", "0", "1"], ["83966.9", "1.54071505", "0", "1"], ["83985", "0.2", "0", "1"], ["83989.1", "0", "0", "0"], ["83996.3", "2.78122919", "0", "1"], ["84020.4", "0.01774536", "0", "1"], ["84140", "0", "0", "0"], ["84140.7", "0", "0", "0"], ["84141.1", "0", "0", "0"]], "bids": [["83918.9", "0", "0", "0"], ["83915.6", "1.5652814", "0", "1"], ["83886.2", "2.88609413", "0", "1"], ["83808", "0", "0", "0"]], "ts": "1742576911800", "checksum": 1752219463, "seqId": 49944899630, "prevSeqId": 49944899616}], "record_time": 1742576911.973393, "EXCHANGE": "OKX"}
{"arg": {"channel": "books", "instId": "BTC-USDT"}, "action": "update", "data": [{"asks": [["83948.1", "0.8634992", "0", "21"], ["83951.6", "0.026", "0", "3"], ["83952.9", "0.00101464", "0", "1"], ["83958.8", "0.01153238", "0", "1"], ["83969.5", "0", "0", "0"], ["83970.1", "0.23837951", "0", "1"], ["83977.3", "0.003573", "0", "1"], ["84137.2", "0", "0", "0"], ["84138.8", "0", "0", "0"]], "bids": [["83948", "0.07077611", "0", "4"], ["83921.4", "0.17868", "0", "1"], ["83916.1", "0", "0", "0"], ["83914.4", "0.31917951", "0", "5"]], "ts": "1742576911900", "checksum": -1191414503, "seqId": 49944899647, "prevSeqId": 49944899630}], "record_time": 1742576912.074136, "EXCHANGE": "OKX"}
{"arg": {"channel": "books", "instId": "BTC-USDT"}, "action": "update", "data": [{"asks": [["83948.1", "1.0634992", "0", "22"], ["83952.9", "0", "0", "0"], ["83967.1", "0", "0", "0"], ["83968.7", "1", "0", "1"], ["83989.1", "0.01774536", "0", "1"], ["84020.4", "0", "0", "0"], ["84137.2", "3.88291", "0", "1"]], "bids": [["83948", "0.06172005", "0", "2"], ["83930.4", "1.00357", "0", "2"], ["83928.9", "0", "0", "0"], ["83915.2", "0.08", "0", "2"], ["83914.4", "0.27917951", "0", "4"], ["83913.6", "0.00039943", "0", "1"], ["83909.6", "0.1", "0", "2"], ["83908.8", "0.05", "0", "1"], ["83908", "0.00072", "0", "2"], ["83808.2", "0", "0", "0"]], "ts": "1742576912000", "checksum": 63860819, "seqId": 49944899667, "prevSeqId": 49944899647}], "record_time": 1742576912.173816, "EXCHANGE": "OKX"}
{"arg": {"channel": "books", "instId": "BTC-USDT"}, "action": "update", "data": [{"asks": [["83948.1", "1.07503158", "0", "23"], ["83958.8", "0", "0", "0"], ["83970.1", "0.23837987", "0", "1"], ["83996.2", "1.25715832", "0", "2"], ["83997.4", "0", "0", "0"], ["84138.8", "0.06044981", "0", "3"], ["84140", "0.00031221", "0", "2"]], "bids": [["83932.1", "1", "0", "1"], ["83930.4", "0.00357", "0", "1"], ["83915.7", "0.98341347", "0", "1"], ["83914.6", "0", "0", "0"], ["83914.4", "0.0408", "0", "3"], ["83913.9", "0.24737955", "0", "2"], ["83900", "0.000471", "0", "2"], ["83886.3", "1.20285332", "0", "1"], ["83885.7", "0", "0", "0"], ["83853.1", "0.49685473", "0", "2"], ["83808.7", "0", "0", "0"]], "ts": "1742576912100", "checksum": 1927431898, "seqId": 49944899697, "prevSeqId": 49944899667}], "record_time": 1742576912.27276, "EXCHANGE": "OKX"}
{"arg": {"channel": "books", "instId": "BTC-USDT"}, "action": "update", "data": [{"asks": [["83970.1", "0.23838023", "0", "1"]], "bids": [["83915.2", "0", "0", "0"], ["83914.4", "0.0808", "0", "4"], ["83913.9", "0.009", "0", "1"], ["83913.6", "0.04039943", "0", "2"], ["83912.9", "0.23838023", "0", "1"], ["83909.6", "0", "0", "0"], ["83908.8", "0.1", "0", "2"], ["83908", "0.05072", "0", "3"], ["83809", "0", "0", "0"], ["83808.7", "0.00001501", "0", "1"], ["83808.2", "0.00001199", "0", "1"]], "ts": "1742576912200", "checksum": 1927431898, "seqId": 49944899724, "prevSeqId": 49944899697}], "record_time": 1742576912.374427, "EXCHANGE": "OKX"}
{"arg": {"channel": "books", "instId": "BTC-USDT"}, "action": "update", "data": [{"asks": [["83967.3", "1", "0", "1"], ["83968.7", "0", "0", "0"], ["83970.1", "0", "0", "0"], ["83970.8", "0.23837987", "0", "1"]], "bids": [["83932.8", "0.5195883", "0", "2"], ["83932.1", "0", "0", "0"], ["83928.6", "0.59343166", "0", "2"], ["83928.5", "1", "0", "1"], ["83928.2", "0", "0", "0"], ["83913.9", "0.2473799", "0", "2"], ["83912.9", "0", "0", "0"], ["83809", "0.2025", "0", "1"], ["83808", "0.00015274", "0", "2"]], "ts": "1742576912300", "checksum": 1927431898, "seqId": 49944899746, "prevSeqId": 49944899724}], "record_time": 1742576912.487673, "EXCHANGE": "OKX"}
{"arg": {"channel": "books", "instId": "BTC-USDT"}, "action": "update", "data": [{"asks": [["83951.8", "0", "0", "0"], ["83966.6", "0.23939744", "0", "3"], ["83966.8", "1.60973803", "0", "2"], ["83967.3", "0", "0", "0"], ["83970.8", "0", "0", "0"], ["83978.4", "0.0008", "0", "2"], ["83979.2", "0.0004", "0", "1"], ["83980", "0.00005736", "0", "1"], ["84140.7", "0.03", "0", "1"], ["84141.1", "0.00005109", "0", "1"]], "bids": [["83928.5", "0", "0", "0"], ["83928.2", "1", "0", "1"], ["83918.9", "0.17868", "0", "1"], ["83915.2", "0.08", "0", "2"], ["83914.4", "0.0408", "0", "3"], ["83913.9", "0.009", "0", "1"], ["83913.6", "0.00039943", "0", "1"], ["83912", "0.25139409", "0", "3"], ["83909.6", "0.1", "0", "2"], ["83908.8", "0.05", "0", "1"], ["83908", "0.00072", "0", "2"], ["83808.7", "0", "0", "0"], ["83808.2", "0", "0", "0"], ["83808", "0", "0", "0"]], "ts": "1742576912400", "checksum": 325052513, "seqId": 49944899781, "prevSeqId": 49944899746}], "record_time": 1742576912.573443, "EXCHANGE": "OKX"}
{"arg": {"channel": "books", "instId": "BTC-USDT"}, "action": "update", "data": [{"asks": [["83966.6", "0.00101534", "0", "2"], ["83969.5", "0.23838124", "0", "1"], ["83970.9", "0.60648947", "0", "2"], ["83974", "1.18772768", "0", "2"], ["84141.1", "0", "0", "0"]], "bids": [["83922", "1.00037199", "0", "3"], ["83912", "0.25139335", "0", "3"]], "ts": "1742576912500", "checksum": 325052513, "seqId": 49944899795, "prevSeqId": 49944899781}], "record_time": 1742576912.677266, "EXCHANGE": "OKX"}
{"arg": {"channel": "books", "instId": "BTC-USDT"}, "action": "update", "data": [{"asks": [["83948.1", "1.07501858", "0", "23"], ["83953.4", "0.0024", "0", "1"], ["83973.4", "0.01974536", "0", "2"], ["83989.1", "0", "0", "0"]], "bids": [], "ts": "1742576912600", "checksum": -557378406, "seqId": 49944899802, "prevSeqId": 49944899795}], "record_time": 1742576912.773321, "EXCHANGE": "OKX"}
{"arg": {"channel": "books", "instId": "BTC-USDT"}, "action": "update", "data": [{"asks": [["83966.7", "1.1563914", "0", "3"], ["83966.8", "1", "0", "1"], ["83978.4", "0", "0", "0"], ["83979.2", "0.0008", "0", "2"], ["83980", "0.00045736", "0", "2"], ["84141.1", "0.00005109", "0", "1"]], "bids": [["83932.8", "0.89672389", "0", "3"], ["83929.5", "1.17868", "0", "2"], ["83928.6", "0.29343166", "0", "2"], ["83928.2", "0", "0", "0"], ["83915.2", "0", "0", "0"], ["83914.4", "0.0808", "0", "4"], ["83913.6", "0.04039943", "0", "2"], ["83909.6", "0", "0", "0"], ["83908.8", "0.1", "0", "2"], ["83908", "0.05072", "0", "3"], ["83808.7", "0.00001501", "0", "1"], ["83808.2", "0.00001199", "0", "1"], ["83808", "0.00015274", "0", "2"]], "ts": "1742576912700", "checksum": -557378406, "seqId": 49944899821, "prevSeqId": 49944899802}], "record_time": 1742576912.874608, "EXCHANGE": "OKX"}
{"arg": {"channel": "books", "instId": "BTC-USDT"}, "action": "update", "data": [{"asks": [["83969.5", "0", "0", "0"], ["83970.8", "0.23837837", "0", "1"], ["83976.4", "0.0335018", "0", "2"], ["83983", "0", "0", "0"], ["84141.2", "0.00011161", "0", "1"]], "bids": [["83931.1", "1.11920246", "0", "2"], ["83929.5", "0.17868", "0", "1"], ["83914.4", "0.08", "0", "2"], ["83913.6", "0.04079943", "0", "3"], ["83912.9", "0.23837837", "0", "1"], ["83912.8", "0.02639943", "0", "3"], ["83912", "0.01301199", "0", "2"], ["83808", "0", "0", "0"]], "ts": "1742576912900", "checksum": -557378406, "seqId": 49944899837, "prevSeqId": 49944899821}], "record_time": 1742576913.094255, "EXCHANGE": "OKX"}
{"arg": {"channel": "books", "instId": "BTC-USDT"}, "action": "update", "data": [{"asks": [["83970.8", "0", "0", "0"], ["83973", "0.2383778", "0", "1"], ["83976.2", "0.01190814", "0", "1"], ["83982.9", "0", "0", "0"]], "bids": [["83931.9", "0.01368199", "0", "2"], ["83914.4", "0.0808", "0", "4"], ["83913.9", "0.2473778", "0", "2"], ["83913.6", "0.04039943", "0", "2"], ["83912.9", "0", "0", "0"], ["83912.8", "0.026", "0", "2"], ["83808", "0.00015274", "0", "2"]], "ts": "1742576913000", "checksum": -557378406, "seqId": 49944899848, "prevSeqId": 49944899837}], "record_time": 1742576913.173798, "EXCHANGE": "OKX"}
{"arg": {"channel": "books", "instId": "BTC-USDT"}, "action": "update", "data": [{"asks": [["83948.1", "0.87501858", "0", "22"], ["83951.3", "0", "0", "0"], ["83953.4", "0", "0", "0"], ["83962.4", "0", "0", "0"], ["83966.8", "0", "0", "0"], ["83968.3", "1", "0", "1"], ["83973", "0.2383781", "0", "1"], ["83992.6", "0.29669705", "0", "3"], ["84141.7", "0.03", "0", "1"], ["84141.9", "0.00002329", "0", "1"], ["84142.2", "0.17898725", "0", "1"]], "bids": [["83948", "0.15737611", "0", "5"], ["83929.6", "0.13513", "0", "1"], ["83923.4", "1.01135052", "0", "2"], ["83913.9", "0.009", "0", "1"], ["83912.9", "0.2383781", "0", "1"], ["83898.7", "0.61004615", "0", "1"], ["83859.7", "0.22913815", "0", "3"], ["83853.1", "0.1764305", "0", "1"], ["83808.7", "0", "0", "0"], ["83808.2", "0", "0", "0"], ["83808", "0", "0", "0"]], "ts": "1742576913100", "checksum": 1189699799, "seqId": 49944899871, "prevSeqId": 49944899848}], "record_time": 1742576913.274066, "EXCHANGE": "OKX"}
{"arg": {"channel": "books", "instId": "BTC-USDT"}, "action": "update", "data": [{"asks": [["83948.1", "0.85714958", "0", "21"], ["83949.5", "0.003573", "0", "1"], ["83953.5", "0.11917081", "0", "1"], ["83958.5", "0.0071985", "0", "1"], ["83968.3", "0", "0", "0"], ["83970.1", "1", "0", "1"], ["83977.3", "0", "0", "0"], ["84141.9", "0", "0", "0"], ["84142.2", "0", "0", "0"]], "bids": [["83932.8", "0.89671669", "0", "3"], ["83931.6", "1", "0", "1"], ["83931.1", "0.11920246", "0", "1"], ["83918.9", "0", "0", "0"], ["83916.1", "0.2383742", "0", "1"], ["83912.9", "0", "0", "0"], ["83809", "0", "0", "0"], ["83808.7", "0.00001501", "0", "1"]], "ts": "1742576913200", "checksum": 1887370299, "seqId": 49944899895, "prevSeqId": 49944899871}], "record_time": 1742576913.373605, "EXCHANGE": "OKX"}
{"arg": {"channel": "books", "instId": "BTC-USDT"}, "action": "update", "data": [{"asks": [["83948.1", "0.75699884", "0", "20"], ["83951.5", "0", "0", "0"], ["83951.9", "0.03037", "0", "2"], ["83953.9", "0", "0", "0"], ["83958.2", "0.03112", "0", "1"], ["83958.5", "0", "0", "0"], ["83974", "0.18772768", "0", "1"], ["84141.9", "0.00002329", "0", "1"], ["84142.2", "0.17898725", "0", "1"]], "bids": [["83948", "0.60562653", "0", "8"], ["83946", "0.0439", "0", "1"], ["83938.5", "0.01367", "0", "1"], ["83934.3", "0", "0", "0"], ["83934.1", "1", "0", "1"], ["83932.2", "0.05295075", "0", "2"], ["83931.6", "0", "0", "0"], ["83927.9", "0", "0", "0"], ["83923.4", "0.31", "0", "1"], ["83922", "0.00037199", "0", "2"], ["83913.7", "0", "0", "0"], ["83910.1", "0.5776526", "0", "1"], ["83873.6", "0.08241272", "0", "1"], ["83871.7", "0", "0", "0"], ["83869.6", "0.46158666", "0", "2"], ["83868.1", "0.58226341", "0", "1"], ["83809", "0.2025", "0", "1"], ["83808.7", "0", "0", "0"]], "ts": "1742576913300", "checksum": -603421292, "seqId": 49944899930, "prevSeqId": 49944899895}], "record_time": 1742576913.47522, "EXCHANGE": "OKX"}
{"arg": {"channel": "books", "instId": "BTC-USDT"}, "action": "update", "data": [{"asks": [["83948.1", "0.59077163", "0", "18"], ["83951.9", "0.02", "0", "1"], ["83952.6", "0.01153238", "0", "1"], ["83954.9", "0.04084853", "0", "1"], ["83955.7", "0.09056203", "0", "1"], ["83956.8", "0", "0", "0"], ["83957.2", "0.00774241", "0", "1"], ["83959.5", "0.000357", "0", "1"], ["83962.3", "0.17868", "0", "1"], ["83962.9", "0.00352647", "0", "1"], ["83966.7", "0.78487703", "0", "3"], ["83970.1", "0", "0", "0"], ["83970.9", "0.39244611", "0", "1"], ["83973", "0", "0", "0"], ["83973.4", "0.002", "0", "1"], ["83978.2", "0.23835848", "0", "1"], ["83985", "0", "0", "0"], ["83989.1", "0.01774536", "0", "1"], ["84005.5", "0.25015", "0", "1"], ["84141.2", "0", "0", "0"], ["84141.7", "0", "0", "0"], ["84141.9", "0", "0", "0"], ["84142.2", "0", "0", "0"]], "bids": [["83944.1", "0.0263436", "0", "1"], ["83938.6", "0.49704059", "0", "1"], ["83938.5", "1.01367", "0", "2"], ["83938.4", "0.00385992", "0", "1"], ["83934.1", "0", "0", "0"], ["83932.8", "0.5195883", "0", "2"], ["83932.1", "0.17868", "0", "1"], ["83929.1", "0", "0", "0"], ["83923.5", "0.23835848", "0", "1"], ["83916.1", "0", "0", "0"], ["83899.5", "0.02488967", "0", "1"], ["83897.6", "0.0249433", "0", "1"], ["83809.5", "0", "0", "0"], ["83809.4", "0", "0", "0"], ["83809", "0", "0", "0"]], "ts": "1742576913400", "checksum": -1870577011, "seqId": 49944899984, "prevSeqId": 49944899930}], "record_time": 1742576913.573759, "EXCHANGE": "OKX"}
{"arg": {"channel": "books", "instId": "BTC-USDT"}, "action": "update", "data": [{"asks": [["83948.1", "0.57885277", "0", "17"], ["83949.5", "0", "0", "0"], ["83949.6", "0.07821401", "0", "1"], ["83950.2", "0.01191848", "0", "1"], ["83951.4", "0", "0", "0"], ["83952.6", "0", "0", "0"], ["83955.2", "0.01037", "0", "1"], ["83955.7", "0.06234593", "0", "1"], ["83956", "0.08683364", "0", "2"], ["83956.7", "0", "0", "0"], ["83958.5", "0.04", "0", "1"], ["83959.7", "0.01153238", "0", "1"], ["83972", "1", "0", "1"], ["83979.6", "0.3601053", "0", "2"], ["84002", "0", "0", "0"]], "bids": [["83948", "0.66011653", "0", "9"], ["83941.8", "0.01368199", "0", "2"], ["83940.1", "0.01191848", "0", "1"], ["83938.6", "0.18936393", "0", "1"], ["83938.5", "0", "0", "0"], ["83937.1", "0", "0", "0"], ["83937", "0.47735847", "0", "2"], ["83935.7", "1", "0", "1"], ["83929.5", "0", "0", "0"], ["83923.5", "0", "0", "0"], ["83922.8", "0.00476629", "0", "1"], ["83921.7", "0.23835958", "0", "1"]], "ts": "1742576913500", "checksum": -1115046572, "seqId": 49944900022, "prevSeqId": 49944899984}], "record_time": 1742576913.674319, "EXCHANGE": "OKX"}
{"arg": {"channel": "books", "instId": "BTC-USDT"}, "action": "update", "data": [{"asks": [["83951.9", "0", "0", "0"], ["83953.7", "0.02", "0", "1"], ["83959.2", "0.25288782", "0", "2"], ["83959.3", "0.35736", "0", "1"], ["83962.3", "0", "0", "0"]], "bids": [["83931.6", "0.35736", "0", "1"], ["83809.7", "0", "0", "0"]], "ts": "1742576913600", "checksum": 1403448923, "seqId": 49944900028, "prevSeqId": 49944900022}], "record_time": 1742576913.775549, "EXCHANGE": "OKX"}
{"arg": {"channel": "books", "instId": "BTC-USDT"}, "action": "update", "data": [{"asks": [["83948.1", "0", "0", "0"], ["83949.6", "0", "0", "0"], ["83950", "0", "0", "0"], ["83950.2", "0", "0", "0"], ["83951.6", "0", "0", "0"], ["83952", "0", "0", "0"], ["83952.3", "0", "0", "0"], ["83953.5", "0", "0", "0"], ["83953.7", "0", "0", "0"], ["83954", "0", "0", "0"], ["83954.2", "0", "0", "0"], ["83954.9", "0", "0", "0"], ["83955.2", "0", "0", "0"], ["83955.7", "0", "0", "0"], ["83956", "0", "0", "0"], ["83956.5", "0", "0", "0"], ["83957", "0", "0", "0"], ["83957.2", "0", "0", "0"], ["83957.4", "0", "0", "0"], ["83957.5", "0", "0", "0"], ["83957.9", "0", "0", "0"], ["83958.2", "0", "0", "0"], ["83958.5", "0", "0", "0"], ["83959.2", "0", "0", "0"], ["83959.3", "0", "0", "0"], ["83959.5", "0", "0", "0"], ["83959.7", "0", "0", "0"], ["83961.3", "0", "0", "0"], ["83961.5", "0", "0", "0"], ["83961.6", "0", "0", "0"], ["83962.2", "0", "0", "0"], ["83962.5", "0", "0", "0"], ["83962.9", "0", "0", "0"], ["83963.5", "0", "0", "0"], ["83963.8", "0", "0", "0"], ["83964.4", "0", "0", "0"], ["83964.5", "0", "0", "0"], ["83964.7", "0", "0", "0"], ["83964.8", "0", "0", "0"], ["83965.4", "0", "0", "0"], ["83966.4", "0", "0", "0"], ["83966.6", "0", "0", "0"], ["83966.7", "0", "0", "0"], ["83966.9", "0", "0", "0"], ["83967.7", "0", "0", "0"], ["83968.4", "0", "0", "0"], ["83969.1", "0", "0", "0"], ["83969.6", "0", "0", "0"], ["83970.2", "0", "0", "0"], ["83970.9", "0", "0", "0"], ["83971", "0", "0", "0"], ["83971.4", "0", "0", "0"], ["83971.8", "0.77056064", "0", "7"], ["83972", "0", "0", "0"], ["83972.9", "0", "0", "0"], ["83973.1", "0", "0", "0"], ["83973.2", "0.01191493", "0", "1"], ["83973.5", "0", "0", "0"], ["83973.6", "0.02077034", "0", "1"], ["83973.7", "0.02383446", "0", "1"], ["83973.8", "0.0015", "0", "1"], ["83974", "0.0439", "0", "1"], ["83976", "0.0439", "0", "1"], ["83976.2", "0.07552964", "0", "1"], ["83976.3", "0.11912149", "0", "3"], ["83976.4", "0.02159369", "0", "1"], ["83976.5", "1", "0", "1"], ["83976.6", "0.01", "0", "1"], ["83976.8", "0", "0", "0"], ["83977.8", "0.05956064", "0", "1"], ["83978.2", "0", "0", "0"], ["83978.3", "0", "0", "0"], ["83978.9", "0", "0", "0"], ["83979.2", "0", "0", "0"], ["83979.5", "0", "0", "0"], ["83979.6", "0", "0", "0"], ["83979.9", "0.30875118", "0", "2"], ["83980", "0.00005736", "0", "1"], ["83981", "0", "0", "0"], ["83981.9", "0", "0", "0"], ["83982.2", "0.000015", "0", "1"], ["83982.8", "0", "0", "0"], ["83983.8", "0", "0", "0"], ["83983.9", "0.17830599", "0", "2"], ["83984", "0.5", "0", "1"], ["83984.3", "0", "0", "0"], ["83984.5", "0", "0", "0"], ["83984.8", "0", "0", "0"], ["83985.2", "0.04084853", "0", "1"], ["83986.7", "0.05956064", "0", "1"], ["83987", "0.04", "0", "1"], ["83987.2", "0", "0", "0"], ["83988", "0", "0", "0"], ["83988.5", "0.2698718", "0", "1"], ["83988.6", "0.2025", "0", "1"], ["83989.2", "0", "0", "0"], ["83989.3", "0.26238", "0", "1"], ["83989.4", "0", "0", "0"], ["83989.5", "0.05956064", "0", "1"], ["83990.5", "0", "0", "0"], ["83990.6", "0.000015", "0", "1"], ["83991", "0.3565323", "0", "1"], ["83991.2", "0.00081199", "0", "3"], ["83992", "0.0005723", "0", "2"], ["83992.3", "0", "0", "0"], ["83992.5", "0.05000102", "0", "1"], ["83992.6", "0.1", "0", "1"], ["83992.9", "0", "0", "0"], ["83994", "0.02964377", "0", "1"], ["83994.1", "0.05959609", "0", "1"], ["83994.2", "0", "0", "0"], ["83994.7", "0.001787", "0", "1"], ["83995.9", "0", "0", "0"], ["83996.1", "0.17898725", "0", "1"], ["83996.2", "0.38535028", "0", "2"], ["83996.3", "0", "0", "0"], ["83997.2", "0.01190516", "0", "1"], ["83998.4", "0.02382141", "0", "1"], ["83999.1", "0.2025", "0", "1"], ["83999.6", "0", "0", "0"], ["84000", "0.26773755", "0", "6"], ["84000.8", "0.03999999", "0", "1"], ["84001.4", "0", "0", "0"], ["84002.6", "0.0119044", "0", "1"], ["84003.1", "0", "0", "0"], ["84004.6", "0.01962952", "0", "1"], ["84005", "0.01190406", "0", "1"], ["84005.1", "0.02380808", "0", "2"], ["84005.3", "0.01190402", "0", "1"], ["84005.4", "0", "0", "0"], ["84005.5", "0", "0", "0"], ["84005.6", "0.24772768", "0", "3"], ["84005.7", "0.04190396", "0", "2"], ["84006.8", "0", "0", "0"], ["84008", "0", "0", "0"], ["84008.7", "0.27727721", "0", "2"], ["84008.8", "0", "0", "0"], ["84009.1", "0", "0", "0"], ["84010.1", "0.00103317", "0", "1"], ["84010.3", "0.1126366", "0", "2"], ["84010.7", "0.17844276", "0", "2"], ["84013.4", "0.14079576", "0", "1"], ["84013.6", "0", "0", "0"], ["84013.7", "0", "0", "0"], ["84015.8", "0.1146467", "0", "2"], ["84016.5", "0.02283169", "0", "1"], ["84019.4", "0", "0", "0"], ["84019.5", "0.21889794", "0", "2"], ["84020.1", "0.05391", "0", "1"], ["84020.3", "0.0010362", "0", "1"], ["84020.5", "0.1", "0", "1"], ["84020.8", "0.1126366", "0", "2"], ["84021.4", "0.32527522", "0", "1"], ["84021.5", "0", "0", "0"], ["84022.4", "0.00589875", "0", "1"], ["84022.5", "0.11597977", "0", "1"], ["84023", "0.0178619", "0", "1"], ["84024.2", "0.00591375", "0", "2"], ["84024.6", "0", "0", "0"], ["84025", "0.00589875", "0", "1"], ["84026.7", "0", "0", "0"], ["84027.8", "0.04764397", "0", "1"], ["84029.2", "0.00595606", "0", "1"], ["84029.3", "0", "0", "0"], ["84030.9", "0.00589875", "0", "1"], ["84031.3", "0.13513153", "0", "3"], ["84034.2", "0", "0", "0"], ["84034.3", "0", "0", "0"], ["84037", "0", "0", "0"], ["84038.3", "0.00589875", "0", "1"], ["84038.4", "0", "0", "0"], ["84038.6", "0", "0", "0"], ["84039", "0.35271685", "0", "1"], ["84039.1", "0", "0", "0"], ["84039.2", "0", "0", "0"], ["84039.3", "0", "0", "0"], ["84039.4", "0", "0", "0"], ["84040.9", "0", "0", "0"], ["84041", "0.000015", "0", "1"], ["84042.4", "0.3869708", "0", "2"], ["84042.6", "0.55582395", "0", "1"], ["84042.8", "0", "0", "0"], ["84045.2", "0.00595193", "0", "1"], ["84045.5", "0.00589875", "0", "1"], ["84046", "0.3565323", "0", "1"], ["84046.4", "0", "0", "0"], ["84046.6", "0.06422538", "0", "2"], ["84046.7", "0", "0", "0"], ["84047.6", "0.02381751", "0", "1"], ["84049.4", "0.000015", "0", "1"], ["84050.2", "0.02381784", "0", "1"], ["84051.3", "0", "0", "0"], ["84053.5", "0.01169752", "0", "2"], ["84057.8", "0.000015", "0", "1"], ["84062", "0.03528943", "0", "3"], ["84062.1", "0.02142296", "0", "2"], ["84062.2", "0", "0", "0"], ["84062.4", "0.00010514", "0", "1"], ["84062.7", "0.0214", "0", "1"], ["84062.9", "0.0214", "0", "1"], ["84063.7", "0.18478602", "0", "2"], ["84064.4", "0.67929468", "0", "1"], ["84064.5", "0.3565323", "0", "1"], ["84067", "0.000012", "0", "1"], ["84067.3", "0.41658084", "0", "2"], ["84067.4", "0", "0", "0"], ["84068.3", "0.00589875", "0", "1"], ["84068.4", "0", "0", "0"], ["84069", "0.00579877", "0", "1"], ["84071.1", "0.0214", "0", "1"], ["84071.2", "0", "0", "0"], ["84071.4", "0.72698575", "0", "2"], ["84078", "0.05943929", "0", "1"], ["84079.3", "0.00001199", "0", "1"], ["84080", "0.07166249", "0", "1"], ["84082.1", "0.24901526", "0", "1"], ["84083", "0", "0", "0"], ["84083.1", "0.2025", "0", "1"], ["84086.7", "0.07165719", "0", "1"], ["84087.3", "0.0284", "0", "2"], ["84087.4", "0.0568", "0", "4"], ["84087.9", "0.0142", "0", "1"], ["84089.6", "0.11889794", "0", "1"], ["84091.5", "0.2025", "0", "1"], ["84093.1", "0.27224905", "0", "1"], ["84094.3", "0.21549", "0", "1"], ["84096.1", "0", "0", "0"], ["84099", "0.00595444", "0", "1"], ["84099.5", "0.0214", "0", "1"], ["84099.9", "1.826165", "0", "5"], ["84101.2", "0.17147741", "0", "1"], ["84104.1", "0.00001199", "0", "1"], ["84104.2", "0", "0", "0"], ["84105.2", "0.00001053", "0", "1"], ["84107", "0.05479021", "0", "4"], ["84108.9", "0.02698292", "0", "1"], ["84114.7", "0.00595438", "0", "1"], ["84115.8", "0.01190888", "0", "2"], ["84116.7", "0.11889794", "0", "1"], ["84118.1", "0", "0", "0"], ["84129.7", "0.00594641", "0", "1"], ["84130.5", "0.11889794", "0", "1"], ["84141.2", "0.00011161", "0", "1"], ["84141.7", "0.03", "0", "1"], ["84141.9", "0.00002329", "0", "1"], ["84142.2", "0.17898725", "0", "1"], ["84142.8", "0.02898561", "0", "3"], ["84143.8", "0.00001314", "0", "1"], ["84144.1", "0.0000568", "0", "1"], ["84144.5", "0.00001211", "0", "1"], ["84145.1", "0.00039405", "0", "2"], ["84145.2", "0.00167282", "0", "19"], ["84145.5", "0.3565323", "0", "1"], ["84145.6", "0.00238839", "0", "1"], ["84145.9", "0.00007383", "0", "2"], ["84146", "0.00030374", "0", "1"], ["84146.4", "0.01057876", "0", "3"], ["84146.6", "0.00316424", "0", "7"], ["84146.8", "0.00006501", "0", "2"], ["84147", "0.00013082", "0", "1"], ["84147.1", "0.00002399", "0", "2"], ["84147.3", "0.11889794", "0", "1"], ["84147.4", "0.00001923", "0", "1"], ["84147.7", "0.00001067", "0", "1"], ["84148.2", "0.00001009", "0", "1"], ["84148.4", "0.00008552", "0", "1"], ["84148.5", "0.0015", "0", "1"], ["84148.6", "0.00010768", "0", "1"], ["84148.7", "0.00001205", "0", "1"], ["84149", "0.00237673", "0", "1"], ["84149.2", "0.00004828", "0", "1"], ["84149.3", "0.00009303", "0", "1"], ["84149.9", "0.00165926", "0", "2"], ["84150", "0.00879676", "0", "23"], ["84150.1", "0.00019562", "0", "1"], ["84150.7", "0.17898725", "0", "1"], ["84150.9", "0.00003349", "0", "2"], ["84151.3", "0.00001016", "0", "1"], ["84151.4", "0.01788", "0", "1"], ["84151.6", "0.00001644", "0", "1"], ["84151.7", "0.00005618", "0", "1"], ["84152", "0.00001039", "0", "1"], ["84152.4", "0.00017873", "0", "6"], ["84152.5", "0.00001049", "0", "1"], ["84152.9", "0.00008", "0", "1"], ["84153", "0.00042337", "0", "1"], ["84153.3", "0.00002848", "0", "1"]], "bids": [["83971.7", "0.67089072", "0", "13"], ["83970.2", "0.00595606", "0", "1"], ["83970", "0.0439", "0", "1"], ["83968", "0.0439", "0", "1"], ["83966", "0.0439", "0", "1"], ["83964.6", "0.20845606", "0", "2"], ["83964.4", "0.17898725", "0", "1"], ["83964", "0.0439", "0", "1"], ["83960", "0.00001", "0", "1"], ["83957.1", "0.00001013", "0", "1"], ["83956.4", "0.3565323", "0", "1"], ["83955.9", "0.17898725", "0", "1"], ["83954.8", "0.00002025", "0", "1"], ["83954.7", "0.0000405", "0", "1"], ["83954", "0.0439", "0", "1"], ["83953.8", "0.000162", "0", "1"], ["83953.6", "0.00032401", "0", "1"], ["83953.4", "0.18772768", "0", "1"], ["83952.5", "0.000081", "0", "1"], ["83952", "0.0439", "0", "1"], ["83951.6", "0.02751695", "0", "1"], ["83951.5", "0.000015", "0", "1"], ["83951.3", "0.11889794", "0", "1"], ["83950.7", "0.00064802", "0", "1"], ["83950.5", "0.00129603", "0", "1"], ["83950.4", "0.00006", "0", "1"], ["83950.1", "0.04", "0", "1"], ["83950", "0.0439", "0", "1"], ["83949.9", "0.00319851", "0", "2"], ["83948.2", "0.74622239", "0", "1"], ["83948", "0.33561449", "0", "7"], ["83947.6", "0.00714732", "0", "1"], ["83947.5", "0.53551955", "0", "2"], ["83947.4", "0", "0", "0"], ["83946.7", "0.00001199", "0", "1"], ["83946", "0", "0", "0"], ["83945.6", "0.08100033", "0", "1"], ["83945.2", "0.01153238", "0", "1"], ["83944.8", "0.00011161", "0", "1"], ["83944.2", "0.23829765", "0", "1"], ["83944.1", "0", "0", "0"], ["83944", "0", "0", "0"], ["83943.5", "0.01191915", "0", "1"], ["83943.1", "0.000015", "0", "1"], ["83942", "0", "0", "0"], ["83941.8", "0.00001199", "0", "1"], ["83940.1", "0", "0", "0"], ["83940", "0.00001", "0", "1"], ["83938.7", "0.11889794", "0", "1"], ["83938.4", "0", "0", "0"], ["83938.1", "0", "0", "0"], ["83938", "0", "0", "0"], ["83937", "0.11362034", "0", "1"], ["83936", "0", "0", "0"], ["83935.7", "0", "0", "0"], ["83935.6", "0", "0", "0"], ["83934", "0", "0", "0"], ["83933.9", "0", "0", "0"], ["83933.3", "0.00101534", "0", "2"], ["83932.8", "0.33186062", "0", "1"], ["83932.2", "0", "0", "0"], ["83932.1", "0", "0", "0"], ["83932", "0", "0", "0"], ["83931.9", "0.00001199", "0", "1"], ["83931.6", "0", "0", "0"], ["83931.5", "0.02383524", "0", "1"], ["83929.4", "0", "0", "0"], ["83928.6", "0.62684829", "0", "3"], ["83927.8", "0", "0", "0"], ["83926.8", "0.59271", "0", "1"], ["83926.6", "0.5397", "0", "1"], ["83926.3", "0.000015", "0", "1"], ["83925.5", "0.05246", "0", "1"], ["83924.4", "0.08991011", "0", "1"], ["83923.5", "0.11889794", "0", "1"], ["83923.4", "0.26698318", "0", "1"], ["83923", "0", "0", "0"], ["83922.8", "0", "0", "0"], ["83921.7", "0", "0", "0"], ["83921.6", "0", "0", "0"], ["83921.4", "0", "0", "0"], ["83921.1", "0.01788358", "0", "1"], ["83919", "0.00774074", "0", "1"], ["83917.9", "0.01192389", "0", "3"], ["83917.4", "0.000015", "0", "1"], ["83917", "0.01505324", "0", "3"], ["83915.7", "0.64098334", "0", "1"], ["83914.5", "0", "0", "0"], ["83914.4", "0.01190888", "0", "2"], ["83914", "0.01244888", "0", "3"], ["83913.8", "0", "0", "0"], ["83913.6", "0", "0", "0"], ["83913.1", "0", "0", "0"], ["83912.8", "0", "0", "0"], ["83912.5", "0.0894", "0", "1"], ["83912.1", "0", "0", "0"], ["83912", "0.09192087", "0", "5"], ["83911.8", "0", "0", "0"], ["83911.2", "0.0408", "0", "3"], ["83911", "0", "0", "0"], ["83910.4", "0.00039968", "0", "1"], ["83910.3", "0", "0", "0"], ["83910.2", "0.2185", "0", "2"], ["83910", "1.01190888", "0", "3"], ["83909.6", "0.026", "0", "2"], ["83908.8", "0.013", "0", "1"], ["83908", "0.00072", "0", "2"], ["83907.3", "0.01964962", "0", "3"], ["83906.7", "0", "0", "0"], ["83906.6", "1.27233393", "0", "2"], ["83906.5", "0", "0", "0"], ["83906.4", "0.1", "0", "2"], ["83905.6", "0.05", "0", "1"], ["83903.4", "0", "0", "0"], ["83901.9", "1.28455245", "0", "2"], ["83900.6", "0", "0", "0"], ["83899.9", "0.01936955", "0", "3"], ["83899.5", "0", "0", "0"], ["83898.8", "0.00595606", "0", "1"], ["83898.5", "0.47790706", "0", "2"], ["83897.6", "0", "0", "0"], ["83897.5", "0", "0", "0"], ["83896.7", "0", "0", "0"], ["83896.1", "0.00357", "0", "1"], ["83895.4", "0.00595606", "0", "1"], ["83895", "0.0563183", "0", "1"], ["83892.8", "0", "0", "0"], ["83889.3", "0", "0", "0"], ["83889.1", "0.20997", "0", "1"], ["83879.2", "0.03576716", "0", "1"], ["83869.6", "0.24407231", "0", "1"], ["83865", "0", "0", "0"], ["83862.6", "0.00001198", "0", "1"], ["83862.1", "0.07166249", "0", "1"], ["83853.1", "0", "0", "0"], ["83853", "0", "0", "0"], ["83851.1", "0", "0", "0"], ["83848.8", "0.01999571", "0", "1"], ["83847.2", "0", "0", "0"], ["83843.9", "0.0054", "0", "1"], ["83843.8", "0", "0", "0"], ["83841.7", "0", "0", "0"], ["83840.1", "0", "0", "0"], ["83839.7", "0.00001", "0", "1"], ["83831.6", "0.1", "0", "1"], ["83831.4", "0.00595444", "0", "1"], ["83830.1", "0", "0", "0"], ["83829.4", "0", "0", "0"], ["83821.5", "0.17898725", "0", "1"], ["83820.5", "0", "0", "0"], ["83820.4", "0", "0", "0"], ["83819.7", "0", "0", "0"], ["83816.7", "0", "0", "0"], ["83815.9", "0.00004266", "0", "1"], ["83815.1", "0", "0", "0"], ["83815", "0.35776874", "0", "1"], ["83814.7", "0.04786326", "0", "4"], ["83813.1", "0", "0", "0"], ["83811.6", "0", "0", "0"], ["83810.9", "0", "0", "0"], ["83810.1", "0", "0", "0"], ["83809.8", "0", "0", "0"]], "ts": "1742576913700", "checksum": 1327722625, "seqId": 49944901525, "prevSeqId": 49944900028}], "record_time": 1742576913.875302, "EXCHANGE": "OKX"}
{"arg": {"channel": "books", "instId": "BTC-USDT"}, "action": "update", "data": [{"asks": [["83964.5", "1.27808652", "0", "15"], ["83966", "0.0439", "0", "1"], ["83968", "0.0439", "0", "1"], ["83968.1", "0.052", "0", "2"], ["83969.3", "0.00333536", "0", "1"], ["83971.7", "0.08399364", "0", "1"], ["83971.8", "0.16484853", "0", "5"], ["83972", "0.0439", "0", "1"], ["83973.6", "0", "0", "0"], ["83973.7", "0", "0", "0"], ["83974", "0.05581534", "0", "2"], ["83975.9", "0.03954719", "0", "1"], ["83976.2", "0", "0", "0"], ["83976.3", "0.00001199", "0", "1"], ["83976.4", "0", "0", "0"], ["83976.5", "0", "0", "0"], ["83977.8", "0", "0", "0"], ["83978.9", "0.0563183", "0", "1"], ["83979.3", "0.03", "0", "1"], ["83979.9", "0", "0", "0"], ["83980", "0.04005736", "0", "2"], ["83980.1", "0.2450408", "0", "3"], ["83980.2", "0.2025", "0", "1"], ["83982.7", "0.06", "0", "2"], ["83982.9", "0.02383193", "0", "1"], ["83983.7", "0.11889794", "0", "1"], ["83983.8", "0.19506155", "0", "1"], ["83983.9", "0.01037", "0", "1"], ["83984.6", "0", "0", "0"], ["83984.7", "0", "0", "0"], ["83985.2", "0", "0", "0"], ["83986.7", "0", "0", "0"], ["83987", "0", "0", "0"], ["83988.4", "0.23831804", "0", "1"], ["83988.5", "0.22900496", "0", "2"], ["83989.1", "0", "0", "0"], ["83989.3", "0.0563183", "0", "1"], ["83989.5", "0", "0", "0"], ["83991", "0", "0", "0"], ["83991.1", "0", "0", "0"], ["83991.2", "0.00001199", "0", "1"], ["83991.3", "0.3565323", "0", "1"], ["83992", "0.0001723", "0", "1"], ["83992.5", "0", "0", "0"], ["83992.6", "0", "0", "0"], ["83993.4", "0.08361603", "0", "1"], ["83993.5", "0.11889794", "0", "1"], ["83994", "0", "0", "0"], ["83994.5", "0", "0", "0"], ["83994.7", "0", "0", "0"], ["83995.3", "0", "0", "0"], ["83997", "0.05321263", "0", "2"], ["83998.4", "0", "0", "0"], ["83999.2", "0.0008", "0", "2"], ["83999.8", "0.0563183", "0", "1"], ["84000", "0.18813756", "0", "5"], ["84000.7", "0.03920164", "0", "1"], ["84000.8", "0", "0", "0"], ["84002.3", "0.11889794", "0", "1"], ["84004.2", "0.32205415", "0", "1"], ["84004.6", "0", "0", "0"], ["84006.1", "0.14080774", "0", "2"], ["84006.7", "0", "0", "0"], ["84007.2", "0.07999999", "0", "2"], ["84008", "0.03999999", "0", "1"], ["84008.7", "0.08308674", "0", "1"], ["84009.2", "0.1", "0", "1"], ["84010.1", "0", "0", "0"], ["84010.7", "0.11889794", "0", "1"], ["84011.1", "0.00001501", "0", "1"], ["84016.5", "0", "0", "0"], ["84016.8", "0.33608225", "0", "2"], ["84017.1", "0.02283169", "0", "1"], ["84017.6", "0.262392", "0", "2"], ["84020.6", "0.00103317", "0", "1"], ["84021.1", "0", "0", "0"], ["84021.2", "0.02381495", "0", "1"], ["84021.4", "0.18691857", "0", "1"], ["84022.9", "0", "0", "0"], ["84023.4", "0", "0", "0"], ["84023.6", "0", "0", "0"], ["84026.1", "0.25504555", "0", "2"], ["84027.6", "0.01133139", "0", "1"], ["84028.3", "0.471891", "0", "1"], ["84031.3", "0.12085114", "0", "2"], ["84034.8", "0.17417168", "0", "1"], ["84035.4", "0", "0", "0"], ["84037.6", "0", "0", "0"], ["84039", "0.1159533", "0", "1"], ["84039.5", "0.001787", "0", "1"], ["84040.8", "0.00598532", "0", "2"], ["84042.4", "0.23192292", "0", "1"], ["84042.6", "0", "0", "0"], ["84045.1", "0.1427805", "0", "2"], ["84050.4", "0.21453965", "0", "2"], ["84051.2", "0.43692", "0", "1"], ["84051.7", "0", "0", "0"], ["84061.9", "0.03633874", "0", "1"], ["84062", "0.01169752", "0", "2"], ["84062.8", "0.0214", "0", "1"], ["84064.4", "0.23160395", "0", "1"], ["84065.7", "0.05950588", "0", "1"], ["84066.3", "0.2025", "0", "1"], ["84067.3", "0.30051565", "0", "1"], ["84067.7", "0.08359014", "0", "1"], ["84068.5", "0", "0", "0"], ["84079.8", "0", "0", "0"], ["84084.6", "0.45313253", "0", "1"], ["84084.7", "0.61647", "0", "1"], ["84089.5", "0.09119502", "0", "1"], ["84091.5", "0", "0", "0"], ["84098.9", "0.1133139", "0", "1"], ["84099.5", "0", "0", "0"], ["84099.8", "0.01774536", "0", "1"], ["84099.9", "1.623665", "0", "4"], ["84112", "0", "0", "0"], ["84118.3", "1.64325", "0", "1"], ["84152.4", "0", "0", "0"], ["84152.5", "0", "0", "0"], ["84152.9", "0", "0", "0"], ["84153", "0", "0", "0"], ["84153.3", "0", "0", "0"]], "bids": [["83971.7", "0", "0", "0"], ["83970.2", "0", "0", "0"], ["83970", "0", "0", "0"], ["83968", "0", "0", "0"], ["83966", "0", "0", "0"], ["83964.6", "0", "0", "0"], ["83964.4", "1.15829377", "0", "7"], ["83964", "0", "0", "0"], ["83963.9", "0.01191511", "0", "1"], ["83962.1", "0.013173", "0", "1"], ["83962", "0.0439", "0", "1"], ["83960", "0.04391", "0", "2"], ["83957.8", "0.43781196", "0", "2"], ["83957.7", "0.2025", "0", "1"], ["83957.1", "0", "0", "0"], ["83956.4", "0", "0", "0"], ["83955", "0.14079576", "0", "1"], ["83954.8", "0", "0", "0"], ["83954.7", "0", "0", "0"], ["83954.2", "0.00112003", "0", "1"], ["83953.8", "0", "0", "0"], ["83953.6", "0", "0", "0"], ["83953.5", "0.10450296", "0", "1"], ["83952.4", "0.00353255", "0", "1"], ["83951.6", "0", "0", "0"], ["83951.3", "0", "0", "0"], ["83950.1", "0", "0", "0"], ["83949.8", "0.11917593", "0", "1"], ["83949.2", "0.02383023", "0", "1"], ["83949", "0.000813", "0", "1"], ["83948.3", "0.05959609", "0", "1"], ["83948.2", "0.19829625", "0", "1"], ["83948", "0.28009", "0", "5"], ["83947.6", "0", "0", "0"], ["83947.5", "0.17898725", "0", "1"], ["83946.7", "0.00358199", "0", "2"], ["83946.4", "0.135127", "0", "1"], ["83945.5", "0.036", "0", "1"], ["83945.2", "0", "0", "0"], ["83944.2", "0", "0", "0"], ["83943.6", "0.09052257", "0", "1"], ["83943.4", "0.003573", "0", "1"], ["83943.2", "0.04", "0", "1"], ["83941.7", "0.14079576", "0", "1"], ["83941.5", "0.04", "0", "1"], ["83941.4", "0.036", "0", "1"], ["83941.2", "0.033", "0", "1"], ["83940.5", "0.15786729", "0", "2"], ["83938.8", "0.2471543", "0", "2"], ["83938.6", "0", "0", "0"], ["83938.3", "0", "0", "0"], ["83937", "0.16993864", "0", "2"], ["83936.2", "0.01153238", "0", "1"], ["83933.1", "0", "0", "0"], ["83932.8", "0.22116946", "0", "1"], ["83931.5", "0", "0", "0"], ["83931.2", "0", "0", "0"], ["83931.1", "0", "0", "0"], ["83929.6", "0", "0", "0"], ["83926.9", "0.24660199", "0", "2"], ["83924", "0.0119036", "0", "1"], ["83923.5", "0.13080162", "0", "2"], ["83923.4", "0.27888687", "0", "2"], ["83923.3", "0.28969", "0", "2"], ["83922.8", "0.01190377", "0", "1"], ["83922.6", "0.0119038", "0", "1"], ["83920.3", "0.36823093", "0", "3"], ["83920.2", "0.18478657", "0", "2"], ["83919", "0", "0", "0"], ["83917.9", "0.0528191", "0", "10"], ["83917.8", "0.22478519", "0", "3"], ["83917.7", "0.6014969", "0", "2"], ["83917.5", "0", "0", "0"], ["83917.2", "0.00589931", "0", "1"], ["83915.7", "0.66733455", "0", "2"], ["83915.5", "0.0249433", "0", "1"], ["83914.3", "0", "0", "0"], ["83912.9", "0.01834592", "0", "1"], ["83911.7", "0", "0", "0"], ["83910.6", "0.00589931", "0", "1"], ["83910.1", "0", "0", "0"], ["83907.3", "0.01190888", "0", "2"], ["83906.6", "0.19631431", "0", "1"], ["83906.5", "0.00579932", "0", "1"], ["83904.1", "0.00100613", "0", "1"], ["83903.7", "0.00145203", "0", "1"], ["83902", "0.00219617", "0", "2"], ["83901.9", "0.18795326", "0", "1"], ["83899.9", "0.00101534", "0", "2"], ["83898.7", "0.35853614", "0", "1"], ["83898.3", "0", "0", "0"], ["83897.6", "0.04763569", "0", "1"], ["83896.1", "0", "0", "0"], ["83893.9", "0.16396686", "0", "1"], ["83889.6", "0.15281024", "0", "2"], ["83888.6", "0.00715234", "0", "1"], ["83887.7", "0.07277575", "0", "2"], ["83886.2", "2.89189345", "0", "2"], ["83883.1", "0.01190414", "0", "1"], ["83880.8", "0", "0", "0"], ["83880.7", "0", "0", "0"], ["83880.6", "0.10834864", "0", "2"], ["83880.4", "0.0715304", "0", "1"], ["83880.1", "0", "0", "0"], ["83880", "0.0000466", "0", "2"], ["83878.9", "0.02381754", "0", "1"], ["83878.3", "0.00579932", "0", "1"], ["83875.7", "0.58226341", "0", "1"], ["83874", "0.41159902", "0", "3"], ["83869.5", "0", "0", "0"], ["83868.5", "0.00579932", "0", "1"], ["83868.1", "0", "0", "0"], ["83867.6", "0", "0", "0"], ["83866.7", "0.00005728", "0", "1"], ["83865.8", "0", "0", "0"], ["83865", "0.10942769", "0", "1"], ["83863.2", "0.00579932", "0", "1"], ["83859.8", "0.20185452", "0", "1"], ["83859.6", "0", "0", "0"], ["83856.5", "0.12397415", "0", "1"], ["83856.4", "0", "0", "0"], ["83851.3", "0", "0", "0"], ["83851.1", "0.18015157", "0", "1"], ["83850.9", "0", "0", "0"], ["83841.8", "0.18345922", "0", "1"], ["83830.2", "0", "0", "0"], ["83830", "0.00005835", "0", "2"], ["83829", "0", "0", "0"], ["83828.3", "0", "0", "0"], ["83826.9", "0", "0", "0"], ["83825.9", "0.00001586", "0", "1"], ["83825.3", "0", "0", "0"], ["83825.2", "0", "0", "0"], ["83822.3", "0", "0", "0"], ["83822.2", "0.00299792", "0", "1"], ["83810.9", "1.72263", "0", "1"], ["83810.1", "0.00001655", "0", "1"]], "ts": "1742576913800", "checksum": -1510944069, "seqId": 49944902386, "prevSeqId": 49944901525}], "record_time": 1742576913.977851, "EXCHANGE": "OKX"}
{"arg": {"channel": "books", "instId": "BTC-USDT"}, "action": "update", "data": [{"asks": [["83964.5", "0.83855236", "0", "11"], ["83965.9", "0.04254", "0", "1"], ["83969.3", "0", "0", "0"], ["83970.8", "0.00334226", "0", "1"], ["83970.9", "0.02964377", "0", "1"], ["83971.4", "0.01191571", "0", "1"], ["83971.7", "0.08179109", "0", "1"], ["83971.8", "0.16284853", "0", "4"], ["83973.8", "0.00151501", "0", "2"], ["83974", "0.05404", "0", "2"], ["83974.4", "0.01014", "0", "1"], ["83975.9", "0.03306909", "0", "1"], ["83979.1", "0.03", "0", "1"], ["83979.3", "0.06", "0", "2"], ["83979.4", "0.03", "0", "1"], ["83980.1", "0.3468338", "0", "3"], ["83981.3", "0.04294563", "0", "2"], ["83982.5", "0.17898725", "0", "1"], ["83982.6", "0.23833088", "0", "1"], ["83982.9", "0.38036423", "0", "2"], ["83983.9", "0", "0", "0"], ["83988.4", "0", "0", "0"], ["83993.4", "0.05654821", "0", "1"], ["83994.9", "0", "0", "0"], ["83996.2", "0.27188896", "0", "2"], ["83997.5", "0", "0", "0"], ["83997.9", "0.02281284", "0", "1"], ["83999.8", "0.1126366", "0", "2"], ["84009.2", "0", "0", "0"], ["84014.5", "0.0115525", "0", "1"], ["84015.7", "0.00002157", "0", "1"], ["84015.8", "0.30661692", "0", "3"], ["84016.3", "0.1", "0", "1"], ["84016.6", "0.52717645", "0", "2"], ["84016.8", "0.49717618", "0", "1"], ["84016.9", "0", "0", "0"], ["84017.1", "0", "0", "0"], ["84018.4", "0.59085", "0", "1"], ["84018.7", "0.00577625", "0", "1"], ["84019.5", "0.11889794", "0", "1"], ["84020.5", "0", "0", "0"], ["84022.9", "0.00577625", "0", "1"], ["84026.2", "0.02381354", "0", "1"], ["84035.7", "0.00118997", "0", "1"], ["84040.5", "0.00152704", "0", "1"], ["84040.7", "0.00197273", "0", "1"], ["84040.9", "0.01427875", "0", "1"], ["84042.6", "0.08769", "0", "1"], ["84046.6", "0.14553273", "0", "3"], ["84047.3", "0.03", "0", "1"], ["84047.5", "0.25011", "0", "1"], ["84067.3", "1.30373697", "0", "2"], ["84068.5", "0.25011", "0", "1"], ["84071.2", "3.50821", "0", "1"], ["84072.7", "1.40586663", "0", "2"], ["84075", "3.93641433", "0", "2"], ["84089.3", "0.00251779", "0", "1"], ["84112.7", "0.002384", "0", "1"], ["84116.5", "0.214428", "0", "1"], ["84137.7", "0.5999", "0", "1"], ["84147.3", "0", "0", "0"], ["84147.4", "0", "0", "0"], ["84147.7", "0", "0", "0"], ["84148.2", "0", "0", "0"], ["84148.4", "0", "0", "0"], ["84148.5", "0", "0", "0"], ["84148.6", "0", "0", "0"], ["84148.7", "0", "0", "0"], ["84149", "0", "0", "0"], ["84149.2", "0", "0", "0"], ["84149.3", "0", "0", "0"], ["84149.9", "0", "0", "0"], ["84150", "0", "0", "0"], ["84150.1", "0", "0", "0"], ["84150.7", "0", "0", "0"], ["84150.9", "0", "0", "0"], ["84151.3", "0", "0", "0"], ["84151.4", "0", "0", "0"], ["84151.6", "0", "0", "0"], ["84151.7", "0", "0", "0"], ["84152", "0", "0", "0"]], "bids": [["83964.4", "1.05886089", "0", "8"], ["83964.1", "0.01317", "0", "1"], ["83964", "0.0439", "0", "1"], ["83963.9", "0", "0", "0"], ["83962.1", "0.32991767", "0", "1"], ["83960.6", "0.02588557", "0", "2"], ["83959.9", "1", "0", "1"], ["83957.8", "0.17868317", "0", "1"], ["83952.4", "0", "0", "0"], ["83950.8", "0.04193", "0", "1"], ["83949.1", "0.00947331", "0", "1"], ["83949", "0", "0", "0"], ["83948.4", "0.01397", "0", "1"], ["83948", "0.27237", "0", "4"], ["83947.4", "0.00675", "0", "1"], ["83947.3", "0.033", "0", "1"], ["83946", "0.02751695", "0", "1"], ["83943.9", "0.039", "0", "1"], ["83943.6", "0.27558725", "0", "3"], ["83943.4", "0", "0", "0"], ["83942.3", "0.5046", "0", "1"], ["83942.1", "0.17865", "0", "1"], ["83938.8", "0.00883229", "0", "1"], ["83937.9", "0.08711", "0", "1"], ["83937", "0.22625694", "0", "3"], ["83932.8", "0.12730031", "0", "2"], ["83931.5", "0.23833088", "0", "1"], ["83931.4", "0.03", "0", "1"], ["83928.7", "0", "0", "0"], ["83926.6", "0", "0", "0"], ["83924.8", "0.003573", "0", "1"], ["83904.1", "0", "0", "0"], ["83903.7", "0", "0", "0"], ["83902", "0.00001", "0", "1"], ["83901.9", "1.16862683", "0", "2"], ["83901.5", "3.36558", "0", "1"], ["83897.7", "0.00100656", "0", "1"], ["83895.5", "0.0036386", "0", "2"], ["83895", "0", "0", "0"], ["83889.6", "1.31062643", "0", "1"], ["83886.8", "3.87531", "0", "1"], ["83880.4", "0.1430608", "0", "2"], ["83878.9", "0", "0", "0"], ["83873", "0.00213863", "0", "1"], ["83871.5", "0.01669664", "0", "1"], ["83870.9", "0.01510819", "0", "1"], ["83869.6", "0", "0", "0"], ["83868.4", "0.00614047", "0", "2"], ["83865", "0", "0", "0"], ["83860.1", "0", "0", "0"], ["83859.8", "0", "0", "0"], ["83858.6", "0.25031004", "0", "2"], ["83856.5", "0", "0", "0"], ["83851.1", "0", "0", "0"], ["83813.5", "0", "0", "0"], ["83812.5", "0", "0", "0"], ["83811.9", "0", "0", "0"], ["83811.3", "0", "0", "0"], ["83811.2", "0", "0", "0"], ["83810.9", "0", "0", "0"], ["83810.1", "0", "0", "0"]], "ts": "1742576913900", "checksum": -488299586, "seqId": 49944902652, "prevSeqId": 49944902386}], "record_time": 1742576914.074068, "EXCHANGE": "OKX"}
{"arg": {"channel": "books", "instId": "BTC-USDT"}, "action": "update", "data": [{"asks": [["83964.5", "0.29751228", "0", "4"], ["83965.9", "0.03114", "0", "1"], ["83968.1", "0.016", "0", "1"], ["83970.8", "0.00334157", "0", "1"], ["83971.7", "0.18264334", "0", "2"], ["83974.5", "0.3565323", "0", "1"], ["83975.1", "0.04594918", "0", "1"], ["83975.9", "0", "0", "0"], ["83977.2", "0.04293364", "0", "1"], ["83981.2", "0.00356222", "0", "1"], ["83981.3", "0.00001199", "0", "1"], ["83982.6", "0", "0", "0"], ["83988.4", "0.2383202", "0", "1"], ["83993.4", "0.57660308", "0", "2"], ["83995.2", "1.757078", "0", "1"], ["83998.3", "0", "0", "0"], ["84000.7", "0.21151161", "0", "2"], ["84001.8", "0.5904468", "0", "1"], ["84005.6", "0.18772768", "0", "1"], ["84005.7", "0.01190396", "0", "1"], ["84009", "0.1", "0", "1"], ["84011.4", "0.01864842", "0", "1"], ["84015.7", "0", "0", "0"], ["84016.3", "0", "0", "0"], ["84025", "0.00592032", "0", "2"], ["84026.1", "1.18720174", "0", "1"], ["84027.6", "0", "0", "0"], ["84027.9", "0", "0", "0"], ["84028.3", "1.296947", "0", "2"], ["84028.8", "3.14560207", "0", "1"], ["84034.7", "0.01133124", "0", "1"], ["84061.9", "0.38936313", "0", "2"], ["84062.5", "1.215481", "0", "1"], ["84063.6", "0.01774536", "0", "1"], ["84081.1", "0.01191143", "0", "1"], ["84098.9", "0", "0", "0"], ["84099.8", "0", "0", "0"], ["84106.9", "0.11331249", "0", "1"], ["84146", "0", "0", "0"], ["84146.4", "0", "0", "0"], ["84146.6", "0", "0", "0"], ["84146.8", "0", "0", "0"], ["84147", "0", "0", "0"], ["84147.1", "0", "0", "0"]], "bids": [["83964.4", "1.28563616", "0", "11"], ["83964.1", "0.32440384", "0", "2"], ["83962.7", "0.04293364", "0", "1"], ["83962.3", "1", "0", "1"], ["83962.1", "0.03410867", "0", "1"], ["83959.9", "0", "0", "0"], ["83952.4", "0.00361621", "0", "1"], ["83935.6", "0.2383202", "0", "1"], ["83932.8", "0.01602244", "0", "1"], ["83931.5", "0", "0", "0"], ["83931.4", "0", "0", "0"], ["83928.6", "0.49768719", "0", "2"], ["83928", "0", "0", "0"], ["83918", "0.01835109", "0", "1"], ["83915.5", "0.8511073", "0", "2"], ["83912.9", "0", "0", "0"], ["83906.3", "0", "0", "0"], ["83901.2", "0.17865", "0", "1"], ["83881.4", "0.4664196", "0", "2"], ["83881.3", "1.218105", "0", "1"], ["83880.6", "0.00595662", "0", "1"], ["83848.7", "0", "0", "0"], ["83846.8", "0.18352095", "0", "2"], ["83841.8", "0", "0", "0"], ["83828.6", "0.01191143", "0", "1"], ["83814.1", "0", "0", "0"]], "ts": "1742576914000", "checksum": -1657931214, "seqId": 49944902782, "prevSeqId": 49944902652}], "record_time": 1742576914.17491, "EXCHANGE": "OKX"}
{"arg": {"channel": "books", "instId": "BTC-USDT"}, "action": "update", "data": [{"asks": [["83973.9", "0.11889794", "0", "1"], ["83975.1", "0.07952014", "0", "2"], ["83976", "0.16303889", "0", "2"], ["83976.1", "0.01190979", "0", "1"], ["83982", "0.03044", "0", "1"], ["83988.4", "0", "0", "0"], ["83990.6", "0.135142", "0", "2"], ["83991.2", "0.23832345", "0", "2"], ["84001", "0.11910337", "0", "1"], ["84022.3", "0.00002157", "0", "1"], ["84025", "0.00589875", "0", "1"], ["84031.3", "0.21088151", "0", "3"], ["84031.9", "0.01133124", "0", "1"], ["84032.4", "0.35729", "0", "1"], ["84034.7", "0", "0", "0"], ["84041.2", "0.044978", "0", "1"], ["84059.2", "0.1", "0", "1"], ["84081.1", "0.01191561", "0", "1"], ["84103.7", "0.11331249", "0", "1"], ["84106.9", "0", "0", "0"], ["84144.1", "0", "0", "0"], ["84144.5", "0", "0", "0"], ["84145.1", "0", "0", "0"], ["84145.2", "0", "0", "0"], ["84145.5", "0", "0", "0"], ["84145.6", "0", "0", "0"], ["84145.9", "0", "0", "0"]], "bids": [["83964.1", "0.31152375", "0", "2"], ["83962.7", "0", "0", "0"], ["83962.3", "0", "0", "0"], ["83962.2", "1", "0", "1"], ["83958.4", "0.04293364", "0", "1"], ["83955.8", "0.04192", "0", "1"], ["83952.4", "0", "0", "0"], ["83950.8", "0", "0", "0"], ["83940.5", "0.1765895", "0", "2"], ["83938.7", "0", "0", "0"], ["83938.3", "0.23831535", "0", "1"], ["83935.6", "0", "0", "0"], ["83932.8", "0", "0", "0"], ["83932", "0.02953324", "0", "1"], ["83931.9", "0.04504799", "0", "2"], ["83923.3", "0.2025", "0", "1"], ["83918", "0", "0", "0"], ["83915.7", "0.45855174", "0", "2"], ["83915.6", "0.0183502", "0", "1"], ["83909", "0.35765", "0", "2"], ["83907.7", "0.03", "0", "1"], ["83906.3", "0.0115525", "0", "1"], ["83895.6", "0.00145225", "0", "1"], ["83895.5", "0.00218635", "0", "1"], ["83895.3", "0", "0", "0"], ["83892.8", "0.12505", "0", "1"], ["83880", "0.0000366", "0", "1"], ["83876.4", "0.00018337", "0", "1"], ["83873.6", "0", "0", "0"], ["83871.8", "0.12505", "0", "1"], ["83869.7", "0.01190723", "0", "1"], ["83868.4", "0.00595708", "0", "1"], ["83858.6", "0.00020004", "0", "1"], ["83855.5", "0.1", "0", "1"], ["83846.8", "0.00001004", "0", "1"], ["83844", "0.18350206", "0", "1"], ["83834.3", "0.002383", "0", "1"], ["83833.3", "0.0075514", "0", "10"], ["83831.6", "0", "0", "0"], ["83830", "0.01197396", "0", "3"], ["83828.6", "0", "0", "0"], ["83814.9", "0", "0", "0"], ["83814.7", "0", "0", "0"], ["83814.4", "0", "0", "0"]], "ts": "1742576914100", "checksum": -1518274898, "seqId": 49944902888, "prevSeqId": 49944902782}], "record_time": 1742576914.273775, "EXCHANGE": "OKX"}
{"arg": {"channel": "books", "instId": "BTC-USDT"}, "action": "update", "data": [{"asks": [["83966.2", "0.00020657", "0", "1"], ["83970.7", "0.00334119", "0", "1"], ["83970.8", "0.00774136", "0", "1"], ["83971.4", "0.0119277", "0", "2"], ["83974", "0.0439", "0", "1"], ["83976.1", "0", "0", "0"], ["83976.4", "0.01014", "0", "1"], ["83982.6", "0.00774136", "0", "1"], ["83987.4", "0.17865", "0", "1"], ["83990.5", "0.23831368", "0", "1"], ["83991.2", "0.00001199", "0", "1"], ["83994.2", "0.12505", "0", "1"], ["84014.8", "0.01962952", "0", "1"], ["84015.1", "0.12505", "0", "1"], ["84015.7", "0.01774536", "0", "1"], ["84063.6", "0", "0", "0"], ["84110.2", "0.00001199", "0", "1"], ["84140", "0", "0", "0"], ["84140.7", "0", "0", "0"], ["84141.1", "0", "0", "0"], ["84141.2", "0", "0", "0"], ["84141.7", "0", "0", "0"], ["84141.9", "0", "0", "0"], ["84142.2", "0", "0", "0"], ["84142.8", "0", "0", "0"], ["84143.8", "0", "0", "0"]], "bids": [["83964.4", "1.27961239", "0", "11"], ["83964.1", "0.01317", "0", "1"], ["83962.9", "0.01397", "0", "1"], ["83962.2", "0", "0", "0"], ["83962.1", "0.34272518", "0", "2"], ["83960.8", "1", "0", "1"], ["83960.6", "0.01191557", "0", "1"], ["83957.3", "0.00774136", "0", "1"], ["83952.4", "0.00352826", "0", "1"], ["83947.4", "0", "0", "0"], ["83945.5", "0.04374136", "0", "2"], ["83937", "0.22661694", "0", "4"], ["83932", "0.06335659", "0", "2"], ["83931.2", "0.12505", "0", "1"], ["83928.6", "0.98714357", "0", "3"], ["83927.3", "1.71662774", "0", "1"], ["83910.3", "0.12505", "0", "1"], ["83878.2", "0.00595594", "0", "1"], ["83815.9", "0", "0", "0"], ["83815.8", "0", "0", "0"], ["83815.5", "0", "0", "0"], ["83815.3", "0", "0", "0"], ["83815", "0", "0", "0"]], "ts": "1742576914200", "checksum": -1888765649, "seqId": 49944902937, "prevSeqId": 49944902888}], "record_time": 1742576914.374347, "EXCHANGE": "OKX"}
{"arg": {"channel": "books", "instId": "BTC-USDT"}, "action": "update", "data": [{"asks": [["83964.5", "0.59228664", "0", "6"], ["84004", "1", "0", "1"], ["84004.2", "0.38417642", "0", "2"], ["84051.4", "0.01191462", "0", "1"], ["84081.1", "0", "0", "0"], ["84138.8", "0", "0", "0"]], "bids": [["83964.1", "0.03191504", "0", "2"], ["83962.5", "0.05400095", "0", "1"], ["83949.1", "0.5647406", "0", "2"], ["83949", "1", "0", "1"], ["83948.2", "0", "0", "0"], ["83945.6", "0", "0", "0"], ["83938.3", "0", "0", "0"], ["83937.1", "0.23831584", "0", "1"], ["83936.9", "0.06027556", "0", "1"], ["83936", "0.00018", "0", "1"], ["83932", "0.097877", "0", "1"], ["83906.6", "0.28070129", "0", "2"], ["83906.5", "0.36308932", "0", "2"], ["83881.4", "0.30822429", "0", "1"], ["83856.2", "0.01191462", "0", "1"], ["83830", "0.00005835", "0", "2"], ["83817.1", "0", "0", "0"], ["83816.9", "0", "0", "0"], ["83816.6", "0", "0", "0"]], "ts": "1742576914300", "checksum": -1888252830, "seqId": 49944902964, "prevSeqId": 49944902937}], "record_time": 1742576914.47373, "EXCHANGE": "OKX"}
{"arg": {"channel": "books", "instId": "BTC-USDT"}, "action": "update", "data": [{"asks": [["83973.1", "0.000015", "0", "1"], ["83973.7", "0.11914211", "0", "1"], ["83974.2", "0.01014", "0", "1"], ["83975.1", "0.04594918", "0", "1"], ["83976", "0.0439", "0", "1"], ["83976.4", "0", "0", "0"], ["83987.4", "0", "0", "0"], ["83992", "0", "0", "0"], ["83993.3", "0.01774536", "0", "1"], ["83997.7", "0", "0", "0"], ["84000.7", "0.27077951", "0", "1"], ["84003.5", "0.1190999", "0", "1"], ["84004", "0", "0", "0"], ["84005.9", "0.0001722", "0", "1"], ["84015.7", "0", "0", "0"], ["84022.4", "0.00762075", "0", "2"], ["84032.4", "0", "0", "0"], ["84138.8", "0.06044981", "0", "3"]], "bids": [["83964.4", "1.16350002", "0", "11"], ["83962.9", "0", "0", "0"], ["83962", "1.0439", "0", "2"], ["83960.8", "0", "0", "0"], ["83960.7", "0.01397", "0", "1"], ["83952.5", "0", "0", "0"], ["83950.7", "0", "0", "0"], ["83948.2", "0.0000225", "0", "1"], ["83900.6", "0.25011", "0", "1"], ["83879.6", "0.25011", "0", "1"]], "ts": "1742576914400", "checksum": 1804624366, "seqId": 49944903005, "prevSeqId": 49944902964}], "record_time": 1742576914.573482, "EXCHANGE": "OKX"}
{"arg": {"channel": "books", "instId": "BTC-USDT"}, "action": "update", "data": [{"asks": [["83964.5", "0.28218387", "0", "4"], ["83973.7", "0", "0", "0"], ["83981.2", "0", "0", "0"], ["83985.4", "0.00897082", "0", "1"], ["83993.4", "0.08399468", "0", "1"], ["83995.1", "0", "0", "0"], ["83995.2", "0", "0", "0"], ["84014.5", "0", "0", "0"], ["84018.7", "0", "0", "0"], ["84022.9", "0", "0", "0"], ["84026.1", "0.5193431", "0", "1"], ["84028.8", "0", "0", "0"], ["84031.3", "0.12085114", "0", "2"], ["84140", "0.00031221", "0", "2"], ["84140.7", "0.03", "0", "1"], ["84141.1", "0.00005109", "0", "1"], ["84141.2", "0.00011161", "0", "1"], ["84141.7", "0.03", "0", "1"], ["84141.9", "0.00002329", "0", "1"], ["84142.2", "0.17898725", "0", "1"]], "bids": [["83964.4", "1.26350002", "0", "12"], ["83964.1", "0.32538091", "0", "1"], ["83963.3", "1", "0", "1"], ["83962.1", "0.03410867", "0", "1"], ["83962", "0.0439", "0", "1"], ["83950", "0.2439", "0", "2"], ["83928.6", "0.49768719", "0", "2"], ["83927.3", "0", "0", "0"], ["83921.6", "0.1", "0", "2"], ["83920.8", "0.05", "0", "1"], ["83911.6", "0.01", "0", "1"], ["83906.4", "0", "0", "0"], ["83905.6", "0", "0", "0"], ["83886.3", "0.34233612", "0", "1"], ["83886.2", "0.00579932", "0", "1"], ["83881.9", "0", "0", "0"], ["83878.2", "0.69770194", "0", "3"], ["83871.8", "0", "0", "0"], ["83859.8", "0.1139436", "0", "1"]], "ts": "1742576914500", "checksum": -1444620697, "seqId": 49944903052, "prevSeqId": 49944903005}], "record_time": 1742576914.674154, "EXCHANGE": "OKX"}
{"arg": {"channel": "books", "instId": "BTC-USDT"}, "action": "update", "data": [{"asks": [["83964.5", "0.28524139", "0", "6"], ["83971.4", "0.00001199", "0", "1"], ["83973.7", "0.01191586", "0", "1"], ["83974.2", "0", "0", "0"], ["83976.5", "0.01014", "0", "1"], ["83981.2", "0.00353005", "0", "1"], ["83987", "0.35729", "0", "1"], ["83988.5", "0.72547147", "0", "1"], ["83990.3", "1.76315239", "0", "1"], ["83990.5", "0", "0", "0"], ["83993.2", "0.16788032", "0", "1"], ["83993.3", "0.25605703", "0", "2"], ["83993.4", "0", "0", "0"], ["83994.8", "0.00017208", "0", "1"], ["83999", "0.00018709", "0", "2"], ["84003.2", "0.00017208", "0", "1"], ["84021.4", "1.12051487", "0", "2"], ["84023.9", "3.18812686", "0", "1"], ["84031.9", "0", "0", "0"], ["84035.4", "0.01132333", "0", "1"], ["84103.7", "0", "0", "0"], ["84106.9", "0.11323331", "0", "1"], ["84140.7", "0", "0", "0"], ["84141.1", "0", "0", "0"], ["84141.2", "0", "0", "0"], ["84141.7", "0", "0", "0"], ["84141.9", "0", "0", "0"], ["84142.2", "0", "0", "0"]], "bids": [["83964.4", "1.23966766", "0", "12"], ["83964.2", "0.02937029", "0", "1"], ["83964.1", "0", "0", "0"], ["83963.3", "0", "0", "0"], ["83963", "0.01397", "0", "1"], ["83962.1", "0.34272518", "0", "2"], ["83961.9", "1", "0", "1"], ["83960.7", "0", "0", "0"], ["83953.5", "0.16777755", "0", "2"], ["83943.6", "0.41886116", "0", "2"], ["83941.7", "0.49808576", "0", "2"], ["83938.3", "0.23831167", "0", "1"], ["83937.1", "0", "0", "0"], ["83928.6", "0.99090575", "0", "3"], ["83927", "1.72916832", "0", "1"], ["83918", "0.01835003", "0", "1"], ["83915.6", "0", "0", "0"], ["83913.8", "0.12505", "0", "1"], ["83909", "0.00036", "0", "1"], ["83906.6", "0.19631431", "0", "1"], ["83906.5", "0.00579932", "0", "1"], ["83906.3", "0", "0", "0"], ["83901.2", "0", "0", "0"], ["83898.6", "0.57568775", "0", "1"], ["83894.4", "1.29906407", "0", "2"], ["83893.4", "3.14942804", "0", "2"], ["83881.4", "0.5414496", "0", "2"], ["83846.8", "0.18351039", "0", "2"], ["83844", "0", "0", "0"], ["83817.1", "0.00001501", "0", "1"]], "ts": "1742576914600", "checksum": 343049149, "seqId": 49944903114, "prevSeqId": 49944903052}], "record_time": 1742576914.774324, "EXCHANGE": "OKX"}
{"arg": {"channel": "books", "instId": "BTC-USDT"}, "action": "update", "data": [{"asks": [["83964.5", "0.29850887", "0", "7"], ["83993.3", "0.23831167", "0", "1"], ["83997", "0.02343907", "0", "1"], ["84015.7", "0.01774536", "0", "1"], ["84046.6", "0.06422538", "0", "2"], ["84047.5", "0", "0", "0"], ["84068.5", "0", "0", "0"], ["84116.4", "0.00001199", "0", "1"]], "bids": [["83951.7", "0.00001199", "0", "1"], ["83937", "0.27457047", "0", "5"], ["83934", "0.17865", "0", "1"], ["83881.4", "0", "0", "0"], ["83879.6", "0", "0", "0"], ["83878.2", "0.00595594", "0", "1"], ["83859.8", "0", "0", "0"], ["83816.9", "0.00126817", "0", "1"]], "ts": "1742576914700", "checksum": -1030597705, "seqId": 49944903132, "prevSeqId": 49944903114}], "record_time": 1742576914.875654, "EXCHANGE": "OKX"}
{"arg": {"channel": "books", "instId": "BTC-USDT"}, "action": "update", "data": [{"asks": [["83964.5", "0.00556655", "0", "4"], ["83965.9", "0", "0", "0"], ["83966", "0", "0", "0"], ["83968.1", "0", "0", "0"], ["83968.7", "0.02", "0", "1"], ["83970", "0.0439", "0", "1"], ["83970.7", "0", "0", "0"], ["83971.8", "0.022", "0", "2"], ["83973.3", "0.00335635", "0", "1"], ["83973.7", "0", "0", "0"], ["83976.8", "0.01191541", "0", "1"], ["83977.8", "0.04084853", "0", "1"], ["83980", "0.00005736", "0", "1"], ["83981.2", "0", "0", "0"], ["83982.9", "0.3565323", "0", "1"], ["83984.9", "0.04", "0", "1"], ["83985.4", "0", "0", "0"], ["83989.3", "0.1126366", "0", "2"], ["83991.5", "0.02383082", "0", "1"], ["83993.2", "0.09111483", "0", "1"], ["83993.3", "0", "0", "0"], ["83999", "0.23848952", "0", "3"], ["84014", "0.00001", "0", "1"], ["84128", "0.00118464", "0", "1"], ["84140", "0", "0", "0"]], "bids": [["83964.2", "0.32989", "0", "2"], ["83963.2", "1", "0", "1"], ["83963", "0.02588569", "0", "2"], ["83962.1", "0.0659842", "0", "2"], ["83961.9", "0", "0", "0"], ["83960.6", "0", "0", "0"], ["83958.8", "0.09150008", "0", "1"], ["83948.1", "0.04", "0", "1"], ["83947.5", "0.23530555", "0", "2"], ["83943.2", "0", "0", "0"], ["83942.8", "0.00476515", "0", "1"], ["83942.4", "0.23830243", "0", "1"], ["83940.9", "0.11788084", "0", "1"], ["83940.5", "0", "0", "0"], ["83938.3", "0", "0", "0"], ["83934", "0", "0", "0"], ["83929", "0.00001", "0", "1"], ["83924", "0.02380883", "0", "2"], ["83906.6", "0.13269233", "0", "1"], ["83905.5", "0.05690663", "0", "3"], ["83902", "0", "0", "0"], ["83886.3", "0", "0", "0"], ["83883.1", "0", "0", "0"], ["83816.6", "0.00060645", "0", "1"], ["83815.9", "0.00004266", "0", "1"]], "ts": "1742576914800", "checksum": -1857525522, "seqId": 49944903222, "prevSeqId": 49944903132}], "record_time": 1742576914.973808, "EXCHANGE": "OKX"}
{"arg": {"channel": "books", "instId": "BTC-USDT"}, "action": "update", "data": [{"asks": [["83964.5", "0.01244087", "0", "8"], ["83967.9", "0.03234", "0", "1"], ["83968.7", "0", "0", "0"], ["83970.9", "0", "0", "0"], ["83973.1", "0", "0", "0"], ["83973.3", "0", "0", "0"], ["83973.7", "0.02", "0", "1"], ["83973.9", "0.12225529", "0", "2"], ["83975.1", "0.09481732", "0", "2"], ["83976.5", "0", "0", "0"], ["83976.8", "0", "0", "0"], ["83978.5", "0.11913537", "0", "1"], ["83978.6", "0.02964377", "0", "1"], ["83978.8", "0.01014", "0", "1"], ["83979.2", "0.01319758", "0", "2"], ["84005.5", "0.25011", "0", "1"], ["84026.5", "0.25011", "0", "1"], ["84137.7", "0", "0", "0"], ["84138.8", "0", "0", "0"]], "bids": [["83964.4", "1.25363766", "0", "13"], ["83963", "0.01191569", "0", "1"], ["83954.9", "0.004845", "0", "1"], ["83948.2", "0", "0", "0"], ["83947.5", "0.29162385", "0", "3"], ["83945.7", "0.08991011", "0", "1"], ["83942.1", "0", "0", "0"], ["83941.7", "0.14079576", "0", "1"], ["83921.6", "0.25011", "0", "1"], ["83920.8", "0.1", "0", "2"], ["83920", "0.05037", "0", "3"], ["83910.7", "0.0115525", "0", "1"], ["83906.5", "0.01157557", "0", "2"], ["83905.5", "0.00058833", "0", "2"], ["83902.3", "0.00577625", "0", "1"], ["83816.6", "0", "0", "0"], ["83815.9", "0", "0", "0"]], "ts": "1742576914900", "checksum": -77559854, "seqId": 49944903266, "prevSeqId": 49944903222}], "record_time": 1742576915.073989, "EXCHANGE": "OKX"}
{"arg": {"channel": "books", "instId": "BTC-USDT"}, "action": "update", "data": [{"asks": [["83964.5", "0.01427831", "0", "9"], ["83971.8", "0.006", "0", "1"], ["83979.2", "0.01191508", "0", "1"], ["84006.4", "0.08", "0", "2"], ["84007.2", "0.03999999", "0", "1"], ["84008", "0", "0", "0"]], "bids": [["83954.9", "0", "0", "0"], ["83944.7", "0.17865", "0", "1"], ["83936.5", "0.17865", "0", "1"], ["83926.4", "0.08", "0", "2"], ["83925.6", "0.04", "0", "1"], ["83912", "0.01192087", "0", "3"], ["83911.2", "0.0008", "0", "2"], ["83817.4", "0", "0", "0"], ["83817.1", "0", "0", "0"], ["83816.9", "0", "0", "0"]], "ts": "1742576915000", "checksum": -914074807, "seqId": 49944903283, "prevSeqId": 49944903266}], "record_time": 1742576915.174779, "EXCHANGE": "OKX"}
{"arg": {"channel": "books", "instId": "BTC-USDT"}, "action": "update", "data": [{"asks": [["83966", "0.0439", "0", "1"], ["83973.1", "0.00335766", "0", "1"], ["83973.9", "0.11889794", "0", "1"], ["83975.4", "0.01191561", "0", "1"], ["83979.2", "0.000063", "0", "1"], ["83996", "0.23830384", "0", "1"], ["83999", "0.00018709", "0", "2"], ["84136", "0", "0", "0"], ["84136.7", "0", "0", "0"], ["84137.1", "0", "0", "0"], ["84137.2", "0", "0", "0"]], "bids": [["83964.2", "0.02937029", "0", "1"], ["83963.2", "0", "0", "0"], ["83962.2", "0.35833898", "0", "2"], ["83962.1", "0", "0", "0"], ["83959.6", "1", "0", "1"], ["83954.9", "0.0000645", "0", "1"], ["83944.3", "0.36371912", "0", "1"], ["83944.2", "0.35729", "0", "1"], ["83943.6", "0.045", "0", "1"], ["83942.4", "0", "0", "0"], ["83940.9", "0.17463726", "0", "2"], ["83938.3", "0.23830506", "0", "1"], ["83932.4", "0.21275926", "0", "1"], ["83932.3", "0.3565323", "0", "1"], ["83932", "0", "0", "0"], ["83819.2", "0", "0", "0"], ["83818.9", "0", "0", "0"], ["83818.1", "0", "0", "0"], ["83818", "0", "0", "0"]], "ts": "1742576915100", "checksum": -2088797974, "seqId": 49944903330, "prevSeqId": 49944903283}], "record_time": 1742576915.273787, "EXCHANGE": "OKX"}
{"arg": {"channel": "books", "instId": "BTC-USDT"}, "action": "update", "data": [{"asks": [["83973.1", "0", "0", "0"], ["83973.3", "0.00335767", "0", "1"]], "bids": [["83956.6", "0.00001199", "0", "1"], ["83937.3", "0", "0", "0"], ["83935.1", "0", "0", "0"], ["83927.2", "0", "0", "0"], ["83925", "0.002", "0", "1"], ["83819.2", "0.00001297", "0", "1"], ["83818.9", "0.00006774", "0", "2"]], "ts": "1742576915200", "checksum": 1571097477, "seqId": 49944903339, "prevSeqId": 49944903330}], "record_time": 1742576915.373855, "EXCHANGE": "OKX"}
{"arg": {"channel": "books", "instId": "BTC-USDT"}, "action": "update", "data": [{"asks": [["83996", "0", "0", "0"], ["83999", "0.23848926", "0", "3"], ["84136", "0.3565323", "0", "1"]], "bids": [["83941.8", "0.23831416", "0", "2"], ["83940.9", "0.11788084", "0", "1"], ["83938.3", "0", "0", "0"], ["83818.1", "0.00006813", "0", "3"]], "ts": "1742576915300", "checksum": 1571097477, "seqId": 49944903346, "prevSeqId": 49944903339}], "record_time": 1742576915.473241, "EXCHANGE": "OKX"}
{"arg": {"channel": "books", "instId": "BTC-USDT"}, "action": "update", "data": [{"asks": [["83975.4", "0", "0", "0"], ["83978.6", "0.04155888", "0", "2"], ["83998.1", "0.01153238", "0", "1"]], "bids": [], "ts": "1742576915400", "checksum": 338579959, "seqId": 49944903356, "prevSeqId": 49944903346}], "record_time": 1742576915.574312, "EXCHANGE": "OKX"}
{"arg": {"channel": "books", "instId": "BTC-USDT"}, "action": "update", "data": [{"asks": [["83975.7", "0.11913931", "0", "1"], ["83978.5", "0", "0", "0"], ["83996", "0.23830509", "0", "1"], ["83997.6", "0.0008", "0", "2"], ["83998.4", "0.0004", "0", "1"], ["83999", "0.00018709", "0", "2"], ["83999.2", "0", "0", "0"], ["84000", "0.18773756", "0", "4"], ["84020.8", "0.1226366", "0", "3"], ["84135.8", "0", "0", "0"], ["84136", "0", "0", "0"]], "bids": [["83964.2", "0.32927371", "0", "2"], ["83962.2", "1.06667312", "0", "2"], ["83959.6", "0", "0", "0"], ["83941.8", "0.00001199", "0", "1"], ["83940.9", "0.17313726", "0", "2"], ["83938.3", "0.23830509", "0", "1"], ["83926.4", "0.0808", "0", "4"], ["83925.6", "0.0403996", "0", "2"], ["83911.2", "0", "0", "0"], ["83910.4", "0", "0", "0"], ["83886.9", "0.01316", "0", "1"], ["83818", "0.00001199", "0", "1"]], "ts": "1742576915500", "checksum": 399989257, "seqId": 49944903393, "prevSeqId": 49944903356}], "record_time": 1742576915.674722, "EXCHANGE": "OKX"}
{"arg": {"channel": "books", "instId": "BTC-USDT"}, "action": "update", "data": [{"asks": [["83971.7", "0.18600142", "0", "3"], ["83973.3", "0", "0", "0"], ["83981.2", "0.00362443", "0", "1"], ["84032", "0", "0", "0"], ["84040.8", "0.000012", "0", "1"], ["84049.2", "0", "0", "0"], ["84057.6", "0", "0", "0"], ["84066", "0", "0", "0"], ["84135.8", "0.00007302", "0", "1"], ["84136", "0.3565323", "0", "1"], ["84136.7", "0.00004748", "0", "1"], ["84137.1", "0.00001501", "0", "1"]], "bids": [["83964.2", "0.01674471", "0", "1"], ["83962.5", "0", "0", "0"], ["83962.2", "0.35833898", "0", "2"], ["83959.6", "1", "0", "1"], ["83832.3", "0", "0", "0"], ["83823.9", "0", "0", "0"], ["83817.4", "0.2025", "0", "1"], ["83817.1", "0.00001501", "0", "1"]], "ts": "1742576915600", "checksum": 116754701, "seqId": 49944903422, "prevSeqId": 49944903393}], "record_time": 1742576915.773522, "EXCHANGE": "OKX"}
{"arg": {"channel": "books", "instId": "BTC-USDT"}, "action": "update", "data": [{"asks": [["83964.5", "0.69920353", "0", "16"], ["83971.7", "0.25409061", "0", "1"], ["83973.2", "0.19090218", "0", "2"], ["83973.3", "0.11914267", "0", "1"], ["83973.4", "0.04493364", "0", "2"], ["83974", "0.05404", "0", "2"], ["83975.1", "0.1341247", "0", "2"], ["83975.7", "0", "0", "0"], ["83976.2", "0.01191546", "0", "1"], ["83976.5", "0.03044", "0", "1"], ["83977.2", "0", "0", "0"], ["83978.6", "0.02964377", "0", "1"], ["83978.8", "0", "0", "0"], ["83979.2", "0", "0", "0"], ["83979.9", "0.04", "0", "1"], ["83982", "0", "0", "0"], ["83984.9", "0", "0", "0"], ["83987", "0", "0", "0"], ["83988.3", "0.005", "0", "1"], ["83988.4", "0.23833009", "0", "1"], ["83993", "0.05359983", "0", "1"], ["83993.2", "0", "0", "0"], ["83994.2", "0", "0", "0"], ["83996", "0", "0", "0"], ["83998.4", "0.0054", "0", "2"], ["84005.5", "0", "0", "0"], ["84005.6", "0.26772768", "0", "3"], ["84006.4", "0.03999999", "0", "1"], ["84007.2", "0", "0", "0"], ["84014.9", "0.02283169", "0", "1"], ["84015.1", "0", "0", "0"], ["84137.2", "3.88291", "0", "1"], ["84137.7", "0.5999", "0", "1"], ["84138.8", "0.06044981", "0", "3"], ["84140", "0.00031221", "0", "2"], ["84140.7", "0.03", "0", "1"]], "bids": [["83964.4", "0.39293133", "0", "5"], ["83964.2", "0", "0", "0"], ["83964", "0", "0", "0"], ["83962.6", "0.005", "0", "1"], ["83962.2", "0", "0", "0"], ["83959.6", "0", "0", "0"], ["83958.4", "0", "0", "0"], ["83957.8", "0.12434292", "0", "1"], ["83957.7", "0", "0", "0"], ["83955.8", "0", "0", "0"], ["83954.9", "0", "0", "0"], ["83953.7", "0.42602572", "0", "1"], ["83953.6", "1", "0", "1"], ["83953.5", "0", "0", "0"], ["83953.4", "0", "0", "0"], ["83952.5", "0.005", "0", "1"], ["83950.4", "0.04199", "0", "2"], ["83948.3", "0", "0", "0"], ["83948.1", "0", "0", "0"], ["83946.4", "0", "0", "0"], ["83945.7", "0", "0", "0"], ["83945.5", "0.23146904", "0", "3"], ["83944.7", "0", "0", "0"], ["83944.3", "0.22486384", "0", "1"], ["83944.2", "0", "0", "0"], ["83943.1", "0.040015", "0", "2"], ["83942.8", "0", "0", "0"], ["83941.7", "0", "0", "0"], ["83940.9", "0.11788084", "0", "1"], ["83938.3", "0", "0", "0"], ["83937", "0.23367802", "0", "4"], ["83936.5", "0", "0", "0"], ["83935.2", "0.14079576", "0", "1"], ["83932.5", "0.23833009", "0", "1"], ["83932.3", "0", "0", "0"], ["83931.2", "0", "0", "0"], ["83928.7", "0.3565323", "0", "1"], ["83921.6", "0", "0", "0"], ["83915.5", "0.826164", "0", "1"], ["83913.8", "0", "0", "0"], ["83910.3", "0", "0", "0"], ["83906.3", "0.17865", "0", "1"], ["83884.9", "0.15679416", "0", "1"], ["83816.9", "0.00126817", "0", "1"], ["83816.6", "0.00060645", "0", "1"], ["83815.9", "0.00004266", "0", "1"], ["83815.8", "0.05366466", "0", "1"], ["83815.3", "0.00018461", "0", "1"], ["83815", "0.35776874", "0", "1"], ["83814.9", "0.0073937", "0", "2"], ["83814.7", "0.04786326", "0", "4"], ["83814.4", "0.00005519", "0", "1"], ["83814.1", "0.00003395", "0", "1"], ["83813.5", "0.00002031", "0", "1"], ["83812.5", "0.00667459", "0", "3"], ["83811.9", "0.0010552", "0", "1"], ["83811.3", "0.00074812", "0", "1"], ["83811.2", "0.183534", "0", "1"], ["83810.9", "1.72263", "0", "1"]], "ts": "1742576915700", "checksum": -1497903961, "seqId": 49944903579, "prevSeqId": 49944903422}], "record_time": 1742576915.873562, "EXCHANGE": "OKX"}
{"arg": {"channel": "books", "instId": "BTC-USDT"}, "action": "update", "data": [{"asks": [["83964.5", "0.9357655", "0", "19"], ["83965.9", "0.04914685", "0", "1"], ["83967.9", "0", "0", "0"], ["83968", "0.07354377", "0", "2"], ["83968.3", "0.01191658", "0", "1"], ["83968.7", "0.02", "0", "1"], ["83971.2", "0.0005595", "0", "1"], ["83973.3", "0", "0", "0"], ["83973.7", "0", "0", "0"], ["83975.1", "0.06439522", "0", "1"], ["83975.3", "0.08991011", "0", "1"], ["83976.2", "0", "0", "0"], ["83977.8", "0", "0", "0"], ["83978.6", "0", "0", "0"], ["83983", "0.02383316", "0", "1"], ["83988.2", "0.2383286", "0", "1"], ["83988.3", "0.1241215", "0", "2"], ["83988.4", "0", "0", "0"], ["83990.6", "0.22505211", "0", "3"], ["83991.5", "0", "0", "0"], ["84003.5", "0", "0", "0"], ["84004.2", "0.52491165", "0", "3"], ["84004.8", "0.08", "0", "2"], ["84005.2", "0.16817823", "0", "1"], ["84005.6", "0.22772767", "0", "2"], ["84006.4", "0.26238", "0", "1"], ["84011.7", "0.02283169", "0", "1"], ["84014.3", "0.02142024", "0", "1"], ["84014.9", "0", "0", "0"], ["84017.6", "0.000012", "0", "1"], ["84054.1", "0.07165719", "0", "1"], ["84086.7", "0", "0", "0"], ["84140.7", "0", "0", "0"]], "bids": [["83964.4", "0.16077606", "0", "4"], ["83963", "0", "0", "0"], ["83961.6", "0.11915922", "0", "1"], ["83957.8", "0", "0", "0"], ["83956.6", "0.01192857", "0", "2"], ["83956", "0.10944091", "0", "1"], ["83953.7", "0.40934633", "0", "2"], ["83953.6", "0", "0", "0"], ["83952.4", "0", "0", "0"], ["83950.4", "0.00006", "0", "1"], ["83950.3", "1", "0", "1"], ["83949.2", "0.02783973", "0", "2"], ["83949.1", "0.80272445", "0", "3"], ["83946.6", "0.135124", "0", "1"], ["83942.5", "0.05959609", "0", "1"], ["83940.9", "0.07798011", "0", "1"], ["83937.9", "0", "0", "0"], ["83937", "0.33233015", "0", "5"], ["83933.5", "0.2383286", "0", "1"], ["83932.5", "0", "0", "0"], ["83927.2", "0.08", "0", "2"], ["83926.4", "0.0408", "0", "3"], ["83925.6", "0.0003996", "0", "1"], ["83925.4", "0.08703", "0", "1"], ["83921.6", "0.1", "0", "2"], ["83920.8", "0.05", "0", "1"], ["83920", "0.00037", "0", "2"], ["83915.7", "0.43220053", "0", "1"], ["83884.9", "0.2115969", "0", "2"], ["83811.3", "0", "0", "0"], ["83811.2", "0", "0", "0"], ["83810.9", "0", "0", "0"]], "ts": "1742576915800", "checksum": -47082137, "seqId": 49944903685, "prevSeqId": 49944903579}], "record_time": 1742576915.978235, "EXCHANGE": "OKX"}
{"arg": {"channel": "books", "instId": "BTC-USDT"}, "action": "update", "data": [{"asks": [["83964.5", "0.73867762", "0", "17"], ["83965.7", "0.00338352", "0", "1"], ["83965.8", "0.09580422", "0", "2"], ["83965.9", "0", "0", "0"], ["83968.3", "0.05485022", "0", "2"], ["83970.8", "0.12690115", "0", "3"], ["83971", "0.03044", "0", "1"], ["83971.2", "0", "0", "0"], ["83973.4", "0.002", "0", "1"], ["83974", "0.0439", "0", "1"], ["83976.5", "0", "0", "0"], ["83988.1", "0.01774536", "0", "1"], ["83996.8", "0.0008", "0", "2"], ["83997.6", "0.0004", "0", "1"], ["83998.4", "0.005", "0", "1"], ["84004.7", "0.35729", "0", "1"], ["84004.8", "0.07999999", "0", "2"], ["84015.7", "0", "0", "0"], ["84046.6", "0.15184474", "0", "3"], ["84047.5", "0.25011", "0", "1"], ["84059", "0.1", "0", "1"], ["84137.2", "0", "0", "0"], ["84137.7", "0", "0", "0"], ["84138.8", "0", "0", "0"], ["84140", "0", "0", "0"]], "bids": [["83964.4", "0.10337606", "0", "4"], ["83964", "0.1191557", "0", "1"], ["83961.6", "0", "0", "0"], ["83953", "1", "0", "1"], ["83952.3", "0.01397", "0", "1"], ["83951.9", "0.04293364", "0", "1"], ["83950.3", "0", "0", "0"], ["83950", "0.0439", "0", "1"], ["83949.2", "0.02383023", "0", "1"], ["83949.1", "0.24745716", "0", "2"], ["83949", "0", "0", "0"], ["83944.9", "0.04193", "0", "1"], ["83942.1", "0.004935", "0", "1"], ["83937.9", "0.08703", "0", "1"], ["83924.8", "0", "0", "0"], ["83909", "0.35765", "0", "2"], ["83884.9", "0.30597026", "0", "1"], ["83881.4", "0.14093734", "0", "1"], ["83879.6", "0.25011", "0", "1"], ["83878.2", "0.14689328", "0", "2"], ["83814.4", "0", "0", "0"], ["83814.1", "0", "0", "0"], ["83813.5", "0", "0", "0"], ["83812.5", "0", "0", "0"], ["83811.9", "0", "0", "0"]], "ts": "1742576915900", "checksum": -877880197, "seqId": 49944903754, "prevSeqId": 49944903685}], "record_time": 1742576916.074054, "EXCHANGE": "OKX"}
{"arg": {"channel": "books", "instId": "BTC-USDT"}, "action": "update", "data": [{"asks": [["83978.3", "0.005", "0", "1"], ["83979.9", "0.21865", "0", "2"], ["83988.4", "0.005", "0", "1"], ["84136.7", "0", "0", "0"], ["84137.1", "0", "0", "0"]], "bids": [["83962.6", "0.01", "0", "2"], ["83956", "0.34877664", "0", "2"], ["83955.9", "0", "0", "0"], ["83954.2", "1.00112003", "0", "2"], ["83953.7", "0.08313413", "0", "1"], ["83953", "0", "0", "0"], ["83952.6", "0.005", "0", "1"], ["83951.9", "0.04658631", "0", "2"], ["83942.1", "0", "0", "0"], ["83940.9", "0.14793659", "0", "2"], ["83939.6", "0.17865", "0", "1"], ["83912", "0.57192087", "0", "4"], ["83906.6", "0.20813318", "0", "2"], ["83903.7", "0.17865", "0", "1"], ["83886.6", "0.26792138", "0", "1"], ["83884.9", "0", "0", "0"], ["83884.8", "0.00595662", "0", "1"]], "ts": "1742576916000", "checksum": 1450167491, "seqId": 49944903781, "prevSeqId": 49944903754}], "record_time": 1742576916.17396, "EXCHANGE": "OKX"}
{"arg": {"channel": "books", "instId": "BTC-USDT"}, "action": "update", "data": [{"asks": [["84004", "0.08", "0", "2"], ["84004.8", "0.03999999", "0", "1"], ["84005.6", "0.18772768", "0", "1"], ["84032.6", "0.01132744", "0", "2"], ["84035.4", "0", "0", "0"], ["84040.7", "0", "0", "0"], ["84040.8", "0.00198464", "0", "2"], ["84136.7", "0.00004748", "0", "1"]], "bids": [["83956.1", "0.17898725", "0", "1"], ["83925.4", "0", "0", "0"], ["83918", "0", "0", "0"], ["83916.1", "0.01835131", "0", "1"], ["83895.8", "0.00145244", "0", "1"], ["83895.7", "0.00218653", "0", "1"], ["83895.6", "0", "0", "0"], ["83895.5", "0", "0", "0"], ["83871.8", "0.12505", "0", "1"], ["83846.8", "0.00001004", "0", "1"], ["83844.7", "0.18357047", "0", "2"], ["83814.7", "0", "0", "0"]], "ts": "1742576916100", "checksum": -838265862, "seqId": 49944903804, "prevSeqId": 49944903781}], "record_time": 1742576916.274407, "EXCHANGE": "OKX"}
{"arg": {"channel": "books", "instId": "BTC-USDT"}, "action": "update", "data": [{"asks": [], "bids": [["83964.4", "0.10027606", "0", "3"], ["83955.6", "1", "0", "1"], ["83954.2", "0.00112003", "0", "1"], ["83934", "0.17865", "0", "1"], ["83815", "0", "0", "0"], ["83814.9", "0", "0", "0"]], "ts": "1742576916200", "checksum": 840613462, "seqId": 49944903810, "prevSeqId": 49944903804}], "record_time": 1742576916.375121, "EXCHANGE": "OKX"}
{"arg": {"channel": "books", "instId": "BTC-USDT"}, "action": "update", "data": [{"asks": [["83964.5", "0.74206092", "0", "18"], ["83965.7", "0", "0", "0"], ["84004.7", "0", "0", "0"], ["84026.5", "0", "0", "0"], ["84046.6", "0.06422538", "0", "2"], ["84047.5", "0", "0", "0"], ["84137.1", "0.00001501", "0", "1"], ["84137.2", "3.88291", "0", "1"], ["84137.7", "0.5999", "0", "1"], ["84138.8", "0.06044981", "0", "3"]], "bids": [["83963.2", "0.0605", "0", "1"], ["83951.9", "0.04293364", "0", "1"], ["83946.2", "0.000015", "0", "1"], ["83931.2", "0.12505", "0", "1"], ["83910.3", "0.12505", "0", "1"], ["83909", "0.00036", "0", "1"], ["83906.6", "0.13269233", "0", "1"], ["83906.3", "0", "0", "0"], ["83903.7", "0", "0", "0"], ["83881.4", "0.19590621", "0", "2"], ["83879.6", "0", "0", "0"], ["83815.3", "0", "0", "0"]], "ts": "1742576916300", "checksum": -501525426, "seqId": 49944903827, "prevSeqId": 49944903810}], "record_time": 1742576916.473182, "EXCHANGE": "OKX"}
{"arg": {"channel": "books", "instId": "BTC-USDT"}, "action": "update", "data": [{"asks": [["83964.5", "0.75221092", "0", "19"], ["83965.8", "0.08566422", "0", "1"], ["83979.5", "0.35729", "0", "1"], ["83984.5", "0.25011", "0", "1"], ["83988.2", "0.23832979", "0", "1"], ["83995.9", "0.63587845", "0", "1"], ["83996", "1", "0", "1"], ["83996.2", "0.00001199", "0", "1"], ["84003", "0.2", "0", "1"], ["84005.5", "0.25011", "0", "1"], ["84136", "0", "0", "0"], ["84136.7", "0", "0", "0"], ["84137.1", "0", "0", "0"], ["84137.2", "0", "0", "0"], ["84137.7", "0", "0", "0"], ["84138.8", "0", "0", "0"]], "bids": [["83964.4", "0.01367606", "0", "2"], ["83962", "0", "0", "0"], ["83956.2", "0.10944091", "0", "1"], ["83956", "0", "0", "0"], ["83955.6", "0", "0", "0"], ["83953.7", "0.37314656", "0", "2"], ["83953.5", "1", "0", "1"], ["83952.3", "0", "0", "0"], ["83949.7", "0.01397", "0", "1"], ["83940.9", "0.25864677", "0", "1"], ["83939.2", "0.35729", "0", "1"], ["83933.5", "0", "0", "0"], ["83932.5", "0.23832955", "0", "1"], ["83921.6", "0.35011", "0", "3"], ["83871.8", "0", "0", "0"], ["83815.3", "0.00018461", "0", "1"]], "ts": "1742576916400", "checksum": 970612082, "seqId": 49944903870, "prevSeqId": 49944903827}], "record_time": 1742576916.583354, "EXCHANGE": "OKX"}
{"arg": {"channel": "books", "instId": "BTC-USDT"}, "action": "update", "data": [{"asks": [["83965.8", "0.05804008", "0", "1"], ["83968.3", "0.01191658", "0", "1"], ["83972.1", "0.04293364", "0", "1"], ["83996", "1.0008", "0", "3"], ["83996.8", "0.0004", "0", "1"], ["83997.6", "0", "0", "0"], ["84063.4", "0.00298666", "0", "1"], ["84072.2", "0.00599348", "0", "2"], ["84080.6", "0.00895999", "0", "1"], ["84089", "0.01194665", "0", "1"], ["84097.4", "0.01493332", "0", "1"], ["84134.6", "0", "0", "0"], ["84135", "0", "0", "0"], ["84135.7", "0", "0", "0"], ["84135.8", "0", "0", "0"]], "bids": [["83964.4", "0.10027606", "0", "3"], ["83963.2", "0", "0", "0"], ["83956.2", "0.3957608", "0", "2"], ["83954.8", "1", "0", "1"], ["83953.7", "0.08313413", "0", "1"], ["83953.5", "0", "0", "0"], ["83857.1", "0.00389988", "0", "5"], ["83848.7", "0.00597332", "0", "1"], ["83840.3", "0.00895999", "0", "1"], ["83831.9", "0.01194665", "0", "1"], ["83823.5", "0.01532865", "0", "2"], ["83815.8", "0", "0", "0"], ["83815.3", "0", "0", "0"]], "ts": "1742576916500", "checksum": 1390270565, "seqId": 49944903894, "prevSeqId": 49944903870}], "record_time": 1742576916.67358, "EXCHANGE": "OKX"}
{"arg": {"channel": "books", "instId": "BTC-USDT"}, "action": "update", "data": [{"asks": [["83964.5", "0.74054762", "0", "17"], ["83965.7", "0.00338487", "0", "1"], ["83968.4", "0.01014", "0", "1"], ["84133.5", "0", "0", "0"], ["84134.5", "0", "0", "0"]], "bids": [["83964.4", "0.3795322", "0", "4"], ["83962", "0.0439", "0", "1"], ["83956.1", "1.17898725", "0", "2"], ["83955.7", "0.04293364", "0", "1"], ["83954.9", "0.01397", "0", "1"], ["83954.8", "0", "0", "0"], ["83951.9", "0", "0", "0"], ["83949.7", "0", "0", "0"], ["83932.5", "0.2383286", "0", "1"], ["83913.8", "0.12505", "0", "1"], ["83815.9", "0", "0", "0"]], "ts": "1742576916600", "checksum": -1950568917, "seqId": 49944903916, "prevSeqId": 49944903894}], "record_time": 1742576916.773979, "EXCHANGE": "OKX"}
{"arg": {"channel": "books", "instId": "BTC-USDT"}, "action": "update", "data": [{"asks": [], "bids": [["83936.4", "0.31", "0", "1"], ["83932.5", "0", "0", "0"], ["83932", "0.23833117", "0", "1"], ["83821.4", "0", "0", "0"]], "ts": "1742576916700", "checksum": -1950568917, "seqId": 49944903923, "prevSeqId": 49944903916}], "record_time": 1742576916.876323, "EXCHANGE": "OKX"}
{"arg": {"channel": "books", "instId": "BTC-USDT"}, "action": "update", "data": [{"asks": [], "bids": [["83951.9", "0.00354864", "0", "1"], ["83816.6", "0", "0", "0"]], "ts": "1742576916800", "checksum": 698304455, "seqId": 49944903926, "prevSeqId": 49944903923}], "record_time": 1742576916.973793, "EXCHANGE": "OKX"}
{"arg": {"channel": "books", "instId": "BTC-USDT"}, "action": "update", "data": [{"asks": [["83964.5", "0.75069762", "0", "18"], ["83965.7", "0.00338408", "0", "1"], ["83968.4", "0", "0", "0"], ["83985.7", "0.00908598", "0", "1"]], "bids": [["83964.4", "0.10027606", "0", "3"], ["83963.1", "0.0605", "0", "1"], ["83954.9", "0", "0", "0"], ["83951.9", "0", "0", "0"], ["83949.6", "0.01397", "0", "1"], ["83937", "0.53233015", "0", "6"], ["83935", "1.002", "0", "2"], ["83842.3", "0.18351501", "0", "2"]], "ts": "1742576916900", "checksum": 334488481, "seqId": 49944903949, "prevSeqId": 49944903926}], "record_time": 1742576917.073167, "EXCHANGE": "OKX"}
{"arg": {"channel": "books", "instId": "BTC-USDT"}, "action": "update", "data": [{"asks": [], "bids": [["83932", "0", "0", "0"], ["83931.3", "0.23833006", "0", "1"]], "ts": "1742576917000", "checksum": 334488481, "seqId": 49944903956, "prevSeqId": 49944903949}], "record_time": 1742576917.175524, "EXCHANGE": "OKX"}
{"arg": {"channel": "books", "instId": "BTC-USDT"}, "action": "update", "data": [{"asks": [["83985.7", "0", "0", "0"], ["84133.5", "0.00001277", "0", "1"]], "bids": [["83937.1", "0.3565323", "0", "1"], ["83816.9", "0", "0", "0"]], "ts": "1742576917100", "checksum": 334488481, "seqId": 49944903959, "prevSeqId": 49944903956}], "record_time": 1742576917.273238, "EXCHANGE": "OKX"}
{"arg": {"channel": "books", "instId": "BTC-USDT"}, "action": "update", "data": [{"asks": [["84045.1", "0.07139025", "0", "1"], ["84121.8", "0.07132516", "0", "1"]], "bids": [["83964.4", "0.01367606", "0", "2"], ["83937", "0.89509505", "0", "5"], ["83880.4", "0.0715304", "0", "1"], ["83878.2", "0.00595594", "0", "1"]], "ts": "1742576917200", "checksum": 1552259115, "seqId": 49944903972, "prevSeqId": 49944903959}], "record_time": 1742576917.375391, "EXCHANGE": "OKX"}
{"arg": {"channel": "books", "instId": "BTC-USDT"}, "action": "update", "data": [{"asks": [["83964.5", "0.75408258", "0", "19"], ["83965.7", "0", "0", "0"], ["83983.5", "0.33423924", "0", "2"], ["83983.8", "0", "0", "0"], ["83988.2", "0.23833164", "0", "1"], ["84121.8", "0", "0", "0"], ["84134.5", "0.0000103", "0", "1"], ["84134.6", "0.00003392", "0", "1"], ["84135", "0.00001199", "0", "1"]], "bids": [["83931.3", "0", "0", "0"], ["83928.8", "0.23833114", "0", "1"]], "ts": "1742576917300", "checksum": 427545509, "seqId": 49944904001, "prevSeqId": 49944903972}], "record_time": 1742576917.473361, "EXCHANGE": "OKX"}
{"arg": {"channel": "books", "instId": "BTC-USDT"}, "action": "update", "data": [{"asks": [["83995.9", "0", "0", "0"], ["83996", "0.0008", "0", "2"], ["84045.1", "0.1427805", "0", "2"], ["84135.7", "0.0000221", "0", "1"]], "bids": [["83962", "0", "0", "0"], ["83937", "0.79509505", "0", "5"], ["83880.4", "0.1430608", "0", "2"], ["83816.9", "0.00126817", "0", "1"]], "ts": "1742576917400", "checksum": 930044654, "seqId": 49944904011, "prevSeqId": 49944904001}], "record_time": 1742576917.575935, "EXCHANGE": "OKX"}
{"arg": {"channel": "books", "instId": "BTC-USDT"}, "action": "update", "data": [{"asks": [["83988.5", "0", "0", "0"], ["83990.3", "0", "0", "0"], ["84023.9", "0", "0", "0"], ["84135.8", "0.00007302", "0", "1"], ["84136", "0.3565323", "0", "1"], ["84136.7", "0.00004748", "0", "1"]], "bids": [["83937", "0.69509505", "0", "4"], ["83931.3", "0.23833081", "0", "1"], ["83928.8", "0", "0", "0"], ["83928.6", "0.49768719", "0", "2"], ["83927", "0", "0", "0"], ["83894.4", "0.31002202", "0", "1"], ["83893.4", "0.001787", "0", "1"], ["83868.4", "0.23595939", "0", "2"], ["83834.1", "0.6", "0", "1"]], "ts": "1742576917500", "checksum": 930044654, "seqId": 49944904030, "prevSeqId": 49944904011}], "record_time": 1742576917.673609, "EXCHANGE": "OKX"}
{"arg": {"channel": "books", "instId": "BTC-USDT"}, "action": "update", "data": [{"asks": [["83964.5", "0.85408258", "0", "20"], ["83988.1", "0", "0", "0"], ["83989.1", "1.68907887", "0", "1"], ["84021.4", "0.18691857", "0", "1"], ["84045.1", "0.07139025", "0", "1"], ["84061.8", "0.01774536", "0", "1"], ["84136.7", "0", "0", "0"]], "bids": [["83964.4", "0.00772", "0", "1"], ["83930.4", "1.72694804", "0", "2"], ["83898.7", "1.21262762", "0", "2"], ["83896.8", "3.06363802", "0", "1"], ["83880.4", "0.0715304", "0", "1"], ["83816.9", "0", "0", "0"]], "ts": "1742576917600", "checksum": 2007752766, "seqId": 49944904050, "prevSeqId": 49944904030}], "record_time": 1742576917.777127, "EXCHANGE": "OKX"}
{"arg": {"channel": "books", "instId": "BTC-USDT"}, "action": "update", "data": [{"asks": [["83988.2", "0.23833166", "0", "1"], ["83990.6", "0.08992511", "0", "2"], ["84021.4", "1.08691808", "0", "2"], ["84022.3", "0", "0", "0"], ["84022.7", "3.07615911", "0", "1"], ["84032.6", "0.000015", "0", "1"], ["84045.1", "0.1427805", "0", "2"], ["84106.9", "0", "0", "0"], ["84136.7", "0.00004748", "0", "1"]], "bids": [["83932.5", "0.23832765", "0", "1"], ["83931.3", "0", "0", "0"], ["83896.9", "0.00218653", "0", "1"], ["83895.7", "0", "0", "0"], ["83880.4", "0.1430608", "0", "2"]], "ts": "1742576917700", "checksum": 2007752766, "seqId": 49944904073, "prevSeqId": 49944904050}], "record_time": 1742576917.873087, "EXCHANGE": "OKX"}
{"arg": {"channel": "books", "instId": "BTC-USDT"}, "action": "update", "data": [{"asks": [["83979.4", "0.50530616", "0", "2"], ["83980.1", "0.04", "0", "1"], ["83981.9", "0.135111", "0", "1"], ["84022.3", "0.00002157", "0", "1"], ["84136", "0", "0", "0"], ["84136.7", "0", "0", "0"]], "bids": [["83957.5", "0.42822198", "0", "1"], ["83957.4", "1", "0", "1"], ["83956.2", "0", "0", "0"], ["83956.1", "0.17898725", "0", "1"], ["83932.5", "0", "0", "0"], ["83931.3", "0.23832991", "0", "1"], ["83895.8", "0", "0", "0"], ["83895.5", "0.00145249", "0", "1"], ["83817.1", "0", "0", "0"]], "ts": "1742576917800", "checksum": -1188682145, "seqId": 49944904090, "prevSeqId": 49944904073}], "record_time": 1742576917.973632, "EXCHANGE": "OKX"}
{"arg": {"channel": "books", "instId": "BTC-USDT"}, "action": "update", "data": [{"asks": [["83964.5", "0.74054762", "0", "17"], ["83965.7", "0.0033855", "0", "1"], ["83968", "0.08368377", "0", "3"], ["84032.6", "0.0113256", "0", "2"], ["84106.9", "0.11310608", "0", "1"], ["84135.7", "0", "0", "0"], ["84135.8", "0", "0", "0"]], "bids": [["83964.4", "0.37913104", "0", "4"], ["83954.5", "0.01397", "0", "1"], ["83949.6", "0", "0", "0"]], "ts": "1742576917900", "checksum": -2090263098, "seqId": 49944904105, "prevSeqId": 49944904090}], "record_time": 1742576918.073639, "EXCHANGE": "OKX"}
{"arg": {"channel": "books", "instId": "BTC-USDT"}, "action": "update", "data": [{"asks": [["83965.7", "0", "0", "0"], ["83966.1", "0.00338607", "0", "1"], ["83987", "0.003573", "0", "1"], ["83994.8", "0", "0", "0"], ["83999", "0.00001501", "0", "1"], ["84003.2", "0", "0", "0"], ["84135.7", "0.0000221", "0", "1"]], "bids": [["83959.2", "1", "0", "1"], ["83957.5", "0.13241298", "0", "1"], ["83957.4", "0", "0", "0"], ["83951.9", "0.00364117", "0", "1"], ["83937", "0.1129966", "0", "3"], ["83935", "0.002", "0", "1"], ["83817.4", "0", "0", "0"]], "ts": "1742576918000", "checksum": -218293777, "seqId": 49944904121, "prevSeqId": 49944904105}], "record_time": 1742576918.174004, "EXCHANGE": "OKX"}
{"arg": {"channel": "books", "instId": "BTC-USDT"}, "action": "update", "data": [{"asks": [["83964.5", "0.92517762", "0", "17"], ["83965.9", "0.00338614", "0", "1"], ["83966.1", "0", "0", "0"], ["84002.7", "0.01155", "0", "1"], ["84006.9", "0.1847635", "0", "2"], ["84011.1", "0.00579126", "0", "2"], ["84135.7", "0", "0", "0"]], "bids": [["83959.2", "0", "0", "0"], ["83957.9", "0.43241298", "0", "1"], ["83957.8", "1", "0", "1"], ["83957.5", "0", "0", "0"], ["83932.5", "0.23832771", "0", "1"], ["83931.3", "0", "0", "0"], ["83910.7", "0", "0", "0"], ["83906.5", "0.00579932", "0", "1"], ["83902.3", "0", "0", "0"], ["83876.4", "0", "0", "0"], ["83817.4", "0.2025", "0", "1"], ["83817.1", "0.00001501", "0", "1"], ["83816.9", "0.00126817", "0", "1"]], "ts": "1742576918100", "checksum": 218158760, "seqId": 49944904151, "prevSeqId": 49944904121}], "record_time": 1742576918.27754, "EXCHANGE": "OKX"}
{"arg": {"channel": "books", "instId": "BTC-USDT"}, "action": "update", "data": [{"asks": [["83988.5", "0.73520546", "0", "1"], ["84135", "0", "0", "0"]], "bids": [["83957.8", "0", "0", "0"], ["83955.9", "1", "0", "1"], ["83932.5", "0", "0", "0"], ["83932.4", "0.70317777", "0", "2"], ["83932", "0.23832888", "0", "1"], ["83914.5", "0.00577625", "0", "1"], ["83910.3", "0.13082625", "0", "2"], ["83881.4", "0.35864386", "0", "1"], ["83876.4", "0.00018348", "0", "1"], ["83817.1", "0", "0", "0"], ["83816.9", "0", "0", "0"]], "ts": "1742576918200", "checksum": 904544739, "seqId": 49944904166, "prevSeqId": 49944904151}], "record_time": 1742576918.374211, "EXCHANGE": "OKX"}
{"arg": {"channel": "books", "instId": "BTC-USDT"}, "action": "update", "data": [{"asks": [["83964.5", "0.94304362", "0", "18"]], "bids": [["83912", "0.01192087", "0", "3"]], "ts": "1742576918300", "checksum": -844362219, "seqId": 49944904172, "prevSeqId": 49944904166}], "record_time": 1742576918.473876, "EXCHANGE": "OKX"}
{"arg": {"channel": "books", "instId": "BTC-USDT"}, "action": "update", "data": [{"asks": [["83999", "1.00001501", "0", "2"], ["84035.7", "0", "0", "0"], ["84040.9", "0", "0", "0"], ["84045.1", "0.07139025", "0", "1"], ["84089.3", "0", "0", "0"], ["84135", "0.00001199", "0", "1"], ["84135.7", "0.0000221", "0", "1"], ["84135.8", "0.00007302", "0", "1"]], "bids": [["83880.4", "0.0715304", "0", "1"], ["83873", "0", "0", "0"], ["83870.9", "0", "0", "0"], ["83817.1", "0.00001501", "0", "1"], ["83816.9", "0.00126817", "0", "1"]], "ts": "1742576918400", "checksum": -844362219, "seqId": 49944904186, "prevSeqId": 49944904172}], "record_time": 1742576918.576449, "EXCHANGE": "OKX"}
{"arg": {"channel": "books", "instId": "BTC-USDT"}, "action": "update", "data": [{"asks": [["83965.7", "0.00338662", "0", "1"], ["83965.9", "0", "0", "0"], ["83988.1", "0.01774536", "0", "1"], ["84040.8", "0.000012", "0", "1"], ["84041", "0.00198763", "0", "2"], ["84061.8", "0", "0", "0"]], "bids": [["83937", "0.3129966", "0", "4"], ["83932", "0", "0", "0"], ["83928.8", "0.23833196", "0", "1"], ["83822.6", "0.00008236", "0", "1"], ["83816.9", "0", "0", "0"]], "ts": "1742576918500", "checksum": 1271196297, "seqId": 49944904215, "prevSeqId": 49944904186}], "record_time": 1742576918.699342, "EXCHANGE": "OKX"}
{"arg": {"channel": "books", "instId": "BTC-USDT"}, "action": "update", "data": [{"asks": [["83965.7", "0", "0", "0"], ["83965.9", "0.00338664", "0", "1"], ["84045.1", "0.1427805", "0", "2"]], "bids": [["83957.5", "1", "0", "1"], ["83955.9", "0", "0", "0"], ["83931.3", "0.23832969", "0", "1"], ["83928.8", "0", "0", "0"], ["83918.6", "0.0115525", "0", "1"], ["83880.4", "0.1430608", "0", "2"], ["83817.1", "0", "0", "0"]], "ts": "1742576918600", "checksum": -1834575605, "seqId": 49944904228, "prevSeqId": 49944904215}], "record_time": 1742576918.773884, "EXCHANGE": "OKX"}
{"arg": {"channel": "books", "instId": "BTC-USDT"}, "action": "update", "data": [{"asks": [["83965.9", "0", "0", "0"], ["83966.1", "0.0033872", "0", "1"], ["83975.1", "0.03456909", "0", "1"], ["83975.3", "0", "0", "0"], ["83987", "0", "0", "0"], ["83999", "0.00001501", "0", "1"], ["84002.3", "0.12247094", "0", "2"], ["84045.1", "0.07139025", "0", "1"], ["84136", "0.3565323", "0", "1"], ["84136.7", "0.00004748", "0", "1"]], "bids": [["83960.1", "1", "0", "1"], ["83957.9", "0.13241298", "0", "1"], ["83957.5", "0", "0", "0"], ["83931.3", "0", "0", "0"], ["83930.5", "0.23833179", "0", "1"], ["83880.4", "0.0715304", "0", "1"]], "ts": "1742576918800", "checksum": 1425020968, "seqId": 49944904259, "prevSeqId": 49944904228}], "record_time": 1742576918.974092, "EXCHANGE": "OKX"}
{"arg": {"channel": "books", "instId": "BTC-USDT"}, "action": "update", "data": [{"asks": [["83966.1", "0.00338694", "0", "1"], ["83988.1", "0", "0", "0"], ["83992.4", "0.01190584", "0", "1"], ["84005.3", "0", "0", "0"], ["84045.1", "0.1427805", "0", "2"], ["84061.8", "0.01774536", "0", "1"]], "bids": [["83960.1", "0", "0", "0"], ["83958.3", "0.3", "0", "1"], ["83958.2", "1", "0", "1"], ["83923.3", "0.21440584", "0", "2"], ["83922.8", "0", "0", "0"], ["83880.4", "0.1430608", "0", "2"]], "ts": "1742576918900", "checksum": -1700399046, "seqId": 49944904279, "prevSeqId": 49944904259}], "record_time": 1742576919.076911, "EXCHANGE": "OKX"}
{"arg": {"channel": "books", "instId": "BTC-USDT"}, "action": "update", "data": [{"asks": [["83964.5", "0.95658186", "0", "20"], ["83966.1", "0", "0", "0"], ["83968", "0.07354377", "0", "2"], ["83992.2", "0.01190587", "0", "1"], ["84005.1", "0.01190404", "0", "1"]], "bids": [["83964.4", "0.00772", "0", "1"], ["83958.2", "0", "0", "0"], ["83956", "1", "0", "1"], ["83954.5", "0", "0", "0"], ["83951.9", "0", "0", "0"], ["83950", "0.05787", "0", "2"], ["83937", "1.3129966", "0", "5"], ["83930.5", "0", "0", "0"], ["83928.8", "0.23833043", "0", "1"], ["83923.2", "0.01190587", "0", "1"], ["83922.6", "0", "0", "0"], ["83817.1", "0.00001501", "0", "1"], ["83816.9", "0.00126817", "0", "1"]], "ts": "1742576919000", "checksum": -220087064, "seqId": 49944904300, "prevSeqId": 49944904279}], "record_time": 1742576919.173466, "EXCHANGE": "OKX"}
{"arg": {"channel": "books", "instId": "BTC-USDT"}, "action": "update", "data": [{"asks": [["83964.5", "1.05319362", "0", "20"], ["83965.7", "0.00338842", "0", "1"], ["83983.4", "0.01190712", "0", "1"], ["83990.6", "0.10183121", "0", "3"], ["83993.9", "0.01190563", "0", "1"], ["83994.5", "0.01190555", "0", "1"], ["83997.2", "0", "0", "0"], ["84002.6", "0", "0", "0"], ["84005.1", "0", "0", "0"], ["84005.7", "0", "0", "0"], ["84033.1", "0.00119", "0", "1"], ["84038.3", "0.02017796", "0", "2"], ["84086.6", "0.00251807", "0", "1"], ["84136", "0", "0", "0"], ["84136.7", "0", "0", "0"]], "bids": [["83964.4", "0.00891098", "0", "2"], ["83958.3", "0", "0", "0"], ["83957.9", "0.41167036", "0", "2"], ["83937", "0.2129966", "0", "4"], ["83931.3", "0.23833027", "0", "1"], ["83928.8", "0", "0", "0"], ["83924", "0.01190523", "0", "1"], ["83923.7", "0.01190555", "0", "1"], ["83923.5", "0.11889794", "0", "1"], ["83923.2", "0.0238115", "0", "2"], ["83872.6", "0.00213881", "0", "1"], ["83869.6", "0.01510818", "0", "1"], ["83817.1", "0", "0", "0"], ["83816.9", "0", "0", "0"]], "ts": "1742576919100", "checksum": 1001019081, "seqId": 49944904336, "prevSeqId": 49944904300}], "record_time": 1742576919.275488, "EXCHANGE": "OKX"}
{"arg": {"channel": "books", "instId": "BTC-USDT"}, "action": "update", "data": [{"asks": [["83993.8", "0.01190565", "0", "1"], ["83997.8", "0.27116379", "0", "1"], ["84005", "0", "0", "0"], ["84135.8", "0", "0", "0"]], "bids": [["83936.5", "0.29142888", "0", "1"], ["83926.1", "0.5776526", "0", "1"], ["83923.4", "0.26698318", "0", "1"], ["83923.1", "0.01190565", "0", "1"], ["83917.8", "0.05741647", "0", "2"], ["83917.7", "0.0238443", "0", "1"], ["83886.6", "0.38079822", "0", "2"], ["83884.1", "0.58226341", "0", "1"], ["83875.7", "0", "0", "0"], ["83818.1", "0", "0", "0"], ["83818", "0", "0", "0"], ["83817.4", "0", "0", "0"]], "ts": "1742576919200", "checksum": 1001019081, "seqId": 49944904350, "prevSeqId": 49944904336}], "record_time": 1742576919.373019, "EXCHANGE": "OKX"}
{"arg": {"channel": "books", "instId": "BTC-USDT"}, "action": "update", "data": [{"asks": [["83988.1", "0.01774536", "0", "1"], ["84061.8", "0", "0", "0"]], "bids": [], "ts": "1742576919300", "checksum": 1001019081, "seqId": 49944904352, "prevSeqId": 49944904350}], "record_time": 1742576919.473153, "EXCHANGE": "OKX"}
{"arg": {"channel": "books", "instId": "BTC-USDT"}, "action": "update", "data": [{"asks": [["83964.1", "1.45626658", "0", "17"], ["83964.2", "0.3565323", "0", "1"], ["83964.3", "0.20058007", "0", "1"], ["83964.5", "0.32110525", "0", "14"], ["83965.3", "0.00338841", "0", "1"], ["83965.7", "0", "0", "0"], ["83965.8", "0", "0", "0"], ["83967.9", "0.04480811", "0", "1"], ["83995.2", "0.0008", "0", "2"], ["83996", "0.0004", "0", "1"], ["83996.8", "0", "0", "0"], ["84003.2", "0.08", "0", "2"], ["84004", "0.03999999", "0", "1"], ["84004.8", "0", "0", "0"], ["84009", "0", "0", "0"], ["84135", "0", "0", "0"], ["84135.7", "0", "0", "0"]], "bids": [["83964.4", "0", "0", "0"], ["83950.5", "0", "0", "0"], ["83949.9", "0.00060645", "0", "1"], ["83941.5", "0.04714784", "0", "2"], ["83937.8", "0.00476543", "0", "1"], ["83927.2", "0.0808", "0", "4"], ["83926.4", "0.04039983", "0", "2"], ["83925.6", "0", "0", "0"], ["83818.1", "0.00006813", "0", "3"], ["83818", "0.00001199", "0", "1"]], "ts": "1742576919400", "checksum": 1635620555, "seqId": 49944904446, "prevSeqId": 49944904352}], "record_time": 1742576919.573214, "EXCHANGE": "OKX"}
{"arg": {"channel": "books", "instId": "BTC-USDT"}, "action": "update", "data": [{"asks": [["83964.1", "1.19911511", "0", "17"], ["83964.3", "0.11058007", "0", "1"], ["83964.5", "0.27825672", "0", "12"], ["83965.3", "0", "0", "0"], ["83965.9", "0.00338848", "0", "1"], ["84008.6", "0.1", "0", "1"], ["84039.4", "0.00152683", "0", "1"], ["84040.4", "0.00197262", "0", "1"], ["84040.5", "0", "0", "0"], ["84041", "0.000015", "0", "1"], ["84134.5", "0", "0", "0"], ["84134.6", "0", "0", "0"]], "bids": [["83964", "0.2057557", "0", "2"], ["83957.4", "1", "0", "1"], ["83956", "0", "0", "0"], ["83950.6", "0.0035586", "0", "1"], ["83897.7", "0", "0", "0"], ["83897", "0.00100669", "0", "1"], ["83896.9", "0", "0", "0"], ["83895.6", "0.00218655", "0", "1"], ["83818", "0", "0", "0"]], "ts": "1742576919500", "checksum": 1106536351, "seqId": 49944904489, "prevSeqId": 49944904446}], "record_time": 1742576919.676646, "EXCHANGE": "OKX"}
{"arg": {"channel": "books", "instId": "BTC-USDT"}, "action": "update", "data": [{"asks": [], "bids": [["83878.7", "0.01190723", "0", "1"], ["83876.4", "0", "0", "0"], ["83876.2", "0.11908141", "0", "2"], ["83869.7", "0", "0", "0"], ["83818", "0.00001199", "0", "1"]], "ts": "1742576919600", "checksum": 1106536351, "seqId": 49944904507, "prevSeqId": 49944904489}], "record_time": 1742576919.774287, "EXCHANGE": "OKX"}
