{"arg": {"channel": "books", "instId": "BTC-USDT"}, "action": "update", "data": [{"asks": [["83958", "0.87898394", "0", "12"], ["83958.3", "0.01191742", "0", "1"], ["83958.8", "0.0428883", "0", "1"], ["83961.4", "0", "0", "0"], ["83962.5", "0.18561902", "0", "1"], ["83962.6", "0.35697351", "0", "1"], ["83962.7", "0", "0", "0"], ["83963.4", "0.03062", "0", "1"], ["83965.8", "0", "0", "0"], ["83972.4", "0.04", "0", "1"], ["83972.6", "0", "0", "0"], ["83975.1", "1.22829665", "0", "1"], ["83975.5", "0", "0", "0"], ["83976.2", "0.23835841", "0", "1"], ["83976.5", "1.01", "0", "2"], ["83976.7", "0.00891426", "0", "1"], ["83979", "0.37316024", "0", "1"], ["83980.1", "0.1191331", "0", "1"], ["83980.2", "0.36054621", "0", "2"], ["83981.8", "0.08991011", "0", "1"], ["83982.8", "0.01190721", "0", "1"], ["83995", "0.2", "0", "1"], ["83996.2", "0.22265782", "0", "2"], ["84003.1", "0.02310614", "0", "1"], ["84004.7", "0.02283169", "0", "1"], ["84135.8", "0", "0", "0"], ["84136", "0", "0", "0"], ["84136.2", "0", "0", "0"], ["84136.7", "0", "0", "0"], ["84137.1", "0", "0", "0"], ["84137.2", "0", "0", "0"]], "bids": [["83957.9", "0.00292913", "0", "2"], ["83957.2", "0", "0", "0"], ["83956", "0", "0", "0"], ["83955", "0", "0", "0"], ["83954.1", "0.01317", "0", "1"], ["83951", "0", "0", "0"], ["83950.7", "0", "0", "0"], ["83947.3", "0", "0", "0"], ["83944.8", "0.01191783", "0", "1"], ["83944.7", "0.05319126", "0", "3"], ["83944.1", "0.016", "0", "1"], ["83943.6", "0.0428883", "0", "1"], ["83937.9", "0", "0", "0"], ["83937.8", "0.01389", "0", "1"], ["83937.4", "0", "0", "0"], ["83937", "0.7242027", "0", "5"], ["83935.6", "1", "0", "1"], ["83933", "0", "0", "0"], ["83932.8", "0.10427419", "0", "2"], ["83932.2", "0.003711", "0", "1"], ["83929.4", "0.08603", "0", "1"], ["83929.1", "0.11920527", "0", "1"], ["83927.2", "0", "0", "0"], ["83921.9", "0.24035841", "0", "2"], ["83910.2", "0.471957", "0", "1"], ["83908.2", "0", "0", "0"], ["83902", "0.002147", "0", "2"], ["83857.1", "0.85209132", "0", "5"], ["83816.6", "0.00060645", "0", "1"], ["83815.9", "0.00004266", "0", "1"], ["83815.5", "0.002384", "0", "1"]], "ts": "1742577148400", "checksum": -812559892, "seqId": 49945044948, "prevSeqId": 49945044829}], "record_time": 1742577148.571386, "EXCHANGE": "OKX"}
{"arg": {"channel": "books", "instId": "BTC-USDT"}, "action": "update", "data": [{"asks": [["83958", "0.92136361", "0", "14"], ["83967.2", "0", "0", "0"], ["83967.6", "0.30175703", "0", "2"], ["83970.4", "0.35732", "0", "1"], ["83975", "0.01774536", "0", "1"], ["83975.4", "0", "0", "0"], ["83976.2", "0", "0", "0"], ["83976.5", "0.01", "0", "1"], ["83977.8", "1.11913633", "0", "2"], ["83980", "0.23835742", "0", "1"], ["83988", "0", "0", "0"], ["83988.8", "0.0008", "0", "2"], ["83989.6", "0.0004", "0", "1"], ["83995", "0", "0", "0"], ["83996", "0.00006639", "0", "1"], ["83996.8", "0.07999999", "0", "2"], ["83997.6", "0.03999999", "0", "1"]], "bids": [["83957.9", "0.00286", "0", "1"], ["83950.4", "0", "0", "0"], ["83936.9", "1", "0", "1"], ["83935.6", "0", "0", "0"], ["83932.8", "0.1485108", "0", "1"], ["83932.2", "0", "0", "0"], ["83930.9", "0.04169", "0", "1"], ["83922.2", "0.23835784", "0", "1"], ["83921.9", "0.002", "0", "1"]], "ts": "1742577148500", "checksum": -49165206, "seqId": 49945044983, "prevSeqId": 49945044948}], "record_time": 1742577148.671459, "EXCHANGE": "OKX"}
{"arg": {"channel": "books", "instId": "BTC-USDT"}, "action": "update", "data": [{"asks": [["83975.1", "0.90531159", "0", "1"], ["83978.5", "0", "0", "0"], ["83980", "0", "0", "0"], ["83980.7", "0.23835508", "0", "1"], ["84005.5", "0.471939", "0", "1"], ["84093.1", "0.11318383", "0", "1"], ["84096.3", "0", "0", "0"]], "bids": [["83954.1", "0", "0", "0"], ["83954", "0.0439696", "0", "2"], ["83953.1", "0.03471498", "0", "1"], ["83941.5", "0.00358358", "0", "1"], ["83929.2", "0.003015", "0", "1"], ["83925", "0.23835508", "0", "1"], ["83922.2", "0", "0", "0"], ["83907.5", "0", "0", "0"], ["83904", "0.01835347", "0", "1"], ["83835.6", "0", "0", "0"], ["83832.4", "0.18353471", "0", "1"], ["83815.5", "0", "0", "0"]], "ts": "1742577148600", "checksum": -1582142438, "seqId": 49945045006, "prevSeqId": 49945044983}], "record_time": 1742577148.775455, "EXCHANGE": "OKX"}
{"arg": {"channel": "books", "instId": "BTC-USDT"}, "action": "update", "data": [{"asks": [["83997.5", "0.0015672", "0", "1"], ["84135.7", "0", "0", "0"]], "bids": [["83953.1", "0", "0", "0"], ["83952.1", "0.02866615", "0", "1"], ["83940.3", "0.54610091", "0", "2"], ["83938.4", "1", "0", "1"], ["83937", "0.46690525", "0", "4"], ["83936.9", "0", "0", "0"], ["83905.4", "0.01", "0", "1"], ["83883.3", "0.00060645", "0", "1"], ["83815.9", "0", "0", "0"]], "ts": "1742577148700", "checksum": 1933833734, "seqId": 49945045021, "prevSeqId": 49945045006}], "record_time": 1742577148.871375, "EXCHANGE": "OKX"}
{"arg": {"channel": "books", "instId": "BTC-USDT"}, "action": "update", "data": [{"asks": [["83950.4", "1.40083267", "0", "15"], ["83951.7", "0.02603649", "0", "1"], ["83952", "0.0439", "0", "1"], ["83953.7", "0.0428883", "0", "1"], ["83955.3", "0.03063", "0", "1"], ["83956", "0.0439", "0", "1"], ["83956.9", "0.16600625", "0", "1"], ["83957", "0.01021", "0", "1"], ["83957.9", "0.2", "0", "1"], ["83958", "0.34433589", "0", "10"], ["83958.3", "0", "0", "0"], ["83958.8", "0", "0", "0"], ["83959.4", "0.14639978", "0", "1"], ["83959.5", "0.17898725", "0", "1"], ["83959.6", "0.09201", "0", "3"], ["83961.5", "0.00001199", "0", "1"], ["83963.4", "0", "0", "0"], ["83965.5", "0", "0", "0"], ["83966.2", "0.05983701", "0", "2"], ["83967.7", "0.08991011", "0", "1"], ["83970.4", "0", "0", "0"], ["83970.9", "0.51118911", "0", "2"], ["83973.4", "1", "0", "1"], ["83975.1", "0.59816116", "0", "1"], ["83975.6", "0", "0", "0"], ["83976.2", "0.23836944", "0", "1"], ["83977.8", "0.11913633", "0", "1"], ["83980.1", "0", "0", "0"], ["83980.7", "0", "0", "0"], ["83982.1", "0", "0", "0"], ["83982.8", "0", "0", "0"], ["83984.5", "0.07357143", "0", "3"], ["83988.2", "0.01190644", "0", "1"], ["83988.9", "0.03573046", "0", "2"], ["83991.8", "0.00006639", "0", "1"], ["83992.9", "0", "0", "0"], ["84033.3", "0.00101534", "0", "2"], ["84110.2", "0", "0", "0"], ["84134.1", "0", "0", "0"], ["84134.5", "0", "0", "0"], ["84134.6", "0", "0", "0"], ["84134.8", "0", "0", "0"]], "bids": [["83957.9", "0", "0", "0"], ["83956.9", "0", "0", "0"], ["83954", "0", "0", "0"], ["83952.1", "0", "0", "0"], ["83952", "0", "0", "0"], ["83951.7", "0", "0", "0"], ["83950.3", "0.0031", "0", "1"], ["83949.8", "0", "0", "0"], ["83948.7", "0", "0", "0"], ["83948.3", "0.0005608", "0", "1"], ["83945.8", "0", "0", "0"], ["83945.2", "0.05299466", "0", "1"], ["83945.1", "0", "0", "0"], ["83945", "0", "0", "0"], ["83944.8", "0", "0", "0"], ["83944.7", "0.00119126", "0", "1"], ["83944.1", "0", "0", "0"], ["83944", "0.0489", "0", "2"], ["83943.6", "0", "0", "0"], ["83942.9", "0.00774164", "0", "1"], ["83942.3", "0", "0", "0"], ["83941.5", "0", "0", "0"], ["83940.3", "0.12106274", "0", "1"], ["83940.2", "0", "0", "0"], ["83940.1", "0.0119185", "0", "1"], ["83939.7", "0", "0", "0"], ["83939.5", "0", "0", "0"], ["83939", "0.0428883", "0", "1"], ["83938.4", "0", "0", "0"], ["83937.8", "0", "0", "0"], ["83936.9", "0.04", "0", "1"], ["83935.3", "0.01389", "0", "1"], ["83934", "0", "0", "0"], ["83933.7", "0", "0", "0"], ["83933.5", "0.03992302", "0", "1"], ["83933.1", "0.01192074", "0", "1"], ["83932.8", "0.425752", "0", "2"], ["83932.7", "1", "0", "1"], ["83932.6", "0.03216924", "0", "2"], ["83932.3", "0.04", "0", "1"], ["83929.4", "0", "0", "0"], ["83929.2", "0", "0", "0"], ["83927.8", "0.007149", "0", "1"], ["83925.6", "0", "0", "0"], ["83925.5", "0.0001395", "0", "1"], ["83925", "0", "0", "0"], ["83924.4", "0.70339952", "0", "2"], ["83924", "0", "0", "0"], ["83923.8", "0", "0", "0"], ["83923.5", "0", "0", "0"], ["83917.7", "0.23836805", "0", "1"], ["83917.3", "0.05784007", "0", "1"], ["83913.6", "0.04079949", "0", "3"], ["83864.3", "0", "0", "0"], ["83863.8", "0", "0", "0"], ["83851.4", "0.17792639", "0", "2"], ["83847", "0.12267035", "0", "1"], ["83837.9", "0.07165719", "0", "1"], ["83837.5", "0.07166249", "0", "1"], ["83815.9", "0.00004266", "0", "1"], ["83815.5", "0.002384", "0", "1"], ["83815.3", "0.00018461", "0", "1"], ["83815.1", "0.00589964", "0", "1"], ["83815", "0.35776874", "0", "1"], ["83814.9", "0.0073937", "0", "2"], ["83814.4", "0.00005519", "0", "1"], ["83814.1", "0.00011633", "0", "2"], ["83813.8", "0.11936928", "0", "1"], ["83813.6", "0.03579964", "0", "2"], ["83813.5", "0.00002031", "0", "1"], ["83813.1", "0.00001199", "0", "1"], ["83812.8", "0.01493332", "0", "1"], ["83812.6", "0.00579923", "0", "1"]], "ts": "1742577148800", "checksum": -1913449126, "seqId": 49945045327, "prevSeqId": 49945045021}], "record_time": 1742577148.972094, "EXCHANGE": "OKX"}
{"arg": {"channel": "books", "instId": "BTC-USDT"}, "action": "update", "data": [{"asks": [["83950.4", "1.23792272", "0", "15"], ["83956.9", "0.16712625", "0", "2"], ["83958", "0.34114417", "0", "8"], ["83959.6", "0.00209989", "0", "2"], ["83969.9", "0.17868", "0", "1"], ["83976.2", "0", "0", "0"], ["83978.8", "0.25744168", "0", "2"], ["83980.2", "0.35697351", "0", "1"], ["83994.9", "0.1", "0", "1"], ["83997.4", "0.00584565", "0", "1"], ["83997.5", "0", "0", "0"], ["84002.5", "0", "0", "0"]], "bids": [["83950.3", "0.139", "0", "3"], ["83949.4", "0.04300001", "0", "1"], ["83947", "0.11917989", "0", "1"], ["83937.2", "0.17868", "0", "1"], ["83923.8", "0.08603", "0", "1"], ["83921.9", "0.24036181", "0", "2"], ["83917.7", "0", "0", "0"], ["83890.8", "0", "0", "0"], ["83890.6", "0", "0", "0"], ["83888.9", "0", "0", "0"], ["83883.4", "0.00100701", "0", "1"], ["83882.9", "0.00218681", "0", "1"], ["83882.6", "0.00145276", "0", "1"], ["83813.1", "0", "0", "0"], ["83812.8", "0", "0", "0"], ["83812.6", "0", "0", "0"]], "ts": "1742577148900", "checksum": -1395723164, "seqId": 49945045393, "prevSeqId": 49945045327}], "record_time": 1742577149.070967, "EXCHANGE": "OKX"}
{"arg": {"channel": "books", "instId": "BTC-USDT"}, "action": "update", "data": [{"asks": [["83950.4", "0.61278821", "0", "10"], ["83955.3", "0", "0", "0"], ["83958", "0.34094467", "0", "7"], ["83963.8", "0.03062", "0", "1"], ["83967.7", "0", "0", "0"], ["83967.9", "0.35735", "0", "1"], ["83978.8", "0.25743898", "0", "2"], ["83983.3", "0.49748166", "0", "2"], ["83985", "1", "0", "1"], ["83997.3", "0.00892559", "0", "1"], ["83997.4", "0", "0", "0"], ["84026.1", "0.044986", "0", "1"], ["84133.3", "0", "0", "0"], ["84133.5", "0", "0", "0"]], "bids": [["83950.3", "0.8326408", "0", "9"], ["83943.8", "0.01389", "0", "1"], ["83940.3", "0.1715339", "0", "2"], ["83937", "0.79931045", "0", "5"], ["83936", "1.08559", "0", "3"], ["83935.3", "0", "0", "0"], ["83935.2", "0.35735", "0", "1"], ["83934.2", "0.04", "0", "1"], ["83932.8", "0.1485108", "0", "1"], ["83932.7", "0", "0", "0"], ["83932.3", "0", "0", "0"], ["83930.9", "0", "0", "0"], ["83925.5", "0.1788195", "0", "2"], ["83921.9", "0.24035898", "0", "2"], ["83916.7", "0.045045", "0", "1"], ["83814.1", "0.00003395", "0", "1"]], "ts": "1742577149000", "checksum": 1805808843, "seqId": 49945045469, "prevSeqId": 49945045393}], "record_time": 1742577149.170882, "EXCHANGE": "OKX"}
{"arg": {"channel": "books", "instId": "BTC-USDT"}, "action": "update", "data": [{"asks": [["83950.1", "1.40677076", "0", "18"], ["83950.2", "0.02919849", "0", "1"], ["83950.4", "0.13466679", "0", "3"], ["83951.7", "0", "0", "0"], ["83953.1", "0.00033", "0", "1"], ["83953.8", "0.01021", "0", "1"], ["83954.6", "0.00360646", "0", "1"], ["83957", "0", "0", "0"], ["83972.1", "1", "0", "1"], ["83973.4", "0", "0", "0"], ["83978.8", "0.01908", "0", "1"], ["83980.1", "0.2383562", "0", "1"], ["84005.4", "0.00002157", "0", "1"], ["84014.4", "0", "0", "0"], ["84132.5", "0", "0", "0"], ["84132.6", "0", "0", "0"], ["84132.8", "0", "0", "0"], ["84133.1", "0", "0", "0"]], "bids": [["83950.3", "0", "0", "0"], ["83950", "0.0963", "0", "3"], ["83949.4", "0", "0", "0"], ["83948.9", "0.04599913", "0", "1"], ["83947", "0", "0", "0"], ["83945.2", "0", "0", "0"], ["83943.8", "0.11918445", "0", "1"], ["83937", "0.46690525", "0", "4"], ["83936", "0.0439", "0", "1"], ["83934.2", "0", "0", "0"], ["83932.3", "0.04", "0", "1"], ["83927.8", "0", "0", "0"], ["83927.2", "0.2383562", "0", "1"], ["83925.5", "0.17868", "0", "1"], ["83924.6", "0", "0", "0"], ["83921.9", "0.002", "0", "1"], ["83870.1", "0", "0", "0"], ["83860.1", "0.00018346", "0", "1"], ["83813.1", "0.00001199", "0", "1"], ["83812.8", "0.01493332", "0", "1"], ["83812.6", "0.00579923", "0", "1"], ["83812.5", "0.00667459", "0", "3"]], "ts": "1742577149100", "checksum": 2053783930, "seqId": 49945045589, "prevSeqId": 49945045469}], "record_time": 1742577149.274988, "EXCHANGE": "OKX"}
{"arg": {"channel": "books", "instId": "BTC-USDT"}, "action": "update", "data": [{"asks": [["83950.1", "1.27954648", "0", "17"], ["83950.4", "0.13109379", "0", "2"], ["83954.6", "0", "0", "0"], ["83956.8", "0.03063", "0", "1"], ["83963.8", "0", "0", "0"], ["83976.9", "0.003573", "0", "1"], ["83978.8", "0.25744097", "0", "2"], ["83980.1", "0", "0", "0"], ["83983.3", "0.23022796", "0", "2"], ["83984.5", "0.06166447", "0", "2"], ["83985", "0", "0", "0"], ["83990.6", "0.0119211", "0", "2"], ["83994.6", "0.1", "0", "1"], ["83994.9", "0", "0", "0"], ["84132.5", "0.17898725", "0", "1"], ["84132.6", "0.0000434", "0", "1"]], "bids": [["83950", "0.1829", "0", "4"], ["83943.9", "0.06085592", "0", "1"], ["83937", "0.78370723", "0", "5"], ["83936.8", "0.01396199", "0", "3"], ["83934.2", "0.134819", "0", "1"], ["83933.9", "0.00856928", "0", "2"], ["83933.8", "1", "0", "1"], ["83930.5", "0.04169", "0", "1"], ["83927.2", "0", "0", "0"], ["83924.4", "0.70786802", "0", "3"], ["83922.2", "0.23836086", "0", "1"], ["83915.2", "0.66104411", "0", "2"], ["83882.6", "0", "0", "0"], ["83880.1", "0.00145279", "0", "1"], ["83813.1", "0", "0", "0"], ["83812.8", "0", "0", "0"], ["83812.6", "0", "0", "0"], ["83812.5", "0", "0", "0"]], "ts": "1742577149200", "checksum": 413828470, "seqId": 49945045630, "prevSeqId": 49945045589}], "record_time": 1742577149.370656, "EXCHANGE": "OKX"}
{"arg": {"channel": "books", "instId": "BTC-USDT"}, "action": "update", "data": [{"asks": [["83950.1", "1.04078982", "0", "14"], ["83953.8", "0", "0", "0"], ["83956.5", "0.00001199", "0", "1"], ["83956.9", "0.1034034", "0", "2"], ["83957.1", "0.01153238", "0", "1"], ["83957.9", "0", "0", "0"], ["83972.1", "0", "0", "0"], ["83973.1", "1", "0", "1"], ["83978.8", "0.01908", "0", "1"], ["83980.1", "0.238358", "0", "1"], ["83990.4", "0.08", "0", "2"], ["83991.2", "0.04001198", "0", "2"], ["83995.2", "0.00978149", "0", "1"], ["83996.8", "0", "0", "0"], ["83997.3", "0", "0", "0"], ["83997.6", "0", "0", "0"]], "bids": [["83950", "0.34222378", "0", "6"], ["83944.2", "0.13552592", "0", "1"], ["83944.1", "0.2", "0", "1"], ["83943.9", "0", "0", "0"], ["83943", "0.00774376", "0", "1"], ["83940.3", "0.465225", "0", "1"], ["83938.1", "0.04", "0", "1"], ["83937", "1.46690525", "0", "5"], ["83933.8", "0", "0", "0"], ["83932.3", "0", "0", "0"], ["83926.4", "0.004935", "0", "1"], ["83924.4", "0.70339952", "0", "2"], ["83922.2", "0.238358", "0", "1"], ["83915.2", "0.46650634", "0", "3"], ["83914.4", "0.04", "0", "1"], ["83913.6", "0.00079949", "0", "2"], ["83909.6", "0.1", "0", "2"], ["83908.8", "0.05", "0", "1"], ["83908", "0", "0", "0"], ["83813.6", "0", "0", "0"], ["83813.5", "0", "0", "0"]], "ts": "1742577149300", "checksum": 1263517067, "seqId": 49945045693, "prevSeqId": 49945045630}], "record_time": 1742577149.4712, "EXCHANGE": "OKX"}
{"arg": {"channel": "books", "instId": "BTC-USDT"}, "action": "update", "data": [{"asks": [["83950.1", "1.14078982", "0", "15"], ["83950.2", "0.05531231", "0", "2"], ["83953.1", "0", "0", "0"], ["83993.8", "0.00427848", "0", "1"], ["83995.2", "0", "0", "0"], ["84132.8", "0.00002013", "0", "1"]], "bids": [["83950", "0.1829", "0", "4"], ["83946.2", "0.11918101", "0", "1"], ["83943.8", "0", "0", "0"], ["83938.3", "1", "0", "1"], ["83937", "0.46690525", "0", "4"], ["83922.5", "0.31", "0", "1"], ["83814.1", "0", "0", "0"], ["83813.8", "0", "0", "0"]], "ts": "1742577149400", "checksum": -2094771354, "seqId": 49945045706, "prevSeqId": 49945045693}], "record_time": 1742577149.570431, "EXCHANGE": "OKX"}
{"arg": {"channel": "books", "instId": "BTC-USDT"}, "action": "update", "data": [{"asks": [["83950.1", "0.36305798", "0", "5"], ["83950.4", "0.01191865", "0", "1"], ["83952.4", "0.11917239", "0", "1"], ["83954.2", "0.0000555", "0", "1"], ["83956.8", "0", "0", "0"], ["83958", "0.32467826", "0", "5"], ["83962.1", "0.03062", "0", "1"], ["83970.9", "0.21937164", "0", "1"], ["83973.1", "0", "0", "0"], ["83974.8", "0.90455666", "0", "1"], ["83974.9", "1", "0", "1"], ["83975.1", "0", "0", "0"], ["83980.1", "0.23835839", "0", "1"], ["84132.6", "0", "0", "0"], ["84132.8", "0", "0", "0"]], "bids": [["83950", "0.46376554", "0", "18"], ["83948.9", "0", "0", "0"], ["83948.8", "0.10976502", "0", "2"], ["83948.7", "0.11917749", "0", "1"], ["83946.2", "0", "0", "0"], ["83940.8", "0.57894107", "0", "1"], ["83940.7", "1", "0", "1"], ["83940.3", "0", "0", "0"], ["83939", "0.0567783", "0", "2"], ["83938.3", "0", "0", "0"], ["83936.8", "0.00007199", "0", "2"], ["83935.7", "0.04169", "0", "1"], ["83930.5", "0", "0", "0"], ["83926.4", "0", "0", "0"], ["83922.6", "0.23835839", "0", "1"], ["83922.2", "0", "0", "0"], ["83814.1", "0.00003395", "0", "1"]], "ts": "1742577149500", "checksum": -1354720951, "seqId": 49945045784, "prevSeqId": 49945045706}], "record_time": 1742577149.671012, "EXCHANGE": "OKX"}
{"arg": {"channel": "books", "instId": "BTC-USDT"}, "action": "update", "data": [{"asks": [["83950.1", "0.33527107", "0", "7"], ["83950.4", "0.01336629", "0", "2"], ["83974.7", "0.01774536", "0", "1"], ["83975", "0", "0", "0"], ["83983.7", "0", "0", "0"], ["83984.2", "0", "0", "0"], ["83989.8", "0.01190621", "0", "1"], ["83990.3", "0.01190614", "0", "1"], ["83990.4", "0", "0", "0"], ["83991.2", "0.08001198", "0", "3"], ["83992", "0.03999999", "0", "1"], ["84004.7", "0", "0", "0"], ["84132.6", "0.0000434", "0", "1"]], "bids": [["83950", "0.46570554", "0", "19"], ["83935.2", "0", "0", "0"], ["83927.8", "0.004935", "0", "1"], ["83925.5", "0", "0", "0"], ["83915.2", "0.38650634", "0", "1"], ["83914.4", "0.08", "0", "2"], ["83913.6", "0.04079949", "0", "3"], ["83909.6", "0", "0", "0"], ["83908.8", "0.1", "0", "2"], ["83908", "0.05", "0", "1"], ["83813.8", "0.11936928", "0", "1"]], "ts": "1742577149600", "checksum": -741620339, "seqId": 49945045813, "prevSeqId": 49945045784}], "record_time": 1742577149.772726, "EXCHANGE": "OKX"}
{"arg": {"channel": "books", "instId": "BTC-USDT"}, "action": "update", "data": [{"asks": [["83958.6", "0.01021", "0", "1"], ["83959.3", "0.00205733", "0", "2"], ["83970.4", "0.30193", "0", "1"], ["84132.5", "0", "0", "0"], ["84132.6", "0", "0", "0"]], "bids": [["83944.8", "0.01389", "0", "1"], ["83939", "0.0428883", "0", "1"], ["83937.7", "0.35736", "0", "1"], ["83928", "0.38118", "0", "2"], ["83912.6", "0.5776526", "0", "1"], ["83907.3", "0", "0", "0"], ["83870.7", "0.58226341", "0", "1"], ["83865.3", "0", "0", "0"], ["83814.1", "0", "0", "0"], ["83813.8", "0", "0", "0"]], "ts": "1742577149700", "checksum": -1332929134, "seqId": 49945045828, "prevSeqId": 49945045813}], "record_time": 1742577149.871198, "EXCHANGE": "OKX"}
{"arg": {"channel": "books", "instId": "BTC-USDT"}, "action": "update", "data": [{"asks": [["83950.1", "0.37355133", "0", "14"], ["83950.2", "0.02919849", "0", "1"], ["83950.5", "0.11917503", "0", "1"], ["83952.4", "0", "0", "0"], ["83957.1", "0", "0", "0"], ["83959.3", "0", "0", "0"], ["83959.6", "0.00104994", "0", "1"], ["83967.6", "0.42904618", "0", "1"], ["83971.9", "1", "0", "1"], ["83974.8", "0", "0", "0"], ["83974.9", "0", "0", "0"], ["83978.8", "0.25744062", "0", "2"], ["83980.1", "0", "0", "0"], ["84132.5", "0.17898725", "0", "1"], ["84132.6", "0.0000434", "0", "1"], ["84132.8", "0.00002013", "0", "1"], ["84133.1", "0.08991011", "0", "1"]], "bids": [["83950", "0.34910554", "0", "10"], ["83940.8", "0.29387474", "0", "1"], ["83940.7", "0", "0", "0"], ["83937", "0.72945493", "0", "5"], ["83935.3", "1", "0", "1"], ["83927.8", "0", "0", "0"], ["83922.6", "0", "0", "0"], ["83919.9", "0.25026642", "0", "2"], ["83909.6", "0.1", "0", "2"], ["83908.8", "0.05", "0", "1"], ["83908", "0", "0", "0"], ["83814.1", "0.00003395", "0", "1"], ["83813.8", "0.11936928", "0", "1"]], "ts": "1742577149800", "checksum": 568553619, "seqId": 49945045879, "prevSeqId": 49945045828}], "record_time": 1742577149.970701, "EXCHANGE": "OKX"}
{"arg": {"channel": "books", "instId": "BTC-USDT"}, "action": "update", "data": [{"asks": [["83950.1", "0.46237895", "0", "14"], ["83950.2", "0.06214907", "0", "2"], ["83955.2", "0.01021", "0", "1"], ["83958.6", "0", "0", "0"], ["83959.6", "0", "0", "0"], ["83974.7", "0", "0", "0"], ["83976.9", "0.02131836", "0", "2"], ["83990.4", "0.08", "0", "2"], ["83991.2", "0.04001198", "0", "2"], ["83992", "0", "0", "0"], ["84133.3", "0.00517228", "0", "9"], ["84133.5", "0.00001277", "0", "1"]], "bids": [["83950", "0.25523554", "0", "8"], ["83948.8", "0.04599994", "0", "1"], ["83948.7", "0", "0", "0"], ["83944.8", "0", "0", "0"], ["83941.4", "0.01389", "0", "1"], ["83936", "1.0439", "0", "2"], ["83935.3", "0", "0", "0"], ["83925.3", "0.0000195", "0", "1"], ["83915.2", "0.46650634", "0", "3"], ["83914.4", "0.04", "0", "1"], ["83913.6", "0.00079949", "0", "2"], ["83813.6", "0.03579964", "0", "2"]], "ts": "1742577149900", "checksum": 1062895119, "seqId": 49945045910, "prevSeqId": 49945045879}], "record_time": 1742577150.071398, "EXCHANGE": "OKX"}
{"arg": {"channel": "books", "instId": "BTC-USDT"}, "action": "update", "data": [{"asks": [["83955", "0.01153238", "0", "1"], ["83970.4", "0", "0", "0"], ["83971.9", "0", "0", "0"], ["83973.3", "1", "0", "1"], ["83982.4", "0.2553", "0", "5"], ["83983.2", "0.0004", "0", "1"], ["83988.8", "0", "0", "0"], ["83989.6", "0", "0", "0"], ["84134.1", "0.0895461", "0", "3"]], "bids": [["83950", "0.41913382", "0", "11"], ["83940.8", "0.5571404", "0", "2"], ["83937.4", "1", "0", "1"], ["83937", "0.46690525", "0", "4"], ["83936", "0.0439", "0", "1"], ["83914.4", "0.0408", "0", "3"], ["83913.6", "0.00039949", "0", "1"], ["83912.8", "0", "0", "0"]], "ts": "1742577150000", "checksum": 1226549968, "seqId": 49945045931, "prevSeqId": 49945045910}], "record_time": 1742577150.171966, "EXCHANGE": "OKX"}
{"arg": {"channel": "books", "instId": "BTC-USDT"}, "action": "update", "data": [{"asks": [["83950.1", "0.5213255", "0", "15"], ["83978.8", "0.25743905", "0", "2"], ["83990.4", "0", "0", "0"], ["83991.2", "0.08001198", "0", "3"], ["83992", "0.03999999", "0", "1"], ["84005.1", "0.00002157", "0", "1"], ["84005.4", "0", "0", "0"], ["84089.6", "0.2320747", "0", "2"], ["84093.1", "0", "0", "0"], ["84134.5", "0.0000103", "0", "1"]], "bids": [["83950", "0.41914382", "0", "12"], ["83939.1", "1.06975077", "0", "2"], ["83937.4", "0", "0", "0"], ["83923.8", "0.32438807", "0", "2"], ["83919.9", "0.0119058", "0", "1"], ["83904", "0", "0", "0"], ["83902.1", "0.0183653", "0", "2"], ["83882.9", "0", "0", "0"], ["83882.6", "0.00218689", "0", "1"], ["83832.4", "0", "0", "0"], ["83830.6", "0.18353304", "0", "1"], ["83813.5", "0.00002031", "0", "1"], ["83813.1", "0.00001199", "0", "1"]], "ts": "1742577150100", "checksum": -1823972991, "seqId": 49945045990, "prevSeqId": 49945045931}], "record_time": 1742577150.275475, "EXCHANGE": "OKX"}
{"arg": {"channel": "books", "instId": "BTC-USDT"}, "action": "update", "data": [{"asks": [["83959.3", "0.0036179", "0", "1"], ["83970.4", "0.18273", "0", "1"], ["83973.3", "0", "0", "0"], ["83978.8", "0.01908", "0", "1"], ["83981", "0.23835107", "0", "1"], ["83990.4", "0.08", "0", "2"], ["83991.2", "0.04001198", "0", "2"], ["83992", "0", "0", "0"], ["84134.1", "0", "0", "0"], ["84134.5", "0", "0", "0"]], "bids": [["83950", "0.43514382", "0", "13"], ["83927.2", "0.2383506", "0", "1"], ["83923.8", "0.08603", "0", "1"], ["83919", "1.2", "0", "2"], ["83813.5", "0", "0", "0"], ["83813.1", "0", "0", "0"]], "ts": "1742577150200", "checksum": 855196415, "seqId": 49945046019, "prevSeqId": 49945045990}], "record_time": 1742577150.376361, "EXCHANGE": "OKX"}
{"arg": {"channel": "books", "instId": "BTC-USDT"}, "action": "update", "data": [{"asks": [["83950.1", "0.3809655", "0", "13"], ["83954.2", "0", "0", "0"], ["83955.2", "0", "0", "0"], ["83956.9", "0.03777348", "0", "2"], ["83957.8", "0.01021", "0", "1"], ["83958", "0.12217826", "0", "4"], ["83958.5", "0.2025", "0", "1"], ["83981", "0", "0", "0"], ["83982.3", "0.23834825", "0", "1"], ["83982.4", "0.2545", "0", "3"], ["83983.2", "0.0008", "0", "2"], ["83984", "0.0004", "0", "1"], ["83990.4", "0", "0", "0"], ["83991.2", "0.08001198", "0", "3"], ["83992", "0.03999999", "0", "1"], ["84133.5", "0", "0", "0"]], "bids": [["83950", "0.63764382", "0", "14"], ["83948.9", "0.04181182", "0", "1"], ["83944.2", "0.38931998", "0", "2"], ["83944", "0.06279", "0", "3"], ["83941.8", "1.00001199", "0", "2"], ["83941.4", "0", "0", "0"], ["83940.8", "0.29387474", "0", "1"], ["83939.1", "0.06975077", "0", "1"], ["83928.1", "0.23834825", "0", "1"], ["83927.2", "0", "0", "0"], ["83925.9", "0.08991011", "0", "1"], ["83919.8", "0.66582986", "0", "2"], ["83915.2", "0.38650634", "0", "1"], ["83914.4", "0.0808", "0", "4"], ["83913.6", "0.04039949", "0", "2"], ["83909.6", "0", "0", "0"], ["83908.8", "0.1", "0", "2"], ["83908", "0.05", "0", "1"], ["83847", "0", "0", "0"]], "ts": "1742577150300", "checksum": -1166556168, "seqId": 49945046066, "prevSeqId": 49945046019}], "record_time": 1742577150.471302, "EXCHANGE": "OKX"}
{"arg": {"channel": "books", "instId": "BTC-USDT"}, "action": "update", "data": [{"asks": [["83950.1", "0.2759655", "0", "9"], ["83950.2", "0.02919849", "0", "1"], ["83950.5", "0", "0", "0"], ["83952.5", "0.11917219", "0", "1"], ["83955.8", "0.0049545", "0", "1"], ["83957.8", "0", "0", "0"], ["83958.5", "0", "0", "0"], ["83959.3", "0", "0", "0"], ["83962.1", "0", "0", "0"], ["83966.6", "0.03163534", "0", "3"], ["83982.3", "0.23834836", "0", "1"], ["84133.5", "0.00001277", "0", "1"], ["84134.1", "0.0895461", "0", "3"], ["84134.5", "0.0000103", "0", "1"]], "bids": [["83950", "0.70509382", "0", "15"], ["83949.5", "0.11917631", "0", "1"], ["83940", "0.0856", "0", "3"], ["83937.2", "0", "0", "0"], ["83935.7", "0", "0", "0"], ["83928.7", "0.23834836", "0", "1"], ["83928.1", "0", "0", "0"], ["83928", "0.2025", "0", "1"], ["83924", "1", "0", "1"], ["83919", "1", "0", "1"], ["83914.4", "0.08", "0", "2"], ["83913.6", "0.04079949", "0", "3"], ["83912.8", "0.0003995", "0", "1"], ["83813.6", "0", "0", "0"]], "ts": "1742577150400", "checksum": 1193451964, "seqId": 49945046100, "prevSeqId": 49945046066}], "record_time": 1742577150.571175, "EXCHANGE": "OKX"}
{"arg": {"channel": "books", "instId": "BTC-USDT"}, "action": "update", "data": [{"asks": [["83950.2", "0.06214822", "0", "2"], ["83958.5", "0.2025", "0", "1"], ["83960.3", "0.0102", "0", "1"], ["83982.3", "0", "0", "0"], ["83983.2", "0", "0", "0"], ["83984", "0", "0", "0"], ["83984.4", "0.23834526", "0", "1"], ["83984.8", "0.0008", "0", "2"], ["83985.6", "0.0004", "0", "1"], ["83986", "0.2", "0", "1"], ["83991.2", "0.00001199", "0", "1"], ["83992", "0", "0", "0"], ["83992.8", "0.07999999", "0", "2"], ["83993.6", "0.03999999", "0", "1"], ["84133.3", "0", "0", "0"], ["84133.5", "0", "0", "0"], ["84134.1", "0", "0", "0"], ["84134.5", "0", "0", "0"]], "bids": [["83949.6", "0.07756471", "0", "1"], ["83948.9", "0", "0", "0"], ["83946.6", "0.01889", "0", "2"], ["83944", "0.0489", "0", "2"], ["83940.2", "0.35736", "0", "1"], ["83939.7", "0.17868", "0", "1"], ["83937.7", "0", "0", "0"], ["83932.8", "0.23835257", "0", "2"], ["83930.5", "0.17868", "0", "1"], ["83929.2", "0.23834526", "0", "1"], ["83928.7", "0", "0", "0"], ["83924", "0", "0", "0"], ["83908.8", "0", "0", "0"], ["83908", "0.1", "0", "2"], ["83907.2", "0.05", "0", "1"], ["83851.4", "0.01852965", "0", "1"], ["83813.8", "0", "0", "0"]], "ts": "1742577150500", "checksum": 842180775, "seqId": 49945046145, "prevSeqId": 49945046100}], "record_time": 1742577150.671109, "EXCHANGE": "OKX"}
{"arg": {"channel": "books", "instId": "BTC-USDT"}, "action": "update", "data": [{"asks": [["83950.1", "0.27270222", "0", "8"], ["83958.5", "0", "0", "0"], ["83975", "1", "0", "1"], ["83986", "0", "0", "0"], ["84133.3", "0.00517228", "0", "9"]], "bids": [["83944.2", "0.13552592", "0", "1"], ["83941.8", "0.00001199", "0", "1"], ["83941.6", "1", "0", "1"], ["83940.8", "0.5696474", "0", "2"], ["83940.2", "0", "0", "0"]], "ts": "1742577150600", "checksum": 418324660, "seqId": 49945046166, "prevSeqId": 49945046145}], "record_time": 1742577150.770596, "EXCHANGE": "OKX"}
{"arg": {"channel": "books", "instId": "BTC-USDT"}, "action": "update", "data": [{"asks": [["83958.5", "0.2025", "0", "1"], ["83974.9", "0.01774536", "0", "1"], ["83976.9", "0.003573", "0", "1"], ["84133.1", "0", "0", "0"], ["84133.3", "0", "0", "0"]], "bids": [["83944.2", "0.38515298", "0", "2"], ["83940.8", "0.19917374", "0", "1"], ["83937.7", "0.35736", "0", "1"], ["83923.7", "0", "0", "0"], ["83907.3", "0.52041", "0", "1"], ["83814.1", "0", "0", "0"]], "ts": "1742577150700", "checksum": -2007718485, "seqId": 49945046178, "prevSeqId": 49945046166}], "record_time": 1742577150.873543, "EXCHANGE": "OKX"}
{"arg": {"channel": "books", "instId": "BTC-USDT"}, "action": "update", "data": [{"asks": [["83950.1", "0.37343208", "0", "10"], ["83973.5", "1.04", "0", "2"], ["83975", "0", "0", "0"], ["83976.9", "0", "0", "0"], ["83983.2", "0.23834764", "0", "1"], ["83984.4", "0", "0", "0"], ["83997.7", "0.003573", "0", "1"], ["84133.1", "0.08991011", "0", "1"]], "bids": [["83950", "0.42144398", "0", "13"], ["83940.8", "0.28148502", "0", "2"], ["83940.2", "0.008", "0", "1"], ["83929.2", "0", "0", "0"], ["83928.1", "0.23834764", "0", "1"], ["83902", "0.00036", "0", "1"], ["83814.4", "0", "0", "0"]], "ts": "1742577150800", "checksum": -278777088, "seqId": 49945046198, "prevSeqId": 49945046178}], "record_time": 1742577150.972815, "EXCHANGE": "OKX"}
{"arg": {"channel": "books", "instId": "BTC-USDT"}, "action": "update", "data": [{"asks": [["83950.1", "0.65212142", "0", "16"], ["83950.2", "0.06214902", "0", "2"], ["83950.7", "0.11917485", "0", "1"], ["83952.2", "0.000357", "0", "1"], ["83952.5", "0", "0", "0"], ["83955", "0", "0", "0"], ["83955.8", "0", "0", "0"], ["83957.4", "0.01021", "0", "1"], ["83959.3", "0.00361647", "0", "1"], ["83960.3", "0", "0", "0"], ["83966.6", "0.00101534", "0", "2"], ["83970.4", "0", "0", "0"], ["83973.4", "0.01774536", "0", "1"], ["83973.5", "0.04", "0", "1"], ["83973.6", "1", "0", "1"], ["83974.9", "0", "0", "0"], ["83980.7", "0.23835505", "0", "1"], ["83983.2", "0", "0", "0"], ["83992", "0.08", "0", "2"], ["83992.8", "0.03999999", "0", "1"], ["83993.6", "0", "0", "0"]], "bids": [["83950", "1.02819136", "0", "12"], ["83949.6", "0", "0", "0"], ["83949.5", "0", "0", "0"], ["83946.6", "0.005", "0", "1"], ["83945.1", "0.0424511", "0", "1"], ["83944.2", "0", "0", "0"], ["83944.1", "0", "0", "0"], ["83941.6", "0", "0", "0"], ["83940.8", "0.55527702", "0", "2"], ["83940.2", "0", "0", "0"], ["83940", "0.04391", "0", "2"], ["83938.6", "1", "0", "1"], ["83932.5", "0.04169", "0", "1"], ["83928.1", "0", "0", "0"], ["83925", "0.23835505", "0", "1"], ["83908.8", "0.1", "0", "2"], ["83908", "0.05", "0", "1"], ["83907.2", "0", "0", "0"], ["83905.2", "0.001787", "0", "1"], ["83814.4", "0.00005519", "0", "1"], ["83814.1", "0.00003395", "0", "1"]], "ts": "1742577150900", "checksum": 1820705798, "seqId": 49945046345, "prevSeqId": 49945046198}], "record_time": 1742577151.074083, "EXCHANGE": "OKX"}
{"arg": {"channel": "books", "instId": "BTC-USDT"}, "action": "update", "data": [{"asks": [["83978.8", "0.25743815", "0", "2"], ["83980.7", "0", "0", "0"], ["83990.4", "0.08", "0", "2"], ["83991.2", "0.04001198", "0", "2"], ["83992", "0", "0", "0"], ["83992.8", "0", "0", "0"], ["84133.3", "0.00517228", "0", "9"], ["84133.5", "0.00001277", "0", "1"]], "bids": [["83950", "0.85422294", "0", "10"], ["83938.6", "0", "0", "0"], ["83937.2", "0.17868", "0", "1"], ["83937.1", "1", "0", "1"], ["83932.8", "0.1485108", "0", "1"], ["83930.5", "0", "0", "0"], ["83928", "0.38118", "0", "2"], ["83925", "0", "0", "0"], ["83922.6", "0.23835815", "0", "1"], ["83915.2", "0.46650634", "0", "3"], ["83914.4", "0.04", "0", "1"], ["83913.6", "0.00079949", "0", "2"]], "ts": "1742577151000", "checksum": 915222115, "seqId": 49945046369, "prevSeqId": 49945046345}], "record_time": 1742577151.171127, "EXCHANGE": "OKX"}
{"arg": {"channel": "books", "instId": "BTC-USDT"}, "action": "update", "data": [{"asks": [["83950.1", "0.75248142", "0", "17"], ["83964.3", "0.03062", "0", "1"], ["84133.5", "0", "0", "0"]], "bids": [["83950", "0.61762294", "0", "8"], ["83944.3", "0.01389", "0", "1"], ["83938", "0.08559", "0", "2"], ["83932.5", "0", "0", "0"], ["83909.6", "0.1", "0", "2"], ["83908.8", "0.05", "0", "1"], ["83908", "0", "0", "0"]], "ts": "1742577151100", "checksum": -1103407774, "seqId": 49945046380, "prevSeqId": 49945046369}], "record_time": 1742577151.270867, "EXCHANGE": "OKX"}
{"arg": {"channel": "books", "instId": "BTC-USDT"}, "action": "update", "data": [{"asks": [["83958", "0.12003326", "0", "3"], ["83978.8", "0.01908", "0", "1"], ["83980.7", "0.23835395", "0", "1"], ["83982.4", "0.2553", "0", "5"], ["83983.2", "0.0004", "0", "1"], ["83984.8", "0", "0", "0"], ["83985", "1", "0", "1"], ["83985.6", "0", "0", "0"], ["84001.4", "0.003287", "0", "2"], ["84133.3", "0", "0", "0"]], "bids": [["83925", "0.23835395", "0", "1"], ["83922.6", "0", "0", "0"], ["83914.4", "0.0408", "0", "3"], ["83913.6", "0.00039949", "0", "1"], ["83912.8", "0", "0", "0"], ["83813.8", "0.11936928", "0", "1"]], "ts": "1742577151200", "checksum": -379656425, "seqId": 49945046397, "prevSeqId": 49945046380}], "record_time": 1742577151.369919, "EXCHANGE": "OKX"}
{"arg": {"channel": "books", "instId": "BTC-USDT"}, "action": "update", "data": [{"asks": [["83980.1", "0.23835673", "0", "1"], ["83980.7", "0", "0", "0"], ["83985", "0", "0", "0"], ["84133.3", "0.00517228", "0", "9"]], "bids": [["83939.7", "0", "0", "0"], ["83938.1", "0", "0", "0"], ["83934.2", "0.174819", "0", "2"], ["83925", "0", "0", "0"], ["83923.9", "0.23835673", "0", "1"], ["83813.6", "0.03579964", "0", "2"], ["83813.5", "0.00002031", "0", "1"]], "ts": "1742577151300", "checksum": -890944474, "seqId": 49945046414, "prevSeqId": 49945046397}], "record_time": 1742577151.47048, "EXCHANGE": "OKX"}
{"arg": {"channel": "books", "instId": "BTC-USDT"}, "action": "update", "data": [{"asks": [["83950.1", "0.74094904", "0", "16"], ["83954.8", "0.01153238", "0", "1"], ["83976.9", "0.55026961", "0", "1"], ["84133.1", "0", "0", "0"], ["84133.3", "0", "0", "0"]], "bids": [["83938.1", "0.008", "0", "1"], ["83929", "0", "0", "0"], ["83919", "1.2", "0", "2"]], "ts": "1742577151400", "checksum": 1084943137, "seqId": 49945046427, "prevSeqId": 49945046414}], "record_time": 1742577151.570937, "EXCHANGE": "OKX"}
{"arg": {"channel": "books", "instId": "BTC-USDT"}, "action": "update", "data": [{"asks": [["83950.1", "0.75248142", "0", "17"], ["83954.8", "0", "0", "0"], ["83973.6", "0", "0", "0"], ["83974.1", "1", "0", "1"], ["83980.1", "0.2383557", "0", "1"], ["84133.1", "0.08991011", "0", "1"]], "bids": [["83950", "0.63167294", "0", "7"], ["83939.2", "1", "0", "1"], ["83937.1", "0", "0", "0"], ["83925", "0.2383557", "0", "1"], ["83923.9", "0", "0", "0"], ["83922", "0.00037199", "0", "2"], ["83919.8", "0.32909819", "0", "1"], ["83919", "0.2", "0", "1"], ["83831.7", "0.183522", "0", "1"], ["83813.5", "0", "0", "0"]], "ts": "1742577151500", "checksum": 201163322, "seqId": 49945046467, "prevSeqId": 49945046427}], "record_time": 1742577151.67063, "EXCHANGE": "OKX"}
{"arg": {"channel": "books", "instId": "BTC-USDT"}, "action": "update", "data": [{"asks": [["83973.4", "0", "0", "0"], ["83974", "0.01774536", "0", "1"], ["83978.8", "0.25743871", "0", "2"], ["83980.1", "0", "0", "0"], ["83985", "0.2", "0", "1"]], "bids": [["83925", "0", "0", "0"], ["83922.6", "0.23835871", "0", "1"], ["83919", "0.21190621", "0", "2"], ["83912.9", "0", "0", "0"], ["83851.4", "0.06209125", "0", "2"], ["83813.5", "0.00002031", "0", "1"]], "ts": "1742577151600", "checksum": 201163322, "seqId": 49945046481, "prevSeqId": 49945046467}], "record_time": 1742577151.77068, "EXCHANGE": "OKX"}
{"arg": {"channel": "books", "instId": "BTC-USDT"}, "action": "update", "data": [{"asks": [["83950.1", "0.71094332", "0", "16"], ["83952.2", "0", "0", "0"], ["83954", "0.0000105", "0", "1"], ["83974.1", "0", "0", "0"], ["83978.8", "0.01908", "0", "1"], ["83981", "0.23835433", "0", "1"], ["83985", "0", "0", "0"], ["83990.4", "0", "0", "0"], ["83991.2", "0.08001198", "0", "3"], ["83992", "0.03999999", "0", "1"], ["84133.3", "0.00517228", "0", "9"]], "bids": [["83948.9", "0.04181182", "0", "1"], ["83945.1", "0.34131171", "0", "2"], ["83941.8", "1.00001199", "0", "2"], ["83940.8", "0.30878174", "0", "1"], ["83939.2", "0", "0", "0"], ["83925", "0.23835433", "0", "1"], ["83922.6", "0", "0", "0"], ["83915.2", "0.38650634", "0", "1"], ["83914.4", "0.0808", "0", "4"], ["83913.6", "0.04039949", "0", "2"]], "ts": "1742577151700", "checksum": 580195264, "seqId": 49945046531, "prevSeqId": 49945046481}], "record_time": 1742577151.873642, "EXCHANGE": "OKX"}
{"arg": {"channel": "books", "instId": "BTC-USDT"}, "action": "update", "data": [{"asks": [["83967.8", "0.04", "0", "1"], ["83967.9", "0", "0", "0"], ["83973.5", "0", "0", "0"], ["83974", "0", "0", "0"], ["83974.4", "1", "0", "1"], ["83976.2", "0.23836676", "0", "1"], ["83976.8", "0.01774536", "0", "1"], ["83981", "0", "0", "0"], ["83990.4", "0.08", "0", "2"], ["83991.2", "0.04001198", "0", "2"], ["83992", "0", "0", "0"]], "bids": [["83950", "0.61567294", "0", "6"], ["83949.1", "0.11917698", "0", "1"], ["83948.9", "0", "0", "0"], ["83945.1", "0.0424511", "0", "1"], ["83941.8", "0.00001199", "0", "1"], ["83940.8", "0.55818402", "0", "2"], ["83938.4", "1", "0", "1"], ["83932.9", "0", "0", "0"], ["83929", "0.00476593", "0", "1"], ["83925", "0", "0", "0"], ["83919.1", "0.23836676", "0", "1"], ["83915.2", "0.46650634", "0", "3"], ["83914.4", "0.0408", "0", "3"], ["83913.6", "0.00039949", "0", "1"], ["83813.5", "0", "0", "0"]], "ts": "1742577151800", "checksum": 1421320075, "seqId": 49945046571, "prevSeqId": 49945046531}], "record_time": 1742577151.971244, "EXCHANGE": "OKX"}
{"arg": {"channel": "books", "instId": "BTC-USDT"}, "action": "update", "data": [{"asks": [["83950.1", "0.74037203", "0", "17"], ["83959.8", "0.02", "0", "1"], ["83963.7", "0", "0", "0"], ["83967.6", "0.28098181", "0", "1"], ["83969.9", "0", "0", "0"], ["83973.1", "1", "0", "1"], ["83974.4", "0", "0", "0"], ["84133.5", "0.00001277", "0", "1"]], "bids": [["83949.1", "0", "0", "0"], ["83940.8", "0.30878174", "0", "1"], ["83938.4", "0", "0", "0"], ["83937", "0.72751822", "0", "5"], ["83935", "1", "0", "1"], ["83813.5", "0.00002031", "0", "1"]], "ts": "1742577151900", "checksum": -1441441102, "seqId": 49945046587, "prevSeqId": 49945046571}], "record_time": 1742577152.072829, "EXCHANGE": "OKX"}
{"arg": {"channel": "books", "instId": "BTC-USDT"}, "action": "update", "data": [{"asks": [["83962.5", "0.26754753", "0", "2"], ["83965.4", "0.35737501", "0", "2"], ["83976.1", "0.01774536", "0", "1"], ["83976.8", "0", "0", "0"], ["83984.5", "0.00137493", "0", "1"]], "bids": [["83950", "0.61736294", "0", "7"], ["83949.1", "0.11917694", "0", "1"], ["83935.2", "0.35736", "0", "1"], ["83918.1", "0", "0", "0"], ["83917.3", "0", "0", "0"], ["83915.1", "0.01190702", "0", "1"], ["83813.5", "0", "0", "0"]], "ts": "1742577152000", "checksum": -1051068333, "seqId": 49945046602, "prevSeqId": 49945046587}], "record_time": 1742577152.17251, "EXCHANGE": "OKX"}
{"arg": {"channel": "books", "instId": "BTC-USDT"}, "action": "update", "data": [{"asks": [["83981.7", "0.01190736", "0", "1"], ["83987.7", "0", "0", "0"], ["83988.8", "0.05951623", "0", "1"], ["84133.5", "0", "0", "0"]], "bids": [["83936.4", "1.2185", "0", "3"], ["83935", "0", "0", "0"], ["83921.9", "0", "0", "0"], ["83921.5", "0.06176086", "0", "1"], ["83919.9", "0.25026726", "0", "2"], ["83919.6", "0", "0", "0"], ["83919.1", "0", "0", "0"], ["83915.7", "0.01190669", "0", "1"], ["83911.8", "0.036", "0", "1"], ["83813.5", "0.00002031", "0", "1"], ["83813.1", "0.00001199", "0", "1"]], "ts": "1742577152100", "checksum": -1051068333, "seqId": 49945046618, "prevSeqId": 49945046602}], "record_time": 1742577152.2717, "EXCHANGE": "OKX"}
{"arg": {"channel": "books", "instId": "BTC-USDT"}, "action": "update", "data": [{"asks": [["83950.1", "0.91344332", "0", "17"], ["83954.8", "0.01021", "0", "1"], ["83957.4", "0", "0", "0"], ["83959.6", "0.03062", "0", "1"], ["83964.3", "0", "0", "0"], ["83976.2", "0.23836181", "0", "1"], ["84091.5", "0", "0", "0"], ["84133.5", "0.00001277", "0", "1"]], "bids": [["83950", "0.1804092", "0", "3"], ["83949.1", "0", "0", "0"], ["83946", "0.16308128", "0", "2"], ["83944.3", "0", "0", "0"], ["83941.1", "0.01389", "0", "1"], ["83938", "0.0439", "0", "1"], ["83936.4", "0.2185", "0", "2"], ["83936", "1.0439", "0", "2"], ["83933.2", "0.04169", "0", "1"], ["83919.9", "0.23836181", "0", "1"], ["83916", "0.12447643", "0", "3"]], "ts": "1742577152200", "checksum": 285214044, "seqId": 49945046658, "prevSeqId": 49945046618}], "record_time": 1742577152.376845, "EXCHANGE": "OKX"}
{"arg": {"channel": "books", "instId": "BTC-USDT"}, "action": "update", "data": [{"asks": [["83948.9", "1.17561766", "0", "15"], ["83949.5", "0.14837334", "0", "1"], ["83949.8", "0.11917612", "0", "1"], ["83950", "0.0439", "0", "1"], ["83950.1", "0.07613326", "0", "2"], ["83950.2", "0", "0", "0"], ["83950.7", "0", "0", "0"], ["83953.6", "0.02739775", "0", "1"], ["83955.1", "0.00774281", "0", "1"], ["83955.9", "0.0374796", "0", "1"], ["83956.9", "0.00112", "0", "1"], ["83958", "0.0799", "0", "2"], ["83963.6", "0", "0", "0"], ["83969", "0.17898725", "0", "1"], ["83976.2", "0.2383681", "0", "1"], ["83994.2", "0.02283169", "0", "1"], ["83994.6", "0", "0", "0"], ["84132.8", "0", "0", "0"], ["84133.1", "0", "0", "0"], ["84133.3", "0", "0", "0"], ["84133.5", "0", "0", "0"]], "bids": [["83950", "0", "0", "0"], ["83948.8", "0.139", "0", "3"], ["83948.7", "0.04599995", "0", "1"], ["83941.1", "0", "0", "0"], ["83936", "0.0439", "0", "1"], ["83935.6", "1", "0", "1"], ["83934.2", "0.134819", "0", "1"], ["83933.2", "0", "0", "0"], ["83932.5", "0.04", "0", "1"], ["83929", "0", "0", "0"], ["83927.3", "0.00476603", "0", "1"], ["83926.3", "0.48334697", "0", "4"], ["83925.9", "0", "0", "0"], ["83919.9", "0", "0", "0"], ["83918.8", "0.2383681", "0", "1"], ["83909.6", "0", "0", "0"], ["83908.8", "0.1", "0", "2"], ["83908", "0.05", "0", "1"], ["83901.7", "0", "0", "0"], ["83883.4", "0", "0", "0"], ["83882.4", "0.08987613", "0", "3"], ["83882", "0.047648", "0", "1"], ["83880.2", "0.00100708", "0", "1"], ["83812.8", "0.01493332", "0", "1"]], "ts": "1742577152300", "checksum": 1283239002, "seqId": 49945046823, "prevSeqId": 49945046658}], "record_time": 1742577152.471293, "EXCHANGE": "OKX"}
{"arg": {"channel": "books", "instId": "BTC-USDT"}, "action": "update", "data": [{"asks": [["83948.9", "0.5206319", "0", "8"], ["83949.5", "0.08718854", "0", "1"], ["83950.1", "0.04013326", "0", "1"], ["83954.8", "0", "0", "0"], ["83958.1", "0.02", "0", "1"], ["83959.8", "0", "0", "0"], ["83962.5", "0.18561902", "0", "1"], ["83965.4", "0.00001501", "0", "1"], ["83970.9", "0", "0", "0"], ["83973.1", "0", "0", "0"], ["83981", "1", "0", "1"], ["83993.4", "0.1", "0", "1"], ["83994.2", "0", "0", "0"], ["84011", "0.00001198", "0", "1"], ["84132.8", "0.00002013", "0", "1"], ["84133.1", "0.08991011", "0", "1"]], "bids": [["83948.8", "0.35377038", "0", "8"], ["83948", "0.16307851", "0", "2"], ["83946", "0.0439", "0", "1"], ["83938.5", "1", "0", "1"], ["83937.1", "0.01389", "0", "1"], ["83935.6", "0", "0", "0"], ["83932.9", "0.04169", "0", "1"], ["83922.6", "0.23836071", "0", "1"], ["83918.8", "0", "0", "0"], ["83917.5", "0.05193", "0", "1"], ["83912.8", "0.026", "0", "2"], ["83912.7", "0.01190735", "0", "1"], ["83912", "0.013012", "0", "2"], ["83903.2", "0.52955039", "0", "1"], ["83902.4", "0", "0", "0"], ["83882.6", "0", "0", "0"], ["83882.1", "0.00100708", "0", "1"], ["83880.2", "0.00218687", "0", "1"], ["83813.5", "0", "0", "0"], ["83813.1", "0", "0", "0"], ["83812.8", "0", "0", "0"]], "ts": "1742577152400", "checksum": -1606184584, "seqId": 49945046885, "prevSeqId": 49945046823}], "record_time": 1742577152.583688, "EXCHANGE": "OKX"}
{"arg": {"channel": "books", "instId": "BTC-USDT"}, "action": "update", "data": [{"asks": [["83948.9", "0.40143052", "0", "5"], ["83950.1", "0", "0", "0"], ["83950.7", "0.002", "0", "1"], ["83955.2", "0.04013326", "0", "1"], ["83956.6", "0.01153238", "0", "1"], ["83960.7", "0.002", "0", "1"], ["83962.5", "0.3037462", "0", "2"], ["83962.9", "0.35736", "0", "1"], ["83964.8", "0.17868", "0", "1"], ["83981.6", "0.0528", "0", "4"], ["83982.4", "0.2549", "0", "4"], ["83983.2", "0", "0", "0"], ["84005.4", "0.01191753", "0", "1"], ["84036.4", "0", "0", "0"], ["84132.5", "0", "0", "0"], ["84132.6", "0", "0", "0"], ["84132.8", "0", "0", "0"], ["84133.1", "0", "0", "0"]], "bids": [["83948.8", "0.38948366", "0", "12"], ["83946.9", "0.002", "0", "1"], ["83940.8", "0.54984402", "0", "2"], ["83940", "1.04391", "0", "3"], ["83938.5", "0", "0", "0"], ["83936.9", "0.042", "0", "2"], ["83919.8", "0.64490628", "0", "2"], ["83919", "1.21190621", "0", "3"], ["83892.4", "0.06", "0", "2"], ["83851.4", "0.01852965", "0", "1"], ["83813.6", "0", "0", "0"]], "ts": "1742577152500", "checksum": 1173095720, "seqId": 49945046929, "prevSeqId": 49945046885}], "record_time": 1742577152.67034, "EXCHANGE": "OKX"}
{"arg": {"channel": "books", "instId": "BTC-USDT"}, "action": "update", "data": [{"asks": [["83955.5", "0.01021", "0", "1"], ["83976.9", "0", "0", "0"], ["83977", "0", "0", "0"], ["84005.2", "0.30521494", "0", "1"], ["84006.4", "0.00103317", "0", "1"], ["84132.5", "0.17898725", "0", "1"]], "bids": [["83948.7", "0", "0", "0"], ["83941.8", "0.01390199", "0", "2"], ["83937.1", "0", "0", "0"], ["83924.4", "0.02383701", "0", "1"], ["83922.6", "0", "0", "0"], ["83922.1", "0", "0", "0"], ["83921.9", "0.2383614", "0", "1"], ["83895", "0.15485072", "0", "3"], ["83892.7", "0.00001501", "0", "1"], ["83871.5", "0.01191767", "0", "1"], ["83844.1", "0", "0", "0"], ["83813.6", "0.03579964", "0", "2"], ["83813.5", "0.00002031", "0", "1"], ["83813.1", "0.00001199", "0", "1"]], "ts": "1742577152600", "checksum": 274834494, "seqId": 49945046951, "prevSeqId": 49945046929}], "record_time": 1742577152.774406, "EXCHANGE": "OKX"}
{"arg": {"channel": "books", "instId": "BTC-USDT"}, "action": "update", "data": [{"asks": [["83949.5", "0.08128322", "0", "2"], ["83949.8", "0", "0", "0"], ["83951.8", "0.11917328", "0", "1"], ["83971.9", "1.59091449", "0", "1"], ["83976.1", "0", "0", "0"], ["83985", "0.2", "0", "1"], ["84001.3", "2.89718648", "0", "1"], ["84043.8", "0.01774536", "0", "1"], ["84131.2", "0", "0", "0"], ["84131.7", "0", "0", "0"], ["84132.5", "0", "0", "0"]], "bids": [["83916.3", "1.5543473", "0", "1"], ["83886.9", "2.84425477", "0", "1"], ["83813.5", "0", "0", "0"], ["83813.1", "0", "0", "0"]], "ts": "1742577152700", "checksum": 514915091, "seqId": 49945046965, "prevSeqId": 49945046951}], "record_time": 1742577152.933542, "EXCHANGE": "OKX"}
{"arg": {"channel": "books", "instId": "BTC-USDT"}, "action": "update", "data": [{"asks": [["83973.3", "1", "0", "1"], ["83989.6", "0.08", "0", "2"], ["83990.4", "0.03999999", "0", "1"], ["83991.2", "0.00001199", "0", "1"], ["84130.5", "0", "0", "0"], ["84131.1", "0", "0", "0"]], "bids": [["83921.9", "0", "0", "0"], ["83919.9", "0.23836438", "0", "1"], ["83909.6", "0.1", "0", "2"], ["83908.8", "0.05", "0", "1"], ["83908", "0", "0", "0"]], "ts": "1742577152800", "checksum": 514915091, "seqId": 49945046978, "prevSeqId": 49945046965}], "record_time": 1742577152.970928, "EXCHANGE": "OKX"}
{"arg": {"channel": "books", "instId": "BTC-USDT"}, "action": "update", "data": [{"asks": [["83978.8", "0.03682536", "0", "2"], ["83989.6", "0", "0", "0"], ["83990.4", "0.07999999", "0", "2"], ["83991.2", "0.04001198", "0", "2"], ["84043.8", "0", "0", "0"], ["84130.5", "0.11889794", "0", "1"], ["84131.1", "0.00008649", "0", "2"]], "bids": [["83940", "0.04391", "0", "2"], ["83938.1", "1.008", "0", "2"]], "ts": "1742577152900", "checksum": -1030611533, "seqId": 49945046991, "prevSeqId": 49945046978}], "record_time": 1742577153.07105, "EXCHANGE": "OKX"}
{"arg": {"channel": "books", "instId": "BTC-USDT"}, "action": "update", "data": [{"asks": [["83948.9", "0.30334419", "0", "6"], ["83968.6", "0.003573", "0", "1"], ["83971.7", "1", "0", "1"], ["83973.3", "0", "0", "0"], ["83989.6", "0.08", "0", "2"], ["83990.4", "0.03999999", "0", "1"], ["83991.2", "0.00001199", "0", "1"], ["83997.7", "0", "0", "0"], ["84131.1", "0", "0", "0"]], "bids": [["83948.8", "0.24313524", "0", "10"], ["83940.8", "0.30878174", "0", "1"], ["83938.1", "0.008", "0", "1"], ["83934.8", "1", "0", "1"], ["83919.9", "0", "0", "0"], ["83918.8", "0.23836913", "0", "1"], ["83813.6", "0", "0", "0"]], "ts": "1742577153000", "checksum": -338650209, "seqId": 49945047015, "prevSeqId": 49945046991}], "record_time": 1742577153.170347, "EXCHANGE": "OKX"}
{"arg": {"channel": "books", "instId": "BTC-USDT"}, "action": "update", "data": [{"asks": [["83948.9", "0.6200201", "0", "11"], ["83968.6", "0", "0", "0"], ["83972.8", "0.13190862", "0", "5"], ["83981.5", "0.14071224", "0", "1"], ["83987", "0.003573", "0", "1"]], "bids": [["83948.8", "0.66572766", "0", "13"], ["83936.5", "1.54096076", "0", "4"], ["83934.8", "0", "0", "0"], ["83914.9", "0", "0", "0"], ["83813.6", "0.03579964", "0", "2"], ["83813.5", "0.00002031", "0", "1"]], "ts": "1742577153100", "checksum": 957509238, "seqId": 49945047034, "prevSeqId": 49945047015}], "record_time": 1742577153.270304, "EXCHANGE": "OKX"}
{"arg": {"channel": "books", "instId": "BTC-USDT"}, "action": "update", "data": [{"asks": [["83987.3", "0.0001722", "0", "1"], ["83996.6", "0", "0", "0"]], "bids": [["83935.2", "0", "0", "0"], ["83909.3", "0.0119076", "0", "1"], ["83900", "0.00047203", "0", "2"]], "ts": "1742577153200", "checksum": 957509238, "seqId": 49945047044, "prevSeqId": 49945047034}], "record_time": 1742577153.374347, "EXCHANGE": "OKX"}
{"arg": {"channel": "books", "instId": "BTC-USDT"}, "action": "update", "data": [{"asks": [["83971.7", "0", "0", "0"], ["84131.1", "0.00008649", "0", "2"]], "bids": [], "ts": "1742577153300", "checksum": 957509238, "seqId": 49945047049, "prevSeqId": 49945047044}], "record_time": 1742577153.471049, "EXCHANGE": "OKX"}
{"arg": {"channel": "books", "instId": "BTC-USDT"}, "action": "update", "data": [{"asks": [["83971.8", "0.52885144", "0", "1"], ["83972", "1", "0", "1"], ["84130.5", "0", "0", "0"], ["84131.1", "0", "0", "0"]], "bids": [["83948.7", "0.04599999", "0", "1"], ["83936.5", "0.54096076", "0", "3"], ["83921.6", "0.23836449", "0", "1"], ["83918.8", "0", "0", "0"], ["83890.5", "0.90955654", "0", "3"], ["83851.4", "0.17792639", "0", "2"], ["83813.5", "0", "0", "0"]], "ts": "1742577153400", "checksum": -1185633575, "seqId": 49945047060, "prevSeqId": 49945047049}], "record_time": 1742577153.571253, "EXCHANGE": "OKX"}
{"arg": {"channel": "books", "instId": "BTC-USDT"}, "action": "update", "data": [{"asks": [["83987", "0", "0", "0"], ["84130.5", "0.11889794", "0", "1"]], "bids": [["83948.8", "0.66707766", "0", "14"], ["83940.8", "0.54567702", "0", "2"], ["83937.8", "1", "0", "1"], ["83937", "0.46690525", "0", "4"], ["83921.6", "0", "0", "0"], ["83919.9", "0.23836799", "0", "1"], ["83813.6", "0", "0", "0"]], "ts": "1742577153500", "checksum": 1459824705, "seqId": 49945047075, "prevSeqId": 49945047060}], "record_time": 1742577153.670359, "EXCHANGE": "OKX"}
{"arg": {"channel": "books", "instId": "BTC-USDT"}, "action": "update", "data": [{"asks": [["83949.5", "0.08128239", "0", "2"], ["83951.8", "0", "0", "0"], ["83953.7", "0.16205879", "0", "2"], ["83972", "0", "0", "0"], ["83973.4", "1", "0", "1"], ["84131.1", "0.00008649", "0", "2"]], "bids": [["83917.2", "0.01190862", "0", "1"], ["83877.5", "0", "0", "0"], ["83853.6", "0.00589966", "0", "1"], ["83850.7", "0.000015", "0", "1"]], "ts": "1742577153600", "checksum": 782796813, "seqId": 49945047090, "prevSeqId": 49945047075}], "record_time": 1742577153.779819, "EXCHANGE": "OKX"}
{"arg": {"channel": "books", "instId": "BTC-USDT"}, "action": "update", "data": [{"asks": [["83966.2", "0.06341006", "0", "3"], ["83981.6", "0.052", "0", "2"], ["83982.4", "0.2553", "0", "5"], ["83983.2", "0.0004", "0", "1"], ["83989.6", "0", "0", "0"], ["83990.4", "0.07999999", "0", "2"], ["83991.2", "0.04001198", "0", "2"]], "bids": [["83909.6", "0", "0", "0"], ["83908.8", "0.1", "0", "2"], ["83908", "0.05", "0", "1"]], "ts": "1742577153700", "checksum": 782796813, "seqId": 49945047105, "prevSeqId": 49945047090}], "record_time": 1742577153.871102, "EXCHANGE": "OKX"}
{"arg": {"channel": "books", "instId": "BTC-USDT"}, "action": "update", "data": [{"asks": [["83976.2", "0", "0", "0"], ["83977.7", "0.23836489", "0", "1"], ["83981", "0", "0", "0"], ["83981.6", "0.0528", "0", "4"], ["83982.4", "0.2549", "0", "4"], ["83983.2", "0", "0", "0"], ["83985", "0", "0", "0"], ["84131.2", "0.03", "0", "1"], ["84131.7", "0.14263366", "0", "2"], ["84132.5", "0.17898725", "0", "1"]], "bids": [["83944.7", "0", "0", "0"], ["83919.9", "0.23836505", "0", "1"], ["83813.6", "0.03579964", "0", "2"]], "ts": "1742577153800", "checksum": 2128896153, "seqId": 49945047120, "prevSeqId": 49945047105}], "record_time": 1742577153.981956, "EXCHANGE": "OKX"}
{"arg": {"channel": "books", "instId": "BTC-USDT"}, "action": "update", "data": [{"asks": [["83978.8", "0.01908", "0", "1"], ["83982.6", "0.01190723", "0", "1"], ["83988", "0.01774536", "0", "1"], ["83988.2", "0", "0", "0"], ["84030.9", "0.34370513", "0", "2"], ["84131.7", "0.07131683", "0", "1"], ["84132.5", "0", "0", "0"]], "bids": [["83948.7", "0", "0", "0"], ["83866.2", "0.07165411", "0", "2"], ["83813.5", "0.00002031", "0", "1"]], "ts": "1742577153900", "checksum": -1078015940, "seqId": 49945047132, "prevSeqId": 49945047120}], "record_time": 1742577154.070548, "EXCHANGE": "OKX"}
{"arg": {"channel": "books", "instId": "BTC-USDT"}, "action": "update", "data": [{"asks": [["83982.4", "0.26680726", "0", "5"], ["83988.9", "0.02382412", "0", "1"], ["84030.9", "0.41510746", "0", "3"], ["84131.7", "0.14263366", "0", "2"]], "bids": [["83948.8", "0.87076886", "0", "16"], ["83939.5", "1", "0", "1"], ["83937.8", "0", "0", "0"], ["83925.3", "0", "0", "0"], ["83866.2", "0.14319661", "0", "3"], ["83813.1", "0.00001199", "0", "1"]], "ts": "1742577154000", "checksum": -354782880, "seqId": 49945047147, "prevSeqId": 49945047132}], "record_time": 1742577154.169857, "EXCHANGE": "OKX"}
{"arg": {"channel": "books", "instId": "BTC-USDT"}, "action": "update", "data": [{"asks": [["83966.2", "0.05983701", "0", "2"], ["83976.2", "0.23836595", "0", "1"], ["83977.7", "0", "0", "0"], ["83985.4", "0.00357305", "0", "1"], ["83988", "0", "0", "0"], ["83998.6", "0.01774536", "0", "1"], ["84003.8", "0.00002157", "0", "1"], ["84005.1", "0", "0", "0"], ["84018.5", "0.01132036", "0", "1"], ["84089.6", "0.11889794", "0", "1"], ["84131.2", "0", "0", "0"], ["84131.7", "0", "0", "0"]], "bids": [["83948.8", "0.51453202", "0", "13"], ["83948.1", "0.06419715", "0", "1"], ["83939.5", "0", "0", "0"], ["83938.1", "1.008", "0", "2"], ["83930.3", "0.0000105", "0", "1"], ["83919.9", "0.23836595", "0", "1"], ["83880.3", "0.00146351", "0", "2"], ["83880.1", "0", "0", "0"], ["83858", "0.00249918", "0", "2"], ["83855", "0.01517681", "0", "1"], ["83813.1", "0", "0", "0"]], "ts": "1742577154100", "checksum": 1730902273, "seqId": 49945047201, "prevSeqId": 49945047147}], "record_time": 1742577154.272076, "EXCHANGE": "OKX"}
{"arg": {"channel": "books", "instId": "BTC-USDT"}, "action": "update", "data": [{"asks": [["83948.9", "0.62065697", "0", "12"], ["83949.5", "0.08128338", "0", "2"], ["83951.4", "0.1191738", "0", "1"], ["83953.7", "0.0428883", "0", "1"], ["84131.1", "0", "0", "0"]], "bids": [["83948.8", "0.50286202", "0", "12"]], "ts": "1742577154200", "checksum": -166018399, "seqId": 49945047208, "prevSeqId": 49945047201}], "record_time": 1742577154.37059, "EXCHANGE": "OKX"}
{"arg": {"channel": "books", "instId": "BTC-USDT"}, "action": "update", "data": [{"asks": [["83981.6", "0.052", "0", "2"], ["83982.4", "0.26720726", "0", "6"], ["83983.2", "0.0004", "0", "1"], ["84130.5", "0", "0", "0"]], "bids": [["83948.8", "0.51886202", "0", "13"]], "ts": "1742577154300", "checksum": -1044014780, "seqId": 49945047214, "prevSeqId": 49945047208}], "record_time": 1742577154.470815, "EXCHANGE": "OKX"}
{"arg": {"channel": "books", "instId": "BTC-USDT"}, "action": "update", "data": [{"asks": [["83949.5", "0.0520357", "0", "1"], ["83951.4", "0", "0", "0"], ["83954", "0.09412661", "0", "2"], ["83954.1", "0.11916991", "0", "1"], ["83955.9", "0", "0", "0"], ["83971.8", "0.76274501", "0", "2"], ["83976.2", "0.23836687", "0", "1"], ["83981.6", "0.0528", "0", "4"], ["83982.4", "0.26680726", "0", "5"], ["83983.2", "0", "0", "0"], ["83989.6", "0.08", "0", "2"], ["83990.4", "0.03999999", "0", "1"], ["83991.2", "0.00001199", "0", "1"], ["84000.2", "1.09818373", "0", "1"], ["84130.5", "0.11889794", "0", "1"]], "bids": [["83948.1", "0", "0", "0"], ["83947.4", "0.04600003", "0", "1"], ["83940.8", "0.30878174", "0", "1"], ["83938.1", "0.008", "0", "1"], ["83937", "0.68817952", "0", "5"], ["83935.2", "1", "0", "1"], ["83934.2", "0", "0", "0"], ["83919.9", "0.23836687", "0", "1"], ["83919.8", "1.07530704", "0", "1"], ["83895", "0.20254799", "0", "4"]], "ts": "1742577154400", "checksum": 1912587880, "seqId": 49945047260, "prevSeqId": 49945047214}], "record_time": 1742577154.571254, "EXCHANGE": "OKX"}
{"arg": {"channel": "books", "instId": "BTC-USDT"}, "action": "update", "data": [{"asks": [["83985.4", "0", "0", "0"], ["84131.1", "0.00008649", "0", "2"]], "bids": [["83948.8", "0.51751202", "0", "12"], ["83936.9", "1.042", "0", "3"], ["83935.2", "0", "0", "0"], ["83930.9", "0.134801", "0", "1"]], "ts": "1742577154500", "checksum": 923090496, "seqId": 49945047269, "prevSeqId": 49945047260}], "record_time": 1742577154.671347, "EXCHANGE": "OKX"}
{"arg": {"channel": "books", "instId": "BTC-USDT"}, "action": "update", "data": [{"asks": [["83948.9", "0.66162697", "0", "13"], ["83949.5", "0.08128312", "0", "2"], ["83952", "0.16307295", "0", "2"], ["83954", "0.05837563", "0", "2"], ["83954.1", "0", "0", "0"], ["84131.2", "0.03", "0", "1"]], "bids": [["83948.8", "0.41181202", "0", "9"], ["83919.9", "0.23837001", "0", "1"]], "ts": "1742577154600", "checksum": 2130168558, "seqId": 49945047283, "prevSeqId": 49945047269}], "record_time": 1742577154.770897, "EXCHANGE": "OKX"}
{"arg": {"channel": "books", "instId": "BTC-USDT"}, "action": "update", "data": [{"asks": [["83970.3", "0.003573", "0", "1"], ["83976.2", "0", "0", "0"], ["83977.7", "0.23836565", "0", "1"], ["83985", "0.01190689", "0", "1"], ["83990.6", "0.000015", "0", "1"], ["84131.1", "0", "0", "0"], ["84131.2", "0", "0", "0"]], "bids": [["83936.9", "0.042", "0", "2"], ["83935.5", "1", "0", "1"], ["83813.5", "0", "0", "0"]], "ts": "1742577154700", "checksum": 2130168558, "seqId": 49945047292, "prevSeqId": 49945047283}], "record_time": 1742577154.870294, "EXCHANGE": "OKX"}
{"arg": {"channel": "books", "instId": "BTC-USDT"}, "action": "update", "data": [{"asks": [["83948.9", "0.66140188", "0", "13"]], "bids": [], "ts": "1742577154800", "checksum": -306110172, "seqId": 49945047316, "prevSeqId": 49945047292}], "record_time": 1742577154.970759, "EXCHANGE": "OKX"}
{"arg": {"channel": "books", "instId": "BTC-USDT"}, "action": "update", "data": [{"asks": [["83989.6", "0", "0", "0"], ["83990.4", "0.07999999", "0", "2"], ["83991.2", "0.04001198", "0", "2"], ["84131.1", "0.00008649", "0", "2"]], "bids": [["83936", "1.0439", "0", "2"], ["83935.5", "0", "0", "0"], ["83813.5", "0.00002031", "0", "1"]], "ts": "1742577154900", "checksum": -306110172, "seqId": 49945047338, "prevSeqId": 49945047316}], "record_time": 1742577155.070792, "EXCHANGE": "OKX"}
{"arg": {"channel": "books", "instId": "BTC-USDT"}, "action": "update", "data": [{"asks": [], "bids": [["83948.8", "0.41306202", "0", "10"]], "ts": "1742577155000", "checksum": 1682428639, "seqId": 49945047348, "prevSeqId": 49945047338}], "record_time": 1742577155.170384, "EXCHANGE": "OKX"}
{"arg": {"channel": "books", "instId": "BTC-USDT"}, "action": "update", "data": [{"asks": [["83983.9", "0.01190705", "0", "1"], ["83984.2", "0.01190701", "0", "1"], ["83989.8", "0", "0", "0"], ["83990.3", "0", "0", "0"]], "bids": [["83940.8", "0.54567702", "0", "2"], ["83938.7", "1", "0", "1"], ["83937", "0.46690525", "0", "4"], ["83936", "0.0439", "0", "1"], ["83813.5", "0", "0", "0"]], "ts": "1742577155100", "checksum": -931792998, "seqId": 49945047358, "prevSeqId": 49945047348}], "record_time": 1742577155.270429, "EXCHANGE": "OKX"}
{"arg": {"channel": "books", "instId": "BTC-USDT"}, "action": "update", "data": [{"asks": [["83959.2", "0.003573", "0", "1"], ["83970.3", "0", "0", "0"], ["84030.9", "0.34370513", "0", "2"]], "bids": [["83948.8", "0.42906202", "0", "11"], ["83940.1", "1.0119185", "0", "2"], ["83938.7", "0", "0", "0"], ["83866.2", "0.07165411", "0", "2"], ["83813.5", "0.00002031", "0", "1"]], "ts": "1742577155200", "checksum": 2135251900, "seqId": 49945047373, "prevSeqId": 49945047358}], "record_time": 1742577155.371671, "EXCHANGE": "OKX"}
{"arg": {"channel": "books", "instId": "BTC-USDT"}, "action": "update", "data": [{"asks": [["83959.2", "0", "0", "0"], ["83979.1", "0.003573", "0", "1"]], "bids": [["83940.1", "0.0119185", "0", "1"], ["83938.7", "1", "0", "1"], ["83922", "0.00001199", "0", "1"], ["83813.5", "0", "0", "0"]], "ts": "1742577155300", "checksum": 1377290724, "seqId": 49945047379, "prevSeqId": 49945047373}], "record_time": 1742577155.471765, "EXCHANGE": "OKX"}
{"arg": {"channel": "books", "instId": "BTC-USDT"}, "action": "update", "data": [{"asks": [["83976.2", "0.19463708", "0", "1"], ["84030.9", "0.41510746", "0", "3"], ["84131.1", "0", "0", "0"]], "bids": [["83923.9", "0.21237986", "0", "1"], ["83921.9", "0.23836413", "0", "1"], ["83920", "0.00037", "0", "2"], ["83919.9", "0", "0", "0"], ["83909.6", "0.1", "0", "2"], ["83908.8", "0.05", "0", "1"], ["83908", "0", "0", "0"], ["83866.2", "0.14319661", "0", "3"], ["83813.6", "0", "0", "0"]], "ts": "1742577155400", "checksum": 1377290724, "seqId": 49945047394, "prevSeqId": 49945047379}], "record_time": 1742577155.570451, "EXCHANGE": "OKX"}
{"arg": {"channel": "books", "instId": "BTC-USDT"}, "action": "update", "data": [{"asks": [["83948.9", "0.47452499", "0", "11"], ["83954", "0.10227563", "0", "3"], ["83971.8", "0.52885144", "0", "1"], ["83973.4", "0", "0", "0"], ["83977.7", "0", "0", "0"], ["83978.8", "0.25744211", "0", "2"], ["84131.1", "0.00008649", "0", "2"], ["84131.2", "0.03", "0", "1"]], "bids": [["83948.8", "0.63406202", "0", "13"], ["83948.1", "0.07799716", "0", "1"], ["83941.4", "1", "0", "1"], ["83938.7", "0", "0", "0"], ["83922.6", "0.23836211", "0", "1"], ["83921.9", "0", "0", "0"], ["83909.6", "0", "0", "0"], ["83908.8", "0.1", "0", "2"], ["83908", "0.05", "0", "1"], ["83813.8", "0", "0", "0"]], "ts": "1742577155500", "checksum": -437928935, "seqId": 49945047429, "prevSeqId": 49945047394}], "record_time": 1742577155.677327, "EXCHANGE": "OKX"}
{"arg": {"channel": "books", "instId": "BTC-USDT"}, "action": "update", "data": [{"asks": [["83948.9", "0.5096722", "0", "12"], ["83981.6", "0.052", "0", "2"], ["83982.4", "0.26720726", "0", "6"], ["83983.2", "0.0004", "0", "1"], ["84131.2", "0", "0", "0"]], "bids": [["83945.1", "0.34095433", "0", "2"], ["83940.8", "0.23067074", "0", "1"], ["83937.2", "0", "0", "0"], ["83933.1", "0.19060074", "0", "2"], ["83928", "0.2025", "0", "1"], ["83915.2", "0.38650634", "0", "1"], ["83914.4", "0.0808", "0", "4"], ["83913.6", "0.04039949", "0", "2"], ["83912.6", "0", "0", "0"], ["83911.4", "0.5776526", "0", "1"], ["83870.7", "0", "0", "0"], ["83869.8", "0.45410321", "0", "2"], ["83869.5", "0.58226341", "0", "1"], ["83851.4", "0.01852965", "0", "1"], ["83813.8", "0.11936928", "0", "1"]], "ts": "1742577155600", "checksum": 1234586461, "seqId": 49945047459, "prevSeqId": 49945047429}], "record_time": 1742577155.772634, "EXCHANGE": "OKX"}
{"arg": {"channel": "books", "instId": "BTC-USDT"}, "action": "update", "data": [{"asks": [["83959.3", "0", "0", "0"], ["84131.2", "0.03", "0", "1"]], "bids": [["83915.2", "0.46650634", "0", "3"], ["83914.4", "0.0408", "0", "3"], ["83913.6", "0.00039949", "0", "1"]], "ts": "1742577155700", "checksum": 851074513, "seqId": 49945047469, "prevSeqId": 49945047459}], "record_time": 1742577155.871552, "EXCHANGE": "OKX"}
{"arg": {"channel": "books", "instId": "BTC-USDT"}, "action": "update", "data": [{"asks": [["83948.9", "0.5571722", "0", "13"], ["83982", "1", "0", "1"], ["83985", "0.21190689", "0", "2"], ["84131.2", "0", "0", "0"]], "bids": [["83939.7", "0.17868", "0", "1"], ["83813.8", "0", "0", "0"]], "ts": "1742577155800", "checksum": 1290795735, "seqId": 49945047475, "prevSeqId": 49945047469}], "record_time": 1742577155.97095, "EXCHANGE": "OKX"}
{"arg": {"channel": "books", "instId": "BTC-USDT"}, "action": "update", "data": [{"asks": [["83948.9", "0.43461595", "0", "11"], ["83949.5", "0.0520357", "0", "1"], ["83952", "0.0439", "0", "1"], ["83953.9", "0.10728933", "0", "1"], ["83954", "0.16308066", "0", "3"], ["83973.1", "1", "0", "1"], ["83977.7", "0.23836465", "0", "1"], ["83978.7", "0.01774536", "0", "1"], ["83978.8", "0.01908", "0", "1"], ["83982", "0", "0", "0"], ["83985", "0.01190689", "0", "1"], ["83998.6", "0", "0", "0"], ["84130.5", "0", "0", "0"], ["84131.1", "0", "0", "0"]], "bids": [["83948.8", "0.63156202", "0", "12"], ["83945.1", "0.0424511", "0", "1"], ["83941.4", "0", "0", "0"], ["83940.8", "0.5554409", "0", "2"], ["83937.4", "1", "0", "1"], ["83932.8", "0.21918445", "0", "2"], ["83930.5", "0.17868", "0", "1"], ["83922.6", "0", "0", "0"], ["83919.9", "0.23836465", "0", "1"], ["83851.4", "0", "0", "0"]], "ts": "1742577155900", "checksum": -1985396501, "seqId": 49945047514, "prevSeqId": 49945047475}], "record_time": 1742577156.070745, "EXCHANGE": "OKX"}
{"arg": {"channel": "books", "instId": "BTC-USDT"}, "action": "update", "data": [{"asks": [["83948.9", "0.38172499", "0", "10"]], "bids": [["83948.8", "0.42906202", "0", "11"], ["83940.8", "0.23067074", "0", "1"], ["83937.4", "0", "0", "0"], ["83937", "0.68817952", "0", "5"], ["83936.1", "1", "0", "1"], ["83933.1", "0.01192074", "0", "1"]], "ts": "1742577156000", "checksum": 1814543686, "seqId": 49945047523, "prevSeqId": 49945047514}], "record_time": 1742577156.171204, "EXCHANGE": "OKX"}
{"arg": {"channel": "books", "instId": "BTC-USDT"}, "action": "update", "data": [{"asks": [["83949.5", "0.08128307", "0", "2"], ["83952.1", "0.11917276", "0", "1"], ["83953.9", "0.07153828", "0", "1"], ["83954", "0.0439105", "0", "2"], ["83959.3", "0.00356391", "0", "1"], ["83976.2", "0.23836587", "0", "1"], ["83977.7", "0", "0", "0"], ["84130.1", "0", "0", "0"]], "bids": [["83940.8", "0.5554409", "0", "2"], ["83938.1", "1.008", "0", "2"], ["83937", "0.46690525", "0", "4"], ["83936.1", "0", "0", "0"], ["83880.4", "0.00218682", "0", "1"], ["83880.2", "0", "0", "0"], ["83857.1", "0.00091322", "0", "4"], ["83813.8", "0.11936928", "0", "1"]], "ts": "1742577156100", "checksum": -117414576, "seqId": 49945047546, "prevSeqId": 49945047523}], "record_time": 1742577156.270852, "EXCHANGE": "OKX"}
{"arg": {"channel": "books", "instId": "BTC-USDT"}, "action": "update", "data": [{"asks": [["83978.7", "0", "0", "0"], ["83998.6", "0.01774536", "0", "1"]], "bids": [["83880.5", "0.00145276", "0", "1"], ["83880.3", "0.00001072", "0", "1"], ["83813.8", "0", "0", "0"]], "ts": "1742577156200", "checksum": -117414576, "seqId": 49945047556, "prevSeqId": 49945047546}], "record_time": 1742577156.372114, "EXCHANGE": "OKX"}
{"arg": {"channel": "books", "instId": "BTC-USDT"}, "action": "update", "data": [{"asks": [["84076.1", "0", "0", "0"], ["84082.8", "0.183512", "0", "1"]], "bids": [["83940.8", "0.23067074", "0", "1"], ["83938.1", "0.008", "0", "1"], ["83937", "0.68817952", "0", "5"], ["83936.7", "1", "0", "1"], ["83814.1", "0", "0", "0"]], "ts": "1742577156300", "checksum": -152711316, "seqId": 49945047575, "prevSeqId": 49945047556}], "record_time": 1742577156.470951, "EXCHANGE": "OKX"}
{"arg": {"channel": "books", "instId": "BTC-USDT"}, "action": "update", "data": [{"asks": [["83971.8", "0.76274501", "0", "2"], ["83976.2", "0", "0", "0"], ["83977.7", "0.23836353", "0", "1"]], "bids": [["83921.9", "0.23836353", "0", "1"], ["83919.9", "0", "0", "0"], ["83894.6", "0.2025", "0", "1"], ["83890.7", "0.01191258", "0", "2"]], "ts": "1742577156400", "checksum": -152711316, "seqId": 49945047585, "prevSeqId": 49945047575}], "record_time": 1742577156.570806, "EXCHANGE": "OKX"}
{"arg": {"channel": "books", "instId": "BTC-USDT"}, "action": "update", "data": [{"asks": [["83971.8", "0.52885144", "0", "1"], ["83973.1", "0", "0", "0"], ["83976.2", "0.23836446", "0", "1"], ["83977.7", "0", "0", "0"], ["84130.1", "0.00001199", "0", "1"]], "bids": [["83940.8", "0.5554409", "0", "2"], ["83938.8", "1", "0", "1"], ["83937", "0.46690525", "0", "4"], ["83936.7", "0", "0", "0"], ["83921.9", "0", "0", "0"], ["83921.6", "0.23836462", "0", "1"], ["83907.4", "0.65307809", "0", "3"], ["83903.2", "0.53532771", "0", "2"], ["83899", "0.00577732", "0", "1"], ["83814.4", "0", "0", "0"]], "ts": "1742577156500", "checksum": 587112711, "seqId": 49945047600, "prevSeqId": 49945047585}], "record_time": 1742577156.67286, "EXCHANGE": "OKX"}
{"arg": {"channel": "books", "instId": "BTC-USDT"}, "action": "update", "data": [{"asks": [["83948.9", "0.44437921", "0", "11"], ["83952.1", "0", "0", "0"], ["83955.5", "0", "0", "0"], ["83957.8", "0.01021", "0", "1"], ["83959.6", "0", "0", "0"], ["83964.1", "0.03062", "0", "1"], ["83976.2", "0", "0", "0"], ["83977.7", "0.23836292", "0", "1"], ["83981.6", "0.0528", "0", "4"], ["83982.4", "0.26680726", "0", "5"], ["83983.2", "0", "0", "0"], ["83987.6", "0", "0", "0"], ["83991.8", "0", "0", "0"], ["83996", "0", "0", "0"], ["84130.5", "0.11889794", "0", "1"], ["84131.1", "0.00008649", "0", "2"], ["84131.2", "0.03", "0", "1"], ["84131.7", "0.14263366", "0", "2"], ["84132.5", "0.17898725", "0", "1"]], "bids": [["83948.8", "0.84565202", "0", "14"], ["83945.1", "0.34095433", "0", "2"], ["83944.1", "0.01389", "0", "1"], ["83941.8", "1.00001199", "0", "2"], ["83940.8", "0.23067074", "0", "1"], ["83938.8", "0", "0", "0"], ["83937.8", "0.04169", "0", "1"], ["83932.9", "0", "0", "0"], ["83924.4", "0.11374712", "0", "2"], ["83922.6", "0.23836292", "0", "1"], ["83921.6", "0", "0", "0"], ["83858", "0.00036", "0", "1"], ["83855", "0", "0", "0"], ["83814.4", "0.00005519", "0", "1"]], "ts": "1742577156800", "checksum": -1595479119, "seqId": 49945047650, "prevSeqId": 49945047600}], "record_time": 1742577156.970781, "EXCHANGE": "OKX"}
{"arg": {"channel": "books", "instId": "BTC-USDT"}, "action": "update", "data": [{"asks": [["83949.5", "0.0520357", "0", "1"], ["83954", "0.16308067", "0", "3"], ["83959.3", "0", "0", "0"], ["83977.7", "0.23836237", "0", "1"], ["83981", "1", "0", "1"], ["83981.6", "0.052", "0", "2"], ["83982.4", "0.26720726", "0", "6"], ["83983.2", "0.0004", "0", "1"], ["83985", "0.21190689", "0", "2"], ["84000.7", "0.54146464", "0", "2"], ["84004.9", "0.00577732", "0", "1"], ["84009.1", "0.00577732", "0", "1"], ["84131.2", "0", "0", "0"], ["84131.7", "0", "0", "0"], ["84132.5", "0", "0", "0"]], "bids": [["83922.6", "0", "0", "0"], ["83921.9", "0.23836237", "0", "1"], ["83912.5", "0.00577732", "0", "1"], ["83907.4", "0.64152345", "0", "2"], ["83903.2", "0.52955039", "0", "1"], ["83899", "0", "0", "0"]], "ts": "1742577156900", "checksum": -202227352, "seqId": 49945047676, "prevSeqId": 49945047650}], "record_time": 1742577157.071309, "EXCHANGE": "OKX"}
{"arg": {"channel": "books", "instId": "BTC-USDT"}, "action": "update", "data": [{"asks": [["83948.9", "0.38150858", "0", "10"], ["83973.1", "1", "0", "1"], ["83976.2", "0.23836372", "0", "1"], ["83977.7", "0", "0", "0"], ["83978.8", "0.03682536", "0", "2"], ["83981.6", "0.0528", "0", "4"], ["83982.4", "0.26680726", "0", "5"], ["83983.2", "0", "0", "0"], ["83998.6", "0", "0", "0"], ["84131.2", "0.03", "0", "1"]], "bids": [["83948.8", "0.44327824", "0", "13"], ["83945.1", "0.0424511", "0", "1"], ["83941.8", "0.00001199", "0", "1"], ["83940.8", "0.5679479", "0", "2"], ["83938.1", "1.008", "0", "2"], ["83937.7", "0", "0", "0"], ["83930.5", "0", "0", "0"], ["83921.9", "0", "0", "0"], ["83919.9", "0.23836521", "0", "1"], ["83856.1", "0.01517603", "0", "1"], ["83814.1", "0.00003395", "0", "1"]], "ts": "1742577157000", "checksum": 1688848766, "seqId": 49945047705, "prevSeqId": 49945047676}], "record_time": 1742577157.171263, "EXCHANGE": "OKX"}
{"arg": {"channel": "books", "instId": "BTC-USDT"}, "action": "update", "data": [{"asks": [["83959.7", "0.124162", "0", "2"], ["83969.7", "0.005", "0", "1"]], "bids": [["83944", "0.0439", "0", "1"], ["83940.8", "0.23067074", "0", "1"], ["83940.2", "0.35736", "0", "1"], ["83938.1", "0.008", "0", "1"], ["83937", "0.67567252", "0", "5"], ["83936.4", "1.2185", "0", "3"], ["83933.9", "0.00356928", "0", "1"], ["83933.1", "0.19060074", "0", "2"], ["83921.6", "0.23836543", "0", "1"], ["83919.9", "0", "0", "0"], ["83919", "1.2", "0", "2"], ["83913.4", "0.01190701", "0", "1"], ["83859.1", "0.00215409", "0", "2"], ["83814.4", "0", "0", "0"], ["83814.1", "0", "0", "0"]], "ts": "1742577157100", "checksum": -1098936396, "seqId": 49945047729, "prevSeqId": 49945047705}], "record_time": 1742577157.27032, "EXCHANGE": "OKX"}
{"arg": {"channel": "books", "instId": "BTC-USDT"}, "action": "update", "data": [{"asks": [["83976.2", "0.23836519", "0", "1"], ["83979.1", "0", "0", "0"], ["83981.6", "0.052", "0", "2"], ["83982.4", "0.26720726", "0", "6"], ["83983.2", "0.0004", "0", "1"], ["83998.2", "0.003573", "0", "1"], ["84131.2", "0", "0", "0"]], "bids": [["83940.8", "0.5679479", "0", "2"], ["83938.2", "1.06589", "0", "4"], ["83937", "0.46690525", "0", "4"], ["83936.4", "0.2185", "0", "2"], ["83921.6", "0", "0", "0"], ["83919.9", "0.23836519", "0", "1"]], "ts": "1742577157200", "checksum": 2061746919, "seqId": 49945047753, "prevSeqId": 49945047729}], "record_time": 1742577157.370674, "EXCHANGE": "OKX"}
{"arg": {"channel": "books", "instId": "BTC-USDT"}, "action": "update", "data": [{"asks": [["83948.9", "0.366925", "0", "10"], ["83949.5", "0.08128302", "0", "2"], ["83952.2", "0.11917261", "0", "1"], ["83954", "0.0439105", "0", "2"], ["83955", "0.01021", "0", "1"], ["83957.8", "0", "0", "0"], ["83959.3", "0.00363006", "0", "1"], ["83970", "0.258073", "0", "4"], ["83976.2", "0", "0", "0"], ["83977.7", "0.23836504", "0", "1"], ["83998.2", "0", "0", "0"], ["84131.1", "0", "0", "0"]], "bids": [["83948.8", "0.25580134", "0", "8"], ["83944.1", "0", "0", "0"], ["83941.3", "0.01389", "0", "1"], ["83937.7", "0.35736", "0", "1"], ["83919.9", "0.23836514", "0", "1"], ["83814.9", "0", "0", "0"]], "ts": "1742577157300", "checksum": 743214670, "seqId": 49945047780, "prevSeqId": 49945047753}], "record_time": 1742577157.471257, "EXCHANGE": "OKX"}
{"arg": {"channel": "books", "instId": "BTC-USDT"}, "action": "update", "data": [{"asks": [], "bids": [["83948.1", "0", "0", "0"], ["83948", "0.0439", "0", "1"], ["83947.5", "0.02907361", "0", "1"], ["83940.8", "0.3751559", "0", "1"], ["83938.2", "0.06589", "0", "3"], ["83937", "0.72777652", "0", "5"], ["83935.5", "1", "0", "1"], ["83930.5", "0.17868", "0", "1"], ["83815.1", "0", "0", "0"], ["83815", "0", "0", "0"]], "ts": "1742577157400", "checksum": -1459727617, "seqId": 49945047803, "prevSeqId": 49945047780}], "record_time": 1742577157.570129, "EXCHANGE": "OKX"}
{"arg": {"channel": "books", "instId": "BTC-USDT"}, "action": "update", "data": [{"asks": [["83942.1", "0.91922245", "0", "12"], ["83944", "0.0439", "0", "1"], ["83945.6", "0.1", "0", "1"], ["83945.8", "0.0428883", "0", "1"], ["83946", "0.90281782", "0", "6"], ["83946.1", "1.35823332", "0", "13"], ["83947", "0.052", "0", "2"], ["83947.5", "0.2044536", "0", "5"], ["83948", "0.0439", "0", "1"], ["83948.3", "0.00112002", "0", "1"], ["83948.9", "0.30299387", "0", "6"], ["83949.5", "0", "0", "0"], ["83950.3", "0.05297225", "0", "1"], ["83950.4", "0.00144764", "0", "1"], ["83951.6", "0.0899221", "0", "2"], ["83952.2", "0", "0", "0"], ["83953.7", "0", "0", "0"], ["83954", "0.0439", "0", "1"], ["83954.2", "0.003573", "0", "1"], ["83955", "0", "0", "0"], ["83955.9", "0.03063", "0", "1"], ["83956.6", "0", "0", "0"], ["83956.9", "0", "0", "0"], ["83957", "0.000015", "0", "1"], ["83957.8", "0.02383893", "0", "1"], ["83958.4", "0.18279939", "0", "1"], ["83959.4", "0", "0", "0"], ["83959.5", "0.19090424", "0", "2"], ["83960.3", "0.0102", "0", "1"], ["83963.5", "0.04", "0", "1"], ["83964.1", "0", "0", "0"], ["83964.5", "0.11889794", "0", "1"], ["83964.9", "0.11915459", "0", "1"], ["83965", "0.03", "0", "1"], ["83965.1", "0.08991011", "0", "1"], ["83966.2", "0.036", "0", "1"], ["83966.7", "0.066", "0", "2"], ["83967.4", "1", "0", "1"], ["83969.1", "0.00001501", "0", "1"], ["83970", "0.2545", "0", "3"], ["83971.1", "0.25613309", "0", "2"], ["83972.4", "0", "0", "0"], ["83972.8", "0.12", "0", "4"], ["83973.1", "0", "0", "0"], ["83973.7", "0.0119085", "0", "1"], ["83977.7", "0", "0", "0"], ["83977.8", "0", "0", "0"], ["83978.8", "0.01908", "0", "1"], ["83981", "0", "0", "0"], ["83981.6", "0.0528", "0", "4"], ["83982.4", "0.26680726", "0", "5"], ["83983.2", "0", "0", "0"], ["83985", "0.01190689", "0", "1"], ["83988.8", "0", "0", "0"], ["83989.9", "0.00427856", "0", "1"], ["83993.8", "0", "0", "0"], ["83999.3", "0.02283169", "0", "1"], ["84016", "0.0113329", "0", "2"], ["84017.9", "0.15693114", "0", "1"], ["84018", "0", "0", "0"], ["84018.5", "0", "0", "0"], ["84026.1", "0", "0", "0"], ["84125.3", "0", "0", "0"], ["84126.2", "0", "0", "0"], ["84126.6", "0", "0", "0"], ["84127.5", "0", "0", "0"], ["84127.7", "0", "0", "0"], ["84129.9", "0", "0", "0"], ["84130.1", "0", "0", "0"], ["84130.5", "0", "0", "0"]], "bids": [["83948.8", "0", "0", "0"], ["83948.3", "0", "0", "0"], ["83948", "0", "0", "0"], ["83947.5", "0", "0", "0"], ["83947.4", "0", "0", "0"], ["83946.9", "0", "0", "0"], ["83946.7", "0", "0", "0"], ["83946.6", "0", "0", "0"], ["83946", "0", "0", "0"], ["83945.1", "0", "0", "0"], ["83944", "0", "0", "0"], ["83943.1", "0", "0", "0"], ["83943", "0", "0", "0"], ["83942.9", "0", "0", "0"], ["83942.8", "0", "0", "0"], ["83942", "0.0963", "0", "3"], ["83941.9", "0", "0", "0"], ["83941.8", "0", "0", "0"], ["83941.3", "0", "0", "0"], ["83940.8", "0", "0", "0"], ["83940.2", "0", "0", "0"], ["83940.1", "0", "0", "0"], ["83939.7", "0.00056094", "0", "1"], ["83939.2", "0.04306223", "0", "1"], ["83939", "0", "0", "0"], ["83938.2", "0.02989", "0", "2"], ["83938.1", "0", "0", "0"], ["83937.8", "0", "0", "0"], ["83937.7", "0", "0", "0"], ["83937.6", "0.2025", "0", "1"], ["83937", "0.20054769", "0", "2"], ["83936.9", "0.002", "0", "1"], ["83936.5", "0.36197351", "0", "2"], ["83936.4", "0.016", "0", "1"], ["83935.5", "0", "0", "0"], ["83933.9", "0", "0", "0"], ["83933.6", "0", "0", "0"], ["83933.5", "0", "0", "0"], ["83933.1", "0.01192074", "0", "1"], ["83932.8", "0.16627366", "0", "1"], ["83932.7", "0.01389", "0", "1"], ["83932.6", "0", "0", "0"], ["83931.2", "0.01191978", "0", "1"], ["83930.9", "0", "0", "0"], ["83930.6", "0.0428883", "0", "1"], ["83930.5", "0", "0", "0"], ["83930.3", "0", "0", "0"], ["83928.8", "0.00774294", "0", "1"], ["83928.6", "0.61576578", "0", "2"], ["83927.6", "0.03992302", "0", "1"], ["83927.5", "1", "0", "1"], ["83926.3", "0.47619784", "0", "3"], ["83925.3", "0.02859924", "0", "1"], ["83924.4", "0.02383701", "0", "1"], ["83921.5", "0", "0", "0"], ["83920.9", "0.00357", "0", "1"], ["83919.9", "0", "0", "0"], ["83919.8", "0.77883497", "0", "1"], ["83919", "0", "0", "0"], ["83917.5", "0.063842", "0", "2"], ["83917.2", "0", "0", "0"], ["83916.7", "0", "0", "0"], ["83916.4", "0.0119085", "0", "1"], ["83915.2", "0.38650634", "0", "1"], ["83915.1", "0", "0", "0"], ["83914.4", "0", "0", "0"], ["83913.6", "0", "0", "0"], ["83912.8", "0", "0", "0"], ["83912.5", "0.01768445", "0", "2"], ["83912.1", "0.2383882", "0", "1"], ["83912", "0.080012", "0", "3"], ["83911.2", "0.04079951", "0", "3"], ["83910.4", "0.00039951", "0", "1"], ["83909.6", "0.026", "0", "2"], ["83908.8", "0.013", "0", "1"], ["83908", "0", "0", "0"], ["83907.4", "0.45027103", "0", "1"], ["83905.6", "0.21889794", "0", "3"], ["83904.9", "0", "0", "0"], ["83904.8", "0.22898725", "0", "2"], ["83902.1", "0.000012", "0", "1"], ["83899.3", "0.01835514", "0", "1"], ["83884.9", "0.03", "0", "1"], ["83860.1", "0", "0", "0"], ["83857.1", "0.22482158", "0", "5"], ["83830.6", "0", "0", "0"], ["83828", "0.18935069", "0", "2"], ["83815.1", "0.00589964", "0", "1"], ["83815", "0.35776874", "0", "1"], ["83814.9", "0.0073937", "0", "2"], ["83814.4", "0.00005519", "0", "1"], ["83814.1", "0.00003395", "0", "1"], ["83813.8", "0.11936928", "0", "1"], ["83813.6", "0.03579964", "0", "2"], ["83813.5", "0.00002031", "0", "1"], ["83813.1", "0.00001199", "0", "1"], ["83812.8", "0.01493332", "0", "1"], ["83812.6", "0.00579923", "0", "1"], ["83812.5", "0.00667459", "0", "3"], ["83812.4", "0.05367661", "0", "2"], ["83812.1", "1.72263", "0", "1"], ["83812", "0.00589921", "0", "1"], ["83811.9", "0.0010552", "0", "1"], ["83811.3", "0.00074812", "0", "1"], ["83810.1", "0.00001655", "0", "1"], ["83810", "0.22033855", "0", "2"], ["83809.8", "0.00013882", "0", "1"], ["83809.7", "0.00001075", "0", "1"], ["83809.4", "0.00005977", "0", "1"], ["83809.2", "0.2025", "0", "1"], ["83808.7", "0.000015", "0", "1"], ["83808.2", "0.00001199", "0", "1"], ["83808", "0.00015274", "0", "2"], ["83807.9", "0.00001018", "0", "1"], ["83807.8", "0.00589964", "0", "1"], ["83807.7", "0.00579964", "0", "1"]], "ts": "1742577157500", "checksum": -1045813107, "seqId": 49945048507, "prevSeqId": 49945047803}], "record_time": 1742577157.671376, "EXCHANGE": "OKX"}
{"arg": {"channel": "books", "instId": "BTC-USDT"}, "action": "update", "data": [{"asks": [["83942.1", "0.71329245", "0", "9"], ["83943", "0.01191948", "0", "1"], ["83943.9", "0.01317", "0", "1"], ["83945.9", "0.1264491", "0", "1"], ["83946", "0.01153238", "0", "1"], ["83946.1", "0", "0", "0"], ["83947.5", "0.06221", "0", "3"], ["83947.6", "0.11917923", "0", "1"], ["83948.3", "0.00886345", "0", "2"], ["83949.9", "0.03559721", "0", "1"], ["83950.3", "0", "0", "0"], ["83951.6", "0.00001199", "0", "1"], ["83963.2", "0", "0", "0"], ["83966.7", "0.126", "0", "4"], ["83967.4", "0", "0", "0"], ["83969", "0.23266725", "0", "2"], ["83969.5", "0.03", "0", "1"], ["83971.1", "0.25612376", "0", "2"], ["83972.8", "0.06", "0", "2"], ["83980", "0.0119076", "0", "1"], ["83981.7", "0", "0", "0"], ["83983.2", "0.06188326", "0", "1"], ["83986.4", "0.07999999", "0", "2"], ["83987.2", "0.03999999", "0", "1"], ["83990.4", "0", "0", "0"], ["83990.5", "0.40103317", "0", "2"], ["83991.2", "0.00001199", "0", "1"], ["83993.4", "0", "0", "0"], ["83996.9", "0.01968784", "0", "2"], ["84006.4", "0", "0", "0"], ["84012.5", "0.01132106", "0", "1"], ["84014.5", "0", "0", "0"], ["84016", "0.00001198", "0", "1"], ["84018.7", "0.04499", "0", "1"], ["84125", "0", "0", "0"], ["84125.1", "0", "0", "0"]], "bids": [["83942", "0.41622473", "0", "7"], ["83941.5", "0.11918772", "0", "1"], ["83939.2", "0.14520472", "0", "1"], ["83937.7", "0.17898725", "0", "1"], ["83936.8", "0.00001199", "0", "1"], ["83933.4", "0.01191948", "0", "1"], ["83932.8", "0.43203117", "0", "2"], ["83932.7", "0", "0", "0"], ["83932.5", "0.08", "0", "2"], ["83931.2", "0", "0", "0"], ["83931", "1", "0", "1"], ["83930.3", "0.00355569", "0", "1"], ["83930.2", "0.35739", "0", "1"], ["83929.6", "0.17869", "0", "1"], ["83928.6", "0.35320512", "0", "1"], ["83928.3", "0.033", "0", "1"], ["83927.8", "0.00006", "0", "1"], ["83927.5", "0", "0", "0"], ["83927", "0.134795", "0", "1"], ["83919.5", "0.00714971", "0", "1"], ["83917.5", "0.05193", "0", "1"], ["83917", "0.23875039", "0", "3"], ["83916.7", "0.0115549", "0", "1"], ["83915.9", "0.06229737", "0", "1"], ["83915.7", "0", "0", "0"], ["83914", "0.01190694", "0", "1"], ["83912.1", "0", "0", "0"], ["83912", "0.000012", "0", "1"], ["83911.2", "0.08", "0", "2"], ["83910.4", "0.04079951", "0", "3"], ["83909.6", "0.00039951", "0", "1"], ["83909.3", "0.0569566", "0", "2"], ["83908.8", "0.026", "0", "2"], ["83908.3", "0.00577745", "0", "1"], ["83908", "0.013", "0", "1"], ["83905.6", "0.11889794", "0", "1"], ["83904.8", "0.27898725", "0", "3"], ["83904", "0.05", "0", "1"], ["83899.3", "0", "0", "0"], ["83896.4", "0.01835522", "0", "1"], ["83882.1", "0", "0", "0"], ["83880.5", "0", "0", "0"], ["83875.3", "0.00102223", "0", "2"], ["83873.8", "0.00145297", "0", "1"], ["83860.1", "0.00018342", "0", "1"], ["83828", "0.00579923", "0", "1"], ["83824.3", "0.18355223", "0", "1"], ["83811.3", "0", "0", "0"], ["83810.1", "0", "0", "0"], ["83810", "0", "0", "0"], ["83809.8", "0", "0", "0"], ["83809.7", "0", "0", "0"], ["83809.4", "0", "0", "0"], ["83809.2", "0", "0", "0"], ["83808.7", "0", "0", "0"], ["83808.2", "0", "0", "0"], ["83808", "0", "0", "0"], ["83807.9", "0", "0", "0"], ["83807.8", "0", "0", "0"], ["83807.7", "0", "0", "0"]], "ts": "1742577157600", "checksum": -584564406, "seqId": 49945048699, "prevSeqId": 49945048507}], "record_time": 1742577157.771264, "EXCHANGE": "OKX"}
{"arg": {"channel": "books", "instId": "BTC-USDT"}, "action": "update", "data": [{"asks": [["83945.1", "0.01021", "0", "1"], ["83947.5", "0.052", "0", "2"], ["83948.3", "0.00950779", "0", "3"], ["83948.9", "0.302357", "0", "5"], ["83949.9", "0.14742862", "0", "2"], ["83951.4", "0.03063", "0", "1"], ["83953.8", "0.35697351", "0", "1"], ["83955.9", "0", "0", "0"], ["83963.3", "0.03", "0", "1"], ["83966.7", "0.156", "0", "5"], ["83968.3", "0.23838372", "0", "1"], ["83969.5", "0", "0", "0"], ["83971.1", "0", "0", "0"], ["83986.1", "0.00513448", "0", "1"], ["83986.6", "0.15956073", "0", "2"], ["83989.9", "0", "0", "0"], ["83998.6", "0.01774536", "0", "1"], ["84007.9", "0.82411", "0", "1"], ["84122.2", "0", "0", "0"], ["84122.3", "0", "0", "0"], ["84123.6", "0", "0", "0"], ["84123.7", "0", "0", "0"]], "bids": [["83942", "0.14825631", "0", "5"], ["83939.2", "0.10381223", "0", "1"], ["83937.7", "0", "0", "0"], ["83937", "0.08831399", "0", "2"], ["83936.5", "0.005", "0", "1"], ["83931.6", "0.069", "0", "2"], ["83931", "0", "0", "0"], ["83930.3", "0", "0", "0"], ["83929.3", "1", "0", "1"], ["83928.3", "0.069", "0", "2"], ["83927", "0.176495", "0", "2"], ["83923", "0.17869", "0", "1"], ["83922.3", "0.005571", "0", "1"], ["83917", "0.00037199", "0", "2"], ["83916", "0.11256978", "0", "2"], ["83915.2", "0", "0", "0"], ["83914.3", "0.01190689", "0", "1"], ["83914.1", "0", "0", "0"], ["83911.9", "0.23838372", "0", "1"], ["83895", "0.44413129", "0", "3"], ["83894.8", "0.825221", "0", "1"], ["83812", "0", "0", "0"], ["83811.9", "0", "0", "0"]], "ts": "1742577157700", "checksum": -1732270879, "seqId": 49945048766, "prevSeqId": 49945048699}], "record_time": 1742577157.870446, "EXCHANGE": "OKX"}
{"arg": {"channel": "books", "instId": "BTC-USDT"}, "action": "update", "data": [{"asks": [["83942.1", "0.71301178", "0", "9"], ["83945.7", "0.19001015", "0", "1"], ["83945.8", "0.16207001", "0", "2"], ["83945.9", "0", "0", "0"], ["83947.6", "0", "0", "0"], ["83964.8", "0", "0", "0"], ["83972.8", "0", "0", "0"], ["84122.2", "0.17898725", "0", "1"], ["84122.3", "0.08764", "0", "1"], ["84123.6", "0.00126715", "0", "1"]], "bids": [["83942", "0.23485631", "0", "6"], ["83939.2", "0", "0", "0"], ["83937.6", "0", "0", "0"], ["83923", "0", "0", "0"], ["83922.3", "0", "0", "0"], ["83812", "0.00589921", "0", "1"], ["83811.9", "0.0010552", "0", "1"], ["83811.3", "0.00074812", "0", "1"], ["83810.1", "0.00001655", "0", "1"]], "ts": "1742577157800", "checksum": -262450582, "seqId": 49945048780, "prevSeqId": 49945048766}], "record_time": 1742577157.975085, "EXCHANGE": "OKX"}
{"arg": {"channel": "books", "instId": "BTC-USDT"}, "action": "update", "data": [{"asks": [["83942.1", "0.31602663", "0", "3"], ["83945.1", "0", "0", "0"], ["83945.6", "0", "0", "0"], ["83945.7", "0.09027032", "0", "2"], ["83945.8", "0.0428883", "0", "1"], ["83947", "0", "0", "0"], ["83947.5", "0", "0", "0"], ["83948.9", "0.083857", "0", "3"], ["83949.6", "0.11917628", "0", "1"], ["83950.8", "0.01021", "0", "1"], ["83951.4", "0", "0", "0"], ["83952.3", "0.005", "0", "1"], ["83957.1", "0.03062", "0", "1"], ["83962.4", "0.005", "0", "1"], ["83965.1", "0", "0", "0"], ["83968.3", "0", "0", "0"], ["83968.8", "0.24203406", "0", "2"], ["84012.5", "0", "0", "0"], ["84016", "0.01133304", "0", "2"], ["84123.7", "0.00005514", "0", "1"], ["84125", "0.00009264", "0", "1"], ["84125.1", "0.00015069", "0", "2"]], "bids": [["83942", "0.83484801", "0", "11"], ["83940.2", "0.005", "0", "1"], ["83939.2", "0.20385046", "0", "1"], ["83937.1", "0.53596076", "0", "2"], ["83937", "0.38014335", "0", "3"], ["83935.9", "1", "0", "1"], ["83935.2", "0.01389", "0", "1"], ["83930.1", "0.005", "0", "1"], ["83929.3", "0", "0", "0"], ["83927.9", "0.00359716", "0", "1"], ["83920.5", "0.17869", "0", "1"], ["83919.2", "0.004935", "0", "1"], ["83914.3", "0.25028729", "0", "2"], ["83911.9", "0", "0", "0"], ["83898.2", "0.01835552", "0", "1"], ["83896.4", "0", "0", "0"], ["83826.8", "0.18355529", "0", "1"], ["83824.3", "0", "0", "0"], ["83812.5", "0", "0", "0"], ["83812.4", "0", "0", "0"], ["83812.1", "0", "0", "0"], ["83812", "0", "0", "0"], ["83811.9", "0", "0", "0"], ["83811.3", "0", "0", "0"], ["83810.1", "0", "0", "0"]], "ts": "1742577157900", "checksum": 2080420060, "seqId": 49945048853, "prevSeqId": 49945048780}], "record_time": 1742577158.071062, "EXCHANGE": "OKX"}
{"arg": {"channel": "books", "instId": "BTC-USDT"}, "action": "update", "data": [{"asks": [["83942.1", "0.08627", "0", "1"], ["83943.9", "0", "0", "0"], ["83944", "0", "0", "0"], ["83944.8", "0.0000999", "0", "1"], ["83945.8", "0", "0", "0"], ["83948.9", "0.0475", "0", "1"], ["83950.1", "0.0428883", "0", "1"], ["83950.8", "0", "0", "0"], ["83952.9", "0.000039", "0", "1"], ["83953.7", "0.11889794", "0", "1"], ["83954.2", "0", "0", "0"], ["83957.1", "0", "0", "0"], ["83968.8", "0.00365366", "0", "1"], ["83974.1", "0.003573", "0", "1"], ["83976.2", "0.23837361", "0", "1"], ["84016", "0.00001198", "0", "1"]], "bids": [["83942", "0.93552801", "0", "13"], ["83937.2", "1", "0", "1"], ["83935.9", "0", "0", "0"], ["83935.1", "0.0428883", "0", "1"], ["83935", "0.00774343", "0", "1"], ["83933.1", "0.05361074", "0", "2"], ["83930.6", "0", "0", "0"], ["83927", "0.134795", "0", "1"], ["83925.8", "0.005355", "0", "1"], ["83922.1", "0.08991011", "0", "1"], ["83920.5", "0", "0", "0"], ["83919.2", "0", "0", "0"], ["83917.7", "0.23837361", "0", "1"], ["83914.3", "0.13080483", "0", "2"], ["83812.8", "0", "0", "0"], ["83812.6", "0", "0", "0"]], "ts": "1742577158000", "checksum": -682531872, "seqId": 49945048910, "prevSeqId": 49945048853}], "record_time": 1742577158.172778, "EXCHANGE": "OKX"}
{"arg": {"channel": "books", "instId": "BTC-USDT"}, "action": "update", "data": [{"asks": [["83943", "0", "0", "0"], ["83945.7", "0", "0", "0"], ["83946", "0", "0", "0"], ["83947.9", "0.03027234", "0", "1"], ["83948.4", "0.0119187", "0", "1"], ["83949.6", "0", "0", "0"], ["83950.1", "0", "0", "0"], ["83950.3", "0.01153238", "0", "1"], ["83950.4", "0", "0", "0"], ["83953.9", "0.14152901", "0", "3"], ["83955.5", "0.11916799", "0", "1"], ["83955.9", "0.0102", "0", "1"], ["83959.7", "0.005", "0", "1"], ["83962.2", "0.03062", "0", "1"], ["83964.8", "0.05926", "0", "1"], ["83973.5", "0.11914238", "0", "1"], ["83974.1", "0", "0", "0"], ["83976.2", "0.23836692", "0", "1"], ["83986.4", "0", "0", "0"], ["83987.2", "0.07999999", "0", "2"], ["83988", "0.03999999", "0", "1"], ["83991.4", "0.003573", "0", "1"], ["83997.7", "0.00002157", "0", "1"], ["83999.3", "0", "0", "0"], ["84003.8", "0", "0", "0"], ["84125.1", "0", "0", "0"]], "bids": [["83942", "0.94941801", "0", "14"], ["83941.4", "0.08991011", "0", "1"], ["83939.3", "0.0428883", "0", "1"], ["83939.2", "0.49525462", "0", "2"], ["83938.9", "1.0119187", "0", "2"], ["83937.2", "0", "0", "0"], ["83937", "0.11200687", "0", "2"], ["83935.3", "0.08991011", "0", "1"], ["83935.2", "0", "0", "0"], ["83935.1", "0", "0", "0"], ["83933.4", "0", "0", "0"], ["83926.8", "0.003096", "0", "1"], ["83925.8", "0", "0", "0"], ["83919.9", "0.23836692", "0", "1"], ["83917.7", "0", "0", "0"], ["83911.2", "0", "0", "0"], ["83910.4", "0.08", "0", "2"], ["83909.6", "0.04079951", "0", "3"], ["83908.8", "0.02639952", "0", "3"], ["83892.8", "0.1500033", "0", "2"], ["83892", "0.02466532", "0", "1"], ["83891.6", "0.01858666", "0", "1"], ["83880.4", "0", "0", "0"], ["83873.9", "0.002187", "0", "1"], ["83860.1", "0", "0", "0"], ["83853.7", "0.00018343", "0", "1"], ["83813.1", "0", "0", "0"]], "ts": "1742577158100", "checksum": -1280013680, "seqId": 49945049006, "prevSeqId": 49945048910}], "record_time": 1742577158.270565, "EXCHANGE": "OKX"}
{"arg": {"channel": "books", "instId": "BTC-USDT"}, "action": "update", "data": [{"asks": [["83946", "0.0439", "0", "1"], ["83951.2", "0.11917405", "0", "1"], ["83955.5", "0", "0", "0"], ["83959.7", "0", "0", "0"], ["83969.7", "0", "0", "0"], ["83971.1", "0.01774536", "0", "1"], ["83998.6", "0", "0", "0"], ["84016.4", "0.01132149", "0", "1"], ["84088.5", "0.11325035", "0", "2"]], "bids": [["83942", "1.14941801", "0", "15"], ["83941.4", "0", "0", "0"], ["83938.9", "0.0119187", "0", "1"], ["83937.6", "1", "0", "1"], ["83936.5", "0", "0", "0"], ["83926.8", "0", "0", "0"], ["83923", "0.17869", "0", "1"], ["83813.1", "0.00001199", "0", "1"]], "ts": "1742577158200", "checksum": 1335604208, "seqId": 49945049023, "prevSeqId": 49945049006}], "record_time": 1742577158.372352, "EXCHANGE": "OKX"}
{"arg": {"channel": "books", "instId": "BTC-USDT"}, "action": "update", "data": [{"asks": [["83942.1", "0", "0", "0"], ["83944.8", "0", "0", "0"], ["83946", "0", "0", "0"], ["83947.9", "0.29572288", "0", "4"], ["83948.3", "0.00176436", "0", "2"], ["83949.6", "0.005", "0", "1"], ["83949.9", "0.0714369", "0", "1"], ["83953.7", "0", "0", "0"], ["83953.8", "0", "0", "0"], ["83953.9", "0.11442658", "0", "2"], ["83955.9", "0", "0", "0"], ["83959.6", "0.005", "0", "1"], ["83959.9", "0.0102", "0", "1"], ["83962.2", "0", "0", "0"], ["83966.2", "0.06662", "0", "2"], ["83986.6", "0.05956073", "0", "1"], ["83987.2", "0", "0", "0"], ["83988", "0.07999999", "0", "2"], ["83988.8", "0.03999999", "0", "1"], ["84125.1", "0.00015069", "0", "2"], ["84125.3", "0.00001956", "0", "1"], ["84126.2", "0.00001805", "0", "1"], ["84126.6", "0.00002004", "0", "1"]], "bids": [["83947.8", "0.96736529", "0", "12"], ["83946.2", "0.01389", "0", "1"], ["83946.1", "0.17545823", "0", "1"], ["83946", "0.0489", "0", "2"], ["83945.9", "0.53596076", "0", "2"], ["83945.2", "0.1", "0", "1"], ["83944.9", "0.12744789", "0", "1"], ["83944.7", "0.052", "0", "2"], ["83944", "0.0439", "0", "1"], ["83942", "0.30908031", "0", "5"], ["83941.8", "0.00001199", "0", "1"], ["83941.5", "0", "0", "0"], ["83940", "0.0856", "0", "3"], ["83936", "0.0489", "0", "2"], ["83933.1", "0.01192074", "0", "1"], ["83929.5", "0.0044685", "0", "1"], ["83925.3", "0.03574845", "0", "2"], ["83919.9", "0.23836786", "0", "1"], ["83919.5", "0", "0", "0"], ["83906.4", "0.1", "0", "2"], ["83905.6", "0.16889794", "0", "2"], ["83904.8", "0.17898725", "0", "1"], ["83904", "0", "0", "0"], ["83880.1", "0.00145287", "0", "1"], ["83878.6", "0.00100713", "0", "1"], ["83875.3", "0.000015", "0", "1"], ["83873.8", "0", "0", "0"], ["83857.1", "0.00091322", "0", "4"], ["83815.3", "0", "0", "0"], ["83815.1", "0", "0", "0"], ["83815", "0", "0", "0"], ["83814.9", "0", "0", "0"], ["83814.4", "0", "0", "0"], ["83814.1", "0", "0", "0"], ["83813.8", "0", "0", "0"], ["83813.6", "0", "0", "0"], ["83813.5", "0", "0", "0"], ["83813.1", "0", "0", "0"]], "ts": "1742577158300", "checksum": -2076673904, "seqId": 49945049252, "prevSeqId": 49945049023}], "record_time": 1742577158.469812, "EXCHANGE": "OKX"}
{"arg": {"channel": "books", "instId": "BTC-USDT"}, "action": "update", "data": [{"asks": [["83947.9", "0.37308432", "0", "5"], ["83967.5", "0", "0", "0"], ["83971.1", "0", "0", "0"], ["83998.6", "0.01774536", "0", "1"], ["84127.5", "0.3565323", "0", "1"]], "bids": [["83946.1", "0.06836618", "0", "1"], ["83945.9", "0.17898725", "0", "1"], ["83880.2", "0.00100712", "0", "1"], ["83880.1", "0.00363965", "0", "2"], ["83878.6", "0", "0", "0"], ["83873.9", "0", "0", "0"], ["83815.3", "0.00018461", "0", "1"]], "ts": "1742577158400", "checksum": -1869494816, "seqId": 49945049283, "prevSeqId": 49945049252}], "record_time": 1742577158.571401, "EXCHANGE": "OKX"}
{"arg": {"channel": "books", "instId": "BTC-USDT"}, "action": "update", "data": [{"asks": [["83947.9", "0.39611088", "0", "9"], ["83976.1", "0.15889656", "0", "1"], ["83981", "1", "0", "1"], ["83983", "0.2", "0", "1"], ["83992.4", "0.1", "0", "1"], ["83997.7", "0", "0", "0"], ["84003", "0.00002157", "0", "1"], ["84125.3", "0", "0", "0"], ["84126.2", "0", "0", "0"], ["84126.6", "0", "0", "0"], ["84127.5", "0", "0", "0"]], "bids": [["83947.8", "0.8459983", "0", "11"], ["83946.2", "0", "0", "0"], ["83944.1", "0.01389", "0", "1"], ["83942", "0.30840031", "0", "4"], ["83939.2", "0.20385046", "0", "1"], ["83937.6", "0", "0", "0"], ["83937", "0.40290196", "0", "3"], ["83936.2", "1", "0", "1"], ["83929.5", "0", "0", "0"], ["83916", "1.11256978", "0", "3"], ["83914", "0.21190694", "0", "2"], ["83912", "0.080012", "0", "3"], ["83911.2", "0.04", "0", "1"], ["83910.4", "0", "0", "0"], ["83909.6", "0.00079951", "0", "2"], ["83860", "0.00054342", "0", "2"], ["83859.1", "0.000015", "0", "1"], ["83857.1", "0.82305242", "0", "5"], ["83853.7", "0", "0", "0"], ["83815.1", "0.00589964", "0", "1"], ["83815", "0.35776874", "0", "1"]], "ts": "1742577158500", "checksum": 79283555, "seqId": 49945049326, "prevSeqId": 49945049283}], "record_time": 1742577158.670725, "EXCHANGE": "OKX"}
{"arg": {"channel": "books", "instId": "BTC-USDT"}, "action": "update", "data": [{"asks": [["83979.2", "0.0008", "0", "2"], ["83980", "0.0123076", "0", "2"], ["83981", "0", "0", "0"], ["83981.6", "0.052", "0", "2"], ["83982.4", "0.26640726", "0", "4"], ["83983", "0", "0", "0"], ["84125.3", "0.00001956", "0", "1"]], "bids": [["83946.1", "0.05186243", "0", "2"], ["83935.3", "0", "0", "0"], ["83927.4", "0.000357", "0", "1"], ["83912", "0.080812", "0", "5"], ["83911.2", "0.04039951", "0", "2"], ["83909.6", "0", "0", "0"], ["83909.3", "0.045049", "0", "1"], ["83908.8", "0.026", "0", "2"], ["83857.6", "0.00215113", "0", "2"], ["83814.9", "0.0073937", "0", "2"]], "ts": "1742577158600", "checksum": 176475046, "seqId": 49945049356, "prevSeqId": 49945049326}], "record_time": 1742577158.770562, "EXCHANGE": "OKX"}
{"arg": {"channel": "books", "instId": "BTC-USDT"}, "action": "update", "data": [{"asks": [["83947.9", "0.31839182", "0", "7"], ["83959.3", "0", "0", "0"], ["83971.1", "0.01774536", "0", "1"], ["83972.3", "1", "0", "1"], ["83976", "0.23836684", "0", "1"], ["83976.1", "0", "0", "0"], ["83976.2", "0", "0", "0"], ["83979.2", "0", "0", "0"], ["83980", "0.0127076", "0", "3"], ["83980.8", "0.17938725", "0", "2"], ["83998.6", "0", "0", "0"], ["84126.2", "0.00001805", "0", "1"], ["84126.6", "0.00002004", "0", "1"]], "bids": [["83929.8", "0.0044685", "0", "1"], ["83927.4", "0", "0", "0"], ["83912", "0.080012", "0", "3"], ["83911.2", "0.04079951", "0", "3"], ["83910.4", "0.00039951", "0", "1"], ["83910.1", "0.01190773", "0", "1"], ["83815", "0", "0", "0"], ["83814.9", "0", "0", "0"]], "ts": "1742577158700", "checksum": 645264593, "seqId": 49945049397, "prevSeqId": 49945049356}], "record_time": 1742577158.873617, "EXCHANGE": "OKX"}
{"arg": {"channel": "books", "instId": "BTC-USDT"}, "action": "update", "data": [{"asks": [["83947.9", "0.36618107", "0", "8"], ["83953.7", "0.0077429", "0", "1"], ["84126.6", "0", "0", "0"]], "bids": [["83946.1", "0.09763779", "0", "1"], ["83945.9", "0.29816866", "0", "2"]], "ts": "1742577158800", "checksum": 270992164, "seqId": 49945049417, "prevSeqId": 49945049397}], "record_time": 1742577158.971975, "EXCHANGE": "OKX"}
{"arg": {"channel": "books", "instId": "BTC-USDT"}, "action": "update", "data": [{"asks": [["83959.9", "0.01371064", "0", "2"], ["83976", "0", "0", "0"], ["83978.8", "0.25744551", "0", "2"], ["84126.6", "0.00002004", "0", "1"]], "bids": [], "ts": "1742577158900", "checksum": 270992164, "seqId": 49945049423, "prevSeqId": 49945049417}], "record_time": 1742577159.070855, "EXCHANGE": "OKX"}
{"arg": {"channel": "books", "instId": "BTC-USDT"}, "action": "update", "data": [{"asks": [["83947.9", "0.38204435", "0", "11"], ["83976.2", "0.23836602", "0", "1"], ["83978.8", "0.01908", "0", "1"], ["84126.6", "0", "0", "0"]], "bids": [["83947.8", "0.8463383", "0", "12"], ["83912", "0.080812", "0", "5"], ["83911.2", "0.04039951", "0", "2"], ["83910.4", "0", "0", "0"], ["83815", "0.35776874", "0", "1"]], "ts": "1742577159000", "checksum": 526450884, "seqId": 49945049436, "prevSeqId": 49945049423}], "record_time": 1742577159.170404, "EXCHANGE": "OKX"}
{"arg": {"channel": "books", "instId": "BTC-USDT"}, "action": "update", "data": [{"asks": [["83946.1", "1.2167293", "0", "16"], ["83947.4", "0.1", "0", "1"], ["83947.8", "1.11171782", "0", "7"], ["83947.9", "0.51361802", "0", "12"], ["83949.4", "0.11917663", "0", "1"], ["83949.9", "0", "0", "0"], ["83950.3", "0", "0", "0"], ["83951.2", "0", "0", "0"], ["83957.4", "0.01021", "0", "1"], ["83959.9", "0.00351064", "0", "1"], ["83961.8", "0.03062", "0", "1"], ["83966.1", "0.23838571", "0", "1"], ["83966.2", "0.036", "0", "1"], ["83967", "0.51658434", "0", "1"], ["83967.1", "1", "0", "1"], ["83967.6", "0", "0", "0"], ["83972.3", "0", "0", "0"], ["83976.2", "0", "0", "0"], ["84125.1", "0", "0", "0"], ["84125.3", "0", "0", "0"], ["84126.2", "0", "0", "0"]], "bids": [["83947.8", "0", "0", "0"], ["83946.1", "0", "0", "0"], ["83946", "0.1013", "0", "4"], ["83945.9", "0", "0", "0"], ["83945.2", "0", "0", "0"], ["83944.9", "0", "0", "0"], ["83944.7", "0", "0", "0"], ["83944.1", "0", "0", "0"], ["83943.6", "0.11918471", "0", "1"], ["83942", "0.10590031", "0", "3"], ["83940", "0.04391", "0", "2"], ["83937.6", "0.2025", "0", "1"], ["83937", "0.08289418", "0", "2"], ["83936.2", "0", "0", "0"], ["83929.9", "1.016", "0", "2"], ["83929.8", "0", "0", "0"], ["83926.1", "0.000039", "0", "1"], ["83922.1", "0", "0", "0"], ["83919.9", "0", "0", "0"], ["83916", "0.11256978", "0", "2"], ["83914", "0.01190694", "0", "1"], ["83912.1", "0.2383808", "0", "1"], ["83898.2", "0", "0", "0"], ["83892", "0", "0", "0"], ["83826.8", "0", "0", "0"], ["83814.9", "0.0073937", "0", "2"], ["83814.4", "0.00005519", "0", "1"], ["83814.1", "0.00003395", "0", "1"], ["83813.8", "0.11936928", "0", "1"], ["83813.6", "0.03579964", "0", "2"], ["83813.5", "0.00002031", "0", "1"], ["83813.1", "0.00001199", "0", "1"], ["83812.8", "0.01493332", "0", "1"], ["83812.6", "0.00579923", "0", "1"], ["83812.5", "0.00667459", "0", "3"]], "ts": "1742577159100", "checksum": -2062148828, "seqId": 49945049586, "prevSeqId": 49945049436}], "record_time": 1742577159.273731, "EXCHANGE": "OKX"}
{"arg": {"channel": "books", "instId": "BTC-USDT"}, "action": "update", "data": [{"asks": [["83946.1", "1.05144319", "0", "15"], ["83947.3", "0.06609463", "0", "1"], ["83947.8", "0", "0", "0"], ["83947.9", "0.2025", "0", "1"], ["83948.4", "0", "0", "0"], ["83949.4", "0", "0", "0"], ["83949.9", "0.03899749", "0", "1"], ["83950.2", "0.0428883", "0", "1"], ["83951.3", "0.01153238", "0", "1"], ["83953.9", "0.07153828", "0", "1"], ["83966.1", "0", "0", "0"], ["83971.1", "0.23838385", "0", "1"], ["83987.2", "0.08", "0", "2"], ["83988", "0.03999999", "0", "1"], ["83988.8", "0", "0", "0"], ["83990.6", "0.100015", "0", "2"], ["83992.4", "0", "0", "0"], ["83998.6", "0.01774536", "0", "1"]], "bids": [["83946", "0.10725607", "0", "5"], ["83939.4", "0.32460046", "0", "1"], ["83939.3", "0.2", "0", "1"], ["83939.2", "0", "0", "0"], ["83938.9", "0", "0", "0"], ["83937", "0.09601022", "0", "3"], ["83936.4", "0.02791905", "0", "2"], ["83935.1", "0.0428883", "0", "1"], ["83931.2", "1", "0", "1"], ["83929.9", "0.016", "0", "1"], ["83925.3", "0.02859924", "0", "1"], ["83912", "0.080012", "0", "3"], ["83911.2", "0.04079951", "0", "3"], ["83910.4", "0.00039951", "0", "1"], ["83898.2", "0.01835569", "0", "1"], ["83880.2", "0", "0", "0"], ["83880.1", "0.00218678", "0", "1"], ["83879.1", "0.00100717", "0", "1"], ["83877.5", "0.0014529", "0", "1"], ["83826.8", "0.1835569", "0", "1"], ["83813.5", "0", "0", "0"], ["83813.1", "0", "0", "0"], ["83812.8", "0", "0", "0"], ["83812.6", "0", "0", "0"], ["83812.5", "0", "0", "0"]], "ts": "1742577159200", "checksum": -1777826483, "seqId": 49945049676, "prevSeqId": 49945049586}], "record_time": 1742577159.37016, "EXCHANGE": "OKX"}
{"arg": {"channel": "books", "instId": "BTC-USDT"}, "action": "update", "data": [{"asks": [["83946.1", "0.93050803", "0", "14"], ["83947.5", "0.01021", "0", "1"], ["83947.9", "0", "0", "0"], ["83949.9", "0.05963801", "0", "2"], ["83953.8", "0.03063", "0", "1"], ["83957.4", "0", "0", "0"], ["83961.8", "0", "0", "0"], ["83971.1", "0", "0", "0"], ["83978.8", "0.25744624", "0", "2"], ["83979.2", "0.0008", "0", "2"], ["83980", "0.0123076", "0", "2"], ["83980.8", "0.17898725", "0", "1"], ["84125.1", "0.00015069", "0", "2"]], "bids": [["83946", "0.20985607", "0", "7"], ["83943.7", "0.0675291", "0", "1"], ["83933.8", "0.01389", "0", "1"], ["83932.6", "1", "0", "1"], ["83931.2", "0", "0", "0"], ["83927.5", "0.04169", "0", "1"], ["83919.9", "0.23836624", "0", "1"], ["83912.1", "0", "0", "0"], ["83880.1", "0", "0", "0"], ["83879.1", "0.00319415", "0", "2"], ["83813.8", "0", "0", "0"], ["83813.6", "0", "0", "0"]], "ts": "1742577159300", "checksum": -1028064958, "seqId": 49945049714, "prevSeqId": 49945049676}], "record_time": 1742577159.470155, "EXCHANGE": "OKX"}
{"arg": {"channel": "books", "instId": "BTC-USDT"}, "action": "update", "data": [{"asks": [["83971.1", "0.23837949", "0", "1"], ["83978.8", "0.01908", "0", "1"], ["83981.8", "0.10181746", "0", "2"], ["83982.6", "0", "0", "0"]], "bids": [["83946", "0.12325607", "0", "6"], ["83943.7", "0", "0", "0"], ["83920", "0.00001", "0", "1"], ["83919.9", "0", "0", "0"], ["83914.4", "0.23838039", "0", "1"], ["83813.8", "0.11936928", "0", "1"]], "ts": "1742577159400", "checksum": 1911394921, "seqId": 49945049731, "prevSeqId": 49945049714}], "record_time": 1742577159.571163, "EXCHANGE": "OKX"}
{"arg": {"channel": "books", "instId": "BTC-USDT"}, "action": "update", "data": [{"asks": [["83946.1", "0.93063451", "0", "15"], ["83971", "0.01774536", "0", "1"], ["83971.1", "0", "0", "0"], ["83976.1", "0.15889886", "0", "1"], ["83976.2", "0.2383746", "0", "1"], ["83982.4", "0.2545", "0", "3"], ["83983.3", "0.24213509", "0", "3"], ["83998.6", "0", "0", "0"], ["84005.2", "0.52659912", "0", "2"], ["84125.1", "0", "0", "0"]], "bids": [["83946", "0.20988607", "0", "8"], ["83917.7", "0.2383746", "0", "1"], ["83914.4", "0", "0", "0"], ["83914.3", "0.43561083", "0", "3"], ["83852.2", "0.19369456", "0", "1"], ["83813.8", "0", "0", "0"]], "ts": "1742577159500", "checksum": -716348875, "seqId": 49945049751, "prevSeqId": 49945049731}], "record_time": 1742577159.671447, "EXCHANGE": "OKX"}
{"arg": {"channel": "books", "instId": "BTC-USDT"}, "action": "update", "data": [{"asks": [["83946.1", "0.35057003", "0", "7"], ["83947.4", "0", "0", "0"], ["83947.5", "0", "0", "0"], ["83949.6", "0.1241764", "0", "2"], ["83951.4", "0.01021", "0", "1"], ["83952.9", "0", "0", "0"], ["83953.8", "0", "0", "0"], ["83959.2", "0.03062", "0", "1"], ["83967.1", "0", "0", "0"], ["83968.7", "1", "0", "1"], ["83976.2", "0", "0", "0"], ["83978.8", "0.25744716", "0", "2"], ["83980", "0.1123076", "0", "3"], ["83981", "1", "0", "1"], ["84125.1", "0.00015069", "0", "2"], ["84125.3", "0.00001956", "0", "1"]], "bids": [["83946", "0.51003074", "0", "10"], ["83943.7", "0.03177369", "0", "1"], ["83943.6", "0", "0", "0"], ["83937.7", "0.01389", "0", "1"], ["83937", "0.39760107", "0", "3"], ["83934.2", "1", "0", "1"], ["83933.8", "0", "0", "0"], ["83932.9", "0.04169", "0", "1"], ["83932.6", "0", "0", "0"], ["83927.5", "0", "0", "0"], ["83919.9", "0.23836716", "0", "1"], ["83917.7", "0", "0", "0"]], "ts": "1742577159600", "checksum": -817777385, "seqId": 49945049804, "prevSeqId": 49945049751}], "record_time": 1742577159.788462, "EXCHANGE": "OKX"}
{"arg": {"channel": "books", "instId": "BTC-USDT"}, "action": "update", "data": [{"asks": [["83946.1", "0.49451049", "0", "12"], ["83950.5", "0.002955", "0", "1"], ["83967", "1", "0", "1"], ["83968.7", "0", "0", "0"], ["83971", "0", "0", "0"], ["83971.1", "0.01774536", "0", "1"], ["83976", "0.23837224", "0", "1"], ["83976.1", "0", "0", "0"], ["83978.8", "0.01908", "0", "1"], ["83980", "0.0123076", "0", "2"], ["83981", "0", "0", "0"], ["84126.2", "0.00001805", "0", "1"]], "bids": [["83946", "0.42343074", "0", "9"], ["83919.9", "0", "0", "0"], ["83918.8", "0.23837224", "0", "1"]], "ts": "1742577159700", "checksum": 91526652, "seqId": 49945049827, "prevSeqId": 49945049804}], "record_time": 1742577159.870771, "EXCHANGE": "OKX"}
{"arg": {"channel": "books", "instId": "BTC-USDT"}, "action": "update", "data": [{"asks": [["83946.1", "0.49432943", "0", "12"], ["83947.3", "0.06674521", "0", "2"], ["83948.3", "0.00112002", "0", "1"]], "bids": [], "ts": "1742577159800", "checksum": 252684732, "seqId": 49945049833, "prevSeqId": 49945049827}], "record_time": 1742577159.970226, "EXCHANGE": "OKX"}
{"arg": {"channel": "books", "instId": "BTC-USDT"}, "action": "update", "data": [{"asks": [["83946.1", "0.59468943", "0", "13"]], "bids": [["83946", "0.42371074", "0", "10"]], "ts": "1742577160000", "checksum": 681236154, "seqId": 49945049837, "prevSeqId": 49945049833}], "record_time": 1742577160.171279, "EXCHANGE": "OKX"}
{"arg": {"channel": "books", "instId": "BTC-USDT"}, "action": "update", "data": [{"asks": [["83973.4", "0.23837391", "0", "1"], ["83976", "0", "0", "0"], ["84001.2", "0.00002157", "0", "1"], ["84003", "0", "0", "0"], ["84016.4", "0", "0", "0"], ["84088.5", "0.00003542", "0", "1"], ["84126.6", "0.00002004", "0", "1"]], "bids": [["83939.3", "0", "0", "0"], ["83918.8", "0", "0", "0"], ["83917.7", "0.23837391", "0", "1"], ["83910", "1", "0", "1"], ["83909", "0.20001", "0", "2"], ["83879.2", "0.00100719", "0", "1"], ["83879.1", "0", "0", "0"], ["83878.6", "0.00218697", "0", "1"], ["83860", "0.00036", "0", "1"], ["83858.1", "0.00018341", "0", "1"], ["83814.4", "0", "0", "0"], ["83814.1", "0", "0", "0"]], "ts": "1742577160100", "checksum": 960314939, "seqId": 49945049870, "prevSeqId": 49945049837}], "record_time": 1742577160.281629, "EXCHANGE": "OKX"}
{"arg": {"channel": "books", "instId": "BTC-USDT"}, "action": "update", "data": [{"asks": [["83967", "0", "0", "0"], ["83967.1", "1", "0", "1"], ["83973.4", "0", "0", "0"], ["83976.2", "0.23837352", "0", "1"]], "bids": [["83918.8", "0.23837219", "0", "1"], ["83917.7", "0", "0", "0"], ["83910", "0", "0", "0"], ["83814.4", "0.00005519", "0", "1"]], "ts": "1742577160200", "checksum": 960314939, "seqId": 49945049887, "prevSeqId": 49945049870}], "record_time": 1742577160.371537, "EXCHANGE": "OKX"}
{"arg": {"channel": "books", "instId": "BTC-USDT"}, "action": "update", "data": [{"asks": [["83950.5", "0", "0", "0"], ["84030.9", "0.34370513", "0", "2"], ["84127.5", "0.3565323", "0", "1"]], "bids": [["83946", "0.42432074", "0", "11"], ["83918.8", "0", "0", "0"], ["83917.7", "0.23837345", "0", "1"], ["83866.2", "0.07165411", "0", "2"]], "ts": "1742577160400", "checksum": -1210337374, "seqId": 49945049897, "prevSeqId": 49945049887}], "record_time": 1742577160.573273, "EXCHANGE": "OKX"}
{"arg": {"channel": "books", "instId": "BTC-USDT"}, "action": "update", "data": [{"asks": [["84030.9", "0.2723028", "0", "1"]], "bids": [["83866.2", "0.00011161", "0", "1"]], "ts": "1742577160500", "checksum": -1210337374, "seqId": 49945049904, "prevSeqId": 49945049897}], "record_time": 1742577160.670875, "EXCHANGE": "OKX"}
{"arg": {"channel": "books", "instId": "BTC-USDT"}, "action": "update", "data": [{"asks": [["83967", "0.51658434", "0", "1"], ["84127.5", "0", "0", "0"]], "bids": [["83919.9", "0.23837057", "0", "1"], ["83917.7", "0", "0", "0"], ["83911.6", "0.46738606", "0", "1"]], "ts": "1742577160600", "checksum": -1210337374, "seqId": 49945049918, "prevSeqId": 49945049904}], "record_time": 1742577160.770915, "EXCHANGE": "OKX"}
{"arg": {"channel": "books", "instId": "BTC-USDT"}, "action": "update", "data": [{"asks": [["83946.1", "0.59444333", "0", "13"], ["83950.2", "0.0473133", "0", "2"], ["83968", "1.2", "0", "2"], ["84024.9", "0.17281486", "0", "3"], ["84125.6", "0.14264386", "0", "2"], ["84126.2", "0", "0", "0"], ["84126.6", "0", "0", "0"]], "bids": [["83919.9", "0", "0", "0"], ["83918.8", "0.2383709", "0", "1"], ["83860.2", "0.14309522", "0", "2"], ["83814.4", "0", "0", "0"]], "ts": "1742577160700", "checksum": -506837035, "seqId": 49945049945, "prevSeqId": 49945049918}], "record_time": 1742577160.874513, "EXCHANGE": "OKX"}
{"arg": {"channel": "books", "instId": "BTC-USDT"}, "action": "update", "data": [{"asks": [["83946.1", "0.59432316", "0", "13"]], "bids": [["83857.6", "0.00001198", "0", "1"], ["83856.1", "0", "0", "0"], ["83814.4", "0.00005519", "0", "1"]], "ts": "1742577160800", "checksum": -1867243833, "seqId": 49945049952, "prevSeqId": 49945049945}], "record_time": 1742577160.970184, "EXCHANGE": "OKX"}
{"arg": {"channel": "books", "instId": "BTC-USDT"}, "action": "update", "data": [{"asks": [["83950.2", "0.0428883", "0", "1"], ["83967.1", "0", "0", "0"], ["83968", "0", "0", "0"], ["83969.8", "1", "0", "1"], ["83979.2", "0", "0", "0"], ["83980", "0.0127076", "0", "3"], ["83980.8", "0.17938725", "0", "2"], ["83987.2", "0", "0", "0"], ["83988", "0.07999999", "0", "2"], ["83988.8", "0.03999999", "0", "1"], ["84126.2", "0.00001805", "0", "1"], ["84126.6", "0.00002004", "0", "1"]], "bids": [["83938.2", "0.016", "0", "1"], ["83936.6", "1", "0", "1"], ["83934.2", "0", "0", "0"], ["83934", "0.01389", "0", "1"], ["83814.4", "0", "0", "0"]], "ts": "1742577160900", "checksum": -1041546807, "seqId": 49945049971, "prevSeqId": 49945049952}], "record_time": 1742577161.070793, "EXCHANGE": "OKX"}
{"arg": {"channel": "books", "instId": "BTC-USDT"}, "action": "update", "data": [{"asks": [["83946.1", "0.55432316", "0", "12"], ["83951.2", "0.0044475", "0", "1"], ["83968.1", "1", "0", "1"], ["83969.8", "0", "0", "0"], ["83976.2", "0", "0", "0"], ["83978.8", "0.25744646", "0", "2"]], "bids": [["83936.6", "0", "0", "0"], ["83934.7", "1.00001501", "0", "2"], ["83919.9", "0.2383658", "0", "1"], ["83918.8", "0", "0", "0"], ["83814.4", "0.00005519", "0", "1"]], "ts": "1742577161000", "checksum": -25465902, "seqId": 49945049988, "prevSeqId": 49945049971}], "record_time": 1742577161.170973, "EXCHANGE": "OKX"}
{"arg": {"channel": "books", "instId": "BTC-USDT"}, "action": "update", "data": [{"asks": [["83946.1", "0.55447619", "0", "13"], ["83951.2", "0", "0", "0"], ["83976.2", "0.23837254", "0", "1"], ["83978.8", "0.01908", "0", "1"], ["83979.2", "0.0008", "0", "2"], ["83980", "0.0123076", "0", "2"], ["83980.8", "0.17898725", "0", "1"], ["83991.6", "0.37618118", "0", "1"], ["83994.2", "0.471887", "0", "1"], ["84005.5", "0", "0", "0"], ["84126.6", "0", "0", "0"]], "bids": [["83919.9", "0", "0", "0"], ["83918.8", "0.23837254", "0", "1"], ["83909.6", "0.026", "0", "2"], ["83909", "0.00001", "0", "1"], ["83908.8", "0.013", "0", "1"], ["83908", "0", "0", "0"], ["83879.2", "0", "0", "0"], ["83879.1", "0.00100721", "0", "1"], ["83844.9", "0.00213941", "0", "1"], ["83842", "0.01535884", "0", "2"], ["83814.4", "0", "0", "0"]], "ts": "1742577161100", "checksum": -1886368333, "seqId": 49945050027, "prevSeqId": 49945049988}], "record_time": 1742577161.270241, "EXCHANGE": "OKX"}
{"arg": {"channel": "books", "instId": "BTC-USDT"}, "action": "update", "data": [{"asks": [["83951", "0.002958", "0", "1"], ["83987.2", "0.08", "0", "2"], ["83988", "0.03999999", "0", "1"], ["83988.8", "0", "0", "0"], ["84126.2", "0", "0", "0"]], "bids": [["83918.8", "0", "0", "0"], ["83917.7", "0.23837414", "0", "1"], ["83911", "1", "0", "1"], ["83814.9", "0", "0", "0"]], "ts": "1742577161200", "checksum": 492705457, "seqId": 49945050036, "prevSeqId": 49945050027}], "record_time": 1742577161.371001, "EXCHANGE": "OKX"}
{"arg": {"channel": "books", "instId": "BTC-USDT"}, "action": "update", "data": [{"asks": [["83951", "0", "0", "0"], ["84126.2", "0.00001805", "0", "1"]], "bids": [["83946", "0.24025746", "0", "9"], ["83842", "0.00018", "0", "1"]], "ts": "1742577161300", "checksum": -96436989, "seqId": 49945050042, "prevSeqId": 49945050036}], "record_time": 1742577161.474585, "EXCHANGE": "OKX"}
{"arg": {"channel": "books", "instId": "BTC-USDT"}, "action": "update", "data": [{"asks": [["83946.1", "0.71032117", "0", "13"], ["83947.8", "0.00018", "0", "1"], ["83948.2", "0.01021", "0", "1"], ["83951.4", "0", "0", "0"], ["83954.5", "0.03063", "0", "1"], ["83959.2", "0", "0", "0"], ["83961.1", "0.003573", "0", "1"], ["83966.8", "1", "0", "1"], ["83967", "0", "0", "0"], ["83968.1", "0", "0", "0"], ["83971.1", "0.25612401", "0", "2"], ["83971.8", "0", "0", "0"], ["83971.9", "0", "0", "0"], ["83976.2", "0", "0", "0"], ["83979.2", "0", "0", "0"], ["83980", "0.0127076", "0", "3"], ["83980.8", "0.17938725", "0", "2"], ["83987.2", "0", "0", "0"], ["83988", "0.07999999", "0", "2"], ["83988.8", "0.03999999", "0", "1"], ["83991.4", "0", "0", "0"], ["84000.2", "0", "0", "0"], ["84001.3", "0", "0", "0"], ["84126.6", "0.00002004", "0", "1"], ["84127.5", "0.3565323", "0", "1"], ["84127.7", "0.00006401", "0", "1"], ["84129.9", "3.72", "0", "1"], ["84130.1", "0.00001199", "0", "1"], ["84130.5", "0.11889794", "0", "1"]], "bids": [["83946", "0.19574746", "0", "7"], ["83943.7", "0", "0", "0"], ["83937.7", "0", "0", "0"], ["83937", "0.10350338", "0", "2"], ["83934.7", "0.00001501", "0", "1"], ["83934.6", "0.01389", "0", "1"], ["83932.9", "0", "0", "0"], ["83930.4", "1", "0", "1"], ["83928.3", "0.11069", "0", "3"], ["83923", "0", "0", "0"], ["83919.8", "0", "0", "0"], ["83917.7", "0", "0", "0"], ["83917", "0.23875064", "0", "3"], ["83916.3", "0", "0", "0"], ["83911", "0", "0", "0"], ["83890.5", "0.07517439", "0", "2"], ["83886.9", "0", "0", "0"], ["83849", "0.01517756", "0", "1"], ["83847", "0.12267035", "0", "1"], ["83844.9", "0", "0", "0"], ["83814.9", "0.0073937", "0", "2"], ["83814.4", "0.00005519", "0", "1"], ["83814.1", "0.00003395", "0", "1"], ["83813.8", "0.11936928", "0", "1"], ["83813.6", "0.03579964", "0", "2"], ["83813.5", "0.00002031", "0", "1"]], "ts": "1742577161400", "checksum": -636060926, "seqId": 49945050108, "prevSeqId": 49945050042}], "record_time": 1742577161.571163, "EXCHANGE": "OKX"}
{"arg": {"channel": "books", "instId": "BTC-USDT"}, "action": "update", "data": [{"asks": [["83947.3", "0.06468344", "0", "3"], ["83947.7", "0.11917909", "0", "1"], ["83947.8", "0", "0", "0"], ["83949.6", "0.005", "0", "1"], ["83962.5", "0.77576579", "0", "1"], ["83966.4", "1.56467421", "0", "2"], ["83971.1", "0", "0", "0"], ["83973.4", "0.23837862", "0", "1"], ["83979.2", "0.0008", "0", "2"], ["83980", "0.0123076", "0", "2"], ["83980.8", "0.17898725", "0", "1"], ["83987.2", "0.08", "0", "2"], ["83988", "0.03999999", "0", "1"], ["83988.8", "0", "0", "0"], ["83995.8", "3.1667964", "0", "2"], ["84043.8", "0.01774536", "0", "1"], ["84130.1", "0", "0", "0"], ["84130.5", "0", "0", "0"]], "bids": [["83946", "0.07656607", "0", "6"], ["83944.1", "0.11918398", "0", "1"], ["83934.6", "0", "0", "0"], ["83923", "0.17869", "0", "1"], ["83917", "0.23875061", "0", "3"], ["83915.7", "1.53402485", "0", "1"], ["83911.4", "0", "0", "0"], ["83907.9", "0.5776526", "0", "1"], ["83886.4", "1.06930985", "0", "1"], ["83886.3", "2.8397261", "0", "2"], ["83886", "0.00928245", "0", "1"], ["83869.5", "0", "0", "0"], ["83865.9", "0.58941768", "0", "2"], ["83851.5", "0.00213925", "0", "1"], ["83813.8", "0", "0", "0"], ["83813.6", "0", "0", "0"], ["83813.5", "0", "0", "0"]], "ts": "1742577161500", "checksum": 1934035351, "seqId": 49945050166, "prevSeqId": 49945050108}], "record_time": 1742577161.671168, "EXCHANGE": "OKX"}
{"arg": {"channel": "books", "instId": "BTC-USDT"}, "action": "update", "data": [{"asks": [["83946.1", "0.71146373", "0", "14"], ["83946.9", "0.0000405", "0", "1"], ["83966.7", "0.67258434", "0", "6"], ["84129.9", "0", "0", "0"]], "bids": [["83939.4", "0.21656893", "0", "1"], ["83937.6", "0", "0", "0"], ["83932.4", "0.20150632", "0", "2"], ["83915.8", "0.8090549", "0", "1"], ["83914.3", "0.13080483", "0", "2"]], "ts": "1742577161600", "checksum": 1823297856, "seqId": 49945050180, "prevSeqId": 49945050166}], "record_time": 1742577161.781999, "EXCHANGE": "OKX"}
{"arg": {"channel": "books", "instId": "BTC-USDT"}, "action": "update", "data": [{"asks": [["83946.1", "0.83320611", "0", "17"], ["83948.2", "0", "0", "0"], ["83951.3", "0", "0", "0"], ["83979.2", "0", "0", "0"], ["83980", "0.0127076", "0", "3"], ["83980.8", "0.17938725", "0", "2"], ["83987.2", "0", "0", "0"], ["83987.9", "0.01774536", "0", "1"], ["83988", "0.07999999", "0", "2"], ["83988.8", "0.03999999", "0", "1"], ["84043.8", "0", "0", "0"], ["84129", "6.58867044", "0", "1"], ["84129.9", "3.72", "0", "1"], ["84130.1", "0.00001199", "0", "1"]], "bids": [["83946", "0.06056607", "0", "5"], ["83937.6", "0.2025", "0", "1"], ["83931.7", "1", "0", "1"], ["83930.4", "0", "0", "0"], ["83885.2", "0.12508", "0", "1"], ["83814.4", "0", "0", "0"], ["83814.1", "0", "0", "0"]], "ts": "1742577161700", "checksum": -1135707088, "seqId": 49945050213, "prevSeqId": 49945050180}], "record_time": 1742577161.872996, "EXCHANGE": "OKX"}
{"arg": {"channel": "books", "instId": "BTC-USDT"}, "action": "update", "data": [{"asks": [["83946.1", "0.83295827", "0", "17"], ["83946.9", "0.00069606", "0", "2"], ["83947.3", "0.06403286", "0", "2"]], "bids": [], "ts": "1742577161800", "checksum": -1724864155, "seqId": 49945050217, "prevSeqId": 49945050213}], "record_time": 1742577161.970995, "EXCHANGE": "OKX"}
{"arg": {"channel": "books", "instId": "BTC-USDT"}, "action": "update", "data": [{"asks": [["83973.4", "0", "0", "0"], ["83976.2", "0.23837575", "0", "1"], ["84045.8", "0.1", "0", "1"], ["84130.1", "0", "0", "0"]], "bids": [["83946", "0.06108607", "0", "6"], ["83917.7", "0.23837575", "0", "1"], ["83917", "0.00037199", "0", "2"], ["83814.9", "0", "0", "0"]], "ts": "1742577161900", "checksum": 727304296, "seqId": 49945050230, "prevSeqId": 49945050217}], "record_time": 1742577162.070438, "EXCHANGE": "OKX"}
{"arg": {"channel": "books", "instId": "BTC-USDT"}, "action": "update", "data": [{"asks": [], "bids": [["83940.1", "0.2", "0", "1"], ["83815", "0", "0", "0"]], "ts": "1742577162000", "checksum": 1737683452, "seqId": 49945050232, "prevSeqId": 49945050230}], "record_time": 1742577162.170794, "EXCHANGE": "OKX"}
{"arg": {"channel": "books", "instId": "BTC-USDT"}, "action": "update", "data": [{"asks": [["83973.4", "0.23837578", "0", "1"], ["83976.2", "0", "0", "0"]], "bids": [["83909", "0.20001", "0", "2"]], "ts": "1742577162100", "checksum": 1737683452, "seqId": 49945050236, "prevSeqId": 49945050232}], "record_time": 1742577162.271242, "EXCHANGE": "OKX"}
{"arg": {"channel": "books", "instId": "BTC-USDT"}, "action": "update", "data": [{"asks": [["84024.9", "0.10140743", "0", "2"], ["84125.6", "0.07132193", "0", "1"]], "bids": [["83860.2", "0.07154761", "0", "1"]], "ts": "1742577162200", "checksum": 1737683452, "seqId": 49945050249, "prevSeqId": 49945050236}], "record_time": 1742577162.370899, "EXCHANGE": "OKX"}
{"arg": {"channel": "books", "instId": "BTC-USDT"}, "action": "update", "data": [{"asks": [["83946.1", "0.4986013", "0", "13"], ["83947.7", "0", "0", "0"], ["83949.6", "0.12417637", "0", "2"], ["83951.8", "0.01153238", "0", "1"], ["83953.1", "0.01021", "0", "1"], ["83954.5", "0", "0", "0"], ["83959.4", "0.03062", "0", "1"], ["83966.8", "0", "0", "0"], ["83969.6", "1", "0", "1"], ["83973.4", "0", "0", "0"], ["83978.8", "0.25744414", "0", "2"]], "bids": [["83946", "1.0520606", "0", "15"], ["83944.2", "0.04494369", "0", "1"], ["83944.1", "0", "0", "0"], ["83939.5", "0.01389", "0", "1"], ["83937", "0.41010807", "0", "3"], ["83935.5", "1", "0", "1"], ["83933.2", "0.04169", "0", "1"], ["83932.4", "0.18761632", "0", "1"], ["83931.7", "0", "0", "0"], ["83928.3", "0.069", "0", "2"], ["83921.9", "0.23836316", "0", "1"], ["83917.7", "0", "0", "0"], ["83909", "0.00001", "0", "1"], ["83815.3", "0", "0", "0"], ["83815.1", "0", "0", "0"]], "ts": "1742577162300", "checksum": -768556788, "seqId": 49945050322, "prevSeqId": 49945050249}], "record_time": 1742577162.470949, "EXCHANGE": "OKX"}
{"arg": {"channel": "books", "instId": "BTC-USDT"}, "action": "update", "data": [{"asks": [["83951.8", "0", "0", "0"], ["83955.2", "0.05166564", "0", "2"], ["83976.2", "0.23836747", "0", "1"], ["83978.8", "0.01908", "0", "1"], ["84024.9", "0.17281486", "0", "3"], ["84125.6", "0.14264386", "0", "2"]], "bids": [["83946", "0.86409218", "0", "13"], ["83922.6", "0.08991011", "0", "1"], ["83921.9", "0", "0", "0"], ["83918.8", "0.23836462", "0", "1"], ["83913", "1", "0", "1"], ["83885.2", "0", "0", "0"], ["83860.2", "0.14309522", "0", "2"], ["83815.5", "0", "0", "0"]], "ts": "1742577162400", "checksum": -304919210, "seqId": 49945050352, "prevSeqId": 49945050322}], "record_time": 1742577162.570444, "EXCHANGE": "OKX"}
{"arg": {"channel": "books", "instId": "BTC-USDT"}, "action": "update", "data": [{"asks": [["83946.1", "0.40835589", "0", "12"]], "bids": [["83946", "0.43781074", "0", "10"], ["83913", "0", "0", "0"], ["83815.5", "0.002384", "0", "1"]], "ts": "1742577162500", "checksum": 1976399843, "seqId": 49945050361, "prevSeqId": 49945050352}], "record_time": 1742577162.670869, "EXCHANGE": "OKX"}
{"arg": {"channel": "books", "instId": "BTC-USDT"}, "action": "update", "data": [{"asks": [["83967.9", "1", "0", "1"], ["83969.6", "0", "0", "0"], ["83972", "0.01190874", "0", "1"], ["83973.7", "0", "0", "0"], ["83976.1", "0.15889672", "0", "1"], ["84000.2", "0.26328334", "0", "1"], ["84129", "0", "0", "0"], ["84129.9", "0", "0", "0"]], "bids": [["83935.5", "0", "0", "0"], ["83934", "1.01389", "0", "2"], ["83918.8", "0.55078991", "0", "2"], ["83918.1", "0.01190874", "0", "1"], ["83916.4", "0", "0", "0"], ["83815.3", "0.00018461", "0", "1"]], "ts": "1742577162600", "checksum": 971224873, "seqId": 49945050376, "prevSeqId": 49945050361}], "record_time": 1742577162.770819, "EXCHANGE": "OKX"}
{"arg": {"channel": "books", "instId": "BTC-USDT"}, "action": "update", "data": [{"asks": [["83946.1", "0.50702589", "0", "13"]], "bids": [], "ts": "1742577162700", "checksum": 1346420726, "seqId": 49945050379, "prevSeqId": 49945050376}], "record_time": 1742577162.888228, "EXCHANGE": "OKX"}
{"arg": {"channel": "books", "instId": "BTC-USDT"}, "action": "update", "data": [{"asks": [["83976", "0.2383736", "0", "1"], ["83976.2", "0", "0", "0"], ["83979.2", "0.0008", "0", "2"], ["83980", "0.0123076", "0", "2"], ["83980.8", "0.17898725", "0", "1"], ["84127.7", "0", "0", "0"]], "bids": [["83946", "0.24014746", "0", "9"], ["83937", "0.10350338", "0", "2"], ["83934", "0.01389", "0", "1"], ["83932.6", "1", "0", "1"], ["83926.1", "0", "0", "0"], ["83918.8", "0.31242529", "0", "1"], ["83917.7", "0.2383736", "0", "1"], ["83905.2", "0", "0", "0"], ["83902.7", "0.248377", "0", "2"]], "ts": "1742577162800", "checksum": -928156384, "seqId": 49945050399, "prevSeqId": 49945050379}], "record_time": 1742577162.97128, "EXCHANGE": "OKX"}
{"arg": {"channel": "books", "instId": "BTC-USDT"}, "action": "update", "data": [{"asks": [["83946.1", "0.70952589", "0", "14"], ["83947.2", "0.05855872", "0", "1"], ["83947.3", "0.11917957", "0", "1"], ["83949", "0.01021", "0", "1"], ["83949.6", "0.005", "0", "1"], ["83953.1", "0", "0", "0"], ["83953.5", "0.03063", "0", "1"], ["83959.4", "0", "0", "0"], ["83964.7", "0.11913", "0", "1"], ["83972", "0", "0", "0"], ["83972.8", "0.01190862", "0", "1"], ["83976", "0", "0", "0"], ["83976.1", "0", "0", "0"], ["83976.2", "0.23837343", "0", "1"], ["83980", "0.1123076", "0", "3"], ["83981", "1", "0", "1"], ["84003.1", "0", "0", "0"], ["84056", "0", "0", "0"]], "bids": [["83946", "0.10444607", "0", "6"], ["83944.2", "0", "0", "0"], ["83944", "0.16308411", "0", "2"], ["83939.5", "0", "0", "0"], ["83933.2", "0", "0", "0"], ["83927.3", "0.04645603", "0", "2"], ["83918.9", "0.23837343", "0", "1"], ["83918.1", "0", "0", "0"], ["83917.7", "0", "0", "0"], ["83917.2", "0.01190862", "0", "1"], ["83837.9", "0", "0", "0"], ["83815.1", "0.00589964", "0", "1"], ["83815", "0.35776874", "0", "1"], ["83814.9", "0.0073937", "0", "2"], ["83814.4", "0.00005519", "0", "1"]], "ts": "1742577162900", "checksum": 1934069593, "seqId": 49945050446, "prevSeqId": 49945050399}], "record_time": 1742577163.070788, "EXCHANGE": "OKX"}
{"arg": {"channel": "books", "instId": "BTC-USDT"}, "action": "update", "data": [{"asks": [["83961.1", "0", "0", "0"], ["83973.4", "0.23837605", "0", "1"], ["83974.4", "0.003573", "0", "1"], ["83976.2", "0", "0", "0"], ["83978.8", "0.03682536", "0", "2"], ["83987.9", "0", "0", "0"], ["84046.6", "0.00009539", "0", "1"], ["84058.7", "0", "0", "0"], ["84073.3", "0", "0", "0"], ["84081.7", "0.03", "0", "1"], ["84090.1", "0", "0", "0"], ["84127.7", "0.00006401", "0", "1"], ["84129", "6.58867044", "0", "1"], ["84129.9", "3.72", "0", "1"], ["84130.1", "0.00001199", "0", "1"]], "bids": [["83946", "0.05514607", "0", "5"], ["83932.6", "0", "0", "0"], ["83931.2", "1", "0", "1"], ["83925.6", "0.0044685", "0", "1"], ["83918.9", "0", "0", "0"], ["83917.7", "0.23837605", "0", "1"], ["83914.2", "0.57673738", "0", "2"], ["83912.5", "0.00577732", "0", "1"], ["83846.4", "0", "0", "0"], ["83838", "0.0015", "0", "1"], ["83829.6", "0", "0", "0"], ["83821.2", "0", "0", "0"], ["83814.1", "0.00003395", "0", "1"], ["83813.8", "0.11936928", "0", "1"]], "ts": "1742577163000", "checksum": 505008495, "seqId": 49945050474, "prevSeqId": 49945050446}], "record_time": 1742577163.169837, "EXCHANGE": "OKX"}
{"arg": {"channel": "books", "instId": "BTC-USDT"}, "action": "update", "data": [{"asks": [["83946.1", "0.71973589", "0", "15"], ["83949", "0", "0", "0"], ["83973.4", "0", "0", "0"], ["83976.2", "0.23837491", "0", "1"], ["83979.1", "0.01190773", "0", "1"], ["83980", "0.1004", "0", "2"]], "bids": [["83946", "0.10442607", "0", "6"], ["83932.2", "0.01389", "0", "1"], ["83813.8", "0", "0", "0"]], "ts": "1742577163100", "checksum": 1709550603, "seqId": 49945050490, "prevSeqId": 49945050474}], "record_time": 1742577163.270883, "EXCHANGE": "OKX"}
{"arg": {"channel": "books", "instId": "BTC-USDT"}, "action": "update", "data": [{"asks": [["83950.7", "0", "0", "0"], ["83960.7", "0", "0", "0"], ["83976.2", "0.2383748", "0", "1"], ["84130.5", "0.11889794", "0", "1"], ["84131.1", "0.00008649", "0", "2"]], "bids": [["83946", "0.10561731", "0", "7"], ["83936.9", "0", "0", "0"], ["83885.2", "0.12508", "0", "1"]], "ts": "1742577163200", "checksum": -1543714812, "seqId": 49945050503, "prevSeqId": 49945050490}], "record_time": 1742577163.370885, "EXCHANGE": "OKX"}
{"arg": {"channel": "books", "instId": "BTC-USDT"}, "action": "update", "data": [{"asks": [["83973.4", "0.23837526", "0", "1"], ["83976.2", "0", "0", "0"]], "bids": [["83911", "0.2", "0", "1"], ["83814.1", "0", "0", "0"]], "ts": "1742577163300", "checksum": -1543714812, "seqId": 49945050511, "prevSeqId": 49945050503}], "record_time": 1742577163.47133, "EXCHANGE": "OKX"}
{"arg": {"channel": "books", "instId": "BTC-USDT"}, "action": "update", "data": [{"asks": [["83946.1", "0.51723589", "0", "14"], ["83973.4", "0", "0", "0"], ["83976.2", "0.23837446", "0", "1"]], "bids": [["83946", "0.12580731", "0", "8"], ["83932.4", "1.18761632", "0", "2"], ["83931.2", "0", "0", "0"], ["83918.9", "0.23837446", "0", "1"], ["83917.7", "0", "0", "0"], ["83913.6", "0.01190747", "0", "1"], ["83912.7", "0", "0", "0"], ["83814.1", "0.00003395", "0", "1"]], "ts": "1742577163400", "checksum": 259922663, "seqId": 49945050532, "prevSeqId": 49945050511}], "record_time": 1742577163.577215, "EXCHANGE": "OKX"}
{"arg": {"channel": "books", "instId": "BTC-USDT"}, "action": "update", "data": [{"asks": [["83946.1", "0.50702589", "0", "13"], ["83947.9", "0.002", "0", "1"], ["83949.7", "0.01021", "0", "1"], ["83957.9", "0.002", "0", "1"], ["83962.9", "0", "0", "0"], ["83964.7", "0", "0", "0"], ["83966.7", "0.156", "0", "5"], ["83976.2", "0.23837111", "0", "1"], ["83980", "0.0004", "0", "1"], ["83981", "0", "0", "0"], ["83983.3", "0.01251358", "0", "2"], ["83984.7", "0", "0", "0"], ["84045.8", "0.10298666", "0", "2"], ["84054.2", "0.00597332", "0", "1"], ["84062.6", "0.0090716", "0", "2"], ["84071", "1.65519665", "0", "2"], ["84079.4", "0.01511526", "0", "2"]], "bids": [["83946", "0.40286273", "0", "12"], ["83945.9", "0.11918147", "0", "1"], ["83944.1", "0.002", "0", "1"], ["83944", "0.0439", "0", "1"], ["83942", "0.08990031", "0", "2"], ["83936.1", "0.01389", "0", "1"], ["83934.1", "0.002", "0", "1"], ["83933.9", "1", "0", "1"], ["83932.4", "0.18761632", "0", "1"], ["83932.2", "0", "0", "0"], ["83930.2", "0", "0", "0"], ["83925.6", "0", "0", "0"], ["83921.8", "0", "0", "0"], ["83918.9", "0.23837111", "0", "1"], ["83911", "0", "0", "0"], ["83902.7", "0.24659", "0", "1"], ["83846.4", "0.00298666", "0", "1"], ["83838", "0.00747332", "0", "2"], ["83829.6", "0.00895999", "0", "1"], ["83821.2", "0.01194665", "0", "1"], ["83814.9", "0", "0", "0"], ["83814.4", "0", "0", "0"], ["83814.1", "0", "0", "0"]], "ts": "1742577163500", "checksum": -634552379, "seqId": 49945050600, "prevSeqId": 49945050532}], "record_time": 1742577163.672132, "EXCHANGE": "OKX"}
{"arg": {"channel": "books", "instId": "BTC-USDT"}, "action": "update", "data": [{"asks": [["83949.7", "0", "0", "0"], ["83953.5", "0", "0", "0"], ["83958.3", "0.03062", "0", "1"], ["83967.8", "0.54458434", "0", "2"], ["83976.2", "0.23837104", "0", "1"], ["83978.8", "0.01908", "0", "1"], ["83979.2", "0", "0", "0"], ["83980", "0.0008", "0", "2"], ["83980.8", "0.17938725", "0", "2"], ["83987.9", "0.01774536", "0", "1"], ["83991.6", "1.22681786", "0", "2"], ["84026.8", "0.25016", "0", "1"]], "bids": [["83946", "0.37108647", "0", "13"], ["83937", "0.40176807", "0", "3"], ["83932.8", "0.16627366", "0", "1"], ["83932.1", "0.04169", "0", "1"], ["83927.3", "0.00476603", "0", "1"], ["83923.4", "0.006699", "0", "1"], ["83882.4", "0.16204993", "0", "2"], ["83879.9", "0.45266", "0", "2"], ["83815.1", "0", "0", "0"], ["83815", "0", "0", "0"]], "ts": "1742577163600", "checksum": -1453652506, "seqId": 49945050632, "prevSeqId": 49945050600}], "record_time": 1742577163.769817, "EXCHANGE": "OKX"}
{"arg": {"channel": "books", "instId": "BTC-USDT"}, "action": "update", "data": [{"asks": [["83946.1", "0.40822941", "0", "11"], ["83946.9", "0.00065556", "0", "1"], ["83947.2", "0.06187698", "0", "2"], ["83947.3", "0", "0", "0"], ["83949.4", "0.11917658", "0", "1"], ["83952.7", "0.01021", "0", "1"], ["83954", "0.0451705", "0", "2"], ["83967.9", "0", "0", "0"], ["83969.3", "1", "0", "1"], ["83976.2", "0", "0", "0"], ["83978.8", "0.257445", "0", "2"], ["83989.9", "0.35737", "0", "1"], ["84131.1", "0", "0", "0"]], "bids": [["83946", "0.42192391", "0", "23"], ["83944.1", "0.04214369", "0", "2"], ["83939.1", "0.08364077", "0", "2"], ["83936.1", "0", "0", "0"], ["83935.3", "1", "0", "1"], ["83933.9", "0", "0", "0"], ["83922.7", "0.238365", "0", "1"], ["83918.9", "0", "0", "0"], ["83906.4", "0", "0", "0"], ["83905.6", "0.21889794", "0", "3"], ["83904.8", "0.22898725", "0", "2"], ["83904.3", "0.35737", "0", "1"], ["83885.2", "0", "0", "0"], ["83815.1", "0.00589964", "0", "1"], ["83815", "0.35776874", "0", "1"]], "ts": "1742577163700", "checksum": -2111644180, "seqId": 49945050680, "prevSeqId": 49945050632}], "record_time": 1742577163.87133, "EXCHANGE": "OKX"}
{"arg": {"channel": "books", "instId": "BTC-USDT"}, "action": "update", "data": [{"asks": [["83946.1", "0.46175026", "0", "12"], ["83952.7", "0", "0", "0"], ["84131.1", "0.00008649", "0", "2"]], "bids": [["83946", "0.67484391", "0", "25"], ["83922.7", "0", "0", "0"], ["83918.9", "0.23836537", "0", "1"]], "ts": "1742577163800", "checksum": 1260525627, "seqId": 49945050690, "prevSeqId": 49945050680}], "record_time": 1742577163.974615, "EXCHANGE": "OKX"}
{"arg": {"channel": "books", "instId": "BTC-USDT"}, "action": "update", "data": [{"asks": [["83946.9", "0", "0", "0"], ["83954.7", "0.01021", "0", "1"], ["83974.4", "0", "0", "0"], ["83989.1", "0.003573", "0", "1"]], "bids": [], "ts": "1742577163900", "checksum": 386309215, "seqId": 49945050702, "prevSeqId": 49945050690}], "record_time": 1742577164.071392, "EXCHANGE": "OKX"}
{"arg": {"channel": "books", "instId": "BTC-USDT"}, "action": "update", "data": [{"asks": [["83946.1", "0.40718183", "0", "11"], ["83947.2", "0.06253753", "0", "3"], ["83989.9", "0", "0", "0"], ["84131.2", "0.03", "0", "1"]], "bids": [["83946", "0.47484391", "0", "24"], ["83906.4", "0.1", "0", "2"], ["83905.6", "0.16889794", "0", "2"], ["83904.8", "0.17898725", "0", "1"], ["83904.3", "0", "0", "0"]], "ts": "1742577164000", "checksum": 1223974561, "seqId": 49945050724, "prevSeqId": 49945050702}], "record_time": 1742577164.171118, "EXCHANGE": "OKX"}
{"arg": {"channel": "books", "instId": "BTC-USDT"}, "action": "update", "data": [{"asks": [["83946.1", "0.38489201", "0", "11"], ["83950.7", "0.01021", "0", "1"], ["83954", "0.0439", "0", "1"], ["83954.7", "0", "0", "0"], ["83967.6", "1", "0", "1"], ["83967.8", "0.04", "0", "1"], ["83969.3", "0", "0", "0"], ["83978.8", "0.01908", "0", "1"], ["83984.9", "0.25016", "0", "1"], ["84001.2", "0", "0", "0"], ["84001.3", "0.00002157", "0", "1"], ["84016.4", "0.01132955", "0", "1"], ["84026.8", "0", "0", "0"], ["84131.2", "0", "0", "0"]], "bids": [["83946", "0.16647117", "0", "14"], ["83937", "0.10350338", "0", "2"], ["83935.3", "0", "0", "0"], ["83932.8", "0.51590275", "0", "2"], ["83932.3", "1", "0", "1"], ["83923.4", "0", "0", "0"], ["83921.9", "0.25016", "0", "1"], ["83918.9", "0", "0", "0"], ["83916.2", "0.23837941", "0", "1"], ["83906.4", "0", "0", "0"], ["83905.6", "0.21889794", "0", "3"], ["83904.8", "0.22898725", "0", "2"], ["83900.1", "0.01835442", "0", "1"], ["83898.2", "0", "0", "0"], ["83882.4", "0.00001198", "0", "1"], ["83879.9", "0.2025", "0", "1"], ["83828.1", "0.18354421", "0", "1"], ["83826.8", "0", "0", "0"], ["83814.9", "0.0073937", "0", "2"]], "ts": "1742577164100", "checksum": 152950967, "seqId": 49945050786, "prevSeqId": 49945050724}], "record_time": 1742577164.274107, "EXCHANGE": "OKX"}
{"arg": {"channel": "books", "instId": "BTC-USDT"}, "action": "update", "data": [{"asks": [["83946.1", "0.38719201", "0", "12"], ["83951.4", "0.004935", "0", "1"], ["83964.7", "0.35737", "0", "1"], ["83973.4", "0.23837952", "0", "1"], ["84130.1", "0", "0", "0"], ["84130.5", "0", "0", "0"], ["84131.1", "0", "0", "0"]], "bids": [["83946", "0.15047117", "0", "13"], ["83939.1", "0.06975077", "0", "1"], ["83935.6", "0.01389", "0", "1"], ["83929.5", "0.35737", "0", "1"], ["83927.1", "0.1295285", "0", "2"], ["83922.6", "0", "0", "0"], ["83917.7", "0.23837658", "0", "1"], ["83916.2", "0", "0", "0"], ["83906.4", "0.1", "0", "2"], ["83905.6", "0.16889794", "0", "2"], ["83904.8", "0.17898725", "0", "1"], ["83885.2", "0.12508", "0", "1"], ["83815.1", "0", "0", "0"], ["83815", "0", "0", "0"], ["83814.9", "0", "0", "0"]], "ts": "1742577164200", "checksum": -117224568, "seqId": 49945050819, "prevSeqId": 49945050786}], "record_time": 1742577164.370235, "EXCHANGE": "OKX"}
{"arg": {"channel": "books", "instId": "BTC-USDT"}, "action": "update", "data": [{"asks": [["83946.1", "0.58969201", "0", "13"], ["83946.6", "0.01021", "0", "1"], ["83949.4", "0", "0", "0"], ["83950.7", "0", "0", "0"], ["83952.9", "0.03063", "0", "1"], ["83958.3", "0", "0", "0"], ["83962.9", "0.003573", "0", "1"], ["83966.4", "2.56467421", "0", "3"], ["83967.6", "0", "0", "0"], ["83989.1", "0", "0", "0"], ["84016", "0.01134153", "0", "2"], ["84016.4", "0", "0", "0"], ["84130.1", "0.00001199", "0", "1"], ["84130.5", "0.11889794", "0", "1"], ["84131.1", "0.00008649", "0", "2"]], "bids": [["83946", "0.07363105", "0", "7"], ["83944.1", "0.002", "0", "1"], ["83940.1", "0", "0", "0"], ["83935.6", "0", "0", "0"], ["83932.3", "0", "0", "0"], ["83932.1", "0", "0", "0"], ["83930.4", "1", "0", "1"], ["83927.1", "0.12506", "0", "1"], ["83926.7", "0.0417", "0", "1"], ["83903", "0.001787", "0", "1"], ["83900.1", "0", "0", "0"], ["83898.2", "0.01835504", "0", "1"], ["83828.1", "0", "0", "0"], ["83827.6", "0.18355042", "0", "1"], ["83815.1", "0.00589964", "0", "1"]], "ts": "1742577164300", "checksum": 860061239, "seqId": 49945050864, "prevSeqId": 49945050819}], "record_time": 1742577164.470893, "EXCHANGE": "OKX"}
{"arg": {"channel": "books", "instId": "BTC-USDT"}, "action": "update", "data": [{"asks": [["83946.1", "0.38719201", "0", "12"], ["83947.2", "0.0625383", "0", "3"], ["83947.6", "0.11917915", "0", "1"], ["83966.4", "1.00001199", "0", "2"], ["83971.1", "0.23837894", "0", "1"], ["83973.4", "0", "0", "0"], ["83979.2", "0.0008", "0", "2"], ["83980", "0.0004", "0", "1"], ["83980.8", "0.17898725", "0", "1"], ["83991.6", "0.37618118", "0", "1"], ["83995.8", "0.28114942", "0", "1"], ["84130.5", "0", "0", "0"], ["84131.1", "0", "0", "0"]], "bids": [["83946", "0.10274105", "0", "7"], ["83945.9", "0", "0", "0"], ["83943.5", "0.11918493", "0", "1"], ["83933.5", "0.01389", "0", "1"], ["83925.9", "0.0044685", "0", "1"], ["83917.7", "0", "0", "0"], ["83916.1", "0.23837957", "0", "1"], ["83915.8", "0.34884756", "0", "1"], ["83915.7", "0", "0", "0"], ["83886.4", "0", "0", "0"], ["83886.3", "0.00579988", "0", "1"]], "ts": "1742577164400", "checksum": 1021373496, "seqId": 49945050895, "prevSeqId": 49945050864}], "record_time": 1742577164.570554, "EXCHANGE": "OKX"}
{"arg": {"channel": "books", "instId": "BTC-USDT"}, "action": "update", "data": [{"asks": [["83966.8", "1.60864909", "0", "1"], ["83971.1", "0", "0", "0"], ["83973.4", "0.23837812", "0", "1"], ["83979.2", "0", "0", "0"], ["83980", "0.1008", "0", "3"], ["83980.8", "0.17938725", "0", "2"], ["83981", "1", "0", "1"], ["83987.9", "0", "0", "0"], ["83996.2", "3.18122611", "0", "3"], ["84043.8", "0.01774536", "0", "1"], ["84130.1", "0", "0", "0"]], "bids": [["83946", "0.05344105", "0", "6"], ["83917", "0.23875011", "0", "3"], ["83916.1", "0", "0", "0"], ["83915.6", "1.60766923", "0", "1"], ["83915", "1.2", "0", "2"], ["83886.3", "2.92033154", "0", "2"], ["83885.2", "0", "0", "0"]], "ts": "1742577164500", "checksum": 1816418450, "seqId": 49945050918, "prevSeqId": 49945050895}], "record_time": 1742577164.672304, "EXCHANGE": "OKX"}
{"arg": {"channel": "books", "instId": "BTC-USDT"}, "action": "update", "data": [{"asks": [["83966.7", "0.85517907", "0", "6"], ["83995.8", "1.16460933", "0", "2"]], "bids": [["83946", "0.10274105", "0", "7"], ["83943.5", "0", "0", "0"], ["83931.6", "1.069", "0", "3"], ["83930.4", "0", "0", "0"], ["83925.9", "0", "0", "0"], ["83922.5", "0.3148345", "0", "2"], ["83886.4", "1.09349148", "0", "1"], ["83815", "0.35776874", "0", "1"], ["83814.9", "0.0073937", "0", "2"]], "ts": "1742577164600", "checksum": 66435879, "seqId": 49945050931, "prevSeqId": 49945050918}], "record_time": 1742577164.771156, "EXCHANGE": "OKX"}
{"arg": {"channel": "books", "instId": "BTC-USDT"}, "action": "update", "data": [{"asks": [["83946.1", "0.60122439", "0", "14"], ["83955.2", "0.04013326", "0", "1"], ["83973.4", "0.23837559", "0", "1"], ["83978.8", "0.03682536", "0", "2"], ["83979.2", "0.0008", "0", "2"], ["83980", "0.1004", "0", "2"], ["83980.8", "0.17898725", "0", "1"], ["83987.2", "0.08", "0", "2"], ["83988", "0.03999999", "0", "1"], ["83988.8", "0", "0", "0"], ["84043.8", "0", "0", "0"]], "bids": [["83945.3", "0.11918231", "0", "1"], ["83922.5", "0.31", "0", "1"], ["83917.7", "0.23837559", "0", "1"], ["83917", "0.00037199", "0", "2"], ["83815", "0", "0", "0"], ["83814.9", "0", "0", "0"]], "ts": "1742577164700", "checksum": 1034220684, "seqId": 49945050962, "prevSeqId": 49945050931}], "record_time": 1742577164.870765, "EXCHANGE": "OKX"}
{"arg": {"channel": "books", "instId": "BTC-USDT"}, "action": "update", "data": [{"asks": [["83946.1", "0.60188743", "0", "15"], ["83947.2", "0.06187775", "0", "2"]], "bids": [["83946", "0.05344105", "0", "6"], ["83926.1", "0.0000105", "0", "1"], ["83815.1", "0", "0", "0"]], "ts": "1742577164800", "checksum": -858441380, "seqId": 49945050978, "prevSeqId": 49945050962}], "record_time": 1742577164.971645, "EXCHANGE": "OKX"}
{"arg": {"channel": "books", "instId": "BTC-USDT"}, "action": "update", "data": [{"asks": [["83946.1", "0.60546043", "0", "16"], ["83962.9", "0", "0", "0"], ["84130.1", "0.00001199", "0", "1"]], "bids": [["83946", "0.07342105", "0", "7"]], "ts": "1742577164900", "checksum": -2079282636, "seqId": 49945050986, "prevSeqId": 49945050978}], "record_time": 1742577165.07169, "EXCHANGE": "OKX"}
{"arg": {"channel": "books", "instId": "BTC-USDT"}, "action": "update", "data": [{"asks": [["83946.1", "0.39938743", "0", "14"], ["83946.6", "0", "0", "0"], ["83949.3", "0.01021", "0", "1"], ["83951.4", "0", "0", "0"], ["83951.5", "0.002199", "0", "1"], ["83962.5", "0.3443384", "0", "1"], ["83966.4", "0.00001199", "0", "1"], ["83967.7", "1", "0", "1"], ["83971.8", "0.003573", "0", "1"], ["83973.4", "0", "0", "0"], ["83976.2", "0.23837295", "0", "1"], ["83982.4", "0.26640726", "0", "4"], ["83983.3", "0.00060645", "0", "1"], ["84001.3", "0", "0", "0"], ["84130.1", "0", "0", "0"]], "bids": [["83946", "0.17912105", "0", "10"], ["83937", "0.40176807", "0", "3"], ["83935.7", "0.01389", "0", "1"], ["83933.5", "0", "0", "0"], ["83932.9", "1", "0", "1"], ["83932.8", "0.31060675", "0", "1"], ["83931.6", "0.069", "0", "2"], ["83927", "0", "0", "0"], ["83918.9", "0.23837295", "0", "1"], ["83917.7", "0", "0", "0"]], "ts": "1742577165000", "checksum": -1223232336, "seqId": 49945051020, "prevSeqId": 49945050986}], "record_time": 1742577165.170451, "EXCHANGE": "OKX"}
{"arg": {"channel": "books", "instId": "BTC-USDT"}, "action": "update", "data": [{"asks": [["83946.1", "0.70073074", "0", "16"], ["83947.2", "0.12093803", "0", "1"], ["83947.5", "0.2", "0", "1"], ["83951.5", "0", "0", "0"], ["83971.8", "0", "0", "0"], ["83976.2", "0.23837475", "0", "1"], ["83980", "0.0004", "0", "1"], ["83981", "0", "0", "0"], ["83986.4", "0.003573", "0", "1"], ["84001.3", "0.00002157", "0", "1"]], "bids": [["83946", "0.02952118", "0", "6"], ["83945.3", "0", "0", "0"], ["83943.4", "0.11918504", "0", "1"], ["83937", "0.10350338", "0", "2"], ["83935.7", "0", "0", "0"], ["83932.9", "0", "0", "0"], ["83926.1", "0", "0", "0"], ["83925.7", "0.134785", "0", "1"], ["83918.9", "0.23837477", "0", "1"], ["83915", "0", "0", "0"], ["83815.1", "0.00589964", "0", "1"], ["83815", "0.35776874", "0", "1"], ["83814.9", "0.0073937", "0", "2"]], "ts": "1742577165100", "checksum": -343967196, "seqId": 49945051087, "prevSeqId": 49945051020}], "record_time": 1742577165.270344, "EXCHANGE": "OKX"}
{"arg": {"channel": "books", "instId": "BTC-USDT"}, "action": "update", "data": [{"asks": [["83946.1", "0.71094074", "0", "17"], ["83949.1", "0.009024", "0", "1"], ["83949.3", "0", "0", "0"], ["83973.4", "0.23837498", "0", "1"], ["83976.2", "0", "0", "0"], ["83978.8", "0.01908", "0", "1"], ["83987.2", "0.07999999", "0", "2"], ["83987.9", "0.01774536", "0", "1"], ["84129.9", "0", "0", "0"]], "bids": [["83946", "0.02356498", "0", "5"], ["83932.8", "0.59256511", "0", "2"], ["83931.4", "0.01389", "0", "1"], ["83929.6", "1.17869", "0", "2"], ["83923", "0", "0", "0"], ["83920.5", "0.0001785", "0", "1"], ["83918.9", "0", "0", "0"], ["83916.1", "0.23837919", "0", "1"], ["83885.2", "0.12508", "0", "1"], ["83815", "0", "0", "0"], ["83814.9", "0", "0", "0"]], "ts": "1742577165200", "checksum": 1264206257, "seqId": 49945051110, "prevSeqId": 49945051087}], "record_time": 1742577165.373382, "EXCHANGE": "OKX"}
{"arg": {"channel": "books", "instId": "BTC-USDT"}, "action": "update", "data": [{"asks": [["83971.1", "0.23838288", "0", "1"], ["83973.4", "0", "0", "0"]], "bids": [["83920.5", "0.1788685", "0", "2"], ["83916.1", "0", "0", "0"], ["83912.1", "0.23838306", "0", "1"]], "ts": "1742577165300", "checksum": 1264206257, "seqId": 49945051129, "prevSeqId": 49945051110}], "record_time": 1742577165.471667, "EXCHANGE": "OKX"}
{"arg": {"channel": "books", "instId": "BTC-USDT"}, "action": "update", "data": [{"asks": [["83947.9", "0.005615", "0", "2"], ["83949.1", "0", "0", "0"], ["83966.6", "0.23940049", "0", "3"], ["83971.1", "0", "0", "0"], ["83978.4", "0.0008", "0", "2"], ["83979.2", "0.0004", "0", "1"], ["83980", "0", "0", "0"], ["84129.9", "3.72", "0", "1"], ["84130.1", "0.00001199", "0", "1"]], "bids": [["83946", "0.00358498", "0", "4"], ["83944", "0", "0", "0"], ["83925.7", "0.1392535", "0", "2"], ["83920.5", "0.17869", "0", "1"], ["83815", "0.35776874", "0", "1"]], "ts": "1742577165400", "checksum": -1495702973, "seqId": 49945051155, "prevSeqId": 49945051129}], "record_time": 1742577165.57077, "EXCHANGE": "OKX"}
{"arg": {"channel": "books", "instId": "BTC-USDT"}, "action": "update", "data": [{"asks": [["83947.2", "0.06560975", "0", "1"], ["83947.5", "0", "0", "0"], ["83947.9", "0.002", "0", "1"], ["83967", "1", "0", "1"], ["83967.7", "0", "0", "0"], ["83977.6", "0.0008", "0", "2"], ["83978.4", "0.0004", "0", "1"], ["83979.2", "0", "0", "0"], ["83985.6", "0.08", "0", "2"], ["83986.4", "0.04357299", "0", "2"], ["83987.2", "0", "0", "0"], ["83988", "0", "0", "0"], ["84130.5", "0.11889794", "0", "1"], ["84131.1", "0.00008649", "0", "2"]], "bids": [["83946", "0.01264118", "0", "6"], ["83944", "0.0439", "0", "1"], ["83929.7", "1", "0", "1"], ["83929.6", "0.17869", "0", "1"], ["83925.7", "0.134785", "0", "1"], ["83912.8", "0.08", "0", "2"], ["83912", "0.040812", "0", "4"], ["83911.2", "0.00039951", "0", "1"], ["83910.4", "0", "0", "0"], ["83815.1", "0", "0", "0"], ["83815", "0", "0", "0"]], "ts": "1742577165500", "checksum": 1735303435, "seqId": 49945051191, "prevSeqId": 49945051155}], "record_time": 1742577165.670306, "EXCHANGE": "OKX"}
{"arg": {"channel": "books", "instId": "BTC-USDT"}, "action": "update", "data": [{"asks": [["83947.6", "0.12119965", "0", "2"], ["83966.6", "0.00101534", "0", "2"], ["83967", "0", "0", "0"], ["83968.4", "1.05628489", "0", "2"], ["83969.9", "0.23838376", "0", "1"], ["83987.9", "0", "0", "0"], ["83988", "0.01774536", "0", "1"]], "bids": [["83946", "0.00954118", "0", "5"], ["83945.1", "0.11918263", "0", "1"], ["83943.4", "0", "0", "0"], ["83931", "1", "0", "1"], ["83929.7", "0", "0", "0"], ["83920.5", "0.1836475", "0", "2"], ["83912.9", "0.23838376", "0", "1"], ["83912.1", "0", "0", "0"]], "ts": "1742577165600", "checksum": -114608988, "seqId": 49945051212, "prevSeqId": 49945051191}], "record_time": 1742577165.778025, "EXCHANGE": "OKX"}
{"arg": {"channel": "books", "instId": "BTC-USDT"}, "action": "update", "data": [{"asks": [["83945.2", "0.90731455", "0", "11"], ["83945.7", "0.1", "0", "1"], ["83945.9", "0.2047632", "0", "1"], ["83946", "0.05543238", "0", "2"], ["83946.1", "0.22658768", "0", "6"], ["83947.2", "0", "0", "0"], ["83947.6", "0.11917915", "0", "1"], ["83962.5", "0.23713804", "0", "1"], ["83964.2", "0.00003549", "0", "1"], ["83964.7", "0", "0", "0"], ["83966.6", "0.23940305", "0", "3"], ["83966.7", "1.85517907", "0", "7"], ["83968.4", "0.05628489", "0", "1"], ["83969.9", "0", "0", "0"], ["83984.9", "0", "0", "0"], ["83985.6", "0", "0", "0"], ["83986.4", "0.08357299", "0", "3"], ["83987.2", "0.03999999", "0", "1"], ["83989.9", "0.35738", "0", "1"], ["84130.5", "0", "0", "0"], ["84131.1", "0", "0", "0"]], "bids": [["83946", "0", "0", "0"], ["83944", "0", "0", "0"], ["83937.6", "0", "0", "0"], ["83937", "0.15835107", "0", "3"], ["83936.7", "0.2025", "0", "1"], ["83932.8", "0.22834696", "0", "1"], ["83931", "0", "0", "0"], ["83929.5", "0", "0", "0"], ["83922.6", "0.00714944", "0", "1"], ["83921.9", "0", "0", "0"], ["83915.8", "0.87129751", "0", "2"], ["83912.9", "0", "0", "0"], ["83912.8", "0", "0", "0"], ["83912.1", "0.23838448", "0", "1"], ["83912", "0.080012", "0", "3"], ["83911.2", "0.04079951", "0", "3"], ["83910.4", "0.00039951", "0", "1"], ["83904.3", "0.35738", "0", "1"], ["83880", "0.08812378", "0", "4"], ["83815.1", "0.00589964", "0", "1"], ["83815", "0.35776874", "0", "1"], ["83814.9", "0.0073937", "0", "2"]], "ts": "1742577165700", "checksum": -1369536120, "seqId": 49945051333, "prevSeqId": 49945051212}], "record_time": 1742577165.870815, "EXCHANGE": "OKX"}
{"arg": {"channel": "books", "instId": "BTC-USDT"}, "action": "update", "data": [{"asks": [["83945.9", "0.1447632", "0", "1"], ["83966.1", "0.23838656", "0", "1"], ["83966.6", "0.00101534", "0", "2"], ["83989.7", "0.1", "0", "1"], ["83990.6", "0.000015", "0", "1"], ["84129.9", "0", "0", "0"], ["84130.1", "0", "0", "0"]], "bids": [["83932.8", "0.49980359", "0", "2"], ["83930.6", "1", "0", "1"], ["83879.1", "0", "0", "0"], ["83878.6", "0", "0", "0"], ["83877.6", "0.00319422", "0", "2"], ["83877.5", "0", "0", "0"], ["83876.4", "0.00145293", "0", "1"]], "ts": "1742577165800", "checksum": 1348647581, "seqId": 49945051369, "prevSeqId": 49945051333}], "record_time": 1742577165.970938, "EXCHANGE": "OKX"}
{"arg": {"channel": "books", "instId": "BTC-USDT"}, "action": "update", "data": [{"asks": [["83945.2", "1.05898019", "0", "14"], ["83945.3", "0.17110553", "0", "1"], ["83945.4", "0.11918236", "0", "1"], ["83945.7", "0", "0", "0"], ["83945.9", "0.00066553", "0", "1"], ["83946", "0.0439", "0", "1"], ["83946.1", "0.22592464", "0", "5"], ["83947.6", "0", "0", "0"], ["83955.2", "0", "0", "0"], ["83964.4", "0.23850223", "0", "2"], ["83966.1", "0", "0", "0"], ["83985.6", "0.08", "0", "2"], ["83986.4", "0.04357299", "0", "2"], ["83987.2", "0", "0", "0"], ["84129.9", "3.72", "0", "1"], ["84130.1", "0.00001199", "0", "1"]], "bids": [["83945.1", "0.01789", "0", "1"], ["83942", "0.16518726", "0", "2"], ["83937", "0.10350338", "0", "2"], ["83936.7", "0", "0", "0"], ["83930.6", "0", "0", "0"], ["83929.2", "1", "0", "1"], ["83927.9", "0", "0", "0"], ["83920.5", "0.17869", "0", "1"], ["83912.1", "0", "0", "0"], ["83910.3", "0.23839062", "0", "1"], ["83831.7", "0", "0", "0"], ["83825.5", "0.18352201", "0", "2"], ["83814.4", "0.00005519", "0", "1"], ["83814.1", "0.00003395", "0", "1"], ["83813.8", "0.11936928", "0", "1"]], "ts": "1742577165900", "checksum": -1573954962, "seqId": 49945051410, "prevSeqId": 49945051369}], "record_time": 1742577166.070906, "EXCHANGE": "OKX"}
{"arg": {"channel": "books", "instId": "BTC-USDT"}, "action": "update", "data": [{"asks": [["83945.2", "1.26919019", "0", "16"], ["83945.3", "0.12469341", "0", "1"], ["83945.9", "0", "0", "0"], ["83946.1", "0.21571464", "0", "4"], ["83949.9", "0.16007858", "0", "1"], ["83953.8", "0.35697351", "0", "1"], ["83954.8", "0.003573", "0", "1"], ["83961.1", "0.08991011", "0", "1"], ["83962.3", "0.17847", "0", "1"], ["83962.5", "0.57901297", "0", "2"], ["83964.4", "0.00011161", "0", "1"], ["83964.5", "1.11889794", "0", "2"], ["83964.8", "0", "0", "0"], ["83966.1", "0.23839155", "0", "1"], ["83966.7", "0.85517907", "0", "6"], ["83986.4", "0.03999999", "0", "1"], ["83987.4", "0.35738", "0", "1"], ["83988.3", "0.02283169", "0", "1"], ["83989.9", "0", "0", "0"], ["84127.7", "0", "0", "0"], ["84129", "0", "0", "0"], ["84129.9", "0", "0", "0"], ["84130.1", "0", "0", "0"]], "bids": [["83945.1", "0.01775744", "0", "1"], ["83939.4", "0", "0", "0"], ["83937.1", "0.17898725", "0", "1"], ["83936.4", "0.016", "0", "1"], ["83933.2", "0.01191953", "0", "1"], ["83932.8", "0.22834696", "0", "1"], ["83932.5", "0.04", "0", "1"], ["83932", "0", "0", "0"], ["83930.2", "0.04", "0", "1"], ["83929.2", "0", "0", "0"], ["83928.6", "0.708895", "0", "2"], ["83927.4", "1", "0", "1"], ["83927.3", "0", "0", "0"], ["83926.1", "0.039", "0", "1"], ["83925.4", "0.00351261", "0", "1"], ["83917.2", "0", "0", "0"], ["83916.7", "0.02346359", "0", "2"], ["83910.3", "0", "0", "0"], ["83909.4", "0.23839409", "0", "1"], ["83892.8", "0.12506", "0", "1"]], "ts": "1742577166000", "checksum": 1534002594, "seqId": 49945051478, "prevSeqId": 49945051410}], "record_time": 1742577166.170929, "EXCHANGE": "OKX"}
{"arg": {"channel": "books", "instId": "BTC-USDT"}, "action": "update", "data": [{"asks": [["83945.2", "1.06919019", "0", "15"], ["83945.6", "0.000015", "0", "1"], ["83946", "0.04456553", "0", "2"], ["83957.6", "0.02", "0", "1"], ["83958.1", "0", "0", "0"], ["83966.1", "0", "0", "0"], ["83966.6", "0.23940483", "0", "3"], ["83968", "1.2", "0", "2"], ["83983.7", "0.01190708", "0", "1"], ["83983.9", "0", "0", "0"], ["83987.3", "0.01791756", "0", "2"], ["83988", "0", "0", "0"], ["84000.1", "0.00002157", "0", "1"], ["84001.3", "0", "0", "0"], ["84011.2", "0.01133139", "0", "1"], ["84016", "0.00001198", "0", "1"], ["84026.8", "0.25016", "0", "1"], ["84126.6", "0", "0", "0"], ["84127.5", "0", "0", "0"]], "bids": [["83945.1", "0.01914326", "0", "2"], ["83911.9", "0.23838949", "0", "1"], ["83909.4", "0", "0", "0"], ["83905", "1.2", "0", "2"], ["83898.2", "0", "0", "0"], ["83895.1", "0.01835609", "0", "1"], ["83879.9", "0.45266", "0", "2"], ["83877.7", "0.00319431", "0", "2"], ["83877.6", "0", "0", "0"], ["83858.1", "0", "0", "0"], ["83857.2", "0.00018341", "0", "1"], ["83827.6", "0", "0", "0"], ["83823.7", "0.18356099", "0", "1"], ["83813.8", "0", "0", "0"]], "ts": "1742577166100", "checksum": 1260595780, "seqId": 49945051542, "prevSeqId": 49945051478}], "record_time": 1742577166.273712, "EXCHANGE": "OKX"}
{"arg": {"channel": "books", "instId": "BTC-USDT"}, "action": "update", "data": [{"asks": [["83940.3", "1.01440654", "0", "14"], ["83941.6", "0.0428883", "0", "1"], ["83941.9", "0.20559981", "0", "1"], ["83942", "0.0439", "0", "1"], ["83942.1", "0.26813721", "0", "4"], ["83943.2", "0.1191855", "0", "1"], ["83944", "0.0439", "0", "1"], ["83944.2", "0.01021", "0", "1"], ["83945.1", "0.2", "0", "1"], ["83945.2", "0.052", "0", "2"], ["83945.3", "0", "0", "0"], ["83945.4", "0", "0", "0"], ["83946", "0.13913593", "0", "3"], ["83946.1", "0.20379559", "0", "3"], ["83946.6", "0.00001199", "0", "1"], ["83946.9", "0.03063", "0", "1"], ["83950.2", "0", "0", "0"], ["83952.9", "0", "0", "0"], ["83953.6", "0", "0", "0"], ["83953.9", "0.12994193", "0", "2"], ["83955.7", "0.11916772", "0", "1"], ["83955.9", "0.11889794", "0", "1"], ["83956.8", "0.04", "0", "1"], ["83961", "0.23840375", "0", "1"], ["83962.3", "0", "0", "0"], ["83962.5", "0.23713804", "0", "1"], ["83963.6", "1", "0", "1"], ["83964.5", "0.11889794", "0", "1"], ["83966.6", "0.00101534", "0", "2"], ["83967.8", "0", "0", "0"], ["83968", "0", "0", "0"], ["83973.5", "0", "0", "0"], ["83982.8", "0.53367", "0", "1"], ["83985.6", "0.07999999", "0", "2"], ["83987.4", "0", "0", "0"], ["83989.7", "0", "0", "0"], ["84000.2", "0.09737203", "0", "1"], ["84000.7", "0.01155464", "0", "1"], ["84009", "0.01133124", "0", "1"], ["84011.2", "0", "0", "0"], ["84091.7", "0", "0", "0"], ["84125", "0", "0", "0"], ["84125.1", "0", "0", "0"], ["84125.3", "0", "0", "0"], ["84125.6", "0", "0", "0"], ["84126.2", "0", "0", "0"]], "bids": [["83945.1", "0", "0", "0"], ["83944.1", "0", "0", "0"], ["83942", "0", "0", "0"], ["83941.8", "0", "0", "0"], ["83940.2", "0.05100008", "0", "2"], ["83940", "0.00001", "0", "1"], ["83939.8", "0.11919014", "0", "1"], ["83938.2", "0", "0", "0"], ["83938", "0", "0", "0"], ["83937.1", "0", "0", "0"], ["83937", "0.05628489", "0", "1"], ["83936.8", "0", "0", "0"], ["83936.4", "0", "0", "0"], ["83936.1", "0.02954855", "0", "1"], ["83935.1", "0", "0", "0"], ["83935", "0", "0", "0"], ["83933.2", "0.0077436", "0", "1"], ["83933.1", "0", "0", "0"], ["83932.8", "0.13753996", "0", "1"], ["83932.5", "0", "0", "0"], ["83931.4", "0", "0", "0"], ["83931", "0.01191984", "0", "1"], ["83929.6", "0", "0", "0"], ["83927.6", "0", "0", "0"], ["83927.4", "0", "0", "0"], ["83927.1", "0", "0", "0"], ["83927", "0.0139", "0", "1"], ["83926.7", "0", "0", "0"], ["83926.2", "0.045", "0", "1"], ["83925.7", "0", "0", "0"], ["83925.4", "0", "0", "0"], ["83925.1", "1", "0", "1"], ["83924.4", "0.10718885", "0", "2"], ["83923.9", "0", "0", "0"], ["83923.8", "0", "0", "0"], ["83922.7", "0.01192222", "0", "1"], ["83922.6", "0", "0", "0"], ["83922.5", "0", "0", "0"], ["83921.4", "0.03992302", "0", "1"], ["83920.8", "0.04", "0", "1"], ["83920.7", "0.0417", "0", "1"], ["83920.5", "0", "0", "0"], ["83917.7", "0.00714986", "0", "1"], ["83916.7", "0.0115549", "0", "1"], ["83915.8", "0.34884756", "0", "1"], ["83915.6", "1.61243592", "0", "2"], ["83915.5", "0.08629", "0", "1"], ["83914.3", "0.01190689", "0", "1"], ["83914.2", "0.01190738", "0", "1"], ["83913.8", "0.14071224", "0", "1"], ["83912", "0.000012", "0", "1"], ["83911.9", "0", "0", "0"], ["83911.2", "0.08", "0", "2"], ["83910.4", "0.04079951", "0", "3"], ["83909.6", "0.00039951", "0", "1"], ["83908.9", "0", "0", "0"], ["83908.8", "0.026", "0", "2"], ["83908", "0.013", "0", "1"], ["83906.5", "0", "0", "0"], ["83906.4", "0", "0", "0"], ["83906.2", "0.23840375", "0", "1"], ["83905.6", "0.11889794", "0", "1"], ["83905", "0", "0", "0"], ["83904.8", "0.27898725", "0", "3"], ["83904.3", "0", "0", "0"], ["83904", "0.05", "0", "1"], ["83900.8", "0.4", "0", "1"], ["83898.1", "0", "0", "0"], ["83896", "0.56728", "0", "1"], ["83895.6", "0", "0", "0"], ["83895.5", "0", "0", "0"], ["83895.1", "0", "0", "0"], ["83892.5", "0.01835596", "0", "1"], ["83877.7", "0.002187", "0", "1"], ["83876.5", "0.00100733", "0", "1"], ["83876.4", "0", "0", "0"], ["83875.3", "0.00146802", "0", "2"], ["83853.6", "0", "0", "0"], ["83853.3", "0.12479762", "0", "2"], ["83845.8", "0.00589968", "0", "1"], ["83839", "0.00591276", "0", "2"], ["83828.3", "0.01191003", "0", "1"], ["83823.7", "0", "0", "0"], ["83821.3", "0.18355961", "0", "1"], ["83813.8", "0.11936928", "0", "1"], ["83813.6", "0.03579964", "0", "2"], ["83813.5", "0.00002031", "0", "1"], ["83813.1", "0.00001199", "0", "1"], ["83812.6", "0.00579923", "0", "1"], ["83812.5", "0.00667459", "0", "3"], ["83812.4", "0.05367661", "0", "2"], ["83812.3", "0.01493332", "0", "1"], ["83812.1", "1.72263", "0", "1"], ["83812", "0.00589921", "0", "1"], ["83811.9", "0.0010552", "0", "1"], ["83811.3", "0.00074812", "0", "1"], ["83810.1", "0.00001655", "0", "1"], ["83810", "0.22033855", "0", "2"], ["83809.8", "0.00013882", "0", "1"], ["83809.7", "0.00001075", "0", "1"], ["83809.4", "0.00005977", "0", "1"], ["83809.2", "0.2025", "0", "1"]], "ts": "1742577166200", "checksum": -175532925, "seqId": 49945052001, "prevSeqId": 49945051542}], "record_time": 1742577166.373397, "EXCHANGE": "OKX"}
{"arg": {"channel": "books", "instId": "BTC-USDT"}, "action": "update", "data": [{"asks": [["83939.2", "1.74080963", "0", "18"], ["83939.8", "0.1359", "0", "2"], ["83940", "0.0439", "0", "1"], ["83940.1", "0.1", "0", "1"], ["83940.2", "0.90647456", "0", "6"], ["83940.3", "0.63229398", "0", "8"], ["83940.5", "0.08991011", "0", "1"], ["83940.7", "0.11918904", "0", "1"], ["83941.8", "0.02739775", "0", "1"], ["83941.9", "0.1443346", "0", "1"], ["83942.1", "0.06391984", "0", "3"], ["83943.2", "0", "0", "0"], ["83945.6", "0", "0", "0"], ["83946.4", "0.02", "0", "1"], ["83949.9", "0.35069914", "0", "1"], ["83950.2", "0.08991011", "0", "1"], ["83950.8", "0.17898725", "0", "1"], ["83952.1", "0.3574", "0", "1"], ["83952.3", "0.1837", "0", "2"], ["83955", "0.01021", "0", "1"], ["83955.1", "0.04774281", "0", "2"], ["83957.6", "0", "0", "0"], ["83957.9", "0.24041351", "0", "2"], ["83958.4", "0.45105317", "0", "2"], ["83959.9", "1.00351064", "0", "2"], ["83960.3", "0", "0", "0"], ["83961", "0", "0", "0"], ["83963.5", "0", "0", "0"], ["83963.6", "0", "0", "0"], ["83968.4", "0.11256978", "0", "2"], ["83979.2", "0.0196305", "0", "1"], ["83987.3", "0.0001722", "0", "1"], ["83988", "0.01774536", "0", "1"], ["83997.8", "0", "0", "0"], ["84003", "0.824159", "0", "1"], ["84005.2", "0", "0", "0"], ["84005.7", "0", "0", "0"], ["84007.9", "0", "0", "0"], ["84018.7", "0", "0", "0"], ["84026.8", "0", "0", "0"], ["84032.3", "0", "0", "0"], ["84037.7", "0", "0", "0"], ["84072.1", "0.02015662", "0", "2"], ["84082.3", "0.00011161", "0", "1"], ["84085.9", "0", "0", "0"], ["84088.9", "0.01191324", "0", "2"], ["84099.1", "0", "0", "0"]], "bids": [["83940.2", "0", "0", "0"], ["83940", "0", "0", "0"], ["83939.8", "0", "0", "0"], ["83939.7", "0", "0", "0"], ["83936.1", "0", "0", "0"], ["83935.7", "0.11919597", "0", "1"], ["83934.7", "0", "0", "0"], ["83934", "0.0439", "0", "1"], ["83931.6", "0", "0", "0"], ["83931", "0", "0", "0"], ["83930.2", "0", "0", "0"], ["83928.8", "0.02164294", "0", "2"], ["83928.6", "0.35320512", "0", "1"], ["83928.3", "0", "0", "0"], ["83926.9", "0.04001199", "0", "2"], ["83926.2", "0", "0", "0"], ["83926.1", "0", "0", "0"], ["83925.7", "0.0119206", "0", "1"], ["83925.3", "0", "0", "0"], ["83925.1", "0", "0", "0"], ["83924.4", "0.51141967", "0", "2"], ["83923", "0.0428883", "0", "1"], ["83922.2", "1", "0", "1"], ["83922.1", "0.1787", "0", "1"], ["83921.9", "0.3574", "0", "1"], ["83915.8", "0.16886021", "0", "1"], ["83915.6", "0", "0", "0"], ["83914.8", "0.02384013", "0", "1"], ["83912.9", "0.1787", "0", "1"], ["83911.2", "0", "0", "0"], ["83910.4", "0", "0", "0"], ["83909.6", "0", "0", "0"], ["83909.3", "0", "0", "0"], ["83908.8", "0", "0", "0"], ["83908", "0", "0", "0"], ["83906.4", "0.08", "0", "2"], ["83906.2", "0", "0", "0"], ["83905.6", "0.15969747", "0", "4"], ["83904.8", "0.17938679", "0", "2"], ["83904", "0.026", "0", "2"], ["83903.2", "0.013", "0", "1"], ["83903.1", "0", "0", "0"], ["83902.9", "0.23841351", "0", "1"], ["83901.3", "0", "0", "0"], ["83900", "0.10047203", "0", "4"], ["83899.2", "0.31097436", "0", "2"], ["83895", "0.09228489", "0", "2"], ["83894.8", "0", "0", "0"], ["83889.8", "0.825269", "0", "1"], ["83883.4", "0.01789162", "0", "1"], ["83877.7", "0", "0", "0"], ["83876.5", "0", "0", "0"], ["83875.3", "0.000015", "0", "1"], ["83873.5", "0.00100741", "0", "1"], ["83872.3", "0.00364015", "0", "2"], ["83871.1", "0", "0", "0"], ["83842.6", "1.08010425", "0", "2"], ["83822.3", "0.00589964", "0", "1"], ["83811.8", "0.00595662", "0", "1"], ["83808.7", "0.000015", "0", "1"], ["83808.2", "0.00001199", "0", "1"], ["83808", "0.00015274", "0", "2"], ["83807.9", "0.00001018", "0", "1"], ["83807.8", "0.00589964", "0", "1"], ["83807.7", "0.00579964", "0", "1"], ["83807.5", "0.03", "0", "1"], ["83807.4", "0.11889794", "0", "1"], ["83807.3", "0.00011161", "0", "1"], ["83807.1", "0.00001527", "0", "1"], ["83806.6", "0.00001217", "0", "1"], ["83806.3", "0.00579923", "0", "1"], ["83805.6", "0.00001394", "0", "1"]], "ts": "1742577166300", "checksum": -1285244414, "seqId": 49945052359, "prevSeqId": 49945052001}], "record_time": 1742577166.471502, "EXCHANGE": "OKX"}
{"arg": {"channel": "books", "instId": "BTC-USDT"}, "action": "update", "data": [{"asks": [["83936.1", "0.36117505", "0", "5"], ["83937.9", "0.03392218", "0", "1"], ["83938", "0.0439", "0", "1"], ["83939.2", "0.0119206", "0", "1"], ["83939.7", "0.00112008", "0", "1"], ["83939.8", "0", "0", "0"], ["83940.1", "0", "0", "0"], ["83940.2", "0", "0", "0"], ["83940.3", "0.05613326", "0", "2"], ["83940.5", "0", "0", "0"], ["83940.7", "0", "0", "0"], ["83941.9", "0", "0", "0"], ["83942", "0.18282505", "0", "2"], ["83942.1", "0.052", "0", "2"], ["83944.2", "0", "0", "0"], ["83945.1", "0", "0", "0"], ["83945.4", "0.35697351", "0", "1"], ["83945.8", "0.02", "0", "1"], ["83946.4", "0", "0", "0"], ["83946.9", "0", "0", "0"], ["83948.3", "0", "0", "0"], ["83948.6", "0.00001501", "0", "1"], ["83950.2", "0", "0", "0"], ["83953.9", "0.15994722", "0", "1"], ["83957.9", "0.002", "0", "1"], ["83958.4", "0.48105317", "0", "3"], ["83959.2", "0.03", "0", "1"], ["83959.9", "0.00351064", "0", "1"], ["83960", "0.00004", "0", "1"], ["83962", "0", "0", "0"], ["83964.4", "0.23851284", "0", "2"], ["83964.7", "0.02383099", "0", "1"], ["83966.7", "0.82517907", "0", "5"], ["83968.2", "0.18761632", "0", "1"], ["83984.9", "0.02653166", "0", "1"], ["83986.1", "0", "0", "0"], ["83988.1", "0", "0", "0"], ["83988.9", "0", "0", "0"], ["83995.2", "0.00002157", "0", "1"], ["84000.1", "0", "0", "0"], ["84045", "0.18438725", "0", "2"], ["84058.5", "0.00251872", "0", "1"], ["84080.1", "0", "0", "0"], ["84125", "0.00009264", "0", "1"], ["84125.1", "0.00015069", "0", "2"], ["84125.3", "0.00001956", "0", "1"], ["84125.6", "0.14264386", "0", "2"], ["84126.2", "0.00001805", "0", "1"]], "bids": [["83939.1", "0", "0", "0"], ["83937", "0", "0", "0"], ["83936", "0.7201391", "0", "10"], ["83934.9", "0.06899727", "0", "1"], ["83933.2", "0", "0", "0"], ["83932.8", "0", "0", "0"], ["83932.5", "0.06189637", "0", "1"], ["83932.4", "0", "0", "0"], ["83932", "0.0439", "0", "1"], ["83931.1", "0.00056102", "0", "1"], ["83927", "0", "0", "0"], ["83925.4", "1", "0", "1"], ["83922.2", "0", "0", "0"], ["83922", "0.01391199", "0", "2"], ["83921.9", "0", "0", "0"], ["83920.7", "0", "0", "0"], ["83920.2", "0.084", "0", "2"], ["83919", "0.134781", "0", "1"], ["83918.9", "0.02859924", "0", "1"], ["83917.7", "0", "0", "0"], ["83917.5", "0", "0", "0"], ["83917.4", "0.18761632", "0", "1"], ["83915.8", "0.11668023", "0", "1"], ["83915.7", "0.0417", "0", "1"], ["83915", "0.00476673", "0", "1"], ["83913.5", "0.02315022", "0", "2"], ["83912.9", "0", "0", "0"], ["83908.2", "0.23840445", "0", "1"], ["83906.4", "0", "0", "0"], ["83905.6", "0.11889794", "0", "1"], ["83904.9", "1.55759413", "0", "1"], ["83904.8", "0.17898725", "0", "1"], ["83904", "0.08", "0", "2"], ["83903.2", "0.04079954", "0", "3"], ["83902.9", "0", "0", "0"], ["83902.4", "0.00039955", "0", "1"], ["83901.6", "0.026", "0", "2"], ["83900.8", "0.413", "0", "2"], ["83900", "0.00047203", "0", "2"], ["83899.2", "0.26097436", "0", "1"], ["83898.5", "0.05208", "0", "1"], ["83898.4", "0.1", "0", "2"], ["83897.6", "0.05", "0", "1"], ["83895", "0.14856978", "0", "3"], ["83892.8", "0.71265126", "0", "2"], ["83891.6", "0", "0", "0"], ["83889.9", "0.56", "0", "1"], ["83873.5", "0", "0", "0"], ["83872.3", "0.00218703", "0", "1"], ["83871.8", "0.1251", "0", "1"], ["83869.2", "0.00100747", "0", "1"], ["83867.5", "0.00146816", "0", "2"], ["83857.2", "0", "0", "0"], ["83841.5", "0.6", "0", "1"], ["83807.3", "0", "0", "0"], ["83807.1", "0", "0", "0"], ["83806.6", "0", "0", "0"], ["83806.3", "0", "0", "0"], ["83805.6", "0", "0", "0"]], "ts": "1742577166400", "checksum": -1322688420, "seqId": 49945052662, "prevSeqId": 49945052359}], "record_time": 1742577166.571349, "EXCHANGE": "OKX"}
{"arg": {"channel": "books", "instId": "BTC-USDT"}, "action": "update", "data": [{"asks": [["83936.1", "0.35321591", "0", "5"], ["83937", "0.01192029", "0", "1"], ["83937.9", "0.06069322", "0", "2"], ["83939.2", "0", "0", "0"], ["83939.3", "0.11919103", "0", "1"], ["83940.3", "0.04013326", "0", "1"], ["83941.1", "0.00018", "0", "1"], ["83944", "0.05543238", "0", "2"], ["83946.1", "0.20265303", "0", "2"], ["83954.8", "0", "0", "0"], ["83955.1", "0.10774281", "0", "4"], ["83958.4", "0.27279939", "0", "4"], ["83963.3", "0", "0", "0"], ["83980.6", "0.1", "0", "1"], ["83988", "0", "0", "0"], ["83996.9", "0.00103644", "0", "1"], ["84003.6", "0.00119042", "0", "1"], ["84007.3", "0.01133124", "0", "1"], ["84007.9", "0.01428437", "0", "1"], ["84009", "0", "0", "0"], ["84014.1", "0.044992", "0", "1"], ["84043.8", "0.01774536", "0", "1"], ["84125.1", "0", "0", "0"], ["84125.3", "0", "0", "0"], ["84125.6", "0", "0", "0"], ["84126.2", "0", "0", "0"]], "bids": [["83928.6", "0.58806572", "0", "2"], ["83927.9", "0.01192029", "0", "1"], ["83927.1", "0.17871", "0", "1"], ["83926.7", "1", "0", "1"], ["83925.7", "0", "0", "0"], ["83925.4", "0", "0", "0"], ["83924.4", "0.16668833", "0", "1"], ["83922.9", "0.069", "0", "2"], ["83922.1", "0", "0", "0"], ["83919.6", "0.069", "0", "2"], ["83917.9", "0.178725", "0", "2"], ["83916.4", "0.003", "0", "1"], ["83904.8", "0.22403825", "0", "2"], ["83892.5", "0", "0", "0"], ["83892.4", "0.03", "0", "1"], ["83888.9", "0.01835715", "0", "1"], ["83879.9", "0.2025", "0", "1"], ["83872.3", "0", "0", "0"], ["83868.4", "0.00218713", "0", "1"], ["83852.3", "0.00018342", "0", "1"], ["83821.3", "0", "0", "0"], ["83818.1", "0.18363963", "0", "4"], ["83807.7", "0", "0", "0"], ["83807.5", "0", "0", "0"], ["83807.4", "0", "0", "0"]], "ts": "1742577166500", "checksum": 702619743, "seqId": 49945052732, "prevSeqId": 49945052662}], "record_time": 1742577166.6705, "EXCHANGE": "OKX"}
{"arg": {"channel": "books", "instId": "BTC-USDT"}, "action": "update", "data": [{"asks": [["83945.7", "0.01021", "0", "1"], ["83946", "0.1384704", "0", "2"], ["83952", "0.07453", "0", "2"], ["83963.9", "0.25019", "0", "1"], ["83966.7", "0.76517907", "0", "3"], ["83984.9", "0.27672166", "0", "2"], ["83991.5", "0.00002157", "0", "1"], ["83995.2", "0", "0", "0"], ["84123.7", "0", "0", "0"], ["84125", "0", "0", "0"]], "bids": [["83932", "0.05779", "0", "2"], ["83927.1", "0", "0", "0"], ["83925.7", "0.0417", "0", "1"], ["83922", "0.00001199", "0", "1"], ["83917.9", "0.000015", "0", "1"], ["83915.7", "0", "0", "0"], ["83900.9", "0.25019", "0", "1"], ["83879.9", "0.45269", "0", "2"], ["83852.3", "0", "0", "0"], ["83847.5", "0.00018343", "0", "1"]], "ts": "1742577166600", "checksum": 1508702980, "seqId": 49945052756, "prevSeqId": 49945052732}], "record_time": 1742577166.770826, "EXCHANGE": "OKX"}
{"arg": {"channel": "books", "instId": "BTC-USDT"}, "action": "update", "data": [{"asks": [["83945.1", "0.11889794", "0", "1"], ["83945.8", "0.02066678", "0", "2"], ["83965", "0", "0", "0"], ["83966.7", "0.73517907", "0", "2"], ["83971.1", "0.11067274", "0", "1"], ["84123.6", "0", "0", "0"]], "bids": [["83929", "0.00774398", "0", "1"], ["83928", "1.2025", "0", "2"], ["83926.7", "0", "0", "0"], ["83923.4", "0.00353799", "0", "1"], ["83907.4", "0.88399629", "0", "2"], ["83892.4", "0", "0", "0"], ["83880", "0.15195742", "0", "5"]], "ts": "1742577166700", "checksum": 1274605812, "seqId": 49945052768, "prevSeqId": 49945052756}], "record_time": 1742577166.870701, "EXCHANGE": "OKX"}
{"arg": {"channel": "books", "instId": "BTC-USDT"}, "action": "update", "data": [{"asks": [["83936.1", "0.37287735", "0", "6"], ["83977.6", "0.0808", "0", "4"], ["83978.4", "0.04039999", "0", "2"], ["83985.6", "0", "0", "0"], ["83986.4", "0", "0", "0"], ["84123.6", "0.00126715", "0", "1"], ["84123.7", "0.00005514", "0", "1"]], "bids": [["83936", "0.72040133", "0", "11"], ["83924.4", "0.27066969", "0", "2"], ["83921.9", "0.35741", "0", "1"], ["83912.9", "0.17871", "0", "1"], ["83904.8", "0.30403825", "0", "4"], ["83904", "0.04", "0", "1"], ["83903.2", "0.00079954", "0", "2"], ["83899.2", "0.36097436", "0", "3"], ["83898.4", "0.05", "0", "1"], ["83897.6", "0", "0", "0"], ["83807.8", "0", "0", "0"]], "ts": "1742577166800", "checksum": 68977442, "seqId": 49945052789, "prevSeqId": 49945052768}], "record_time": 1742577166.970853, "EXCHANGE": "OKX"}
{"arg": {"channel": "books", "instId": "BTC-USDT"}, "action": "update", "data": [{"asks": [["83936.1", "0.28627735", "0", "5"], ["83941.1", "0", "0", "0"], ["83942.1", "0.036", "0", "1"], ["83960.9", "1", "0", "1"], ["83971.2", "0.35777351", "0", "3"], ["83972", "0.0004", "0", "1"], ["83977.6", "0", "0", "0"], ["83978.4", "0", "0", "0"], ["83979.2", "0.0996305", "0", "3"], ["83980", "0.03999999", "0", "1"], ["84003.6", "0", "0", "0"], ["84007.9", "0", "0", "0"], ["84125", "0.00009264", "0", "1"], ["84125.1", "0.00015069", "0", "2"]], "bids": [["83936", "0.72367133", "0", "12"], ["83924.4", "0.16668833", "0", "1"], ["83921.9", "0", "0", "0"], ["83913.8", "0.26581224", "0", "2"], ["83912.9", "0", "0", "0"], ["83904.8", "0.22403825", "0", "2"], ["83904", "0.08", "0", "2"], ["83903.2", "0.04079954", "0", "3"], ["83899.2", "0.26097436", "0", "1"], ["83898.4", "0.1", "0", "2"], ["83897.6", "0.05", "0", "1"], ["83871.8", "0", "0", "0"], ["83851.5", "0", "0", "0"], ["83849", "0", "0", "0"], ["83807.8", "0.00589964", "0", "1"], ["83807.7", "0.00579964", "0", "1"], ["83807.5", "0.03", "0", "1"], ["83807.4", "0.11889794", "0", "1"]], "ts": "1742577166900", "checksum": -205656019, "seqId": 49945052830, "prevSeqId": 49945052789}], "record_time": 1742577167.070947, "EXCHANGE": "OKX"}
{"arg": {"channel": "books", "instId": "BTC-USDT"}, "action": "update", "data": [{"asks": [["83942.1", "0", "0", "0"], ["83945.5", "0.006267", "0", "1"], ["83960.9", "0", "0", "0"], ["83979.2", "0.09963049", "0", "3"], ["84006.4", "0.00119038", "0", "1"], ["84011.7", "0.01428372", "0", "1"], ["84125.1", "0", "0", "0"]], "bids": [["83932.5", "0.36064951", "0", "2"], ["83929.8", "1", "0", "1"], ["83928.6", "0.35320512", "0", "1"], ["83928", "0.2025", "0", "1"], ["83926.7", "0.0428883", "0", "1"], ["83924.6", "0.17871", "0", "1"], ["83924.4", "0.47521324", "0", "2"], ["83923", "0", "0", "0"], ["83914.2", "0", "0", "0"], ["83901.1", "0.01192402", "0", "2"], ["83844.8", "0.00219536", "0", "2"], ["83841.8", "0.0151792", "0", "1"], ["83807.5", "0", "0", "0"], ["83807.4", "0", "0", "0"]], "ts": "1742577167000", "checksum": -1286331123, "seqId": 49945052855, "prevSeqId": 49945052830}], "record_time": 1742577167.171184, "EXCHANGE": "OKX"}
{"arg": {"channel": "books", "instId": "BTC-USDT"}, "action": "update", "data": [{"asks": [["83936.1", "0.26304267", "0", "3"], ["83937.9", "0.03392218", "0", "1"], ["83939.3", "0", "0", "0"], ["83940.3", "0", "0", "0"], ["83941.5", "0.2402033", "0", "1"], ["83941.6", "0.16207607", "0", "2"], ["83942", "0.0439", "0", "1"], ["83945.2", "0.036", "0", "1"], ["83945.5", "0", "0", "0"], ["83946", "0.07347401", "0", "2"], ["83946.1", "0.00015303", "0", "1"], ["83948.1", "0.0047805", "0", "1"], ["83958.4", "0.09", "0", "3"], ["83961.1", "0", "0", "0"], ["83963.3", "0.00357324", "0", "1"], ["84125.1", "0.00015069", "0", "2"]], "bids": [["83936", "0.9372579", "0", "14"], ["83935.8", "0.07085991", "0", "1"], ["83917.9", "0.178725", "0", "2"], ["83913.4", "0", "0", "0"], ["83902", "0.01226888", "0", "2"], ["83886", "0.03422575", "0", "2"]], "ts": "1742577167100", "checksum": -1009421162, "seqId": 49945052894, "prevSeqId": 49945052855}], "record_time": 1742577167.271204, "EXCHANGE": "OKX"}
{"arg": {"channel": "books", "instId": "BTC-USDT"}, "action": "update", "data": [{"asks": [["83961", "1", "0", "1"], ["83966.8", "0", "0", "0"], ["83968", "1.2", "0", "2"], ["83995.8", "0.28114942", "0", "1"], ["83996.2", "0.22265782", "0", "2"], ["84125.1", "0", "0", "0"]], "bids": [["83914.3", "0", "0", "0"], ["83904.9", "0", "0", "0"], ["83904", "1.08", "0", "3"], ["83902", "0.22417752", "0", "4"], ["83886.4", "0", "0", "0"], ["83886.3", "0.00579988", "0", "1"], ["83807.5", "0.03", "0", "1"], ["83807.4", "0.11889794", "0", "1"], ["83807.3", "0.00011161", "0", "1"]], "ts": "1742577167200", "checksum": -1009421162, "seqId": 49945052911, "prevSeqId": 49945052894}], "record_time": 1742577167.3709, "EXCHANGE": "OKX"}
{"arg": {"channel": "books", "instId": "BTC-USDT"}, "action": "update", "data": [{"asks": [["83936.1", "0.12973", "0", "2"], ["83945.5", "0.05231117", "0", "1"], ["83945.6", "0.04013326", "0", "1"], ["83945.7", "0", "0", "0"], ["83946", "0.0439", "0", "1"], ["83948.1", "0", "0", "0"], ["83950.5", "0.01021", "0", "1"], ["83952", "0.0439", "0", "1"], ["83953.1", "0.13478", "0", "1"], ["83956.8", "0.07062", "0", "2"], ["83959.9", "1.61305615", "0", "2"], ["83964.4", "0.00011161", "0", "1"], ["83966.1", "0.2383957", "0", "1"], ["83968.9", "0", "0", "0"], ["83989.3", "3.02193853", "0", "3"], ["84123.7", "0", "0", "0"], ["84125", "0", "0", "0"]], "bids": [["83936", "0.9511479", "0", "15"], ["83932.5", "0.06189637", "0", "1"], ["83932", "0.0439", "0", "1"], ["83930.6", "0.04169", "0", "1"], ["83929.8", "0", "0", "0"], ["83928.6", "0.7693287", "0", "2"], ["83928.3", "1", "0", "1"], ["83925.7", "0", "0", "0"], ["83917", "0.00001199", "0", "1"], ["83915.4", "0.17871", "0", "1"], ["83910.3", "0.2383957", "0", "1"], ["83908.2", "0", "0", "0"], ["83904.9", "1.60392017", "0", "1"], ["83875.5", "2.87962289", "0", "1"], ["83807.5", "0", "0", "0"], ["83807.4", "0", "0", "0"], ["83807.3", "0", "0", "0"]], "ts": "1742577167300", "checksum": 844423674, "seqId": 49945052942, "prevSeqId": 49945052911}], "record_time": 1742577167.47021, "EXCHANGE": "OKX"}
{"arg": {"channel": "books", "instId": "BTC-USDT"}, "action": "update", "data": [{"asks": [["83936.1", "0.04313", "0", "1"], ["83945.3", "0.000015", "0", "1"], ["83970.4", "0.0008", "0", "2"], ["83971.2", "0.35737351", "0", "2"], ["83972", "0", "0", "0"], ["83978.4", "0.08", "0", "2"], ["83979.2", "0.05963049", "0", "2"], ["83980", "0", "0", "0"], ["84039", "0.1", "0", "1"], ["84122.3", "0", "0", "0"], ["84123.6", "0", "0", "0"]], "bids": [["83936", "0.9518379", "0", "16"], ["83913.6", "0", "0", "0"], ["83911.6", "0", "0", "0"], ["83907.9", "0", "0", "0"], ["83904", "1.0808", "0", "5"], ["83903.2", "0.04039954", "0", "2"], ["83902.4", "0", "0", "0"], ["83900.4", "0.01190909", "0", "1"], ["83898.6", "0.5776526", "0", "1"], ["83869.8", "0.2808453", "0", "1"], ["83865.9", "0.00715427", "0", "1"], ["83856.6", "0.58226341", "0", "1"], ["83807.5", "0.03", "0", "1"]], "ts": "1742577167400", "checksum": -1431599760, "seqId": 49945052968, "prevSeqId": 49945052942}], "record_time": 1742577167.57092, "EXCHANGE": "OKX"}
{"arg": {"channel": "books", "instId": "BTC-USDT"}, "action": "update", "data": [{"asks": [["83949.9", "0.2344517", "0", "1"], ["83952.1", "0", "0", "0"], ["83952.3", "0.005", "0", "1"], ["83954.7", "0.35741", "0", "1"], ["83966.1", "0", "0", "0"], ["83968.9", "0.23839084", "0", "1"], ["83988.3", "0", "0", "0"], ["84122.3", "0.08764", "0", "1"]], "bids": [["83932.5", "0.36898951", "0", "2"], ["83929.9", "1.016", "0", "2"], ["83928.6", "0.35320512", "0", "1"], ["83928.3", "0", "0", "0"], ["83915.4", "0", "0", "0"], ["83911.9", "0.23839084", "0", "1"], ["83910.3", "0", "0", "0"], ["83908", "0.00036", "0", "1"], ["83807.4", "0.11889794", "0", "1"]], "ts": "1742577167500", "checksum": -2065497033, "seqId": 49945052985, "prevSeqId": 49945052968}], "record_time": 1742577167.670543, "EXCHANGE": "OKX"}
{"arg": {"channel": "books", "instId": "BTC-USDT"}, "action": "update", "data": [{"asks": [["83953.9", "0.27329091", "0", "2"]], "bids": [], "ts": "1742577167600", "checksum": -2065497033, "seqId": 49945052991, "prevSeqId": 49945052985}], "record_time": 1742577167.771074, "EXCHANGE": "OKX"}
{"arg": {"channel": "books", "instId": "BTC-USDT"}, "action": "update", "data": [{"asks": [["83941.6", "0.11918777", "0", "1"], ["83945.5", "0.09519947", "0", "2"]], "bids": [], "ts": "1742577167700", "checksum": -1857966546, "seqId": 49945052994, "prevSeqId": 49945052991}], "record_time": 1742577167.871342, "EXCHANGE": "OKX"}
{"arg": {"channel": "books", "instId": "BTC-USDT"}, "action": "update", "data": [{"asks": [["83959.8", "0.78393244", "0", "1"], ["83978.4", "0", "0", "0"], ["83979.2", "0.09963049", "0", "3"], ["83980", "0.03999999", "0", "1"], ["83988.6", "1.12904481", "0", "2"], ["84122.3", "0", "0", "0"]], "bids": [["83899.2", "0.6439819", "0", "2"], ["83857.1", "1.23181201", "0", "6"]], "ts": "1742577167800", "checksum": -1857966546, "seqId": 49945053002, "prevSeqId": 49945052994}], "record_time": 1742577167.970351, "EXCHANGE": "OKX"}
{"arg": {"channel": "books", "instId": "BTC-USDT"}, "action": "update", "data": [{"asks": [["83959.8", "0", "0", "0"], ["83959.9", "2.61305615", "0", "3"], ["83961", "0", "0", "0"], ["84122.3", "0.08764", "0", "1"], ["84123.6", "0.00126715", "0", "1"]], "bids": [["83936", "0.9518479", "0", "17"], ["83932.5", "0.06189637", "0", "1"], ["83929.9", "0.016", "0", "1"], ["83928.6", "0.7568187", "0", "2"], ["83928.3", "1", "0", "1"], ["83807.4", "0", "0", "0"]], "ts": "1742577167900", "checksum": 1643088961, "seqId": 49945053012, "prevSeqId": 49945053002}], "record_time": 1742577168.075558, "EXCHANGE": "OKX"}
{"arg": {"channel": "books", "instId": "BTC-USDT"}, "action": "update", "data": [{"asks": [["83936.1", "0.12973", "0", "2"], ["83944.5", "0.2025", "0", "1"], ["83953.9", "0.15994722", "0", "1"], ["83954.7", "0", "0", "0"], ["83958.5", "1.2025", "0", "2"], ["83959.9", "1.61305615", "0", "2"], ["83963.3", "0", "0", "0"], ["83991.6", "0.37975435", "0", "2"], ["84123.7", "0.00005514", "0", "1"]], "bids": [["83936", "0.7518479", "0", "16"], ["83928.3", "0", "0", "0"], ["83927", "1", "0", "1"], ["83902", "0.02417752", "0", "3"]], "ts": "1742577168000", "checksum": -1147499833, "seqId": 49945053025, "prevSeqId": 49945053012}], "record_time": 1742577168.171811, "EXCHANGE": "OKX"}
