{"arg": {"channel": "books", "instId": "BTC-USDT"}, "action": "update", "data": [{"asks": [["88528", "0.20086921", "0", "6"], ["88528.4", "0.00129879", "0", "3"], ["88528.8", "0.005", "0", "1"], ["88529.3", "0.04360879", "0", "1"], ["88529.4", "0.11295464", "0", "1"], ["88529.8", "0.00012635", "0", "3"], ["88530.3", "0.0001", "0", "1"], ["88533.1", "0.07330902", "0", "2"], ["88535.7", "0.02758606", "0", "2"], ["88535.9", "0.02690037", "0", "2"], ["88536.1", "0.02747516", "0", "1"], ["88536.2", "0.02767968", "0", "1"], ["88538", "0.09430977", "0", "2"], ["88539.4", "0.08361973", "0", "1"], ["88540", "0.16976521", "0", "6"], ["88540.4", "0.07875236", "0", "1"], ["88540.5", "0.00072792", "0", "3"], ["88540.8", "0.000015", "0", "1"], ["88543", "0.08318186", "0", "3"], ["88543.1", "0.13417772", "0", "2"], ["88543.5", "0.13809383", "0", "2"], ["88544.9", "0.14004604", "0", "1"], ["88545.9", "0.06131616", "0", "3"], ["88546.1", "0.3227207", "0", "1"], ["88546.2", "0.18002555", "0", "2"], ["88548.6", "0", "0", "0"], ["88552.4", "0.00338997", "0", "1"], ["88556", "0.00001349", "0", "1"], ["88556.4", "0.012102", "0", "1"], ["88563.2", "0.15510154", "0", "1"], ["88563.3", "0.22590436", "0", "1"], ["88563.4", "0", "0", "0"], ["88566.8", "0.0000907", "0", "1"], ["88595.9", "0", "0", "0"], ["88599.3", "0.0173942", "0", "1"], ["88613.2", "0", "0", "0"], ["88614.1", "0.01128489", "0", "1"], ["88616.7", "0", "0", "0"], ["88616.8", "0", "0", "0"], ["88617.6", "0", "0", "0"], ["88617.9", "0", "0", "0"], ["88618.2", "0", "0", "0"], ["88618.5", "0", "0", "0"], ["88618.7", "0", "0", "0"]], "bids": [["88527.9", "0.29911783", "0", "9"], ["88526.8", "0.0001", "0", "1"], ["88526.3", "0.0001", "0", "1"], ["88525.5", "0", "0", "0"], ["88518.5", "0.17748169", "0", "5"], ["88518.4", "0.02858932", "0", "1"], ["88518", "0.04454471", "0", "2"], ["88517.8", "0.02697024", "0", "1"], ["88514.7", "0.55354125", "0", "2"], ["88514.5", "0.08129624", "0", "1"], ["88513.9", "0.07922228", "0", "1"], ["88513.7", "0.07860057", "0", "1"], ["88511.4", "0.12351924", "0", "1"], ["88510.5", "0.13508628", "0", "1"], ["88509.2", "0.14156911", "0", "1"], ["88507.7", "0.13886084", "0", "1"], ["88507.2", "0.01650401", "0", "1"], ["88507.1", "0.22590436", "0", "1"], ["88506.7", "0", "0", "0"], ["88480", "0.05194673", "0", "2"], ["88476.1", "0.0173942", "0", "1"], ["88474.9", "0", "0", "0"], ["88474", "0.01128489", "0", "1"], ["88472.3", "0", "0", "0"], ["88466.1", "1.15733902", "0", "2"], ["88463.6", "2.93714918", "0", "1"], ["88453.2", "0.21979143", "0", "1"], ["88434.4", "0.00007205", "0", "1"], ["88423.1", "0.0052401", "0", "2"], ["88400.8", "0.173942", "0", "1"], ["88398.8", "0", "0", "0"], ["88397.8", "0", "0", "0"], ["88397", "0.01128636", "0", "1"], ["88391.8", "0", "0", "0"], ["88380.5", "0", "0", "0"], ["88296.3", "0", "0", "0"]], "ts": "1741338232805", "checksum": 1268266362, "seqId": 48070577974, "prevSeqId": 48070577722}]}
{"arg": {"channel": "books", "instId": "BTC-USDT"}, "action": "update", "data": [{"asks": [["88528.4", "0.00330881", "0", "5"], ["88535.8", "0.03783263", "0", "3"], ["88535.9", "0.00025932", "0", "1"], ["88536", "0.02647515", "0", "1"], ["88536.1", "0", "0", "0"], ["88537.9", "0.000162", "0", "1"], ["88543", "0.22204305", "0", "4"], ["88543.1", "0.00131779", "0", "1"], ["88555.9", "0.012102", "0", "1"], ["88556.4", "0", "0", "0"], ["88559.5", "0.56239463", "0", "5"], ["88561.1", "0.2259222", "0", "2"], ["88563.2", "0", "0", "0"], ["88563.3", "0", "0", "0"], ["88566.8", "0.0741952", "0", "2"], ["88616.7", "0.00006147", "0", "2"]], "bids": [["88527.9", "0.26069857", "0", "10"], ["88527.5", "0", "0", "0"], ["88527.4", "0", "0", "0"], ["88526.8", "0", "0", "0"], ["88526.7", "0.00145491", "0", "1"], ["88524.7", "0.11296054", "0", "1"], ["88518.5", "0.15295865", "0", "4"], ["88518.4", "0.05423755", "0", "2"], ["88514.7", "0.46402493", "0", "1"], ["88514.6", "0.987874", "0", "2"], ["88514.5", "0", "0", "0"], ["88514.4", "0.08369531", "0", "1"], ["88513.9", "0", "0", "0"], ["88513.8", "0.08862561", "0", "1"], ["88512.6", "0.05204673", "0", "3"], ["88508.2", "0.104236", "0", "2"], ["88507.2", "0", "0", "0"], ["88507.1", "0.01657001", "0", "2"], ["88507", "0.03", "0", "1"], ["88503.8", "0.2259088", "0", "1"], ["88486", "0.06", "0", "2"], ["88485", "0.03", "0", "1"], ["88484", "0", "0", "0"], ["88333.4", "0.16039124", "0", "1"], ["88305.9", "0", "0", "0"], ["88296.3", "0.11343045", "0", "1"]], "ts": "1741338232905", "checksum": -707024648, "seqId": 48070578036, "prevSeqId": 48070577974}]}
{"arg": {"channel": "books", "instId": "BTC-USDT"}, "action": "update", "data": [{"asks": [["88528.5", "0.0002", "0", "2"], ["88529.8", "0.00002635", "0", "2"], ["88530.3", "0", "0", "0"], ["88535.8", "0.01155702", "0", "2"], ["88535.9", "0.0270292", "0", "2"], ["88543", "0.08318186", "0", "3"], ["88543.1", "0.12931306", "0", "2"], ["88552.4", "0", "0", "0"], ["88554.8", "0.027102", "0", "2"], ["88555.9", "0", "0", "0"], ["88561.1", "0.0000134", "0", "1"], ["88561.4", "0.22816252", "0", "2"], ["88567.8", "0.00338997", "0", "1"], ["88603.7", "0.01001139", "0", "2"], ["88616.8", "0.00570108", "0", "1"]], "bids": [["88527.9", "0.26073308", "0", "11"], ["88526.3", "0", "0", "0"], ["88523.9", "0.0002", "0", "2"], ["88519.4", "0.11295865", "0", "3"], ["88518.5", "0.04", "0", "1"], ["88514.7", "0.55156219", "0", "2"], ["88514.6", "0.90244663", "0", "1"], ["88514.5", "0.07612131", "0", "1"], ["88514.4", "0", "0", "0"], ["88513.9", "0.08118646", "0", "1"], ["88513.8", "0", "0", "0"], ["88512.6", "0.05194673", "0", "2"], ["88507.1", "0.01650401", "0", "1"], ["88503.8", "0.22590878", "0", "1"], ["88487", "0.47921", "0", "1"], ["88485", "0.06", "0", "2"], ["88484", "0.03", "0", "1"], ["88355.8", "0.00007", "0", "1"], ["88299.9", "0", "0", "0"], ["88298.3", "0", "0", "0"], ["88296.3", "0", "0", "0"]], "ts": "1741338233005", "checksum": -876838987, "seqId": 48070578104, "prevSeqId": 48070578036}]}
{"arg": {"channel": "books", "instId": "BTC-USDT"}, "action": "update", "data": [{"asks": [["88528.5", "0.0001", "0", "1"], ["88528.6", "0.00055714", "0", "2"], ["88547.5", "0.00547849", "0", "1"], ["88554.3", "0.012102", "0", "1"], ["88554.8", "0.015", "0", "1"], ["88557.7", "0.22674443", "0", "2"], ["88561.4", "0.00225374", "0", "1"], ["88576", "0.0138977", "0", "5"], ["88576.8", "0.81705346", "0", "3"], ["88577.6", "0.00004084", "0", "4"], ["88580", "0.2", "0", "1"], ["88616.6", "0", "0", "0"], ["88616.7", "0", "0", "0"], ["88616.8", "0", "0", "0"]], "bids": [["88527.2", "0.00145491", "0", "1"], ["88527.1", "0.11295738", "0", "1"], ["88526.7", "0", "0", "0"], ["88526.2", "0.27868274", "0", "2"], ["88524.7", "0", "0", "0"], ["88524", "0.0156", "0", "2"], ["88523.9", "0", "0", "0"], ["88512.7", "0.0001", "0", "1"], ["88503.8", "0", "0", "0"], ["88498.2", "0.22591443", "0", "1"]], "ts": "1741338233105", "checksum": -340684691, "seqId": 48070578173, "prevSeqId": 48070578104}]}
{"arg": {"channel": "books", "instId": "BTC-USDT"}, "action": "update", "data": [{"asks": [["88528", "0.20305283", "0", "8"], ["88528.5", "0.0002", "0", "2"], ["88528.6", "0.00045714", "0", "1"], ["88537.9", "0", "0", "0"], ["88543", "0.21129546", "0", "4"], ["88543.1", "0.00131779", "0", "1"], ["88553.8", "0.012102", "0", "1"], ["88554.3", "0", "0", "0"], ["88576", "0.0132977", "0", "3"], ["88576.8", "0.81735346", "0", "4"], ["88577.6", "0.00034084", "0", "5"], ["88594.4", "0.01739499", "0", "1"], ["88599.3", "0", "0", "0"], ["88616.6", "0.000657", "0", "2"]], "bids": [["88524", "0.0155", "0", "1"], ["88514.7", "0.46402493", "0", "1"], ["88514.6", "0.99015403", "0", "2"], ["88514.5", "0", "0", "0"], ["88514.4", "0.07980525", "0", "1"], ["88512.7", "0.0002", "0", "2"], ["88502", "1", "0", "1"], ["88476.1", "0", "0", "0"], ["88471.2", "0.01739499", "0", "1"], ["88400.8", "0", "0", "0"], ["88393.3", "0.17394991", "0", "1"], ["88317.3", "0.00589288", "0", "1"], ["88300.1", "0", "0", "0"], ["88300", "0", "0", "0"]], "ts": "1741338233205", "checksum": 85557968, "seqId": 48070578267, "prevSeqId": 48070578173}]}
{"arg": {"channel": "books", "instId": "BTC-USDT"}, "action": "update", "data": [{"asks": [["88528", "0.20000006", "0", "7"], ["88528.5", "0", "0", "0"], ["88529.9", "0.00023508", "0", "4"], ["88535.9", "0.0270457", "0", "3"], ["88536.9", "0.0000465", "0", "1"], ["88543", "0.08318186", "0", "3"], ["88543.1", "0.12557946", "0", "2"], ["88552.1", "0.01347318", "0", "2"], ["88553.8", "0", "0", "0"], ["88557.7", "0.00083", "0", "1"], ["88561.1", "0.22592303", "0", "2"], ["88576.8", "0.339712", "0", "4"], ["88576.9", "0.00007915", "0", "1"], ["88610.9", "0", "0", "0"], ["88616.7", "0.00006147", "0", "2"], ["88616.8", "0.00570108", "0", "1"]], "bids": [["88527.9", "0.28013588", "0", "12"], ["88526.6", "0", "0", "0"], ["88526.2", "0.27888274", "0", "4"], ["88514.7", "0.54328149", "0", "2"], ["88514.6", "0.90244663", "0", "1"], ["88514.5", "0.07884994", "0", "1"], ["88514.4", "0", "0", "0"], ["88512.7", "0", "0", "0"], ["88503.8", "0.22590963", "0", "1"], ["88501.6", "0.14793332", "0", "2"], ["88501.5", "0", "0", "0"], ["88498.2", "0", "0", "0"], ["88466.1", "0.39951597", "0", "1"], ["88463.6", "0", "0", "0"], ["88453.2", "0.92643182", "0", "1"], ["88446.6", "0.21769389", "0", "2"], ["88438.1", "0.02670024", "0", "1"], ["88300.1", "0.00001316", "0", "1"], ["88300", "0.00484161", "0", "5"], ["88299.9", "0.00057148", "0", "1"]], "ts": "1741338233305", "checksum": -810756065, "seqId": 48070578354, "prevSeqId": 48070578267}]}
{"arg": {"channel": "books", "instId": "BTC-USDT"}, "action": "update", "data": [{"asks": [["88528", "0.21940006", "0", "8"], ["88529.6", "0.00013358", "0", "3"], ["88529.7", "0.0001", "0", "1"], ["88529.9", "0.00003508", "0", "2"], ["88535.6", "0.02933731", "0", "1"], ["88535.7", "0.0000114", "0", "1"], ["88535.8", "0.03879493", "0", "3"], ["88535.9", "0.00027582", "0", "2"], ["88536.9", "0", "0", "0"], ["88539.9", "0.08973885", "0", "2"], ["88540", "0.08149087", "0", "5"], ["88543", "0.21317524", "0", "4"], ["88543.1", "0.00131779", "0", "1"], ["88546.1", "0.45378671", "0", "2"], ["88546.2", "0.04059", "0", "1"], ["88551.4", "0.01586177", "0", "1"], ["88551.5", "0.012102", "0", "1"], ["88552.1", "0.00137118", "0", "1"], ["88557.7", "0.2267451", "0", "2"], ["88561.1", "0.0000134", "0", "1"], ["88566.8", "0.1873678", "0", "3"], ["88567.6", "0.66117105", "0", "1"], ["88567.9", "1.6196884", "0", "2"], ["88586.2", "0.00001765", "0", "1"], ["88586.3", "0", "0", "0"], ["88589.9", "0", "0", "0"], ["88601.8", "2.83526675", "0", "1"], ["88616.7", "0", "0", "0"], ["88616.8", "0", "0", "0"]], "bids": [["88527.9", "0.27279373", "0", "11"], ["88527.2", "0", "0", "0"], ["88527.1", "0", "0", "0"], ["88526.3", "0.00145491", "0", "1"], ["88526.2", "0.27878274", "0", "3"], ["88526.1", "0.2125", "0", "10"], ["88525.8", "0.00734215", "0", "1"], ["88524.6", "0.11296059", "0", "1"], ["88518.4", "0.02564823", "0", "1"], ["88518.3", "0.02706376", "0", "1"], ["88518", "0.0155", "0", "1"], ["88517.9", "0.02758731", "0", "1"], ["88514.7", "0.46402493", "0", "1"], ["88514.6", "0.9837437", "0", "2"], ["88514.5", "0", "0", "0"], ["88514.4", "0.07987064", "0", "1"], ["88513.9", "0", "0", "0"], ["88513.8", "0.0810811", "0", "1"], ["88507.7", "0", "0", "0"], ["88507.6", "0.13303583", "0", "1"], ["88503.8", "0", "0", "0"], ["88501.6", "0.6439253", "0", "3"], ["88498.2", "0.2259151", "0", "1"], ["88497.7", "1.71445942", "0", "1"], ["88487", "0.53921", "0", "3"], ["88486", "0", "0", "0"], ["88466.1", "1.22656319", "0", "2"], ["88463.8", "3.16789643", "0", "1"], ["88453.2", "0", "0", "0"], ["88300.1", "0", "0", "0"], ["88300", "0", "0", "0"], ["88299.9", "0", "0", "0"]], "ts": "1741338233405", "checksum": 1445048858, "seqId": 48070578472, "prevSeqId": 48070578354}]}
{"arg": {"channel": "books", "instId": "BTC-USDT"}, "action": "update", "data": [{"asks": [["88529.6", "0.00023358", "0", "4"], ["88529.7", "0", "0", "0"], ["88530.6", "0.00003321", "0", "2"], ["88534.9", "0.00339997", "0", "2"], ["88550.6", "0.012102", "0", "1"], ["88551.4", "0", "0", "0"], ["88551.5", "0", "0", "0"], ["88567.8", "0", "0", "0"], ["88581.2", "0.497848", "0", "1"], ["88584.6", "0.497829", "0", "1"], ["88616.7", "0.00006147", "0", "2"]], "bids": [["88527.9", "0.23389093", "0", "8"], ["88508.2", "0.1", "0", "1"], ["88506", "0.71000828", "0", "3"], ["88503", "0.1", "0", "1"], ["88486", "0.06", "0", "2"], ["88485", "0.03", "0", "1"], ["88484", "0", "0", "0"], ["88301.4", "0", "0", "0"]], "ts": "1741338233505", "checksum": 1678789248, "seqId": 48070578568, "prevSeqId": 48070578472}]}
{"arg": {"channel": "books", "instId": "BTC-USDT"}, "action": "update", "data": [{"asks": [["88528.5", "0.0001", "0", "1"], ["88528.6", "0.00055714", "0", "2"], ["88529.6", "0.00003358", "0", "2"], ["88534.9", "0.00001003", "0", "1"], ["88536", "0.02505478", "0", "1"], ["88536.9", "0.00004725", "0", "1"], ["88539.4", "0.0832434", "0", "1"], ["88540", "0.08651785", "0", "5"], ["88542.9", "0.08327922", "0", "1"], ["88543", "0.13006757", "0", "3"], ["88543.2", "0.00225374", "0", "1"], ["88543.5", "0.1324646", "0", "2"], ["88550", "0.01319216", "0", "10"], ["88550.6", "0", "0", "0"], ["88556.7", "0.00373494", "0", "2"], ["88561.4", "0", "0", "0"], ["88576", "0.0138977", "0", "5"], ["88576.8", "0.339412", "0", "3"], ["88577.6", "0.00004084", "0", "4"], ["88616.6", "0", "0", "0"], ["88616.7", "0", "0", "0"]], "bids": [["88527.9", "0.25335393", "0", "10"], ["88526.2", "0.27868274", "0", "2"], ["88526.1", "0.2124", "0", "9"], ["88519.6", "0.0194028", "0", "1"], ["88518.4", "0.02520198", "0", "1"], ["88512.1", "0.0002", "0", "2"], ["88511.4", "0.12223966", "0", "1"], ["88510.5", "0.14007194", "0", "1"], ["88500.8", "0.08602891", "0", "3"], ["88500", "0.00029915", "0", "1"], ["88499.2", "0", "0", "0"], ["88303.2", "0", "0", "0"]], "ts": "1741338233605", "checksum": -285592531, "seqId": 48070578674, "prevSeqId": 48070578568}]}
{"arg": {"channel": "books", "instId": "BTC-USDT"}, "action": "update", "data": [{"asks": [["88528.5", "0.0002", "0", "2"], ["88528.6", "0.00045714", "0", "1"], ["88530.6", "0.00001446", "0", "1"], ["88530.7", "0.0000195", "0", "1"], ["88533.1", "0.07395371", "0", "2"], ["88535.5", "0.09058277", "0", "13"], ["88535.6", "0", "0", "0"], ["88535.7", "0.02821057", "0", "2"], ["88535.8", "0.01155702", "0", "2"], ["88535.9", "0.02693231", "0", "3"], ["88536", "0", "0", "0"], ["88536.9", "0.0000465", "0", "1"], ["88538", "0.08956731", "0", "2"], ["88539.4", "0", "0", "0"], ["88539.8", "0.08051144", "0", "1"], ["88539.9", "0.07913983", "0", "2"], ["88540", "0.00503926", "0", "4"], ["88542.8", "0.07309605", "0", "1"], ["88542.9", "0.13504749", "0", "1"], ["88543", "0.00007419", "0", "2"], ["88543.4", "0.14383287", "0", "3"], ["88543.5", "0.00001124", "0", "1"], ["88546", "0.14019971", "0", "4"], ["88546.1", "0.3227207", "0", "1"], ["88549.6", "0.012117", "0", "2"], ["88550", "0.00109016", "0", "9"], ["88566.8", "0.0741952", "0", "2"]], "bids": [["88527.9", "0.21736893", "0", "8"], ["88524.3", "0.0001", "0", "1"], ["88518.4", "0", "0", "0"], ["88518.3", "0.02556044", "0", "1"], ["88518.2", "0.02751701", "0", "1"], ["88517.9", "0", "0", "0"], ["88517.8", "0.05328495", "0", "2"], ["88514.6", "0.90244663", "0", "1"], ["88514.5", "0.08499125", "0", "1"], ["88514.4", "0", "0", "0"], ["88514.3", "0.08282939", "0", "1"], ["88513.8", "0", "0", "0"], ["88513.7", "0.16072799", "0", "2"], ["88512.1", "0", "0", "0"], ["88512", "0.0156", "0", "2"], ["88511.4", "0", "0", "0"], ["88511.3", "0.15316072", "0", "2"], ["88510.5", "0", "0", "0"], ["88510.4", "0.31857143", "0", "3"], ["88507.6", "0", "0", "0"], ["88507.5", "0.1505961", "0", "1"], ["88503", "0", "0", "0"], ["88502", "0", "0", "0"], ["88500.8", "0.08542891", "0", "1"], ["88500", "0.00059915", "0", "2"], ["88499.2", "0.00029915", "0", "1"], ["88303.2", "0.27969405", "0", "1"], ["88302.9", "0.033884", "0", "1"], ["88301.4", "0.00003447", "0", "1"], ["88300.1", "0.00001316", "0", "1"]], "ts": "1741338233705", "checksum": -1567797218, "seqId": 48070578800, "prevSeqId": 48070578674}]}
{"arg": {"channel": "books", "instId": "BTC-USDT"}, "action": "update", "data": [{"asks": [["88535.7", "0.0285958", "0", "2"], ["88535.9", "0.02792021", "0", "3"], ["88536.9", "0", "0", "0"], ["88538", "0.2115093", "0", "1"], ["88539.3", "0.08686537", "0", "1"], ["88539.7", "0.33929724", "0", "1"], ["88539.9", "0.08281717", "0", "2"], ["88541.6", "0.0410377", "0", "3"], ["88542.8", "0.08324306", "0", "2"], ["88542.9", "0.13166743", "0", "1"], ["88543.4", "0.13350337", "0", "3"], ["88546.2", "0", "0", "0"], ["88549.2", "0.012102", "0", "1"], ["88549.6", "0.000015", "0", "1"], ["88616.2", "0", "0", "0"]], "bids": [["88527.9", "0.21946893", "0", "9"], ["88524.3", "0", "0", "0"], ["88518.3", "0.02628391", "0", "1"], ["88518.2", "0.02711886", "0", "1"], ["88514.5", "0.09004667", "0", "1"], ["88514.3", "0.0810967", "0", "1"], ["88513.7", "0.16767334", "0", "2"], ["88511.9", "0.0001", "0", "1"], ["88511.3", "0.15337323", "0", "2"], ["88510.4", "0.31843038", "0", "3"]], "ts": "1741338233805", "checksum": 1001961463, "seqId": 48070578918, "prevSeqId": 48070578800}]}
{"arg": {"channel": "books", "instId": "BTC-USDT"}, "action": "update", "data": [{"asks": [["88535.6", "0.02640657", "0", "1"], ["88535.7", "0.0000114", "0", "1"], ["88535.9", "0.00027582", "0", "2"], ["88536.9", "0.207", "0", "1"], ["88538.1", "0.00007794", "0", "3"], ["88539.2", "0.08286988", "0", "1"], ["88539.3", "0", "0", "0"], ["88539.9", "0.00003598", "0", "1"], ["88542.8", "0.04428121", "0", "1"], ["88542.9", "0", "0", "0"], ["88543.3", "0.13482734", "0", "2"], ["88543.4", "0.00111045", "0", "2"], ["88548.9", "0.35139924", "0", "2"], ["88549.2", "0", "0", "0"], ["88571", "0.12", "0", "4"], ["88572", "0.03", "0", "1"]], "bids": [["88518.3", "0", "0", "0"], ["88518.2", "0.02634776", "0", "1"], ["88518.1", "0.02836071", "0", "2"], ["88514.5", "0", "0", "0"], ["88514.4", "0.08175873", "0", "1"], ["88514.3", "0", "0", "0"], ["88513.7", "0.07860057", "0", "1"], ["88513.6", "0.09840844", "0", "2"], ["88512", "0.0155", "0", "1"], ["88511.8", "0.0001", "0", "1"], ["88511.3", "0.03", "0", "1"], ["88510.4", "0.18294682", "0", "2"], ["88510.3", "0.13772351", "0", "1"]], "ts": "1741338233905", "checksum": 1001961463, "seqId": 48070579043, "prevSeqId": 48070578918}]}
{"arg": {"channel": "books", "instId": "BTC-USDT"}, "action": "update", "data": [{"asks": [["88528.5", "0.0001", "0", "1"], ["88529.1", "0.0001", "0", "1"], ["88533.1", "0.06505668", "0", "2"], ["88535.5", "0.06161508", "0", "12"], ["88535.6", "0.0290875", "0", "1"], ["88535.8", "0.03890227", "0", "3"], ["88536", "0.02507906", "0", "1"], ["88536.8", "0.23292755", "0", "1"], ["88538", "0", "0", "0"], ["88539.2", "0", "0", "0"], ["88539.4", "0.08100821", "0", "1"], ["88539.8", "0", "0", "0"], ["88539.9", "0.08800198", "0", "2"], ["88540", "0.08518651", "0", "5"], ["88543", "0.12545101", "0", "3"], ["88543.3", "0.00001005", "0", "1"], ["88543.5", "0.13869996", "0", "2"], ["88545.9", "0.00007302", "0", "1"], ["88546", "0.00011484", "0", "3"], ["88546.1", "0.46875236", "0", "2"], ["88547.8", "0.0121149", "0", "2"], ["88548.9", "0.33929724", "0", "1"], ["88580", "0", "0", "0"], ["88594", "0.01739529", "0", "1"], ["88594.4", "0", "0", "0"]], "bids": [["88527.9", "0.25125493", "0", "9"], ["88524.3", "0.0001", "0", "1"], ["88518.4", "0.02707127", "0", "1"], ["88518.3", "0.02617917", "0", "1"], ["88518.2", "0", "0", "0"], ["88518.1", "0.0000405", "0", "1"], ["88517.9", "0.02949323", "0", "1"], ["88517.8", "0.02697024", "0", "1"], ["88514.6", "0.98416297", "0", "2"], ["88514.4", "0.07796084", "0", "1"], ["88513.8", "0.08548785", "0", "1"], ["88513.6", "0.00942", "0", "1"], ["88511.9", "0", "0", "0"], ["88511.4", "0.12677318", "0", "1"], ["88510.5", "0.1333425", "0", "1"], ["88510.3", "0", "0", "0"], ["88507.6", "0.14600361", "0", "1"], ["88507.5", "0", "0", "0"], ["88507.1", "0", "0", "0"], ["88506.4", "0.01650401", "0", "1"], ["88303.2", "0", "0", "0"], ["88302.9", "0", "0", "0"], ["88301.4", "0", "0", "0"], ["88300.1", "0", "0", "0"]], "ts": "1741338234005", "checksum": 1899522262, "seqId": 48070579163, "prevSeqId": 48070579043}]}
{"arg": {"channel": "books", "instId": "BTC-USDT"}, "action": "update", "data": [{"asks": [["88528", "0.20000006", "0", "7"], ["88528.5", "0", "0", "0"], ["88529", "0.00011678", "0", "2"], ["88535.6", "0.02731165", "0", "1"], ["88535.8", "0.01155702", "0", "2"], ["88535.9", "0.02800394", "0", "3"], ["88536", "0", "0", "0"], ["88539.3", "0.08971053", "0", "1"], ["88539.4", "0", "0", "0"], ["88539.9", "0.16334513", "0", "3"], ["88540", "0.00503926", "0", "4"], ["88542.8", "0.07886128", "0", "1"], ["88543", "0.12923073", "0", "3"], ["88543.4", "0.13482786", "0", "3"], ["88543.5", "0.00001124", "0", "1"], ["88546.1", "0.3227207", "0", "1"], ["88547.5", "0.01758049", "0", "2"], ["88547.8", "0.0000129", "0", "1"], ["88556.7", "0.000345", "0", "1"], ["88557.7", "0.22674299", "0", "2"], ["88575.9", "0.00340667", "0", "2"], ["88581.1", "0.68733171", "0", "1"], ["88582", "0", "0", "0"], ["88591.9", "0.01739528", "0", "1"], ["88594", "0", "0", "0"], ["88616.2", "0.00570112", "0", "1"], ["88616.6", "0.000657", "0", "2"]], "bids": [["88527.9", "0.21946893", "0", "9"], ["88524.3", "0.0002", "0", "2"], ["88518.4", "0", "0", "0"], ["88518.3", "0.05675", "0", "2"], ["88517.9", "0.02676677", "0", "1"], ["88514.6", "0.99015475", "0", "2"], ["88514.4", "0.07462687", "0", "1"], ["88513.8", "0", "0", "0"], ["88511.8", "0", "0", "0"], ["88511.4", "0", "0", "0"], ["88511.3", "0.16457211", "0", "2"], ["88510.5", "0", "0", "0"], ["88510.4", "0.31423463", "0", "3"], ["88507.6", "0", "0", "0"], ["88502.3", "0.22591299", "0", "1"], ["88498.2", "0", "0", "0"], ["88471.2", "0", "0", "0"], ["88468", "0.01740528", "0", "2"], ["88465.2", "0.00102641", "0", "1"], ["88464", "0", "0", "0"], ["88452.4", "0.00019389", "0", "1"], ["88450.1", "0.00547861", "0", "1"], ["88403", "0", "0", "0"], ["88402.9", "0.00211986", "0", "1"], ["88306", "0.033884", "0", "1"], ["88303.2", "0.27969405", "0", "1"], ["88301.4", "0.00003447", "0", "1"], ["88300.1", "0.00001316", "0", "1"], ["88300", "0.00484161", "0", "5"], ["88299.9", "0.00057148", "0", "1"]], "ts": "1741338234105", "checksum": -1151210431, "seqId": 48070579286, "prevSeqId": 48070579163}]}
{"arg": {"channel": "books", "instId": "BTC-USDT"}, "action": "update", "data": [{"asks": [["88528", "0.21940006", "0", "8"], ["88528.5", "0.0001", "0", "1"], ["88529", "0.00001678", "0", "1"], ["88535.6", "0.02991804", "0", "1"], ["88535.8", "0.03994286", "0", "3"], ["88535.9", "0.00027582", "0", "2"], ["88536", "0.02762905", "0", "1"], ["88539.3", "0", "0", "0"], ["88539.4", "0.0824706", "0", "1"], ["88539.9", "0.08979835", "0", "2"], ["88540", "0.08722384", "0", "5"], ["88541.5", "0.09660902", "0", "3"], ["88542.8", "0", "0", "0"], ["88543", "0.12874692", "0", "3"], ["88543.4", "0.00111045", "0", "2"], ["88543.5", "0.14471557", "0", "2"], ["88546.1", "0.46116598", "0", "2"], ["88547", "0.01211339", "0", "2"], ["88547.5", "0.00547849", "0", "1"], ["88557.7", "0.00083", "0", "1"], ["88558.5", "0.22591369", "0", "1"], ["88616.2", "0", "0", "0"], ["88616.6", "0", "0", "0"]], "bids": [["88527.9", "0.25335293", "0", "10"], ["88524.3", "0.0001", "0", "1"], ["88519.4", "0", "0", "0"], ["88518.4", "0.02451241", "0", "1"], ["88518.3", "0.02830775", "0", "1"], ["88517.9", "0.02867919", "0", "1"], ["88514.6", "0.98785394", "0", "2"], ["88514.4", "0.0817068", "0", "1"], ["88513.8", "0.08670526", "0", "1"], ["88511.9", "0.0001", "0", "1"], ["88511.4", "0.13145126", "0", "1"], ["88511.3", "0.03", "0", "1"], ["88510.5", "0.14789438", "0", "1"], ["88510.4", "0.18294682", "0", "2"], ["88507.6", "0.13953357", "0", "1"], ["88502.3", "0", "0", "0"], ["88500.9", "0.22591345", "0", "1"], ["88306", "0", "0", "0"], ["88301.4", "0", "0", "0"], ["88300.1", "0", "0", "0"], ["88300", "0", "0", "0"], ["88299.9", "0", "0", "0"]], "ts": "1741338234205", "checksum": 128165840, "seqId": 48070579420, "prevSeqId": 48070579286}]}
{"arg": {"channel": "books", "instId": "BTC-USDT"}, "action": "update", "data": [{"asks": [["88528", "0.1030709", "0", "5"], ["88528.5", "0", "0", "0"], ["88529.1", "0", "0", "0"], ["88530.2", "0.0001", "0", "1"], ["88530.3", "0.0001", "0", "1"], ["88530.7", "0", "0", "0"], ["88533.1", "0.04628326", "0", "1"], ["88535.6", "0", "0", "0"], ["88535.8", "0.01155702", "0", "2"], ["88536", "0.02910686", "0", "1"], ["88536.2", "0", "0", "0"], ["88536.3", "0.0261925", "0", "1"], ["88536.6", "0.02693471", "0", "1"], ["88536.8", "0.11063319", "0", "1"], ["88536.9", "0.0000465", "0", "1"], ["88537", "0.00005129", "0", "1"], ["88539.4", "0", "0", "0"], ["88539.7", "0.42471217", "0", "2"], ["88539.9", "0.00003598", "0", "1"], ["88540", "0.01856926", "0", "5"], ["88540.4", "0", "0", "0"], ["88540.7", "0.08896744", "0", "1"], ["88541.5", "0.00001152", "0", "1"], ["88541.6", "0.0004477", "0", "2"], ["88543", "0.00007419", "0", "2"], ["88543.5", "0.00001124", "0", "1"], ["88543.8", "0.13878461", "0", "1"], ["88544.9", "0", "0", "0"], ["88546.1", "0.3227207", "0", "1"], ["88546.4", "0.13156979", "0", "8"], ["88546.7", "0.04059", "0", "1"], ["88558.5", "0", "0", "0"], ["88558.8", "0.22591942", "0", "2"], ["88590.5", "0.00002281", "0", "2"], ["88591.9", "0", "0", "0"], ["88598.2", "0.01758002", "0", "2"], ["88616.2", "0.00570112", "0", "1"], ["88616.6", "0.000657", "0", "2"], ["88616.7", "0.00006147", "0", "2"]], "bids": [["88527.9", "0.36630941", "0", "11"], ["88524.6", "0", "0", "0"], ["88524.5", "0.0002", "0", "2"], ["88524.3", "0.00942", "0", "1"], ["88521.8", "0", "0", "0"], ["88519.8", "0.11295865", "0", "3"], ["88519.1", "0.15120765", "0", "1"], ["88518.4", "0", "0", "0"], ["88518.3", "0", "0", "0"], ["88518.1", "0.0262465", "0", "2"], ["88517.9", "0", "0", "0"], ["88517.8", "0", "0", "0"], ["88514.6", "0.90244663", "0", "1"], ["88514.4", "0", "0", "0"], ["88514.1", "0.13115897", "0", "3"], ["88513.8", "0", "0", "0"], ["88513.7", "0", "0", "0"], ["88511.9", "0", "0", "0"], ["88511.4", "0", "0", "0"], ["88510.5", "0", "0", "0"], ["88510.4", "0.14159864", "0", "2"], ["88509.2", "0", "0", "0"], ["88507.9", "0.14578074", "0", "1"], ["88507.6", "0", "0", "0"], ["88503.8", "0.22590944", "0", "1"], ["88500.9", "0", "0", "0"], ["88475.2", "0.01739477", "0", "1"], ["88468", "0.00001", "0", "1"], ["88447.9", "0", "0", "0"], ["88437.3", "0", "0", "0"], ["88400.6", "0.17394771", "0", "1"], ["88393.3", "0", "0", "0"], ["88301.4", "0.00003447", "0", "1"], ["88300.1", "0.00001316", "0", "1"], ["88300", "0.00484161", "0", "5"], ["88299.9", "0.00057148", "0", "1"], ["88298.3", "5.96308196", "0", "1"], ["88296.3", "0.11343045", "0", "1"], ["88296.2", "0.34056098", "0", "1"], ["88294.7", "0.00001118", "0", "1"], ["88294.1", "0.00289318", "0", "3"], ["88294", "0.0025", "0", "1"], ["88293.4", "0.04093218", "0", "1"], ["88292.4", "0.00001139", "0", "1"]], "ts": "1741338234305", "checksum": -1454625700, "seqId": 48070579642, "prevSeqId": 48070579420}]}
{"arg": {"channel": "books", "instId": "BTC-USDT"}, "action": "update", "data": [{"asks": [["88528", "0.31295163", "0", "13"], ["88528.2", "0.0001", "0", "1"], ["88528.3", "0.0001", "0", "1"], ["88530.2", "0", "0", "0"], ["88530.3", "0", "0", "0"], ["88533.1", "0.06517303", "0", "2"], ["88534.7", "0.02751753", "0", "1"], ["88534.9", "0.02899544", "0", "2"], ["88535", "0.02601939", "0", "1"], ["88535.7", "0.02777205", "0", "2"], ["88536", "0", "0", "0"], ["88536.3", "0", "0", "0"], ["88536.6", "0", "0", "0"], ["88536.8", "0.22703171", "0", "2"], ["88536.9", "0.207", "0", "1"], ["88538.4", "0.09135862", "0", "6"], ["88539", "0.16848966", "0", "2"], ["88539.7", "0.33929724", "0", "1"], ["88539.8", "0.08056904", "0", "1"], ["88540.7", "0", "0", "0"], ["88541.8", "0.17082769", "0", "2"], ["88542.1", "0.13508765", "0", "2"], ["88542.5", "0.14228778", "0", "1"], ["88543.2", "0.01435574", "0", "2"], ["88543.8", "0", "0", "0"], ["88544.4", "0.14556098", "0", "1"], ["88545.2", "0.14683221", "0", "2"], ["88545.8", "0.60273251", "0", "1"], ["88545.9", "0.90251965", "0", "2"], ["88546.1", "0", "0", "0"], ["88546.4", "0.00026336", "0", "7"], ["88547", "0.00001139", "0", "1"], ["88554.1", "0.22593856", "0", "2"], ["88558.7", "0.04", "0", "1"], ["88558.8", "0.00001001", "0", "1"], ["88566.9", "0", "0", "0"], ["88591", "0.01128783", "0", "1"], ["88592", "0.10018194", "0", "2"], ["88598.2", "0.00018525", "0", "1"], ["88599.8", "0.01739484", "0", "1"], ["88608.2", "0.33857", "0", "1"], ["88614.1", "0", "0", "0"], ["88616.1", "0", "0", "0"], ["88616.2", "0", "0", "0"], ["88616.6", "0", "0", "0"], ["88616.7", "0", "0", "0"]], "bids": [["88527.9", "0.13261523", "0", "6"], ["88526.3", "0", "0", "0"], ["88526.2", "0.000066", "0", "1"], ["88526.1", "0", "0", "0"], ["88525.4", "0", "0", "0"], ["88524.5", "0", "0", "0"], ["88524.3", "0", "0", "0"], ["88523.7", "0", "0", "0"], ["88523.5", "0.00145491", "0", "1"], ["88523.4", "0.06588618", "0", "1"], ["88522.5", "0", "0", "0"], ["88521.7", "0.04", "0", "1"], ["88520.9", "0.01357284", "0", "1"], ["88519.8", "0", "0", "0"], ["88519.1", "0.20875548", "0", "2"], ["88518.1", "0.0000405", "0", "1"], ["88517.9", "0.02671259", "0", "1"], ["88517.4", "0.05556173", "0", "2"], ["88517.3", "0.02785056", "0", "1"], ["88517.2", "0.0001", "0", "1"], ["88517.1", "0.0001", "0", "1"], ["88517", "0.02973045", "0", "1"], ["88516.6", "0", "0", "0"], ["88516.5", "0", "0", "0"], ["88515.8", "0", "0", "0"], ["88515.3", "0", "0", "0"], ["88514.7", "0.23656102", "0", "1"], ["88514.6", "0", "0", "0"], ["88514.1", "0.05194673", "0", "2"], ["88513.7", "0.0866854", "0", "1"], ["88513.5", "0.07802252", "0", "1"], ["88513.1", "0.08364695", "0", "2"], ["88512.9", "0.08657243", "0", "1"], ["88511.7", "0", "0", "0"], ["88510.9", "0.02834", "0", "2"], ["88510.4", "0.29530708", "0", "4"], ["88509.5", "0.13838973", "0", "1"], ["88508.6", "0.13916236", "0", "1"], ["88508.2", "0", "0", "0"], ["88507.9", "0", "0", "0"], ["88507.7", "0.00451938", "0", "1"], ["88506.7", "0.14829979", "0", "1"], ["88503.8", "0", "0", "0"], ["88503.7", "0", "0", "0"], ["88500.5", "0", "0", "0"], ["88496", "0", "0", "0"], ["88495", "0.22592873", "0", "1"], ["88494.5", "0", "0", "0"], ["88490", "0.04518385", "0", "1"], ["88486.6", "0", "0", "0"], ["88479.4", "0", "0", "0"], ["88476.1", "0.01739484", "0", "1"], ["88475.2", "0", "0", "0"], ["88452.1", "0.25392684", "0", "2"], ["88401.7", "0.17394843", "0", "1"], ["88400.6", "0", "0", "0"], ["88397", "0", "0", "0"], ["88382.8", "0.01128592", "0", "1"], ["88301.4", "0.03391547", "0", "2"], ["88292.3", "0.00002159", "0", "1"], ["88292", "0.0025", "0", "1"], ["88291", "0.005", "0", "2"], ["88290", "0.00001172", "0", "1"], ["88289.4", "0.03", "0", "1"]], "ts": "1741338234405", "checksum": -2007981625, "seqId": 48070580019, "prevSeqId": 48070579642}]}
{"arg": {"channel": "books", "instId": "BTC-USDT"}, "action": "update", "data": [{"asks": [["88528", "0.29355163", "0", "12"], ["88528.2", "0.0002", "0", "2"], ["88528.3", "0", "0", "0"], ["88530.6", "0.00003321", "0", "2"], ["88532", "0.02903", "0", "2"], ["88536.8", "0.22707821", "0", "3"], ["88538.6", "0.04059", "0", "1"], ["88540", "0.00503926", "0", "4"], ["88546.7", "0", "0", "0"], ["88547", "0.04501139", "0", "2"], ["88554.1", "0.00001148", "0", "1"], ["88554.8", "0", "0", "0"], ["88558.5", "0.22591641", "0", "1"], ["88575", "0.2000626", "0", "3"], ["88616.1", "0.00014217", "0", "1"]], "bids": [["88519.1", "0.36357478", "0", "1"], ["88518.3", "0.11295865", "0", "3"], ["88517.8", "0.33891", "0", "1"], ["88517.6", "0.0002", "0", "2"], ["88517.2", "0.00942", "0", "1"], ["88517.1", "0", "0", "0"], ["88516.1", "0.33892", "0", "1"], ["88506.8", "0.01650401", "0", "1"], ["88506.4", "0", "0", "0"], ["88503.5", "0.28591641", "0", "3"], ["88495", "0", "0", "0"], ["88486", "0", "0", "0"], ["88485", "0.06", "0", "2"], ["88484", "0.03", "0", "1"], ["88473.6", "0.33908", "0", "1"], ["88291", "0", "0", "0"], ["88290", "0", "0", "0"], ["88289.4", "0", "0", "0"]], "ts": "1741338234505", "checksum": 961980051, "seqId": 48070580124, "prevSeqId": 48070580019}]}
{"arg": {"channel": "books", "instId": "BTC-USDT"}, "action": "update", "data": [{"asks": [["88528", "0.31295163", "0", "13"], ["88529.8", "0.00202635", "0", "3"], ["88530.6", "0.00001446", "0", "1"], ["88530.7", "0.0000195", "0", "1"], ["88533.1", "0.10665981", "0", "1"], ["88534.7", "0", "0", "0"], ["88534.8", "0.02863857", "0", "2"], ["88534.9", "0.00001003", "0", "1"], ["88535", "0.02792735", "0", "1"], ["88535.2", "0.02756304", "0", "2"], ["88535.7", "0.0000114", "0", "1"], ["88535.9", "0.02915348", "0", "3"], ["88536.8", "0.22707746", "0", "3"], ["88538.4", "0.00528414", "0", "5"], ["88538.6", "0.12666187", "0", "2"], ["88539", "0", "0", "0"], ["88539.1", "0.0850863", "0", "1"], ["88539.2", "0.07858538", "0", "1"], ["88539.8", "0", "0", "0"], ["88540", "0.09207871", "0", "5"], ["88540.5", "0.00272792", "0", "4"], ["88541.8", "0.16367479", "0", "2"], ["88542.1", "0.00010289", "0", "1"], ["88542.2", "0.12376639", "0", "5"], ["88542.5", "0", "0", "0"], ["88542.7", "0.15233332", "0", "2"], ["88543.2", "0.00225374", "0", "1"], ["88544.4", "0", "0", "0"], ["88544.5", "0.13778238", "0", "2"], ["88545.2", "0.00002513", "0", "1"], ["88545.3", "0.14185704", "0", "1"], ["88547", "0.09001139", "0", "3"], ["88550.5", "0.135", "0", "3"], ["88555.4", "0", "0", "0"], ["88558.5", "0", "0", "0"], ["88558.9", "0.129", "0", "3"], ["88559.4", "0.22624177", "0", "2"], ["88616.2", "0.00570112", "0", "1"]], "bids": [["88527.9", "0.14084434", "0", "7"], ["88526.2", "0", "0", "0"], ["88526.1", "0.01370539", "0", "1"], ["88523.4", "0.06595356", "0", "2"], ["88521.5", "0.0001", "0", "1"], ["88517.6", "0.02714446", "0", "1"], ["88517.5", "0.05719418", "0", "2"], ["88517.4", "0", "0", "0"], ["88517.3", "0.0001", "0", "1"], ["88517.1", "0.02959333", "0", "1"], ["88517", "0", "0", "0"], ["88514.7", "0.34934869", "0", "2"], ["88514.3", "0.33893", "0", "1"], ["88513.8", "0.07910514", "0", "1"], ["88513.7", "0", "0", "0"], ["88513.6", "0.09313027", "0", "2"], ["88513.5", "0", "0", "0"], ["88513.3", "0.08336226", "0", "1"], ["88513.1", "0.00001138", "0", "1"], ["88513", "0.08039985", "0", "1"], ["88512.9", "0", "0", "0"], ["88510.6", "0.1332467", "0", "1"], ["88510.4", "0.18630158", "0", "3"], ["88509.7", "0.14504371", "0", "1"], ["88509.5", "0", "0", "0"], ["88508.8", "0.13218676", "0", "1"], ["88508.6", "0", "0", "0"], ["88506.9", "0.01650401", "0", "1"], ["88506.8", "0.13973521", "0", "1"], ["88506.7", "0", "0", "0"], ["88503.6", "0.22591504", "0", "1"], ["88503.5", "0.06", "0", "2"], ["88486", "0.06", "0", "2"], ["88485", "0.03", "0", "1"], ["88484", "0", "0", "0"], ["88471.9", "0.002", "0", "1"], ["88461.3", "0.002", "0", "1"], ["88294.1", "0", "0", "0"], ["88294", "0", "0", "0"], ["88293.4", "0", "0", "0"], ["88292.4", "0", "0", "0"], ["88292.3", "0", "0", "0"], ["88292", "0", "0", "0"]], "ts": "1741338234605", "checksum": 433448644, "seqId": 48070580311, "prevSeqId": 48070580124}]}
{"arg": {"channel": "books", "instId": "BTC-USDT"}, "action": "update", "data": [{"asks": [["88530.7", "0", "0", "0"], ["88533.1", "0.07987316", "0", "1"], ["88536.8", "0.22703171", "0", "2"], ["88542.7", "0.14023132", "0", "1"], ["88542.9", "0.012102", "0", "1"], ["88550.5", "0.174", "0", "4"], ["88558.8", "0.22592586", "0", "2"], ["88558.9", "0.039", "0", "1"], ["88559.4", "0.00032673", "0", "1"]], "bids": [["88527.9", "0.13874434", "0", "6"], ["88521.5", "0", "0", "0"], ["88517.5", "0.05739418", "0", "4"], ["88517.3", "0", "0", "0"], ["88503.6", "0", "0", "0"], ["88501.7", "0.22591585", "0", "1"], ["88474.3", "0.0353838", "0", "1"], ["88469.8", "0", "0", "0"], ["88469.7", "0", "0", "0"], ["88294.1", "0.00289318", "0", "3"], ["88294", "0.0025", "0", "1"], ["88293.4", "0.04093218", "0", "1"]], "ts": "1741338234705", "checksum": -1816660757, "seqId": 48070580370, "prevSeqId": 48070580311}]}
{"arg": {"channel": "books", "instId": "BTC-USDT"}, "action": "update", "data": [{"asks": [["88526.1", "0.38918574", "0", "14"], ["88526.9", "0.0001", "0", "1"], ["88527.3", "0.06637781", "0", "1"], ["88527.4", "0.11295712", "0", "1"], ["88528", "0.0791037", "0", "7"], ["88528.1", "0.0001", "0", "1"], ["88528.2", "0", "0", "0"], ["88528.7", "0.0000195", "0", "1"], ["88529.3", "0", "0", "0"], ["88529.4", "0", "0", "0"], ["88532", "0.0155", "0", "1"], ["88533.1", "0.07356987", "0", "2"], ["88533.8", "0.0406", "0", "1"], ["88534.8", "0.00092933", "0", "1"], ["88535", "0.00004725", "0", "1"], ["88535.2", "0.00012748", "0", "1"], ["88535.9", "0.00027582", "0", "2"], ["88536.8", "0.25499994", "0", "2"], ["88538.6", "0", "0", "0"], ["88539.1", "0", "0", "0"], ["88539.2", "0", "0", "0"], ["88540", "0.00503926", "0", "4"], ["88541.5", "0.01211352", "0", "2"], ["88541.6", "0.08920698", "0", "4"], ["88541.8", "0", "0", "0"], ["88542.2", "0.00026414", "0", "4"], ["88542.7", "0", "0", "0"], ["88542.9", "0", "0", "0"], ["88544.5", "0.00111578", "0", "1"], ["88545.3", "0", "0", "0"], ["88554.3", "0.22592581", "0", "1"], ["88554.6", "0.04199223", "0", "6"], ["88555.3", "0.00016236", "0", "2"], ["88558.8", "0.00001001", "0", "1"], ["88558.9", "0", "0", "0"], ["88563.6", "0.00001026", "0", "1"], ["88570", "0.06", "0", "2"], ["88571", "0.09", "0", "3"], ["88572", "0", "0", "0"], ["88592", "0.00018194", "0", "1"], ["88600.4", "0.02941223", "0", "1"], ["88606.4", "0", "0", "0"], ["88616.6", "0.000657", "0", "2"], ["88616.7", "0.00006147", "0", "2"], ["88616.8", "0.00570108", "0", "1"], ["88617.6", "0.00002674", "0", "2"]], "bids": [["88527.9", "0", "0", "0"], ["88526.1", "0", "0", "0"], ["88526", "0.150846", "0", "5"], ["88525.9", "0", "0", "0"], ["88525.8", "0", "0", "0"], ["88524.9", "0.00734279", "0", "1"], ["88524.6", "0.0001", "0", "1"], ["88524.4", "0.0001", "0", "1"], ["88523.5", "0", "0", "0"], ["88519.2", "0.00145491", "0", "1"], ["88518.5", "0", "0", "0"], ["88518.3", "0", "0", "0"], ["88518.1", "0", "0", "0"], ["88517.6", "0", "0", "0"], ["88517.5", "0", "0", "0"], ["88517.2", "0", "0", "0"], ["88517.1", "0", "0", "0"], ["88516.3", "0", "0", "0"], ["88516.2", "0.00005475", "0", "1"], ["88515.6", "0.0535", "0", "2"], ["88515.4", "0.32851344", "0", "14"], ["88514.7", "0.36264592", "0", "2"], ["88514.2", "0", "0", "0"], ["88513.8", "0", "0", "0"], ["88513.6", "0.00942", "0", "1"], ["88513.3", "0", "0", "0"], ["88513", "0", "0", "0"], ["88512.4", "0.00942", "0", "1"], ["88511.7", "0.33929724", "0", "1"], ["88510.9", "0.00006", "0", "1"], ["88510.6", "0", "0", "0"], ["88510.4", "0.25355654", "0", "3"], ["88509.7", "0", "0", "0"], ["88508.8", "0", "0", "0"], ["88507.9", "0.1", "0", "1"], ["88506.9", "0", "0", "0"], ["88506.8", "0", "0", "0"], ["88506.4", "0.01650401", "0", "1"], ["88505.7", "0.02829", "0", "1"], ["88503.5", "0.16", "0", "3"], ["88503", "0.1", "0", "1"], ["88501.7", "0", "0", "0"], ["88500", "0", "0", "0"], ["88499.2", "0.00059915", "0", "2"], ["88498.4", "0.00029915", "0", "1"], ["88495", "0.22592581", "0", "1"], ["88486", "0", "0", "0"], ["88485.6", "0.0112", "0", "1"], ["88485", "0.06", "0", "2"], ["88484", "0.03", "0", "1"], ["88481.1", "0", "0", "0"], ["88472.4", "0.0353323", "0", "1"], ["88464.7", "0", "0", "0"], ["88301.4", "0.00003447", "0", "1"], ["88292.4", "0.00001139", "0", "1"], ["88292.3", "0.00002159", "0", "1"], ["88292", "0.0025", "0", "1"], ["88291", "0.005", "0", "2"], ["88290", "0.00001172", "0", "1"], ["88289.4", "0.03", "0", "1"], ["88287.1", "0.03", "0", "1"], ["88287", "0.03", "0", "1"], ["88286.3", "0.03", "0", "1"], ["88284.9", "0.08542891", "0", "1"], ["88283.5", "0.11343045", "0", "1"]], "ts": "1741338234805", "checksum": -444502072, "seqId": 48070580794, "prevSeqId": 48070580370}]}
{"arg": {"channel": "books", "instId": "BTC-USDT"}, "action": "update", "data": [{"asks": [["88526.1", "0.38815883", "0", "11"], ["88526.9", "0", "0", "0"], ["88528", "0.08202223", "0", "8"], ["88528.1", "0", "0", "0"], ["88528.6", "0.00055714", "0", "2"], ["88529.1", "0.0001", "0", "1"], ["88532.8", "0.02615205", "0", "1"], ["88533", "0.02664961", "0", "1"], ["88533.2", "0.08579843", "0", "3"], ["88533.7", "0.02936314", "0", "1"], ["88536.6", "0.08423858", "0", "1"], ["88536.8", "0.22247228", "0", "2"], ["88537.1", "0.08383571", "0", "27"], ["88537.2", "0.08161327", "0", "2"], ["88537.8", "0.083444", "0", "1"], ["88540.2", "0.1352925", "0", "2"], ["88540.7", "0.14803168", "0", "1"], ["88540.8", "0.012117", "0", "2"], ["88541.5", "0.00001152", "0", "1"], ["88541.6", "0.0004477", "0", "2"], ["88542.3", "0.08796688", "0", "2"], ["88542.4", "0.14695527", "0", "1"], ["88543.3", "0.13853931", "0", "2"], ["88545.4", "0.02272441", "0", "5"], ["88554.3", "0.22592558", "0", "1"], ["88554.4", "0.00016676", "0", "1"], ["88554.8", "0.015", "0", "1"], ["88590.1", "0.1", "0", "1"], ["88597.9", "0.0173959", "0", "1"], ["88599.8", "0", "0", "0"], ["88615.9", "0", "0", "0"], ["88616", "0", "0", "0"], ["88616.1", "0", "0", "0"], ["88616.2", "0", "0", "0"], ["88616.6", "0", "0", "0"], ["88616.7", "0", "0", "0"], ["88616.8", "0", "0", "0"], ["88617.6", "0", "0", "0"]], "bids": [["88526", "0.09746", "0", "2"], ["88525.2", "0.0001", "0", "1"], ["88524.9", "0.00744279", "0", "2"], ["88524.6", "0", "0", "0"], ["88524.4", "0", "0", "0"], ["88521.9", "0", "0", "0"], ["88515.6", "0.07957482", "0", "3"], ["88515.5", "0.02764913", "0", "1"], ["88515.3", "0.02765151", "0", "1"], ["88515.1", "0.03000223", "0", "1"], ["88511.8", "0.08966334", "0", "1"], ["88511.6", "0.12968895", "0", "3"], ["88511.3", "0.04853488", "0", "2"], ["88511.2", "0.08056634", "0", "1"], ["88511", "0.07875539", "0", "1"], ["88510.4", "0.24843032", "0", "2"], ["88508.6", "0.1306956", "0", "1"], ["88507.7", "0.14432817", "0", "2"], ["88506.7", "0.01650401", "0", "1"], ["88506.6", "0.14796837", "0", "1"], ["88506.4", "0", "0", "0"], ["88504.8", "0.14457313", "0", "1"], ["88495", "0.22592558", "0", "1"], ["88487", "0.47921", "0", "1"], ["88486", "0.06", "0", "2"], ["88479.2", "0.1", "0", "1"], ["88476.1", "0", "0", "0"], ["88475.2", "0.0173959", "0", "1"], ["88465.2", "0", "0", "0"], ["88462.1", "0.00103795", "0", "2"], ["88401.7", "0", "0", "0"], ["88400.3", "0.17395909", "0", "1"], ["88304", "0.033886", "0", "1"], ["88292", "0", "0", "0"], ["88291", "0", "0", "0"], ["88290", "0", "0", "0"], ["88289.4", "0", "0", "0"], ["88287.1", "0", "0", "0"], ["88287", "0", "0", "0"], ["88286.3", "0", "0", "0"], ["88284.9", "0", "0", "0"], ["88283.5", "0", "0", "0"]], "ts": "1741338234905", "checksum": 799343348, "seqId": 48070581009, "prevSeqId": 48070580794}]}
{"arg": {"channel": "books", "instId": "BTC-USDT"}, "action": "update", "data": [{"asks": [["88527.8", "0.0001", "0", "1"], ["88528", "0.08494076", "0", "9"], ["88528.7", "0", "0", "0"], ["88529.1", "0", "0", "0"], ["88532.8", "0", "0", "0"], ["88533", "0", "0", "0"], ["88533.2", "0.06124314", "0", "2"], ["88533.3", "0.04677208", "0", "19"], ["88533.4", "0.0266652", "0", "3"], ["88533.6", "0.02653599", "0", "2"], ["88533.7", "0", "0", "0"], ["88534.2", "0.02817617", "0", "1"], ["88536.6", "0", "0", "0"], ["88537", "0.08092834", "0", "2"], ["88537.1", "0.0028354", "0", "26"], ["88537.2", "0.00007282", "0", "1"], ["88537.8", "0", "0", "0"], ["88538.4", "0.08843197", "0", "6"], ["88539.6", "0.00370761", "0", "3"], ["88540.2", "0.00007853", "0", "1"], ["88540.7", "0.012102", "0", "1"], ["88540.8", "0.000015", "0", "1"], ["88541.1", "0.13898905", "0", "1"], ["88541.6", "0.01368407", "0", "3"], ["88542.3", "0.00005413", "0", "1"], ["88542.4", "0", "0", "0"], ["88543.3", "0.00001005", "0", "1"], ["88554.3", "0", "0", "0"], ["88554.8", "0", "0", "0"], ["88557.7", "0.2267537", "0", "2"], ["88561.5", "0", "0", "0"], ["88572.2", "0.00002253", "0", "2"], ["88575.9", "0.00001673", "0", "1"], ["88615.9", "0.00001023", "0", "1"], ["88616", "0.00002123", "0", "1"], ["88616.1", "0.00014217", "0", "1"], ["88616.2", "0.00570112", "0", "1"], ["88616.6", "0.000657", "0", "2"], ["88616.7", "0.00006147", "0", "2"], ["88616.8", "0.00570108", "0", "1"], ["88617.6", "0.00002674", "0", "2"]], "bids": [["88526", "0.18196", "0", "2"], ["88525.6", "0.0001", "0", "1"], ["88524.9", "0", "0", "0"], ["88523.4", "0", "0", "0"], ["88521.6", "0.1", "0", "1"], ["88520.2", "0.00145491", "0", "1"], ["88520.1", "0.11296638", "0", "1"], ["88519.2", "0", "0", "0"], ["88516", "0.04228995", "0", "2"], ["88515.9", "0.02636219", "0", "1"], ["88515.8", "0.02745812", "0", "1"], ["88515.6", "0.08047716", "0", "3"], ["88515.5", "0", "0", "0"], ["88515.3", "0", "0", "0"], ["88515.1", "0", "0", "0"], ["88511.8", "0", "0", "0"], ["88511.6", "0.05194673", "0", "2"], ["88511.4", "0.0863378", "0", "1"], ["88511.2", "0", "0", "0"], ["88511", "0", "0", "0"], ["88510.4", "0.11142306", "0", "2"], ["88508.6", "0", "0", "0"], ["88507.9", "0", "0", "0"], ["88507.7", "0.00451938", "0", "1"], ["88506.7", "0", "0", "0"], ["88506.6", "0", "0", "0"], ["88506.4", "0.01650401", "0", "1"], ["88504.8", "0", "0", "0"], ["88503.5", "0.06", "0", "2"], ["88499.2", "0.00059828", "0", "2"], ["88498.4", "0.00029913", "0", "1"], ["88498.2", "0.2259237", "0", "1"], ["88495", "0", "0", "0"], ["88292", "0.0025", "0", "1"], ["88291", "0.005", "0", "2"], ["88290", "0.00001172", "0", "1"], ["88289.4", "0.03", "0", "1"], ["88287.1", "0.03", "0", "1"], ["88287", "0.03", "0", "1"]], "ts": "1741338235005", "checksum": 395436696, "seqId": 48070581121, "prevSeqId": 48070581009}]}
{"arg": {"channel": "books", "instId": "BTC-USDT"}, "action": "update", "data": [{"asks": [["88526.1", "0.32317883", "0", "10"], ["88528", "0.0742833", "0", "9"], ["88528.6", "0.00045714", "0", "1"], ["88529.1", "0.0001", "0", "1"], ["88530.5", "0.01353", "0", "1"], ["88533.1", "0.11266223", "0", "1"], ["88533.3", "0.01783903", "0", "18"], ["88533.4", "0.00026258", "0", "2"], ["88533.5", "0.02856281", "0", "2"], ["88533.6", "0.0000568", "0", "1"], ["88533.7", "0.02739827", "0", "1"], ["88533.9", "0.02673753", "0", "2"], ["88534.2", "0", "0", "0"], ["88534.3", "0.02944488", "0", "1"], ["88536.8", "0.29116002", "0", "2"], ["88537", "0.00005129", "0", "1"], ["88537.2", "0.08330591", "0", "2"], ["88537.8", "0.1676804", "0", "2"], ["88538.4", "0.00528414", "0", "5"], ["88538.5", "0.08501044", "0", "1"], ["88540.5", "0.01482992", "0", "5"], ["88540.7", "0", "0", "0"], ["88540.9", "0.12737828", "0", "1"], ["88541.1", "0", "0", "0"], ["88541.2", "0.13221176", "0", "2"], ["88541.3", "0.14732916", "0", "1"], ["88541.6", "0.0004477", "0", "2"], ["88543", "0.13756466", "0", "3"], ["88544", "0.13652872", "0", "3"], ["88552.4", "0.128161", "0", "1"], ["88554.8", "0.015", "0", "1"], ["88572.6", "0.11992126", "0", "2"], ["88595.3", "0.01739559", "0", "1"], ["88597.9", "0", "0", "0"], ["88612.3", "0.0018374", "0", "1"], ["88613.9", "0", "0", "0"], ["88615.9", "0", "0", "0"], ["88616", "0", "0", "0"], ["88616.1", "0", "0", "0"], ["88616.2", "0", "0", "0"], ["88616.6", "0", "0", "0"], ["88616.7", "0", "0", "0"], ["88616.8", "0", "0", "0"], ["88617.6", "0", "0", "0"]], "bids": [["88526", "0.21591384", "0", "4"], ["88525.8", "0.0001", "0", "1"], ["88525.7", "0.0001", "0", "1"], ["88525.6", "0", "0", "0"], ["88525.2", "0", "0", "0"], ["88522.7", "0.00145491", "0", "1"], ["88520.2", "0", "0", "0"], ["88516.3", "0.02656075", "0", "2"], ["88516.2", "0.02906651", "0", "1"], ["88516", "0.0155", "0", "1"], ["88515.9", "0.02742999", "0", "1"], ["88515.8", "0.03569489", "0", "2"], ["88515.6", "0.0535", "0", "2"], ["88512.5", "0.08710307", "0", "1"], ["88512.4", "0", "0", "0"], ["88512.3", "0.07543772", "0", "1"], ["88511.8", "0.0881782", "0", "1"], ["88511.7", "0.42787909", "0", "2"], ["88511.4", "0", "0", "0"], ["88510.4", "0.22377631", "0", "3"], ["88509.2", "0.13199671", "0", "1"], ["88508.3", "0.14827737", "0", "1"], ["88507.3", "0.12942061", "0", "1"], ["88505.5", "0.14735675", "0", "1"], ["88499.2", "0.00059913", "0", "2"], ["88487", "0.53921", "0", "3"], ["88486", "0", "0", "0"], ["88475.2", "0", "0", "0"], ["88472.5", "0.01739559", "0", "1"], ["88456.5", "0.00001138", "0", "1"], ["88455.9", "0.0009866", "0", "1"], ["88400.3", "0", "0", "0"], ["88393.3", "0.17395598", "0", "1"], ["88304", "0", "0", "0"], ["88291", "0", "0", "0"], ["88290", "0", "0", "0"], ["88289.4", "0", "0", "0"], ["88287.1", "0", "0", "0"], ["88287", "0", "0", "0"]], "ts": "1741338235105", "checksum": -1548970326, "seqId": 48070581293, "prevSeqId": 48070581121}]}
{"arg": {"channel": "books", "instId": "BTC-USDT"}, "action": "update", "data": [{"asks": [["88526.1", "0.32319833", "0", "11"], ["88527.8", "0.0002", "0", "2"], ["88528.7", "0.0000195", "0", "1"], ["88529.1", "0", "0", "0"], ["88533.1", "0.0799282", "0", "1"], ["88533.8", "0", "0", "0"], ["88535.9", "0.00025932", "0", "1"], ["88538.3", "0.04183659", "0", "10"], ["88540.4", "0.012102", "0", "1"], ["88540.5", "0.00272792", "0", "4"], ["88554.8", "0", "0", "0"], ["88595.3", "0.0173956", "0", "1"], ["88615.9", "0.00001023", "0", "1"]], "bids": [["88525.8", "0", "0", "0"], ["88525.7", "0.0002", "0", "2"], ["88511.7", "0.08858185", "0", "1"], ["88510.3", "0.02828", "0", "1"], ["88505.7", "0", "0", "0"], ["88505.1", "0.00198343", "0", "1"], ["88500", "0.0006", "0", "2"], ["88499.2", "0.00029913", "0", "1"], ["88498.4", "0", "0", "0"], ["88497.9", "0", "0", "0"], ["88487", "0.47921", "0", "1"], ["88486", "0.06", "0", "2"], ["88472.5", "0.0173956", "0", "1"], ["88460.8", "2.89663863", "0", "3"], ["88456.2", "0.38583411", "0", "1"], ["88453.7", "0", "0", "0"], ["88414.8", "0.33127863", "0", "2"], ["88304.7", "3.16566437", "0", "1"]], "ts": "1741338235205", "checksum": -487202746, "seqId": 48070581366, "prevSeqId": 48070581293}]}
{"arg": {"channel": "books", "instId": "BTC-USDT"}, "action": "update", "data": [{"asks": [["88526.1", "0.4019162", "0", "12"], ["88527.8", "0", "0", "0"], ["88527.9", "0.0001", "0", "1"], ["88528.6", "0.00055714", "0", "2"], ["88529.9", "0.00006808", "0", "3"], ["88532.4", "0.02990194", "0", "2"], ["88532.6", "0.02707878", "0", "1"], ["88532.8", "0.02643199", "0", "1"], ["88533.1", "0.09767919", "0", "2"], ["88533.3", "0.04725358", "0", "19"], ["88533.5", "0.00001131", "0", "1"], ["88533.7", "0", "0", "0"], ["88533.9", "0.00004614", "0", "1"], ["88534.3", "0", "0", "0"], ["88536.1", "0.08017743", "0", "1"], ["88536.7", "0.08596419", "0", "2"], ["88536.8", "0.27276566", "0", "2"], ["88537.2", "0.00007282", "0", "1"], ["88537.4", "0.08108958", "0", "1"], ["88537.8", "0", "0", "0"], ["88538.5", "0", "0", "0"], ["88539.8", "0.13510123", "0", "1"], ["88540.1", "0.01213493", "0", "2"], ["88540.4", "0", "0", "0"], ["88540.9", "0", "0", "0"], ["88541.2", "0.09663764", "0", "2"], ["88541.3", "0", "0", "0"], ["88542", "0.13839305", "0", "1"], ["88542.9", "0.14472453", "0", "1"], ["88543", "0.00007419", "0", "2"], ["88544", "0.00084248", "0", "2"], ["88554.5", "0.22592538", "0", "1"], ["88557.7", "0.00083", "0", "1"], ["88567.7", "0.08542891", "0", "1"], ["88569", "0.0600615", "0", "3"], ["88570", "0.03", "0", "1"], ["88571", "0.06", "0", "2"], ["88581.1", "0", "0", "0"], ["88581.2", "0", "0", "0"], ["88584.2", "0.23551952", "0", "1"], ["88584.6", "0", "0", "0"], ["88593.3", "0.01739588", "0", "1"], ["88595.3", "0", "0", "0"], ["88595.4", "0.03119322", "0", "2"], ["88600.4", "0", "0", "0"], ["88616", "0.00002123", "0", "1"]], "bids": [["88526", "0.10006784", "0", "2"], ["88525.7", "0", "0", "0"], ["88524.3", "0.0001", "0", "1"], ["88524", "0", "0", "0"], ["88522.9", "0.0001", "0", "1"], ["88522.7", "0", "0", "0"], ["88522.6", "0", "0", "0"], ["88522", "0.0163", "0", "1"], ["88521.8", "0.00145491", "0", "1"], ["88520.1", "0", "0", "0"], ["88519.6", "0", "0", "0"], ["88519.1", "0", "0", "0"], ["88517.8", "0", "0", "0"], ["88516.3", "0", "0", "0"], ["88516.2", "0.00005475", "0", "1"], ["88516.1", "0", "0", "0"], ["88515.9", "0", "0", "0"], ["88515.8", "0.00942", "0", "1"], ["88515.6", "0.0135", "0", "1"], ["88515.5", "0.1129723", "0", "1"], ["88515.4", "0.29256671", "0", "13"], ["88515.2", "0.02647253", "0", "1"], ["88515.1", "0.02689996", "0", "1"], ["88514.9", "0.02611612", "0", "1"], ["88514.7", "0.1336675", "0", "2"], ["88514.3", "0", "0", "0"], ["88514.1", "0", "0", "0"], ["88512.6", "0", "0", "0"], ["88512.5", "0", "0", "0"], ["88512.3", "0", "0", "0"], ["88511.8", "0", "0", "0"], ["88511.7", "0", "0", "0"], ["88511.6", "0", "0", "0"], ["88511.4", "0.08039786", "0", "1"], ["88511.2", "0.08341916", "0", "1"], ["88510.8", "0.11501469", "0", "2"], ["88510.6", "0.0833143", "0", "1"], ["88510.4", "0.32066504", "0", "3"], ["88509.2", "0", "0", "0"], ["88508.3", "0", "0", "0"], ["88507.4", "0.33896138", "0", "2"], ["88507.3", "0", "0", "0"], ["88506.2", "0.13890101", "0", "1"], ["88506", "0.70998728", "0", "2"], ["88505.7", "0.33896", "0", "1"], ["88505.6", "0.00734247", "0", "1"], ["88505.5", "0", "0", "0"], ["88504.4", "0.13697131", "0", "1"], ["88502.2", "0.33929724", "0", "1"], ["88500.8", "0", "0", "0"], ["88500", "0", "0", "0"], ["88499.2", "0.00059913", "0", "2"], ["88498.4", "0.00029913", "0", "1"], ["88498.2", "0", "0", "0"], ["88495", "0.22592538", "0", "1"], ["88493", "0.207", "0", "1"], ["88490", "0", "0", "0"], ["88485.4", "0.93744224", "0", "2"], ["88483.6", "0.2446306", "0", "1"], ["88480.3", "0", "0", "0"], ["88474.3", "0", "0", "0"], ["88473.6", "0", "0", "0"], ["88472.5", "0", "0", "0"], ["88468", "0.01740588", "0", "2"], ["88465", "0.33912", "0", "1"], ["88452.4", "0", "0", "0"], ["88389.5", "0.1260849", "0", "1"], ["88298.9", "0.033886", "0", "1"], ["88291", "0.005", "0", "2"], ["88290", "0.00001172", "0", "1"], ["88289.4", "0.03", "0", "1"], ["88287.1", "0.03", "0", "1"], ["88287", "0.03", "0", "1"], ["88286.3", "0.03", "0", "1"], ["88284.9", "0.08542891", "0", "1"], ["88283.5", "0.11343045", "0", "1"], ["88283.3", "0.00416498", "0", "2"], ["88283", "0.00001722", "0", "1"], ["88281.2", "0.00006263", "0", "1"], ["88281.1", "0.34078752", "0", "2"], ["88280.5", "0.00002567", "0", "1"]], "ts": "1741338235305", "checksum": -433968035, "seqId": 48070581585, "prevSeqId": 48070581366}]}
{"arg": {"channel": "books", "instId": "BTC-USDT"}, "action": "update", "data": [{"asks": [["88526.1", "0.41606521", "0", "13"], ["88526.2", "0.00002025", "0", "1"], ["88527.9", "0", "0", "0"], ["88528.7", "0.00001875", "0", "1"], ["88529", "0.00011678", "0", "2"], ["88529.9", "0.00003508", "0", "2"], ["88532", "0.027602", "0", "2"], ["88536.2", "0.0186343", "0", "1"], ["88536.8", "0.3466517", "0", "3"], ["88540.1", "0.00003293", "0", "1"], ["88540.3", "0.14205692", "0", "1"], ["88548.4", "0.00002745", "0", "2"], ["88568", "0.06", "0", "2"], ["88569", "0.0300615", "0", "2"], ["88569.8", "0.21704", "0", "1"], ["88570", "0", "0", "0"], ["88572.6", "0.07845078", "0", "1"], ["88575", "0.0000626", "0", "2"], ["88583.4", "0.0048", "0", "1"], ["88615.4", "0", "0", "0"], ["88615.9", "0", "0", "0"], ["88616", "0", "0", "0"]], "bids": [["88524.3", "0", "0", "0"], ["88524", "0.0001", "0", "1"], ["88523.1", "0.0001", "0", "1"], ["88522.9", "0", "0", "0"], ["88521.8", "0", "0", "0"], ["88517.9", "0", "0", "0"], ["88516.1", "0.00145491", "0", "1"], ["88515.6", "0.15900829", "0", "2"], ["88515.5", "0", "0", "0"], ["88514.7", "0.17689374", "0", "3"], ["88511.3", "0.08853488", "0", "3"], ["88510.7", "0.0194028", "0", "1"], ["88510.6", "0.2114753", "0", "2"], ["88508.2", "0.13315836", "0", "1"], ["88507.3", "0.13289624", "0", "1"], ["88506.4", "0", "0", "0"], ["88503", "0", "0", "0"], ["88502.6", "0.02671259", "0", "1"], ["88498.2", "0.01650401", "0", "1"], ["88496.5", "0.000168", "0", "1"], ["88469.7", "0.03557385", "0", "1"], ["88450.2", "0.00019397", "0", "1"], ["88283", "0", "0", "0"], ["88281.2", "0", "0", "0"], ["88281.1", "0", "0", "0"], ["88280.5", "0", "0", "0"]], "ts": "1741338235405", "checksum": -968721685, "seqId": 48070581675, "prevSeqId": 48070581585}]}
{"arg": {"channel": "books", "instId": "BTC-USDT"}, "action": "update", "data": [{"asks": [["88520", "0.55077239", "0", "20"], ["88520.9", "0.03383826", "0", "1"], ["88521", "0.06064094", "0", "2"], ["88521.3", "0.0001", "0", "1"], ["88522", "0.0001", "0", "1"], ["88523.2", "0.05205327", "0", "2"], ["88524", "0.0163", "0", "1"], ["88524.3", "0.08051453", "0", "1"], ["88526", "0.0163", "0", "1"], ["88526.1", "0.06334942", "0", "3"], ["88526.2", "0", "0", "0"], ["88527.3", "0", "0", "0"], ["88527.4", "0", "0", "0"], ["88528", "0.0878133", "0", "10"], ["88528.4", "0.17674706", "0", "6"], ["88528.6", "0.00045714", "0", "1"], ["88528.7", "0", "0", "0"], ["88528.8", "0.00503975", "0", "2"], ["88529", "0.00001678", "0", "1"], ["88530.5", "0", "0", "0"], ["88530.8", "0.04061156", "0", "2"], ["88532", "0.027617", "0", "3"], ["88532.4", "0.00037328", "0", "1"], ["88532.6", "0", "0", "0"], ["88532.8", "0", "0", "0"], ["88533.1", "0.11473418", "0", "2"], ["88533.2", "0", "0", "0"], ["88533.3", "0.01783903", "0", "18"], ["88535", "0", "0", "0"], ["88535.5", "0.00037194", "0", "10"], ["88535.8", "0.00026192", "0", "1"], ["88536.1", "0", "0", "0"], ["88536.5", "0.01888533", "0", "1"], ["88536.7", "0.00001", "0", "1"], ["88536.8", "0.17390784", "0", "1"], ["88537.2", "0.01136778", "0", "2"], ["88537.4", "0", "0", "0"], ["88538.3", "0.00124659", "0", "9"], ["88539.8", "0", "0", "0"], ["88540.3", "0", "0", "0"], ["88541.2", "0.01337413", "0", "1"], ["88542", "0", "0", "0"], ["88542.9", "0", "0", "0"], ["88546.5", "0.08543891", "0", "2"], ["88548.7", "0", "0", "0"], ["88549.7", "0.207", "0", "1"], ["88552.3", "0.2259343", "0", "1"], ["88553.7", "0.04", "0", "1"], ["88554.5", "0", "0", "0"], ["88556", "0.03616508", "0", "2"], ["88556.6", "0", "0", "0"], ["88558.7", "0", "0", "0"], ["88562.1", "0", "0", "0"], ["88568", "0", "0", "0"], ["88569", "0.1200615", "0", "5"], ["88570", "0.03", "0", "1"], ["88571", "0", "0", "0"], ["88573.7", "0.497891", "0", "1"], ["88577.2", "0.497871", "0", "1"], ["88587.3", "0.01739752", "0", "1"], ["88590.1", "0", "0", "0"], ["88593.3", "0", "0", "0"], ["88612.3", "0", "0", "0"], ["88612.7", "0.02259321", "0", "1"], ["88615.4", "0.00002919", "0", "1"], ["88615.9", "0.00001023", "0", "1"], ["88616", "0.00169776", "0", "2"], ["88616.1", "0.00014217", "0", "1"], ["88616.2", "0.00570112", "0", "1"], ["88616.6", "0.000657", "0", "2"], ["88616.7", "0.00006147", "0", "2"], ["88616.8", "0.00570108", "0", "1"]], "bids": [["88526", "0", "0", "0"], ["88524", "0", "0", "0"], ["88523.2", "0", "0", "0"], ["88523.1", "0", "0", "0"], ["88522", "0", "0", "0"], ["88521.7", "0", "0", "0"], ["88521.6", "0", "0", "0"], ["88521", "0", "0", "0"], ["88520.9", "0", "0", "0"], ["88520", "0", "0", "0"], ["88519.9", "0.02174267", "0", "3"], ["88519.8", "0.00002775", "0", "1"], ["88516.2", "0", "0", "0"], ["88516.1", "0", "0", "0"], ["88515.8", "0", "0", "0"], ["88515.6", "0", "0", "0"], ["88515.4", "0", "0", "0"], ["88515.2", "0", "0", "0"], ["88515.1", "0", "0", "0"], ["88514.9", "0", "0", "0"], ["88514.7", "0.04322624", "0", "1"], ["88513.2", "0.04", "0", "1"], ["88512.1", "0.0001", "0", "1"], ["88511.8", "0.0001", "0", "1"], ["88511.4", "0", "0", "0"], ["88511.3", "0.05983315", "0", "3"], ["88511.2", "0", "0", "0"], ["88510.8", "0", "0", "0"], ["88510.6", "0", "0", "0"], ["88510.4", "0.06024515", "0", "1"], ["88510.3", "0", "0", "0"], ["88510.1", "0.00007275", "0", "1"], ["88509.8", "0.04", "0", "1"], ["88508.2", "0.00145491", "0", "1"], ["88508.1", "0.01357284", "0", "1"], ["88507.7", "0", "0", "0"], ["88507.4", "0.00001138", "0", "1"], ["88507.3", "0", "0", "0"], ["88506.3", "0", "0", "0"], ["88506.2", "0", "0", "0"], ["88506", "0.47980543", "0", "2"], ["88505.7", "0", "0", "0"], ["88504.4", "0", "0", "0"], ["88502.7", "0", "0", "0"], ["88502.6", "0", "0", "0"], ["88499.2", "0", "0", "0"], ["88498.8", "0.00451984", "0", "1"], ["88498.4", "0", "0", "0"], ["88496.9", "0.36286189", "0", "1"], ["88496.5", "0", "0", "0"], ["88496", "0.0006", "0", "2"], ["88495.3", "0.008436", "0", "1"], ["88495.2", "0.00031415", "0", "2"], ["88495", "0", "0", "0"], ["88494.9", "0", "0", "0"], ["88494.4", "0.2259343", "0", "1"], ["88493.4", "0.02671259", "0", "1"], ["88492", "0.02698183", "0", "1"], ["88491.6", "0.183915", "0", "1"], ["88491.3", "0", "0", "0"], ["88490.4", "0.00001138", "0", "1"], ["88489.6", "0", "0", "0"], ["88486", "0", "0", "0"], ["88485.6", "0", "0", "0"], ["88485.4", "0.90244663", "0", "1"], ["88485.3", "0.03632717", "0", "1"], ["88485.2", "0.498388", "0", "1"], ["88485", "0", "0", "0"], ["88484", "0", "0", "0"], ["88483", "0.06", "0", "2"], ["88481", "0.06", "0", "2"], ["88480", "0.08194673", "0", "3"], ["88479.2", "0", "0", "0"], ["88476.3", "0.55897384", "0", "1"], ["88473.5", "0.01128902", "0", "1"], ["88472.6", "0.0112889", "0", "1"], ["88472.4", "0", "0", "0"], ["88471.8", "0.498463", "0", "1"], ["88471.1", "0.21828909", "0", "2"], ["88468", "0.00001", "0", "1"], ["88466.9", "0.03247121", "0", "1"], ["88465", "0", "0", "0"], ["88464", "0.01739752", "0", "1"], ["88462.1", "0.00001138", "0", "1"], ["88459.4", "0.00102679", "0", "1"], ["88455.9", "0", "0", "0"], ["88453.1", "0", "0", "0"], ["88452.4", "0.00098675", "0", "1"], ["88450.2", "0", "0", "0"], ["88448.6", "0", "0", "0"], ["88434", "0", "0", "0"], ["88433.6", "0.748033", "0", "2"], ["88409.6", "0", "0", "0"], ["88400.7", "0", "0", "0"], ["88393.3", "0", "0", "0"], ["88391.2", "0.00564806", "0", "1"], ["88389.6", "0.17399021", "0", "2"], ["88363.3", "0.14881257", "0", "1"], ["88354.6", "0", "0", "0"], ["88340.7", "0.00001138", "0", "1"], ["88327.1", "2.88866", "0", "1"], ["88296.4", "0.207", "0", "1"], ["88283", "0.00001722", "0", "1"], ["88281.2", "0.00006263", "0", "1"], ["88281.1", "0.34078752", "0", "2"], ["88280.5", "0.00002567", "0", "1"], ["88279.9", "0.00001655", "0", "1"], ["88276.1", "0.00007", "0", "1"], ["88275.5", "0.00001139", "0", "1"], ["88275", "0.00009665", "0", "2"], ["88274.6", "0.00001339", "0", "1"], ["88274.4", "0.000015", "0", "1"], ["88274.2", "0.00002298", "0", "1"], ["88274.1", "0.03", "0", "1"], ["88274", "0.06797011", "0", "1"], ["88273.4", "0.01785714", "0", "1"], ["88272.7", "0.00003889", "0", "1"], ["88272.2", "0.00282458", "0", "1"], ["88272", "0.0025", "0", "1"], ["88271.5", "0.01148", "0", "1"], ["88271.3", "0.00002208", "0", "1"], ["88270.8", "0.00001148", "0", "1"], ["88270.7", "0.00003554", "0", "1"], ["88270", "0.00004066", "0", "1"], ["88269.4", "0.11343045", "0", "1"]], "ts": "1741338235505", "checksum": -1448806027, "seqId": 48070582462, "prevSeqId": 48070581675}]}
{"arg": {"channel": "books", "instId": "BTC-USDT"}, "action": "update", "data": [{"asks": [["88520", "0.51671912", "0", "20"], ["88521.3", "0", "0", "0"], ["88522", "0", "0", "0"], ["88524.3", "0.05318047", "0", "2"], ["88524.5", "0.02779477", "0", "1"], ["88524.7", "0.02708217", "0", "1"], ["88524.9", "0.02643047", "0", "1"], ["88525", "0.0002", "0", "2"], ["88525.5", "0.02886284", "0", "1"], ["88528.3", "0.25132746", "0", "2"], ["88528.4", "0.00330881", "0", "5"], ["88528.8", "0.08394159", "0", "3"], ["88528.9", "0.07529358", "0", "2"], ["88529.7", "0.08540052", "0", "1"], ["88531.9", "0.13041885", "0", "3"], ["88532.4", "0.14480588", "0", "2"], ["88533.1", "0.09480512", "0", "2"], ["88534.2", "0.13128137", "0", "1"], ["88535", "0.13397189", "0", "1"], ["88536.4", "0.02279001", "0", "3"], ["88541.2", "0", "0", "0"], ["88541.5", "0.04501152", "0", "2"], ["88545.1", "0.13501083", "0", "4"], ["88545.4", "0.00013356", "0", "4"], ["88550.5", "0.129", "0", "3"], ["88567", "0.06", "0", "2"], ["88568", "0.09", "0", "3"], ["88569", "0.0000615", "0", "1"], ["88570", "0", "0", "0"], ["88587.2", "0.10003998", "0", "2"], ["88612.9", "0.00167653", "0", "1"], ["88615.4", "0", "0", "0"], ["88615.9", "0", "0", "0"], ["88616", "0", "0", "0"], ["88616.1", "0", "0", "0"], ["88616.2", "0", "0", "0"], ["88616.6", "0", "0", "0"], ["88616.7", "0", "0", "0"], ["88616.8", "0", "0", "0"]], "bids": [["88519.9", "0.01964267", "0", "2"], ["88512.1", "0", "0", "0"], ["88511.8", "0", "0", "0"], ["88511.5", "0.0001", "0", "1"], ["88511.2", "0.0001", "0", "1"], ["88510.5", "0.0007445", "0", "1"], ["88510.4", "0.09845562", "0", "1"], ["88508.2", "0", "0", "0"], ["88507.3", "0.02662518", "0", "1"], ["88507.2", "0.02632903", "0", "1"], ["88507.1", "0.02841218", "0", "1"], ["88506.8", "0.02734873", "0", "1"], ["88506.3", "0.128161", "0", "1"], ["88503.5", "0.14615793", "0", "3"], ["88503.3", "0.97529903", "0", "2"], ["88503", "0.08094287", "0", "1"], ["88502.7", "0.08642169", "0", "1"], ["88500.3", "0.1242986", "0", "1"], ["88499.9", "0.00058262", "0", "2"], ["88499.4", "0.13562448", "0", "1"], ["88498.6", "0.01650401", "0", "1"], ["88498.5", "0.13017118", "0", "1"], ["88498.3", "0.015", "0", "1"], ["88498.2", "0", "0", "0"], ["88496.5", "0.13169098", "0", "1"], ["88459.4", "0", "0", "0"], ["88456.5", "0.00103815", "0", "2"], ["88452.4", "0", "0", "0"], ["88450.2", "0.00019397", "0", "1"], ["88447", "0.00098673", "0", "1"], ["88446.3", "0", "0", "0"], ["88432.7", "0.02259367", "0", "1"], ["88402.9", "0", "0", "0"], ["88393.4", "0.00212215", "0", "1"], ["88274.1", "0", "0", "0"], ["88274", "0", "0", "0"], ["88273.4", "0", "0", "0"], ["88272.7", "0", "0", "0"], ["88272.2", "0", "0", "0"], ["88272", "0", "0", "0"], ["88271.5", "0", "0", "0"], ["88271.3", "0", "0", "0"], ["88270.8", "0", "0", "0"], ["88270.7", "0", "0", "0"], ["88270", "0", "0", "0"], ["88269.4", "0", "0", "0"]], "ts": "1741338235605", "checksum": 1384452066, "seqId": 48070582617, "prevSeqId": 48070582462}]}
{"arg": {"channel": "books", "instId": "BTC-USDT"}, "action": "update", "data": [{"asks": [["88520", "0.516596", "0", "19"], ["88520.9", "0.01970498", "0", "1"], ["88521", "0", "0", "0"], ["88521.5", "0.01353", "0", "1"], ["88524.8", "0.02527629", "0", "1"], ["88524.9", "0", "0", "0"], ["88527.9", "0.000183", "0", "1"], ["88528", "0.0742833", "0", "9"], ["88528.2", "0.08340723", "0", "1"], ["88528.3", "0.1711373", "0", "2"], ["88528.8", "0.16599919", "0", "4"], ["88528.9", "0.00112783", "0", "1"], ["88532.3", "0.14894809", "0", "2"], ["88532.4", "0.00037328", "0", "1"], ["88541.5", "0.09001152", "0", "3"], ["88545.1", "0.17401083", "0", "5"], ["88550.5", "0.039", "0", "1"], ["88557.7", "0", "0", "0"], ["88570.3", "0.00461", "0", "2"], ["88572.8", "0.0006", "0", "2"], ["88573.6", "0.0003", "0", "1"], ["88576", "0.0132977", "0", "3"], ["88576.8", "0.339112", "0", "2"], ["88584", "0.21343045", "0", "2"], ["88587.2", "0.00003998", "0", "1"], ["88615", "0", "0", "0"], ["88615.2", "0", "0", "0"], ["88615.3", "0", "0", "0"]], "bids": [["88511.5", "0", "0", "0"], ["88511.3", "0.02993315", "0", "3"], ["88507.8", "0.02698183", "0", "1"], ["88507.3", "0", "0", "0"], ["88507.2", "0.05298944", "0", "2"], ["88506.7", "0.03", "0", "1"], ["88504.4", "0.00943", "0", "1"], ["88500.4", "0.015", "0", "1"], ["88500.3", "0", "0", "0"], ["88500.2", "0.12420033", "0", "1"], ["88499.4", "0", "0", "0"], ["88499.3", "0.14391524", "0", "1"], ["88498.3", "0", "0", "0"], ["88497.8", "0.02829", "0", "1"], ["88492", "0", "0", "0"], ["88473.1", "0.1", "0", "1"], ["88450.2", "0", "0", "0"], ["88444", "0.00019398", "0", "1"], ["88434.4", "0", "0", "0"], ["88423.1", "0.0045196", "0", "1"], ["88422.7", "0.00007205", "0", "1"], ["88422.6", "0.0007205", "0", "1"], ["88298.3", "0", "0", "0"], ["88274.4", "0", "0", "0"], ["88274.2", "0", "0", "0"]], "ts": "1741338235705", "checksum": -1904093805, "seqId": 48070582714, "prevSeqId": 48070582617}]}
{"arg": {"channel": "books", "instId": "BTC-USDT"}, "action": "update", "data": [{"asks": [["88520", "0.27891901", "0", "11"], ["88520.9", "0.04918098", "0", "2"], ["88521.5", "0", "0", "0"], ["88522.3", "0.11296374", "0", "1"], ["88523.2", "0.03625327", "0", "3"], ["88524.5", "0", "0", "0"], ["88524.7", "0", "0", "0"], ["88524.8", "0", "0", "0"], ["88525", "0", "0", "0"], ["88525.5", "0", "0", "0"], ["88526.1", "0.04734942", "0", "2"], ["88526.9", "0.0000105", "0", "1"], ["88527.5", "0.0276631", "0", "1"], ["88527.6", "0.02935055", "0", "1"], ["88527.8", "0.02437801", "0", "1"], ["88527.9", "0", "0", "0"], ["88528.2", "0.02782091", "0", "1"], ["88528.3", "0.11441125", "0", "1"], ["88528.8", "0.00503975", "0", "2"], ["88529.7", "0", "0", "0"], ["88531.2", "0.08687583", "0", "1"], ["88531.8", "0.15462097", "0", "2"], ["88531.9", "0.0002131", "0", "2"], ["88532", "0.015515", "0", "2"], ["88532.3", "0.00011329", "0", "1"], ["88532.4", "0.07837668", "0", "2"], ["88533.1", "0.09549836", "0", "1"], ["88534.2", "0", "0", "0"], ["88534.8", "0.13086145", "0", "2"], ["88535", "0", "0", "0"], ["88535.3", "0.13257593", "0", "1"], ["88536.9", "0.34794608", "0", "2"], ["88538", "0.13404855", "0", "1"], ["88546.5", "0.00001", "0", "1"], ["88547", "0.00001139", "0", "1"], ["88558", "0.00004957", "0", "3"], ["88615", "0.00001139", "0", "1"]], "bids": [["88519.9", "0.19996764", "0", "7"], ["88519.3", "0.0002", "0", "2"], ["88518.9", "0.11296791", "0", "1"], ["88516.4", "0.00734297", "0", "1"], ["88514.7", "0.11523011", "0", "1"], ["88511.5", "0.00145491", "0", "1"], ["88511.4", "0.06064512", "0", "2"], ["88511.3", "0.02983315", "0", "2"], ["88511.2", "0", "0", "0"], ["88510.8", "0.06064512", "0", "2"], ["88510.5", "0", "0", "0"], ["88510.4", "0.34811051", "0", "1"], ["88510.2", "0.05756232", "0", "2"], ["88509.8", "0.09434163", "0", "3"], ["88508.8", "0.33895", "0", "1"], ["88508.1", "0", "0", "0"], ["88507.2", "0", "0", "0"], ["88507.1", "0", "0", "0"], ["88507", "0.36896", "0", "2"], ["88506.8", "0", "0", "0"], ["88506.4", "0.08048596", "0", "1"], ["88506.2", "0.07345564", "0", "1"], ["88505.7", "0.07763425", "0", "1"], ["88505.6", "0.09226411", "0", "2"], ["88503.5", "0.06", "0", "2"], ["88503.3", "0.90244663", "0", "1"], ["88503.2", "0.12290631", "0", "1"], ["88503", "0", "0", "0"], ["88502.7", "0", "0", "0"], ["88502.3", "0.13380387", "0", "1"], ["88502.1", "0.207", "0", "1"], ["88501.7", "0.01650401", "0", "1"], ["88501.2", "0.14158069", "0", "1"], ["88500.2", "0", "0", "0"], ["88499.9", "0.00057148", "0", "1"], ["88499.5", "0.14152045", "0", "1"], ["88499.3", "0", "0", "0"], ["88498.6", "0", "0", "0"], ["88498.5", "0", "0", "0"], ["88496.5", "0", "0", "0"], ["88276.1", "0", "0", "0"], ["88275.5", "0", "0", "0"], ["88275", "0", "0", "0"], ["88274.6", "0", "0", "0"]], "ts": "1741338235805", "checksum": -291865535, "seqId": 48070582887, "prevSeqId": 48070582714}]}
{"arg": {"channel": "books", "instId": "BTC-USDT"}, "action": "update", "data": [{"asks": [["88520", "0.0406", "0", "1"], ["88520.9", "0", "0", "0"], ["88522", "0.0163", "0", "1"], ["88523.2", "0.0001", "0", "1"], ["88523.9", "0.01986785", "0", "1"], ["88524.3", "0", "0", "0"], ["88524.7", "0.0001", "0", "1"], ["88526.1", "0.01129615", "0", "1"], ["88526.9", "0", "0", "0"], ["88527.5", "0", "0", "0"], ["88527.6", "0", "0", "0"], ["88527.8", "0", "0", "0"], ["88528", "0.02016213", "0", "6"], ["88528.2", "0", "0", "0"], ["88528.3", "0.04296132", "0", "1"], ["88528.4", "0.00129879", "0", "3"], ["88529.1", "0.05678484", "0", "2"], ["88530.8", "0.00001156", "0", "1"], ["88531.2", "0", "0", "0"], ["88531.8", "0", "0", "0"], ["88532.4", "0.08215697", "0", "2"], ["88532.6", "0.12258545", "0", "2"], ["88533", "0.07935978", "0", "1"], ["88533.1", "0", "0", "0"], ["88533.2", "0.08842579", "0", "1"], ["88534.8", "0.00092933", "0", "1"], ["88535.3", "0", "0", "0"], ["88536.8", "0.25144158", "0", "3"], ["88536.9", "0.207", "0", "1"], ["88537.7", "0.13444579", "0", "1"], ["88538", "0", "0", "0"], ["88538.9", "0.04059", "0", "1"], ["88539.2", "0.14775344", "0", "1"], ["88541.4", "0.08579688", "0", "1"], ["88550.5", "0", "0", "0"], ["88552.3", "0", "0", "0"], ["88553.7", "0", "0", "0"], ["88555.9", "0.22592132", "0", "1"], ["88556.3", "0.04", "0", "1"], ["88567", "0", "0", "0"], ["88568", "0.12", "0", "4"], ["88569", "0.0300615", "0", "2"], ["88570", "0.2", "0", "1"], ["88615.2", "0.0036953", "0", "1"], ["88615.3", "0.00001787", "0", "1"]], "bids": [["88519.9", "0.32906464", "0", "10"], ["88519.8", "0.0002", "0", "2"], ["88519.5", "0.00145491", "0", "1"], ["88519.4", "0.04", "0", "1"], ["88519.3", "0", "0", "0"], ["88519.1", "0.02239748", "0", "1"], ["88519", "0.2333127", "0", "2"], ["88518.5", "0.08542891", "0", "1"], ["88516.5", "0.03032256", "0", "1"], ["88515.5", "0.1", "0", "1"], ["88515.4", "0.33892", "0", "1"], ["88514.7", "0.36909399", "0", "1"], ["88513.6", "0.34835", "0", "2"], ["88513.2", "0", "0", "0"], ["88511.9", "0.33894", "0", "1"], ["88511.5", "0.36384205", "0", "2"], ["88511.4", "0.02836624", "0", "1"], ["88511.3", "0.14280203", "0", "5"], ["88511", "0.00943", "0", "1"], ["88510.8", "0", "0", "0"], ["88510.6", "0.02716924", "0", "1"], ["88510.4", "0.12477521", "0", "1"], ["88510.3", "0.05648444", "0", "1"], ["88510.2", "0", "0", "0"], ["88510.1", "0.0000735", "0", "1"], ["88509.8", "0.04", "0", "1"], ["88508.8", "0", "0", "0"], ["88507.8", "0", "0", "0"], ["88507.7", "0.08687613", "0", "1"], ["88507", "0.03", "0", "1"], ["88506.5", "0.08067343", "0", "1"], ["88506.4", "0", "0", "0"], ["88506.2", "0", "0", "0"], ["88506", "0.69951537", "0", "3"], ["88505.9", "0.08542891", "0", "1"], ["88505.7", "0", "0", "0"], ["88505.6", "0.00734247", "0", "1"], ["88504.4", "0", "0", "0"], ["88504.3", "0.02829", "0", "1"], ["88504.2", "0.1", "0", "1"], ["88503.2", "0", "0", "0"], ["88502.3", "0", "0", "0"], ["88502", "0.13280656", "0", "1"], ["88501.6", "0.6477803", "0", "4"], ["88501.2", "0", "0", "0"], ["88500.9", "0.02698183", "0", "1"], ["88500.7", "0.15049152", "0", "1"], ["88500.4", "0", "0", "0"], ["88500.3", "0.00001114", "0", "1"], ["88499.5", "0", "0", "0"], ["88498.8", "0", "0", "0"], ["88498.2", "0.22592132", "0", "1"], ["88497.8", "0", "0", "0"], ["88497.5", "0", "0", "0"], ["88495.3", "0", "0", "0"], ["88494.6", "0.02671259", "0", "1"], ["88494.4", "0", "0", "0"], ["88493.4", "0", "0", "0"], ["88491.5", "0.17448117", "0", "1"], ["88488.5", "0.1", "0", "1"], ["88488.3", "0.00343", "0", "1"], ["88483.3", "0.01177148", "0", "2"], ["88483", "0.12", "0", "4"], ["88482", "0.03", "0", "1"], ["88481", "0", "0", "0"], ["88480", "0.05194673", "0", "2"], ["88316.5", "6.20124559", "0", "1"], ["88283.3", "0", "0", "0"], ["88283", "0", "0", "0"], ["88281.2", "0", "0", "0"], ["88281.1", "0", "0", "0"], ["88280.5", "0", "0", "0"], ["88279.9", "0", "0", "0"]], "ts": "1741338235905", "checksum": 795228496, "seqId": 48070583295, "prevSeqId": 48070582887}]}
{"arg": {"channel": "books", "instId": "BTC-USDT"}, "action": "update", "data": [{"asks": [["88520", "0", "0", "0"], ["88522", "0.0971", "0", "4"], ["88523.2", "0", "0", "0"], ["88524.7", "0", "0", "0"], ["88525.7", "0.0001", "0", "1"], ["88525.8", "0.0001", "0", "1"], ["88528.3", "0.03529642", "0", "2"], ["88528.4", "0.00029378", "0", "2"], ["88528.8", "0.005", "0", "1"], ["88529.1", "0", "0", "0"], ["88529.8", "0.03128782", "0", "4"], ["88530", "0.04290145", "0", "4"], ["88530.2", "0.02667935", "0", "1"], ["88530.3", "0.02649081", "0", "1"], ["88532.4", "0.00037328", "0", "1"], ["88532.6", "0.09685924", "0", "2"], ["88533", "0", "0", "0"], ["88533.2", "0", "0", "0"], ["88533.5", "0.08325974", "0", "2"], ["88534.1", "0.08043628", "0", "1"], ["88534.2", "0.07413462", "0", "1"], ["88534.4", "0.08588911", "0", "2"], ["88534.9", "0.01211203", "0", "2"], ["88536.8", "0.23933958", "0", "2"], ["88536.9", "0", "0", "0"], ["88537.2", "0.14269007", "0", "3"], ["88537.7", "0.13415388", "0", "1"], ["88539", "0.13130381", "0", "1"], ["88539.2", "0", "0", "0"], ["88539.6", "0.00031761", "0", "2"], ["88539.8", "0.207", "0", "1"], ["88540.3", "0.13361737", "0", "1"], ["88554.8", "0.015", "0", "1"], ["88555.9", "0", "0", "0"], ["88556.2", "0.22592066", "0", "1"], ["88558.8", "0.00340008", "0", "2"], ["88567", "0.06", "0", "2"], ["88568", "0.09", "0", "3"], ["88569", "0.0000615", "0", "1"], ["88584", "0.11343045", "0", "1"], ["88586", "0.1", "0", "1"], ["88596", "0.03003743", "0", "3"], ["88612.9", "0", "0", "0"], ["88615", "0", "0", "0"], ["88615.2", "0", "0", "0"], ["88615.3", "0", "0", "0"]], "bids": [["88521.9", "0.41498191", "0", "11"], ["88520.3", "0.00145491", "0", "1"], ["88520.2", "0.0380479", "0", "1"], ["88520.1", "0.01516128", "0", "1"], ["88520", "0.03869748", "0", "2"], ["88519.9", "0.00224267", "0", "1"], ["88519.8", "0", "0", "0"], ["88519.7", "0.0002", "0", "2"], ["88519.5", "0", "0", "0"], ["88519", "0.21091522", "0", "1"], ["88518.9", "0", "0", "0"], ["88516.5", "0", "0", "0"], ["88512.6", "0.02563767", "0", "1"], ["88512.5", "0.02873359", "0", "1"], ["88512.2", "0.000072", "0", "1"], ["88512.1", "0.02918539", "0", "1"], ["88511.9", "0.36818527", "0", "2"], ["88511.5", "0.33929724", "0", "1"], ["88511.4", "0", "0", "0"], ["88510.6", "0", "0", "0"], ["88510.4", "0.18349537", "0", "2"], ["88510.1", "0", "0", "0"], ["88508.8", "0.08739247", "0", "1"], ["88508.6", "0.07824545", "0", "1"], ["88508", "0.09838153", "0", "2"], ["88507.8", "0.08396464", "0", "1"], ["88507.7", "0", "0", "0"], ["88506.5", "0", "0", "0"], ["88505.6", "0.13310266", "0", "2"], ["88505.4", "0.0045195", "0", "1"], ["88504.7", "0.14684082", "0", "1"], ["88503.2", "0.13008798", "0", "1"], ["88502", "0", "0", "0"], ["88501.8", "0.13424223", "0", "2"], ["88500.7", "0", "0", "0"], ["88500.3", "0", "0", "0"], ["88497.6", "0.00059914", "0", "2"], ["88496.8", "0.00029914", "0", "1"], ["88496", "0", "0", "0"], ["88495.2", "0.00001501", "0", "1"], ["88488.5", "0", "0", "0"], ["88485", "0.06", "0", "2"], ["88484", "0.06", "0", "2"], ["88483", "0.03", "0", "1"], ["88482", "0", "0", "0"], ["88473.1", "0", "0", "0"], ["88471.1", "0.24101909", "0", "3"], ["88458.8", "0.00102666", "0", "1"], ["88456.5", "0.00001138", "0", "1"], ["88451.9", "0.00098661", "0", "1"], ["88447", "0", "0", "0"], ["88388.1", "0.174001", "0", "1"], ["88343.7", "0", "0", "0"], ["88287.1", "0", "0", "0"], ["88287", "0", "0", "0"], ["88286.3", "0", "0", "0"], ["88284.9", "0", "0", "0"], ["88283.5", "0", "0", "0"]], "ts": "1741338236005", "checksum": -555748119, "seqId": 48070583599, "prevSeqId": 48070583295}]}
{"arg": {"channel": "books", "instId": "BTC-USDT"}, "action": "update", "data": [{"asks": [["88522", "0.0777", "0", "3"], ["88525.4", "0.0002", "0", "2"], ["88525.7", "0", "0", "0"], ["88525.8", "0", "0", "0"], ["88528.3", "0.04271516", "0", "2"], ["88529.8", "0.00202635", "0", "3"], ["88530", "0.01559419", "0", "3"], ["88530.2", "0", "0", "0"], ["88530.3", "0", "0", "0"], ["88532.6", "0.10618578", "0", "2"], ["88533.5", "0.00034131", "0", "2"], ["88534.1", "0", "0", "0"], ["88534.2", "0", "0", "0"], ["88534.4", "0.00001094", "0", "1"], ["88534.6", "0.01353", "0", "1"], ["88534.9", "0.00001003", "0", "1"], ["88536.8", "0.25144158", "0", "3"], ["88537.2", "0.01136778", "0", "2"], ["88537.7", "0", "0", "0"], ["88539", "0", "0", "0"], ["88540.3", "0", "0", "0"], ["88552.3", "0.03873033", "0", "1"], ["88554.8", "0", "0", "0"], ["88556.2", "0", "0", "0"], ["88559.4", "0.22624231", "0", "2"], ["88567.9", "0.00001005", "0", "1"], ["88582", "0.39406355", "0", "1"], ["88587.3", "0", "0", "0"], ["88593.1", "0.01739543", "0", "1"], ["88601.8", "0", "0", "0"], ["88615", "0.00001139", "0", "1"], ["88615.1", "0.0016765", "0", "1"], ["88615.2", "0.0036953", "0", "1"], ["88615.3", "0.00001787", "0", "1"], ["88615.4", "0.00002919", "0", "1"], ["88615.9", "0.00001023", "0", "1"], ["88616", "0.00002123", "0", "1"], ["88616.1", "0.00014217", "0", "1"]], "bids": [["88521.8", "0.00001275", "0", "1"], ["88520.6", "0.00942", "0", "1"], ["88519.8", "0.0002", "0", "2"], ["88519.7", "0", "0", "0"], ["88514", "0.04378", "0", "2"], ["88512.6", "0", "0", "0"], ["88512.5", "0", "0", "0"], ["88512.2", "0", "0", "0"], ["88512.1", "0.00007275", "0", "1"], ["88511.9", "0.33894", "0", "1"], ["88511", "0", "0", "0"], ["88510.4", "0.18302026", "0", "2"], ["88508.8", "0", "0", "0"], ["88508.6", "0", "0", "0"], ["88508", "0.0155", "0", "1"], ["88507.8", "0", "0", "0"], ["88505.6", "0.00734247", "0", "1"], ["88504.7", "0", "0", "0"], ["88504.3", "0", "0", "0"], ["88503.6", "0.22591558", "0", "1"], ["88503.2", "0", "0", "0"], ["88501.8", "0.00001138", "0", "1"], ["88498.2", "0", "0", "0"], ["88497.7", "0", "0", "0"], ["88475.1", "0.74644062", "0", "2"], ["88469.8", "0.01739543", "0", "1"], ["88464", "0", "0", "0"], ["88463.8", "0", "0", "0"], ["88462", "1.01216159", "0", "1"], ["88458.8", "0.00102667", "0", "1"], ["88433.9", "0.14948066", "0", "3"], ["88397.8", "0.00212121", "0", "1"], ["88393.5", "0.17395386", "0", "1"], ["88393.4", "0", "0", "0"], ["88389.6", "0.00001501", "0", "1"], ["88363.3", "0", "0", "0"], ["88287.1", "0.03", "0", "1"], ["88287", "0.03", "0", "1"], ["88286.3", "0.03", "0", "1"], ["88284.9", "0.08542891", "0", "1"], ["88283.5", "0.11343045", "0", "1"], ["88283.3", "0.00416498", "0", "2"], ["88283", "0.00001722", "0", "1"], ["88281.2", "0.00006263", "0", "1"], ["88281.1", "0.34078752", "0", "2"], ["88280.5", "0.00002567", "0", "1"]], "ts": "1741338236105", "checksum": 1442109953, "seqId": 48070583808, "prevSeqId": 48070583599}]}
{"arg": {"channel": "books", "instId": "BTC-USDT"}, "action": "update", "data": [{"asks": [["88522", "0", "0", "0"], ["88522.3", "0", "0", "0"], ["88523.9", "0", "0", "0"], ["88524", "0", "0", "0"], ["88525.4", "0", "0", "0"], ["88526", "0", "0", "0"], ["88526.1", "0", "0", "0"], ["88528", "0.15418515", "0", "9"], ["88528.1", "0.0000345", "0", "1"], ["88528.3", "0", "0", "0"], ["88530.9", "0.0001", "0", "1"], ["88531.5", "0.0001", "0", "1"], ["88532", "0.0155", "0", "1"], ["88532.6", "0", "0", "0"], ["88533.5", "0.00001131", "0", "1"], ["88534.6", "0", "0", "0"], ["88536", "0.01129488", "0", "1"], ["88536.2", "0", "0", "0"], ["88536.4", "0.00019692", "0", "2"], ["88536.5", "0", "0", "0"], ["88536.6", "0.02695284", "0", "1"], ["88536.8", "0", "0", "0"], ["88537.2", "0.00007282", "0", "1"], ["88538.9", "0", "0", "0"], ["88539.6", "0.11667589", "0", "3"], ["88539.8", "0", "0", "0"], ["88540.7", "0.08795223", "0", "1"], ["88541.4", "0", "0", "0"], ["88541.5", "0.00001152", "0", "1"], ["88543.2", "0", "0", "0"], ["88545.1", "0.00001083", "0", "1"], ["88546.6", "0.02260556", "0", "2"], ["88547.1", "0.0186343", "0", "1"], ["88547.7", "0.01948235", "0", "2"], ["88548.5", "0.01888533", "0", "1"], ["88548.7", "0.0112935", "0", "1"], ["88550.6", "0.00225374", "0", "1"], ["88552.5", "0.048", "0", "1"], ["88554.6", "0.00199223", "0", "5"], ["88554.8", "0.015", "0", "1"], ["88556", "0.00001349", "0", "1"], ["88556.3", "0", "0", "0"], ["88557.2", "0.04", "0", "1"], ["88558.8", "0.00001001", "0", "1"], ["88559.4", "0.00032673", "0", "1"], ["88565.1", "0.04", "0", "1"], ["88567", "0", "0", "0"], ["88567.6", "0", "0", "0"], ["88567.7", "0", "0", "0"], ["88567.9", "0.22590351", "0", "2"], ["88568", "0.06", "0", "2"], ["88569", "0.0900615", "0", "4"], ["88570.8", "1.68866656", "0", "1"], ["88572.8", "0", "0", "0"], ["88573.6", "0.0006", "0", "2"], ["88573.7", "0", "0", "0"], ["88574.4", "0.00045275", "0", "5"], ["88577.2", "0", "0", "0"], ["88586", "0", "0", "0"], ["88588.8", "0.00011082", "0", "1"], ["88590.1", "0.01739511", "0", "1"], ["88591", "0", "0", "0"], ["88593.1", "0", "0", "0"], ["88595.4", "0.00007", "0", "1"], ["88603.9", "0.01128619", "0", "1"], ["88604.8", "3.03951905", "0", "1"], ["88608.2", "0", "0", "0"], ["88612.7", "0", "0", "0"], ["88615.1", "0.00167646", "0", "1"], ["88616.2", "0.00570112", "0", "1"], ["88616.6", "0.000657", "0", "2"], ["88616.7", "0.00006147", "0", "2"], ["88616.8", "0.00570108", "0", "1"], ["88617.6", "0.00002674", "0", "2"], ["88617.9", "0.0009692", "0", "1"], ["88618.2", "0.0000551", "0", "1"], ["88618.5", "0.00002031", "0", "2"], ["88618.7", "0.00165291", "0", "3"], ["88618.8", "0.24276", "0", "1"], ["88618.9", "0.00003018", "0", "2"]], "bids": [["88527.9", "0.32669446", "0", "9"], ["88527.8", "0.0001", "0", "1"], ["88526.7", "0.06728696", "0", "1"], ["88526.6", "0.03722555", "0", "2"], ["88526.5", "0.04", "0", "1"], ["88526", "0.0163", "0", "1"], ["88525.7", "0.03575371", "0", "2"], ["88525.6", "0.033887", "0", "1"], ["88525.4", "0.0001", "0", "1"], ["88524", "0.01775491", "0", "2"], ["88523.6", "0.08078746", "0", "1"], ["88523.5", "0.13594673", "0", "2"], ["88522", "0.0163", "0", "1"], ["88521.9", "0.0194028", "0", "1"], ["88521.8", "0", "0", "0"], ["88520.6", "0", "0", "0"], ["88520.3", "0.01129711", "0", "1"], ["88520.2", "0", "0", "0"], ["88520.1", "0", "0", "0"], ["88520", "0.0163", "0", "1"], ["88519.8", "0", "0", "0"], ["88519.7", "0.04", "0", "1"], ["88519.4", "0", "0", "0"], ["88519.1", "0", "0", "0"], ["88519", "0.12143004", "0", "1"], ["88515.5", "0", "0", "0"], ["88515.4", "0", "0", "0"], ["88514.8", "0.22589346", "0", "1"], ["88514.7", "0.61508344", "0", "2"], ["88513.7", "0.90244663", "0", "1"], ["88513.6", "0.00942", "0", "1"], ["88512.4", "0.00222", "0", "1"], ["88512.1", "0", "0", "0"], ["88511.9", "0", "0", "0"], ["88511.3", "0.13150376", "0", "4"], ["88510.7", "0", "0", "0"], ["88510.5", "0.1", "0", "1"], ["88510.4", "0.09229825", "0", "1"], ["88509.8", "0", "0", "0"], ["88509.6", "0.02698183", "0", "1"], ["88509.5", "0.13282104", "0", "1"], ["88507.8", "0.03", "0", "1"], ["88506.4", "0.01650401", "0", "1"], ["88505.6", "0", "0", "0"], ["88505.4", "0", "0", "0"], ["88504.4", "0.02671259", "0", "1"], ["88504.2", "0", "0", "0"], ["88503.6", "0", "0", "0"], ["88501.7", "0", "0", "0"], ["88501.6", "0.09868549", "0", "2"], ["88500.9", "0.00001299", "0", "1"], ["88498.4", "0.00059913", "0", "2"], ["88497.9", "0.00343", "0", "1"], ["88497.6", "0.00029914", "0", "1"], ["88496.8", "0", "0", "0"], ["88495.5", "0.1", "0", "1"], ["88494.6", "0", "0", "0"], ["88493", "1.88466991", "0", "2"], ["88486", "0.12", "0", "4"], ["88485.2", "0", "0", "0"], ["88485", "0.03", "0", "1"], ["88484", "0", "0", "0"], ["88483.3", "0.00057148", "0", "1"], ["88483", "0", "0", "0"], ["88475.1", "0.64644062", "0", "1"], ["88471.8", "0", "0", "0"], ["88471.1", "0.21828909", "0", "2"], ["88469.8", "0", "0", "0"], ["88469.7", "0", "0", "0"], ["88467", "0.01739511", "0", "1"], ["88466.9", "0", "0", "0"], ["88466.1", "0.39951597", "0", "1"], ["88459.3", "0", "0", "0"], ["88459", "3.04608055", "0", "1"], ["88447.2", "0.02259223", "0", "1"], ["88446.7", "0.00019397", "0", "1"], ["88444", "0", "0", "0"], ["88432.7", "0", "0", "0"], ["88393.5", "0", "0", "0"], ["88391.3", "0.17395116", "0", "1"], ["88298.9", "0", "0", "0"]], "ts": "1741338236205", "checksum": 2129188116, "seqId": 48070584613, "prevSeqId": 48070583808}]}
{"arg": {"channel": "books", "instId": "BTC-USDT"}, "action": "update", "data": [{"asks": [["88528", "0.29197778", "0", "13"], ["88528.9", "0.00122783", "0", "2"], ["88529.5", "0.0001", "0", "1"], ["88530.7", "0.0000195", "0", "1"], ["88530.9", "0", "0", "0"], ["88531.5", "0", "0", "0"], ["88533.2", "0.0404158", "0", "2"], ["88535.6", "0.02722469", "0", "1"], ["88535.7", "0.02826255", "0", "2"], ["88535.9", "0.02584255", "0", "2"], ["88536.2", "0.0291657", "0", "1"], ["88536.6", "0", "0", "0"], ["88536.9", "0.0000465", "0", "1"], ["88537.5", "0.06066274", "0", "4"], ["88538", "0.11721795", "0", "2"], ["88538.1", "0.06071752", "0", "5"], ["88539.3", "0.0871882", "0", "1"], ["88539.6", "0.01384761", "0", "3"], ["88539.7", "0", "0", "0"], ["88539.9", "0.1710616", "0", "3"], ["88540.4", "0.08791358", "0", "1"], ["88540.7", "0", "0", "0"], ["88542.8", "0.12407931", "0", "1"], ["88542.9", "0.1321024", "0", "1"], ["88543.4", "0.1462244", "0", "3"], ["88544.9", "0.13120915", "0", "1"], ["88545.8", "0.258141", "0", "1"], ["88545.9", "0.00007302", "0", "1"], ["88546.1", "0.14035847", "0", "1"], ["88547.7", "0.00738035", "0", "1"], ["88548.9", "0.38429724", "0", "2"], ["88550.5", "0.012102", "0", "1"], ["88552.3", "0.05998904", "0", "2"], ["88552.5", "0.087", "0", "2"], ["88566.7", "0.22589784", "0", "1"], ["88567.9", "0.00001005", "0", "1"], ["88569.8", "0.25236536", "0", "2"], ["88570", "0", "0", "0"], ["88570.8", "0", "0", "0"], ["88590.1", "0", "0", "0"], ["88591.9", "0.01739223", "0", "1"], ["88602.1", "0.0113232", "0", "4"], ["88603.9", "0", "0", "0"], ["88604.8", "0", "0", "0"], ["88606.6", "0.0340734", "0", "1"], ["88615.1", "0", "0", "0"], ["88617.9", "0", "0", "0"], ["88618.2", "0", "0", "0"], ["88618.5", "0", "0", "0"], ["88618.7", "0", "0", "0"], ["88618.8", "0", "0", "0"], ["88618.9", "0", "0", "0"]], "bids": [["88527.9", "0.29553611", "0", "10"], ["88527.8", "0", "0", "0"], ["88526.7", "0.03665743", "0", "3"], ["88526.6", "0", "0", "0"], ["88525.7", "0.01357284", "0", "1"], ["88525.4", "0", "0", "0"], ["88525.2", "0.02698183", "0", "1"], ["88524", "0.01631", "0", "2"], ["88523.7", "0.00145491", "0", "1"], ["88523.6", "0.05584193", "0", "1"], ["88523.5", "0.1", "0", "1"], ["88519", "0.04237111", "0", "2"], ["88518.5", "0", "0", "0"], ["88518.3", "0.05448189", "0", "2"], ["88518.1", "0.0000405", "0", "1"], ["88517.9", "0.02717572", "0", "1"], ["88517.8", "0.02945784", "0", "1"], ["88514.8", "0", "0", "0"], ["88514.5", "0.08200337", "0", "1"], ["88514.3", "0.07631745", "0", "1"], ["88513.7", "1.0705448", "0", "3"], ["88512.4", "0", "0", "0"], ["88511.4", "0.03", "0", "1"], ["88511.3", "0.25707523", "0", "5"], ["88510.6", "0.22589964", "0", "1"], ["88510.4", "0.28653555", "0", "3"], ["88509.6", "0", "0", "0"], ["88509.5", "0", "0", "0"], ["88509.2", "0.13891233", "0", "1"], ["88507.9", "0.01650401", "0", "1"], ["88507.8", "0.06", "0", "2"], ["88507.6", "0.13422337", "0", "1"], ["88506.4", "0", "0", "0"], ["88503.4", "0.03", "0", "1"], ["88487", "0.53921", "0", "3"], ["88486", "0.06", "0", "2"], ["88481.8", "0.03729085", "0", "1"], ["88479.4", "0.03321773", "0", "1"], ["88478", "0.01128642", "0", "1"], ["88476.7", "0.1", "0", "1"], ["88474", "0", "0", "0"], ["88468", "0.01740223", "0", "2"], ["88467", "0", "0", "0"], ["88464", "0.00102639", "0", "1"], ["88458.8", "0", "0", "0"], ["88456.5", "0.00099776", "0", "2"], ["88451.9", "0", "0", "0"], ["88402.9", "0.00211957", "0", "1"], ["88397.8", "0", "0", "0"], ["88393.3", "0.17392237", "0", "1"], ["88391.3", "0", "0", "0"], ["88389.5", "0.13737132", "0", "2"], ["88382.8", "0", "0", "0"], ["88283", "0", "0", "0"], ["88281.2", "0", "0", "0"], ["88281.1", "0", "0", "0"], ["88280.5", "0", "0", "0"]], "ts": "1741338236305", "checksum": 1813076666, "seqId": 48070585004, "prevSeqId": 48070584613}]}
{"arg": {"channel": "books", "instId": "BTC-USDT"}, "action": "update", "data": [{"asks": [["88528", "0.01169787", "0", "5"], ["88528.9", "0.00112783", "0", "1"], ["88529.5", "0", "0", "0"], ["88530.7", "0", "0", "0"], ["88531.4", "0.0001", "0", "1"], ["88531.8", "0.0001", "0", "1"], ["88533.2", "0", "0", "0"], ["88535.6", "0", "0", "0"], ["88535.7", "0.0000114", "0", "1"], ["88535.9", "0.00025932", "0", "1"], ["88536.2", "0", "0", "0"], ["88536.9", "0", "0", "0"], ["88537.4", "0.03134879", "0", "1"], ["88538", "0", "0", "0"], ["88538.1", "0.00007794", "0", "3"], ["88538.5", "0.02926588", "0", "1"], ["88539.3", "0", "0", "0"], ["88539.9", "0.00003598", "0", "1"], ["88540.4", "0", "0", "0"], ["88540.8", "0", "0", "0"], ["88542", "0.02601164", "0", "1"], ["88542.7", "0.08111211", "0", "1"], ["88542.8", "0", "0", "0"], ["88542.9", "0", "0", "0"], ["88543.4", "0.00111045", "0", "2"], ["88543.5", "0.00013124", "0", "2"], ["88544.9", "0", "0", "0"], ["88545.7", "0.06063958", "0", "2"], ["88545.8", "0.298731", "0", "2"], ["88546.1", "0", "0", "0"], ["88548.9", "0.53338959", "0", "3"], ["88550.5", "0", "0", "0"], ["88550.7", "0.04503658", "0", "2"], ["88552.3", "0.0834317", "0", "1"], ["88553.8", "0.012102", "0", "1"], ["88554.2", "0.08770666", "0", "4"], ["88566.7", "0", "0", "0"], ["88568", "0", "0", "0"], ["88568.9", "0.22594283", "0", "3"], ["88569", "0.0000615", "0", "1"], ["88570", "0.06", "0", "2"], ["88571", "0.09", "0", "3"], ["88573.6", "0", "0", "0"], ["88574.4", "0.00015275", "0", "4"], ["88576", "0.0138977", "0", "5"], ["88576.8", "0.339412", "0", "3"], ["88582", "0.93026624", "0", "2"], ["88591.9", "0", "0", "0"], ["88592", "0.10018194", "0", "2"], ["88593.1", "0.01739395", "0", "1"], ["88617.9", "0.0009692", "0", "1"], ["88618.2", "0.0000551", "0", "1"], ["88618.5", "0.00002031", "0", "2"], ["88618.7", "0.00165291", "0", "3"], ["88618.8", "0.24276", "0", "1"], ["88618.9", "0.00003018", "0", "2"], ["88619.2", "0.00002036", "0", "2"], ["88619.4", "0.05335289", "0", "1"]], "bids": [["88527.9", "0.30182611", "0", "11"], ["88526.8", "0.0002", "0", "2"], ["88526.7", "0.06581779", "0", "2"], ["88526.3", "0.11295849", "0", "1"], ["88525.2", "0", "0", "0"], ["88520.7", "0.02909239", "0", "1"], ["88519.9", "0.03052267", "0", "2"], ["88519", "0.09826888", "0", "1"], ["88518.3", "0", "0", "0"], ["88517.9", "0", "0", "0"], ["88517.8", "0", "0", "0"], ["88517.3", "0.22588916", "0", "1"], ["88516.5", "0.08722006", "0", "1"], ["88514.5", "0", "0", "0"], ["88514.3", "0", "0", "0"], ["88514", "0.0155", "0", "1"], ["88513.7", "0.90244663", "0", "1"], ["88511.3", "0.13150376", "0", "4"], ["88510.7", "0.0042345", "0", "1"], ["88510.6", "0", "0", "0"], ["88510.4", "0.28202752", "0", "3"], ["88509.2", "0", "0", "0"], ["88507.6", "0", "0", "0"], ["88506.8", "0.02698183", "0", "1"], ["88506.7", "0", "0", "0"], ["88504.4", "0", "0", "0"], ["88500.9", "0", "0", "0"], ["88494.1", "0.02671259", "0", "1"], ["88486", "0", "0", "0"], ["88485", "0.06", "0", "2"], ["88484", "0.03", "0", "1"], ["88481.1", "0.1", "0", "1"], ["88476.7", "0", "0", "0"], ["88468", "0.01740395", "0", "2"], ["88450.2", "0.00019396", "0", "1"], ["88446.7", "0", "0", "0"], ["88393.3", "0.17393955", "0", "1"], ["88283", "0.00001722", "0", "1"], ["88281.2", "0.00006263", "0", "1"], ["88281.1", "0.34078752", "0", "2"], ["88280.5", "0.00002567", "0", "1"]], "ts": "1741338236405", "checksum": -772814297, "seqId": 48070585280, "prevSeqId": 48070585004}]}
{"arg": {"channel": "books", "instId": "BTC-USDT"}, "action": "update", "data": [{"asks": [["88530", "0.00009419", "0", "2"], ["88530.6", "0.00003321", "0", "2"], ["88531.4", "0", "0", "0"], ["88531.8", "0", "0", "0"], ["88532.3", "0.00021329", "0", "2"], ["88532.4", "0.00047328", "0", "2"], ["88536.8", "0.0000465", "0", "1"], ["88539.6", "0.00031761", "0", "2"], ["88540.1", "0.02608645", "0", "2"], ["88541.9", "0.06063958", "0", "2"], ["88542", "0.07737181", "0", "2"], ["88542.6", "0.06063958", "0", "2"], ["88543.5", "0.00001124", "0", "1"], ["88543.6", "0.01353", "0", "1"], ["88544.2", "0.08176347", "0", "1"], ["88544.5", "0.06175536", "0", "3"], ["88548.8", "0.13704741", "0", "2"], ["88553.8", "0", "0", "0"], ["88557.2", "0.052102", "0", "2"], ["88570.8", "1.63229578", "0", "1"], ["88584.9", "0.49806001", "0", "2"], ["88588.4", "0.49806718", "0", "2"], ["88593.1", "0", "0", "0"], ["88595.9", "0.01739296", "0", "1"], ["88602.1", "0.00003678", "0", "3"], ["88604.8", "3.0164221", "0", "1"], ["88605.7", "0.01128596", "0", "1"], ["88618.7", "0", "0", "0"], ["88618.8", "0", "0", "0"], ["88618.9", "0", "0", "0"], ["88619.2", "0", "0", "0"], ["88619.4", "0", "0", "0"]], "bids": [["88527.9", "0.28826382", "0", "13"], ["88526.8", "0", "0", "0"], ["88526.6", "0.00942", "0", "1"], ["88526.3", "0.11315849", "0", "3"], ["88525.7", "0", "0", "0"], ["88525.6", "0", "0", "0"], ["88524.1", "0.00145491", "0", "1"], ["88524", "0.0163", "0", "1"], ["88523.7", "0", "0", "0"], ["88521.9", "0", "0", "0"], ["88521.7", "0.027982", "0", "1"], ["88518.9", "0.08542891", "0", "1"], ["88517.6", "0.0805971", "0", "1"], ["88513", "0.1410417", "0", "1"], ["88503.4", "0", "0", "0"], ["88500", "0.0006", "0", "2"], ["88499.9", "0.00058633", "0", "2"], ["88499.2", "0.00029913", "0", "1"], ["88498.4", "0", "0", "0"], ["88497.6", "0", "0", "0"], ["88495.8", "0.498329", "0", "1"], ["88482.2", "0.498405", "0", "1"], ["88478", "0", "0", "0"], ["88474.4", "0.01128596", "0", "1"], ["88472.7", "0.01739296", "0", "1"], ["88468", "0.00001", "0", "1"], ["88444.5", "0.3392", "0", "1"], ["88397.8", "0.17392962", "0", "1"], ["88393.3", "0", "0", "0"], ["88389.5", "0.1260849", "0", "1"], ["88373.5", "0.01128438", "0", "1"], ["88283.3", "0", "0", "0"], ["88283", "0", "0", "0"], ["88281.2", "0", "0", "0"], ["88281.1", "0", "0", "0"], ["88280.5", "0", "0", "0"]], "ts": "1741338236505", "checksum": 2055689364, "seqId": 48070585414, "prevSeqId": 48070585280}]}
{"arg": {"channel": "books", "instId": "BTC-USDT"}, "action": "update", "data": [{"asks": [["88530", "0.01639419", "0", "3"], ["88530.6", "0.00001446", "0", "1"], ["88531.2", "0.0001", "0", "1"], ["88531.4", "0.0001", "0", "1"], ["88532.3", "0.00011329", "0", "1"], ["88532.4", "0.00037328", "0", "1"], ["88533.3", "0.1307887", "0", "19"], ["88536.8", "0", "0", "0"], ["88537.4", "0.04386926", "0", "2"], ["88538.4", "0.03291817", "0", "6"], ["88538.7", "0.02716285", "0", "1"], ["88540.1", "0.00003293", "0", "1"], ["88542", "0.10675678", "0", "1"], ["88542.1", "0.08659502", "0", "2"], ["88542.7", "0.24883568", "0", "3"], ["88544.2", "0", "0", "0"], ["88545.7", "0.19080263", "0", "3"], ["88545.8", "0.40743332", "0", "3"], ["88546.2", "0.14610478", "0", "1"], ["88547.2", "0.12970266", "0", "1"], ["88548.8", "0.00001", "0", "1"], ["88568.9", "0.00005367", "0", "2"], ["88570", "0", "0", "0"], ["88571", "0.12", "0", "4"], ["88572", "0.03", "0", "1"], ["88576.3", "0.22588389", "0", "1"], ["88617.6", "0", "0", "0"], ["88617.9", "0", "0", "0"], ["88618.2", "0", "0", "0"], ["88618.5", "0", "0", "0"]], "bids": [["88526.3", "0.11295849", "0", "1"], ["88525.8", "0.0002", "0", "2"], ["88523.6", "0.15477286", "0", "1"], ["88521.7", "0", "0", "0"], ["88521.2", "0.22588389", "0", "1"], ["88521.1", "0.02613432", "0", "1"], ["88521", "0.02838324", "0", "1"], ["88520.1", "0.02633777", "0", "1"], ["88519", "0.14297541", "0", "2"], ["88517.6", "0", "0", "0"], ["88517.3", "0.08347053", "0", "1"], ["88517.1", "0.07538765", "0", "1"], ["88516", "0.1043251", "0", "2"], ["88514.1", "0.13117912", "0", "1"], ["88513.2", "0.13832926", "0", "1"], ["88513", "0", "0", "0"], ["88511.5", "0.46937388", "0", "2"], ["88510.5", "0.12671259", "0", "2"], ["88494.1", "0", "0", "0"], ["88287", "0", "0", "0"], ["88286.3", "0", "0", "0"], ["88284.9", "0", "0", "0"], ["88283.5", "0", "0", "0"]], "ts": "1741338236605", "checksum": -1984287174, "seqId": 48070585535, "prevSeqId": 48070585414}]}
{"arg": {"channel": "books", "instId": "BTC-USDT"}, "action": "update", "data": [{"asks": [["88528", "0.09139787", "0", "9"], ["88530.4", "0.00025135", "0", "8"], ["88530.6", "0.00011446", "0", "2"], ["88530.9", "0.11295275", "0", "1"], ["88531.2", "0", "0", "0"], ["88531.4", "0", "0", "0"], ["88533.2", "0.01763997", "0", "1"], ["88533.3", "0.01783903", "0", "18"], ["88536.5", "0.02700885", "0", "1"], ["88536.8", "0.00004575", "0", "1"], ["88536.9", "0.02842768", "0", "1"], ["88537.4", "0.09976758", "0", "1"], ["88538.4", "0.00528414", "0", "5"], ["88538.7", "0", "0", "0"], ["88540.2", "0.08808638", "0", "2"], ["88540.8", "0.07303034", "0", "1"], ["88541.1", "0.08815099", "0", "1"], ["88541.3", "0.01353", "0", "1"], ["88541.4", "0.19254739", "0", "2"], ["88542", "0", "0", "0"], ["88542.1", "0.00010289", "0", "1"], ["88542.7", "0.08111211", "0", "1"], ["88543.5", "0.00013124", "0", "2"], ["88543.6", "0", "0", "0"], ["88544.3", "0.14044466", "0", "3"], ["88544.5", "0.00111578", "0", "1"], ["88545.6", "0.14238571", "0", "1"], ["88545.7", "0", "0", "0"], ["88546.2", "0", "0", "0"], ["88547.2", "0", "0", "0"], ["88547.4", "0.00225374", "0", "1"], ["88553.8", "0.012102", "0", "1"], ["88557.2", "0.04", "0", "1"], ["88568", "0.22589307", "0", "1"], ["88576.3", "0", "0", "0"], ["88605.7", "0", "0", "0"], ["88608.3", "0.01128563", "0", "1"], ["88616.2", "0", "0", "0"], ["88616.6", "0", "0", "0"], ["88616.7", "0", "0", "0"], ["88616.8", "0", "0", "0"]], "bids": [["88527.9", "0.28198382", "0", "13"], ["88526.7", "0.09639584", "0", "1"], ["88526.3", "0.13967108", "0", "2"], ["88525.8", "0", "0", "0"], ["88524.1", "0", "0", "0"], ["88523.7", "0.00145491", "0", "1"], ["88523.6", "0.28169819", "0", "2"], ["88522.6", "0.3389", "0", "1"], ["88521.2", "0", "0", "0"], ["88521.1", "0", "0", "0"], ["88521", "0", "0", "0"], ["88520.1", "0", "0", "0"], ["88519.2", "0.33475561", "0", "3"], ["88519.1", "0.33891", "0", "1"], ["88519", "0", "0", "0"], ["88518.9", "0", "0", "0"], ["88518.5", "0.02781503", "0", "1"], ["88517.3", "0", "0", "0"], ["88517.1", "0", "0", "0"], ["88516", "0.0155", "0", "1"], ["88515.6", "0.22589307", "0", "1"], ["88515.4", "0.079048", "0", "1"], ["88515.2", "0.07510772", "0", "1"], ["88514.4", "0.08834604", "0", "1"], ["88514.1", "0", "0", "0"], ["88513.2", "0", "0", "0"], ["88512.6", "0.0001", "0", "1"], ["88512.5", "0.0001", "0", "1"], ["88512.2", "0.12713366", "0", "1"], ["88511.5", "0.33929724", "0", "1"], ["88511.3", "0.26939116", "0", "5"], ["88510.5", "0.1", "0", "1"], ["88510.4", "0.27724575", "0", "3"], ["88509.9", "0.14386365", "0", "1"], ["88506.8", "0", "0", "0"], ["88499.9", "0.00057148", "0", "1"], ["88486", "0.06", "0", "2"], ["88485", "0.03", "0", "1"], ["88484", "0", "0", "0"], ["88474.4", "0", "0", "0"], ["88471.8", "0.01128563", "0", "1"], ["88444.5", "0", "0", "0"], ["88287", "0.03", "0", "1"]], "ts": "1741338236705", "checksum": 363312308, "seqId": 48070585730, "prevSeqId": 48070585535}]}
{"arg": {"channel": "books", "instId": "BTC-USDT"}, "action": "update", "data": [{"asks": [["88528", "0.21882403", "0", "12"], ["88528.5", "0.11295584", "0", "1"], ["88528.8", "0.0051", "0", "2"], ["88529", "0.00011678", "0", "2"], ["88530.4", "0.00015135", "0", "7"], ["88530.6", "0.00001446", "0", "1"], ["88530.7", "0.0000195", "0", "1"], ["88530.9", "0", "0", "0"], ["88533.2", "0.03174282", "0", "2"], ["88535.6", "0.02864853", "0", "1"], ["88535.7", "0.02664862", "0", "2"], ["88535.9", "0.0272075", "0", "2"], ["88536.2", "0.02598241", "0", "1"], ["88536.5", "0", "0", "0"], ["88536.8", "0", "0", "0"], ["88536.9", "0", "0", "0"], ["88537.3", "0.09820831", "0", "3"], ["88537.4", "0", "0", "0"], ["88538.5", "0", "0", "0"], ["88539.3", "0.08493126", "0", "1"], ["88539.9", "0.15353009", "0", "3"], ["88540.2", "0.00007853", "0", "1"], ["88540.4", "0.08323247", "0", "1"], ["88540.8", "0.000015", "0", "1"], ["88541.1", "0", "0", "0"], ["88541.4", "0.14007993", "0", "2"], ["88542.6", "0", "0", "0"], ["88542.7", "0", "0", "0"], ["88542.9", "0.13644975", "0", "1"], ["88543.4", "0.14788929", "0", "3"], ["88544.3", "0.00012172", "0", "2"], ["88544.9", "0.13275092", "0", "1"], ["88545.6", "0", "0", "0"], ["88545.9", "0.01217502", "0", "2"], ["88546.1", "0.13172337", "0", "1"], ["88548.9", "0.38429724", "0", "2"], ["88553.8", "0", "0", "0"], ["88566.7", "0.22589938", "0", "1"], ["88568", "0", "0", "0"], ["88580", "0.2", "0", "1"], ["88616.2", "0.00570112", "0", "1"]], "bids": [["88527.9", "0.2588603", "0", "13"], ["88526.6", "0", "0", "0"], ["88525.8", "0.0001", "0", "1"], ["88520.8", "0.3389", "0", "1"], ["88520.7", "0", "0", "0"], ["88519.9", "0.00224267", "0", "1"], ["88519.2", "0.13935747", "0", "1"], ["88518.5", "0", "0", "0"], ["88518.3", "0.05262433", "0", "2"], ["88517.9", "0.02960721", "0", "1"], ["88517.8", "0.02590894", "0", "1"], ["88516.5", "0", "0", "0"], ["88516.3", "0.0001", "0", "1"], ["88515.6", "0", "0", "0"], ["88515.4", "0", "0", "0"], ["88515.2", "0", "0", "0"], ["88514.7", "0.64336344", "0", "3"], ["88514.5", "0.08182242", "0", "1"], ["88514.4", "0", "0", "0"], ["88514.3", "0.08034465", "0", "1"], ["88513.7", "1.07464811", "0", "3"], ["88512.6", "0", "0", "0"], ["88512.5", "0", "0", "0"], ["88512.2", "0", "0", "0"], ["88511.3", "0.25736052", "0", "5"], ["88510.7", "0", "0", "0"], ["88510.4", "0.34099842", "0", "2"], ["88509.9", "0", "0", "0"], ["88509.3", "0.22589938", "0", "1"], ["88509.2", "0.14085917", "0", "1"], ["88507.9", "0", "0", "0"], ["88507.6", "0.14888833", "0", "1"], ["88507.5", "0.01650401", "0", "1"], ["88500", "0.00061485", "0", "3"], ["88286.3", "0.03", "0", "1"], ["88284.9", "0.08542891", "0", "1"]], "ts": "1741338236805", "checksum": 1096330587, "seqId": 48070585896, "prevSeqId": 48070585730}]}
{"arg": {"channel": "books", "instId": "BTC-USDT"}, "action": "update", "data": [{"asks": [["88528", "0", "0", "0"], ["88528.1", "0", "0", "0"], ["88528.4", "0", "0", "0"], ["88528.5", "0", "0", "0"], ["88528.6", "0", "0", "0"], ["88528.8", "0", "0", "0"], ["88528.9", "0", "0", "0"], ["88529", "0", "0", "0"], ["88529.6", "0", "0", "0"], ["88529.8", "0", "0", "0"], ["88529.9", "0", "0", "0"], ["88530", "0", "0", "0"], ["88530.1", "0", "0", "0"], ["88530.4", "0", "0", "0"], ["88530.6", "0", "0", "0"], ["88530.7", "0", "0", "0"], ["88530.8", "0", "0", "0"], ["88533.1", "0.06063958", "0", "2"], ["88533.2", "0", "0", "0"], ["88534.4", "0.06065052", "0", "3"], ["88535.5", "0.06101152", "0", "12"], ["88535.6", "0", "0", "0"], ["88535.7", "0.06065098", "0", "3"], ["88535.9", "0.00025932", "0", "1"], ["88536", "0.02482488", "0", "2"], ["88536.2", "0", "0", "0"], ["88537.3", "0.00002092", "0", "1"], ["88539.1", "0.04059", "0", "1"], ["88539.3", "0", "0", "0"], ["88539.9", "0.00003598", "0", "1"], ["88540.4", "0", "0", "0"], ["88540.8", "0", "0", "0"], ["88541.3", "0", "0", "0"], ["88541.4", "0", "0", "0"], ["88542.9", "0", "0", "0"], ["88543.4", "0.00111045", "0", "2"], ["88544.9", "0", "0", "0"], ["88545.7", "0.90244663", "0", "1"], ["88545.8", "0", "0", "0"], ["88545.9", "0.00007302", "0", "1"], ["88546.1", "0", "0", "0"], ["88552.3", "0", "0", "0"], ["88552.4", "0", "0", "0"], ["88557.1", "0.22591625", "0", "1"], ["88557.2", "0", "0", "0"], ["88558.7", "0.04", "0", "1"], ["88565.1", "0", "0", "0"], ["88566.7", "0", "0", "0"], ["88570.8", "0", "0", "0"], ["88604.8", "0", "0", "0"], ["88616.6", "0.000657", "0", "2"], ["88616.7", "0.00006147", "0", "2"], ["88616.8", "0.00570108", "0", "1"], ["88617.6", "0.00002674", "0", "2"], ["88617.9", "0.0009692", "0", "1"], ["88618.2", "0.0000551", "0", "1"], ["88618.5", "0.00002031", "0", "2"], ["88618.7", "0.00165291", "0", "3"], ["88618.8", "0.24276", "0", "1"], ["88618.9", "0.00003018", "0", "2"], ["88619.2", "0.00002036", "0", "2"], ["88619.4", "0.05335289", "0", "1"], ["88619.6", "0.00570112", "0", "1"], ["88619.8", "0.00020826", "0", "1"], ["88619.9", "0.00001", "0", "1"], ["88620", "0.00003647", "0", "2"], ["88620.2", "0.00002207", "0", "1"], ["88620.6", "0.00002265", "0", "1"], ["88620.7", "0.00001139", "0", "1"], ["88620.8", "0.00011317", "0", "1"], ["88621", "0.00027554", "0", "1"], ["88621.1", "0.00002626", "0", "1"], ["88621.6", "0.00015113", "0", "1"], ["88621.8", "0.746431", "0", "1"], ["88621.9", "0.00572321", "0", "2"], ["88622", "0.00001139", "0", "1"], ["88622.2", "0.00011317", "0", "1"], ["88622.3", "0.000119", "0", "4"], ["88622.5", "0.00007987", "0", "3"], ["88622.6", "0.04242624", "0", "5"], ["88622.7", "0.00009738", "0", "1"]], "bids": [["88531.2", "0.01161897", "0", "1"], ["88527.9", "0.17242724", "0", "16"], ["88526.7", "0", "0", "0"], ["88526.5", "0", "0", "0"], ["88526.3", "0.11295849", "0", "1"], ["88525.8", "0.0002", "0", "2"], ["88523.6", "0.10964918", "0", "1"], ["88523.5", "0", "0", "0"], ["88522.6", "0", "0", "0"], ["88521.8", "0.04", "0", "1"], ["88520.8", "0", "0", "0"], ["88519.2", "0.04419084", "0", "1"], ["88519.1", "0", "0", "0"], ["88518.3", "0", "0", "0"], ["88517.9", "0", "0", "0"], ["88517.8", "0", "0", "0"], ["88517.7", "0.01357284", "0", "1"], ["88517.5", "0.0194028", "0", "1"], ["88516.3", "0", "0", "0"], ["88514.5", "0", "0", "0"], ["88514.3", "0", "0", "0"], ["88513.7", "0.90244663", "0", "1"], ["88511.3", "0.01853488", "0", "1"], ["88510.7", "0.00006", "0", "1"], ["88510.5", "0", "0", "0"], ["88510.4", "0.19471081", "0", "1"], ["88510.3", "0", "0", "0"], ["88509.3", "0", "0", "0"], ["88509.2", "0", "0", "0"], ["88507.8", "0.06451938", "0", "3"], ["88507.7", "0.01650401", "0", "1"], ["88507.6", "0", "0", "0"], ["88507.5", "0", "0", "0"], ["88506", "0.47980543", "0", "2"], ["88505.9", "0", "0", "0"], ["88498.2", "0.22591625", "0", "1"], ["88495.5", "0", "0", "0"], ["88485.7", "0.01258144", "0", "2"], ["88484.4", "0.02671259", "0", "1"], ["88299.4", "0.033886", "0", "1"], ["88283.5", "0.11343045", "0", "1"], ["88283.3", "0.00416498", "0", "2"], ["88283", "0.00001722", "0", "1"], ["88281.2", "0.00006263", "0", "1"], ["88281.1", "0.34078752", "0", "2"], ["88280.5", "0.00002567", "0", "1"], ["88279.9", "0.00001655", "0", "1"], ["88276.1", "0.00007", "0", "1"], ["88275.5", "0.00001139", "0", "1"], ["88275", "0.00009665", "0", "2"], ["88274.6", "0.00001339", "0", "1"]], "ts": "1741338236905", "checksum": 736970962, "seqId": 48070586216, "prevSeqId": 48070585896}]}
{"arg": {"channel": "books", "instId": "BTC-USDT"}, "action": "update", "data": [{"asks": [["88531.3", "0", "0", "0"], ["88531.7", "0", "0", "0"], ["88531.9", "0", "0", "0"], ["88532", "0", "0", "0"], ["88532.3", "0", "0", "0"], ["88532.4", "0", "0", "0"], ["88532.9", "0", "0", "0"], ["88533.1", "0", "0", "0"], ["88533.3", "0.01789801", "0", "19"], ["88534", "0.01711007", "0", "2"], ["88534.4", "0.00001094", "0", "1"], ["88535.5", "0.00037194", "0", "10"], ["88535.7", "0", "0", "0"], ["88536", "0.0163", "0", "1"], ["88536.1", "0.000021", "0", "1"], ["88537.5", "0.00002316", "0", "2"], ["88537.9", "0.00112767", "0", "1"], ["88538", "0.0163", "0", "1"], ["88538.3", "0.00134659", "0", "10"], ["88538.5", "0.0001", "0", "1"], ["88539.1", "0", "0", "0"], ["88541.7", "0.00002123", "0", "2"], ["88541.9", "0", "0", "0"], ["88542.1", "0.06078883", "0", "4"], ["88543.3", "0.06065099", "0", "3"], ["88543.5", "0.00001124", "0", "1"], ["88544.4", "0.0274301", "0", "1"], ["88544.5", "0.06175672", "0", "3"], ["88544.6", "0.02875161", "0", "3"], ["88544.7", "0.02763253", "0", "1"], ["88544.8", "0.02664099", "0", "2"], ["88545.1", "0.01130454", "0", "2"], ["88545.7", "0", "0", "0"], ["88545.9", "0.06071396", "0", "3"], ["88546.6", "0.00001512", "0", "1"], ["88547", "0.06065233", "0", "3"], ["88547.1", "0", "0", "0"], ["88547.3", "0.01353", "0", "1"], ["88547.4", "0", "0", "0"], ["88547.5", "0", "0", "0"], ["88548.1", "0.14778985", "0", "4"], ["88548.3", "0.00107218", "0", "5"], ["88548.7", "0.07925516", "0", "1"], ["88548.8", "0.07858009", "0", "2"], ["88548.9", "0.08444952", "0", "1"], ["88549.3", "0.06068922", "0", "3"], ["88549.4", "0", "0", "0"], ["88549.7", "0", "0", "0"], ["88550.3", "0.06470222", "0", "1"], ["88550.4", "0.06064094", "0", "2"], ["88550.6", "0", "0", "0"], ["88550.7", "0.00003658", "0", "1"], ["88551.6", "0.06065234", "0", "3"], ["88551.7", "0.06064094", "0", "2"], ["88551.8", "0.13616113", "0", "2"], ["88552.3", "0.14149447", "0", "1"], ["88552.5", "0", "0", "0"], ["88553.4", "0.13741654", "0", "1"], ["88553.8", "0.03032047", "0", "1"], ["88554.2", "0.00070666", "0", "2"], ["88554.9", "0.39264672", "0", "2"], ["88557.1", "0", "0", "0"], ["88558", "0.20704957", "0", "4"], ["88558.3", "0.0450114", "0", "2"], ["88558.4", "0.02260242", "0", "2"], ["88558.6", "0", "0", "0"], ["88558.7", "0", "0", "0"], ["88559.6", "0.91373874", "0", "2"], ["88560.6", "0.073566", "0", "1"], ["88561.8", "0.135", "0", "3"], ["88563.5", "0.04", "0", "1"], ["88565.4", "0.11164002", "0", "1"], ["88565.5", "0.11291975", "0", "2"], ["88566.6", "0.04368388", "0", "10"], ["88566.8", "0.0000907", "0", "1"], ["88568.1", "0.00007008", "0", "2"], ["88569.7", "0.27321997", "0", "1"], ["88569.8", "0.21704", "0", "1"], ["88570.2", "0.012102", "0", "1"], ["88571", "0", "0", "0"], ["88572", "0", "0", "0"], ["88576", "0.0132977", "0", "3"], ["88576.8", "0.339112", "0", "2"], ["88578.1", "0.03617458", "0", "4"], ["88579", "0.12276168", "0", "8"], ["88579.8", "0.22587725", "0", "2"], ["88580", "0.23", "0", "2"], ["88582", "0.39406355", "0", "1"], ["88584", "0.11403045", "0", "3"], ["88584.8", "0.000315", "0", "2"], ["88584.9", "0.00023201", "0", "1"], ["88588.4", "0.00025918", "0", "1"], ["88592", "0.00018194", "0", "1"], ["88595.3", "0.1", "0", "1"], ["88596", "0.00003743", "0", "2"], ["88596.6", "0.0225738", "0", "1"], ["88599.2", "0.00338992", "0", "1"], ["88604.9", "0.073566", "0", "1"], ["88606.6", "0", "0", "0"], ["88608.9", "0.90814775", "0", "2"], ["88613.6", "0.0318903", "0", "1"], ["88620.9", "0.207", "0", "1"], ["88622.6", "0.0022178", "0", "4"], ["88622.9", "0.00012971", "0", "2"], ["88623.3", "0.00057765", "0", "3"]], "bids": [["88533.2", "0.27362075", "0", "8"], ["88532.7", "0.0002", "0", "2"], ["88532.6", "0.16425342", "0", "1"], ["88532.4", "0.00145491", "0", "1"], ["88532.3", "0.02299284", "0", "2"], ["88532.2", "0.04724233", "0", "2"], ["88532", "0.0163", "0", "1"], ["88531.2", "0.05534953", "0", "2"], ["88530", "0.0163", "0", "1"], ["88528.9", "0.00224255", "0", "1"], ["88528.1", "0.04", "0", "1"], ["88528", "0.24113621", "0", "2"], ["88527.9", "0.09929838", "0", "5"], ["88527.3", "0.02828", "0", "1"], ["88527.2", "0.02732977", "0", "1"], ["88527.1", "0.04546057", "0", "2"], ["88526.7", "0.02700288", "0", "1"], ["88526.3", "0.02848517", "0", "1"], ["88525.8", "0", "0", "0"], ["88524.4", "0.00001138", "0", "1"], ["88523.8", "0.22587156", "0", "1"], ["88523.7", "0.33929724", "0", "1"], ["88523.6", "0.0356693", "0", "1"], ["88523.4", "0.09015209", "0", "2"], ["88523.2", "0.07843859", "0", "1"], ["88522.6", "0.08025556", "0", "1"], ["88522.2", "0.08068675", "0", "1"], ["88521.8", "0", "0", "0"], ["88521.6", "0.000015", "0", "1"], ["88521.4", "0.00839429", "0", "1"], ["88520.3", "0", "0", "0"], ["88520.2", "0.12418641", "0", "1"], ["88519.9", "0", "0", "0"], ["88519.8", "0.05647723", "0", "1"], ["88519.7", "0", "0", "0"], ["88519.3", "0.14094569", "0", "1"], ["88519.2", "0.04554351", "0", "1"], ["88518.4", "0.11295865", "0", "3"], ["88518.1", "0.00942", "0", "1"], ["88517.7", "0", "0", "0"], ["88517.6", "0.14245715", "0", "1"], ["88517.5", "0", "0", "0"], ["88517", "0.03", "0", "1"], ["88516.4", "0.1445667", "0", "2"], ["88515.3", "0.0074955", "0", "1"], ["88514.8", "0.01650401", "0", "1"], ["88514.7", "0.51974531", "0", "2"], ["88514.1", "0.00451905", "0", "1"], ["88513.6", "0", "0", "0"], ["88513.5", "0.09", "0", "3"], ["88513.4", "0.207", "0", "1"], ["88511.5", "0.53770345", "0", "3"], ["88511.3", "0", "0", "0"], ["88510.7", "0", "0", "0"], ["88510.4", "0", "0", "0"], ["88510", "0", "0", "0"], ["88509.2", "0.02698183", "0", "1"], ["88508", "0", "0", "0"], ["88507.8", "0.06", "0", "2"], ["88507.7", "0", "0", "0"], ["88506", "0.46430543", "0", "1"], ["88505.4", "0.015", "0", "1"], ["88504.6", "0.02671259", "0", "1"], ["88503.6", "0.15405916", "0", "2"], ["88503.5", "0.03", "0", "1"], ["88500", "0.00061398", "0", "3"], ["88498.2", "0", "0", "0"], ["88495.8", "0", "0", "0"], ["88492.4", "0", "0", "0"], ["88492", "0.0112", "0", "1"], ["88486.4", "0.03226475", "0", "2"], ["88485.7", "0.00138144", "0", "1"], ["88485.3", "0", "0", "0"], ["88484.4", "0.1", "0", "1"], ["88484.3", "0.03562461", "0", "1"], ["88482.2", "0", "0", "0"], ["88481.8", "0", "0", "0"], ["88481.1", "0", "0", "0"], ["88479.4", "0", "0", "0"], ["88461.2", "0.3402835", "0", "2"], ["88456.5", "0.00001138", "0", "1"], ["88450.3", "0.33917", "0", "1"], ["88446.6", "0.02670024", "0", "1"], ["88445.9", "0", "0", "0"], ["88443", "0.01316", "0", "1"], ["88434.3", "0", "0", "0"], ["88433.6", "0.000015", "0", "1"], ["88431.9", "0", "0", "0"], ["88427.4", "0", "0", "0"], ["88420.4", "0.06666822", "0", "1"], ["88420", "0.06804094", "0", "1"], ["88407.8", "0", "0", "0"], ["88405.4", "0.00564766", "0", "1"], ["88394.4", "0.01694297", "0", "3"], ["88391.2", "0", "0", "0"], ["88386.1", "0", "0", "0"], ["88385.2", "0", "0", "0"], ["88378.6", "0", "0", "0"], ["88377.2", "0.0000114", "0", "1"], ["88372.8", "0", "0", "0"], ["88354.8", "0", "0", "0"], ["88345.6", "0", "0", "0"], ["88328", "0.0011044", "0", "1"], ["88313.1", "0.0000168", "0", "1"], ["88305.3", "0", "0", "0"], ["88296.4", "0", "0", "0"], ["88284.9", "0", "0", "0"], ["88283.5", "0", "0", "0"], ["88283.3", "0", "0", "0"], ["88283", "0", "0", "0"], ["88281.2", "0", "0", "0"], ["88281.1", "0", "0", "0"], ["88280.5", "0", "0", "0"], ["88279.9", "0", "0", "0"], ["88276.1", "0", "0", "0"], ["88275.5", "0", "0", "0"], ["88275", "0", "0", "0"], ["88274.6", "0", "0", "0"]], "ts": "1741338237005", "checksum": 160399871, "seqId": 48070587386, "prevSeqId": 48070586216}]}
{"arg": {"channel": "books", "instId": "BTC-USDT"}, "action": "update", "data": [{"asks": [["88533.3", "0.07789801", "0", "21"], ["88537.9", "0.00132767", "0", "3"], ["88538.3", "0.00124659", "0", "9"], ["88538.5", "0", "0", "0"], ["88539.7", "0.11294145", "0", "1"], ["88542", "0.09163094", "0", "1"], ["88543.9", "0.028993", "0", "2"], ["88544.1", "0.02662845", "0", "2"], ["88544.2", "0.02913265", "0", "1"], ["88544.3", "0.02517576", "0", "3"], ["88544.4", "0", "0", "0"], ["88544.6", "0.00040015", "0", "2"], ["88544.7", "0", "0", "0"], ["88544.8", "0.00001536", "0", "1"], ["88546.8", "0.33948763", "0", "2"], ["88546.9", "0.14228342", "0", "1"], ["88547.6", "0.080504", "0", "2"], ["88548.1", "0.06065105", "0", "3"], ["88548.2", "0.08037157", "0", "2"], ["88548.3", "0.07405768", "0", "6"], ["88548.4", "0.08840911", "0", "3"], ["88548.7", "0", "0", "0"], ["88548.8", "0.00001", "0", "1"], ["88548.9", "0", "0", "0"], ["88549.3", "0.00004828", "0", "1"], ["88549.4", "0.01353", "0", "1"], ["88550.3", "0", "0", "0"], ["88550.4", "0", "0", "0"], ["88551.2", "0.16894463", "0", "1"], ["88551.3", "0.12169377", "0", "2"], ["88551.6", "0.0000114", "0", "1"], ["88551.7", "0", "0", "0"], ["88551.8", "0.14290404", "0", "2"], ["88552.3", "0", "0", "0"], ["88552.9", "0.14769788", "0", "1"], ["88553.4", "0", "0", "0"], ["88553.8", "0", "0", "0"], ["88554.4", "0.14768316", "0", "2"], ["88554.5", "0.128161", "0", "1"], ["88554.9", "0.25659681", "0", "1"], ["88555", "0.2967477", "0", "5"], ["88555.9", "0.0186343", "0", "1"], ["88556", "0.04060349", "0", "2"], ["88558.4", "0.06760242", "0", "3"], ["88561.9", "0.22291502", "0", "2"], ["88569.6", "0.012102", "0", "1"], ["88570.2", "0", "0", "0"], ["88580", "0.03", "0", "1"], ["88589", "0.00001077", "0", "1"], ["88589.1", "1.69288077", "0", "1"], ["88591.8", "0.56745625", "0", "1"], ["88593.6", "0.497794", "0", "2"], ["88595.3", "0", "0", "0"], ["88595.9", "0", "0", "0"], ["88597", "0.49776", "0", "1"], ["88597.3", "0.1", "0", "1"], ["88597.4", "0.01128702", "0", "1"], ["88599.2", "0", "0", "0"], ["88606.8", "0.01739192", "0", "1"], ["88608.3", "0", "0", "0"], ["88618.6", "0.00183741", "0", "1"], ["88622.9", "0", "0", "0"], ["88623.3", "0", "0", "0"]], "bids": [["88533.2", "0.29302355", "0", "9"], ["88532.8", "0.0001", "0", "1"], ["88532.7", "0.0001", "0", "1"], ["88532.6", "0.12011329", "0", "1"], ["88532.3", "0.13594371", "0", "3"], ["88531.2", "0.03594673", "0", "1"], ["88527.9", "0.08328838", "0", "3"], ["88527.2", "0", "0", "0"], ["88527.1", "0.01853488", "0", "1"], ["88526.7", "0.02700521", "0", "1"], ["88526.6", "0.0268473", "0", "1"], ["88526.3", "0", "0", "0"], ["88526.2", "0.02724494", "0", "1"], ["88525.8", "0.02615428", "0", "1"], ["88525.1", "0.02698183", "0", "1"], ["88523.6", "0.16130168", "0", "1"], ["88523.4", "0.00001527", "0", "1"], ["88523.2", "0", "0", "0"], ["88522.9", "0.08205621", "0", "1"], ["88522.7", "0.08082339", "0", "1"], ["88522.6", "0", "0", "0"], ["88522.2", "0", "0", "0"], ["88522.1", "0.08656744", "0", "1"], ["88521.7", "0.08141843", "0", "1"], ["88520.2", "0", "0", "0"], ["88519.7", "0.13014657", "0", "1"], ["88519.3", "0", "0", "0"], ["88519.2", "0.17427535", "0", "1"], ["88518.8", "0.14088485", "0", "2"], ["88518.3", "0.002382", "0", "1"], ["88517.6", "0", "0", "0"], ["88517.2", "0.13330931", "0", "1"], ["88516.9", "0.03", "0", "1"], ["88516.4", "0.00734297", "0", "1"], ["88515.9", "0.13969429", "0", "1"], ["88515.3", "0", "0", "0"], ["88513.4", "0.237", "0", "2"], ["88509.2", "0", "0", "0"], ["88507.8", "0.03", "0", "1"], ["88505.4", "0", "0", "0"], ["88504.9", "0.498277", "0", "1"], ["88503.6", "0.04062871", "0", "1"], ["88503.5", "0", "0", "0"], ["88495.1", "0", "0", "0"], ["88493", "0.207", "0", "1"], ["88491.3", "0.498354", "0", "1"], ["88485.7", "0.01266846", "0", "2"], ["88484.5", "0.01739192", "0", "1"], ["88472.7", "0", "0", "0"], ["88471.8", "0", "0", "0"], ["88468", "0.00103617", "0", "2"], ["88464", "0", "0", "0"], ["88453", "0.747854", "0", "1"], ["88450.2", "0.00134347", "0", "2"], ["88406.8", "0.17603821", "0", "2"], ["88402.9", "0", "0", "0"], ["88397.8", "0", "0", "0"], ["88387.4", "0.01128577", "0", "1"], ["88373.5", "0", "0", "0"], ["88286.3", "0", "0", "0"]], "ts": "1741338237105", "checksum": 474196889, "seqId": 48070587701, "prevSeqId": 48070587386}]}
{"arg": {"channel": "books", "instId": "BTC-USDT"}, "action": "update", "data": [{"asks": [["88533.3", "0.02419801", "0", "20"], ["88534.9", "0.1129576", "0", "2"], ["88536.3", "0.0001", "0", "1"], ["88536.4", "0.00029692", "0", "3"], ["88537.9", "0.00112767", "0", "1"], ["88539.3", "0.02067517", "0", "1"], ["88539.4", "0.06064094", "0", "2"], ["88539.7", "0", "0", "0"], ["88541.6", "0.06887546", "0", "3"], ["88542", "0.02914508", "0", "1"], ["88542.2", "0.02883626", "0", "5"], ["88542.4", "0.05371432", "0", "2"], ["88543.9", "0.00001817", "0", "1"], ["88544.1", "0.00007666", "0", "1"], ["88544.2", "0", "0", "0"], ["88544.3", "0.00012172", "0", "2"], ["88544.5", "0.06413872", "0", "4"], ["88545.7", "0.08146777", "0", "1"], ["88546.1", "0.18471358", "0", "2"], ["88546.3", "0.08537896", "0", "2"], ["88546.4", "0.07831974", "0", "8"], ["88546.5", "0.07818073", "0", "2"], ["88546.9", "0", "0", "0"], ["88547", "0.00001139", "0", "1"], ["88547.6", "0.00131779", "0", "1"], ["88548.1", "0.00001011", "0", "1"], ["88548.2", "0.00002329", "0", "1"], ["88548.3", "0.00048118", "0", "4"], ["88548.4", "0.00002745", "0", "2"], ["88549.4", "0.14593007", "0", "2"], ["88549.9", "0.14241524", "0", "7"], ["88550.4", "0.01520535", "0", "1"], ["88550.8", "0.00225374", "0", "1"], ["88551.1", "0.14759704", "0", "1"], ["88551.2", "0", "0", "0"], ["88551.3", "0.00001204", "0", "1"], ["88551.8", "0.00001097", "0", "1"], ["88552.5", "0.13193705", "0", "1"], ["88552.9", "0", "0", "0"], ["88553.4", "0.045", "0", "1"], ["88554.4", "0.00016676", "0", "1"], ["88556.9", "0.135", "0", "3"], ["88557.7", "0.012102", "0", "1"], ["88561.8", "0.09", "0", "2"], ["88567.1", "0.00225374", "0", "1"], ["88569.6", "0", "0", "0"], ["88576.3", "0.22588106", "0", "1"], ["88578", "0.0625", "0", "3"], ["88578.1", "0.00009546", "0", "3"], ["88579", "0.09276168", "0", "7"], ["88579.8", "0.00001056", "0", "1"], ["88580", "0", "0", "0"], ["88589", "0.507875", "0", "2"], ["88593.6", "0.000015", "0", "1"], ["88595", "0.00005751", "0", "2"], ["88597", "0", "0", "0"], ["88602.8", "0.0174027", "0", "2"], ["88606.8", "0", "0", "0"], ["88613.5", "0", "0", "0"], ["88622.2", "0", "0", "0"], ["88622.3", "0", "0", "0"], ["88622.5", "0", "0", "0"], ["88622.6", "0", "0", "0"], ["88622.7", "0", "0", "0"]], "bids": [["88533.2", "0.16777992", "0", "7"], ["88532.8", "0", "0", "0"], ["88532.7", "0", "0", "0"], ["88532.6", "0.06285908", "0", "2"], ["88532.5", "0.0001", "0", "1"], ["88532.4", "0", "0", "0"], ["88532.3", "0", "0", "0"], ["88532.2", "0.0113956", "0", "2"], ["88531.2", "0", "0", "0"], ["88529.5", "0.06064094", "0", "2"], ["88529.4", "0.00942", "0", "1"], ["88529.2", "0.02671259", "0", "1"], ["88528.3", "0.05384708", "0", "3"], ["88528.2", "0.03032047", "0", "1"], ["88528", "0.08080914", "0", "2"], ["88527.9", "0.00734165", "0", "1"], ["88527.3", "0", "0", "0"], ["88526.7", "0", "0", "0"], ["88526.6", "0", "0", "0"], ["88526.2", "0", "0", "0"], ["88525.8", "0", "0", "0"], ["88525.2", "0.06064094", "0", "2"], ["88524.9", "0.04", "0", "1"], ["88524.8", "0.02681785", "0", "1"], ["88524.7", "0.02728923", "0", "1"], ["88524.3", "0.02797873", "0", "1"], ["88524", "0.04241243", "0", "2"], ["88523.8", "0", "0", "0"], ["88523.7", "0", "0", "0"], ["88523.6", "0.24058321", "0", "1"], ["88523", "0.0194028", "0", "1"], ["88522.9", "0", "0", "0"], ["88522.7", "0", "0", "0"], ["88522.1", "0", "0", "0"], ["88522", "0.24218106", "0", "2"], ["88521.9", "0.02828", "0", "1"], ["88521.7", "0", "0", "0"], ["88521", "0.08361613", "0", "1"], ["88520.8", "0.0744176", "0", "1"], ["88520.4", "0.33929724", "0", "1"], ["88520.2", "0.08963228", "0", "1"], ["88519.9", "0.0798905", "0", "1"], ["88519.7", "0", "0", "0"], ["88519.2", "0.10529849", "0", "1"], ["88518.8", "0.00001138", "0", "1"], ["88518.3", "0", "0", "0"], ["88517.8", "0.13026198", "0", "1"], ["88517.2", "0", "0", "0"], ["88516.9", "0.17101952", "0", "2"], ["88515.9", "0", "0", "0"], ["88515.3", "0.14002628", "0", "1"], ["88514.8", "0", "0", "0"], ["88514", "0.16306276", "0", "2"], ["88513.2", "0.01650401", "0", "1"], ["88512.3", "0.00198343", "0", "1"], ["88511.7", "0.003855", "0", "1"], ["88511.4", "0", "0", "0"], ["88510.3", "1.66773955", "0", "1"], ["88507", "0", "0", "0"], ["88505.1", "0", "0", "0"], ["88504.9", "0", "0", "0"], ["88504.6", "0", "0", "0"], ["88503.6", "0", "0", "0"], ["88503.2", "0.03405739", "0", "1"], ["88492.7", "0.52006974", "0", "1"], ["88492", "0.0712", "0", "3"], ["88491.3", "0", "0", "0"], ["88491", "0.06", "0", "2"], ["88490", "0.03", "0", "1"], ["88487", "0.47921", "0", "1"], ["88486.4", "0.100015", "0", "2"], ["88486", "0", "0", "0"], ["88485", "0", "0", "0"], ["88484.5", "0", "0", "0"], ["88484.4", "0", "0", "0"], ["88484.3", "0", "0", "0"], ["88481.8", "0.03113232", "0", "1"], ["88478.3", "0.01739262", "0", "1"], ["88468.1", "2.12624221", "0", "1"], ["88460.8", "0.77039642", "0", "2"], ["88435.8", "2.16256986", "0", "1"], ["88429.4", "0.00170628", "0", "1"], ["88424.4", "0.21123262", "0", "2"], ["88406.8", "0.00211897", "0", "1"], ["88402.9", "0.17392626", "0", "1"], ["88391.1", "0.2451118", "0", "1"], ["88389.5", "0", "0", "0"], ["88389.4", "0", "0", "0"], ["88378.3", "2.12495248", "0", "1"], ["88307.2", "0", "0", "0"], ["88286.3", "0.03", "0", "1"]], "ts": "1741338237205", "checksum": 92379600, "seqId": 48070588157, "prevSeqId": 48070587701}]}
{"arg": {"channel": "books", "instId": "BTC-USDT"}, "action": "update", "data": [{"asks": [["88533.3", "0.05849801", "0", "20"], ["88535.1", "0.0001", "0", "1"], ["88536.3", "0", "0", "0"], ["88536.4", "0.00019692", "0", "2"], ["88536.7", "0.00011", "0", "2"], ["88541.6", "0.11137402", "0", "4"], ["88541.7", "0.02686312", "0", "3"], ["88541.9", "0.0299193", "0", "1"], ["88542", "0", "0", "0"], ["88542.1", "0.11693037", "0", "6"], ["88542.2", "0.00026414", "0", "4"], ["88542.4", "0", "0", "0"], ["88544.5", "0.06175672", "0", "3"], ["88545.4", "0.08648864", "0", "5"], ["88545.7", "0", "0", "0"], ["88546", "0.10379074", "0", "5"], ["88546.1", "0.25701814", "0", "3"], ["88546.2", "0.07827806", "0", "1"], ["88546.3", "0.00013676", "0", "1"], ["88546.4", "0.00026336", "0", "7"], ["88546.5", "0.00001", "0", "1"], ["88549.1", "0.13496461", "0", "1"], ["88549.4", "0", "0", "0"], ["88549.6", "0.14188799", "0", "2"], ["88549.9", "0.00076516", "0", "6"], ["88550", "0.09701769", "0", "11"], ["88550.4", "0", "0", "0"], ["88550.8", "0.14485693", "0", "2"], ["88551.1", "0", "0", "0"], ["88552.2", "0.14926031", "0", "1"], ["88552.5", "0", "0", "0"], ["88553.4", "0.09", "0", "2"], ["88556.4", "0.012102", "0", "1"], ["88556.9", "0.174", "0", "4"], ["88557.7", "0", "0", "0"], ["88561.8", "0", "0", "0"], ["88622.2", "0.00011317", "0", "1"], ["88622.3", "0.000119", "0", "4"], ["88622.5", "0.00007987", "0", "3"], ["88622.6", "0.0022178", "0", "4"]], "bids": [["88533.2", "0.19685992", "0", "9"], ["88532.5", "0.0002", "0", "2"], ["88532.2", "0.0112956", "0", "1"], ["88529.6", "0.00145491", "0", "1"], ["88528.3", "0.05239217", "0", "2"], ["88528.2", "0", "0", "0"], ["88524.8", "0", "0", "0"], ["88524.7", "0", "0", "0"], ["88524.5", "0.0265325", "0", "1"], ["88524.4", "0.02983093", "0", "2"], ["88524.3", "0", "0", "0"], ["88524", "0.04396335", "0", "2"], ["88523.7", "0.02799422", "0", "1"], ["88521", "0", "0", "0"], ["88520.8", "0", "0", "0"], ["88520.7", "0.08478985", "0", "1"], ["88520.5", "0.08200612", "0", "1"], ["88520.2", "0", "0", "0"], ["88519.9", "0.08143006", "0", "1"], ["88519.5", "0.07959869", "0", "1"], ["88519.2", "0.14202181", "0", "2"], ["88517.8", "0", "0", "0"], ["88517.5", "0.12285551", "0", "1"], ["88516.9", "0.03", "0", "1"], ["88516.6", "0.13950194", "0", "1"], ["88515.3", "0", "0", "0"], ["88515", "0.14365468", "0", "1"], ["88514", "0.0155", "0", "1"], ["88513.7", "1.03727465", "0", "2"], ["88511.7", "0", "0", "0"], ["88507.8", "0", "0", "0"], ["88284.9", "0.08542891", "0", "1"], ["88283.5", "0.11343045", "0", "1"]], "ts": "1741338237305", "checksum": -2030307646, "seqId": 48070588341, "prevSeqId": 48070588157}]}
{"arg": {"channel": "books", "instId": "BTC-USDT"}, "action": "update", "data": [{"asks": [["88533.3", "0.01789801", "0", "19"], ["88534.9", "0.00001003", "0", "1"], ["88535.1", "0", "0", "0"], ["88535.2", "0.00022748", "0", "2"], ["88536.4", "0.00029692", "0", "3"], ["88536.7", "0.00001", "0", "1"], ["88537.4", "0.11294438", "0", "1"], ["88541.6", "0.06887546", "0", "3"], ["88541.7", "0.00002123", "0", "2"], ["88541.9", "0", "0", "0"], ["88542.1", "0.06078883", "0", "4"], ["88543.6", "0.02663356", "0", "1"], ["88543.8", "0.0284644", "0", "1"], ["88544", "0.05471107", "0", "4"], ["88544.5", "0.06194422", "0", "4"], ["88545.4", "0.00013356", "0", "4"], ["88545.9", "0.20227753", "0", "4"], ["88546", "0.01364484", "0", "4"], ["88546.1", "0", "0", "0"], ["88546.2", "0", "0", "0"], ["88547.3", "0.0998327", "0", "2"], ["88548.1", "0.08070628", "0", "2"], ["88549.1", "0", "0", "0"], ["88549.6", "0.000015", "0", "1"], ["88550.8", "0.00225374", "0", "1"], ["88551", "0.1351756", "0", "3"], ["88552.2", "0", "0", "0"], ["88554.1", "0.14290491", "0", "2"], ["88556.4", "0", "0", "0"], ["88558.3", "0.0000114", "0", "1"], ["88558.4", "0.02260242", "0", "2"], ["88561.6", "0.12553245", "0", "2"], ["88588.8", "0.49791682", "0", "2"], ["88592.1", "0.49783762", "0", "4"], ["88622.7", "0.00009738", "0", "1"], ["88622.9", "0.00012971", "0", "2"], ["88623", "3.10374441", "0", "1"], ["88623.3", "0.00057765", "0", "3"]], "bids": [["88532.6", "0.06305908", "0", "4"], ["88532.5", "0", "0", "0"], ["88532.2", "0.12424652", "0", "2"], ["88532", "0.02572", "0", "2"], ["88529.4", "0", "0", "0"], ["88526.4", "0.02602231", "0", "1"], ["88526.3", "0.02880134", "0", "1"], ["88524.5", "0", "0", "0"], ["88524.4", "0.00001138", "0", "1"], ["88524", "0.0163", "0", "1"], ["88523.7", "0", "0", "0"], ["88522.6", "0.08054406", "0", "1"], ["88522.4", "0.0798724", "0", "1"], ["88521.8", "0.08923187", "0", "1"], ["88521.4", "0.09420741", "0", "2"], ["88520.7", "0", "0", "0"], ["88520.5", "0", "0", "0"], ["88519.9", "0", "0", "0"], ["88519.5", "0", "0", "0"], ["88517.5", "0", "0", "0"], ["88516.9", "0.16285711", "0", "2"], ["88516.6", "0", "0", "0"], ["88515", "0", "0", "0"], ["88513.8", "0.01650401", "0", "1"], ["88513.7", "0.90244663", "0", "1"], ["88513.2", "0", "0", "0"], ["88512.9", "0.003855", "0", "1"], ["88499.5", "0.498308", "0", "1"], ["88485.8", "0.498385", "0", "1"], ["88283.3", "0.00416498", "0", "2"], ["88283", "0.00001722", "0", "1"], ["88281.2", "0.00006263", "0", "1"]], "ts": "1741338237405", "checksum": -401654420, "seqId": 48070588468, "prevSeqId": 48070588341}]}
{"arg": {"channel": "books", "instId": "BTC-USDT"}, "action": "update", "data": [{"asks": [["88535.2", "0.00012748", "0", "1"], ["88536.3", "0.0001", "0", "1"], ["88536.4", "0.00019692", "0", "2"], ["88537.3", "0.06179726", "0", "2"], ["88537.8", "0.0001", "0", "1"], ["88539.3", "0", "0", "0"], ["88539.4", "0", "0", "0"], ["88542.2", "0.02701092", "0", "5"], ["88542.5", "0.0251097", "0", "1"], ["88543.6", "0", "0", "0"], ["88543.8", "0", "0", "0"], ["88544", "0.00084248", "0", "2"], ["88545.9", "0.28405545", "0", "5"], ["88546.5", "0.08130789", "0", "2"], ["88546.8", "0.00019039", "0", "1"], ["88547.3", "0.01353", "0", "1"], ["88548.1", "0.00001011", "0", "1"], ["88549.6", "0.12303746", "0", "2"], ["88550", "0.24311455", "0", "12"], ["88551", "0.00003451", "0", "2"], ["88554.1", "0.00001148", "0", "1"], ["88558.1", "0.012102", "0", "1"], ["88558.2", "0.00917421", "0", "3"], ["88561.6", "0.11343045", "0", "1"], ["88561.9", "0.18391502", "0", "1"]], "bids": [["88532.7", "0.0002", "0", "2"], ["88532.6", "0.09705552", "0", "1"], ["88532.3", "0.00145491", "0", "1"], ["88529.6", "0", "0", "0"], ["88528", "0.11768103", "0", "3"], ["88526.6", "0.02828", "0", "1"], ["88526.4", "0", "0", "0"], ["88526.3", "0", "0", "0"], ["88524.9", "0.09287455", "0", "3"], ["88522.6", "0", "0", "0"], ["88522.4", "0", "0", "0"], ["88521.9", "0", "0", "0"], ["88521.8", "0", "0", "0"], ["88521.4", "0.00839429", "0", "1"], ["88521.2", "0.08311936", "0", "1"], ["88521", "0.07335682", "0", "1"], ["88519.2", "0.14562712", "0", "2"], ["88517.9", "0.12223545", "0", "1"], ["88517", "0.17694743", "0", "2"], ["88516.9", "0.03", "0", "1"], ["88513.8", "0", "0", "0"], ["88513.6", "0.01650401", "0", "1"], ["88512.9", "0", "0", "0"], ["88495.1", "0.00341227", "0", "1"], ["88281.1", "0.34078752", "0", "2"]], "ts": "1741338237505", "checksum": 98260195, "seqId": 48070588616, "prevSeqId": 48070588468}]}
{"arg": {"channel": "books", "instId": "BTC-USDT"}, "action": "update", "data": [{"asks": [["88534", "0.00001007", "0", "1"], ["88536", "0.00002025", "0", "1"], ["88536.1", "0", "0", "0"], ["88536.3", "0", "0", "0"], ["88537.3", "0.00002092", "0", "1"], ["88537.4", "0", "0", "0"], ["88537.8", "0", "0", "0"], ["88539.2", "0.0001", "0", "1"], ["88539.8", "0.11294135", "0", "1"], ["88539.9", "0.00013598", "0", "2"], ["88542.1", "0.06078958", "0", "4"], ["88542.2", "0.00026414", "0", "4"], ["88542.5", "0", "0", "0"], ["88544.1", "0.02791316", "0", "2"], ["88544.2", "0.02752181", "0", "1"], ["88544.4", "0.02780858", "0", "1"], ["88544.5", "0.08990309", "0", "5"], ["88545.9", "0.15231714", "0", "5"], ["88546", "0.00011484", "0", "3"], ["88546.5", "0.00001", "0", "1"], ["88547.8", "0.08794913", "0", "2"], ["88548.3", "0.01401118", "0", "5"], ["88548.4", "0.16256556", "0", "4"], ["88548.6", "0.0868753", "0", "1"], ["88549.6", "0.000015", "0", "1"], ["88550", "0.14217081", "0", "11"], ["88551.4", "0.12705173", "0", "1"], ["88551.9", "0.14005536", "0", "1"], ["88553.2", "0.13792209", "0", "1"], ["88554.6", "0.13716687", "0", "6"], ["88558.1", "0", "0", "0"], ["88558.2", "0.00574872", "0", "2"], ["88561.8", "0.012102", "0", "1"], ["88569.7", "0.28183456", "0", "2"], ["88571.9", "0.03507357", "0", "1"], ["88576.3", "0", "0", "0"], ["88581.9", "0.22588725", "0", "3"], ["88622.9", "0", "0", "0"], ["88623", "0", "0", "0"], ["88623.3", "0", "0", "0"]], "bids": [["88533.2", "0.26995714", "0", "12"], ["88532.7", "0", "0", "0"], ["88532.6", "0.13917098", "0", "1"], ["88531.5", "0.0001", "0", "1"], ["88531.4", "0.0001", "0", "1"], ["88529.5", "0", "0", "0"], ["88529.2", "0", "0", "0"], ["88528.3", "0", "0", "0"], ["88528", "0.35512032", "0", "2"], ["88526.8", "0.0532387", "0", "2"], ["88526.7", "0.22586708", "0", "1"], ["88526.4", "0.02662378", "0", "1"], ["88526.1", "0.02769372", "0", "1"], ["88525.2", "0", "0", "0"], ["88525.1", "0", "0", "0"], ["88524.9", "0.04", "0", "1"], ["88524.3", "0.207", "0", "1"], ["88523.7", "0.90244663", "0", "1"], ["88523.6", "0.22777897", "0", "2"], ["88523", "0.08983195", "0", "1"], ["88522.8", "0.07987951", "0", "1"], ["88522.2", "0.08475972", "0", "1"], ["88522", "0.0163", "0", "1"], ["88521.9", "0.08419618", "0", "1"], ["88521.2", "0", "0", "0"], ["88521", "0", "0", "0"], ["88519.8", "0.18284775", "0", "2"], ["88519.2", "0.18340882", "0", "2"], ["88518.9", "0.14078124", "0", "1"], ["88517.9", "0", "0", "0"], ["88517.4", "0.13629339", "0", "1"], ["88517", "0.03", "0", "1"], ["88516.2", "0.0039", "0", "1"], ["88516.1", "0.1479418", "0", "1"], ["88513.8", "0.01650401", "0", "1"], ["88513.6", "0", "0", "0"], ["88505.6", "0.0006", "0", "2"], ["88504.8", "0.00029911", "0", "1"], ["88502.3", "0.11343045", "0", "1"], ["88501.6", "0.09751889", "0", "1"], ["88500", "0", "0", "0"], ["88499.2", "0", "0", "0"], ["88476.4", "0.03833192", "0", "1"], ["88287", "0", "0", "0"], ["88286.3", "0", "0", "0"], ["88284.9", "0", "0", "0"], ["88283.5", "0", "0", "0"], ["88283.3", "0", "0", "0"], ["88283", "0", "0", "0"], ["88281.2", "0", "0", "0"], ["88281.1", "0", "0", "0"]], "ts": "1741338237605", "checksum": -895589372, "seqId": 48070588883, "prevSeqId": 48070588616}]}
{"arg": {"channel": "books", "instId": "BTC-USDT"}, "action": "update", "data": [{"asks": [["88538.2", "0.0001", "0", "1"], ["88538.3", "0.00134659", "0", "10"], ["88539.2", "0", "0", "0"], ["88539.8", "0", "0", "0"], ["88539.9", "0.00003598", "0", "1"], ["88541.6", "0.0004477", "0", "2"], ["88542.1", "0.00014864", "0", "2"], ["88543.1", "0.06195873", "0", "3"], ["88543.2", "0.04094636", "0", "1"], ["88544.1", "0.00007666", "0", "1"], ["88544.2", "0", "0", "0"], ["88544.4", "0", "0", "0"], ["88544.5", "0.06175672", "0", "3"], ["88545.6", "0.02697965", "0", "1"], ["88545.9", "0.06071396", "0", "3"], ["88547.8", "0.0000129", "0", "1"], ["88548.2", "0.04088633", "0", "2"], ["88548.4", "0.00002745", "0", "2"], ["88548.5", "0", "0", "0"], ["88548.6", "0", "0", "0"], ["88548.8", "0.06065094", "0", "3"], ["88549.6", "0", "0", "0"], ["88549.7", "0.08120501", "0", "1"], ["88549.8", "0.06064094", "0", "2"], ["88550", "0.00109016", "0", "9"], ["88550.8", "0.07495377", "0", "1"], ["88550.9", "0.06064094", "0", "2"], ["88551.2", "0.06064094", "0", "2"], ["88551.4", "0", "0", "0"], ["88551.9", "0", "0", "0"], ["88553.1", "0.06454094", "0", "3"], ["88553.2", "0", "0", "0"], ["88553.4", "0", "0", "0"], ["88554.2", "0.14879421", "0", "3"], ["88554.4", "0.03048723", "0", "2"], ["88554.6", "0.00199223", "0", "5"], ["88556.9", "0", "0", "0"], ["88558.3", "0.0450114", "0", "2"], ["88560.8", "0.11516828", "0", "2"], ["88561.8", "0", "0", "0"], ["88563.9", "0.012102", "0", "1"], ["88569.7", "0.27321997", "0", "1"], ["88571.9", "0", "0", "0"], ["88588.8", "0.00011082", "0", "1"], ["88592.1", "0.00005062", "0", "3"], ["88608", "0.0305953", "0", "2"], ["88622.9", "0.00012971", "0", "2"], ["88623", "3.10374441", "0", "1"], ["88623.3", "0.00057765", "0", "3"], ["88623.6", "0.00001103", "0", "1"], ["88623.7", "0.0064954", "0", "3"]], "bids": [["88533.2", "0.35435042", "0", "15"], ["88532.5", "0.0002", "0", "2"], ["88531.5", "0", "0", "0"], ["88531.4", "0", "0", "0"], ["88527.8", "0.08542891", "0", "1"], ["88527.1", "0.38474026", "0", "3"], ["88526.8", "0", "0", "0"], ["88526.4", "0", "0", "0"], ["88526.1", "0", "0", "0"], ["88523.6", "0.16303553", "0", "1"], ["88523.5", "0.33889", "0", "1"], ["88523", "0.08379382", "0", "1"], ["88522.8", "0", "0", "0"], ["88522.2", "0", "0", "0"], ["88521.9", "0", "0", "0"], ["88521.6", "0.0011999", "0", "2"], ["88519.8", "0.05647723", "0", "1"], ["88519.2", "0.07115143", "0", "1"], ["88518.9", "0", "0", "0"], ["88518.5", "0.14845711", "0", "1"], ["88517.4", "0", "0", "0"], ["88516.1", "0", "0", "0"], ["88499.5", "0", "0", "0"], ["88485.8", "0", "0", "0"], ["88482.9", "0.33905", "0", "1"], ["88476.4", "0", "0", "0"], ["88450.3", "0", "0", "0"], ["88409.5", "0.203583", "0", "1"], ["88363.2", "0.000015", "0", "1"], ["88299.4", "0", "0", "0"], ["88287", "0.03", "0", "1"], ["88286.3", "0.03", "0", "1"], ["88284.9", "0.08542891", "0", "1"], ["88283.5", "0.11343045", "0", "1"], ["88283.3", "0.00416498", "0", "2"], ["88283", "0.00001722", "0", "1"], ["88281.2", "0.00006263", "0", "1"], ["88281.1", "0.34078752", "0", "2"], ["88280.5", "0.00002567", "0", "1"], ["88279.9", "0.00001655", "0", "1"]], "ts": "1741338237705", "checksum": -2025575124, "seqId": 48070589099, "prevSeqId": 48070588883}]}
{"arg": {"channel": "books", "instId": "BTC-USDT"}, "action": "update", "data": [{"asks": [["88533.3", "0.00660254", "0", "11"], ["88538.2", "0", "0", "0"], ["88538.3", "0.00124659", "0", "9"], ["88539.3", "0.0001", "0", "1"], ["88539.4", "0.0001", "0", "1"], ["88543", "0.04141588", "0", "3"], ["88543.2", "0", "0", "0"], ["88543.3", "0.00001005", "0", "1"], ["88545.6", "0", "0", "0"], ["88549.6", "0.00001501", "0", "1"], ["88549.7", "0", "0", "0"], ["88550.8", "0.04766535", "0", "1"], ["88551.2", "0", "0", "0"], ["88553.1", "0.06064094", "0", "2"], ["88554.2", "0.00070666", "0", "2"], ["88558.3", "0.0900114", "0", "3"], ["88559.2", "0.01888533", "0", "1"], ["88561.9", "0.31891502", "0", "4"], ["88563.4", "0.012102", "0", "1"], ["88563.9", "0", "0", "0"], ["88576.3", "0.22587181", "0", "1"], ["88581.9", "0.00002381", "0", "2"], ["88607.1", "0", "0", "0"], ["88611.6", "0.03", "0", "1"]], "bids": [["88533.2", "0.3064801", "0", "14"], ["88533.1", "0.0002", "0", "2"], ["88532.7", "0.00145491", "0", "1"], ["88532.5", "0", "0", "0"], ["88532.3", "0", "0", "0"], ["88532", "0.0163", "0", "1"], ["88528", "0.54806223", "0", "3"], ["88527.1", "0.35741488", "0", "2"], ["88526.7", "0", "0", "0"], ["88525.4", "0.33889", "0", "1"], ["88523.6", "0.23782088", "0", "2"], ["88523", "0", "0", "0"], ["88520.5", "0.22587181", "0", "1"], ["88518.5", "0", "0", "0"], ["88516.6", "0.00057148", "0", "1"], ["88516.2", "0", "0", "0"], ["88495.1", "0", "0", "0"], ["88466.6", "0.00459996", "0", "3"], ["88462", "0", "0", "0"], ["88459", "0", "0", "0"], ["88299.9", "0.00466033", "0", "3"], ["88276.1", "0.00007", "0", "1"], ["88275.5", "0.00001139", "0", "1"], ["88275", "0.00009665", "0", "2"], ["88274.6", "0.00001339", "0", "1"]], "ts": "1741338237805", "checksum": -178953302, "seqId": 48070589216, "prevSeqId": 48070589099}]}
{"arg": {"channel": "books", "instId": "BTC-USDT"}, "action": "update", "data": [{"asks": [["88539.3", "0", "0", "0"], ["88539.4", "0.0002", "0", "2"], ["88552.4", "0.002382", "0", "1"], ["88561.9", "0.35791502", "0", "5"], ["88563", "0.01447319", "0", "2"], ["88563.4", "0", "0", "0"], ["88623.8", "0.00451898", "0", "1"]], "bids": [["88532.6", "0.06461672", "0", "1"], ["88520.6", "0.001314", "0", "1"], ["88480.6", "3.19335614", "0", "2"], ["88274.6", "0", "0", "0"]], "ts": "1741338237905", "checksum": 13097919, "seqId": 48070589238, "prevSeqId": 48070589216}]}
{"arg": {"channel": "books", "instId": "BTC-USDT"}, "action": "update", "data": [{"asks": [["88545.8", "0.06636873", "0", "1"], ["88548.2", "0.00002329", "0", "1"], ["88552.4", "0", "0", "0"], ["88558.4", "0.02599221", "0", "3"], ["88562.6", "0.012102", "0", "1"], ["88563", "0.00237119", "0", "1"], ["88593.6", "0.497794", "0", "2"], ["88596.8", "0.49778228", "0", "2"], ["88623.8", "0", "0", "0"]], "bids": [["88533.1", "0", "0", "0"], ["88532.3", "0.0002", "0", "2"], ["88528", "0.54895269", "0", "4"], ["88504", "0.49829701", "0", "2"], ["88490.4", "0.49837038", "0", "2"], ["88450.2", "0.00114951", "0", "1"], ["88434.7", "0.1", "0", "1"], ["88275", "0", "0", "0"]], "ts": "1741338238005", "checksum": -1685568625, "seqId": 48070589283, "prevSeqId": 48070589238}]}
{"arg": {"channel": "books", "instId": "BTC-USDT"}, "action": "update", "data": [{"asks": [["88575.3", "0.2364427", "0", "4"], ["88575.4", "0.03701617", "0", "1"], ["88576.3", "0", "0", "0"], ["88595", "0.20005751", "0", "3"], ["88602.8", "0.00001008", "0", "1"], ["88603.3", "0.0182819", "0", "3"], ["88609.7", "0.01692", "0", "1"], ["88618.6", "0", "0", "0"], ["88619.3", "0.00183741", "0", "1"], ["88623.7", "0", "0", "0"]], "bids": [["88480.7", "0.01739199", "0", "1"], ["88479.9", "0.03821447", "0", "1"], ["88478.3", "0", "0", "0"], ["88468.2", "0.00102614", "0", "1"], ["88468", "0.00001", "0", "1"], ["88462", "0.0009861", "0", "1"], ["88461.2", "0.33929724", "0", "1"], ["88456.5", "0.00020531", "0", "2"], ["88409.6", "0.00211808", "0", "1"], ["88406.8", "0", "0", "0"], ["88405.5", "0.17393133", "0", "2"], ["88402.9", "0", "0", "0"], ["88387.1", "0", "0", "0"], ["88275.5", "0", "0", "0"]], "ts": "1741338238105", "checksum": -1685568625, "seqId": 48070589335, "prevSeqId": 48070589283}]}
{"arg": {"channel": "books", "instId": "BTC-USDT"}, "action": "update", "data": [{"asks": [["88533.3", "0", "0", "0"], ["88533.4", "0", "0", "0"], ["88533.5", "0", "0", "0"], ["88533.6", "0", "0", "0"], ["88533.9", "0", "0", "0"], ["88534", "0.05771007", "0", "3"], ["88536", "0.0171", "0", "1"], ["88536.1", "0.000021", "0", "1"], ["88538.5", "0.0001", "0", "1"], ["88539.4", "0", "0", "0"], ["88539.6", "0.00041761", "0", "3"], ["88542.1", "0.00014789", "0", "2"], ["88542.8", "0.06004644", "0", "2"], ["88542.9", "0.06064094", "0", "2"], ["88543", "0.00007419", "0", "2"], ["88543.1", "0.00131779", "0", "1"], ["88545.8", "0.19208531", "0", "2"], ["88548", "0.00256553", "0", "2"], ["88548.7", "0.33929724", "0", "1"], ["88548.8", "0.00001", "0", "1"], ["88549.8", "0", "0", "0"], ["88550.8", "0.1134286", "0", "1"], ["88550.9", "0", "0", "0"], ["88553.1", "0", "0", "0"], ["88554.3", "0.14701734", "0", "1"], ["88554.4", "0.39472846", "0", "2"], ["88554.9", "0", "0", "0"], ["88558.2", "0.01785072", "0", "3"], ["88558.4", "0.02260242", "0", "2"], ["88562.6", "0", "0", "0"], ["88572.5", "0.22588106", "0", "1"], ["88575.3", "0.01056929", "0", "3"], ["88578", "0.0025", "0", "1"], ["88579", "0.12276168", "0", "8"], ["88580", "0.03", "0", "1"], ["88587", "1", "0", "1"], ["88603.3", "0.00088991", "0", "2"], ["88604", "0.01740247", "0", "2"], ["88623.7", "0.0064954", "0", "3"], ["88623.8", "0.00451898", "0", "1"]], "bids": [["88533.9", "0.25217213", "0", "9"], ["88533.8", "0.033986", "0", "2"], ["88533.5", "0.08341083", "0", "1"], ["88533.4", "0.11294941", "0", "1"], ["88533.2", "0.08252722", "0", "5"], ["88532.7", "0", "0", "0"], ["88532.6", "0", "0", "0"], ["88532.3", "0.0001", "0", "1"], ["88532.2", "0.0112956", "0", "1"], ["88528.2", "0.00145491", "0", "1"], ["88527.8", "0", "0", "0"], ["88524.3", "0", "0", "0"], ["88523.6", "0.2330576", "0", "1"], ["88523.4", "0.00002412", "0", "1"], ["88523.1", "0.07761286", "0", "1"], ["88520.6", "0", "0", "0"], ["88520.5", "0", "0", "0"], ["88519.2", "0.12526095", "0", "1"], ["88518.6", "0.13735844", "0", "1"], ["88517.1", "0.22588106", "0", "1"], ["88510.4", "0.53877358", "0", "1"], ["88493", "0.267", "0", "3"], ["88492", "0.0112", "0", "1"], ["88483.6", "1.23243291", "0", "2"], ["88424.4", "0.00451934", "0", "1"], ["88414.8", "0.00565", "0", "1"], ["88399.9", "0.0082205", "0", "6"], ["88391.1", "0", "0", "0"], ["88371.1", "0.00005685", "0", "1"], ["88280.5", "0", "0", "0"], ["88279.9", "0", "0", "0"], ["88276.1", "0", "0", "0"]], "ts": "1741338238205", "checksum": -836341483, "seqId": 48070589688, "prevSeqId": 48070589335}]}
{"arg": {"channel": "books", "instId": "BTC-USDT"}, "action": "update", "data": [{"asks": [["88534.1", "0.00005613", "0", "1"], ["88536.1", "0", "0", "0"], ["88536.8", "0.00002025", "0", "1"], ["88537.4", "0.0001", "0", "1"], ["88537.8", "0.0001", "0", "1"], ["88538.5", "0", "0", "0"], ["88539.6", "0.00031761", "0", "2"], ["88542.1", "0.00010289", "0", "1"], ["88542.8", "0.06037862", "0", "3"], ["88544.7", "0.02714201", "0", "1"], ["88545.8", "0.19076429", "0", "2"], ["88548", "0.00018353", "0", "1"], ["88548.8", "0.0805322", "0", "2"], ["88550.8", "0.18733968", "0", "2"], ["88553.3", "0.14135822", "0", "1"], ["88554.3", "0", "0", "0"], ["88556.6", "0.012102", "0", "1"], ["88558.2", "0.00574872", "0", "2"], ["88559.5", "0.56573268", "0", "6"], ["88572.5", "0.22588341", "0", "1"], ["88587", "0", "0", "0"], ["88595", "0.00005751", "0", "2"], ["88597.3", "0", "0", "0"], ["88598", "0.10002736", "0", "2"], ["88619.3", "0", "0", "0"], ["88619.9", "0.00184739", "0", "2"], ["88623.8", "0", "0", "0"]], "bids": [["88533.9", "0.25227213", "0", "10"], ["88532.3", "0", "0", "0"], ["88526.2", "0.02775799", "0", "1"], ["88524.1", "0.00001887", "0", "1"], ["88523.4", "0", "0", "0"], ["88523.1", "0", "0", "0"], ["88522.1", "0.07979793", "0", "1"], ["88519.2", "0.20409256", "0", "2"], ["88518.6", "0", "0", "0"], ["88517.9", "0.003855", "0", "1"], ["88517.6", "0.13936301", "0", "1"], ["88517.1", "0", "0", "0"], ["88514.8", "0.22588447", "0", "1"], ["88495.1", "0.00345904", "0", "1"], ["88487.1", "0.12260169", "0", "2"], ["88486.4", "0.000015", "0", "1"], ["88471.2", "0.00102623", "0", "1"], ["88468.2", "0", "0", "0"], ["88464", "0.00098618", "0", "1"], ["88462", "0", "0", "0"], ["88317.3", "0", "0", "0"], ["88281.1", "0", "0", "0"]], "ts": "1741338238305", "checksum": 896505973, "seqId": 48070589968, "prevSeqId": 48070589688}]}
{"arg": {"channel": "books", "instId": "BTC-USDT"}, "action": "update", "data": [{"asks": [["88534", "0.01711007", "0", "2"], ["88537.1", "0.0029354", "0", "27"], ["88537.4", "0", "0", "0"], ["88537.8", "0", "0", "0"], ["88538.5", "0.0001", "0", "1"], ["88542.8", "0.04140895", "0", "2"], ["88544.7", "0", "0", "0"], ["88545.8", "0.13248794", "0", "1"], ["88548.8", "0.00001", "0", "1"], ["88550.8", "0.1134286", "0", "1"], ["88553.3", "0", "0", "0"], ["88556.6", "0", "0", "0"], ["88557.7", "0.012102", "0", "1"], ["88572.5", "0", "0", "0"], ["88575.3", "0.23644806", "0", "4"], ["88623.8", "0.00451898", "0", "1"], ["88623.9", "0.06804094", "0", "1"], ["88624.2", "0.00005126", "0", "4"], ["88624.4", "0.00008705", "0", "1"]], "bids": [["88533.9", "0.25172427", "0", "9"], ["88533.8", "0.033886", "0", "1"], ["88533.4", "0.11314941", "0", "3"], ["88533.2", "0.08251722", "0", "4"], ["88526.2", "0", "0", "0"], ["88522.1", "0", "0", "0"], ["88519.2", "0.12526095", "0", "1"], ["88518.5", "0.22587877", "0", "1"], ["88517.6", "0", "0", "0"], ["88514.8", "0", "0", "0"], ["88281.1", "0.34078752", "0", "2"], ["88280.5", "0.00002567", "0", "1"], ["88279.9", "0.00001655", "0", "1"]], "ts": "1741338238405", "checksum": 969475012, "seqId": 48070590024, "prevSeqId": 48070589968}]}
{"arg": {"channel": "books", "instId": "BTC-USDT"}, "action": "update", "data": [{"asks": [["88534", "0", "0", "0"], ["88534.1", "0", "0", "0"], ["88534.4", "0", "0", "0"], ["88534.5", "0", "0", "0"], ["88534.8", "0", "0", "0"], ["88534.9", "0", "0", "0"], ["88535.2", "0", "0", "0"], ["88535.5", "0", "0", "0"], ["88535.8", "0", "0", "0"], ["88535.9", "0", "0", "0"], ["88536", "0", "0", "0"], ["88536.8", "0", "0", "0"], ["88537.1", "0.0028354", "0", "26"], ["88537.5", "0.00001176", "0", "1"], ["88538.5", "0", "0", "0"], ["88539.9", "0.00013598", "0", "2"], ["88540", "0.02213926", "0", "5"], ["88540.4", "0.0001", "0", "1"], ["88542", "0.0171", "0", "1"], ["88542.8", "0", "0", "0"], ["88542.9", "0", "0", "0"], ["88544.5", "0.00111578", "0", "1"], ["88545.3", "0.0000465", "0", "1"], ["88545.9", "0.00007302", "0", "1"], ["88547.2", "0.000255", "0", "1"], ["88548.2", "0.02730405", "0", "2"], ["88548.3", "0.00048118", "0", "4"], ["88550.8", "0", "0", "0"], ["88551.4", "0.01353", "0", "1"], ["88552.2", "0.02533542", "0", "1"], ["88552.3", "0.08351128", "0", "1"], ["88554.5", "0", "0", "0"], ["88556.9", "0.13299299", "0", "1"], ["88557.7", "0", "0", "0"], ["88557.9", "0.012102", "0", "1"], ["88572.6", "0.13851864", "0", "2"], ["88575.3", "0.23644439", "0", "4"], ["88579", "0.06276168", "0", "6"], ["88580", "0.09", "0", "3"], ["88584", "0.11343045", "0", "1"], ["88584.8", "0.000615", "0", "3"], ["88585.6", "0.0003", "0", "1"], ["88590.7", "0.3284017", "0", "1"], ["88591.8", "0", "0", "0"], ["88593.7", "0.00345254", "0", "2"], ["88595", "0.61438896", "0", "3"], ["88598", "0.00002736", "0", "1"], ["88616", "0.54776488", "0", "2"], ["88619.9", "0.00001", "0", "1"], ["88622.1", "0.00183739", "0", "1"], ["88624.5", "0.00006409", "0", "1"], ["88624.6", "0.00901032", "0", "1"], ["88624.9", "0.03705738", "0", "4"], ["88625", "0.046948", "0", "14"], ["88625.1", "0.0003639", "0", "1"], ["88625.6", "0.00570108", "0", "1"], ["88625.7", "0.03386796", "0", "1"]], "bids": [["88536.3", "0.59834603", "0", "13"], ["88536.2", "0.0002", "0", "2"], ["88536", "0.14338293", "0", "3"], ["88535.9", "0.0236731", "0", "3"], ["88534.5", "0.0219174", "0", "1"], ["88534.4", "0.12677102", "0", "5"], ["88534.1", "0.03032047", "0", "1"], ["88534", "0.0171", "0", "1"], ["88533.9", "0.05194673", "0", "2"], ["88533.8", "0", "0", "0"], ["88533.5", "0", "0", "0"], ["88533.4", "0", "0", "0"], ["88533.3", "0.00145491", "0", "1"], ["88533.2", "0.07309722", "0", "3"], ["88532.1", "0.02804638", "0", "1"], ["88531.2", "0.02828", "0", "1"], ["88530.8", "0.01357284", "0", "1"], ["88529.8", "0.0296817", "0", "1"], ["88528.2", "0", "0", "0"], ["88526.6", "0", "0", "0"], ["88526.1", "0.00001229", "0", "1"], ["88525.7", "0.08203902", "0", "1"], ["88524.1", "0", "0", "0"], ["88521.1", "0.14348415", "0", "1"], ["88520.9", "0.00006", "0", "1"], ["88519.9", "0.2258751", "0", "1"], ["88519.2", "0.06593998", "0", "1"], ["88518.5", "0", "0", "0"], ["88517.9", "0", "0", "0"], ["88516.4", "0", "0", "0"], ["88515.2", "0.00198343", "0", "1"], ["88514", "0", "0", "0"], ["88512.3", "0", "0", "0"], ["88512", "0", "0", "0"], ["88510.9", "0", "0", "0"], ["88508.2", "0.00343", "0", "1"], ["88505.6", "0.00059911", "0", "2"], ["88494", "0.06", "0", "2"], ["88493", "0.207", "0", "1"], ["88492", "0.0712", "0", "3"], ["88491", "0.03", "0", "1"], ["88490", "0", "0", "0"], ["88488.3", "0", "0", "0"], ["88487.1", "0.02260169", "0", "1"], ["88476.4", "0.17391732", "0", "1"], ["88475.1", "1.05508573", "0", "2"], ["88472.7", "0.00102615", "0", "1"], ["88471.2", "0", "0", "0"], ["88470.9", "2.12624221", "0", "1"], ["88468.1", "0", "0", "0"], ["88465.2", "0.00098611", "0", "1"], ["88464", "0", "0", "0"], ["88461.3", "0.25011484", "0", "2"], ["88452.1", "0.005", "0", "1"], ["88446.6", "0", "0", "0"], ["88438.1", "0", "0", "0"], ["88433.9", "0.03955697", "0", "2"], ["88283", "0", "0", "0"], ["88281.2", "0", "0", "0"], ["88281.1", "0", "0", "0"], ["88280.5", "0", "0", "0"], ["88279.9", "0", "0", "0"]], "ts": "1741338238505", "checksum": 427847579, "seqId": 48070590591, "prevSeqId": 48070590024}]}
{"arg": {"channel": "books", "instId": "BTC-USDT"}, "action": "update", "data": [{"asks": [["88539.2", "0.0002", "0", "2"], ["88539.9", "0.0414249", "0", "2"], ["88540.4", "0", "0", "0"], ["88540.6", "0.11294037", "0", "1"], ["88546.1", "0.0263513", "0", "1"], ["88546.3", "0.02730168", "0", "2"], ["88546.5", "0.05267221", "0", "3"], ["88548.2", "0.00002329", "0", "1"], ["88549.8", "0.08875696", "0", "1"], ["88550.3", "0.14706635", "0", "2"], ["88550.4", "0.07875467", "0", "1"], ["88550.5", "0.07953676", "0", "1"], ["88550.6", "0.08542275", "0", "1"], ["88552.2", "0", "0", "0"], ["88552.3", "0", "0", "0"], ["88553.5", "0.13785795", "0", "1"], ["88554", "0.14508061", "0", "2"], ["88555.1", "0.13653112", "0", "2"], ["88556", "0.16875149", "0", "3"], ["88556.6", "0.14725844", "0", "1"], ["88556.9", "0", "0", "0"], ["88557.7", "0.012102", "0", "1"], ["88557.9", "0", "0", "0"], ["88572.6", "0.13851859", "0", "2"], ["88575.3", "0.23644422", "0", "4"], ["88593.7", "0.00006257", "0", "1"], ["88600.4", "0.1", "0", "1"], ["88624.5", "0", "0", "0"], ["88624.6", "0", "0", "0"], ["88624.9", "0", "0", "0"], ["88625", "0", "0", "0"], ["88625.1", "0", "0", "0"], ["88625.6", "0", "0", "0"], ["88625.7", "0", "0", "0"]], "bids": [["88536.3", "0.59806603", "0", "14"], ["88536.2", "0", "0", "0"], ["88536", "0.09423066", "0", "2"], ["88535.9", "0.01676164", "0", "2"], ["88535.8", "0.0001", "0", "1"], ["88535.7", "0.0001", "0", "1"], ["88534.1", "0", "0", "0"], ["88533.9", "0", "0", "0"], ["88532.1", "0.06289412", "0", "1"], ["88531.7", "0.01357284", "0", "1"], ["88530.8", "0", "0", "0"], ["88529.8", "0", "0", "0"], ["88528.9", "0.02955928", "0", "2"], ["88528.8", "0.02634431", "0", "1"], ["88528.4", "0.02782689", "0", "1"], ["88528", "0.57578401", "0", "5"], ["88525.7", "0", "0", "0"], ["88525.1", "0.08629057", "0", "1"], ["88524.9", "0.11762203", "0", "2"], ["88524.6", "0.0000375", "0", "1"], ["88524.3", "0.08962141", "0", "1"], ["88523.9", "0.08047243", "0", "1"], ["88523.6", "0.39005123", "0", "2"], ["88521.9", "0.12185877", "0", "1"], ["88521.1", "0", "0", "0"], ["88521", "0.13836658", "0", "1"], ["88519.9", "0.22587493", "0", "1"], ["88519.4", "0.13426376", "0", "1"], ["88519.2", "0.09804486", "0", "2"], ["88518.1", "0.14776625", "0", "2"], ["88507.2", "0.0006", "0", "2"], ["88506.4", "0.00029911", "0", "1"], ["88505.6", "0", "0", "0"], ["88504.8", "0", "0", "0"], ["88491.7", "0.02075056", "0", "1"], ["88489.1", "0.1", "0", "1"], ["88476", "0", "0", "0"], ["88461.3", "0.2679261", "0", "3"], ["88456.2", "0", "0", "0"], ["88412.2", "0.00211815", "0", "1"], ["88409.6", "0", "0", "0"], ["88287", "0", "0", "0"], ["88286.3", "0", "0", "0"], ["88284.9", "0", "0", "0"], ["88283.5", "0", "0", "0"], ["88283.3", "0", "0", "0"]], "ts": "1741338238605", "checksum": 509922245, "seqId": 48070590760, "prevSeqId": 48070590591}]}
{"arg": {"channel": "books", "instId": "BTC-USDT"}, "action": "update", "data": [{"asks": [["88539", "0.0002", "0", "2"], ["88539.2", "0", "0", "0"], ["88557.7", "0", "0", "0"], ["88558.9", "0.012102", "0", "1"], ["88563.5", "0", "0", "0"], ["88567.3", "0.04", "0", "1"], ["88572.6", "0.07845078", "0", "1"], ["88575.3", "0.01056929", "0", "3"], ["88577.2", "0.22587206", "0", "1"], ["88604", "0.00001042", "0", "1"], ["88606.8", "0.01739179", "0", "1"], ["88614.5", "0", "0", "0"], ["88624.4", "0", "0", "0"]], "bids": [["88536.3", "0.61163887", "0", "15"], ["88535.8", "0.0002", "0", "2"], ["88535.7", "0", "0", "0"], ["88531.7", "0", "0", "0"], ["88521.1", "0.22587206", "0", "1"], ["88519.9", "0", "0", "0"], ["88516.6", "0.00509041", "0", "2"], ["88514.1", "0", "0", "0"], ["88494.5", "0.0001", "0", "1"], ["88492", "0.06", "0", "2"], ["88489.5", "0.1", "0", "1"], ["88489.1", "0", "0", "0"], ["88483.8", "0.01739179", "0", "1"], ["88480.7", "0", "0", "0"], ["88456.5", "0.00001138", "0", "1"], ["88406.8", "0.17391793", "0", "1"], ["88405.5", "0.00001139", "0", "1"], ["88384", "0.00137301", "0", "1"]], "ts": "1741338238705", "checksum": -719357266, "seqId": 48070590827, "prevSeqId": 48070590760}]}
{"arg": {"channel": "books", "instId": "BTC-USDT"}, "action": "update", "data": [{"asks": [["88539", "0.0001", "0", "1"], ["88539.4", "0.0001", "0", "1"], ["88556", "0.04060349", "0", "2"], ["88557.9", "0.012102", "0", "1"], ["88558.9", "0", "0", "0"], ["88590", "0.20001453", "0", "2"], ["88603.6", "0.01739201", "0", "1"], ["88606.8", "0", "0", "0"], ["88624.2", "0", "0", "0"]], "bids": [["88527.2", "0.05647397", "0", "1"], ["88483.8", "0", "0", "0"], ["88480.7", "0.01739201", "0", "1"], ["88460.9", "0.00019395", "0", "1"], ["88406.8", "0", "0", "0"], ["88405.5", "0.17393158", "0", "2"], ["88287.1", "0", "0", "0"]], "ts": "1741338238805", "checksum": -339051106, "seqId": 48070590859, "prevSeqId": 48070590827}]}
{"arg": {"channel": "books", "instId": "BTC-USDT"}, "action": "update", "data": [{"asks": [["88536.4", "0.04079692", "0", "3"], ["88538.8", "0.0001", "0", "1"], ["88539", "0", "0", "0"], ["88541.9", "0.01912254", "0", "1"], ["88545.5", "0.02958654", "0", "2"], ["88545.7", "0.02708914", "0", "1"], ["88545.8", "0.1846949", "0", "2"], ["88545.9", "0.02785283", "0", "2"], ["88546", "0.02729337", "0", "4"], ["88546.1", "0", "0", "0"], ["88546.3", "0.00013676", "0", "1"], ["88546.5", "0.00001", "0", "1"], ["88549.2", "0.08926416", "0", "1"], ["88549.8", "0.16130196", "0", "2"], ["88550.1", "0.10265609", "0", "2"], ["88550.2", "0.08715601", "0", "1"], ["88550.3", "0", "0", "0"], ["88550.4", "0", "0", "0"], ["88550.5", "0", "0", "0"], ["88550.6", "0", "0", "0"], ["88552.9", "0.12556622", "0", "1"], ["88553.4", "0.14344979", "0", "1"], ["88553.5", "0", "0", "0"], ["88554", "0.000035", "0", "1"], ["88554.7", "0.14811804", "0", "1"], ["88555.1", "0.00001032", "0", "1"], ["88556", "0.18016719", "0", "3"], ["88556.6", "0", "0", "0"], ["88557.7", "0.012102", "0", "1"], ["88557.9", "0", "0", "0"], ["88572.6", "0.13851889", "0", "2"], ["88575.3", "0.23644522", "0", "4"], ["88577.2", "0", "0", "0"], ["88619.4", "0", "0", "0"], ["88624.2", "0.00005126", "0", "4"]], "bids": [["88535.8", "0.0001", "0", "1"], ["88535.7", "0.0001", "0", "1"], ["88534.4", "0.1129481", "0", "1"], ["88533.3", "0", "0", "0"], ["88532.1", "0.0360939", "0", "1"], ["88528.9", "0.00224255", "0", "1"], ["88528.8", "0", "0", "0"], ["88528.4", "0", "0", "0"], ["88528.3", "0.02711879", "0", "2"], ["88528.2", "0.02711492", "0", "1"], ["88528", "0.54895269", "0", "4"], ["88527.8", "0.03003282", "0", "1"], ["88527.6", "0.02814333", "0", "1"], ["88525.1", "0", "0", "0"], ["88524.9", "0.04", "0", "1"], ["88524.5", "0.07936362", "0", "1"], ["88524.3", "0.08279959", "0", "1"], ["88523.9", "0", "0", "0"], ["88523.7", "0.99231719", "0", "2"], ["88523.6", "0.33228874", "0", "2"], ["88523.5", "0.42289219", "0", "2"], ["88521.9", "0", "0", "0"], ["88521.2", "0.1388389", "0", "1"], ["88521.1", "0", "0", "0"], ["88521", "0", "0", "0"], ["88520.4", "0.47916862", "0", "2"], ["88519.4", "0", "0", "0"], ["88519.2", "0.16315021", "0", "1"], ["88518.9", "0.13455864", "0", "1"], ["88518.1", "0.00942", "0", "1"], ["88517.5", "0.13511655", "0", "1"], ["88514.8", "0.24238511", "0", "2"], ["88513.8", "0", "0", "0"]], "ts": "1741338238905", "checksum": -799415201, "seqId": 48070590957, "prevSeqId": 48070590859}]}
{"arg": {"channel": "books", "instId": "BTC-USDT"}, "action": "update", "data": [{"asks": [["88536.4", "0.13579692", "0", "6"], ["88538.4", "0.00538414", "0", "6"], ["88539.4", "0", "0", "0"], ["88541.9", "0", "0", "0"], ["88544.6", "0.02927881", "0", "3"], ["88544.7", "0.0289189", "0", "1"], ["88544.9", "0.02838387", "0", "1"], ["88545.1", "0.03872852", "0", "3"], ["88545.5", "0.00001035", "0", "1"], ["88545.7", "0", "0", "0"], ["88545.8", "0.13248794", "0", "1"], ["88545.9", "0.00007302", "0", "1"], ["88546", "0.00011484", "0", "3"], ["88548.4", "0.08493721", "0", "3"], ["88549", "0.08321734", "0", "3"], ["88549.2", "0.0867494", "0", "1"], ["88549.8", "0", "0", "0"], ["88550.1", "0", "0", "0"], ["88550.2", "0", "0", "0"], ["88552.5", "0.1436988", "0", "1"], ["88552.9", "0", "0", "0"], ["88553.4", "0", "0", "0"], ["88553.7", "0.1436988", "0", "1"], ["88554.7", "0", "0", "0"], ["88555.2", "0.14261477", "0", "3"], ["88555.8", "0.012102", "0", "1"], ["88556", "0.04060349", "0", "2"], ["88557.7", "0", "0", "0"], ["88561.7", "0.128148", "0", "1"], ["88569.6", "0.22588694", "0", "1"], ["88572.6", "0.07845078", "0", "1"], ["88575.3", "0.01056929", "0", "3"], ["88585.2", "0.07169795", "0", "1"], ["88589", "0.00001077", "0", "1"], ["88589.1", "0", "0", "0"], ["88623", "0", "0", "0"], ["88624.4", "0.00008705", "0", "1"], ["88624.5", "0.00006409", "0", "1"], ["88624.6", "0.00901032", "0", "1"], ["88624.9", "0.00025948", "0", "3"]], "bids": [["88536.3", "0.53573887", "0", "14"], ["88535.8", "0", "0", "0"], ["88535.7", "0", "0", "0"], ["88534.6", "0.0001", "0", "1"], ["88534.5", "0", "0", "0"], ["88528.3", "0", "0", "0"], ["88528.2", "0.00145491", "0", "1"], ["88527.8", "0", "0", "0"], ["88527.6", "0", "0", "0"], ["88527.4", "0.02872956", "0", "1"], ["88527", "0.02745782", "0", "1"], ["88526.6", "0.0260834", "0", "1"], ["88524.5", "0", "0", "0"], ["88524.3", "0", "0", "0"], ["88523.7", "0.98750949", "0", "2"], ["88523.5", "0.33889", "0", "1"], ["88522.9", "0.08179166", "0", "1"], ["88522.5", "0.08144607", "0", "1"], ["88521.4", "0.00849429", "0", "2"], ["88521.2", "0", "0", "0"], ["88520.4", "0.33929724", "0", "1"], ["88519.5", "0.13366332", "0", "1"], ["88519.2", "0.07109036", "0", "1"], ["88518.9", "0", "0", "0"], ["88518", "0.1526124", "0", "2"], ["88517.5", "0", "0", "0"], ["88516.7", "0.13535153", "0", "1"], ["88514.8", "0.01650401", "0", "1"], ["88511.6", "0.22588968", "0", "1"], ["88510.4", "0.03975045", "0", "1"], ["88510.3", "0", "0", "0"], ["88483.6", "0.33652607", "0", "1"], ["88480.6", "0.207", "0", "1"], ["88456.5", "0.51451069", "0", "2"], ["88452.1", "0.97308434", "0", "2"], ["88435.9", "0.24487483", "0", "2"], ["88287.1", "0.03", "0", "1"], ["88287", "0.03", "0", "1"], ["88286.3", "0.03", "0", "1"]], "ts": "1741338239005", "checksum": -710204422, "seqId": 48070591185, "prevSeqId": 48070590957}]}
{"arg": {"channel": "books", "instId": "BTC-USDT"}, "action": "update", "data": [{"asks": [["88536.4", "0.14605524", "0", "6"], ["88537.7", "0.1033438", "0", "1"], ["88537.8", "0.11294387", "0", "1"], ["88538.4", "0.00528414", "0", "5"], ["88538.9", "0.0001", "0", "1"], ["88539.8", "0.06064094", "0", "2"], ["88539.9", "0.00003598", "0", "1"], ["88540.6", "0", "0", "0"], ["88541", "0.06068501", "0", "5"], ["88541.8", "0.10498025", "0", "1"], ["88541.9", "0.06064094", "0", "2"], ["88543.1", "0.01995209", "0", "2"], ["88543.3", "0.06065099", "0", "3"], ["88544", "0.03057725", "0", "3"], ["88544.2", "0.02982196", "0", "1"], ["88544.3", "0.02775695", "0", "3"], ["88544.5", "0.06175672", "0", "3"], ["88544.6", "0.08865864", "0", "5"], ["88544.7", "0", "0", "0"], ["88544.9", "0", "0", "0"], ["88545.1", "0.01130454", "0", "2"], ["88545.8", "0", "0", "0"], ["88546.2", "0.00225374", "0", "1"], ["88546.9", "0.01888533", "0", "1"], ["88547.2", "0", "0", "0"], ["88547.7", "0.09171317", "0", "2"], ["88548", "0.01371353", "0", "2"], ["88548.1", "0.57423224", "0", "2"], ["88548.2", "0.02022883", "0", "2"], ["88548.3", "1.06102592", "0", "7"], ["88548.4", "0.00002745", "0", "2"], ["88548.8", "0.07906254", "0", "2"], ["88549", "0.00006618", "0", "2"], ["88549.2", "0", "0", "0"], ["88549.6", "0.04060501", "0", "2"], ["88550.9", "0.11372454", "0", "2"], ["88551.3", "0.12337816", "0", "2"], ["88551.4", "0", "0", "0"], ["88551.8", "0.13691001", "0", "2"], ["88552", "0.01311598", "0", "4"], ["88552.5", "0", "0", "0"], ["88553.3", "0.13513014", "0", "1"], ["88553.7", "0", "0", "0"], ["88554.4", "0.28773947", "0", "2"], ["88554.5", "0.1427917", "0", "1"], ["88555.2", "0.00006893", "0", "2"], ["88555.8", "0", "0", "0"], ["88555.9", "0", "0", "0"], ["88556", "0.00001349", "0", "1"], ["88557.3", "0.04", "0", "1"], ["88558.4", "0.000015", "0", "1"], ["88559.2", "0", "0", "0"], ["88563.5", "0.03714877", "0", "1"], ["88566.6", "0.00368388", "0", "9"], ["88567.1", "0", "0", "0"], ["88569.6", "0", "0", "0"], ["88570.3", "0.01313223", "0", "3"], ["88572.6", "0.1274158", "0", "2"], ["88575.3", "0.2364511", "0", "4"], ["88575.4", "0", "0", "0"], ["88589.9", "0.23931247", "0", "1"], ["88590.7", "0", "0", "0"], ["88593.6", "0.000015", "0", "1"], ["88595", "0.43506066", "0", "3"], ["88596.8", "0.00002128", "0", "1"], ["88613.6", "0", "0", "0"], ["88625", "0.09212718", "0", "15"], ["88625.1", "0.0003639", "0", "1"]], "bids": [["88536.3", "0.22233911", "0", "6"], ["88536", "0.0171", "0", "1"], ["88535.9", "0", "0", "0"], ["88534.6", "0", "0", "0"], ["88534.4", "0", "0", "0"], ["88533.2", "0", "0", "0"], ["88532.9", "0.0001", "0", "1"], ["88532.8", "0.0001", "0", "1"], ["88532.1", "0", "0", "0"], ["88531.2", "0", "0", "0"], ["88530.3", "0.01357284", "0", "1"], ["88528.7", "0.00734158", "0", "1"], ["88528.2", "0.06209585", "0", "3"], ["88528", "0.10143956", "0", "3"], ["88527.4", "0", "0", "0"], ["88527.1", "0", "0", "0"], ["88527", "0", "0", "0"], ["88526.7", "0.05506709", "0", "2"], ["88526.6", "0", "0", "0"], ["88526.3", "0.02842867", "0", "1"], ["88526.2", "0.02916489", "0", "1"], ["88525.4", "0", "0", "0"], ["88524.9", "0", "0", "0"], ["88524.6", "0", "0", "0"], ["88523.7", "0", "0", "0"], ["88523.6", "0.33813631", "0", "2"], ["88523.5", "0", "0", "0"], ["88523", "0.08430455", "0", "1"], ["88522.9", "0", "0", "0"], ["88522.7", "0.08275368", "0", "1"], ["88522.5", "0", "0", "0"], ["88522.2", "0.0880505", "0", "1"], ["88522.1", "0.08193933", "0", "1"], ["88522", "0.04328183", "0", "2"], ["88521.4", "0", "0", "0"], ["88521.1", "0.02671259", "0", "1"], ["88520.8", "0.04", "0", "1"], ["88520.6", "0.33929724", "0", "1"], ["88520.5", "0.22588181", "0", "1"], ["88520.4", "0", "0", "0"], ["88519.7", "0.13926983", "0", "1"], ["88519.5", "0", "0", "0"], ["88519.2", "0.19467928", "0", "2"], ["88518.8", "0.1418678", "0", "2"], ["88518.5", "0.0194028", "0", "1"], ["88518", "0.0155", "0", "1"], ["88517.6", "0.13194674", "0", "1"], ["88516.7", "0", "0", "0"], ["88516.1", "0.01853488", "0", "1"], ["88516", "0.15988783", "0", "2"], ["88514.8", "0", "0", "0"], ["88513.8", "0.01650401", "0", "1"], ["88511.6", "0", "0", "0"], ["88511.5", "0.45227454", "0", "2"], ["88508.7", "0.02020488", "0", "1"], ["88504", "0.00001501", "0", "1"], ["88502.3", "0", "0", "0"], ["88490.4", "0.00001138", "0", "1"], ["88483.6", "0.24458586", "0", "1"], ["88482.9", "0", "0", "0"], ["88481.8", "0", "0", "0"], ["88479.9", "0", "0", "0"], ["88476.4", "0", "0", "0"], ["88476.3", "0", "0", "0"], ["88473.1", "0.0306639", "0", "1"], ["88461.3", "0.37637031", "0", "2"], ["88453", "0", "0", "0"], ["88447", "0.15920507", "0", "1"], ["88441.4", "0.10178917", "0", "1"], ["88435.9", "0.63071377", "0", "2"], ["88300.5", "0.033881", "0", "1"], ["88284.9", "0.08542891", "0", "1"], ["88283.5", "0.11343045", "0", "1"], ["88283.3", "0.00416498", "0", "2"], ["88283", "0.00001722", "0", "1"], ["88281.2", "0.00006263", "0", "1"]], "ts": "1741338239105", "checksum": -1615173216, "seqId": 48070591559, "prevSeqId": 48070591185}]}
{"arg": {"channel": "books", "instId": "BTC-USDT"}, "action": "update", "data": [{"asks": [["88536.4", "0.06462911", "0", "4"], ["88537.7", "0", "0", "0"], ["88538.8", "0", "0", "0"], ["88538.9", "0", "0", "0"], ["88540.2", "0.00017853", "0", "2"], ["88540.6", "0.0001", "0", "1"], ["88541", "0.00004407", "0", "3"], ["88541.8", "0.06470648", "0", "1"], ["88543.1", "0.00131779", "0", "1"], ["88544", "0.00084248", "0", "2"], ["88544.2", "0", "0", "0"], ["88544.3", "0.00012172", "0", "2"], ["88544.6", "0.00040015", "0", "2"], ["88544.7", "0.02653259", "0", "1"], ["88546.7", "0.001881", "0", "1"], ["88547.7", "0.00738035", "0", "1"], ["88548.1", "0.3912029", "0", "2"], ["88548.3", "0.90292781", "0", "5"], ["88548.4", "0.08184403", "0", "3"], ["88548.8", "0.00001", "0", "1"], ["88549.2", "0.08587609", "0", "1"], ["88549.6", "0.00001501", "0", "1"], ["88550.9", "0", "0", "0"], ["88551.3", "0.00001204", "0", "1"], ["88551.7", "0.0186343", "0", "1"], ["88551.8", "0.12475541", "0", "2"], ["88552", "0.00101398", "0", "3"], ["88552.3", "0.012102", "0", "1"], ["88553.3", "0", "0", "0"], ["88554.5", "0", "0", "0"], ["88572.4", "0.13723481", "0", "2"], ["88572.6", "0", "0", "0"], ["88575.3", "0.01056929", "0", "3"], ["88576.3", "0.22588258", "0", "1"], ["88583.9", "0.49791591", "0", "2"], ["88585.2", "0.21208021", "0", "2"], ["88587.2", "0.49785498", "0", "2"], ["88589.9", "0.17931247", "0", "1"], ["88590", "0.00001453", "0", "1"], ["88593.5", "1.6700623", "0", "1"], ["88601.2", "0.03014281", "0", "1"], ["88625.1", "0", "0", "0"]], "bids": [["88536.3", "0.23591195", "0", "7"], ["88535.7", "0.0001", "0", "1"], ["88535.6", "0.0001", "0", "1"], ["88532.9", "0", "0", "0"], ["88532.8", "0", "0", "0"], ["88530.3", "0", "0", "0"], ["88529.1", "0.00145491", "0", "1"], ["88529", "0.03306752", "0", "1"], ["88528.9", "0.06288349", "0", "3"], ["88528.2", "0", "0", "0"], ["88528", "0.0999324", "0", "4"], ["88526.7", "0", "0", "0"], ["88526.3", "0", "0", "0"], ["88526.2", "0", "0", "0"], ["88523.6", "0.3361795", "0", "2"], ["88523", "0", "0", "0"], ["88522.7", "0", "0", "0"], ["88522.2", "0", "0", "0"], ["88522.1", "0", "0", "0"], ["88520.7", "0.22588258", "0", "1"], ["88520.5", "0", "0", "0"], ["88519.7", "0", "0", "0"], ["88519.5", "0.14005621", "0", "1"], ["88519.2", "0.14821477", "0", "2"], ["88518.8", "0.00001138", "0", "1"], ["88518", "0.15158627", "0", "2"], ["88517.6", "0", "0", "0"], ["88516", "0.0155", "0", "1"], ["88513.3", "0.0000315", "0", "1"], ["88512.6", "1.67086511", "0", "1"], ["88496.9", "0.50019168", "0", "2"], ["88494.8", "0.498334", "0", "1"], ["88483.6", "0.36353562", "0", "2"], ["88481.4", "0.49841", "0", "1"], ["88478.7", "2.99211906", "0", "1"], ["88443.1", "0.2452534", "0", "3"], ["88443", "0.761099", "0", "2"], ["88441.4", "0", "0", "0"], ["88435.9", "0.005", "0", "1"], ["88424.4", "0.10630851", "0", "2"], ["88281.1", "0.34078752", "0", "2"], ["88280.5", "0.00002567", "0", "1"], ["88279.9", "0.00001655", "0", "1"], ["88276.1", "0.00007", "0", "1"]], "ts": "1741338239205", "checksum": 2128521946, "seqId": 48070591816, "prevSeqId": 48070591559}]}
{"arg": {"channel": "books", "instId": "BTC-USDT"}, "action": "update", "data": [{"asks": [["88537.7", "0.06695924", "0", "1"], ["88539.6", "0.00051761", "0", "4"], ["88540.2", "0.00007853", "0", "1"], ["88540.6", "0", "0", "0"], ["88541.8", "0.08941291", "0", "2"], ["88544.5", "0.08889515", "0", "4"], ["88544.6", "0.03032257", "0", "3"], ["88544.7", "0", "0", "0"], ["88544.8", "0.0267654", "0", "2"], ["88545.1", "0.04042987", "0", "3"], ["88548.2", "0.10001981", "0", "3"], ["88548.4", "0.00002745", "0", "2"], ["88548.8", "0.16778679", "0", "3"], ["88551.7", "0.143555", "0", "2"], ["88551.8", "0.13068576", "0", "2"], ["88551.9", "0.012102", "0", "1"], ["88552.3", "0.13627066", "0", "1"], ["88553.8", "0.1341854", "0", "1"], ["88555", "0.4871239", "0", "7"], ["88589.9", "0.6579171", "0", "2"], ["88599.6", "0.01739243", "0", "1"], ["88603.6", "0", "0", "0"], ["88625", "0", "0", "0"]], "bids": [["88536.1", "0.013146", "0", "1"], ["88535.6", "0", "0", "0"], ["88533.8", "0.0001", "0", "1"], ["88533.6", "0.00942", "0", "1"], ["88528", "0.10838193", "0", "4"], ["88527.2", "0.08181284", "0", "2"], ["88527.1", "0.02811019", "0", "1"], ["88527", "0.02828", "0", "1"], ["88526.8", "0.02725672", "0", "1"], ["88526.7", "0.02778607", "0", "1"], ["88523.6", "0.37245738", "0", "2"], ["88523.4", "0.07939898", "0", "1"], ["88523.2", "0.07420909", "0", "1"], ["88522.6", "0.08194409", "0", "1"], ["88522.5", "0.08562175", "0", "1"], ["88520.2", "0.1319535", "0", "1"], ["88519.5", "0", "0", "0"], ["88519.3", "0.13759328", "0", "1"], ["88516.5", "0.13225254", "0", "1"], ["88514.7", "0.94577629", "0", "1"], ["88495.1", "0.56007782", "0", "2"], ["88480.7", "0", "0", "0"], ["88478.8", "0.90272634", "0", "1"], ["88475.2", "0.01739243", "0", "1"], ["88452.1", "0.005", "0", "1"], ["88443.1", "0.16888055", "0", "2"], ["88424.4", "0.00451934", "0", "1"], ["88405.5", "0.00001139", "0", "1"], ["88401.7", "0.17392434", "0", "1"], ["88290", "0", "0", "0"], ["88289.4", "0", "0", "0"], ["88287.1", "0", "0", "0"], ["88287", "0", "0", "0"], ["88286.3", "0", "0", "0"], ["88284.9", "0", "0", "0"], ["88283.5", "0", "0", "0"], ["88283.3", "0", "0", "0"], ["88283", "0", "0", "0"], ["88281.2", "0", "0", "0"], ["88281.1", "0", "0", "0"], ["88280.5", "0", "0", "0"], ["88279.9", "0", "0", "0"], ["88276.1", "0", "0", "0"]], "ts": "1741338239305", "checksum": 2130706590, "seqId": 48070591944, "prevSeqId": 48070591816}]}
{"arg": {"channel": "books", "instId": "BTC-USDT"}, "action": "update", "data": [{"asks": [["88536.4", "0", "0", "0"], ["88537.7", "0", "0", "0"], ["88537.8", "0", "0", "0"], ["88539.6", "0.00031761", "0", "2"], ["88539.8", "0.0002", "0", "2"], ["88541.9", "0", "0", "0"], ["88543.3", "0.00001005", "0", "1"], ["88546.9", "0", "0", "0"], ["88548.2", "0.07981427", "0", "2"], ["88548.3", "0.00048118", "0", "4"], ["88551.5", "0.012102", "0", "1"], ["88551.9", "0", "0", "0"], ["88557.3", "0", "0", "0"], ["88558.2", "0.02619726", "0", "3"], ["88563.5", "0", "0", "0"], ["88566.1", "0.04", "0", "1"], ["88583.9", "0.00008291", "0", "1"], ["88587.2", "0.00003998", "0", "1"], ["88625", "0.09212718", "0", "15"], ["88625.1", "0.0003639", "0", "1"], ["88625.6", "0.00570108", "0", "1"], ["88625.9", "0.11344277", "0", "2"], ["88626", "0.00570108", "0", "1"], ["88626.1", "0.03", "0", "1"]], "bids": [["88536.6", "0.0354", "0", "2"], ["88536.3", "0.29886595", "0", "9"], ["88535.7", "0", "0", "0"], ["88534.1", "0.0220717", "0", "1"], ["88533.8", "0", "0", "0"], ["88533.1", "0.0002", "0", "2"], ["88532.3", "0.11303311", "0", "4"], ["88530.1", "0.09096141", "0", "3"], ["88523.7", "0.90244663", "0", "1"], ["88512.6", "1.75629402", "0", "2"], ["88508.7", "0", "0", "0"], ["88497.9", "0", "0", "0"], ["88497.4", "0.11343045", "0", "1"], ["88494.8", "0", "0", "0"], ["88469.6", "0.00343", "0", "1"], ["88300.5", "0", "0", "0"], ["88292", "0", "0", "0"], ["88291", "0", "0", "0"]], "ts": "1741338239405", "checksum": -1646814778, "seqId": 48070592035, "prevSeqId": 48070591944}]}
{"arg": {"channel": "books", "instId": "BTC-USDT"}, "action": "update", "data": [{"asks": [["88536.7", "0", "0", "0"], ["88537", "0", "0", "0"], ["88537.1", "0", "0", "0"], ["88537.2", "0", "0", "0"], ["88537.3", "0", "0", "0"], ["88537.5", "0", "0", "0"], ["88537.9", "0", "0", "0"], ["88538", "0.01636496", "0", "2"], ["88539.8", "0", "0", "0"], ["88539.9", "0.00013598", "0", "2"], ["88540.5", "0.11566835", "0", "5"], ["88540.7", "0.00002025", "0", "1"], ["88541.1", "0.0001", "0", "1"], ["88541.8", "0", "0", "0"], ["88544.5", "0.00111578", "0", "1"], ["88544.6", "0.00040015", "0", "2"], ["88544.8", "0.00001536", "0", "1"], ["88545.1", "0.01130454", "0", "2"], ["88545.3", "0", "0", "0"], ["88546.2", "0", "0", "0"], ["88546.7", "0", "0", "0"], ["88546.8", "0.00023614", "0", "2"], ["88546.9", "0.00112749", "0", "1"], ["88548", "0.00018353", "0", "1"], ["88548.1", "0.1025573", "0", "2"], ["88548.2", "0.00002329", "0", "1"], ["88548.8", "0.00001", "0", "1"], ["88549.2", "0", "0", "0"], ["88550.4", "0.14542335", "0", "2"], ["88551.5", "0", "0", "0"], ["88551.7", "0.0186343", "0", "1"], ["88551.8", "0.00001097", "0", "1"], ["88552.3", "0", "0", "0"], ["88552.4", "0.0016995", "0", "1"], ["88552.9", "0.01353", "0", "1"], ["88553.8", "0", "0", "0"], ["88555", "0.2967477", "0", "5"], ["88558.5", "0.01888533", "0", "1"], ["88559.9", "0.04059", "0", "1"], ["88560.5", "0.012102", "0", "1"], ["88572.4", "0.06946916", "0", "2"], ["88576.3", "0", "0", "0"], ["88579", "0.00276168", "0", "4"], ["88580", "0.12", "0", "4"], ["88581", "0.03017534", "0", "3"], ["88585.1", "0.22585521", "0", "1"], ["88585.2", "0.07169795", "0", "1"], ["88593.5", "2.1678413", "0", "2"], ["88596.7", "0.49777116", "0", "2"], ["88600.4", "0", "0", "0"], ["88600.7", "0.1", "0", "1"], ["88601.2", "0", "0", "0"], ["88606.9", "0.03294849", "0", "2"], ["88616", "0.00002123", "0", "1"], ["88622.1", "0", "0", "0"], ["88623.6", "0.00184841", "0", "2"], ["88626.2", "0.03", "0", "1"], ["88626.3", "0.36929724", "0", "2"], ["88626.4", "0.0399405", "0", "1"], ["88626.5", "0.01358534", "0", "2"], ["88626.6", "0.74641525", "0", "2"], ["88626.9", "0.00013978", "0", "2"], ["88627.4", "0.0406", "0", "2"], ["88627.5", "3.02981812", "0", "1"], ["88627.6", "0.06091043", "0", "4"]], "bids": [["88537.9", "0.17899072", "0", "8"], ["88537.8", "0.0001", "0", "1"], ["88537.2", "0.07479037", "0", "1"], ["88537.1", "0.01393661", "0", "1"], ["88537", "0.00685017", "0", "2"], ["88536.6", "0", "0", "0"], ["88536.4", "0.0001", "0", "1"], ["88536.3", "0.0532968", "0", "3"], ["88536.1", "0", "0", "0"], ["88534.6", "0.01357284", "0", "1"], ["88533.6", "0", "0", "0"], ["88533.1", "0", "0", "0"], ["88532.6", "0.00145491", "0", "1"], ["88532.5", "0.03243285", "0", "2"], ["88532.4", "0.2159628", "0", "2"], ["88532.3", "0", "0", "0"], ["88532", "0.04457", "0", "2"], ["88530.2", "0.22585521", "0", "1"], ["88530.1", "0.03033185", "0", "2"], ["88529.1", "0.03856924", "0", "2"], ["88529", "0", "0", "0"], ["88528.9", "0.03032047", "0", "1"], ["88528", "0.34648886", "0", "3"], ["88527.2", "0.05647397", "0", "1"], ["88527.1", "0", "0", "0"], ["88527", "0", "0", "0"], ["88526.8", "0", "0", "0"], ["88526.7", "0", "0", "0"], ["88526.1", "0", "0", "0"], ["88523.6", "0.2624091", "0", "2"], ["88523.4", "0", "0", "0"], ["88523.2", "0", "0", "0"], ["88522.6", "0", "0", "0"], ["88522.5", "0", "0", "0"], ["88520.7", "0", "0", "0"], ["88520.4", "0.000591", "0", "1"], ["88520.2", "0", "0", "0"], ["88519.3", "0", "0", "0"], ["88519.2", "0.07752047", "0", "1"], ["88518.5", "0", "0", "0"], ["88518", "0.0155", "0", "1"], ["88516.5", "0", "0", "0"], ["88516.1", "0", "0", "0"], ["88514.8", "0.01650401", "0", "1"], ["88514", "0.1129741", "0", "1"], ["88513.8", "0", "0", "0"], ["88513.3", "0", "0", "0"], ["88503.7", "0.498284", "0", "1"], ["88497.3", "0", "0", "0"], ["88493", "0.267", "0", "3"], ["88492", "0.03", "0", "1"], ["88491", "0.00001", "0", "1"], ["88490.1", "0.49836", "0", "1"], ["88489.5", "0", "0", "0"], ["88483.6", "0.24458586", "0", "1"], ["88481.4", "0", "0", "0"], ["88478.6", "0.03573868", "0", "1"], ["88474.2", "0.00102615", "0", "1"], ["88473.1", "0", "0", "0"], ["88472.7", "0", "0", "0"], ["88468", "0", "0", "0"], ["88466.7", "0.00098611", "0", "1"], ["88465.2", "0", "0", "0"], ["88456.5", "0.10452539", "0", "3"], ["88368.8", "0.00001138", "0", "1"], ["88360.3", "0", "0", "0"], ["88325", "0.00001177", "0", "1"], ["88298.5", "0.00002094", "0", "1"], ["88292", "0.0025", "0", "1"], ["88291", "0.005", "0", "2"], ["88290", "0.00001172", "0", "1"], ["88289.4", "0.03", "0", "1"], ["88287.1", "0.03", "0", "1"], ["88287", "0.03", "0", "1"], ["88286.3", "0.03", "0", "1"], ["88284.9", "0.08542891", "0", "1"], ["88283.5", "0.11343045", "0", "1"]], "ts": "1741338239505", "checksum": 488655087, "seqId": 48070592686, "prevSeqId": 48070592035}]}
{"arg": {"channel": "books", "instId": "BTC-USDT"}, "action": "update", "data": [{"asks": [["88539.9", "0.00003598", "0", "1"], ["88541.1", "0", "0", "0"], ["88541.5", "0.00011152", "0", "2"], ["88541.6", "0.0005477", "0", "3"], ["88547.6", "0.05614397", "0", "3"], ["88547.7", "0.03722556", "0", "2"], ["88547.9", "0.02771934", "0", "1"], ["88550.4", "0", "0", "0"], ["88551.2", "0.08532038", "0", "1"], ["88551.3", "0.08833524", "0", "2"], ["88551.7", "0.09951371", "0", "2"], ["88551.9", "0.15860738", "0", "2"], ["88552.1", "0.00201618", "0", "2"], ["88552.4", "0", "0", "0"], ["88554.4", "0.43154546", "0", "3"], ["88554.9", "0.12616274", "0", "1"], ["88555.4", "0.14728169", "0", "2"], ["88556.3", "0.14065811", "0", "1"], ["88558", "0.35504218", "0", "5"], ["88560.3", "0.012102", "0", "1"], ["88560.5", "0", "0", "0"], ["88573.6", "0.03575724", "0", "1"], ["88580.9", "0.22586541", "0", "1"], ["88585.1", "0", "0", "0"], ["88589.9", "0.9139269", "0", "1"], ["88592.4", "0.55500558", "0", "1"], ["88599.6", "0", "0", "0"], ["88600.7", "0", "0", "0"], ["88605.9", "0.0173914", "0", "1"], ["88626.9", "0", "0", "0"], ["88627.4", "0", "0", "0"], ["88627.5", "0", "0", "0"], ["88627.6", "0", "0", "0"]], "bids": [["88537.9", "0.19246256", "0", "9"], ["88537.8", "0", "0", "0"], ["88537.7", "0.0001", "0", "1"], ["88537.5", "0.0001", "0", "1"], ["88536.4", "0", "0", "0"], ["88536.3", "0.0532868", "0", "2"], ["88534.6", "0", "0", "0"], ["88532.8", "0.00145491", "0", "1"], ["88532.7", "0.03243285", "0", "2"], ["88532.6", "0.00463264", "0", "2"], ["88530.3", "0.02507676", "0", "1"], ["88530.2", "0.02662939", "0", "1"], ["88529.9", "0.0285342", "0", "1"], ["88529.5", "0.01853488", "0", "1"], ["88529.2", "0.02759924", "0", "1"], ["88529.1", "0.00824877", "0", "1"], ["88528.2", "0.22586541", "0", "1"], ["88526.5", "0.08444324", "0", "1"], ["88526.3", "0.07969741", "0", "1"], ["88525.7", "0.08600731", "0", "1"], ["88525.1", "0.08834669", "0", "1"], ["88523.6", "0.30642219", "0", "2"], ["88523.3", "0.12382522", "0", "1"], ["88522.4", "0.13634615", "0", "1"], ["88520.5", "0.14650781", "0", "1"], ["88519.5", "0.14759146", "0", "1"], ["88502.7", "0.03701159", "0", "1"], ["88483.4", "0.0173914", "0", "1"], ["88475.2", "0", "0", "0"], ["88456.5", "0.23065501", "0", "2"], ["88414.3", "0.00211796", "0", "1"], ["88412.2", "0", "0", "0"], ["88406.8", "0.17391407", "0", "1"], ["88403.4", "0.00092559", "0", "1"], ["88401.7", "0", "0", "0"], ["88376.2", "0", "0", "0"], ["88294.7", "0", "0", "0"], ["88294.1", "0", "0", "0"], ["88294", "0", "0", "0"], ["88293.4", "0", "0", "0"], ["88292.4", "0", "0", "0"], ["88292.3", "0", "0", "0"], ["88292", "0", "0", "0"], ["88291", "0", "0", "0"], ["88290", "0", "0", "0"], ["88289.4", "0", "0", "0"], ["88287.1", "0", "0", "0"], ["88287", "0", "0", "0"], ["88286.3", "0", "0", "0"], ["88284.9", "0", "0", "0"], ["88283.5", "0", "0", "0"]], "ts": "1741338239605", "checksum": 501466976, "seqId": 48070592824, "prevSeqId": 48070592686}]}
{"arg": {"channel": "books", "instId": "BTC-USDT"}, "action": "update", "data": [{"asks": [["88538", "0.03868496", "0", "3"], ["88539.7", "0.0001", "0", "1"], ["88539.9", "0.00013598", "0", "2"], ["88540.7", "0", "0", "0"], ["88541.5", "0.00001152", "0", "1"], ["88541.6", "0.0004477", "0", "2"], ["88546.4", "0.02977054", "0", "8"], ["88546.6", "0.0271773", "0", "2"], ["88546.7", "0.02506189", "0", "1"], ["88546.8", "0.00019039", "0", "1"], ["88546.9", "0.02746019", "0", "2"], ["88547.6", "0.00131779", "0", "1"], ["88547.7", "0.00738035", "0", "1"], ["88547.9", "0", "0", "0"], ["88548.7", "0.35282724", "0", "2"], ["88550.1", "0.08414689", "0", "1"], ["88550.6", "0.15667553", "0", "2"], ["88550.7", "0.16920761", "0", "3"], ["88551", "0.08756251", "0", "3"], ["88551.2", "0", "0", "0"], ["88551.3", "0.00001204", "0", "1"], ["88551.7", "0.0186343", "0", "1"], ["88551.9", "0", "0", "0"], ["88552.9", "0", "0", "0"], ["88553.8", "0.13620239", "0", "1"], ["88554.2", "0.15006017", "0", "3"], ["88554.4", "0.28773947", "0", "2"], ["88554.9", "0", "0", "0"], ["88555.4", "0.04284374", "0", "2"], ["88555.6", "0.13559856", "0", "1"], ["88556.3", "0", "0", "0"], ["88556.9", "0.14008482", "0", "1"], ["88558", "0.20704957", "0", "4"], ["88559.9", "0.012102", "0", "1"], ["88560.3", "0", "0", "0"], ["88579.9", "0.22634001", "0", "3"], ["88580.9", "0", "0", "0"], ["88590", "0.20001453", "0", "2"], ["88602", "0.1", "0", "1"], ["88626.9", "0.00013978", "0", "2"]], "bids": [["88537.9", "0.18109947", "0", "8"], ["88537.7", "0", "0", "0"], ["88537.5", "0", "0", "0"], ["88537.2", "0.07499037", "0", "3"], ["88534.1", "0.03564454", "0", "2"], ["88534", "0.02652", "0", "2"], ["88532.4", "0.10787103", "0", "1"], ["88532", "0.0163", "0", "1"], ["88530.3", "0", "0", "0"], ["88530.2", "0", "0", "0"], ["88530.1", "0.00001138", "0", "1"], ["88529.9", "0", "0", "0"], ["88529.2", "0", "0", "0"], ["88529.1", "0.06226335", "0", "3"], ["88528.7", "0.03455908", "0", "2"], ["88528.5", "0.02659856", "0", "1"], ["88528.2", "0", "0", "0"], ["88527.4", "0.02828", "0", "1"], ["88526.5", "0", "0", "0"], ["88526.3", "0", "0", "0"], ["88525.7", "0", "0", "0"], ["88525.5", "0.22587071", "0", "1"], ["88525.4", "0.08726383", "0", "1"], ["88525.2", "0.07601282", "0", "1"], ["88525.1", "0", "0", "0"], ["88524.6", "0.08947629", "0", "1"], ["88524.3", "0.08194833", "0", "1"], ["88523.6", "0.32350086", "0", "2"], ["88523.3", "0", "0", "0"], ["88522.4", "0", "0", "0"], ["88522.1", "0.12689986", "0", "1"], ["88521.2", "0.14232582", "0", "1"], ["88520.5", "0", "0", "0"], ["88519.8", "0.2024205", "0", "2"], ["88519.5", "0", "0", "0"], ["88518.4", "0.25299355", "0", "4"], ["88491.1", "0.1", "0", "1"], ["88456.5", "0.25549337", "0", "3"], ["88435.9", "0.01070038", "0", "2"], ["88430", "0.00570038", "0", "1"], ["88294.7", "0.00001118", "0", "1"], ["88294.1", "0.00289318", "0", "3"], ["88294", "0.0025", "0", "1"], ["88293.4", "0.04093218", "0", "1"]], "ts": "1741338239705", "checksum": -336438968, "seqId": 48070592970, "prevSeqId": 48070592824}]}
{"arg": {"channel": "books", "instId": "BTC-USDT"}, "action": "update", "data": [{"asks": [["88538", "0.07928496", "0", "4"], ["88539.3", "0.0001", "0", "1"], ["88539.5", "0.0001", "0", "1"], ["88539.7", "0", "0", "0"], ["88539.9", "0.00003598", "0", "1"], ["88540.8", "0.000021", "0", "1"], ["88546.4", "0.02678297", "0", "8"], ["88546.5", "0.06024306", "0", "3"], ["88546.6", "0.0297408", "0", "2"], ["88546.7", "0.02738586", "0", "1"], ["88546.8", "0.00023539", "0", "2"], ["88546.9", "0.15525124", "0", "3"], ["88548.1", "0.00001011", "0", "1"], ["88548.7", "0.33929724", "0", "1"], ["88550", "0.17497854", "0", "11"], ["88550.1", "0.0891504", "0", "1"], ["88550.6", "0", "0", "0"], ["88550.7", "0.15817519", "0", "3"], ["88551", "0.08018139", "0", "3"], ["88553.8", "0.131569", "0", "1"], ["88554.2", "0.14004823", "0", "3"], ["88554.4", "0.39932963", "0", "3"], ["88555.6", "0.14725639", "0", "1"], ["88556.9", "0.14546472", "0", "1"], ["88559.7", "0.012102", "0", "1"], ["88559.9", "0", "0", "0"], ["88572.4", "0.13927666", "0", "3"], ["88576.3", "0.2258751", "0", "1"], ["88579.9", "0.0004693", "0", "2"], ["88626.6", "0", "0", "0"], ["88626.9", "0", "0", "0"]], "bids": [["88537.9", "0.18471749", "0", "9"], ["88537.3", "0.0001", "0", "1"], ["88537.2", "0.07479037", "0", "1"], ["88535.2", "0.0001", "0", "1"], ["88532.4", "0.0573093", "0", "1"], ["88529.1", "0.06118406", "0", "3"], ["88528.7", "0.03438907", "0", "2"], ["88528.5", "0.02800488", "0", "1"], ["88525.5", "0", "0", "0"], ["88525.4", "0.08051607", "0", "1"], ["88525.2", "0.07842488", "0", "1"], ["88524.6", "0.08421038", "0", "1"], ["88524.4", "0.07811181", "0", "2"], ["88524.3", "0", "0", "0"], ["88523.6", "0.32255466", "0", "2"], ["88522.1", "0.34814217", "0", "2"], ["88521.2", "0.14950078", "0", "1"], ["88519.8", "0.19672299", "0", "2"], ["88518.4", "0.25657085", "0", "4"], ["88456.5", "0.31768485", "0", "2"]], "ts": "1741338239805", "checksum": 1466376383, "seqId": 48070593168, "prevSeqId": 48070592970}]}
{"arg": {"channel": "books", "instId": "BTC-USDT"}, "action": "update", "data": [{"asks": [["88538", "0.03868496", "0", "3"], ["88538.3", "0.00041659", "0", "8"], ["88539.3", "0", "0", "0"], ["88539.5", "0", "0", "0"], ["88539.8", "0.0002", "0", "2"], ["88540.8", "0", "0", "0"], ["88546.4", "0.00026336", "0", "7"], ["88546.6", "0.00001512", "0", "1"], ["88546.7", "0", "0", "0"], ["88546.8", "0.00019039", "0", "1"], ["88546.9", "0.12847841", "0", "2"], ["88549.1", "0.01353", "0", "1"], ["88550", "0.15223058", "0", "11"], ["88550.1", "0", "0", "0"], ["88550.7", "0.00003658", "0", "1"], ["88551", "0.00003451", "0", "2"], ["88553.8", "0", "0", "0"], ["88554.2", "0.00070666", "0", "2"], ["88555.6", "0", "0", "0"], ["88556.9", "0", "0", "0"], ["88559.4", "0.01242873", "0", "2"], ["88559.7", "0", "0", "0"], ["88572.4", "0.06946916", "0", "2"], ["88576.3", "0", "0", "0"], ["88579.9", "0.2263392", "0", "3"], ["88626.6", "0.74641525", "0", "2"], ["88626.9", "0.00013978", "0", "2"], ["88627.4", "0.0406", "0", "2"], ["88627.5", "3.02981812", "0", "1"], ["88627.6", "0.06091043", "0", "4"], ["88627.8", "0.00001024", "0", "1"], ["88627.9", "0.00011112", "0", "1"], ["88628", "0.00011321", "0", "5"]], "bids": [["88537.9", "0.18305256", "0", "9"], ["88537.4", "0.0001", "0", "1"], ["88537.3", "0", "0", "0"], ["88536.5", "0.00942", "0", "1"], ["88535.2", "0", "0", "0"], ["88534.1", "0.0220717", "0", "1"], ["88534", "0.0171", "0", "1"], ["88529.1", "0.00824877", "0", "1"], ["88528.7", "0.00734158", "0", "1"], ["88528.5", "0", "0", "0"], ["88525.5", "0.2258699", "0", "1"], ["88525.4", "0", "0", "0"], ["88525.2", "0", "0", "0"], ["88524.6", "0", "0", "0"], ["88524.4", "0.00001138", "0", "1"], ["88523.6", "0.20790314", "0", "1"], ["88523", "0.0001", "0", "1"], ["88522.1", "0", "0", "0"], ["88521.2", "0", "0", "0"], ["88519.8", "0.05647723", "0", "1"], ["88518.4", "0.11295865", "0", "3"], ["88480.1", "0.00056509", "0", "1"], ["88439", "0.1", "0", "1"], ["88292.4", "0.00001139", "0", "1"], ["88292.3", "0.00002159", "0", "1"]], "ts": "1741338239905", "checksum": -220126149, "seqId": 48070593280, "prevSeqId": 48070593168}]}
{"arg": {"channel": "books", "instId": "BTC-USDT"}, "action": "update", "data": [{"asks": [["88539.8", "0.0001", "0", "1"], ["88539.9", "0.00096598", "0", "3"], ["88547.1", "0.02793004", "0", "1"], ["88547.2", "0.0563732", "0", "2"], ["88547.4", "0.02519209", "0", "1"], ["88550", "0.00109016", "0", "9"], ["88550.7", "0.14123827", "0", "3"], ["88550.8", "0.08476587", "0", "1"], ["88551.3", "0.08425878", "0", "2"], ["88551.4", "0.17117436", "0", "2"], ["88554.4", "0.53177412", "0", "4"], ["88554.9", "0.13078648", "0", "1"], ["88555.9", "0.12924417", "0", "1"], ["88557.5", "0.1428427", "0", "1"], ["88559.3", "0.012102", "0", "1"], ["88559.4", "0.00032673", "0", "1"], ["88572.4", "0.13927591", "0", "3"], ["88576.3", "0.22587261", "0", "1"], ["88579.9", "0.0004693", "0", "2"], ["88585.2", "0.36273571", "0", "2"], ["88587", "1", "0", "1"], ["88604", "0.01740229", "0", "2"], ["88605.9", "0", "0", "0"], ["88625", "0.046948", "0", "14"], ["88625.5", "0.03920011", "0", "1"], ["88626.3", "0", "0", "0"], ["88626.4", "0", "0", "0"], ["88626.5", "0", "0", "0"], ["88626.6", "0", "0", "0"], ["88626.9", "0", "0", "0"], ["88627.4", "0", "0", "0"], ["88627.5", "0", "0", "0"], ["88627.6", "0", "0", "0"], ["88627.8", "0", "0", "0"], ["88627.9", "0", "0", "0"], ["88628", "0", "0", "0"]], "bids": [["88537.4", "0", "0", "0"], ["88535.2", "0.0002", "0", "2"], ["88532.4", "0.17780485", "0", "2"], ["88529.8", "0.02763047", "0", "1"], ["88529.7", "0.02792902", "0", "1"], ["88529.4", "0.02827192", "0", "1"], ["88528.8", "0.36808027", "0", "2"], ["88526", "0.09661463", "0", "2"], ["88525.8", "0.07325372", "0", "1"], ["88525.5", "0", "0", "0"], ["88525.2", "0.09011408", "0", "1"], ["88524.7", "0.08410119", "0", "1"], ["88523.6", "0.31987275", "0", "2"], ["88523", "0", "0", "0"], ["88522.8", "0.12479112", "0", "1"], ["88522.1", "0.22587261", "0", "1"], ["88521.9", "0.13799387", "0", "1"], ["88520.1", "0.14029141", "0", "1"], ["88519", "0.14780635", "0", "1"], ["88483.4", "0", "0", "0"], ["88480.7", "0.01739187", "0", "1"], ["88443.1", "0.00564951", "0", "1"], ["88422", "0", "0", "0"], ["88406.8", "0", "0", "0"], ["88405.5", "0.17393018", "0", "2"], ["88296.3", "0", "0", "0"], ["88296.2", "0", "0", "0"], ["88294.7", "0", "0", "0"], ["88294.1", "0", "0", "0"], ["88294", "0", "0", "0"], ["88293.4", "0", "0", "0"], ["88292.4", "0", "0", "0"], ["88292.3", "0", "0", "0"]], "ts": "1741338240005", "checksum": 1749876812, "seqId": 48070593393, "prevSeqId": 48070593280}]}
{"arg": {"channel": "books", "instId": "BTC-USDT"}, "action": "update", "data": [{"asks": [["88538", "0.17121109", "0", "6"], ["88538.1", "0.11302153", "0", "4"], ["88539.8", "0", "0", "0"], ["88540.2", "0.00017853", "0", "2"], ["88540.5", "0.00272792", "0", "4"], ["88540.8", "0.000021", "0", "1"], ["88545.5", "0.02633783", "0", "2"], ["88545.7", "0.02831515", "0", "1"], ["88545.9", "0.02465745", "0", "2"], ["88546.2", "0.02584898", "0", "1"], ["88546.8", "0.00023539", "0", "2"], ["88547.1", "0", "0", "0"], ["88547.2", "0", "0", "0"], ["88547.4", "0", "0", "0"], ["88549.1", "0", "0", "0"], ["88549.3", "0.08572738", "0", "2"], ["88549.8", "0.08908447", "0", "1"], ["88549.9", "0.08129624", "0", "7"], ["88550.1", "0.07888312", "0", "1"], ["88550.4", "0.08050245", "0", "1"], ["88550.7", "0.00003658", "0", "1"], ["88550.8", "0", "0", "0"], ["88551.3", "0.00001204", "0", "1"], ["88551.4", "0", "0", "0"], ["88551.5", "0.01353", "0", "1"], ["88552.1", "0.00137118", "0", "1"], ["88552.9", "0.12192582", "0", "1"], ["88553.4", "0.13443989", "0", "1"], ["88554.4", "0.39932963", "0", "3"], ["88554.9", "0.13886862", "0", "1"], ["88555.9", "0", "0", "0"], ["88556", "0.14658547", "0", "2"], ["88557.5", "0", "0", "0"], ["88558.9", "0.012102", "0", "1"], ["88559.3", "0", "0", "0"], ["88559.5", "0.56239463", "0", "5"], ["88572.2", "0.14797525", "0", "3"], ["88572.4", "0.00001155", "0", "1"], ["88573.5", "0.22588146", "0", "1"], ["88576.3", "0", "0", "0"], ["88585.2", "0.07169795", "0", "1"], ["88587", "0", "0", "0"], ["88623.6", "0.00001103", "0", "1"], ["88624.1", "0.00183737", "0", "1"]], "bids": [["88537.9", "0.21040919", "0", "10"], ["88537.3", "0.11294449", "0", "1"], ["88537.2", "0.05311036", "0", "1"], ["88537.1", "0", "0", "0"], ["88537", "0.0001", "0", "1"], ["88536.5", "0", "0", "0"], ["88536.3", "0.0194028", "0", "1"], ["88535.2", "0.0001", "0", "1"], ["88532.6", "0.01405264", "0", "3"], ["88529.8", "0", "0", "0"], ["88529.7", "0", "0", "0"], ["88529.4", "0", "0", "0"], ["88528.8", "0.33887", "0", "1"], ["88528.3", "0.02679178", "0", "1"], ["88528.2", "0.02765821", "0", "1"], ["88528", "0.48417334", "0", "4"], ["88527.8", "0.05402815", "0", "2"], ["88527", "0.33888", "0", "1"], ["88526", "0.0163", "0", "1"], ["88525.8", "0", "0", "0"], ["88525.2", "0.33889", "0", "1"], ["88524.7", "0", "0", "0"], ["88524.5", "0.08325557", "0", "1"], ["88524.3", "0.08036423", "0", "1"], ["88523.7", "1.07597162", "0", "3"], ["88523.6", "0.20790314", "0", "1"], ["88522.8", "0", "0", "0"], ["88522.1", "0", "0", "0"], ["88521.9", "0", "0", "0"], ["88521.3", "0.12630803", "0", "1"], ["88520.4", "0.13958336", "0", "1"], ["88520.1", "0", "0", "0"], ["88519.2", "0.31067095", "0", "3"], ["88519", "0", "0", "0"], ["88517.5", "0.1385811", "0", "1"], ["88517.1", "0.22588157", "0", "1"], ["88516.8", "0.006573", "0", "1"], ["88495.1", "0.55661878", "0", "1"], ["88484.5", "0.33904", "0", "1"], ["88475.2", "0.00102619", "0", "1"], ["88474.2", "0", "0", "0"], ["88468", "0.00098614", "0", "1"], ["88466.7", "0", "0", "0"], ["88462", "0.00019394", "0", "1"], ["88460.9", "0", "0", "0"], ["88447", "0", "0", "0"], ["88296.3", "0.11343045", "0", "1"]], "ts": "1741338240105", "checksum": -1141262262, "seqId": 48070593599, "prevSeqId": 48070593393}]}
{"arg": {"channel": "books", "instId": "BTC-USDT"}, "action": "update", "data": [{"asks": [["88538", "0.43306936", "0", "11"], ["88539.7", "0.0001", "0", "1"], ["88539.9", "0.00086598", "0", "2"], ["88544.1", "0.06030972", "0", "3"], ["88545", "0.06023306", "0", "2"], ["88545.5", "0.00001035", "0", "1"], ["88545.6", "0.03001323", "0", "1"], ["88545.7", "0", "0", "0"], ["88545.8", "0.02541496", "0", "1"], ["88545.9", "0.00007302", "0", "1"], ["88546.1", "0.02892867", "0", "1"], ["88546.2", "0", "0", "0"], ["88546.3", "0.12060288", "0", "5"], ["88548.6", "0.06023306", "0", "2"], ["88549.3", "0.00004828", "0", "1"], ["88549.7", "0.07877108", "0", "1"], ["88549.8", "0", "0", "0"], ["88549.9", "0.00076516", "0", "6"], ["88550.1", "0", "0", "0"], ["88550.3", "0.08343516", "0", "1"], ["88550.4", "0", "0", "0"], ["88552.1", "0.01347318", "0", "2"], ["88552.9", "0", "0", "0"], ["88553.3", "0.13647513", "0", "1"], ["88553.4", "0", "0", "0"], ["88554.9", "0", "0", "0"], ["88556", "0.00001349", "0", "1"], ["88558.9", "0", "0", "0"], ["88559.5", "0.56574488", "0", "6"], ["88567.2", "0.22590698", "0", "2"], ["88572", "0.080195", "0", "1"], ["88572.2", "0.00002253", "0", "2"], ["88573.5", "0", "0", "0"], ["88581.7", "0.00358448", "0", "6"], ["88589.9", "0.55514785", "0", "1"], ["88593.5", "0.497779", "0", "1"], ["88597.4", "0", "0", "0"], ["88605.3", "0.01698416", "0", "2"], ["88626.3", "0.36929724", "0", "2"]], "bids": [["88537.9", "0.05582528", "0", "4"], ["88537.2", "0", "0", "0"], ["88537", "0", "0", "0"], ["88536.3", "0", "0", "0"], ["88535.2", "0", "0", "0"], ["88534.1", "0", "0", "0"], ["88532.7", "0", "0", "0"], ["88532.6", "0.00942", "0", "1"], ["88532.5", "0", "0", "0"], ["88528.3", "0", "0", "0"], ["88528.2", "0.02475403", "0", "1"], ["88528.1", "0.06994537", "0", "2"], ["88527.8", "0", "0", "0"], ["88527.7", "0.02765486", "0", "1"], ["88526.5", "0.0001", "0", "1"], ["88524.5", "0", "0", "0"], ["88524.4", "0.08220613", "0", "2"], ["88524.3", "0", "0", "0"], ["88523.7", "0.90244663", "0", "1"], ["88523.6", "0.29780398", "0", "2"], ["88522.8", "0.0001", "0", "1"], ["88521.3", "0", "0", "0"], ["88520.4", "0", "0", "0"], ["88520.3", "0.14779868", "0", "1"], ["88519.2", "0.07752047", "0", "1"], ["88519.1", "0.13468227", "0", "1"], ["88517.5", "0", "0", "0"], ["88517.1", "0", "0", "0"], ["88516.8", "0", "0", "0"], ["88506.4", "0.22619109", "0", "2"], ["88495.1", "0.56003342", "0", "2"], ["88485.7", "0.00138144", "0", "1"], ["88482.9", "0.01128601", "0", "1"], ["88315.7", "0.03389254", "0", "2"], ["88296.2", "0.34056098", "0", "1"], ["88294.7", "0.00001118", "0", "1"], ["88294.1", "0.00289318", "0", "3"], ["88294", "0.0025", "0", "1"], ["88293.4", "0.04093218", "0", "1"], ["88292.4", "0.00001139", "0", "1"], ["88292.3", "0.00002159", "0", "1"], ["88292", "0.0025", "0", "1"], ["88291", "0.005", "0", "2"], ["88290", "0.00001172", "0", "1"]], "ts": "1741338240205", "checksum": 1387496972, "seqId": 48070593776, "prevSeqId": 48070593599}]}
