{"arg": {"channel": "books", "instId": "BTC-USDT"}, "action": "update", "data": [{"asks": [["83984.6", "0.005", "0", "1"], ["83987", "0.000015", "0", "1"], ["83994.6", "0.005", "0", "1"], ["84008", "0", "0", "0"], ["84010.1", "0.23827359", "0", "1"], ["84141.2", "0", "0", "0"], ["84141.3", "0", "0", "0"], ["84141.4", "0", "0", "0"]], "bids": [["83981", "0.01", "0", "2"], ["83971", "0.005", "0", "1"], ["83958.9", "0.0038355", "0", "1"], ["83825.4", "0", "0", "0"], ["83825.1", "0", "0", "0"]], "ts": "1742577059200", "checksum": -1496140865, "seqId": 49944988319, "prevSeqId": 49944988305}], "record_time": 1742577059.37429, "EXCHANGE": "OKX"}
{"arg": {"channel": "books", "instId": "BTC-USDT"}, "action": "update", "data": [{"asks": [], "bids": [["83982", "0.00626868", "0", "4"], ["83975.2", "0.01191369", "0", "1"], ["83972.7", "0", "0", "0"], ["83949.6", "0.08", "0", "2"], ["83948.8", "0.0408", "0", "3"], ["83948", "0.53116234", "0", "3"]], "ts": "1742577059300", "checksum": 904309859, "seqId": 49944988334, "prevSeqId": 49944988319}], "record_time": 1742577059.473404, "EXCHANGE": "OKX"}
{"arg": {"channel": "books", "instId": "BTC-USDT"}, "action": "update", "data": [{"asks": [["84006.1", "0.2432886", "0", "3"], ["84010.1", "0", "0", "0"], ["84141.2", "0.00011161", "0", "1"]], "bids": [["83976.7", "0.000015", "0", "1"], ["83975.3", "1", "0", "1"], ["83974.8", "0.39426129", "0", "3"], ["83974.4", "0", "0", "0"], ["83894.6", "0", "0", "0"], ["83825.4", "0.00001365", "0", "1"]], "ts": "1742577059400", "checksum": 902007757, "seqId": 49944988342, "prevSeqId": 49944988334}], "record_time": 1742577059.572614, "EXCHANGE": "OKX"}
{"arg": {"channel": "books", "instId": "BTC-USDT"}, "action": "update", "data": [{"asks": [["84006.1", "0.00501198", "0", "2"], ["84008", "0.23827569", "0", "1"], ["84141.2", "0", "0", "0"]], "bids": [["83976.8", "0.18009525", "0", "1"], ["83975.3", "0", "0", "0"], ["83974.8", "0.74105829", "0", "3"], ["83974.4", "0.2025", "0", "1"], ["83973.5", "1", "0", "1"], ["83964.4", "0.00457861", "0", "2"], ["83958.9", "0", "0", "0"], ["83894.6", "0.00018358", "0", "1"], ["83825.4", "0", "0", "0"]], "ts": "1742577059500", "checksum": 610075057, "seqId": 49944988361, "prevSeqId": 49944988342}], "record_time": 1742577059.674978, "EXCHANGE": "OKX"}
{"arg": {"channel": "books", "instId": "BTC-USDT"}, "action": "update", "data": [{"asks": [["84020", "0.2", "0", "1"], ["84141.1", "0", "0", "0"]], "bids": [["83974.4", "0", "0", "0"], ["83964.4", "0.00011161", "0", "1"], ["83825.4", "0.00001365", "0", "1"]], "ts": "1742577059600", "checksum": -1070757721, "seqId": 49944988366, "prevSeqId": 49944988361}], "record_time": 1742577059.772628, "EXCHANGE": "OKX"}
{"arg": {"channel": "books", "instId": "BTC-USDT"}, "action": "update", "data": [{"asks": [["84008", "0.2382765", "0", "1"]], "bids": [["83980", "0.00001", "0", "1"], ["83974.4", "0.2025", "0", "1"], ["83957.9", "0.400082", "0", "2"], ["83952.1", "0.25602182", "0", "2"], ["83949.6", "0.0808", "0", "4"], ["83948.8", "0.0404", "0", "2"], ["83948", "0.53076234", "0", "2"], ["83898.2", "0.06009335", "0", "2"], ["83825.4", "0", "0", "0"]], "ts": "1742577059700", "checksum": 1406965216, "seqId": 49944988396, "prevSeqId": 49944988366}], "record_time": 1742577059.87218, "EXCHANGE": "OKX"}
{"arg": {"channel": "books", "instId": "BTC-USDT"}, "action": "update", "data": [{"asks": [["84099.6", "0", "0", "0"], ["84141.1", "0.00005109", "0", "1"]], "bids": [["83967.4", "0.00362759", "0", "1"], ["83957.9", "0.4000715", "0", "1"], ["83825.9", "0", "0", "0"]], "ts": "1742577059800", "checksum": 1406965216, "seqId": 49944988401, "prevSeqId": 49944988396}], "record_time": 1742577059.972386, "EXCHANGE": "OKX"}
{"arg": {"channel": "books", "instId": "BTC-USDT"}, "action": "update", "data": [{"asks": [["84005.7", "0.25018124", "0", "2"], ["84008", "0", "0", "0"], ["84141.2", "0.00011161", "0", "1"]], "bids": [["83960.3", "0.01161323", "0", "2"], ["83952.1", "0.25602264", "0", "2"]], "ts": "1742577059900", "checksum": 1406965216, "seqId": 49944988412, "prevSeqId": 49944988401}], "record_time": 1742577060.072003, "EXCHANGE": "OKX"}
{"arg": {"channel": "books", "instId": "BTC-USDT"}, "action": "update", "data": [{"asks": [["83995.5", "0.003573", "0", "1"], ["84005.4", "0.23827839", "0", "1"], ["84005.7", "0.01190396", "0", "1"], ["84020", "0", "0", "0"], ["84020.5", "0", "0", "0"]], "bids": [["83976.8", "0.45758335", "0", "2"], ["83974.8", "1.39068709", "0", "4"], ["83974.4", "0", "0", "0"], ["83973.5", "0", "0", "0"], ["83960.3", "0.00714623", "0", "1"], ["83952.1", "0.01774536", "0", "1"], ["83949.7", "0.23827839", "0", "1"], ["83949.6", "0.08", "0", "2"], ["83948.8", "0.0408", "0", "3"], ["83948", "0.53116234", "0", "3"], ["83944", "0", "0", "0"], ["83943.2", "0.1", "0", "2"], ["83942.4", "0.05", "0", "1"], ["83825.9", "0.00001586", "0", "1"]], "ts": "1742577060000", "checksum": -1419806538, "seqId": 49944988444, "prevSeqId": 49944988412}], "record_time": 1742577060.174507, "EXCHANGE": "OKX"}
{"arg": {"channel": "books", "instId": "BTC-USDT"}, "action": "update", "data": [{"asks": [["83995.5", "0", "0", "0"], ["84005.4", "0", "0", "0"], ["84006.1", "0.24328932", "0", "3"], ["84017.3", "0.003573", "0", "1"], ["84038.2", "0.00002157", "0", "1"], ["84038.5", "0", "0", "0"], ["84141.3", "0.00083", "0", "1"]], "bids": [["83974.8", "1.44819036", "0", "5"], ["83974.4", "0.2025", "0", "1"], ["83952.1", "0.2560227", "0", "2"], ["83949.7", "0", "0", "0"], ["83948", "0.73116234", "0", "4"], ["83947", "1", "0", "1"], ["83915.4", "0", "0", "0"], ["83915.1", "0.00218613", "0", "1"], ["83826", "0", "0", "0"]], "ts": "1742577060100", "checksum": 503059988, "seqId": 49944988482, "prevSeqId": 49944988444}], "record_time": 1742577060.272736, "EXCHANGE": "OKX"}
{"arg": {"channel": "books", "instId": "BTC-USDT"}, "action": "update", "data": [{"asks": [["83989.9", "0.003573", "0", "1"], ["84005.5", "0.26827754", "0", "2"], ["84006.1", "0.00501198", "0", "2"], ["84017.3", "0", "0", "0"]], "bids": [["83958.5", "0.004935", "0", "1"], ["83949.6", "0.0808", "0", "4"], ["83948.8", "0.0404", "0", "2"], ["83948", "0.73076234", "0", "3"], ["83944", "0.1", "0", "2"], ["83943.2", "0.05", "0", "1"], ["83942.4", "0", "0", "0"], ["83825.9", "0", "0", "0"]], "ts": "1742577060200", "checksum": 1672728490, "seqId": 49944988500, "prevSeqId": 49944988482}], "record_time": 1742577060.372374, "EXCHANGE": "OKX"}
{"arg": {"channel": "books", "instId": "BTC-USDT"}, "action": "update", "data": [{"asks": [["84005.5", "0.03", "0", "1"], ["84006.3", "0.23827626", "0", "1"], ["84141.3", "0", "0", "0"]], "bids": [["83974.4", "0", "0", "0"], ["83960.7", "0.03278688", "0", "2"], ["83958.5", "0", "0", "0"], ["83949.6", "0.08", "0", "2"], ["83948.8", "0.0408", "0", "3"], ["83948", "0.73116234", "0", "4"], ["83944", "0", "0", "0"], ["83943.2", "0.1", "0", "2"], ["83942.4", "0.05", "0", "1"], ["83826", "0.2025", "0", "1"], ["83825.9", "0.00001586", "0", "1"]], "ts": "1742577060300", "checksum": -66862230, "seqId": 49944988519, "prevSeqId": 49944988500}], "record_time": 1742577060.472662, "EXCHANGE": "OKX"}
{"arg": {"channel": "books", "instId": "BTC-USDT"}, "action": "update", "data": [{"asks": [["84007.6", "1", "0", "1"], ["84052.7", "0", "0", "0"]], "bids": [["83978", "0", "0", "0"], ["83974.8", "1.39068709", "0", "4"], ["83960.7", "0.02831988", "0", "1"], ["83945.9", "0.56005952", "0", "2"], ["83945.5", "0", "0", "0"], ["83825.4", "0.00001365", "0", "1"], ["83825.1", "0.0166188", "0", "1"]], "ts": "1742577060400", "checksum": 1800422269, "seqId": 49944988530, "prevSeqId": 49944988519}], "record_time": 1742577060.571991, "EXCHANGE": "OKX"}
{"arg": {"channel": "books", "instId": "BTC-USDT"}, "action": "update", "data": [{"asks": [["83982.4", "0.10732", "0", "2"], ["83982.9", "1.3553467", "0", "20"], ["83987.4", "0", "0", "0"], ["83989.9", "0", "0", "0"], ["83992.7", "0", "0", "0"], ["84001.9", "0.23828498", "0", "1"], ["84006.3", "1", "0", "1"], ["84007.6", "0", "0", "0"], ["84008.6", "0.003573", "0", "1"], ["84024", "0.07999999", "0", "2"], ["84045.7", "0.00578696", "0", "2"], ["84141.3", "0.00083", "0", "1"]], "bids": [["83982.8", "0", "0", "0"], ["83976.8", "0", "0", "0"], ["83974.8", "0.68744036", "0", "4"], ["83973.1", "1", "0", "1"], ["83967.4", "0", "0", "0"], ["83966.8", "0", "0", "0"], ["83956.2", "0.3565323", "0", "1"], ["83955.8", "0.0001785", "0", "1"], ["83952.1", "0.01774536", "0", "1"], ["83948.2", "0.23828498", "0", "1"], ["83948", "0.63116234", "0", "4"], ["83825", "0.00008012", "0", "2"]], "ts": "1742577060500", "checksum": 271222098, "seqId": 49944988604, "prevSeqId": 49944988530}], "record_time": 1742577060.672872, "EXCHANGE": "OKX"}
{"arg": {"channel": "books", "instId": "BTC-USDT"}, "action": "update", "data": [{"asks": [["83971.1", "1.53535913", "0", "21"], ["83972", "0.0439", "0", "1"], ["83972.8", "0.19018123", "0", "1"], ["83972.9", "0.01048316", "0", "1"], ["83973", "0.052", "0", "2"], ["83973.8", "0.2025", "0", "1"], ["83973.9", "0.28216597", "0", "1"], ["83974", "0.0439", "0", "1"], ["83974.2", "0.0428883", "0", "1"], ["83975.5", "0.15340678", "0", "1"], ["83975.7", "0.052", "0", "2"], ["83976", "0.0439", "0", "1"], ["83976.9", "0.35964043", "0", "1"], ["83978", "0.0439", "0", "1"], ["83980", "0.00004", "0", "1"], ["83980.9", "0.75405596", "0", "3"], ["83981", "0.2025", "0", "1"], ["83981.1", "0.09442847", "0", "3"], ["83981.3", "0.00774043", "0", "1"], ["83981.6", "0.052", "0", "2"], ["83982", "0.0439", "0", "1"], ["83982.1", "0.0102", "0", "1"], ["83982.2", "0.000015", "0", "1"], ["83982.4", "0.275065", "0", "6"], ["83982.7", "0.03062", "0", "1"], ["83982.9", "0.052", "0", "2"], ["83983", "0", "0", "0"], ["83983.3", "0", "0", "0"], ["83983.4", "0.00021617", "0", "1"], ["83983.5", "0.09618608", "0", "2"], ["83984.1", "0", "0", "0"], ["83986.2", "0.00001199", "0", "1"], ["83987", "0", "0", "0"], ["83987.9", "0.22782564", "0", "2"], ["83988.1", "0.02", "0", "1"], ["83988.5", "0", "0", "0"], ["83988.6", "0.02383024", "0", "1"], ["83990", "0.40087351", "0", "2"], ["83990.6", "0.006315", "0", "3"], ["83990.9", "0.11911771", "0", "1"], ["83991.1", "0", "0", "0"], ["83991.5", "0.2383266", "0", "1"], ["83991.6", "0.2394069", "0", "1"], ["83991.7", "0.17898725", "0", "1"], ["83992.5", "0.07", "0", "2"], ["83994", "0.0102", "0", "1"], ["83994.1", "0.11911316", "0", "1"], ["83994.5", "0.08991011", "0", "1"], ["83994.9", "0", "0", "0"], ["83995.2", "0.04", "0", "1"], ["83995.8", "0.50442955", "0", "1"], ["83995.9", "1", "0", "1"], ["83996", "0.005", "0", "1"], ["83996.9", "0", "0", "0"], ["83997", "0", "0", "0"], ["83997.4", "0", "0", "0"], ["83998", "0", "0", "0"], ["83999.8", "0.05628489", "0", "1"], ["84000", "0.00004", "0", "1"], ["84000.2", "0.17211714", "0", "1"], ["84000.6", "0", "0", "0"], ["84001.9", "0", "0", "0"], ["84002", "0.069858", "0", "3"], ["84003.4", "0", "0", "0"], ["84003.8", "0", "0", "0"], ["84004", "0", "0", "0"], ["84004.9", "0", "0", "0"], ["84005.6", "0", "0", "0"], ["84006.3", "0", "0", "0"], ["84008.6", "0", "0", "0"], ["84008.7", "0.0238185", "0", "1"], ["84010.3", "0.46954329", "0", "3"], ["84012.6", "0.34202801", "0", "1"], ["84013.1", "0.016", "0", "1"], ["84014", "0", "0", "0"], ["84014.7", "0.35725", "0", "1"], ["84015.1", "0.14071224", "0", "1"], ["84016.3", "0.06152164", "0", "1"], ["84016.4", "0.05956073", "0", "1"], ["84018.9", "0.53451", "0", "1"], ["84020", "0.00004", "0", "1"], ["84022.6", "0", "0", "0"], ["84023.2", "0.07999999", "0", "2"], ["84024", "0.03999999", "0", "1"], ["84024.8", "0", "0", "0"], ["84027.4", "0", "0", "0"], ["84027.8", "0.00589973", "0", "1"], ["84029.1", "0.02310614", "0", "1"], ["84029.5", "0.02283169", "0", "1"], ["84030.9", "0.28103865", "0", "2"], ["84031", "0.22036016", "0", "2"], ["84031.3", "0.57201", "0", "1"], ["84033.6", "0.00595434", "0", "1"], ["84035.2", "0.0057751", "0", "1"], ["84035.8", "0.00596632", "0", "2"], ["84037.3", "0.00595434", "0", "1"], ["84037.8", "0.11747977", "0", "2"], ["84039.1", "0.00595416", "0", "1"], ["84039.2", "0.1052", "0", "3"], ["84039.8", "0", "0", "0"], ["84041.8", "0.00589954", "0", "1"], ["84042.4", "0.00713925", "0", "1"], ["84042.8", "0", "0", "0"], ["84042.9", "0", "0", "0"], ["84043.9", "0.09475522", "0", "1"], ["84044.2", "0", "0", "0"], ["84044.9", "0.01128065", "0", "1"], ["84045.7", "0.00001198", "0", "1"], ["84045.9", "0.05951993", "0", "1"], ["84047.9", "0", "0", "0"], ["84049.7", "0.08767", "0", "1"], ["84050.3", "0.00589973", "0", "1"], ["84050.4", "0.1143786", "0", "1"], ["84051.5", "0.00589954", "0", "1"], ["84051.9", "0", "0", "0"], ["84052.4", "0.05628489", "0", "1"], ["84053.1", "0.00001501", "0", "1"], ["84055.2", "0.00118969", "0", "1"], ["84056.9", "0", "0", "0"], ["84058.7", "0.00589973", "0", "1"], ["84063.5", "0.02381744", "0", "1"], ["84063.8", "0.11889794", "0", "1"], ["84063.9", "0", "0", "0"], ["84066.1", "0.00589973", "0", "1"], ["84067.8", "0.09524494", "0", "2"], ["84072.7", "0.00589973", "0", "1"], ["84076.1", "0", "0", "0"], ["84076.2", "0", "0", "0"], ["84076.8", "0.00581881", "0", "2"], ["84081.5", "0", "0", "0"], ["84085.1", "0.16556884", "0", "1"], ["84085.2", "0", "0", "0"], ["84092.7", "1.36260513", "0", "2"], ["84094.2", "0", "0", "0"], ["84101.7", "0.47549316", "0", "2"], ["84103.8", "0", "0", "0"], ["84106.9", "0.00590056", "0", "1"], ["84107", "0.0071582", "0", "4"], ["84108.3", "0", "0", "0"], ["84110", "0", "0", "0"], ["84110.3", "0", "0", "0"], ["84116.6", "0.00062146", "0", "2"], ["84123.8", "0.01786107", "0", "3"], ["84127", "0", "0", "0"], ["84133.1", "0", "0", "0"], ["84133.3", "0", "0", "0"], ["84133.4", "0", "0", "0"], ["84133.5", "0", "0", "0"], ["84134.1", "0", "0", "0"], ["84134.2", "0", "0", "0"], ["84134.5", "0", "0", "0"], ["84134.6", "0", "0", "0"], ["84134.9", "0", "0", "0"], ["84135", "0", "0", "0"], ["84135.7", "0", "0", "0"], ["84135.8", "0", "0", "0"], ["84136", "0", "0", "0"], ["84136.2", "0", "0", "0"], ["84136.7", "0", "0", "0"], ["84136.8", "0", "0", "0"], ["84137.1", "0", "0", "0"], ["84138.8", "0", "0", "0"], ["84140", "0", "0", "0"], ["84141.1", "0", "0", "0"], ["84141.2", "0", "0", "0"], ["84141.3", "0", "0", "0"]], "bids": [["83982.3", "0", "0", "0"], ["83982.1", "0", "0", "0"], ["83982", "0", "0", "0"], ["83981.5", "0", "0", "0"], ["83981", "0", "0", "0"], ["83980", "0", "0", "0"], ["83977.8", "0", "0", "0"], ["83976.7", "0", "0", "0"], ["83976.4", "0", "0", "0"], ["83975.8", "0", "0", "0"], ["83975.6", "0", "0", "0"], ["83975.2", "0", "0", "0"], ["83974.8", "0", "0", "0"], ["83974.1", "0", "0", "0"], ["83974", "0", "0", "0"], ["83973.1", "0", "0", "0"], ["83972.9", "0", "0", "0"], ["83972.3", "0", "0", "0"], ["83971.7", "0", "0", "0"], ["83971.5", "0", "0", "0"], ["83970.4", "0", "0", "0"], ["83969.7", "0", "0", "0"], ["83969.5", "0", "0", "0"], ["83968.8", "0", "0", "0"], ["83968.5", "0.11256978", "0", "2"], ["83968", "0", "0", "0"], ["83966.5", "0", "0", "0"], ["83966.4", "0.05730431", "0", "1"], ["83966.3", "0", "0", "0"], ["83966.2", "0", "0", "0"], ["83966", "0.0439", "0", "1"], ["83965.9", "0", "0", "0"], ["83965.4", "0", "0", "0"], ["83965.3", "0", "0", "0"], ["83965.2", "0", "0", "0"], ["83965", "0", "0", "0"], ["83964.3", "0", "0", "0"], ["83964", "0", "0", "0"], ["83963.4", "0", "0", "0"], ["83963.1", "0", "0", "0"], ["83962.7", "0", "0", "0"], ["83962.6", "0.0119064", "0", "1"], ["83962", "0", "0", "0"], ["83961.9", "0", "0", "0"], ["83961.5", "0.10605434", "0", "1"], ["83960.8", "0.033", "0", "1"], ["83960.7", "0", "0", "0"], ["83960.6", "0.00006", "0", "1"], ["83960.3", "0", "0", "0"], ["83960.1", "0", "0", "0"], ["83960", "0.03301", "0", "2"], ["83959.3", "0", "0", "0"], ["83959", "0.00304", "0", "2"], ["83958.9", "0.04329594", "0", "1"], ["83958.1", "1", "0", "1"], ["83957.9", "0.2345289", "0", "1"], ["83957.8", "0", "0", "0"], ["83956.8", "0.0428883", "0", "1"], ["83956.6", "0.00001199", "0", "1"], ["83955.8", "0", "0", "0"], ["83955.4", "0.04", "0", "1"], ["83955.1", "0", "0", "0"], ["83954", "0.05956073", "0", "1"], ["83952.3", "0.38058549", "0", "3"], ["83952", "0", "0", "0"], ["83951.9", "0", "0", "0"], ["83950.8", "0.02751449", "0", "1"], ["83950.2", "0.00476473", "0", "1"], ["83950.1", "0", "0", "0"], ["83949.9", "0.00417645", "0", "2"], ["83949.6", "0", "0", "0"], ["83949", "0.05839583", "0", "1"], ["83948.8", "0", "0", "0"], ["83948.2", "0", "0", "0"], ["83948", "0.01190234", "0", "1"], ["83947.6", "0.08581", "0", "1"], ["83947.2", "0.01190247", "0", "1"], ["83947", "0", "0", "0"], ["83946.4", "0", "0", "0"], ["83946.3", "0", "0", "0"], ["83945.8", "0", "0", "0"], ["83945.6", "0.02383153", "0", "1"], ["83945.4", "0.23705265", "0", "2"], ["83945.3", "0", "0", "0"], ["83943.2", "0", "0", "0"], ["83942.4", "0", "0", "0"], ["83941.4", "0", "0", "0"], ["83940.5", "0", "0", "0"], ["83939.5", "0.36803357", "0", "2"], ["83938.8", "0", "0", "0"], ["83938.4", "0.08", "0", "2"], ["83938", "0.00077593", "0", "2"], ["83937.6", "0.0408", "0", "3"], ["83937.2", "0.5776526", "0", "1"], ["83937", "0.11256978", "0", "2"], ["83936.8", "0.00191199", "0", "3"], ["83936.6", "0", "0", "0"], ["83936.1", "0.19010055", "0", "2"], ["83936", "0.026", "0", "2"], ["83935.7", "0.05754972", "0", "2"], ["83935.3", "0", "0", "0"], ["83935.2", "0.013", "0", "1"], ["83933.7", "0.24412638", "0", "2"], ["83933.6", "0", "0", "0"], ["83933.2", "0", "0", "0"], ["83932.8", "0.1", "0", "2"], ["83932", "0.05", "0", "1"], ["83931.3", "0.02384044", "0", "1"], ["83931.2", "0", "0", "0"], ["83931", "0", "0", "0"], ["83930.9", "0", "0", "0"], ["83930.2", "0.522", "0", "1"], ["83930.1", "0", "0", "0"], ["83930", "0", "0", "0"], ["83929.6", "0.00589974", "0", "1"], ["83928.3", "0.01835018", "0", "1"], ["83928.2", "0", "0", "0"], ["83927.3", "0", "0", "0"], ["83927", "0.07508827", "0", "1"], ["83926.9", "0.00001199", "0", "1"], ["83925.7", "0", "0", "0"], ["83925", "0.00589961", "0", "1"], ["83924.2", "0.12502", "0", "1"], ["83922.3", "0", "0", "0"], ["83920", "0.00001", "0", "1"], ["83919.3", "0.5622", "0", "1"], ["83917.4", "0.01787802", "0", "4"], ["83916.1", "0", "0", "0"], ["83915.3", "0.00595434", "0", "1"], ["83915", "0", "0", "0"], ["83914.6", "0.00100642", "0", "1"], ["83914.5", "0.01786242", "0", "3"], ["83914.4", "0", "0", "0"], ["83913.5", "0.01335964", "0", "3"], ["83913.1", "0.01190877", "0", "2"], ["83911.2", "0.41147357", "0", "2"], ["83911.1", "0.18494159", "0", "2"], ["83908.2", "0.01190877", "0", "2"], ["83908.1", "0.11889794", "0", "1"], ["83905.9", "0.00595443", "0", "1"], ["83905.8", "0.01786266", "0", "3"], ["83905.7", "0.0058994", "0", "1"], ["83905.6", "0.0058996", "0", "1"], ["83904.8", "0.13745484", "0", "1"], ["83904.4", "0", "0", "0"], ["83904.1", "0", "0", "0"], ["83903.9", "0", "0", "0"], ["83903.7", "0", "0", "0"], ["83903.6", "0", "0", "0"], ["83903.4", "0", "0", "0"], ["83903.3", "0", "0", "0"], ["83901.9", "0.15624025", "0", "1"], ["83900.6", "0", "0", "0"], ["83900.1", "0.0058994", "0", "1"], ["83898.4", "0.0058996", "0", "1"], ["83898.3", "0", "0", "0"], ["83898.2", "0.22808142", "0", "1"], ["83896", "0", "0", "0"], ["83895.2", "0.58226341", "0", "1"], ["83894.6", "0", "0", "0"], ["83893.3", "0.04763535", "0", "1"], ["83892", "0", "0", "0"], ["83891.9", "0.0058994", "0", "1"], ["83891.6", "0.00803808", "0", "2"], ["83891.5", "0", "0", "0"], ["83890.3", "0", "0", "0"], ["83890.2", "0.1119234", "0", "1"], ["83889.1", "0", "0", "0"], ["83888.3", "0.01266216", "0", "2"], ["83888.1", "3.48181", "0", "1"], ["83887.3", "0.20714198", "0", "2"], ["83887.1", "0.00579944", "0", "1"], ["83886.9", "0.07963956", "0", "1"], ["83885.6", "1.46346525", "0", "1"], ["83884.6", "0.0058994", "0", "1"], ["83884.1", "0.0058996", "0", "1"], ["83881.4", "0.00579944", "0", "1"], ["83880.6", "0.03", "0", "1"], ["83880.1", "0.00579941", "0", "1"], ["83877.3", "0.0058994", "0", "1"], ["83877.2", "0.0058996", "0", "1"], ["83876.5", "0.00579944", "0", "1"], ["83876.2", "0.6364124", "0", "2"], ["83875.1", "0.00579941", "0", "1"], ["83873.6", "0.02961431", "0", "2"], ["83872.9", "0", "0", "0"], ["83870.7", "0.0058994", "0", "1"], ["83869.6", "0.00581139", "0", "2"], ["83859.9", "0.18404542", "0", "1"], ["83859.5", "0", "0", "0"], ["83858.2", "0.01194665", "0", "1"], ["83856.7", "0.18350188", "0", "1"], ["83849.6", "0.35784874", "0", "2"], ["83846.9", "0.22927232", "0", "2"], ["83846.5", "0.00595363", "0", "1"], ["83841.4", "0.00011803", "0", "3"], ["83832.6", "0.00001199", "0", "1"], ["83829.7", "0.01786089", "0", "3"], ["83827.7", "0.08991011", "0", "1"], ["83824.2", "0.20833794", "0", "2"], ["83823.6", "0.35776874", "0", "1"], ["83823.5", "0.00039533", "0", "1"], ["83823", "0.00001199", "0", "1"], ["83822.5", "0.00003465", "0", "2"], ["83822.4", "0.00001007", "0", "1"], ["83822.2", "0.00299792", "0", "1"], ["83822", "0.00001994", "0", "1"], ["83821.8", "0.00033901", "0", "2"], ["83821.5", "0.17898725", "0", "1"], ["83820.2", "0.00083", "0", "1"], ["83820", "0.00021617", "0", "3"], ["83819.9", "0.00012246", "0", "2"], ["83819.4", "0.00014808", "0", "2"], ["83819.2", "0.00001297", "0", "1"], ["83818.9", "0.00006774", "0", "2"], ["83818.1", "0.00006813", "0", "3"], ["83817.6", "0.2025", "0", "1"], ["83817.1", "0.00083", "0", "1"], ["83816.9", "0.00126817", "0", "1"], ["83816.6", "0.02900645", "0", "3"], ["83816.5", "0.0426", "0", "3"], ["83815.9", "0.00004266", "0", "1"], ["83815.3", "0.00018461", "0", "1"], ["83815", "0.35776874", "0", "1"], ["83814.9", "0.0073937", "0", "2"], ["83814.4", "0.00005519", "0", "1"], ["83814.1", "0.00003395", "0", "1"], ["83813.6", "0.03", "0", "1"], ["83813.5", "0.00002031", "0", "1"], ["83813.2", "0.0142", "0", "1"], ["83813.1", "0.00001199", "0", "1"], ["83812.5", "3.72667459", "0", "4"], ["83811.9", "0.0010552", "0", "1"], ["83811.7", "0.00006401", "0", "1"], ["83811.3", "0.00074812", "0", "1"], ["83810.8", "0.0054", "0", "1"], ["83810.1", "0.00001655", "0", "1"], ["83809.8", "0.01433882", "0", "2"]], "ts": "1742577060600", "checksum": -1314594543, "seqId": 49944990371, "prevSeqId": 49944988604}], "record_time": 1742577060.77409, "EXCHANGE": "OKX"}
{"arg": {"channel": "books", "instId": "BTC-USDT"}, "action": "update", "data": [{"asks": [["83971.1", "1.45755235", "0", "21"], ["83972.7", "0.02893196", "0", "1"], ["83972.8", "0.30932465", "0", "2"], ["83972.9", "0", "0", "0"], ["83973.4", "0.006975", "0", "1"], ["83973.7", "0.00111985", "0", "1"], ["83980.8", "0.17898725", "0", "1"], ["83980.9", "0.67836577", "0", "3"], ["83981.1", "0.072", "0", "3"], ["83982.4", "0.264073", "0", "5"], ["83982.9", "0.2188", "0", "3"], ["83983.5", "0.0746436", "0", "2"], ["83984.3", "0", "0", "0"], ["83986.5", "0.04", "0", "1"], ["83987.9", "0.31903072", "0", "1"], ["83988", "0.0839", "0", "2"], ["83988.1", "0", "0", "0"], ["83989.8", "0.23832464", "0", "1"], ["83989.9", "0.134853", "0", "1"], ["83990.9", "0.17911771", "0", "3"], ["83991.5", "0", "0", "0"], ["83992.5", "0.03", "0", "1"], ["83993.3", "1", "0", "1"], ["83993.6", "0.14071224", "0", "1"], ["83995.2", "0", "0", "0"], ["83995.8", "0.20442955", "0", "1"], ["83995.9", "0", "0", "0"], ["83999.8", "0.11256978", "0", "2"], ["84005.5", "0", "0", "0"], ["84005.8", "0", "0", "0"], ["84005.9", "0", "0", "0"], ["84007.1", "0", "0", "0"], ["84012.6", "0.23485301", "0", "1"], ["84014.7", "0", "0", "0"], ["84018.2", "0.02232", "0", "1"], ["84018.3", "0.01962952", "0", "1"], ["84018.5", "0.01190215", "0", "1"], ["84019.6", "0.00103317", "0", "1"], ["84026", "0.00103662", "0", "1"], ["84030.8", "0.00001198", "0", "1"], ["84031", "0.23191037", "0", "3"], ["84033.1", "0", "0", "0"], ["84037.4", "0.35697351", "0", "1"], ["84037.7", "0.01128065", "0", "1"], ["84039.4", "0.0057751", "0", "1"], ["84043.1", "0.19840806", "0", "1"], ["84043.2", "0.25009", "0", "1"], ["84043.9", "0", "0", "0"], ["84044.9", "0", "0", "0"], ["84049", "0.03749761", "0", "2"], ["84052.4", "0", "0", "0"], ["84064.4", "0", "0", "0"], ["84132.8", "0", "0", "0"]], "bids": [["83968.5", "0", "0", "0"], ["83968.3", "0", "0", "0"], ["83966.4", "0", "0", "0"], ["83966.1", "0", "0", "0"], ["83966", "0", "0", "0"], ["83965.1", "0.00056068", "0", "1"], ["83961.5", "0.04611294", "0", "1"], ["83961.2", "0", "0", "0"], ["83960.8", "0", "0", "0"], ["83958.9", "0", "0", "0"], ["83958.1", "0", "0", "0"], ["83957.9", "0.5078666", "0", "2"], ["83957.5", "0", "0", "0"], ["83956.8", "0", "0", "0"], ["83956.7", "0.01191622", "0", "1"], ["83956", "0", "0", "0"], ["83955.4", "0", "0", "0"], ["83953.1", "1", "0", "1"], ["83952.5", "0.084", "0", "2"], ["83952.4", "0.0428883", "0", "1"], ["83952.3", "0.43360353", "0", "4"], ["83952.1", "0", "0", "0"], ["83952", "0.04329594", "0", "1"], ["83950.3", "0.11917515", "0", "1"], ["83950.2", "0", "0", "0"], ["83950", "0", "0", "0"], ["83948.1", "0.17898725", "0", "1"], ["83947.8", "0.05190239", "0", "2"], ["83947.7", "0.35266831", "0", "1"], ["83947.6", "0", "0", "0"], ["83945.5", "0.14071224", "0", "1"], ["83939.6", "0.01774536", "0", "1"], ["83938.4", "0", "0", "0"], ["83937.6", "0.08", "0", "2"], ["83937.1", "0.00357", "0", "1"], ["83936.8", "0.04191199", "0", "4"], ["83936.1", "0.08802846", "0", "1"], ["83936", "0", "0", "0"], ["83935.8", "0.23832464", "0", "1"], ["83935.7", "0.05175", "0", "1"], ["83935.2", "0.026", "0", "2"], ["83934.4", "0.013", "0", "1"], ["83934.3", "0.14071224", "0", "1"], ["83933.7", "0", "0", "0"], ["83932.8", "0", "0", "0"], ["83932", "0.50948202", "0", "1"], ["83931.9", "0.00001199", "0", "1"], ["83931.2", "0.1", "0", "2"], ["83931.1", "0", "0", "0"], ["83930.8", "0.01", "0", "1"], ["83930.4", "0.05", "0", "1"], ["83928.3", "0", "0", "0"], ["83926.5", "0.11256978", "0", "2"], ["83923.5", "0.22850728", "0", "1"], ["83921.9", "0", "0", "0"], ["83920.3", "0.01835097", "0", "1"], ["83919.4", "0.22809912", "0", "1"], ["83917.3", "0", "0", "0"], ["83915.1", "0", "0", "0"], ["83914.6", "0", "0", "0"], ["83913.5", "0.01190728", "0", "2"], ["83905.6", "0", "0", "0"], ["83905.3", "0", "0", "0"], ["83904.5", "0.00218642", "0", "1"], ["83904.1", "0.00100655", "0", "1"], ["83901.9", "0.15769275", "0", "2"], ["83898.4", "0", "0", "0"], ["83896.3", "0.25009", "0", "1"], ["83895.7", "0.00579944", "0", "1"], ["83894.5", "0.00589943", "0", "1"], ["83891.6", "0.00213848", "0", "1"], ["83890.2", "1.17148272", "0", "2"], ["83890.1", "0.03", "0", "1"], ["83889.2", "0", "0", "0"], ["83888.6", "0.00579944", "0", "1"], ["83887.4", "0.00589943", "0", "1"], ["83887.1", "0", "0", "0"], ["83884.1", "0", "0", "0"], ["83884", "0", "0", "0"], ["83883", "0.60579944", "0", "2"], ["83881.4", "0", "0", "0"], ["83880.1", "0.01169884", "0", "2"], ["83879.3", "0", "0", "0"], ["83878.1", "0.03576755", "0", "1"], ["83877.2", "0", "0", "0"], ["83877.1", "0.00579944", "0", "1"], ["83876.9", "0.02381761", "0", "1"], ["83876.5", "0", "0", "0"], ["83875.8", "0.07746193", "0", "2"], ["83875.3", "0.250105", "0", "2"], ["83874.6", "0.00589973", "0", "1"], ["83873.5", "0.08418245", "0", "1"], ["83870.9", "0.00589943", "0", "1"], ["83870.8", "0.00579944", "0", "1"], ["83869.7", "0.00579944", "0", "1"], ["83868.4", "0.20238196", "0", "2"], ["83867.5", "0.00591473", "0", "2"], ["83866.5", "0.01159903", "0", "2"], ["83865.1", "0.01169887", "0", "2"], ["83865", "0.10904491", "0", "1"], ["83856.7", "0", "0", "0"], ["83850.1", "0.18353179", "0", "2"], ["83842.7", "0", "0", "0"], ["83828.6", "0", "0", "0"], ["83824.2", "0.20842029", "0", "3"], ["83813", "0.0008235", "0", "1"], ["83809.7", "0.00001075", "0", "1"], ["83809.2", "0.2025", "0", "1"], ["83808", "0.00014075", "0", "1"], ["83807.9", "0.00001018", "0", "1"], ["83807.5", "0.03", "0", "1"]], "ts": "1742577060700", "checksum": -1348750948, "seqId": 49944990713, "prevSeqId": 49944990371}], "record_time": 1742577060.873122, "EXCHANGE": "OKX"}
{"arg": {"channel": "books", "instId": "BTC-USDT"}, "action": "update", "data": [{"asks": [["83971.1", "1.4070733", "0", "22"], ["83973.4", "0", "0", "0"], ["83973.6", "0.02", "0", "1"], ["83973.9", "0", "0", "0"], ["83976", "0.07452", "0", "2"], ["83981.1", "0.052", "0", "2"], ["83982.1", "0", "0", "0"], ["83982.6", "0.04", "0", "1"], ["83982.7", "0", "0", "0"], ["83982.9", "0.052", "0", "2"], ["83986", "0.0541", "0", "2"], ["83987.5", "0.03", "0", "1"], ["83988", "0.0439", "0", "1"], ["83989.8", "0", "0", "0"], ["83990.9", "0.20911771", "0", "4"], ["83991.6", "0.49109035", "0", "2"], ["83991.7", "0.20898725", "0", "2"], ["83994", "0", "0", "0"], ["83995.3", "0.23831408", "0", "1"], ["83995.8", "0.23442955", "0", "2"], ["83998.8", "0", "0", "0"], ["84010.2", "0.26828805", "0", "2"], ["84010.4", "0.26238", "0", "1"], ["84015.6", "0.1", "0", "1"], ["84016.3", "0", "0", "0"], ["84026.6", "0", "0", "0"], ["84030.7", "0.00002157", "0", "1"], ["84031.4", "0.16020501", "0", "3"], ["84038.2", "0", "0", "0"], ["84043.1", "0.31479166", "0", "2"], ["84044", "0.57180611", "0", "3"], ["84049.8", "0", "0", "0"], ["84058.8", "0.04598659", "0", "3"], ["84060.2", "0.01427548", "0", "1"], ["84090", "0", "0", "0"], ["84132", "0.00594625", "0", "1"], ["84132.8", "0.00002013", "0", "1"], ["84133.1", "0.08991011", "0", "1"], ["84133.3", "0.00517228", "0", "9"], ["84133.5", "0.00001277", "0", "1"]], "bids": [["83966", "0.0439", "0", "1"], ["83964.7", "0.11915477", "0", "1"], ["83960", "0.00001", "0", "1"], ["83959.5", "0.01390501", "0", "2"], ["83957.9", "0.46895343", "0", "2"], ["83956.2", "1.3565323", "0", "2"], ["83955.9", "0.036", "0", "1"], ["83955.7", "0.01389", "0", "1"], ["83953.9", "0.04", "0", "1"], ["83953.2", "0.16190274", "0", "1"], ["83953.1", "0", "0", "0"], ["83952.8", "0.036", "0", "1"], ["83952.5", "0", "0", "0"], ["83952.3", "0.30678866", "0", "2"], ["83952", "0", "0", "0"], ["83951", "0.033", "0", "1"], ["83950.8", "0", "0", "0"], ["83949.8", "0.134853", "0", "1"], ["83949.4", "0.04168", "0", "1"], ["83949", "0", "0", "0"], ["83947.7", "0.23413898", "0", "2"], ["83946.2", "0.04329594", "0", "1"], ["83945.9", "0.00005952", "0", "1"], ["83943.1", "0.00001501", "0", "1"], ["83942.7", "0.00476516", "0", "1"], ["83942.2", "0.02751449", "0", "1"], ["83941.4", "0.23831408", "0", "1"], ["83940.6", "0.08581", "0", "1"], ["83937.6", "0", "0", "0"], ["83936.8", "0.08191199", "0", "5"], ["83936.1", "0.13957749", "0", "1"], ["83936", "0.04", "0", "1"], ["83935.8", "0", "0", "0"], ["83934.6", "0.045035", "0", "1"], ["83932.1", "0.63475417", "0", "1"], ["83932", "0.471645", "0", "1"], ["83924.9", "0.03579962", "0", "2"], ["83923.5", "0.37274211", "0", "2"], ["83923", "0.022", "0", "1"], ["83922.2", "0.93203505", "0", "2"], ["83921.9", "0.24659", "0", "1"], ["83913.4", "0", "0", "0"], ["83911.2", "0.16571851", "0", "2"], ["83909.5", "0.000015", "0", "1"], ["83888.3", "0.91513216", "0", "3"], ["83887.1", "0.00018359", "0", "1"], ["83813", "0", "0", "0"], ["83812.5", "0", "0", "0"], ["83811.9", "0", "0", "0"], ["83811.7", "0", "0", "0"], ["83811.3", "0", "0", "0"], ["83810.8", "0", "0", "0"], ["83810.1", "0", "0", "0"], ["83809.8", "0", "0", "0"], ["83809.7", "0", "0", "0"], ["83809.2", "0", "0", "0"], ["83808", "0", "0", "0"], ["83807.9", "0", "0", "0"], ["83807.5", "0", "0", "0"]], "ts": "1742577060800", "checksum": 582667182, "seqId": 49944990849, "prevSeqId": 49944990713}], "record_time": 1742577060.97273, "EXCHANGE": "OKX"}
{"arg": {"channel": "books", "instId": "BTC-USDT"}, "action": "update", "data": [{"asks": [["83971.1", "1.27715571", "0", "19"], ["83972.8", "0.22786587", "0", "2"], ["83973.1", "0.005262", "0", "1"], ["83980.8", "0.51331016", "0", "2"], ["83980.9", "0.47587145", "0", "2"], ["83983.5", "0.1563714", "0", "3"], ["83987.9", "0.5057916", "0", "2"], ["83989.8", "0.23832532", "0", "1"], ["83990.5", "1", "0", "1"], ["83991.6", "0.2394069", "0", "1"], ["83993.3", "0", "0", "0"], ["83995.3", "0", "0", "0"], ["84000.2", "0.12041004", "0", "1"], ["84002.1", "0", "0", "0"], ["84004.5", "0.22211729", "0", "1"], ["84004.6", "0.35727", "0", "1"], ["84006.4", "0", "0", "0"], ["84025.4", "0.01191469", "0", "1"], ["84027.8", "0.0059213", "0", "2"], ["84029.9", "0.55614218", "0", "1"], ["84030", "0.824733", "0", "1"], ["84030.7", "0", "0", "0"], ["84030.9", "0", "0", "0"], ["84053.4", "0", "0", "0"], ["84063.6", "0.58930629", "0", "2"], ["84064.2", "1.214555", "0", "1"], ["84133.5", "0", "0", "0"]], "bids": [["83966", "0", "0", "0"], ["83958", "0.12756978", "0", "5"], ["83956.2", "0.3565323", "0", "1"], ["83955.9", "0", "0", "0"], ["83955", "1", "0", "1"], ["83952.8", "0", "0", "0"], ["83947.7", "0.31813898", "0", "4"], ["83941.4", "0", "0", "0"], ["83939.6", "0", "0", "0"], ["83939.5", "0.79743442", "0", "1"], ["83938.7", "1.58131467", "0", "1"], ["83936.8", "0.00151199", "0", "2"], ["83936.1", "0.23685211", "0", "2"], ["83936", "0", "0", "0"], ["83935.2", "0", "0", "0"], ["83934.7", "0.23834033", "0", "2"], ["83934.4", "0.0804", "0", "3"], ["83933.6", "0.04", "0", "1"], ["83932.8", "0.026", "0", "2"], ["83932", "0.484645", "0", "2"], ["83931.2", "0", "0", "0"], ["83930.4", "0", "0", "0"], ["83928.8", "0.1", "0", "2"], ["83928", "0.05", "0", "1"], ["83924.7", "0", "0", "0"], ["83922.2", "0.3565323", "0", "1"], ["83919.4", "0.44733963", "0", "2"], ["83917", "0.82657499", "0", "3"], ["83911.2", "0.97864091", "0", "3"], ["83908.7", "2.77630968", "0", "1"], ["83903.3", "0.17863", "0", "1"], ["83901.1", "0.000015", "0", "1"], ["83896.4", "0.01774536", "0", "1"], ["83894", "0.12504", "0", "1"], ["83887.7", "0", "0", "0"], ["83887.1", "0", "0", "0"], ["83884.2", "0.0001836", "0", "1"], ["83882.9", "1.217179", "0", "1"], ["83876.2", "0.11889794", "0", "1"], ["83873", "0.12504", "0", "1"], ["83871.5", "0.01191469", "0", "1"], ["83865", "0", "0", "0"], ["83859.9", "0", "0", "0"]], "ts": "1742577060900", "checksum": -2009352939, "seqId": 49944990997, "prevSeqId": 49944990849}], "record_time": 1742577061.072971, "EXCHANGE": "OKX"}
{"arg": {"channel": "books", "instId": "BTC-USDT"}, "action": "update", "data": [{"asks": [["83971.1", "1.21792571", "0", "18"], ["83971.5", "0.00095933", "0", "1"], ["83980.4", "0.17863", "0", "1"], ["83983.4", "0.08848863", "0", "2"], ["83983.5", "0.066", "0", "2"], ["83986.9", "0.03", "0", "1"], ["83987.9", "0.31903072", "0", "1"], ["83990.5", "0", "0", "0"], ["83991.6", "0.9531257", "0", "1"], ["83991.7", "0.17898725", "0", "1"], ["83991.9", "1", "0", "1"], ["83992.5", "0", "0", "0"], ["83993.1", "1.63141093", "0", "1"], ["84002.2", "0", "0", "0"], ["84003", "0.2", "0", "1"], ["84132.8", "0", "0", "0"], ["84133.1", "0", "0", "0"], ["84133.3", "0", "0", "0"]], "bids": [["83971", "0.00694094", "0", "3"], ["83957.6", "1.17898725", "0", "2"], ["83955", "0", "0", "0"], ["83953.2", "0.24834603", "0", "2"], ["83951", "0.069", "0", "2"], ["83950.2", "0.17863", "0", "1"], ["83947.7", "0.35413898", "0", "5"], ["83934.4", "0.08", "0", "2"], ["83933.6", "0.0404", "0", "2"], ["83932.8", "0", "0", "0"], ["83932.1", "0.36443129", "0", "1"], ["83932", "0.497645", "0", "3"], ["83931.2", "0.013", "0", "1"], ["83928.8", "0", "0", "0"], ["83928", "0.1", "0", "2"], ["83927.2", "0.05", "0", "1"], ["83924.9", "0.00579962", "0", "1"], ["83891.6", "0", "0", "0"], ["83888.5", "0", "0", "0"], ["83876.2", "0.15367174", "0", "2"], ["83875", "0.00811227", "0", "2"], ["83813", "0.0008235", "0", "1"], ["83812.5", "0.00667459", "0", "3"]], "ts": "1742577061000", "checksum": -985335232, "seqId": 49944991061, "prevSeqId": 49944990997}], "record_time": 1742577061.17413, "EXCHANGE": "OKX"}
{"arg": {"channel": "books", "instId": "BTC-USDT"}, "action": "update", "data": [{"asks": [["83971.1", "1.22349871", "0", "20"], ["83973.1", "0", "0", "0"], ["83973.3", "0.00774076", "0", "1"], ["83981.3", "0.00775242", "0", "2"], ["83982.4", "0.2605", "0", "4"], ["83989.8", "0", "0", "0"], ["83991.9", "0", "0", "0"], ["83993.8", "1", "0", "1"], ["83995.3", "0.23831694", "0", "1"], ["84003", "0", "0", "0"], ["84009.7", "0.06097891", "0", "1"], ["84075.2", "0.06744", "0", "1"], ["84132.6", "0", "0", "0"]], "bids": [["83966", "0.0439", "0", "1"], ["83961.5", "0", "0", "0"], ["83960", "0.00774282", "0", "2"], ["83959", "0.34131093", "0", "3"], ["83958.9", "1", "0", "1"], ["83958", "0.11756978", "0", "4"], ["83957.9", "0.2345289", "0", "1"], ["83957.6", "0.17898725", "0", "1"], ["83950.1", "0.004467", "0", "1"], ["83948.1", "0.18672007", "0", "2"], ["83942.4", "0.06030547", "0", "1"], ["83941.9", "0.01774536", "0", "1"], ["83939.6", "0.23831694", "0", "1"], ["83935.2", "0.57889033", "0", "1"], ["83934.7", "0.00001501", "0", "1"], ["83928.1", "0.12150145", "0", "1"], ["83927", "0", "0", "0"], ["83898.6", "0.067582", "0", "1"], ["83896.4", "0", "0", "0"], ["83871.9", "0.01510855", "0", "1"], ["83820.3", "0.00001199", "0", "1"], ["83814.4", "0", "0", "0"], ["83814.1", "0", "0", "0"], ["83813.6", "0", "0", "0"], ["83813.5", "0", "0", "0"], ["83813.2", "0", "0", "0"], ["83813.1", "0", "0", "0"], ["83813", "0", "0", "0"], ["83812.5", "0", "0", "0"]], "ts": "1742577061100", "checksum": 636775992, "seqId": 49944991101, "prevSeqId": 49944991061}], "record_time": 1742577061.27264, "EXCHANGE": "OKX"}
{"arg": {"channel": "books", "instId": "BTC-USDT"}, "action": "update", "data": [{"asks": [["83971.7", "0.0021255", "0", "1"], ["83991.6", "0.5804518", "0", "1"], ["83993.1", "0", "0", "0"], ["83993.5", "0.23831863", "0", "1"], ["83995.3", "0", "0", "0"], ["83995.8", "0.20442955", "0", "1"], ["83999.6", "0.01190482", "0", "1"], ["84004.5", "0.11493629", "0", "1"], ["84004.6", "0", "0", "0"], ["84017.1", "0", "0", "0"], ["84033.9", "0.36190399", "0", "1"], ["84036.4", "0", "0", "0"], ["84043.2", "0", "0", "0"], ["84132.6", "0.0000434", "0", "1"], ["84132.8", "0.00002013", "0", "1"], ["84133.1", "0.08991011", "0", "1"]], "bids": [["83960.3", "0.34268179", "0", "1"], ["83960.2", "1", "0", "1"], ["83959", "0.00304", "0", "2"], ["83958.9", "0", "0", "0"], ["83956.6", "0.04290029", "0", "2"], ["83952.7", "0.17863", "0", "1"], ["83952.4", "0", "0", "0"], ["83950.2", "0", "0", "0"], ["83950.1", "0", "0", "0"], ["83948", "0", "0", "0"], ["83939.6", "0", "0", "0"], ["83939.5", "0.4405398", "0", "1"], ["83938.7", "0", "0", "0"], ["83937.3", "0.23831863", "0", "1"], ["83930.6", "0.36843712", "0", "2"], ["83911.5", "0.21843391", "0", "1"], ["83911.2", "0.00595443", "0", "1"], ["83908.7", "0", "0", "0"], ["83903.3", "0", "0", "0"], ["83896.3", "0", "0", "0"], ["83894", "0", "0", "0"], ["83876.2", "0.81587063", "0", "3"], ["83875.3", "0.000015", "0", "1"], ["83873.5", "0.12104845", "0", "2"], ["83873", "0", "0", "0"], ["83814.4", "0.00005519", "0", "1"], ["83814.1", "0.00003395", "0", "1"], ["83813.6", "0.03", "0", "1"], ["83813.5", "0.00002031", "0", "1"], ["83813.2", "0.0142", "0", "1"], ["83813.1", "0.00001199", "0", "1"], ["83813", "0.0008235", "0", "1"]], "ts": "1742577061200", "checksum": 1770733949, "seqId": 49944991160, "prevSeqId": 49944991101}], "record_time": 1742577061.372207, "EXCHANGE": "OKX"}
{"arg": {"channel": "books", "instId": "BTC-USDT"}, "action": "update", "data": [{"asks": [["83987.8", "0.23832679", "0", "1"], ["83991.6", "0.89634954", "0", "2"], ["83991.9", "1", "0", "1"], ["83993.5", "0", "0", "0"], ["83993.6", "1.67387824", "0", "2"], ["83993.8", "0", "0", "0"], ["84021.3", "1.08102574", "0", "2"], ["84023", "2.81526093", "0", "1"], ["84037.5", "0.4", "0", "1"], ["84132.8", "0", "0", "0"], ["84133.1", "0", "0", "0"]], "bids": [["83960.7", "0.2", "0", "1"], ["83960.2", "0", "0", "0"], ["83958.7", "1", "0", "1"], ["83952.7", "0", "0", "0"], ["83939.5", "0.77278592", "0", "2"], ["83939.3", "1.52936395", "0", "1"], ["83937.3", "0", "0", "0"], ["83936.1", "0.39055967", "0", "1"], ["83934.7", "0.2383418", "0", "2"], ["83911.5", "1.01141178", "0", "2"], ["83909.9", "2.73427371", "0", "1"], ["83876.2", "0.15367174", "0", "2"], ["83813", "0", "0", "0"]], "ts": "1742577061300", "checksum": 48632949, "seqId": 49944991191, "prevSeqId": 49944991160}], "record_time": 1742577061.475021, "EXCHANGE": "OKX"}
{"arg": {"channel": "books", "instId": "BTC-USDT"}, "action": "update", "data": [{"asks": [["83979.4", "0.35727", "0", "1"], ["84074", "0.10595164", "0", "2"], ["84089.9", "0", "0", "0"]], "bids": [["83971", "0.00522094", "0", "2"], ["83966.9", "0.11915161", "0", "1"], ["83966", "0", "0", "0"], ["83964.7", "0", "0", "0"], ["83947.7", "0.45064689", "0", "6"], ["83946.7", "0.35728199", "0", "2"], ["83946.1", "0.004935", "0", "1"], ["83938.6", "0.17863", "0", "1"], ["83915", "0.12504", "0", "1"], ["83894", "0.12504", "0", "1"], ["83868.4", "0", "0", "0"], ["83813.2", "0", "0", "0"], ["83813.1", "0", "0", "0"]], "ts": "1742577061400", "checksum": -455721260, "seqId": 49944991210, "prevSeqId": 49944991191}], "record_time": 1742577061.573084, "EXCHANGE": "OKX"}
{"arg": {"channel": "books", "instId": "BTC-USDT"}, "action": "update", "data": [{"asks": [["83971.1", "1.23503109", "0", "21"], ["83971.7", "0", "0", "0"], ["83972.7", "0.03343196", "0", "2"], ["83978.6", "0.00354753", "0", "1"], ["83987.8", "0", "0", "0"], ["83991.9", "0", "0", "0"], ["83993.5", "1", "0", "1"], ["83995.3", "0.23831674", "0", "1"], ["83998.8", "0.01190494", "0", "1"], ["84014.5", "0", "0", "0"], ["84060", "0", "0", "0"], ["84132.8", "0.00002013", "0", "1"]], "bids": [["83971", "0.0067026", "0", "3"], ["83954.2", "0.00363975", "0", "1"], ["83950.2", "0.17863", "0", "1"], ["83948.2", "0.32804369", "0", "1"], ["83947.7", "0.153", "0", "4"], ["83947.1", "0", "0", "0"], ["83946.7", "0.00001199", "0", "1"], ["83946.2", "0.04825194", "0", "2"], ["83946.1", "0", "0", "0"], ["83937.3", "0.23831674", "0", "1"], ["83934.7", "0.00001501", "0", "1"], ["83928", "0.11190494", "0", "3"], ["83873.5", "0.08418245", "0", "1"], ["83813.6", "0", "0", "0"], ["83813.5", "0", "0", "0"]], "ts": "1742577061500", "checksum": 1007088763, "seqId": 49944991238, "prevSeqId": 49944991210}], "record_time": 1742577061.672107, "EXCHANGE": "OKX"}
{"arg": {"channel": "books", "instId": "BTC-USDT"}, "action": "update", "data": [{"asks": [["83972.7", "0.02893196", "0", "1"], ["83978.6", "0", "0", "0"], ["83987.9", "0.5057916", "0", "2"], ["83989.8", "0.23832428", "0", "1"], ["83991.6", "1.5804518", "0", "2"], ["83993.5", "0", "0", "0"], ["83995.3", "0", "0", "0"], ["83999.1", "0.01", "0", "1"], ["83999.4", "0.01190485", "0", "1"], ["83999.7", "0.01190481", "0", "1"], ["84016.2", "0", "0", "0"], ["84018.5", "0", "0", "0"], ["84021", "0", "0", "0"], ["84024.3", "0.01", "0", "1"], ["84057", "0", "0", "0"], ["84133.1", "0.08991011", "0", "1"], ["84133.3", "0.00517228", "0", "9"]], "bids": [["83947.8", "0.04", "0", "1"], ["83947.2", "0", "0", "0"], ["83940.3", "0.01", "0", "1"], ["83937.3", "0.56", "0", "1"], ["83936.1", "0.73134547", "0", "2"], ["83936", "0.2", "0", "1"], ["83933.7", "0.23832428", "0", "1"], ["83933", "1", "0", "1"], ["83929.5", "0.01190474", "0", "1"], ["83928.9", "0.01190481", "0", "1"], ["83885.6", "0.73294138", "0", "1"], ["83881.3", "0", "0", "0"], ["83815", "0", "0", "0"], ["83814.9", "0", "0", "0"], ["83814.4", "0", "0", "0"], ["83814.1", "0", "0", "0"]], "ts": "1742577061600", "checksum": 1011966874, "seqId": 49944991274, "prevSeqId": 49944991238}], "record_time": 1742577061.772384, "EXCHANGE": "OKX"}
{"arg": {"channel": "books", "instId": "BTC-USDT"}, "action": "update", "data": [{"asks": [["83971.1", "1.23549609", "0", "22"], ["84000.2", "0.17138578", "0", "2"], ["84001.2", "0.25009", "0", "1"], ["84018", "0.00001", "0", "1"], ["84041", "0.000015", "0", "1"], ["84133.1", "0", "0", "0"], ["84133.3", "0", "0", "0"]], "bids": [["83966.6", "0.00231995", "0", "3"], ["83949.2", "0.35727", "0", "1"], ["83938.3", "0.42907725", "0", "2"], ["83936.1", "0.39055967", "0", "1"], ["83933", "0", "0", "0"], ["83932", "0.497655", "0", "4"], ["83917.3", "0.25009", "0", "1"], ["83885.6", "1.07372718", "0", "2"], ["83815.3", "0", "0", "0"]], "ts": "1742577061700", "checksum": 215011877, "seqId": 49944991290, "prevSeqId": 49944991274}], "record_time": 1742577061.872741, "EXCHANGE": "OKX"}
{"arg": {"channel": "books", "instId": "BTC-USDT"}, "action": "update", "data": [{"asks": [["83971.1", "1.23503109", "0", "21"], ["83989.8", "0", "0", "0"], ["83995.3", "0.23831677", "0", "1"]], "bids": [["83966.6", "0.00341189", "0", "4"], ["83960.7", "0", "0", "0"], ["83958.7", "0", "0", "0"], ["83958.3", "1", "0", "1"], ["83946.2", "0.04329594", "0", "1"], ["83939.5", "1.09936619", "0", "1"], ["83937.4", "0.23831677", "0", "1"], ["83933.7", "0", "0", "0"], ["83815.3", "0.00018461", "0", "1"]], "ts": "1742577061800", "checksum": -2115871035, "seqId": 49944991308, "prevSeqId": 49944991290}], "record_time": 1742577061.981753, "EXCHANGE": "OKX"}
{"arg": {"channel": "books", "instId": "BTC-USDT"}, "action": "update", "data": [{"asks": [["83971.1", "1.39885552", "0", "22"], ["83983.4", "0.14318439", "0", "3"], ["83987.4", "0.23832892", "0", "1"], ["83995.3", "0", "0", "0"]], "bids": [["83971", "0.0072526", "0", "4"], ["83966.6", "0.00690037", "0", "7"], ["83960.3", "0.04268179", "0", "1"], ["83958.3", "0", "0", "0"], ["83957.9", "0.48181992", "0", "2"], ["83956.9", "1", "0", "1"], ["83954.2", "0", "0", "0"], ["83949.2", "0", "0", "0"], ["83946.7", "0.35728199", "0", "2"], ["83937.4", "0", "0", "0"], ["83936", "0", "0", "0"], ["83932.1", "0.52428686", "0", "2"], ["83931.4", "0.23832892", "0", "1"], ["83873.5", "0", "0", "0"], ["83815", "0.35776874", "0", "1"], ["83814.9", "0.0073937", "0", "2"], ["83814.4", "0.00005519", "0", "1"], ["83814.1", "0.00003395", "0", "1"]], "ts": "1742577061900", "checksum": -1760423622, "seqId": 49944991337, "prevSeqId": 49944991308}], "record_time": 1742577062.076068, "EXCHANGE": "OKX"}
{"arg": {"channel": "books", "instId": "BTC-USDT"}, "action": "update", "data": [{"asks": [["83971.1", "1.39887502", "0", "23"]], "bids": [["83966.9", "0", "0", "0"], ["83965", "0.11915431", "0", "1"], ["83933.6", "0.0408", "0", "3"], ["83932.8", "0.0004", "0", "1"], ["83814.1", "0", "0", "0"]], "ts": "1742577062000", "checksum": 765759767, "seqId": 49944991346, "prevSeqId": 49944991337}], "record_time": 1742577062.171699, "EXCHANGE": "OKX"}
{"arg": {"channel": "books", "instId": "BTC-USDT"}, "action": "update", "data": [{"asks": [["83983.4", "0.08848863", "0", "2"], ["83987.4", "0", "0", "0"], ["83989.8", "0.23832472", "0", "1"], ["84002", "0.269858", "0", "5"], ["84026.4", "0.00002157", "0", "1"], ["84027.8", "0.00589973", "0", "1"], ["84033.8", "0.01128686", "0", "1"], ["84037.7", "0", "0", "0"], ["84088.2", "0.00011938", "0", "1"], ["84132.8", "0", "0", "0"]], "bids": [["83943.4", "0.004935", "0", "1"], ["83933.1", "0.23832403", "0", "1"], ["83931.4", "0", "0", "0"], ["83920.3", "0", "0", "0"], ["83917.5", "0.01835101", "0", "1"], ["83904.5", "0", "0", "0"], ["83903.6", "0.00218666", "0", "1"], ["83902", "0.00145262", "0", "1"], ["83901.9", "0.15624025", "0", "1"], ["83884.2", "0", "0", "0"], ["83883.1", "0.00018358", "0", "1"], ["83850.1", "0.00002208", "0", "1"], ["83844.7", "0.18356741", "0", "2"], ["83814.9", "0", "0", "0"], ["83814.4", "0", "0", "0"]], "ts": "1742577062100", "checksum": 765759767, "seqId": 49944991386, "prevSeqId": 49944991346}], "record_time": 1742577062.272695, "EXCHANGE": "OKX"}
{"arg": {"channel": "books", "instId": "BTC-USDT"}, "action": "update", "data": [{"asks": [["83978.6", "0.00349713", "0", "1"], ["83989.8", "0.23832412", "0", "1"], ["84002", "0.169858", "0", "4"], ["84067.8", "0.10104416", "0", "3"], ["84132.6", "0", "0", "0"]], "bids": [["83960.3", "0.33734656", "0", "2"], ["83958.3", "1", "0", "1"], ["83957.9", "0.2345289", "0", "1"], ["83956.9", "0", "0", "0"], ["83952.8", "0.00365011", "0", "1"], ["83943.4", "0", "0", "0"], ["83933.1", "0", "0", "0"], ["83933", "0.23832412", "0", "1"], ["83876.2", "0.11889794", "0", "1"]], "ts": "1742577062200", "checksum": 1671292360, "seqId": 49944991423, "prevSeqId": 49944991386}], "record_time": 1742577062.372533, "EXCHANGE": "OKX"}
{"arg": {"channel": "books", "instId": "BTC-USDT"}, "action": "update", "data": [{"asks": [["83971.1", "1.59887502", "0", "24"], ["83989.8", "0", "0", "0"], ["83990.8", "0.23832313", "0", "1"], ["84011.2", "0.09190318", "0", "3"], ["84012", "0.03999999", "0", "1"], ["84023.2", "0", "0", "0"], ["84024", "0", "0", "0"], ["84132.6", "0.0000434", "0", "1"]], "bids": [["83944.8", "0.00458011", "0", "2"], ["83933.7", "0.23832313", "0", "1"], ["83933", "0", "0", "0"]], "ts": "1742577062300", "checksum": -1884523632, "seqId": 49944991436, "prevSeqId": 49944991423}], "record_time": 1742577062.472436, "EXCHANGE": "OKX"}
{"arg": {"channel": "books", "instId": "BTC-USDT"}, "action": "update", "data": [{"asks": [["83966.7", "1.05841432", "0", "15"], ["83966.8", "0.060108", "0", "1"], ["83968", "0.0439", "0", "1"], ["83970.9", "0.92199652", "0", "1"], ["83971", "0.21153238", "0", "2"], ["83971.1", "0.2597365", "0", "7"], ["83971.6", "0.03062", "0", "1"], ["83972.8", "0", "0", "0"], ["83976", "0.0439", "0", "1"], ["83976.3", "0.00001199", "0", "1"], ["83980.1", "0.02383287", "0", "1"], ["83988.6", "0", "0", "0"], ["83990", "0.35697351", "0", "1"], ["83990.8", "0.23832559", "0", "1"], ["83992", "0", "0", "0"], ["83992.8", "0.18761632", "0", "1"], ["84002", "0.069858", "0", "3"], ["84009.6", "0.08", "0", "2"], ["84010.4", "0.30237999", "0", "2"], ["84011.1", "0.000015", "0", "1"], ["84011.2", "0.01190318", "0", "1"], ["84012", "0", "0", "0"], ["84013.2", "0", "0", "0"], ["84050.8", "0", "0", "0"], ["84131.1", "0", "0", "0"], ["84131.2", "0", "0", "0"], ["84132", "0", "0", "0"], ["84132.5", "0", "0", "0"], ["84132.6", "0", "0", "0"]], "bids": [["83971", "0", "0", "0"], ["83970.9", "0", "0", "0"], ["83962", "0.0439", "0", "1"], ["83960.3", "0.04268179", "0", "1"], ["83958.3", "0", "0", "0"], ["83957.9", "0.47824506", "0", "2"], ["83956.7", "0", "0", "0"], ["83956.6", "1.04290029", "0", "3"], ["83955.7", "0", "0", "0"], ["83954.4", "0.01191643", "0", "1"], ["83951.4", "0.01389", "0", "1"], ["83949.4", "0", "0", "0"], ["83949.3", "0.53526423", "0", "1"], ["83949.2", "0.35727", "0", "1"], ["83948.2", "0", "0", "0"], ["83945.1", "0.04168", "0", "1"], ["83944.8", "0.00011161", "0", "1"], ["83944.1", "0.00714761", "0", "1"], ["83934.4", "0", "0", "0"], ["83933.7", "0", "0", "0"], ["83933.6", "0.08", "0", "2"], ["83932.8", "0.0408", "0", "3"], ["83932.2", "0.23832579", "0", "1"], ["83932", "0.472055", "0", "3"], ["83931.2", "0.026", "0", "2"], ["83930.4", "0.013", "0", "1"], ["83928", "0.01190494", "0", "1"], ["83927.2", "0.1", "0", "2"], ["83926.4", "0.05", "0", "1"], ["83903.5", "0.36248704", "0", "2"], ["83902.1", "0.00596674", "0", "2"], ["83900.5", "0.18494199", "0", "2"], ["83885.6", "0.73294138", "0", "1"], ["83815", "0", "0", "0"]], "ts": "1742577062400", "checksum": -460025431, "seqId": 49944991613, "prevSeqId": 49944991436}], "record_time": 1742577062.573656, "EXCHANGE": "OKX"}
{"arg": {"channel": "books", "instId": "BTC-USDT"}, "action": "update", "data": [{"asks": [["83966.7", "1.0703309", "0", "16"], ["83966.8", "0.016743", "0", "2"], ["83970.8", "0.28267682", "0", "1"], ["83970.9", "0", "0", "0"], ["83971.1", "0.2541635", "0", "5"], ["83989.8", "0.23832876", "0", "1"], ["83990.8", "0", "0", "0"], ["84012.6", "0.15297006", "0", "1"], ["84015.6", "0", "0", "0"], ["84022.9", "0.01786422", "0", "3"], ["84024.2", "0.00596974", "0", "2"], ["84025.3", "0.00595474", "0", "1"], ["84029.1", "0.02906088", "0", "2"], ["84029.8", "0.00595474", "0", "1"], ["84033.2", "0.00595474", "0", "1"], ["84127.4", "0", "0", "0"], ["84130.1", "0", "0", "0"], ["84130.5", "0", "0", "0"]], "bids": [["83965", "0", "0", "0"], ["83962.4", "0.11915806", "0", "1"], ["83960.3", "0", "0", "0"], ["83956.6", "0.04290029", "0", "2"], ["83954.2", "1", "0", "1"], ["83950.2", "0", "0", "0"], ["83949.3", "0.32090223", "0", "1"], ["83949.2", "0", "0", "0"], ["83947.7", "0.33164", "0", "5"], ["83946.7", "0.00001199", "0", "1"], ["83942.5", "0.004935", "0", "1"], ["83936", "0.30369", "0", "2"], ["83933.6", "0", "0", "0"], ["83932.8", "0.0808", "0", "4"], ["83932.2", "0", "0", "0"], ["83932", "0.512055", "0", "4"], ["83931.4", "0.23832876", "0", "1"], ["83930.7", "0", "0", "0"], ["83909.7", "0.01310528", "0", "2"], ["83909.6", "0.00595474", "0", "1"], ["83908.3", "0.00595474", "0", "1"], ["83906", "0.00595474", "0", "1"], ["83905.5", "0.00666965", "0", "4"], ["83904.1", "0", "0", "0"], ["83903.6", "0", "0", "0"], ["83902", "0", "0", "0"], ["83901.1", "0.00220162", "0", "2"], ["83900", "0.00222149", "0", "5"], ["83898.7", "0.00145256", "0", "1"], ["83859.9", "0.00579953", "0", "1"]], "ts": "1742577062500", "checksum": 173146412, "seqId": 49944991712, "prevSeqId": 49944991613}], "record_time": 1742577062.672439, "EXCHANGE": "OKX"}
{"arg": {"channel": "books", "instId": "BTC-USDT"}, "action": "update", "data": [{"asks": [["83966.8", "0.05084195", "0", "3"], ["83967.7", "0.11915066", "0", "1"], ["83970", "0.0428883", "0", "1"], ["83974.2", "0", "0", "0"], ["83980.9", "0.59500331", "0", "3"], ["83994.1", "0", "0", "0"], ["83995.8", "0.49504715", "0", "2"], ["83997", "1", "0", "1"], ["84011.2", "0.11190318", "0", "2"], ["84129.2", "0", "0", "0"]], "bids": [["83962.4", "0", "0", "0"], ["83962", "0", "0", "0"], ["83960.5", "0.11916073", "0", "1"], ["83958.1", "0.03527093", "0", "1"], ["83942.5", "0", "0", "0"], ["83940.5", "0.0012705", "0", "1"], ["83901.1", "0.000015", "0", "1"], ["83899.1", "0.00218662", "0", "1"], ["83815.3", "0", "0", "0"]], "ts": "1742577062600", "checksum": 1507368205, "seqId": 49944991738, "prevSeqId": 49944991712}], "record_time": 1742577062.77675, "EXCHANGE": "OKX"}
{"arg": {"channel": "books", "instId": "BTC-USDT"}, "action": "update", "data": [{"asks": [["83962.7", "1.29549622", "0", "15"], ["83964", "0.0439", "0", "1"], ["83965.1", "0.12559262", "0", "1"], ["83965.2", "0.2127", "0", "2"], ["83965.5", "0.11915375", "0", "1"], ["83966", "0.0439", "0", "1"], ["83966.2", "0.0428883", "0", "1"], ["83966.5", "0.01662971", "0", "1"], ["83966.6", "0.01153238", "0", "1"], ["83966.7", "0.06391658", "0", "3"], ["83966.8", "0.003573", "0", "1"], ["83967.7", "0", "0", "0"], ["83970", "0", "0", "0"], ["83970.8", "0.14575872", "0", "1"], ["83971", "0", "0", "0"], ["83971.1", "0.0541635", "0", "4"], ["83971.4", "0.00001199", "0", "1"], ["83973.8", "0.20251501", "0", "2"], ["83977.7", "0.04", "0", "1"], ["83980.3", "0.50204639", "0", "1"], ["83980.8", "0.17898725", "0", "1"], ["83981.4", "0.0102", "0", "1"], ["83983.3", "0.00060645", "0", "1"], ["83983.4", "0.05452325", "0", "2"], ["83984.1", "0.00011161", "0", "1"], ["83986", "0", "0", "0"], ["83986.5", "0", "0", "0"], ["83987.6", "0.22906683", "0", "1"], ["83987.9", "0", "0", "0"], ["83988", "0", "0", "0"], ["83989.3", "0.05628489", "0", "1"], ["83989.8", "0", "0", "0"], ["83991.6", "0.5804518", "0", "1"], ["83992.7", "0.23832771", "0", "1"], ["83995.8", "0.20442955", "0", "1"], ["83997", "0", "0", "0"], ["83999.9", "0.00101534", "0", "2"], ["84001.6", "0.0008", "0", "2"], ["84002.4", "0.0004", "0", "1"], ["84009.6", "0.07999999", "0", "2"], ["84009.7", "0", "0", "0"], ["84016", "0.00001198", "0", "1"], ["84016.8", "0", "0", "0"], ["84022.9", "0.01788579", "0", "4"], ["84026.4", "0", "0", "0"], ["84039", "0.044979", "0", "1"], ["84041.9", "0.05628489", "0", "1"], ["84044", "0.52683011", "0", "2"], ["84046.4", "0.07138915", "0", "1"], ["84058.8", "0.00592856", "0", "2"], ["84060.3", "0", "0", "0"], ["84067.6", "0.00579953", "0", "1"], ["84099.9", "1.623665", "0", "4"], ["84116.4", "0", "0", "0"], ["84123.8", "0", "0", "0"], ["84124.9", "0", "0", "0"], ["84125", "0", "0", "0"], ["84125.1", "0", "0", "0"], ["84125.3", "0", "0", "0"], ["84125.9", "0", "0", "0"], ["84126.2", "0", "0", "0"], ["84126.6", "0", "0", "0"], ["84127.5", "0", "0", "0"]], "bids": [["83966.6", "0", "0", "0"], ["83965.1", "0", "0", "0"], ["83964.4", "0", "0", "0"], ["83962.6", "0.0612064", "0", "2"], ["83960.6", "0", "0", "0"], ["83960.5", "0", "0", "0"], ["83960", "0.04391", "0", "2"], ["83958", "0.16146978", "0", "5"], ["83957.9", "0.16297931", "0", "1"], ["83956.6", "0.00001199", "0", "1"], ["83954.4", "0", "0", "0"], ["83954.2", "0", "0", "0"], ["83954", "0", "0", "0"], ["83953.9", "0", "0", "0"], ["83953.4", "0.1912308", "0", "1"], ["83953.2", "0", "0", "0"], ["83953", "0.0428883", "0", "1"], ["83952.3", "0.18761632", "0", "1"], ["83952", "0.01191677", "0", "1"], ["83951.4", "0", "0", "0"], ["83949.9", "0.00060645", "0", "1"], ["83949.8", "0", "0", "0"], ["83949.2", "0.04", "0", "1"], ["83948.4", "0.00006", "0", "1"], ["83947.6", "0.01389", "0", "1"], ["83945.8", "0.05956073", "0", "1"], ["83945.6", "0", "0", "0"], ["83944.1", "0.35728", "0", "1"], ["83942.4", "0", "0", "0"], ["83940.4", "0.00357", "0", "1"], ["83939.5", "0.66458921", "0", "1"], ["83939.3", "1", "0", "1"], ["83938.9", "0.11919142", "0", "1"], ["83937.1", "0", "0", "0"], ["83936.3", "0.02391898", "0", "2"], ["83936.1", "0.28797605", "0", "1"], ["83935.2", "0", "0", "0"], ["83934.6", "0", "0", "0"], ["83933", "0.23832834", "0", "1"], ["83932.8", "0", "0", "0"], ["83932.1", "0.77703772", "0", "1"], ["83932", "0.471655", "0", "2"], ["83931.4", "0", "0", "0"], ["83931.2", "0.08", "0", "2"], ["83931", "1", "0", "1"], ["83930.4", "0.0408", "0", "3"], ["83929.6", "0.05133774", "0", "3"], ["83928.8", "0.026", "0", "2"], ["83928", "0.02490494", "0", "2"], ["83927.2", "0", "0", "0"], ["83926.4", "0", "0", "0"], ["83925.6", "0.21889794", "0", "3"], ["83924.8", "0.05", "0", "1"], ["83919.4", "0.67444708", "0", "1"], ["83916.1", "0.57993403", "0", "1"], ["83911.7", "0.00357", "0", "1"], ["83903.2", "0.12505", "0", "1"], ["83895.6", "0", "0", "0"], ["83885.6", "1.19109072", "0", "1"], ["83883.1", "0", "0", "0"], ["83881.7", "0.07152929", "0", "1"], ["83878.2", "0.00018351", "0", "1"], ["83862.4", "0", "0", "0"], ["83836.7", "0.00001", "0", "1"], ["83815.3", "0.00018461", "0", "1"], ["83815", "0.35776874", "0", "1"], ["83814.9", "0.0073937", "0", "2"], ["83814.4", "0.00005519", "0", "1"], ["83814.1", "0.00003395", "0", "1"]], "ts": "1742577062700", "checksum": -2128253355, "seqId": 49944992104, "prevSeqId": 49944991738}], "record_time": 1742577062.872786, "EXCHANGE": "OKX"}
{"arg": {"channel": "books", "instId": "BTC-USDT"}, "action": "update", "data": [{"asks": [["83962.7", "1.13381988", "0", "13"], ["83965.1", "0.06484262", "0", "1"], ["83965.2", "0.0102", "0", "1"], ["84005.2", "0.06017668", "0", "1"], ["84007.2", "0.1", "0", "1"], ["84011.2", "0.01190318", "0", "1"], ["84046.4", "0.1427783", "0", "2"], ["84123.6", "0", "0", "0"], ["84123.7", "0", "0", "0"]], "bids": [["83959", "0.0025", "0", "1"], ["83957.9", "0.44386199", "0", "2"], ["83955.2", "1", "0", "1"], ["83954.1", "0.01191647", "0", "1"], ["83952", "0", "0", "0"], ["83946.2", "0.17814594", "0", "2"], ["83945.4", "0.34303931", "0", "1"], ["83945.2", "0.17865", "0", "1"], ["83940.7", "0.0016395", "0", "1"], ["83940.5", "0", "0", "0"], ["83939.5", "0.91727299", "0", "2"], ["83939.3", "0", "0", "0"], ["83938", "0.05837808", "0", "3"], ["83907.9", "0.03", "0", "1"], ["83900", "0.00121483", "0", "4"], ["83899.1", "0", "0", "0"], ["83898.7", "0", "0", "0"], ["83895.8", "0.00319336", "0", "2"], ["83894.6", "0.00145261", "0", "1"], ["83885.6", "0.45603031", "0", "1"], ["83881.7", "0.14305858", "0", "2"], ["83814.4", "0", "0", "0"], ["83814.1", "0", "0", "0"]], "ts": "1742577062800", "checksum": -568897051, "seqId": 49944992168, "prevSeqId": 49944992104}], "record_time": 1742577062.972993, "EXCHANGE": "OKX"}
{"arg": {"channel": "books", "instId": "BTC-USDT"}, "action": "update", "data": [{"asks": [["83962.7", "1.16747918", "0", "16"], ["83963.9", "0.07005175", "0", "2"], ["83965.1", "0", "0", "0"], ["83965.2", "0", "0", "0"], ["83965.5", "0", "0", "0"], ["83966.6", "0", "0", "0"], ["83966.7", "0.052", "0", "2"], ["83971.1", "0.054144", "0", "3"], ["83972.5", "0.35697351", "0", "1"], ["83981.9", "0.23834361", "0", "1"], ["83983.4", "0.11923538", "0", "3"], ["83992.7", "0", "0", "0"], ["84008.8", "0.07999999", "0", "2"], ["84009.6", "0.03999999", "0", "1"], ["84010.4", "0.26238", "0", "1"], ["84096", "0.00601831", "0", "2"], ["84100.9", "0", "0", "0"], ["84107", "0.00120451", "0", "3"], ["84112.8", "0.01786509", "0", "3"], ["84122.1", "0", "0", "0"], ["84123.6", "0.00126715", "0", "1"], ["84123.7", "0.00005514", "0", "1"]], "bids": [["83962.6", "0.0119164", "0", "2"], ["83960", "0.00001", "0", "1"], ["83959.9", "0", "0", "0"], ["83959.5", "0", "0", "0"], ["83958.1", "0", "0", "0"], ["83958", "0.11756978", "0", "4"], ["83957.9", "0", "0", "0"], ["83955.2", "0", "0", "0"], ["83954.1", "0", "0", "0"], ["83953.4", "0.46791892", "0", "2"], ["83952", "1", "0", "1"], ["83951.9", "0.01389", "0", "1"], ["83951.5", "0.000015", "0", "1"], ["83951", "0.08091692", "0", "3"], ["83947.8", "0", "0", "0"], ["83946.5", "0", "0", "0"], ["83946.2", "0.04329594", "0", "1"], ["83945.4", "0.2118919", "0", "1"], ["83945.2", "0", "0", "0"], ["83944.5", "0.04", "0", "1"], ["83944.1", "0", "0", "0"], ["83942.7", "0", "0", "0"], ["83941.6", "0.3573", "0", "1"], ["83940.7", "0", "0", "0"], ["83939.5", "0.66458921", "0", "1"], ["83938.6", "0", "0", "0"], ["83938", "0.05765808", "0", "2"], ["83936.1", "0.12000632", "0", "1"], ["83936", "0", "0", "0"], ["83934.2", "0", "0", "0"], ["83933", "0", "0", "0"], ["83932.1", "1.22131913", "0", "2"], ["83931.2", "0", "0", "0"], ["83931", "0", "0", "0"], ["83930.4", "0", "0", "0"], ["83929.9", "0", "0", "0"], ["83929.6", "0.045038", "0", "1"], ["83929.3", "0", "0", "0"], ["83929.2", "1.58625091", "0", "1"], ["83928.8", "0.0808", "0", "4"], ["83928", "0.05230494", "0", "3"], ["83927.5", "0.01190515", "0", "1"], ["83927.2", "0.026", "0", "2"], ["83926.4", "0.013", "0", "1"], ["83925.7", "0.23834361", "0", "1"], ["83925.6", "0.11889794", "0", "1"], ["83924.8", "0", "0", "0"], ["83923.2", "0.1", "0", "2"], ["83922.4", "0.05", "0", "1"], ["83916.8", "0.01788446", "0", "1"], ["83914.5", "0.01190877", "0", "2"], ["83913.5", "0", "0", "0"], ["83898.3", "0.00595502", "0", "1"], ["83895.9", "0.00595502", "0", "1"], ["83894.7", "0.00595502", "0", "1"], ["83885.6", "0.65545999", "0", "2"], ["83878.2", "0", "0", "0"], ["83876.9", "0", "0", "0"], ["83874.3", "0.01710168", "0", "1"], ["83865.2", "0.0058998", "0", "1"], ["83858.4", "0.0116996", "0", "2"], ["83857.2", "0.07165719", "0", "1"], ["83846.5", "0", "0", "0"], ["83834.7", "0.00595503", "0", "1"], ["83829.7", "0", "0", "0"], ["83818", "0.01786509", "0", "3"], ["83814.4", "0.00005519", "0", "1"], ["83814.1", "0.00003395", "0", "1"], ["83813.6", "0.03", "0", "1"], ["83813.5", "0.00002031", "0", "1"], ["83813.2", "0.0142", "0", "1"], ["83813.1", "0.00001199", "0", "1"]], "ts": "1742577062900", "checksum": -1245268354, "seqId": 49944992351, "prevSeqId": 49944992168}], "record_time": 1742577063.073528, "EXCHANGE": "OKX"}
{"arg": {"channel": "books", "instId": "BTC-USDT"}, "action": "update", "data": [{"asks": [["83962.7", "1.24129944", "0", "19"], ["83963.9", "0.06127871", "0", "2"], ["83964.4", "0.0006005", "0", "1"], ["83965.6", "0.08991011", "0", "1"], ["83966.2", "0", "0", "0"], ["83966.5", "0.03376319", "0", "2"], ["83967.5", "0.00774154", "0", "1"], ["83969.6", "0.02", "0", "1"], ["83970.8", "0.35179776", "0", "1"], ["83972.4", "0.29788519", "0", "2"], ["83972.7", "0", "0", "0"], ["83972.9", "0.17865", "0", "1"], ["83973.6", "0", "0", "0"], ["83974.9", "0.0102", "0", "1"], ["83975.8", "0.04", "0", "1"], ["83976.4", "0.06", "0", "2"], ["83979.4", "0", "0", "0"], ["83979.8", "0.03", "0", "1"], ["83980.4", "0", "0", "0"], ["83981.3", "0.00001199", "0", "1"], ["83981.4", "0", "0", "0"], ["83981.9", "0.23834402", "0", "1"], ["83982.6", "0", "0", "0"], ["83982.8", "0.03", "0", "1"], ["83983.4", "0.34773487", "0", "3"], ["83983.5", "0.036", "0", "1"], ["83984.2", "1", "0", "1"], ["83987.5", "0.25906683", "0", "2"], ["83987.6", "0", "0", "0"], ["84000.2", "0.32572681", "0", "1"], ["84000.6", "0.53451", "0", "1"], ["84012.6", "0.17580175", "0", "2"], ["84013", "0.02310614", "0", "1"], ["84014", "0.01786377", "0", "1"], ["84017.7", "0.18944577", "0", "1"], ["84018.9", "0", "0", "0"], ["84029.1", "0.00595474", "0", "1"], ["84029.5", "0", "0", "0"], ["84029.9", "0.30515066", "0", "1"], ["84030", "0", "0", "0"], ["84031", "0.21405021", "0", "2"], ["84051.2", "0.02163319", "0", "2"], ["84055", "1.22621378", "0", "2"], ["84055.2", "0", "0", "0"], ["84056.7", "3.56121", "0", "1"], ["84060.1", "0.03430839", "0", "2"], ["84060.2", "0", "0", "0"], ["84061.7", "0.0214", "0", "1"], ["84061.8", "0.0856", "0", "4"], ["84081.2", "0", "0", "0"], ["84082.1", "0", "0", "0"], ["84086.9", "0.0142", "0", "1"], ["84087", "0.0426", "0", "3"], ["84087.2", "0.0426", "0", "3"], ["84098.1", "0.05359131", "0", "1"], ["84105.9", "0", "0", "0"], ["84106.4", "0", "0", "0"], ["84108.6", "0", "0", "0"], ["84111.3", "0.69209544", "0", "1"], ["84118.9", "0", "0", "0"], ["84121.5", "0", "0", "0"], ["84122.2", "0", "0", "0"], ["84123.3", "0", "0", "0"], ["84123.6", "0", "0", "0"], ["84123.7", "0", "0", "0"]], "bids": [["83958", "0.06128489", "0", "3"], ["83956.2", "0", "0", "0"], ["83954.7", "0.11916893", "0", "1"], ["83953.4", "0.0606587", "0", "1"], ["83953", "0", "0", "0"], ["83952.8", "0", "0", "0"], ["83952", "0", "0", "0"], ["83951", "0", "0", "0"], ["83950.3", "0", "0", "0"], ["83949.3", "0.59557526", "0", "2"], ["83949.2", "0", "0", "0"], ["83948.9", "0.0428883", "0", "1"], ["83948.4", "0.01197728", "0", "2"], ["83948.2", "1", "0", "1"], ["83947.7", "0", "0", "0"], ["83946.8", "0.04", "0", "1"], ["83946.2", "0", "0", "0"], ["83944.5", "0", "0", "0"], ["83941.6", "0", "0", "0"], ["83940.7", "0.04", "0", "1"], ["83940.1", "0.17865", "0", "1"], ["83939.9", "0.0044685", "0", "1"], ["83939.7", "0.04329594", "0", "1"], ["83939.5", "0.49052651", "0", "1"], ["83937.2", "0", "0", "0"], ["83936.7", "0", "0", "0"], ["83936.1", "0.23920174", "0", "2"], ["83936", "0.00036", "0", "1"], ["83928.8", "0", "0", "0"], ["83928.3", "0.33401045", "0", "2"], ["83928.1", "0", "0", "0"], ["83928", "0.01190494", "0", "1"], ["83927.2", "0", "0", "0"], ["83926.7", "0", "0", "0"], ["83926.4", "0.580152", "0", "1"], ["83925.7", "0.23834402", "0", "1"], ["83925.6", "0.19969794", "0", "5"], ["83925", "0", "0", "0"], ["83924.9", "0", "0", "0"], ["83924.8", "0.0404", "0", "2"], ["83924.1", "0", "0", "0"], ["83924", "0.02636", "0", "3"], ["83923.2", "0.013", "0", "1"], ["83922.5", "0.5776526", "0", "1"], ["83922.4", "0", "0", "0"], ["83920", "0.10001", "0", "3"], ["83919.4", "0.34588223", "0", "1"], ["83919.2", "0.05", "0", "1"], ["83917", "0.00073199", "0", "2"], ["83916.1", "0", "0", "0"], ["83916", "0.05664489", "0", "2"], ["83913.8", "0.02384542", "0", "1"], ["83905.7", "0", "0", "0"], ["83900.1", "0", "0", "0"], ["83898.7", "0.04454905", "0", "1"], ["83898.2", "0", "0", "0"], ["83895.2", "0", "0", "0"], ["83891.9", "0", "0", "0"], ["83887", "0.09531952", "0", "2"], ["83885.6", "1.43546512", "0", "1"], ["83884.6", "0", "0", "0"], ["83880.5", "0.58226341", "0", "1"], ["83880.1", "0.00589943", "0", "1"], ["83878.2", "0.00589952", "0", "1"], ["83877.3", "0", "0", "0"], ["83875.1", "0", "0", "0"], ["83874.7", "0.00018351", "0", "1"], ["83873.6", "0.00579953", "0", "1"], ["83872", "0.00589952", "0", "1"], ["83870.7", "0", "0", "0"], ["83869.6", "0.00001198", "0", "1"], ["83867.6", "0.00579953", "0", "1"], ["83863.3", "0.01184047", "0", "3"], ["83863.2", "0.00589952", "0", "1"], ["83860", "0.00615953", "0", "2"], ["83857.4", "0.01179884", "0", "2"], ["83857.3", "0.0059115", "0", "2"], ["83857.2", "0.00579953", "0", "1"], ["83857.1", "0.01251208", "0", "6"], ["83856.5", "0.02382008", "0", "1"], ["83816.6", "0.00060645", "0", "1"], ["83816.5", "0", "0", "0"], ["83813", "0.0008235", "0", "1"], ["83812.5", "0.00667459", "0", "3"], ["83811.9", "0.0010552", "0", "1"], ["83811.3", "0.00074812", "0", "1"], ["83810.8", "0.0054", "0", "1"], ["83810.1", "0.00001655", "0", "1"], ["83809.8", "0.01433882", "0", "2"], ["83809.7", "0.00001075", "0", "1"], ["83809.2", "0.2025", "0", "1"]], "ts": "1742577063000", "checksum": -206896164, "seqId": 49944992666, "prevSeqId": 49944992351}], "record_time": 1742577063.179998, "EXCHANGE": "OKX"}
{"arg": {"channel": "books", "instId": "BTC-USDT"}, "action": "update", "data": [{"asks": [["83962.7", "1.25603344", "0", "21"], ["83963.7", "0.09524006", "0", "1"], ["83963.8", "0.11915624", "0", "1"], ["83963.9", "0", "0", "0"], ["83966.2", "0.02", "0", "1"], ["83969.6", "0", "0", "0"], ["83979.7", "0.06", "0", "2"], ["83980.4", "0.05954961", "0", "1"], ["83981.9", "0", "0", "0"], ["83984.2", "0", "0", "0"], ["83985.5", "1", "0", "1"], ["83986.8", "0.23833703", "0", "1"], ["83987.6", "0.01190652", "0", "1"], ["83989.3", "0.11256978", "0", "2"], ["83990.9", "0.14911771", "0", "2"], ["84004.5", "0.11681159", "0", "2"], ["84013.8", "0", "0", "0"], ["84024.4", "0", "0", "0"], ["84024.9", "0", "0", "0"], ["84025.9", "0.01130746", "0", "2"], ["84027", "0.0309513", "0", "2"], ["84033.8", "0", "0", "0"], ["84035.8", "0.02978643", "0", "3"], ["84041.9", "0", "0", "0"], ["84045.8", "0.02382011", "0", "1"], ["84049", "0.01368", "0", "1"], ["84063.5", "0", "0", "0"], ["84080.5", "0.00251862", "0", "1"], ["84086.2", "0.002382", "0", "1"], ["84120", "0", "0", "0"]], "bids": [["83958", "0.005", "0", "2"], ["83957.6", "0", "0", "0"], ["83956.5", "0.11916637", "0", "1"], ["83954.7", "0", "0", "0"], ["83953.4", "0", "0", "0"], ["83952.4", "0.0606587", "0", "1"], ["83949.3", "0.54967526", "0", "2"], ["83948.2", "0", "0", "0"], ["83947.7", "1", "0", "1"], ["83941", "0", "0", "0"], ["83940.7", "0", "0", "0"], ["83940.4", "0.08757", "0", "3"], ["83939.9", "0", "0", "0"], ["83938.4", "0.04", "0", "1"], ["83938.3", "0.17898725", "0", "1"], ["83937.3", "0.5644685", "0", "2"], ["83935.7", "0", "0", "0"], ["83933", "0.00476571", "0", "1"], ["83931.4", "0.23833703", "0", "1"], ["83928.3", "0.19618624", "0", "1"], ["83926.4", "0", "0", "0"], ["83925.7", "0", "0", "0"], ["83917.5", "0", "0", "0"], ["83916", "0.16467978", "0", "4"], ["83911.7", "0.58340988", "0", "2"], ["83909.1", "0.01835263", "0", "1"], ["83898.8", "0.00579929", "0", "1"], ["83896", "0.00579929", "0", "1"], ["83895.7", "0", "0", "0"], ["83894.8", "0.00579929", "0", "1"], ["83894.6", "0.00735189", "0", "2"], ["83894.5", "0", "0", "0"], ["83890.3", "0.00579929", "0", "1"], ["83888.7", "0.00589928", "0", "1"], ["83888.6", "0", "0", "0"], ["83887.4", "0", "0", "0"], ["83883", "0.6", "0", "1"], ["83882", "0.01205857", "0", "3"], ["83880.1", "0", "0", "0"], ["83877.1", "0", "0", "0"], ["83876.2", "0.1636435", "0", "2"], ["83875.8", "0.07166249", "0", "1"], ["83875.1", "0.00579929", "0", "1"], ["83875", "0.01401155", "0", "3"], ["83874.6", "0", "0", "0"], ["83874.5", "0", "0", "0"], ["83870.9", "0", "0", "0"], ["83870.8", "0", "0", "0"], ["83869.7", "0", "0", "0"], ["83868.4", "0.00579929", "0", "1"], ["83867.5", "0.000015", "0", "1"], ["83866.7", "0.00595656", "0", "2"], ["83866.5", "0", "0", "0"], ["83865.1", "0", "0", "0"], ["83860.1", "0.00579929", "0", "1"], ["83859.8", "0.20839928", "0", "2"], ["83857.4", "0.01759813", "0", "3"], ["83853", "0.00589928", "0", "1"], ["83851.4", "0.00579929", "0", "1"], ["83848.2", "0.05732575", "0", "1"], ["83844.7", "0.00005731", "0", "1"], ["83838.1", "0.18352633", "0", "1"], ["83824.2", "0.20833794", "0", "2"], ["83814.4", "0.00013754", "0", "2"], ["83813.2", "0", "0", "0"], ["83808", "0.00014075", "0", "1"], ["83807.9", "0.00001018", "0", "1"], ["83807.5", "0.03", "0", "1"], ["83807.4", "0.11889794", "0", "1"], ["83807.3", "0.00011161", "0", "1"], ["83807.1", "0.00001527", "0", "1"]], "ts": "1742577063100", "checksum": -997256900, "seqId": 49944992793, "prevSeqId": 49944992666}], "record_time": 1742577063.273991, "EXCHANGE": "OKX"}
{"arg": {"channel": "books", "instId": "BTC-USDT"}, "action": "update", "data": [{"asks": [["83962.7", "1.25549944", "0", "20"], ["83963.9", "0.02", "0", "1"], ["83965.6", "0", "0", "0"], ["83966.2", "0", "0", "0"], ["83966.5", "0.13513396", "0", "1"], ["83969.3", "0.3573", "0", "1"], ["83972.9", "0", "0", "0"], ["83980.3", "0.71628639", "0", "2"], ["83986.9", "0", "0", "0"], ["83987.5", "0.22906683", "0", "1"], ["83990.9", "0.11911771", "0", "1"], ["84023.8", "0.824795", "0", "1"], ["84032.8", "0.01428013", "0", "1"]], "bids": [["83958", "0.0489", "0", "3"], ["83956.5", "0", "0", "0"], ["83954.2", "0.00773282", "0", "1"], ["83952.4", "0.35307636", "0", "2"], ["83951.5", "1.000015", "0", "2"], ["83949.3", "0.32090223", "0", "1"], ["83947.7", "0", "0", "0"], ["83941.5", "0.20385", "0", "3"], ["83939.5", "0.26084006", "0", "1"], ["83938.1", "0.069", "0", "2"], ["83937.3", "0", "0", "0"], ["83936.7", "0.22038473", "0", "1"], ["83936.6", "0.3573", "0", "1"], ["83936.1", "0.11919542", "0", "1"], ["83928.3", "0.11298492", "0", "1"], ["83923.7", "0.64892219", "0", "1"], ["83923.6", "0.56", "0", "1"], ["83923.5", "0", "0", "0"], ["83910.8", "0.825904", "0", "1"], ["83898.7", "0.11401338", "0", "2"], ["83896.3", "0.25011", "0", "1"], ["83880.7", "0.22889868", "0", "2"], ["83880", "0.0000366", "0", "1"], ["83868.4", "0.02623172", "0", "2"], ["83808", "0", "0", "0"], ["83807.9", "0", "0", "0"], ["83807.5", "0", "0", "0"], ["83807.4", "0", "0", "0"], ["83807.3", "0", "0", "0"], ["83807.1", "0", "0", "0"]], "ts": "1742577063200", "checksum": -308580089, "seqId": 49944992854, "prevSeqId": 49944992793}], "record_time": 1742577063.372065, "EXCHANGE": "OKX"}
{"arg": {"channel": "books", "instId": "BTC-USDT"}, "action": "update", "data": [{"asks": [["83962.7", "1.44611106", "0", "21"], ["83963.6", "0.000039", "0", "1"], ["83963.7", "0.06826702", "0", "1"], ["83965.1", "0.00111991", "0", "1"], ["83970.3", "0.17865", "0", "1"], ["83971.1", "0.052", "0", "2"], ["83971.5", "0.01249171", "0", "2"], ["83973.7", "0", "0", "0"], ["83983.9", "0.23834275", "0", "1"], ["83986.8", "0", "0", "0"], ["84012.6", "0.15297006", "0", "1"], ["84020.8", "0.14256978", "0", "3"], ["84065.3", "0.1", "0", "1"], ["84084.6", "0.05732575", "0", "1"], ["84117.8", "0", "0", "0"], ["84119", "0", "0", "0"], ["84119.4", "0", "0", "0"]], "bids": [["83958", "0.005", "0", "2"], ["83956.5", "0.00056076", "0", "1"], ["83943.8", "0.01542962", "0", "2"], ["83943.4", "0.01153238", "0", "1"], ["83941.7", "0.00452802", "0", "2"], ["83940.6", "0", "0", "0"], ["83932.1", "0.44428141", "0", "1"], ["83931.5", "0.08585", "0", "1"], ["83931.4", "0", "0", "0"], ["83929.2", "0", "0", "0"], ["83928.6", "0.23834275", "0", "1"], ["83928.5", "0.17865", "0", "1"], ["83911.5", "0.46055225", "0", "1"], ["83909.9", "0", "0", "0"], ["83876.2", "0.72584499", "0", "3"], ["83873.5", "0.09054963", "0", "1"], ["83868.4", "0.21598158", "0", "3"], ["83865", "0.11435141", "0", "1"], ["83859.9", "0.20545028", "0", "2"], ["83809.8", "0", "0", "0"], ["83809.7", "0", "0", "0"], ["83809.2", "0", "0", "0"]], "ts": "1742577063300", "checksum": 1315008956, "seqId": 49944992906, "prevSeqId": 49944992854}], "record_time": 1742577063.472626, "EXCHANGE": "OKX"}
{"arg": {"channel": "books", "instId": "BTC-USDT"}, "action": "update", "data": [{"asks": [["83962.8", "0.00357335", "0", "1"], ["83966.8", "0", "0", "0"], ["83995", "0.2", "0", "1"], ["84003.5", "0.01962952", "0", "1"], ["84018.3", "0", "0", "0"], ["84025.9", "0.00001198", "0", "1"], ["84030.9", "0.01129562", "0", "1"], ["84117.3", "0", "0", "0"], ["84117.6", "0", "0", "0"]], "bids": [["83962.6", "0.0119364", "0", "3"], ["83958", "0.0489", "0", "3"], ["83945.4", "0.15081139", "0", "1"], ["83941.9", "0", "0", "0"], ["83941.8", "0.00001199", "0", "1"], ["83941.7", "0.00005952", "0", "1"], ["83927.8", "1.56225522", "0", "1"], ["83913.9", "0.01835264", "0", "1"], ["83909.1", "0", "0", "0"], ["83898.4", "2.80235475", "0", "1"], ["83842.2", "0.18352647", "0", "1"], ["83838.1", "0", "0", "0"], ["83810.1", "0", "0", "0"]], "ts": "1742577063400", "checksum": -420642322, "seqId": 49944992930, "prevSeqId": 49944992906}], "record_time": 1742577063.572215, "EXCHANGE": "OKX"}
{"arg": {"channel": "books", "instId": "BTC-USDT"}, "action": "update", "data": [{"asks": [["83962.7", "0.5251827", "0", "10"], ["83963.6", "0", "0", "0"], ["83963.7", "0.06449507", "0", "2"], ["83963.8", "0", "0", "0"], ["83964.9", "0.0102", "0", "1"], ["83969.3", "0", "0", "0"], ["83970.3", "0", "0", "0"], ["83975.5", "0.08499274", "0", "1"], ["83976.9", "0", "0", "0"], ["83983.4", "0.10123636", "0", "2"], ["83983.9", "0", "0", "0"], ["83985.5", "0", "0", "0"], ["83992.7", "0.23832149", "0", "1"], ["83995", "0", "0", "0"], ["84007.3", "0.002144", "0", "1"], ["84013", "0", "0", "0"], ["84117.3", "0.214308", "0", "1"], ["84117.6", "0.18342405", "0", "2"], ["84117.8", "0.01493332", "0", "1"], ["84119", "0.35658448", "0", "2"], ["84119.4", "0.08761", "0", "1"], ["84120", "0.00006444", "0", "2"]], "bids": [["83962.6", "0.62130984", "0", "8"], ["83962", "0.0439", "0", "1"], ["83960.8", "0.11916032", "0", "1"], ["83960", "0.04391", "0", "2"], ["83955.9", "0.72004336", "0", "2"], ["83955.8", "1", "0", "1"], ["83954.2", "0.21023282", "0", "2"], ["83952.9", "0.0606587", "0", "1"], ["83952.4", "0", "0", "0"], ["83951.5", "0.000015", "0", "1"], ["83951.2", "0.01191689", "0", "1"], ["83951", "0.01389", "0", "1"], ["83948.4", "0.00006", "0", "1"], ["83947.6", "0", "0", "0"], ["83945.2", "0.17865", "0", "1"], ["83938.5", "0.23832149", "0", "1"], ["83931", "0.17865", "0", "1"], ["83928.6", "0", "0", "0"], ["83928.3", "0.56753837", "0", "2"], ["83898.7", "0.94603676", "0", "1"], ["83883", "0", "0", "0"], ["83876.2", "0.1636435", "0", "2"], ["83868.4", "0.02623172", "0", "2"], ["83866.8", "0.07165719", "0", "1"], ["83865", "0", "0", "0"], ["83859.9", "0.00579953", "0", "1"], ["83813.1", "0", "0", "0"], ["83813", "0", "0", "0"], ["83812.5", "0", "0", "0"], ["83811.9", "0", "0", "0"], ["83811.3", "0", "0", "0"], ["83810.8", "0", "0", "0"]], "ts": "1742577063500", "checksum": -77992179, "seqId": 49944993019, "prevSeqId": 49944992930}], "record_time": 1742577063.672801, "EXCHANGE": "OKX"}
{"arg": {"channel": "books", "instId": "BTC-USDT"}, "action": "update", "data": [{"asks": [["83962.7", "0.33690223", "0", "7"], ["83963.7", "0.03285612", "0", "1"], ["83963.9", "0", "0", "0"], ["83964.9", "0", "0", "0"], ["83966.5", "0.04320094", "0", "2"], ["83966.7", "0", "0", "0"], ["83967.3", "0.0428883", "0", "1"], ["83967.6", "0.02", "0", "1"], ["83968.5", "0.04242847", "0", "1"], ["83971.5", "0.00095933", "0", "1"], ["83971.6", "0", "0", "0"], ["83975.8", "0", "0", "0"], ["83976.2", "0.01153238", "0", "1"], ["83977.5", "0.03062", "0", "1"], ["83980.4", "0", "0", "0"], ["83980.7", "0.04", "0", "1"], ["83983.4", "0.03652325", "0", "2"], ["83983.5", "0.04790711", "0", "2"], ["83989.2", "0.23832519", "0", "1"], ["83992.7", "0", "0", "0"], ["84005.7", "0", "0", "0"], ["84121.5", "0.00011161", "0", "1"]], "bids": [["83962.6", "0.64050984", "0", "9"], ["83960.9", "0.0643411", "0", "1"], ["83957.3", "0.64932097", "0", "2"], ["83955.9", "0.35697351", "0", "1"], ["83955.8", "0", "0", "0"], ["83955.7", "1", "0", "1"], ["83953.4", "0.01191658", "0", "1"], ["83953.1", "0.0428883", "0", "1"], ["83951.2", "0", "0", "0"], ["83951", "0.05557", "0", "2"], ["83948.9", "0", "0", "0"], ["83945.1", "0", "0", "0"], ["83944", "0.04", "0", "1"], ["83942.2", "0.02762399", "0", "2"], ["83940.1", "0", "0", "0"], ["83938.7", "0.00476538", "0", "1"], ["83938.5", "0", "0", "0"], ["83938.4", "0.31", "0", "1"], ["83936.6", "0", "0", "0"], ["83934.4", "0.23832519", "0", "1"], ["83933", "0", "0", "0"], ["83932.2", "0.01774536", "0", "1"], ["83931", "0", "0", "0"], ["83930.8", "0", "0", "0"], ["83928.5", "0", "0", "0"], ["83876.2", "0.11889794", "0", "1"], ["83873.5", "0", "0", "0"], ["83813.1", "0.00001199", "0", "1"], ["83813", "0.0008235", "0", "1"], ["83812.5", "0.00667459", "0", "3"]], "ts": "1742577063600", "checksum": -2061753830, "seqId": 49944993095, "prevSeqId": 49944993019}], "record_time": 1742577063.773747, "EXCHANGE": "OKX"}
{"arg": {"channel": "books", "instId": "BTC-USDT"}, "action": "update", "data": [{"asks": [["83962.7", "0.44075439", "0", "17"], ["83967.6", "0", "0", "0"], ["83969", "0.0102", "0", "1"], ["83969.6", "0.02", "0", "1"], ["83970.8", "0.35308926", "0", "2"], ["83974.4", "0.3573", "0", "1"], ["83987.1", "0.02378", "0", "1"], ["83994", "1", "0", "1"], ["84119", "0", "0", "0"], ["84119.4", "0", "0", "0"], ["84120", "0", "0", "0"], ["84121.5", "0", "0", "0"]], "bids": [["83962.6", "0.35234142", "0", "6"], ["83958", "0.0464", "0", "2"], ["83955.7", "0", "0", "0"], ["83953.9", "1", "0", "1"], ["83951", "0.04168", "0", "1"], ["83945.4", "0.29227381", "0", "2"], ["83944.1", "0.3573", "0", "1"], ["83938.3", "0.42909725", "0", "2"], ["83896.3", "0", "0", "0"], ["83880.7", "0.13851515", "0", "1"]], "ts": "1742577063700", "checksum": 243815171, "seqId": 49944993127, "prevSeqId": 49944993095}], "record_time": 1742577063.874966, "EXCHANGE": "OKX"}
{"arg": {"channel": "books", "instId": "BTC-USDT"}, "action": "update", "data": [{"asks": [["83962.7", "0.45859337", "0", "18"]], "bids": [["83959", "0", "0", "0"], ["83955.1", "0.01389", "0", "1"], ["83946.4", "0.069", "0", "2"], ["83943.1", "0.06901501", "0", "3"], ["83939.5", "0.40505711", "0", "2"], ["83938.6", "0.17865", "0", "1"], ["83880.7", "0", "0", "0"], ["83812.5", "0", "0", "0"]], "ts": "1742577063800", "checksum": 980487768, "seqId": 49944993143, "prevSeqId": 49944993127}], "record_time": 1742577063.971831, "EXCHANGE": "OKX"}
{"arg": {"channel": "books", "instId": "BTC-USDT"}, "action": "update", "data": [{"asks": [["83962.7", "0.66109337", "0", "19"], ["83962.8", "0", "0", "0"], ["83966.5", "0.08049275", "0", "1"], ["83967.3", "0.16203954", "0", "2"], ["83969", "0", "0", "0"], ["83971.2", "0.03062", "0", "1"], ["83977.5", "0", "0", "0"], ["83986.8", "1", "0", "1"], ["83992.5", "0.00357335", "0", "1"], ["83994", "0", "0", "0"], ["84119", "0.35658448", "0", "2"]], "bids": [["83962.6", "0.18384998", "0", "3"], ["83962", "0", "0", "0"], ["83960.9", "0", "0", "0"], ["83957.3", "0.28857097", "0", "2"], ["83955.1", "0", "0", "0"], ["83954.2", "0.00773282", "0", "1"], ["83953.9", "0", "0", "0"], ["83952.9", "0.35307636", "0", "2"], ["83952.6", "1", "0", "1"], ["83951", "0.01389", "0", "1"], ["83945.2", "0", "0", "0"], ["83944.7", "0.04168", "0", "1"], ["83941.5", "0.16785", "0", "2"], ["83938.6", "0", "0", "0"], ["83938.1", "0.036", "0", "1"], ["83930", "1", "0", "1"], ["83866.8", "0", "0", "0"], ["83812.5", "0.00667459", "0", "3"], ["83811.9", "0.0010552", "0", "1"], ["83811.3", "0.00074812", "0", "1"], ["83810.8", "0.0054", "0", "1"]], "ts": "1742577063900", "checksum": -813402665, "seqId": 49944993186, "prevSeqId": 49944993143}], "record_time": 1742577064.073828, "EXCHANGE": "OKX"}
{"arg": {"channel": "books", "instId": "BTC-USDT"}, "action": "update", "data": [{"asks": [["83962.7", "0.80352184", "0", "21"], ["83964.9", "0.0102", "0", "1"], ["83968.5", "0", "0", "0"], ["83970.8", "0.35179776", "0", "1"], ["83983.9", "0.23833928", "0", "1"], ["83989.2", "0", "0", "0"]], "bids": [["83941.6", "0.3573", "0", "1"], ["83941.5", "0.13485", "0", "1"], ["83938.1", "0", "0", "0"], ["83936.7", "0", "0", "0"], ["83934.4", "0", "0", "0"], ["83931", "0.17865", "0", "1"], ["83928.4", "0.23833928", "0", "1"]], "ts": "1742577064000", "checksum": 975234498, "seqId": 49944993210, "prevSeqId": 49944993186}], "record_time": 1742577064.17283, "EXCHANGE": "OKX"}
{"arg": {"channel": "books", "instId": "BTC-USDT"}, "action": "update", "data": [{"asks": [["83983.9", "0", "0", "0"], ["83985.2", "0.23833877", "0", "1"], ["83990.6", "0.004315", "0", "2"], ["83991.5", "0.01190597", "0", "1"], ["84000.7", "0", "0", "0"], ["84004.8", "0.08", "0", "2"], ["84005.6", "0.03999999", "0", "1"], ["84008.8", "0", "0", "0"], ["84009.6", "0", "0", "0"], ["84011.2", "0", "0", "0"], ["84017.6", "0.00002157", "0", "1"], ["84022.9", "0.01786422", "0", "3"], ["84030.9", "0", "0", "0"], ["84032", "0.01129675", "0", "1"]], "bids": [["83962.6", "0.18592735", "0", "4"], ["83960", "0.00001", "0", "1"], ["83943.8", "0.00352644", "0", "1"], ["83942.6", "0.17865", "0", "1"], ["83930.3", "0.23833735", "0", "1"], ["83928.4", "0", "0", "0"], ["83920.8", "0.01190597", "0", "1"], ["83915.4", "0.01835181", "0", "1"], ["83913.9", "0", "0", "0"], ["83896", "0.00680604", "0", "2"], ["83895.8", "0", "0", "0"], ["83894.9", "0.00363928", "0", "2"], ["83894.6", "0.00589928", "0", "1"], ["83874.7", "0", "0", "0"], ["83874.4", "0.00018351", "0", "1"], ["83843.3", "0.18351811", "0", "1"], ["83842.2", "0", "0", "0"], ["83811.3", "0", "0", "0"], ["83810.8", "0", "0", "0"]], "ts": "1742577064100", "checksum": 218851353, "seqId": 49944993270, "prevSeqId": 49944993210}], "record_time": 1742577064.273013, "EXCHANGE": "OKX"}
{"arg": {"channel": "books", "instId": "BTC-USDT"}, "action": "update", "data": [{"asks": [["83962.7", "1.01373184", "0", "23"], ["83963.3", "0.001095", "0", "1"], ["83964.9", "0", "0", "0"], ["83985.2", "0.23833531", "0", "1"]], "bids": [["83962.6", "0.01398377", "0", "2"], ["83951", "0", "0", "0"], ["83947.9", "0.01389", "0", "1"], ["83942.2", "0.02751449", "0", "1"], ["83931.4", "0.23833569", "0", "1"], ["83930.3", "0", "0", "0"], ["83930", "0", "0", "0"], ["83811.3", "0.00074812", "0", "1"]], "ts": "1742577064200", "checksum": 2012477277, "seqId": 49944993301, "prevSeqId": 49944993270}], "record_time": 1742577064.373086, "EXCHANGE": "OKX"}
{"arg": {"channel": "books", "instId": "BTC-USDT"}, "action": "update", "data": [{"asks": [["83962.8", "0.00357335", "0", "1"], ["83985.2", "0", "0", "0"], ["83986.7", "0.23833337", "0", "1"], ["83992.5", "0", "0", "0"]], "bids": [["83938.6", "0.004956", "0", "1"], ["83933", "0.23833334", "0", "1"], ["83931.4", "0", "0", "0"], ["83811.3", "0", "0", "0"]], "ts": "1742577064300", "checksum": 426109729, "seqId": 49944993317, "prevSeqId": 49944993301}], "record_time": 1742577064.476949, "EXCHANGE": "OKX"}
{"arg": {"channel": "books", "instId": "BTC-USDT"}, "action": "update", "data": [{"asks": [["83962.7", "0.61123184", "0", "21"], ["83963.3", "0", "0", "0"], ["83970.1", "0.00135", "0", "1"], ["83975.6", "0.002", "0", "1"], ["83985.7", "0.002", "0", "1"], ["83986.7", "0", "0", "0"], ["83986.8", "0", "0", "0"], ["83989.2", "0.23832779", "0", "1"], ["84119", "0", "0", "0"]], "bids": [["83962.6", "0.10654879", "0", "5"], ["83960.7", "0.002", "0", "1"], ["83960", "0.04391", "0", "2"], ["83957.3", "0.6297415", "0", "2"], ["83954.2", "0.21023282", "0", "2"], ["83953.9", "1", "0", "1"], ["83952.9", "0.0606587", "0", "1"], ["83952.6", "0", "0", "0"], ["83950.7", "0.002", "0", "1"], ["83942.6", "0", "0", "0"], ["83941.6", "0", "0", "0"], ["83938.6", "0", "0", "0"], ["83934.4", "0.23832779", "0", "1"], ["83933.1", "0.01774536", "0", "1"], ["83933", "0", "0", "0"], ["83932.2", "0", "0", "0"], ["83931", "0", "0", "0"], ["83923.8", "0.56", "0", "1"], ["83923.7", "0", "0", "0"], ["83923.6", "0", "0", "0"], ["83868.4", "0.21598158", "0", "3"], ["83811.3", "0.00074812", "0", "1"], ["83810.8", "0.0054", "0", "1"], ["83810.1", "0.00001655", "0", "1"]], "ts": "1742577064400", "checksum": -1221236099, "seqId": 49944993365, "prevSeqId": 49944993317}], "record_time": 1742577064.576427, "EXCHANGE": "OKX"}
{"arg": {"channel": "books", "instId": "BTC-USDT"}, "action": "update", "data": [{"asks": [["83997", "0.2", "0", "1"], ["84008.9", "0.471676", "0", "1"], ["84027", "0.02976121", "0", "1"], ["84038.3", "0.17138182", "0", "1"], ["84038.4", "0", "0", "0"], ["84080.5", "0", "0", "0"]], "bids": [["83962", "0.0439", "0", "1"], ["83940.6", "0.0001305", "0", "1"], ["83936", "0.17901", "0", "2"], ["83875", "0.0118726", "0", "2"], ["83871.9", "0", "0", "0"], ["83810.1", "0", "0", "0"]], "ts": "1742577064500", "checksum": -557424008, "seqId": 49944993380, "prevSeqId": 49944993365}], "record_time": 1742577064.672832, "EXCHANGE": "OKX"}
{"arg": {"channel": "books", "instId": "BTC-USDT"}, "action": "update", "data": [{"asks": [], "bids": [["83945.2", "0.17865", "0", "1"], ["83940.6", "0", "0", "0"], ["83908", "0.01072", "0", "3"]], "ts": "1742577064600", "checksum": -557424008, "seqId": 49944993406, "prevSeqId": 49944993380}], "record_time": 1742577064.772355, "EXCHANGE": "OKX"}
{"arg": {"channel": "books", "instId": "BTC-USDT"}, "action": "update", "data": [{"asks": [["83962.7", "0.8136189", "0", "22"], ["83962.8", "0", "0", "0"], ["83986.5", "0.23833423", "0", "1"], ["83986.6", "1", "0", "1"], ["83988.4", "0.003573", "0", "1"], ["83989.2", "0", "0", "0"], ["83996.8", "0.0008", "0", "2"], ["83997.6", "0.0004", "0", "1"], ["84001.6", "0", "0", "0"], ["84002.4", "0", "0", "0"], ["84030.9", "0.00119003", "0", "1"], ["84084.4", "0.00251815", "0", "1"], ["84117.3", "0", "0", "0"], ["84117.6", "0", "0", "0"], ["84117.8", "0", "0", "0"]], "bids": [["83962.6", "0.01399377", "0", "3"], ["83962", "0", "0", "0"], ["83957.3", "0.34932097", "0", "2"], ["83953.9", "0", "0", "0"], ["83952.9", "0.35367636", "0", "2"], ["83951.5", "1.000015", "0", "2"], ["83943.7", "0.0044685", "0", "1"], ["83934.4", "0", "0", "0"], ["83933.1", "0", "0", "0"], ["83932.2", "0.2560799", "0", "2"], ["83870.1", "0.00213895", "0", "1"], ["83867", "0.01510862", "0", "1"]], "ts": "1742577064700", "checksum": -33519448, "seqId": 49944993446, "prevSeqId": 49944993406}], "record_time": 1742577064.872928, "EXCHANGE": "OKX"}
{"arg": {"channel": "books", "instId": "BTC-USDT"}, "action": "update", "data": [{"asks": [["83962.7", "0.6111189", "0", "21"], ["83983.4", "0.41479127", "0", "3"], ["83986.5", "0", "0", "0"], ["83989.2", "0.23832918", "0", "1"], ["83997", "0", "0", "0"], ["84008.8", "0.43038406", "0", "1"], ["84010.2", "0", "0", "0"], ["84117.3", "0.214308", "0", "1"]], "bids": [["83962.6", "0.01994879", "0", "4"], ["83953", "0.25515579", "0", "1"], ["83952.9", "1", "0", "1"], ["83951.5", "0.000015", "0", "1"], ["83934.4", "0.23832918", "0", "1"], ["83932.2", "0.01774536", "0", "1"], ["83926.4", "0.08", "0", "2"], ["83925.6", "0.15969794", "0", "4"], ["83924.8", "0.0004", "0", "1"], ["83923.9", "0.65249398", "0", "1"], ["83812.5", "0", "0", "0"], ["83811.9", "0", "0", "0"], ["83811.3", "0", "0", "0"], ["83810.8", "0", "0", "0"]], "ts": "1742577064800", "checksum": 262998482, "seqId": 49944993470, "prevSeqId": 49944993446}], "record_time": 1742577064.972483, "EXCHANGE": "OKX"}
{"arg": {"channel": "books", "instId": "BTC-USDT"}, "action": "update", "data": [{"asks": [["83962.7", "0.81299958", "0", "22"], ["83970.1", "0", "0", "0"], ["83994", "1", "0", "1"]], "bids": [["83962.6", "0.01399377", "0", "3"], ["83956.5", "0.00158915", "0", "2"], ["83934.4", "0", "0", "0"], ["83933", "0.23832991", "0", "1"], ["83931", "0.2", "0", "1"], ["83926.4", "0", "0", "0"], ["83925.6", "0.19969794", "0", "5"], ["83924.8", "0.0404", "0", "2"]], "ts": "1742577064900", "checksum": 704840032, "seqId": 49944993497, "prevSeqId": 49944993470}], "record_time": 1742577065.073029, "EXCHANGE": "OKX"}
{"arg": {"channel": "books", "instId": "BTC-USDT"}, "action": "snapshot", "data": [{"asks": [["83936.5", "0.04313", "0", "1"], ["83936.8", "0.07698413", "0", "1"], ["83938", "0.0439", "0", "1"], ["83938.3", "0.002", "0", "1"], ["83939.6", "0.11919059", "0", "1"], ["83939.7", "0.00112012", "0", "1"], ["83939.9", "0.01153238", "0", "1"], ["83940", "0.05581995", "0", "2"], ["83940.8", "0.0428883", "0", "1"], ["83942", "0.38665941", "0", "3"], ["83943.7", "0.11889794", "0", "1"], ["83943.8", "0.0000195", "0", "1"], ["83944", "0.0439", "0", "1"], ["83944.2", "0.02739775", "0", "1"], ["83944.3", "0.17898725", "0", "1"], ["83944.4", "0.35697351", "0", "1"], ["83944.8", "0.24837173", "0", "9"], ["83945", "0.02", "0", "1"], ["83945.1", "0.005", "0", "1"], ["83945.9", "0.02867118", "0", "1"], ["83946", "0.0439", "0", "1"], ["83946.3", "0.00774362", "0", "1"], ["83946.6", "0.00001199", "0", "1"], ["83948", "0.0439", "0", "1"], ["83948.3", "0.002", "0", "1"], ["83948.6", "0.000015", "0", "1"], ["83949.9", "0.00060645", "0", "1"], ["83950", "0.0439", "0", "1"], ["83950.2", "0.26348803", "0", "1"], ["83950.4", "0.01021", "0", "1"], ["83951.6", "0.00001199", "0", "1"], ["83952.3", "0.18371", "0", "2"], ["83953.3", "0.35697351", "0", "1"], ["83953.6", "0.04", "0", "1"], ["83953.7", "0.11889794", "0", "1"], ["83953.8", "0.03063", "0", "1"], ["83955.2", "0.09623902", "0", "1"], ["83955.4", "0.00774318", "0", "1"], ["83955.7", "0.0102", "0", "1"], ["83956.1", "0.134851", "0", "1"], ["83956.4", "0.04", "0", "1"], ["83956.5", "0.00001199", "0", "1"], ["83956.8", "0.0238393", "0", "1"], ["83957", "0.000015", "0", "1"], ["83957.3", "0.06", "0", "2"], ["83957.9", "0.17898725", "0", "1"], ["83958.1", "0.036", "0", "1"], ["83958.9", "0.01191708", "0", "1"], ["83959.6", "0.12", "0", "4"], ["83960", "0.00004", "0", "1"], ["83960.9", "0.2545", "0", "3"], ["83961.5", "0.00001199", "0", "1"], ["83962.4", "0.005", "0", "1"], ["83962.6", "0.23839513", "0", "1"], ["83962.7", "0.79114763", "0", "2"], ["83962.8", "0.35697351", "0", "1"], ["83963.7", "0.25016", "0", "1"], ["83964", "0.11915584", "0", "1"], ["83964.4", "0.00011161", "0", "1"], ["83964.5", "0.11889794", "0", "1"], ["83965", "0.00356105", "0", "1"], ["83965.2", "0.052", "0", "2"], ["83965.4", "0.00001501", "0", "1"], ["83966", "1.54018492", "0", "1"], ["83966.1", "0.11915299", "0", "1"], ["83966.2", "0.14191011", "0", "3"], ["83966.4", "0.00001199", "0", "1"], ["83966.6", "0.00101534", "0", "2"], ["83966.7", "0.052", "0", "2"], ["83968.2", "0.24393029", "0", "1"], ["83968.4", "0.11256978", "0", "2"], ["83969", "0.30410725", "0", "2"], ["83969.1", "0.00001501", "0", "1"], ["83970", "0.2545", "0", "3"], ["83970.1", "0.0090421", "0", "1"], ["83970.6", "0.01190894", "0", "1"], ["83970.9", "0.19031037", "0", "1"], ["83971", "0.00001", "0", "1"], ["83971.2", "0.35697351", "0", "1"], ["83971.4", "0.00001199", "0", "1"], ["83972", "0.18761632", "0", "1"], ["83973.8", "0.00001501", "0", "1"], ["83975.5", "0.28734705", "0", "2"], ["83976.3", "0.14072423", "0", "2"], ["83976.5", "0.01", "0", "1"], ["83976.7", "0.0196305", "0", "1"], ["83976.8", "0.0008", "0", "2"], ["83977.6", "0.0004", "0", "1"], ["83978.4", "0.02966481", "0", "2"], ["83978.5", "0.472109", "0", "1"], ["83978.8", "0.01908", "0", "1"], ["83978.9", "0.11256978", "0", "2"], ["83979", "0.60204464", "0", "1"], ["83979.3", "0.06241344", "0", "1"], ["83980.2", "0.35697351", "0", "1"], ["83980.6", "0.53749", "0", "1"], ["83980.8", "0.17898725", "0", "1"], ["83980.9", "0.11889794", "0", "1"], ["83981", "0.1", "0", "1"], ["83981.1", "0.052", "0", "2"], ["83981.3", "0.00001199", "0", "1"], ["83981.5", "0.14071224", "0", "1"], ["83981.6", "0.052", "0", "2"], ["83982.2", "0.000015", "0", "1"], ["83982.4", "0.2545", "0", "3"], ["83982.9", "0.052", "0", "2"], ["83983.2", "0.00084754", "0", "1"], ["83983.3", "0.16914969", "0", "2"], ["83983.4", "0.00357335", "0", "1"], ["83983.5", "0.29838", "0", "2"], ["83984.1", "0.00011161", "0", "1"], ["83984.7", "0.25021", "0", "1"], ["83984.8", "0.09190691", "0", "3"], ["83984.9", "0.00103317", "0", "1"], ["83985.2", "0.02382517", "0", "1"], ["83985.3", "0.036", "0", "1"], ["83985.4", "0.05956073", "0", "1"], ["83985.6", "0.0519068", "0", "2"], ["83985.7", "0.0001723", "0", "1"], ["83986.2", "0.00001199", "0", "1"], ["83986.3", "0.01190671", "0", "1"], ["83987.2", "0.01190658", "0", "1"], ["83987.4", "0.00084754", "0", "1"], ["83988.6", "0.4909756", "0", "2"], ["83988.7", "0.57634", "0", "1"], ["83988.9", "0.02382412", "0", "1"], ["83989.3", "0.11256978", "0", "2"], ["83989.4", "0.08991011", "0", "1"], ["83990", "0.48207351", "0", "2"], ["83990.5", "0.4", "0", "1"], ["83990.6", "0.000015", "0", "1"], ["83991.2", "0.00001199", "0", "1"], ["83991.3", "0.0010365", "0", "1"], ["83991.5", "0.00002157", "0", "1"], ["83991.6", "1.06994423", "0", "2"], ["83991.7", "0.17898725", "0", "1"], ["83991.8", "0.59269983", "0", "2"], ["83994.1", "0.01786804", "0", "1"], ["83995.3", "0.00714325", "0", "1"], ["83995.4", "2.88546433", "0", "2"], ["83995.8", "0.20442955", "0", "1"], ["83996.2", "0.00001199", "0", "1"], ["83996.9", "0.0186514", "0", "1"], ["83997.8", "0.01190776", "0", "1"], ["83998.7", "0.35697351", "0", "1"], ["83998.9", "0.2025", "0", "1"], ["83999", "0.000015", "0", "1"], ["83999.8", "0.11256978", "0", "2"], ["83999.9", "0.0051126", "0", "6"], ["84000", "0.10146136", "0", "4"], ["84000.2", "0.1227214", "0", "1"], ["84000.3", "0.17898725", "0", "1"], ["84001", "0.824179", "0", "1"], ["84001.1", "0.00001199", "0", "1"], ["84001.4", "0.0015", "0", "1"], ["84001.5", "0.03", "0", "1"], ["84001.7", "0.01", "0", "1"], ["84002.3", "0.001723", "0", "1"], ["84003.7", "0.00011161", "0", "1"], ["84003.9", "0.11889794", "0", "1"], ["84004.9", "0.03", "0", "1"], ["84005.3", "0.11597977", "0", "1"], ["84005.7", "0.1", "0", "1"], ["84006.1", "0.00001198", "0", "1"], ["84007.4", "0.00591502", "0", "2"], ["84007.6", "0.1", "0", "1"], ["84008.2", "0.2025", "0", "1"], ["84008.7", "0.00590001", "0", "1"], ["84008.8", "1.19584656", "0", "2"], ["84009.6", "0.05348", "0", "1"], ["84010.1", "0.00590001", "0", "1"], ["84010.2", "3.54157", "0", "1"], ["84010.3", "0.35697351", "0", "1"], ["84011", "0.00001198", "0", "1"], ["84011.1", "0.000015", "0", "1"], ["84011.2", "0.1", "0", "1"], ["84011.3", "0.17898725", "0", "1"], ["84011.7", "0.044994", "0", "1"], ["84012.6", "0.23775629", "0", "1"], ["84012.7", "0.27953218", "0", "1"], ["84013.5", "0.00119028", "0", "1"], ["84013.6", "0.00298666", "0", "1"], ["84015.8", "0.00001501", "0", "1"], ["84016", "0.00001198", "0", "1"], ["84016.1", "0.43692", "0", "1"], ["84016.5", "0.00035881", "0", "1"], ["84016.6", "0.04825689", "0", "2"], ["84018.1", "0.01428262", "0", "1"], ["84018.6", "0.00590001", "0", "1"], ["84018.7", "0.18338503", "0", "1"], ["84019.1", "0.11889794", "0", "1"], ["84019.4", "0.35697351", "0", "1"], ["84020.8", "0.03", "0", "1"], ["84020.9", "0.00001198", "0", "1"], ["84021.2", "0.09365", "0", "2"], ["84021.3", "0.20007177", "0", "2"], ["84021.6", "0.2025", "0", "1"], ["84022.6", "0.11907283", "0", "1"], ["84022.9", "0.01786422", "0", "3"], ["84023.3", "0.00011161", "0", "1"], ["84024.2", "0.00596974", "0", "2"], ["84024.8", "0.00590001", "0", "1"], ["84024.9", "0.03", "0", "1"], ["84025.1", "0.17898725", "0", "1"], ["84025.6", "1.28912685", "0", "2"], ["84025.8", "3.81411", "0", "1"], ["84025.9", "0.00001198", "0", "1"], ["84027.8", "0.00589973", "0", "1"], ["84027.9", "0.35697351", "0", "1"], ["84028", "0.11889794", "0", "1"], ["84028.1", "0.08991011", "0", "1"], ["84028.2", "0.01809756", "0", "1"], ["84029", "0.00589943", "0", "1"], ["84029.1", "0.00595474", "0", "1"], ["84030.8", "0.00001198", "0", "1"], ["84030.9", "0.41510746", "0", "3"], ["84031", "0.2025", "0", "1"], ["84031.4", "0.00012652", "0", "1"], ["84031.5", "0.00693745", "0", "2"], ["84031.8", "0.05732575", "0", "1"], ["84032.3", "0.0214", "0", "1"], ["84032.6", "0.08094428", "0", "3"], ["84033.3", "0.00101534", "0", "2"], ["84033.6", "0.73292647", "0", "2"], ["84033.7", "0.17898725", "0", "1"], ["84033.9", "0.26582064", "0", "1"], ["84034.4", "0.00597332", "0", "1"], ["84034.8", "0.00589954", "0", "1"], ["84035.8", "0.00001198", "0", "1"], ["84035.9", "0.0000597", "0", "1"], ["84036.2", "0.00594", "0", "1"], ["84037.4", "0.97344351", "0", "2"], ["84037.8", "0.0015", "0", "1"], ["84038.3", "0.12456718", "0", "1"], ["84038.6", "0.11889794", "0", "1"], ["84039.7", "0.00590001", "0", "1"], ["84039.9", "0.2025", "0", "1"], ["84040.1", "0.03", "0", "1"], ["84040.8", "0.00001198", "0", "1"], ["84041", "0.000015", "0", "1"], ["84041.7", "0.00589948", "0", "1"], ["84042.3", "0.000012", "0", "1"], ["84043", "0.00011161", "0", "1"], ["84043.2", "0.0238252", "0", "1"], ["84043.5", "0.03", "0", "1"], ["84043.9", "0.61342003", "0", "1"], ["84044", "0.08991011", "0", "1"], ["84044.1", "0.03573268", "0", "1"], ["84044.4", "1.212369", "0", "1"], ["84044.5", "0.00589962", "0", "1"], ["84044.6", "0.6", "0", "1"], ["84045", "0.17898725", "0", "1"], ["84045.5", "0.02976121", "0", "1"], ["84046.6", "0.00009539", "0", "1"], ["84046.9", "0.02730001", "0", "2"], ["84047", "0.27570086", "0", "3"], ["84047.1", "0.36287369", "0", "2"], ["84047.9", "0.00895999", "0", "1"], ["84048", "0.0015", "0", "1"], ["84048.1", "0.03", "0", "1"], ["84049.4", "0.000015", "0", "1"], ["84049.5", "0.2025", "0", "1"], ["84049.7", "0.08767", "0", "1"], ["84049.9", "0.00060645", "0", "1"], ["84050", "0.00018518", "0", "2"], ["84050.4", "0.1143786", "0", "1"], ["84050.5", "0.11889794", "0", "1"], ["84050.7", "0.000012", "0", "1"], ["84051.2", "0.01568", "0", "1"], ["84051.9", "0.00589962", "0", "1"], ["84052", "0.0015", "0", "1"], ["84052.6", "0.00001738", "0", "1"], ["84053.1", "0.00001501", "0", "1"], ["84053.5", "0.00590001", "0", "1"], ["84053.6", "0.17898725", "0", "1"], ["84054.6", "0.000012", "0", "1"], ["84054.9", "0.00590018", "0", "1"], ["84055", "0.179784", "0", "1"], ["84055.4", "0.067456", "0", "1"], ["84055.6", "0.3565323", "0", "1"], ["84056", "0.07165719", "0", "1"], ["84057.1", "0.00007544", "0", "2"], ["84057.2", "0.07166249", "0", "1"], ["84057.3", "0.03", "0", "1"], ["84057.4", "0.00009384", "0", "1"], ["84057.5", "0.0142", "0", "1"], ["84057.6", "0.0142", "0", "1"], ["84057.7", "0.0142", "0", "1"], ["84057.8", "0.014215", "0", "2"], ["84057.9", "0.20252241", "0", "2"], ["84058.3", "0.01194665", "0", "1"], ["84058.8", "0.00002902", "0", "1"], ["84059.1", "0.06621014", "0", "1"], ["84059.2", "0.214491", "0", "1"], ["84060.6", "0.000012", "0", "1"], ["84062.1", "0.00002296", "0", "1"], ["84062.4", "0.00010514", "0", "1"], ["84062.6", "0.00011161", "0", "1"], ["84063.7", "0.40448085", "0", "2"], ["84063.8", "0.11889794", "0", "1"], ["84064", "0.05361312", "0", "1"], ["84064.5", "0.3565323", "0", "1"], ["84065.2", "0.00008584", "0", "1"], ["84065.6", "0.000012", "0", "1"], ["84066.2", "0.000015", "0", "1"], ["84066.3", "0.2025", "0", "1"], ["84066.4", "0.00251827", "0", "1"], ["84066.6", "0.00504382", "0", "4"], ["84066.7", "0.01493332", "0", "1"], ["84067", "0.000012", "0", "1"], ["84067.7", "0.04486818", "0", "1"], ["84067.8", "0.05952242", "0", "1"], ["84068.7", "0.08991011", "0", "1"], ["84069.7", "0.00011444", "0", "1"], ["84069.9", "0.00595636", "0", "1"], ["84071", "1.64325", "0", "1"], ["84071.4", "0.00001362", "0", "1"], ["84071.7", "0.5999", "0", "1"], ["84072.1", "0.0142", "0", "1"], ["84072.2", "0.01422016", "0", "2"], ["84072.6", "0.00007814", "0", "1"], ["84072.8", "0.11889794", "0", "1"], ["84073", "0.3565323", "0", "1"], ["84073.2", "0.17898725", "0", "1"], ["84074.3", "0.0142", "0", "1"], ["84074.7", "0.2025", "0", "1"], ["84075", "0.00004433", "0", "1"], ["84075.5", "0.00001199", "0", "1"], ["84076.1", "0.183563", "0", "1"], ["84076.5", "0.00010284", "0", "1"], ["84076.8", "0.00001957", "0", "1"], ["84076.9", "0.03009125", "0", "2"], ["84077", "0.00008", "0", "1"], ["84079.3", "0.00001199", "0", "1"], ["84079.4", "0.00018194", "0", "1"], ["84079.9", "0.00001026", "0", "1"], ["84080.1", "0.0054", "0", "1"], ["84081.4", "0.00003364", "0", "1"], ["84081.6", "0.00212326", "0", "1"], ["84081.7", "0.03", "0", "1"], ["84082.2", "0.17898725", "0", "1"], ["84082.3", "0.00011161", "0", "1"], ["84082.4", "0.21376", "0", "1"], ["84082.6", "0.00001984", "0", "1"], ["84083.1", "0.2025", "0", "1"], ["84083.3", "0.00422986", "0", "3"], ["84083.4", "0.11764", "0", "2"], ["84083.8", "0.3565323", "0", "1"], ["84085.4", "0.00001199", "0", "1"], ["84085.7", "0.00068775", "0", "1"], ["84086.2", "0.002382", "0", "1"], ["84086.7", "0.04191272", "0", "3"], ["84088.2", "0.00011938", "0", "1"], ["84088.5", "0.11331115", "0", "2"], ["84088.6", "0.01736", "0", "1"], ["84089.1", "0.00002215", "0", "1"], ["84089.6", "0.11889794", "0", "1"], ["84089.7", "0.0015", "0", "1"], ["84090.2", "0.00074396", "0", "1"], ["84090.4", "0.00002339", "0", "2"], ["84090.8", "0.00376703", "0", "1"], ["84090.9", "0.00003887", "0", "1"], ["84091.1", "0.17898725", "0", "1"], ["84091.2", "0.00001297", "0", "1"], ["84091.3", "0.0059563", "0", "1"], ["84093.2", "0.3565323", "0", "1"], ["84094.5", "0.31997186", "0", "1"], ["84095.1", "0.000015", "0", "1"], ["84096", "0.00006328", "0", "1"], ["84096.4", "0.03", "0", "1"], ["84099.9", "0.11991328", "0", "3"], ["84100", "5.01499374", "0", "7"], ["84100.3", "0.00001199", "0", "1"], ["84101", "0.0025", "0", "1"], ["84101.3", "0.17898725", "0", "1"], ["84101.7", "0.3565323", "0", "1"], ["84101.9", "0.00011161", "0", "1"], ["84104.9", "0.03", "0", "1"], ["84105.2", "0.00001053", "0", "1"], ["84106.6", "0.00001008", "0", "1"], ["84107", "0.00120451", "0", "3"], ["84107.6", "0.00001881", "0", "1"], ["84109", "0.08994305", "0", "2"], ["84110.1", "0.01232", "0", "1"], ["84110.2", "0.00001199", "0", "1"], ["84110.5", "0.3565323", "0", "1"], ["84111.1", "0.00003344", "0", "1"], ["84111.2", "0.00004855", "0", "1"], ["84111.3", "0.69209544", "0", "1"], ["84111.6", "0.0015", "0", "1"], ["84112", "0.00118464", "0", "1"], ["84112.6", "0.00003552", "0", "1"], ["84113.3", "0.17898725", "0", "1"], ["84113.5", "0.00003103", "0", "1"], ["84114", "0.00014547", "0", "1"], ["84115.7", "0.00103744", "0", "1"], ["84116.6", "0.00060645", "0", "1"], ["84116.7", "0.13677594", "0", "2"], ["84117.6", "0.00001805", "0", "1"], ["84119", "0.35658448", "0", "2"]], "bids": [["83936.4", "0.75188851", "0", "13"], ["83936.1", "0.06316329", "0", "2"], ["83936", "0.0439", "0", "1"], ["83934.7", "0.11921244", "0", "2"], ["83934", "0.0439", "0", "1"], ["83933.3", "0.00269142", "0", "2"], ["83932.8", "0.03697529", "0", "1"], ["83932", "0.0439", "0", "1"], ["83931.5", "0.005", "0", "1"], ["83931.1", "0.00056097", "0", "1"], ["83930", "0.0439", "0", "1"], ["83929.9", "0.016", "0", "1"], ["83929.4", "0.0335539", "0", "3"], ["83928.6", "0.689509", "0", "1"], ["83928.1", "0.00506", "0", "2"], ["83928", "0.2464", "0", "2"], ["83927.5", "0.0417", "0", "1"], ["83927.2", "1", "0", "1"], ["83926.9", "0.00001199", "0", "1"], ["83926.6", "0.17898725", "0", "1"], ["83926.5", "0.11256978", "0", "2"], ["83926.3", "0.35698851", "0", "2"], ["83926.2", "0.033", "0", "1"], ["83926", "0.0439", "0", "1"], ["83925.4", "0.0428883", "0", "1"], ["83925.3", "0.04", "0", "1"], ["83925.2", "0.00011161", "0", "1"], ["83925.1", "0.35741", "0", "1"], ["83924.9", "0.05956073", "0", "1"], ["83924.7", "0.00897002", "0", "1"], ["83924.6", "0.17871", "0", "1"], ["83924.4", "0.12536279", "0", "1"], ["83924.3", "0.14071224", "0", "1"], ["83924", "0.0439", "0", "1"], ["83923.8", "0.00357", "0", "1"], ["83923.2", "0.00349953", "0", "1"], ["83922.6", "0.036", "0", "1"], ["83922.4", "0.01192226", "0", "1"], ["83922", "0.00001199", "0", "1"], ["83921.9", "0.002", "0", "1"], ["83921.5", "0.005", "0", "1"], ["83921.3", "0.19535994", "0", "2"], ["83920.9", "0.04100122", "0", "1"], ["83920", "0.00001", "0", "1"], ["83919.9", "0.008", "0", "1"], ["83919.8", "0.35769743", "0", "2"], ["83919.7", "0.134851", "0", "1"], ["83919.3", "0.153", "0", "4"], ["83918.7", "0.2545", "0", "3"], ["83918.4", "0.04", "0", "1"], ["83918", "0.01262", "0", "3"], ["83917.9", "0.178725", "0", "2"], ["83917.6", "0.54596076", "0", "3"], ["83917.3", "0.08597", "0", "1"], ["83917", "0.00001199", "0", "1"], ["83916.9", "0.036", "0", "1"], ["83916.8", "0.016", "0", "1"], ["83916.6", "0.00060645", "0", "1"], ["83916", "0.11256978", "0", "2"], ["83915.7", "0.0238396", "0", "1"], ["83914.5", "0.016", "0", "1"], ["83913.8", "0.26580224", "0", "2"], ["83913.5", "0.016", "0", "1"], ["83912.1", "0.06113773", "0", "1"], ["83912", "0.000012", "0", "1"], ["83911.8", "0.038", "0", "2"], ["83911.7", "0.016", "0", "1"], ["83911.6", "0.16205254", "0", "1"], ["83911.5", "0.02384607", "0", "1"], ["83911.3", "0.11923053", "0", "1"], ["83910.8", "0.016", "0", "1"], ["83909.9", "0.23839513", "0", "1"], ["83909.8", "0.2185", "0", "2"], ["83909.5", "0.00001501", "0", "1"], ["83908.6", "0.11923451", "0", "1"], ["83908.1", "0.02768955", "0", "2"], ["83907.1", "0.000012", "0", "1"], ["83907", "1.06410459", "0", "1"], ["83906.9", "1.55826141", "0", "1"], ["83906.1", "0.1251", "0", "1"], ["83905.5", "0.64064139", "0", "4"], ["83905.3", "0.5776526", "0", "1"], ["83904.8", "0.17898725", "0", "1"], ["83904.7", "0.35697351", "0", "1"], ["83904", "0.08079914", "0", "4"], ["83903.9", "0.0286", "0", "1"], ["83903.2", "0.06639914", "0", "4"], ["83903.1", "0.57530375", "0", "1"], ["83902.8", "0.08991011", "0", "1"], ["83902.7", "0.24659", "0", "1"], ["83902.4", "0.058052", "0", "2"], ["83902.1", "0.000012", "0", "1"], ["83902", "0.00036", "0", "1"], ["83901.8", "0.01190891", "0", "1"], ["83901.2", "0.01190875", "0", "1"], ["83901.1", "0.00001501", "0", "1"], ["83901", "0.00036", "0", "1"], ["83900.9", "0.001787", "0", "1"], ["83900.8", "0.65021", "0", "2"], ["83900", "0.00001", "0", "1"], ["83899.9", "0.03064937", "0", "5"], ["83899.2", "0.45392649", "0", "3"], ["83899.1", "0.016", "0", "1"], ["83898.8", "0.01190909", "0", "1"], ["83898.4", "0.05", "0", "1"], ["83898", "0.016", "0", "1"], ["83897.8", "0.05203", "0", "1"], ["83897.2", "0.000012", "0", "1"], ["83896.7", "0.00595629", "0", "1"], ["83896.3", "0.00595629", "0", "1"], ["83896.2", "0.11889794", "0", "1"], ["83896.1", "0.35697351", "0", "1"], ["83896", "0.01190807", "0", "1"], ["83895.4", "0.17898725", "0", "1"], ["83895.2", "0.016", "0", "1"], ["83895.1", "0.01190821", "0", "1"], ["83895", "0.14856978", "0", "3"], ["83894.8", "0.5665", "0", "1"], ["83894.7", "0.00595629", "0", "1"], ["83894.6", "0.21856946", "0", "4"], ["83892.7", "0.00001501", "0", "1"], ["83892.2", "0.000012", "0", "1"], ["83890.8", "0.01835661", "0", "1"], ["83890.7", "0.01196141", "0", "3"], ["83890.6", "0.56", "0", "1"], ["83890.5", "0.07517439", "0", "2"], ["83889.1", "0.02466532", "0", "1"], ["83889", "0.00357", "0", "1"], ["83888.8", "0.00007596", "0", "1"], ["83888.7", "0.00595629", "0", "1"], ["83888.6", "0.00579997", "0", "1"], ["83888.5", "0.08991011", "0", "1"], ["83888.3", "0.0007582", "0", "1"], ["83888", "0.07710607", "0", "1"], ["83887.9", "0.825289", "0", "1"], ["83887.7", "0.00595629", "0", "1"], ["83887.6", "0.00579962", "0", "1"], ["83887.3", "0.00581193", "0", "2"], ["83886.4", "2.80496565", "0", "1"], ["83886.3", "0.00579988", "0", "1"], ["83886.2", "0.0249433", "0", "1"], ["83886.1", "0.00589962", "0", "1"], ["83886", "0.33082361", "0", "3"], ["83885.9", "0.35708512", "0", "2"], ["83885.3", "0.11889794", "0", "1"], ["83885.2", "0.12508", "0", "1"], ["83884.3", "0.00001501", "0", "1"], ["83884", "0.01789149", "0", "1"], ["83883.3", "0.01060645", "0", "2"], ["83882.8", "0.14897423", "0", "2"], ["83882.5", "0.17898725", "0", "1"], ["83882.4", "0.0627032", "0", "2"], ["83881.9", "0.00001198", "0", "1"], ["83880.3", "0.00001072", "0", "1"], ["83880", "0.00600289", "0", "3"], ["83879.9", "0.2025", "0", "1"], ["83879.8", "0.25019", "0", "1"], ["83879", "0.00036", "0", "1"], ["83878.8", "0.067597", "0", "1"], ["83878.5", "0.00008513", "0", "1"], ["83877.4", "0.00017505", "0", "1"], ["83876.3", "0.00595629", "0", "1"], ["83876.2", "0.1104284", "0", "1"], ["83876.1", "0.3565323", "0", "1"], ["83875.9", "0.000015", "0", "1"], ["83875.3", "0.000015", "0", "1"], ["83875.2", "0.01153238", "0", "1"], ["83873.7", "0.64097532", "0", "3"], ["83873.6", "0.472109", "0", "1"], ["83873.4", "0.17898725", "0", "1"], ["83873.2", "0.01672", "0", "1"], ["83872.5", "0.00001198", "0", "1"], ["83872.2", "0.01191517", "0", "2"], ["83872.1", "0.08944", "0", "1"], ["83871.3", "0.00595711", "0", "1"], ["83871", "0.00036", "0", "1"], ["83870.1", "0.00100749", "0", "1"], ["83870", "0.90247", "0", "1"], ["83869.8", "0.2808453", "0", "1"], ["83869.7", "0.192388", "0", "1"], ["83869.6", "0.00001198", "0", "1"], ["83869.2", "0.00218712", "0", "1"], ["83869.1", "0.06", "0", "2"], ["83868.4", "0.00145319", "0", "1"], ["83868.3", "0.2025", "0", "1"], ["83867.7", "0.0387048", "0", "1"], ["83867.5", "0.000015", "0", "1"], ["83867.4", "0.3565323", "0", "1"], ["83867", "0.00036", "0", "1"], ["83866.7", "0.00005728", "0", "1"], ["83866.6", "0.01034823", "0", "10"], ["83866.2", "0.14319661", "0", "3"], ["83865.9", "0.00715427", "0", "1"], ["83865", "0.44298456", "0", "2"], ["83864.9", "0.17898725", "0", "1"], ["83864", "0.00002125", "0", "1"], ["83863.4", "0.13750771", "0", "1"], ["83863.3", "0.58230504", "0", "2"], ["83863.1", "0.00103791", "0", "1"], ["83863", "0.11889794", "0", "1"], ["83862.8", "1.214992", "0", "1"], ["83862.6", "0.00001198", "0", "1"], ["83860.7", "0.20004149", "0", "1"], ["83860", "0.00036", "0", "1"], ["83859.8", "0.2025", "0", "1"], ["83859.4", "0.0023222", "0", "1"], ["83859.2", "0.04468045", "0", "2"], ["83859.1", "0.000015", "0", "1"], ["83858.6", "0.00020004", "0", "1"], ["83858.3", "0.3565323", "0", "1"], ["83858", "0.00036", "0", "1"], ["83857.6", "0.00001198", "0", "1"], ["83857.5", "0.00004084", "0", "1"], ["83857.4", "0.01899998", "0", "1"], ["83857.3", "0.00001198", "0", "1"], ["83857.1", "1.14739716", "0", "5"], ["83857", "3.52194", "0", "2"], ["83855.1", "0.17898725", "0", "1"], ["83854.7", "0.00168677", "0", "1"], ["83854.3", "0.03577774", "0", "1"], ["83853.6", "0.00213917", "0", "1"], ["83853.4", "0.00010118", "0", "1"], ["83853.3", "0.11889794", "0", "1"], ["83852.9", "0.08991011", "0", "1"], ["83852.5", "0.00001059", "0", "1"], ["83852.2", "0.14372899", "0", "1"], ["83852.1", "0.05965742", "0", "1"], ["83852", "0.00036", "0", "1"], ["83851.3", "0.2025", "0", "1"], ["83851", "0.00044214", "0", "2"], ["83850.7", "0.01519252", "0", "2"], ["83850.4", "0.00001302", "0", "1"], ["83850.1", "0.01914059", "0", "3"], ["83850", "0.0009247", "0", "5"], ["83849.9", "0.00419995", "0", "2"], ["83849.6", "0.35784874", "0", "2"], ["83848.9", "0.00054698", "0", "1"], ["83848.6", "0.08944", "0", "1"], ["83848.4", "0.00017177", "0", "1"], ["83847.8", "0.00001319", "0", "1"], ["83847.7", "0.00001199", "0", "1"], ["83847.4", "0.00595851", "0", "1"], ["83847.1", "0.00595851", "0", "1"], ["83847", "0.14566622", "0", "1"], ["83846.9", "0.03", "0", "1"], ["83846.8", "0.00001004", "0", "1"], ["83846.7", "0.17898725", "0", "1"], ["83846.6", "0.00011161", "0", "1"], ["83846.1", "0.00002549", "0", "1"], ["83845.7", "0.03", "0", "1"], ["83845.6", "0.03", "0", "1"], ["83845.2", "0.00589921", "0", "1"], ["83845", "0.0118697", "0", "3"], ["83844.8", "0.00005594", "0", "1"], ["83844.7", "0.07969687", "0", "2"], ["83844.6", "0.11889794", "0", "1"], ["83844.5", "0.20747", "0", "1"], ["83844.1", "0.01191987", "0", "1"], ["83843.3", "0.00589921", "0", "1"], ["83843.2", "0.01191851", "0", "2"], ["83843", "0.00596352", "0", "1"], ["83842.9", "0.00001008", "0", "1"], ["83842.8", "0.2025", "0", "1"], ["83842.6", "0.02382522", "0", "1"], ["83842.5", "3.77906", "0", "1"], ["83842.4", "0.00003928", "0", "2"], ["83842.3", "0.00001501", "0", "1"], ["83842.1", "0.00602439", "0", "2"], ["83842", "0.00018", "0", "1"], ["83841.4", "0.00011803", "0", "3"], ["83841.3", "0.00595951", "0", "1"], ["83841.1", "0.00595851", "0", "1"], ["83840.9", "0.00589921", "0", "1"], ["83840.8", "0.00579923", "0", "1"], ["83840.7", "0.35776874", "0", "1"], ["83840.3", "0.00579977", "0", "1"], ["83840.2", "0.00595951", "0", "1"], ["83840", "0.00029869", "0", "2"], ["83839.9", "0.00007308", "0", "1"], ["83839", "0.00001308", "0", "1"], ["83838.9", "0.00595951", "0", "1"], ["83838.8", "0.00598877", "0", "2"], ["83838.3", "0.17998725", "0", "2"], ["83838", "0.0015", "0", "1"], ["83837.8", "0.00001199", "0", "1"], ["83837.7", "0.00589921", "0", "1"], ["83837.6", "0.00595951", "0", "1"], ["83837.4", "0.00595888", "0", "1"], ["83837.2", "0.00003224", "0", "1"], ["83836.8", "0.00579923", "0", "1"], ["83836.6", "0.00003296", "0", "1"], ["83836.5", "0.00012802", "0", "1"], ["83836.4", "1.57648", "0", "1"], ["83835.5", "0.11175928", "0", "3"], ["83835.4", "0.00103978", "0", "1"], ["83834.9", "0.00589977", "0", "1"], ["83834.7", "0.10589921", "0", "2"], ["83834.6", "0.00595951", "0", "1"], ["83834.5", "0.11889794", "0", "1"], ["83834.4", "0.2025", "0", "1"], ["83834", "0.00013099", "0", "1"], ["83833.9", "0.00001501", "0", "1"], ["83833.7", "0.00579923", "0", "1"], ["83833.3", "0.0075514", "0", "10"], ["83833.2", "0.000015", "0", "1"], ["83832.9", "0.00002955", "0", "2"], ["83832.6", "0.00001199", "0", "1"], ["83832.3", "0.01169844", "0", "2"], ["83832.2", "0.01191902", "0", "2"], ["83832.1", "0.35776874", "0", "1"], ["83831.3", "0.00589921", "0", "1"], ["83831", "0.00004167", "0", "1"], ["83830.5", "0.01725915", "0", "3"], ["83830", "0.00005835", "0", "2"], ["83829.9", "0.17901312", "0", "2"], ["83829.8", "0.07166249", "0", "1"], ["83828.5", "0.07165719", "0", "1"], ["83828", "0.00579923", "0", "1"], ["83827.9", "0.01191902", "0", "2"], ["83827.8", "0.00595951", "0", "1"], ["83827.7", "0.08991011", "0", "1"], ["83827.5", "0.04971356", "0", "1"], ["83827", "0.00011161", "0", "1"], ["83826.7", "0.00589921", "0", "1"], ["83826.5", "0.00040898", "0", "2"], ["83826.1", "0.00015468", "0", "1"], ["83826", "0.2025", "0", "1"], ["83825.9", "0.00001586", "0", "1"], ["83825.5", "0.00001501", "0", "1"], ["83825.4", "0.00001365", "0", "1"], ["83825.1", "0.0166188", "0", "1"], ["83825", "0.00008012", "0", "2"], ["83824.2", "0.20833794", "0", "2"], ["83824.1", "0.00017037", "0", "1"], ["83823.6", "0.3607554", "0", "2"], ["83823.5", "0.00039533", "0", "1"], ["83823", "0.10001199", "0", "2"], ["83822.5", "0.00003465", "0", "2"], ["83822.4", "0.00001007", "0", "1"], ["83822.3", "0.00589964", "0", "1"], ["83822.2", "0.00299792", "0", "1"], ["83822", "0.00001994", "0", "1"], ["83821.8", "0.05766476", "0", "3"], ["83821.5", "0.17898725", "0", "1"], ["83820.3", "0.00001199", "0", "1"], ["83820.1", "0.18356614", "0", "1"], ["83820", "0.00021617", "0", "3"], ["83819.9", "0.00012246", "0", "2"], ["83819.6", "0.00083", "0", "1"], ["83819.5", "0.01169844", "0", "2"], ["83819.4", "0.00014808", "0", "2"], ["83819.2", "0.00084297", "0", "2"], ["83818.9", "0.00006774", "0", "2"], ["83818.1", "0.00006813", "0", "3"], ["83818", "0.0025", "0", "1"], ["83817.7", "0.00083", "0", "1"], ["83817.6", "0.2025", "0", "1"], ["83817.1", "0.000845", "0", "2"], ["83816.9", "0.00126817", "0", "1"], ["83816.7", "0.01190956", "0", "1"], ["83816.6", "0.00060645", "0", "1"], ["83815.9", "0.00004266", "0", "1"], ["83815.5", "0.002384", "0", "1"], ["83815.3", "0.00018461", "0", "1"], ["83815.2", "0.00597332", "0", "1"], ["83815.1", "0.00589964", "0", "1"], ["83815", "0.35776874", "0", "1"], ["83814.9", "0.0073937", "0", "2"], ["83814.4", "0.00005519", "0", "1"], ["83814.1", "0.00003395", "0", "1"], ["83813.8", "0.11936928", "0", "1"], ["83813.6", "0.03579964", "0", "2"], ["83813.5", "0.00002031", "0", "1"], ["83813.1", "0.00001199", "0", "1"], ["83812.6", "0.00579923", "0", "1"], ["83812.5", "0.00667459", "0", "3"], ["83812.4", "0.05367661", "0", "2"], ["83812.1", "1.72263", "0", "1"], ["83812", "0.00589921", "0", "1"], ["83811.9", "0.0010552", "0", "1"], ["83811.3", "0.00074812", "0", "1"], ["83810.1", "0.00001655", "0", "1"], ["83810", "0.22033855", "0", "2"], ["83809.8", "0.00013882", "0", "1"], ["83809.7", "0.00001075", "0", "1"], ["83809.6", "0.00595636", "0", "1"], ["83809.4", "0.00005977", "0", "1"], ["83809.2", "0.2025", "0", "1"], ["83808.7", "0.000015", "0", "1"], ["83808.2", "0.18358799", "0", "2"], ["83808", "0.00015274", "0", "2"], ["83807.9", "0.00001018", "0", "1"], ["83807.8", "0.00589964", "0", "1"], ["83807.7", "0.00579964", "0", "1"], ["83807.5", "0.03", "0", "1"], ["83807.4", "0.11889794", "0", "1"], ["83807.3", "0.00011161", "0", "1"], ["83807.1", "0.00001527", "0", "1"], ["83806.8", "0.00895999", "0", "1"], ["83806.6", "0.00001217", "0", "1"]], "ts": "1742577141600", "checksum": -1572573203, "seqId": 49945041207, "prevSeqId": -1}], "record_time": 1742577141.772373, "EXCHANGE": "OKX"}
{"arg": {"channel": "books", "instId": "BTC-USDT"}, "action": "update", "data": [{"asks": [["83936.8", "0", "0", "0"], ["83938", "0", "0", "0"], ["83939.6", "0", "0", "0"], ["83939.9", "0", "0", "0"], ["83940", "0.01191995", "0", "1"], ["83943.2", "0.01153238", "0", "1"], ["83943.8", "0", "0", "0"], ["83944.8", "0.00672077", "0", "4"], ["83950.2", "0.16851703", "0", "1"], ["83952.3", "0.005", "0", "1"], ["83959.5", "0.1123656", "0", "1"], ["83962.6", "0", "0", "0"], ["83968.1", "0.23838612", "0", "1"], ["83980", "0.08", "0", "2"], ["83980.8", "0.21898724", "0", "2"], ["83984.8", "0.01190692", "0", "1"], ["83985.6", "0.01190681", "0", "1"], ["84120", "0.00006444", "0", "2"], ["84121.5", "0.00011161", "0", "1"]], "bids": [["83936.4", "0.85188851", "0", "14"], ["83932.8", "0.33825255", "0", "2"], ["83931.1", "1.00056097", "0", "2"], ["83928.6", "0.51188046", "0", "1"], ["83927.2", "0", "0", "0"], ["83918", "0.00536", "0", "2"], ["83913.9", "0.23838612", "0", "1"], ["83909.9", "0", "0", "0"], ["83905.6", "0.19889794", "0", "3"], ["83904.8", "0.21898725", "0", "2"], ["83904", "0.00079914", "0", "2"], ["83903.2", "0.02639914", "0", "3"]], "ts": "1742577141700", "checksum": 1019813287, "seqId": 49945041262, "prevSeqId": 49945041207}], "record_time": 1742577141.87174, "EXCHANGE": "OKX"}
{"arg": {"channel": "books", "instId": "BTC-USDT"}, "action": "update", "data": [{"asks": [["83940", "0.0439", "0", "1"], ["83940.8", "0", "0", "0"], ["83942", "0.1692305", "0", "3"], ["83942.2", "0.01191962", "0", "1"], ["83944.3", "0", "0", "0"], ["83944.4", "0", "0", "0"], ["83944.8", "0.00567045", "0", "3"], ["83944.9", "0.2025", "0", "1"], ["83945.7", "0.05417177", "0", "1"], ["83945.8", "0.0428883", "0", "1"], ["83945.9", "0", "0", "0"], ["83948.4", "0.04009267", "0", "1"], ["83949.4", "0.000021", "0", "1"], ["83955.2", "0.17827744", "0", "2"], ["83955.3", "0.35741", "0", "1"], ["83957.3", "0.23871", "0", "3"], ["83965.9", "0.01774536", "0", "1"], ["83978.4", "0.01191945", "0", "1"], ["84117.6", "0", "0", "0"], ["84119", "0", "0", "0"], ["84120", "0", "0", "0"], ["84121.5", "0", "0", "0"]], "bids": [["83931.6", "0.01191962", "0", "1"], ["83931.1", "0.00056097", "0", "1"], ["83930", "0.0867883", "0", "2"], ["83929.6", "1", "0", "1"], ["83929.4", "0.02163395", "0", "2"], ["83925.4", "0", "0", "0"], ["83924.4", "0.13029779", "0", "2"], ["83820.2", "0.00083", "0", "1"], ["83806.8", "0", "0", "0"], ["83806.6", "0", "0", "0"]], "ts": "1742577141800", "checksum": 604300689, "seqId": 49945041294, "prevSeqId": 49945041262}], "record_time": 1742577141.971672, "EXCHANGE": "OKX"}
{"arg": {"channel": "books", "instId": "BTC-USDT"}, "action": "update", "data": [{"asks": [["83940", "0", "0", "0"], ["83942", "0.11361956", "0", "2"], ["83944.9", "0", "0", "0"], ["83955.2", "0.27524564", "0", "1"], ["84117.6", "0.00001805", "0", "1"], ["84119", "0.35658448", "0", "2"]], "bids": [], "ts": "1742577141900", "checksum": 974415984, "seqId": 49945041303, "prevSeqId": 49945041294}], "record_time": 1742577142.071496, "EXCHANGE": "OKX"}
{"arg": {"channel": "books", "instId": "BTC-USDT"}, "action": "update", "data": [{"asks": [["83936.5", "0.04311", "0", "1"], ["83943.2", "0", "0", "0"], ["83946.5", "0.01153238", "0", "1"], ["83978.4", "0", "0", "0"], ["83984", "0.2", "0", "1"], ["84008.4", "0.01191838", "0", "1"], ["84119", "0", "0", "0"]], "bids": [["83936.4", "1.05188851", "0", "15"], ["83912", "0.200012", "0", "2"], ["83910", "1", "0", "1"], ["83807.1", "0", "0", "0"]], "ts": "1742577142000", "checksum": -127120050, "seqId": 49945041318, "prevSeqId": 49945041303}], "record_time": 1742577142.175082, "EXCHANGE": "OKX"}
{"arg": {"channel": "books", "instId": "BTC-USDT"}, "action": "update", "data": [{"asks": [["83942", "0.14077559", "0", "3"], ["83945.1", "0.1241827", "0", "2"], ["83966", "1.55209451", "0", "2"], ["83970.6", "0", "0", "0"], ["83972", "0.18841632", "0", "3"], ["83972.8", "0.0004", "0", "1"], ["83976.8", "0", "0", "0"], ["83977.6", "0", "0", "0"], ["83984", "0", "0", "0"], ["84007.3", "0.01133379", "0", "1"], ["84080", "0.11333794", "0", "1"], ["84088.5", "0.00003542", "0", "1"], ["84119", "0.35658448", "0", "2"]], "bids": [["83924.4", "0.12536279", "0", "1"], ["83924.3", "0.14125074", "0", "2"], ["83910", "0", "0", "0"], ["83904.8", "0.21978725", "0", "4"], ["83904", "0.00039914", "0", "1"], ["83903.2", "0.026", "0", "2"], ["83899.9", "0.01874043", "0", "4"], ["83897", "0.01190959", "0", "1"], ["83890.8", "0", "0", "0"], ["83889.2", "0.01835562", "0", "1"], ["83870.1", "0", "0", "0"], ["83869.8", "0.28185253", "0", "2"], ["83820.1", "0", "0", "0"], ["83818.1", "0.18362439", "0", "4"], ["83807.1", "0.00001527", "0", "1"], ["83806.8", "0.00895999", "0", "1"]], "ts": "1742577142100", "checksum": -1499318043, "seqId": 49945041361, "prevSeqId": 49945041318}], "record_time": 1742577142.278513, "EXCHANGE": "OKX"}
{"arg": {"channel": "books", "instId": "BTC-USDT"}, "action": "update", "data": [{"asks": [["84000.2", "0.33428306", "0", "2"]], "bids": [["83912", "0.000012", "0", "1"], ["83903.2", "0.55555039", "0", "3"], ["83869.2", "0", "0", "0"], ["83868.5", "0.00218693", "0", "1"], ["83865", "0.61475525", "0", "1"]], "ts": "1742577142200", "checksum": -1499318043, "seqId": 49945041371, "prevSeqId": 49945041361}], "record_time": 1742577142.370669, "EXCHANGE": "OKX"}
{"arg": {"channel": "books", "instId": "BTC-USDT"}, "action": "update", "data": [{"asks": [["83942.9", "0.11918587", "0", "1"], ["83945.1", "0.005", "0", "1"], ["83968.1", "0.2383874", "0", "1"], ["84119", "0", "0", "0"]], "bids": [["83936.4", "0.85188851", "0", "14"], ["83932.8", "0.05111894", "0", "1"], ["83929.6", "0", "0", "0"], ["83928.6", "0.73502891", "0", "2"], ["83928", "1.2464", "0", "3"], ["83924.3", "0.14071224", "0", "1"], ["83913.9", "0", "0", "0"], ["83912.2", "0.23838743", "0", "1"], ["83806.6", "0.00001217", "0", "1"]], "ts": "1742577142300", "checksum": 1465736843, "seqId": 49945041390, "prevSeqId": 49945041371}], "record_time": 1742577142.471275, "EXCHANGE": "OKX"}
{"arg": {"channel": "books", "instId": "BTC-USDT"}, "action": "update", "data": [{"asks": [["83966.2", "0.052", "0", "2"]], "bids": [["83936.4", "1.05188851", "0", "15"], ["83932.8", "0.34935098", "0", "2"], ["83929.5", "1", "0", "1"], ["83928.6", "0.51188046", "0", "1"], ["83928", "0.2464", "0", "2"], ["83923.5", "0.08991011", "0", "1"], ["83922.8", "0.000039", "0", "1"], ["83913.9", "0.23838711", "0", "1"], ["83912.2", "0", "0", "0"], ["83900", "0.10001", "0", "3"], ["83899.2", "0.40392649", "0", "2"], ["83898.4", "0", "0", "0"], ["83806.8", "0", "0", "0"], ["83806.6", "0", "0", "0"]], "ts": "1742577142400", "checksum": 1995929116, "seqId": 49945041412, "prevSeqId": 49945041390}], "record_time": 1742577142.571168, "EXCHANGE": "OKX"}
{"arg": {"channel": "books", "instId": "BTC-USDT"}, "action": "update", "data": [{"asks": [["83936.5", "0.04309", "0", "1"], ["83965.9", "0", "0", "0"], ["83978.4", "0.01774536", "0", "1"]], "bids": [["83932.8", "0.05111894", "0", "1"], ["83929.5", "0", "0", "0"], ["83928.6", "0.73502891", "0", "2"], ["83928.1", "1.00506", "0", "3"], ["83919.9", "0", "0", "0"], ["83806.8", "0.00895999", "0", "1"], ["83806.6", "0.00001217", "0", "1"]], "ts": "1742577142500", "checksum": -1914002127, "seqId": 49945041423, "prevSeqId": 49945041412}], "record_time": 1742577142.671206, "EXCHANGE": "OKX"}
{"arg": {"channel": "books", "instId": "BTC-USDT"}, "action": "update", "data": [{"asks": [["83936.5", "0", "0", "0"], ["83942", "0.09687559", "0", "2"], ["83955.3", "0", "0", "0"], ["83957.9", "0.31447725", "0", "2"], ["83968.1", "0", "0", "0"], ["83975.4", "0.23837453", "0", "1"], ["84119", "0.35658448", "0", "2"], ["84120", "0.00006444", "0", "2"]], "bids": [["83938.2", "0.48028502", "0", "7"], ["83936.4", "1.05088851", "0", "14"], ["83918.8", "0.23837453", "0", "1"], ["83913.9", "0", "0", "0"], ["83890.6", "0", "0", "0"]], "ts": "1742577142600", "checksum": -776353343, "seqId": 49945041456, "prevSeqId": 49945041423}], "record_time": 1742577142.771658, "EXCHANGE": "OKX"}
{"arg": {"channel": "books", "instId": "BTC-USDT"}, "action": "update", "data": [{"asks": [["83938.3", "0", "0", "0"], ["83939.7", "0", "0", "0"], ["83942", "0", "0", "0"], ["83942.2", "0", "0", "0"], ["83942.9", "0", "0", "0"], ["83943.7", "0", "0", "0"], ["83944", "0", "0", "0"], ["83944.2", "0", "0", "0"], ["83944.8", "0.09227045", "0", "4"], ["83945", "0", "0", "0"], ["83945.7", "0", "0", "0"], ["83945.8", "0", "0", "0"], ["83946", "0", "0", "0"], ["83946.3", "0", "0", "0"], ["83946.5", "0", "0", "0"], ["83948.3", "0.00256092", "0", "2"], ["83948.4", "0", "0", "0"], ["83948.6", "0", "0", "0"], ["83950", "0.0639", "0", "2"], ["83950.4", "0", "0", "0"], ["83953.6", "0", "0", "0"], ["83953.8", "0", "0", "0"], ["83954.2", "0.01191806", "0", "1"], ["83954.4", "0.04009267", "0", "1"], ["83954.8", "0.0428883", "0", "1"], ["83954.9", "0.02739775", "0", "1"], ["83955.2", "0.09623902", "0", "1"], ["83956.1", "0", "0", "0"], ["83956.4", "0", "0", "0"], ["83956.8", "0", "0", "0"], ["83957.3", "0.06", "0", "2"], ["83957.9", "0.17898725", "0", "1"], ["83960.6", "0.01153238", "0", "1"], ["83962.3", "0.04", "0", "1"], ["83962.7", "0.83114763", "0", "3"], ["83963.7", "0", "0", "0"], ["83966.7", "0.07583798", "0", "3"], ["83972", "0.18761632", "0", "1"], ["83972.8", "0", "0", "0"], ["83975.2", "0.0008", "0", "2"], ["83975.4", "0.2383684", "0", "1"], ["83976", "0.0004", "0", "1"], ["83979.3", "0", "0", "0"], ["83980", "0", "0", "0"], ["83980.8", "0.17898725", "0", "1"], ["83981", "0", "0", "0"], ["83982.8", "0.1", "0", "1"], ["83983.2", "0.08084753", "0", "3"], ["83983.4", "0", "0", "0"], ["83984", "0.03999999", "0", "1"], ["83985.5", "0.05788252", "0", "1"], ["84000.2", "0.1227214", "0", "1"], ["84001", "0", "0", "0"], ["84007.3", "0", "0", "0"], ["84008.8", "0", "0", "0"], ["84010.2", "0", "0", "0"], ["84011.7", "0", "0", "0"], ["84091.7", "0.00001199", "0", "1"], ["84121.5", "0.00011161", "0", "1"], ["84122.2", "0.17898725", "0", "1"], ["84122.3", "0.08764", "0", "1"], ["84123.6", "0.00126715", "0", "1"], ["84123.7", "0.00005514", "0", "1"], ["84125", "0.00009264", "0", "1"], ["84125.1", "0.00015069", "0", "2"], ["84125.3", "0.00001956", "0", "1"], ["84126.2", "0.00001805", "0", "1"], ["84126.6", "0.00002004", "0", "1"], ["84127.5", "0.3565323", "0", "1"], ["84127.7", "0.00006401", "0", "1"], ["84129.9", "3.72", "0", "1"], ["84130.1", "0.00001199", "0", "1"], ["84130.5", "0.11889794", "0", "1"], ["84131.1", "0.00008649", "0", "2"], ["84131.2", "0.03", "0", "1"], ["84131.7", "0.14263366", "0", "2"], ["84132.5", "0.17898725", "0", "1"], ["84132.6", "0.0000434", "0", "1"], ["84132.8", "0.00002013", "0", "1"]], "bids": [["83944.7", "0.85720692", "0", "11"], ["83944.2", "0.07671413", "0", "1"], ["83944.1", "0.052", "0", "2"], ["83944", "0.0439", "0", "1"], ["83942.8", "0.052", "0", "2"], ["83942", "0.05581806", "0", "2"], ["83941.9", "0.052", "0", "2"], ["83940.1", "0.38046034", "0", "2"], ["83940", "0.13382011", "0", "3"], ["83939.7", "0.00112012", "0", "1"], ["83938.7", "1", "0", "1"], ["83938.6", "0.0428883", "0", "1"], ["83938.2", "0.06589", "0", "3"], ["83938", "0.0439", "0", "1"], ["83936.6", "0.28036304", "0", "1"], ["83936.5", "0.53596076", "0", "2"], ["83936.4", "0.21864336", "0", "3"], ["83936.1", "0", "0", "0"], ["83935", "0.0077429", "0", "1"], ["83934.7", "0.00001501", "0", "1"], ["83934.2", "0.04", "0", "1"], ["83933.3", "0.04438142", "0", "3"], ["83931.9", "0.00001199", "0", "1"], ["83931.6", "0", "0", "0"], ["83931.1", "0", "0", "0"], ["83930.8", "0.04100122", "0", "1"], ["83930", "0.0439", "0", "1"], ["83929.3", "0.04", "0", "1"], ["83928.6", "0.51188046", "0", "1"], ["83928.1", "0.00506", "0", "2"], ["83927.5", "0", "0", "0"], ["83926.3", "0.47619784", "0", "3"], ["83925.3", "0", "0", "0"], ["83925.1", "0.007815", "0", "1"], ["83924.9", "0.0643269", "0", "2"], ["83922.8", "0", "0", "0"], ["83921.3", "0.18761632", "0", "1"], ["83920.9", "0", "0", "0"], ["83919.9", "0.2383684", "0", "1"], ["83919.8", "0.49944158", "0", "2"], ["83919.7", "0", "0", "0"], ["83918.8", "0", "0", "0"], ["83918.4", "0", "0", "0"], ["83918.2", "0.05947069", "0", "1"], ["83912.1", "0", "0", "0"], ["83909.1", "0.01190949", "0", "1"], ["83908.6", "0", "0", "0"], ["83906.4", "0.08", "0", "2"], ["83905.6", "0.15889794", "0", "2"], ["83904.8", "0.17978679", "0", "3"], ["83903.9", "0.05326532", "0", "2"], ["83902.4", "0.013", "0", "1"], ["83901.4", "0.0249433", "0", "1"], ["83900.8", "0.75021", "0", "4"], ["83900", "0.05001", "0", "2"], ["83899.2", "0.35392649", "0", "1"], ["83890.8", "0.01835327", "0", "1"], ["83889.2", "0", "0", "0"], ["83889.1", "0", "0", "0"], ["83887.9", "0", "0", "0"], ["83886.2", "0", "0", "0"], ["83884.8", "0.04765129", "0", "1"], ["83877.5", "0.00100694", "0", "1"], ["83876.4", "0.0014526", "0", "1"], ["83869.8", "0.2808453", "0", "1"], ["83868.4", "0", "0", "0"], ["83867.7", "0", "0", "0"], ["83822.4", "0.18354279", "0", "2"], ["83818.1", "0.00006813", "0", "3"], ["83816.7", "0", "0", "0"], ["83808", "0", "0", "0"], ["83807.9", "0", "0", "0"], ["83807.8", "0", "0", "0"], ["83807.7", "0", "0", "0"], ["83807.5", "0", "0", "0"], ["83807.4", "0", "0", "0"], ["83807.3", "0", "0", "0"], ["83807.1", "0", "0", "0"], ["83806.8", "0", "0", "0"], ["83806.6", "0", "0", "0"]], "ts": "1742577142700", "checksum": 293163952, "seqId": 49945042101, "prevSeqId": 49945041456}], "record_time": 1742577142.882461, "EXCHANGE": "OKX"}
{"arg": {"channel": "books", "instId": "BTC-USDT"}, "action": "update", "data": [{"asks": [["83946", "0.0439", "0", "1"], ["83949.2", "0.01191878", "0", "1"], ["83950", "0.0439", "0", "1"], ["83954.2", "0", "0", "0"], ["83955.2", "0.06508723", "0", "1"], ["83955.7", "0.0302", "0", "2"], ["83957.3", "0", "0", "0"], ["83959.6", "0", "0", "0"], ["83960.7", "0.134837", "0", "1"], ["83962", "0.06", "0", "2"], ["83962.3", "0.21869", "0", "2"], ["83975.2", "0", "0", "0"], ["83975.4", "0.23837426", "0", "1"], ["83976", "0.0008", "0", "2"], ["83976.7", "0", "0", "0"], ["83976.8", "0.0004", "0", "1"], ["83978.4", "0", "0", "0"], ["83982.8", "0", "0", "0"], ["83983.2", "0.00084754", "0", "1"], ["83984", "0.07999999", "0", "2"], ["83984.8", "0.05190691", "0", "2"], ["83985.5", "0", "0", "0"], ["83987.3", "0.0196305", "0", "1"], ["83989.3", "0.21256978", "0", "3"], ["84013.4", "0.01133817", "0", "1"], ["84047", "1.28111549", "0", "4"], ["84047.9", "3.53940999", "0", "2"], ["84080", "0", "0", "0"], ["84085.6", "0.11338178", "0", "1"], ["84099.8", "0.01774536", "0", "1"]], "bids": [["83944.7", "0.4654119", "0", "7"], ["83944.1", "0.13518408", "0", "2"], ["83942.8", "0.016", "0", "1"], ["83942", "0.0439", "0", "1"], ["83941.9", "0.016", "0", "1"], ["83940", "0.04391", "0", "2"], ["83938.7", "0", "0", "0"], ["83937.3", "1", "0", "1"], ["83937.1", "0.01191878", "0", "1"], ["83932.8", "0.11923105", "0", "2"], ["83931.1", "0.02859924", "0", "1"], ["83929.6", "0.17869", "0", "1"], ["83928.6", "0.35320512", "0", "1"], ["83928.5", "0.036", "0", "1"], ["83925.1", "0", "0", "0"], ["83924.6", "0.134837", "0", "1"], ["83922.6", "0", "0", "0"], ["83919.9", "0", "0", "0"], ["83918.3", "0.23837464", "0", "1"], ["83918.2", "0", "0", "0"], ["83917.9", "0.000015", "0", "1"], ["83900.8", "0.65021", "0", "2"], ["83900", "0.10001", "0", "3"], ["83899.2", "0.40392649", "0", "2"], ["83896.8", "0.0183545", "0", "1"], ["83890.8", "0", "0", "0"], ["83879.8", "0", "0", "0"], ["83825.2", "0.18354507", "0", "1"], ["83822.4", "0.00001007", "0", "1"], ["83808.2", "0", "0", "0"]], "ts": "1742577142800", "checksum": -403748205, "seqId": 49945042187, "prevSeqId": 49945042101}], "record_time": 1742577142.971751, "EXCHANGE": "OKX"}
{"arg": {"channel": "books", "instId": "BTC-USDT"}, "action": "update", "data": [{"asks": [["83944.8", "0.26863373", "0", "5"], ["83949.2", "0", "0", "0"], ["83951.5", "0.01191845", "0", "1"], ["83957.5", "0.0102", "0", "1"], ["83959.5", "0.23144471", "0", "2"], ["83960.4", "0.35738", "0", "1"], ["83963.8", "0.03062", "0", "1"], ["83965.4", "0.06001501", "0", "3"], ["83976", "0", "0", "0"], ["83976.8", "0.0008", "0", "2"], ["83977.6", "0.0004", "0", "1"], ["83984", "0", "0", "0"], ["83984.8", "0.09190691", "0", "3"], ["83985.6", "0.0519068", "0", "2"], ["83991.5", "0", "0", "0"], ["83999.7", "0.00002157", "0", "1"], ["84005.7", "0.35016", "0", "2"], ["84132.6", "0", "0", "0"], ["84132.8", "0", "0", "0"]], "bids": [["83939.4", "0.01191845", "0", "1"], ["83938.2", "0.052", "0", "2"], ["83937.1", "0", "0", "0"], ["83932.8", "0.21793104", "0", "1"], ["83930.2", "0.35738", "0", "1"], ["83925.3", "0.000039", "0", "1"], ["83925.2", "0.08411161", "0", "3"], ["83921.8", "0.25016", "0", "1"], ["83920.5", "0.17869", "0", "1"], ["83919.3", "0.069", "0", "2"], ["83906.4", "0", "0", "0"], ["83905.6", "0.19889794", "0", "3"], ["83904.8", "0.21978679", "0", "4"], ["83885.2", "0", "0", "0"], ["83809.2", "0", "0", "0"], ["83808.7", "0", "0", "0"]], "ts": "1742577142900", "checksum": 580379017, "seqId": 49945042241, "prevSeqId": 49945042187}], "record_time": 1742577143.071291, "EXCHANGE": "OKX"}
{"arg": {"channel": "books", "instId": "BTC-USDT"}, "action": "update", "data": [{"asks": [["83944.8", "0.34749517", "0", "6"], ["83949.3", "0.01191876", "0", "1"], ["83951.5", "0", "0", "0"], ["83965.4", "0.12001501", "0", "5"], ["83968.2", "0.47357896", "0", "2"], ["83969.8", "1", "0", "1"], ["83978.4", "0.01774536", "0", "1"], ["84010.5", "0.824085", "0", "1"], ["84021.3", "0.24506077", "0", "3"], ["84099.8", "0", "0", "0"], ["84131.7", "0", "0", "0"], ["84132.5", "0", "0", "0"]], "bids": [["83944.7", "0.6878575", "0", "11"], ["83940.1", "0.05514553", "0", "1"], ["83939.4", "0", "0", "0"], ["83937.3", "0.01191876", "0", "1"], ["83936.6", "0.57429702", "0", "1"], ["83935.9", "1", "0", "1"], ["83927.1", "0.12508", "0", "1"], ["83925.2", "0.15311161", "0", "5"], ["83912", "0.045059", "0", "2"], ["83897.4", "0.825195", "0", "1"], ["83809.6", "0", "0", "0"], ["83809.4", "0", "0", "0"]], "ts": "1742577143000", "checksum": -801139165, "seqId": 49945042287, "prevSeqId": 49945042241}], "record_time": 1742577143.170661, "EXCHANGE": "OKX"}
{"arg": {"channel": "books", "instId": "BTC-USDT"}, "action": "update", "data": [{"asks": [["83944.8", "0.26089517", "0", "5"], ["83949.3", "0", "0", "0"], ["83951.5", "0.01191844", "0", "1"], ["83953.5", "0.01021", "0", "1"], ["83957.5", "0", "0", "0"], ["83970.4", "0.01190896", "0", "1"], ["83997.8", "0", "0", "0"]], "bids": [["83944.7", "0.7108575", "0", "13"], ["83940.1", "0.35241933", "0", "2"], ["83939.5", "0.01191844", "0", "1"], ["83939.1", "0.01389", "0", "1"], ["83937.3", "1", "0", "1"], ["83936.6", "0.30997303", "0", "1"], ["83935.9", "0", "0", "0"], ["83919.3", "0.036", "0", "1"], ["83915", "1", "0", "1"], ["83809.8", "0", "0", "0"], ["83809.7", "0", "0", "0"]], "ts": "1742577143100", "checksum": -1551505089, "seqId": 49945042320, "prevSeqId": 49945042287}], "record_time": 1742577143.271901, "EXCHANGE": "OKX"}
{"arg": {"channel": "books", "instId": "BTC-USDT"}, "action": "update", "data": [{"asks": [["83950.4", "0.0428883", "0", "1"], ["83951.1", "0.00774318", "0", "1"], ["83954.8", "0", "0", "0"], ["83983.3", "0.23676155", "0", "3"], ["83990", "0.54057812", "0", "3"], ["84010.2", "0.43802182", "0", "1"], ["84131.1", "0", "0", "0"], ["84131.2", "0", "0", "0"]], "bids": [["83938.6", "0", "0", "0"], ["83936.8", "0.00001199", "0", "1"], ["83934.7", "0.04290331", "0", "2"], ["83922.7", "0.05955265", "0", "1"], ["83919.3", "0", "0", "0"], ["83916", "0.31256978", "0", "3"], ["83915.1", "0.41425837", "0", "1"], ["83886.5", "1.11182351", "0", "1"], ["83886", "0.00929245", "0", "2"], ["83810.1", "0", "0", "0"], ["83810", "0", "0", "0"]], "ts": "1742577143200", "checksum": -625732430, "seqId": 49945042337, "prevSeqId": 49945042320}], "record_time": 1742577143.37058, "EXCHANGE": "OKX"}
{"arg": {"channel": "books", "instId": "BTC-USDT"}, "action": "update", "data": [{"asks": [["83965.9", "0.01774536", "0", "1"], ["83978.4", "0", "0", "0"]], "bids": [], "ts": "1742577143300", "checksum": -625732430, "seqId": 49945042343, "prevSeqId": 49945042337}], "record_time": 1742577143.487505, "EXCHANGE": "OKX"}
{"arg": {"channel": "books", "instId": "BTC-USDT"}, "action": "update", "data": [{"asks": [["83944.8", "0.00567045", "0", "3"], ["83946", "0", "0", "0"], ["83947.7", "0.11917902", "0", "1"], ["83949.4", "0", "0", "0"], ["83953.3", "0", "0", "0"], ["83953.5", "0", "0", "0"], ["83959.5", "0.1123656", "0", "1"], ["83960.4", "0", "0", "0"], ["83962.7", "0.79114763", "0", "2"], ["83965.5", "0.04", "0", "1"], ["83966", "0.01190959", "0", "1"], ["83968.2", "0.24393029", "0", "1"], ["83969.8", "0", "0", "0"], ["83970.4", "0", "0", "0"], ["83974.2", "0.01190842", "0", "1"], ["83975.4", "0", "0", "0"], ["83978.4", "0.23836204", "0", "1"], ["83995.4", "0.11889794", "0", "1"], ["84131.1", "0.00008649", "0", "2"], ["84131.2", "0.03", "0", "1"], ["84131.7", "0.14263366", "0", "2"], ["84132.5", "0.17898725", "0", "1"]], "bids": [["83944.7", "0.9308575", "0", "15"], ["83942.6", "0.01389", "0", "1"], ["83940.1", "0.07844141", "0", "1"], ["83939.1", "0", "0", "0"], ["83937.9", "0.08991011", "0", "1"], ["83937.8", "0.04169", "0", "1"], ["83937.3", "0", "0", "0"], ["83937", "0.58072612", "0", "1"], ["83936.9", "1", "0", "1"], ["83936.6", "0", "0", "0"], ["83933.3", "0.00269142", "0", "2"], ["83928.6", "0.5129031", "0", "2"], ["83924.9", "0.05956073", "0", "1"], ["83921.9", "0.24036204", "0", "2"], ["83920.5", "0", "0", "0"], ["83919.7", "0.00357264", "0", "1"], ["83918.3", "0", "0", "0"], ["83918", "0.005", "0", "1"], ["83917", "0.00037199", "0", "2"], ["83915.1", "0", "0", "0"], ["83915", "0", "0", "0"], ["83906.9", "0", "0", "0"], ["83861", "0.01736", "0", "1"], ["83847", "0", "0", "0"], ["83810.1", "0.00001655", "0", "1"], ["83810", "0.22033855", "0", "2"]], "ts": "1742577143400", "checksum": 2036008583, "seqId": 49945042415, "prevSeqId": 49945042343}], "record_time": 1742577143.571351, "EXCHANGE": "OKX"}
{"arg": {"channel": "books", "instId": "BTC-USDT"}, "action": "update", "data": [{"asks": [["83948", "0", "0", "0"], ["83950.2", "0.05593796", "0", "1"], ["83950.4", "0", "0", "0"], ["83954.5", "0.0428883", "0", "1"], ["83955.7", "0.0102", "0", "1"], ["83956.4", "0.01191259", "0", "1"], ["83957.6", "0.02", "0", "1"], ["83962.3", "0.04", "0", "1"], ["83962.7", "0.29033617", "0", "1"], ["83965.5", "0", "0", "0"], ["83965.9", "0", "0", "0"], ["83967.2", "0.04", "0", "1"], ["83967.7", "1.59326088", "0", "1"], ["83978.4", "0.23835672", "0", "1"], ["83984", "1", "0", "1"], ["83984.9", "0", "0", "0"], ["83991.3", "0", "0", "0"], ["83991.6", "0.00084754", "0", "1"], ["83996.1", "0.00103317", "0", "1"], ["83997.1", "2.79425195", "0", "1"], ["84002.5", "0.0010364", "0", "1"], ["84011", "0.03890198", "0", "2"], ["84025", "0.01774536", "0", "1"], ["84131.1", "0", "0", "0"], ["84131.2", "0", "0", "0"], ["84131.7", "0", "0", "0"], ["84132.5", "0", "0", "0"]], "bids": [["83940.1", "0.38839591", "0", "2"], ["83938.6", "0.0428883", "0", "1"], ["83938.2", "1.052", "0", "3"], ["83937", "0.26785963", "0", "1"], ["83936.9", "0", "0", "0"], ["83934.7", "0.00001501", "0", "1"], ["83925", "0.23835672", "0", "1"], ["83921.9", "0.002", "0", "1"], ["83919.7", "0", "0", "0"], ["83914", "1.60071847", "0", "1"], ["83907", "0", "0", "0"], ["83897.8", "0.05560264", "0", "2"], ["83886.5", "0", "0", "0"], ["83886.4", "0", "0", "0"], ["83847", "0.14566622", "0", "1"], ["83809.8", "0.00013882", "0", "1"]], "ts": "1742577143500", "checksum": -1284219783, "seqId": 49945042462, "prevSeqId": 49945042415}], "record_time": 1742577143.671095, "EXCHANGE": "OKX"}
{"arg": {"channel": "books", "instId": "BTC-USDT"}, "action": "update", "data": [{"asks": [["83944.8", "0.00777109", "0", "5"], ["83959.2", "0.0102", "0", "1"], ["83962.7", "0.41985184", "0", "2"], ["83962.9", "0.35738", "0", "1"], ["83964.8", "0.17869", "0", "1"], ["83967.6", "0.68204851", "0", "1"], ["83968.2", "0", "0", "0"], ["83975.4", "0.23836659", "0", "1"], ["83978.4", "0", "0", "0"], ["83984", "0", "0", "0"], ["84011", "0.00001198", "0", "1"], ["84130.1", "0", "0", "0"], ["84130.5", "0", "0", "0"]], "bids": [["83944.1", "0.14907408", "0", "3"], ["83942.6", "0", "0", "0"], ["83940.1", "0.07844141", "0", "1"], ["83938.2", "0.052", "0", "2"], ["83937", "0.53437718", "0", "2"], ["83936.4", "1.21864336", "0", "4"], ["83925", "0", "0", "0"], ["83923", "0.17869", "0", "1"], ["83919.9", "0.23836659", "0", "1"]], "ts": "1742577143600", "checksum": -53204306, "seqId": 49945042485, "prevSeqId": 49945042462}], "record_time": 1742577143.771326, "EXCHANGE": "OKX"}
{"arg": {"channel": "books", "instId": "BTC-USDT"}, "action": "update", "data": [{"asks": [["83944.8", "0.01092205", "0", "8"], ["83967.5", "0.01774536", "0", "1"], ["83968.8", "1", "0", "1"], ["83984.5", "0.01190696", "0", "1"], ["83985.6", "0.03999999", "0", "1"], ["84025", "0", "0", "0"], ["84127.7", "0", "0", "0"], ["84129.9", "0", "0", "0"]], "bids": [["83907.2", "0.08", "0", "2"], ["83906.4", "0.0408", "0", "3"], ["83905.6", "0.11929747", "0", "2"], ["83904.8", "0.17898725", "0", "1"], ["83904", "0", "0", "0"], ["83900.8", "0.75021", "0", "4"], ["83900", "0.05001", "0", "2"], ["83899.2", "0.35392649", "0", "1"], ["83884.6", "2.817032", "0", "1"], ["83810", "0", "0", "0"], ["83809.8", "0", "0", "0"]], "ts": "1742577143700", "checksum": -669364929, "seqId": 49945042513, "prevSeqId": 49945042485}], "record_time": 1742577143.870887, "EXCHANGE": "OKX"}
{"arg": {"channel": "books", "instId": "BTC-USDT"}, "action": "update", "data": [{"asks": [], "bids": [["83907.3", "0.5776526", "0", "1"], ["83905.3", "0", "0", "0"], ["83865.3", "0.58226341", "0", "1"], ["83863.3", "0.00004163", "0", "1"], ["83810.1", "0", "0", "0"]], "ts": "1742577143800", "checksum": -669364929, "seqId": 49945042517, "prevSeqId": 49945042513}], "record_time": 1742577143.97094, "EXCHANGE": "OKX"}
{"arg": {"channel": "books", "instId": "BTC-USDT"}, "action": "update", "data": [{"asks": [["83944.8", "0.01197237", "0", "9"], ["83956.4", "0", "0", "0"], ["83962.9", "0", "0", "0"], ["83965.4", "0.47739501", "0", "6"], ["83975.4", "0", "0", "0"], ["83978.4", "0.23836034", "0", "1"], ["84030.9", "0.34370513", "0", "2"], ["84127.7", "0.00006401", "0", "1"], ["84129.9", "3.72", "0", "1"]], "bids": [["83940.1", "0.38839591", "0", "2"], ["83937.7", "1", "0", "1"], ["83937", "0.26785963", "0", "1"], ["83936.4", "0.21864336", "0", "3"], ["83925.3", "0", "0", "0"], ["83923.1", "0.23836034", "0", "1"], ["83919.9", "0", "0", "0"], ["83914.1", "0.11889794", "0", "1"], ["83866.2", "0.07165411", "0", "2"], ["83811.3", "0", "0", "0"]], "ts": "1742577143900", "checksum": -1362433005, "seqId": 49945042541, "prevSeqId": 49945042517}], "record_time": 1742577144.072991, "EXCHANGE": "OKX"}
{"arg": {"channel": "books", "instId": "BTC-USDT"}, "action": "update", "data": [{"asks": [["83944.8", "0.01302269", "0", "10"], ["83945.6", "0.11918197", "0", "1"], ["83947.7", "0", "0", "0"], ["83948", "0.0439", "0", "1"], ["83956.8", "0.00018", "0", "1"], ["83965.3", "0.01774536", "0", "1"], ["83967.5", "0", "0", "0"], ["83975.4", "0.23836741", "0", "1"], ["83978.4", "0", "0", "0"], ["83982.8", "0.01190721", "0", "1"], ["83986.3", "0", "0", "0"], ["84018.1", "0", "0", "0"], ["84066.4", "0", "0", "0"]], "bids": [["83923.1", "0", "0", "0"], ["83917.7", "0.23837181", "0", "1"]], "ts": "1742577144000", "checksum": 2129886817, "seqId": 49945042562, "prevSeqId": 49945042541}], "record_time": 1742577144.17103, "EXCHANGE": "OKX"}
{"arg": {"channel": "books", "instId": "BTC-USDT"}, "action": "update", "data": [{"asks": [["83962.9", "0.35738", "0", "1"], ["83965.4", "0.12001501", "0", "5"], ["83983.7", "0.01190708", "0", "1"], ["83984.2", "0.01190701", "0", "1"], ["83985", "0.2", "0", "1"], ["83987.2", "0", "0", "0"], ["83988.6", "0.47906922", "0", "1"], ["83990", "0.48207351", "0", "2"], ["84013.4", "0", "0", "0"], ["84016", "0.01134902", "0", "2"], ["84025.4", "0.01428139", "0", "1"], ["84030.9", "0.41510746", "0", "3"], ["84073.7", "0.00251813", "0", "1"], ["84126.6", "0", "0", "0"], ["84127.5", "0", "0", "0"], ["84127.7", "0", "0", "0"], ["84129.9", "0", "0", "0"]], "bids": [["83918.8", "0.23837088", "0", "1"], ["83917.7", "0", "0", "0"], ["83916", "0.11256978", "0", "2"], ["83898.1", "0.01835403", "0", "1"], ["83896.8", "0", "0", "0"], ["83876.5", "0.00218667", "0", "1"], ["83868.5", "0", "0", "0"], ["83866.2", "0.14319661", "0", "3"], ["83826.8", "0.18354037", "0", "1"], ["83825.2", "0", "0", "0"]], "ts": "1742577144100", "checksum": 2129886817, "seqId": 49945042604, "prevSeqId": 49945042562}], "record_time": 1742577144.271029, "EXCHANGE": "OKX"}
{"arg": {"channel": "books", "instId": "BTC-USDT"}, "action": "update", "data": [{"asks": [["83965.3", "0", "0", "0"], ["83967.5", "0.01774536", "0", "1"], ["83985.8", "0.06141715", "0", "1"], ["84126.2", "0", "0", "0"]], "bids": [["83937.7", "0", "0", "0"], ["83936.3", "1", "0", "1"], ["83928.9", "0.001953", "0", "1"], ["83922.7", "0", "0", "0"], ["83918.8", "0.23837084", "0", "1"]], "ts": "1742577144200", "checksum": -1548906285, "seqId": 49945042616, "prevSeqId": 49945042604}], "record_time": 1742577144.370529, "EXCHANGE": "OKX"}
{"arg": {"channel": "books", "instId": "BTC-USDT"}, "action": "update", "data": [{"asks": [["83950.2", "0.09607922", "0", "2"], ["83951", "0.2", "0", "1"], ["83985", "0", "0", "0"], ["83995.8", "1.05222701", "0", "2"]], "bids": [["83944.7", "1.01018483", "0", "16"], ["83940.1", "0.07844141", "0", "1"], ["83937", "0.53437718", "0", "2"], ["83933.3", "0.0015", "0", "1"], ["83918.2", "0.05746368", "0", "1"], ["83909.7", "0.31", "0", "1"], ["83907.4", "0.65181886", "0", "1"], ["83812.1", "0", "0", "0"], ["83812", "0", "0", "0"], ["83811.9", "0", "0", "0"]], "ts": "1742577144300", "checksum": 1551117688, "seqId": 49945042629, "prevSeqId": 49945042616}], "record_time": 1742577144.471635, "EXCHANGE": "OKX"}
{"arg": {"channel": "books", "instId": "BTC-USDT"}, "action": "update", "data": [{"asks": [["83948", "0", "0", "0"], ["83950.2", "0.05593796", "0", "1"], ["83951", "0", "0", "0"], ["83956.8", "0", "0", "0"], ["84013.5", "0", "0", "0"], ["84126.2", "0.00001805", "0", "1"], ["84126.6", "0.00002004", "0", "1"], ["84127.5", "0.3565323", "0", "1"], ["84127.7", "0.00006401", "0", "1"]], "bids": [["83919.9", "0.23836725", "0", "1"], ["83918.8", "0", "0", "0"], ["83907.2", "0", "0", "0"], ["83906.4", "0.0808", "0", "4"], ["83905.6", "0.15929747", "0", "3"], ["83903.9", "0.0286", "0", "1"], ["83901.4", "0", "0", "0"], ["83894.9", "0.02466532", "0", "1"], ["83812.1", "1.72263", "0", "1"]], "ts": "1742577144400", "checksum": 1685640854, "seqId": 49945042647, "prevSeqId": 49945042629}], "record_time": 1742577144.571677, "EXCHANGE": "OKX"}
{"arg": {"channel": "books", "instId": "BTC-USDT"}, "action": "update", "data": [{"asks": [["83944.8", "0.00983965", "0", "10"], ["83962.9", "0", "0", "0"], ["83968.8", "0", "0", "0"], ["83975.4", "0", "0", "0"], ["83976.8", "0", "0", "0"], ["83977.6", "0.0008", "0", "2"], ["83978.4", "0.23875826", "0", "2"], ["83984.8", "0.01190692", "0", "1"], ["83985.6", "0.07999999", "0", "2"], ["83986.4", "0.03999999", "0", "1"], ["84129.9", "3.72", "0", "1"], ["84130.1", "0.00001199", "0", "1"]], "bids": [["83944.7", "1.01137609", "0", "17"], ["83940.1", "0.38839591", "0", "2"], ["83937.8", "1.04169", "0", "2"], ["83937", "0.26785963", "0", "1"], ["83936.3", "0", "0", "0"], ["83923.6", "0.23835888", "0", "1"], ["83919.9", "0", "0", "0"], ["83919.8", "0.32909819", "0", "1"], ["83906.4", "0.08", "0", "2"], ["83905.6", "0.15969747", "0", "4"], ["83904.8", "0.17938679", "0", "2"], ["83894.4", "0.0249433", "0", "1"]], "ts": "1742577144500", "checksum": -1983732099, "seqId": 49945042685, "prevSeqId": 49945042647}], "record_time": 1742577144.671349, "EXCHANGE": "OKX"}
{"arg": {"channel": "books", "instId": "BTC-USDT"}, "action": "update", "data": [{"asks": [["83965.4", "0.47739501", "0", "6"], ["83967.4", "0.11897", "0", "1"], ["84021.2", "0.09484017", "0", "3"], ["84130.1", "0", "0", "0"]], "bids": [], "ts": "1742577144600", "checksum": -1983732099, "seqId": 49945042693, "prevSeqId": 49945042685}], "record_time": 1742577144.771445, "EXCHANGE": "OKX"}
{"arg": {"channel": "books", "instId": "BTC-USDT"}, "action": "update", "data": [{"asks": [["83950.2", "0", "0", "0"], ["83958", "0.003129", "0", "1"], ["83960.7", "0", "0", "0"], ["83965.3", "0.01774536", "0", "1"], ["83967.5", "0", "0", "0"], ["84130.1", "0.00001199", "0", "1"]], "bids": [["83923.6", "0", "0", "0"], ["83921.9", "0.2403606", "0", "2"], ["83812", "0.00589921", "0", "1"]], "ts": "1742577144700", "checksum": -1533941648, "seqId": 49945042700, "prevSeqId": 49945042693}], "record_time": 1742577144.871432, "EXCHANGE": "OKX"}
{"arg": {"channel": "books", "instId": "BTC-USDT"}, "action": "update", "data": [{"asks": [["83949.9", "0.05684792", "0", "2"], ["83964.5", "0.25372694", "0", "2"], ["83968.7", "1", "0", "1"], ["84130.1", "0", "0", "0"]], "bids": [["83927.8", "0.003573", "0", "1"], ["83897.8", "0.05203", "0", "1"], ["83812", "0", "0", "0"]], "ts": "1742577144800", "checksum": 12316224, "seqId": 49945042706, "prevSeqId": 49945042700}], "record_time": 1742577144.970371, "EXCHANGE": "OKX"}
{"arg": {"channel": "books", "instId": "BTC-USDT"}, "action": "update", "data": [{"asks": [["83967.4", "0", "0", "0"], ["83975.4", "0.23836746", "0", "1"], ["83978.4", "0.0004", "0", "1"]], "bids": [["83940.1", "0.07844141", "0", "1"], ["83937.8", "0.04169", "0", "1"], ["83937", "0.53401975", "0", "2"], ["83936.5", "1.53596076", "0", "3"], ["83921.9", "0.002", "0", "1"], ["83918.8", "0.23836907", "0", "1"], ["83812.1", "0", "0", "0"]], "ts": "1742577144900", "checksum": -1144644668, "seqId": 49945042718, "prevSeqId": 49945042706}], "record_time": 1742577145.07042, "EXCHANGE": "OKX"}
{"arg": {"channel": "books", "instId": "BTC-USDT"}, "action": "update", "data": [{"asks": [], "bids": [["83929.4", "0.02603495", "0", "3"], ["83928.9", "0", "0", "0"], ["83812.1", "1.72263", "0", "1"]], "ts": "1742577145000", "checksum": -1144644668, "seqId": 49945042723, "prevSeqId": 49945042718}], "record_time": 1742577145.171177, "EXCHANGE": "OKX"}
{"arg": {"channel": "books", "instId": "BTC-USDT"}, "action": "update", "data": [{"asks": [["83975.4", "0", "0", "0"], ["83976.2", "0.23836599", "0", "1"]], "bids": [["83929.4", "0.02163395", "0", "2"], ["83927.8", "0", "0", "0"], ["83919.9", "0.23836599", "0", "1"], ["83918.8", "0", "0", "0"], ["83917", "0.10037199", "0", "3"], ["83907.3", "0.5812256", "0", "2"], ["83812", "0.00589921", "0", "1"]], "ts": "1742577145100", "checksum": -1144644668, "seqId": 49945042735, "prevSeqId": 49945042723}], "record_time": 1742577145.270252, "EXCHANGE": "OKX"}
{"arg": {"channel": "books", "instId": "BTC-USDT"}, "action": "update", "data": [{"asks": [["83965.4", "0.12001501", "0", "5"], ["83976.2", "0", "0", "0"], ["83978.4", "0.23876394", "0", "2"], ["84130.1", "0.00001199", "0", "1"]], "bids": [["83940.1", "0.38839591", "0", "2"], ["83937.8", "1.04169", "0", "2"], ["83937", "0.26785963", "0", "1"], ["83936.5", "0.53596076", "0", "2"], ["83921.4", "0.23836381", "0", "1"], ["83919.9", "0", "0", "0"]], "ts": "1742577145200", "checksum": 12316224, "seqId": 49945042756, "prevSeqId": 49945042735}], "record_time": 1742577145.37139, "EXCHANGE": "OKX"}
{"arg": {"channel": "books", "instId": "BTC-USDT"}, "action": "update", "data": [{"asks": [["83965.3", "0", "0", "0"], ["83967.5", "0.01774536", "0", "1"], ["83976.2", "0.23836554", "0", "1"], ["83978.4", "0.0004", "0", "1"], ["83986", "0.2", "0", "1"], ["83991.7", "0.39996997", "0", "2"], ["84129.9", "0", "0", "0"], ["84130.1", "0", "0", "0"]], "bids": [["83944.7", "0.81137609", "0", "15"], ["83932.7", "0.000015", "0", "1"], ["83921.4", "0", "0", "0"], ["83919.9", "0.23836554", "0", "1"], ["83914.1", "0.70857185", "0", "2"], ["83910.2", "0.471957", "0", "1"], ["83884.7", "0.95205552", "0", "1"], ["83873.7", "0.36324809", "0", "2"], ["83873.6", "0", "0", "0"], ["83812.1", "0", "0", "0"], ["83812", "0", "0", "0"]], "ts": "1742577145300", "checksum": -1907840301, "seqId": 49945042788, "prevSeqId": 49945042756}], "record_time": 1742577145.47208, "EXCHANGE": "OKX"}
{"arg": {"channel": "books", "instId": "BTC-USDT"}, "action": "update", "data": [{"asks": [["83965.4", "0.47739501", "0", "6"], ["83976.2", "0.23836557", "0", "1"], ["83982.1", "0.0119073", "0", "1"], ["83984.8", "0", "0", "0"], ["83986", "0", "0", "0"], ["84129.9", "3.72", "0", "1"]], "bids": [["83919.9", "0.23836557", "0", "1"], ["83915", "1", "0", "1"], ["83812.4", "0", "0", "0"]], "ts": "1742577145400", "checksum": -1907840301, "seqId": 49945042803, "prevSeqId": 49945042788}], "record_time": 1742577145.573712, "EXCHANGE": "OKX"}
{"arg": {"channel": "books", "instId": "BTC-USDT"}, "action": "update", "data": [{"asks": [["83976.2", "0", "0", "0"], ["83978.4", "0.23876355", "0", "2"], ["84130.1", "0.00001199", "0", "1"]], "bids": [["83921.9", "0.24036355", "0", "2"], ["83919.9", "0", "0", "0"], ["83812.4", "0.05367661", "0", "2"]], "ts": "1742577145500", "checksum": -1907840301, "seqId": 49945042809, "prevSeqId": 49945042803}], "record_time": 1742577145.671259, "EXCHANGE": "OKX"}
{"arg": {"channel": "books", "instId": "BTC-USDT"}, "action": "update", "data": [{"asks": [["83945.6", "0", "0", "0"], ["83947.7", "0.11917909", "0", "1"], ["83956.6", "0.0000225", "0", "1"], ["83958", "0", "0", "0"], ["83965.3", "0.01774536", "0", "1"], ["83967.5", "0", "0", "0"], ["83990", "1.48207351", "0", "3"]], "bids": [["83915", "0", "0", "0"], ["83812.1", "1.72263", "0", "1"]], "ts": "1742577145600", "checksum": 1231217774, "seqId": 49945042818, "prevSeqId": 49945042809}], "record_time": 1742577145.770314, "EXCHANGE": "OKX"}
{"arg": {"channel": "books", "instId": "BTC-USDT"}, "action": "update", "data": [{"asks": [["83990", "0.48207351", "0", "2"]], "bids": [], "ts": "1742577145700", "checksum": 1231217774, "seqId": 49945042820, "prevSeqId": 49945042818}], "record_time": 1742577145.871071, "EXCHANGE": "OKX"}
{"arg": {"channel": "books", "instId": "BTC-USDT"}, "action": "update", "data": [{"asks": [], "bids": [["83925.3", "0.11921065", "0", "1"], ["83911.3", "0", "0", "0"], ["83820.2", "0", "0", "0"], ["83812", "0.00589921", "0", "1"]], "ts": "1742577145800", "checksum": 1231217774, "seqId": 49945042825, "prevSeqId": 49945042820}], "record_time": 1742577145.970761, "EXCHANGE": "OKX"}
{"arg": {"channel": "books", "instId": "BTC-USDT"}, "action": "update", "data": [{"asks": [["83945.8", "0.11918169", "0", "1"], ["83947.7", "0", "0", "0"], ["83976.2", "0.23836579", "0", "1"], ["83978.4", "0.0004", "0", "1"], ["84030.9", "0.34370513", "0", "2"], ["84130.1", "0", "0", "0"]], "bids": [["83921.9", "0.002", "0", "1"], ["83919.9", "0.23836579", "0", "1"], ["83866.2", "0.07165411", "0", "2"], ["83819.2", "0.00001297", "0", "1"], ["83812", "0", "0", "0"]], "ts": "1742577145900", "checksum": -669563483, "seqId": 49945042840, "prevSeqId": 49945042825}], "record_time": 1742577146.0708, "EXCHANGE": "OKX"}
{"arg": {"channel": "books", "instId": "BTC-USDT"}, "action": "update", "data": [{"asks": [["83945.8", "0", "0", "0"], ["83976.2", "0", "0", "0"], ["83977.6", "0", "0", "0"], ["83978.4", "0.0008", "0", "2"], ["83979.2", "0.0004", "0", "1"], ["83980.1", "0.23835675", "0", "1"], ["83985.6", "0", "0", "0"], ["83986.4", "0.07999999", "0", "2"], ["83987.2", "0.03999999", "0", "1"], ["84030.9", "0.41510746", "0", "3"], ["84130.1", "0.00001199", "0", "1"]], "bids": [["83940", "1.04391", "0", "3"], ["83939.5", "0", "0", "0"], ["83937.8", "0.04169", "0", "1"], ["83924.7", "0.24732677", "0", "2"], ["83919.9", "0", "0", "0"], ["83866.2", "0.14319661", "0", "3"], ["83812", "0.00589921", "0", "1"], ["83811.9", "0.0010552", "0", "1"]], "ts": "1742577146000", "checksum": -103582890, "seqId": 49945042870, "prevSeqId": 49945042840}], "record_time": 1742577146.171348, "EXCHANGE": "OKX"}
{"arg": {"channel": "books", "instId": "BTC-USDT"}, "action": "update", "data": [{"asks": [["83948.4", "0.1191781", "0", "1"], ["83951.5", "0", "0", "0"], ["83952.3", "0", "0", "0"], ["83954.2", "0.01191801", "0", "1"], ["83962.4", "0", "0", "0"], ["83978.4", "0.23915851", "0", "3"], ["83980.1", "0", "0", "0"], ["84016", "0.00001198", "0", "1"], ["84018.5", "0.01132276", "0", "1"], ["84085.6", "0", "0", "0"], ["84088.5", "0.11326308", "0", "2"], ["84130.5", "0.11889794", "0", "1"], ["84131.1", "0.00008649", "0", "2"]], "bids": [["83944.7", "0.81316309", "0", "16"], ["83943.3", "0.04650051", "0", "1"], ["83942", "0.05581816", "0", "2"], ["83940", "0.04391", "0", "2"], ["83939.1", "0.06975077", "0", "1"], ["83937.9", "1.08991011", "0", "2"], ["83928.1", "0.00006", "0", "1"], ["83924.9", "0.08339705", "0", "2"], ["83924.7", "0.00897002", "0", "1"], ["83923.1", "0.23835988", "0", "1"], ["83918", "0", "0", "0"], ["83915.7", "0", "0", "0"], ["83912.9", "0.01190698", "0", "1"], ["83900.9", "0.01835368", "0", "1"], ["83898.1", "0", "0", "0"], ["83896", "0", "0", "0"], ["83876.6", "0.0014527", "0", "1"], ["83876.4", "0", "0", "0"], ["83828.6", "0.18353682", "0", "1"], ["83826.8", "0", "0", "0"]], "ts": "1742577146100", "checksum": 865367470, "seqId": 49945042912, "prevSeqId": 49945042870}], "record_time": 1742577146.274921, "EXCHANGE": "OKX"}
{"arg": {"channel": "books", "instId": "BTC-USDT"}, "action": "update", "data": [{"asks": [["83944.8", "0", "0", "0"], ["83945.1", "0", "0", "0"], ["83946.6", "0", "0", "0"], ["83948.3", "0", "0", "0"], ["83948.4", "0", "0", "0"], ["83949.9", "0", "0", "0"], ["83950", "0", "0", "0"], ["83951.6", "0", "0", "0"], ["83953.6", "0.03566938", "0", "1"], ["83958.1", "0", "0", "0"], ["83959.5", "0.08222531", "0", "1"], ["83960.9", "0", "0", "0"], ["83964.5", "0.11889794", "0", "1"], ["83964.8", "0", "0", "0"], ["83965.2", "0.036", "0", "1"], ["83965.4", "0.12001501", "0", "5"], ["83966.2", "0.036", "0", "1"], ["83966.7", "0.05983798", "0", "2"], ["83967.7", "0", "0", "0"], ["83968.7", "0", "0", "0"], ["83969", "0.17898725", "0", "1"], ["83972", "0", "0", "0"], ["83978.4", "0.0008", "0", "2"], ["83980.1", "0.23835694", "0", "1"], ["83984.7", "0", "0", "0"], ["83985.4", "0", "0", "0"], ["83990", "0.35697351", "0", "1"], ["84018.5", "0", "0", "0"], ["84069.9", "0", "0", "0"], ["84082.3", "0.00606791", "0", "2"], ["84091.5", "0.2025", "0", "1"], ["84131.2", "0.03", "0", "1"], ["84131.7", "0.14263366", "0", "2"], ["84132.5", "0.17898725", "0", "1"], ["84132.6", "0.0000434", "0", "1"], ["84132.8", "0.00002013", "0", "1"], ["84133.1", "0.08991011", "0", "1"], ["84133.3", "0.00517228", "0", "9"], ["84133.5", "0.00001277", "0", "1"], ["84134.1", "0.0895461", "0", "3"], ["84134.5", "0.0000103", "0", "1"], ["84134.6", "0.00003392", "0", "1"], ["84135.7", "0.0000221", "0", "1"], ["84135.8", "0.00007302", "0", "1"], ["84136", "0.3565323", "0", "1"], ["84136.2", "0.03", "0", "1"]], "bids": [["83951", "0.25934", "0", "6"], ["83950", "0.0439", "0", "1"], ["83949.9", "0.0897", "0", "2"], ["83949.8", "0.34163262", "0", "5"], ["83948.3", "1.26899377", "0", "13"], ["83948.2", "1.4768453", "0", "14"], ["83948", "0.0439", "0", "1"], ["83946.5", "0.19045", "0", "1"], ["83946", "0.0439", "0", "1"], ["83945.1", "0.53596076", "0", "2"], ["83945", "2.0532353", "0", "18"], ["83944.8", "1.03118544", "0", "6"], ["83944.7", "0.90520204", "0", "17"], ["83944.3", "1", "0", "1"], ["83944.1", "0.13518408", "0", "2"], ["83942", "0.0439", "0", "1"], ["83937.9", "0.08991011", "0", "1"], ["83933.3", "0.00210645", "0", "2"], ["83930.2", "0", "0", "0"], ["83929.6", "0", "0", "0"], ["83927.1", "0", "0", "0"], ["83925.3", "0", "0", "0"], ["83924.4", "0.36371973", "0", "2"], ["83923.1", "0", "0", "0"], ["83923", "0", "0", "0"], ["83921.8", "0", "0", "0"], ["83921.3", "0", "0", "0"], ["83917", "0.20037199", "0", "4"], ["83913.8", "0.14071224", "0", "1"], ["83906.1", "0", "0", "0"], ["83900.9", "0", "0", "0"], ["83900.1", "0.01835373", "0", "1"], ["83876.7", "0.00218682", "0", "1"], ["83876.5", "0", "0", "0"], ["83855.2", "0.00018336", "0", "1"], ["83812.5", "0", "0", "0"], ["83812.4", "0", "0", "0"], ["83812.1", "0", "0", "0"], ["83812", "0", "0", "0"], ["83811.9", "0", "0", "0"]], "ts": "1742577146200", "checksum": -447484927, "seqId": 49945043143, "prevSeqId": 49945042912}], "record_time": 1742577146.371259, "EXCHANGE": "OKX"}
{"arg": {"channel": "books", "instId": "BTC-USDT"}, "action": "update", "data": [{"asks": [["83951.1", "0", "0", "0"], ["83953.6", "0", "0", "0"], ["83953.7", "0", "0", "0"], ["83954.2", "0", "0", "0"], ["83954.4", "0", "0", "0"], ["83954.5", "0", "0", "0"], ["83954.9", "0", "0", "0"], ["83955.2", "0", "0", "0"], ["83955.4", "0", "0", "0"], ["83955.7", "0", "0", "0"], ["83956", "0.1305", "0", "2"], ["83956.5", "0", "0", "0"], ["83956.6", "0", "0", "0"], ["83956.9", "0.00056082", "0", "1"], ["83957.6", "0", "0", "0"], ["83957.9", "0", "0", "0"], ["83958", "0.0439", "0", "1"], ["83958.1", "0.03803238", "0", "1"], ["83958.9", "0", "0", "0"], ["83959.1", "0.000015", "0", "1"], ["83959.2", "0", "0", "0"], ["83959.5", "0", "0", "0"], ["83960.2", "0.0102", "0", "1"], ["83960.6", "0", "0", "0"], ["83960.9", "0.02", "0", "1"], ["83961.4", "0.04013326", "0", "1"], ["83961.5", "0", "0", "0"], ["83962.3", "0", "0", "0"], ["83962.7", "0.25615184", "0", "2"], ["83963.6", "0.02739775", "0", "1"], ["83963.8", "0", "0", "0"], ["83964", "0", "0", "0"], ["83964.1", "0.0119166", "0", "1"], ["83965.3", "0", "0", "0"], ["83966.1", "0", "0", "0"], ["83966.7", "0.036", "0", "1"], ["83967.2", "0", "0", "0"], ["83967.6", "0.16653424", "0", "1"], ["83969", "0.18672985", "0", "2"], ["83969.1", "0.01193064", "0", "2"], ["83969.9", "0.04", "0", "1"], ["83970.1", "0", "0", "0"], ["83970.9", "0.11067568", "0", "1"], ["83971", "0", "0", "0"], ["83972.3", "0.03062", "0", "1"], ["83972.6", "0.01153238", "0", "1"], ["83974.2", "0", "0", "0"], ["83975.4", "0.04", "0", "1"], ["83975.6", "0.02383477", "0", "1"], ["83977.8", "0.11913633", "0", "1"], ["83978.4", "0.01774536", "0", "1"], ["83979", "0.37316024", "0", "1"], ["83979.2", "0", "0", "0"], ["83980.1", "0", "0", "0"], ["83980.6", "0", "0", "0"], ["83980.9", "0.13080541", "0", "2"], ["83983.3", "0.16914969", "0", "2"], ["83984.5", "0.01328189", "0", "2"], ["83985.6", "0.0008", "0", "2"], ["83985.7", "0.23850569", "0", "2"], ["83986.4", "0.0004", "0", "1"], ["83986.6", "0.05956073", "0", "1"], ["83987.2", "0", "0", "0"], ["83988.1", "0.18761632", "0", "1"], ["83988.6", "0.33977058", "0", "1"], ["83988.7", "0", "0", "0"], ["83989.3", "0.11256978", "0", "2"], ["83989.4", "0", "0", "0"], ["83993.6", "0.07999999", "0", "2"], ["83994.1", "0", "0", "0"], ["83994.4", "0.03999999", "0", "1"], ["83995.6", "0.1", "0", "1"], ["83995.8", "0.20442955", "0", "1"], ["83997.1", "0", "0", "0"], ["84000.2", "0.24631328", "0", "2"], ["84000.7", "0.52991", "0", "1"], ["84005.6", "0.12610361", "0", "1"], ["84005.7", "0.1", "0", "1"], ["84009.3", "0.38100833", "0", "1"], ["84009.4", "0.57466", "0", "1"], ["84010.2", "0", "0", "0"], ["84010.5", "0", "0", "0"], ["84014.6", "0.01786368", "0", "1"], ["84021.3", "0.20007177", "0", "2"], ["84025.6", "0.1804935", "0", "1"], ["84025.8", "0", "0", "0"], ["84032.3", "0", "0", "0"], ["84032.6", "0.05954428", "0", "2"], ["84041.7", "0", "0", "0"], ["84050.5", "0.14029794", "0", "2"], ["84050.6", "0.0214", "0", "1"], ["84054.9", "0.01180011", "0", "2"], ["84057.1", "0.00597506", "0", "3"], ["84057.5", "0", "0", "0"], ["84057.6", "0", "0", "0"], ["84057.7", "0", "0", "0"], ["84057.8", "0.000015", "0", "1"], ["84064", "0", "0", "0"], ["84067.7", "0.53223465", "0", "2"], ["84072.9", "1.3919232", "0", "1"], ["84074", "3.82815", "0", "1"], ["84075.6", "0.0568", "0", "4"], ["84086.7", "0.03", "0", "1"], ["84098.6", "0.05359104", "0", "1"], ["84099.1", "0.0119117", "0", "2"], ["84136.7", "0.00004748", "0", "1"], ["84137.1", "0.00001501", "0", "1"], ["84137.2", "0.03", "0", "1"], ["84138.8", "0.00044981", "0", "1"], ["84140", "0.00031221", "0", "2"], ["84141.1", "0.00005109", "0", "1"], ["84141.2", "0.00011161", "0", "1"], ["84141.3", "0.00083", "0", "1"], ["84141.9", "0.00002329", "0", "1"], ["84142.1", "0.00083", "0", "1"], ["84142.2", "0.17898725", "0", "1"], ["84142.8", "0.02898561", "0", "3"]], "bids": [["83955.9", "0.59851788", "0", "7"], ["83954.3", "0.10125811", "0", "1"], ["83954", "0.0439", "0", "1"], ["83953.5", "0.016", "0", "1"], ["83953", "0.0119166", "0", "1"], ["83952", "0.0439", "0", "1"], ["83951.4", "0.08991011", "0", "1"], ["83951.1", "0.00357273", "0", "1"], ["83951", "0.016", "0", "1"], ["83949.9", "0", "0", "0"], ["83949.8", "0", "0", "0"], ["83948.3", "0", "0", "0"], ["83948.2", "0", "0", "0"], ["83948.1", "0.04986774", "0", "2"], ["83947.3", "0.0428883", "0", "1"], ["83946.7", "0.00001199", "0", "1"], ["83946.5", "0", "0", "0"], ["83946.1", "0.04650051", "0", "1"], ["83945.7", "1", "0", "1"], ["83945.1", "1.04456225", "0", "4"], ["83945", "0.37389", "0", "3"], ["83944.8", "0", "0", "0"], ["83944.7", "0.16050454", "0", "6"], ["83944.3", "0", "0", "0"], ["83944.2", "0", "0", "0"], ["83944", "0.0516423", "0", "2"], ["83943.3", "0", "0", "0"], ["83943.1", "0.000015", "0", "1"], ["83942.4", "0.04169", "0", "1"], ["83941.8", "0.00001199", "0", "1"], ["83940.1", "0.07844141", "0", "1"], ["83939.7", "0", "0", "0"], ["83939.5", "0.03992302", "0", "1"], ["83938.6", "0", "0", "0"], ["83937.8", "0", "0", "0"], ["83936.8", "0.00007199", "0", "2"], ["83936.4", "0.2185", "0", "2"], ["83935", "0", "0", "0"], ["83934", "0.0839", "0", "2"], ["83933.9", "0.01389", "0", "1"], ["83933.7", "0.02383386", "0", "1"], ["83933.1", "0.01192074", "0", "1"], ["83932.9", "0.23833339", "0", "1"], ["83932.8", "0.07201842", "0", "1"], ["83932.6", "0.00357", "0", "1"], ["83932.4", "0.18761632", "0", "1"], ["83932.3", "0.00476575", "0", "1"], ["83932", "0.084", "0", "2"], ["83931.9", "0.03301199", "0", "2"], ["83931.1", "0", "0", "0"], ["83930.8", "0", "0", "0"], ["83930", "0", "0", "0"], ["83929.4", "0", "0", "0"], ["83929.3", "0", "0", "0"], ["83928.1", "0", "0", "0"], ["83928", "0.2025", "0", "1"], ["83926", "0", "0", "0"], ["83925.2", "0.06911161", "0", "3"], ["83924.9", "0.05956073", "0", "1"], ["83924.4", "0.07234016", "0", "1"], ["83924", "0", "0", "0"], ["83923.8", "0", "0", "0"], ["83922.4", "0", "0", "0"], ["83917.5", "0.05193", "0", "1"], ["83917.3", "0", "0", "0"], ["83914.2", "0.56483", "0", "1"], ["83913.3", "0.02466532", "0", "1"], ["83912", "0.000012", "0", "1"], ["83911.6", "0.30371857", "0", "2"], ["83910.2", "0.4969003", "0", "2"], ["83907.3", "0.5776526", "0", "1"], ["83906.5", "0.00589966", "0", "1"], ["83901.3", "0.01788779", "0", "1"], ["83899.9", "0.01701534", "0", "3"], ["83898.1", "0.0059555", "0", "1"], ["83897.8", "0", "0", "0"], ["83897.4", "0", "0", "0"], ["83897.2", "0.003582", "0", "2"], ["83896.7", "0.09536629", "0", "2"], ["83895.5", "0.0059555", "0", "1"], ["83895.2", "0", "0", "0"], ["83895", "0.21113561", "0", "4"], ["83894.9", "0", "0", "0"], ["83894.8", "0", "0", "0"], ["83894.6", "0.20256946", "0", "3"], ["83894.4", "0", "0", "0"], ["83889", "0", "0", "0"], ["83886.4", "0.00100674", "0", "1"], ["83885.4", "0.00145247", "0", "1"], ["83884", "0", "0", "0"], ["83877.5", "0", "0", "0"], ["83876.6", "0", "0", "0"], ["83873.7", "0.48763362", "0", "3"], ["83871.8", "0.12507", "0", "1"], ["83867", "0.07622917", "0", "2"], ["83864.3", "0.07165719", "0", "1"], ["83863.8", "0.07166249", "0", "1"], ["83860.7", "0", "0", "0"], ["83859.9", "0.18770243", "0", "1"], ["83857.1", "0.85694208", "0", "5"], ["83853.6", "0.00803883", "0", "2"], ["83852.2", "0", "0", "0"], ["83851.4", "0.16942629", "0", "2"], ["83847.2", "0.08653044", "0", "1"], ["83847", "0", "0", "0"], ["83844.7", "0.00005731", "0", "1"], ["83829.8", "0", "0", "0"], ["83828.5", "0", "0", "0"], ["83822.3", "0.01185531", "0", "2"]], "ts": "1742577146300", "checksum": -1848275578, "seqId": 49945043824, "prevSeqId": 49945043143}], "record_time": 1742577146.471216, "EXCHANGE": "OKX"}
{"arg": {"channel": "books", "instId": "BTC-USDT"}, "action": "update", "data": [{"asks": [["83956", "0", "0", "0"], ["83956.9", "0.08716082", "0", "2"], ["83957", "0", "0", "0"], ["83958.1", "0", "0", "0"], ["83959.9", "0.06402996", "0", "1"], ["83960", "0.04394", "0", "2"], ["83960.9", "0", "0", "0"], ["83961.2", "0.11915993", "0", "1"], ["83961.4", "0", "0", "0"], ["83962", "0", "0", "0"], ["83962.7", "0.11663476", "0", "2"], ["83962.8", "0", "0", "0"], ["83963.7", "0.02", "0", "1"], ["83965", "0", "0", "0"], ["83965.4", "0.00001501", "0", "1"], ["83967.2", "0.04013326", "0", "1"], ["83968.9", "0.134827", "0", "1"], ["83969.5", "0.03", "0", "1"], ["83969.9", "0", "0", "0"], ["83972.3", "0", "0", "0"], ["83972.4", "0.04", "0", "1"], ["83972.8", "0.06", "0", "2"], ["83977.4", "0.17867", "0", "1"], ["83980.9", "0.11889794", "0", "1"], ["83981.4", "0.0119074", "0", "1"], ["83985.2", "0.26215937", "0", "2"], ["83985.6", "0", "0", "0"], ["83985.7", "0.0001723", "0", "1"], ["83986.4", "0.0008", "0", "2"], ["83987.2", "0.0004", "0", "1"], ["83987.3", "0", "0", "0"], ["83993.6", "0", "0", "0"], ["83994.4", "0.07999999", "0", "2"], ["83995.2", "0.03999999", "0", "1"], ["83995.6", "0", "0", "0"], ["83997.8", "0.0196305", "0", "1"], ["84000.5", "0.1", "0", "1"], ["84005.6", "0.21753966", "0", "2"], ["84008.2", "0.55983", "0", "2"], ["84017.9", "0.40073833", "0", "1"], ["84018", "0.824011", "0", "1"], ["84018.7", "0", "0", "0"], ["84026.7", "0.25013", "0", "1"], ["84028.8", "0.044985", "0", "1"], ["84047.6", "0.25013", "0", "1"], ["84088.5", "0.00003542", "0", "1"], ["84096.3", "0.113222", "0", "1"], ["84134.8", "6.51096044", "0", "1"], ["84141.2", "0", "0", "0"], ["84141.3", "0", "0", "0"], ["84141.9", "0", "0", "0"], ["84142.1", "0", "0", "0"], ["84142.2", "0", "0", "0"], ["84142.8", "0", "0", "0"]], "bids": [["83956.8", "1.61299332", "0", "15"], ["83956.1", "0.21580123", "0", "1"], ["83956", "0.0439", "0", "1"], ["83955.9", "0.34124006", "0", "4"], ["83954.3", "0", "0", "0"], ["83953.1", "0.03471498", "0", "1"], ["83952.4", "0.01389", "0", "1"], ["83951.4", "0", "0", "0"], ["83951.1", "0", "0", "0"], ["83948.1", "0.34692677", "0", "1"], ["83945.1", "0.7674933", "0", "3"], ["83945", "0.36", "0", "2"], ["83942.3", "0.02859924", "0", "1"], ["83940.1", "0.14561399", "0", "2"], ["83939.7", "0.17867", "0", "1"], ["83937", "0.30385963", "0", "2"], ["83934.3", "0.00714845", "0", "1"], ["83934", "0.04", "0", "1"], ["83933.6", "0.069", "0", "2"], ["83932.9", "0", "0", "0"], ["83932.8", "0.16126185", "0", "2"], ["83932.3", "0", "0", "0"], ["83932", "0.32233427", "0", "3"], ["83928.6", "0.35320512", "0", "1"], ["83926.2", "0", "0", "0"], ["83924.4", "0.21942064", "0", "2"], ["83923.7", "0.52041", "0", "1"], ["83919.5", "0.045043", "0", "1"], ["83917", "0.00037199", "0", "2"], ["83915.1", "0.35733", "0", "1"], ["83909.7", "0", "0", "0"], ["83907.9", "0.17866", "0", "1"], ["83907.4", "0.64152345", "0", "2"], ["83906.6", "0.01835148", "0", "1"], ["83905.5", "0.11268139", "0", "3"], ["83904.9", "0.825121", "0", "1"], ["83900.1", "0", "0", "0"], ["83898", "0", "0", "0"], ["83888.9", "0.00100671", "0", "1"], ["83888.1", "0.00145244", "0", "1"], ["83886.4", "0", "0", "0"], ["83885.4", "0", "0", "0"], ["83882.4", "0.15018489", "0", "3"], ["83879.8", "0.25013", "0", "1"], ["83871.1", "0.01736", "0", "1"], ["83861", "0", "0", "0"], ["83835.6", "0.18351483", "0", "1"], ["83828.6", "0", "0", "0"], ["83814.4", "0", "0", "0"], ["83814.1", "0", "0", "0"], ["83813.8", "0", "0", "0"], ["83813.6", "0", "0", "0"], ["83813.5", "0", "0", "0"], ["83813.1", "0", "0", "0"], ["83812.6", "0", "0", "0"]], "ts": "1742577146400", "checksum": 104279045, "seqId": 49945044018, "prevSeqId": 49945043824}], "record_time": 1742577146.571621, "EXCHANGE": "OKX"}
{"arg": {"channel": "books", "instId": "BTC-USDT"}, "action": "update", "data": [{"asks": [["83956.9", "0.08721672", "0", "3"], ["83959.3", "0.11916251", "0", "1"], ["83959.9", "0.016242", "0", "1"], ["83961.2", "0", "0", "0"], ["83969.5", "0.06", "0", "2"], ["83971.5", "0.0102", "0", "1"], ["83972.8", "0.12", "0", "4"], ["83977.8", "0.14975633", "0", "2"], ["83978.4", "0", "0", "0"], ["83979", "0.62615518", "0", "2"], ["83980.1", "0.1191331", "0", "1"], ["83981.7", "1", "0", "1"], ["83990", "0.48203351", "0", "2"], ["83994.4", "0", "0", "0"], ["83995.2", "0.07999999", "0", "2"], ["83996", "0.03999999", "0", "1"], ["83999.7", "0", "0", "0"], ["84000.5", "0", "0", "0"], ["84001.4", "0.1015", "0", "2"], ["84001.5", "0", "0", "0"], ["84004.9", "0", "0", "0"], ["84005.2", "0.10090402", "0", "1"], ["84005.6", "0", "0", "0"], ["84005.7", "0", "0", "0"], ["84007.6", "0", "0", "0"], ["84008.2", "0.2025", "0", "1"], ["84011", "0.12507198", "0", "2"], ["84011.1", "0.00003657", "0", "2"], ["84043.8", "0.01774536", "0", "1"], ["84141.2", "0.00011161", "0", "1"], ["84141.3", "0.00083", "0", "1"], ["84141.9", "0.00002329", "0", "1"]], "bids": [["83956.1", "0.12871202", "0", "1"], ["83955.9", "0.33766733", "0", "3"], ["83948.2", "0.06566424", "0", "1"], ["83948.1", "0", "0", "0"], ["83947", "0.04168", "0", "1"], ["83945.7", "0", "0", "0"], ["83945.1", "1.05057634", "0", "4"], ["83944.4", "1", "0", "1"], ["83942.4", "0", "0", "0"], ["83937", "0.33685963", "0", "3"], ["83932", "0.084", "0", "2"], ["83928.7", "0.23833517", "0", "1"], ["83928.5", "0", "0", "0"], ["83928.1", "0.00357273", "0", "1"], ["83927.1", "0.12506", "0", "1"], ["83925.2", "0.03611161", "0", "2"], ["83918.1", "0.01190607", "0", "1"], ["83915.2", "0.38650634", "0", "1"], ["83914.1", "0.11889794", "0", "1"], ["83914", "0", "0", "0"], ["83906.1", "0.12506", "0", "1"], ["83895.1", "0", "0", "0"], ["83886", "0.26796123", "0", "3"], ["83884.7", "0", "0", "0"], ["83884.6", "0", "0", "0"], ["83867.5", "0.00019838", "0", "2"], ["83855.2", "0", "0", "0"]], "ts": "1742577146500", "checksum": 49174184, "seqId": 49945044107, "prevSeqId": 49945044018}], "record_time": 1742577146.671149, "EXCHANGE": "OKX"}
{"arg": {"channel": "books", "instId": "BTC-USDT"}, "action": "update", "data": [{"asks": [["83975.5", "0.77113863", "0", "1"], ["83977", "1.58344592", "0", "1"], ["83979", "0.66189511", "0", "2"], ["83981.6", "1.052", "0", "3"], ["83981.7", "0", "0", "0"], ["83985.2", "0.02382517", "0", "1"], ["83985.7", "0", "0", "0"], ["83986.4", "0", "0", "0"], ["83986.5", "0.23833765", "0", "1"], ["83987.2", "0", "0", "0"], ["83988", "0.0008", "0", "2"], ["83988.8", "0.0004", "0", "1"], ["83995.2", "0", "0", "0"], ["83996", "0.07999999", "0", "2"], ["83996.6", "0.0001722", "0", "1"], ["83996.8", "0.03999999", "0", "1"], ["84005.2", "0.93937274", "0", "2"], ["84006.4", "2.84887904", "0", "1"], ["84008.4", "0", "0", "0"], ["84012.9", "0.03", "0", "1"], ["84036.4", "0.0119171", "0", "1"], ["84141.2", "0", "0", "0"], ["84141.3", "0", "0", "0"], ["84141.9", "0", "0", "0"]], "bids": [["83944.7", "0.15764454", "0", "5"], ["83931.9", "0.00001199", "0", "1"], ["83928.6", "0.65736305", "0", "2"], ["83925.2", "0.00011161", "0", "1"], ["83925", "1", "0", "1"], ["83924.4", "0.67956251", "0", "1"], ["83923.8", "0.11889794", "0", "1"], ["83922.1", "1.59508977", "0", "1"], ["83919.6", "0.01190586", "0", "1"], ["83901.8", "0", "0", "0"], ["83895", "1.06167701", "0", "5"], ["83892.7", "2.86122211", "0", "2"], ["83857.1", "0.04669159", "0", "5"], ["83815.1", "0", "0", "0"], ["83815", "0", "0", "0"], ["83814.9", "0", "0", "0"]], "ts": "1742577146600", "checksum": 1282624125, "seqId": 49945044163, "prevSeqId": 49945044107}], "record_time": 1742577146.77428, "EXCHANGE": "OKX"}
{"arg": {"channel": "books", "instId": "BTC-USDT"}, "action": "update", "data": [{"asks": [["83957.2", "0.11916559", "0", "1"], ["83959.3", "0", "0", "0"], ["83965.3", "0.01", "0", "1"], ["83966", "0", "0", "0"], ["83986.5", "0", "0", "0"], ["83987.7", "0.01190651", "0", "1"], ["83988", "0.23913532", "0", "3"], ["83995.8", "0.55588575", "0", "2"], ["83996", "1.07999999", "0", "3"], ["84008.2", "0.55983", "0", "2"], ["84011.2", "0", "0", "0"], ["84059.1", "0", "0", "0"], ["84059.2", "0", "0", "0"], ["84084.7", "0.214399", "0", "1"], ["84141.2", "0.00011161", "0", "1"], ["84141.9", "0.00002329", "0", "1"]], "bids": [["83919.9", "0.0119058", "0", "1"], ["83908.9", "0.00589951", "0", "1"], ["83908.8", "0.1", "0", "2"], ["83908", "0.05", "0", "1"], ["83901.2", "0", "0", "0"], ["83900.8", "0.65021", "0", "2"], ["83900", "0.00001", "0", "1"], ["83815.5", "0", "0", "0"], ["83815.3", "0", "0", "0"], ["83815.2", "0", "0", "0"]], "ts": "1742577146700", "checksum": -1482558393, "seqId": 49945044197, "prevSeqId": 49945044163}], "record_time": 1742577146.872728, "EXCHANGE": "OKX"}
{"arg": {"channel": "books", "instId": "BTC-USDT"}, "action": "update", "data": [{"asks": [["83956.9", "0", "0", "0"], ["83957.2", "0", "0", "0"], ["83958", "0.1305", "0", "2"], ["83959.6", "0.0651606", "0", "1"], ["83959.7", "0.119162", "0", "1"], ["83959.9", "0", "0", "0"], ["83962", "0.0439", "0", "1"], ["83963.2", "0.00774153", "0", "1"], ["83965.2", "0", "0", "0"], ["83965.5", "0.00056073", "0", "1"], ["83975.3", "0.01774536", "0", "1"], ["83980.1", "1.1191331", "0", "2"], ["83981.6", "0.052", "0", "2"], ["83983.2", "0", "0", "0"], ["83987.4", "0", "0", "0"], ["83991.6", "0", "0", "0"], ["84008.2", "0.2025", "0", "1"], ["84043.8", "0", "0", "0"], ["84105.2", "0.00002252", "0", "2"], ["84142.1", "0.00083", "0", "1"], ["84142.2", "0.17898725", "0", "1"]], "bids": [["83957.9", "0.8629222", "0", "11"], ["83957.1", "0.11916555", "0", "1"], ["83957", "0.11490252", "0", "1"], ["83956.8", "0.252", "0", "3"], ["83956.1", "0", "0", "0"], ["83955.9", "0.2185", "0", "2"], ["83951.7", "0.00001199", "0", "1"], ["83949.8", "0.00774183", "0", "1"], ["83934.3", "0", "0", "0"], ["83932.9", "0.00476571", "0", "1"], ["83932.7", "0", "0", "0"], ["83928.7", "0.23833526", "0", "1"], ["83928.1", "0", "0", "0"], ["83908.2", "0.00357273", "0", "1"], ["83899.1", "0", "0", "0"], ["83895.6", "0.00595536", "0", "1"], ["83857.1", "0.21383757", "0", "6"], ["83851.4", "0", "0", "0"], ["83847.2", "0", "0", "0"], ["83815.9", "0", "0", "0"]], "ts": "1742577146800", "checksum": 226807589, "seqId": 49945044296, "prevSeqId": 49945044197}], "record_time": 1742577146.977977, "EXCHANGE": "OKX"}
{"arg": {"channel": "books", "instId": "BTC-USDT"}, "action": "update", "data": [{"asks": [["83958", "0.29936328", "0", "3"], ["83959.7", "0.124162", "0", "2"], ["83965.3", "0", "0", "0"], ["83968.5", "0.0102", "0", "1"], ["83968.8", "0.0035948", "0", "1"], ["83969.7", "0.005", "0", "1"], ["83971.5", "0", "0", "0"], ["83979", "0.66164085", "0", "2"], ["83980.1", "0.1191331", "0", "1"], ["83982.5", "1", "0", "1"], ["83987.6", "0.00006639", "0", "1"], ["83988", "0.23913394", "0", "3"], ["83991.8", "0.59276622", "0", "3"], ["83996", "0.08006638", "0", "3"], ["83996.1", "0", "0", "0"], ["84001.4", "0.0015", "0", "1"], ["84002.5", "0.1010364", "0", "2"], ["84006.4", "2.84991221", "0", "2"], ["84008.2", "0.55982", "0", "2"], ["84013.6", "0", "0", "0"], ["84021.2", "0.09365", "0", "2"], ["84025.4", "0", "0", "0"], ["84034.4", "0", "0", "0"], ["84047.9", "3.53045", "0", "1"], ["84058.3", "0", "0", "0"], ["84066.7", "0", "0", "0"], ["84073.7", "0", "0", "0"], ["84142.7", "0.00044", "0", "1"], ["84142.8", "0.02898561", "0", "3"], ["84143.8", "0.00001314", "0", "1"], ["84144.1", "0.0000568", "0", "1"]], "bids": [["83957.9", "0.51211882", "0", "8"], ["83956.9", "0.00112002", "0", "1"], ["83956.8", "0.052", "0", "2"], ["83952.4", "0", "0", "0"], ["83949.2", "0.01389", "0", "1"], ["83948.2", "0.35745621", "0", "2"], ["83947", "0", "0", "0"], ["83946.1", "1", "0", "1"], ["83945.2", "0.2491027", "0", "1"], ["83945.1", "0.53596076", "0", "2"], ["83944.4", "0", "0", "0"], ["83944", "0.0566423", "0", "3"], ["83942.6", "0.04169", "0", "1"], ["83938.9", "0.0043425", "0", "1"], ["83933.9", "0.01889", "0", "2"], ["83932.9", "0.24309965", "0", "2"], ["83932.8", "0.07201842", "0", "1"], ["83928.7", "0", "0", "0"], ["83928.6", "0.35320512", "0", "1"], ["83925", "0", "0", "0"], ["83923.2", "0", "0", "0"], ["83917.5", "0.06383614", "0", "2"], ["83914.4", "0.08", "0", "2"], ["83913.6", "0.04", "0", "1"], ["83906.4", "0", "0", "0"], ["83905.6", "0.11969747", "0", "3"], ["83898.8", "0", "0", "0"], ["83890.8", "0.00100669", "0", "1"], ["83888.9", "0", "0", "0"], ["83857.1", "0.58095984", "0", "5"], ["83823.6", "0.35776874", "0", "1"], ["83815.9", "0.00004266", "0", "1"]], "ts": "1742577146900", "checksum": 717485306, "seqId": 49945044385, "prevSeqId": 49945044296}], "record_time": 1742577147.071735, "EXCHANGE": "OKX"}
{"arg": {"channel": "books", "instId": "BTC-USDT"}, "action": "update", "data": [{"asks": [["83980.9", "1.11889794", "0", "2"], ["83982.5", "0", "0", "0"], ["83995.8", "0.20442955", "0", "1"], ["84008.2", "0.2025", "0", "1"], ["84032.3", "0.00119001", "0", "1"], ["84037.7", "0.01427931", "0", "1"], ["84054.8", "0.00589943", "0", "1"], ["84063.6", "0.00589943", "0", "1"], ["84085.9", "0.00251776", "0", "1"], ["84142.7", "0", "0", "0"], ["84142.8", "0", "0", "0"], ["84143.8", "0", "0", "0"], ["84144.1", "0", "0", "0"]], "bids": [["83956.9", "0.00117592", "0", "2"], ["83948.2", "0.04027662", "0", "1"], ["83946.5", "0.00355511", "0", "1"], ["83946.1", "0", "0", "0"], ["83945.2", "0.50117198", "0", "2"], ["83944.7", "0.05497826", "0", "4"], ["83943.9", "1", "0", "1"], ["83938.9", "0", "0", "0"], ["83915.1", "0", "0", "0"], ["83907.9", "0", "0", "0"], ["83882.8", "0.02385423", "0", "1"], ["83871.8", "0", "0", "0"], ["83815.5", "0.002384", "0", "1"], ["83815.3", "0.00018461", "0", "1"], ["83815.1", "0.00589964", "0", "1"]], "ts": "1742577147000", "checksum": 155106525, "seqId": 49945044411, "prevSeqId": 49945044385}], "record_time": 1742577147.171327, "EXCHANGE": "OKX"}
{"arg": {"channel": "books", "instId": "BTC-USDT"}, "action": "update", "data": [{"asks": [["83970.9", "0.15391141", "0", "2"], ["83973.4", "0.03062", "0", "1"], ["83977.8", "0.11913633", "0", "1"], ["83979.5", "1", "0", "1"], ["83980.9", "0.11889794", "0", "1"], ["84026.7", "0", "0", "0"], ["84047.6", "0", "0", "0"]], "bids": [["83957.9", "0.51497882", "0", "9"], ["83950.4", "0.04600077", "0", "1"], ["83939", "0.0012345", "0", "1"], ["83882.4", "0.0627032", "0", "2"], ["83879.8", "0", "0", "0"], ["83857.1", "0.73355184", "0", "5"], ["83815.1", "0", "0", "0"]], "ts": "1742577147100", "checksum": -182108357, "seqId": 49945044432, "prevSeqId": 49945044411}], "record_time": 1742577147.271358, "EXCHANGE": "OKX"}
{"arg": {"channel": "books", "instId": "BTC-USDT"}, "action": "update", "data": [{"asks": [["83975.5", "1.12845863", "0", "2"], ["83977.4", "0", "0", "0"], ["83979.5", "0", "0", "0"], ["83981.2", "1", "0", "1"], ["84142.7", "0.00044", "0", "1"]], "bids": [["83940.3", "0.28368552", "0", "1"], ["83940.2", "0.35732", "0", "1"], ["83940.1", "0", "0", "0"], ["83937", "0.46330508", "0", "4"], ["83933.1", "0.19058074", "0", "2"], ["83931.5", "0", "0", "0"], ["83921.5", "0", "0", "0"], ["83815.1", "0.00589964", "0", "1"]], "ts": "1742577147200", "checksum": -182108357, "seqId": 49945044445, "prevSeqId": 49945044432}], "record_time": 1742577147.373941, "EXCHANGE": "OKX"}
{"arg": {"channel": "books", "instId": "BTC-USDT"}, "action": "update", "data": [{"asks": [["83958", "0.21276328", "0", "2"], ["83959.1", "0", "0", "0"], ["83959.6", "0", "0", "0"], ["83959.7", "0.129162", "0", "3"], ["83968.8", "0", "0", "0"], ["83969.7", "0.01", "0", "2"], ["83988", "0.0008", "0", "2"], ["83989.9", "0.23833072", "0", "1"], ["83994", "0.00001", "0", "1"], ["83996", "0.00006639", "0", "1"], ["83996.8", "0.07999999", "0", "2"], ["83997.6", "0.03999999", "0", "1"]], "bids": [["83946.6", "0.005", "0", "1"], ["83936.5", "0.54096076", "0", "3"], ["83934.1", "0.23833072", "0", "1"], ["83932.9", "0.00476571", "0", "1"], ["83913.8", "0.26577224", "0", "2"], ["83909", "0.00001", "0", "1"], ["83901.7", "0.04764264", "0", "1"], ["83892.8", "0.12506", "0", "1"], ["83886", "0.26795123", "0", "2"], ["83884.8", "0", "0", "0"], ["83815.9", "0", "0", "0"], ["83815.5", "0", "0", "0"], ["83815.3", "0", "0", "0"], ["83815.1", "0", "0", "0"]], "ts": "1742577147300", "checksum": 639325126, "seqId": 49945044472, "prevSeqId": 49945044445}], "record_time": 1742577147.471498, "EXCHANGE": "OKX"}
{"arg": {"channel": "books", "instId": "BTC-USDT"}, "action": "update", "data": [{"asks": [["83959.3", "0.00205734", "0", "2"], ["83959.6", "0.0681606", "0", "1"], ["83963.4", "0.000015", "0", "1"], ["83967.5", "0.01", "0", "1"], ["83981.2", "0", "0", "0"], ["83983.1", "1", "0", "1"], ["83984.7", "0.25013", "0", "1"], ["83988.5", "0.23833314", "0", "1"], ["83989.9", "0", "0", "0"], ["83995.8", "0.31559572", "0", "2"], ["84005.7", "0.25013", "0", "1"], ["84046", "0.1", "0", "1"], ["84140", "0", "0", "0"], ["84141.1", "0", "0", "0"], ["84141.2", "0", "0", "0"], ["84141.9", "0", "0", "0"], ["84142.1", "0", "0", "0"], ["84142.2", "0", "0", "0"], ["84142.7", "0", "0", "0"]], "bids": [["83957.9", "0.61497882", "0", "10"], ["83948.2", "0.33674204", "0", "2"], ["83946.5", "1.00355511", "0", "2"], ["83943.9", "0", "0", "0"], ["83934.1", "0", "0", "0"], ["83932.5", "0.23833314", "0", "1"], ["83926", "0.2", "0", "1"], ["83921.8", "0.25013", "0", "1"], ["83908.8", "0", "0", "0"], ["83908", "0.1", "0", "2"], ["83907.2", "0.05", "0", "1"], ["83841.6", "0.1", "0", "1"], ["83816.9", "0", "0", "0"], ["83816.6", "0", "0", "0"]], "ts": "1742577147400", "checksum": -1113262781, "seqId": 49945044508, "prevSeqId": 49945044472}], "record_time": 1742577147.572607, "EXCHANGE": "OKX"}
{"arg": {"channel": "books", "instId": "BTC-USDT"}, "action": "update", "data": [{"asks": [["83959.3", "0.00411468", "0", "4"], ["83960.2", "0", "0", "0"], ["83964.5", "0.12909794", "0", "2"], ["83978", "0.21847", "0", "1"]], "bids": [["83948.2", "0.04027662", "0", "1"], ["83946.5", "0.00355511", "0", "1"], ["83944.9", "1", "0", "1"], ["83932.8", "0.14985713", "0", "2"], ["83929", "0.00036", "0", "1"], ["83823", "0.00001199", "0", "1"], ["83817.6", "0", "0", "0"], ["83817.1", "0", "0", "0"]], "ts": "1742577147500", "checksum": 585510522, "seqId": 49945044520, "prevSeqId": 49945044508}], "record_time": 1742577147.670655, "EXCHANGE": "OKX"}
{"arg": {"channel": "books", "instId": "BTC-USDT"}, "action": "update", "data": [{"asks": [["83958", "0.0439", "0", "1"], ["83959.3", "0.00514334", "0", "5"], ["83959.6", "0.00209989", "0", "2"], ["83968.5", "0", "0", "0"], ["83972.1", "0.0102", "0", "1"], ["83973.4", "0", "0", "0"], ["83975.5", "0.77113863", "0", "1"], ["83978", "0", "0", "0"], ["83978.4", "0.03062", "0", "1"], ["83996", "0.08006639", "0", "3"], ["83996.8", "0.03999999", "0", "1"], ["83997.6", "0", "0", "0"], ["84140", "0.00031221", "0", "2"], ["84141.1", "0.00005109", "0", "1"]], "bids": [["83953.1", "0.05066898", "0", "2"], ["83952.4", "0.01389", "0", "1"], ["83949.2", "0", "0", "0"], ["83938.2", "0.06589", "0", "3"], ["83933.9", "0.005", "0", "1"], ["83933.1", "0.01192074", "0", "1"], ["83914.9", "0.01190652", "0", "1"], ["83908.8", "0.1", "0", "2"], ["83908", "0.05", "0", "1"], ["83907.2", "0", "0", "0"], ["83897", "0", "0", "0"]], "ts": "1742577147600", "checksum": -996177794, "seqId": 49945044551, "prevSeqId": 49945044520}], "record_time": 1742577147.776457, "EXCHANGE": "OKX"}
{"arg": {"channel": "books", "instId": "BTC-USDT"}, "action": "update", "data": [{"asks": [["83980.5", "0.35732", "0", "1"], ["84002.5", "0.1", "0", "1"], ["84014.5", "0.00103624", "0", "1"], ["84140", "0", "0", "0"], ["84141.1", "0", "0", "0"]], "bids": [["83933.1", "0.19058074", "0", "2"]], "ts": "1742577147700", "checksum": -996177794, "seqId": 49945044558, "prevSeqId": 49945044551}], "record_time": 1742577147.870502, "EXCHANGE": "OKX"}
{"arg": {"channel": "books", "instId": "BTC-USDT"}, "action": "update", "data": [{"asks": [["83981", "1", "0", "1"], ["83983.1", "0", "0", "0"], ["84030.9", "0.34370513", "0", "2"], ["84131.7", "0.07131683", "0", "1"]], "bids": [["83866.2", "0.07165411", "0", "2"]], "ts": "1742577147800", "checksum": -996177794, "seqId": 49945044567, "prevSeqId": 49945044558}], "record_time": 1742577147.972937, "EXCHANGE": "OKX"}
{"arg": {"channel": "books", "instId": "BTC-USDT"}, "action": "update", "data": [{"asks": [["83968.4", "0.05628489", "0", "1"], ["83981", "0", "0", "0"], ["83981.1", "1.052", "0", "3"], ["83985.8", "0", "0", "0"], ["83988.5", "0", "0", "0"], ["83989.9", "0.23832938", "0", "1"], ["83991.6", "0.25572186", "0", "2"], ["83991.7", "0.17898725", "0", "1"], ["83991.8", "0.00221139", "0", "2"], ["83993.9", "0.5835626", "0", "1"], ["83997", "1", "0", "1"], ["84010.3", "0.4132584", "0", "2"], ["84028.8", "0", "0", "0"]], "bids": [["83948.2", "0.34874204", "0", "2"], ["83946.9", "1", "0", "1"], ["83945.8", "0.04", "0", "1"], ["83944.9", "0", "0", "0"], ["83937", "0.51958997", "0", "5"], ["83934.2", "0", "0", "0"], ["83934.1", "0.23832938", "0", "1"], ["83932.8", "0.07201842", "0", "1"], ["83932.5", "0", "0", "0"], ["83928.6", "0.70549123", "0", "2"], ["83925", "1", "0", "1"], ["83919.5", "0", "0", "0"], ["83918.2", "0", "0", "0"], ["83913.6", "0.0408", "0", "3"], ["83912.8", "0.0003995", "0", "1"], ["83905.6", "0.11889794", "0", "1"], ["83904.8", "0.17898725", "0", "1"], ["83899.2", "0.26097436", "0", "1"], ["83895", "1.00539212", "0", "4"], ["83857.1", "0.00091322", "0", "4"]], "ts": "1742577147900", "checksum": -1848024310, "seqId": 49945044625, "prevSeqId": 49945044567}], "record_time": 1742577148.071482, "EXCHANGE": "OKX"}
{"arg": {"channel": "books", "instId": "BTC-USDT"}, "action": "update", "data": [{"asks": [["83958", "0.1305", "0", "2"], ["83969.8", "0.0102", "0", "1"], ["83972.1", "0", "0", "0"], ["83975.4", "0", "0", "0"], ["83977.1", "0.04", "0", "1"], ["83979", "0.37316024", "0", "1"], ["83980.5", "0", "0", "0"], ["83981.1", "0.052", "0", "2"], ["83981.4", "0", "0", "0"], ["83981.5", "0.15261963", "0", "2"], ["83992.9", "0.05666011", "0", "1"], ["83995.8", "0.28114942", "0", "1"], ["83997", "0", "0", "0"], ["84030.9", "0.41510746", "0", "3"], ["84033.3", "0.04599734", "0", "3"], ["84046.6", "0.00308205", "0", "2"], ["84058.7", "0.00597332", "0", "1"], ["84073.3", "0.00895999", "0", "1"], ["84081.7", "0.04194665", "0", "2"], ["84090.1", "0.01493332", "0", "1"], ["84131.7", "0.14263366", "0", "2"], ["84138.8", "0", "0", "0"]], "bids": [["83957.9", "0.61504795", "0", "11"], ["83948.7", "0.35377662", "0", "1"], ["83948.6", "1", "0", "1"], ["83948.2", "0", "0", "0"], ["83946.9", "0", "0", "0"], ["83925.6", "0.05973116", "0", "1"], ["83924", "0.045041", "0", "1"], ["83866.2", "0.14319661", "0", "3"], ["83846.4", "0.00298666", "0", "1"], ["83838", "0.00747332", "0", "2"], ["83829.6", "0.00895999", "0", "1"], ["83821.2", "0.01194665", "0", "1"], ["83819.2", "0", "0", "0"], ["83818.9", "0", "0", "0"], ["83818.1", "0", "0", "0"], ["83818", "0", "0", "0"], ["83817.7", "0", "0", "0"]], "ts": "1742577148000", "checksum": 1947462864, "seqId": 49945044679, "prevSeqId": 49945044625}], "record_time": 1742577148.170794, "EXCHANGE": "OKX"}
{"arg": {"channel": "books", "instId": "BTC-USDT"}, "action": "update", "data": [{"asks": [["83968.8", "0.00365366", "0", "1"], ["83975.3", "0", "0", "0"], ["83975.4", "0.01774536", "0", "1"], ["83979", "0.66164085", "0", "2"], ["83982.7", "1", "0", "1"], ["83988", "0.23913177", "0", "3"], ["83989.9", "0", "0", "0"], ["84011.1", "0.000015", "0", "1"], ["84014.4", "0.00002157", "0", "1"], ["84137.1", "0", "0", "0"], ["84137.2", "0", "0", "0"]], "bids": [["83957.2", "0.08284244", "0", "1"], ["83957", "0", "0", "0"], ["83955.9", "0.016", "0", "1"], ["83948.6", "0", "0", "0"], ["83946.7", "1.00001199", "0", "2"], ["83946.5", "0", "0", "0"], ["83934.1", "0", "0", "0"], ["83932.8", "0.14996531", "0", "2"], ["83932.1", "0.23833476", "0", "1"], ["83909.1", "0", "0", "0"], ["83907.5", "0.01835156", "0", "1"], ["83906.6", "0", "0", "0"], ["83890.6", "0.0021865", "0", "1"], ["83888.9", "0.00145242", "0", "1"], ["83888.1", "0", "0", "0"], ["83877.5", "0.01190739", "0", "1"], ["83876.7", "0", "0", "0"], ["83867.5", "0.000015", "0", "1"], ["83819.2", "0.00001297", "0", "1"], ["83818.9", "0.00006774", "0", "2"]], "ts": "1742577148100", "checksum": 1624350948, "seqId": 49945044735, "prevSeqId": 49945044679}], "record_time": 1742577148.278662, "EXCHANGE": "OKX"}
{"arg": {"channel": "books", "instId": "BTC-USDT"}, "action": "update", "data": [{"asks": [["83958", "0.44942656", "0", "5"], ["83959.6", "0.06720049", "0", "3"], ["83965.8", "0.0102", "0", "1"], ["83969.8", "0", "0", "0"], ["83972.4", "0.07062", "0", "2"], ["83973.5", "0.04", "0", "1"], ["83975.5", "1.12845863", "0", "2"], ["83977.1", "0", "0", "0"], ["83978.4", "0", "0", "0"], ["83981.4", "1", "0", "1"], ["83982.7", "0", "0", "0"], ["83983.3", "0.26257682", "0", "3"], ["83988", "0.23913619", "0", "3"], ["84137.1", "0.00001501", "0", "1"]], "bids": [["83957.9", "0.38964626", "0", "9"], ["83956.8", "0.016", "0", "1"], ["83952.4", "0", "0", "0"], ["83946.8", "0.01389", "0", "1"], ["83932.8", "0.14996605", "0", "2"], ["83932.1", "0", "0", "0"], ["83928.7", "0.23833619", "0", "1"], ["83928.6", "0.35320512", "0", "1"], ["83926", "0", "0", "0"], ["83925", "0", "0", "0"], ["83857.1", "0.17942841", "0", "5"], ["83818.1", "0.00006813", "0", "3"], ["83818", "0.0025", "0", "1"]], "ts": "1742577148200", "checksum": 1897029613, "seqId": 49945044778, "prevSeqId": 49945044735}], "record_time": 1742577148.372422, "EXCHANGE": "OKX"}
{"arg": {"channel": "books", "instId": "BTC-USDT"}, "action": "update", "data": [{"asks": [["83961.4", "0.01191698", "0", "1"], ["83964.1", "0", "0", "0"], ["83980.1", "1.1191331", "0", "2"], ["83981.4", "0", "0", "0"], ["83982.8", "0.25025573", "0", "2"], ["83988", "0.0008", "0", "2"], ["84137.2", "0.03", "0", "1"]], "bids": [["83957.9", "0.15854457", "0", "5"], ["83957.2", "0.02669278", "0", "1"], ["83957.1", "0", "0", "0"], ["83956.8", "0", "0", "0"], ["83955.9", "0", "0", "0"], ["83955", "0.11916849", "0", "1"], ["83953.5", "0", "0", "0"], ["83953", "0", "0", "0"], ["83950.7", "0.01191698", "0", "1"], ["83948.7", "0.05271009", "0", "1"], ["83946.8", "0", "0", "0"], ["83946.7", "0.00001199", "0", "1"], ["83945.2", "0.34304965", "0", "1"], ["83945", "0.2025", "0", "1"], ["83942.6", "0", "0", "0"], ["83939", "0", "0", "0"], ["83937.4", "0.04169", "0", "1"], ["83933", "1", "0", "1"], ["83932.8", "0.07201842", "0", "1"], ["83928.7", "0", "0", "0"], ["83927.2", "0.23834852", "0", "1"], ["83913.3", "0", "0", "0"], ["83870.1", "0.00018338", "0", "1"], ["83857.1", "0.77271382", "0", "6"], ["83817.7", "0.00083", "0", "1"], ["83817.6", "0.2025", "0", "1"], ["83817.1", "0.000845", "0", "2"], ["83816.9", "0.00126817", "0", "1"]], "ts": "1742577148300", "checksum": -1286425316, "seqId": 49945044829, "prevSeqId": 49945044778}], "record_time": 1742577148.471563, "EXCHANGE": "OKX"}
