{"arg": {"channel": "books", "instId": "BTC-USDT"}, "action": "update", "data": [{"asks": [["83471.8", "0", "0", "0"], ["83471.9", "0.0002", "0", "2"], ["83496.5", "0.77182298", "0", "2"], ["83520.5", "0", "0", "0"], ["83531.7", "0.55513117", "0", "1"], ["83534.8", "0", "0", "0"], ["83572.4", "0.00589893", "0", "1"], ["83572.7", "0.23757182", "0", "2"], ["83630.9", "0.11992025", "0", "1"]], "bids": [["83468.1", "0", "0", "0"], ["83467.8", "0", "0", "0"], ["83466.8", "0.0002", "0", "2"], ["83436.1", "0.72317814", "0", "2"], ["83435.6", "0.00367", "0", "1"], ["83433.7", "0", "0", "0"], ["83405.7", "0.01280714", "0", "1"], ["83364.4", "0", "0", "0"], ["83331", "0.00001097", "0", "1"], ["83330.8", "0.035909", "0", "1"]], "ts": "1742377420702", "checksum": 859580897, "seqId": 49713707988, "prevSeqId": 49713707954}], "record_time": 1742377421.56896}
{"arg": {"channel": "books", "instId": "BTC-USDT"}, "action": "update", "data": [{"asks": [], "bids": [["83423.1", "0.79", "0", "1"], ["83417.6", "0.0008", "0", "2"], ["83416.8", "0.20289998", "0", "2"], ["83416", "0.08", "0", "2"], ["83331", "0", "0", "0"], ["83330.8", "0", "0", "0"]], "ts": "1742377420802", "checksum": 859580897, "seqId": 49713707998, "prevSeqId": 49713707988}], "record_time": 1742377421.669171}
{"arg": {"channel": "books", "instId": "BTC-USDT"}, "action": "update", "data": [{"asks": [["83476.8", "0.23961819", "0", "1"], ["83478.8", "0", "0", "0"]], "bids": [["83458.9", "0", "0", "0"], ["83431", "0.2", "0", "1"], ["83423.2", "0.23961819", "0", "1"], ["83422.5", "0", "0", "0"]], "ts": "1742377420902", "checksum": -1060762647, "seqId": 49713708017, "prevSeqId": 49713707998}], "record_time": 1742377421.769239}
{"arg": {"channel": "books", "instId": "BTC-USDT"}, "action": "update", "data": [{"asks": [], "bids": [["83458.9", "0.0010725", "0", "1"], ["83431", "0", "0", "0"]], "ts": "1742377421002", "checksum": 1242374669, "seqId": 49713708024, "prevSeqId": 49713708017}], "record_time": 1742377421.869154}
{"arg": {"channel": "books", "instId": "BTC-USDT"}, "action": "update", "data": [{"asks": [["83571.2", "0.02395611", "0", "1"], ["83598.7", "0.70001204", "0", "2"]], "bids": [["83469.7", "0.86322258", "0", "13"]], "ts": "1742377421102", "checksum": -2142358354, "seqId": 49713708031, "prevSeqId": 49713708024}], "record_time": 1742377421.97235}
{"arg": {"channel": "books", "instId": "BTC-USDT"}, "action": "update", "data": [{"asks": [["83479.3", "1.20602586", "0", "2"], ["83531.7", "0.56977908", "0", "2"]], "bids": [["83469.7", "0.74445272", "0", "12"], ["83468.9", "0.19861786", "0", "1"], ["83466.6", "0.28362561", "0", "1"], ["83444.8", "0.00372912", "0", "1"], ["83436", "0", "0", "0"], ["83435.6", "0.00726386", "0", "2"], ["83375.4", "0.01439273", "0", "1"], ["83331.2", "0", "0", "0"]], "ts": "1742377421202", "checksum": -433695925, "seqId": 49713708053, "prevSeqId": 49713708031}], "record_time": 1742377422.070108}
{"arg": {"channel": "books", "instId": "BTC-USDT"}, "action": "update", "data": [{"asks": [["83469.8", "0.75169762", "0", "7"], ["83471.6", "0.0002", "0", "2"], ["83471.9", "0", "0", "0"], ["83475.2", "0.23962308", "0", "1"], ["83476.8", "0", "0", "0"], ["83478.6", "0.08991011", "0", "1"], ["83480.2", "0.03916", "0", "2"], ["83482.6", "0.11910016", "0", "2"], ["83483.2", "0", "0", "0"], ["83483.5", "0.25900423", "0", "2"], ["83483.7", "0.09675125", "0", "1"], ["83484", "0.14607361", "0", "2"], ["83484.2", "0.005", "0", "1"], ["83484.4", "0", "0", "0"], ["83485.5", "0", "0", "0"], ["83487.2", "0", "0", "0"], ["83490.2", "0.51720648", "0", "3"], ["83490.5", "0.16776881", "0", "1"], ["83490.7", "0.16124828", "0", "2"], ["83491", "0.11977102", "0", "1"], ["83491.3", "0.15324258", "0", "1"], ["83491.4", "0", "0", "0"], ["83491.7", "0.08991011", "0", "1"], ["83491.9", "0", "0", "0"], ["83492.4", "0.15912959", "0", "1"], ["83492.7", "0", "0", "0"], ["83497.3", "0.25274208", "0", "1"], ["83497.5", "0.24759493", "0", "1"], ["83497.7", "0", "0", "0"], ["83498.4", "0.00001206", "0", "1"], ["83499.4", "0.23653979", "0", "1"], ["83500", "0.22733089", "0", "4"], ["83501.2", "0.26652857", "0", "1"], ["83501.5", "0", "0", "0"], ["83584.4", "0", "0", "0"], ["83630.9", "0", "0", "0"]], "bids": [["83469.7", "0.81250077", "0", "16"], ["83469", "0", "0", "0"], ["83468.2", "0.0001", "0", "1"], ["83467.6", "0.0001", "0", "1"], ["83466.8", "0", "0", "0"], ["83466.7", "0.11980574", "0", "1"], ["83459.9", "0.05420836", "0", "1"], ["83458.9", "0", "0", "0"], ["83458.1", "0.24120851", "0", "1"], ["83457.9", "0", "0", "0"], ["83457.3", "0.35972754", "0", "1"], ["83457.1", "0", "0", "0"], ["83456.7", "0.09945055", "0", "1"], ["83456.2", "0.08953493", "0", "1"], ["83456", "0", "0", "0"], ["83455.7", "0.10088697", "0", "1"], ["83455.6", "0.01198085", "0", "1"], ["83455.3", "0.09484013", "0", "2"], ["83454.9", "0", "0", "0"], ["83450.1", "0", "0", "0"], ["83449.2", "0.66048188", "0", "4"], ["83449", "0", "0", "0"], ["83448.7", "0.16125332", "0", "1"], ["83448.5", "0", "0", "0"], ["83447.9", "0.16731366", "0", "1"], ["83447.2", "0", "0", "0"], ["83446.9", "0.17902879", "0", "2"], ["83443.1", "0", "0", "0"], ["83442.4", "0", "0", "0"], ["83442.2", "0.25009376", "0", "1"], ["83442", "0.4683699", "0", "2"], ["83440.5", "0", "0", "0"], ["83440.4", "0", "0", "0"], ["83439.9", "0.25856058", "0", "1"], ["83438.5", "0", "0", "0"], ["83438.2", "0.25599298", "0", "1"], ["83436.1", "0", "0", "0"], ["83435.6", "0.00367", "0", "1"], ["83428.5", "0.01219896", "0", "1"], ["83423.2", "0", "0", "0"], ["83421.8", "0.23962246", "0", "1"], ["83331.2", "0.00005685", "0", "1"], ["83331", "0.00001097", "0", "1"], ["83330.8", "0.035909", "0", "1"]], "ts": "1742377421302", "checksum": 1643236990, "seqId": 49713708177, "prevSeqId": 49713708053}], "record_time": 1742377422.169831}
{"arg": {"channel": "books", "instId": "BTC-USDT"}, "action": "update", "data": [{"asks": [["83471.9", "0.23962826", "0", "1"], ["83475.2", "0", "0", "0"], ["83493", "0.1", "0", "1"], ["83498", "1.0055", "0", "2"], ["83571.3", "0", "0", "0"]], "bids": [["83469.7", "0.6082761", "0", "12"], ["83468.9", "0.10855958", "0", "1"], ["83468.1", "0.0001", "0", "1"], ["83467.6", "0", "0", "0"], ["83467.5", "0", "0", "0"], ["83455.3", "0.09418613", "0", "1"], ["83442.6", "0", "0", "0"], ["83421.8", "0", "0", "0"], ["83420.1", "0.24030901", "0", "2"], ["83330.6", "0.00001852", "0", "1"], ["83330.1", "0.00003016", "0", "2"], ["83329.7", "0.00008173", "0", "1"]], "ts": "1742377421402", "checksum": 441807644, "seqId": 49713708206, "prevSeqId": 49713708177}], "record_time": 1742377422.27075}
{"arg": {"channel": "books", "instId": "BTC-USDT"}, "action": "update", "data": [{"asks": [["83469.8", "0.76267696", "0", "8"], ["83470.4", "0", "0", "0"], ["83470.7", "0.08991011", "0", "1"], ["83471.6", "0", "0", "0"], ["83471.7", "0.0001", "0", "1"], ["83471.9", "0", "0", "0"], ["83472.3", "0.0001", "0", "1"], ["83473.8", "0.23962797", "0", "1"], ["83475.5", "0.00916", "0", "1"], ["83480.2", "0.030129", "0", "2"], ["83491.4", "0.003594", "0", "1"], ["83598.7", "0.00001204", "0", "1"], ["83630.6", "0", "0", "0"], ["83630.7", "0", "0", "0"], ["83630.8", "0", "0", "0"]], "bids": [["83469.7", "0.5562761", "0", "10"], ["83468.7", "0.0674628", "0", "2"], ["83468.2", "0.0002", "0", "2"], ["83468.1", "0", "0", "0"], ["83454.9", "0.0004635", "0", "1"], ["83452.5", "0.01566", "0", "1"], ["83439", "0.05983983", "0", "1"], ["83436.7", "0.01097934", "0", "1"], ["83420.5", "0.23962797", "0", "1"], ["83420.1", "0.00068075", "0", "1"], ["83330.8", "0", "0", "0"], ["83330.6", "0", "0", "0"], ["83330.1", "0", "0", "0"], ["83329.7", "0", "0", "0"]], "ts": "1742377421502", "checksum": 11582399, "seqId": 49713708248, "prevSeqId": 49713708206}], "record_time": 1742377422.369166}
{"arg": {"channel": "books", "instId": "BTC-USDT"}, "action": "update", "data": [{"asks": [["83471.7", "0", "0", "0"], ["83472.2", "0.0002", "0", "2"], ["83472.3", "0", "0", "0"], ["83493", "0", "0", "0"], ["83498", "0.0055", "0", "1"], ["83630.6", "0.00011142", "0", "1"], ["83630.7", "0.0000484", "0", "1"]], "bids": [["83468.7", "0.0314628", "0", "1"], ["83468.2", "0", "0", "0"], ["83468.1", "0.0002", "0", "2"]], "ts": "1742377421602", "checksum": -1058890602, "seqId": 49713708278, "prevSeqId": 49713708248}], "record_time": 1742377422.469711}
{"arg": {"channel": "books", "instId": "BTC-USDT"}, "action": "update", "data": [{"asks": [["83472.2", "0.0001", "0", "1"], ["83472.8", "0.0001", "0", "1"], ["83475.8", "0.0314628", "0", "1"], ["83478.9", "0", "0", "0"], ["83511.1", "0.41257565", "0", "2"], ["83534.8", "0.06547883", "0", "1"], ["83630.6", "0", "0", "0"], ["83630.7", "0", "0", "0"]], "bids": [["83469.7", "0.4996261", "0", "9"], ["83468.9", "0.06792074", "0", "1"], ["83468.7", "0", "0", "0"], ["83467.4", "0.04969672", "0", "1"], ["83466.5", "0.03779828", "0", "4"], ["83465.3", "0.0314628", "0", "1"], ["83462.4", "0.09625751", "0", "1"], ["83461.3", "0.2025", "0", "1"], ["83458", "0", "0", "0"], ["83455.6", "0", "0", "0"], ["83452.3", "0.01198132", "0", "1"], ["83449.3", "0.52676751", "0", "1"], ["83449.2", "0.37472246", "0", "3"], ["83419.5", "0.67421353", "0", "1"], ["83418.3", "0", "0", "0"], ["83331", "0", "0", "0"]], "ts": "1742377421702", "checksum": 492301641, "seqId": 49713708309, "prevSeqId": 49713708278}], "record_time": 1742377422.574108}
{"arg": {"channel": "books", "instId": "BTC-USDT"}, "action": "update", "data": [{"asks": [["83469.8", "0.76266499", "0", "8"], ["83472.2", "0", "0", "0"], ["83472.8", "0", "0", "0"], ["83476.6", "0.0001", "0", "1"], ["83476.7", "0.0001", "0", "1"]], "bids": [["83469.4", "0.0001", "0", "1"], ["83469.3", "0.0001", "0", "1"], ["83468.1", "0", "0", "0"], ["83331.2", "0", "0", "0"]], "ts": "1742377421802", "checksum": -1530602199, "seqId": 49713708325, "prevSeqId": 49713708309}], "record_time": 1742377422.669575}
{"arg": {"channel": "books", "instId": "BTC-USDT"}, "action": "update", "data": [{"asks": [["83469.8", "0.76462499", "0", "9"], ["83473.3", "0.00916", "0", "1"], ["83475.5", "0", "0", "0"]], "bids": [["83469.7", "0.35507972", "0", "6"], ["83469.3", "0", "0", "0"], ["83469.1", "0.0001", "0", "1"], ["83457.7", "0", "0", "0"], ["83454.9", "0", "0", "0"], ["83452.5", "0", "0", "0"], ["83451.8", "0.02956077", "0", "1"], ["83450.3", "0.01566", "0", "1"], ["83449.2", "0.32772246", "0", "2"], ["83444.1", "0.04701", "0", "1"]], "ts": "1742377421902", "checksum": -1934780919, "seqId": 49713708357, "prevSeqId": 49713708325}], "record_time": 1742377422.769483}
{"arg": {"channel": "books", "instId": "BTC-USDT"}, "action": "update", "data": [{"asks": [["83476.6", "0.0002", "0", "2"], ["83476.7", "0", "0", "0"], ["83479.3", "0.6307031", "0", "2"], ["83479.4", "0.000015", "0", "1"], ["83504.4", "0", "0", "0"], ["83508.6", "0", "0", "0"], ["83571.1", "0.04643753", "0", "3"], ["83593.7", "0.25102278", "0", "2"], ["83630.6", "0.00011142", "0", "1"], ["83630.7", "0.0000484", "0", "1"], ["83630.8", "0.00110397", "0", "1"]], "bids": [["83469.4", "0", "0", "0"], ["83469.3", "0.0002", "0", "2"], ["83469.1", "0", "0", "0"], ["83428.4", "0.00001205", "0", "1"], ["83428.3", "0", "0", "0"], ["83428", "0.10007368", "0", "2"], ["83406.3", "0.01197486", "0", "1"], ["83405.7", "0", "0", "0"], ["83405.5", "0", "0", "0"], ["83399.3", "0.12452466", "0", "2"], ["83399.1", "0", "0", "0"], ["83331.2", "0.00005685", "0", "1"], ["83331", "0.00001097", "0", "1"], ["83330.8", "0.035909", "0", "1"], ["83330.6", "0.00001852", "0", "1"]], "ts": "1742377422002", "checksum": 667387545, "seqId": 49713708397, "prevSeqId": 49713708357}], "record_time": 1742377422.869266}
{"arg": {"channel": "books", "instId": "BTC-USDT"}, "action": "update", "data": [{"asks": [["83476.6", "0", "0", "0"], ["83476.9", "0.35963", "0", "3"], ["83479.3", "1.05798605", "0", "3"], ["83482", "1.59388299", "0", "2"], ["83496.4", "0", "0", "0"], ["83511.2", "2.81121609", "0", "2"], ["83527.4", "0.00378486", "0", "1"], ["83528.9", "0", "0", "0"], ["83531.6", "0.01219896", "0", "1"], ["83630.9", "0.11992025", "0", "1"]], "bids": [["83469.3", "0", "0", "0"], ["83469.1", "0.0002", "0", "2"], ["83455.1", "0.0004785", "0", "1"], ["83429.3", "1.57664689", "0", "1"], ["83428.5", "0", "0", "0"], ["83428", "0.00007368", "0", "1"], ["83420.5", "0.23962707", "0", "1"], ["83405.6", "0", "0", "0"], ["83405.1", "0.01845102", "0", "1"], ["83402.8", "0.01219896", "0", "1"], ["83400.1", "3.00157751", "0", "2"], ["83351", "0.00112958", "0", "1"], ["83350.6", "0", "0", "0"], ["83336.6", "0.00004163", "0", "1"], ["83334.8", "0.1845102", "0", "1"], ["83331", "0", "0", "0"], ["83330.8", "0", "0", "0"], ["83330.6", "0", "0", "0"]], "ts": "1742377422102", "checksum": 163731538, "seqId": 49713708444, "prevSeqId": 49713708397}], "record_time": 1742377422.970629}
{"arg": {"channel": "books", "instId": "BTC-USDT"}, "action": "update", "data": [{"asks": [["83473.8", "0.23962776", "0", "1"], ["83476.7", "0.0002", "0", "2"], ["83476.9", "0.35943", "0", "1"], ["83630.9", "0", "0", "0"]], "bids": [["83469.3", "0.0002", "0", "2"], ["83469.1", "0", "0", "0"]], "ts": "1742377422202", "checksum": -1496795684, "seqId": 49713708462, "prevSeqId": 49713708444}], "record_time": 1742377423.07267}
{"arg": {"channel": "books", "instId": "BTC-USDT"}, "action": "update", "data": [{"asks": [["83469.8", "0.80272499", "0", "11"], ["83476.7", "0", "0", "0"], ["83476.9", "0.35963", "0", "3"], ["83496.4", "0.01219896", "0", "1"], ["83510.4", "0.07999999", "0", "2"], ["83531.6", "0", "0", "0"], ["83630.9", "0.11992025", "0", "1"]], "bids": [["83469.4", "0.0001", "0", "1"], ["83469.3", "0.0001", "0", "1"], ["83433", "1.48724", "0", "2"], ["83430.1", "0.01647154", "0", "2"], ["83423.1", "0", "0", "0"], ["83402.8", "0", "0", "0"], ["83331", "0.00001097", "0", "1"]], "ts": "1742377422302", "checksum": -569254261, "seqId": 49713708488, "prevSeqId": 49713708462}], "record_time": 1742377423.169492}
{"arg": {"channel": "books", "instId": "BTC-USDT"}, "action": "update", "data": [{"asks": [["83476.7", "0.0002", "0", "2"], ["83476.9", "0.35943", "0", "1"], ["83510.4", "0.08", "0", "2"], ["83630.9", "0", "0", "0"]], "bids": [["83469.4", "0", "0", "0"], ["83469.3", "0.0002", "0", "2"], ["83433", "0.48724", "0", "1"], ["83417.6", "0", "0", "0"], ["83416.8", "0.20329998", "0", "3"], ["83416", "0.08039998", "0", "3"], ["83330.8", "0.035909", "0", "1"], ["83330.6", "0.00001852", "0", "1"]], "ts": "1742377422402", "checksum": 2036349658, "seqId": 49713708518, "prevSeqId": 49713708488}], "record_time": 1742377423.270248}
{"arg": {"channel": "books", "instId": "BTC-USDT"}, "action": "update", "data": [{"asks": [["83476.7", "0", "0", "0"], ["83476.8", "0.0002", "0", "2"], ["83490.9", "0.20315596", "0", "2"], ["83560.8", "0.05802294", "0", "1"], ["83630.8", "0", "0", "0"]], "bids": [["83469.5", "0.0002", "0", "2"], ["83469.3", "0", "0", "0"], ["83468.9", "0.26369865", "0", "1"], ["83467.4", "0", "0", "0"], ["83466.9", "0.35972754", "0", "1"], ["83466.8", "0.42", "0", "1"], ["83462.4", "0.14423514", "0", "2"], ["83458.2", "0.17953568", "0", "1"], ["83430.1", "0.00427258", "0", "1"], ["83402.8", "0.01219896", "0", "1"], ["83352", "0.05802294", "0", "1"], ["83331.2", "0", "0", "0"], ["83331", "0", "0", "0"], ["83330.8", "0", "0", "0"], ["83330.6", "0", "0", "0"]], "ts": "1742377422502", "checksum": 81192817, "seqId": 49713708548, "prevSeqId": 49713708518}], "record_time": 1742377423.369515}
{"arg": {"channel": "books", "instId": "BTC-USDT"}, "action": "update", "data": [{"asks": [["83476.6", "0.0001", "0", "1"], ["83476.8", "0.0001", "0", "1"], ["83630.7", "0", "0", "0"]], "bids": [], "ts": "1742377422602", "checksum": -1362983956, "seqId": 49713708558, "prevSeqId": 49713708548}], "record_time": 1742377423.469032}
{"arg": {"channel": "books", "instId": "BTC-USDT"}, "action": "update", "data": [{"asks": [["83476.6", "0.0002", "0", "2"], ["83476.8", "0", "0", "0"], ["83586.4", "0.192876", "0", "1"], ["83593.8", "0", "0", "0"], ["83630.7", "0.0000484", "0", "1"]], "bids": [["83466.8", "0", "0", "0"], ["83331.2", "0.00005685", "0", "1"]], "ts": "1742377422702", "checksum": 756415020, "seqId": 49713708570, "prevSeqId": 49713708558}], "record_time": 1742377423.569241}
{"arg": {"channel": "books", "instId": "BTC-USDT"}, "action": "update", "data": [{"asks": [["83471.9", "0.23962879", "0", "1"], ["83473.8", "0", "0", "0"], ["83476.6", "0.0001", "0", "1"], ["83476.7", "0.0001", "0", "1"], ["83511.1", "1.20733499", "0", "3"], ["83534.8", "0.69599585", "0", "2"], ["83593.7", "0.00001204", "0", "1"], ["83630.7", "0", "0", "0"]], "bids": [["83468.9", "0.16086998", "0", "1"], ["83459.9", "0", "0", "0"], ["83430.1", "0.62043745", "0", "2"], ["83420.5", "0", "0", "0"], ["83420.1", "0.24030954", "0", "2"], ["83416", "0.08039996", "0", "3"], ["83402.7", "2.75437656", "0", "3"], ["83331", "0.00001097", "0", "1"], ["83330.8", "0.035909", "0", "1"]], "ts": "1742377422802", "checksum": 1140209965, "seqId": 49713708605, "prevSeqId": 49713708570}], "record_time": 1742377423.669801}
{"arg": {"channel": "books", "instId": "BTC-USDT"}, "action": "update", "data": [{"asks": [["83471.9", "0", "0", "0"], ["83473.7", "0.23962814", "0", "1"], ["83476.6", "0", "0", "0"], ["83476.7", "0.0002", "0", "2"], ["83491.4", "0", "0", "0"], ["83630.7", "0.0000484", "0", "1"], ["83630.8", "0.00110397", "0", "1"]], "bids": [["83469.7", "0.41203376", "0", "7"], ["83469.6", "0.0001", "0", "1"], ["83469.5", "0", "0", "0"], ["83469.3", "0.0001", "0", "1"], ["83455.1", "0", "0", "0"], ["83454.5", "0.05424725", "0", "2"], ["83420.5", "0.23962825", "0", "1"], ["83420.1", "0.00068075", "0", "1"], ["83330.8", "0", "0", "0"]], "ts": "1742377422902", "checksum": 151595930, "seqId": 49713708643, "prevSeqId": 49713708605}], "record_time": 1742377423.771305}
{"arg": {"channel": "books", "instId": "BTC-USDT"}, "action": "update", "data": [{"asks": [], "bids": [["83469.6", "0", "0", "0"], ["83469.3", "0.0002", "0", "2"], ["83330.8", "0.035909", "0", "1"]], "ts": "1742377423002", "checksum": 1729162763, "seqId": 49713708651, "prevSeqId": 49713708643}], "record_time": 1742377423.869589}
{"arg": {"channel": "books", "instId": "BTC-USDT"}, "action": "update", "data": [{"asks": [["83470.7", "0", "0", "0"], ["83473.7", "0", "0", "0"], ["83473.8", "0.23962482", "0", "1"], ["83480.2", "0.03", "0", "1"], ["83630.9", "0.11992025", "0", "1"]], "bids": [["83469.6", "0.0001", "0", "1"], ["83469.5", "0.0001", "0", "1"], ["83469.3", "0", "0", "0"], ["83455.6", "0.00006", "0", "1"], ["83429", "0.1", "0", "1"], ["83421.8", "0.23962482", "0", "1"], ["83420.5", "0", "0", "0"], ["83331.2", "0", "0", "0"], ["83331", "0", "0", "0"], ["83330.8", "0", "0", "0"]], "ts": "1742377423102", "checksum": 1605901839, "seqId": 49713708669, "prevSeqId": 49713708651}], "record_time": 1742377423.969622}
{"arg": {"channel": "books", "instId": "BTC-USDT"}, "action": "update", "data": [{"asks": [["83480.8", "0.00054", "0", "1"], ["83630.9", "0", "0", "0"]], "bids": [["83469.6", "0", "0", "0"], ["83469.5", "0.0002", "0", "2"], ["83331.2", "0.00005685", "0", "1"]], "ts": "1742377423202", "checksum": 173048340, "seqId": 49713708675, "prevSeqId": 49713708669}], "record_time": 1742377424.069482}
{"arg": {"channel": "books", "instId": "BTC-USDT"}, "action": "update", "data": [{"asks": [["83473.8", "0.23962379", "0", "1"], ["83476.6", "0.0002", "0", "2"], ["83476.7", "0", "0", "0"], ["83510.4", "0", "0", "0"], ["83511.2", "2.85121609", "0", "3"], ["83512", "0.03999999", "0", "1"]], "bids": [["83421.8", "0", "0", "0"], ["83420.5", "0.23962596", "0", "1"]], "ts": "1742377423302", "checksum": 1358933507, "seqId": 49713708703, "prevSeqId": 49713708675}], "record_time": 1742377424.172933}
{"arg": {"channel": "books", "instId": "BTC-USDT"}, "action": "update", "data": [{"asks": [["83473.6", "0.39266695", "0", "1"], ["83473.7", "0.42", "0", "1"], ["83473.9", "0", "0", "0"], ["83490.8", "0.35972754", "0", "1"], ["83572.7", "0.00298666", "0", "1"], ["83630.8", "0", "0", "0"]], "bids": [["83469.5", "0.0001", "0", "1"], ["83469.1", "0.0001", "0", "1"], ["83434", "1", "0", "1"], ["83429", "0", "0", "0"], ["83331.2", "0", "0", "0"]], "ts": "1742377423502", "checksum": -781715643, "seqId": 49713708722, "prevSeqId": 49713708703}], "record_time": 1742377424.369569}
{"arg": {"channel": "books", "instId": "BTC-USDT"}, "action": "update", "data": [{"asks": [["83510.4", "0.08", "0", "2"], ["83511.2", "2.81121609", "0", "2"], ["83512", "0", "0", "0"], ["83545.6", "0.07181707", "0", "1"]], "bids": [["83469.5", "0", "0", "0"], ["83469.4", "0.0001", "0", "1"], ["83469.3", "0.0001", "0", "1"], ["83469.1", "0", "0", "0"], ["83435.6", "0.01586896", "0", "2"], ["83402.8", "0", "0", "0"], ["83381.9", "0.07195805", "0", "1"], ["83331.2", "0.00005685", "0", "1"]], "ts": "1742377423602", "checksum": -103028448, "seqId": 49713708749, "prevSeqId": 49713708722}], "record_time": 1742377424.46923}
{"arg": {"channel": "books", "instId": "BTC-USDT"}, "action": "update", "data": [{"asks": [["83493", "0.2", "0", "1"], ["83497", "1", "0", "1"], ["83539.6", "0.07182223", "0", "1"], ["83545.6", "0", "0", "0"], ["83630.6", "0", "0", "0"], ["83630.7", "0", "0", "0"]], "bids": [["83469.4", "0", "0", "0"], ["83469.3", "0.0002", "0", "2"], ["83381.9", "0", "0", "0"], ["83375.9", "0.07196323", "0", "1"], ["83331", "0.00001097", "0", "1"]], "ts": "1742377423702", "checksum": 1093710505, "seqId": 49713708778, "prevSeqId": 49713708749}], "record_time": 1742377424.570068}
{"arg": {"channel": "books", "instId": "BTC-USDT"}, "action": "update", "data": [{"asks": [["83476.6", "0", "0", "0"], ["83476.9", "0.35963", "0", "3"], ["83493", "0", "0", "0"], ["83497", "0", "0", "0"], ["83505.4", "0.39231869", "0", "1"], ["83539.6", "0.14364446", "0", "2"], ["83559.8", "0.02004994", "0", "2"], ["83566.6", "0.00101501", "0", "2"], ["83571.1", "0.01199783", "0", "2"], ["83630.6", "0.00011142", "0", "1"], ["83630.7", "0.0000484", "0", "1"]], "bids": [["83435.2", "0.58878101", "0", "1"], ["83406.4", "0.0128075", "0", "1"], ["83375.9", "0.14392646", "0", "2"], ["83331.2", "0", "0", "0"], ["83331", "0", "0", "0"]], "ts": "1742377423802", "checksum": -23166450, "seqId": 49713708802, "prevSeqId": 49713708778}], "record_time": 1742377424.668708}
{"arg": {"channel": "books", "instId": "BTC-USDT"}, "action": "update", "data": [{"asks": [["83473.4", "0.17954774", "0", "2"], ["83473.5", "0.24741507", "0", "2"], ["83473.8", "0", "0", "0"], ["83476.6", "0.0002", "0", "2"], ["83476.9", "0.35943", "0", "1"]], "bids": [["83420.5", "0", "0", "0"], ["83420.1", "0.24030896", "0", "2"], ["83331.2", "0.00005685", "0", "1"]], "ts": "1742377423902", "checksum": -130491769, "seqId": 49713708827, "prevSeqId": 49713708802}], "record_time": 1742377424.769397}
{"arg": {"channel": "books", "instId": "BTC-USDT"}, "action": "update", "data": [{"asks": [["83539.6", "0.07182223", "0", "1"]], "bids": [["83445.5", "0.16904615", "0", "1"], ["83375.9", "0.07196323", "0", "1"]], "ts": "1742377424002", "checksum": -130491769, "seqId": 49713708836, "prevSeqId": 49713708827}], "record_time": 1742377424.868999}
{"arg": {"channel": "books", "instId": "BTC-USDT"}, "action": "update", "data": [{"asks": [["83473.3", "0.24878746", "0", "2"], ["83473.5", "0.00778734", "0", "1"], ["83527.3", "0.00013267", "0", "1"], ["83527.5", "0", "0", "0"], ["83539.6", "0.14364446", "0", "2"]], "bids": [["83469.4", "0.0002", "0", "2"], ["83469.3", "0", "0", "0"], ["83445", "0.13272", "0", "1"], ["83420.5", "0.23962732", "0", "1"], ["83420.1", "0.00068075", "0", "1"], ["83375.9", "0.14392646", "0", "2"], ["83332.3", "0", "0", "0"], ["83331.2", "0", "0", "0"]], "ts": "1742377424102", "checksum": 1124521278, "seqId": 49713708861, "prevSeqId": 49713708836}], "record_time": 1742377424.9696}
{"arg": {"channel": "books", "instId": "BTC-USDT"}, "action": "update", "data": [{"asks": [], "bids": [["83420.5", "0", "0", "0"], ["83420.1", "0.240308", "0", "2"], ["83332.3", "0.00001364", "0", "1"]], "ts": "1742377424202", "checksum": 1124521278, "seqId": 49713708868, "prevSeqId": 49713708861}], "record_time": 1742377425.069046}
{"arg": {"channel": "books", "instId": "BTC-USDT"}, "action": "update", "data": [{"asks": [["83469.8", "0.80076499", "0", "10"], ["83473.1", "0.25372833", "0", "1"], ["83473.3", "0.23962581", "0", "1"], ["83473.6", "0", "0", "0"], ["83473.7", "0", "0", "0"], ["83475.6", "0.00916", "0", "1"], ["83476.6", "0", "0", "0"], ["83476.7", "0.0001", "0", "1"], ["83477.1", "0.0001", "0", "1"], ["83534.8", "0.26152076", "0", "2"], ["83630.7", "0", "0", "0"]], "bids": [["83469.7", "0.77208989", "0", "10"], ["83469.5", "0.0001", "0", "1"], ["83469.4", "0", "0", "0"], ["83469.3", "0.0001", "0", "1"], ["83468.9", "0.26676124", "0", "2"], ["83467", "0.42", "0", "1"], ["83452.7", "0.01567204", "0", "2"], ["83450.3", "0", "0", "0"], ["83420.5", "0.23962581", "0", "1"], ["83420.1", "0.00068075", "0", "1"], ["83332.6", "0", "0", "0"], ["83332.3", "0", "0", "0"]], "ts": "1742377424302", "checksum": 581780066, "seqId": 49713708918, "prevSeqId": 49713708868}], "record_time": 1742377425.176648}
{"arg": {"channel": "books", "instId": "BTC-USDT"}, "action": "update", "data": [{"asks": [["83473.3", "0", "0", "0"], ["83475.2", "0.23962581", "0", "1"], ["83476.4", "0.0002", "0", "2"], ["83476.7", "0", "0", "0"], ["83477.1", "0", "0", "0"], ["83479.3", "0.69825851", "0", "2"], ["83481.6", "0.35972754", "0", "1"]], "bids": [["83469.5", "0.0002", "0", "2"], ["83469.3", "0", "0", "0"], ["83435.2", "0", "0", "0"], ["83434", "0", "0", "0"], ["83332.6", "0.00001302", "0", "1"], ["83332.3", "0.00001364", "0", "1"], ["83331.2", "0.00005685", "0", "1"]], "ts": "1742377424402", "checksum": 1149568591, "seqId": 49713708944, "prevSeqId": 49713708918}], "record_time": 1742377425.269219}
{"arg": {"channel": "books", "instId": "BTC-USDT"}, "action": "update", "data": [{"asks": [["83475.2", "0", "0", "0"], ["83475.7", "0.24162339", "0", "2"], ["83630.7", "0.0000484", "0", "1"]], "bids": [["83435.6", "0.00367", "0", "1"], ["83429", "0.2", "0", "1"], ["83421.8", "0.23962339", "0", "1"], ["83420.5", "0", "0", "0"], ["83402.8", "0.01219896", "0", "1"], ["83332.3", "0", "0", "0"], ["83331.2", "0", "0", "0"]], "ts": "1742377424502", "checksum": -1190653643, "seqId": 49713708959, "prevSeqId": 49713708944}], "record_time": 1742377425.369962}
{"arg": {"channel": "books", "instId": "BTC-USDT"}, "action": "update", "data": [{"asks": [["83469.8", "0.70539194", "0", "9"], ["83475.7", "0.002", "0", "1"], ["83476.3", "0.0001", "0", "1"], ["83476.4", "0.0001", "0", "1"], ["83476.8", "0.23962245", "0", "1"], ["83478.6", "0", "0", "0"], ["83480.8", "0", "0", "0"]], "bids": [["83429", "0.19999999", "0", "1"], ["83421.8", "0.23962382", "0", "1"]], "ts": "1742377424602", "checksum": -554274246, "seqId": 49713708985, "prevSeqId": 49713708959}], "record_time": 1742377425.473703}
{"arg": {"channel": "books", "instId": "BTC-USDT"}, "action": "update", "data": [{"asks": [["83476.3", "0", "0", "0"], ["83476.4", "0.0002", "0", "2"], ["83630.8", "0.00110397", "0", "1"]], "bids": [["83469.7", "0.79021013", "0", "11"], ["83430.2", "0.01219896", "0", "1"], ["83402.8", "0", "0", "0"]], "ts": "1742377424702", "checksum": -1017762919, "seqId": 49713709003, "prevSeqId": 49713708985}], "record_time": 1742377425.569607}
{"arg": {"channel": "books", "instId": "BTC-USDT"}, "action": "update", "data": [{"asks": [["83476.4", "0", "0", "0"], ["83476.8", "0", "0", "0"], ["83477.6", "0.0002", "0", "2"], ["83477.9", "0.23962034", "0", "1"], ["83479.3", "0.27097556", "0", "1"], ["83482", "0.0567", "0", "1"], ["83492.3", "0.12787192", "0", "1"], ["83499", "1.2", "0", "2"], ["83511.1", "0.41257565", "0", "2"], ["83511.2", "0.03999999", "0", "1"], ["83572.7", "0.23757182", "0", "2"], ["83630.7", "0", "0", "0"], ["83630.8", "0", "0", "0"]], "bids": [["83469.7", "0.77217882", "0", "11"], ["83469.6", "0.0001", "0", "1"], ["83469.5", "0", "0", "0"], ["83469.4", "0.0001", "0", "1"], ["83435.6", "0.41236927", "0", "2"], ["83430.1", "0.00427258", "0", "1"], ["83429.3", "0", "0", "0"], ["83429", "0", "0", "0"], ["83422.5", "0.23962034", "0", "1"], ["83421.8", "0", "0", "0"], ["83402.7", "2.05037485", "0", "2"], ["83400.1", "0.11992025", "0", "1"], ["83332.3", "0.00001364", "0", "1"]], "ts": "1742377424802", "checksum": 1091089286, "seqId": 49713709049, "prevSeqId": 49713709003}], "record_time": 1742377425.66949}
{"arg": {"channel": "books", "instId": "BTC-USDT"}, "action": "update", "data": [{"asks": [["83469.8", "0.70491395", "0", "9"], ["83477", "0.0002", "0", "2"], ["83477.6", "0", "0", "0"], ["83479.3", "0.80991314", "0", "2"], ["83482", "1.60645606", "0", "2"], ["83482.3", "0.0000105", "0", "1"], ["83496.4", "0", "0", "0"], ["83499", "0", "0", "0"], ["83511.2", "2.90987272", "0", "2"], ["83531.6", "0.01219896", "0", "1"]], "bids": [["83469.7", "0.82882882", "0", "12"], ["83469.6", "0", "0", "0"], ["83469.4", "0", "0", "0"], ["83469.3", "0.0002", "0", "2"], ["83433.6", "1.81073719", "0", "2"], ["83430.2", "0", "0", "0"], ["83406.4", "0.88993594", "0", "2"], ["83404.4", "2.92909791", "0", "1"], ["83402.8", "0.01219896", "0", "1"]], "ts": "1742377424902", "checksum": 1056040282, "seqId": 49713709087, "prevSeqId": 49713709049}], "record_time": 1742377425.76933}
{"arg": {"channel": "books", "instId": "BTC-USDT"}, "action": "update", "data": [{"asks": [], "bids": [["83469.5", "0.0002", "0", "2"], ["83469.3", "0", "0", "0"], ["83416.8", "0.20329996", "0", "3"], ["83404.5", "0.00198617", "0", "1"], ["83403.8", "0", "0", "0"]], "ts": "1742377425002", "checksum": 1312036326, "seqId": 49713709105, "prevSeqId": 49713709087}], "record_time": 1742377425.8749}
{"arg": {"channel": "books", "instId": "BTC-USDT"}, "action": "update", "data": [{"asks": [["83476.8", "0.23982085", "0", "3"], ["83477", "0", "0", "0"], ["83477.9", "0", "0", "0"], ["83496.4", "0.01219896", "0", "1"], ["83531.6", "0", "0", "0"], ["83600.2", "0.32064763", "0", "1"]], "bids": [["83469.7", "0.82198882", "0", "10"], ["83419.6", "0.01219896", "0", "1"], ["83402.8", "0", "0", "0"]], "ts": "1742377425102", "checksum": -1000376348, "seqId": 49713709124, "prevSeqId": 49713709105}], "record_time": 1742377425.969461}
{"arg": {"channel": "books", "instId": "BTC-USDT"}, "action": "update", "data": [{"asks": [["83475.7", "0.24162233", "0", "2"], ["83476.8", "0.0002", "0", "2"], ["83483.3", "0.00060612", "0", "1"], ["83493.3", "0", "0", "0"], ["83630.7", "0.0000484", "0", "1"]], "bids": [["83468.9", "0.16086998", "0", "1"], ["83467", "0", "0", "0"], ["83462.1", "0.005", "0", "1"], ["83422.5", "0", "0", "0"], ["83421.8", "0.23962233", "0", "1"], ["83331.2", "0.00005685", "0", "1"]], "ts": "1742377425202", "checksum": 1113139236, "seqId": 49713709144, "prevSeqId": 49713709124}], "record_time": 1742377426.069551}
{"arg": {"channel": "books", "instId": "BTC-USDT"}, "action": "update", "data": [{"asks": [["83476.8", "0", "0", "0"], ["83477", "0.0001", "0", "1"], ["83477.1", "0.0001", "0", "1"], ["83630.7", "0", "0", "0"]], "bids": [["83433.6", "2.60073719", "0", "3"]], "ts": "1742377425302", "checksum": 2019094150, "seqId": 49713709156, "prevSeqId": 49713709144}], "record_time": 1742377426.1697}
{"arg": {"channel": "books", "instId": "BTC-USDT"}, "action": "update", "data": [{"asks": [["83475.2", "0.23962376", "0", "1"], ["83475.7", "0.002", "0", "1"], ["83476.2", "0.005", "0", "1"], ["83486.2", "0.005", "0", "1"], ["83630.2", "0", "0", "0"], ["83630.5", "0", "0", "0"], ["83630.6", "0", "0", "0"]], "bids": [["83469", "0.24", "0", "1"], ["83467.9", "0.005", "0", "1"], ["83457.9", "0.005", "0", "1"], ["83436", "1", "0", "1"], ["83435.7", "0.01219896", "0", "1"], ["83421.8", "0", "0", "0"], ["83420.5", "0.23962376", "0", "1"], ["83419.6", "0", "0", "0"], ["83332.7", "0", "0", "0"], ["83332.6", "0", "0", "0"], ["83332.3", "0", "0", "0"], ["83331.2", "0", "0", "0"]], "ts": "1742377425402", "checksum": -1255867780, "seqId": 49713709174, "prevSeqId": 49713709156}], "record_time": 1742377426.269347}
{"arg": {"channel": "books", "instId": "BTC-USDT"}, "action": "update", "data": [{"asks": [["83476.8", "0.0002", "0", "2"], ["83477", "0", "0", "0"], ["83477.1", "0", "0", "0"], ["83630.2", "0.00428793", "0", "3"]], "bids": [["83469.7", "0.82727882", "0", "11"], ["83436.1", "0.01219896", "0", "1"], ["83435.7", "0", "0", "0"]], "ts": "1742377425602", "checksum": -489948121, "seqId": 49713709184, "prevSeqId": 49713709174}], "record_time": 1742377426.469133}
{"arg": {"channel": "books", "instId": "BTC-USDT"}, "action": "update", "data": [{"asks": [["83475.2", "0", "0", "0"], ["83475.7", "0.24162228", "0", "2"], ["83476.8", "0", "0", "0"], ["83477", "0.0002", "0", "2"], ["83511.1", "1.23693198", "0", "3"], ["83600.2", "0", "0", "0"], ["83630.5", "0.00003988", "0", "1"], ["83630.6", "0.00011142", "0", "1"]], "bids": [["83469", "0", "0", "0"], ["83435.6", "1.08075302", "0", "3"], ["83424", "0.2", "0", "1"], ["83420.5", "0.23962228", "0", "1"], ["83332.8", "0", "0", "0"], ["83332.7", "0.01536105", "0", "2"]], "ts": "1742377425802", "checksum": -501338316, "seqId": 49713709214, "prevSeqId": 49713709184}], "record_time": 1742377426.669312}
{"arg": {"channel": "books", "instId": "BTC-USDT"}, "action": "update", "data": [{"asks": [["83473", "0.23962583", "0", "1"], ["83475.7", "0.002", "0", "1"], ["83476.8", "0.0002", "0", "2"], ["83477", "0", "0", "0"], ["83493", "0.1", "0", "1"], ["83498", "1.0055", "0", "2"], ["83630.5", "0", "0", "0"], ["83630.6", "0", "0", "0"]], "bids": [["83424", "0", "0", "0"], ["83420.5", "0.23962516", "0", "1"], ["83332.8", "0.2025", "0", "1"]], "ts": "1742377425902", "checksum": -249375512, "seqId": 49713709248, "prevSeqId": 49713709214}], "record_time": 1742377426.774187}
{"arg": {"channel": "books", "instId": "BTC-USDT"}, "action": "update", "data": [{"asks": [["83469.8", "0.66897095", "0", "8"], ["83473", "0", "0", "0"], ["83475.2", "0.23962476", "0", "1"]], "bids": [["83469.5", "0.0001", "0", "1"], ["83469.3", "0.0001", "0", "1"], ["83332.7", "0", "0", "0"]], "ts": "1742377426002", "checksum": -1367640471, "seqId": 49713709266, "prevSeqId": 49713709248}], "record_time": 1742377426.869689}
{"arg": {"channel": "books", "instId": "BTC-USDT"}, "action": "update", "data": [{"asks": [["83527.4", "0", "0", "0"], ["83527.9", "0.00378623", "0", "1"]], "bids": [["83469.5", "0", "0", "0"], ["83469.3", "0.0002", "0", "2"], ["83406.5", "0.01845081", "0", "1"], ["83405.1", "0", "0", "0"], ["83332.7", "0.01536105", "0", "2"]], "ts": "1742377426102", "checksum": 184247380, "seqId": 49713709281, "prevSeqId": 49713709266}], "record_time": 1742377426.969707}
{"arg": {"channel": "books", "instId": "BTC-USDT"}, "action": "update", "data": [{"asks": [["83475.2", "0", "0", "0"], ["83475.9", "0.23962184", "0", "1"]], "bids": [["83469.5", "0.0002", "0", "2"], ["83469.3", "0", "0", "0"], ["83421.8", "0.23962227", "0", "1"], ["83420.5", "0", "0", "0"]], "ts": "1742377426302", "checksum": -1989650756, "seqId": 49713709300, "prevSeqId": 49713709281}], "record_time": 1742377427.169184}
{"arg": {"channel": "books", "instId": "BTC-USDT"}, "action": "update", "data": [{"asks": [["83469.8", "0.70491295", "0", "9"], ["83474", "0.59377252", "0", "4"], ["83475.7", "0.24162259", "0", "2"], ["83475.9", "0", "0", "0"], ["83476.8", "0.0001", "0", "1"], ["83476.9", "0.35953", "0", "2"], ["83493", "0", "0", "0"], ["83498", "0.0055", "0", "1"], ["83630.5", "0.00003988", "0", "1"], ["83630.6", "0.00011142", "0", "1"]], "bids": [["83469.1", "0.26436998", "0", "1"], ["83469", "0.34", "0", "1"], ["83468.9", "0", "0", "0"], ["83421.8", "0", "0", "0"], ["83420.5", "0.23962259", "0", "1"], ["83332.7", "0", "0", "0"]], "ts": "1742377426402", "checksum": 452176476, "seqId": 49713709329, "prevSeqId": 49713709300}], "record_time": 1742377427.270562}
{"arg": {"channel": "books", "instId": "BTC-USDT"}, "action": "update", "data": [{"asks": [["83476.8", "0.0002", "0", "2"], ["83476.9", "0.35943", "0", "1"]], "bids": [["83469.1", "0.16236998", "0", "1"], ["83469", "0", "0", "0"], ["83332.7", "0.01536105", "0", "2"]], "ts": "1742377426502", "checksum": -169345562, "seqId": 49713709346, "prevSeqId": 49713709329}], "record_time": 1742377427.375563}
{"arg": {"channel": "books", "instId": "BTC-USDT"}, "action": "update", "data": [{"asks": [["83475.2", "0.23962312", "0", "1"], ["83475.7", "0.002", "0", "1"], ["83630.6", "0", "0", "0"]], "bids": [["83469.7", "0.82198882", "0", "10"]], "ts": "1742377426602", "checksum": 232057456, "seqId": 49713709359, "prevSeqId": 49713709346}], "record_time": 1742377427.469378}
{"arg": {"channel": "books", "instId": "BTC-USDT"}, "action": "update", "data": [{"asks": [["83539.6", "0.07182223", "0", "1"]], "bids": [["83375.9", "0.07196323", "0", "1"]], "ts": "1742377426802", "checksum": 232057456, "seqId": 49713709369, "prevSeqId": 49713709359}], "record_time": 1742377427.669433}
{"arg": {"channel": "books", "instId": "BTC-USDT"}, "action": "update", "data": [{"asks": [["83469.8", "0.70251688", "0", "8"], ["83476.8", "0.0001", "0", "1"], ["83477", "0.0001", "0", "1"], ["83513.9", "0.07592308", "0", "1"], ["83539.6", "0", "0", "0"], ["83630.5", "0", "0", "0"]], "bids": [["83463.8", "0.01566", "0", "1"], ["83457.6", "0.047", "0", "1"], ["83452.7", "0.00001204", "0", "1"], ["83446.7", "0", "0", "0"], ["83444.1", "0", "0", "0"], ["83440.9", "0.22368356", "0", "2"], ["83429", "0.19999999", "0", "1"], ["83415.3", "0.18452642", "0", "1"], ["83413.2", "0.00589947", "0", "1"], ["83375.9", "0", "0", "0"], ["83332.7", "0", "0", "0"]], "ts": "1742377426902", "checksum": -12015935, "seqId": 49713709399, "prevSeqId": 49713709369}], "record_time": 1742377427.769401}
{"arg": {"channel": "books", "instId": "BTC-USDT"}, "action": "update", "data": [{"asks": [["83475.2", "0.23962518", "0", "1"], ["83476.8", "0.0002", "0", "2"], ["83477", "0", "0", "0"], ["83531.7", "0.55513117", "0", "1"], ["83630.5", "0.00003988", "0", "1"]], "bids": [["83444.8", "0", "0", "0"], ["83375.4", "0", "0", "0"], ["83332.7", "0.01536105", "0", "2"], ["83332.6", "0.00001302", "0", "1"]], "ts": "1742377427002", "checksum": -1782963101, "seqId": 49713709416, "prevSeqId": 49713709399}], "record_time": 1742377427.869217}
{"arg": {"channel": "books", "instId": "BTC-USDT"}, "action": "update", "data": [{"asks": [["83469.8", "0.76482684", "0", "10"], ["83484.2", "0", "0", "0"], ["83494.2", "0", "0", "0"], ["83539.6", "0.14364446", "0", "2"], ["83630.6", "0.00011142", "0", "1"]], "bids": [["83469.7", "0.82640882", "0", "11"], ["83463.8", "0", "0", "0"], ["83462.1", "0", "0", "0"], ["83457.6", "0", "0", "0"], ["83453.9", "0.38005118", "0", "4"], ["83447.7", "0.047", "0", "1"], ["83446.7", "0.00239673", "0", "1"], ["83375.9", "0.14392646", "0", "2"]], "ts": "1742377427102", "checksum": -1005781606, "seqId": 49713709446, "prevSeqId": 49713709416}], "record_time": 1742377427.969333}
{"arg": {"channel": "books", "instId": "BTC-USDT"}, "action": "update", "data": [{"asks": [["83475.2", "0.2396243", "0", "1"], ["83476.3", "0.005", "0", "1"], ["83486.3", "0.005", "0", "1"], ["83499.7", "0", "0", "0"], ["83528", "0.06670648", "0", "3"], ["83630.6", "0", "0", "0"]], "bids": [["83457.9", "0.01", "0", "2"], ["83441.3", "0.00372901", "0", "1"], ["83429", "0", "0", "0"], ["83420.5", "0.2396243", "0", "1"], ["83372.1", "0.0143933", "0", "1"], ["83332.6", "0", "0", "0"]], "ts": "1742377427202", "checksum": 1259638332, "seqId": 49713709488, "prevSeqId": 49713709446}], "record_time": 1742377428.072255}
{"arg": {"channel": "books", "instId": "BTC-USDT"}, "action": "update", "data": [{"asks": [["83475.2", "0", "0", "0"], ["83475.7", "0.24162297", "0", "2"], ["83572.7", "0.23458516", "0", "1"], ["83581", "0", "0", "0"], ["83589.4", "0", "0", "0"], ["83597.7", "0", "0", "0"], ["83606.1", "0", "0", "0"], ["83630.6", "0.00011142", "0", "1"], ["83630.7", "0.0000484", "0", "1"], ["83630.8", "0.00110397", "0", "1"], ["83630.9", "0.11992025", "0", "1"], ["83631.1", "0.00001167", "0", "1"]], "bids": [["83468", "0.0617", "0", "2"], ["83373", "0.00201959", "0", "1"], ["83363.9", "0", "0", "0"], ["83350.7", "0", "0", "0"], ["83341.1", "0", "0", "0"], ["83332.7", "0.00042773", "0", "1"], ["83332.6", "0.00001302", "0", "1"], ["83332.3", "0.00001364", "0", "1"], ["83331.2", "0.00005685", "0", "1"]], "ts": "1742377427302", "checksum": -55727225, "seqId": 49713709511, "prevSeqId": 49713709488}], "record_time": 1742377428.169625}
{"arg": {"channel": "books", "instId": "BTC-USDT"}, "action": "update", "data": [{"asks": [["83499", "1.2", "0", "2"], ["83631.1", "0", "0", "0"]], "bids": [], "ts": "1742377427402", "checksum": -55727225, "seqId": 49713709519, "prevSeqId": 49713709511}], "record_time": 1742377428.270102}
{"arg": {"channel": "books", "instId": "BTC-USDT"}, "action": "update", "data": [{"asks": [["83499", "0.5", "0", "1"]], "bids": [["83419.4", "0", "0", "0"], ["83418.1", "0.495975", "0", "1"], ["83406.3", "0", "0", "0"], ["83405.5", "0.01197473", "0", "1"]], "ts": "1742377427502", "checksum": -55727225, "seqId": 49713709534, "prevSeqId": 49713709519}], "record_time": 1742377428.369877}
{"arg": {"channel": "books", "instId": "BTC-USDT"}, "action": "update", "data": [{"asks": [["83539.6", "0.07182223", "0", "1"]], "bids": [["83469.7", "0.82641882", "0", "12"], ["83375.9", "0.07196323", "0", "1"]], "ts": "1742377427602", "checksum": -738712465, "seqId": 49713709545, "prevSeqId": 49713709534}], "record_time": 1742377428.475836}
{"arg": {"channel": "books", "instId": "BTC-USDT"}, "action": "update", "data": [{"asks": [["83469.8", "0.76243077", "0", "9"], ["83539.6", "0", "0", "0"], ["83631.1", "0.00001167", "0", "1"]], "bids": [["83446.7", "0", "0", "0"], ["83375.9", "0", "0", "0"], ["83331", "0.00001097", "0", "1"], ["83330.8", "0.035909", "0", "1"]], "ts": "1742377427702", "checksum": -1643316243, "seqId": 49713709555, "prevSeqId": 49713709545}], "record_time": 1742377428.569667}
{"arg": {"channel": "books", "instId": "BTC-USDT"}, "action": "update", "data": [{"asks": [["83469.8", "0.72888484", "0", "9"], ["83473.1", "0.14927272", "0", "2"], ["83473.9", "0.23962477", "0", "1"], ["83474", "0.09377252", "0", "3"], ["83475.7", "0.002", "0", "1"], ["83476.8", "0", "0", "0"], ["83477.3", "0.0002", "0", "2"], ["83479.3", "0.27097556", "0", "1"], ["83482", "0.0567", "0", "1"], ["83511.1", "0.41257565", "0", "2"], ["83511.2", "0.03999999", "0", "1"], ["83539.6", "0.07182223", "0", "1"], ["83544.7", "0.51419506", "0", "1"], ["83571.1", "0.04643753", "0", "3"], ["83594.3", "0.15546432", "0", "1"], ["83630.7", "0", "0", "0"], ["83630.8", "0", "0", "0"], ["83630.9", "0", "0", "0"], ["83631.1", "0", "0", "0"]], "bids": [["83469.6", "0.0002", "0", "2"], ["83469.5", "0", "0", "0"], ["83446.7", "0.00239673", "0", "1"], ["83435.6", "0.41236927", "0", "2"], ["83433.6", "0.9925", "0", "2"], ["83406.4", "0", "0", "0"], ["83404.5", "0", "0", "0"], ["83404.4", "0", "0", "0"], ["83403.8", "0.00198617", "0", "1"], ["83375.9", "0.07196323", "0", "1"]], "ts": "1742377427802", "checksum": -1105642402, "seqId": 49713709604, "prevSeqId": 49713709555}], "record_time": 1742377428.669755}
{"arg": {"channel": "books", "instId": "BTC-USDT"}, "action": "update", "data": [{"asks": [["83479.3", "0.81753549", "0", "2"], ["83482", "1.63686389", "0", "2"], ["83496.4", "0", "0", "0"], ["83511.1", "1.23845167", "0", "3"], ["83511.2", "2.91493834", "0", "2"], ["83531.6", "0.01219896", "0", "1"], ["83534.8", "0", "0", "0"], ["83572.7", "0", "0", "0"], ["83594.3", "0", "0", "0"], ["83630.7", "0.0000484", "0", "1"], ["83630.8", "0.00110397", "0", "1"], ["83630.9", "0.11992025", "0", "1"]], "bids": [["83469.6", "0", "0", "0"], ["83469.5", "0.0002", "0", "2"], ["83436.1", "0", "0", "0"], ["83435.6", "1.08076882", "0", "3"], ["83433.6", "2.60078985", "0", "3"], ["83406.6", "0.01280741", "0", "1"], ["83404.4", "2.83717286", "0", "1"], ["83402.8", "0.01219896", "0", "1"], ["83331", "0", "0", "0"], ["83330.8", "0", "0", "0"]], "ts": "1742377427902", "checksum": -792315214, "seqId": 49713709634, "prevSeqId": 49713709604}], "record_time": 1742377428.769711}
{"arg": {"channel": "books", "instId": "BTC-USDT"}, "action": "update", "data": [{"asks": [["83469.8", "0.76482684", "0", "10"], ["83476.8", "0.0002", "0", "2"], ["83477.3", "0", "0", "0"], ["83539.6", "0.14364446", "0", "2"], ["83571.9", "0.00298666", "0", "1"], ["83580.2", "0.00597332", "0", "1"], ["83588.6", "0.0149578", "0", "3"], ["83596.9", "0.01194665", "0", "1"], ["83605.3", "0.01493332", "0", "1"], ["83630.6", "0", "0", "0"], ["83630.7", "0", "0", "0"], ["83630.8", "0", "0", "0"], ["83630.9", "0", "0", "0"]], "bids": [["83375.9", "0.14392646", "0", "2"], ["83367.1", "0.00298666", "0", "1"], ["83357.6", "0.00597332", "0", "1"], ["83344.3", "0.00895999", "0", "1"], ["83334.7", "0.04194665", "0", "2"], ["83332.6", "0", "0", "0"], ["83332.3", "0", "0", "0"], ["83331.2", "0", "0", "0"]], "ts": "1742377428002", "checksum": 997676248, "seqId": 49713709664, "prevSeqId": 49713709634}], "record_time": 1742377428.870595}
{"arg": {"channel": "books", "instId": "BTC-USDT"}, "action": "update", "data": [{"asks": [["83469.8", "0.76241684", "0", "10"], ["83496.4", "0.01219896", "0", "1"], ["83527.3", "0", "0", "0"], ["83527.5", "0.00013267", "0", "1"], ["83531.6", "0", "0", "0"]], "bids": [["83436.1", "0.01219896", "0", "1"], ["83406.7", "0.01845078", "0", "1"], ["83406.5", "0", "0", "0"], ["83404.5", "0.00198615", "0", "1"], ["83403.8", "0", "0", "0"], ["83402.8", "0", "0", "0"]], "ts": "1742377428102", "checksum": -903839498, "seqId": 49713709682, "prevSeqId": 49713709664}], "record_time": 1742377428.969222}
{"arg": {"channel": "books", "instId": "BTC-USDT"}, "action": "update", "data": [{"asks": [["83472.9", "0.16032797", "0", "1"], ["83473", "0.23962545", "0", "1"], ["83473.1", "0", "0", "0"], ["83473.9", "0", "0", "0"], ["83475.7", "0", "0", "0"], ["83485.8", "0.05909124", "0", "1"], ["83539.6", "0.07182223", "0", "1"], ["83630.6", "0.00011142", "0", "1"]], "bids": [["83462", "0.0567", "0", "1"], ["83429", "0.19999999", "0", "1"], ["83375.9", "0.07196323", "0", "1"], ["83332.7", "0", "0", "0"]], "ts": "1742377428202", "checksum": -303755894, "seqId": 49713709704, "prevSeqId": 49713709682}], "record_time": 1742377429.070115}
{"arg": {"channel": "books", "instId": "BTC-USDT"}, "action": "update", "data": [{"asks": [["83469.8", "0.76002077", "0", "9"], ["83473", "0", "0", "0"], ["83473.9", "0.23962513", "0", "1"], ["83539.6", "0", "0", "0"], ["83630.7", "0.0000484", "0", "1"]], "bids": [["83446.7", "0", "0", "0"], ["83375.9", "0", "0", "0"], ["83332.7", "0.00042773", "0", "1"], ["83332.6", "0.00001302", "0", "1"]], "ts": "1742377428302", "checksum": -1004387981, "seqId": 49713709730, "prevSeqId": 49713709704}], "record_time": 1742377429.169661}
{"arg": {"channel": "books", "instId": "BTC-USDT"}, "action": "update", "data": [{"asks": [["83469.8", "0.76241684", "0", "10"], ["83472.7", "0.21444033", "0", "1"], ["83472.8", "0.42", "0", "1"], ["83472.9", "0", "0", "0"], ["83473.9", "0", "0", "0"], ["83475.2", "0.23962441", "0", "1"], ["83527.9", "0", "0", "0"], ["83528", "0.05205602", "0", "2"], ["83528.6", "0.00378745", "0", "1"], ["83539.6", "0.14364446", "0", "2"], ["83544.7", "0", "0", "0"], ["83630.7", "0", "0", "0"]], "bids": [["83446.7", "0.00239673", "0", "1"], ["83441.3", "0", "0", "0"], ["83375.9", "0.14392646", "0", "2"], ["83372.1", "0", "0", "0"], ["83336.4", "0.18450665", "0", "1"], ["83334.8", "0", "0", "0"]], "ts": "1742377428402", "checksum": 2046928802, "seqId": 49713709784, "prevSeqId": 49713709730}], "record_time": 1742377429.269407}
{"arg": {"channel": "books", "instId": "BTC-USDT"}, "action": "update", "data": [{"asks": [["83476.2", "0.007", "0", "2"], ["83486.2", "0.007", "0", "2"], ["83495", "0.1", "0", "1"], ["83498", "1.0055", "0", "2"], ["83530.2", "0.01465009", "0", "1"], ["83630.5", "0", "0", "0"], ["83630.6", "0", "0", "0"]], "bids": [["83467.9", "0.007", "0", "2"], ["83457.8", "0.002", "0", "1"], ["83439", "0.06356894", "0", "2"], ["83429", "0", "0", "0"], ["83369.8", "0.0143937", "0", "1"], ["83332.6", "0", "0", "0"]], "ts": "1742377428502", "checksum": 1386923699, "seqId": 49713709810, "prevSeqId": 49713709784}], "record_time": 1742377429.371852}
{"arg": {"channel": "books", "instId": "BTC-USDT"}, "action": "update", "data": [{"asks": [["83469.8", "0.72647484", "0", "9"], ["83481.8", "0.17953568", "0", "1"], ["83501", "0.00761303", "0", "1"], ["83527.9", "0.0037876", "0", "1"], ["83528.6", "0", "0", "0"], ["83630.2", "0", "0", "0"]], "bids": [["83336.4", "0", "0", "0"], ["83334.8", "0.18450712", "0", "1"]], "ts": "1742377428602", "checksum": -1595401868, "seqId": 49713709824, "prevSeqId": 49713709810}], "record_time": 1742377429.470588}
{"arg": {"channel": "books", "instId": "BTC-USDT"}, "action": "update", "data": [{"asks": [["83472.7", "0.08844033", "0", "1"], ["83472.8", "0", "0", "0"], ["83476.8", "0", "0", "0"], ["83476.9", "0.35963", "0", "3"], ["83495", "0", "0", "0"], ["83498", "0.0055", "0", "1"], ["83630.2", "0.00428793", "0", "3"], ["83630.5", "0.00003988", "0", "1"], ["83630.6", "0.00011142", "0", "1"]], "bids": [], "ts": "1742377428702", "checksum": 784510375, "seqId": 49713709838, "prevSeqId": 49713709824}], "record_time": 1742377429.570177}
{"arg": {"channel": "books", "instId": "BTC-USDT"}, "action": "update", "data": [{"asks": [["83469.8", "0.61561233", "0", "6"], ["83470", "0", "0", "0"], ["83473", "0.00239598", "0", "1"], ["83475.2", "0.23961984", "0", "1"], ["83475.6", "0", "0", "0"], ["83476.3", "0.0051", "0", "2"], ["83476.6", "0.0001", "0", "1"], ["83476.9", "0.35943", "0", "1"], ["83478.2", "0.00916", "0", "1"], ["83481.6", "0", "0", "0"], ["83481.9", "0.6621995", "0", "3"], ["83499.3", "0.00761304", "0", "1"], ["83501", "0", "0", "0"], ["83513.5", "0.002157", "0", "1"], ["83630.6", "0", "0", "0"]], "bids": [["83469.7", "1.0311036", "0", "16"], ["83469.3", "0.11980201", "0", "1"], ["83466.7", "0", "0", "0"], ["83446.7", "0", "0", "0"], ["83422.5", "0.23961608", "0", "1"], ["83420.5", "0", "0", "0"], ["83332.6", "0.00001302", "0", "1"]], "ts": "1742377428802", "checksum": 575382288, "seqId": 49713709892, "prevSeqId": 49713709838}], "record_time": 1742377429.671891}
{"arg": {"channel": "books", "instId": "BTC-USDT"}, "action": "update", "data": [{"asks": [["83469.8", "0.20310987", "0", "4"], ["83475.2", "0", "0", "0"], ["83476.3", "0.005", "0", "1"], ["83476.6", "0", "0", "0"], ["83477.2", "0.0001", "0", "1"], ["83477.7", "0.0001", "0", "1"], ["83478.2", "0", "0", "0"], ["83478.9", "0.2396148", "0", "1"], ["83482.6", "0", "0", "0"], ["83483", "0.0929294", "0", "1"], ["83483.5", "0.16224935", "0", "1"], ["83483.7", "0", "0", "0"], ["83483.9", "0.09702373", "0", "1"], ["83484", "0.0567", "0", "1"], ["83484.1", "0.09469174", "0", "1"], ["83484.2", "0.09721258", "0", "1"], ["83488", "0.08418", "0", "2"], ["83490.2", "0.5260412", "0", "3"], ["83490.5", "0", "0", "0"], ["83490.7", "0.00884137", "0", "1"], ["83490.9", "0.35932216", "0", "3"], ["83491.1", "0.16447645", "0", "1"], ["83491.3", "0", "0", "0"], ["83491.7", "0.24852457", "0", "2"], ["83492.3", "0", "0", "0"], ["83492.4", "0", "0", "0"], ["83492.6", "0.16472595", "0", "1"], ["83497.3", "0", "0", "0"], ["83497.5", "0.26259367", "0", "1"], ["83498.1", "0.25538891", "0", "1"], ["83499.4", "0", "0", "0"], ["83499.8", "0.61063887", "0", "2"], ["83501.2", "0", "0", "0"], ["83501.4", "0.2649252", "0", "1"], ["83534.8", "0.0726201", "0", "1"], ["83572.7", "0.22979129", "0", "1"], ["83630.5", "0", "0", "0"]], "bids": [["83468.6", "0.0314628", "0", "1"], ["83465.3", "0", "0", "0"], ["83458.8", "0.01566", "0", "1"], ["83458.1", "0.27409849", "0", "2"], ["83457.1", "0.09436813", "0", "1"], ["83456.8", "0.11174092", "0", "2"], ["83456.7", "0", "0", "0"], ["83456.2", "0", "0", "0"], ["83455.9", "0.08946583", "0", "1"], ["83455.7", "0", "0", "0"], ["83455.6", "0", "0", "0"], ["83455.5", "0.09804301", "0", "1"], ["83455.3", "0", "0", "0"], ["83454.8", "0.01198099", "0", "1"], ["83453.9", "0.36439118", "0", "3"], ["83452.6", "0.047", "0", "1"], ["83452.3", "0", "0", "0"], ["83450.9", "0.00239661", "0", "1"], ["83449.8", "0.15289664", "0", "1"], ["83449.3", "0", "0", "0"], ["83449.2", "0.17953568", "0", "1"], ["83448.9", "0.51368357", "0", "2"], ["83448.7", "0", "0", "0"], ["83448.3", "0.16513665", "0", "2"], ["83447.9", "0", "0", "0"], ["83447.7", "0", "0", "0"], ["83447.1", "0.16268042", "0", "1"], ["83446.9", "0.01198396", "0", "1"], ["83442.8", "0.26423162", "0", "1"], ["83442.2", "0.26482674", "0", "1"], ["83442", "0.2025", "0", "1"], ["83440.9", "0.05879252", "0", "1"], ["83440.3", "0.24859481", "0", "1"], ["83439.9", "0", "0", "0"], ["83438.4", "0.24855893", "0", "2"], ["83438.2", "0", "0", "0"], ["83406.6", "0.8568231", "0", "2"], ["83332.3", "0.00001364", "0", "1"]], "ts": "1742377428902", "checksum": -1992693168, "seqId": 49713709998, "prevSeqId": 49713709892}], "record_time": 1742377429.769744}
{"arg": {"channel": "books", "instId": "BTC-USDT"}, "action": "update", "data": [{"asks": [["83472.7", "0", "0", "0"], ["83474", "0.09397252", "0", "5"], ["83475.9", "0.23961613", "0", "1"], ["83477.2", "0", "0", "0"], ["83477.7", "0", "0", "0"], ["83478.9", "0", "0", "0"], ["83482.1", "0.00916", "0", "1"], ["83484.1", "0", "0", "0"], ["83484.2", "0.18539485", "0", "2"], ["83491.1", "0", "0", "0"], ["83491.2", "0.14828996", "0", "1"], ["83491.7", "0.08991011", "0", "1"], ["83491.8", "0.15571011", "0", "1"], ["83498.1", "0", "0", "0"], ["83498.2", "0.24357095", "0", "1"], ["83630.5", "0.00003988", "0", "1"], ["83630.6", "0.00011142", "0", "1"]], "bids": [["83469.7", "0.8286036", "0", "16"], ["83469.6", "0.0001", "0", "1"], ["83469.5", "0", "0", "0"], ["83469.3", "0", "0", "0"], ["83469.1", "0.16246998", "0", "2"], ["83467.2", "0.11980511", "0", "1"], ["83458.9", "0.0000105", "0", "1"], ["83456.9", "0.09172502", "0", "1"], ["83456.8", "0.01566", "0", "1"], ["83449.9", "0.16858034", "0", "2"], ["83449.8", "0", "0", "0"], ["83448.4", "0.14798857", "0", "1"], ["83448.3", "0.00719008", "0", "1"], ["83442.9", "0.25706018", "0", "1"], ["83442.8", "0", "0", "0"], ["83332.6", "0", "0", "0"], ["83332.3", "0", "0", "0"]], "ts": "1742377429002", "checksum": 277298962, "seqId": 49713710041, "prevSeqId": 49713709998}], "record_time": 1742377429.869562}
{"arg": {"channel": "books", "instId": "BTC-USDT"}, "action": "update", "data": [{"asks": [["83475.9", "0", "0", "0"], ["83477.9", "0.23961348", "0", "1"]], "bids": [["83469.7", "0.8241736", "0", "14"], ["83469.6", "0", "0", "0"], ["83469.2", "0.0001", "0", "1"]], "ts": "1742377429102", "checksum": -1204529774, "seqId": 49713710063, "prevSeqId": 49713710041}], "record_time": 1742377429.969508}
{"arg": {"channel": "books", "instId": "BTC-USDT"}, "action": "update", "data": [{"asks": [["83470", "0.0567", "0", "1"], ["83473.9", "0.0002", "0", "2"], ["83474", "0.09377252", "0", "3"], ["83479.4", "0.359425", "0", "2"], ["83482.7", "0.10023795", "0", "1"], ["83483", "0", "0", "0"], ["83483.7", "0.10077765", "0", "1"], ["83483.9", "0.09211106", "0", "1"], ["83484.1", "0.09470768", "0", "1"], ["83484.2", "0", "0", "0"], ["83490.2", "0.52563694", "0", "3"], ["83490.7", "0.17582369", "0", "2"], ["83490.9", "0.35945649", "0", "3"], ["83491.2", "0", "0", "0"], ["83491.5", "0.15462671", "0", "1"], ["83491.8", "0", "0", "0"], ["83492.4", "0.16733268", "0", "1"], ["83492.6", "0", "0", "0"], ["83497.4", "0.38626092", "0", "3"], ["83497.5", "0", "0", "0"], ["83497.9", "0.2617081", "0", "1"], ["83498.2", "0", "0", "0"], ["83499.5", "0.235922", "0", "1"], ["83499.8", "0.35972754", "0", "1"], ["83501.2", "0.24585689", "0", "1"], ["83501.4", "0", "0", "0"], ["83600.2", "0.08844033", "0", "1"], ["83630.2", "0", "0", "0"], ["83630.5", "0", "0", "0"], ["83630.6", "0", "0", "0"]], "bids": [["83469.7", "0.7241736", "0", "13"], ["83469.2", "0", "0", "0"], ["83469.1", "0.16236998", "0", "1"], ["83468.8", "0.0002", "0", "2"], ["83458.1", "0.27466028", "0", "2"], ["83457.1", "0", "0", "0"], ["83456.9", "0", "0", "0"], ["83456.8", "0.11186588", "0", "2"], ["83456.6", "0.09291636", "0", "1"], ["83455.9", "0", "0", "0"], ["83455.7", "0.09415048", "0", "1"], ["83455.5", "0", "0", "0"], ["83455.4", "0.09661782", "0", "1"], ["83449.9", "0.00060612", "0", "1"], ["83449.6", "0.16469928", "0", "2"], ["83448.9", "0.35972754", "0", "1"], ["83448.7", "0.14626344", "0", "1"], ["83448.4", "0", "0", "0"], ["83448.1", "0.15145638", "0", "1"], ["83447.1", "0", "0", "0"], ["83446.9", "0.16908166", "0", "2"], ["83442.9", "0", "0", "0"], ["83442.6", "0.23877029", "0", "1"], ["83442.2", "0", "0", "0"], ["83442.1", "0.2612122", "0", "1"], ["83440.3", "0", "0", "0"], ["83440", "0.26733816", "0", "3"], ["83438.4", "0.00001629", "0", "1"], ["83438.2", "0.26036603", "0", "1"], ["83332.6", "0.00001302", "0", "1"]], "ts": "1742377429202", "checksum": 20958632, "seqId": 49713710137, "prevSeqId": 49713710063}], "record_time": 1742377430.069998}
{"arg": {"channel": "books", "instId": "BTC-USDT"}, "action": "update", "data": [{"asks": [], "bids": [["83469.7", "1.11100711", "0", "17"], ["83469.1", "0.16256998", "0", "3"], ["83468.8", "0", "0", "0"], ["83332.3", "0.00001364", "0", "1"]], "ts": "1742377429302", "checksum": 427474188, "seqId": 49713710251, "prevSeqId": 49713710137}], "record_time": 1742377430.171489}
{"arg": {"channel": "books", "instId": "BTC-USDT"}, "action": "update", "data": [{"asks": [["83469.8", "0.18779475", "0", "3"], ["83471.5", "0.0001", "0", "1"], ["83471.7", "0.0001", "0", "1"], ["83473.9", "0", "0", "0"], ["83477.9", "0", "0", "0"], ["83478.8", "0.23961137", "0", "1"], ["83482.7", "0", "0", "0"], ["83482.8", "0.09866334", "0", "1"], ["83483.9", "0", "0", "0"], ["83484", "0.15268872", "0", "2"], ["83490.9", "0.20315596", "0", "2"], ["83491", "0.26665426", "0", "2"], ["83492.4", "0", "0", "0"], ["83492.5", "0.15766187", "0", "1"], ["83497.9", "0", "0", "0"], ["83498", "0.24741926", "0", "2"], ["83499.5", "0", "0", "0"], ["83499.6", "0.2684794", "0", "1"], ["83527.9", "0", "0", "0"], ["83530.1", "0.00378775", "0", "1"], ["83630.2", "0.00428793", "0", "3"]], "bids": [["83469.7", "1.32773325", "0", "17"], ["83469.3", "0.29990864", "0", "1"], ["83469.2", "0.42", "0", "1"], ["83469.1", "0", "0", "0"], ["83466.3", "0.0002", "0", "2"], ["83456.9", "0.10021594", "0", "1"], ["83456.8", "0.01566", "0", "1"], ["83456.7", "0.09261003", "0", "1"], ["83456.6", "0", "0", "0"], ["83449.7", "0.15558291", "0", "1"], ["83449.6", "0.01", "0", "1"], ["83447", "0.1606417", "0", "1"], ["83446.9", "0.01198396", "0", "1"], ["83442.7", "0.24903531", "0", "1"], ["83442.6", "0", "0", "0"], ["83440.1", "0.25940246", "0", "2"], ["83440", "0.00309005", "0", "2"], ["83425.7", "0.23961137", "0", "1"], ["83425.1", "0.0056", "0", "1"], ["83423", "0", "0", "0"], ["83422.5", "0", "0", "0"], ["83418.8", "0.581523", "0", "1"], ["83414.6", "0.00011142", "0", "1"], ["83408.5", "0.01845008", "0", "1"], ["83408.4", "0.20811205", "0", "3"], ["83406.7", "0", "0", "0"], ["83399.3", "0.11892466", "0", "1"], ["83366.6", "0.05430448", "0", "9"], ["83365.9", "0", "0", "0"], ["83337.4", "0.18450083", "0", "1"], ["83334.8", "0", "0", "0"], ["83332.8", "0", "0", "0"], ["83332.7", "0", "0", "0"], ["83332.6", "0", "0", "0"], ["83332.3", "0", "0", "0"]], "ts": "1742377429402", "checksum": 278598532, "seqId": 49713710385, "prevSeqId": 49713710251}], "record_time": 1742377430.269711}
{"arg": {"channel": "books", "instId": "BTC-USDT"}, "action": "update", "data": [{"asks": [["83471.2", "0.0002", "0", "2"], ["83471.5", "0", "0", "0"], ["83471.7", "0", "0", "0"], ["83478.8", "0", "0", "0"], ["83478.9", "0.23961238", "0", "1"], ["83630.5", "0.00003988", "0", "1"]], "bids": [["83425.7", "0", "0", "0"], ["83422.5", "0.23961363", "0", "1"]], "ts": "1742377429502", "checksum": -189750271, "seqId": 49713710404, "prevSeqId": 49713710385}], "record_time": 1742377430.369786}
{"arg": {"channel": "books", "instId": "BTC-USDT"}, "action": "update", "data": [{"asks": [["83471.2", "0.0001", "0", "1"], ["83471.3", "0.0001", "0", "1"], ["83475.8", "0", "0", "0"], ["83478.9", "0.23961078", "0", "1"], ["83479.3", "0.84899829", "0", "3"]], "bids": [["83469.7", "1.33215325", "0", "18"], ["83425.9", "0.23960962", "0", "1"], ["83422.5", "0", "0", "0"]], "ts": "1742377429602", "checksum": -206455589, "seqId": 49713710440, "prevSeqId": 49713710404}], "record_time": 1742377430.470146}
{"arg": {"channel": "books", "instId": "BTC-USDT"}, "action": "update", "data": [{"asks": [["83470", "0", "0", "0"], ["83471.2", "0", "0", "0"], ["83471.3", "0", "0", "0"], ["83471.4", "0.0001", "0", "1"], ["83471.5", "0.0001", "0", "1"], ["83482.8", "0", "0", "0"], ["83483.1", "0.10060224", "0", "1"], ["83483.7", "0", "0", "0"], ["83484", "0.15452318", "0", "2"], ["83484.1", "0", "0", "0"], ["83484.3", "0.19093751", "0", "2"], ["83490.2", "0.38084741", "0", "2"], ["83490.7", "0.00884137", "0", "1"], ["83491", "0.27563473", "0", "2"], ["83491.3", "0.15259855", "0", "1"], ["83491.5", "0", "0", "0"], ["83491.9", "0.15119211", "0", "1"], ["83492.5", "0", "0", "0"], ["83492.7", "0.14982314", "0", "1"], ["83497.4", "0.15199316", "0", "2"], ["83497.6", "0.25447407", "0", "1"], ["83498", "0.0055", "0", "1"], ["83498.3", "0.24645988", "0", "1"], ["83499", "0.7", "0", "2"], ["83499.6", "0", "0", "0"], ["83499.9", "0.43339099", "0", "4"], ["83500", "1.22733089", "0", "5"], ["83501.2", "0", "0", "0"], ["83501.5", "0.23731422", "0", "1"]], "bids": [["83458.1", "0.27374694", "0", "2"], ["83457.2", "0.09116145", "0", "1"], ["83457", "0.09954537", "0", "1"], ["83456.9", "0", "0", "0"], ["83456.7", "0", "0", "0"], ["83456", "0.0985026", "0", "1"], ["83455.7", "0", "0", "0"], ["83455.6", "0.08763665", "0", "1"], ["83455.4", "0", "0", "0"], ["83450", "0.15366024", "0", "3"], ["83449.7", "0", "0", "0"], ["83449", "0.1504223", "0", "1"], ["83448.7", "0", "0", "0"], ["83448.5", "0.16608947", "0", "1"], ["83448.1", "0", "0", "0"], ["83447.2", "0.16064105", "0", "1"], ["83447", "0", "0", "0"], ["83443", "0.23713105", "0", "1"], ["83442.7", "0", "0", "0"], ["83442.3", "0.3870205", "0", "2"], ["83442.1", "0", "0", "0"], ["83440.4", "0.26237085", "0", "1"], ["83440.1", "0.00001204", "0", "1"], ["83438.5", "0.26465328", "0", "1"], ["83438.2", "0", "0", "0"], ["83332.8", "0.2025", "0", "1"]], "ts": "1742377429702", "checksum": 345748805, "seqId": 49713710513, "prevSeqId": 49713710440}], "record_time": 1742377430.570331}
{"arg": {"channel": "books", "instId": "BTC-USDT"}, "action": "update", "data": [{"asks": [["83471.2", "0.0001", "0", "1"], ["83471.4", "0", "0", "0"], ["83478.9", "0", "0", "0"], ["83481.6", "0.23960836", "0", "1"], ["83499", "0.5", "0", "1"], ["83500", "0.22733089", "0", "4"], ["83629.3", "0.00058039", "0", "1"], ["83630.5", "0", "0", "0"]], "bids": [["83457.5", "0.0119806", "0", "1"], ["83454.8", "0", "0", "0"], ["83426.6", "0.23960836", "0", "1"], ["83425.9", "0", "0", "0"]], "ts": "1742377429802", "checksum": -1596741329, "seqId": 49713710539, "prevSeqId": 49713710513}], "record_time": 1742377430.669883}
{"arg": {"channel": "books", "instId": "BTC-USDT"}, "action": "update", "data": [{"asks": [["83471.2", "0", "0", "0"], ["83471.3", "0.0002", "0", "2"], ["83471.5", "0", "0", "0"], ["83473.3", "0.08844033", "0", "1"], ["83478.9", "0.23960994", "0", "1"], ["83481.6", "0", "0", "0"], ["83491.8", "0.16743762", "0", "1"], ["83534.8", "0.2578538", "0", "2"], ["83630.2", "0", "0", "0"]], "bids": [["83469.7", "1.33151229", "0", "18"], ["83469.3", "0.17390864", "0", "1"], ["83469.2", "0", "0", "0"], ["83449.1", "0.40809406", "0", "1"], ["83426.6", "0", "0", "0"], ["83425.9", "0.23960994", "0", "1"], ["83422.5", "0.07982426", "0", "1"], ["83332.8", "0", "0", "0"]], "ts": "1742377429902", "checksum": 113793133, "seqId": 49713710569, "prevSeqId": 49713710539}], "record_time": 1742377430.771714}
{"arg": {"channel": "books", "instId": "BTC-USDT"}, "action": "update", "data": [{"asks": [], "bids": [["83469.7", "1.33152229", "0", "19"], ["83466.3", "0", "0", "0"], ["83466.2", "0.5202", "0", "3"], ["83332.8", "0.2025", "0", "1"]], "ts": "1742377430002", "checksum": 797630731, "seqId": 49713710576, "prevSeqId": 49713710569}], "record_time": 1742377430.869577}
{"arg": {"channel": "books", "instId": "BTC-USDT"}, "action": "update", "data": [{"asks": [["83498.9", "0.00761305", "0", "1"], ["83499.3", "0", "0", "0"]], "bids": [["83425.9", "0", "0", "0"], ["83425.7", "0.23961109", "0", "1"]], "ts": "1742377430102", "checksum": 797630731, "seqId": 49713710592, "prevSeqId": 49713710576}], "record_time": 1742377430.969838}
{"arg": {"channel": "books", "instId": "BTC-USDT"}, "action": "update", "data": [{"asks": [["83469.8", "0.17681541", "0", "2"], ["83477.8", "0.01097934", "0", "1"], ["83483.1", "0", "0", "0"], ["83483.2", "0.0991299", "0", "1"], ["83484.3", "0.09141271", "0", "1"], ["83484.4", "0.09816215", "0", "1"], ["83491", "0.11977102", "0", "1"], ["83491.1", "0.16106814", "0", "1"], ["83491.8", "0", "0", "0"], ["83492.7", "0", "0", "0"], ["83492.8", "0.15124122", "0", "1"], ["83497.6", "0", "0", "0"], ["83497.7", "0.26471382", "0", "1"], ["83499.9", "0.18055069", "0", "3"], ["83500", "0.48205937", "0", "5"], ["83629.5", "0", "0", "0"], ["83629.9", "0", "0", "0"]], "bids": [["83457.3", "0.4552273", "0", "2"], ["83457.2", "0", "0", "0"], ["83455.7", "0.09666765", "0", "1"], ["83455.6", "0", "0", "0"], ["83449.1", "0.56564761", "0", "2"], ["83449", "0", "0", "0"], ["83447.3", "0.1492287", "0", "1"], ["83447.2", "0", "0", "0"], ["83442.4", "0.23581718", "0", "1"], ["83442.3", "0.11984077", "0", "1"], ["83440.5", "0.24527356", "0", "1"], ["83440.4", "0", "0", "0"], ["83332.7", "0.00042773", "0", "1"]], "ts": "1742377430202", "checksum": -1047513319, "seqId": 49713710620, "prevSeqId": 49713710592}], "record_time": 1742377431.069712}
{"arg": {"channel": "books", "instId": "BTC-USDT"}, "action": "update", "data": [{"asks": [["83469.8", "0.17897241", "0", "3"], ["83491.1", "0", "0", "0"], ["83513.5", "0", "0", "0"], ["83539.6", "0.07182223", "0", "1"], ["83629.5", "0.00437872", "0", "2"], ["83629.9", "0.00002782", "0", "1"]], "bids": [["83449.1", "0.40809406", "0", "1"], ["83375.9", "0.07196323", "0", "1"]], "ts": "1742377430302", "checksum": -2114051481, "seqId": 49713710631, "prevSeqId": 49713710620}], "record_time": 1742377431.169862}
{"arg": {"channel": "books", "instId": "BTC-USDT"}, "action": "update", "data": [{"asks": [["83491", "0.28141659", "0", "2"]], "bids": [["83469.3", "0.29371075", "0", "2"], ["83467.2", "0", "0", "0"], ["83449", "0.14637178", "0", "1"]], "ts": "1742377430402", "checksum": -515318884, "seqId": 49713710637, "prevSeqId": 49713710631}], "record_time": 1742377431.269611}
{"arg": {"channel": "books", "instId": "BTC-USDT"}, "action": "update", "data": [{"asks": [["83471.2", "0.0002", "0", "2"], ["83471.3", "0", "0", "0"], ["83473.3", "0", "0", "0"], ["83478.9", "0.23961018", "0", "1"], ["83509.6", "0.08", "0", "2"], ["83510.4", "0.03999999", "0", "1"], ["83511.2", "2.87493835", "0", "1"], ["83543.8", "0.07181862", "0", "1"], ["83629.9", "0", "0", "0"]], "bids": [["83466.3", "0.0002", "0", "2"], ["83466.2", "0.52", "0", "1"], ["83425.9", "0.23961023", "0", "1"], ["83425.7", "0", "0", "0"], ["83416.8", "0.2025", "0", "1"], ["83416", "0", "0", "0"], ["83415.2", "0.0008", "0", "2"], ["83414.4", "0.08629944", "0", "4"], ["83413.6", "0.14", "0", "3"], ["83412.8", "0.05", "0", "1"], ["83412", "0.026", "0", "2"], ["83411.2", "0.073", "0", "3"], ["83380.1", "0.0719596", "0", "1"], ["83332.8", "0", "0", "0"], ["83332.7", "0", "0", "0"]], "ts": "1742377430502", "checksum": -903277947, "seqId": 49713710696, "prevSeqId": 49713710637}], "record_time": 1742377431.373021}
{"arg": {"channel": "books", "instId": "BTC-USDT"}, "action": "update", "data": [{"asks": [], "bids": [["83431", "0.2", "0", "1"], ["83425.9", "0", "0", "0"], ["83425.3", "0.25141107", "0", "3"]], "ts": "1742377430602", "checksum": -903277947, "seqId": 49713710710, "prevSeqId": 49713710696}], "record_time": 1742377431.469618}
{"arg": {"channel": "books", "instId": "BTC-USDT"}, "action": "update", "data": [{"asks": [["83471.2", "0", "0", "0"], ["83471.6", "0.0001", "0", "1"], ["83476.2", "0.0071", "0", "3"], ["83478.9", "0.23961163", "0", "1"], ["83479.3", "0.47893861", "0", "2"], ["83482", "0.0567", "0", "1"], ["83511.1", "0.41257565", "0", "2"], ["83511.2", "0", "0", "0"], ["83629.9", "0.00002782", "0", "1"]], "bids": [["83435.6", "0.41236927", "0", "2"], ["83433.6", "0.9925", "0", "2"], ["83426.6", "0.23961128", "0", "1"], ["83425.3", "0.01179894", "0", "2"], ["83406.6", "0", "0", "0"], ["83404.4", "0", "0", "0"], ["83332.8", "0.2025", "0", "1"]], "ts": "1742377430702", "checksum": -167884543, "seqId": 49713710746, "prevSeqId": 49713710710}], "record_time": 1742377431.572556}
{"arg": {"channel": "books", "instId": "BTC-USDT"}, "action": "update", "data": [{"asks": [["83471.2", "0.0002", "0", "2"], ["83471.6", "0", "0", "0"], ["83476.2", "0.007", "0", "2"], ["83483.5", "0.6894861", "0", "2"], ["83486", "1.67444007", "0", "2"], ["83496.4", "0", "0", "0"], ["83499", "0.7", "0", "2"], ["83500", "1.48205937", "0", "6"], ["83515.2", "2.89256259", "0", "2"], ["83531.6", "0.01219896", "0", "1"]], "bids": [["83436.1", "0", "0", "0"], ["83433.6", "2.60280969", "0", "3"], ["83426.6", "0", "0", "0"], ["83425.9", "0.23961131", "0", "1"], ["83404.5", "0", "0", "0"], ["83404.4", "2.9529082", "0", "1"], ["83403.8", "0.00198613", "0", "1"], ["83402.8", "0.01219896", "0", "1"], ["83332.8", "0", "0", "0"]], "ts": "1742377430802", "checksum": -654721703, "seqId": 49713710778, "prevSeqId": 49713710746}], "record_time": 1742377431.724552}
{"arg": {"channel": "books", "instId": "BTC-USDT"}, "action": "update", "data": [{"asks": [["83491.8", "0.16786304", "0", "1"], ["83499", "0.5", "0", "1"], ["83500", "0.48205937", "0", "5"], ["83534.8", "0.92612733", "0", "1"], ["83629.9", "0", "0", "0"]], "bids": [["83435.6", "1.08137477", "0", "3"], ["83404.5", "0.8877507", "0", "1"], ["83332.9", "0", "0", "0"]], "ts": "1742377430902", "checksum": -654721703, "seqId": 49713710791, "prevSeqId": 49713710778}], "record_time": 1742377431.772917}
{"arg": {"channel": "books", "instId": "BTC-USDT"}, "action": "update", "data": [{"asks": [["83496.4", "0.01219896", "0", "1"], ["83531.6", "0", "0", "0"]], "bids": [["83436.1", "0.01219896", "0", "1"], ["83431", "0", "0", "0"], ["83402.8", "0", "0", "0"], ["83332.9", "0.00002031", "0", "1"]], "ts": "1742377431002", "checksum": -654721703, "seqId": 49713710798, "prevSeqId": 49713710791}], "record_time": 1742377431.877452}
{"arg": {"channel": "books", "instId": "BTC-USDT"}, "action": "update", "data": [{"asks": [["83473", "0", "0", "0"], ["83543.8", "0", "0", "0"], ["83629.9", "0.00002782", "0", "1"], ["83630.2", "0.00428793", "0", "3"]], "bids": [["83450.9", "0", "0", "0"], ["83419.7", "0.00001322", "0", "1"], ["83415.5", "0.00001322", "0", "1"], ["83411.3", "0.00001322", "0", "1"], ["83404.6", "0.00200115", "0", "2"], ["83403.8", "0", "0", "0"], ["83380.1", "0", "0", "0"]], "ts": "1742377431102", "checksum": 1801334227, "seqId": 49713710815, "prevSeqId": 49713710798}], "record_time": 1742377431.969603}
{"arg": {"channel": "books", "instId": "BTC-USDT"}, "action": "update", "data": [{"asks": [["83473", "0.00239598", "0", "1"], ["83543.8", "0.07181862", "0", "1"], ["83594.6", "0.7", "0", "1"], ["83629.5", "0", "0", "0"], ["83629.9", "0", "0", "0"], ["83630.2", "0", "0", "0"]], "bids": [["83450.9", "0.00239661", "0", "1"], ["83380.1", "0.0719596", "0", "1"], ["83333.1", "0", "0", "0"], ["83332.9", "0", "0", "0"]], "ts": "1742377431202", "checksum": -654721703, "seqId": 49713710830, "prevSeqId": 49713710815}], "record_time": 1742377432.073443}
{"arg": {"channel": "books", "instId": "BTC-USDT"}, "action": "update", "data": [{"asks": [["83469.8", "0.19428753", "0", "4"], ["83474.7", "0", "0", "0"], ["83475.3", "0.37434848", "0", "2"], ["83475.9", "0.42", "0", "1"], ["83478.9", "0", "0", "0"], ["83481.6", "0.23961005", "0", "1"], ["83483.1", "0.08901087", "0", "1"], ["83483.2", "0", "0", "0"], ["83483.9", "0.09593216", "0", "1"], ["83484", "0.0567", "0", "1"], ["83484.2", "0.09734632", "0", "1"], ["83484.3", "0.09987912", "0", "1"], ["83484.4", "0", "0", "0"], ["83490.2", "0.48218974", "0", "3"], ["83490.9", "0.37041579", "0", "3"], ["83491", "0.11977102", "0", "1"], ["83491.2", "0.16582572", "0", "1"], ["83491.3", "0", "0", "0"], ["83491.8", "0.16679177", "0", "1"], ["83491.9", "0", "0", "0"], ["83492.7", "0.15216324", "0", "1"], ["83492.8", "0", "0", "0"], ["83497.6", "0.26257693", "0", "1"], ["83497.7", "0", "0", "0"], ["83498.2", "0.25215214", "0", "1"], ["83498.3", "0", "0", "0"], ["83499.9", "0.44777283", "0", "4"], ["83500", "0.22733089", "0", "4"], ["83501.4", "0.26252289", "0", "1"], ["83501.5", "0", "0", "0"]], "bids": [["83469.7", "1.11402229", "0", "19"], ["83466.3", "0", "0", "0"], ["83466.2", "0.5201", "0", "2"], ["83466.1", "0.0001", "0", "1"], ["83458.1", "0.27444492", "0", "2"], ["83457.3", "0.35972754", "0", "1"], ["83457.2", "0.09900767", "0", "1"], ["83457", "0", "0", "0"], ["83456.9", "0.09286925", "0", "1"], ["83456", "0", "0", "0"], ["83455.9", "0.09186141", "0", "1"], ["83455.7", "0", "0", "0"], ["83455.6", "0.09543472", "0", "1"], ["83450", "0.00013604", "0", "2"], ["83449.9", "0.14913575", "0", "2"], ["83449.1", "0", "0", "0"], ["83449", "0", "0", "0"], ["83448.9", "0.52662774", "0", "2"], ["83448.5", "0", "0", "0"], ["83448.4", "0.16518947", "0", "1"], ["83447.3", "0", "0", "0"], ["83447.2", "0.16041909", "0", "1"], ["83446.9", "0", "0", "0"], ["83443", "0", "0", "0"], ["83442.9", "0.25150804", "0", "1"], ["83442.4", "0", "0", "0"], ["83442.3", "0.3784263", "0", "2"], ["83440.5", "0", "0", "0"], ["83440.4", "0.23724446", "0", "1"], ["83438.5", "0", "0", "0"], ["83438.4", "0.2513017", "0", "2"], ["83333.1", "0.00002212", "0", "1"], ["83332.9", "0.00002031", "0", "1"], ["83332.8", "0.2025", "0", "1"], ["83332.7", "0.00042773", "0", "1"]], "ts": "1742377431302", "checksum": 1928854052, "seqId": 49713710904, "prevSeqId": 49713710830}], "record_time": 1742377432.170019}
{"arg": {"channel": "books", "instId": "BTC-USDT"}, "action": "update", "data": [{"asks": [["83469.8", "0.17897241", "0", "3"], ["83471.2", "0", "0", "0"], ["83471.5", "0.0001", "0", "1"], ["83471.8", "0.0001", "0", "1"], ["83475.3", "0.21475866", "0", "1"], ["83475.9", "0", "0", "0"], ["83479.2", "0.24877033", "0", "2"], ["83481.6", "0", "0", "0"], ["83483.1", "0", "0", "0"], ["83483.2", "0.09008911", "0", "1"], ["83483.9", "0", "0", "0"], ["83484", "0.15672257", "0", "2"], ["83484.2", "0", "0", "0"], ["83484.3", "0.09083513", "0", "1"], ["83484.4", "0.09169326", "0", "1"], ["83490.9", "0.20315596", "0", "2"], ["83491", "0.27989627", "0", "2"], ["83491.2", "0", "0", "0"], ["83491.3", "0.15320242", "0", "1"], ["83491.8", "0", "0", "0"], ["83491.9", "0.16355741", "0", "1"], ["83492.7", "0", "0", "0"], ["83492.8", "0.1544988", "0", "1"], ["83497.6", "0", "0", "0"], ["83497.7", "0.23805285", "0", "1"], ["83498.2", "0", "0", "0"], ["83498.3", "0.26619361", "0", "1"], ["83499.9", "0.18055069", "0", "3"], ["83500", "0.46925853", "0", "5"], ["83501.4", "0", "0", "0"], ["83501.5", "0.23777907", "0", "1"], ["83559.8", "0.08657065", "0", "3"], ["83629.5", "0.00437872", "0", "2"], ["83629.9", "0.00002782", "0", "1"]], "bids": [["83469.7", "1.53402229", "0", "20"], ["83466.3", "0.0002", "0", "2"], ["83466.2", "0.52", "0", "1"], ["83466.1", "0", "0", "0"], ["83458.1", "0.24727911", "0", "2"], ["83457.3", "0.45889805", "0", "2"], ["83457.2", "0", "0", "0"], ["83457", "0.0955242", "0", "1"], ["83456.9", "0", "0", "0"], ["83456", "0.09096454", "0", "1"], ["83455.9", "0", "0", "0"], ["83455.7", "0.09392564", "0", "1"], ["83455.6", "0", "0", "0"], ["83450", "0.16191071", "0", "3"], ["83449.9", "0.00060612", "0", "1"], ["83449", "0.14994534", "0", "1"], ["83448.9", "0.35972754", "0", "1"], ["83448.5", "0.15457398", "0", "1"], ["83448.4", "0", "0", "0"], ["83447.3", "0.16468085", "0", "1"], ["83447.2", "0", "0", "0"], ["83443", "0.24868079", "0", "1"], ["83442.9", "0", "0", "0"], ["83442.4", "0.25969026", "0", "1"], ["83442.3", "0.11984077", "0", "1"], ["83440.5", "0.24964595", "0", "1"], ["83440.4", "0", "0", "0"], ["83438.5", "0.26082723", "0", "1"], ["83438.4", "0.00001629", "0", "1"], ["83332.8", "0", "0", "0"], ["83332.7", "0", "0", "0"]], "ts": "1742377431402", "checksum": -365464121, "seqId": 49713711086, "prevSeqId": 49713710904}], "record_time": 1742377432.278254}
{"arg": {"channel": "books", "instId": "BTC-USDT"}, "action": "update", "data": [{"asks": [["83471.3", "0.0001", "0", "1"], ["83471.4", "0.0001", "0", "1"], ["83471.5", "0", "0", "0"], ["83471.8", "0", "0", "0"]], "bids": [["83469.3", "0.17390864", "0", "1"], ["83467.2", "0.11980502", "0", "1"], ["83466.3", "0", "0", "0"], ["83466.2", "0.5202", "0", "3"]], "ts": "1742377431502", "checksum": -563543857, "seqId": 49713711106, "prevSeqId": 49713711086}], "record_time": 1742377432.382972}
{"arg": {"channel": "books", "instId": "BTC-USDT"}, "action": "update", "data": [{"asks": [["83471.2", "0.0002", "0", "2"], ["83471.3", "0", "0", "0"], ["83471.4", "0", "0", "0"], ["83630.2", "0.00428793", "0", "3"]], "bids": [["83466.3", "0.0002", "0", "2"], ["83466.2", "0.52", "0", "1"], ["83332.9", "0", "0", "0"]], "ts": "1742377431602", "checksum": 711991646, "seqId": 49713711114, "prevSeqId": 49713711106}], "record_time": 1742377432.4699}
{"arg": {"channel": "books", "instId": "BTC-USDT"}, "action": "update", "data": [{"asks": [["83470", "0.0567", "0", "1"], ["83478.9", "0.23961165", "0", "1"], ["83479.2", "0.00916", "0", "1"], ["83482.8", "0.09159341", "0", "1"], ["83483.2", "0", "0", "0"], ["83483.8", "0.0926409", "0", "1"], ["83484", "0.14709015", "0", "2"], ["83484.1", "0.09233589", "0", "1"], ["83484.3", "0", "0", "0"], ["83484.4", "0", "0", "0"], ["83490.8", "0.51781029", "0", "2"], ["83491", "0.2759157", "0", "2"], ["83491.3", "0", "0", "0"], ["83491.6", "0.14770434", "0", "1"], ["83491.9", "0", "0", "0"], ["83492.5", "0.15901646", "0", "1"], ["83492.8", "0", "0", "0"], ["83497.4", "0.40270656", "0", "3"], ["83497.7", "0", "0", "0"], ["83498", "0.24937907", "0", "2"], ["83498.3", "0", "0", "0"], ["83499.6", "0.26648058", "0", "1"], ["83500", "0.22733089", "0", "4"], ["83501.3", "0.23663311", "0", "1"], ["83501.5", "0", "0", "0"]], "bids": [["83469.7", "0.91152229", "0", "18"], ["83469.1", "0.11980227", "0", "1"], ["83467.2", "0", "0", "0"], ["83466.3", "0", "0", "0"], ["83466.2", "0.5201", "0", "2"], ["83466.1", "0.0001", "0", "1"], ["83458.1", "0.2484481", "0", "2"], ["83457.3", "0.35972754", "0", "1"], ["83457", "0", "0", "0"], ["83456.9", "0.0979641", "0", "1"], ["83456.7", "0.10077054", "0", "1"], ["83456", "0", "0", "0"], ["83455.8", "0.24484131", "0", "3"], ["83455.7", "0", "0", "0"], ["83455.4", "0.09378235", "0", "1"], ["83450", "0.00013604", "0", "2"], ["83449.7", "0.14975918", "0", "1"], ["83449", "0", "0", "0"], ["83448.8", "0.16334609", "0", "1"], ["83448.5", "0", "0", "0"], ["83448.2", "0.15554862", "0", "2"], ["83447.3", "0", "0", "0"], ["83447", "0.1528881", "0", "1"], ["83443", "0", "0", "0"], ["83442.7", "0.23823166", "0", "1"], ["83442.4", "0", "0", "0"], ["83442.1", "0.24463556", "0", "1"], ["83440.5", "0", "0", "0"], ["83440.1", "0.24690831", "0", "2"], ["83438.5", "0", "0", "0"], ["83438.3", "0.2380835", "0", "1"], ["83425.9", "0.23961165", "0", "1"], ["83380.5", "0", "0", "0"], ["83332.9", "0.00002031", "0", "1"], ["83332.8", "0.2025", "0", "1"]], "ts": "1742377431702", "checksum": 1666653174, "seqId": 49713711198, "prevSeqId": 49713711114}], "record_time": 1742377432.569733}
{"arg": {"channel": "books", "instId": "BTC-USDT"}, "action": "update", "data": [{"asks": [["83478.9", "0.23961138", "0", "1"]], "bids": [["83466.2", "0.5202", "0", "3"], ["83466.1", "0", "0", "0"], ["83425.9", "0.23961138", "0", "1"], ["83380.5", "0.00008831", "0", "1"]], "ts": "1742377431802", "checksum": 2128567579, "seqId": 49713711224, "prevSeqId": 49713711198}], "record_time": 1742377432.669434}
{"arg": {"channel": "books", "instId": "BTC-USDT"}, "action": "update", "data": [{"asks": [["83471.2", "0.0001", "0", "1"], ["83471.5", "0.0001", "0", "1"], ["83478.9", "0.23961158", "0", "1"], ["83492.4", "0.12483798", "0", "1"], ["83629.9", "0", "0", "0"], ["83630.2", "0", "0", "0"]], "bids": [["83449.3", "0.45670181", "0", "1"], ["83425.9", "0", "0", "0"], ["83425.7", "0.23961158", "0", "1"], ["83422.7", "0.15170845", "0", "1"], ["83422.5", "0", "0", "0"], ["83332.8", "0", "0", "0"]], "ts": "1742377431902", "checksum": 1290914933, "seqId": 49713711264, "prevSeqId": 49713711224}], "record_time": 1742377432.769901}
{"arg": {"channel": "books", "instId": "BTC-USDT"}, "action": "update", "data": [{"asks": [["83477.9", "0.23961398", "0", "1"], ["83478.9", "0", "0", "0"], ["83500", "0.22707531", "0", "3"]], "bids": [["83431", "0.2", "0", "1"], ["83425.7", "0", "0", "0"], ["83422.8", "0.23961398", "0", "1"], ["83422.7", "0", "0", "0"]], "ts": "1742377432002", "checksum": 2013272500, "seqId": 49713711277, "prevSeqId": 49713711264}], "record_time": 1742377432.871389}
{"arg": {"channel": "books", "instId": "BTC-USDT"}, "action": "update", "data": [{"asks": [["83471.2", "0.0002", "0", "2"], ["83471.5", "0", "0", "0"], ["83477.9", "0.23961508", "0", "1"], ["83498.3", "0.00761307", "0", "1"], ["83498.9", "0", "0", "0"], ["83528.9", "0.00378851", "0", "1"], ["83530.1", "0", "0", "0"], ["83629.9", "0.00002782", "0", "1"]], "bids": [["83466.3", "0.0002", "0", "2"], ["83466.2", "0.52", "0", "1"], ["83431", "0", "0", "0"], ["83422.8", "0", "0", "0"], ["83422.5", "0.23961426", "0", "1"]], "ts": "1742377432102", "checksum": 1964854779, "seqId": 49713711310, "prevSeqId": 49713711277}], "record_time": 1742377432.969644}
{"arg": {"channel": "books", "instId": "BTC-USDT"}, "action": "update", "data": [{"asks": [], "bids": [["83469.1", "0", "0", "0"], ["83466.5", "0.15760433", "0", "5"], ["83332.8", "0.2025", "0", "1"]], "ts": "1742377432202", "checksum": -1285475081, "seqId": 49713711324, "prevSeqId": 49713711310}], "record_time": 1742377433.069314}
{"arg": {"channel": "books", "instId": "BTC-USDT"}, "action": "update", "data": [{"asks": [["83471.2", "0.0001", "0", "1"], ["83471.3", "0.0001", "0", "1"], ["83477.9", "0", "0", "0"], ["83478.9", "0.23961149", "0", "1"], ["83629.9", "0", "0", "0"]], "bids": [["83466.3", "0.0001", "0", "1"], ["83466.2", "0.5201", "0", "2"], ["83425.7", "0.23961149", "0", "1"], ["83422.5", "0", "0", "0"], ["83418.8", "1.0775", "0", "2"], ["83418.1", "0", "0", "0"], ["83332.7", "0.00042773", "0", "1"]], "ts": "1742377432302", "checksum": 535663150, "seqId": 49713711346, "prevSeqId": 49713711324}], "record_time": 1742377433.170615}
{"arg": {"channel": "books", "instId": "BTC-USDT"}, "action": "update", "data": [{"asks": [["83477.9", "0.23961291", "0", "1"], ["83478.9", "0", "0", "0"], ["83528.9", "0", "0", "0"], ["83530.1", "0.00378866", "0", "1"]], "bids": [["83469.7", "1.33152229", "0", "19"], ["83469.5", "0.2639671", "0", "1"], ["83469.4", "0.42", "0", "1"], ["83469.3", "0", "0", "0"], ["83466.3", "0.0002", "0", "2"], ["83466.2", "0.52", "0", "1"], ["83425.7", "0", "0", "0"], ["83422.5", "0.23961291", "0", "1"], ["83332.7", "0", "0", "0"]], "ts": "1742377432402", "checksum": 191701261, "seqId": 49713711378, "prevSeqId": 49713711346}], "record_time": 1742377433.269744}
{"arg": {"channel": "books", "instId": "BTC-USDT"}, "action": "update", "data": [{"asks": [["83477.9", "0", "0", "0"], ["83478.9", "0.23961184", "0", "1"], ["83509.6", "0", "0", "0"], ["83510.4", "0.07999999", "0", "2"], ["83511.2", "0.03999999", "0", "1"], ["83530.2", "0", "0", "0"], ["83629.9", "0.00002782", "0", "1"]], "bids": [["83469.7", "0.91152229", "0", "18"], ["83469.4", "0", "0", "0"], ["83422.5", "0.23961219", "0", "1"], ["83416.8", "0.2033", "0", "3"], ["83416", "0.08039996", "0", "3"], ["83415.2", "0.14", "0", "3"], ["83414.4", "0.05589947", "0", "2"], ["83413.6", "0.026", "0", "2"], ["83412.8", "0.013", "0", "1"], ["83412", "0", "0", "0"], ["83411.2", "0.06", "0", "2"], ["83332.7", "0.00042773", "0", "1"]], "ts": "1742377432502", "checksum": -1648428233, "seqId": 49713711427, "prevSeqId": 49713711378}], "record_time": 1742377433.370263}
{"arg": {"channel": "books", "instId": "BTC-USDT"}, "action": "update", "data": [{"asks": [["83469.8", "0.19428753", "0", "4"], ["83471.2", "0.0002", "0", "2"], ["83471.3", "0", "0", "0"], ["83478.9", "0.2396103", "0", "1"], ["83483.7", "0.09532254", "0", "1"], ["83483.8", "0", "0", "0"], ["83490.7", "0.15767122", "0", "2"], ["83490.8", "0.35972754", "0", "1"], ["83491.5", "0.16774907", "0", "1"], ["83491.6", "0", "0", "0"], ["83492.4", "0.16428802", "0", "1"], ["83492.5", "0", "0", "0"], ["83501.2", "0.25437493", "0", "1"], ["83501.3", "0", "0", "0"], ["83533.3", "0.01969137", "0", "5"], ["83539", "0.06652071", "0", "1"], ["83630.2", "0.00428793", "0", "3"]], "bids": [["83469.5", "0.1379671", "0", "1"], ["83466.3", "0", "0", "0"], ["83466.2", "0.5202", "0", "3"], ["83455.8", "0.15199316", "0", "2"], ["83455.7", "0.0894111", "0", "1"], ["83449.3", "0", "0", "0"], ["83448.8", "0", "0", "0"], ["83448.7", "0.15168435", "0", "1"], ["83448.2", "0.00015588", "0", "1"], ["83448.1", "0.15265481", "0", "1"], ["83447", "0", "0", "0"], ["83446.9", "0.15614209", "0", "1"], ["83438.3", "0", "0", "0"], ["83438.2", "0.26573602", "0", "1"], ["83425.9", "0.2396103", "0", "1"], ["83422.5", "0", "0", "0"]], "ts": "1742377432602", "checksum": 1915011855, "seqId": 49713711494, "prevSeqId": 49713711427}], "record_time": 1742377433.470522}
{"arg": {"channel": "books", "instId": "BTC-USDT"}, "action": "update", "data": [{"asks": [["83469.8", "0.17897241", "0", "3"], ["83471.2", "0", "0", "0"], ["83471.3", "0.0001", "0", "1"], ["83471.5", "0.0001", "0", "1"], ["83477.9", "0.2396133", "0", "1"], ["83478.9", "0", "0", "0"], ["83483.7", "0", "0", "0"], ["83483.8", "0.09160285", "0", "1"], ["83490.7", "0.00884137", "0", "1"], ["83490.8", "0.52594806", "0", "2"], ["83491.5", "0", "0", "0"], ["83491.6", "0.15456749", "0", "1"], ["83492.4", "0", "0", "0"], ["83492.5", "0.14884743", "0", "1"], ["83501.2", "0", "0", "0"], ["83501.3", "0.23761552", "0", "1"], ["83630.2", "0", "0", "0"]], "bids": [["83469.7", "1.11402229", "0", "19"], ["83466.3", "0.0002", "0", "2"], ["83466.2", "0.52", "0", "1"], ["83455.8", "0.25292105", "0", "3"], ["83455.7", "0", "0", "0"], ["83448.8", "0.16359424", "0", "1"], ["83448.7", "0", "0", "0"], ["83448.2", "0.16411029", "0", "2"], ["83448.1", "0", "0", "0"], ["83447", "0.15011708", "0", "1"], ["83446.9", "0", "0", "0"], ["83438.3", "0.24533596", "0", "1"], ["83438.2", "0", "0", "0"], ["83425.9", "0", "0", "0"], ["83422.5", "0.2396133", "0", "1"], ["83332.6", "0.00001302", "0", "1"]], "ts": "1742377432702", "checksum": 1656271323, "seqId": 49713711535, "prevSeqId": 49713711494}], "record_time": 1742377433.570265}
{"arg": {"channel": "books", "instId": "BTC-USDT"}, "action": "update", "data": [{"asks": [["83471.2", "0.0001", "0", "1"], ["83471.5", "0", "0", "0"]], "bids": [["83466.3", "0.0001", "0", "1"], ["83466.2", "0.5201", "0", "2"]], "ts": "1742377432802", "checksum": 625239590, "seqId": 49713711541, "prevSeqId": 49713711535}], "record_time": 1742377433.669538}
{"arg": {"channel": "books", "instId": "BTC-USDT"}, "action": "update", "data": [{"asks": [["83469.8", "0.19428753", "0", "4"], ["83471.2", "0", "0", "0"], ["83471.3", "0.0002", "0", "2"], ["83477.9", "0", "0", "0"], ["83481.6", "0.23960875", "0", "1"], ["83483.7", "0.08895225", "0", "1"], ["83483.8", "0", "0", "0"], ["83490.7", "0.15625874", "0", "2"], ["83490.8", "0.35972754", "0", "1"], ["83491.5", "0.16513927", "0", "1"], ["83491.6", "0", "0", "0"], ["83492.3", "0.15681299", "0", "1"], ["83492.4", "0.1655998", "0", "1"], ["83492.5", "0", "0", "0"], ["83496", "0.100015", "0", "2"], ["83498", "1.24937907", "0", "3"], ["83501.2", "0.24456903", "0", "1"], ["83501.3", "0", "0", "0"]], "bids": [["83466.3", "0", "0", "0"], ["83466.1", "0.0001", "0", "1"], ["83458.8", "0", "0", "0"], ["83455.8", "0.15199316", "0", "2"], ["83455.7", "0.09609094", "0", "1"], ["83452.6", "0", "0", "0"], ["83449.3", "0.45835706", "0", "1"], ["83448.8", "0", "0", "0"], ["83448.7", "0.14759521", "0", "1"], ["83448.2", "0.00015588", "0", "1"], ["83448.1", "0.16551055", "0", "1"], ["83447", "0", "0", "0"], ["83446.9", "0.16403866", "0", "1"], ["83438.3", "0", "0", "0"], ["83438.2", "0.24200714", "0", "1"], ["83426.6", "0.23961096", "0", "1"], ["83422.5", "0", "0", "0"], ["83332.6", "0", "0", "0"]], "ts": "1742377432902", "checksum": -1205637459, "seqId": 49713711619, "prevSeqId": 49713711541}], "record_time": 1742377433.775058}
{"arg": {"channel": "books", "instId": "BTC-USDT"}, "action": "update", "data": [{"asks": [["83469.8", "0.17897241", "0", "3"], ["83471.2", "0.0002", "0", "2"], ["83471.3", "0", "0", "0"], ["83477.9", "0.23961364", "0", "1"], ["83481.6", "0", "0", "0"], ["83483.7", "0", "0", "0"], ["83483.8", "0.09193954", "0", "1"], ["83490.7", "0.00884137", "0", "1"], ["83490.8", "0.50955053", "0", "2"], ["83491.5", "0", "0", "0"], ["83491.6", "0.15723694", "0", "1"], ["83492.3", "0", "0", "0"], ["83492.4", "0", "0", "0"], ["83492.5", "0.16330861", "0", "1"], ["83501.2", "0", "0", "0"], ["83501.3", "0.23792789", "0", "1"], ["83630.2", "0.00428793", "0", "3"]], "bids": [["83466.3", "0.0002", "0", "2"], ["83466.2", "0.52", "0", "1"], ["83466.1", "0", "0", "0"], ["83455.8", "0.24294107", "0", "3"], ["83455.7", "0", "0", "0"], ["83449.3", "0", "0", "0"], ["83448.8", "0.14750281", "0", "1"], ["83448.7", "0", "0", "0"], ["83448.2", "0.16371764", "0", "2"], ["83448.1", "0", "0", "0"], ["83447", "0.15263446", "0", "1"], ["83446.9", "0", "0", "0"], ["83438.3", "0.24987169", "0", "1"], ["83438.2", "0", "0", "0"], ["83426.6", "0", "0", "0"], ["83422.5", "0.23961364", "0", "1"], ["83406.3", "0.01197486", "0", "1"], ["83405.5", "0", "0", "0"], ["83332.6", "0.00001302", "0", "1"], ["83332.3", "0.00001364", "0", "1"], ["83331.2", "0.00005685", "0", "1"]], "ts": "1742377433002", "checksum": 1803079660, "seqId": 49713711676, "prevSeqId": 49713711619}], "record_time": 1742377433.869711}
{"arg": {"channel": "books", "instId": "BTC-USDT"}, "action": "update", "data": [{"asks": [["83471.2", "0", "0", "0"], ["83471.3", "0.0001", "0", "1"], ["83471.4", "0.0001", "0", "1"], ["83477.9", "0", "0", "0"], ["83478.9", "0.23961228", "0", "1"], ["83630.2", "0", "0", "0"]], "bids": [["83459.4", "0.01566", "0", "1"], ["83453.1", "0.047", "0", "1"], ["83425.3", "0.25141147", "0", "3"], ["83422.5", "0", "0", "0"], ["83331.2", "0", "0", "0"]], "ts": "1742377433102", "checksum": 1402083681, "seqId": 49713711714, "prevSeqId": 49713711676}], "record_time": 1742377433.969976}
{"arg": {"channel": "books", "instId": "BTC-USDT"}, "action": "update", "data": [{"asks": [["83469.8", "0.17681541", "0", "2"], ["83471.2", "0.0002", "0", "2"], ["83471.3", "0", "0", "0"], ["83471.4", "0", "0", "0"], ["83482.8", "0", "0", "0"], ["83482.9", "0.09562231", "0", "1"], ["83491.7", "0", "0", "0"], ["83499.6", "0", "0", "0"], ["83499.7", "0.24671587", "0", "1"], ["83512", "0.002157", "0", "1"], ["83527.5", "0", "0", "0"], ["83630.2", "0.00428793", "0", "3"], ["83630.5", "0.00003988", "0", "1"]], "bids": [["83457", "0.09921371", "0", "1"], ["83456.9", "0", "0", "0"], ["83440.2", "0.26522377", "0", "1"], ["83440.1", "0.00001204", "0", "1"], ["83332.3", "0", "0", "0"]], "ts": "1742377433202", "checksum": -1773113280, "seqId": 49713711741, "prevSeqId": 49713711714}], "record_time": 1742377434.070126}
{"arg": {"channel": "books", "instId": "BTC-USDT"}, "action": "update", "data": [{"asks": [], "bids": [["83469.7", "1.11267079", "0", "19"]], "ts": "1742377433302", "checksum": -1013260375, "seqId": 49713711757, "prevSeqId": 49713711741}], "record_time": 1742377434.169812}
{"arg": {"channel": "books", "instId": "BTC-USDT"}, "action": "update", "data": [{"asks": [["83469.8", "0.17897241", "0", "3"], ["83470", "0", "0", "0"], ["83471.2", "0", "0", "0"], ["83471.5", "0.0001", "0", "1"], ["83472", "0.0568", "0", "2"], ["83476.9", "0", "0", "0"], ["83482.9", "0", "0", "0"], ["83483.2", "0.09871189", "0", "1"], ["83483.8", "0", "0", "0"], ["83484", "0.1558457", "0", "2"], ["83484.1", "0", "0", "0"], ["83484.3", "0.09006403", "0", "1"], ["83484.4", "0.09608114", "0", "1"], ["83490.2", "0.38084741", "0", "2"], ["83490.8", "0.35972754", "0", "1"], ["83491", "0.27383329", "0", "2"], ["83491.3", "0.15489849", "0", "1"], ["83491.6", "0", "0", "0"], ["83491.9", "0.15278362", "0", "1"], ["83492.5", "0", "0", "0"], ["83492.8", "0.1613366", "0", "1"], ["83497.4", "0.15199316", "0", "2"], ["83497.7", "0.24490203", "0", "1"], ["83498", "1.0055", "0", "2"], ["83498.3", "0.26898971", "0", "2"], ["83499.7", "0", "0", "0"], ["83500", "0.48512127", "0", "4"], ["83501.3", "0", "0", "0"], ["83501.5", "0.24117659", "0", "1"], ["83512", "0", "0", "0"], ["83559.8", "0.12139227", "0", "4"], ["83630.6", "0.00011142", "0", "1"], ["83630.7", "0.0000484", "0", "1"]], "bids": [["83469.7", "1.53267079", "0", "20"], ["83469", "0.11980243", "0", "1"], ["83466.5", "0.03779828", "0", "4"], ["83466.2", "0.65", "0", "2"], ["83458.1", "0.27059192", "0", "2"], ["83457.3", "0.45036308", "0", "2"], ["83457", "0.08840917", "0", "1"], ["83456.7", "0", "0", "0"], ["83456", "0.09346779", "0", "1"], ["83455.8", "0.15199316", "0", "2"], ["83455.7", "0.09381723", "0", "1"], ["83455.4", "0", "0", "0"], ["83450", "0.16387955", "0", "3"], ["83449.7", "0", "0", "0"], ["83449", "0.15515583", "0", "1"], ["83448.8", "0", "0", "0"], ["83448.5", "0.16794723", "0", "1"], ["83448.2", "0.00015588", "0", "1"], ["83447.3", "0.16093538", "0", "1"], ["83447", "0", "0", "0"], ["83443", "0.23430937", "0", "1"], ["83442.7", "0", "0", "0"], ["83442.4", "0.24234464", "0", "1"], ["83442.1", "0", "0", "0"], ["83440.5", "0.26601198", "0", "1"], ["83440.2", "0", "0", "0"], ["83438.5", "0.25685596", "0", "1"], ["83438.3", "0", "0", "0"], ["83332.6", "0", "0", "0"]], "ts": "1742377433402", "checksum": 1283384257, "seqId": 49713711831, "prevSeqId": 49713711757}], "record_time": 1742377434.273417}
{"arg": {"channel": "books", "instId": "BTC-USDT"}, "action": "update", "data": [{"asks": [["83471.2", "0.0001", "0", "1"], ["83471.4", "0.0001", "0", "1"], ["83471.5", "0", "0", "0"], ["83472", "0.0567", "0", "1"], ["83527.5", "0.00013267", "0", "1"], ["83630.6", "0", "0", "0"], ["83630.7", "0", "0", "0"]], "bids": [], "ts": "1742377433502", "checksum": 531644028, "seqId": 49713711847, "prevSeqId": 49713711831}], "record_time": 1742377434.371778}
{"arg": {"channel": "books", "instId": "BTC-USDT"}, "action": "update", "data": [{"asks": [["83469.6", "0.05835112", "0", "5"], ["83469.7", "2.25052948", "0", "1"], ["83469.8", "0.11690152", "0", "1"], ["83469.9", "0.0001", "0", "1"], ["83470", "0.0567", "0", "1"], ["83471.4", "0", "0", "0"], ["83475", "0.02919354", "0", "2"], ["83478.9", "0", "0", "0"], ["83482.1", "0", "0", "0"], ["83483.1", "0.2396096", "0", "1"], ["83483.2", "0", "0", "0"], ["83484", "0.0567", "0", "1"], ["83484.3", "0", "0", "0"], ["83484.4", "0", "0", "0"], ["83488", "0.0567", "0", "1"], ["83491", "0.11977102", "0", "1"], ["83491.3", "0", "0", "0"], ["83491.9", "0", "0", "0"], ["83492.8", "0", "0", "0"], ["83497.7", "0", "0", "0"], ["83498.3", "0.00761307", "0", "1"], ["83500", "0.22707531", "0", "3"], ["83501.5", "0", "0", "0"], ["83630.6", "0.00011142", "0", "1"], ["83630.7", "0.0000484", "0", "1"], ["83630.8", "0.00110397", "0", "1"], ["83630.9", "0.11992025", "0", "1"], ["83631.1", "0.00001167", "0", "1"], ["83631.4", "0.00048794", "0", "12"]], "bids": [["83469.7", "0", "0", "0"], ["83469.5", "0.71160106", "0", "5"], ["83466.3", "0.0001", "0", "1"], ["83462.5", "0.0001", "0", "1"], ["83459.4", "0", "0", "0"], ["83457.3", "0.35972754", "0", "1"], ["83457", "0", "0", "0"], ["83456", "0", "0", "0"], ["83455.7", "0", "0", "0"], ["83453.1", "0", "0", "0"], ["83450", "0.00013604", "0", "2"], ["83449", "0", "0", "0"], ["83448.5", "0", "0", "0"], ["83448.3", "0", "0", "0"], ["83447.3", "0", "0", "0"], ["83446.1", "0.015675", "0", "2"], ["83443", "0", "0", "0"], ["83442.4", "0", "0", "0"], ["83440.5", "0", "0", "0"], ["83439.8", "0.04701", "0", "1"], ["83438.5", "0", "0", "0"], ["83426.6", "0.2396096", "0", "1"], ["83425.3", "0.01179894", "0", "2"], ["83332.6", "0.00001302", "0", "1"], ["83332.3", "0.00001364", "0", "1"], ["83331.2", "0.00005685", "0", "1"], ["83331", "0.00001097", "0", "1"], ["83330.8", "0.035909", "0", "1"], ["83330.6", "0.00001852", "0", "1"], ["83330.1", "0.00003016", "0", "2"], ["83329.7", "0.00008173", "0", "1"], ["83329.3", "0.00428218", "0", "1"], ["83328.8", "0.17953568", "0", "1"], ["83328.7", "0.11992025", "0", "1"]], "ts": "1742377433602", "checksum": -2083098713, "seqId": 49713711947, "prevSeqId": 49713711847}], "record_time": 1742377434.470143}
{"arg": {"channel": "books", "instId": "BTC-USDT"}, "action": "update", "data": [{"asks": [["83469.6", "0.01849112", "0", "3"], ["83469.9", "0", "0", "0"], ["83471", "0.0002", "0", "2"], ["83471.2", "0", "0", "0"], ["83475", "0.00171354", "0", "1"], ["83475.3", "0.09548082", "0", "1"], ["83482.4", "0.08984883", "0", "1"], ["83483.4", "0.09555327", "0", "2"], ["83483.5", "0.25971243", "0", "2"], ["83483.9", "0.09122357", "0", "1"], ["83486", "0.0567", "0", "1"], ["83490.2", "0.49512453", "0", "3"], ["83490.4", "0.16028037", "0", "1"], ["83490.5", "0.1556396", "0", "1"], ["83491.2", "0.15019167", "0", "1"], ["83492.3", "0.16061332", "0", "1"], ["83496", "0.000015", "0", "1"], ["83497.2", "0.25003364", "0", "1"], ["83497.4", "0.41421336", "0", "3"], ["83499.2", "0.24662326", "0", "1"], ["83501", "0.24453681", "0", "1"], ["83513.9", "0.1", "0", "1"], ["83514", "0", "0", "0"], ["83515.2", "0.02960533", "0", "1"], ["83584.4", "0.42411655", "0", "1"], ["83630.2", "0", "0", "0"], ["83630.5", "0", "0", "0"], ["83630.6", "0", "0", "0"], ["83630.7", "0", "0", "0"], ["83630.8", "0", "0", "0"], ["83630.9", "0", "0", "0"], ["83631.1", "0", "0", "0"], ["83631.4", "0", "0", "0"]], "bids": [["83469.5", "0.8065134", "0", "7"], ["83469.1", "0.17390783", "0", "1"], ["83466.3", "0", "0", "0"], ["83466", "0.0568", "0", "2"], ["83465.2", "0.0001", "0", "1"], ["83462.5", "0", "0", "0"], ["83458.1", "0.27384757", "0", "2"], ["83456.5", "0.10068777", "0", "1"], ["83456.1", "0.08820485", "0", "1"], ["83455.5", "0.0886291", "0", "1"], ["83455.2", "0.09966017", "0", "1"], ["83449.1", "0.16517106", "0", "1"], ["83448.5", "0.15224972", "0", "1"], ["83448.1", "0.0071901", "0", "1"], ["83447.8", "0.16349024", "0", "1"], ["83446.8", "0.15394996", "0", "2"], ["83442.1", "0.26174582", "0", "1"], ["83441.9", "0.23964345", "0", "1"], ["83439.7", "0.26418494", "0", "1"], ["83438", "0.24794726", "0", "1"], ["83435.6", "0.41236927", "0", "2"], ["83433.6", "0.9925", "0", "2"], ["83421.7", "0", "0", "0"], ["83421.6", "0.1", "0", "1"], ["83404.5", "0", "0", "0"], ["83404.4", "0", "0", "0"], ["83332.3", "0", "0", "0"], ["83331.2", "0", "0", "0"], ["83331", "0", "0", "0"], ["83330.8", "0", "0", "0"], ["83330.6", "0", "0", "0"], ["83330.1", "0", "0", "0"], ["83329.7", "0", "0", "0"], ["83329.3", "0", "0", "0"], ["83328.8", "0", "0", "0"], ["83328.7", "0", "0", "0"]], "ts": "1742377433702", "checksum": 1385102682, "seqId": 49713712035, "prevSeqId": 49713711947}], "record_time": 1742377434.570444}
{"arg": {"channel": "books", "instId": "BTC-USDT"}, "action": "update", "data": [{"asks": [["83469.6", "0.01531512", "0", "1"], ["83470.9", "0.0002", "0", "2"], ["83471", "0", "0", "0"], ["83483.5", "0.71388619", "0", "3"], ["83484.1", "0.00916", "0", "1"], ["83486", "1.62707126", "0", "2"], ["83490.4", "0.18775037", "0", "2"], ["83496.4", "0", "0", "0"], ["83511.9", "0.002157", "0", "1"], ["83515.2", "2.88899621", "0", "2"], ["83531.6", "0.01219896", "0", "1"], ["83629.5", "0", "0", "0"], ["83629.9", "0", "0", "0"]], "bids": [["83469.3", "0.29990783", "0", "1"], ["83469.2", "0.42", "0", "1"], ["83469.1", "0", "0", "0"], ["83466", "0.0567", "0", "1"], ["83465.2", "0", "0", "0"], ["83463.4", "0.0002", "0", "2"], ["83459.9", "0.01566", "0", "1"], ["83446.1", "0.000015", "0", "1"], ["83439.8", "0", "0", "0"], ["83436.1", "0", "0", "0"], ["83434.9", "1.70881728", "0", "3"], ["83421.6", "0", "0", "0"], ["83421.5", "0.1", "0", "1"], ["83405.7", "2.78350859", "0", "1"], ["83404.6", "0.00001501", "0", "1"], ["83403.8", "0.0019861", "0", "1"], ["83402.8", "0.01219896", "0", "1"], ["83332.8", "0", "0", "0"], ["83332.7", "0", "0", "0"], ["83332.6", "0", "0", "0"]], "ts": "1742377433802", "checksum": -1622833466, "seqId": 49713712091, "prevSeqId": 49713712035}], "record_time": 1742377434.669767}
{"arg": {"channel": "books", "instId": "BTC-USDT"}, "action": "update", "data": [{"asks": [["83492.2", "0.12531704", "0", "1"], ["83497.9", "0.00761308", "0", "1"], ["83498.3", "0", "0", "0"], ["83513.8", "0.1", "0", "1"], ["83513.9", "0", "0", "0"], ["83544.7", "0.21019907", "0", "1"], ["83584.4", "0", "0", "0"], ["83629.4", "0", "0", "0"]], "bids": [["83455.2", "0.14666017", "0", "2"], ["83435.6", "1.0653291", "0", "3"], ["83405.8", "0.83873231", "0", "1"], ["83332.9", "0", "0", "0"]], "ts": "1742377433902", "checksum": -1622833466, "seqId": 49713712121, "prevSeqId": 49713712091}], "record_time": 1742377434.769563}
{"arg": {"channel": "books", "instId": "BTC-USDT"}, "action": "update", "data": [{"asks": [["83469.6", "0", "0", "0"], ["83469.7", "2.26125006", "0", "2"], ["83470.9", "0", "0", "0"], ["83471.3", "0.0002", "0", "2"], ["83475", "0.01087354", "0", "2"], ["83482.4", "0", "0", "0"], ["83482.5", "0.090654", "0", "1"], ["83483.5", "0.61642311", "0", "2"], ["83483.6", "0.21636632", "0", "5"], ["83484.1", "0", "0", "0"], ["83490.4", "0.16028037", "0", "1"], ["83490.5", "0", "0", "0"], ["83490.6", "0.16214547", "0", "1"], ["83496.4", "0.01219896", "0", "1"], ["83499.2", "0", "0", "0"], ["83499.3", "0.2386759", "0", "1"], ["83501", "0", "0", "0"], ["83501.1", "0.76757578", "0", "2"], ["83513.8", "0", "0", "0"], ["83513.9", "0.1", "0", "1"], ["83531.6", "0", "0", "0"], ["83629.4", "0.00001001", "0", "1"], ["83629.5", "0.00437872", "0", "2"], ["83629.9", "0.00002782", "0", "1"]], "bids": [["83469.6", "1.6784849", "0", "17"], ["83469.5", "0.33466194", "0", "4"], ["83469.4", "0.0001", "0", "1"], ["83469.3", "0", "0", "0"], ["83468.6", "0.0315628", "0", "2"], ["83463.4", "0", "0", "0"], ["83459.9", "0", "0", "0"], ["83456.6", "0.09551256", "0", "1"], ["83456.5", "0", "0", "0"], ["83455.6", "0.08981921", "0", "1"], ["83455.5", "0", "0", "0"], ["83455.2", "0.09966017", "0", "1"], ["83452.2", "0.01566", "0", "1"], ["83448.6", "0.14687122", "0", "1"], ["83448.5", "0", "0", "0"], ["83448.1", "0", "0", "0"], ["83446", "0.047", "0", "1"], ["83439.8", "0.25985806", "0", "1"], ["83439.7", "0", "0", "0"], ["83438.1", "0.2488809", "0", "1"], ["83438", "0", "0", "0"], ["83436.1", "0.01219896", "0", "1"], ["83421.6", "0.1", "0", "1"], ["83421.5", "0", "0", "0"], ["83402.8", "0", "0", "0"]], "ts": "1742377434002", "checksum": 1531930499, "seqId": 49713712207, "prevSeqId": 49713712121}], "record_time": 1742377434.870276}
{"arg": {"channel": "books", "instId": "BTC-USDT"}, "action": "update", "data": [{"asks": [["83470.2", "0.0002", "0", "2"], ["83471.3", "0", "0", "0"], ["83481.3", "0.02748", "0", "1"], ["83483.1", "0", "0", "0"], ["83483.3", "0.24021521", "0", "2"], ["83530.1", "0", "0", "0"], ["83531.2", "0.00378882", "0", "1"], ["83533.3", "0.00504349", "0", "4"]], "bids": [["83469.4", "0", "0", "0"], ["83469.2", "0", "0", "0"], ["83468.6", "0.0314628", "0", "1"], ["83468.1", "0.0002", "0", "2"], ["83426.6", "0", "0", "0"], ["83425.9", "0.23960934", "0", "1"], ["83424", "0.2", "0", "1"], ["83408.5", "0.0184495", "0", "1"], ["83338.2", "0.18449518", "0", "1"], ["83337.4", "0", "0", "0"]], "ts": "1742377434102", "checksum": -722396967, "seqId": 49713712256, "prevSeqId": 49713712207}], "record_time": 1742377434.974732}
{"arg": {"channel": "books", "instId": "BTC-USDT"}, "action": "update", "data": [{"asks": [["83469.8", "0.11710152", "0", "3"], ["83470.2", "0", "0", "0"], ["83537.8", "0.0146455", "0", "1"], ["83539.6", "0", "0", "0"], ["83630.2", "0.00428793", "0", "3"]], "bids": [["83469.6", "1.42164945", "0", "17"], ["83469.5", "0.1899671", "0", "3"], ["83468.1", "0", "0", "0"], ["83465.4", "0.0002", "0", "2"], ["83424", "0", "0", "0"], ["83375.9", "0", "0", "0"], ["83332.9", "0.00002031", "0", "1"], ["83332.7", "0.00042773", "0", "1"]], "ts": "1742377434202", "checksum": -1473763560, "seqId": 49713712290, "prevSeqId": 49713712256}], "record_time": 1742377435.072308}
{"arg": {"channel": "books", "instId": "BTC-USDT"}, "action": "update", "data": [{"asks": [["83469.8", "0.11700152", "0", "2"], ["83470.1", "0.0001", "0", "1"], ["83473", "0", "0", "0"], ["83543.8", "0", "0", "0"], ["83630.5", "0.00003988", "0", "1"]], "bids": [["83465.5", "0.0002", "0", "2"], ["83465.4", "0", "0", "0"], ["83450.9", "0", "0", "0"], ["83380.1", "0", "0", "0"], ["83332.8", "0.2025", "0", "1"], ["83332.6", "0.00001302", "0", "1"]], "ts": "1742377434302", "checksum": 1154217644, "seqId": 49713712307, "prevSeqId": 49713712290}], "record_time": 1742377435.178105}
{"arg": {"channel": "books", "instId": "BTC-USDT"}, "action": "update", "data": [{"asks": [["83483.3", "0.24021731", "0", "2"]], "bids": [], "ts": "1742377434502", "checksum": 1154217644, "seqId": 49713712319, "prevSeqId": 49713712307}], "record_time": 1742377435.371819}
{"arg": {"channel": "books", "instId": "BTC-USDT"}, "action": "update", "data": [{"asks": [["83469.7", "2.26340706", "0", "3"], ["83469.8", "0.11690152", "0", "1"], ["83469.9", "0.0002", "0", "2"], ["83470.1", "0", "0", "0"], ["83473", "0.00239598", "0", "1"], ["83475.3", "0.05566542", "0", "1"], ["83479", "0", "0", "0"], ["83498", "1.2055", "0", "3"], ["83511.9", "0", "0", "0"], ["83537.8", "0", "0", "0"], ["83543.8", "0.14363724", "0", "2"], ["83600.2", "0", "0", "0"], ["83630.6", "0.00011142", "0", "1"], ["83630.7", "0.0000484", "0", "1"]], "bids": [["83469.6", "1.5067645", "0", "18"], ["83465.9", "0.0001", "0", "1"], ["83465.8", "0.0001", "0", "1"], ["83465.5", "0", "0", "0"], ["83450.9", "0.00239661", "0", "1"], ["83380.1", "0.1439192", "0", "2"], ["83332.8", "0", "0", "0"], ["83332.7", "0", "0", "0"], ["83332.6", "0", "0", "0"]], "ts": "1742377434702", "checksum": -1459932965, "seqId": 49713712372, "prevSeqId": 49713712319}], "record_time": 1742377435.570278}
{"arg": {"channel": "books", "instId": "BTC-USDT"}, "action": "update", "data": [{"asks": [["83469.8", "0.11700152", "0", "2"], ["83469.9", "0.0001", "0", "1"], ["83482.1", "0.132722", "0", "1"], ["83483.3", "0.24021535", "0", "2"], ["83630.7", "0", "0", "0"]], "bids": [["83465.9", "0", "0", "0"], ["83465.8", "0", "0", "0"], ["83465.7", "0.0002", "0", "2"], ["83439", "0.05983983", "0", "1"], ["83426.6", "0.23960924", "0", "1"], ["83425.9", "0", "0", "0"], ["83369.8", "0", "0", "0"], ["83332.8", "0.2025", "0", "1"], ["83332.7", "0.00042773", "0", "1"]], "ts": "1742377434802", "checksum": -1025069110, "seqId": 49713712410, "prevSeqId": 49713712372}], "record_time": 1742377435.669784}
{"arg": {"channel": "books", "instId": "BTC-USDT"}, "action": "update", "data": [{"asks": [["83469.8", "0.11710152", "0", "3"], ["83469.9", "0", "0", "0"], ["83483.3", "0.24021576", "0", "2"], ["83496.5", "1.0928327", "0", "1"], ["83559.8", "0.08657065", "0", "3"], ["83571.1", "0.01199783", "0", "2"], ["83572.7", "0", "0", "0"], ["83630.7", "0.0000484", "0", "1"], ["83630.8", "0.00110397", "0", "1"]], "bids": [["83469.6", "1.4981715", "0", "17"], ["83449.2", "0.64039555", "0", "2"], ["83426.6", "0.23960964", "0", "1"], ["83422.5", "0.07982426", "0", "1"], ["83332.7", "0", "0", "0"]], "ts": "1742377434902", "checksum": -1863202831, "seqId": 49713712438, "prevSeqId": 49713712410}], "record_time": 1742377435.769969}
{"arg": {"channel": "books", "instId": "BTC-USDT"}, "action": "update", "data": [{"asks": [["83469.8", "0.11700152", "0", "2"], ["83470.2", "0.0001", "0", "1"], ["83481.2", "0.23961258", "0", "1"], ["83483.3", "0.00060612", "0", "1"], ["83541", "0.01464494", "0", "1"], ["83630.6", "0", "0", "0"], ["83630.7", "0", "0", "0"], ["83630.8", "0", "0", "0"]], "bids": [["83466.4", "0.0001", "0", "1"], ["83465.7", "0", "0", "0"], ["83465.3", "0.0001", "0", "1"], ["83444.2", "0.00372886", "0", "1"], ["83426.6", "0", "0", "0"], ["83422.6", "0.23961258", "0", "1"], ["83374.9", "0.01439282", "0", "1"], ["83333.1", "0", "0", "0"], ["83332.9", "0", "0", "0"], ["83332.8", "0", "0", "0"]], "ts": "1742377435002", "checksum": -210329399, "seqId": 49713712496, "prevSeqId": 49713712438}], "record_time": 1742377435.869696}
{"arg": {"channel": "books", "instId": "BTC-USDT"}, "action": "update", "data": [{"asks": [["83469.8", "0.11710152", "0", "3"], ["83470.2", "0", "0", "0"], ["83481.2", "0", "0", "0"], ["83481.6", "0.23961196", "0", "1"], ["83630.6", "0.00011142", "0", "1"]], "bids": [["83466.4", "0", "0", "0"], ["83465.3", "0.0002", "0", "2"], ["83425.3", "0.2514109", "0", "3"], ["83422.6", "0", "0", "0"], ["83333.1", "0.00002212", "0", "1"], ["83332.9", "0.00002031", "0", "1"]], "ts": "1742377435102", "checksum": 493080914, "seqId": 49713712516, "prevSeqId": 49713712496}], "record_time": 1742377435.971512}
{"arg": {"channel": "books", "instId": "BTC-USDT"}, "action": "update", "data": [{"asks": [["83481.6", "0", "0", "0"], ["83483.3", "0.24021705", "0", "2"], ["83630.7", "0.0000484", "0", "1"]], "bids": [["83465.9", "0.0002", "0", "2"], ["83465.3", "0", "0", "0"], ["83432", "0.2", "0", "1"], ["83425.9", "0.23961093", "0", "1"], ["83425.3", "0.01179894", "0", "2"], ["83333.1", "0", "0", "0"], ["83332.9", "0", "0", "0"]], "ts": "1742377435202", "checksum": 1984393764, "seqId": 49713712556, "prevSeqId": 49713712516}], "record_time": 1742377436.069981}
{"arg": {"channel": "books", "instId": "BTC-USDT"}, "action": "update", "data": [{"asks": [["83479.6", "0.01804", "0", "1"], ["83483.3", "0.24021611", "0", "2"], ["83630.7", "0", "0", "0"]], "bids": [["83469.6", "1.49457697", "0", "17"], ["83425.9", "0.23960999", "0", "1"]], "ts": "1742377435302", "checksum": 1714638355, "seqId": 49713712573, "prevSeqId": 49713712556}], "record_time": 1742377436.169766}
{"arg": {"channel": "books", "instId": "BTC-USDT"}, "action": "update", "data": [{"asks": [], "bids": [["83465.9", "0", "0", "0"], ["83465.7", "0.0002", "0", "2"], ["83432", "0", "0", "0"], ["83333.1", "0.00002212", "0", "1"]], "ts": "1742377435402", "checksum": -2138702906, "seqId": 49713712585, "prevSeqId": 49713712573}], "record_time": 1742377436.269708}
{"arg": {"channel": "books", "instId": "BTC-USDT"}, "action": "update", "data": [{"asks": [["83469.7", "2.26185914", "0", "3"], ["83469.8", "0.11690152", "0", "1"], ["83471.2", "0.0001", "0", "1"], ["83471.4", "0.0001", "0", "1"], ["83472", "0.06767934", "0", "2"], ["83477.8", "0", "0", "0"], ["83481.2", "0.23961349", "0", "1"], ["83483.3", "0.00060612", "0", "1"], ["83527.5", "0", "0", "0"], ["83630.6", "0", "0", "0"]], "bids": [["83469.5", "0.1379671", "0", "1"], ["83466.3", "0.0002", "0", "2"], ["83465.7", "0", "0", "0"], ["83436", "0", "0", "0"], ["83425.9", "0", "0", "0"], ["83422.6", "0.23961349", "0", "1"], ["83332.9", "0.00002031", "0", "1"]], "ts": "1742377435602", "checksum": 319976122, "seqId": 49713712624, "prevSeqId": 49713712585}], "record_time": 1742377436.469942}
{"arg": {"channel": "books", "instId": "BTC-USDT"}, "action": "update", "data": [{"asks": [["83471.3", "0.0001", "0", "1"], ["83471.4", "0", "0", "0"], ["83479.2", "0.09907011", "0", "2"], ["83479.4", "0.000015", "0", "1"], ["83492.6", "0.08991011", "0", "1"], ["83527.5", "0.00013267", "0", "1"], ["83630.2", "0", "0", "0"], ["83630.5", "0", "0", "0"]], "bids": [["83469.6", "1.37583042", "0", "16"], ["83469", "0", "0", "0"], ["83466.8", "0.11980563", "0", "1"], ["83466.3", "0.0001", "0", "1"], ["83466.2", "0.6501", "0", "3"], ["83457.5", "0", "0", "0"], ["83454.9", "0.01198098", "0", "1"], ["83436.1", "0", "0", "0"], ["83435.7", "0.01219896", "0", "1"]], "ts": "1742377435702", "checksum": -298817114, "seqId": 49713712652, "prevSeqId": 49713712624}], "record_time": 1742377436.569864}
{"arg": {"channel": "books", "instId": "BTC-USDT"}, "action": "update", "data": [{"asks": [["83471.3", "0", "0", "0"], ["83471.4", "0.0001", "0", "1"], ["83471.9", "0.10861694", "0", "1"], ["83475.3", "0.18020947", "0", "2"], ["83476.9", "0.35941", "0", "1"], ["83544.7", "0", "0", "0"], ["83629.9", "0", "0", "0"]], "bids": [["83466.3", "0", "0", "0"], ["83466.2", "0.6502", "0", "4"], ["83332.8", "0.2025", "0", "1"]], "ts": "1742377435802", "checksum": -190867619, "seqId": 49713712672, "prevSeqId": 49713712652}], "record_time": 1742377436.675548}
{"arg": {"channel": "books", "instId": "BTC-USDT"}, "action": "update", "data": [{"asks": [["83471.2", "0.0002", "0", "2"], ["83471.4", "0", "0", "0"], ["83498", "1.0055", "0", "2"], ["83515.1", "0.90208284", "0", "1"], ["83534.8", "0", "0", "0"], ["83629.9", "0.00002782", "0", "1"]], "bids": [["83466.3", "0.0001", "0", "1"], ["83466.2", "0.6501", "0", "3"], ["83440.9", "0.22193918", "0", "2"], ["83332.8", "0", "0", "0"]], "ts": "1742377435902", "checksum": -1382116089, "seqId": 49713712688, "prevSeqId": 49713712672}], "record_time": 1742377436.77003}
{"arg": {"channel": "books", "instId": "BTC-USDT"}, "action": "update", "data": [{"asks": [], "bids": [["83466.3", "0", "0", "0"], ["83466.2", "0.6502", "0", "4"], ["83332.8", "0.2025", "0", "1"]], "ts": "1742377436002", "checksum": -132438259, "seqId": 49713712698, "prevSeqId": 49713712688}], "record_time": 1742377436.869772}
{"arg": {"channel": "books", "instId": "BTC-USDT"}, "action": "update", "data": [{"asks": [["83476.2", "0.002", "0", "1"], ["83479.1", "0.23961735", "0", "1"], ["83481.2", "0", "0", "0"], ["83486.2", "0.002", "0", "1"], ["83498", "0.0055", "0", "1"], ["83528.6", "0.00378897", "0", "1"], ["83531.2", "0", "0", "0"]], "bids": [["83469.6", "1.30243042", "0", "15"], ["83467.9", "0.002", "0", "1"], ["83466.5", "0.00179828", "0", "3"], ["83466.3", "0.0002", "0", "2"], ["83466.2", "0.65", "0", "2"], ["83457.9", "0.005", "0", "1"], ["83408.5", "0", "0", "0"], ["83408", "0.01845001", "0", "1"], ["83338.2", "0", "0", "0"], ["83337.2", "0.18450015", "0", "1"], ["83332.8", "0", "0", "0"]], "ts": "1742377436102", "checksum": 2024632722, "seqId": 49713712734, "prevSeqId": 49713712698}], "record_time": 1742377436.971697}
{"arg": {"channel": "books", "instId": "BTC-USDT"}, "action": "update", "data": [{"asks": [["83469.7", "2.27283848", "0", "4"], ["83472", "0.0567", "0", "1"], ["83472.8", "0.08991011", "0", "1"], ["83629.9", "0", "0", "0"]], "bids": [["83469.6", "1.24578042", "0", "14"], ["83466.3", "0.0001", "0", "1"], ["83466.2", "0.6501", "0", "3"]], "ts": "1742377436202", "checksum": 1376713009, "seqId": 49713712753, "prevSeqId": 49713712734}], "record_time": 1742377437.069699}
{"arg": {"channel": "books", "instId": "BTC-USDT"}, "action": "update", "data": [{"asks": [["83474.7", "0.01197997", "0", "1"], ["83479.1", "0", "0", "0"], ["83479.9", "0.23961733", "0", "1"], ["83629.5", "0", "0", "0"]], "bids": [["83466.3", "0.0002", "0", "2"], ["83466.2", "0.65", "0", "2"], ["83448.2", "0.01213966", "0", "2"]], "ts": "1742377436302", "checksum": -1160496219, "seqId": 49713712787, "prevSeqId": 49713712753}], "record_time": 1742377437.170384}
{"arg": {"channel": "books", "instId": "BTC-USDT"}, "action": "update", "data": [{"asks": [["83476.2", "0.007", "0", "2"], ["83486.2", "0.007", "0", "2"]], "bids": [["83467.8", "0.005", "0", "1"], ["83457.8", "0.007", "0", "2"], ["83332.9", "0", "0", "0"]], "ts": "1742377436402", "checksum": -2053980663, "seqId": 49713712805, "prevSeqId": 49713712787}], "record_time": 1742377437.269475}
{"arg": {"channel": "books", "instId": "BTC-USDT"}, "action": "update", "data": [{"asks": [["83471.2", "0.0001", "0", "1"], ["83472.4", "0.0001", "0", "1"], ["83479.1", "0.23961766", "0", "1"], ["83479.9", "0", "0", "0"], ["83483.5", "0.16224935", "0", "1"], ["83486", "0.0567", "0", "1"], ["83515.1", "0", "0", "0"], ["83515.2", "0.02960533", "0", "1"], ["83543.7", "0.55728623", "0", "1"], ["83572.7", "0.23458516", "0", "1"], ["83629.3", "0", "0", "0"], ["83629.4", "0", "0", "0"]], "bids": [["83466.3", "0.0001", "0", "1"], ["83466.2", "0.6501", "0", "3"], ["83435.6", "0.41236927", "0", "2"], ["83434.9", "0.15199316", "0", "2"], ["83405.8", "0", "0", "0"], ["83405.7", "0", "0", "0"], ["83332.9", "0.00002031", "0", "1"], ["83332.8", "0.2025", "0", "1"]], "ts": "1742377436502", "checksum": -205771334, "seqId": 49713712834, "prevSeqId": 49713712805}], "record_time": 1742377437.369569}
{"arg": {"channel": "books", "instId": "BTC-USDT"}, "action": "update", "data": [{"asks": [["83471.2", "0", "0", "0"], ["83472.4", "0.0002", "0", "2"], ["83479.1", "0", "0", "0"], ["83479.3", "0.96890793", "0", "3"], ["83479.9", "0.23961748", "0", "1"], ["83482.6", "1.57041808", "0", "1"], ["83496.4", "0", "0", "0"], ["83511.8", "2.83490309", "0", "1"], ["83531.6", "0.01219896", "0", "1"], ["83543.8", "0.07181862", "0", "1"], ["83628.8", "0", "0", "0"]], "bids": [["83466.3", "0.0002", "0", "2"], ["83466.2", "0.65", "0", "2"], ["83436", "1", "0", "1"], ["83435.7", "0", "0", "0"], ["83433.6", "2.57298171", "0", "3"], ["83404.5", "0.8398302", "0", "1"], ["83404.4", "2.79317323", "0", "1"], ["83402.8", "0.01219896", "0", "1"], ["83380.1", "0.0719596", "0", "1"], ["83333.1", "0", "0", "0"], ["83332.9", "0", "0", "0"], ["83332.8", "0", "0", "0"]], "ts": "1742377436602", "checksum": 2060096924, "seqId": 49713712870, "prevSeqId": 49713712834}], "record_time": 1742377437.473812}
{"arg": {"channel": "books", "instId": "BTC-USDT"}, "action": "update", "data": [{"asks": [["83469.8", "0.11710152", "0", "3"], ["83472.4", "0", "0", "0"], ["83479.1", "0.23961777", "0", "1"], ["83479.9", "0", "0", "0"], ["83628.8", "0.00001501", "0", "1"]], "bids": [["83469.6", "1.24564929", "0", "14"], ["83466.3", "0", "0", "0"], ["83462.9", "0.0002", "0", "2"], ["83404.5", "0.84181636", "0", "2"], ["83403.8", "0", "0", "0"], ["83333.1", "0.00002212", "0", "1"]], "ts": "1742377436702", "checksum": -1053801047, "seqId": 49713712920, "prevSeqId": 49713712870}], "record_time": 1742377437.569789}
{"arg": {"channel": "books", "instId": "BTC-USDT"}, "action": "update", "data": [{"asks": [["83543.8", "0.14363724", "0", "2"]], "bids": [["83436", "0", "0", "0"], ["83380.1", "0.1439192", "0", "2"], ["83332.9", "0.00002031", "0", "1"]], "ts": "1742377436802", "checksum": -1053801047, "seqId": 49713712933, "prevSeqId": 49713712920}], "record_time": 1742377437.671706}
{"arg": {"channel": "books", "instId": "BTC-USDT"}, "action": "update", "data": [{"asks": [["83469.7", "2.42877998", "0", "7"], ["83469.8", "0.11690152", "0", "1"], ["83470", "0.0569", "0", "3"], ["83471.7", "0.00916", "0", "1"], ["83475", "0.00171354", "0", "1"], ["83495", "0.2", "0", "1"], ["83496.4", "0.01219896", "0", "1"], ["83531.6", "0", "0", "0"], ["83628.6", "0", "0", "0"], ["83628.8", "0", "0", "0"]], "bids": [["83469.6", "0.62641421", "0", "5"], ["83469.5", "0", "0", "0"], ["83467", "0.14385995", "0", "1"], ["83462.9", "0", "0", "0"], ["83462.7", "0.0001", "0", "1"], ["83462.5", "0.0001", "0", "1"], ["83458.9", "0", "0", "0"], ["83454.9", "0", "0", "0"], ["83452.2", "0", "0", "0"], ["83448.9", "0.37538754", "0", "2"], ["83435.7", "0.01219896", "0", "1"], ["83402.8", "0", "0", "0"], ["83332.8", "0.2025", "0", "1"], ["83332.7", "0.00042773", "0", "1"]], "ts": "1742377436902", "checksum": 160296031, "seqId": 49713712989, "prevSeqId": 49713712933}], "record_time": 1742377437.770236}
{"arg": {"channel": "books", "instId": "BTC-USDT"}, "action": "update", "data": [{"asks": [["83469.8", "0.11710152", "0", "3"], ["83470", "0.0567", "0", "1"], ["83476.8", "0.23962409", "0", "1"], ["83479.1", "0", "0", "0"], ["83495", "0", "0", "0"], ["83511.1", "1.22644109", "0", "3"], ["83543.7", "0", "0", "0"], ["83572.7", "0", "0", "0"], ["83628.6", "0.0000528", "0", "4"], ["83628.8", "0.00001501", "0", "1"], ["83629.3", "0.00058039", "0", "1"]], "bids": [["83462.8", "0.0001", "0", "1"], ["83462.5", "0", "0", "0"], ["83435.6", "1.07242638", "0", "3"], ["83422.6", "0", "0", "0"], ["83421.7", "0.23962409", "0", "1"]], "ts": "1742377437002", "checksum": -1979993971, "seqId": 49713713015, "prevSeqId": 49713712989}], "record_time": 1742377437.871434}
{"arg": {"channel": "books", "instId": "BTC-USDT"}, "action": "update", "data": [{"asks": [["83469.7", "2.43793998", "0", "8"], ["83471.7", "0", "0", "0"], ["83475.2", "0.2396297", "0", "1"], ["83475.3", "0.25421208", "0", "1"], ["83475.7", "0.02748", "0", "1"], ["83476.3", "0.0364628", "0", "2"], ["83476.8", "0", "0", "0"], ["83479.3", "0.93744513", "0", "2"], ["83481.3", "0", "0", "0"], ["83482.2", "0.09168873", "0", "1"], ["83482.5", "0", "0", "0"], ["83483.1", "0.09244024", "0", "1"], ["83483.4", "0.00001206", "0", "1"], ["83483.5", "0.25147214", "0", "2"], ["83483.6", "0.12", "0", "4"], ["83490.1", "0.15464884", "0", "1"], ["83490.4", "0", "0", "0"], ["83491", "0.26941071", "0", "2"], ["83491.2", "0", "0", "0"], ["83496.5", "0", "0", "0"], ["83497.1", "0.26675541", "0", "1"], ["83497.4", "0.15199316", "0", "2"], ["83499", "0.76654445", "0", "2"], ["83499.3", "0", "0", "0"], ["83501", "0.25521161", "0", "1"], ["83501.1", "0.51806255", "0", "1"], ["83534.8", "0.659342", "0", "1"], ["83586.4", "0", "0", "0"], ["83587.5", "0.192881", "0", "1"]], "bids": [["83469.6", "0.2416031", "0", "3"], ["83468.6", "0", "0", "0"], ["83468", "0.005", "0", "1"], ["83465.2", "0.0314628", "0", "1"], ["83462.7", "0", "0", "0"], ["83462.1", "0.0001", "0", "1"], ["83456.6", "0", "0", "0"], ["83456.3", "0.10030922", "0", "1"], ["83456.1", "0", "0", "0"], ["83455.8", "0.24060257", "0", "3"], ["83455.6", "0", "0", "0"], ["83455.5", "0.09736903", "0", "1"], ["83453.1", "0.00087", "0", "1"], ["83449.1", "0", "0", "0"], ["83448.9", "0.35972754", "0", "1"], ["83448.8", "0.16787362", "0", "1"], ["83447.8", "0", "0", "0"], ["83447.6", "0.16883917", "0", "1"], ["83446.6", "0.20565146", "0", "2"], ["83446", "0", "0", "0"], ["83442.1", "0", "0", "0"], ["83441.8", "0.23982241", "0", "1"], ["83440.9", "0.05879252", "0", "1"], ["83440.4", "0.04701", "0", "1"], ["83439.8", "0", "0", "0"], ["83439.5", "0.26339619", "0", "1"], ["83438.1", "0", "0", "0"], ["83438", "0.26254892", "0", "1"], ["83421.7", "0", "0", "0"], ["83419.6", "0.2396297", "0", "1"], ["83404.6", "0.00200122", "0", "2"], ["83404.5", "0.8398302", "0", "1"]], "ts": "1742377437102", "checksum": -1051542007, "seqId": 49713713095, "prevSeqId": 49713713015}], "record_time": 1742377437.971464}
{"arg": {"channel": "books", "instId": "BTC-USDT"}, "action": "update", "data": [{"asks": [["83475.1", "0.23963061", "0", "1"], ["83475.2", "0", "0", "0"], ["83496.4", "0", "0", "0"], ["83497", "0.01219896", "0", "1"]], "bids": [["83466.8", "0", "0", "0"], ["83464.6", "0.11980877", "0", "1"], ["83462.8", "0", "0", "0"], ["83462.7", "0.0002", "0", "2"], ["83462.1", "0", "0", "0"], ["83444.2", "0", "0", "0"], ["83419.6", "0", "0", "0"], ["83418.9", "0.23963046", "0", "1"], ["83374.9", "0", "0", "0"], ["83332.6", "0.00001302", "0", "1"], ["83332.3", "0.00001364", "0", "1"], ["83331.2", "0.00005685", "0", "1"]], "ts": "1742377437202", "checksum": -679430689, "seqId": 49713713122, "prevSeqId": 49713713095}], "record_time": 1742377438.069878}
{"arg": {"channel": "books", "instId": "BTC-USDT"}, "action": "update", "data": [{"asks": [["83469.7", "2.85793998", "0", "9"], ["83469.8", "0.11700152", "0", "2"], ["83470", "0.0568", "0", "2"], ["83473.3", "0.23963327", "0", "1"], ["83474", "0.15377239", "0", "4"], ["83475.1", "0", "0", "0"], ["83481.2", "0.09190614", "0", "1"], ["83481.7", "0", "0", "0"], ["83482.2", "0.09183922", "0", "1"], ["83482.3", "0.09719195", "0", "1"], ["83482.7", "0.09411082", "0", "1"], ["83483.1", "0", "0", "0"], ["83483.5", "0.16224935", "0", "1"], ["83483.9", "0", "0", "0"], ["83489.2", "0.59864043", "0", "2"], ["83489.3", "0.15813058", "0", "1"], ["83489.9", "0.15476999", "0", "1"], ["83490.1", "0", "0", "0"], ["83490.2", "0.11973173", "0", "1"], ["83490.6", "0", "0", "0"], ["83491", "0.28357944", "0", "2"], ["83492.3", "0", "0", "0"], ["83496", "0.26143413", "0", "2"], ["83496.2", "0.24898517", "0", "1"], ["83497.1", "0", "0", "0"], ["83497.2", "0", "0", "0"], ["83498", "0.2595381", "0", "2"], ["83499", "0.5", "0", "1"], ["83499.8", "0.6232046", "0", "2"], ["83501", "0", "0", "0"], ["83527.4", "0.00378912", "0", "1"], ["83528.6", "0", "0", "0"], ["83629.4", "0.00001001", "0", "1"], ["83629.5", "0.00437872", "0", "2"], ["83629.9", "0.00002782", "0", "1"]], "bids": [["83469.6", "0.00411", "0", "1"], ["83462.7", "0", "0", "0"], ["83462.4", "0.09625751", "0", "1"], ["83460.9", "0.0001", "0", "1"], ["83460.6", "0.0001", "0", "1"], ["83458.2", "0", "0", "0"], ["83458.1", "0.27566403", "0", "2"], ["83456.3", "0", "0", "0"], ["83455.8", "0.15199316", "0", "2"], ["83455.5", "0", "0", "0"], ["83455.3", "0.10081348", "0", "1"], ["83455.2", "0", "0", "0"], ["83454.9", "0.09575386", "0", "1"], ["83454.3", "0.1012704", "0", "1"], ["83454", "0.09737962", "0", "1"], ["83449.2", "0.55416284", "0", "3"], ["83448.8", "0", "0", "0"], ["83448.6", "0", "0", "0"], ["83447.9", "0.156258", "0", "1"], ["83447.6", "0", "0", "0"], ["83447.3", "0.15580319", "0", "1"], ["83446.8", "0.0042696", "0", "1"], ["83446.5", "0.15651938", "0", "1"], ["83445.5", "0.32864363", "0", "2"], ["83441.9", "0", "0", "0"], ["83441.8", "0", "0", "0"], ["83440.9", "0.30356071", "0", "2"], ["83440.7", "0.26285971", "0", "1"], ["83439.5", "0", "0", "0"], ["83438.5", "0.26466064", "0", "1"], ["83438", "0", "0", "0"], ["83436.8", "0.23612098", "0", "1"], ["83418.9", "0", "0", "0"], ["83417.1", "0.23963327", "0", "1"], ["83408", "0", "0", "0"], ["83405.1", "0.01845133", "0", "1"], ["83337.2", "0", "0", "0"], ["83334.8", "0.18451338", "0", "1"]], "ts": "1742377437302", "checksum": -1803780979, "seqId": 49713713234, "prevSeqId": 49713713122}], "record_time": 1742377438.170557}
{"arg": {"channel": "books", "instId": "BTC-USDT"}, "action": "update", "data": [{"asks": [["83467.1", "0.73110544", "0", "12"], ["83467.3", "0.10601574", "0", "1"], ["83467.7", "0.0001", "0", "1"], ["83467.9", "0.002157", "0", "1"], ["83468", "0.0567", "0", "1"], ["83468.1", "0.00916", "0", "1"], ["83468.2", "0.0001", "0", "1"], ["83468.9", "0.11980271", "0", "1"], ["83469.4", "0.1", "0", "1"], ["83469.5", "1.17144152", "0", "2"], ["83469.6", "0.42", "0", "1"], ["83469.7", "2.75290506", "0", "5"], ["83469.8", "0", "0", "0"], ["83470", "0.0567", "0", "1"], ["83473.3", "0", "0", "0"], ["83477.3", "0.00105", "0", "1"], ["83477.9", "0.23963119", "0", "1"], ["83479.9", "0.09061272", "0", "1"], ["83480.8", "0.09136464", "0", "1"], ["83481.2", "0", "0", "0"], ["83481.3", "0.09305607", "0", "1"], ["83482.2", "0", "0", "0"], ["83482.3", "0", "0", "0"], ["83482.7", "0", "0", "0"], ["83487.8", "0.16582899", "0", "1"], ["83488", "0.22371072", "0", "2"], ["83488.6", "0.15829239", "0", "1"], ["83489.2", "0", "0", "0"], ["83489.3", "0", "0", "0"], ["83489.7", "0.15693609", "0", "2"], ["83489.9", "0", "0", "0"], ["83491", "0.11977102", "0", "1"], ["83494.6", "0.24964387", "0", "1"], ["83494.8", "0.26557511", "0", "1"], ["83495.8", "0.01219896", "0", "1"], ["83496", "0.000015", "0", "1"], ["83496.2", "0", "0", "0"], ["83496.7", "0.26366867", "0", "1"], ["83497", "0", "0", "0"], ["83498", "0.0055", "0", "1"], ["83498.5", "0.27000142", "0", "1"], ["83499.8", "0.35972754", "0", "1"], ["83509.6", "0.08", "0", "2"], ["83510.4", "0.03999999", "0", "1"], ["83511.2", "0", "0", "0"], ["83521.4", "0", "0", "0"], ["83531.7", "0", "0", "0"], ["83534.8", "0", "0", "0"], ["83539", "0", "0", "0"], ["83559.8", "0.02004994", "0", "2"], ["83628.4", "0", "0", "0"], ["83628.5", "0", "0", "0"], ["83628.6", "0", "0", "0"], ["83628.8", "0", "0", "0"], ["83629.3", "0", "0", "0"], ["83629.4", "0", "0", "0"], ["83629.5", "0", "0", "0"], ["83629.9", "0", "0", "0"]], "bids": [["83469.6", "0", "0", "0"], ["83468", "0", "0", "0"], ["83467.9", "0", "0", "0"], ["83467.8", "0", "0", "0"], ["83467", "0.22995058", "0", "3"], ["83466.9", "0", "0", "0"], ["83464.9", "0.0001", "0", "1"], ["83464.8", "0.0001", "0", "1"], ["83460.9", "0", "0", "0"], ["83460.6", "0", "0", "0"], ["83458.1", "0.17956208", "0", "1"], ["83455.3", "0", "0", "0"], ["83454.9", "0", "0", "0"], ["83454.3", "0", "0", "0"], ["83454", "0.08974101", "0", "1"], ["83453.5", "0.08937789", "0", "1"], ["83452.6", "0.09714932", "0", "1"], ["83449.2", "0.44702482", "0", "2"], ["83447.9", "0", "0", "0"], ["83447.3", "0", "0", "0"], ["83446.5", "0.14892734", "0", "1"], ["83446", "0.16170884", "0", "1"], ["83445.6", "0.00719031", "0", "1"], ["83445.5", "0.16904615", "0", "1"], ["83445.2", "0.14799098", "0", "1"], ["83444.2", "0.1650632", "0", "1"], ["83440.9", "0.05879252", "0", "1"], ["83440.7", "0", "0", "0"], ["83439.5", "0.26058974", "0", "1"], ["83439.3", "0.233692", "0", "1"], ["83438.5", "0", "0", "0"], ["83437.2", "0.23933824", "0", "1"], ["83436.8", "0", "0", "0"], ["83435.7", "0.01592838", "0", "2"], ["83435.5", "0.61128741", "0", "2"], ["83418.9", "0.23963092", "0", "1"], ["83417.1", "0", "0", "0"], ["83366.4", "0.21689429", "0", "2"], ["83331", "0.00001097", "0", "1"], ["83330.8", "0.035909", "0", "1"], ["83330.6", "0.00001852", "0", "1"], ["83330.1", "0.00003016", "0", "2"]], "ts": "1742377437402", "checksum": 1986855993, "seqId": 49713713444, "prevSeqId": 49713713234}], "record_time": 1742377438.273289}
{"arg": {"channel": "books", "instId": "BTC-USDT"}, "action": "update", "data": [{"asks": [["83467.1", "0.74308746", "0", "13"], ["83467.7", "0", "0", "0"], ["83467.9", "0", "0", "0"], ["83468.2", "0", "0", "0"], ["83469", "0.0001", "0", "1"], ["83469.4", "0.1001", "0", "2"], ["83469.7", "2.32092356", "0", "3"], ["83479.8", "0.09604776", "0", "1"], ["83479.9", "0", "0", "0"], ["83480.7", "0.0992065", "0", "1"], ["83480.8", "0", "0", "0"], ["83480.9", "0.08958843", "0", "1"], ["83487.7", "0.16669839", "0", "2"], ["83487.8", "0", "0", "0"], ["83487.9", "0.15961493", "0", "1"], ["83488", "0.0567", "0", "1"], ["83488.5", "0.16261124", "0", "1"], ["83488.6", "0", "0", "0"], ["83489.6", "0.15091256", "0", "1"], ["83489.7", "0.00366233", "0", "1"], ["83494.7", "0.26567718", "0", "1"], ["83494.8", "0", "0", "0"], ["83496.6", "0.26113694", "0", "1"], ["83496.7", "0", "0", "0"], ["83498.4", "0.24310891", "0", "2"], ["83498.5", "0", "0", "0"], ["83508.8", "0.08", "0", "2"], ["83509.6", "0.03999999", "0", "1"], ["83510", "0.001822", "0", "2"], ["83510.4", "0", "0", "0"], ["83511.3", "0.45972754", "0", "2"], ["83513.9", "0", "0", "0"], ["83628.4", "0.00016982", "0", "1"], ["83628.5", "0.00001067", "0", "1"]], "bids": [["83467", "0.14821086", "0", "3"], ["83466", "0.0568", "0", "2"], ["83465.6", "0.0001", "0", "1"], ["83464.9", "0", "0", "0"], ["83464.8", "0", "0", "0"], ["83454", "0", "0", "0"], ["83453.9", "0.45323632", "0", "4"], ["83453.5", "0", "0", "0"], ["83453.4", "0.09943136", "0", "2"], ["83452.9", "0.09710956", "0", "1"], ["83446.5", "0", "0", "0"], ["83446.4", "0.15189702", "0", "1"], ["83446", "0", "0", "0"], ["83445.9", "0.15649186", "0", "1"], ["83445.2", "0", "0", "0"], ["83445.1", "0.15526737", "0", "1"], ["83444.2", "0", "0", "0"], ["83444.1", "0.16173868", "0", "1"], ["83439.5", "0", "0", "0"], ["83439.4", "0.24777062", "0", "1"], ["83437.2", "0", "0", "0"], ["83437.1", "0.25961825", "0", "1"], ["83435.5", "0.35972754", "0", "1"], ["83435.4", "0.29778228", "0", "2"], ["83422.5", "0", "0", "0"], ["83421.6", "0", "0", "0"], ["83419", "0.1", "0", "1"], ["83404.6", "0.00001501", "0", "1"], ["83402.8", "0.00198623", "0", "1"], ["83384.1", "0", "0", "0"], ["83382.1", "0.00276129", "0", "1"], ["83351", "0", "0", "0"], ["83348", "0.00112962", "0", "1"], ["83329.7", "0.00008173", "0", "1"], ["83329.3", "0.00428218", "0", "1"]], "ts": "1742377437502", "checksum": 1819412970, "seqId": 49713713554, "prevSeqId": 49713713444}], "record_time": 1742377438.370096}
{"arg": {"channel": "books", "instId": "BTC-USDT"}, "action": "update", "data": [{"asks": [["83469", "0", "0", "0"], ["83469.4", "0.1", "0", "1"], ["83469.9", "0.0002", "0", "2"], ["83473.4", "0.21101054", "0", "3"], ["83476.3", "0.005", "0", "1"]], "bids": [["83466", "0.0567", "0", "1"], ["83465.8", "0.0002", "0", "2"], ["83465.6", "0", "0", "0"], ["83465.2", "0", "0", "0"], ["83462.3", "0.0314628", "0", "1"]], "ts": "1742377437602", "checksum": 93971724, "seqId": 49713713571, "prevSeqId": 49713713554}], "record_time": 1742377438.470864}
{"arg": {"channel": "books", "instId": "BTC-USDT"}, "action": "update", "data": [{"asks": [["83467.1", "0.84308746", "0", "14"], ["83467.3", "0", "0", "0"], ["83469.4", "0.0001", "0", "1"], ["83469.9", "0.0001", "0", "1"], ["83475.6", "0.23963316", "0", "1"], ["83477.9", "0", "0", "0"], ["83479.7", "0.13985591", "0", "2"], ["83479.8", "0", "0", "0"], ["83480.8", "0.09648093", "0", "1"], ["83480.9", "0", "0", "0"], ["83481.2", "0.09243201", "0", "1"], ["83481.3", "0", "0", "0"], ["83487.8", "0.16438138", "0", "1"], ["83487.9", "0", "0", "0"], ["83494.5", "0.2336306", "0", "1"], ["83494.6", "0", "0", "0"], ["83495.8", "0", "0", "0"], ["83496.5", "0.26017069", "0", "1"], ["83496.6", "0", "0", "0"], ["83498.3", "0.2479441", "0", "2"], ["83498.4", "0.00001206", "0", "1"], ["83628.6", "0.0000528", "0", "4"], ["83628.8", "0.00001501", "0", "1"]], "bids": [["83467", "0.05400807", "0", "3"], ["83466", "0.0568", "0", "2"], ["83465.8", "0.0001", "0", "1"], ["83453.9", "0.36439118", "0", "3"], ["83453.8", "0.34268324", "0", "3"], ["83452.9", "0", "0", "0"], ["83452.8", "0.10055043", "0", "1"], ["83452.6", "0", "0", "0"], ["83452.5", "0.09105483", "0", "1"], ["83445.9", "0", "0", "0"], ["83445.8", "0.28285783", "0", "2"], ["83439.3", "0", "0", "0"], ["83439.2", "0.25572844", "0", "1"], ["83437.1", "0", "0", "0"], ["83437", "0.25865171", "0", "1"], ["83435.4", "0.04", "0", "1"], ["83435.3", "0.26431749", "0", "1"], ["83425.1", "0", "0", "0"], ["83419.1", "0.23963316", "0", "1"], ["83418.9", "0", "0", "0"], ["83408.4", "0.20251205", "0", "2"], ["83400", "0.61730205", "0", "48"], ["83328.8", "0.17953568", "0", "1"]], "ts": "1742377437702", "checksum": 895149906, "seqId": 49713713642, "prevSeqId": 49713713571}], "record_time": 1742377438.570019}
{"arg": {"channel": "books", "instId": "BTC-USDT"}, "action": "update", "data": [{"asks": [["83467.1", "0.73210812", "0", "12"], ["83469.5", "0.96894152", "0", "1"], ["83471.6", "0.01097934", "0", "1"], ["83475.6", "0", "0", "0"], ["83476.8", "0.2396309", "0", "1"], ["83479.7", "0.13858926", "0", "2"], ["83480.8", "0.08950301", "0", "1"], ["83481.2", "0.09577122", "0", "1"], ["83487.8", "0", "0", "0"], ["83487.9", "0.15010105", "0", "1"], ["83489.6", "0.15994041", "0", "1"], ["83494.5", "0.25368507", "0", "1"], ["83496.5", "0.2608101", "0", "1"], ["83498.3", "0.2502247", "0", "2"], ["83543.8", "0.07181862", "0", "1"], ["83628.8", "0", "0", "0"]], "bids": [["83467", "0.10103006", "0", "4"], ["83466", "0.0567", "0", "1"], ["83465.7", "0.0001", "0", "1"], ["83453.8", "0.34940699", "0", "3"], ["83452.8", "0.10088073", "0", "1"], ["83452.5", "0.08843187", "0", "1"], ["83445.9", "0.1610208", "0", "1"], ["83445.8", "0.11983573", "0", "1"], ["83444.1", "0.15110588", "0", "1"], ["83439.2", "0.24269471", "0", "1"], ["83437", "0.26460714", "0", "1"], ["83435.3", "0.26674638", "0", "1"], ["83432", "1", "0", "1"], ["83419.1", "0.23963091", "0", "1"], ["83380.1", "0.0719596", "0", "1"], ["83329.7", "0", "0", "0"], ["83329.3", "0", "0", "0"], ["83328.8", "0", "0", "0"]], "ts": "1742377437802", "checksum": -282705734, "seqId": 49713713752, "prevSeqId": 49713713642}], "record_time": 1742377438.670094}
{"arg": {"channel": "books", "instId": "BTC-USDT"}, "action": "update", "data": [{"asks": [["83467.1", "0.74308746", "0", "13"], ["83469.4", "0", "0", "0"], ["83469.7", "2.32112356", "0", "5"], ["83469.9", "0", "0", "0"], ["83471.6", "0", "0", "0"], ["83473", "0", "0", "0"], ["83479.7", "0.04", "0", "1"], ["83479.8", "0.09691738", "0", "1"], ["83480.8", "0", "0", "0"], ["83480.9", "0.08836646", "0", "1"], ["83481.2", "0", "0", "0"], ["83481.3", "0.09634393", "0", "1"], ["83489.6", "0", "0", "0"], ["83489.7", "0.15855914", "0", "2"], ["83494.5", "0", "0", "0"], ["83494.6", "0.25717018", "0", "1"], ["83496.5", "0", "0", "0"], ["83496.6", "0.25769794", "0", "1"], ["83498.3", "0.01219896", "0", "1"], ["83498.4", "0.24014335", "0", "2"], ["83543.8", "0", "0", "0"], ["83600.2", "0.38675957", "0", "1"], ["83628.8", "0.00001501", "0", "1"], ["83629.3", "0.00058039", "0", "1"], ["83629.4", "0.00001001", "0", "1"], ["83629.5", "0.00437872", "0", "2"]], "bids": [["83467", "0.17045119", "0", "6"], ["83465.8", "0", "0", "0"], ["83465.7", "0", "0", "0"], ["83463.4", "0.0002", "0", "2"], ["83453.9", "0.46402972", "0", "4"], ["83453.8", "0.24999146", "0", "2"], ["83453.1", "0", "0", "0"], ["83452.9", "0.10098073", "0", "1"], ["83452.8", "0", "0", "0"], ["83452.6", "0.09387908", "0", "1"], ["83452.5", "0", "0", "0"], ["83450.9", "0", "0", "0"], ["83444.2", "0.15807078", "0", "1"], ["83444.1", "0", "0", "0"], ["83439.3", "0.24505447", "0", "1"], ["83439.2", "0", "0", "0"], ["83437.1", "0.24552233", "0", "1"], ["83437", "0", "0", "0"], ["83435.4", "0.2863721", "0", "2"], ["83435.3", "0", "0", "0"], ["83432", "0", "0", "0"], ["83380.1", "0", "0", "0"], ["83329.7", "0.00008173", "0", "1"], ["83329.3", "0.00428218", "0", "1"], ["83328.8", "0.17953568", "0", "1"], ["83328.7", "0.11992025", "0", "1"], ["83328.4", "0.00001206", "0", "1"], ["83328.3", "0.0004012", "0", "1"]], "ts": "1742377437902", "checksum": 1021307390, "seqId": 49713713819, "prevSeqId": 49713713752}], "record_time": 1742377439.777247}
{"arg": {"channel": "books", "instId": "BTC-USDT"}, "action": "update", "data": [{"asks": [["83469.7", "2.32092356", "0", "3"], ["83469.8", "0.0002", "0", "2"], ["83473", "0.00239598", "0", "1"], ["83476.8", "0", "0", "0"], ["83477.9", "0.23962908", "0", "1"], ["83479.7", "0.13281952", "0", "2"], ["83479.8", "0", "0", "0"], ["83480.8", "0.08852142", "0", "1"], ["83480.9", "0", "0", "0"], ["83481.2", "0.09329188", "0", "1"], ["83481.3", "0", "0", "0"], ["83489.6", "0.16506231", "0", "1"], ["83489.7", "0.00366233", "0", "1"], ["83494.5", "0.24746274", "0", "1"], ["83494.6", "0", "0", "0"], ["83496.5", "0.26769505", "0", "1"], ["83496.6", "0", "0", "0"], ["83498.3", "0.88091418", "0", "3"], ["83498.4", "0.00001206", "0", "1"], ["83521.4", "0.2434715", "0", "1"], ["83543.8", "0.14363724", "0", "2"], ["83628.8", "0", "0", "0"], ["83629.3", "0", "0", "0"], ["83629.4", "0", "0", "0"], ["83629.5", "0", "0", "0"]], "bids": [["83467", "0.10187119", "0", "5"], ["83466.2", "0.52", "0", "1"], ["83453.9", "0.36439118", "0", "3"], ["83453.8", "0.34164053", "0", "3"], ["83452.9", "0", "0", "0"], ["83452.8", "0.09529908", "0", "1"], ["83452.6", "0", "0", "0"], ["83452.5", "0.09498511", "0", "1"], ["83450.9", "0.00239661", "0", "1"], ["83444.2", "0", "0", "0"], ["83444.1", "0.15833266", "0", "1"], ["83439.3", "0", "0", "0"], ["83439.2", "0.26314237", "0", "1"], ["83437.1", "0", "0", "0"], ["83437", "0.26074085", "0", "1"], ["83435.4", "0.04", "0", "1"], ["83435.3", "0.24829896", "0", "1"], ["83426.6", "0.38160056", "0", "1"], ["83420.5", "0.23962908", "0", "1"], ["83419.1", "0", "0", "0"], ["83380.1", "0.1439192", "0", "2"], ["83328.8", "0", "0", "0"], ["83328.7", "0", "0", "0"], ["83328.4", "0", "0", "0"], ["83328.3", "0", "0", "0"]], "ts": "1742377438002", "checksum": 1718871932, "seqId": 49713713886, "prevSeqId": 49713713819}], "record_time": 1742377439.77918}
{"arg": {"channel": "books", "instId": "BTC-USDT"}, "action": "update", "data": [{"asks": [["83469.4", "0.42", "0", "1"], ["83469.8", "0", "0", "0"], ["83469.9", "0.0002", "0", "2"], ["83472.8", "0", "0", "0"], ["83476.3", "0", "0", "0"], ["83476.8", "0.23963074", "0", "1"], ["83477.9", "0", "0", "0"], ["83486.3", "0", "0", "0"], ["83500.4", "0.02960533", "0", "1"], ["83515.2", "0", "0", "0"], ["83523.8", "0.00013267", "0", "1"], ["83525.9", "0.11659206", "0", "3"], ["83527.4", "0", "0", "0"], ["83527.5", "0", "0", "0"], ["83628.8", "0.00001501", "0", "1"], ["83629.3", "0.00058039", "0", "1"], ["83629.4", "0.00001001", "0", "1"]], "bids": [["83463.4", "0", "0", "0"], ["83462.4", "0.09645751", "0", "3"], ["83457.9", "0", "0", "0"], ["83420.5", "0", "0", "0"], ["83419.6", "0.23963074", "0", "1"], ["83402.8", "0", "0", "0"], ["83402", "0.00198624", "0", "1"], ["83380.5", "0", "0", "0"], ["83377.9", "0.00008831", "0", "1"], ["83328.8", "0.17953568", "0", "1"], ["83328.7", "0.11992025", "0", "1"]], "ts": "1742377438102", "checksum": 1107380245, "seqId": 49713713931, "prevSeqId": 49713713886}], "record_time": 1742377439.780576}
{"arg": {"channel": "books", "instId": "BTC-USDT"}, "action": "update", "data": [{"asks": [["83467.1", "0.78388186", "0", "15"], ["83468.1", "0", "0", "0"], ["83469.5", "0.70254707", "0", "1"], ["83469.6", "0", "0", "0"], ["83469.7", "2.28492356", "0", "2"], ["83469.8", "0.0002", "0", "2"], ["83469.9", "0", "0", "0"], ["83472.4", "0.00916", "0", "1"], ["83475.9", "0.23963061", "0", "1"], ["83476.8", "0", "0", "0"], ["83477.3", "0", "0", "0"], ["83479.7", "0.04", "0", "1"], ["83479.9", "0.09502239", "0", "1"], ["83480.7", "0", "0", "0"], ["83480.8", "0.0981651", "0", "1"], ["83481", "0.10079151", "0", "1"], ["83481.2", "0", "0", "0"], ["83481.3", "0.0962353", "0", "1"], ["83487.7", "0.000015", "0", "1"], ["83487.8", "0.1677338", "0", "1"], ["83487.9", "0", "0", "0"], ["83488", "0.21435074", "0", "2"], ["83488.5", "0", "0", "0"], ["83488.6", "0.15800896", "0", "1"], ["83489.6", "0", "0", "0"], ["83489.7", "0.17130752", "0", "2"], ["83494.5", "0", "0", "0"], ["83494.6", "0.2449867", "0", "1"], ["83494.7", "0", "0", "0"], ["83494.8", "0.24164642", "0", "1"], ["83496.5", "0", "0", "0"], ["83496.7", "0.24687154", "0", "1"], ["83498.3", "0.63873813", "0", "2"], ["83498.5", "0.25961801", "0", "1"], ["83525.9", "0.11280294", "0", "2"], ["83527.5", "0.00378912", "0", "1"], ["83548.8", "0.16035231", "0", "1"], ["83629.4", "0", "0", "0"]], "bids": [["83467", "0.55579211", "0", "8"], ["83463.5", "0.00011206", "0", "2"], ["83463.3", "0.05565555", "0", "2"], ["83462.4", "0.09625751", "0", "1"], ["83454", "0.09251164", "0", "1"], ["83453.8", "0.24999146", "0", "2"], ["83453.5", "0.0963066", "0", "1"], ["83453.4", "0.00001204", "0", "1"], ["83453", "0.0946499", "0", "1"], ["83452.8", "0", "0", "0"], ["83452.6", "0.0910121", "0", "1"], ["83452.5", "0", "0", "0"], ["83452.2", "0.01566", "0", "1"], ["83451.9", "0.0009", "0", "1"], ["83446.6", "0.18999146", "0", "1"], ["83446.5", "0.15476826", "0", "1"], ["83446.4", "0", "0", "0"], ["83446", "0.20789766", "0", "2"], ["83445.9", "0", "0", "0"], ["83445.2", "0.15716514", "0", "1"], ["83445.1", "0", "0", "0"], ["83445", "0", "0", "0"], ["83444.2", "0.14756167", "0", "1"], ["83444.1", "0", "0", "0"], ["83440.4", "0", "0", "0"], ["83439.5", "0.23579514", "0", "1"], ["83439.4", "0", "0", "0"], ["83439.3", "0.2584308", "0", "1"], ["83439.2", "0", "0", "0"], ["83437.2", "0.2683751", "0", "1"], ["83437", "0", "0", "0"], ["83435.5", "0.6130344", "0", "2"], ["83435.3", "0", "0", "0"], ["83419.6", "0.23963061", "0", "1"], ["83328.7", "0", "0", "0"]], "ts": "1742377438202", "checksum": -1429996571, "seqId": 49713714047, "prevSeqId": 49713713931}], "record_time": 1742377439.782154}
{"arg": {"channel": "books", "instId": "BTC-USDT"}, "action": "update", "data": [{"asks": [["83468.7", "0.005", "0", "1"], ["83469.4", "0", "0", "0"], ["83469.8", "0", "0", "0"], ["83470", "0.0569", "0", "3"], ["83475.9", "0", "0", "0"], ["83476.7", "0.23962901", "0", "1"], ["83477.7", "0.000117", "0", "1"], ["83478.8", "0.005", "0", "1"], ["83629.3", "0", "0", "0"]], "bids": [["83467", "0.55464316", "0", "8"], ["83465.3", "0.005", "0", "1"], ["83463.6", "0.0002", "0", "2"], ["83463.5", "0.00001206", "0", "1"], ["83463.3", "0.05555555", "0", "1"], ["83455.2", "0.005", "0", "1"], ["83445.2", "0.28988614", "0", "2"], ["83435.7", "0.01219896", "0", "1"], ["83420.1", "0.24030976", "0", "2"], ["83419.6", "0", "0", "0"], ["83329.3", "0", "0", "0"], ["83328.8", "0", "0", "0"]], "ts": "1742377438302", "checksum": -1363175195, "seqId": 49713714088, "prevSeqId": 49713714047}], "record_time": 1742377439.783946}
{"arg": {"channel": "books", "instId": "BTC-USDT"}, "action": "update", "data": [{"asks": [["83467.1", "0.76027086", "0", "14"], ["83469.9", "0.0002", "0", "2"], ["83470", "0.0567", "0", "1"], ["83476.7", "0", "0", "0"], ["83476.8", "0.2396291", "0", "1"], ["83628.8", "0", "0", "0"]], "bids": [["83467", "0.52394316", "0", "7"], ["83420.1", "0.24030985", "0", "2"], ["83406.3", "0.0157056", "0", "2"], ["83372.4", "0", "0", "0"], ["83366.4", "0.2025", "0", "1"], ["83329.3", "0.00428218", "0", "1"]], "ts": "1742377438402", "checksum": 2079624271, "seqId": 49713714111, "prevSeqId": 49713714088}], "record_time": 1742377439.785448}
{"arg": {"channel": "books", "instId": "BTC-USDT"}, "action": "update", "data": [{"asks": [["83541", "0", "0", "0"], ["83628.8", "0.00001501", "0", "1"]], "bids": [["83406.3", "0.00373074", "0", "1"], ["83405.5", "0.01197473", "0", "1"], ["83342.7", "0.00723702", "0", "1"], ["83330.4", "0.0144005", "0", "1"], ["83330.1", "0", "0", "0"], ["83329.7", "0", "0", "0"], ["83329.3", "0", "0", "0"]], "ts": "1742377438502", "checksum": 2079624271, "seqId": 49713714129, "prevSeqId": 49713714111}], "record_time": 1742377439.786465}
{"arg": {"channel": "books", "instId": "BTC-USDT"}, "action": "update", "data": [{"asks": [["83543.8", "0.07181862", "0", "1"]], "bids": [["83380.1", "0.0719596", "0", "1"]], "ts": "1742377438602", "checksum": 2079624271, "seqId": 49713714137, "prevSeqId": 49713714129}], "record_time": 1742377439.787181}
{"arg": {"channel": "books", "instId": "BTC-USDT"}, "action": "update", "data": [{"asks": [["83467.1", "0.78098573", "0", "15"], ["83469.9", "0", "0", "0"], ["83470.4", "0.0002", "0", "2"], ["83475.2", "0.23963121", "0", "1"], ["83476.8", "0", "0", "0"]], "bids": [["83420.1", "0.00068075", "0", "1"], ["83419.1", "0.23963121", "0", "1"], ["83330.4", "0", "0", "0"]], "ts": "1742377438702", "checksum": 250417468, "seqId": 49713714174, "prevSeqId": 49713714137}], "record_time": 1742377439.78788}
{"arg": {"channel": "books", "instId": "BTC-USDT"}, "action": "update", "data": [{"asks": [["83467.1", "0.84090155", "0", "16"], ["83524", "0.01465116", "0", "1"], ["83543.8", "0.14363724", "0", "2"], ["83628.8", "0", "0", "0"]], "bids": [["83467", "0.55464316", "0", "8"], ["83380.1", "0.1439192", "0", "2"]], "ts": "1742377438802", "checksum": 1680701843, "seqId": 49713714193, "prevSeqId": 49713714174}], "record_time": 1742377439.788599}
{"arg": {"channel": "books", "instId": "BTC-USDT"}, "action": "update", "data": [{"asks": [["83470.4", "0", "0", "0"], ["83470.7", "0.0002", "0", "2"], ["83471.9", "0.19466955", "0", "2"], ["83473.3", "0.23963581", "0", "1"], ["83475.2", "0", "0", "0"]], "bids": [["83467", "0.48504316", "0", "6"], ["83419.1", "0", "0", "0"], ["83416.9", "0.24553528", "0", "2"], ["83416", "0.08039992", "0", "3"], ["83409.8", "0", "0", "0"], ["83408.4", "0.79908082", "0", "3"], ["83368.1", "0.00002977", "0", "1"], ["83366.7", "0.5808447", "0", "1"], ["83330.4", "0.0144005", "0", "1"]], "ts": "1742377438902", "checksum": -1238309506, "seqId": 49713714219, "prevSeqId": 49713714193}], "record_time": 1742377439.789348}
