{"arg": {"channel": "books", "instId": "BTC-USDT"}, "action": "snapshot", "data": [{"asks": [["83854.1", "0.77723444", "0", "11"], ["83854.2", "0.0224404", "0", "1"], ["83854.3", "0.01967", "0", "1"], ["83855.5", "0.008", "0", "1"], ["83855.6", "0.01193132", "0", "1"], ["83856", "0.0352", "0", "1"], ["83856.8", "0.0036341", "0", "1"], ["83857.6", "0.12285841", "0", "2"], ["83857.8", "0.2545", "0", "3"], ["83858", "0.0352", "0", "1"], ["83858.8", "0.03868101", "0", "1"], ["83860.1", "0.052", "0", "2"], ["83860.2", "0.05902", "0", "1"], ["83861.7", "0.12327613", "0", "2"], ["83861.9", "0.052", "0", "2"], ["83862", "0.10050332", "0", "2"], ["83862.1", "0.0682544", "0", "1"], ["83862.5", "0.000012", "0", "1"], ["83862.6", "0.02722338", "0", "1"], ["83862.7", "0.05968388", "0", "1"], ["83863.2", "0.052", "0", "2"], ["83863.5", "0.06206015", "0", "1"], ["83863.7", "0.052", "0", "2"], ["83864", "0.0352", "0", "1"], ["83865.9", "0.36926118", "0", "2"], ["83866", "0.0352", "0", "1"], ["83866.5", "0.06719814", "0", "1"], ["83866.8", "0.00880037", "0", "1"], ["83867.4", "0.000012", "0", "1"], ["83867.6", "0.17915015", "0", "1"], ["83867.7", "0.35819548", "0", "1"], ["83867.9", "0.25927207", "0", "4"], ["83868", "0.0352", "0", "1"], ["83868.3", "0.09743758", "0", "1"], ["83869.6", "0.005", "0", "1"], ["83869.7", "0.000015", "0", "1"], ["83870.8", "0.01967", "0", "1"], ["83871.2", "0.00422796", "0", "1"], ["83871.3", "0.18501126", "0", "1"], ["83871.5", "0.40031", "0", "3"], ["83871.6", "0.1409635", "0", "1"], ["83872", "0.0352", "0", "1"], ["83872.3", "0.09750075", "0", "1"], ["83872.4", "0.000012", "0", "1"], ["83874", "0.0452", "0", "2"], ["83874.2", "0.08991011", "0", "1"], ["83874.8", "0.02386212", "0", "1"], ["83875.2", "1.61804212", "0", "2"], ["83875.4", "0.17888", "0", "1"], ["83875.7", "0.01192938", "0", "1"], ["83876.2", "0.35776", "0", "1"], ["83876.5", "0.10192571", "0", "2"], ["83877.2", "0.12", "0", "1"], ["83877.3", "0.117012", "0", "2"], ["83877.4", "0.53734563", "0", "2"], ["83877.5", "0.16637192", "0", "1"], ["83877.7", "0.15440167", "0", "1"], ["83877.9", "0.2025", "0", "1"], ["83878.1", "0.052015", "0", "3"], ["83878.2", "0.20210647", "0", "1"], ["83878.9", "0.04", "0", "1"], ["83879.7", "0.005", "0", "1"], ["83879.9", "0.21", "0", "2"], ["83880.1", "0.2025", "0", "1"], ["83880.5", "0.08636509", "0", "4"], ["83880.7", "0.23863209", "0", "1"], ["83880.8", "0.21", "0", "2"], ["83881", "0.17185613", "0", "1"], ["83881.3", "0.00422712", "0", "1"], ["83881.4", "0.00005728", "0", "1"], ["83881.9", "0.11933395", "0", "1"], ["83882", "0.04", "0", "1"], ["83882.3", "0.11928394", "0", "2"], ["83882.5", "0.34635032", "0", "1"], ["83882.6", "0.0165", "0", "1"], ["83883", "0.13566", "0", "1"], ["83883.3", "0.00060645", "0", "1"], ["83883.7", "0.02823758", "0", "1"], ["83884.4", "0.1127708", "0", "2"], ["83884.5", "0.48884635", "0", "2"], ["83885.9", "0.00011161", "0", "1"], ["83886.2", "0.00016529", "0", "1"], ["83886.4", "0.17411566", "0", "1"], ["83886.5", "0.00001501", "0", "1"], ["83886.6", "0.06297976", "0", "2"], ["83887.1", "0.17915015", "0", "1"], ["83887.2", "0.00001201", "0", "1"], ["83887.5", "0.3782572", "0", "1"], ["83887.8", "0.35819548", "0", "1"], ["83887.9", "0.2025", "0", "1"], ["83888", "0.12519", "0", "1"], ["83888.3", "0.01787779", "0", "1"], ["83888.4", "0.00884689", "0", "1"], ["83888.8", "0.00007589", "0", "1"], ["83889.3", "0.13233938", "0", "1"], ["83889.4", "0.02693528", "0", "1"], ["83889.6", "0.25038", "0", "1"], ["83889.7", "0.0005", "0", "1"], ["83889.8", "0.0005", "0", "1"], ["83890.2", "0.002", "0", "1"], ["83890.3", "0.05966709", "0", "1"], ["83890.4", "0.00422588", "0", "1"], ["83891.2", "0.18596666", "0", "3"], ["83891.3", "0.18795133", "0", "1"], ["83891.8", "0.08991011", "0", "1"], ["83892.1", "0.00001201", "0", "1"], ["83893", "0.00357", "0", "1"], ["83893.8", "0.11933395", "0", "1"], ["83894.9", "0.11278581", "0", "3"], ["83895.4", "0.0005", "0", "1"], ["83895.5", "0.44664635", "0", "1"], ["83895.6", "0.00422588", "0", "1"], ["83896.4", "0.00010514", "0", "1"], ["83896.5", "0.3577103", "0", "1"], ["83896.8", "2.32136", "0", "1"], ["83897.1", "0.000012", "0", "1"], ["83897.5", "0.04972", "0", "1"], ["83897.8", "0.17915015", "0", "1"], ["83898.1", "0.11924957", "0", "1"], ["83898.2", "0.00336031", "0", "2"], ["83898.5", "0.1", "0", "1"], ["83899", "0.093112", "0", "1"], ["83899.2", "0.01", "0", "1"], ["83899.7", "0.27350337", "0", "1"], ["83899.8", "0.1409635", "0", "1"], ["83899.9", "0.00101534", "0", "2"], ["83900", "0.26261038", "0", "8"], ["83900.3", "0.002", "0", "1"], ["83901.2", "0.23628", "0", "1"], ["83902", "0.00001201", "0", "1"], ["83902.3", "0.00357", "0", "1"], ["83902.6", "0.11933395", "0", "1"], ["83903.3", "0.00001501", "0", "1"], ["83903.8", "0.867244", "0", "1"], ["83903.9", "0.21351817", "0", "1"], ["83904.4", "0.00100225", "0", "1"], ["83904.7", "0.58761173", "0", "2"], ["83904.8", "0.08", "0", "2"], ["83905", "0.00009125", "0", "1"], ["83905.3", "0.3577103", "0", "1"], ["83905.4", "0.1127708", "0", "2"], ["83905.5", "0.00023813", "0", "2"], ["83905.6", "0.03999999", "0", "1"], ["83906.2", "0.17915015", "0", "1"], ["83906.6", "0.00423459", "0", "2"], ["83906.7", "0.01672", "0", "1"], ["83907", "0.000012", "0", "1"], ["83907.1", "0.08991011", "0", "1"], ["83908.1", "1.53386491", "0", "1"], ["83908.4", "0.2025", "0", "1"], ["83908.7", "0.02384687", "0", "1"], ["83908.9", "0.12519", "0", "1"], ["83909", "0.00003887", "0", "1"], ["83910.1", "0.04769183", "0", "1"], ["83910.4", "0.0008", "0", "2"], ["83910.6", "0.25038", "0", "1"], ["83911.2", "0.0004", "0", "1"], ["83911.7", "0.40001501", "0", "2"], ["83911.9", "0.00001201", "0", "1"], ["83912", "0.00001", "0", "1"], ["83912.7", "0.0054", "0", "1"], ["83912.8", "0.00100335", "0", "1"], ["83912.9", "0.00357", "0", "1"], ["83913", "0.00002241", "0", "1"], ["83913.4", "0.11510149", "0", "1"], ["83914.4", "0.11881882", "0", "1"], ["83914.6", "0.01193018", "0", "1"], ["83915.2", "0.35763993", "0", "1"], ["83915.4", "0.00422261", "0", "1"], ["83915.5", "0.00008624", "0", "1"], ["83915.6", "0.08938", "0", "1"], ["83916.3", "0.00074396", "0", "1"], ["83916.6", "0.00102991", "0", "3"], ["83916.9", "0.01791201", "0", "2"], ["83919.2", "0.00003542", "0", "1"], ["83919.4", "0.00422261", "0", "1"], ["83920.1", "0.00001501", "0", "1"], ["83921.7", "0.27049517", "0", "1"], ["83921.9", "0.000012", "0", "1"], ["83922.3", "0.39931444", "0", "1"], ["83922.4", "0.472349", "0", "1"], ["83922.8", "0.11940904", "0", "1"], ["83923", "0.17915015", "0", "1"], ["83924", "0.35763993", "0", "1"], ["83924.1", "0.01652", "0", "1"], ["83924.2", "0.2025", "0", "1"], ["83924.5", "0.0238424", "0", "1"], ["83925", "0.00027354", "0", "1"], ["83925.2", "0.00011161", "0", "1"], ["83925.4", "0.00008", "0", "1"], ["83926.1", "0.00007814", "0", "1"], ["83926.8", "0.00001201", "0", "1"], ["83928.5", "0.000015", "0", "1"], ["83928.6", "0.00001501", "0", "1"], ["83929", "0.01271806", "0", "1"], ["83929.1", "0.01788255", "0", "1"], ["83929.9", "0.00007143", "0", "1"], ["83930.2", "0.00011444", "0", "1"], ["83930.5", "0.06", "0", "2"], ["83930.7", "0.00001805", "0", "1"], ["83931.2", "0.11940904", "0", "1"], ["83931.4", "0.17915015", "0", "1"], ["83931.5", "0.07148689", "0", "1"], ["83931.8", "0.000012", "0", "1"], ["83932", "0.00422144", "0", "1"], ["83932.8", "0.21124007", "0", "1"], ["83932.9", "0.35714307", "0", "1"], ["83933.3", "0.00513921", "0", "5"], ["83933.8", "0.00011938", "0", "1"], ["83934.4", "0.2025", "0", "1"], ["83935.1", "0.00595", "0", "1"], ["83935.2", "0.00184777", "0", "2"], ["83935.3", "0.00714836", "0", "1"], ["83936.4", "0.11919513", "0", "1"], ["83936.7", "0.00001201", "0", "1"], ["83936.9", "0.00001501", "0", "1"], ["83937.7", "0.03", "0", "1"], ["83938.4", "0.00001881", "0", "1"], ["83939.4", "0.00422144", "0", "1"], ["83939.8", "1.47945715", "0", "2"], ["83940.1", "3.68547", "0", "2"], ["83940.4", "0.08991011", "0", "1"], ["83941.1", "0.00001805", "0", "1"], ["83941.7", "0.00001201", "0", "1"], ["83941.8", "0.00596247", "0", "1"], ["83941.9", "0.0042203", "0", "1"], ["83942.2", "0.20030019", "0", "1"], ["83942.3", "0.37165859", "0", "3"], ["83942.9", "0.03", "0", "1"], ["83943.1", "0.071477", "0", "1"], ["83943.5", "0.00001201", "0", "1"], ["83943.7", "0.00714127", "0", "2"], ["83943.8", "0.2025", "0", "1"], ["83944.1", "0.02385106", "0", "1"], ["83944.2", "0.00023861", "0", "1"], ["83944.8", "0.00011161", "0", "1"], ["83945.3", "0.000015", "0", "1"], ["83945.5", "0.16237756", "0", "1"], ["83945.6", "0.13959", "0", "1"], ["83946", "0.01736", "0", "1"], ["83946.3", "0.08935", "0", "1"], ["83947.3", "0.00103744", "0", "1"], ["83948", "0.11940904", "0", "1"], ["83949.6", "0.17915015", "0", "1"], ["83949.9", "0.00060645", "0", "1"], ["83950", "0.00013393", "0", "2"], ["83950.6", "0.17863276", "0", "1"], ["83950.7", "0.35714307", "0", "1"], ["83951.6", "0.00001201", "0", "1"], ["83952.5", "0.2025", "0", "1"], ["83953.7", "0.000015", "0", "1"], ["83955", "0.04260751", "0", "1"], ["83955.1", "0.03596146", "0", "2"], ["83955.8", "0.00001201", "0", "1"], ["83956", "0.000164", "0", "1"], ["83956.3", "0.00166789", "0", "1"], ["83956.7", "0.1", "0", "1"], ["83957.9", "0.00421967", "0", "1"], ["83958.3", "0.00006056", "0", "1"], ["83959.1", "0.00001008", "0", "1"], ["83959.7", "0.00596132", "0", "1"], ["83959.8", "0.14578123", "0", "2"], ["83959.9", "0.35715329", "0", "2"], ["83960", "0.0001237", "0", "2"], ["83960.3", "0.02384829", "0", "1"], ["83960.5", "0.08991011", "0", "1"], ["83960.9", "0.2025", "0", "1"], ["83961.5", "0.00001201", "0", "1"], ["83962.1", "0.002215", "0", "2"], ["83962.6", "0.75123", "0", "1"], ["83962.9", "0.00350166", "0", "1"], ["83964.4", "0.00011161", "0", "1"], ["83964.8", "0.11940904", "0", "1"], ["83965.1", "0.00421829", "0", "1"], ["83965.4", "0.17915015", "0", "1"], ["83965.5", "0.5999", "0", "1"], ["83966.4", "0.00001201", "0", "1"], ["83966.6", "0.00460884", "0", "3"], ["83967.1", "0.07125036", "0", "1"], ["83967.2", "0.00001506", "0", "1"], ["83967.4", "0.0001387", "0", "1"], ["83967.7", "0.00003999", "0", "1"], ["83968", "0.00325845", "0", "1"], ["83968.2", "0.00001201", "0", "1"], ["83969", "0.00005514", "0", "1"], ["83969.1", "0.08360408", "0", "1"], ["83969.2", "0.19586966", "0", "1"], ["83969.3", "0.2025", "0", "1"], ["83969.5", "0.08991011", "0", "1"], ["83969.9", "0.00213979", "0", "1"], ["83970.5", "0.000015", "0", "1"], ["83970.6", "0.35714307", "0", "1"], ["83970.9", "0.00002848", "0", "1"], ["83971.3", "0.03", "0", "1"], ["83971.4", "0.00068775", "0", "1"], ["83971.9", "0.07102314", "0", "1"], ["83973.7", "0.00580006", "0", "1"], ["83973.8", "0.17915015", "0", "1"], ["83973.9", "0.17321762", "0", "2"], ["83974.3", "0.00003392", "0", "1"], ["83974.6", "0.00003453", "0", "1"], ["83975", "0.00010892", "0", "3"], ["83975.5", "0.00298666", "0", "1"], ["83976.3", "0.00001201", "0", "1"], ["83977.7", "0.2025", "0", "1"], ["83978.9", "0.00221501", "0", "1"], ["83979.1", "0.0357617", "0", "1"], ["83979.5", "0.0000434", "0", "1"], ["83979.7", "0.35714307", "0", "1"], ["83980", "0.00005452", "0", "1"], ["83981.3", "0.00001201", "0", "1"], ["83981.5", "0.0000568", "0", "1"], ["83981.6", "0.11940904", "0", "1"], ["83981.9", "0.00004916", "0", "1"], ["83982.2", "0.17915015", "0", "1"], ["83982.4", "0.06421639", "0", "3"], ["83983", "0.00001115", "0", "1"], ["83983.2", "0.05700028", "0", "1"], ["83983.3", "0.00060645", "0", "1"], ["83983.9", "0.99955", "0", "1"], ["83984", "0.00001189", "0", "1"], ["83984.1", "0.00011161", "0", "1"], ["83984.9", "0.00597332", "0", "1"], ["83985.7", "0.00001675", "0", "1"], ["83985.8", "0.0000326", "0", "1"], ["83986.1", "0.20274832", "0", "2"], ["83986.2", "0.10056212", "0", "3"], ["83987.8", "0.00007302", "0", "1"], ["83987.9", "0.00037549", "0", "1"], ["83988", "0.01096012", "0", "1"], ["83988.1", "0.35714307", "0", "1"], ["83988.7", "0.00001565", "0", "1"], ["83989.3", "0.00001096", "0", "1"], ["83989.6", "0.183706", "0", "1"], ["83990.3", "0.00009227", "0", "1"], ["83990.8", "0.00421548", "0", "1"], ["83991.2", "0.00001201", "0", "1"], ["83992.2", "0.00596248", "0", "1"], ["83992.4", "0.00201868", "0", "1"], ["83992.6", "0.00001005", "0", "1"], ["83992.9", "0.00001201", "0", "1"], ["83993.4", "0.00895999", "0", "1"], ["83993.7", "0.03", "0", "1"], ["83994.3", "0.00001328", "0", "1"], ["83994.5", "0.2025", "0", "1"], ["83995.3", "0.00005488", "0", "1"], ["83995.9", "0.00001678", "0", "1"], ["83997.8", "0.35714307", "0", "1"], ["83998.1", "0.1074", "0", "1"], ["83998.4", "0.12271125", "0", "2"], ["83998.9", "0.08932", "0", "1"], ["83999", "0.17915015", "0", "1"], ["83999.7", "0.214627", "0", "1"], ["83999.9", "0.07467821", "0", "16"], ["84000", "0.31072751", "0", "69"], ["84001.1", "0.00001201", "0", "1"], ["84001.2", "0.00011542", "0", "2"], ["84001.8", "0.01194665", "0", "1"], ["84002", "0.0025", "0", "1"], ["84002.7", "0.1985", "0", "1"], ["84002.9", "0.2025", "0", "1"], ["84003", "0.0025", "0", "1"], ["84003.3", "0.00024979", "0", "1"], ["84003.7", "0.00011161", "0", "1"], ["84004.3", "0.0110717", "0", "5"], ["84004.9", "0.00002943", "0", "2"], ["84005.2", "0.000012", "0", "1"], ["84005.4", "0.002388", "0", "1"], ["84007", "0.01933267", "0", "2"], ["84007.9", "0.35714307", "0", "1"], ["84008.2", "0.05965622", "0", "1"], ["84008.3", "0.00001363", "0", "1"], ["84009", "0.01788693", "0", "3"], ["84009.7", "0.08928", "0", "1"], ["84010.1", "0.01493332", "0", "1"], ["84010.7", "0.0000142", "0", "1"], ["84011", "0.00001201", "0", "1"], ["84011.3", "0.2025", "0", "1"], ["84011.7", "0.00001362", "0", "1"], ["84011.8", "0.05364843", "0", "1"], ["84012", "0.00421374", "0", "1"], ["84012.1", "0.00001016", "0", "1"], ["84012.2", "0.08991011", "0", "1"], ["84012.3", "0.03", "0", "1"], ["84013.2", "0.0000185", "0", "1"], ["84013.3", "0.00001653", "0", "1"], ["84013.4", "0.000015", "0", "1"], ["84014.6", "0.00001012", "0", "1"], ["84014.7", "0.00001097", "0", "1"], ["84014.8", "0.01299784", "0", "1"], ["84014.9", "0.11936586", "0", "1"], ["84015", "0.03", "0", "1"], ["84015.1", "0.00119026", "0", "1"], ["84015.2", "0.00011882", "0", "1"], ["84015.8", "0.17915015", "0", "1"], ["84016.4", "0.35714307", "0", "1"], ["84016.6", "0.00080013", "0", "6"], ["84016.8", "2.03182", "0", "1"], ["84017.4", "0.00001429", "0", "1"], ["84017.8", "0.00001222", "0", "1"]], "bids": [["83854", "0.0375451", "0", "4"], ["83853.1", "0.1127708", "0", "2"], ["83852.2", "0.005", "0", "1"], ["83852", "0.0352", "0", "1"], ["83851.8", "0.005", "0", "1"], ["83850", "0.0352", "0", "1"], ["83849.9", "0.00060645", "0", "1"], ["83848.9", "0.00775156", "0", "1"], ["83848.6", "0.11931979", "0", "1"], ["83848.2", "0.94769609", "0", "2"], ["83847.7", "1.74813004", "0", "2"], ["83846.6", "0.00011161", "0", "1"], ["83845.9", "1.24", "0", "1"], ["83845.7", "0.16961831", "0", "3"], ["83845.5", "0.05734551", "0", "2"], ["83844.6", "0.2015364", "0", "2"], ["83844.2", "0.35819548", "0", "1"], ["83843.6", "0.03868101", "0", "1"], ["83843.5", "0.0003", "0", "1"], ["83843.4", "0.03", "0", "1"], ["83843.3", "0.03", "0", "1"], ["83842.8", "0.000012", "0", "1"], ["83842.6", "0.1427708", "0", "3"], ["83842.5", "0.03", "0", "1"], ["83842.4", "0.00422858", "0", "1"], ["83842.2", "0.005", "0", "1"], ["83840.1", "0.13907984", "0", "2"], ["83840", "0.08694212", "0", "2"], ["83839.7", "0.02737741", "0", "1"], ["83839.3", "0.06", "0", "2"], ["83838", "0.135766", "0", "1"], ["83837.8", "0.00001201", "0", "1"], ["83837.6", "0.00775156", "0", "1"], ["83837.1", "0.00001501", "0", "1"], ["83836.2", "0.17915015", "0", "1"], ["83836.1", "0.11933395", "0", "1"], ["83835.8", "0.25756657", "0", "1"], ["83835.6", "0.35819548", "0", "1"], ["83835.5", "0.00095456", "0", "1"], ["83834.6", "0.00356728", "0", "1"], ["83834.2", "0.19272265", "0", "2"], ["83833.3", "0.00101534", "0", "2"], ["83833.2", "0.1409635", "0", "1"], ["83833.1", "0.00422865", "0", "1"], ["83832.9", "0.00001201", "0", "1"], ["83832.1", "0.1127708", "0", "2"], ["83829.9", "0.1409635", "0", "1"], ["83828.7", "0.000015", "0", "1"], ["83828.4", "0.23126334", "0", "1"], ["83828.3", "0.11934865", "0", "1"], ["83828", "0.472367", "0", "1"], ["83827.9", "0.00001201", "0", "1"], ["83827.8", "0.17915015", "0", "1"], ["83827.7", "0.11933395", "0", "1"], ["83827.3", "0.00239585", "0", "2"], ["83827.2", "0.0042075", "0", "2"], ["83827", "0.00012161", "0", "2"], ["83826.8", "0.18567", "0", "2"], ["83826.7", "0.61337217", "0", "1"], ["83826.6", "0.35819548", "0", "1"], ["83826.5", "0.000015", "0", "1"], ["83825.2", "1.59239888", "0", "1"], ["83823.8", "0.13459187", "0", "3"], ["83823.2", "0.001788", "0", "1"], ["83823", "0.00001201", "0", "1"], ["83821.8", "0.23863209", "0", "1"], ["83821.7", "0.03532566", "0", "1"], ["83821.6", "0.1527708", "0", "3"], ["83820.8", "0.00423058", "0", "1"], ["83820.3", "0.00001501", "0", "1"], ["83820.1", "0.01204456", "0", "3"], ["83820", "0.00060651", "0", "2"], ["83819.4", "0.06206231", "0", "1"], ["83819.2", "0.00079901", "0", "2"], ["83818.6", "0.56907984", "0", "1"], ["83818.4", "0.27155643", "0", "2"], ["83818.3", "0.2984841", "0", "2"], ["83818.2", "0.35819548", "0", "1"], ["83818", "0.00001201", "0", "1"], ["83816.6", "0.00060645", "0", "1"], ["83815.2", "0.24656", "0", "2"], ["83813.2", "0.06695361", "0", "1"], ["83813.1", "0.00001201", "0", "1"], ["83811.9", "0.00001501", "0", "1"], ["83811.6", "0.0899674", "0", "2"], ["83811.2", "0.1127708", "0", "2"], ["83810.6", "0.01191641", "0", "1"], ["83809.6", "0.026", "0", "2"], ["83809.3", "0.24868283", "0", "1"], ["83809.2", "0.19106676", "0", "2"], ["83809.1", "0.01191663", "0", "1"], ["83808.9", "0.00211445", "0", "1"], ["83808.8", "0.093", "0", "3"], ["83808.2", "0.00001201", "0", "1"], ["83808.1", "0.11933395", "0", "1"], ["83808", "0.04", "0", "1"], ["83807.9", "0.35819548", "0", "1"], ["83807.5", "0.0179085", "0", "1"], ["83807.3", "0.00011161", "0", "1"], ["83807.1", "0.00579976", "0", "1"], ["83807", "0.00423125", "0", "1"], ["83806.4", "0.1", "0", "2"], ["83805.8", "0.25041", "0", "1"], ["83805.6", "0.05", "0", "1"], ["83804.7", "0.02415649", "0", "2"], ["83804.6", "2.7448668", "0", "1"], ["83804.4", "0.00005038", "0", "1"], ["83803.5", "0.000015", "0", "1"], ["83803.2", "0.00001201", "0", "1"], ["83802.6", "0.03", "0", "1"], ["83802.5", "0.03", "0", "1"], ["83802.3", "0.1", "0", "1"], ["83800.8", "0.29357058", "0", "1"], ["83800.7", "0.23553555", "0", "2"], ["83800.5", "0.00578319", "0", "1"], ["83800.2", "0.09414206", "0", "2"], ["83800.1", "0.02387775", "0", "1"], ["83800", "0.00001", "0", "1"], ["83799.9", "0.00504382", "0", "4"], ["83799.8", "0.03", "0", "1"], ["83799.6", "0.11933395", "0", "1"], ["83799.5", "0.35819548", "0", "1"], ["83799.3", "0.06", "0", "2"], ["83799", "0.05244", "0", "1"], ["83798.3", "0.00001201", "0", "1"], ["83798.2", "0.02387831", "0", "1"], ["83796.7", "0.00716018", "0", "1"], ["83795.1", "0.000015", "0", "1"], ["83794.2", "0.00423246", "0", "1"], ["83793.3", "0.0119281", "0", "2"], ["83792.3", "0.23171571", "0", "1"], ["83792.2", "0.17915015", "0", "1"], ["83791.3", "0.41575", "0", "1"], ["83791", "0.11933395", "0", "1"], ["83790.8", "0.35819548", "0", "1"], ["83789.3", "0.00235969", "0", "1"], ["83788.4", "0.00001201", "0", "1"], ["83788.1", "0.50565", "0", "1"], ["83787.7", "0.00011161", "0", "1"], ["83787.1", "0.01191604", "0", "1"], ["83786.7", "0.00001501", "0", "1"], ["83785.4", "0.01192401", "0", "2"], ["83785.1", "0.05970512", "0", "1"], ["83784.5", "0.000015", "0", "1"], ["83784.4", "0.00423352", "0", "1"], ["83783.7", "0.13333863", "0", "2"], ["83783.4", "0.21575326", "0", "2"], ["83783.3", "0.1797566", "0", "2"], ["83782.4", "0.35819548", "0", "1"], ["83782.1", "0.08210734", "0", "1"], ["83781.8", "0.13693487", "0", "2"], ["83781.6", "0.84635", "0", "1"], ["83780.6", "0.01908636", "0", "1"], ["83779.6", "0.28236337", "0", "1"], ["83779.5", "0.868529", "0", "1"], ["83778.9", "0.00103791", "0", "1"], ["83778.6", "0.07161732", "0", "1"], ["83778.5", "0.00001201", "0", "1"], ["83778.3", "0.000015", "0", "1"], ["83777.2", "0.01515001", "0", "1"], ["83777.1", "0.01192833", "0", "1"], ["83776.3", "0.00423411", "0", "1"], ["83776.1", "0.07455521", "0", "1"], ["83775.3", "0.093249", "0", "1"], ["83774.4", "0.00332226", "0", "2"], ["83773.5", "0.00001201", "0", "1"], ["83772.8", "0.24169743", "0", "2"], ["83772.7", "0.1907501", "0", "3"], ["83772.5", "0.35819548", "0", "1"], ["83772.4", "0.04", "0", "1"], ["83772.2", "0.11933395", "0", "1"], ["83769.9", "0.000015", "0", "1"], ["83769.6", "0.00423487", "0", "1"], ["83769.4", "0.1", "0", "1"], ["83769.3", "0.08991011", "0", "1"], ["83768.8", "0.10554587", "0", "2"], ["83768.7", "0.0214", "0", "1"], ["83768.6", "0.00001201", "0", "1"], ["83768.5", "0.0214", "0", "1"], ["83768.1", "0.00011161", "0", "1"], ["83767.4", "0.10490746", "0", "2"], ["83767.3", "0.0214", "0", "1"], ["83767.1", "0.0214", "0", "1"], ["83767", "0.07162722", "0", "1"], ["83766.7", "0.00580017", "0", "1"], ["83766.6", "0.00101534", "0", "2"], ["83766.1", "0.1", "0", "1"], ["83765.6", "0.03581701", "0", "1"], ["83764.1", "0.00579976", "0", "1"], ["83763.7", "0.00611275", "0", "2"], ["83763.5", "0.00596331", "0", "1"], ["83763.4", "0.26330409", "0", "1"], ["83763", "0.17915015", "0", "1"], ["83762.9", "0.47752943", "0", "2"], ["83761.9", "0.1", "0", "1"], ["83761.6", "0.00610043", "0", "1"], ["83761.5", "0.0038388", "0", "2"], ["83761.2", "0.00298666", "0", "1"], ["83761.1", "0.03", "0", "1"], ["83759.2", "0.00609998", "0", "1"], ["83759.1", "0.00596331", "0", "1"], ["83758.7", "0.00001201", "0", "1"], ["83758.1", "0.07771019", "0", "2"], ["83758", "0.09871223", "0", "2"], ["83757.7", "0.00579976", "0", "1"], ["83757.6", "0.00041134", "0", "1"], ["83756.5", "0.183678", "0", "1"], ["83756.3", "0.0180013", "0", "3"], ["83756.2", "0.00596424", "0", "1"], ["83755.5", "0.002388", "0", "1"], ["83753.8", "0.00001201", "0", "1"], ["83753.5", "0.17915015", "0", "1"], ["83753.4", "0.41519576", "0", "2"], ["83753.1", "0.00001501", "0", "1"], ["83753", "0.00580107", "0", "1"], ["83752.9", "0.03580043", "0", "2"], ["83752.8", "0.00597332", "0", "1"], ["83751.8", "0.0179", "0", "1"], ["83751.2", "0.51430143", "0", "2"], ["83751.1", "0.35800014", "0", "1"], ["83750.7", "0.01830129", "0", "3"], ["83750.6", "0.00610072", "0", "1"], ["83750.4", "0.07102314", "0", "1"], ["83750", "0.01432572", "0", "2"], ["83749.9", "0.00063636", "0", "2"], ["83749.6", "0.008927", "0", "1"], ["83748.8", "0.00001201", "0", "1"], ["83748.6", "0.00105843", "0", "1"], ["83748.4", "0.00011161", "0", "1"], ["83748.2", "0.00580013", "0", "1"], ["83748.1", "1.28503886", "0", "4"], ["83746.6", "0.005", "0", "1"], ["83746.5", "0.00580043", "0", "1"], ["83746.4", "0.08991011", "0", "1"], ["83746.3", "0.01484", "0", "1"], ["83745.9", "0.07125036", "0", "1"], ["83745.6", "0.139924", "0", "1"], ["83745.4", "0.05371128", "0", "1"], ["83745", "0.35819548", "0", "1"], ["83744.8", "0.00059559", "0", "1"], ["83744.7", "0.000015", "0", "1"], ["83744.4", "0.00895999", "0", "1"], ["83743.9", "0.00001201", "0", "1"], ["83743.8", "0.00001", "0", "1"], ["83743.6", "0.0143", "0", "1"], ["83743.5", "1.303354", "0", "1"], ["83742.8", "0.20555181", "0", "3"], ["83742.5", "0.000015", "0", "1"], ["83742.2", "0.0429", "0", "3"], ["83741.7", "0.11947209", "0", "1"], ["83741.3", "0.00580017", "0", "1"], ["83741.2", "0.00580017", "0", "1"], ["83741", "0.00596573", "0", "1"], ["83740.9", "0.00423834", "0", "1"], ["83739.8", "0.00116399", "0", "1"], ["83739.7", "0.35800014", "0", "1"], ["83739", "1.08242611", "0", "3"], ["83738.9", "0.17915015", "0", "1"], ["83737.7", "0.06", "0", "2"], ["83737.5", "0.00006462", "0", "1"], ["83736.6", "0.35819548", "0", "1"], ["83736.3", "3.088195", "0", "4"], ["83736", "0.01194665", "0", "1"], ["83734.7", "0.18372744", "0", "1"], ["83734.6", "0.00596633", "0", "1"], ["83734.5", "0.06", "0", "2"], ["83734", "0.00001201", "0", "1"], ["83733.3", "0.00863732", "0", "5"], ["83732.9", "0.00596633", "0", "1"], ["83731.6", "0.00596633", "0", "1"], ["83731.3", "0.32791579", "0", "2"], ["83730.5", "0.20937", "0", "1"], ["83730.4", "0.17915015", "0", "1"], ["83730.3", "0.47240132", "0", "1"], ["83730.1", "0.12524803", "0", "2"], ["83730", "1.00035829", "0", "2"], ["83729.2", "0.214826", "0", "1"], ["83729.1", "0.00001201", "0", "1"], ["83729", "0.01787826", "0", "1"], ["83728.9", "0.00580017", "0", "1"], ["83728.8", "0.00591178", "0", "2"], ["83728.7", "0.00596633", "0", "1"], ["83728.6", "0.00017505", "0", "1"], ["83727.9", "0.00001501", "0", "1"], ["83727.7", "0.01677448", "0", "3"], ["83727.3", "0.00066186", "0", "2"], ["83727.2", "0.00053542", "0", "8"], ["83727.1", "0.00287741", "0", "4"], ["83727", "0.16396133", "0", "1"], ["83726.9", "0.4", "0", "1"], ["83726.8", "0.00923953", "0", "1"], ["83726.6", "0.07996035", "0", "2"], ["83725.9", "0.00006284", "0", "1"], ["83725.5", "0.0116006", "0", "2"], ["83725.4", "0.00306287", "0", "3"], ["83725.1", "3.37827", "0", "1"], ["83725", "0.00161298", "0", "2"], ["83724.3", "0.00018938", "0", "2"], ["83724.1", "0.000012", "0", "1"], ["83723.9", "0.00002933", "0", "2"], ["83723.6", "0.0178874", "0", "1"], ["83723.5", "0.0000593", "0", "1"], ["83723.2", "0.00424004", "0", "1"], ["83723.1", "0.00008513", "0", "1"], ["83722.5", "0.27861283", "0", "1"], ["83722.3", "0.00001016", "0", "1"], ["83722.2", "0.00610819", "0", "4"], ["83722", "0.17915015", "0", "1"], ["83721.8", "0.000012", "0", "1"], ["83721.7", "0.00018241", "0", "2"], ["83721.6", "0.00405668", "0", "4"], ["83721.5", "0.00003533", "0", "1"], ["83721.3", "0.0000884", "0", "2"], ["83720.9", "0.00001487", "0", "1"], ["83720.4", "0.00007881", "0", "1"], ["83720.3", "0.00002298", "0", "1"], ["83720.1", "0.00001146", "0", "1"], ["83720", "0.0003365", "0", "7"], ["83719.9", "0.00001023", "0", "1"], ["83719.8", "0.00001065", "0", "1"], ["83719.6", "0.00013901", "0", "2"], ["83719.5", "0.000015", "0", "1"], ["83719.4", "0.0000194", "0", "1"], ["83719.1", "0.00005731", "0", "1"], ["83719", "0.71888555", "0", "3"], ["83718.6", "0.00013924", "0", "1"], ["83718.5", "0.0000104", "0", "1"], ["83718.4", "0.00018203", "0", "1"], ["83718.3", "0.00001256", "0", "1"], ["83718.2", "0.00037995", "0", "3"], ["83718.1", "0.0001735", "0", "1"], ["83718", "0.0025", "0", "1"], ["83717.8", "0.00001316", "0", "1"], ["83717.5", "0.0002101", "0", "2"], ["83717.3", "0.11928555", "0", "1"], ["83717.2", "0.68237374", "0", "2"], ["83717", "2", "0", "1"], ["83716.8", "0.00070566", "0", "2"], ["83716.6", "0.00166145", "0", "2"], ["83716.5", "0.00002504", "0", "1"], ["83716.3", "0.00003392", "0", "2"], ["83716.1", "0.00007485", "0", "1"], ["83716", "0.00009195", "0", "2"], ["83715.9", "0.00440706", "0", "6"], ["83715.8", "0.00213075", "0", "1"], ["83715.6", "0.00002706", "0", "2"], ["83715.5", "0.00001082", "0", "1"], ["83715.2", "0.00007977", "0", "1"], ["83715", "0.03597", "0", "2"], ["83714.7", "0.00173373", "0", "2"], ["83714.6", "0.08991011", "0", "1"], ["83714.3", "0.000012", "0", "1"], ["83714.2", "0.10488004", "0", "21"], ["83713.8", "0.00012098", "0", "1"], ["83713.4", "0.19703725", "0", "4"], ["83713.3", "0.00051636", "0", "7"], ["83712.6", "0.01364212", "0", "2"], ["83712.5", "0.00024899", "0", "2"], ["83712.4", "0.00001483", "0", "1"], ["83712.3", "0.0000161", "0", "1"], ["83712.2", "0.00001748", "0", "1"], ["83712.1", "0.00047062", "0", "14"], ["83711.9", "0.00001049", "0", "1"], ["83711.8", "0.00002917", "0", "1"], ["83711.7", "0.00001691", "0", "1"], ["83711.4", "0.00002977", "0", "1"], ["83711.1", "0.000015", "0", "1"], ["83710.7", "0.00001017", "0", "1"], ["83710.6", "0.00178577", "0", "1"], ["83710.5", "0.71642942", "0", "4"], ["83710.3", "0.00012869", "0", "3"], ["83710.1", "0.00007352", "0", "1"], ["83710", "0.00030781", "0", "2"], ["83709.8", "0.0022146", "0", "4"], ["83709.7", "0.01141021", "0", "1"], ["83709.5", "0.000012", "0", "1"], ["83709.4", "0.00001004", "0", "1"], ["83709.2", "0.00011161", "0", "1"], ["83709.1", "0.00005515", "0", "1"], ["83709", "0.00002081", "0", "2"], ["83708.9", "0.00006987", "0", "2"], ["83708.8", "0.00001211", "0", "1"], ["83708.7", "0.00083364", "0", "3"], ["83708.6", "0.01232", "0", "1"], ["83708.5", "1.69297283", "0", "2"], ["83707.8", "0.00001237", "0", "1"], ["83707.5", "0.00423892", "0", "1"], ["83707.4", "0.00083", "0", "1"], ["83706.8", "0.00001039", "0", "1"], ["83706.6", "0.00009543", "0", "1"], ["83706.3", "0.0002558", "0", "2"], ["83705.9", "0.00004926", "0", "3"], ["83705.8", "0.00021259", "0", "6"], ["83705.4", "0.00301001", "0", "4"], ["83705", "0.00238934", "0", "1"], ["83704.9", "0.00051375", "0", "1"], ["83704.6", "0.00001063", "0", "1"], ["83704.4", "0.00072019", "0", "2"], ["83704", "0.00085217", "0", "2"], ["83703.7", "0.00039589", "0", "3"]], "ts": "1742543253003", "checksum": -664081225, "seqId": 49919345463, "prevSeqId": -1}], "record_time": 1742543252.956254}
{"arg": {"channel": "books", "instId": "BTC-USDT"}, "action": "update", "data": [{"asks": [["83854.1", "0.53740444", "0", "5"], ["83854.2", "0", "0", "0"], ["83854.3", "0", "0", "0"], ["83855.6", "0", "0", "0"], ["83855.9", "0.016461", "0", "1"], ["83856.8", "0", "0", "0"], ["83857.1", "0.01967", "0", "1"], ["83857.6", "0", "0", "0"], ["83857.7", "0.01193105", "0", "1"], ["83857.8", "0.016", "0", "1"], ["83857.9", "0.02616", "0", "1"], ["83858.8", "0", "0", "0"], ["83860.2", "0", "0", "0"], ["83862", "0.0352", "0", "1"], ["83862.1", "0", "0", "0"], ["83863", "0.10634757", "0", "2"], ["83863.1", "0.06768022", "0", "1"], ["83863.5", "0", "0", "0"], ["83864.4", "0.06230543", "0", "1"], ["83864.8", "0.05902", "0", "1"], ["83865.9", "0.1063962", "0", "1"], ["83866.5", "0", "0", "0"], ["83867.6", "0", "0", "0"], ["83867.7", "0", "0", "0"], ["83867.8", "0.06128142", "0", "1"], ["83868.3", "0", "0", "0"], ["83869.4", "0.09306859", "0", "1"], ["83871.7", "0.10470737", "0", "1"], ["83872.3", "0", "0", "0"], ["83873.2", "0.10074331", "0", "1"], ["83874.2", "0", "0", "0"], ["83875.2", "0.01100705", "0", "1"], ["83876.1", "0.54279958", "0", "1"], ["83876.5", "0.005", "0", "1"], ["83877.5", "0", "0", "0"], ["83877.7", "0", "0", "0"], ["83877.8", "0.10149707", "0", "1"], ["83878.4", "0.15446461", "0", "1"], ["83878.9", "0.20962421", "0", "2"], ["83880.7", "0", "0", "0"], ["83881", "0", "0", "0"], ["83881.9", "0.40687461", "0", "2"], ["83882.5", "0", "0", "0"], ["83886.4", "0", "0", "0"], ["83887.7", "0.16711553", "0", "1"], ["83908.1", "0", "0", "0"], ["84018", "0.00032751", "0", "1"], ["84019.7", "0.2025", "0", "1"], ["84019.9", "0.00421287", "0", "1"], ["84021.7", "0.00001852", "0", "1"], ["84022.6", "0.00002206", "0", "1"], ["84023.2", "0.01316", "0", "1"]], "bids": [["83854", "0.27220027", "0", "11"], ["83853.2", "0.09227543", "0", "2"], ["83851.2", "0.11931599", "0", "1"], ["83848.8", "0.01193105", "0", "1"], ["83848.6", "0", "0", "0"], ["83848.3", "0.17915015", "0", "1"], ["83831.3", "0.00003577", "0", "1"], ["83829.9", "0", "0", "0"], ["83826.9", "0.23862708", "0", "1"], ["83821.8", "0", "0", "0"], ["83819.2", "0", "0", "0"], ["83818.4", "0.27195643", "0", "3"], ["83817.6", "0.00039902", "0", "1"], ["83812.1", "0.1409635", "0", "1"], ["83806.4", "0", "0", "0"], ["83805.6", "0.1", "0", "2"], ["83804.8", "0.05", "0", "1"], ["83752.1", "0.07125036", "0", "1"], ["83745.9", "0", "0", "0"], ["83704.6", "0", "0", "0"], ["83704.4", "0", "0", "0"], ["83704", "0", "0", "0"], ["83703.7", "0", "0", "0"]], "ts": "1742543253103", "checksum": 1667796578, "seqId": 49919345567, "prevSeqId": 49919345463}], "record_time": 1742543253.054219}
{"arg": {"channel": "books", "instId": "BTC-USDT"}, "action": "update", "data": [{"asks": [["83854.1", "0.49539137", "0", "4"], ["83875.2", "1.56119363", "0", "2"], ["83875.4", "0", "0", "0"], ["83876.1", "0", "0", "0"], ["83876.2", "0", "0", "0"], ["83877.9", "0.38138", "0", "2"], ["83904.6", "2.73335083", "0", "1"], ["84023.3", "0.00011161", "0", "1"], ["84023.8", "0.00001575", "0", "1"]], "bids": [["83850", "0.03623828", "0", "2"]], "ts": "1742543253203", "checksum": 1965599914, "seqId": 49919345585, "prevSeqId": 49919345567}], "record_time": 1742543253.190104}
{"arg": {"channel": "books", "instId": "BTC-USDT"}, "action": "update", "data": [{"asks": [["83854.1", "0.49896772", "0", "5"], ["83857.9", "0.10089", "0", "2"], ["83860", "0.26", "0", "1"], ["83862.8", "0.06171058", "0", "1"], ["83862.9", "0.0647053", "0", "1"], ["83863", "0.03868101", "0", "1"], ["83863.1", "0", "0", "0"], ["83864.2", "0.0636162", "0", "1"], ["83864.4", "0", "0", "0"], ["83865.9", "0.297259", "0", "2"], ["83867.6", "0.06936375", "0", "1"], ["83867.7", "0.35819548", "0", "1"], ["83867.8", "0.17915015", "0", "1"], ["83869.2", "0.09585906", "0", "1"], ["83869.4", "0", "0", "0"], ["83871.5", "0.50549198", "0", "4"], ["83871.7", "0", "0", "0"], ["83873", "0.10352325", "0", "1"], ["83873.2", "0", "0", "0"], ["83877.6", "0.09908431", "0", "1"], ["83877.8", "0", "0", "0"], ["83878.2", "0.35986261", "0", "2"], ["83878.4", "0", "0", "0"], ["83878.7", "0.16544643", "0", "1"], ["83878.9", "0.04", "0", "1"], ["83880.5", "0.44412509", "0", "5"], ["83881.7", "0.15739364", "0", "1"], ["83881.8", "0.23862788", "0", "1"], ["83881.9", "0", "0", "0"], ["83884.5", "0.48527", "0", "1"], ["83887.5", "0.54530715", "0", "2"], ["83887.7", "0", "0", "0"], ["84023.2", "0", "0", "0"], ["84023.3", "0", "0", "0"], ["84023.8", "0", "0", "0"]], "bids": [["83854", "0.12865743", "0", "8"], ["83826.9", "0", "0", "0"], ["83823.9", "0.23862788", "0", "1"]], "ts": "1742543253303", "checksum": 742075637, "seqId": 49919345627, "prevSeqId": 49919345585}], "record_time": 1742543253.253699}
{"arg": {"channel": "books", "instId": "BTC-USDT"}, "action": "update", "data": [{"asks": [["83875.4", "0.17888", "0", "1"], ["83877.9", "0.2025", "0", "1"], ["83880.5", "0.08636509", "0", "4"], ["84022.6", "0", "0", "0"]], "bids": [["83854", "0.12867993", "0", "9"], ["83848.3", "0", "0", "0"], ["83704.6", "0.00001063", "0", "1"]], "ts": "1742543253403", "checksum": 438615093, "seqId": 49919345633, "prevSeqId": 49919345627}], "record_time": 1742543253.352881}
{"arg": {"channel": "books", "instId": "BTC-USDT"}, "action": "update", "data": [{"asks": [["83854.1", "0.49896775", "0", "5"], ["83875.2", "0.01100705", "0", "1"], ["83878", "0.35776", "0", "1"], ["83884.3", "0.11933395", "0", "1"], ["83892.8", "0.08", "0", "2"], ["83893.6", "0.03999999", "0", "1"], ["83904.6", "0", "0", "0"], ["83904.8", "0", "0", "0"], ["83905.6", "0", "0", "0"], ["84021.7", "0", "0", "0"]], "bids": [["83845.7", "0.30060227", "0", "4"], ["83826.7", "0", "0", "0"], ["83825.2", "0", "0", "0"], ["83809.6", "0.106", "0", "4"], ["83808.8", "0.053", "0", "2"], ["83808", "0", "0", "0"], ["83806.4", "0.1", "0", "2"], ["83805.6", "0.05", "0", "1"], ["83804.8", "0", "0", "0"], ["83804.6", "0", "0", "0"], ["83752.1", "0", "0", "0"], ["83749.3", "0.07125036", "0", "1"], ["83704.4", "0.00072019", "0", "2"], ["83704", "0.00085217", "0", "2"], ["83703.7", "0.00039589", "0", "3"], ["83703.6", "0.00001075", "0", "1"]], "ts": "1742543253503", "checksum": -1591511788, "seqId": 49919345661, "prevSeqId": 49919345633}], "record_time": 1742543253.453877}
{"arg": {"channel": "books", "instId": "BTC-USDT"}, "action": "update", "data": [{"asks": [["83862.8", "0.06427461", "0", "1"], ["83862.9", "0.06991253", "0", "1"], ["83866.8", "0", "0", "0"], ["83867.6", "0.06231523", "0", "1"], ["83869.2", "0.09384348", "0", "1"], ["83873", "0.10536471", "0", "1"], ["83877.6", "0.10077324", "0", "1"], ["83878.2", "0.35900173", "0", "2"], ["83878.7", "0.15573559", "0", "1"], ["83879.9", "1.75796955", "0", "3"], ["83887.5", "0.53119559", "0", "2"], ["83909.3", "2.76686008", "0", "1"]], "bids": [["83854", "0.12865743", "0", "8"], ["83853.2", "0.10014424", "0", "1"], ["83834.6", "0", "0", "0"], ["83829.1", "0.00916669", "0", "1"], ["83822", "1.55201491", "0", "1"], ["83792.6", "2.78940196", "0", "1"], ["83703.7", "0", "0", "0"], ["83703.6", "0", "0", "0"]], "ts": "1742543253603", "checksum": 1217531984, "seqId": 49919345691, "prevSeqId": 49919345661}], "record_time": 1742543253.552749}
{"arg": {"channel": "books", "instId": "BTC-USDT"}, "action": "update", "data": [{"asks": [["83861.5", "0.00356933", "0", "1"], ["83862.7", "0.12186722", "0", "2"], ["83862.8", "0.0696224", "0", "1"], ["83862.9", "0", "0", "0"], ["83867.4", "0.06652999", "0", "2"], ["83867.6", "0", "0", "0"], ["83869.1", "0.10402165", "0", "1"], ["83869.2", "0", "0", "0"], ["83872.9", "0.09495644", "0", "1"], ["83873", "0", "0", "0"], ["83877.3", "0.21441515", "0", "3"], ["83877.6", "0", "0", "0"], ["83878.1", "0.21488461", "0", "4"], ["83878.2", "0.83316404", "0", "2"], ["83878.5", "0.15725529", "0", "1"], ["83878.7", "0", "0", "0"], ["83887.2", "0.00081201", "0", "3"], ["83887.3", "0.17423403", "0", "1"], ["83887.5", "0.3782572", "0", "1"], ["83888", "0.12559", "0", "2"], ["83909.2", "1.03948408", "0", "1"], ["83910.4", "0", "0", "0"], ["83911.2", "0", "0", "0"], ["83939.6", "0.11933395", "0", "1"], ["83939.7", "1.57645659", "0", "1"], ["83962.5", "0.49725983", "0", "1"], ["84019.9", "0", "0", "0"]], "bids": [["83854", "0.12868143", "0", "9"], ["83853.2", "0", "0", "0"], ["83845.7", "0.35438505", "0", "5"], ["83834.4", "0.00355466", "0", "1"], ["83822.1", "0.5351234", "0", "1"], ["83821.7", "0", "0", "0"], ["83819.2", "0.0008", "0", "2"], ["83818.4", "0.27155643", "0", "2"], ["83817.6", "0", "0", "0"], ["83792.7", "1.15854946", "0", "1"], ["83792.3", "0", "0", "0"], ["83755.5", "0", "0", "0"], ["83753.6", "0.19258072", "0", "1"], ["83729.3", "0.002385", "0", "1"], ["83704", "0", "0", "0"]], "ts": "1742543253703", "checksum": 1002960449, "seqId": 49919345740, "prevSeqId": 49919345691}], "record_time": 1742543253.712408}
{"arg": {"channel": "books", "instId": "BTC-USDT"}, "action": "update", "data": [{"asks": [["83861.5", "0", "0", "0"], ["83892.8", "0", "0", "0"], ["83893.6", "0.07999999", "0", "2"], ["83894.4", "0.03999999", "0", "1"], ["84019.9", "0.00421287", "0", "1"]], "bids": [["83854", "0.12847743", "0", "7"], ["83809.6", "0.026", "0", "2"], ["83808.8", "0.093", "0", "3"], ["83808", "0.04", "0", "1"], ["83789.3", "0", "0", "0"], ["83780.6", "0", "0", "0"], ["83704", "0.00085217", "0", "2"]], "ts": "1742543253803", "checksum": -173117917, "seqId": 49919345757, "prevSeqId": 49919345740}], "record_time": 1742543253.752982}
{"arg": {"channel": "books", "instId": "BTC-USDT"}, "action": "update", "data": [{"asks": [["83854.1", "0.49539137", "0", "4"], ["83854.8", "0.01967", "0", "1"], ["83857.1", "0", "0", "0"], ["83862.7", "0.05968388", "0", "1"], ["83862.8", "0", "0", "0"], ["83864.2", "0", "0", "0"], ["83867.4", "0.000012", "0", "1"], ["83869.1", "0", "0", "0"], ["83871.5", "0.40031", "0", "3"], ["83872.9", "0", "0", "0"], ["83877.3", "0.117012", "0", "2"], ["83878.1", "0.052015", "0", "3"], ["83878.5", "0", "0", "0"], ["83881.7", "0", "0", "0"], ["83884", "1.2", "0", "2"], ["83884.6", "0.00357638", "0", "1"], ["83887.3", "0", "0", "0"], ["84019.7", "0", "0", "0"], ["84021.7", "0.00001852", "0", "1"], ["84022.6", "0.00002206", "0", "1"], ["84023.2", "0.01316", "0", "1"], ["84023.3", "0.00011161", "0", "1"], ["84023.8", "0.00001575", "0", "1"], ["84024.9", "0.35714307", "0", "1"]], "bids": [["83854", "0.04583743", "0", "6"], ["83853.2", "0.10014424", "0", "1"], ["83781.5", "0.00235991", "0", "1"], ["83773.4", "0.01908761", "0", "1"], ["83704.6", "0", "0", "0"], ["83704.4", "0", "0", "0"], ["83704", "0", "0", "0"]], "ts": "1742543253903", "checksum": 16378340, "seqId": 49919345803, "prevSeqId": 49919345757}], "record_time": 1742543253.854117}
{"arg": {"channel": "books", "instId": "BTC-USDT"}, "action": "update", "data": [{"asks": [["83854.1", "0.80146775", "0", "7"], ["83854.7", "0.018861", "0", "1"], ["83855.9", "0", "0", "0"], ["83860.5", "0.05902", "0", "1"], ["83864.8", "0", "0", "0"], ["83881.8", "0", "0", "0"], ["83882.9", "0.23862768", "0", "1"], ["83884", "0", "0", "0"], ["83884.6", "0", "0", "0"], ["83887", "0.01156771", "0", "1"], ["83887.2", "0.00001201", "0", "1"], ["83888", "0.12599", "0", "3"], ["83888.8", "0.00047589", "0", "2"], ["84025", "0.00001717", "0", "1"]], "bids": [["83854", "0.04585993", "0", "7"], ["83853.2", "0", "0", "0"], ["83838", "0", "0", "0"], ["83826.9", "0.23862768", "0", "1"], ["83823.9", "0", "0", "0"], ["83819.2", "0", "0", "0"], ["83818.4", "0.27195643", "0", "3"], ["83817.6", "0.00039902", "0", "1"], ["83704.6", "0.00001063", "0", "1"], ["83704.4", "0.00072019", "0", "2"]], "ts": "1742543254003", "checksum": -1650021617, "seqId": 49919345855, "prevSeqId": 49919345803}], "record_time": 1742543253.952856}
{"arg": {"channel": "books", "instId": "BTC-USDT"}, "action": "update", "data": [{"asks": [["83854.1", "0.49539137", "0", "4"], ["83862.3", "0.0643445", "0", "1"], ["83862.4", "0.06803192", "0", "1"], ["83863.8", "0.06689479", "0", "1"], ["83867", "0.06967955", "0", "1"], ["83868.7", "0.09874586", "0", "1"], ["83871.1", "0.10111748", "0", "1"], ["83872.5", "0.09182083", "0", "1"], ["83876.9", "0.09924816", "0", "1"], ["83877.7", "0.15813115", "0", "1"], ["83878.1", "0.20725316", "0", "4"], ["83881.3", "0.17358523", "0", "2"], ["83882", "0.04357638", "0", "2"], ["83882.9", "0.23862799", "0", "1"], ["83886.9", "0.15416767", "0", "1"], ["84017.8", "0", "0", "0"], ["84018", "0", "0", "0"], ["84019.9", "0", "0", "0"], ["84021.7", "0", "0", "0"], ["84022.6", "0", "0", "0"], ["84023.2", "0", "0", "0"], ["84023.3", "0", "0", "0"], ["84023.8", "0", "0", "0"], ["84024.9", "0", "0", "0"], ["84025", "0", "0", "0"]], "bids": [["83854", "0.04583743", "0", "6"], ["83837.1", "0.13608201", "0", "2"], ["83826.9", "0", "0", "0"], ["83823.9", "0.23862811", "0", "1"], ["83808", "1.04", "0", "2"], ["83805.7", "0.01837426", "0", "1"], ["83804.7", "0.00578319", "0", "1"], ["83773.4", "0", "0", "0"], ["83748.6", "0", "0", "0"], ["83748.5", "0.00105845", "0", "1"], ["83734.7", "0", "0", "0"], ["83733.4", "0.18374261", "0", "1"], ["83715.8", "0", "0", "0"], ["83704", "0.00085217", "0", "2"]], "ts": "1742543254103", "checksum": 155717910, "seqId": 49919345910, "prevSeqId": 49919345855}], "record_time": 1742543254.05286}
{"arg": {"channel": "books", "instId": "BTC-USDT"}, "action": "update", "data": [{"asks": [["83854.1", "0.49294429", "0", "4"], ["83920.1", "0.00023491", "0", "2"], ["83939.9", "0.002199", "0", "1"], ["83942.3", "0.35714307", "0", "1"], ["83962.1", "0.000015", "0", "1"], ["83975.5", "0", "0", "0"], ["83984.9", "0", "0", "0"], ["83993.4", "0", "0", "0"], ["84001.8", "0", "0", "0"], ["84010.1", "0", "0", "0"], ["84017.8", "0.00001222", "0", "1"], ["84018", "0.00032751", "0", "1"], ["84019.7", "0.2025", "0", "1"], ["84019.9", "0.00421287", "0", "1"]], "bids": [["83854", "0.04584793", "0", "7"], ["83793", "0.2", "0", "1"], ["83781.5", "0", "0", "0"], ["83761.2", "0", "0", "0"], ["83758.1", "0.02583633", "0", "1"], ["83756.5", "0", "0", "0"], ["83752.8", "0", "0", "0"], ["83744.4", "0", "0", "0"], ["83736", "0", "0", "0"], ["83730.5", "0.393051", "0", "2"], ["83727.7", "0.00184116", "0", "2"], ["83709.9", "0.00213072", "0", "1"], ["83703.7", "0.00039589", "0", "3"], ["83703.6", "0.00001075", "0", "1"], ["83703.3", "0.00006334", "0", "1"], ["83703.2", "0.00001159", "0", "1"]], "ts": "1742543254203", "checksum": -1811783173, "seqId": 49919345943, "prevSeqId": 49919345910}], "record_time": 1742543254.255168}
{"arg": {"channel": "books", "instId": "BTC-USDT"}, "action": "update", "data": [{"asks": [["83854.1", "0.69544429", "0", "5"], ["83861.5", "0.00351171", "0", "1"], ["83876.9", "0", "0", "0"], ["83877", "0.09310208", "0", "1"], ["83878", "0", "0", "0"], ["83882.9", "0.23862757", "0", "1"], ["83940", "0.01429592", "0", "1"], ["84019.9", "0", "0", "0"]], "bids": [["83854", "0.04600743", "0", "7"], ["83850", "0.03656625", "0", "3"], ["83808", "0.04", "0", "1"], ["83793", "0", "0", "0"], ["83782.6", "0.00235988", "0", "1"], ["83773.4", "0.01908762", "0", "1"], ["83753.1", "0.00013323", "0", "2"], ["83703.2", "0", "0", "0"]], "ts": "1742543254303", "checksum": 1387888792, "seqId": 49919345966, "prevSeqId": 49919345943}], "record_time": 1742543254.257791}
{"arg": {"channel": "books", "instId": "BTC-USDT"}, "action": "update", "data": [{"asks": [["83854.1", "0.49294429", "0", "4"], ["83854.6", "0.008", "0", "1"], ["83855.5", "0", "0", "0"], ["83857.9", "0.040596", "0", "1"], ["83860", "0", "0", "0"], ["83862.3", "0", "0", "0"], ["83862.4", "0", "0", "0"], ["83862.6", "0.09580553", "0", "2"], ["83862.7", "0.12563543", "0", "2"], ["83863.8", "0", "0", "0"], ["83864.1", "0.06278022", "0", "1"], ["83867", "0", "0", "0"], ["83867.3", "0.06319975", "0", "1"], ["83868.7", "0", "0", "0"], ["83869", "0.10473728", "0", "1"], ["83871.1", "0", "0", "0"], ["83871.4", "0.09414864", "0", "1"], ["83872.5", "0", "0", "0"], ["83872.8", "0.10396591", "0", "1"], ["83877", "0", "0", "0"], ["83877.3", "0.21440442", "0", "3"], ["83877.7", "0", "0", "0"], ["83878", "0.16206291", "0", "1"], ["83878.1", "0.052015", "0", "3"], ["83878.5", "0.17214379", "0", "1"], ["83881.3", "0.00422712", "0", "1"], ["83881.6", "0.15648871", "0", "1"], ["83882.2", "0.2386273", "0", "1"], ["83882.9", "0", "0", "0"], ["83886.9", "0", "0", "0"], ["83887.3", "0.17482454", "0", "1"], ["83912.4", "0.01191719", "0", "1"], ["83996.4", "0.01191719", "0", "1"]], "bids": [["83853.2", "0.10151163", "0", "1"], ["83826.9", "0.23862683", "0", "1"], ["83823.9", "0", "0", "0"], ["83808.2", "0.0119292", "0", "2"], ["83724.3", "0.01210657", "0", "3"], ["83703.3", "0", "0", "0"]], "ts": "1742543254403", "checksum": 540727205, "seqId": 49919346033, "prevSeqId": 49919345966}], "record_time": 1742543254.353081}
{"arg": {"channel": "books", "instId": "BTC-USDT"}, "action": "update", "data": [{"asks": [["83864.1", "0", "0", "0"], ["83875.5", "0.35776", "0", "1"], ["83878.4", "0.17218885", "0", "1"], ["83878.5", "0", "0", "0"], ["83881.5", "0.17022861", "0", "1"], ["83881.6", "0", "0", "0"], ["83882.2", "0", "0", "0"], ["83883.6", "0.23862524", "0", "1"], ["83887.2", "0.17146769", "0", "2"], ["83887.3", "0", "0", "0"], ["83893.6", "0", "0", "0"], ["83894.4", "0.07999999", "0", "2"], ["83895.2", "0.03999999", "0", "1"], ["84019.9", "0.00421287", "0", "1"]], "bids": [["83854", "0.03734331", "0", "7"], ["83853.2", "0", "0", "0"], ["83806.4", "0", "0", "0"], ["83805.6", "0.1", "0", "2"], ["83804.8", "0.05", "0", "1"], ["83703.3", "0.00006334", "0", "1"]], "ts": "1742543254503", "checksum": 1187773648, "seqId": 49919346060, "prevSeqId": 49919346033}], "record_time": 1742543254.452836}
{"arg": {"channel": "books", "instId": "BTC-USDT"}, "action": "update", "data": [{"asks": [["83854.6", "0", "0", "0"], ["83862.3", "0.12765986", "0", "2"], ["83862.6", "0.02722338", "0", "1"], ["83862.7", "0.05968388", "0", "1"], ["83863.7", "0.120281", "0", "3"], ["83866.7", "0.06426104", "0", "1"], ["83867.3", "0", "0", "0"], ["83868.6", "0.09267362", "0", "1"], ["83869", "0", "0", "0"], ["83871", "0.10380907", "0", "1"], ["83871.4", "0", "0", "0"], ["83872.5", "0.10417891", "0", "1"], ["83872.8", "0", "0", "0"], ["83876.5", "0.10786981", "0", "2"], ["83877.3", "0.117012", "0", "2"], ["83877.7", "0.15872982", "0", "1"], ["83878", "0", "0", "0"], ["83878.1", "0.22679401", "0", "4"], ["83878.4", "0", "0", "0"], ["83881.2", "0.16467145", "0", "1"], ["83881.5", "0", "0", "0"], ["83882.2", "0.23862748", "0", "1"], ["83883.6", "0", "0", "0"], ["83886.3", "0.17433051", "0", "1"], ["83887.2", "0.00001201", "0", "1"]], "bids": [["83826.9", "0.23862746", "0", "1"]], "ts": "1742543254603", "checksum": -1829181501, "seqId": 49919346110, "prevSeqId": 49919346060}], "record_time": 1742543254.553402}
{"arg": {"channel": "books", "instId": "BTC-USDT"}, "action": "update", "data": [{"asks": [["83882.2", "0", "0", "0"], ["83883.6", "0.23862513", "0", "1"]], "bids": [["83854", "0.03937131", "0", "8"], ["83827.9", "0.23863714", "0", "2"], ["83826.9", "0", "0", "0"], ["83703.2", "0.00001159", "0", "1"]], "ts": "1742543254703", "checksum": -849276958, "seqId": 49919346115, "prevSeqId": 49919346110}], "record_time": 1742543254.74901}
{"arg": {"channel": "books", "instId": "BTC-USDT"}, "action": "update", "data": [{"asks": [["83854.1", "0.69544429", "0", "5"], ["83862.3", "0.12437142", "0", "2"], ["83866.6", "0.06448685", "0", "1"], ["83866.7", "0", "0", "0"], ["83868.6", "0.09605625", "0", "1"], ["83872.4", "0.10264672", "0", "2"], ["83872.5", "0", "0", "0"], ["83875.4", "0.7308622", "0", "2"], ["83903.7", "0.66500859", "0", "1"], ["83903.9", "0", "0", "0"], ["83931.1", "0.11228386", "0", "1"], ["83959.8", "0.2508746", "0", "3"], ["83969.2", "0", "0", "0"], ["84021.7", "0.00001852", "0", "1"]], "bids": [["83854", "0.03138057", "0", "6"], ["83818.7", "0.44224078", "0", "1"], ["83818.4", "0.00079902", "0", "2"], ["83806.4", "0.1", "0", "2"], ["83805.6", "0.05", "0", "1"], ["83804.8", "0", "0", "0"], ["83783.4", "0.4547556", "0", "3"], ["83743.6", "0.56851931", "0", "2"], ["83742.8", "0.00068806", "0", "1"], ["83703.2", "0", "0", "0"]], "ts": "1742543254803", "checksum": -1068051409, "seqId": 49919346148, "prevSeqId": 49919346115}], "record_time": 1742543254.756676}
{"arg": {"channel": "books", "instId": "BTC-USDT"}, "action": "update", "data": [{"asks": [["83879.4", "0.003579", "0", "1"], ["83882", "0.04", "0", "1"], ["83883.6", "0.23862674", "0", "1"], ["84003", "0.005", "0", "2"], ["84021.7", "0", "0", "0"]], "bids": [["83852", "0.0394195", "0", "2"], ["83827.9", "0.00001201", "0", "1"], ["83826.9", "0.23862674", "0", "1"], ["83819.2", "0.0008", "0", "2"], ["83818.4", "0.00039877", "0", "1"], ["83817.6", "0", "0", "0"], ["83703.3", "0", "0", "0"]], "ts": "1742543254903", "checksum": 1916422678, "seqId": 49919346167, "prevSeqId": 49919346148}], "record_time": 1742543254.860329}
{"arg": {"channel": "books", "instId": "BTC-USDT"}, "action": "update", "data": [{"asks": [["83877", "0.2", "0", "1"], ["83880", "1", "0", "1"], ["83883.6", "0", "0", "0"], ["83884.2", "0.23862603", "0", "1"], ["83893.6", "0.08", "0", "2"], ["83894.4", "0.03999999", "0", "1"], ["83895.2", "0", "0", "0"], ["84019.7", "0", "0", "0"], ["84019.9", "0", "0", "0"]], "bids": [["83854", "0.03191307", "0", "7"], ["83852", "0.0352", "0", "1"], ["83826.9", "0.23862603", "0", "1"]], "ts": "1742543255003", "checksum": -1107347346, "seqId": 49919346186, "prevSeqId": 49919346167}], "record_time": 1742543254.95253}
{"arg": {"channel": "books", "instId": "BTC-USDT"}, "action": "update", "data": [{"asks": [["83850.1", "0.10785", "0", "3"], ["83851.3", "1.09715189", "0", "13"], ["83851.9", "0.08447", "0", "4"], ["83852", "0.0352", "0", "1"], ["83852.1", "0.07308749", "0", "2"], ["83852.3", "0.0648", "0", "3"], ["83853.1", "0.22922634", "0", "3"], ["83853.2", "1.3710033", "0", "17"], ["83853.7", "0.1", "0", "1"], ["83854", "0.79485863", "0", "8"], ["83854.1", "0.63171129", "0", "7"], ["83854.7", "0", "0", "0"], ["83854.8", "0", "0", "0"], ["83857.6", "0.01", "0", "1"], ["83857.7", "0.10184116", "0", "2"], ["83858.8", "0.03868101", "0", "1"], ["83862.3", "0", "0", "0"], ["83863", "0", "0", "0"], ["83863.7", "0.052", "0", "2"], ["83866.6", "0", "0", "0"], ["83866.7", "0.08991011", "0", "1"], ["83867.5", "0.18795133", "0", "1"], ["83868.1", "0.04", "0", "1"], ["83868.6", "0", "0", "0"], ["83870.8", "0", "0", "0"], ["83871", "0", "0", "0"], ["83872.4", "0.000012", "0", "1"], ["83873.9", "0.23864486", "0", "1"], ["83875.3", "0.11933395", "0", "1"], ["83875.4", "0.5519822", "0", "1"], ["83875.5", "0", "0", "0"], ["83876.5", "0.005", "0", "1"], ["83877", "0", "0", "0"], ["83877.7", "0", "0", "0"], ["83878.1", "0.052015", "0", "3"], ["83879.4", "0", "0", "0"], ["83880", "0", "0", "0"], ["83881.2", "0", "0", "0"], ["83882", "0", "0", "0"], ["83884.2", "0", "0", "0"], ["83886.3", "0", "0", "0"], ["83886.6", "0.005", "0", "1"], ["83888", "0.0008", "0", "2"], ["83889.6", "0", "0", "0"], ["83891.2", "0.11367108", "0", "2"], ["83891.3", "0", "0", "0"], ["83893.6", "0.07999999", "0", "2"], ["83898.1", "0", "0", "0"], ["83908.9", "0", "0", "0"], ["83910.6", "0", "0", "0"], ["83998.1", "0", "0", "0"], ["84019.7", "0.2025", "0", "1"], ["84019.9", "0.00421287", "0", "1"], ["84021.7", "0.00001852", "0", "1"], ["84022.6", "0.00002206", "0", "1"], ["84023.2", "0.01316", "0", "1"], ["84023.3", "0.00011161", "0", "1"]], "bids": [["83854", "0", "0", "0"], ["83853.1", "0", "0", "0"], ["83852.2", "0", "0", "0"], ["83852", "0", "0", "0"], ["83851.8", "0", "0", "0"], ["83851.2", "0", "0", "0"], ["83850", "0.00136625", "0", "2"], ["83848.9", "0", "0", "0"], ["83848.2", "0", "0", "0"], ["83845.9", "0", "0", "0"], ["83845.7", "0.3424514", "0", "4"], ["83845.5", "0.000015", "0", "1"], ["83844.6", "0.05897434", "0", "1"], ["83844.2", "0", "0", "0"], ["83843.6", "0", "0", "0"], ["83837.1", "0.00001501", "0", "1"], ["83837", "0.01193488", "0", "1"], ["83836.1", "0", "0", "0"], ["83835.8", "0.14565085", "0", "1"], ["83834.4", "0", "0", "0"], ["83834.2", "0.00477132", "0", "1"], ["83833.2", "0", "0", "0"], ["83829.1", "0", "0", "0"], ["83826.9", "0", "0", "0"], ["83824.2", "0.18795133", "0", "1"], ["83822", "0", "0", "0"], ["83821.6", "0.1127708", "0", "2"], ["83819.8", "0.1409635", "0", "1"], ["83819.5", "0.23864486", "0", "1"], ["83819.4", "0", "0", "0"], ["83819.2", "0", "0", "0"], ["83818.6", "0", "0", "0"], ["83818.4", "0", "0", "0"], ["83818.1", "0.04", "0", "1"], ["83817.6", "0.0008", "0", "2"], ["83816.8", "0.00039878", "0", "1"], ["83809.6", "0", "0", "0"], ["83808.8", "0.026", "0", "2"], ["83808", "0.013", "0", "1"], ["83807.2", "0.08", "0", "2"], ["83806.4", "0.04", "0", "1"], ["83805.8", "0", "0", "0"], ["83805.6", "0", "0", "0"], ["83804.8", "0.1", "0", "2"], ["83804", "0.05", "0", "1"], ["83792.6", "0", "0", "0"], ["83772.4", "0", "0", "0"], ["83766.8", "0.04", "0", "1"], ["83703.3", "0.00006334", "0", "1"], ["83703.2", "0.00001159", "0", "1"], ["83703.1", "0.00001028", "0", "1"], ["83702.9", "0.00168307", "0", "17"], ["83702.8", "0.00002617", "0", "1"], ["83702.6", "0.00423892", "0", "1"], ["83702.2", "0.00001007", "0", "1"], ["83702.1", "0.18495977", "0", "3"], ["83702", "0.71627081", "0", "1"], ["83701.9", "0.00011924", "0", "1"], ["83701.7", "0.01775437", "0", "1"], ["83701.6", "0.00002279", "0", "1"], ["83701.2", "0.00001141", "0", "1"], ["83701", "0.001", "0", "1"], ["83700.9", "0.00001011", "0", "1"]], "ts": "1742543255103", "checksum": -2100386049, "seqId": 49919346460, "prevSeqId": 49919346186}], "record_time": 1742543255.055287}
{"arg": {"channel": "books", "instId": "BTC-USDT"}, "action": "update", "data": [{"asks": [["83847.8", "0.48338054", "0", "10"], ["83848", "0.0352", "0", "1"], ["83848.7", "0.067602", "0", "1"], ["83848.9", "0.11894", "0", "2"], ["83850", "0.0352", "0", "1"], ["83850.1", "0.036", "0", "1"], ["83851.3", "0", "0", "0"], ["83851.9", "0", "0", "0"], ["83852.1", "0", "0", "0"], ["83852.3", "0", "0", "0"], ["83853", "0.26391812", "0", "1"], ["83853.1", "0", "0", "0"], ["83853.2", "0", "0", "0"], ["83853.6", "0.03868101", "0", "1"], ["83854", "0.0352", "0", "1"], ["83854.1", "0.258079", "0", "4"], ["83854.8", "0.34254", "0", "1"], ["83856.7", "0.06872935", "0", "1"], ["83856.9", "0.06290521", "0", "1"], ["83857.3", "0.04691127", "0", "2"], ["83857.5", "0.00001201", "0", "1"], ["83857.7", "0", "0", "0"], ["83857.9", "0", "0", "0"], ["83858.1", "0.06517876", "0", "1"], ["83858.8", "0", "0", "0"], ["83860.5", "0", "0", "0"], ["83861.3", "0.06606226", "0", "2"], ["83863.2", "0.14900148", "0", "3"], ["83863.6", "0.00477207", "0", "1"], ["83865.4", "0.09309651", "0", "1"], ["83865.9", "0.45629463", "0", "1"], ["83866.3", "0.01967", "0", "1"], ["83866.6", "0.00060645", "0", "1"], ["83866.8", "0.00890903", "0", "1"], ["83866.9", "0.09311705", "0", "1"], ["83867.8", "0.35804015", "0", "2"], ["83867.9", "0.2545", "0", "3"], ["83868.3", "0.05966709", "0", "1"], ["83870.5", "0.30624085", "0", "1"], ["83870.6", "0.23865885", "0", "1"], ["83870.7", "0.237", "0", "2"], ["83871.1", "0.10257839", "0", "1"], ["83871.3", "0", "0", "0"], ["83871.5", "0.052", "0", "2"], ["83871.6", "0.15197055", "0", "2"], ["83872", "0", "0", "0"], ["83872.1", "0.17241818", "0", "1"], ["83872.6", "0.17408939", "0", "1"], ["83872.8", "0.1067445", "0", "2"], ["83873.6", "0.04", "0", "1"], ["83873.9", "0", "0", "0"], ["83874", "0.1227708", "0", "3"], ["83874.1", "0.02693528", "0", "1"], ["83874.2", "0.105", "0", "1"], ["83874.8", "0", "0", "0"], ["83875.2", "0", "0", "0"], ["83875.4", "0", "0", "0"], ["83875.6", "0.15885112", "0", "1"], ["83876.1", "0.35852812", "0", "1"], ["83878.5", "0.11927744", "0", "1"], ["83878.9", "0", "0", "0"], ["83879", "0.05773278", "0", "1"], ["83880.5", "0.08635459", "0", "3"], ["83881", "0.16685287", "0", "1"], ["83884.2", "0.288755", "0", "1"], ["83884.6", "0.00357", "0", "1"], ["83885.1", "0.23628", "0", "1"], ["83887", "0.29072696", "0", "2"], ["83887.5", "0", "0", "0"], ["83889.4", "0.02310736", "0", "1"], ["83890.3", "0", "0", "0"], ["83891.2", "0.16460135", "0", "3"], ["83891.7", "0.08935", "0", "1"], ["83893", "0", "0", "0"], ["83893.3", "0.04295281", "0", "1"], ["83895.5", "0.82186234", "0", "2"], ["83898.5", "0", "0", "0"], ["83899", "0", "0", "0"], ["83899.7", "0.15778506", "0", "1"], ["83901.2", "0", "0", "0"], ["83902.3", "0", "0", "0"], ["83903.7", "0", "0", "0"], ["83903.8", "0", "0", "0"], ["83904.6", "0.38068689", "0", "1"], ["83904.7", "0.56450437", "0", "1"], ["83905.4", "0.0563854", "0", "1"], ["83910.1", "0", "0", "0"], ["83911", "0.01788642", "0", "1"], ["83914.3", "0.17462333", "0", "1"], ["83916.5", "0.22387946", "0", "1"], ["83916.6", "0.25147991", "0", "4"], ["83918.7", "0.47238", "0", "1"], ["83924.4", "0.03259741", "0", "1"], ["83925.1", "0.01273977", "0", "1"], ["83927.2", "0.07149055", "0", "1"], ["83929", "0", "0", "0"], ["83929.1", "0", "0", "0"], ["83930.4", "0.01192636", "0", "2"], ["83931", "0.00596318", "0", "1"], ["83937.6", "0.25045", "0", "1"], ["83939.5", "0.07102314", "0", "1"], ["83940.1", "3.21309", "0", "1"], ["83942.2", "0", "0", "0"], ["83943.1", "0", "0", "0"], ["83945.5", "0", "0", "0"], ["83945.6", "0", "0", "0"], ["83950.6", "0", "0", "0"], ["83951.3", "0.19873", "0", "1"], ["83952.9", "0.03577284", "0", "1"], ["83955", "0", "0", "0"], ["83959.8", "0.05958092", "0", "1"], ["83962.5", "0", "0", "0"], ["83964.2", "0.00298666", "0", "1"], ["83971.9", "0", "0", "0"], ["83972.6", "0.00597332", "0", "1"], ["83979.1", "0", "0", "0"], ["83981", "0.00895999", "0", "1"], ["83982.2", "0.18511334", "0", "2"], ["83985.7", "2.03183675", "0", "2"], ["83989.4", "0.01194665", "0", "1"], ["83992.2", "0", "0", "0"], ["83997.9", "0.01493332", "0", "1"], ["83999", "0.19703972", "0", "4"], ["84005.2", "0", "0", "0"], ["84009", "0", "0", "0"], ["84009.7", "0", "0", "0"], ["84013.7", "0.0286", "0", "2"], ["84014.7", "0", "0", "0"], ["84014.8", "0", "0", "0"], ["84014.9", "0", "0", "0"], ["84015", "0", "0", "0"], ["84015.1", "0", "0", "0"], ["84015.2", "0", "0", "0"], ["84015.8", "0", "0", "0"], ["84016.4", "0", "0", "0"], ["84016.6", "0", "0", "0"], ["84016.8", "0", "0", "0"], ["84017.4", "0", "0", "0"], ["84017.8", "0", "0", "0"], ["84018", "0", "0", "0"], ["84019.7", "0", "0", "0"], ["84019.9", "0", "0", "0"], ["84021.7", "0", "0", "0"], ["84022.6", "0", "0", "0"], ["84023.2", "0", "0", "0"], ["84023.3", "0", "0", "0"]], "bids": [["83850", "0", "0", "0"], ["83849.9", "0", "0", "0"], ["83848.8", "0", "0", "0"], ["83847.7", "1.75408078", "0", "2"], ["83845.8", "0.10275792", "0", "2"], ["83845.5", "0", "0", "0"], ["83844.6", "0.03533124", "0", "1"], ["83843.5", "0", "0", "0"], ["83843.4", "0", "0", "0"], ["83843.3", "0", "0", "0"], ["83842.8", "0", "0", "0"], ["83842.6", "0.1127708", "0", "2"], ["83842.5", "0", "0", "0"], ["83842.4", "0", "0", "0"], ["83840.1", "0.08019548", "0", "1"], ["83839.7", "0", "0", "0"], ["83839.3", "0", "0", "0"], ["83839.1", "0.05733051", "0", "1"], ["83837", "0", "0", "0"], ["83835", "0.03", "0", "1"], ["83834.6", "0.0003", "0", "1"], ["83834.2", "0", "0", "0"], ["83828.4", "0.05732951", "0", "1"], ["83828.3", "0", "0", "0"], ["83828", "0", "0", "0"], ["83827.8", "0.19108634", "0", "2"], ["83827", "0.00011161", "0", "1"], ["83826.9", "0.25662499", "0", "1"], ["83823.8", "0.12358482", "0", "2"], ["83822.1", "0", "0", "0"], ["83821.7", "0.08118929", "0", "1"], ["83819.5", "0", "0", "0"], ["83818.7", "0", "0", "0"], ["83818.4", "0.28709027", "0", "1"], ["83818.3", "0.30564244", "0", "3"], ["83818.1", "0", "0", "0"], ["83817.6", "0", "0", "0"], ["83816.8", "0", "0", "0"], ["83816", "0.23865885", "0", "1"], ["83815.9", "0.05100705", "0", "2"], ["83815.2", "0.01", "0", "1"], ["83813.6", "0.00079879", "0", "2"], ["83813.2", "0.09474941", "0", "2"], ["83812.8", "0.0003988", "0", "1"], ["83810.6", "0.06956267", "0", "2"], ["83808.9", "0", "0", "0"], ["83808.8", "0", "0", "0"], ["83808.4", "0.11937692", "0", "1"], ["83808", "0", "0", "0"], ["83807.2", "0", "0", "0"], ["83807.1", "0", "0", "0"], ["83806.4", "0", "0", "0"], ["83805.7", "0", "0", "0"], ["83804.8", "0.026", "0", "2"], ["83804.7", "0", "0", "0"], ["83804.1", "0.05442086", "0", "1"], ["83804", "0.093", "0", "3"], ["83803.2", "0.04001201", "0", "2"], ["83802.7", "0.01837587", "0", "1"], ["83802.4", "0.23656", "0", "1"], ["83802.3", "0", "0", "0"], ["83800.8", "0.39357058", "0", "3"], ["83800.5", "0", "0", "0"], ["83800", "0.05001", "0", "2"], ["83799", "0", "0", "0"], ["83798.4", "0.04058939", "0", "1"], ["83798.3", "0.10001201", "0", "2"], ["83792.7", "0", "0", "0"], ["83791.4", "0.26798383", "0", "1"], ["83788.2", "0.1553078", "0", "1"], ["83785.4", "0.00596188", "0", "1"], ["83782.5", "0.56", "0", "1"], ["83779.6", "0", "0", "0"], ["83779.5", "0", "0", "0"], ["83778.6", "0", "0", "0"], ["83777.2", "0.04778011", "0", "2"], ["83775.3", "0", "0", "0"], ["83775.2", "0.05244", "0", "1"], ["83769.8", "0.25045", "0", "1"], ["83769.7", "0.00596302", "0", "1"], ["83768.7", "0", "0", "0"], ["83768.5", "0", "0", "0"], ["83767.5", "0.00596318", "0", "1"], ["83767.4", "0.08350746", "0", "1"], ["83767.3", "0", "0", "0"], ["83767.1", "0", "0", "0"], ["83765.7", "0.00596318", "0", "1"], ["83764.1", "0", "0", "0"], ["83762.7", "0.0716309", "0", "1"], ["83761.3", "0.00298666", "0", "1"], ["83759.2", "0", "0", "0"], ["83757.7", "0", "0", "0"], ["83753.1", "0.00001501", "0", "1"], ["83752.9", "0.04177375", "0", "3"], ["83751.5", "0.0214", "0", "1"], ["83751.4", "0.0214", "0", "1"], ["83749.5", "0.0642", "0", "3"], ["83748.9", "0.25045", "0", "1"], ["83748.5", "0", "0", "0"], ["83746.4", "0.22081192", "0", "2"], ["83745.6", "0", "0", "0"], ["83744.5", "0.00895999", "0", "1"], ["83743.7", "0.00105868", "0", "1"], ["83743.6", "0.55421931", "0", "1"], ["83742.2", "0", "0", "0"], ["83739.8", "0", "0", "0"], ["83735.6", "0.01194665", "0", "1"], ["83734.7", "0.00116416", "0", "1"], ["83733.4", "0", "0", "0"], ["83733.1", "0.15708215", "0", "1"], ["83733", "0.1837587", "0", "1"], ["83727", "1.17661351", "0", "2"], ["83726.4", "0.0143", "0", "1"], ["83724.3", "0.05500657", "0", "6"], ["83722.8", "0.01493332", "0", "1"], ["83700.6", "0.00011879", "0", "1"], ["83700.5", "0.00002502", "0", "2"], ["83700.3", "0.00005632", "0", "2"], ["83700.2", "0.11940904", "0", "1"], ["83700.1", "0.28444537", "0", "1"], ["83700", "3.35232623", "0", "60"], ["83699.9", "0.0010487", "0", "4"], ["83699.4", "0.00001201", "0", "1"], ["83699.3", "0.00001299", "0", "1"], ["83699.2", "0.00002033", "0", "1"], ["83698.8", "0.00001914", "0", "1"], ["83698.4", "0.00008", "0", "1"]], "ts": "1742543255203", "checksum": -1496161950, "seqId": 49919347160, "prevSeqId": 49919346460}], "record_time": 1742543255.154512}
{"arg": {"channel": "books", "instId": "BTC-USDT"}, "action": "update", "data": [{"asks": [["83847.8", "0.56989954", "0", "12"], ["83848.5", "0.14359123", "0", "2"], ["83848.6", "0.11931992", "0", "1"], ["83848.7", "0", "0", "0"], ["83848.9", "0.036", "0", "1"], ["83852.9", "0.26", "0", "1"], ["83854.1", "0.2545", "0", "3"], ["83859.7", "0.01967", "0", "1"], ["83867.8", "0.17915015", "0", "1"], ["83868.3", "0", "0", "0"], ["83870.5", "0.4454585", "0", "2"], ["83870.6", "0", "0", "0"], ["83872.5", "0.23865026", "0", "1"], ["83872.8", "0.2147445", "0", "3"], ["83872.9", "0.102", "0", "1"], ["83875.4", "0.05966709", "0", "1"], ["83877.3", "0.000012", "0", "1"], ["83880.8", "0", "0", "0"], ["83895.6", "0.36201588", "0", "2"], ["83908.9", "0.12523", "0", "1"], ["83917.8", "0.01274059", "0", "1"], ["83917.9", "0.01652", "0", "1"], ["83924.1", "0", "0", "0"], ["83925.1", "0", "0", "0"], ["83939.7", "0.87860482", "0", "1"], ["84013.3", "0", "0", "0"], ["84013.4", "0", "0", "0"], ["84013.7", "0", "0", "0"], ["84014.6", "0", "0", "0"]], "bids": [["83847.7", "1.75415078", "0", "3"], ["83845.8", "0", "0", "0"], ["83840.3", "0.13515992", "0", "1"], ["83840.2", "0.11933169", "0", "1"], ["83840.1", "0", "0", "0"], ["83835", "0.06", "0", "2"], ["83834.9", "0.03", "0", "1"], ["83833.4", "0.03868101", "0", "1"], ["83832", "0.10697574", "0", "1"], ["83831.9", "0.136041", "0", "1"], ["83830.2", "0.02939567", "0", "1"], ["83828.4", "0", "0", "0"], ["83821.7", "0.1426357", "0", "2"], ["83819.9", "0.23865026", "0", "1"], ["83816", "0", "0", "0"], ["83813.4", "0.27606541", "0", "1"], ["83813.3", "0.5760905", "0", "1"], ["83813.2", "0", "0", "0"], ["83809.3", "0.36083234", "0", "2"], ["83807.5", "0.4902305", "0", "2"], ["83804", "0.013", "0", "1"], ["83803.2", "0.08001201", "0", "3"], ["83802.7", "0", "0", "0"], ["83802.4", "0.27656", "0", "2"], ["83799.3", "0.03", "0", "1"], ["83798.4", "0.30609598", "0", "3"], ["83798.3", "0.00001201", "0", "1"], ["83796", "1.1", "0", "2"], ["83794.3", "0.01837627", "0", "1"], ["83794.2", "0.00467882", "0", "2"], ["83790.1", "0.00044636", "0", "1"], ["83790", "0.20589", "0", "1"], ["83789", "0.165", "0", "1"], ["83753.1", "0.00013319", "0", "2"], ["83743.7", "0", "0", "0"], ["83741.8", "0.00105865", "0", "1"], ["83734.7", "0", "0", "0"], ["83733.4", "0.00116413", "0", "1"], ["83733.1", "0.10195454", "0", "1"], ["83733", "0", "0", "0"], ["83725.2", "0.18376274", "0", "1"], ["83710.6", "0", "0", "0"], ["83705", "0.00417554", "0", "2"], ["83700.1", "0", "0", "0"], ["83700", "0", "0", "0"], ["83699.9", "0", "0", "0"], ["83699.4", "0", "0", "0"], ["83699.3", "0", "0", "0"], ["83699.2", "0", "0", "0"], ["83698.8", "0", "0", "0"], ["83698.4", "0", "0", "0"]], "ts": "1742543255303", "checksum": 1671707798, "seqId": 49919347293, "prevSeqId": 49919347160}], "record_time": 1742543255.282206}
{"arg": {"channel": "books", "instId": "BTC-USDT"}, "action": "update", "data": [{"asks": [["83857.3", "0.070373", "0", "1"], ["83866", "0.09421", "0", "2"], ["83872.5", "0", "0", "0"], ["83872.8", "0.213", "0", "2"], ["83875.1", "0.41559026", "0", "1"], ["83875.2", "0.23864671", "0", "1"], ["83876.1", "0", "0", "0"], ["83877.2", "0", "0", "0"], ["83879.9", "1.54796955", "0", "1"], ["83890.2", "0.095122", "0", "2"], ["83892.2", "0.1", "0", "1"], ["83895.3", "1.24537913", "0", "1"], ["83895.4", "0.86783", "0", "2"], ["83895.5", "0", "0", "0"], ["83911.6", "0.00008624", "0", "1"], ["83915.5", "0", "0", "0"], ["83926.1", "0.13970114", "0", "2"], ["83939.7", "0.93441617", "0", "2"]], "bids": [["83844.6", "0", "0", "0"], ["83844.5", "0.0000315", "0", "1"], ["83842.7", "0.03533124", "0", "1"], ["83840.3", "0.08141487", "0", "1"], ["83838.2", "0.06", "0", "2"], ["83836.2", "0", "0", "0"], ["83835", "0.09", "0", "3"], ["83824.5", "0.00353927", "0", "1"], ["83821.9", "0.1527833", "0", "1"], ["83821.8", "0.23864671", "0", "1"], ["83821.7", "0", "0", "0"], ["83819.9", "0", "0", "0"], ["83818.4", "0.650183", "0", "2"], ["83815.4", "1.56143419", "0", "1"], ["83804.1", "0.0369081", "0", "1"], ["83799.8", "0", "0", "0"], ["83798.4", "0.04103575", "0", "2"], ["83796", "0.1", "0", "1"], ["83790.1", "0.03044636", "0", "2"], ["83789", "0", "0", "0"], ["83788.2", "0.99299499", "0", "2"], ["83786.1", "2.85700221", "0", "1"], ["83772.8", "0.57255056", "0", "3"], ["83772", "0.868607", "0", "1"], ["83767.3", "0.093258", "0", "1"], ["83753.7", "0.01774536", "0", "1"], ["83753.1", "0.00001501", "0", "1"], ["83748.6", "0.00011819", "0", "1"], ["83731.5", "0.139947", "0", "1"], ["83701.2", "0", "0", "0"], ["83701", "0", "0", "0"], ["83700.9", "0", "0", "0"], ["83700.6", "0", "0", "0"], ["83700.5", "0", "0", "0"], ["83700.3", "0", "0", "0"], ["83700.2", "0", "0", "0"]], "ts": "1742543255403", "checksum": -1043895018, "seqId": 49919347356, "prevSeqId": 49919347293}], "record_time": 1742543255.35516}
{"arg": {"channel": "books", "instId": "BTC-USDT"}, "action": "update", "data": [{"asks": [["83847.8", "0.62189954", "0", "14"], ["83867.8", "0.35805015", "0", "2"], ["83872.5", "0.001125", "0", "1"], ["83911.7", "0.00001501", "0", "1"], ["83924.4", "0.0665877", "0", "2"], ["83939.7", "0.87860482", "0", "1"], ["83999.6", "0.05940858", "0", "1"], ["84008.2", "0", "0", "0"], ["84013.2", "0", "0", "0"]], "bids": [["83845.8", "0.0000165", "0", "1"], ["83844.5", "0", "0", "0"], ["83802.6", "0", "0", "0"], ["83799.3", "0", "0", "0"], ["83701.2", "0.00001141", "0", "1"], ["83701", "0.001", "0", "1"]], "ts": "1742543255503", "checksum": 487857369, "seqId": 49919347371, "prevSeqId": 49919347356}], "record_time": 1742543255.456866}
{"arg": {"channel": "books", "instId": "BTC-USDT"}, "action": "update", "data": [{"asks": [["83851.9", "0.01", "0", "1"], ["83857.6", "0", "0", "0"], ["83878.2", "0.20210647", "0", "1"], ["83879.9", "0", "0", "0"], ["83939.7", "0.93143819", "0", "2"], ["84013.2", "0.0000185", "0", "1"]], "bids": [["83847.7", "1.75433976", "0", "4"], ["83802.5", "0", "0", "0"], ["83793.3", "0.0719281", "0", "4"], ["83791.5", "0.01774536", "0", "1"], ["83790.1", "0.06044636", "0", "3"], ["83753.7", "0", "0", "0"], ["83700.9", "0.00001011", "0", "1"]], "ts": "1742543255603", "checksum": -163222484, "seqId": 49919347386, "prevSeqId": 49919347371}], "record_time": 1742543255.553572}
{"arg": {"channel": "books", "instId": "BTC-USDT"}, "action": "update", "data": [{"asks": [["83865.9", "0.89250073", "0", "2"], ["83869.6", "1.62477861", "0", "2"], ["83875.2", "0", "0", "0"], ["83877.3", "0.23865869", "0", "2"], ["84013.3", "0.00001653", "0", "1"]], "bids": [["83842.6", "0.12052294", "0", "3"], ["83822.1", "0.1527833", "0", "1"], ["83822", "0.23864669", "0", "1"], ["83821.9", "0", "0", "0"], ["83821.8", "0", "0", "0"]], "ts": "1742543255703", "checksum": 997481331, "seqId": 49919347401, "prevSeqId": 49919347386}], "record_time": 1742543255.652522}
{"arg": {"channel": "books", "instId": "BTC-USDT"}, "action": "update", "data": [{"asks": [["83872.5", "0", "0", "0"], ["83888", "0.12603", "0", "3"], ["83888.8", "0.08047588", "0", "4"], ["83889.6", "0.03999999", "0", "1"], ["83893.6", "0", "0", "0"], ["83894.4", "0", "0", "0"], ["84013.4", "0.000015", "0", "1"], ["84013.7", "0.0286", "0", "2"]], "bids": [["83847.7", "1.75446976", "0", "5"], ["83845.8", "0", "0", "0"], ["83804", "0.093", "0", "3"], ["83803.2", "0.04001201", "0", "2"], ["83802.4", "0.23656", "0", "1"], ["83739.8", "0.00580055", "0", "1"]], "ts": "1742543255803", "checksum": -771984698, "seqId": 49919347426, "prevSeqId": 49919347401}], "record_time": 1742543255.823661}
{"arg": {"channel": "books", "instId": "BTC-USDT"}, "action": "update", "data": [{"asks": [["83872.2", "0.00423", "0", "1"], ["83888", "0.20603", "0", "5"], ["83888.8", "0.04047588", "0", "3"], ["83889.6", "0", "0", "0"], ["83895.6", "0.00422588", "0", "1"]], "bids": [["83845.7", "0.34346828", "0", "5"], ["83844.5", "0.0000105", "0", "1"], ["83790", "0", "0", "0"], ["83782.5", "0", "0", "0"], ["83700.6", "0.00011879", "0", "1"]], "ts": "1742543255903", "checksum": 2105015825, "seqId": 49919347440, "prevSeqId": 49919347426}], "record_time": 1742543255.856704}
{"arg": {"channel": "books", "instId": "BTC-USDT"}, "action": "update", "data": [{"asks": [["83847.8", "0.55117954", "0", "11"], ["83848.5", "0.06569182", "0", "1"], ["83848.9", "0", "0", "0"], ["83850.1", "0", "0", "0"], ["83852.9", "0", "0", "0"], ["83866.7", "0", "0", "0"], ["83870.5", "0.8032485", "0", "3"], ["83872.2", "0", "0", "0"], ["83882.4", "0.0008", "0", "2"], ["83883.2", "0.0004", "0", "1"], ["83888", "0.12523", "0", "1"], ["83888.8", "0.08007588", "0", "3"], ["83889.6", "0.03999999", "0", "1"], ["83916.5", "0.15752264", "0", "1"], ["83916.6", "0.00102991", "0", "3"], ["83937.6", "0", "0", "0"], ["84014.6", "0.00001012", "0", "1"], ["84014.7", "0.00001097", "0", "1"], ["84014.8", "0.01299784", "0", "1"]], "bids": [["83847.7", "1.75625776", "0", "6"], ["83840.2", "0", "0", "0"], ["83823.2", "0", "0", "0"], ["83822.7", "0.35779", "0", "1"], ["83822.2", "0.23864504", "0", "1"], ["83822", "0", "0", "0"], ["83814.4", "0.0008", "0", "2"], ["83813.6", "0.00039879", "0", "1"], ["83812.8", "0", "0", "0"], ["83801.6", "0.1", "0", "2"], ["83800.8", "0.34357058", "0", "2"], ["83800", "0.00001", "0", "1"], ["83791.5", "0", "0", "0"], ["83769.8", "0", "0", "0"], ["83753.7", "0.01774536", "0", "1"], ["83748.9", "0", "0", "0"], ["83700.5", "0.00002502", "0", "2"], ["83700.3", "0.00005632", "0", "2"]], "ts": "1742543256003", "checksum": 43224608, "seqId": 49919347489, "prevSeqId": 49919347440}], "record_time": 1742543255.95733}
{"arg": {"channel": "books", "instId": "BTC-USDT"}, "action": "update", "data": [{"asks": [["83875", "0.2", "0", "1"], ["83876.3", "0.001404", "0", "1"], ["83877", "1", "0", "1"], ["83877.3", "0.000012", "0", "1"], ["83878.1", "0.29065725", "0", "4"], ["83888", "0.20523", "0", "3"], ["83888.8", "0.04007588", "0", "2"], ["83889.6", "0", "0", "0"], ["83908.9", "0.12531624", "0", "2"], ["83911.6", "0", "0", "0"], ["83916.2", "0.01274101", "0", "1"], ["83917.8", "0", "0", "0"], ["84014.8", "0", "0", "0"]], "bids": [["83845.8", "0.10304048", "0", "1"], ["83845.7", "0.34448517", "0", "6"], ["83843.4", "0.07345507", "0", "1"], ["83843.3", "0.11932728", "0", "1"], ["83842.7", "0", "0", "0"], ["83823.9", "0.23864164", "0", "1"], ["83822.8", "0.08118929", "0", "1"], ["83822.7", "0", "0", "0"], ["83822.2", "0", "0", "0"], ["83822.1", "0", "0", "0"], ["83748.6", "0", "0", "0"], ["83746.7", "0.00011819", "0", "1"], ["83725.2", "0", "0", "0"], ["83723.7", "0.18375593", "0", "1"], ["83705", "0.00238934", "0", "1"], ["83704.5", "0.00178646", "0", "1"], ["83700.5", "0", "0", "0"], ["83700.3", "0", "0", "0"]], "ts": "1742543256103", "checksum": -1531972780, "seqId": 49919347543, "prevSeqId": 49919347489}], "record_time": 1742543256.054854}
{"arg": {"channel": "books", "instId": "BTC-USDT"}, "action": "update", "data": [{"asks": [["83847.8", "0.41386339", "0", "7"], ["83874.1", "0", "0", "0"], ["83874.4", "0.00357926", "0", "1"], ["83874.7", "0.25045", "0", "1"], ["83875", "0", "0", "0"], ["83877", "0", "0", "0"], ["83878.1", "0.052015", "0", "3"], ["83880", "0.23864102", "0", "1"], ["83884.7", "0.02693528", "0", "1"], ["83891", "0.00001", "0", "1"], ["83895.6", "0.25467588", "0", "2"], ["83912", "0", "0", "0"], ["84014.7", "0", "0", "0"]], "bids": [["83845.7", "0.34550205", "0", "7"], ["83824.3", "0.23864102", "0", "1"], ["83823.9", "0", "0", "0"], ["83811.8", "0.25045", "0", "1"], ["83806", "0.00001", "0", "1"], ["83790.8", "0.60864548", "0", "2"], ["83700.9", "0", "0", "0"], ["83700.6", "0", "0", "0"]], "ts": "1742543256203", "checksum": 2005909212, "seqId": 49919347576, "prevSeqId": 49919347543}], "record_time": 1742543256.153807}
{"arg": {"channel": "books", "instId": "BTC-USDT"}, "action": "update", "data": [{"asks": [["83854.1", "0.2185", "0", "2"], ["83876.3", "0", "0", "0"], ["83880", "0.23863931", "0", "1"], ["83916.2", "0", "0", "0"], ["83917.8", "0.012752", "0", "1"], ["83973.7", "0", "0", "0"], ["84014.7", "0.00001097", "0", "1"], ["84014.8", "0.01299784", "0", "1"]], "bids": [["83847.7", "1.76320776", "0", "7"], ["83844.5", "0", "0", "0"], ["83843", "0.01193196", "0", "1"], ["83837.5", "0.03868101", "0", "1"], ["83833.4", "0", "0", "0"], ["83796.8", "0.01837507", "0", "1"], ["83794.3", "0", "0", "0"], ["83725.6", "0.18375071", "0", "1"], ["83723.7", "0", "0", "0"]], "ts": "1742543256303", "checksum": 2011154008, "seqId": 49919347599, "prevSeqId": 49919347576}], "record_time": 1742543256.354414}
{"arg": {"channel": "books", "instId": "BTC-USDT"}, "action": "update", "data": [{"asks": [["83847.8", "0.0648", "0", "3"], ["83854.1", "0.2025", "0", "1"], ["83856.7", "0", "0", "0"], ["83856.9", "0.0640058", "0", "1"], ["83857.2", "0.06638717", "0", "1"], ["83857.3", "0.04592172", "0", "2"], ["83858.1", "0", "0", "0"], ["83858.3", "0.06274875", "0", "1"], ["83859.7", "0", "0", "0"], ["83861.3", "0.00001501", "0", "1"], ["83861.8", "0.06665085", "0", "1"], ["83862.8", "0.01967", "0", "1"], ["83863.2", "0.052", "0", "2"], ["83863.5", "0.10099968", "0", "1"], ["83865.4", "0", "0", "0"], ["83865.7", "0.09574111", "0", "1"], ["83866.9", "0", "0", "0"], ["83867.1", "0.10258888", "0", "1"], ["83870.4", "0.51721482", "0", "1"], ["83870.5", "0.35779", "0", "1"], ["83871.1", "0", "0", "0"], ["83871.7", "0.09617982", "0", "1"], ["83872.1", "0", "0", "0"], ["83872.3", "0.17310853", "0", "1"], ["83872.6", "0", "0", "0"], ["83872.9", "0.26900753", "0", "2"], ["83875.1", "0.29634092", "0", "1"], ["83875.6", "0", "0", "0"], ["83875.8", "0.1624221", "0", "1"], ["83881", "0", "0", "0"], ["83881.5", "0.15602308", "0", "1"], ["83888", "0.12523", "0", "1"], ["83888.8", "0.08007588", "0", "3"], ["83889.6", "0.03999999", "0", "1"], ["83916.2", "0.01275227", "0", "1"], ["83917.8", "0", "0", "0"], ["83939.7", "0.97511471", "0", "1"], ["83942.2", "0.08689791", "0", "1"], ["83950.6", "0.23825188", "0", "1"], ["83956.2", "0.00580055", "0", "1"], ["83959.8", "0.11920092", "0", "2"], ["84013.3", "0", "0", "0"], ["84013.4", "0", "0", "0"], ["84013.7", "0", "0", "0"], ["84014.6", "0", "0", "0"], ["84014.7", "0", "0", "0"], ["84014.8", "0", "0", "0"]], "bids": [["83847.7", "1.76647776", "0", "8"], ["83814.4", "0", "0", "0"], ["83813.6", "0.00079879", "0", "2"], ["83812.8", "0.0003988", "0", "1"], ["83806.1", "0.34772622", "0", "1"], ["83806", "1.00001", "0", "2"], ["83804.1", "0", "0", "0"], ["83796.8", "0", "0", "0"], ["83794.3", "0.01837505", "0", "1"], ["83789", "0.2", "0", "1"], ["83725.6", "0", "0", "0"], ["83723.7", "0.18375056", "0", "1"], ["83701", "0", "0", "0"]], "ts": "1742543256403", "checksum": -1510769126, "seqId": 49919347677, "prevSeqId": 49919347599}], "record_time": 1742543256.359166}
{"arg": {"channel": "books", "instId": "BTC-USDT"}, "action": "update", "data": [{"asks": [["83847.8", "0.06477082", "0", "3"], ["83852.3", "0.01193179", "0", "1"], ["83854.1", "0", "0", "0"], ["83856.2", "0.2025", "0", "1"], ["83865.9", "0.45629463", "0", "1"], ["83869.6", "0.005", "0", "1"], ["83874.6", "0.49179426", "0", "1"], ["83875.1", "0", "0", "0"], ["83877.7", "0.00423", "0", "1"], ["83878", "0.23863904", "0", "1"], ["83880", "0", "0", "0"], ["83908.3", "0.11088102", "0", "1"], ["83909.2", "0", "0", "0"], ["83909.3", "0", "0", "0"], ["83916.2", "0", "0", "0"], ["83917.8", "0.01275227", "0", "1"], ["83942.2", "0.17544155", "0", "2"], ["83946.2", "0.11668399", "0", "1"], ["84002.7", "0", "0", "0"], ["84013.2", "0", "0", "0"]], "bids": [["83818.4", "0.28709027", "0", "1"], ["83815.5", "0.01774536", "0", "1"], ["83815.4", "0", "0", "0"], ["83796.1", "0.01837513", "0", "1"], ["83794.3", "0", "0", "0"], ["83789", "0", "0", "0"], ["83788.2", "0.1553078", "0", "1"], ["83786.1", "0", "0", "0"], ["83753.7", "0", "0", "0"], ["83725.2", "0.18375135", "0", "1"], ["83723.7", "0", "0", "0"], ["83701", "0.001", "0", "1"], ["83700.9", "0.00001011", "0", "1"], ["83700.6", "0.00011879", "0", "1"]], "ts": "1742543256503", "checksum": -1061236910, "seqId": 49919347709, "prevSeqId": 49919347677}], "record_time": 1742543256.453659}
{"arg": {"channel": "books", "instId": "BTC-USDT"}, "action": "update", "data": [{"asks": [["83870.4", "0.92766241", "0", "2"], ["83873.1", "1.59064701", "0", "1"], ["83877.7", "0", "0", "0"], ["83878", "0", "0", "0"], ["83880", "0.2386375", "0", "1"], ["83899.7", "0.97289018", "0", "2"], ["83902.4", "2.78276084", "0", "1"], ["84012.3", "0", "0", "0"]], "bids": [["83813.6", "0.81131504", "0", "3"], ["83813.5", "1.5310528", "0", "1"], ["83813.4", "0", "0", "0"], ["83784.3", "1.33339548", "0", "1"], ["83784.2", "2.70559678", "0", "1"], ["83783.4", "0.00001201", "0", "1"], ["83700.9", "0", "0", "0"], ["83700.6", "0", "0", "0"]], "ts": "1742543256603", "checksum": -1061236910, "seqId": 49919347727, "prevSeqId": 49919347709}], "record_time": 1742543256.557391}
{"arg": {"channel": "books", "instId": "BTC-USDT"}, "action": "update", "data": [{"asks": [["83877.7", "0.0000165", "0", "1"], ["83878.9", "0.23864079", "0", "1"], ["83880", "0", "0", "0"], ["84012.2", "0", "0", "0"]], "bids": [["83824.3", "0.23864079", "0", "1"], ["83823", "0.0812013", "0", "2"], ["83822.8", "0", "0", "0"], ["83806.1", "0.04772622", "0", "1"], ["83806", "0.00001", "0", "1"], ["83700.9", "0.00001011", "0", "1"]], "ts": "1742543256703", "checksum": -1061236910, "seqId": 49919347744, "prevSeqId": 49919347727}], "record_time": 1742543256.655917}
{"arg": {"channel": "books", "instId": "BTC-USDT"}, "action": "update", "data": [{"asks": [["83877.3", "0.23865589", "0", "2"], ["83878.9", "0", "0", "0"], ["84012.2", "0.08991011", "0", "1"]], "bids": [["83824.3", "0", "0", "0"], ["83823.1", "0.23864389", "0", "1"], ["83815.5", "0", "0", "0"], ["83753.7", "0.01774536", "0", "1"]], "ts": "1742543256803", "checksum": -1061236910, "seqId": 49919347752, "prevSeqId": 49919347744}], "record_time": 1742543256.752822}
{"arg": {"channel": "books", "instId": "BTC-USDT"}, "action": "update", "data": [{"asks": [["83877.3", "0.23865449", "0", "2"]], "bids": [["83823.4", "0.15278204", "0", "1"], ["83823.3", "0.23864249", "0", "1"], ["83823.1", "0", "0", "0"], ["83823", "0.00001201", "0", "1"], ["83700.9", "0", "0", "0"]], "ts": "1742543256903", "checksum": -1061236910, "seqId": 49919347768, "prevSeqId": 49919347752}], "record_time": 1742543256.853177}
{"arg": {"channel": "books", "instId": "BTC-USDT"}, "action": "update", "data": [{"asks": [["83851.9", "0", "0", "0"], ["83874.4", "0", "0", "0"], ["83886.6", "0.405", "0", "2"], ["84012.3", "0.03", "0", "1"], ["84013.2", "0.0000185", "0", "1"]], "bids": [["83824.5", "0.01257355", "0", "2"]], "ts": "1742543257003", "checksum": -1367970062, "seqId": 49919347774, "prevSeqId": 49919347768}], "record_time": 1742543256.954502}
{"arg": {"channel": "books", "instId": "BTC-USDT"}, "action": "update", "data": [{"asks": [["83877.3", "0.000012", "0", "1"], ["83878.1", "0.29065658", "0", "4"], ["83888", "0.20523", "0", "3"], ["83888.8", "0.04007588", "0", "2"], ["83889.6", "0", "0", "0"], ["83890.2", "0.093122", "0", "1"], ["83900.3", "0", "0", "0"], ["84013.3", "0.00001653", "0", "1"], ["84013.4", "0.000015", "0", "1"]], "bids": [["83823.9", "0.23864158", "0", "1"], ["83823.4", "0.08118929", "0", "1"], ["83823.3", "0", "0", "0"]], "ts": "1742543257103", "checksum": -1367970062, "seqId": 49919347789, "prevSeqId": 49919347774}], "record_time": 1742543257.055465}
{"arg": {"channel": "books", "instId": "BTC-USDT"}, "action": "update", "data": [{"asks": [["83847.8", "0.06232356", "0", "3"], ["83870", "0.2", "0", "1"], ["83874", "1.1227708", "0", "4"], ["83878.1", "0.052015", "0", "3"], ["83880", "0.23864103", "0", "1"], ["83908.9", "0.12523", "0", "1"], ["84013.3", "0", "0", "0"], ["84013.4", "0", "0", "0"]], "bids": [["83824.3", "0.23864103", "0", "1"], ["83823.9", "0", "0", "0"], ["83814.4", "0.0008", "0", "2"], ["83813.6", "0.81091504", "0", "2"], ["83812.8", "0", "0", "0"]], "ts": "1742543257203", "checksum": -856456680, "seqId": 49919347811, "prevSeqId": 49919347789}], "record_time": 1742543257.154175}
{"arg": {"channel": "books", "instId": "BTC-USDT"}, "action": "update", "data": [{"asks": [["83847.8", "0.0648", "0", "3"], ["83856.9", "0.06190921", "0", "1"], ["83857.2", "0.10032401", "0", "2"], ["83857.3", "0", "0", "0"], ["83858.3", "0.06217016", "0", "1"], ["83861.8", "0.06119832", "0", "1"], ["83863.5", "0.10180459", "0", "1"], ["83867", "0.135939", "0", "1"], ["83867.1", "0.09314511", "0", "1"], ["83871.7", "0.09450462", "0", "1"], ["83872.3", "0.15291004", "0", "1"], ["83872.9", "0.26133875", "0", "2"], ["83875.8", "0", "0", "0"], ["83880", "0.23863953", "0", "1"], ["83881.5", "0.16334248", "0", "1"], ["83883", "0", "0", "0"], ["83908.9", "0.12531624", "0", "2"], ["84013.3", "0.00001653", "0", "1"], ["84013.4", "0.000015", "0", "1"]], "bids": [["83847.7", "1.78046776", "0", "7"], ["83843", "0", "0", "0"], ["83824.3", "0.23863953", "0", "1"], ["83700.9", "0.00001011", "0", "1"]], "ts": "1742543257303", "checksum": -723201863, "seqId": 49919347877, "prevSeqId": 49919347811}], "record_time": 1742543257.254189}
{"arg": {"channel": "books", "instId": "BTC-USDT"}, "action": "update", "data": [{"asks": [["83847.8", "0.0246", "0", "1"], ["83857.2", "0.11510404", "0", "3"], ["83874", "0.1227708", "0", "3"], ["83875.8", "0.17527118", "0", "1"], ["84013.4", "0", "0", "0"]], "bids": [["83782.6", "0", "0", "0"], ["83773.4", "0", "0", "0"], ["83709.9", "0", "0", "0"], ["83700.6", "0.00011879", "0", "1"], ["83700.5", "0.00002502", "0", "2"], ["83700.3", "0.00005632", "0", "2"]], "ts": "1742543257403", "checksum": -1712124731, "seqId": 49919347887, "prevSeqId": 49919347877}], "record_time": 1742543257.371247}
{"arg": {"channel": "books", "instId": "BTC-USDT"}, "action": "update", "data": [{"asks": [["83847.8", "0", "0", "0"], ["83848", "0", "0", "0"], ["83848.5", "0.0648", "0", "3"], ["83849.9", "0.02469954", "0", "1"], ["83853.5", "0.008", "0", "1"], ["83856.9", "0", "0", "0"], ["83857.2", "0.09453944", "0", "2"], ["83857.6", "0.06821221", "0", "1"], ["83858.1", "0.06553122", "0", "1"], ["83858.3", "0", "0", "0"], ["83859", "0.06958705", "0", "1"], ["83861.1", "0.02147733", "0", "1"], ["83861.8", "0", "0", "0"], ["83862.8", "0.06293189", "0", "1"], ["83863.5", "0", "0", "0"], ["83864.4", "0.09891857", "0", "1"], ["83865.7", "0", "0", "0"], ["83866.4", "0.10280829", "0", "1"], ["83867.1", "0", "0", "0"], ["83867.8", "0.45921479", "0", "3"], ["83871.7", "0", "0", "0"], ["83872.3", "0", "0", "0"], ["83872.6", "0.0980032", "0", "1"], ["83872.9", "0.102", "0", "1"], ["83873", "0.16117084", "0", "1"], ["83873.8", "0.16175196", "0", "1"], ["83875.8", "0", "0", "0"], ["83876.5", "0.17597432", "0", "2"], ["83881.5", "0", "0", "0"], ["83882.4", "0.1594111", "0", "3"], ["83892.2", "0", "0", "0"], ["83892.9", "0.1", "0", "1"], ["83959.8", "0.05958092", "0", "1"], ["84013.4", "0.000015", "0", "1"]], "bids": [["83848.4", "0.62429557", "0", "9"], ["83848", "0.0352", "0", "1"], ["83847.8", "0.63909343", "0", "1"], ["83847.7", "1.77694702", "0", "6"], ["83845.8", "0", "0", "0"], ["83829.8", "0.00477157", "0", "1"], ["83818.3", "0.2984841", "0", "2"], ["83814.4", "0.00079879", "0", "2"], ["83806.4", "0.026", "0", "2"], ["83805.6", "0.093", "0", "3"], ["83804.8", "0.04", "0", "1"], ["83804", "0", "0", "0"], ["83803.2", "0.00001201", "0", "1"], ["83802.4", "0.33656", "0", "3"], ["83801.6", "0.05", "0", "1"], ["83800.8", "0.29357058", "0", "1"], ["83798.4", "0.0166822", "0", "2"], ["83796", "0", "0", "0"], ["83792.1", "0.42125274", "0", "1"], ["83792", "0.2", "0", "1"], ["83791.4", "0", "0", "0"], ["83764.1", "0.01908875", "0", "1"], ["83742.9", "0.00105877", "0", "1"], ["83741.8", "0", "0", "0"], ["83734.7", "0.00116416", "0", "1"], ["83733.4", "0", "0", "0"], ["83704", "0.0029829", "0", "3"], ["83701", "0", "0", "0"], ["83700.9", "0", "0", "0"], ["83700.6", "0", "0", "0"], ["83700.5", "0", "0", "0"], ["83700.3", "0", "0", "0"]], "ts": "1742543257503", "checksum": 729768112, "seqId": 49919348085, "prevSeqId": 49919347887}], "record_time": 1742543257.453711}
{"arg": {"channel": "books", "instId": "BTC-USDT"}, "action": "update", "data": [{"asks": [["83870", "0", "0", "0"], ["83878.9", "0.23864099", "0", "1"], ["83880", "0", "0", "0"], ["84013.7", "0.0286", "0", "2"]], "bids": [["83847.7", "1.77271702", "0", "5"], ["83832", "0.19264624", "0", "2"], ["83830.2", "0.35476567", "0", "2"], ["83824.3", "0", "0", "0"], ["83823.4", "0.14263653", "0", "2"], ["83821.7", "0.23864099", "0", "1"], ["83806.4", "0", "0", "0"], ["83805.6", "0.026", "0", "2"], ["83804.8", "0.093", "0", "3"], ["83804", "0.04", "0", "1"], ["83798.4", "0.04465272", "0", "3"], ["83796.7", "0.10716018", "0", "2"], ["83792", "0", "0", "0"], ["83773.3", "0.0023602", "0", "1"], ["83746.6", "0", "0", "0"], ["83701", "0.001", "0", "1"]], "ts": "1742543257603", "checksum": 2113877033, "seqId": 49919348113, "prevSeqId": 49919348085}], "record_time": 1742543257.552345}
{"arg": {"channel": "books", "instId": "BTC-USDT"}, "action": "update", "data": [{"asks": [["83848.5", "0", "0", "0"], ["83848.6", "0.12241992", "0", "2"], ["83849.9", "0", "0", "0"], ["83853.6", "0", "0", "0"], ["83857.2", "0.07293911", "0", "2"], ["83857.6", "0", "0", "0"], ["83858", "0.07388101", "0", "2"], ["83858.1", "0", "0", "0"], ["83858.3", "0.06689782", "0", "1"], ["83858.7", "0.06620279", "0", "1"], ["83859", "0", "0", "0"], ["83861.1", "0", "0", "0"], ["83862.7", "0.07935388", "0", "2"], ["83862.8", "0", "0", "0"], ["83863.3", "0.06554857", "0", "1"], ["83864.4", "0", "0", "0"], ["83865", "0.10142937", "0", "1"], ["83866.4", "0", "0", "0"], ["83867.1", "0.10037727", "0", "1"], ["83867.8", "0.35805015", "0", "2"], ["83871.9", "0.002", "0", "1"], ["83872.6", "0", "0", "0"], ["83873", "0", "0", "0"], ["83873.2", "0.09877065", "0", "1"], ["83873.7", "0.15456001", "0", "1"], ["83873.8", "0", "0", "0"], ["83874.5", "0.17351677", "0", "1"], ["83876.5", "0.005", "0", "1"], ["83878.9", "0", "0", "0"], ["83882", "0.002", "0", "1"], ["83882.2", "0.23863553", "0", "1"], ["83882.4", "0.0008", "0", "2"], ["83883", "0.16419249", "0", "1"], ["84014.6", "0.00001012", "0", "1"], ["84014.7", "0.00001097", "0", "1"]], "bids": [["83848.5", "0.96659623", "0", "16"], ["83848.4", "0.80570548", "0", "3"], ["83847.8", "0", "0", "0"], ["83847.7", "1.74850702", "0", "4"], ["83846.5", "0.002", "0", "1"], ["83836.5", "0.002", "0", "1"], ["83824.3", "0.23863674", "0", "1"], ["83823.4", "0.08118929", "0", "1"], ["83821.7", "0", "0", "0"], ["83819.1", "0.00715827", "0", "1"], ["83806.1", "0.34176044", "0", "2"], ["83805.6", "0.106", "0", "4"], ["83805", "1", "0", "1"], ["83804.8", "0.053", "0", "2"], ["83804", "0", "0", "0"], ["83743.7", "0.0058005", "0", "1"], ["83701.7", "0", "0", "0"], ["83701.6", "0", "0", "0"], ["83701.2", "0", "0", "0"], ["83701", "0", "0", "0"]], "ts": "1742543257703", "checksum": -320314614, "seqId": 49919348248, "prevSeqId": 49919348113}], "record_time": 1742543257.654621}
{"arg": {"channel": "books", "instId": "BTC-USDT"}, "action": "update", "data": [{"asks": [["83859.7", "0.06965701", "0", "1"], ["83868.5", "0.10120978", "0", "1"], ["83877.2", "0.1592244", "0", "1"], ["83892.9", "0", "0", "0"], ["83893", "0.1", "0", "1"], ["84013.7", "0", "0", "0"], ["84014.6", "0", "0", "0"], ["84014.7", "0", "0", "0"]], "bids": [["83847.7", "1.74830702", "0", "2"], ["83813.7", "0.01774536", "0", "1"], ["83805.6", "0.026", "0", "2"], ["83804.8", "0.093", "0", "3"], ["83804", "0.04", "0", "1"], ["83802.4", "0.23656", "0", "1"], ["83801.6", "0.1", "0", "2"], ["83800.8", "0.34357058", "0", "2"], ["83796.8", "0.1", "0", "1"], ["83796.7", "0.00716018", "0", "1"], ["83753.7", "0", "0", "0"], ["83702", "0", "0", "0"], ["83701.9", "0", "0", "0"]], "ts": "1742543257803", "checksum": -1107472193, "seqId": 49919348271, "prevSeqId": 49919348248}], "record_time": 1742543257.758035}
{"arg": {"channel": "books", "instId": "BTC-USDT"}, "action": "update", "data": [{"asks": [], "bids": [["83802.4", "0.33656", "0", "3"], ["83801.6", "0.05", "0", "1"], ["83800.8", "0.29357058", "0", "1"]], "ts": "1742543257903", "checksum": -1107472193, "seqId": 49919348275, "prevSeqId": 49919348271}], "record_time": 1742543257.894273}
{"arg": {"channel": "books", "instId": "BTC-USDT"}, "action": "update", "data": [{"asks": [["83848.6", "0.15951992", "0", "3"], ["83853.5", "0", "0", "0"], ["83857.2", "0.0772161", "0", "2"], ["83858", "0.13759166", "0", "3"], ["83858.3", "0", "0", "0"], ["83858.4", "0.0646717", "0", "1"], ["83858.7", "0", "0", "0"], ["83859.4", "0.06769023", "0", "1"], ["83859.7", "0", "0", "0"], ["83863.1", "0.06838831", "0", "1"], ["83863.3", "0", "0", "0"], ["83864.7", "0.09549777", "0", "1"], ["83865", "0", "0", "0"], ["83866.7", "0.09650473", "0", "1"], ["83867.1", "0", "0", "0"], ["83868.2", "0.10523795", "0", "1"], ["83868.5", "0", "0", "0"], ["83872.9", "0.20023836", "0", "2"], ["83873.2", "0", "0", "0"], ["83873.4", "0.17500153", "0", "1"], ["83873.7", "0", "0", "0"], ["83874.2", "0.27632516", "0", "2"], ["83874.5", "0", "0", "0"], ["83876.9", "0.17193245", "0", "1"], ["83877.2", "0", "0", "0"], ["83882.8", "0.16746706", "0", "1"], ["83883", "0", "0", "0"], ["83884.7", "0", "0", "0"], ["83895.9", "0.02693528", "0", "1"], ["84013.7", "0.0286", "0", "2"], ["84014.6", "0.00001012", "0", "1"], ["84014.7", "0.00001097", "0", "1"], ["84014.8", "0.01299784", "0", "1"]], "bids": [], "ts": "1742543258003", "checksum": 2085228306, "seqId": 49919348305, "prevSeqId": 49919348275}], "record_time": 1742543257.954673}
{"arg": {"channel": "books", "instId": "BTC-USDT"}, "action": "update", "data": [{"asks": [["83880", "0.23863886", "0", "1"], ["83882.2", "0", "0", "0"], ["83908.9", "0.12523", "0", "1"], ["83910.9", "0.00008624", "0", "1"], ["84014.8", "0", "0", "0"]], "bids": [["83824.3", "0", "0", "0"], ["83823.6", "0.15278454", "0", "1"], ["83823.4", "0", "0", "0"], ["83821.7", "0.23863894", "0", "1"], ["83817.4", "1.24", "0", "1"], ["83796.1", "0", "0", "0"], ["83794.3", "0.01837515", "0", "1"], ["83746.7", "0", "0", "0"], ["83746.6", "0.00011816", "0", "1"], ["83743.6", "0.55527807", "0", "2"], ["83742.9", "0", "0", "0"], ["83705.1", "0.001786", "0", "1"], ["83704.5", "0", "0", "0"]], "ts": "1742543258103", "checksum": 2085228306, "seqId": 49919348345, "prevSeqId": 49919348305}], "record_time": 1742543258.052784}
{"arg": {"channel": "books", "instId": "BTC-USDT"}, "action": "update", "data": [{"asks": [["83848.6", "0.15707265", "0", "3"], ["83849.9", "0.02469954", "0", "1"], ["83857.2", "0.07814507", "0", "2"], ["83857.9", "0.06799227", "0", "1"], ["83858", "0.07388101", "0", "2"], ["83858.3", "0.06348666", "0", "1"], ["83858.4", "0", "0", "0"], ["83859.3", "0.06333623", "0", "1"], ["83859.4", "0", "0", "0"], ["83863", "0.06928907", "0", "1"], ["83863.1", "0", "0", "0"], ["83864.6", "0.10412648", "0", "1"], ["83864.7", "0", "0", "0"], ["83866.6", "0.09594698", "0", "2"], ["83866.7", "0", "0", "0"], ["83868", "0.13475206", "0", "2"], ["83868.2", "0", "0", "0"], ["83872.4", "0.00359099", "0", "2"], ["83872.8", "0.30692554", "0", "3"], ["83872.9", "0.102", "0", "1"], ["83873.3", "0.16000894", "0", "1"], ["83873.4", "0", "0", "0"], ["83874.1", "0.15687264", "0", "1"], ["83874.2", "0.105", "0", "1"], ["83876.8", "0.17108869", "0", "1"], ["83876.9", "0", "0", "0"], ["83878.9", "0.23863996", "0", "1"], ["83880", "0", "0", "0"], ["83882.7", "0.16189534", "0", "1"], ["83882.8", "0", "0", "0"], ["84014.7", "0", "0", "0"]], "bids": [["83823.6", "0", "0", "0"], ["83821.7", "0.23863996", "0", "1"], ["83818.4", "0.55160524", "0", "2"], ["83817.5", "0.01774536", "0", "1"], ["83813.7", "0", "0", "0"], ["83702", "0.71627081", "0", "1"]], "ts": "1742543258203", "checksum": 1386834215, "seqId": 49919348395, "prevSeqId": 49919348345}], "record_time": 1742543258.158783}
{"arg": {"channel": "books", "instId": "BTC-USDT"}, "action": "update", "data": [{"asks": [["83878.9", "0", "0", "0"], ["83880", "0.23863881", "0", "1"]], "bids": [["83848.5", "0.97374623", "0", "17"], ["83814.4", "0.00079871", "0", "2"]], "ts": "1742543258303", "checksum": 1887837447, "seqId": 49919348414, "prevSeqId": 49919348395}], "record_time": 1742543258.255369}
{"arg": {"channel": "books", "instId": "BTC-USDT"}, "action": "update", "data": [{"asks": [["83875", "1", "0", "1"], ["84014.6", "0", "0", "0"]], "bids": [["83821.7", "0.23863823", "0", "1"]], "ts": "1742543258403", "checksum": 1887837447, "seqId": 49919348422, "prevSeqId": 49919348414}], "record_time": 1742543258.418837}
{"arg": {"channel": "books", "instId": "BTC-USDT"}, "action": "update", "data": [{"asks": [["83849.9", "0", "0", "0"], ["83855.9", "0.008", "0", "1"], ["83857.2", "0.07832114", "0", "2"], ["83857.9", "0", "0", "0"], ["83858", "0.14005365", "0", "3"], ["83858.3", "0", "0", "0"], ["83858.5", "0.06589316", "0", "1"], ["83859.3", "0", "0", "0"], ["83859.4", "0.06170159", "0", "1"], ["83863", "0", "0", "0"], ["83863.1", "0.06611634", "0", "1"], ["83864.6", "0", "0", "0"], ["83864.8", "0.09454602", "0", "1"], ["83866.6", "0.00060645", "0", "1"], ["83866.7", "0.09413681", "0", "1"], ["83868", "0.0352", "0", "1"], ["83868.2", "0.09326775", "0", "1"], ["83872.8", "0.213", "0", "2"], ["83872.9", "0.20301664", "0", "2"], ["83873.3", "0", "0", "0"], ["83873.4", "0.16803454", "0", "1"], ["83874.1", "0", "0", "0"], ["83874.2", "0.27572439", "0", "2"], ["83876.8", "0", "0", "0"], ["83876.9", "0.1612736", "0", "1"], ["83880", "0.23863918", "0", "1"], ["83882.7", "0", "0", "0"], ["83882.8", "0.17234185", "0", "1"]], "bids": [["83821.7", "0.23863918", "0", "1"]], "ts": "1742543258503", "checksum": -2017614115, "seqId": 49919348468, "prevSeqId": 49919348422}], "record_time": 1742543258.453897}
{"arg": {"channel": "books", "instId": "BTC-USDT"}, "action": "update", "data": [{"asks": [["83849.9", "0.02469954", "0", "1"], ["83857.2", "0.07771749", "0", "2"], ["83857.9", "0.06563836", "0", "1"], ["83858", "0.07388101", "0", "2"], ["83858.3", "0.0644153", "0", "1"], ["83858.5", "0", "0", "0"], ["83859.3", "0.06862887", "0", "1"], ["83859.4", "0", "0", "0"], ["83863", "0.06405409", "0", "1"], ["83863.1", "0", "0", "0"], ["83864.6", "0.10041184", "0", "1"], ["83864.8", "0", "0", "0"], ["83866.6", "0.10088265", "0", "2"], ["83866.7", "0", "0", "0"], ["83868", "0.13382076", "0", "2"], ["83868.2", "0", "0", "0"], ["83870", "0.2", "0", "1"], ["83872.8", "0.30574168", "0", "3"], ["83872.9", "0.102", "0", "1"], ["83873.3", "0.16116297", "0", "1"], ["83873.4", "0", "0", "0"], ["83874.1", "0.17370892", "0", "1"], ["83874.2", "0.105", "0", "1"], ["83876.8", "0.15319726", "0", "1"], ["83876.9", "0", "0", "0"], ["83882.7", "0.15573412", "0", "1"], ["83882.8", "0", "0", "0"], ["84013.4", "0", "0", "0"], ["84013.7", "0", "0", "0"]], "bids": [["83813.6", "0.81091496", "0", "2"], ["83802.4", "0.23656", "0", "1"], ["83801.6", "0.1", "0", "2"], ["83800.8", "0.34357058", "0", "2"]], "ts": "1742543258603", "checksum": -1922701692, "seqId": 49919348505, "prevSeqId": 49919348468}], "record_time": 1742543258.553791}
{"arg": {"channel": "books", "instId": "BTC-USDT"}, "action": "update", "data": [{"asks": [["83848.6", "0.11997265", "0", "2"], ["83849.9", "0", "0", "0"], ["83857.2", "0.07767795", "0", "2"], ["83857.9", "0", "0", "0"], ["83858.3", "0.06436291", "0", "1"], ["83858.7", "0.06555895", "0", "1"], ["83859.3", "0", "0", "0"], ["83863", "0", "0", "0"], ["83864.6", "0", "0", "0"], ["83865", "0.1007846", "0", "1"], ["83866.6", "0.00060645", "0", "1"], ["83867.1", "0.09830684", "0", "1"], ["83868", "0.0352", "0", "1"], ["83872.8", "0.213", "0", "2"], ["83873.2", "0.09363164", "0", "1"], ["83873.3", "0", "0", "0"], ["83873.7", "0.15300719", "0", "1"], ["83874.1", "0", "0", "0"], ["83874.5", "0.16998621", "0", "1"], ["83876.8", "0", "0", "0"], ["83880", "0.23863796", "0", "1"], ["83882.4", "0", "0", "0"], ["83882.7", "0", "0", "0"], ["83883", "0.17324972", "0", "1"], ["83883.2", "0.0008", "0", "2"], ["83884", "0.0004", "0", "1"], ["83888", "0.12523", "0", "1"], ["83888.8", "0.08007588", "0", "3"], ["83889.6", "0.03999999", "0", "1"], ["84013.4", "0.000015", "0", "1"]], "bids": [["83848.5", "0.97597138", "0", "18"], ["83840.2", "0.00252329", "0", "1"], ["83823.9", "0.23863796", "0", "1"], ["83821.7", "0", "0", "0"], ["83806.1", "0.04772622", "0", "1"], ["83805", "0", "0", "0"]], "ts": "1742543258703", "checksum": -1470485276, "seqId": 49919348591, "prevSeqId": 49919348505}], "record_time": 1742543258.653931}
{"arg": {"channel": "books", "instId": "BTC-USDT"}, "action": "update", "data": [{"asks": [["83849.9", "0.02469954", "0", "1"], ["83857.2", "0.07808866", "0", "2"], ["83858.2", "0.06650194", "0", "1"], ["83858.3", "0", "0", "0"], ["83858.6", "0.06478895", "0", "1"], ["83858.7", "0", "0", "0"], ["83859.6", "0.06759918", "0", "1"], ["83863.2", "0.11719254", "0", "3"], ["83864.9", "0.09335436", "0", "1"], ["83865", "0", "0", "0"], ["83866.9", "0.09468108", "0", "1"], ["83867.1", "0", "0", "0"], ["83868.3", "0.09669936", "0", "1"], ["83873.1", "1.69508284", "0", "2"], ["83873.2", "0", "0", "0"], ["83873.6", "0.19383643", "0", "2"], ["83873.7", "0", "0", "0"], ["83874.3", "0.17099131", "0", "1"], ["83874.5", "0", "0", "0"], ["83877.1", "0.17437959", "0", "1"], ["83880", "0", "0", "0"], ["83882.2", "0.23863694", "0", "1"], ["83882.9", "0.15566881", "0", "1"], ["83883", "0", "0", "0"], ["84013.3", "0", "0", "0"], ["84013.4", "0", "0", "0"]], "bids": [["83848.5", "0.97598138", "0", "19"], ["83824.3", "0.23863694", "0", "1"], ["83823.9", "0", "0", "0"], ["83817.5", "0", "0", "0"], ["83804.8", "0.013", "0", "1"], ["83804", "0.08", "0", "2"], ["83803.2", "0.04001201", "0", "2"], ["83753.7", "0.01774536", "0", "1"]], "ts": "1742543258803", "checksum": 1786386739, "seqId": 49919348666, "prevSeqId": 49919348591}], "record_time": 1742543258.753588}
{"arg": {"channel": "books", "instId": "BTC-USDT"}, "action": "update", "data": [{"asks": [["83848.6", "0.15707265", "0", "3"], ["83857.2", "0.07705721", "0", "2"], ["83857.9", "0.06382666", "0", "1"], ["83858.2", "0", "0", "0"], ["83858.3", "0.06402604", "0", "1"], ["83858.6", "0", "0", "0"], ["83859.3", "0.06155047", "0", "1"], ["83859.6", "0", "0", "0"], ["83863", "0.06606465", "0", "1"], ["83863.2", "0.052", "0", "2"], ["83864.6", "0.10559815", "0", "1"], ["83864.9", "0", "0", "0"], ["83866.6", "0.09467237", "0", "2"], ["83866.9", "0", "0", "0"], ["83868", "0.13372843", "0", "2"], ["83868.3", "0", "0", "0"], ["83870", "0", "0", "0"], ["83872.4", "0.000012", "0", "1"], ["83872.8", "0.30823224", "0", "3"], ["83873.1", "1.59064701", "0", "1"], ["83873.3", "0.15945909", "0", "1"], ["83873.6", "0.04", "0", "1"], ["83874.1", "0.16880068", "0", "1"], ["83874.3", "0", "0", "0"], ["83875", "0", "0", "0"], ["83876.8", "0.17525522", "0", "1"], ["83877.1", "0", "0", "0"], ["83880", "0.23863945", "0", "1"], ["83882.2", "0", "0", "0"], ["83882.7", "0.1719305", "0", "1"], ["83882.9", "0", "0", "0"], ["83891.1", "0.00357896", "0", "1"], ["84003", "0.0025", "0", "1"], ["84013.3", "0.00001653", "0", "1"]], "bids": [["83848.4", "0.80568448", "0", "2"], ["83824.3", "0", "0", "0"], ["83821.7", "0.23863945", "0", "1"], ["83796.8", "0.11837511", "0", "2"], ["83794.3", "0", "0", "0"], ["83725.5", "0.19535177", "0", "3"], ["83725.2", "0", "0", "0"], ["83701.9", "0.00011924", "0", "1"], ["83701.7", "0.01775437", "0", "1"]], "ts": "1742543258903", "checksum": -1870349474, "seqId": 49919348726, "prevSeqId": 49919348666}], "record_time": 1742543258.854578}
{"arg": {"channel": "books", "instId": "BTC-USDT"}, "action": "update", "data": [{"asks": [], "bids": [["83848.5", "0.68295109", "0", "17"], ["83823.9", "0.23863805", "0", "1"], ["83821.7", "0", "0", "0"], ["83804.8", "0.093", "0", "3"], ["83804", "0.04", "0", "1"], ["83803.2", "0.00001201", "0", "1"]], "ts": "1742543259003", "checksum": 863445652, "seqId": 49919348734, "prevSeqId": 49919348726}], "record_time": 1742543258.953598}
{"arg": {"channel": "books", "instId": "BTC-USDT"}, "action": "update", "data": [{"asks": [], "bids": [["83848.5", "0.68297359", "0", "18"], ["83823.9", "0", "0", "0"], ["83821.7", "0.2386395", "0", "1"]], "ts": "1742543259103", "checksum": -1351098607, "seqId": 49919348737, "prevSeqId": 49919348734}], "record_time": 1742543259.052333}
{"arg": {"channel": "books", "instId": "BTC-USDT"}, "action": "update", "data": [{"asks": [["83848.6", "0.15462539", "0", "3"], ["83868", "0.0352", "0", "1"], ["83868.1", "0.13215254", "0", "2"]], "bids": [["83802.4", "0.33656", "0", "3"], ["83801.6", "0.05", "0", "1"], ["83800.8", "0.29357058", "0", "1"]], "ts": "1742543259203", "checksum": 1635751984, "seqId": 49919348745, "prevSeqId": 49919348737}], "record_time": 1742543259.152654}
{"arg": {"channel": "books", "instId": "BTC-USDT"}, "action": "update", "data": [{"asks": [["83849.9", "0", "0", "0"], ["83857.2", "0.07864147", "0", "2"], ["83857.9", "0", "0", "0"], ["83858", "0.14411195", "0", "3"], ["83858.3", "0", "0", "0"], ["83858.5", "0.06290263", "0", "1"], ["83859.3", "0", "0", "0"], ["83859.4", "0.06401541", "0", "1"], ["83861.7", "0.19108472", "0", "1"], ["83863", "0", "0", "0"], ["83863.1", "0.06766597", "0", "1"], ["83864.6", "0", "0", "0"], ["83864.8", "0.09524274", "0", "1"], ["83865.3", "0.17889", "0", "1"], ["83866.6", "0.00060645", "0", "1"], ["83866.8", "0.10105688", "0", "2"], ["83867.8", "0.17915015", "0", "1"], ["83868.1", "0.04", "0", "1"], ["83868.2", "0.09458788", "0", "1"], ["83872.8", "0.213", "0", "2"], ["83873", "0.09585791", "0", "1"], ["83873.1", "0", "0", "0"], ["83873.3", "0", "0", "0"], ["83873.4", "0.16681606", "0", "1"], ["83874.1", "0", "0", "0"], ["83874.2", "0.26379332", "0", "2"], ["83876.8", "0", "0", "0"], ["83876.9", "0.16531629", "0", "1"], ["83882.7", "0", "0", "0"], ["83882.8", "0.15952345", "0", "1"], ["83902.4", "0", "0", "0"], ["83940", "0", "0", "0"], ["84013.4", "0.000015", "0", "1"], ["84013.7", "0.0286", "0", "2"], ["84014.6", "0.00001012", "0", "1"]], "bids": [["83848.5", "0.67581359", "0", "16"], ["83821.7", "0.23863942", "0", "1"], ["83813.5", "0", "0", "0"], ["83784.2", "0", "0", "0"], ["83764.1", "0", "0", "0"], ["83704", "0.00085217", "0", "2"], ["83701.6", "0.00002279", "0", "1"], ["83701.2", "0.00001141", "0", "1"], ["83701", "0.001", "0", "1"]], "ts": "1742543259303", "checksum": -689063830, "seqId": 49919348799, "prevSeqId": 49919348745}], "record_time": 1742543259.254151}
{"arg": {"channel": "books", "instId": "BTC-USDT"}, "action": "update", "data": [{"asks": [["83848.6", "0.11442539", "0", "1"], ["83850", "0", "0", "0"], ["83851.9", "0.01413954", "0", "1"], ["83853", "0.187032", "0", "1"], ["83853.7", "0", "0", "0"], ["83857.2", "0.0673079", "0", "2"], ["83858", "0.07388101", "0", "2"], ["83858.5", "0", "0", "0"], ["83858.6", "0.06597631", "0", "1"], ["83858.9", "0.06537872", "0", "1"], ["83859.4", "0", "0", "0"], ["83860", "0.06160109", "0", "1"], ["83860.1", "0.016", "0", "1"], ["83863.1", "0", "0", "0"], ["83863.5", "0.06590965", "0", "1"], ["83864.8", "0", "0", "0"], ["83865.2", "0.10310342", "0", "1"], ["83866.8", "0.00890903", "0", "1"], ["83867.3", "0.10027699", "0", "1"], ["83868.2", "0", "0", "0"], ["83868.7", "0.09754711", "0", "1"], ["83870.4", "0.38483139", "0", "1"], ["83873", "0", "0", "0"], ["83873.3", "0.09329902", "0", "1"], ["83873.4", "0", "0", "0"], ["83874", "0.29026598", "0", "4"], ["83874.2", "0.105", "0", "1"], ["83874.7", "0.41535422", "0", "2"], ["83875.7", "1.60063169", "0", "2"], ["83876.9", "0", "0", "0"], ["83877.5", "0.15368017", "0", "1"], ["83877.8", "0.23863929", "0", "1"], ["83880", "0", "0", "0"], ["83882.8", "0", "0", "0"], ["83883.2", "0.16673926", "0", "3"], ["83899.7", "0.15778506", "0", "1"], ["83905.1", "2.89477667", "0", "1"], ["83955", "0.04434767", "0", "1"], ["84014.6", "0", "0", "0"]], "bids": [["83813.6", "1.55365103", "0", "2"], ["83784.3", "2.84580528", "0", "1"]], "ts": "1742543259403", "checksum": -538502777, "seqId": 49919348848, "prevSeqId": 49919348799}], "record_time": 1742543259.357126}
{"arg": {"channel": "books", "instId": "BTC-USDT"}, "action": "update", "data": [{"asks": [["83857.8", "0", "0", "0"], ["83877.8", "0", "0", "0"], ["83880", "0.23863575", "0", "1"], ["83882.4", "0.0008", "0", "2"], ["83883.2", "0.16633926", "0", "2"], ["83884", "0", "0", "0"], ["83888", "0.20523", "0", "3"], ["83888.8", "0.04007588", "0", "2"], ["83889.6", "0", "0", "0"], ["83904.6", "1.20153403", "0", "2"], ["83934.6", "0.01429685", "0", "1"], ["84014.6", "0.00001012", "0", "1"]], "bids": [["83824.3", "0.23863575", "0", "1"], ["83821.7", "0", "0", "0"], ["83815.2", "0.0108", "0", "3"], ["83814.4", "0.00039871", "0", "1"], ["83813.6", "1.55325232", "0", "1"], ["83771.9", "0.01908668", "0", "1"], ["83711.7", "0.00214741", "0", "2"], ["83701", "0", "0", "0"]], "ts": "1742543259503", "checksum": -1586063353, "seqId": 49919348878, "prevSeqId": 49919348848}], "record_time": 1742543259.50874}
{"arg": {"channel": "books", "instId": "BTC-USDT"}, "action": "update", "data": [{"asks": [["83848.6", "0.11752539", "0", "2"], ["83858.5", "0.06149732", "0", "1"], ["83858.6", "0", "0", "0"], ["83873.9", "0.16380716", "0", "1"], ["83874", "0.1227708", "0", "3"], ["83874.6", "0.64755604", "0", "2"], ["83874.7", "0.25045", "0", "1"], ["83912.4", "0", "0", "0"], ["83996.4", "0", "0", "0"], ["84014.7", "0.00001097", "0", "1"]], "bids": [["83848.5", "0.67579109", "0", "15"], ["83808.2", "0.00001201", "0", "1"], ["83724.3", "0.04308938", "0", "5"]], "ts": "1742543259603", "checksum": 1909170318, "seqId": 49919348902, "prevSeqId": 49919348878}], "record_time": 1742543259.560113}
{"arg": {"channel": "books", "instId": "BTC-USDT"}, "action": "update", "data": [{"asks": [["83848.6", "0.15462539", "0", "3"], ["83857.2", "0.06389629", "0", "2"], ["83858.2", "0.06753167", "0", "1"], ["83858.5", "0", "0", "0"], ["83858.6", "0.06845131", "0", "1"], ["83858.9", "0", "0", "0"], ["83859.6", "0.06418638", "0", "1"], ["83860", "0", "0", "0"], ["83863.3", "0.0693621", "0", "1"], ["83863.5", "0", "0", "0"], ["83864.9", "0.10055117", "0", "1"], ["83865.2", "0", "0", "0"], ["83866.9", "0.09199967", "0", "1"], ["83867.3", "0", "0", "0"], ["83868.4", "0.09819337", "0", "1"], ["83868.7", "0", "0", "0"], ["83873.1", "0.09241718", "0", "1"], ["83873.3", "0", "0", "0"], ["83873.6", "0.20418691", "0", "2"], ["83873.9", "0", "0", "0"], ["83874.4", "0.16343605", "0", "1"], ["83874.6", "0.49179426", "0", "1"], ["83877.1", "0.17172728", "0", "1"], ["83877.5", "0", "0", "0"], ["83882.9", "0.16206294", "0", "1"], ["83883.2", "0.0004", "0", "1"], ["84014.7", "0", "0", "0"]], "bids": [["83848.5", "0.68719209", "0", "17"], ["83805", "1", "0", "1"], ["83701.2", "0", "0", "0"]], "ts": "1742543259703", "checksum": 1397149774, "seqId": 49919348933, "prevSeqId": 49919348902}], "record_time": 1742543259.65279}
{"arg": {"channel": "books", "instId": "BTC-USDT"}, "action": "update", "data": [{"asks": [["83848.6", "0.11752539", "0", "2"], ["83857.2", "0.06280756", "0", "2"], ["83858.2", "0", "0", "0"], ["83858.5", "0.06981927", "0", "1"], ["83858.6", "0", "0", "0"], ["83858.9", "0.06253461", "0", "1"], ["83859.6", "0", "0", "0"], ["83860", "0.06852842", "0", "1"], ["83863.3", "0", "0", "0"], ["83863.5", "0.06891273", "0", "1"], ["83864.9", "0", "0", "0"], ["83865.2", "0.09884393", "0", "1"], ["83866.9", "0", "0", "0"], ["83867.3", "0.10233114", "0", "1"], ["83868.4", "0", "0", "0"], ["83868.7", "0.09637512", "0", "1"], ["83873.1", "0", "0", "0"], ["83873.3", "0.09368686", "0", "1"], ["83873.6", "0.04", "0", "1"], ["83873.9", "0.15701652", "0", "1"], ["83874.4", "0", "0", "0"], ["83874.6", "0.64636809", "0", "2"], ["83877.1", "0", "0", "0"], ["83877.5", "0.17293174", "0", "1"], ["83878.9", "0.23863881", "0", "1"], ["83880", "0", "0", "0"], ["83882.9", "0", "0", "0"], ["83883.2", "0.15709044", "0", "2"], ["83888", "0.12523", "0", "1"], ["83888.8", "0.08007588", "0", "3"], ["83889.6", "0.03999999", "0", "1"], ["83893.1", "0.472379", "0", "1"], ["83922.3", "0", "0", "0"], ["83922.4", "0", "0", "0"], ["84014.7", "0.00001097", "0", "1"]], "bids": [["83824.3", "0", "0", "0"], ["83821.7", "0.23863881", "0", "1"], ["83815.2", "0.01", "0", "1"], ["83814.4", "0.00079871", "0", "2"], ["83813.7", "0.81717608", "0", "1"], ["83813.6", "1.55365103", "0", "2"], ["83802.4", "0.23656", "0", "1"], ["83801.6", "0.1", "0", "2"], ["83800.8", "0.34357058", "0", "2"], ["83784.4", "1.37898358", "0", "2"], ["83701.6", "0", "0", "0"]], "ts": "1742543259803", "checksum": -1320741182, "seqId": 49919348983, "prevSeqId": 49919348933}], "record_time": 1742543259.752481}
{"arg": {"channel": "books", "instId": "BTC-USDT"}, "action": "update", "data": [{"asks": [["83848.6", "0.15462539", "0", "3"], ["83857.2", "0.06330995", "0", "2"], ["83858.2", "0.06419322", "0", "1"], ["83858.5", "0", "0", "0"], ["83858.6", "0.0698353", "0", "1"], ["83858.9", "0", "0", "0"], ["83859.6", "0.06405809", "0", "1"], ["83860", "0", "0", "0"], ["83863.3", "0.06628249", "0", "1"], ["83863.5", "0", "0", "0"], ["83864.9", "0.09650553", "0", "1"], ["83865.2", "0", "0", "0"], ["83866.9", "0.09635887", "0", "1"], ["83867.3", "0", "0", "0"], ["83868.4", "0.09576544", "0", "1"], ["83868.7", "0", "0", "0"], ["83873.1", "0.1042804", "0", "1"], ["83873.3", "0", "0", "0"], ["83873.6", "0.21158929", "0", "2"], ["83873.9", "0", "0", "0"], ["83874.4", "0.16910724", "0", "1"], ["83874.6", "0.49179426", "0", "1"], ["83877.1", "0.15789599", "0", "1"], ["83877.5", "0", "0", "0"], ["83878.9", "0", "0", "0"], ["83880", "0.23863709", "0", "1"], ["83882.9", "0.15428473", "0", "1"], ["83883.2", "0.0004", "0", "1"], ["84014.7", "0", "0", "0"]], "bids": [["83824.3", "0.23863709", "0", "1"], ["83821.7", "0", "0", "0"], ["83817.5", "0.01774536", "0", "1"], ["83802.4", "0.33656", "0", "3"], ["83801.6", "0.05", "0", "1"], ["83800.8", "0.29357058", "0", "1"], ["83753.7", "0", "0", "0"]], "ts": "1742543259903", "checksum": 1788101375, "seqId": 49919349024, "prevSeqId": 49919348983}], "record_time": 1742543259.853121}
{"arg": {"channel": "books", "instId": "BTC-USDT"}, "action": "update", "data": [{"asks": [["83850", "0.0352", "0", "1"], ["83857.2", "0.03096811", "0", "1"], ["83858.2", "0", "0", "0"], ["83858.3", "0.06139038", "0", "1"], ["83858.6", "0", "0", "0"], ["83858.7", "0.07075652", "0", "1"], ["83859.6", "0", "0", "0"], ["83863.3", "0.06774632", "0", "1"], ["83864.9", "0", "0", "0"], ["83865", "0.10029981", "0", "1"], ["83866.9", "0", "0", "0"], ["83867.1", "0.09758454", "0", "1"], ["83868.4", "0", "0", "0"], ["83873.1", "0", "0", "0"], ["83873.2", "0.09708644", "0", "1"], ["83873.6", "0.04", "0", "1"], ["83873.7", "0.1623142", "0", "1"], ["83874.4", "0", "0", "0"], ["83874.5", "0.17024407", "0", "1"], ["83877.1", "0", "0", "0"], ["83877.2", "0.17255555", "0", "1"], ["83878.9", "0.23863938", "0", "1"], ["83880", "0", "0", "0"], ["83882.9", "0", "0", "0"], ["83883", "0.17480857", "0", "1"]], "bids": [["83848.5", "0.68294109", "0", "16"], ["83824.3", "0", "0", "0"], ["83821.7", "0.23863938", "0", "1"], ["83815.2", "0.0108", "0", "3"], ["83814.4", "0.00039871", "0", "1"], ["83813.6", "1.55325232", "0", "1"]], "ts": "1742543260003", "checksum": -283837927, "seqId": 49919349061, "prevSeqId": 49919349024}], "record_time": 1742543260.002328}
{"arg": {"channel": "books", "instId": "BTC-USDT"}, "action": "update", "data": [{"asks": [["83857.2", "0.08149673", "0", "2"], ["83858", "0.13846087", "0", "3"], ["83858.3", "0", "0", "0"], ["83858.4", "0.06539827", "0", "1"], ["83858.7", "0", "0", "0"], ["83859.4", "0.064673", "0", "1"], ["83863.1", "0.06628544", "0", "1"], ["83863.3", "0", "0", "0"], ["83864.7", "0.09777351", "0", "1"], ["83865", "0", "0", "0"], ["83866.7", "0.0941636", "0", "1"], ["83867.1", "0", "0", "0"], ["83868.2", "0.09730834", "0", "1"], ["83872.9", "0.20446505", "0", "2"], ["83873.2", "0", "0", "0"], ["83873.4", "0.17047183", "0", "1"], ["83873.7", "0", "0", "0"], ["83874.2", "0.26070283", "0", "2"], ["83874.5", "0", "0", "0"], ["83876.9", "0.16099545", "0", "1"], ["83877.2", "0", "0", "0"], ["83878.9", "0", "0", "0"], ["83880", "0.23863779", "0", "1"], ["83882.8", "0.17486056", "0", "1"], ["83883", "0", "0", "0"], ["84014.7", "0.00001097", "0", "1"]], "bids": [["83823.9", "0.23863852", "0", "1"], ["83821.7", "0", "0", "0"], ["83802.4", "0.23656", "0", "1"], ["83801.6", "0.1", "0", "2"], ["83800.8", "0.34357058", "0", "2"], ["83796.9", "0.01837506", "0", "1"], ["83796.8", "0.1", "0", "1"], ["83725.6", "0.18375061", "0", "1"], ["83725.5", "0.0116006", "0", "2"], ["83701.9", "0", "0", "0"], ["83701.7", "0", "0", "0"]], "ts": "1742543260103", "checksum": 233473863, "seqId": 49919349114, "prevSeqId": 49919349061}], "record_time": 1742543260.063957}
{"arg": {"channel": "books", "instId": "BTC-USDT"}, "action": "update", "data": [{"asks": [["83848.6", "0.15217812", "0", "3"], ["83858.4", "0", "0", "0"], ["83858.5", "0.06789393", "0", "1"], ["83864.7", "0", "0", "0"], ["83864.8", "0.09285306", "0", "1"], ["83866.7", "0", "0", "0"], ["83866.8", "0.11032188", "0", "2"], ["83872.9", "0.102", "0", "1"], ["83873", "0.10488336", "0", "1"]], "bids": [["83848.5", "0.68295109", "0", "17"], ["83805", "0", "0", "0"], ["83802.4", "0.33656", "0", "3"], ["83801.6", "0.05", "0", "1"], ["83800.8", "0.29357058", "0", "1"], ["83701.9", "0.00011924", "0", "1"]], "ts": "1742543260203", "checksum": 270064698, "seqId": 49919349152, "prevSeqId": 49919349114}], "record_time": 1742543260.154809}
{"arg": {"channel": "books", "instId": "BTC-USDT"}, "action": "update", "data": [{"asks": [["83888", "0.20523", "0", "3"], ["83888.8", "0.04007588", "0", "2"], ["83889.6", "0", "0", "0"], ["84014.8", "0.01299784", "0", "1"]], "bids": [["83817.5", "0", "0", "0"], ["83815.2", "0.01", "0", "1"], ["83814.4", "0.00079871", "0", "2"], ["83813.6", "1.55365103", "0", "2"], ["83802.4", "0.23656", "0", "1"], ["83801.6", "0.1", "0", "2"], ["83800.8", "0.34357058", "0", "2"], ["83753.7", "0.01774536", "0", "1"]], "ts": "1742543260303", "checksum": 270064698, "seqId": 49919349177, "prevSeqId": 49919349152}], "record_time": 1742543260.255757}
{"arg": {"channel": "books", "instId": "BTC-USDT"}, "action": "update", "data": [{"asks": [["83850", "0", "0", "0"], ["83858.5", "0", "0", "0"], ["83858.6", "0.06495228", "0", "1"], ["83863.1", "0", "0", "0"], ["83864.8", "0", "0", "0"], ["83864.9", "0.09357515", "0", "1"], ["83873", "0", "0", "0"], ["83874.2", "0.105", "0", "1"], ["83874.4", "0.17239447", "0", "1"], ["83882.8", "0", "0", "0"], ["84014.9", "0.11936586", "0", "1"], ["84015", "0.03", "0", "1"], ["84015.1", "0.00119026", "0", "1"]], "bids": [["83848.5", "0.68718109", "0", "18"], ["83815.2", "0.0108", "0", "3"], ["83814.4", "0.00039871", "0", "1"], ["83813.6", "1.55325232", "0", "1"], ["83802.4", "0.33656", "0", "3"], ["83801.6", "0.05", "0", "1"], ["83800.8", "0.29357058", "0", "1"]], "ts": "1742543260403", "checksum": -610608700, "seqId": 49919349205, "prevSeqId": 49919349177}], "record_time": 1742543260.353606}
{"arg": {"channel": "books", "instId": "BTC-USDT"}, "action": "update", "data": [{"asks": [["83848.6", "0", "0", "0"], ["83851.9", "0", "0", "0"], ["83852", "0", "0", "0"], ["83852.3", "0", "0", "0"], ["83853", "0", "0", "0"], ["83854", "0", "0", "0"], ["83854.8", "0.35597751", "0", "2"], ["83855.9", "0", "0", "0"], ["83856", "0", "0", "0"], ["83856.2", "0", "0", "0"], ["83857.2", "0", "0", "0"], ["83858", "0.0352", "0", "1"], ["83858.6", "0", "0", "0"], ["83859.4", "0", "0", "0"], ["83860", "0.0352", "0", "1"], ["83860.1", "0", "0", "0"], ["83861.7", "0.0602317", "0", "1"], ["83861.9", "0", "0", "0"], ["83862.7", "0.09836489", "0", "2"], ["83863.2", "0", "0", "0"], ["83863.7", "0", "0", "0"], ["83863.9", "0.06801581", "0", "1"], ["83864.9", "0", "0", "0"], ["83865.3", "0", "0", "0"], ["83865.9", "0.33242383", "0", "1"], ["83866", "0.0352", "0", "1"], ["83866.8", "0.00890903", "0", "1"], ["83867", "0", "0", "0"], ["83867.3", "0.01967", "0", "1"], ["83867.9", "0.2185", "0", "2"], ["83868.1", "0", "0", "0"], ["83868.2", "0", "0", "0"], ["83869.7", "0.040015", "0", "2"], ["83870.2", "0.10173606", "0", "1"], ["83870.4", "0.27749439", "0", "1"], ["83870.5", "0", "0", "0"], ["83871.6", "0.1409635", "0", "1"], ["83873.4", "0", "0", "0"], ["83873.6", "0.09901", "0", "2"], ["83874.4", "0", "0", "0"], ["83874.6", "0.31242957", "0", "1"], ["83874.7", "0", "0", "0"], ["83875.3", "0", "0", "0"], ["83875.7", "0.01192938", "0", "1"], ["83876.9", "0", "0", "0"], ["83877.7", "0", "0", "0"], ["83878", "0.01100705", "0", "1"], ["83879.6", "0.17281931", "0", "1"], ["83880", "0", "0", "0"], ["83882.4", "0", "0", "0"], ["83883.2", "0", "0", "0"], ["83883.7", "0", "0", "0"], ["83884", "0.0008", "0", "2"], ["83884.1", "0.2386192", "0", "1"], ["83884.6", "0", "0", "0"], ["83884.8", "0.0004", "0", "1"], ["83888", "0", "0", "0"], ["83888.8", "0.00007589", "0", "1"], ["83889.6", "0.07999999", "0", "2"], ["83890.4", "0.04422587", "0", "2"], ["83893.3", "0.04652281", "0", "2"], ["83895.6", "0.00422588", "0", "1"], ["83895.9", "0.05517286", "0", "2"], ["83904.7", "0", "0", "0"], ["83908.3", "0", "0", "0"], ["83908.9", "0", "0", "0"], ["83910.9", "0", "0", "0"], ["83923.3", "0.58406484", "0", "1"], ["83991", "0.01191781", "0", "1"], ["83993.3", "0.01191779", "0", "1"], ["84005.2", "0.000012", "0", "1"], ["84015.2", "0.00011882", "0", "1"], ["84015.8", "0.17915015", "0", "1"], ["84016.4", "0.35714307", "0", "1"], ["84016.6", "0.00080013", "0", "6"], ["84017.4", "0.00001429", "0", "1"], ["84017.8", "0.00001222", "0", "1"], ["84018", "0.00032751", "0", "1"], ["84019.7", "0.2025", "0", "1"], ["84019.9", "0.00421287", "0", "1"], ["84021.4", "0.11925761", "0", "2"], ["84021.7", "0.00001852", "0", "1"], ["84022.6", "0.00002206", "0", "1"], ["84023.2", "0.01316", "0", "1"], ["84023.3", "0.00011161", "0", "1"], ["84023.4", "0.01191759", "0", "1"], ["84023.8", "0.00001575", "0", "1"], ["84024.9", "0.35714307", "0", "1"], ["84025", "0.00001717", "0", "1"], ["84025.3", "0.01191758", "0", "1"], ["84025.9", "0.000012", "0", "1"], ["84026.4", "0.03", "0", "1"], ["84026.6", "0.0001749", "0", "1"], ["84027.3", "0.00001525", "0", "1"], ["84027.6", "0.32367639", "0", "1"]], "bids": [["83854.7", "0.78329847", "0", "14"], ["83854.6", "0.08991011", "0", "1"], ["83854", "0.0352", "0", "1"], ["83852.4", "0.09034894", "0", "1"], ["83852", "0.0352", "0", "1"], ["83848.6", "0.76220307", "0", "1"], ["83848.5", "0.19974464", "0", "6"], ["83848.4", "0", "0", "0"], ["83846.2", "0.03868101", "0", "1"], ["83845.5", "0.00001501", "0", "1"], ["83844.4", "0.18369646", "0", "1"], ["83844.3", "0.35819548", "0", "1"], ["83843.7", "0.08991011", "0", "1"], ["83843.4", "0", "0", "0"], ["83843.3", "0", "0", "0"], ["83842.8", "0.000012", "0", "1"], ["83837.5", "0", "0", "0"], ["83836.6", "0.17915015", "0", "1"], ["83832", "0.10697574", "0", "1"], ["83830.9", "0.08991011", "0", "1"], ["83830.2", "0", "0", "0"], ["83827.9", "0.23863221", "0", "2"], ["83825.3", "0.00715774", "0", "1"], ["83823.9", "0", "0", "0"], ["83820.1", "0.0001293", "0", "2"], ["83819.1", "0", "0", "0"], ["83815.2", "0.01079871", "0", "3"], ["83811.8", "0", "0", "0"], ["83810.6", "0.05764626", "0", "1"], ["83809.2", "0.17915015", "0", "1"], ["83809.1", "0", "0", "0"], ["83806.4", "0.08", "0", "2"], ["83805.6", "0.066", "0", "3"], ["83804.8", "0.013", "0", "1"], ["83804.7", "0.01191769", "0", "1"], ["83804", "0.1", "0", "2"], ["83803.9", "0.01191772", "0", "1"], ["83803.2", "0.05001201", "0", "2"], ["83802.4", "0.23656", "0", "1"], ["83801.6", "0", "0", "0"], ["83787.1", "0", "0", "0"], ["83781.8", "0.14885222", "0", "3"], ["83743.6", "0.55421931", "0", "1"], ["83742.9", "0.00105868", "0", "1"], ["83742.5", "0.01193279", "0", "2"], ["83737.3", "0.01191781", "0", "1"], ["83703.2", "0", "0", "0"], ["83703.1", "0", "0", "0"], ["83702.9", "0", "0", "0"], ["83702.8", "0", "0", "0"], ["83702.6", "0", "0", "0"], ["83702.2", "0", "0", "0"], ["83702.1", "0", "0", "0"], ["83702", "0", "0", "0"], ["83701.9", "0", "0", "0"]], "ts": "1742543260503", "checksum": -1868717644, "seqId": 49919349583, "prevSeqId": 49919349205}], "record_time": 1742543260.522553}
{"arg": {"channel": "books", "instId": "BTC-USDT"}, "action": "update", "data": [{"asks": [["83854.8", "0.0648", "0", "3"], ["83856", "0.0352", "0", "1"], ["83862.6", "0.03722338", "0", "2"], ["83863.9", "0", "0", "0"], ["83866", "0.0994883", "0", "2"], ["83867.3", "0.155526", "0", "2"], ["83870.2", "0", "0", "0"], ["83870.4", "0.39239485", "0", "2"], ["83870.8", "0.35586", "0", "1"], ["83872.3", "0.09766378", "0", "1"], ["83872.9", "0.28088", "0", "2"], ["83879.6", "0", "0", "0"], ["83880.6", "1.58596256", "0", "1"], ["83881.7", "0.16950997", "0", "1"], ["83884", "0", "0", "0"], ["83884.8", "0.0008", "0", "2"], ["83885.6", "0.0004", "0", "1"], ["83886.3", "0.0013425", "0", "1"], ["83889.6", "0", "0", "0"], ["83890.4", "0.08422587", "0", "3"], ["83891.2", "0.20460134", "0", "4"], ["83893", "0", "0", "0"], ["83900.7", "0.35776", "0", "1"], ["83910.9", "0.00008624", "0", "1"], ["83917.8", "0.03", "0", "1"], ["83920", "0.01275681", "0", "1"], ["84026.4", "0", "0", "0"], ["84026.6", "0", "0", "0"], ["84027.3", "0", "0", "0"], ["84027.6", "0", "0", "0"]], "bids": [["83854.7", "0.73008997", "0", "13"], ["83854.6", "0", "0", "0"], ["83854.1", "0.02112", "0", "1"], ["83852.4", "0", "0", "0"], ["83840.9", "0.02939567", "0", "1"], ["83827.9", "0.23863238", "0", "2"], ["83818.4", "0.28709027", "0", "1"], ["83817.4", "0", "0", "0"], ["83807.2", "0.08", "0", "2"], ["83806.4", "0.04", "0", "1"], ["83805.6", "0.026", "0", "2"], ["83805.1", "0.35776", "0", "1"], ["83804.8", "0.113", "0", "3"], ["83804", "0.05", "0", "1"], ["83803.2", "0.00001201", "0", "1"], ["83800.5", "0.1", "0", "1"], ["83798.5", "0.01837393", "0", "1"], ["83798.4", "0.0166822", "0", "2"], ["83796.9", "0", "0", "0"], ["83796.8", "0", "0", "0"], ["83748.5", "0.00105865", "0", "1"], ["83742.9", "0", "0", "0"], ["83741.1", "0.00116402", "0", "1"], ["83734.7", "0", "0", "0"], ["83727.8", "0.18373938", "0", "1"], ["83726.9", "0", "0", "0"], ["83725.6", "0", "0", "0"], ["83710.2", "0.0017854", "0", "1"], ["83705.1", "0", "0", "0"]], "ts": "1742543260603", "checksum": -854688286, "seqId": 49919349707, "prevSeqId": 49919349583}], "record_time": 1742543260.554624}
{"arg": {"channel": "books", "instId": "BTC-USDT"}, "action": "update", "data": [{"asks": [["83854.8", "0.06430692", "0", "3"], ["83867.8", "0", "0", "0"], ["83872.9", "0.102", "0", "1"], ["83882.2", "0.23862594", "0", "1"], ["83884.1", "0", "0", "0"], ["83899.2", "0.11", "0", "2"], ["83910.9", "0", "0", "0"], ["83913.3", "0.00008624", "0", "1"], ["83916.6", "0.25145991", "0", "4"], ["83937.6", "0.25043", "0", "1"]], "bids": [["83854.7", "0.72996078", "0", "13"], ["83848.5", "0.17470564", "0", "4"], ["83803", "0.1", "0", "1"], ["83800.5", "0", "0", "0"], ["83798.4", "0.00044636", "0", "1"], ["83753.7", "0", "0", "0"], ["83751.5", "0.02151813", "0", "2"], ["83746.6", "0", "0", "0"], ["83703.2", "0.00001159", "0", "1"], ["83703.1", "0.00001028", "0", "1"]], "ts": "1742543260703", "checksum": 1863252725, "seqId": 49919349736, "prevSeqId": 49919349707}], "record_time": 1742543260.716747}
{"arg": {"channel": "books", "instId": "BTC-USDT"}, "action": "update", "data": [{"asks": [["83854.8", "0.03970692", "0", "2"], ["83866", "0.0352", "0", "1"], ["83872.3", "0", "0", "0"], ["83878.2", "0.75189618", "0", "2"], ["83881.7", "0", "0", "0"], ["83888", "0.12522", "0", "1"], ["83908.3", "0.11085215", "0", "1"], ["83908.9", "0.12522", "0", "1"], ["83909", "0.01195655", "0", "2"], ["83913.3", "0", "0", "0"], ["83916.2", "0.00008624", "0", "1"], ["83959.8", "0.26164964", "0", "2"], ["83993", "0.01191768", "0", "1"], ["84025.3", "0", "0", "0"], ["84025.9", "0", "0", "0"]], "bids": [["83854.7", "0.52689137", "0", "12"], ["83832", "0.18477568", "0", "2"], ["83806.1", "0.19523906", "0", "2"], ["83803.1", "0.01191768", "0", "1"], ["83753.8", "0.00013014", "0", "2"], ["83751.5", "0.0214", "0", "1"], ["83719.2", "0.01191768", "0", "1"], ["83703.2", "0", "0", "0"], ["83703.1", "0", "0", "0"]], "ts": "1742543260803", "checksum": -658478930, "seqId": 49919349759, "prevSeqId": 49919349736}], "record_time": 1742543260.753837}
{"arg": {"channel": "books", "instId": "BTC-USDT"}, "action": "update", "data": [{"asks": [["83866.3", "0.08469443", "0", "2"], ["83867.8", "0.17915015", "0", "1"], ["83872.6", "0.10405331", "0", "1"], ["83872.9", "0.28088", "0", "2"], ["83882", "0.16695527", "0", "2"], ["83882.2", "0", "0", "0"], ["83884.1", "0.23862619", "0", "1"], ["83916.2", "0", "0", "0"], ["84025", "0", "0", "0"]], "bids": [["83854.7", "0.57601137", "0", "13"], ["83813.8", "0.01774536", "0", "1"], ["83703.3", "0", "0", "0"]], "ts": "1742543260903", "checksum": -981439166, "seqId": 49919349781, "prevSeqId": 49919349759}], "record_time": 1742543260.853795}
{"arg": {"channel": "books", "instId": "BTC-USDT"}, "action": "update", "data": [{"asks": [["83916.2", "0.00008624", "0", "1"], ["84024.9", "0", "0", "0"]], "bids": [["83854.7", "0.28054524", "0", "11"], ["83848.5", "0.00402315", "0", "3"], ["83847.7", "1.74831902", "0", "3"]], "ts": "1742543261003", "checksum": -529442390, "seqId": 49919349791, "prevSeqId": 49919349781}], "record_time": 1742543260.952687}
{"arg": {"channel": "books", "instId": "BTC-USDT"}, "action": "update", "data": [{"asks": [["83862.5", "0.010012", "0", "2"], ["83862.6", "0.02722338", "0", "1"], ["83881.9", "0.23862727", "0", "1"], ["83884.1", "0", "0", "0"], ["83934.6", "0", "0", "0"], ["84024.9", "0.35714307", "0", "1"]], "bids": [["83854.7", "0.30434524", "0", "12"], ["83817.6", "0.0008", "0", "2"], ["83816.8", "0.0003987", "0", "1"], ["83815.2", "0.01", "0", "1"], ["83814.4", "0", "0", "0"], ["83703.6", "0", "0", "0"]], "ts": "1742543261103", "checksum": -1191613131, "seqId": 49919349804, "prevSeqId": 49919349791}], "record_time": 1742543261.053881}
{"arg": {"channel": "books", "instId": "BTC-USDT"}, "action": "update", "data": [{"asks": [["83854.8", "0.03726079", "0", "2"], ["83861.6", "0.26", "0", "1"], ["83866.3", "0.08215388", "0", "2"], ["83872.6", "0.10248732", "0", "1"], ["83881.9", "0", "0", "0"], ["83882", "0.002", "0", "1"], ["83882.1", "0.1670421", "0", "1"], ["83884.1", "0.23862479", "0", "1"], ["83895.6", "0.25465588", "0", "2"], ["84023.8", "0", "0", "0"], ["84024.9", "0", "0", "0"]], "bids": [["83848.7", "0.26", "0", "1"], ["83848.5", "0.00401315", "0", "2"], ["83845.7", "0.34346828", "0", "5"], ["83812", "1", "0", "1"], ["83704", "0", "0", "0"], ["83703.7", "0", "0", "0"]], "ts": "1742543261203", "checksum": -234500165, "seqId": 49919349827, "prevSeqId": 49919349804}], "record_time": 1742543261.245774}
{"arg": {"channel": "books", "instId": "BTC-USDT"}, "action": "update", "data": [{"asks": [["83854.8", "0.0402", "0", "2"], ["83861.5", "0.14474341", "0", "2"], ["83861.7", "0", "0", "0"], ["83866.1", "0.07016046", "0", "1"], ["83866.3", "0.01967", "0", "1"], ["83872.4", "0.10556842", "0", "2"], ["83872.6", "0", "0", "0"], ["83881.9", "0.16642544", "0", "1"], ["83882.1", "0", "0", "0"], ["83900.7", "0", "0", "0"], ["83937.6", "0", "0", "0"], ["83941.1", "0.01431379", "0", "2"], ["84023.8", "0.00001575", "0", "1"], ["84024.9", "0.35714307", "0", "1"], ["84025", "0.00001717", "0", "1"]], "bids": [["83845.7", "0.3424514", "0", "4"], ["83806.1", "0.04772622", "0", "1"], ["83805.1", "0", "0", "0"], ["83704", "0.00085217", "0", "2"]], "ts": "1742543261303", "checksum": 1525966744, "seqId": 49919349849, "prevSeqId": 49919349827}], "record_time": 1742543261.252943}
{"arg": {"channel": "books", "instId": "BTC-USDT"}, "action": "update", "data": [{"asks": [["83854.8", "0", "0", "0"], ["83856", "0.17294637", "0", "4"], ["83861.5", "0.0632317", "0", "1"], ["83861.6", "0", "0", "0"], ["83865.9", "0.39533634", "0", "2"], ["83866.1", "0", "0", "0"], ["83868.6", "0.02147733", "0", "1"], ["83869.7", "0.000015", "0", "1"], ["83870.6", "0.04", "0", "1"], ["83870.7", "0.30641367", "0", "3"], ["83872.2", "0.1057793", "0", "1"], ["83872.4", "0.000012", "0", "1"], ["83875.5", "0.35776", "0", "1"], ["83879", "0", "0", "0"], ["83880.5", "0.1864357", "0", "4"], ["83881.7", "0.1571745", "0", "1"], ["83881.9", "0", "0", "0"], ["83883.8", "0.05997052", "0", "1"], ["83886.3", "0", "0", "0"], ["83886.6", "0.40923", "0", "3"], ["83890.3", "0.16883415", "0", "1"], ["83899.2", "0.01", "0", "1"], ["83899.8", "0.2409635", "0", "2"], ["83940", "0.01191792", "0", "1"], ["83942.9", "0.0419179", "0", "2"], ["83991", "0", "0", "0"], ["83993.3", "0", "0", "0"]], "bids": [["83855.9", "0.44290379", "0", "12"], ["83854.8", "0.00391926", "0", "1"], ["83854.7", "0", "0", "0"], ["83854.1", "0", "0", "0"], ["83848.4", "0.11932007", "0", "1"], ["83825.3", "0", "0", "0"], ["83815.4", "0.06119156", "0", "1"], ["83812", "0", "0", "0"], ["83810.6", "0", "0", "0"], ["83804.7", "0", "0", "0"], ["83803.9", "0", "0", "0"], ["83803", "0", "0", "0"], ["83774", "0.01191769", "0", "1"], ["83772.8", "0.24169743", "0", "2"], ["83772", "0", "0", "0"], ["83768.2", "0.01191772", "0", "1"], ["83750.8", "0.00105865", "0", "1"], ["83748.5", "0", "0", "0"], ["83703.7", "0.00039589", "0", "3"], ["83703.6", "0.00001075", "0", "1"], ["83703.3", "0.00006334", "0", "1"]], "ts": "1742543261403", "checksum": 894469641, "seqId": 49919349980, "prevSeqId": 49919349849}], "record_time": 1742543261.353613}
{"arg": {"channel": "books", "instId": "BTC-USDT"}, "action": "update", "data": [{"asks": [["83862.5", "0.000012", "0", "1"], ["83862.7", "0.03868101", "0", "1"], ["83865.4", "0.06998409", "0", "1"], ["83874.1", "0.10002478", "0", "1"], ["83880.8", "0.16613078", "0", "1"], ["83899.8", "0.1409635", "0", "1"], ["84023.8", "0", "0", "0"], ["84024.9", "0", "0", "0"], ["84025", "0", "0", "0"]], "bids": [["83855.9", "0.44713379", "0", "13"], ["83813.8", "0", "0", "0"], ["83777.2", "0.30282583", "0", "1"], ["83776.8", "0.868558", "0", "1"], ["83711.8", "0.00181457", "0", "2"], ["83710.2", "0", "0", "0"], ["83703.2", "0.00001159", "0", "1"]], "ts": "1742543261503", "checksum": 1471584635, "seqId": 49919350004, "prevSeqId": 49919349980}], "record_time": 1742543261.457567}
{"arg": {"channel": "books", "instId": "BTC-USDT"}, "action": "update", "data": [{"asks": [["83856", "0.13274637", "0", "2"], ["83861.5", "0", "0", "0"], ["83865.4", "0", "0", "0"], ["83865.9", "0.3981983", "0", "2"], ["83866.4", "0.06862126", "0", "1"], ["83867.8", "0.23883403", "0", "2"], ["83870.7", "0.237", "0", "2"], ["83871.3", "0.06571196", "0", "1"], ["83872.2", "0", "0", "0"], ["83872.7", "0.10195906", "0", "1"], ["83874.1", "0", "0", "0"], ["83874.6", "0.41372774", "0", "2"], ["83878.2", "0.20210647", "0", "1"], ["83880.5", "0.08635459", "0", "3"], ["83880.6", "0", "0", "0"], ["83880.8", "0", "0", "0"], ["83881.1", "0.09182102", "0", "1"], ["83881.3", "0.17315057", "0", "2"], ["83881.7", "0", "0", "0"], ["83882.2", "0.15652275", "0", "1"], ["83883.7", "0.23862184", "0", "1"], ["83884.1", "0", "0", "0"], ["83884.8", "0.16674851", "0", "1"], ["83885.6", "0.0008", "0", "2"], ["83886.4", "0.0004", "0", "1"], ["83886.6", "0.405", "0", "2"], ["83890.3", "0", "0", "0"], ["83890.4", "0.00422588", "0", "1"], ["83890.9", "0.17392133", "0", "1"], ["83891.2", "0.24460134", "0", "5"], ["83892", "0.03999999", "0", "1"], ["83895.9", "0.02823758", "0", "1"], ["83900.4", "0.1", "0", "1"], ["83904.6", "0", "0", "0"], ["83905.1", "0", "0", "0"], ["83916.2", "0", "0", "0"], ["84023.8", "0.00001575", "0", "1"], ["84024.9", "0.35714307", "0", "1"]], "bids": [["83855.9", "0.49592449", "0", "15"], ["83850.8", "0.11931666", "0", "1"], ["83848.4", "0", "0", "0"], ["83817.6", "0", "0", "0"], ["83816.8", "0.0007987", "0", "2"], ["83816", "0.0003987", "0", "1"], ["83804.8", "0.013", "0", "1"], ["83804.2", "0.1", "0", "1"], ["83804", "0.1", "0", "2"], ["83803.2", "0.05001201", "0", "2"], ["83793", "0.2", "0", "1"], ["83767.3", "0", "0", "0"], ["83703.2", "0", "0", "0"]], "ts": "1742543261603", "checksum": -1229266448, "seqId": 49919350071, "prevSeqId": 49919350004}], "record_time": 1742543261.569036}
{"arg": {"channel": "books", "instId": "BTC-USDT"}, "action": "update", "data": [{"asks": [["83856", "0.01343707", "0", "1"], ["83858", "0", "0", "0"], ["83860", "0", "0", "0"], ["83861.3", "0", "0", "0"], ["83862.7", "0", "0", "0"], ["83863.6", "0", "0", "0"], ["83865.9", "0.21927941", "0", "1"], ["83866.4", "0", "0", "0"], ["83866.6", "0.06568658", "0", "2"], ["83867.3", "0.08712431", "0", "2"], ["83867.7", "0", "0", "0"], ["83867.8", "0.05968388", "0", "1"], ["83867.9", "0.2025", "0", "1"], ["83870.6", "0", "0", "0"], ["83871.3", "0", "0", "0"], ["83871.5", "0", "0", "0"], ["83872.2", "0.06567959", "0", "1"], ["83872.7", "0", "0", "0"], ["83872.9", "0.17888", "0", "1"], ["83873.5", "0.04", "0", "1"], ["83873.6", "0.15861646", "0", "2"], ["83874.6", "0.31242957", "0", "1"], ["83875.4", "0.15565264", "0", "2"], ["83880.4", "0.04", "0", "1"], ["83881.1", "0", "0", "0"], ["83881.3", "0.00422712", "0", "1"], ["83882", "0.2630051", "0", "3"], ["83882.2", "0", "0", "0"], ["83883.1", "0.16384378", "0", "1"], ["83883.7", "0", "0", "0"], ["83884.3", "0", "0", "0"], ["83884.8", "0", "0", "0"], ["83885.6", "0", "0", "0"], ["83886.4", "0.0008", "0", "2"], ["83887.2", "0.00041201", "0", "2"], ["83889.4", "0", "0", "0"], ["83890.2", "0", "0", "0"], ["83890.9", "0", "0", "0"], ["83891.1", "0", "0", "0"], ["83891.2", "0.16460135", "0", "3"], ["83891.8", "0.17238566", "0", "1"], ["83892", "0", "0", "0"], ["83892.7", "0.23859972", "0", "1"], ["83892.8", "0.07999999", "0", "2"], ["83893.6", "0.03999999", "0", "1"], ["83895.4", "0.0005", "0", "1"], ["83895.9", "0", "0", "0"], ["83900.1", "0.02310736", "0", "1"], ["83903.9", "0.02823758", "0", "1"], ["83905.4", "0.09156615", "0", "2"], ["83906.2", "0.20608543", "0", "2"], ["83917.7", "0.00008624", "0", "1"], ["83917.9", "0", "0", "0"], ["83937.4", "0.01316", "0", "1"], ["83939.5", "0", "0", "0"], ["83940", "0", "0", "0"], ["83942.9", "0.03", "0", "1"], ["83944.1", "0", "0", "0"], ["83946.7", "0.0177997", "0", "1"], ["83975.6", "0.07102314", "0", "1"], ["84021.4", "0.10734", "0", "1"], ["84023.4", "0", "0", "0"], ["84025", "0.00001717", "0", "1"], ["84025.9", "0.000012", "0", "1"], ["84026.4", "0.03", "0", "1"], ["84026.6", "0.0001749", "0", "1"], ["84027.3", "0.00001525", "0", "1"], ["84027.6", "0.32367639", "0", "1"], ["84027.7", "0.00007589", "0", "1"], ["84027.8", "0.0143", "0", "1"], ["84027.9", "0.0143", "0", "1"], ["84028", "0.0429", "0", "3"], ["84028.1", "0.2025", "0", "1"], ["84028.4", "0.00012012", "0", "1"], ["84028.5", "0.00002158", "0", "1"], ["84028.7", "0.00001047", "0", "1"], ["84029", "0.03", "0", "1"]], "bids": [["83855.9", "0.49415211", "0", "17"], ["83854.1", "0.03753303", "0", "1"], ["83853.2", "0.08991011", "0", "1"], ["83852.1", "0.09430567", "0", "2"], ["83851.3", "0.03868101", "0", "1"], ["83850.8", "0.00775063", "0", "1"], ["83848.8", "0.17915015", "0", "1"], ["83847.8", "0.05733051", "0", "1"], ["83847.6", "0.00211331", "0", "1"], ["83846.2", "0", "0", "0"], ["83841.5", "0.01193424", "0", "1"], ["83840.3", "0.1629229", "0", "2"], ["83839.1", "0", "0", "0"], ["83838.3", "0.23859972", "0", "1"], ["83837.6", "0", "0", "0"], ["83836.8", "0.11933395", "0", "1"], ["83832", "0.10697574", "0", "1"], ["83831.1", "0.00357873", "0", "1"], ["83829.8", "0", "0", "0"], ["83827.9", "0.00001201", "0", "1"], ["83827.8", "0.17915015", "0", "1"], ["83826.4", "0.11935136", "0", "1"], ["83822.9", "0.04", "0", "1"], ["83815.9", "0.01100705", "0", "1"], ["83811.2", "0.12468733", "0", "3"], ["83810.4", "0.01191664", "0", "1"], ["83810.3", "0.01191666", "0", "1"], ["83810.2", "0.01191667", "0", "1"], ["83809", "0.01191685", "0", "1"], ["83808.8", "0.01191687", "0", "1"], ["83808.4", "0", "0", "0"], ["83807.2", "0", "0", "0"], ["83806.4", "0.08", "0", "2"], ["83805.6", "0.066", "0", "3"], ["83793.3", "0.06001201", "0", "3"], ["83793", "0", "0", "0"], ["83792.1", "0", "0", "0"], ["83790.8", "0.35819548", "0", "1"], ["83781.8", "0.13693487", "0", "2"], ["83774", "0", "0", "0"], ["83772", "0.093253", "0", "1"], ["83768.2", "0", "0", "0"], ["83756.4", "0.00610046", "0", "1"], ["83750.9", "0.00610046", "0", "1"], ["83746.6", "0.00609998", "0", "1"], ["83742.5", "0.000015", "0", "1"], ["83737.3", "0", "0", "0"], ["83705.9", "0", "0", "0"], ["83705.8", "0", "0", "0"], ["83705.4", "0", "0", "0"], ["83705", "0", "0", "0"], ["83704.9", "0", "0", "0"], ["83704.6", "0", "0", "0"], ["83704.4", "0", "0", "0"], ["83704", "0", "0", "0"], ["83703.7", "0", "0", "0"], ["83703.6", "0", "0", "0"], ["83703.3", "0", "0", "0"]], "ts": "1742543261703", "checksum": 2027127056, "seqId": 49919350320, "prevSeqId": 49919350071}], "record_time": 1742543261.653778}
{"arg": {"channel": "books", "instId": "BTC-USDT"}, "action": "update", "data": [{"asks": [["83856", "0", "0", "0"], ["83857.5", "0", "0", "0"], ["83862", "0", "0", "0"], ["83862.5", "0", "0", "0"], ["83862.6", "0", "0", "0"], ["83864", "0.0031", "0", "1"], ["83865.9", "0", "0", "0"], ["83866.3", "0", "0", "0"], ["83866.6", "0.00060645", "0", "1"], ["83866.8", "0", "0", "0"], ["83867.3", "0", "0", "0"], ["83867.5", "0", "0", "0"], ["83867.7", "0.011", "0", "1"], ["83867.8", "0", "0", "0"], ["83867.9", "0", "0", "0"], ["83868.6", "0", "0", "0"], ["83870.2", "0.00477207", "0", "1"], ["83870.4", "0", "0", "0"], ["83870.7", "0", "0", "0"], ["83870.8", "0", "0", "0"], ["83871.5", "0.01967", "0", "1"], ["83871.6", "0", "0", "0"], ["83872.2", "0", "0", "0"], ["83872.8", "0.09049524", "0", "1"], ["83873.5", "0", "0", "0"], ["83873.6", "0", "0", "0"], ["83874.2", "0.06572951", "0", "1"], ["83874.3", "0.03868101", "0", "1"], ["83874.4", "0.06250372", "0", "1"], ["83874.5", "0.06655455", "0", "1"], ["83875.4", "0.05966709", "0", "1"], ["83878", "0.04", "0", "1"], ["83878.2", "0.63262863", "0", "2"], ["83879.1", "0.0672983", "0", "1"], ["83880.1", "0.21", "0", "2"], ["83880.8", "0.09297153", "0", "1"], ["83882", "0.002", "0", "1"], ["83882.2", "1.61427275", "0", "1"], ["83883", "0.10343881", "0", "1"], ["83883.1", "0", "0", "0"], ["83883.8", "0", "0", "0"], ["83884.1", "0.1409635", "0", "1"], ["83884.2", "0.44815655", "0", "2"], ["83885.1", "0.24728705", "0", "2"], ["83885.6", "0.36355", "0", "1"], ["83886.4", "0", "0", "0"], ["83887.2", "0.00001201", "0", "1"], ["83889", "0.10342891", "0", "1"], ["83889.6", "0.16525508", "0", "1"], ["83890.2", "0.166996", "0", "1"], ["83891.2", "0.30962416", "0", "2"], ["83891.8", "0", "0", "0"], ["83892.7", "0", "0", "0"], ["83892.8", "0", "0", "0"], ["83893.6", "0", "0", "0"], ["83894.8", "0.23859855", "0", "1"], ["83897.6", "0.07999999", "0", "2"], ["83898.4", "0.03999999", "0", "1"], ["83898.8", "0.16512216", "0", "1"], ["83900.4", "0", "0", "0"], ["83901.9", "0.1", "0", "1"], ["83906.2", "0.17915015", "0", "1"], ["83911.5", "2.98002666", "0", "1"], ["83912.3", "0.02693528", "0", "1"], ["83920", "0", "0", "0"], ["83922.7", "0.43665627", "0", "1"], ["83923.9", "0.01275695", "0", "1"], ["83962.5", "0.49815583", "0", "1"], ["83975.4", "0.01191664", "0", "1"], ["83978", "0.01191663", "0", "1"], ["84009.2", "0.01191644", "0", "1"], ["84011.5", "0.01191643", "0", "1"], ["84013.7", "0.04051641", "0", "3"]], "bids": [["83863.9", "1.09906282", "0", "12"], ["83862", "0.22659222", "0", "2"], ["83860", "0.03521", "0", "2"], ["83857.5", "0.08173642", "0", "1"], ["83857.4", "0.27245472", "0", "2"], ["83856.1", "0.02229578", "0", "1"], ["83856", "0.0352", "0", "1"], ["83855.9", "0.05109301", "0", "3"], ["83854.1", "0", "0", "0"], ["83853.9", "0.000015", "0", "1"], ["83853.2", "0", "0", "0"], ["83852.7", "0.000012", "0", "1"], ["83852.1", "0.046355", "0", "1"], ["83851.3", "0", "0", "0"], ["83847.9", "0.11933395", "0", "1"], ["83844.5", "0.06", "0", "2"], ["83844.4", "0.26899567", "0", "2"], ["83843.2", "0.0003", "0", "1"], ["83841.3", "0.06", "0", "2"], ["83841", "0.11933056", "0", "1"], ["83838.3", "0.23859855", "0", "1"], ["83838", "0.00477111", "0", "1"], ["83835.8", "0.2638497", "0", "2"], ["83835", "0.18258", "0", "4"], ["83834.6", "0", "0", "0"], ["83832.7", "0.25043", "0", "1"], ["83831.1", "0", "0", "0"], ["83824.5", "0.00903428", "0", "1"], ["83823.8", "0.00422971", "0", "1"], ["83818.4", "0", "0", "0"], ["83815.5", "0.00357873", "0", "1"], ["83815.4", "0", "0", "0"], ["83813.9", "0.02041347", "0", "1"], ["83811.8", "0.03372", "0", "1"], ["83811.2", "0.1127708", "0", "2"], ["83810.4", "0", "0", "0"], ["83810.3", "0", "0", "0"], ["83810.2", "0", "0", "0"], ["83809", "0", "0", "0"], ["83808.8", "0", "0", "0"], ["83806.1", "0.07184723", "0", "2"], ["83804.2", "0", "0", "0"], ["83803.2", "0.06838364", "0", "3"], ["83798.5", "0", "0", "0"], ["83797.8", "0.05243", "0", "1"], ["83785.1", "0.07162142", "0", "2"], ["83776.8", "0", "0", "0"], ["83775.7", "0.04", "0", "1"], ["83775.2", "0", "0", "0"], ["83772", "0", "0", "0"], ["83766.8", "0", "0", "0"], ["83762.4", "0.01191641", "0", "1"], ["83759.7", "0.01191643", "0", "1"], ["83757", "0.01191644", "0", "1"], ["83753.9", "0.00105839", "0", "1"], ["83753.1", "0.00611547", "0", "2"], ["83751.9", "0.00580013", "0", "1"], ["83750.8", "0", "0", "0"], ["83748.3", "0.00116376", "0", "1"], ["83741.1", "0", "0", "0"], ["83731.7", "0.18371634", "0", "1"], ["83727.8", "0", "0", "0"], ["83727.2", "0.01245205", "0", "9"], ["83722.7", "0.01191664", "0", "1"], ["83708.6", "0", "0", "0"], ["83708.5", "0", "0", "0"], ["83707.8", "0", "0", "0"], ["83707.5", "0", "0", "0"], ["83707.4", "0", "0", "0"], ["83706.8", "0", "0", "0"], ["83706.6", "0", "0", "0"], ["83706.3", "0", "0", "0"]], "ts": "1742543261803", "checksum": -379289569, "seqId": 49919350885, "prevSeqId": 49919350320}], "record_time": 1742543261.766014}
{"arg": {"channel": "books", "instId": "BTC-USDT"}, "action": "update", "data": [{"asks": [["83864", "0", "0", "0"], ["83866", "0.23273214", "0", "6"], ["83867.7", "0", "0", "0"], ["83869.7", "0", "0", "0"], ["83870.2", "0", "0", "0"], ["83871.4", "0.01192911", "0", "1"], ["83871.8", "0.00477207", "0", "1"], ["83872.7", "0.02722338", "0", "1"], ["83874.2", "0", "0", "0"], ["83874.3", "0", "0", "0"], ["83874.5", "0", "0", "0"], ["83874.8", "0.05968388", "0", "1"], ["83875.4", "0.23852709", "0", "2"], ["83876.9", "0.136019", "0", "1"], ["83877.4", "0", "0", "0"], ["83878", "0", "0", "0"], ["83878.1", "0.41021048", "0", "4"], ["83879.1", "0", "0", "0"], ["83879.8", "0.04", "0", "1"], ["83880.8", "0", "0", "0"], ["83883", "0", "0", "0"], ["83883.4", "0.18795133", "0", "1"], ["83884.2", "0.55615655", "0", "3"], ["83884.3", "0.102", "0", "1"], ["83885.1", "0.01100705", "0", "1"], ["83887", "0.41620984", "0", "3"], ["83889", "0", "0", "0"], ["83889.6", "0", "0", "0"], ["83890.2", "0", "0", "0"], ["83891.1", "0.32734244", "0", "1"], ["83891.2", "0.00578385", "0", "1"], ["83892.4", "0.05723722", "0", "1"], ["83893.3", "0.04295281", "0", "1"], ["83893.8", "0", "0", "0"], ["83894.8", "0", "0", "0"], ["83897.6", "0", "0", "0"], ["83898.3", "0.23859074", "0", "1"], ["83898.4", "0", "0", "0"], ["83898.8", "0", "0", "0"], ["83899.7", "0.22594977", "0", "2"], ["83901.2", "0.23628", "0", "1"], ["83901.9", "0", "0", "0"], ["83902.6", "0.12290395", "0", "2"], ["83904.4", "0", "0", "0"], ["83905.2", "0.22186243", "0", "1"], ["83908.3", "0.99100363", "0", "2"], ["83909", "0.00003887", "0", "1"], ["83912.8", "0", "0", "0"], ["83916.5", "0.08755802", "0", "1"], ["83918.3", "0.00100225", "0", "1"], ["83918.7", "0", "0", "0"], ["83918.9", "0.01191664", "0", "1"], ["83920.1", "0.00001501", "0", "1"], ["83922.2", "0.01191663", "0", "1"], ["83922.7", "0.26143682", "0", "1"], ["83923.3", "0", "0", "0"], ["83923.9", "0", "0", "0"], ["83926.7", "0.00100323", "0", "1"], ["83927.3", "0.00022", "0", "1"], ["83929.8", "0.01275626", "0", "1"], ["83932.8", "0.32502997", "0", "2"], ["83934.7", "0.47238", "0", "1"], ["83937.9", "0.01191656", "0", "1"], ["83938.8", "0.00357", "0", "1"], ["83943.9", "0.01191653", "0", "1"], ["83961.2", "0.01191644", "0", "1"], ["83964", "0.01191643", "0", "1"], ["83969", "0.14554408", "0", "2"], ["83975.4", "0", "0", "0"], ["83978", "0", "0", "0"], ["83982.2", "0.17915015", "0", "1"], ["83993", "0", "0", "0"], ["83994.1", "0.00596204", "0", "1"], ["83999", "0.17915015", "0", "1"], ["84009.2", "0", "0", "0"], ["84010.9", "0.01788612", "0", "3"], ["84011.5", "0", "0", "0"], ["84013.7", "0.0286", "0", "2"], ["84017.6", "0.000012", "0", "1"], ["84029.1", "0.0000221", "0", "1"], ["84030.8", "0.00027532", "0", "2"], ["84031.4", "0.00018117", "0", "2"]], "bids": [["83865.9", "0.39486167", "0", "9"], ["83864.1", "0.02469873", "0", "1"], ["83864", "0.0352", "0", "1"], ["83863.9", "0.01192911", "0", "1"], ["83862", "0.0352", "0", "1"], ["83861.1", "0.02590372", "0", "1"], ["83861", "0.03868101", "0", "1"], ["83857.5", "0", "0", "0"], ["83857.4", "0.01245472", "0", "1"], ["83856.1", "0.12697195", "0", "2"], ["83855.9", "0.012412", "0", "2"], ["83854", "0.39339548", "0", "2"], ["83851.7", "0.0003", "0", "1"], ["83848.7", "0", "0", "0"], ["83848.5", "0.001788", "0", "1"], ["83843.2", "0", "0", "0"], ["83842.9", "0.03", "0", "1"], ["83842.8", "0.030012", "0", "2"], ["83842.6", "0.1127708", "0", "2"], ["83841.1", "0.23859074", "0", "1"], ["83840.9", "0", "0", "0"], ["83839", "0.09296", "0", "1"], ["83838.3", "0", "0", "0"], ["83838.2", "0.03", "0", "1"], ["83837.8", "0.12462201", "0", "2"], ["83836.5", "0.00915679", "0", "2"], ["83835", "0.12258", "0", "2"], ["83825.2", "0.0612601", "0", "1"], ["83821.7", "0.07761471", "0", "1"], ["83819", "0.23656", "0", "1"], ["83818.4", "0.20492437", "0", "1"], ["83815.5", "0", "0", "0"], ["83807.1", "0.01837135", "0", "1"], ["83803.2", "0.05001201", "0", "2"], ["83803.1", "0", "0", "0"], ["83802.4", "0", "0", "0"], ["83798.3", "0.0264607", "0", "2"], ["83792.3", "0.33986278", "0", "1"], ["83785.1", "0.05970512", "0", "1"], ["83777.2", "0", "0", "0"], ["83776.2", "0.0360749", "0", "1"], ["83773.3", "0", "0", "0"], ["83762.4", "0", "0", "0"], ["83759.7", "0", "0", "0"], ["83758.2", "0.00105833", "0", "1"], ["83757", "0", "0", "0"], ["83754", "0.00609985", "0", "1"], ["83753.9", "0", "0", "0"], ["83752", "0.0011637", "0", "1"], ["83748.3", "0", "0", "0"], ["83735.7", "0.18371356", "0", "1"], ["83734", "0.01192831", "0", "2"], ["83731.7", "0", "0", "0"], ["83731.5", "0", "0", "0"], ["83727.2", "0.00053542", "0", "8"], ["83722.7", "0", "0", "0"], ["83719.2", "0", "0", "0"], ["83716.2", "0.0017839", "0", "1"], ["83715.8", "0.01191641", "0", "1"], ["83713.6", "0.01191643", "0", "1"], ["83711.8", "0.00002917", "0", "1"], ["83711.5", "0.01191644", "0", "1"], ["83709.5", "0", "0", "0"], ["83709", "0", "0", "0"], ["83708.9", "0", "0", "0"], ["83708.8", "0", "0", "0"], ["83708.7", "0", "0", "0"]], "ts": "1742543261903", "checksum": 1948109544, "seqId": 49919351220, "prevSeqId": 49919350885}], "record_time": 1742543261.856862}
{"arg": {"channel": "books", "instId": "BTC-USDT"}, "action": "update", "data": [{"asks": [["83870.5", "0.0036659", "0", "1"], ["83872.8", "0.03683124", "0", "1"], ["83872.9", "0", "0", "0"], ["83874.3", "0.01967", "0", "1"], ["83874.4", "0", "0", "0"], ["83874.6", "0.44067291", "0", "2"], ["83874.9", "0.06878996", "0", "1"], ["83875.4", "0.30850299", "0", "3"], ["83877.1", "0.03868101", "0", "1"], ["83878", "0.011", "0", "1"], ["83878.1", "0.58936063", "0", "5"], ["83880.3", "0.06126043", "0", "1"], ["83880.6", "0.05901", "0", "1"], ["83880.7", "0.12", "0", "1"], ["83880.8", "0.117", "0", "1"], ["83881.7", "0.10481167", "0", "1"], ["83883.7", "0.09396303", "0", "1"], ["83885.1", "0.10293962", "0", "2"], ["83890.1", "0.1003516", "0", "1"], ["83890.3", "0.15416589", "0", "1"], ["83891.1", "0.32811495", "0", "2"], ["83891.2", "0.16350412", "0", "2"], ["83893.5", "0.000015", "0", "1"], ["83893.9", "0.17254039", "0", "1"], ["83894.8", "0.23859724", "0", "1"], ["83898.3", "0", "0", "0"], ["83899.9", "0.15716855", "0", "3"], ["83903.1", "0.093107", "0", "1"], ["83904", "0.57415672", "0", "1"], ["83908.4", "1.069697", "0", "2"], ["83910.4", "0.1", "0", "1"], ["83914.6", "0", "0", "0"], ["83917.7", "0", "0", "0"], ["83921.6", "0.00008624", "0", "1"], ["83949.2", "0.01192919", "0", "1"], ["84026.4", "0", "0", "0"], ["84026.6", "0", "0", "0"], ["84027.3", "0", "0", "0"], ["84027.6", "0", "0", "0"], ["84027.7", "0", "0", "0"], ["84027.8", "0", "0", "0"], ["84027.9", "0", "0", "0"], ["84028", "0", "0", "0"], ["84028.1", "0", "0", "0"], ["84028.4", "0", "0", "0"], ["84028.5", "0", "0", "0"], ["84028.7", "0", "0", "0"], ["84029", "0", "0", "0"], ["84029.1", "0", "0", "0"], ["84030.8", "0", "0", "0"], ["84031.4", "0", "0", "0"]], "bids": [["83865.9", "0.38469167", "0", "8"], ["83852.1", "0.06974456", "0", "2"], ["83850.6", "0.02939567", "0", "1"], ["83846.9", "0.00353024", "0", "1"], ["83841.1", "0", "0", "0"], ["83840.3", "0.24605614", "0", "1"], ["83839.1", "0.23859724", "0", "1"], ["83838.2", "0", "0", "0"], ["83834.9", "0", "0", "0"], ["83814.2", "0.1", "0", "1"], ["83796.5", "0.00235914", "0", "1"], ["83786.5", "0.868457", "0", "1"], ["83781.6", "0.87464208", "0", "2"], ["83781.5", "0.093242", "0", "1"], ["83777.1", "0", "0", "0"], ["83758.2", "0.00117645", "0", "2"], ["83753.8", "0.00001201", "0", "1"], ["83745.9", "0.139923", "0", "1"], ["83729.4", "0.01192954", "0", "1"], ["83720.5", "0.00178349", "0", "1"], ["83716.2", "0", "0", "0"], ["83709.8", "0", "0", "0"], ["83709.7", "0", "0", "0"], ["83709.4", "0", "0", "0"], ["83709.2", "0", "0", "0"], ["83709.1", "0", "0", "0"]], "ts": "1742543262003", "checksum": -1054603365, "seqId": 49919351304, "prevSeqId": 49919351220}], "record_time": 1742543261.954773}
{"arg": {"channel": "books", "instId": "BTC-USDT"}, "action": "update", "data": [{"asks": [["83866", "0.27885848", "0", "7"], ["83875.1", "0.06180876", "0", "1"], ["83875.4", "0.23852709", "0", "2"], ["83876.3", "0.06375677", "0", "1"], ["83879.7", "0.06814155", "0", "2"], ["83880.3", "0", "0", "0"], ["83881.4", "0.09949929", "0", "2"], ["83881.7", "0", "0", "0"], ["83883.6", "0.09795432", "0", "1"], ["83883.7", "0", "0", "0"], ["83885.1", "0.10343736", "0", "2"], ["83889.5", "0.10115819", "0", "1"], ["83890.1", "0", "0", "0"], ["83890.8", "0.16889213", "0", "1"], ["83891.2", "0.00578385", "0", "1"], ["83893", "0.11933395", "0", "1"], ["83893.8", "0.16001184", "0", "1"], ["83893.9", "0", "0", "0"], ["83899.3", "0.16579807", "0", "1"], ["83899.9", "0.00101534", "0", "2"], ["83903.9", "0.4223744", "0", "2"], ["83905.2", "0", "0", "0"], ["83921.6", "0", "0", "0"], ["83926.6", "0.01275599", "0", "1"], ["83927.1", "0.00008624", "0", "1"], ["83929.8", "0", "0", "0"], ["84025", "0", "0", "0"], ["84025.9", "0", "0", "0"]], "bids": [["83865.9", "0.27899167", "0", "8"], ["83861.1", "0.03986491", "0", "2"], ["83861", "0", "0", "0"], ["83857.4", "0.06978523", "0", "2"], ["83857.1", "0.03868101", "0", "1"], ["83847.8", "0", "0", "0"], ["83835", "0.09258", "0", "1"], ["83807.1", "0", "0", "0"], ["83805.7", "0.01837181", "0", "1"], ["83788.2", "0.39285661", "0", "2"], ["83763.8", "0.00011811", "0", "1"], ["83759.2", "0.00105834", "0", "1"], ["83758.2", "0", "0", "0"], ["83735.7", "0", "0", "0"], ["83734.7", "0.1837181", "0", "1"], ["83722.3", "0.00179375", "0", "2"], ["83720.5", "0", "0", "0"], ["83709.8", "0.0022146", "0", "4"]], "ts": "1742543262103", "checksum": -35516523, "seqId": 49919351380, "prevSeqId": 49919351304}], "record_time": 1742543262.08824}
{"arg": {"channel": "books", "instId": "BTC-USDT"}, "action": "update", "data": [{"asks": [["83876.5", "0", "0", "0"], ["83879.6", "0.0672253", "0", "1"], ["83879.7", "0.005", "0", "1"], ["83886.6", "0.4", "0", "1"], ["83889.5", "0.09608474", "0", "1"], ["83894.8", "0", "0", "0"], ["83899.2", "0.24859151", "0", "2"], ["83899.3", "0.16434301", "0", "1"], ["83923.7", "0.01193004", "0", "1"], ["83949.2", "0", "0", "0"], ["84025", "0.00001717", "0", "1"]], "bids": [["83865.9", "0.27900167", "0", "9"], ["83864.1", "0.01413873", "0", "1"], ["83861.1", "0.10684054", "0", "1"], ["83859.1", "0.00775029", "0", "1"], ["83857.5", "0.26", "0", "1"], ["83841.1", "0.23859211", "0", "1"], ["83839.1", "0", "0", "0"], ["83826.8", "0.09269", "0", "1"], ["83813.9", "0", "0", "0"], ["83757.6", "0.01234131", "0", "2"], ["83729.4", "0", "0", "0"]], "ts": "1742543262203", "checksum": 801403672, "seqId": 49919351428, "prevSeqId": 49919351380}], "record_time": 1742543262.152904}
{"arg": {"channel": "books", "instId": "BTC-USDT"}, "action": "update", "data": [{"asks": [["83896.4", "0.23869894", "0", "2"], ["83899.2", "0.01", "0", "1"]], "bids": [["83865.9", "0.27865827", "0", "9"], ["83857.6", "0.000012", "0", "1"], ["83841.1", "0", "0", "0"], ["83839.1", "0.23859454", "0", "1"], ["83784.4", "0.525242", "0", "2"], ["83784.3", "0", "0", "0"]], "ts": "1742543262303", "checksum": 1142767221, "seqId": 49919351446, "prevSeqId": 49919351428}], "record_time": 1742543262.286891}
{"arg": {"channel": "books", "instId": "BTC-USDT"}, "action": "update", "data": [{"asks": [["83896.4", "0.2387006", "0", "2"]], "bids": [["83839.1", "0.23859546", "0", "1"], ["83832", "0.57178782", "0", "2"], ["83828.1", "1.54536857", "0", "1"], ["83826.8", "0", "0", "0"], ["83822.1", "0.37761471", "0", "1"], ["83822", "1", "0", "1"], ["83821.7", "0", "0", "0"], ["83709.8", "0", "0", "0"]], "ts": "1742543262403", "checksum": 1142767221, "seqId": 49919351463, "prevSeqId": 49919351446}], "record_time": 1742543262.354041}
{"arg": {"channel": "books", "instId": "BTC-USDT"}, "action": "update", "data": [{"asks": [["83866", "0.23273214", "0", "6"], ["83875.1", "0", "0", "0"], ["83876.3", "0", "0", "0"], ["83879.6", "0", "0", "0"], ["83880.2", "0.06903611", "0", "1"], ["83881.4", "0.00005728", "0", "1"], ["83883.6", "0", "0", "0"], ["83889.5", "0", "0", "0"], ["83890", "0.09627939", "0", "1"], ["83890.8", "0", "0", "0"], ["83891.2", "0.17989596", "0", "2"], ["83893.8", "0", "0", "0"], ["83896.4", "0.2387008", "0", "2"], ["83899.3", "0", "0", "0"], ["83899.8", "0.30767112", "0", "2"], ["83916.5", "0.10623254", "0", "2"], ["84025.9", "0.000012", "0", "1"], ["84026.4", "0.03", "0", "1"], ["84026.6", "0.0001749", "0", "1"], ["84027.3", "0.00001525", "0", "1"], ["84027.6", "0.32367639", "0", "1"], ["84027.7", "0.00007589", "0", "1"]], "bids": [["83865.9", "0.30265827", "0", "10"], ["83839.1", "0.23859626", "0", "1"]], "ts": "1742543262503", "checksum": 491426143, "seqId": 49919351494, "prevSeqId": 49919351463}], "record_time": 1742543262.462529}
{"arg": {"channel": "books", "instId": "BTC-USDT"}, "action": "update", "data": [{"asks": [["83875.4", "0.302779", "0", "3"], ["83876.4", "0.06995903", "0", "1"], ["83880.2", "0", "0", "0"], ["83880.3", "0.06239951", "0", "1"], ["83881.7", "0.09740545", "0", "1"], ["83883.7", "0.0931321", "0", "1"], ["83890", "0", "0", "0"], ["83890.1", "0.10036687", "0", "1"], ["83893.9", "0.16119026", "0", "1"], ["83896.4", "0.00010514", "0", "1"], ["83899.6", "0.23859294", "0", "1"], ["83899.8", "0.1409635", "0", "1"], ["83899.9", "0.16287313", "0", "3"], ["84026.4", "0", "0", "0"], ["84026.6", "0", "0", "0"], ["84027.3", "0", "0", "0"], ["84027.6", "0", "0", "0"], ["84027.7", "0", "0", "0"]], "bids": [["83865.9", "0.36045827", "0", "11"], ["83840.4", "0.23859294", "0", "1"], ["83839.1", "0", "0", "0"]], "ts": "1742543262603", "checksum": -1270750711, "seqId": 49919351523, "prevSeqId": 49919351494}], "record_time": 1742543262.613197}
{"arg": {"channel": "books", "instId": "BTC-USDT"}, "action": "update", "data": [{"asks": [["83866", "0.32645848", "0", "8"], ["83869.6", "0.00610908", "0", "2"], ["83894.8", "0.23859702", "0", "1"], ["83899.6", "0", "0", "0"], ["83943.7", "0.00595", "0", "1"]], "bids": [["83865.9", "0.32683193", "0", "10"], ["83864.1", "0.01525465", "0", "2"], ["83858.7", "0.11930544", "0", "1"], ["83855.9", "0.005262", "0", "1"], ["83840.4", "0", "0", "0"], ["83837.9", "0.23859702", "0", "1"], ["83806.1", "0.07423776", "0", "1"], ["83710", "0", "0", "0"]], "ts": "1742543262703", "checksum": -1085594417, "seqId": 49919351552, "prevSeqId": 49919351523}], "record_time": 1742543262.656729}
{"arg": {"channel": "books", "instId": "BTC-USDT"}, "action": "update", "data": [{"asks": [["83867.9", "0.01272545", "0", "1"], ["83869.6", "0.00721815", "0", "3"], ["83870.5", "0", "0", "0"], ["83871.1", "0.01967", "0", "1"], ["83874.3", "0", "0", "0"], ["83874.5", "0.06247379", "0", "1"], ["83874.6", "0.50610708", "0", "3"], ["83874.9", "0", "0", "0"], ["83875.4", "0.23852709", "0", "2"], ["83876", "0.06999684", "0", "1"], ["83876.4", "0", "0", "0"], ["83878.7", "0.06969367", "0", "1"], ["83880.3", "0", "0", "0"], ["83880.8", "0.21228404", "0", "2"], ["83881.7", "0", "0", "0"], ["83883.4", "0.28344101", "0", "2"], ["83883.7", "0", "0", "0"], ["83884.8", "0.09487865", "0", "1"], ["83885.1", "0.01100705", "0", "1"], ["83888.6", "0.09176142", "0", "1"], ["83890", "0.16107965", "0", "1"], ["83890.1", "0", "0", "0"], ["83890.2", "0.15818697", "0", "1"], ["83890.3", "0", "0", "0"], ["83891.2", "0.00578385", "0", "1"], ["83893.5", "0.17479044", "0", "2"], ["83893.9", "0", "0", "0"], ["83898.4", "0.16197273", "0", "1"], ["83899.9", "0.00101534", "0", "2"], ["83953.5", "0.00119113", "0", "1"], ["84025.9", "0", "0", "0"]], "bids": [["83865.9", "0.18479533", "0", "7"], ["83855.9", "0", "0", "0"], ["83846.9", "0", "0", "0"], ["83843.7", "0", "0", "0"], ["83710", "0.00030781", "0", "2"], ["83709.8", "0.0022146", "0", "4"], ["83709.7", "0.01141021", "0", "1"]], "ts": "1742543262803", "checksum": 582519087, "seqId": 49919351613, "prevSeqId": 49919351552}], "record_time": 1742543262.805556}
{"arg": {"channel": "books", "instId": "BTC-USDT"}, "action": "update", "data": [{"asks": [["83866", "0.34434448", "0", "9"], ["83867.9", "0", "0", "0"], ["83869.6", "0.00832723", "0", "4"], ["83876", "0", "0", "0"], ["83876.1", "0.06359698", "0", "1"], ["83878.7", "0.06149586", "0", "1"], ["83887", "0.75955704", "0", "2"], ["83888", "0.32522", "0", "2"], ["83888.5", "0.09776776", "0", "1"], ["83888.6", "0", "0", "0"], ["83890", "1.16107965", "0", "2"], ["83890.2", "0", "0", "0"], ["83890.3", "0.17360779", "0", "1"], ["83893.5", "0.000015", "0", "1"], ["83893.6", "0.15738245", "0", "1"], ["83894.8", "0", "0", "0"], ["83896.4", "0.23870293", "0", "2"], ["83900", "0.34261038", "0", "10"], ["83900.8", "0.03999999", "0", "1"], ["83962.5", "0", "0", "0"], ["84025.9", "0.000012", "0", "1"]], "bids": [["83865.9", "0.18902533", "0", "8"]], "ts": "1742543262903", "checksum": -89244115, "seqId": 49919351641, "prevSeqId": 49919351613}], "record_time": 1742543262.853411}
{"arg": {"channel": "books", "instId": "BTC-USDT"}, "action": "update", "data": [{"asks": [["83871.4", "0.07646789", "0", "2"], ["83872.5", "0.03868101", "0", "1"], ["83872.8", "0", "0", "0"], ["83874.5", "0", "0", "0"], ["83874.6", "0.44067291", "0", "2"], ["83874.9", "0.07010788", "0", "1"], ["83875", "0.06620642", "0", "1"], ["83876.1", "0", "0", "0"], ["83876.3", "0.06460943", "0", "1"], ["83877.1", "0", "0", "0"], ["83878.7", "0", "0", "0"], ["83879.3", "0.06128681", "0", "1"], ["83880.8", "0.117", "0", "1"], ["83881.3", "0.09960224", "0", "2"], ["83883.4", "0.18795133", "0", "1"], ["83883.6", "0.09887931", "0", "1"], ["83884.8", "0", "0", "0"], ["83885.1", "0.10324699", "0", "2"], ["83887", "0.32040075", "0", "2"], ["83888", "0.12522", "0", "1"], ["83888.5", "0", "0", "0"], ["83889.1", "0.09638991", "0", "1"], ["83890", "0", "0", "0"], ["83890.3", "0.17279595", "0", "1"], ["83890.7", "0.15635433", "0", "1"], ["83893.6", "0", "0", "0"], ["83893.8", "0.15993849", "0", "1"], ["83898.4", "0", "0", "0"], ["83899", "0.17509736", "0", "1"], ["83917.2", "0.01191651", "0", "1"], ["83962.5", "0.28198498", "0", "2"], ["84001.2", "0.01203193", "0", "3"], ["84025", "0", "0", "0"], ["84025.9", "0", "0", "0"]], "bids": [["83865.9", "0.28047801", "0", "10"], ["83811.3", "0.01191651", "0", "1"], ["83727.4", "0.01191651", "0", "1"], ["83709.8", "0", "0", "0"], ["83709.7", "0", "0", "0"]], "ts": "1742543263003", "checksum": -925983466, "seqId": 49919351687, "prevSeqId": 49919351641}], "record_time": 1742543262.953924}
{"arg": {"channel": "books", "instId": "BTC-USDT"}, "action": "update", "data": [{"asks": [["83867.7", "0.005", "0", "1"], ["83869.6", "0.00332723", "0", "3"], ["83877.7", "0.005", "0", "1"], ["83879.7", "0", "0", "0"], ["84024.9", "0", "0", "0"]], "bids": [["83847.6", "0.00711331", "0", "2"], ["83842.2", "0", "0", "0"], ["83837.5", "0.005", "0", "1"]], "ts": "1742543263103", "checksum": 1181841240, "seqId": 49919351696, "prevSeqId": 49919351687}], "record_time": 1742543263.138709}
{"arg": {"channel": "books", "instId": "BTC-USDT"}, "action": "update", "data": [{"asks": [["83866", "0.33945002", "0", "9"], ["83871.2", "0.15034547", "0", "2"], ["83871.4", "0.01192911", "0", "1"], ["83879.3", "0", "0", "0"], ["83879.4", "0.06833557", "0", "1"], ["83889.1", "0", "0", "0"], ["83889.2", "0.09409158", "0", "1"], ["83890.7", "0", "0", "0"], ["83890.8", "0.16058424", "0", "1"], ["83896.3", "0.23859517", "0", "1"], ["83896.4", "0.00010514", "0", "1"], ["84023.8", "0", "0", "0"]], "bids": [["83865.9", "0.28761801", "0", "11"], ["83858.8", "0.26", "0", "1"], ["83857.5", "0", "0", "0"], ["83839.1", "0.23859517", "0", "1"], ["83837.9", "0", "0", "0"], ["83812.8", "0.08", "0", "2"], ["83812", "0.04", "0", "1"], ["83806.4", "0", "0", "0"], ["83805.6", "0.026", "0", "2"], ["83710", "0", "0", "0"]], "ts": "1742543263203", "checksum": -1016109443, "seqId": 49919351728, "prevSeqId": 49919351696}], "record_time": 1742543263.15481}
{"arg": {"channel": "books", "instId": "BTC-USDT"}, "action": "update", "data": [{"asks": [["83871.2", "0.07234547", "0", "2"], ["83879.3", "0.0645643", "0", "1"], ["83879.4", "0", "0", "0"]], "bids": [["83863.9", "0", "0", "0"], ["83861.6", "0.01192942", "0", "1"], ["83827.2", "0.0000573", "0", "1"]], "ts": "1742543263303", "checksum": -766187770, "seqId": 49919351738, "prevSeqId": 49919351728}], "record_time": 1742543263.252353}
{"arg": {"channel": "books", "instId": "BTC-USDT"}, "action": "update", "data": [{"asks": [["83866", "0.21336402", "0", "5"], ["83871.1", "0", "0", "0"], ["83873.8", "0.01967", "0", "1"], ["83874.9", "0", "0", "0"], ["83875", "0.06722311", "0", "1"], ["83875.5", "0.41959518", "0", "2"], ["83876.3", "0", "0", "0"], ["83876.4", "0.06325541", "0", "1"], ["83877.9", "0.38136", "0", "2"], ["83879.3", "0", "0", "0"], ["83880.1", "0.27897967", "0", "3"], ["83881.3", "0.00422712", "0", "1"], ["83881.8", "0.10069943", "0", "1"], ["83883.6", "0", "0", "0"], ["83883.8", "0.10440364", "0", "1"], ["83885.1", "0.01100705", "0", "1"], ["83885.2", "0.0949537", "0", "1"], ["83889.2", "0", "0", "0"], ["83890", "0.09327871", "0", "1"], ["83890.3", "0", "0", "0"], ["83890.4", "0.16627573", "0", "2"], ["83890.8", "0", "0", "0"], ["83891.3", "0.16710255", "0", "1"], ["83893.8", "0", "0", "0"], ["83893.9", "0.16012144", "0", "1"], ["83894.4", "0.0008", "0", "2"], ["83895.2", "0.0004", "0", "1"], ["83896.3", "0", "0", "0"], ["83898.9", "0.23859138", "0", "1"], ["83899", "0", "0", "0"], ["83899.7", "0.31792297", "0", "1"], ["83899.8", "0.29483795", "0", "2"]], "bids": [["83841.4", "0.23859138", "0", "1"], ["83839.1", "0", "0", "0"], ["83813.6", "1.63325232", "0", "3"], ["83812.8", "0.04", "0", "1"], ["83812", "0", "0", "0"], ["83810.4", "0.1", "0", "2"], ["83809.6", "0.05", "0", "1"], ["83804", "0", "0", "0"], ["83803.2", "0.00001201", "0", "1"]], "ts": "1742543263403", "checksum": -2008252809, "seqId": 49919351813, "prevSeqId": 49919351738}], "record_time": 1742543263.359014}
{"arg": {"channel": "books", "instId": "BTC-USDT"}, "action": "update", "data": [{"asks": [["83874.6", "0.4441695", "0", "3"], ["83877.9", "0.2025", "0", "1"], ["83897.7", "0.23859385", "0", "1"], ["83898.9", "0", "0", "0"], ["83926.6", "0", "0", "0"], ["83929.8", "0.01274678", "0", "1"]], "bids": [["83844.3", "0.36175435", "0", "2"], ["83841.4", "0", "0", "0"], ["83840.1", "0.23859385", "0", "1"], ["83807.4", "0.01837173", "0", "1"], ["83806.1", "0", "0", "0"], ["83805.7", "0", "0", "0"], ["83735.7", "0.18371732", "0", "1"], ["83734.7", "0", "0", "0"], ["83710", "0.00030781", "0", "2"]], "ts": "1742543263503", "checksum": 1814313150, "seqId": 49919351831, "prevSeqId": 49919351813}], "record_time": 1742543263.479253}
{"arg": {"channel": "books", "instId": "BTC-USDT"}, "action": "update", "data": [{"asks": [["83867.7", "0.01", "0", "2"], ["83877.7", "0.01", "0", "2"], ["83889.9", "0.09240603", "0", "1"], ["83890", "0", "0", "0"], ["83899.7", "0.48231437", "0", "2"], ["83899.8", "0.1409635", "0", "1"]], "bids": [["83848", "0.0402", "0", "2"], ["83840.3", "0.60016347", "0", "2"], ["83837.9", "0.005", "0", "1"], ["83836.8", "1.35933395", "0", "2"], ["83710", "0", "0", "0"]], "ts": "1742543263603", "checksum": -1253486901, "seqId": 49919351846, "prevSeqId": 49919351831}], "record_time": 1742543263.658609}
{"arg": {"channel": "books", "instId": "BTC-USDT"}, "action": "update", "data": [{"asks": [["83875.4", "0.30615899", "0", "3"], ["83875.5", "0.35776", "0", "1"], ["83880", "0.06884725", "0", "1"], ["83880.1", "0.21", "0", "2"], ["83881.7", "0.10445394", "0", "1"], ["83881.8", "0", "0", "0"], ["83889.8", "0.10480324", "0", "2"], ["83889.9", "0", "0", "0"], ["83891.2", "0.17971852", "0", "2"], ["83891.3", "0", "0", "0"], ["83894.8", "0.23859636", "0", "1"], ["83897.7", "0", "0", "0"], ["83899.6", "0.16902597", "0", "1"], ["83899.7", "0.31792297", "0", "1"]], "bids": [["83865.9", "0.26425384", "0", "11"], ["83857.6", "0.01540976", "0", "2"], ["83840.1", "0", "0", "0"], ["83837.9", "0.24359636", "0", "2"], ["83710", "0.00030781", "0", "2"]], "ts": "1742543263703", "checksum": 1115955488, "seqId": 49919351869, "prevSeqId": 49919351846}], "record_time": 1742543263.663929}
{"arg": {"channel": "books", "instId": "BTC-USDT"}, "action": "update", "data": [{"asks": [["83866", "0.23125102", "0", "6"], ["83874.9", "0.06920308", "0", "1"], ["83875", "0", "0", "0"], ["83875.3", "0.06963277", "0", "1"], ["83875.4", "0.23852709", "0", "2"], ["83879.8", "0.10422607", "0", "2"], ["83880", "0", "0", "0"], ["83881.6", "0.10456187", "0", "1"], ["83881.7", "0", "0", "0"], ["83883.7", "0.09270301", "0", "1"], ["83883.8", "0", "0", "0"], ["83885.1", "0.10488728", "0", "2"], ["83885.2", "0", "0", "0"], ["83889.6", "0.10516027", "0", "1"], ["83889.8", "0.0005", "0", "1"], ["83890.3", "0.15831578", "0", "1"], ["83890.4", "0.00422588", "0", "1"], ["83891", "0.1596212", "0", "2"], ["83891.2", "0.00578385", "0", "1"], ["83899.5", "0.16832777", "0", "1"], ["83899.6", "0", "0", "0"], ["84023.3", "0", "0", "0"]], "bids": [["83823.2", "0.0008", "0", "2"], ["83822.4", "0.00039867", "0", "1"], ["83816.8", "0", "0", "0"], ["83816", "0", "0", "0"]], "ts": "1742543263803", "checksum": 271460329, "seqId": 49919351900, "prevSeqId": 49919351869}], "record_time": 1742543263.75329}
{"arg": {"channel": "books", "instId": "BTC-USDT"}, "action": "update", "data": [{"asks": [["83899.5", "0", "0", "0"], ["84023.3", "0.00011161", "0", "1"]], "bids": [["83865.9", "0.26002384", "0", "10"], ["83854.8", "0", "0", "0"], ["83844.3", "0.35819548", "0", "1"], ["83709.8", "0.0022146", "0", "4"]], "ts": "1742543263903", "checksum": -574880157, "seqId": 49919351913, "prevSeqId": 49919351900}], "record_time": 1742543263.853127}
{"arg": {"channel": "books", "instId": "BTC-USDT"}, "action": "update", "data": [{"asks": [["83867.6", "0.01455817", "0", "1"], ["83875.2", "0.06463616", "0", "1"], ["83875.3", "0", "0", "0"], ["83876.9", "0", "0", "0"], ["83879.7", "0.06168012", "0", "1"], ["83879.8", "0.04", "0", "1"], ["83881.5", "0.09805362", "0", "1"], ["83881.6", "0", "0", "0"], ["83889.5", "0.0936411", "0", "1"], ["83889.6", "0", "0", "0"], ["83890.9", "0.16761976", "0", "1"], ["83891", "0.00001", "0", "1"], ["83899.4", "0.15863461", "0", "1"], ["84022.6", "0", "0", "0"], ["84023.2", "0", "0", "0"], ["84023.3", "0", "0", "0"]], "bids": [["83852.8", "0.01", "0", "1"], ["83809", "0.50565", "0", "1"], ["83788.2", "0.24116161", "0", "1"], ["83788.1", "0", "0", "0"], ["83785.2", "0.01148", "0", "1"], ["83710", "0", "0", "0"], ["83709.8", "0", "0", "0"]], "ts": "1742543264003", "checksum": 787369473, "seqId": 49919351937, "prevSeqId": 49919351913}], "record_time": 1742543264.182398}
{"arg": {"channel": "books", "instId": "BTC-USDT"}, "action": "update", "data": [{"asks": [["83877.9", "0.38136", "0", "2"], ["83878.4", "0.135953", "0", "1"], ["83889.5", "0", "0", "0"]], "bids": [["83865.9", "0.26421634", "0", "11"]], "ts": "1742543264103", "checksum": 1910858800, "seqId": 49919351942, "prevSeqId": 49919351937}], "record_time": 1742543264.188561}
{"arg": {"channel": "books", "instId": "BTC-USDT"}, "action": "update", "data": [{"asks": [["83866", "0.2288039", "0", "6"], ["83867.6", "0", "0", "0"], ["83871", "0.1532869", "0", "1"], ["83871.1", "0.26", "0", "1"], ["83871.2", "0.00422796", "0", "1"], ["83874.9", "0", "0", "0"], ["83875", "0.06399329", "0", "1"], ["83875.2", "0", "0", "0"], ["83875.4", "0.30031634", "0", "3"], ["83879.7", "0", "0", "0"], ["83879.9", "0.067532", "0", "1"], ["83881.5", "0", "0", "0"], ["83881.7", "0.10372334", "0", "1"], ["83889.7", "0.0964513", "0", "2"], ["83890.3", "0", "0", "0"], ["83890.4", "0.16315734", "0", "2"], ["83890.9", "0", "0", "0"], ["83891.1", "0.49083365", "0", "3"], ["83894.8", "0", "0", "0"], ["83895.2", "0.23899634", "0", "2"], ["83899.4", "0", "0", "0"], ["83899.6", "0.17279839", "0", "1"], ["83941.1", "0.00001805", "0", "1"], ["84015.1", "0", "0", "0"], ["84022.6", "0.00002206", "0", "1"], ["84023.2", "0.01316", "0", "1"], ["84023.3", "0.00011161", "0", "1"], ["84023.8", "0.00001575", "0", "1"]], "bids": [["83865.9", "0.28421634", "0", "12"], ["83839.1", "0.23859634", "0", "1"], ["83837.9", "0.005", "0", "1"], ["83722.6", "0.00178428", "0", "1"], ["83722.3", "0.00001016", "0", "1"], ["83710.3", "0", "0", "0"], ["83710.1", "0", "0", "0"]], "ts": "1742543264203", "checksum": 2073304460, "seqId": 49919351983, "prevSeqId": 49919351942}], "record_time": 1742543264.189794}
{"arg": {"channel": "books", "instId": "BTC-USDT"}, "action": "update", "data": [{"asks": [["83866", "0.1989169", "0", "5"], ["83871", "0.06225098", "0", "1"], ["83871.1", "0", "0", "0"], ["83871.2", "0", "0", "0"], ["83871.8", "0", "0", "0"], ["83872.5", "0", "0", "0"], ["83875", "0", "0", "0"], ["83875.1", "0.06299492", "0", "1"], ["83875.4", "0.23852709", "0", "2"], ["83875.7", "0.07369235", "0", "2"], ["83876.4", "0", "0", "0"], ["83876.5", "0.06511644", "0", "1"], ["83879.9", "0", "0", "0"], ["83880.4", "0.06825438", "0", "1"], ["83881.7", "0", "0", "0"], ["83882", "0.09905197", "0", "2"], ["83883.7", "0", "0", "0"], ["83883.8", "0.10061049", "0", "1"], ["83885.1", "0.01100705", "0", "1"], ["83885.3", "0.10165887", "0", "1"], ["83886.3", "0.003576", "0", "1"], ["83888.7", "0.04", "0", "1"], ["83889.7", "0.0005", "0", "1"], ["83890.2", "0.09256933", "0", "1"], ["83890.4", "0.00422588", "0", "1"], ["83890.5", "0.15610683", "0", "1"], ["83891.1", "0.32811495", "0", "2"], ["83891.4", "0.15829107", "0", "1"], ["83893.9", "0", "0", "0"], ["83894", "0.1558747", "0", "1"], ["83895.2", "0.0004", "0", "1"], ["83899.6", "0.23858861", "0", "1"], ["83900", "0.49549222", "0", "11"], ["83903.9", "0.25012738", "0", "2"], ["83904", "0", "0", "0"], ["83918.9", "0", "0", "0"], ["83921.8", "0.43508217", "0", "1"], ["83921.9", "0.57964474", "0", "2"], ["83922.2", "0", "0", "0"], ["83922.7", "0", "0", "0"], ["83926.1", "0.00007814", "0", "1"], ["83937.9", "0", "0", "0"], ["83943.9", "0", "0", "0"], ["83951.8", "0.01429391", "0", "1"], ["83956.2", "0", "0", "0"], ["83961.2", "0", "0", "0"], ["83962.5", "0.3645466", "0", "1"], ["83964", "0", "0", "0"], ["83972.5", "0.00580014", "0", "1"], ["84013.7", "0", "0", "0"], ["84023.4", "0.00119014", "0", "1"], ["84024.9", "0.35714307", "0", "1"], ["84025", "0.00001717", "0", "1"], ["84025.9", "0.000012", "0", "1"], ["84026.4", "0.03", "0", "1"], ["84026.6", "0.0001749", "0", "1"], ["84027.3", "0.00001525", "0", "1"]], "bids": [["83865.9", "0.36146634", "0", "13"], ["83857.4", "0.05733051", "0", "1"], ["83852.1", "0.07553894", "0", "1"], ["83844.1", "0.00422797", "0", "1"], ["83841.4", "0.23858861", "0", "1"], ["83839.1", "0", "0", "0"], ["83838", "0", "0", "0"], ["83832", "0.82568631", "0", "1"], ["83828.5", "0.04", "0", "1"], ["83828", "1", "0", "1"], ["83822.9", "0", "0", "0"], ["83817.4", "0.01191551", "0", "1"], ["83816.7", "0.0119156", "0", "1"], ["83816.5", "0.02383126", "0", "2"], ["83799.3", "0.01191582", "0", "1"], ["83796.2", "0.01191583", "0", "1"], ["83770", "0.0214", "0", "1"], ["83769.8", "0.0214", "0", "1"], ["83767.3", "0.0642", "0", "3"], ["83751.5", "0", "0", "0"], ["83751.4", "0", "0", "0"], ["83749.5", "0", "0", "0"], ["83744.8", "0.01489559", "0", "2"], ["83742.2", "0.0286", "0", "2"], ["83742.1", "0.0143", "0", "1"], ["83734", "0.00001201", "0", "1"], ["83726.4", "0", "0", "0"], ["83724.3", "0.00018938", "0", "2"], ["83715.8", "0", "0", "0"], ["83713.6", "0", "0", "0"], ["83711.5", "0", "0", "0"], ["83711.4", "0", "0", "0"], ["83711.1", "0", "0", "0"], ["83710.7", "0", "0", "0"], ["83710.5", "0", "0", "0"]], "ts": "1742543264303", "checksum": 482425607, "seqId": 49919352154, "prevSeqId": 49919351983}], "record_time": 1742543264.253182}
{"arg": {"channel": "books", "instId": "BTC-USDT"}, "action": "update", "data": [{"asks": [["83866", "0.23584324", "0", "6"], ["83874.5", "0.06483288", "0", "1"], ["83874.6", "0.51057104", "0", "4"], ["83875.1", "0", "0", "0"], ["83875.7", "0.01192938", "0", "1"], ["83876", "0.07000747", "0", "1"], ["83876.5", "0", "0", "0"], ["83879.1", "0.06301129", "0", "1"], ["83880.1", "0", "0", "0"], ["83880.4", "0", "0", "0"], ["83880.9", "0.09516121", "0", "1"], ["83882", "0.002", "0", "1"], ["83883.3", "0.10098982", "0", "2"], ["83883.8", "0", "0", "0"], ["83884.7", "0.09801036", "0", "1"], ["83885.3", "0", "0", "0"], ["83886.3", "0", "0", "0"], ["83889", "0.10210897", "0", "1"], ["83889.9", "0.16880583", "0", "1"], ["83890.2", "0", "0", "0"], ["83890.4", "0.16086429", "0", "2"], ["83890.5", "0", "0", "0"], ["83891.4", "0", "0", "0"], ["83893.5", "0.15657403", "0", "2"], ["83894", "0", "0", "0"], ["83894.8", "0.23859975", "0", "1"], ["83898.8", "0.15503395", "0", "1"], ["83899.6", "0", "0", "0"], ["83899.7", "0.32149897", "0", "2"], ["83900", "0.34261038", "0", "10"], ["83924.4", "0.03259741", "0", "1"], ["84027.6", "0.32367639", "0", "1"], ["84027.7", "0.00007589", "0", "1"], ["84027.8", "0.0143", "0", "1"]], "bids": [["83865.9", "0.17276366", "0", "9"], ["83841.4", "0", "0", "0"], ["83837.8", "0.00001201", "0", "1"], ["83836.9", "0.23860135", "0", "1"], ["83832", "0.59715978", "0", "1"], ["83828", "0", "0", "0"], ["83822.1", "0.07761471", "0", "1"], ["83822", "0", "0", "0"], ["83711.4", "0.00002977", "0", "1"], ["83711.1", "0.000015", "0", "1"]], "ts": "1742543264403", "checksum": 1412997997, "seqId": 49919352234, "prevSeqId": 49919352154}], "record_time": 1742543264.354889}
{"arg": {"channel": "books", "instId": "BTC-USDT"}, "action": "update", "data": [{"asks": [["83866", "0.82809514", "0", "16"], ["83867.6", "0.01455817", "0", "1"], ["83868.3", "0.01192954", "0", "1"], ["83869.7", "0.01967", "0", "1"], ["83870.6", "0.03868101", "0", "1"], ["83871.4", "0", "0", "0"], ["83872.3", "0.12915599", "0", "2"], ["83873.8", "0.07012185", "0", "1"], ["83874.4", "0.003576", "0", "1"], ["83874.5", "0", "0", "0"], ["83874.6", "0.4441695", "0", "3"], ["83876", "0.05902", "0", "1"], ["83876.6", "0.06434046", "0", "1"], ["83878.6", "0.10462142", "0", "1"], ["83879.1", "0", "0", "0"], ["83880.6", "0", "0", "0"], ["83880.9", "0", "0", "0"], ["83881.1", "0.09654584", "0", "1"], ["83882.5", "0.09808041", "0", "1"], ["83883.3", "0.00060645", "0", "1"], ["83884.7", "0", "0", "0"], ["83885", "0.21", "0", "2"], ["83886.4", "0.09910509", "0", "1"], ["83887.3", "0.08991011", "0", "1"], ["83887.7", "0.15567695", "0", "2"], ["83888.1", "0.16057757", "0", "1"], ["83889", "0", "0", "0"], ["83889.1", "0.02823758", "0", "1"], ["83889.9", "0", "0", "0"], ["83890.4", "0.00422588", "0", "1"], ["83891.6", "0.23860532", "0", "1"], ["83893.5", "0", "0", "0"], ["83894.8", "0", "0", "0"], ["83896.2", "0.15645147", "0", "1"], ["83896.7", "0.02693528", "0", "1"], ["83898.8", "0", "0", "0"], ["83899.7", "0.31792297", "0", "1"], ["83903.9", "0.2218898", "0", "1"], ["83912.3", "0", "0", "0"], ["83917.8", "0", "0", "0"], ["84026.4", "0", "0", "0"], ["84026.6", "0", "0", "0"], ["84027.3", "0", "0", "0"], ["84027.6", "0", "0", "0"], ["84027.7", "0", "0", "0"], ["84027.8", "0", "0", "0"]], "bids": [["83865.9", "0.00716", "0", "3"], ["83864", "0", "0", "0"], ["83863.5", "0.004473", "0", "1"], ["83861.1", "0.0705018", "0", "1"], ["83858.8", "0", "0", "0"], ["83857.4", "0", "0", "0"], ["83856.1", "0.02229578", "0", "1"], ["83854", "0.0352", "0", "1"], ["83852.8", "0", "0", "0"], ["83845.8", "0.06", "0", "2"], ["83844.4", "0.18369646", "0", "1"], ["83841.3", "0", "0", "0"], ["83836.9", "0", "0", "0"], ["83832.8", "0.23860582", "0", "1"], ["83710.7", "0.00001017", "0", "1"], ["83710.5", "0.71642942", "0", "4"], ["83710.3", "0.00012869", "0", "3"]], "ts": "1742543264503", "checksum": -988867591, "seqId": 49919352399, "prevSeqId": 49919352234}], "record_time": 1742543264.454957}
{"arg": {"channel": "books", "instId": "BTC-USDT"}, "action": "update", "data": [{"asks": [["83871", "0.103327", "0", "2"], ["83872.3", "0", "0", "0"], ["83872.5", "0.06938415", "0", "1"], ["83872.6", "0.06718321", "0", "1"], ["83873.8", "0", "0", "0"], ["83874", "0.1848885", "0", "4"], ["83876.6", "0", "0", "0"], ["83876.8", "0.06167201", "0", "1"], ["83877.9", "0.2025", "0", "1"], ["83878.6", "0", "0", "0"], ["83878.8", "0.1046292", "0", "1"], ["83881.1", "0", "0", "0"], ["83881.3", "0.10517795", "0", "2"], ["83882.5", "0", "0", "0"], ["83882.8", "0.095778", "0", "1"], ["83886.4", "0", "0", "0"], ["83886.6", "0.49782877", "0", "2"], ["83887.7", "0.0000225", "0", "1"], ["83888", "0.29673068", "0", "2"], ["83888.1", "0", "0", "0"], ["83888.3", "0.17595336", "0", "2"], ["83891.1", "0.23241506", "0", "1"], ["83891.4", "0.23860601", "0", "1"], ["83891.5", "0.17534371", "0", "1"], ["83891.6", "0", "0", "0"], ["83893.1", "0", "0", "0"], ["83896.2", "0", "0", "0"], ["83896.4", "0.15636115", "0", "2"], ["83903.9", "0.33586878", "0", "2"], ["83904", "0.472384", "0", "1"], ["83939.6", "0.25893395", "0", "2"], ["84026.4", "0.03", "0", "1"], ["84026.6", "0.0001749", "0", "1"], ["84027.3", "0.00001525", "0", "1"]], "bids": [["83864", "0.0352", "0", "1"], ["83863.5", "0", "0", "0"], ["83861.6", "0", "0", "0"], ["83857.1", "0", "0", "0"], ["83852.8", "0.03868101", "0", "1"], ["83850.6", "0.08672618", "0", "2"], ["83849", "0.06", "0", "2"], ["83832.8", "0.23860601", "0", "1"]], "ts": "1742543264603", "checksum": 196450570, "seqId": 49919352486, "prevSeqId": 49919352399}], "record_time": 1742543264.725256}
{"arg": {"channel": "books", "instId": "BTC-USDT"}, "action": "update", "data": [{"asks": [["83866", "0.84776514", "0", "17"], ["83869.7", "0", "0", "0"], ["83871.4", "0.05902", "0", "1"], ["83872.5", "0", "0", "0"], ["83872.6", "0.12953053", "0", "2"], ["83874", "0.1227708", "0", "3"], ["83874.1", "0.06937179", "0", "1"], ["83876", "0", "0", "0"], ["83878.8", "0", "0", "0"], ["83878.9", "0.10120739", "0", "1"], ["83881.3", "0.00422712", "0", "1"], ["83881.4", "0.0952515", "0", "2"], ["83891.4", "0", "0", "0"], ["83891.5", "0", "0", "0"], ["83891.6", "0.15876287", "0", "1"], ["83892.3", "0.23860361", "0", "1"], ["83896.4", "0.00010514", "0", "1"], ["84027.6", "0.32367639", "0", "1"]], "bids": [["83865.9", "0.00715", "0", "2"], ["83863.6", "0.00423", "0", "1"], ["83857.6", "0.02877596", "0", "3"], ["83848.8", "0", "0", "0"], ["83845.3", "0.08905", "0", "1"], ["83844.5", "0.03", "0", "1"], ["83836.9", "0.23860361", "0", "1"], ["83832.8", "0", "0", "0"], ["83802", "0.2", "0", "1"], ["83710.5", "0", "0", "0"], ["83710.3", "0", "0", "0"]], "ts": "1742543264703", "checksum": -701597398, "seqId": 49919352515, "prevSeqId": 49919352486}], "record_time": 1742543264.728966}
{"arg": {"channel": "books", "instId": "BTC-USDT"}, "action": "update", "data": [{"asks": [["83872.5", "0.06756002", "0", "1"], ["83872.6", "0.06718321", "0", "1"], ["83874", "0.19124276", "0", "4"], ["83874.1", "0", "0", "0"], ["83878.8", "0.10427494", "0", "1"], ["83878.9", "0", "0", "0"], ["83881.3", "0.09654961", "0", "2"], ["83881.4", "0.00005728", "0", "1"], ["83891.5", "0.17567574", "0", "1"], ["83891.6", "0", "0", "0"], ["83896.4", "0.17424417", "0", "2"]], "bids": [["83863.6", "0", "0", "0"], ["83848", "0.21935015", "0", "3"], ["83845.3", "0", "0", "0"], ["83844.5", "0", "0", "0"], ["83802", "0", "0", "0"], ["83710.5", "0.71642942", "0", "4"], ["83710.3", "0.00012869", "0", "3"], ["83710.1", "0.00007352", "0", "1"], ["83710", "0.00030781", "0", "2"]], "ts": "1742543264803", "checksum": 1554480694, "seqId": 49919352538, "prevSeqId": 49919352515}], "record_time": 1742543264.759}
{"arg": {"channel": "books", "instId": "BTC-USDT"}, "action": "update", "data": [{"asks": [["83866", "0.23594324", "0", "7"], ["83867.6", "0", "0", "0"], ["83868.3", "0", "0", "0"], ["83871", "0", "0", "0"], ["83871.3", "0.05740385", "0", "1"], ["83871.4", "0", "0", "0"], ["83872.5", "0", "0", "0"], ["83872.6", "0", "0", "0"], ["83873.6", "0.01967", "0", "1"], ["83874", "0.1227708", "0", "3"], ["83874.6", "0.31592616", "0", "2"], ["83874.8", "0.12362131", "0", "2"], ["83874.9", "0.06927257", "0", "1"], ["83875.4", "0", "0", "0"], ["83875.5", "0", "0", "0"], ["83875.6", "0.05966709", "0", "1"], ["83876.2", "0.06436853", "0", "1"], ["83876.8", "0", "0", "0"], ["83878.2", "0.20210647", "0", "1"], ["83878.8", "0", "0", "0"], ["83879.4", "0.06739417", "0", "1"], ["83879.8", "0", "0", "0"], ["83879.9", "0.05901", "0", "1"], ["83881.2", "0.10339357", "0", "1"], ["83881.3", "0.00422712", "0", "1"], ["83881.4", "0.04005728", "0", "2"], ["83882.2", "0", "0", "0"], ["83882.8", "0", "0", "0"], ["83883.4", "0", "0", "0"], ["83883.6", "0.10166255", "0", "1"], ["83885", "0.30485081", "0", "3"], ["83885.5", "0.18795133", "0", "1"], ["83886.6", "0.4", "0", "1"], ["83887.3", "0", "0", "0"], ["83887.7", "0", "0", "0"], ["83888", "0", "0", "0"], ["83888.3", "0.01787779", "0", "1"], ["83889.2", "0.09273677", "0", "1"], ["83890.2", "0.15918967", "0", "1"], ["83890.7", "0.15747382", "0", "1"], ["83891.1", "0", "0", "0"], ["83891.5", "0", "0", "0"], ["83892.3", "0", "0", "0"], ["83893.7", "0.17020394", "0", "1"], ["83895.3", "0.87784313", "0", "1"], ["83895.6", "0.00422588", "0", "1"], ["83896.4", "0.00010514", "0", "1"], ["83896.7", "0", "0", "0"], ["83901.1", "0.23858373", "0", "1"], ["83907.8", "0.02693528", "0", "1"], ["83908.9", "0", "0", "0"], ["83969", "0.20246264", "0", "3"], ["84027.7", "0.00007589", "0", "1"], ["84027.8", "0.0143", "0", "1"], ["84027.9", "0.0143", "0", "1"], ["84028", "0.0429", "0", "3"], ["84028.1", "0.2025", "0", "1"], ["84028.4", "0.00012012", "0", "1"]], "bids": [["83865.9", "0.21793823", "0", "7"], ["83861.4", "0.0573114", "0", "1"], ["83861.3", "0.11930174", "0", "1"], ["83861.1", "0", "0", "0"], ["83858.7", "0", "0", "0"], ["83852.8", "0.2031363", "0", "2"], ["83852.7", "0.35820748", "0", "2"], ["83852.1", "0", "0", "0"], ["83845.6", "0.18795133", "0", "1"], ["83844.5", "0.23858373", "0", "1"], ["83843.1", "0.00362724", "0", "1"], ["83836.9", "0", "0", "0"], ["83835.8", "0.14565085", "0", "1"], ["83832.7", "0", "0", "0"], ["83826.9", "0.16562578", "0", "1"], ["83824.2", "0", "0", "0"], ["83814.4", "0.08", "0", "2"], ["83813.6", "1.59325232", "0", "2"], ["83812.8", "0", "0", "0"], ["83812", "0.1", "0", "2"], ["83811.2", "0.1627708", "0", "3"], ["83810.4", "0", "0", "0"], ["83809.6", "0", "0", "0"], ["83709.8", "0.0022146", "0", "4"], ["83709.7", "0.01141021", "0", "1"]], "ts": "1742543264903", "checksum": 271364380, "seqId": 49919352674, "prevSeqId": 49919352538}], "record_time": 1742543264.873676}
{"arg": {"channel": "books", "instId": "BTC-USDT"}, "action": "update", "data": [{"asks": [["83867.6", "0.01455817", "0", "1"], ["83874.9", "0.06249012", "0", "1"], ["83879.4", "0.06901408", "0", "1"], ["83881.2", "0.09778886", "0", "1"], ["83889.2", "0.09252272", "0", "1"], ["83890.6", "0.16578643", "0", "1"], ["83890.7", "0", "0", "0"], ["83891.8", "1.60642193", "0", "1"], ["83894.5", "0.00021", "0", "1"], ["83895.2", "0.23898929", "0", "2"], ["83899", "0.15863942", "0", "1"], ["83900.7", "0.35771", "0", "1"], ["83901.1", "0", "0", "0"], ["84027.9", "0", "0", "0"], ["84028", "0", "0", "0"], ["84028.1", "0", "0", "0"], ["84028.4", "0", "0", "0"]], "bids": [["83850.9", "0.008", "0", "1"], ["83844.5", "0", "0", "0"], ["83841.1", "0.23858929", "0", "1"], ["83820.2", "0.35771", "0", "1"], ["83815.2", "0.09", "0", "3"], ["83814.4", "0.04", "0", "1"], ["83813.6", "1.55325232", "0", "1"], ["83709.8", "0", "0", "0"], ["83709.7", "0", "0", "0"]], "ts": "1742543265003", "checksum": 942961976, "seqId": 49919352714, "prevSeqId": 49919352674}], "record_time": 1742543264.964656}
{"arg": {"channel": "books", "instId": "BTC-USDT"}, "action": "update", "data": [{"asks": [["83869", "0.01192946", "0", "1"], ["83879.4", "0", "0", "0"], ["83890.6", "0", "0", "0"], ["83893.6", "0.0008", "0", "2"], ["83894.4", "0.0004", "0", "1"], ["83894.8", "0.23859431", "0", "1"], ["83895.2", "0", "0", "0"]], "bids": [["83865.9", "0.21173223", "0", "7"], ["83861.4", "0.06924086", "0", "2"], ["83841.1", "0", "0", "0"], ["83839.1", "0.23859431", "0", "1"], ["83824.8", "0.0008", "0", "2"], ["83824", "0.00039866", "0", "1"], ["83823.2", "0", "0", "0"], ["83822.4", "0", "0", "0"]], "ts": "1742543265103", "checksum": 1582198359, "seqId": 49919352740, "prevSeqId": 49919352714}], "record_time": 1742543265.435237}
{"arg": {"channel": "books", "instId": "BTC-USDT"}, "action": "update", "data": [{"asks": [["83866", "0.23463378", "0", "8"], ["83874.9", "0.06274158", "0", "1"], ["83877.9", "0.38136", "0", "2"], ["83879.3", "0.06457399", "0", "1"], ["83881.2", "0.09692159", "0", "1"], ["83883.5", "0.10366724", "0", "1"], ["83883.6", "0", "0", "0"], ["83889.1", "0.1254391", "0", "2"], ["83889.2", "0", "0", "0"], ["83890.6", "0.15789043", "0", "1"], ["83891.8", "0", "0", "0"], ["83893.6", "0", "0", "0"], ["83894.4", "0.0008", "0", "2"], ["83895.2", "0.0004", "0", "1"], ["83898.9", "0.1552431", "0", "1"], ["83899", "0", "0", "0"], ["83903.2", "0.35771", "0", "1"], ["83908.3", "0.11085215", "0", "1"], ["83911.5", "0", "0", "0"]], "bids": [["83865.9", "0.21174223", "0", "8"], ["83856.3", "0.0991245", "0", "1"], ["83856.2", "0.26", "0", "1"], ["83856.1", "0", "0", "0"], ["83832", "0", "0", "0"], ["83828.1", "0", "0", "0"], ["83815.2", "0.01", "0", "1"], ["83814.4", "0.08", "0", "2"], ["83813.6", "1.59325232", "0", "2"], ["83709.8", "0.0022146", "0", "4"]], "ts": "1742543265203", "checksum": 1447731770, "seqId": 49919352783, "prevSeqId": 49919352740}], "record_time": 1742543265.439343}
{"arg": {"channel": "books", "instId": "BTC-USDT"}, "action": "update", "data": [{"asks": [["83866", "0.33463378", "0", "9"], ["83871.4", "0.01967", "0", "1"], ["83873.6", "0", "0", "0"], ["83874.4", "0", "0", "0"], ["83874.6", "0.38654285", "0", "3"], ["83874.7", "0.06316492", "0", "1"], ["83874.8", "0.05968388", "0", "1"], ["83874.9", "0", "0", "0"], ["83878.9", "0.06630329", "0", "1"], ["83879.3", "0", "0", "0"], ["83880.9", "0.10050641", "0", "1"], ["83881.2", "0", "0", "0"], ["83885", "0.21", "0", "2"], ["83888", "0.1252", "0", "1"], ["83888.7", "0.13220646", "0", "2"], ["83889.1", "0.02823758", "0", "1"], ["83890.1", "0.1728533", "0", "1"], ["83890.2", "0", "0", "0"], ["83890.4", "0.18017432", "0", "2"], ["83890.6", "0", "0", "0"], ["83891.8", "1.57539365", "0", "1"], ["83898.5", "0.15658679", "0", "1"], ["83898.9", "0", "0", "0"], ["83900.9", "0.003576", "0", "1"], ["83908.9", "0.1252", "0", "1"], ["83921.1", "1.35784316", "0", "1"], ["83921.2", "2.8053748", "0", "1"], ["83921.8", "0", "0", "0"], ["83937.6", "0.2504", "0", "1"], ["84027.3", "0", "0", "0"], ["84027.6", "0", "0", "0"], ["84027.7", "0", "0", "0"], ["84027.8", "0", "0", "0"]], "bids": [["83831", "1.57524235", "0", "1"], ["83813.7", "0", "0", "0"], ["83813.6", "0.04", "0", "1"]], "ts": "1742543265303", "checksum": 1215343009, "seqId": 49919352818, "prevSeqId": 49919352783}], "record_time": 1742543265.441859}
{"arg": {"channel": "books", "instId": "BTC-USDT"}, "action": "update", "data": [{"asks": [["83866", "0.53713378", "0", "10"], ["83875.4", "0.17886", "0", "1"], ["83876.2", "0", "0", "0"], ["83877.9", "0.2025", "0", "1"], ["83878.9", "0", "0", "0"], ["83888.7", "0.04", "0", "1"], ["83893.7", "0", "0", "0"], ["83903.2", "0", "0", "0"], ["84027.3", "0.00001525", "0", "1"], ["84027.6", "0.32367639", "0", "1"], ["84027.7", "0.00007589", "0", "1"]], "bids": [["83865.9", "0.20724823", "0", "7"], ["83824", "1.00039866", "0", "2"], ["83801.8", "1.10679277", "0", "1"], ["83801.7", "2.84080844", "0", "1"], ["83800.8", "0", "0", "0"], ["83709.8", "0", "0", "0"]], "ts": "1742543265403", "checksum": 1571182409, "seqId": 49919352831, "prevSeqId": 49919352818}], "record_time": 1742543265.450629}
{"arg": {"channel": "books", "instId": "BTC-USDT"}, "action": "update", "data": [{"asks": [["83878.8", "0.06933929", "0", "1"], ["83888.6", "0.09247126", "0", "1"], ["83890.3", "0.16264009", "0", "1"], ["83890.4", "0.00422588", "0", "1"], ["83892.9", "0.23859832", "0", "1"], ["83894.8", "0", "0", "0"], ["83898.4", "0.16613075", "0", "1"], ["83898.5", "0", "0", "0"], ["84027.3", "0", "0", "0"], ["84027.6", "0", "0", "0"], ["84027.7", "0", "0", "0"]], "bids": [["83865.9", "0.20414823", "0", "6"], ["83839.1", "0", "0", "0"], ["83836.9", "0.23859832", "0", "1"]], "ts": "1742543265503", "checksum": 69960063, "seqId": 49919352844, "prevSeqId": 49919352831}], "record_time": 1742543265.454811}
{"arg": {"channel": "books", "instId": "BTC-USDT"}, "action": "update", "data": [{"asks": [["83866", "0.33463378", "0", "9"], ["83887", "0.30883304", "0", "1"], ["83891.2", "0", "0", "0"], ["83900.7", "0", "0", "0"], ["84027.3", "0.00001525", "0", "1"], ["84027.6", "0.32367639", "0", "1"]], "bids": [["83856.5", "0.0991245", "0", "1"], ["83856.4", "0.26", "0", "1"], ["83856.3", "0", "0", "0"], ["83856.2", "0", "0", "0"], ["83820.2", "0", "0", "0"], ["83709.8", "0.0022146", "0", "4"]], "ts": "1742543265603", "checksum": -438393663, "seqId": 49919352853, "prevSeqId": 49919352844}], "record_time": 1742543265.55512}
