{"arg": {"channel": "books", "instId": "BTC-USDT"}, "action": "update", "data": [{"asks": [["84116.5", "0.03728865", "0", "1"], ["84120.1", "0.00001197", "0", "1"], ["84120.2", "0.03084581", "0", "1"], ["84120.7", "0", "0", "0"], ["84120.8", "0.38786302", "0", "2"], ["84120.9", "0.03219145", "0", "1"], ["84121", "0.03406617", "0", "1"], ["84127.1", "0", "0", "0"], ["84127.2", "0.03436986", "0", "1"], ["84127.3", "0.0326928", "0", "1"], ["84129", "0.23790562", "0", "1"], ["84134", "0", "0", "0"], ["84134.1", "0", "0", "0"], ["84134.2", "0.06851292", "0", "1"], ["84136.2", "0", "0", "0"], ["84136.3", "0.06698079", "0", "1"], ["84136.6", "0", "0", "0"], ["84136.7", "0.06724183", "0", "1"], ["84138.2", "0", "0", "0"], ["84138.3", "0.15540788", "0", "2"], ["84262.4", "0", "0", "0"]], "bids": [["84102.1", "0.05476408", "0", "1"], ["84092.9", "0.03462274", "0", "2"], ["84092.8", "0.03152726", "0", "1"], ["84092.7", "0.087", "0", "2"], ["84092.2", "1.03130933", "0", "2"], ["84092.1", "0", "0", "0"], ["84091.6", "0.03463414", "0", "1"], ["84091.5", "0", "0", "0"], ["84088", "0.35667", "0", "1"], ["84085.9", "0.03289524", "0", "1"], ["84085.8", "0", "0", "0"], ["84085.3", "0.03258241", "0", "1"], ["84085.2", "0", "0", "0"], ["84078.9", "0.08683063", "0", "2"], ["84078.8", "1.86894369", "0", "2"], ["84076.8", "0.06971297", "0", "1"], ["84076.7", "0", "0", "0"], ["84076.1", "0.000015", "0", "1"], ["84075.8", "0.06895679", "0", "1"], ["84075.7", "0", "0", "0"], ["84075.3", "0.06191057", "0", "1"], ["84075.2", "0", "0", "0"], ["84074.6", "0.23790562", "0", "1"], ["84071", "0.0264348", "0", "4"], ["84045.1", "0.00005207", "0", "1"], ["83959.1", "0", "0", "0"], ["83958.8", "0", "0", "0"]], "ts": "1742554953004", "checksum": 1591530132, "seqId": 49927366762, "prevSeqId": 49927366702}], "record_time": 1742554953.014421, "EXCHANGE": "OKX"}
{"arg": {"channel": "books", "instId": "BTC-USDT"}, "action": "update", "data": [{"asks": [["84134.1", "0.01774536", "0", "1"], ["84199.1", "0", "0", "0"]], "bids": [["84091.3", "0.18309673", "0", "2"]], "ts": "1742554953104", "checksum": 1591530132, "seqId": 49927366768, "prevSeqId": 49927366762}], "record_time": 1742554953.119501, "EXCHANGE": "OKX"}
{"arg": {"channel": "books", "instId": "BTC-USDT"}, "action": "update", "data": [{"asks": [["84111.4", "0.8006045", "0", "14"], ["84118.7", "0.0103941", "0", "1"], ["84120.1", "0.03321968", "0", "2"], ["84120.2", "0", "0", "0"], ["84120.7", "0.03296676", "0", "1"], ["84120.8", "0.39162335", "0", "2"], ["84120.9", "0.03420287", "0", "1"], ["84121", "0", "0", "0"], ["84127.1", "0.03443119", "0", "1"], ["84127.2", "0.03173128", "0", "1"], ["84127.3", "0", "0", "0"], ["84129", "0", "0", "0"], ["84129.4", "0.03359996", "0", "1"], ["84129.5", "0.03324806", "0", "1"], ["84129.6", "0", "0", "0"], ["84134", "0.23790287", "0", "1"], ["84134.1", "0.08353278", "0", "2"], ["84134.2", "0", "0", "0"], ["84136.2", "0.06969182", "0", "1"], ["84136.3", "0", "0", "0"], ["84136.6", "0.06548399", "0", "1"], ["84136.7", "0", "0", "0"], ["84138.2", "0.06326419", "0", "1"], ["84138.3", "0.08991011", "0", "1"]], "bids": [["84111.3", "0.00001", "0", "1"], ["84100.5", "0.11896236", "0", "1"], ["84098.4", "0.03854779", "0", "1"], ["84092.9", "0.00001501", "0", "1"], ["84092.8", "0.03256938", "0", "1"], ["84092.7", "0.12093175", "0", "3"], ["84092.2", "1", "0", "1"], ["84092.1", "0.03112953", "0", "1"], ["84091.6", "0", "0", "0"], ["84091.5", "0.03398912", "0", "1"], ["84085.9", "0", "0", "0"], ["84085.8", "0.0347552", "0", "1"], ["84085.3", "0", "0", "0"], ["84085.2", "0.03107416", "0", "1"], ["84084", "0.11228184", "0", "2"], ["84083.9", "0.04955002", "0", "2"], ["84083.4", "0", "0", "0"], ["84083.3", "0.03379445", "0", "2"], ["84078.9", "0.01774536", "0", "1"], ["84078.8", "1.9386787", "0", "3"], ["84076.8", "0", "0", "0"], ["84076.7", "0.06656056", "0", "1"], ["84075.8", "0.23790287", "0", "1"], ["84075.7", "0.0649965", "0", "1"], ["84075.3", "0", "0", "0"], ["84075.2", "0.06362773", "0", "1"], ["84074.6", "0", "0", "0"], ["83959.8", "0", "0", "0"]], "ts": "1742554953204", "checksum": 1618639298, "seqId": 49927366841, "prevSeqId": 49927366768}], "record_time": 1742554953.217095, "EXCHANGE": "OKX"}
{"arg": {"channel": "books", "instId": "BTC-USDT"}, "action": "update", "data": [{"asks": [["84111.4", "0.8109986", "0", "15"], ["84118.7", "0", "0", "0"], ["84120.1", "0.00001197", "0", "1"], ["84120.2", "0.03234164", "0", "1"], ["84120.7", "0", "0", "0"], ["84120.8", "0.39034199", "0", "2"], ["84120.9", "0.03390815", "0", "1"], ["84121", "0.03419804", "0", "1"], ["84127.1", "0", "0", "0"], ["84127.2", "0.03237061", "0", "1"], ["84127.3", "0.03354705", "0", "1"], ["84129.4", "0", "0", "0"], ["84129.5", "0.03488114", "0", "1"], ["84129.6", "0.0316652", "0", "1"], ["84133.9", "0.01774536", "0", "1"], ["84134", "0", "0", "0"], ["84134.1", "0.23790258", "0", "1"], ["84134.2", "0.06140269", "0", "1"], ["84136.2", "0", "0", "0"], ["84136.3", "0.0662343", "0", "1"], ["84136.6", "0", "0", "0"], ["84136.7", "0.06415972", "0", "1"], ["84138.2", "0", "0", "0"], ["84138.3", "0.15153312", "0", "2"], ["84143.3", "0.9883207", "0", "2"]], "bids": [["84106", "0.0146", "0", "1"], ["84092.9", "0.03358615", "0", "2"], ["84092.8", "0.03183242", "0", "1"], ["84092.7", "0.087", "0", "2"], ["84092.2", "1.03275842", "0", "2"], ["84092.1", "0", "0", "0"], ["84091.6", "0.03411446", "0", "1"], ["84091.5", "0", "0", "0"], ["84085.9", "0.03337571", "0", "1"], ["84085.8", "0", "0", "0"], ["84085.3", "0.0311068", "0", "1"], ["84085.2", "0", "0", "0"], ["84084", "0.14331593", "0", "3"], ["84083.9", "0.01596287", "0", "1"], ["84083.4", "0.03358665", "0", "1"], ["84083.3", "0.00060645", "0", "1"], ["84078.9", "1.18216172", "0", "3"], ["84078.8", "1.86894369", "0", "2"], ["84076.8", "0.06413077", "0", "1"], ["84076.7", "0", "0", "0"], ["84075.8", "0.06277202", "0", "1"], ["84075.7", "0", "0", "0"], ["84075.4", "0.24330258", "0", "2"], ["84075.3", "0.06723281", "0", "1"], ["84075.2", "0", "0", "0"], ["84049.6", "1.89403495", "0", "2"]], "ts": "1742554953304", "checksum": -1892679587, "seqId": 49927366913, "prevSeqId": 49927366841}], "record_time": 1742554953.30455, "EXCHANGE": "OKX"}
{"arg": {"channel": "books", "instId": "BTC-USDT"}, "action": "update", "data": [{"asks": [["84120.8", "0.42137169", "0", "3"], ["84120.9", "0.03390436", "0", "1"], ["84121", "0", "0", "0"], ["84127.2", "0.06524505", "0", "2"], ["84127.3", "0", "0", "0"], ["84136.2", "0.06299836", "0", "1"], ["84136.3", "0", "0", "0"], ["84262.4", "0.0023991", "0", "2"], ["84262.9", "0.17821722", "0", "1"]], "bids": [["84103.1", "0", "0", "0"], ["84092.2", "1", "0", "1"], ["84092.1", "0.03125758", "0", "1"], ["84091.6", "0", "0", "0"], ["84091.5", "0.03231423", "0", "1"], ["84085.3", "0", "0", "0"], ["84085.2", "0.03143906", "0", "1"], ["84076.8", "0", "0", "0"], ["84076.7", "0.06280906", "0", "1"]], "ts": "1742554953404", "checksum": 438963777, "seqId": 49927366930, "prevSeqId": 49927366913}], "record_time": 1742554953.454497, "EXCHANGE": "OKX"}
{"arg": {"channel": "books", "instId": "BTC-USDT"}, "action": "update", "data": [{"asks": [["84111.4", "1.0109986", "0", "16"], ["84113.9", "0.03552126", "0", "1"], ["84116.8", "0", "0", "0"], ["84117.5", "0", "0", "0"], ["84128.8", "1", "0", "1"], ["84130", "0.0146", "0", "1"]], "bids": [["84052.4", "0.01188163", "0", "1"], ["84030.7", "0", "0", "0"]], "ts": "1742554953504", "checksum": -2015700069, "seqId": 49927366941, "prevSeqId": 49927366930}], "record_time": 1742554953.506969, "EXCHANGE": "OKX"}
{"arg": {"channel": "books", "instId": "BTC-USDT"}, "action": "update", "data": [{"asks": [["84113.9", "0.07584906", "0", "2"], ["84117.6", "0.41896805", "0", "1"], ["84119", "0.3916709", "0", "2"], ["84128.3", "0.24967", "0", "1"], ["84133.9", "0", "0", "0"], ["84134", "0.01774536", "0", "1"], ["84262.9", "0", "0", "0"]], "bids": [["84088.1", "0.43695353", "0", "1"], ["84087.2", "0", "0", "0"], ["84086.2", "0.41519253", "0", "2"], ["84044.2", "0.26771", "0", "2"]], "ts": "1742554953604", "checksum": 641280200, "seqId": 49927366953, "prevSeqId": 49927366941}], "record_time": 1742554953.604172, "EXCHANGE": "OKX"}
{"arg": {"channel": "books", "instId": "BTC-USDT"}, "action": "update", "data": [{"asks": [["84120.2", "0", "0", "0"], ["84120.3", "0.03159186", "0", "1"], ["84120.8", "0.35667", "0", "1"], ["84120.9", "0.06417548", "0", "2"], ["84121", "0.03192549", "0", "1"], ["84127.2", "0", "0", "0"], ["84127.3", "0.06902352", "0", "2"], ["84129.5", "0", "0", "0"], ["84129.6", "0.03334741", "0", "1"], ["84129.7", "0.03304036", "0", "1"], ["84134.2", "0", "0", "0"], ["84134.3", "1.96109539", "0", "3"], ["84136.2", "0", "0", "0"], ["84136.3", "0.06527133", "0", "1"], ["84136.7", "0", "0", "0"], ["84136.8", "0.15355744", "0", "2"], ["84138.3", "0.08991011", "0", "1"], ["84138.4", "0.06179127", "0", "1"]], "bids": [["84111.3", "0.00545", "0", "2"], ["84093", "0.07027026", "0", "2"], ["84092.9", "0.03501563", "0", "2"], ["84092.8", "0", "0", "0"], ["84092.2", "1.03531616", "0", "2"], ["84092.1", "0", "0", "0"], ["84091.6", "0.03473595", "0", "1"], ["84091.5", "0", "0", "0"], ["84086", "0.03381111", "0", "1"], ["84085.9", "0", "0", "0"], ["84085.3", "0.03353777", "0", "1"], ["84085.2", "0", "0", "0"], ["84084.1", "0.03468532", "0", "1"], ["84084", "0.11228184", "0", "2"], ["84083.5", "0.03242366", "0", "1"], ["84083.4", "0", "0", "0"], ["84079", "0.06221861", "0", "1"], ["84078.9", "1.11497328", "0", "2"], ["84076.8", "0.06778393", "0", "1"], ["84076.7", "0", "0", "0"], ["84075.9", "0.07079167", "0", "1"], ["84075.8", "0", "0", "0"], ["84075.4", "0.31340062", "0", "3"], ["84075.3", "0", "0", "0"], ["84068", "0", "0", "0"], ["84067.2", "0", "0", "0"], ["83959.8", "0.00421771", "0", "1"], ["83959.1", "0.00001009", "0", "1"], ["83958.8", "0.00005335", "0", "1"]], "ts": "1742554953704", "checksum": -1997769351, "seqId": 49927367011, "prevSeqId": 49927366953}], "record_time": 1742554953.710125, "EXCHANGE": "OKX"}
{"arg": {"channel": "books", "instId": "BTC-USDT"}, "action": "update", "data": [{"asks": [["84111.4", "0.8109986", "0", "15"], ["84134.1", "0", "0", "0"], ["84134.2", "0.23790465", "0", "1"]], "bids": [["84075.4", "0.07549804", "0", "2"], ["84073.6", "0.23790465", "0", "1"], ["84044.4", "0", "0", "0"]], "ts": "1742554953804", "checksum": 1740336900, "seqId": 49927367018, "prevSeqId": 49927367011}], "record_time": 1742554953.803598, "EXCHANGE": "OKX"}
{"arg": {"channel": "books", "instId": "BTC-USDT"}, "action": "update", "data": [{"asks": [["84113.9", "0.03552126", "0", "1"], ["84134", "0", "0", "0"], ["84134.1", "0.01774536", "0", "1"]], "bids": [["84071", "1.0264348", "0", "5"], ["84063", "0.21228184", "0", "3"], ["84035.1", "0.03569988", "0", "1"]], "ts": "1742554953904", "checksum": 1510318395, "seqId": 49927367024, "prevSeqId": 49927367018}], "record_time": 1742554953.904463, "EXCHANGE": "OKX"}
{"arg": {"channel": "books", "instId": "BTC-USDT"}, "action": "update", "data": [{"asks": [["84111.4", "0.8006045", "0", "14"], ["84119.6", "0.03166", "0", "1"], ["84124.4", "0.01055", "0", "1"], ["84131.8", "0.01040911", "0", "2"], ["84166.5", "0", "0", "0"]], "bids": [["84100.1", "0", "0", "0"], ["84098.3", "0.01339", "0", "1"], ["84098.1", "0.36641581", "0", "3"], ["84093.5", "0", "0", "0"], ["84092", "0.05189786", "0", "2"], ["84074.6", "0.23790311", "0", "1"], ["84073.6", "0", "0", "0"], ["84071", "0.0264348", "0", "4"], ["84063", "0.11228184", "0", "2"], ["84052.4", "0", "0", "0"], ["84008.2", "0", "0", "0"], ["84008.1", "0", "0", "0"], ["84005.6", "0.00579964", "0", "1"], ["83987.5", "0", "0", "0"], ["83982.6", "0.183121", "0", "1"], ["83958.3", "0.00006061", "0", "1"], ["83955.5", "0.01188151", "0", "1"], ["83955", "0.00620748", "0", "1"], ["83954.5", "0.17821722", "0", "1"], ["83954.4", "0.35579296", "0", "1"]], "ts": "1742554954004", "checksum": -754270666, "seqId": 49927367054, "prevSeqId": 49927367024}], "record_time": 1742554954.004849, "EXCHANGE": "OKX"}
{"arg": {"channel": "books", "instId": "BTC-USDT"}, "action": "update", "data": [{"asks": [["84110.1", "2.06138399", "0", "26"], ["84110.6", "0.03854779", "0", "1"], ["84110.9", "0.1", "0", "1"], ["84111.2", "0.3144214", "0", "2"], ["84111.3", "0.2", "0", "1"], ["84111.4", "0.73310944", "0", "5"], ["84113.7", "0.03426833", "0", "1"], ["84113.8", "0.04", "0", "1"], ["84113.9", "0", "0", "0"], ["84114.7", "0.03166", "0", "1"], ["84114.9", "0", "0", "0"], ["84116.5", "0", "0", "0"], ["84118.6", "0.03366876", "0", "1"], ["84119.5", "0.06441148", "0", "2"], ["84119.6", "0.03277853", "0", "1"], ["84120.3", "0", "0", "0"], ["84120.9", "0", "0", "0"], ["84121", "0", "0", "0"], ["84121.6", "0.21834", "0", "2"], ["84122.6", "0.09991011", "0", "3"], ["84122.7", "0.47420715", "0", "2"], ["84122.8", "0", "0", "0"], ["84124", "0.2525244", "0", "2"], ["84124.1", "1.01603713", "0", "2"], ["84124.4", "0.01475325", "0", "2"], ["84125", "0", "0", "0"], ["84125.6", "0.03310417", "0", "1"], ["84125.8", "0.39138596", "0", "2"], ["84126.5", "0.14198023", "0", "1"], ["84127.3", "0", "0", "0"], ["84128.3", "0.2838425", "0", "2"], ["84128.8", "0", "0", "0"], ["84129.6", "0", "0", "0"], ["84129.7", "0", "0", "0"], ["84129.8", "0", "0", "0"], ["84131.8", "0.00001501", "0", "1"], ["84132.6", "0.07385736", "0", "2"], ["84134.2", "0", "0", "0"], ["84134.3", "1.8990194", "0", "2"], ["84135", "0.06295546", "0", "2"], ["84135.2", "0.12800501", "0", "2"], ["84136.3", "0", "0", "0"], ["84136.8", "0.08609", "0", "1"], ["84138.4", "0", "0", "0"], ["84143.3", "0.27006173", "0", "1"], ["84143.7", "0", "0", "0"], ["84145", "0.20001197", "0", "2"], ["84145.3", "0.06076188", "0", "1"], ["84153.6", "0.01917563", "0", "1"], ["84156.3", "0.01608292", "0", "2"], ["84157.3", "0.02377716", "0", "2"], ["84157.4", "0.0118825", "0", "1"], ["84157.5", "0.12416433", "0", "3"], ["84158.1", "0.0118824", "0", "1"], ["84158.8", "0.02004759", "0", "1"], ["84162.9", "0", "0", "0"], ["84166.5", "0.00004312", "0", "1"], ["84170.5", "0", "0", "0"], ["84173.6", "0.11890903", "0", "1"], ["84173.8", "0.000015", "0", "1"], ["84175.7", "0.01124441", "0", "1"], ["84178.1", "0", "0", "0"], ["84189.7", "0", "0", "0"], ["84209.7", "0", "0", "0"], ["84216.4", "0", "0", "0"], ["84219", "0", "0", "0"], ["84219.1", "0", "0", "0"], ["84262.9", "0.17821722", "0", "1"], ["84263.9", "0.00003969", "0", "2"], ["84264", "0.00074396", "0", "1"], ["84264.2", "0.00001197", "0", "1"], ["84264.7", "0.2025", "0", "1"], ["84264.9", "0.00031778", "0", "3"], ["84265.1", "0.00418989", "0", "1"], ["84265.8", "0.00001156", "0", "1"], ["84266", "0.11878326", "0", "1"]], "bids": [["84111.3", "0", "0", "0"], ["84106", "0", "0", "0"], ["84105.7", "0", "0", "0"], ["84104.5", "0", "0", "0"], ["84102.1", "0", "0", "0"], ["84101.5", "0", "0", "0"], ["84101.3", "0", "0", "0"], ["84100.8", "0", "0", "0"], ["84100.5", "0", "0", "0"], ["84100", "0.00001", "0", "1"], ["84098.4", "0", "0", "0"], ["84097.5", "0", "0", "0"], ["84096.6", "0.15649617", "0", "1"], ["84096", "0", "0", "0"], ["84095", "0", "0", "0"], ["84093.6", "0.01189683", "0", "1"], ["84093.3", "0", "0", "0"], ["84093", "0.03713992", "0", "1"], ["84092.9", "0.00001501", "0", "1"], ["84092.7", "0", "0", "0"], ["84092.2", "0", "0", "0"], ["84092", "0.01189786", "0", "1"], ["84091.6", "0", "0", "0"], ["84091.5", "0.03244811", "0", "1"], ["84091.3", "0.03446465", "0", "1"], ["84090.9", "0.15426387", "0", "4"], ["84090.1", "0.55088251", "0", "2"], ["84089.9", "0", "0", "0"], ["84089.1", "0.04", "0", "1"], ["84088.5", "0", "0", "0"], ["84088.1", "0.42725414", "0", "2"], ["84088", "0", "0", "0"], ["84087.5", "0.00713542", "0", "1"], ["84087.2", "0.04", "0", "1"], ["84087.1", "0", "0", "0"], ["84086.3", "1", "0", "1"], ["84086.2", "0", "0", "0"], ["84086", "0", "0", "0"], ["84085.6", "0", "0", "0"], ["84085.3", "0", "0", "0"], ["84084.3", "0.03275251", "0", "1"], ["84084.1", "0", "0", "0"], ["84083.8", "0.04177772", "0", "1"], ["84083.5", "0", "0", "0"], ["84082.1", "0.03764323", "0", "2"], ["84079", "0", "0", "0"], ["84077.9", "0.0596212", "0", "1"], ["84077.6", "0", "0", "0"], ["84077.3", "0.06635482", "0", "1"], ["84076.8", "0", "0", "0"], ["84075.9", "0", "0", "0"], ["84075.5", "0.06627541", "0", "1"], ["84075.4", "0", "0", "0"], ["84074.6", "0", "0", "0"], ["84072.9", "0", "0", "0"], ["84072.1", "0.25935491", "0", "2"], ["84070.9", "0", "0", "0"], ["84070.7", "0", "0", "0"], ["84067.6", "0.2379244", "0", "1"], ["84065.8", "0.3109201", "0", "1"], ["84065.7", "0.00001197", "0", "1"], ["84063.6", "0", "0", "0"], ["84061.5", "0.1", "0", "1"], ["84059.9", "0", "0", "0"], ["84058.6", "0.0183185", "0", "1"], ["84057.6", "0", "0", "0"], ["84053.7", "0.0054", "0", "1"], ["84050.4", "0.01785561", "0", "1"], ["84045.1", "0.12488207", "0", "2"], ["84044.7", "0.5802515", "0", "1"], ["84036.9", "0.002356", "0", "1"], ["84035.1", "0", "0", "0"], ["84034.2", "0", "0", "0"], ["84031.5", "3.44946791", "0", "2"], ["84030.2", "0.0054", "0", "1"], ["84028.5", "0", "0", "0"], ["84027.6", "0.01901709", "0", "1"], ["84024.6", "0", "0", "0"], ["84021.8", "0", "0", "0"], ["84019.9", "0.60646061", "0", "1"], ["84013.4", "0", "0", "0"], ["84008.3", "0.03572487", "0", "2"], ["84002.7", "0.02377811", "0", "1"], ["83991.9", "0.00594389", "0", "1"], ["83986.7", "0.18318504", "0", "1"], ["83983.7", "0.00001501", "0", "1"], ["83980.3", "0", "0", "0"], ["83980.1", "0.00201185", "0", "1"], ["83971.3", "0.0054", "0", "1"], ["83955.9", "0.00001197", "0", "1"], ["83955.5", "0", "0", "0"], ["83952.9", "0.08991011", "0", "1"], ["83952.7", "0.00001065", "0", "1"], ["83952.3", "0.2025", "0", "1"], ["83950", "0.00013403", "0", "2"], ["83949.9", "0.00482516", "0", "2"], ["83947.3", "0.00103791", "0", "1"], ["83946.7", "0.00002763", "0", "2"], ["83946.1", "0.17821722", "0", "1"], ["83946", "0.35579296", "0", "1"], ["83945.8", "3.17354", "0", "1"], ["83945.4", "0.11890903", "0", "1"], ["83945.1", "0.002378", "0", "1"], ["83944.8", "0.00011161", "0", "1"], ["83944.6", "0.00421935", "0", "1"], ["83943.8", "0.2025", "0", "1"], ["83943.5", "0.03", "0", "1"], ["83943.1", "0.01775819", "0", "1"], ["83942.5", "6.49843346", "0", "1"], ["83942", "0.00007352", "0", "1"], ["83941.1", "0.00001807", "0", "1"], ["83940.4", "0.00002279", "0", "1"], ["83939.8", "2.4621163", "0", "2"]], "ts": "1742554954104", "checksum": 113291041, "seqId": 49927367445, "prevSeqId": 49927367054}], "record_time": 1742554954.104905, "EXCHANGE": "OKX"}
{"arg": {"channel": "books", "instId": "BTC-USDT"}, "action": "update", "data": [{"asks": [["84098.3", "1.17805685", "0", "12"], ["84100", "0.01464", "0", "2"], ["84102.6", "0.0103941", "0", "1"], ["84102.8", "0.06513", "0", "1"], ["84102.9", "0.2025", "0", "1"], ["84103.2", "0.00111895", "0", "1"], ["84104", "0.0146", "0", "1"], ["84105.6", "0.17274256", "0", "1"], ["84105.7", "0.03854779", "0", "1"], ["84105.8", "0.35964043", "0", "1"], ["84106", "0.0146", "0", "1"], ["84108.2", "0.05203713", "0", "2"], ["84109.4", "0.32667515", "0", "1"], ["84110", "0.0146", "0", "1"], ["84110.1", "0.27716578", "0", "6"], ["84110.3", "0.03272025", "0", "1"], ["84110.4", "0.01189526", "0", "1"], ["84110.6", "0", "0", "0"], ["84110.9", "0", "0", "0"], ["84111.1", "0.03096865", "0", "1"], ["84111.2", "0.09751887", "0", "3"], ["84111.3", "0", "0", "0"], ["84111.4", "0.61417756", "0", "4"], ["84111.9", "0", "0", "0"], ["84112.5", "0.00006", "0", "1"], ["84113.1", "0.01055", "0", "1"], ["84115", "0.00001501", "0", "1"], ["84116.3", "0", "0", "0"], ["84116.6", "0.00060645", "0", "1"], ["84116.8", "0.04", "0", "1"], ["84117.3", "0.03169731", "0", "1"], ["84117.5", "0.03419248", "0", "1"], ["84118.6", "0", "0", "0"], ["84119", "0.35667", "0", "1"], ["84119.1", "0.11893621", "0", "1"], ["84119.5", "0", "0", "0"], ["84119.6", "0", "0", "0"], ["84119.9", "0.23312921", "0", "2"], ["84120", "0.16529936", "0", "4"], ["84120.4", "0", "0", "0"], ["84121.1", "0.03", "0", "1"], ["84121.5", "0.00011161", "0", "1"], ["84121.6", "0.17834", "0", "1"], ["84122", "0", "0", "0"], ["84122.2", "0.65872272", "0", "1"], ["84122.3", "1", "0", "1"], ["84122.7", "0", "0", "0"], ["84124", "0", "0", "0"], ["84124.1", "0.15638943", "0", "2"], ["84124.3", "0.06373818", "0", "1"], ["84124.4", "0.00420325", "0", "1"], ["84125.6", "0", "0", "0"], ["84125.7", "0.23792528", "0", "1"], ["84125.8", "0.38020116", "0", "2"], ["84125.9", "0.11228184", "0", "2"], ["84126", "0", "0", "0"], ["84126.6", "0.068934", "0", "1"], ["84126.9", "0.06928608", "0", "1"], ["84128", "0", "0", "0"], ["84128.3", "0.24967", "0", "1"], ["84130", "0", "0", "0"], ["84130.6", "0", "0", "0"], ["84132", "0", "0", "0"], ["84132.4", "0.00357", "0", "1"], ["84132.6", "0.00420263", "0", "1"], ["84134.1", "0", "0", "0"], ["84134.4", "0.17821722", "0", "1"], ["84135", "0.00001197", "0", "1"], ["84135.2", "0.05940838", "0", "1"], ["84136.4", "0.22267101", "0", "2"], ["84137", "0.48999", "0", "1"], ["84138.8", "0.1696567", "0", "2"], ["84143.3", "0.40584486", "0", "2"], ["84145.6", "0.07999999", "0", "2"], ["84146", "0.25755", "0", "1"], ["84146.4", "0.03999999", "0", "1"], ["84147.2", "0.01603713", "0", "1"], ["84147.9", "0.40664892", "0", "1"], ["84150.9", "0", "0", "0"], ["84151", "0", "0", "0"], ["84152.1", "0.55918738", "0", "1"], ["84152.2", "0.52892", "0", "1"], ["84152.8", "0", "0", "0"], ["84153", "0", "0", "0"], ["84154.4", "0.01188292", "0", "1"], ["84154.7", "0.1", "0", "1"], ["84155.5", "0.01657538", "0", "1"], ["84155.7", "0", "0", "0"], ["84156", "0", "0", "0"], ["84156.3", "0.00420026", "0", "1"], ["84157.3", "0.01189464", "0", "1"], ["84157.4", "0", "0", "0"], ["84157.5", "0.11228184", "0", "2"], ["84158.1", "0", "0", "0"], ["84160", "0.00004", "0", "1"], ["84160.2", "1.08611104", "0", "2"], ["84164.1", "0", "0", "0"], ["84166.6", "0.05563525", "0", "4"], ["84168.4", "0.2362684", "0", "1"], ["84169.1", "0", "0", "0"], ["84169.4", "0", "0", "0"], ["84169.8", "0.01125715", "0", "2"], ["84170.4", "0", "0", "0"], ["84175.7", "0", "0", "0"], ["84176.9", "0", "0", "0"], ["84178.5", "0", "0", "0"], ["84179", "0.20383878", "0", "2"], ["84179.7", "0.47217196", "0", "2"], ["84181", "0.08749", "0", "1"], ["84184.1", "0.00012217", "0", "1"], ["84191.6", "0", "0", "0"], ["84192.4", "0", "0", "0"], ["84192.8", "0.01316", "0", "1"], ["84193.2", "0.05013489", "0", "1"], ["84193.9", "0.07125036", "0", "1"], ["84196.4", "0", "0", "0"], ["84199.1", "0.01774536", "0", "1"], ["84211.9", "0", "0", "0"], ["84227.3", "0", "0", "0"], ["84238.3", "0.01188328", "0", "1"], ["84242.1", "0.09338483", "0", "2"], ["84242.8", "0.01188325", "0", "1"], ["84247.3", "0.10179333", "0", "2"], ["84251.6", "0.0160747", "0", "2"], ["84252.5", "0.00001145", "0", "1"], ["84253.8", "0.01188318", "0", "1"], ["84254.1", "0", "0", "0"], ["84259.6", "0.01783377", "0", "3"], ["84261.1", "0", "0", "0"], ["84262.2", "0", "0", "0"], ["84262.4", "0", "0", "0"], ["84262.9", "0", "0", "0"], ["84263.9", "0", "0", "0"], ["84264", "0", "0", "0"], ["84264.2", "0", "0", "0"], ["84264.7", "0", "0", "0"], ["84264.9", "0", "0", "0"], ["84265.1", "0", "0", "0"], ["84265.8", "0", "0", "0"], ["84266", "0", "0", "0"]], "bids": [["84110", "0", "0", "0"], ["84109.4", "0", "0", "0"], ["84108.2", "0", "0", "0"], ["84105.3", "0", "0", "0"], ["84103.2", "0", "0", "0"], ["84102", "0", "0", "0"], ["84101.9", "0", "0", "0"], ["84100.4", "0", "0", "0"], ["84100", "0", "0", "0"], ["84099.9", "0", "0", "0"], ["84099.8", "0", "0", "0"], ["84099.3", "0", "0", "0"], ["84098.3", "0", "0", "0"], ["84098.2", "0.12285318", "0", "2"], ["84098.1", "0.01", "0", "2"], ["84098", "0.0146", "0", "1"], ["84096.7", "0", "0", "0"], ["84096.6", "0", "0", "0"], ["84096.4", "0", "0", "0"], ["84096", "0.0146", "0", "1"], ["84095.7", "0", "0", "0"], ["84094.5", "0.11284772", "0", "3"], ["84094.3", "0", "0", "0"], ["84094", "0.0146", "0", "1"], ["84093.6", "0", "0", "0"], ["84093", "0", "0", "0"], ["84092.4", "0.19137661", "0", "2"], ["84092", "0", "0", "0"], ["84091.9", "0", "0", "0"], ["84091.8", "0", "0", "0"], ["84091.5", "0", "0", "0"], ["84091.3", "0", "0", "0"], ["84090.9", "0.02846459", "0", "1"], ["84090.1", "0", "0", "0"], ["84089.6", "0.01339", "0", "1"], ["84089.1", "0", "0", "0"], ["84088.7", "0.57318082", "0", "3"], ["84088.1", "0.121147", "0", "1"], ["84087.8", "0.03713992", "0", "1"], ["84087.5", "0", "0", "0"], ["84086.5", "0.042", "0", "1"], ["84086.4", "0.055", "0", "2"], ["84086.3", "0", "0", "0"], ["84084.4", "0.049", "0", "2"], ["84084.3", "0", "0", "0"], ["84084", "0.45208167", "0", "4"], ["84083.8", "0", "0", "0"], ["84083.7", "0", "0", "0"], ["84083.3", "0.01250554", "0", "2"], ["84083.1", "0.04912623", "0", "2"], ["84083", "0.03362981", "0", "1"], ["84082.5", "0.03277188", "0", "1"], ["84082.1", "0", "0", "0"], ["84081.9", "1", "0", "1"], ["84081.8", "0.03535851", "0", "1"], ["84080.2", "0.00475736", "0", "1"], ["84079.7", "0.1403523", "0", "1"], ["84079.5", "0.47986", "0", "1"], ["84078.3", "0", "0", "0"], ["84077.3", "0", "0", "0"], ["84076.1", "0.1871514", "0", "2"], ["84076", "0.28837866", "0", "4"], ["84075.7", "0.00713643", "0", "1"], ["84075.5", "0.03523967", "0", "1"], ["84074.5", "0.31306587", "0", "3"], ["84074.4", "0.03298098", "0", "1"], ["84073.8", "0.03316803", "0", "1"], ["84072.5", "0.51699", "0", "1"], ["84072.4", "0", "0", "0"], ["84072", "0.0025", "0", "1"], ["84071.6", "0.05940838", "0", "1"], ["84071.2", "0.35787758", "0", "1"], ["84071.1", "0", "0", "0"], ["84070.4", "0", "0", "0"], ["84069", "0.06535327", "0", "1"], ["84067.9", "0.23792528", "0", "1"], ["84067.6", "0", "0", "0"], ["84067.1", "0.06652686", "0", "1"], ["84066.3", "0.31949482", "0", "1"], ["84065.8", "0", "0", "0"], ["84064.8", "0.0103941", "0", "1"], ["84064", "0.08", "0", "2"], ["84063.2", "0.066", "0", "3"], ["84062.8", "0.25729118", "0", "1"], ["84062.7", "0.20908", "0", "1"], ["84062.6", "0.00011161", "0", "1"], ["84062.4", "0.013", "0", "1"], ["84061.5", "0", "0", "0"], ["84060.2", "0.12204823", "0", "3"], ["84058.6", "0.21065081", "0", "1"], ["84057.9", "0.01188156", "0", "1"], ["84056.3", "0", "0", "0"], ["84053.3", "0.4305908", "0", "3"], ["84051.5", "0.02817312", "0", "1"], ["84049.5", "0.11670264", "0", "2"], ["84048.9", "0", "0", "0"], ["84048.2", "0.01188308", "0", "1"], ["84048", "0.01188288", "0", "1"], ["84047.9", "0.01188345", "0", "1"], ["84045.8", "0.85388149", "0", "4"], ["84045.7", "0", "0", "0"], ["84045.2", "0", "0", "0"], ["84044.4", "0.59964265", "0", "1"], ["84040.6", "0.00285191", "0", "1"], ["84040", "0.00001", "0", "1"], ["84037.9", "0", "0", "0"], ["84037.2", "0", "0", "0"], ["84037", "0.00105164", "0", "1"], ["84032.6", "1.01227696", "0", "2"], ["84032.3", "0", "0", "0"], ["84029.1", "0.98397", "0", "1"], ["84026.5", "0.0356492", "0", "3"], ["84021.8", "0.02531027", "0", "2"], ["84019.9", "0", "0", "0"], ["84019.8", "0", "0", "0"], ["84019.2", "0.04756313", "0", "1"], ["84014.3", "0", "0", "0"], ["84014", "0.07963908", "0", "1"], ["84009", "0.03600024", "0", "2"], ["84008", "0", "0", "0"], ["84007.7", "0", "0", "0"], ["84002.4", "0.59432247", "0", "1"], ["84001.6", "0", "0", "0"], ["83995.4", "1.48377", "0", "1"], ["83991.9", "0", "0", "0"], ["83990.6", "0", "0", "0"], ["83986.7", "0", "0", "0"], ["83981.4", "0.18321755", "0", "2"], ["83981.3", "0.00594483", "0", "1"], ["83981.1", "0.07102314", "0", "1"], ["83980.6", "0.07126232", "0", "2"], ["83976.4", "0", "0", "0"], ["83972.1", "0.00001", "0", "1"], ["83964.5", "0.01783377", "0", "3"], ["83956.6", "0.00001197", "0", "1"], ["83939.7", "0.03", "0", "1"], ["83939.5", "0.00007329", "0", "1"], ["83938.4", "0.00001883", "0", "1"], ["83938.2", "0.6000735", "0", "2"], ["83937", "0.07148216", "0", "1"], ["83936.8", "0.00001197", "0", "1"], ["83936.1", "0.0000442", "0", "1"], ["83935.6", "0.00001925", "0", "1"], ["83935.3", "0.2025", "0", "1"], ["83934.9", "0.17821722", "0", "1"]], "ts": "1742554954204", "checksum": 485309902, "seqId": 49927368474, "prevSeqId": 49927367445}], "record_time": 1742554954.221472, "EXCHANGE": "OKX"}
{"arg": {"channel": "books", "instId": "BTC-USDT"}, "action": "update", "data": [{"asks": [["84098.2", "0.95519228", "0", "14"], ["84098.3", "0.11896555", "0", "1"], ["84100.9", "0.03854779", "0", "1"], ["84102.6", "0", "0", "0"], ["84103", "0.03166", "0", "1"], ["84105.7", "0", "0", "0"], ["84106.6", "0.00001501", "0", "1"], ["84107.8", "0.03820806", "0", "2"], ["84108.5", "0.06570987", "0", "2"], ["84108.6", "0.03257404", "0", "1"], ["84109.3", "0.11890903", "0", "1"], ["84110.1", "0.26661578", "0", "5"], ["84110.3", "0", "0", "0"], ["84111.1", "0", "0", "0"], ["84111.2", "0.0297729", "0", "1"], ["84111.5", "0.35673", "0", "1"], ["84111.8", "0.04", "0", "1"], ["84113.6", "0.03", "0", "1"], ["84113.7", "0.25869987", "0", "1"], ["84114.7", "0", "0", "0"], ["84114.8", "0.06582933", "0", "2"], ["84115.4", "0.05614092", "0", "1"], ["84116.6", "0.17882367", "0", "2"], ["84116.8", "0", "0", "0"], ["84116.9", "0", "0", "0"], ["84117", "0.06", "0", "2"], ["84117.2", "0.35641581", "0", "1"], ["84117.3", "0.06534498", "0", "2"], ["84117.4", "0.00420403", "0", "1"], ["84117.5", "0", "0", "0"], ["84117.6", "0.54051243", "0", "2"], ["84117.7", "0.03", "0", "1"], ["84118.7", "1", "0", "1"], ["84119", "0", "0", "0"], ["84119.9", "0.2025", "0", "1"], ["84120", "0.13354903", "0", "3"], ["84120.7", "0.0054", "0", "1"], ["84120.8", "0", "0", "0"], ["84121", "0.23793562", "0", "1"], ["84121.6", "0", "0", "0"], ["84121.8", "0.07098181", "0", "2"], ["84122.2", "0.37467917", "0", "1"], ["84122.3", "0", "0", "0"], ["84124", "0.06385435", "0", "1"], ["84124.3", "0.07014624", "0", "1"], ["84125.7", "0", "0", "0"], ["84126", "0.06908886", "0", "1"], ["84126.6", "0", "0", "0"], ["84126.9", "0", "0", "0"], ["84128.2", "0.03", "0", "1"], ["84130.3", "0.30604543", "0", "2"], ["84131.8", "0.00125145", "0", "2"], ["84132.4", "0.00897", "0", "2"], ["84132.7", "0.01", "0", "2"], ["84133.8", "0.059905", "0", "1"], ["84136.8", "0", "0", "0"], ["84140.8", "0.11846252", "0", "1"], ["84144.4", "0", "0", "0"], ["84145", "0.00001197", "0", "1"], ["84146.5", "0.01188404", "0", "1"], ["84147.5", "0.0118839", "0", "1"], ["84148", "1.01188383", "0", "2"], ["84148.2", "0.0118838", "0", "1"], ["84148.3", "0.01188379", "0", "1"], ["84148.8", "0", "0", "0"], ["84154.7", "0", "0", "0"], ["84159.6", "0.0118837", "0", "1"], ["84161.9", "0.916983", "0", "1"], ["84162.8", "0.17821722", "0", "1"], ["84163.3", "0", "0", "0"], ["84166.5", "0.01128831", "0", "2"], ["84168", "0.05614092", "0", "1"], ["84169.8", "0.00001196", "0", "1"], ["84170", "0.089818", "0", "1"], ["84172.1", "0.1425652", "0", "2"], ["84178.9", "0.00012217", "0", "1"], ["84180.5", "0.17940514", "0", "2"], ["84183.5", "0.02378201", "0", "1"], ["84184.1", "0", "0", "0"], ["84185", "0.08697303", "0", "1"], ["84185.9", "0", "0", "0"], ["84186.7", "0.02378201", "0", "1"], ["84197.6", "0", "0", "0"], ["84203.9", "0", "0", "0"], ["84209.8", "0", "0", "0"], ["84222.1", "0", "0", "0"], ["84222.2", "0.2025", "0", "1"], ["84233.5", "0.01190661", "0", "2"], ["84238.3", "0", "0", "0"], ["84242.8", "0", "0", "0"], ["84247.3", "0.08991011", "0", "1"], ["84248.3", "0.03", "0", "1"], ["84251.6", "0.00419151", "0", "1"], ["84253.8", "0", "0", "0"], ["84259.4", "0.0852", "0", "6"], ["84259.6", "0", "0", "0"], ["84259.7", "0", "0", "0"], ["84259.9", "0", "0", "0"], ["84260", "0", "0", "0"], ["84260.2", "0", "0", "0"], ["84260.6", "0", "0", "0"], ["84260.8", "0", "0", "0"]], "bids": [["84098.2", "0", "0", "0"], ["84098.1", "0.0469", "0", "3"], ["84098", "0", "0", "0"], ["84094.5", "0.00056588", "0", "1"], ["84092.4", "0.01596287", "0", "1"], ["84091.5", "0.133769", "0", "1"], ["84090.9", "0", "0", "0"], ["84089.6", "0", "0", "0"], ["84088.8", "0.17195425", "0", "1"], ["84088.7", "0.53463303", "0", "2"], ["84087.8", "0", "0", "0"], ["84087.2", "0", "0", "0"], ["84087.1", "0.102", "0", "2"], ["84086.4", "0.01", "0", "1"], ["84084.4", "0", "0", "0"], ["84084.1", "0.03854779", "0", "1"], ["84084", "0.21796505", "0", "3"], ["84083.7", "0.02848409", "0", "2"], ["84083.5", "0.08", "0", "2"], ["84083.1", "0.01596287", "0", "1"], ["84083", "0", "0", "0"], ["84082.5", "0", "0", "0"], ["84082.2", "0.03713992", "0", "1"], ["84081.9", "0", "0", "0"], ["84081.8", "0", "0", "0"], ["84081", "0.093", "0", "2"], ["84080.5", "0.06300666", "0", "3"], ["84080.2", "0", "0", "0"], ["84079.9", "0.03474146", "0", "1"], ["84079.1", "1.0352693", "0", "2"], ["84078.7", "0.35673", "0", "1"], ["84076", "0.25446287", "0", "3"], ["84075.7", "0", "0", "0"], ["84075.5", "0", "0", "0"], ["84075.2", "0.00475765", "0", "1"], ["84074.4", "0", "0", "0"], ["84073.8", "0", "0", "0"], ["84073.5", "0.14329018", "0", "3"], ["84072.8", "0.03418424", "0", "1"], ["84071.8", "0.03363245", "0", "1"], ["84071.1", "0.03135923", "0", "1"], ["84071", "0.00501", "0", "3"], ["84069.8", "0.11900587", "0", "1"], ["84069", "0", "0", "0"], ["84067.9", "0", "0", "0"], ["84067.1", "0", "0", "0"], ["84064.5", "0.06766951", "0", "1"], ["84064", "0", "0", "0"], ["84063.5", "0.23793562", "0", "1"], ["84063.4", "0.06540706", "0", "1"], ["84063.2", "0", "0", "0"], ["84063", "0.17955944", "0", "3"], ["84062.4", "0", "0", "0"], ["84060.2", "0.02204823", "0", "2"], ["84060", "0.11157886", "0", "6"], ["84059.2", "0.053", "0", "2"], ["84057.9", "0", "0", "0"], ["84057.1", "0.0214248", "0", "1"], ["84053.3", "0.18669947", "0", "1"], ["84053", "0", "0", "0"], ["84052.5", "0.05614092", "0", "1"], ["84050.1", "0.01832079", "0", "1"], ["84048.8", "0", "0", "0"], ["84048.2", "0", "0", "0"], ["84048", "0", "0", "0"], ["84047.9", "0", "0", "0"], ["84045.3", "0.918255", "0", "1"], ["84045", "0", "0", "0"], ["84040.6", "0", "0", "0"], ["84040.5", "0", "0", "0"], ["84040.2", "0.01188301", "0", "1"], ["84037.6", "0", "0", "0"], ["84037", "0", "0", "0"], ["84035.4", "0.00285194", "0", "1"], ["84031.9", "0.00105167", "0", "1"], ["84029.6", "0", "0", "0"], ["84029.2", "0.3704331", "0", "1"], ["84028.6", "0", "0", "0"], ["84026.8", "0", "0", "0"], ["84026.5", "0", "0", "0"], ["84022.8", "0", "0", "0"], ["84021.8", "0.10904325", "0", "3"], ["84021.5", "0.11898097", "0", "2"], ["84020.8", "0", "0", "0"], ["84018.8", "0", "0", "0"], ["84017.3", "0.00001501", "0", "1"], ["84017", "0", "0", "0"], ["84016.6", "0.00060645", "0", "1"], ["84014.5", "0", "0", "0"], ["84013.3", "0", "0", "0"], ["84013.2", "0", "0", "0"], ["84013.1", "0", "0", "0"], ["84013", "0", "0", "0"], ["84012.8", "0", "0", "0"], ["84012.3", "0.02378148", "0", "1"], ["84011.9", "0.08373298", "0", "1"], ["84011.8", "0.2025", "0", "1"], ["84011.4", "0.00298666", "0", "1"], ["84011.3", "0", "0", "0"], ["84010.4", "1.377953", "0", "1"], ["84010.1", "0", "0", "0"], ["84009.1", "0", "0", "0"], ["84009", "0.03", "0", "1"], ["84008.9", "0.000015", "0", "1"], ["84008.7", "0.059994", "0", "1"], ["84007", "0.14284508", "0", "2"], ["84005.9", "0", "0", "0"], ["84005.8", "0", "0", "0"], ["84005.6", "0", "0", "0"], ["84003.7", "0.26823894", "0", "3"], ["84002.5", "0.01149496", "0", "1"], ["83994.5", "0.0273997", "0", "2"], ["83994.4", "0.0059999", "0", "1"], ["83994.3", "0.25101722", "0", "4"], ["83994.2", "0.0214", "0", "1"], ["83994", "0.0214", "0", "1"], ["83991.4", "0.01159951", "0", "2"], ["83986.2", "0", "0", "0"], ["83986.1", "0.2094027", "0", "1"], ["83981.4", "0.00001197", "0", "1"], ["83980.1", "0", "0", "0"], ["83978.3", "0.18320795", "0", "1"], ["83972.5", "0.090029", "0", "1"], ["83971.5", "0.00202575", "0", "2"], ["83969.2", "0.0142", "0", "1"], ["83969.1", "0.071", "0", "5"], ["83934.7", "0.03", "0", "1"], ["83934.2", "0.35579296", "0", "1"], ["83934.1", "0.00422012", "0", "1"], ["83933.8", "0.00011948", "0", "1"], ["83933.3", "0.00525171", "0", "7"], ["83932.9", "0.00001845", "0", "1"], ["83932.8", "0.014", "0", "1"], ["83930.7", "0.00001807", "0", "1"], ["83930.5", "0.00001316", "0", "1"], ["83930.2", "0.00606454", "0", "2"], ["83930", "0.01188328", "0", "1"], ["83929.9", "0.00007149", "0", "1"], ["83928.5", "0.14848165", "0", "4"], ["83927.9", "0.00199404", "0", "5"]], "ts": "1742554954304", "checksum": 720328356, "seqId": 49927369068, "prevSeqId": 49927368474}], "record_time": 1742554954.307995, "EXCHANGE": "OKX"}
{"arg": {"channel": "books", "instId": "BTC-USDT"}, "action": "update", "data": [{"asks": [["84105.4", "0.11895551", "0", "1"], ["84107.8", "0.04030539", "0", "2"], ["84108.5", "0.03275835", "0", "1"], ["84108.6", "0.06623708", "0", "2"], ["84111.5", "0.53509", "0", "2"], ["84114.8", "0.03350304", "0", "1"], ["84114.9", "0.03240257", "0", "1"], ["84117", "0.09", "0", "3"], ["84117.3", "0.03177496", "0", "1"], ["84117.4", "0.0364343", "0", "2"], ["84121", "0", "0", "0"], ["84121.8", "0.06690323", "0", "2"], ["84123.9", "0.23793028", "0", "1"], ["84124", "0.062251", "0", "1"], ["84124.3", "0.06678303", "0", "1"], ["84126", "0.06590828", "0", "1"], ["84128.2", "0", "0", "0"], ["84128.6", "0.06", "0", "2"], ["84130.1", "0.01775733", "0", "2"], ["84152.1", "0.5592305", "0", "2"], ["84161.8", "0.01124545", "0", "1"], ["84166.5", "0", "0", "0"], ["84199.1", "0", "0", "0"]], "bids": [["84098.1", "0.01", "0", "2"], ["84091.6", "0.2", "0", "1"], ["84088.1", "0.17723927", "0", "2"], ["84087.1", "0", "0", "0"], ["84086.5", "0", "0", "0"], ["84085.6", "0.11898341", "0", "1"], ["84084.2", "0.01339", "0", "1"], ["84084", "0.26658172", "0", "4"], ["84083.4", "0.01339", "0", "1"], ["84081.2", "0.17836", "0", "1"], ["84081", "0.138", "0", "3"], ["84080.5", "0.06525751", "0", "3"], ["84079.9", "0.03100478", "0", "1"], ["84079.2", "0.03461731", "0", "1"], ["84079.1", "0", "0", "0"], ["84079", "1", "0", "1"], ["84077.1", "0.04019", "0", "1"], ["84073.5", "0.14523933", "0", "3"], ["84072.9", "0.03277948", "0", "1"], ["84072.8", "0", "0", "0"], ["84071.8", "0.03248147", "0", "1"], ["84071.2", "0.39168353", "0", "2"], ["84071.1", "0", "0", "0"], ["84070", "0.18336", "0", "3"], ["84066.5", "0.0655798", "0", "1"], ["84066.4", "0.23793028", "0", "1"], ["84064.5", "0.06851164", "0", "1"], ["84063.5", "0", "0", "0"], ["84063.4", "0.06374649", "0", "1"], ["84063", "0.17983394", "0", "3"], ["84060.1", "0", "0", "0"], ["84056.4", "0", "0", "0"], ["84052.5", "0.11228184", "0", "2"], ["84050.1", "0.00100367", "0", "1"], ["84048.3", "3.30044", "0", "2"], ["84046.4", "0.00099874", "0", "1"], ["84045.2", "0.01832066", "0", "1"], ["84021.8", "0.10888055", "0", "2"], ["84021.5", "0.11890903", "0", "1"], ["84010.8", "0", "0", "0"], ["84008.4", "0.00017772", "0", "2"], ["84005.4", "0.00007196", "0", "1"], ["83994.7", "0.00651984", "0", "2"], ["83978.3", "0", "0", "0"], ["83973.6", "0.18320661", "0", "1"], ["83971.3", "0.00899002", "0", "2"], ["83930.2", "0", "0", "0"], ["83930", "0", "0", "0"], ["83929.9", "0", "0", "0"], ["83928.5", "0", "0", "0"], ["83927.9", "0", "0", "0"]], "ts": "1742554954404", "checksum": 1885225345, "seqId": 49927369262, "prevSeqId": 49927369068}], "record_time": 1742554954.426456, "EXCHANGE": "OKX"}
{"arg": {"channel": "books", "instId": "BTC-USDT"}, "action": "update", "data": [{"asks": [["84105.6", "0.12788777", "0", "1"], ["84107.6", "0.03195363", "0", "1"], ["84107.8", "0", "0", "0"], ["84108.3", "0.03236826", "0", "1"], ["84108.4", "0.06524848", "0", "2"], ["84108.5", "0", "0", "0"], ["84108.6", "0", "0", "0"], ["84113.7", "0.49410235", "0", "2"], ["84114.6", "0.03125939", "0", "1"], ["84114.7", "0.03326082", "0", "1"], ["84114.8", "0", "0", "0"], ["84114.9", "0", "0", "0"], ["84117.1", "1.03332677", "0", "2"], ["84117.2", "0.38816466", "0", "2"], ["84117.3", "0", "0", "0"], ["84117.4", "0.00420403", "0", "1"], ["84117.6", "0.19329202", "0", "1"], ["84118.7", "0", "0", "0"], ["84121", "0.23793458", "0", "1"], ["84121.6", "0.06453539", "0", "1"], ["84121.8", "0.002", "0", "1"], ["84123.8", "0.07017656", "0", "1"], ["84123.9", "0", "0", "0"], ["84124", "0", "0", "0"], ["84124.2", "0.066926", "0", "1"], ["84124.3", "0", "0", "0"], ["84125", "0.133769", "0", "1"], ["84125.8", "0.44418347", "0", "3"], ["84126", "0", "0", "0"], ["84128.6", "0", "0", "0"], ["84141.7", "0", "0", "0"], ["84142.8", "0.1", "0", "1"], ["84259.5", "0.0142", "0", "1"]], "bids": [["84096", "0", "0", "0"], ["84091.6", "0", "0", "0"], ["84088.1", "0.18465116", "0", "1"], ["84085.6", "0", "0", "0"], ["84084.1", "0.04854779", "0", "2"], ["84084", "0.32942012", "0", "3"], ["84082.3", "0.10211161", "0", "3"], ["84080.5", "0.00001197", "0", "1"], ["84080.3", "0.06582113", "0", "2"], ["84079.9", "0", "0", "0"], ["84079.7", "0.17192766", "0", "2"], ["84079.2", "0", "0", "0"], ["84079", "0.0310804", "0", "1"], ["84077.9", "0", "0", "0"], ["84077.3", "1", "0", "1"], ["84073.5", "0.11228184", "0", "2"], ["84073.3", "0.03062193", "0", "1"], ["84072.9", "0", "0", "0"], ["84072.7", "0.03314699", "0", "1"], ["84071.8", "0", "0", "0"], ["84071.6", "0.09004935", "0", "2"], ["84071.2", "0.35787758", "0", "1"], ["84071", "0.03855919", "0", "4"], ["84066.5", "0", "0", "0"], ["84066.4", "0", "0", "0"], ["84066.3", "0.38759756", "0", "2"], ["84064.5", "0", "0", "0"], ["84064.3", "0.0698764", "0", "1"], ["84063.4", "0", "0", "0"], ["84063.2", "0.23793458", "0", "1"], ["84063", "0.11228184", "0", "2"], ["83966.1", "0.03", "0", "1"], ["83930.2", "0.00606454", "0", "2"], ["83930", "0.01188328", "0", "1"], ["83929.9", "0.00007149", "0", "1"], ["83928.5", "0.14848165", "0", "4"], ["83927.9", "0.00199404", "0", "5"]], "ts": "1742554954504", "checksum": -450727889, "seqId": 49927369403, "prevSeqId": 49927369262}], "record_time": 1742554954.505062, "EXCHANGE": "OKX"}
{"arg": {"channel": "books", "instId": "BTC-USDT"}, "action": "update", "data": [{"asks": [["84098.2", "0.89951727", "0", "13"], ["84103.8", "0.00772906", "0", "1"], ["84107.5", "0.00564", "0", "1"], ["84107.6", "0", "0", "0"], ["84107.7", "0.0322667", "0", "1"], ["84108.3", "0", "0", "0"], ["84108.4", "0.03338163", "0", "1"], ["84108.5", "0.06603889", "0", "2"], ["84110.2", "0.00001197", "0", "1"], ["84113.1", "0.01827906", "0", "2"], ["84114.6", "0", "0", "0"], ["84114.7", "0.03092332", "0", "1"], ["84114.8", "0.03213769", "0", "1"], ["84116.1", "0.03", "0", "1"], ["84121.6", "0", "0", "0"], ["84121.7", "0.06396893", "0", "1"], ["84123.8", "0", "0", "0"], ["84123.9", "0.06410371", "0", "1"], ["84125.8", "0.38020116", "0", "2"], ["84125.9", "0.17404299", "0", "3"], ["84145.3", "0", "0", "0"], ["84259.2", "0", "0", "0"], ["84259.4", "0", "0", "0"], ["84259.5", "0", "0", "0"]], "bids": [["84098.1", "0.01141", "0", "3"], ["84092.6", "0.00772906", "0", "1"], ["84083.3", "0.0202346", "0", "3"], ["84082.3", "0.22109968", "0", "4"], ["84080.4", "0.06529179", "0", "2"], ["84080.3", "0", "0", "0"], ["84079.8", "0.03109194", "0", "1"], ["84079.7", "0.1403523", "0", "1"], ["84079.1", "0.03286507", "0", "1"], ["84079", "0", "0", "0"], ["84078.9", "1.15697328", "0", "3"], ["84078.2", "1.23018009", "0", "4"], ["84077.3", "0", "0", "0"], ["84075.5", "0.3149424", "0", "1"], ["84074.5", "0.02728", "0", "1"], ["84073.4", "0.03485994", "0", "1"], ["84073.3", "0", "0", "0"], ["84072.8", "0.0352244", "0", "1"], ["84072.7", "0", "0", "0"], ["84066.4", "0.06691078", "0", "1"], ["84066.3", "0.31949482", "0", "1"], ["84064.4", "0.06678654", "0", "1"], ["84064.3", "0", "0", "0"], ["84063.3", "0.0687057", "0", "1"], ["84055.4", "0", "0", "0"], ["84052.1", "0", "0", "0"], ["84011.9", "0", "0", "0"], ["83927.9", "0", "0", "0"]], "ts": "1742554954604", "checksum": -933562030, "seqId": 49927369476, "prevSeqId": 49927369403}], "record_time": 1742554954.612726, "EXCHANGE": "OKX"}
{"arg": {"channel": "books", "instId": "BTC-USDT"}, "action": "update", "data": [{"asks": [["84112.7", "0.03", "0", "1"], ["84115.2", "0.00001197", "0", "1"], ["84117.1", "1", "0", "1"], ["84117.2", "0.423309", "0", "3"], ["84135.2", "0.13940838", "0", "3"], ["84136", "0.03999999", "0", "1"], ["84140.6", "0.26001767", "0", "2"], ["84145.6", "0", "0", "0"], ["84146.4", "0", "0", "0"], ["84160.2", "0.44601382", "0", "1"], ["84163.7", "0", "0", "0"]], "bids": [["84084.3", "0.11898522", "0", "1"], ["84082.3", "0.10211161", "0", "3"], ["84073.2", "0.05697845", "0", "2"], ["84071.7", "0.03177349", "0", "1"], ["84071.6", "0.05940838", "0", "1"], ["84062.9", "0.06307888", "0", "1"], ["83930", "0", "0", "0"], ["83929.9", "0", "0", "0"], ["83928.5", "0", "0", "0"]], "ts": "1742554954704", "checksum": -2047432358, "seqId": 49927369499, "prevSeqId": 49927369476}], "record_time": 1742554954.703949, "EXCHANGE": "OKX"}
{"arg": {"channel": "books", "instId": "BTC-USDT"}, "action": "update", "data": [{"asks": [["84117.7", "0", "0", "0"], ["84119.2", "0", "0", "0"], ["84121.1", "0", "0", "0"], ["84122.2", "0.80872561", "0", "2"], ["84122.4", "1.57804138", "0", "1"], ["84130.1", "0.00001197", "0", "1"], ["84199.1", "0.01774536", "0", "1"], ["84259.2", "0.00001197", "0", "1"]], "bids": [["84084", "0.60295505", "0", "4"], ["84081.5", "1", "0", "1"], ["84078.2", "0.23018009", "0", "3"], ["83930.2", "0", "0", "0"]], "ts": "1742554954804", "checksum": 293715849, "seqId": 49927369515, "prevSeqId": 49927369499}], "record_time": 1742554954.804029, "EXCHANGE": "OKX"}
{"arg": {"channel": "books", "instId": "BTC-USDT"}, "action": "update", "data": [{"asks": [], "bids": [["84084", "0.32942012", "0", "3"], ["84081.5", "0", "0", "0"], ["84078.4", "1.35641581", "0", "2"], ["83930.2", "0.00606454", "0", "2"]], "ts": "1742554954904", "checksum": -2047432358, "seqId": 49927369522, "prevSeqId": 49927369515}], "record_time": 1742554954.904225, "EXCHANGE": "OKX"}
{"arg": {"channel": "books", "instId": "BTC-USDT"}, "action": "update", "data": [{"asks": [["84117.2", "0.39156015", "0", "2"], ["84117.3", "0.03124727", "0", "1"], ["84259.2", "0", "0", "0"]], "bids": [["84098.1", "0.01229333", "0", "4"], ["84094.5", "0.00166157", "0", "2"], ["84071.1", "0.0314772", "0", "1"], ["84071", "0.00501", "0", "3"], ["84059", "1", "0", "1"], ["84051", "0.2", "0", "1"], ["83989.8", "0.00579971", "0", "1"], ["83932.8", "0", "0", "0"], ["83930.7", "0", "0", "0"], ["83930.5", "0", "0", "0"], ["83930.2", "0", "0", "0"]], "ts": "1742554955004", "checksum": 1694708899, "seqId": 49927369535, "prevSeqId": 49927369522}], "record_time": 1742554955.053406, "EXCHANGE": "OKX"}
{"arg": {"channel": "books", "instId": "BTC-USDT"}, "action": "update", "data": [{"asks": [["84102.5", "0.00349804", "0", "1"], ["84105.2", "0.00001197", "0", "1"], ["84114.9", "1", "0", "1"], ["84117.1", "0", "0", "0"], ["84117.3", "0", "0", "0"], ["84126.5", "0.39460606", "0", "2"], ["84130", "1", "0", "1"], ["84258.9", "0", "0", "0"], ["84259", "0", "0", "0"]], "bids": [["84098.1", "0.01088333", "0", "3"], ["84092.9", "0", "0", "0"], ["84083.5", "0.04", "0", "1"], ["84081.3", "0.00355263", "0", "1"], ["84078.5", "0.04", "0", "1"], ["84078.4", "0.35641581", "0", "1"], ["84077.6", "1", "0", "1"], ["84071.1", "0", "0", "0"], ["84062.8", "0.53862868", "0", "2"], ["84059", "0", "0", "0"], ["84003.2", "0.00579971", "0", "1"], ["83996", "0.00579971", "0", "1"], ["83992.7", "0.0059997", "0", "1"], ["83992.6", "0.0059997", "0", "1"], ["83989.9", "0.00579971", "0", "1"], ["83934.2", "0", "0", "0"], ["83934.1", "0", "0", "0"], ["83933.8", "0", "0", "0"], ["83933.3", "0", "0", "0"], ["83932.9", "0", "0", "0"]], "ts": "1742554955104", "checksum": -1730678400, "seqId": 49927369563, "prevSeqId": 49927369535}], "record_time": 1742554955.112108, "EXCHANGE": "OKX"}
{"arg": {"channel": "books", "instId": "BTC-USDT"}, "action": "update", "data": [{"asks": [["84103.9", "0.029738", "0", "1"], ["84108.2", "0.09664413", "0", "3"], ["84114.9", "0", "0", "0"], ["84116.4", "1", "0", "1"], ["84117.3", "0.03383856", "0", "1"], ["84119", "0.23794226", "0", "1"], ["84121", "0", "0", "0"], ["84122.1", "0.01774536", "0", "1"], ["84199.1", "0", "0", "0"], ["84199.2", "1.87716699", "0", "1"], ["84258.2", "0", "0", "0"], ["84258.3", "0", "0", "0"]], "bids": [["84098.1", "0.01342785", "0", "5"], ["84088.1", "0.12207443", "0", "1"], ["84084.3", "0", "0", "0"], ["84082.3", "0.22109976", "0", "4"], ["84071.1", "0.03263066", "0", "1"], ["84063.2", "0", "0", "0"], ["84062.8", "0.25729118", "0", "1"], ["84060.8", "0.23794226", "0", "1"], ["84060", "0.08557886", "0", "4"], ["84059.2", "0.066", "0", "3"], ["84058.4", "0.013", "0", "1"], ["84008.4", "0.00001501", "0", "1"], ["83934.7", "0", "0", "0"]], "ts": "1742554955204", "checksum": 460088616, "seqId": 49927369594, "prevSeqId": 49927369563}], "record_time": 1742554955.238756, "EXCHANGE": "OKX"}
{"arg": {"channel": "books", "instId": "BTC-USDT"}, "action": "update", "data": [{"asks": [["84098.2", "1.21179484", "0", "19"], ["84098.4", "0.01189695", "0", "1"], ["84098.9", "0.01332387", "0", "1"], ["84099", "0.0297729", "0", "1"], ["84102.8", "0.09006255", "0", "2"], ["84104", "0.0546", "0", "2"], ["84105.1", "0.4948191", "0", "1"], ["84105.2", "0.35642778", "0", "2"], ["84105.3", "0.17821722", "0", "1"], ["84105.5", "0.02379687", "0", "1"], ["84105.6", "0", "0", "0"], ["84107", "0.03450412", "0", "1"], ["84107.4", "0.03076289", "0", "1"], ["84107.5", "0.03396102", "0", "1"], ["84107.6", "0.03459203", "0", "1"], ["84107.7", "0", "0", "0"], ["84108.3", "0.01055", "0", "1"], ["84108.4", "0", "0", "0"], ["84108.5", "0", "0", "0"], ["84109", "0.35673", "0", "1"], ["84109.4", "0.7084129", "0", "2"], ["84109.6", "1", "0", "1"], ["84110.1", "0.22932713", "0", "4"], ["84110.4", "0", "0", "0"], ["84111.2", "0", "0", "0"], ["84111.3", "0.2379572", "0", "1"], ["84111.5", "0.17836", "0", "1"], ["84112", "0.0746", "0", "3"], ["84113.1", "0", "0", "0"], ["84113.7", "0.25869987", "0", "1"], ["84113.8", "0", "0", "0"], ["84113.9", "0.03096704", "0", "1"], ["84114", "0.04636074", "0", "2"], ["84114.7", "0", "0", "0"], ["84114.8", "0", "0", "0"], ["84116.1", "0.06402724", "0", "2"], ["84116.2", "0.03484667", "0", "1"], ["84116.4", "0", "0", "0"], ["84117.2", "0.35641581", "0", "1"], ["84117.3", "0", "0", "0"], ["84119", "0", "0", "0"], ["84120.3", "0.1403523", "0", "1"], ["84121", "0.06879238", "0", "1"], ["84121.7", "0", "0", "0"], ["84122.9", "0.06495086", "0", "1"], ["84123.4", "0.06451518", "0", "2"], ["84123.9", "0", "0", "0"], ["84124.2", "0", "0", "0"], ["84124.9", "0.06859015", "0", "1"], ["84125.9", "0.11228184", "0", "2"], ["84126.5", "0.14198023", "0", "1"], ["84130", "0", "0", "0"], ["84133.8", "0", "0", "0"], ["84134", "0.2", "0", "1"], ["84134.4", "0.25821721", "0", "3"], ["84134.7", "0.05788539", "0", "1"], ["84135.2", "0.09940837", "0", "2"], ["84136", "0", "0", "0"], ["84138.9", "0.01783683", "0", "1"], ["84140.6", "0.2025", "0", "1"], ["84144.1", "0.01188438", "0", "1"], ["84153.3", "0", "0", "0"], ["84154.4", "0", "0", "0"], ["84155.8", "0", "0", "0"], ["84160.2", "0.20491632", "0", "1"], ["84161.9", "0", "0", "0"], ["84174.4", "3.26489", "0", "1"], ["84176.2", "0.01425581", "0", "1"], ["84181", "0.12316366", "0", "2"], ["84201.8", "0.09190951", "0", "1"], ["84205.5", "0", "0", "0"], ["84214.4", "0", "0", "0"], ["84229.2", "0.01191875", "0", "2"], ["84242.1", "0.08744", "0", "1"], ["84246", "0.01783629", "0", "3"], ["84258.1", "0", "0", "0"]], "bids": [["84098.1", "0.0147001", "0", "6"], ["84094", "0", "0", "0"], ["84092.6", "0", "0", "0"], ["84092.4", "0", "0", "0"], ["84091.5", "0", "0", "0"], ["84089.8", "0", "0", "0"], ["84088.8", "0", "0", "0"], ["84088.7", "0.17821722", "0", "1"], ["84088.1", "0", "0", "0"], ["84086.4", "0", "0", "0"], ["84084.2", "0", "0", "0"], ["84084.1", "0.01", "0", "1"], ["84084", "0.25484346", "0", "3"], ["84083.7", "0", "0", "0"], ["84083.5", "0", "0", "0"], ["84083.3", "0.00833551", "0", "2"], ["84082.3", "0.10211161", "0", "3"], ["84081.3", "0", "0", "0"], ["84081.2", "0", "0", "0"], ["84080.4", "0", "0", "0"], ["84079.9", "0.11899156", "0", "1"], ["84079.8", "0.01339", "0", "1"], ["84079.7", "0.17360175", "0", "2"], ["84079.6", "0.55853592", "0", "2"], ["84079.5", "0", "0", "0"], ["84079.4", "0.03248302", "0", "1"], ["84079.1", "0", "0", "0"], ["84078.9", "0.042", "0", "1"], ["84078.8", "0.03504151", "0", "1"], ["84078.7", "0", "0", "0"], ["84078.5", "0", "0", "0"], ["84078.2", "0.30342588", "0", "5"], ["84077.6", "0", "0", "0"], ["84077.1", "0.06865459", "0", "2"], ["84075.5", "0.54332453", "0", "2"], ["84075.2", "0", "0", "0"], ["84074.3", "0.01190036", "0", "1"], ["84073.4", "0", "0", "0"], ["84073.2", "0.00005206", "0", "1"], ["84072.8", "0", "0", "0"], ["84072.7", "0.03136938", "0", "1"], ["84072.1", "0.1403523", "0", "1"], ["84071.9", "0.03536251", "0", "1"], ["84071.7", "0", "0", "0"], ["84071.1", "0.35673", "0", "1"], ["84070.6", "0.03424505", "0", "2"], ["84070", "0.0384021", "0", "3"], ["84069.6", "0", "0", "0"], ["84067.3", "0.06290606", "0", "2"], ["84066.4", "0", "0", "0"], ["84066.2", "0.47986", "0", "1"], ["84065.7", "0.06740901", "0", "2"], ["84064.8", "0", "0", "0"], ["84064.4", "0", "0", "0"], ["84063.4", "0.06648003", "0", "1"], ["84063.3", "0", "0", "0"], ["84062.9", "0", "0", "0"], ["84062.5", "0.18943917", "0", "2"], ["84061.9", "0.06254435", "0", "1"], ["84060.8", "0", "0", "0"], ["84060.7", "0.00001197", "0", "1"], ["84060", "0.00557886", "0", "2"], ["84059.2", "0", "0", "0"], ["84058.6", "0.32422509", "0", "2"], ["84058.4", "0", "0", "0"], ["84057.8", "0.36894094", "0", "3"], ["84056.9", "0.2379572", "0", "1"], ["84056", "0.08", "0", "2"], ["84055.2", "0.066", "0", "3"], ["84054.4", "0.013", "0", "1"], ["84053.7", "0", "0", "0"], ["84051.5", "0", "0", "0"], ["84049.7", "0.01774536", "0", "1"], ["84049.5", "0", "0", "0"], ["84048.5", "0.0542", "0", "1"], ["84045.3", "0", "0", "0"], ["84040.2", "0.01728301", "0", "2"], ["84036.9", "0", "0", "0"], ["84036.8", "0.02381051", "0", "1"], ["84030.6", "0", "0", "0"], ["84030.2", "0", "0", "0"], ["84027.6", "0", "0", "0"], ["84020.4", "0.33966209", "0", "2"], ["84016.6", "0.00600645", "0", "2"], ["84014.1", "0.06134815", "0", "1"], ["84011.1", "0.48269671", "0", "2"], ["84008.7", "0", "0", "0"], ["84005.7", "0", "0", "0"], ["83999.4", "0.08239598", "0", "1"], ["83992.8", "0.0059997", "0", "1"], ["83987.4", "0", "0", "0"], ["83986.7", "0.00579971", "0", "1"], ["83981.3", "0", "0", "0"], ["83972.9", "0.00594543", "0", "1"], ["83964.5", "0", "0", "0"], ["83956.1", "0.01783629", "0", "3"], ["83934.7", "0.03", "0", "1"], ["83934.2", "0.35579296", "0", "1"], ["83934.1", "0.00422012", "0", "1"], ["83933.8", "0.00011948", "0", "1"], ["83933.3", "0.00525171", "0", "7"], ["83932.9", "0.00001845", "0", "1"], ["83932.8", "0.014", "0", "1"], ["83930.7", "0.00001807", "0", "1"], ["83930.5", "0.00001316", "0", "1"], ["83930.2", "0.00606454", "0", "2"], ["83929.9", "0.00007149", "0", "1"], ["83928.5", "0.14848165", "0", "4"], ["83927.9", "0.00199404", "0", "5"], ["83926.8", "0.2025", "0", "1"], ["83926.1", "0.00007821", "0", "1"], ["83925.9", "0.00001002", "0", "1"], ["83925.8", "0.20821722", "0", "2"], ["83925.6", "0.35579296", "0", "1"], ["83925.3", "0.00008", "0", "1"], ["83925.2", "0.00011161", "0", "1"], ["83925", "0.00027367", "0", "1"], ["83924.8", "0.00422077", "0", "1"]], "ts": "1742554955304", "checksum": -1431123418, "seqId": 49927369914, "prevSeqId": 49927369594}], "record_time": 1742554955.306776, "EXCHANGE": "OKX"}
{"arg": {"channel": "books", "instId": "BTC-USDT"}, "action": "update", "data": [{"asks": [["84090.1", "0.53909436", "0", "5"], ["84092", "0.0146", "0", "1"], ["84093.8", "0.01939827", "0", "1"], ["84094.5", "0.01151311", "0", "2"], ["84095.1", "0.03854779", "0", "1"], ["84096", "0.0146", "0", "1"], ["84097.8", "0.08850083", "0", "1"], ["84097.9", "0.2", "0", "1"], ["84098.2", "0.06105484", "0", "3"], ["84098.3", "0", "0", "0"], ["84098.9", "0", "0", "0"], ["84100.3", "0.00001197", "0", "1"], ["84100.9", "0", "0", "0"], ["84103", "0", "0", "0"], ["84103.2", "0", "0", "0"], ["84103.7", "0.06480516", "0", "2"], ["84105.1", "0.25781394", "0", "1"], ["84105.8", "0", "0", "0"], ["84106.8", "0.0000105", "0", "1"], ["84107", "0", "0", "0"], ["84107.4", "0", "0", "0"], ["84107.5", "0", "0", "0"], ["84107.6", "0", "0", "0"], ["84108.1", "0.06", "0", "2"], ["84109", "0", "0", "0"], ["84111.3", "0", "0", "0"], ["84111.5", "0.05940838", "0", "1"], ["84112.4", "0.03477159", "0", "1"], ["84112.5", "0.03173931", "0", "2"], ["84113.9", "0", "0", "0"], ["84114", "0", "0", "0"], ["84115.4", "0.11228184", "0", "2"], ["84116", "0", "0", "0"], ["84116.1", "0.03", "0", "1"], ["84116.2", "0", "0", "0"], ["84117", "0.06", "0", "2"], ["84117.6", "0.2826205", "0", "2"], ["84118", "0", "0", "0"], ["84118.4", "0.23794924", "0", "1"], ["84119.1", "0.18770215", "0", "2"], ["84120", "0.11894903", "0", "2"], ["84121", "0", "0", "0"], ["84121.2", "0.0655157", "0", "1"], ["84122.4", "1.58161138", "0", "2"], ["84122.9", "0", "0", "0"], ["84123.4", "0.000015", "0", "1"], ["84124.9", "0", "0", "0"], ["84127", "0.03693417", "0", "1"], ["84133.3", "0.25856534", "0", "3"], ["84134", "0", "0", "0"], ["84135.2", "0.03999999", "0", "1"], ["84142.3", "0", "0", "0"], ["84142.8", "0", "0", "0"], ["84143.3", "0.27006173", "0", "1"], ["84145.1", "0", "0", "0"], ["84146", "0", "0", "0"], ["84146.5", "0", "0", "0"], ["84147.5", "0", "0", "0"], ["84148", "1", "0", "1"], ["84148.2", "0", "0", "0"], ["84148.3", "0", "0", "0"], ["84159.6", "0", "0", "0"], ["84168", "0", "0", "0"], ["84171.5", "0.00012217", "0", "1"], ["84173.1", "1.16456986", "0", "2"], ["84178.9", "0", "0", "0"], ["84184.5", "0.01188469", "0", "1"], ["84187.3", "0.01188468", "0", "1"], ["84200.6", "0.64996", "0", "1"], ["84203.3", "0.01188459", "0", "1"], ["84227.6", "0", "0", "0"], ["84230", "0.00023762", "0", "1"], ["84230.2", "0.01188444", "0", "1"], ["84230.5", "0.00594197", "0", "1"], ["84232.5", "0.01188442", "0", "1"], ["84245.7", "0.01188434", "0", "1"], ["84258.1", "0.00003542", "0", "1"], ["84258.2", "0.35579296", "0", "1"], ["84258.3", "0.00002584", "0", "1"], ["84258.9", "0.00001016", "0", "1"], ["84259", "0.00011161", "0", "1"], ["84259.2", "0.00001197", "0", "1"], ["84259.4", "0.0852", "0", "6"], ["84259.5", "0.0142", "0", "1"], ["84259.7", "0.00419094", "0", "1"]], "bids": [["84098.1", "0", "0", "0"], ["84095.4", "0", "0", "0"], ["84094.5", "0", "0", "0"], ["84090.5", "0", "0", "0"], ["84090", "0.63061599", "0", "14"], ["84085.8", "0.00056597", "0", "1"], ["84085.7", "0.01596287", "0", "1"], ["84084", "0.1676143", "0", "4"], ["84083.4", "0", "0", "0"], ["84082.6", "0.133769", "0", "1"], ["84082.3", "0.00011161", "0", "1"], ["84082.2", "0", "0", "0"], ["84081", "0", "0", "0"], ["84080", "0.0036208", "0", "2"], ["84079.9", "0", "0", "0"], ["84079.7", "0.1403523", "0", "1"], ["84079.6", "0.41111729", "0", "2"], ["84079.4", "0", "0", "0"], ["84078.9", "0", "0", "0"], ["84078.8", "0", "0", "0"], ["84078.2", "0.27018009", "0", "4"], ["84077.1", "0.02846459", "0", "1"], ["84076.6", "0.00984551", "0", "2"], ["84076.2", "0.17838", "0", "1"], ["84075.7", "0.03456842", "0", "1"], ["84075.5", "0.52401869", "0", "2"], ["84075.2", "1", "0", "1"], ["84075", "0.03167213", "0", "1"], ["84074.3", "0.05190036", "0", "2"], ["84073.8", "0.087", "0", "2"], ["84072.7", "0", "0", "0"], ["84071.9", "0", "0", "0"], ["84071.6", "0", "0", "0"], ["84071.3", "0.00475787", "0", "1"], ["84071.1", "0", "0", "0"], ["84071", "0.005", "0", "2"], ["84070.6", "0.00001197", "0", "1"], ["84070", "0.005", "0", "2"], ["84069.9", "0.35641581", "0", "1"], ["84069.1", "0.0402", "0", "1"], ["84067.5", "0.35659722", "0", "2"], ["84066.9", "0.03162324", "0", "1"], ["84066.3", "0.35217178", "0", "2"], ["84065.7", "0.00001197", "0", "1"], ["84063.4", "0", "0", "0"], ["84062.7", "0", "0", "0"], ["84062.5", "0.12484", "0", "1"], ["84061.9", "0", "0", "0"], ["84060.1", "0.00357", "0", "1"], ["84059.6", "0.070755", "0", "1"], ["84058.8", "0.34596541", "0", "1"], ["84058.7", "0.237954", "0", "1"], ["84058.6", "0", "0", "0"], ["84058.2", "0.06733421", "0", "1"], ["84058", "0.0103941", "0", "1"], ["84056.9", "0", "0", "0"], ["84056", "0", "0", "0"], ["84055.2", "0", "0", "0"], ["84054.4", "0", "0", "0"], ["84053.6", "0.08", "0", "2"], ["84052.8", "0.066", "0", "3"], ["84052", "0.013", "0", "1"], ["84049.2", "0.20908", "0", "1"], ["84048.3", "3.20044", "0", "1"], ["84046", "0.05817312", "0", "2"], ["84045.8", "0.67736934", "0", "4"], ["84044.4", "0", "0", "0"], ["84041.7", "0.1325809", "0", "2"], ["84040.8", "0.01188445", "0", "1"], ["84040", "0.02377936", "0", "3"], ["84037.4", "0.34251155", "0", "2"], ["84036.2", "0.59964265", "0", "1"], ["84035.4", "0", "0", "0"], ["84031.9", "0", "0", "0"], ["84027.6", "0.0028522", "0", "1"], ["84027.5", "0.04188442", "0", "2"], ["84024.3", "0.01188444", "0", "1"], ["84023.4", "0.00105193", "0", "1"], ["84020.4", "0.21481209", "0", "1"], ["84014.7", "0.00235659", "0", "1"], ["84007.1", "0.096616", "0", "1"], ["84005", "0.01902221", "0", "1"], ["84002.4", "0", "0", "0"], ["83994.8", "0.21438459", "0", "2"], ["83994.2", "0.61572247", "0", "2"], ["83994.1", "0", "0", "0"], ["83992.9", "0.00599942", "0", "1"], ["83986.8", "0.00599942", "0", "1"], ["83968.6", "0.214033", "0", "1"], ["83937", "0", "0", "0"], ["83926.8", "0", "0", "0"], ["83925", "0", "0", "0"], ["83924.8", "0", "0", "0"]], "ts": "1742554955404", "checksum": -1184667110, "seqId": 49927370568, "prevSeqId": 49927369914}], "record_time": 1742554955.406963, "EXCHANGE": "OKX"}
{"arg": {"channel": "books", "instId": "BTC-USDT"}, "action": "update", "data": [{"asks": [["84097.8", "0.02850083", "0", "1"], ["84097.9", "0", "0", "0"], ["84102.8", "0.13434427", "0", "1"], ["84103.3", "0.03096481", "0", "1"], ["84103.9", "0.06474126", "0", "2"], ["84104.7", "0.06", "0", "2"], ["84110.2", "0.03159466", "0", "2"], ["84110.3", "0.03191294", "0", "1"], ["84113.6", "0", "0", "0"], ["84117", "0", "0", "0"], ["84117.3", "0.06479148", "0", "1"], ["84119.7", "0.06516887", "0", "1"], ["84122.4", "0.00357", "0", "1"], ["84134.3", "0.35641581", "0", "1"], ["84139.1", "0.1", "0", "1"], ["84223.6", "0.214033", "0", "1"], ["84259.2", "0", "0", "0"], ["84259.4", "0", "0", "0"], ["84259.5", "0", "0", "0"], ["84259.7", "0", "0", "0"]], "bids": [["84090", "0.83311599", "0", "15"], ["84084.1", "0", "0", "0"], ["84079.6", "0.73790049", "0", "3"], ["84077.8", "0.03713992", "0", "1"], ["84077.2", "0.102", "0", "2"], ["84076.6", "0.00420551", "0", "1"], ["84076.4", "1", "0", "1"], ["84076", "0.28784948", "0", "4"], ["84075.5", "0.3149424", "0", "1"], ["84075.2", "0", "0", "0"], ["84074.5", "0.03441197", "0", "1"], ["84073.8", "0.18", "0", "4"], ["84069", "0.03094007", "0", "1"], ["84068.2", "0.03410263", "0", "1"], ["84064.8", "0.05940838", "0", "1"], ["84062.8", "0.17552246", "0", "1"], ["84062", "0.06899293", "0", "2"], ["84058.8", "0.41293855", "0", "2"], ["84049.6", "1.99403495", "0", "4"], ["84049.3", "0", "0", "0"], ["84048.8", "0.05", "0", "1"], ["84008.4", "0.00017764", "0", "2"], ["84007.6", "0.014", "0", "1"], ["83971.5", "0.00001197", "0", "1"], ["83961.6", "0.00202724", "0", "2"], ["83925.9", "0", "0", "0"], ["83925.8", "0", "0", "0"], ["83925.6", "0", "0", "0"], ["83925.3", "0", "0", "0"], ["83925.2", "0", "0", "0"]], "ts": "1742554955504", "checksum": 201440389, "seqId": 49927370646, "prevSeqId": 49927370568}], "record_time": 1742554955.509704, "EXCHANGE": "OKX"}
{"arg": {"channel": "books", "instId": "BTC-USDT"}, "action": "update", "data": [{"asks": [["84095.1", "0", "0", "0"], ["84097.6", "0.01055", "0", "1"], ["84097.8", "0.01689655", "0", "1"], ["84099.1", "0.03854779", "0", "1"], ["84103.9", "0.09640126", "0", "3"], ["84106.4", "0.53514", "0", "2"], ["84112.7", "0", "0", "0"], ["84116.1", "0", "0", "0"], ["84118.5", "1.5579357", "0", "1"], ["84122.1", "0", "0", "0"], ["84122.2", "0.37467917", "0", "1"], ["84123.9", "0.059912", "0", "1"], ["84130.2", "0.50099515", "0", "1"], ["84130.4", "0.33453712", "0", "5"], ["84131.2", "0.03999999", "0", "1"], ["84134.4", "0.17821722", "0", "1"], ["84134.6", "0.1", "0", "1"], ["84135.2", "0", "0", "0"], ["84139.1", "0", "0", "0"], ["84144", "0.00004312", "0", "1"], ["84152.1", "0.55918738", "0", "1"], ["84152.5", "0.917086", "0", "1"], ["84173", "0.01774536", "0", "1"], ["84180.6", "0.19189909", "0", "2"], ["84185", "0.49931821", "0", "2"], ["84187.5", "1.375056", "0", "1"], ["84198.8", "0.001964", "0", "1"], ["84200.7", "0", "0", "0"], ["84218.9", "0", "0", "0"], ["84258.2", "0", "0", "0"], ["84258.3", "0", "0", "0"], ["84258.9", "0", "0", "0"], ["84259", "0", "0", "0"]], "bids": [["84090", "0.83403599", "0", "16"], ["84084", "0.1810043", "0", "5"], ["84083.8", "0.0118982", "0", "1"], ["84079.6", "0.74354049", "0", "4"], ["84077.7", "0.04019", "0", "1"], ["84076.2", "0.53514", "0", "2"], ["84069.1", "0", "0", "0"], ["84063.9", "1.61092806", "0", "1"], ["84051", "0", "0", "0"], ["84049.6", "1.19631356", "0", "3"], ["84040.2", "0.11728301", "0", "3"], ["84037.4", "0.59149287", "0", "1"], ["84034.4", "0.918373", "0", "1"], ["84008.4", "0.00001501", "0", "1"], ["84005.4", "0", "0", "0"], ["84000.5", "0.00017766", "0", "2"], ["84000.1", "0.49797546", "0", "2"], ["83997.5", "0.00007196", "0", "1"], ["83996.9", "0.07189685", "0", "2"], ["83941.8", "0.00001197", "0", "1"], ["83928.5", "0", "0", "0"], ["83927.9", "0", "0", "0"], ["83926.1", "0", "0", "0"]], "ts": "1742554955604", "checksum": -2012964438, "seqId": 49927370746, "prevSeqId": 49927370646}], "record_time": 1742554955.604179, "EXCHANGE": "OKX"}
{"arg": {"channel": "books", "instId": "BTC-USDT"}, "action": "update", "data": [{"asks": [["84093.8", "0", "0", "0"], ["84094.5", "0.00111901", "0", "1"], ["84097.8", "0", "0", "0"], ["84098.1", "0.04989557", "0", "1"], ["84099.7", "0.0103941", "0", "1"], ["84103.9", "0.06666326", "0", "2"], ["84105.1", "0.67004706", "0", "1"], ["84108.2", "1.09664413", "0", "4"], ["84109.4", "0.32667515", "0", "1"], ["84109.6", "0", "0", "0"], ["84117.6", "0.73975141", "0", "1"], ["84134.9", "0.34893028", "0", "1"], ["84135", "0.47091897", "0", "2"], ["84136.4", "0", "0", "0"], ["84147.9", "1.17435698", "0", "2"], ["84148", "3.72998246", "0", "2"], ["84155.1", "0", "0", "0"], ["84258.2", "0.35579296", "0", "1"], ["84258.3", "0.00002584", "0", "1"]], "bids": [["84066.3", "0.88591579", "0", "3"], ["84064.7", "0.01774536", "0", "1"], ["84050.4", "0.11785561", "0", "3"], ["84049.7", "0", "0", "0"], ["84049.6", "1.14631356", "0", "2"], ["84048.8", "0", "0", "0"], ["84037.4", "1.42591105", "0", "2"], ["84034.4", "3.80350915", "0", "2"], ["84011.1", "0.00001196", "0", "1"], ["84007.1", "0", "0", "0"], ["84000.1", "0.00597332", "0", "1"], ["83994.7", "0.01251984", "0", "3"], ["83986.9", "0.006", "0", "1"], ["83928.5", "0.14848165", "0", "4"]], "ts": "1742554955704", "checksum": -278338384, "seqId": 49927370790, "prevSeqId": 49927370746}], "record_time": 1742554955.704131, "EXCHANGE": "OKX"}
{"arg": {"channel": "books", "instId": "BTC-USDT"}, "action": "update", "data": [{"asks": [["84104", "0.06515", "0", "3"], ["84105.2", "0.00001197", "0", "1"], ["84108", "0.35641581", "0", "1"], ["84108.3", "0", "0", "0"], ["84117.1", "0.01774536", "0", "1"], ["84173", "0", "0", "0"]], "bids": [["84090", "0.85198106", "0", "18"], ["84084.6", "0.0077298", "0", "1"], ["83928.5", "0", "0", "0"]], "ts": "1742554955804", "checksum": -6103988, "seqId": 49927370802, "prevSeqId": 49927370790}], "record_time": 1742554955.804853, "EXCHANGE": "OKX"}
{"arg": {"channel": "books", "instId": "BTC-USDT"}, "action": "update", "data": [{"asks": [["84090.1", "0.46037997", "0", "5"], ["84098.2", "0.04501771", "0", "2"], ["84102.5", "0", "0", "0"], ["84258.9", "0.00001016", "0", "1"]], "bids": [["84084", "0.21428664", "0", "4"], ["84083.9", "0.1349487", "0", "2"], ["84080", "0.00001", "0", "1"], ["84079.6", "0.73790049", "0", "3"], ["84003.8", "0.0058", "0", "1"], ["83998.8", "0.0117995", "0", "2"], ["83991.8", "0.0058", "0", "1"], ["83983.9", "0.0058", "0", "1"], ["83983.8", "0.0058", "0", "1"], ["83983.7", "0.00581501", "0", "2"], ["83930.7", "0", "0", "0"], ["83930.5", "0", "0", "0"], ["83930.2", "0", "0", "0"], ["83929.9", "0", "0", "0"]], "ts": "1742554955904", "checksum": -1529343087, "seqId": 49927370823, "prevSeqId": 49927370802}], "record_time": 1742554955.904219, "EXCHANGE": "OKX"}
{"arg": {"channel": "books", "instId": "BTC-USDT"}, "action": "update", "data": [{"asks": [["84118.4", "0", "0", "0"], ["84119.6", "0.23794313", "0", "1"], ["84159.9", "0.01125286", "0", "1"], ["84161.8", "0", "0", "0"]], "bids": [["84081.7", "0.00564", "0", "1"], ["84077.8", "1.03713992", "0", "2"], ["84076.4", "0", "0", "0"], ["84059.7", "0.23794313", "0", "1"], ["84058.7", "0", "0", "0"], ["84045.2", "0", "0", "0"], ["84043.1", "0.01832163", "0", "1"], ["83973.6", "0", "0", "0"], ["83971.5", "0.18322828", "0", "2"], ["83930.7", "0.00001807", "0", "1"]], "ts": "1742554956004", "checksum": 683700214, "seqId": 49927370838, "prevSeqId": 49927370823}], "record_time": 1742554956.052287, "EXCHANGE": "OKX"}
{"arg": {"channel": "books", "instId": "BTC-USDT"}, "action": "update", "data": [{"asks": [["84119", "0.23794368", "0", "1"], ["84119.6", "0", "0", "0"], ["84123.6", "0.01", "0", "1"], ["84145.4", "0", "0", "0"], ["84148.8", "0.01", "0", "1"], ["84170.6", "0", "0", "0"]], "bids": [["84064.6", "0.481023", "0", "2"], ["84062.8", "0.24558854", "0", "2"], ["84058.8", "0.32176076", "0", "2"], ["84058", "1.0103941", "0", "2"], ["84054.4", "0.08", "0", "2"], ["84053.6", "0.04", "0", "1"], ["84052.8", "0.026", "0", "2"], ["84050.4", "0.01785561", "0", "1"], ["84049.6", "1.19631356", "0", "3"], ["84048.8", "0.05", "0", "1"], ["83961.6", "0.00001197", "0", "1"], ["83958.9", "0.00201511", "0", "1"], ["83932.9", "0", "0", "0"], ["83932.8", "0", "0", "0"], ["83930.7", "0", "0", "0"]], "ts": "1742554956104", "checksum": 683700214, "seqId": 49927370870, "prevSeqId": 49927370838}], "record_time": 1742554956.104131, "EXCHANGE": "OKX"}
{"arg": {"channel": "books", "instId": "BTC-USDT"}, "action": "update", "data": [{"asks": [["84090.1", "0.44681756", "0", "4"], ["84092.6", "0.01189811", "0", "1"], ["84099.2", "0.02973996", "0", "1"], ["84119", "0", "0", "0"], ["84119.6", "0.23794351", "0", "1"], ["84232", "0.00054", "0", "2"], ["84258.3", "0", "0", "0"], ["84258.9", "0", "0", "0"]], "bids": [["84058", "0.0103941", "0", "1"]], "ts": "1742554956204", "checksum": -1798607749, "seqId": 49927370888, "prevSeqId": 49927370870}], "record_time": 1742554956.203813, "EXCHANGE": "OKX"}
{"arg": {"channel": "books", "instId": "BTC-USDT"}, "action": "update", "data": [{"asks": [["84119.6", "0.2379435", "0", "1"], ["84122.2", "0.59952054", "0", "2"], ["84126", "1", "0", "1"], ["84258.2", "0", "0", "0"]], "bids": [["84084", "0.25283443", "0", "5"], ["84079.6", "0.6993527", "0", "2"]], "ts": "1742554956304", "checksum": 1290702045, "seqId": 49927370899, "prevSeqId": 49927370888}], "record_time": 1742554956.313795, "EXCHANGE": "OKX"}
{"arg": {"channel": "books", "instId": "BTC-USDT"}, "action": "update", "data": [{"asks": [["84105.6", "0.00361957", "0", "1"], ["84133", "0.00001", "0", "1"], ["84135", "0.67091897", "0", "3"], ["84158", "0", "0", "0"], ["84258.1", "0", "0", "0"]], "bids": [["84076.2", "0.53871246", "0", "3"], ["84070.2", "0.02379623", "0", "1"], ["84050.4", "0.11785561", "0", "3"], ["84049.6", "1.14631356", "0", "2"], ["84048.8", "0", "0", "0"], ["84047", "0.00001", "0", "1"], ["83933.3", "0", "0", "0"]], "ts": "1742554956404", "checksum": 1290702045, "seqId": 49927370915, "prevSeqId": 49927370899}], "record_time": 1742554956.442215, "EXCHANGE": "OKX"}
{"arg": {"channel": "books", "instId": "BTC-USDT"}, "action": "update", "data": [{"asks": [["84090.1", "0.4503849", "0", "5"], ["84092.5", "0.01266514", "0", "1"], ["84094", "0.0146", "0", "1"], ["84105.6", "0", "0", "0"], ["84106.8", "0", "0", "0"], ["84109.4", "0.24074734", "0", "1"], ["84111.4", "0.25453713", "0", "3"], ["84122.2", "0.37467917", "0", "1"], ["84126", "0", "0", "0"], ["84219.1", "0.002378", "0", "1"]], "bids": [["84088.8", "0.11127832", "0", "1"], ["84061.5", "0.23794222", "0", "1"], ["84059.7", "0", "0", "0"], ["84040.6", "0.02745264", "0", "1"], ["83934.1", "0", "0", "0"], ["83933.8", "0", "0", "0"]], "ts": "1742554956504", "checksum": -1652296981, "seqId": 49927370934, "prevSeqId": 49927370915}], "record_time": 1742554957.059436, "EXCHANGE": "OKX"}
{"arg": {"channel": "books", "instId": "BTC-USDT"}, "action": "update", "data": [{"asks": [["84104.6", "0.004461", "0", "1"], ["84119", "0.23794298", "0", "1"], ["84119.6", "0", "0", "0"], ["84135", "0.47091897", "0", "2"], ["84159.9", "0.01125571", "0", "1"], ["84180.5", "0.17821722", "0", "1"], ["84257.6", "0", "0", "0"]], "bids": [["84090", "0.83414406", "0", "17"], ["84081.7", "0", "0", "0"], ["84076.2", "0.53514", "0", "2"], ["84061.5", "0", "0", "0"], ["84059.7", "0.23794298", "0", "1"], ["84054.4", "0", "0", "0"], ["84053.6", "0.08", "0", "2"], ["84053.3", "0.28056049", "0", "2"], ["84052.8", "0.066", "0", "3"], ["84051", "0.2", "0", "1"], ["84043.1", "0.01832159", "0", "1"], ["84020.4", "0", "0", "0"], ["83971.5", "0.18322788", "0", "2"], ["83934.1", "0.00422012", "0", "1"], ["83933.8", "0.00011948", "0", "1"]], "ts": "1742554956604", "checksum": -1105899766, "seqId": 49927370983, "prevSeqId": 49927370934}], "record_time": 1742554957.062773, "EXCHANGE": "OKX"}
{"arg": {"channel": "books", "instId": "BTC-USDT"}, "action": "update", "data": [{"asks": [["84104.6", "0", "0", "0"], ["84183.8", "0.00118787", "0", "1"]], "bids": [["84090", "0.83598901", "0", "18"], ["84081.9", "0.004476", "0", "1"], ["83933.8", "0", "0", "0"]], "ts": "1742554956704", "checksum": 465208416, "seqId": 49927370997, "prevSeqId": 49927370983}], "record_time": 1742554957.066893, "EXCHANGE": "OKX"}
{"arg": {"channel": "books", "instId": "BTC-USDT"}, "action": "update", "data": [{"asks": [["84108.4", "0.005631", "0", "1"], ["84126.5", "0.27485562", "0", "2"], ["84128.8", "0.56389769", "0", "1"], ["84168.4", "0.12322037", "0", "1"], ["84169.9", "0", "0", "0"], ["84256.2", "0", "0", "0"]], "bids": [], "ts": "1742554956804", "checksum": 465208416, "seqId": 49927371004, "prevSeqId": 49927370997}], "record_time": 1742554957.0682, "EXCHANGE": "OKX"}
{"arg": {"channel": "books", "instId": "BTC-USDT"}, "action": "update", "data": [{"asks": [], "bids": [["84081.9", "0", "0", "0"], ["83933.8", "0.00011948", "0", "1"]], "ts": "1742554956904", "checksum": 1698931361, "seqId": 49927371023, "prevSeqId": 49927371004}], "record_time": 1742554957.068855, "EXCHANGE": "OKX"}
{"arg": {"channel": "books", "instId": "BTC-USDT"}, "action": "update", "data": [{"asks": [["84106.2", "0.00365705", "0", "1"], ["84107.1", "0.005661", "0", "1"], ["84108.4", "0", "0", "0"], ["84117.1", "0.25568924", "0", "2"], ["84119", "0", "0", "0"]], "bids": [["84076", "0.29141159", "0", "5"]], "ts": "1742554957004", "checksum": 1698931361, "seqId": 49927371043, "prevSeqId": 49927371023}], "record_time": 1742554957.06953, "EXCHANGE": "OKX"}
{"arg": {"channel": "books", "instId": "BTC-USDT"}, "action": "update", "data": [{"asks": [["84122.2", "0.67152054", "0", "2"], ["84125.1", "1.41822919", "0", "3"]], "bids": [["84090", "0.83506901", "0", "17"], ["84051", "0", "0", "0"], ["83933.3", "0.00525171", "0", "7"]], "ts": "1742554957104", "checksum": -832851898, "seqId": 49927371047, "prevSeqId": 49927371043}], "record_time": 1742554957.104516, "EXCHANGE": "OKX"}
{"arg": {"channel": "books", "instId": "BTC-USDT"}, "action": "update", "data": [{"asks": [["84090.1", "0.34699269", "0", "4"], ["84116.8", "0.00356734", "0", "1"], ["84117.1", "0.25568906", "0", "2"], ["84122.6", "0.09491011", "0", "2"], ["84132.7", "0.005", "0", "1"], ["84255.6", "0", "0", "0"]], "bids": [["84079.3", "0.009669", "0", "1"], ["84058.8", "0.5899123", "0", "3"], ["84058", "1.0103941", "0", "2"], ["84054.4", "0.08", "0", "2"], ["84053.6", "0.04", "0", "1"], ["84052.8", "0.026", "0", "2"], ["84029.2", "0", "0", "0"], ["83933.3", "0", "0", "0"]], "ts": "1742554957204", "checksum": 1146800436, "seqId": 49927371079, "prevSeqId": 49927371047}], "record_time": 1742554957.207746, "EXCHANGE": "OKX"}
{"arg": {"channel": "books", "instId": "BTC-USDT"}, "action": "update", "data": [{"asks": [], "bids": [["84090", "0.63256901", "0", "16"], ["84088.8", "0", "0", "0"], ["83933.3", "0.00525171", "0", "7"]], "ts": "1742554957304", "checksum": -1852503953, "seqId": 49927371082, "prevSeqId": 49927371079}], "record_time": 1742554957.308551, "EXCHANGE": "OKX"}
{"arg": {"channel": "books", "instId": "BTC-USDT"}, "action": "update", "data": [{"asks": [["84090.1", "0.45038423", "0", "5"], ["84097.8", "0.11890903", "0", "1"], ["84097.9", "0.11400641", "0", "1"], ["84098", "0.2", "0", "1"], ["84098.1", "0", "0", "0"], ["84107.1", "0", "0", "0"], ["84255", "0", "0", "0"]], "bids": [], "ts": "1742554957404", "checksum": 570939031, "seqId": 49927371088, "prevSeqId": 49927371082}], "record_time": 1742554957.403753, "EXCHANGE": "OKX"}
{"arg": {"channel": "books", "instId": "BTC-USDT"}, "action": "update", "data": [{"asks": [["84099.2", "0", "0", "0"], ["84104.1", "0.00564", "0", "1"], ["84108.2", "1.05203713", "0", "3"], ["84116.8", "0", "0", "0"], ["84117.1", "0.25568975", "0", "2"], ["84126.5", "0.5582462", "0", "1"], ["84127", "1.03693417", "0", "2"], ["84255", "0.00001181", "0", "1"]], "bids": [["84090", "0.85290601", "0", "18"], ["84054.4", "0", "0", "0"], ["84053.6", "0.08", "0", "2"], ["84052.8", "0.066", "0", "3"], ["83932.9", "0.00001845", "0", "1"]], "ts": "1742554957504", "checksum": 689587336, "seqId": 49927371110, "prevSeqId": 49927371088}], "record_time": 1742554957.506969, "EXCHANGE": "OKX"}
{"arg": {"channel": "books", "instId": "BTC-USDT"}, "action": "update", "data": [{"asks": [["84104.1", "0", "0", "0"], ["84117.1", "0.25568995", "0", "2"], ["84255.6", "0.01493332", "0", "1"]], "bids": [["84090", "0.65124601", "0", "18"], ["83973.8", "0", "0", "0"], ["83953.8", "0.01188438", "0", "1"]], "ts": "1742554957604", "checksum": 614527989, "seqId": 49927371126, "prevSeqId": 49927371110}], "record_time": 1742554957.625506, "EXCHANGE": "OKX"}
{"arg": {"channel": "books", "instId": "BTC-USDT"}, "action": "update", "data": [{"asks": [["84099.7", "0", "0", "0"], ["84104", "0.069611", "0", "4"], ["84112.3", "0.0103941", "0", "1"], ["84117.1", "0.25568986", "0", "2"], ["84155.8", "0.01125662", "0", "1"], ["84159.9", "0", "0", "0"]], "bids": [["84059.7", "0.2379432", "0", "1"], ["84058.8", "0.32176076", "0", "2"], ["84058", "0.0103941", "0", "1"], ["84043.1", "0", "0", "0"], ["84037.6", "0.0183216", "0", "1"], ["84029.2", "0.12268543", "0", "1"], ["83971.5", "0.00001197", "0", "1"], ["83966.9", "0.18321602", "0", "1"], ["83933.3", "0", "0", "0"], ["83932.9", "0", "0", "0"]], "ts": "1742554957704", "checksum": -1103426192, "seqId": 49927371157, "prevSeqId": 49927371126}], "record_time": 1742554957.727814, "EXCHANGE": "OKX"}
{"arg": {"channel": "books", "instId": "BTC-USDT"}, "action": "update", "data": [{"asks": [["84098.4", "0", "0", "0"], ["84102.3", "0.005", "0", "1"], ["84108.9", "0.01189547", "0", "1"], ["84112.3", "0.0153941", "0", "2"], ["84255.6", "0", "0", "0"]], "bids": [["84088.2", "0.005", "0", "1"], ["84078.1", "0.005", "0", "1"], ["84054.4", "0.08", "0", "2"], ["84053.6", "0.04", "0", "1"], ["84052.8", "0.026", "0", "2"], ["83934.2", "0", "0", "0"], ["83934.1", "0", "0", "0"], ["83933.8", "0", "0", "0"]], "ts": "1742554957804", "checksum": 119926501, "seqId": 49927371167, "prevSeqId": 49927371157}], "record_time": 1742554957.84861, "EXCHANGE": "OKX"}
{"arg": {"channel": "books", "instId": "BTC-USDT"}, "action": "update", "data": [{"asks": [["84097.7", "0.07406982", "0", "1"], ["84097.9", "0", "0", "0"], ["84098", "0", "0", "0"], ["84115.3", "0.23795002", "0", "1"], ["84117.1", "0.01774536", "0", "1"], ["84129.6", "0.08", "0", "2"], ["84130.4", "0.29453712", "0", "4"], ["84131.2", "0", "0", "0"]], "bids": [["84090", "0.85374601", "0", "19"], ["84059.7", "0", "0", "0"], ["84054.9", "0.23795175", "0", "1"]], "ts": "1742554957904", "checksum": -1920711128, "seqId": 49927371181, "prevSeqId": 49927371167}], "record_time": 1742554957.906386, "EXCHANGE": "OKX"}
{"arg": {"channel": "books", "instId": "BTC-USDT"}, "action": "update", "data": [{"asks": [["84113.6", "0.23795337", "0", "1"], ["84115.3", "0", "0", "0"]], "bids": [["84090", "0.65124601", "0", "18"]], "ts": "1742554958004", "checksum": 1266924333, "seqId": 49927371184, "prevSeqId": 49927371181}], "record_time": 1742554958.007953, "EXCHANGE": "OKX"}
{"arg": {"channel": "books", "instId": "BTC-USDT"}, "action": "update", "data": [{"asks": [["84113.6", "0.23795624", "0", "1"], ["84122.6", "0.08991011", "0", "1"], ["84129.6", "0", "0", "0"], ["84130.4", "0.33453712", "0", "5"], ["84131.2", "0.03999999", "0", "1"], ["84132.7", "0", "0", "0"], ["84176.2", "0", "0", "0"], ["84255.6", "0.01493332", "0", "1"], ["84256.2", "0.2025", "0", "1"]], "bids": [["84090", "0.65125601", "0", "19"], ["84051", "0.2", "0", "1"], ["83942.5", "0", "0", "0"]], "ts": "1742554958104", "checksum": -1698138186, "seqId": 49927371209, "prevSeqId": 49927371184}], "record_time": 1742554958.105248, "EXCHANGE": "OKX"}
{"arg": {"channel": "books", "instId": "BTC-USDT"}, "action": "update", "data": [{"asks": [["84104", "0.06515", "0", "3"], ["84112.3", "0.25335066", "0", "3"], ["84113.6", "0", "0", "0"], ["84183.8", "0", "0", "0"], ["84206.1", "0.01425074", "0", "1"], ["84257.6", "0.00008291", "0", "1"]], "bids": [["84090", "0.85375601", "0", "20"], ["83971.3", "0.0054", "0", "1"]], "ts": "1742554958204", "checksum": 1528932648, "seqId": 49927371221, "prevSeqId": 49927371209}], "record_time": 1742554958.204138, "EXCHANGE": "OKX"}
{"arg": {"channel": "books", "instId": "BTC-USDT"}, "action": "update", "data": [{"asks": [["84102.3", "0.01", "0", "2"], ["84104.4", "0.004461", "0", "1"], ["84112.3", "0.0203941", "0", "3"], ["84113.6", "0.23795633", "0", "1"], ["84129.6", "0.08", "0", "2"], ["84130.4", "0.29453712", "0", "4"], ["84131.2", "0", "0", "0"], ["84183", "0.00118788", "0", "1"], ["84255.6", "0", "0", "0"], ["84256.2", "0", "0", "0"], ["84257.6", "0", "0", "0"]], "bids": [["84090", "0.85842868", "0", "23"], ["84088.2", "0.01", "0", "2"], ["84079.5", "0.000015", "0", "1"], ["84079.3", "0", "0", "0"], ["84078.1", "0.01", "0", "2"], ["83972.9", "0.00953491", "0", "2"]], "ts": "1742554958304", "checksum": 1033768668, "seqId": 49927371259, "prevSeqId": 49927371221}], "record_time": 1742554958.34513, "EXCHANGE": "OKX"}
{"arg": {"channel": "books", "instId": "BTC-USDT"}, "action": "update", "data": [{"asks": [["84097.4", "0.13723482", "0", "1"], ["84097.5", "0.2", "0", "1"], ["84097.7", "0", "0", "0"], ["84113.6", "0.23795611", "0", "1"], ["84255", "0", "0", "0"]], "bids": [], "ts": "1742554958404", "checksum": 1455002119, "seqId": 49927371266, "prevSeqId": 49927371259}], "record_time": 1742554958.404939, "EXCHANGE": "OKX"}
{"arg": {"channel": "books", "instId": "BTC-USDT"}, "action": "update", "data": [{"asks": [["84117.6", "0", "0", "0"], ["84118.5", "0", "0", "0"], ["84147.9", "0.40664892", "0", "1"], ["84148", "1", "0", "1"], ["84255", "0.00001181", "0", "1"], ["84255.6", "0.01493332", "0", "1"]], "bids": [["84066.3", "0.35217178", "0", "2"], ["84063.9", "0", "0", "0"], ["84037.4", "0.59149287", "0", "1"], ["84034.4", "0.918373", "0", "1"], ["84000.1", "1.20390681", "0", "2"], ["83934.2", "0.35579296", "0", "1"]], "ts": "1742554958504", "checksum": 1455002119, "seqId": 49927371275, "prevSeqId": 49927371266}], "record_time": 1742554958.516319, "EXCHANGE": "OKX"}
{"arg": {"channel": "books", "instId": "BTC-USDT"}, "action": "update", "data": [{"asks": [["84097.4", "0.07723482", "0", "1"], ["84097.5", "0", "0", "0"], ["84104.3", "0.003567", "0", "1"], ["84104.4", "0", "0", "0"], ["84110", "0.0332", "0", "2"], ["84116.9", "1.53194083", "0", "1"], ["84117.1", "0", "0", "0"], ["84122.1", "0.01774536", "0", "1"], ["84133", "0.20001", "0", "2"], ["84146.4", "2.72911642", "0", "1"], ["84255.6", "0", "0", "0"]], "bids": [["84090", "0.85757868", "0", "21"], ["84066.3", "0.89036313", "0", "3"], ["84064.7", "0", "0", "0"], ["84064.5", "1.61575251", "0", "1"], ["84055", "0.01774536", "0", "1"], ["84037.4", "1.42254117", "0", "2"], ["84035.1", "2.87390324", "0", "1"], ["84000.5", "0.00001501", "0", "1"], ["84000.1", "0.00597332", "0", "1"], ["83934.7", "0", "0", "0"], ["83934.2", "0", "0", "0"]], "ts": "1742554958604", "checksum": 1702607259, "seqId": 49927371302, "prevSeqId": 49927371275}], "record_time": 1742554958.604472, "EXCHANGE": "OKX"}
{"arg": {"channel": "books", "instId": "BTC-USDT"}, "action": "update", "data": [{"asks": [["84098.4", "0.01189695", "0", "1"], ["84106.4", "0.17838", "0", "1"], ["84108.9", "0", "0", "0"], ["84128.3", "0", "0", "0"], ["84129.1", "0", "0", "0"], ["84138.8", "0.0945107", "0", "1"], ["84141.8", "0", "0", "0"], ["84150.2", "0.00420106", "0", "1"], ["84246.9", "0", "0", "0"], ["84255.6", "0.01493332", "0", "1"], ["84256.2", "0.2025", "0", "1"], ["84257.6", "0.00008291", "0", "1"], ["84258.1", "0.00003542", "0", "1"]], "bids": [["84076.2", "0.17838", "0", "1"], ["84067.5", "0.17821722", "0", "1"], ["84066.1", "0", "0", "0"], ["84062.8", "0.17552246", "0", "1"], ["84062.5", "0", "0", "0"], ["84057.8", "0.11927094", "0", "2"], ["84045.8", "0.20672021", "0", "3"], ["84045.1", "0.00005207", "0", "1"], ["84044.2", "0.01804", "0", "1"], ["84042.3", "0.17838", "0", "1"], ["84041.5", "0", "0", "0"], ["84000.5", "0.00017763", "0", "2"], ["83934.7", "0.03", "0", "1"], ["83934.2", "0.35579296", "0", "1"]], "ts": "1742554958704", "checksum": 1756467154, "seqId": 49927371333, "prevSeqId": 49927371302}], "record_time": 1742554958.705288, "EXCHANGE": "OKX"}
{"arg": {"channel": "books", "instId": "BTC-USDT"}, "action": "update", "data": [{"asks": [["84090.1", "0.45395123", "0", "6"], ["84104.3", "0", "0", "0"], ["84105.1", "0.67570806", "0", "2"], ["84116.5", "0.01774536", "0", "1"], ["84122.1", "0", "0", "0"], ["84258.2", "0.35579296", "0", "1"]], "bids": [["84064.7", "0.01774536", "0", "1"], ["84055", "0", "0", "0"]], "ts": "1742554958804", "checksum": -1962042759, "seqId": 49927371341, "prevSeqId": 49927371333}], "record_time": 1742554958.803817, "EXCHANGE": "OKX"}
{"arg": {"channel": "books", "instId": "BTC-USDT"}, "action": "update", "data": [{"asks": [], "bids": [["84050.9", "0.356775", "0", "2"], ["84020.4", "0.12487", "0", "1"], ["83999.4", "0.20726598", "0", "2"], ["83934.2", "0", "0", "0"]], "ts": "1742554958904", "checksum": -1962042759, "seqId": 49927371346, "prevSeqId": 49927371341}], "record_time": 1742554958.904041, "EXCHANGE": "OKX"}
{"arg": {"channel": "books", "instId": "BTC-USDT"}, "action": "update", "data": [{"asks": [], "bids": [["84084", "0.21962029", "0", "5"], ["84082.6", "0", "0", "0"], ["83934.2", "0.35579296", "0", "1"]], "ts": "1742554959004", "checksum": 880720760, "seqId": 49927371349, "prevSeqId": 49927371346}], "record_time": 1742554959.04935, "EXCHANGE": "OKX"}
{"arg": {"channel": "books", "instId": "BTC-USDT"}, "action": "update", "data": [{"asks": [["84090.1", "0.33526815", "0", "4"], ["84097.6", "0", "0", "0"], ["84100.4", "0.01055", "0", "1"], ["84103.3", "0", "0", "0"], ["84103.4", "0.03218619", "0", "1"], ["84105.1", "0.67004706", "0", "1"], ["84110.3", "0", "0", "0"], ["84110.4", "0.03215652", "0", "1"], ["84117.3", "0", "0", "0"], ["84117.4", "0.06614503", "0", "2"], ["84129.1", "0.12487", "0", "1"], ["84150.2", "0.12907106", "0", "2"]], "bids": [["84090", "0.85836868", "0", "22"], ["84088.8", "0.10431408", "0", "1"], ["84086.8", "0.01339", "0", "1"], ["84084", "0.23944011", "0", "5"], ["84081.3", "0.133783", "0", "1"], ["84076.1", "0.21860406", "0", "3"], ["84076", "0.25802498", "0", "4"], ["84069.1", "0.03287921", "0", "1"], ["84069", "0", "0", "0"], ["84066.1", "0.12487", "0", "1"], ["84062.1", "0.06786858", "0", "1"], ["84062", "0.00024809", "0", "1"], ["84045.1", "0.12492207", "0", "2"], ["83935.6", "0", "0", "0"], ["83935.3", "0", "0", "0"], ["83934.9", "0", "0", "0"], ["83934.7", "0", "0", "0"], ["83934.2", "0", "0", "0"]], "ts": "1742554959104", "checksum": -1427228224, "seqId": 49927371377, "prevSeqId": 49927371349}], "record_time": 1742554959.104975, "EXCHANGE": "OKX"}
{"arg": {"channel": "books", "instId": "BTC-USDT"}, "action": "update", "data": [{"asks": [["84112.4", "0.27272745", "0", "2"], ["84113.6", "0", "0", "0"], ["84128.3", "0.24973", "0", "1"], ["84149.3", "0.24973", "0", "1"], ["84258.2", "0", "0", "0"]], "bids": [["84075.5", "0.16596718", "0", "1"], ["84072.5", "0", "0", "0"], ["84067.5", "0.35659722", "0", "2"], ["84065.2", "0.24973", "0", "1"], ["84056.4", "0.23795523", "0", "1"], ["84056.3", "0.51699", "0", "1"], ["84054.9", "0", "0", "0"], ["84050.9", "0.000015", "0", "1"], ["84044.2", "0.26777", "0", "2"], ["84042.3", "0", "0", "0"]], "ts": "1742554959204", "checksum": -1427228224, "seqId": 49927371395, "prevSeqId": 49927371377}], "record_time": 1742554959.220662, "EXCHANGE": "OKX"}
{"arg": {"channel": "books", "instId": "BTC-USDT"}, "action": "update", "data": [{"asks": [["84106.8", "0.005619", "0", "1"], ["84112.4", "0.03477159", "0", "1"], ["84113.6", "0.23795544", "0", "1"], ["84257.6", "0", "0", "0"], ["84258.1", "0", "0", "0"]], "bids": [["84051", "0", "0", "0"], ["84020.4", "0", "0", "0"], ["83999.4", "0.08239598", "0", "1"], ["83935.6", "0.00001925", "0", "1"], ["83935.3", "0.2025", "0", "1"]], "ts": "1742554959304", "checksum": -1427228224, "seqId": 49927371404, "prevSeqId": 49927371395}], "record_time": 1742554959.348699, "EXCHANGE": "OKX"}
{"arg": {"channel": "books", "instId": "BTC-USDT"}, "action": "update", "data": [{"asks": [["84106.4", "0.53514", "0", "2"], ["84106.8", "0", "0", "0"], ["84113.7", "0.64667637", "0", "2"], ["84143.3", "1.02096771", "0", "2"], ["84257.6", "0.00008291", "0", "1"]], "bids": [["84076.2", "0.53514", "0", "2"], ["84062.5", "0.12487", "0", "1"], ["84041.5", "0.12487", "0", "1"], ["84029.2", "0.46210727", "0", "2"], ["83935.6", "0", "0", "0"], ["83935.3", "0", "0", "0"]], "ts": "1742554959404", "checksum": -1427228224, "seqId": 49927371414, "prevSeqId": 49927371404}], "record_time": 1742554959.403982, "EXCHANGE": "OKX"}
{"arg": {"channel": "books", "instId": "BTC-USDT"}, "action": "update", "data": [{"asks": [["84090.1", "0.33170115", "0", "3"], ["84133", "0.00001", "0", "1"]], "bids": [], "ts": "1742554959504", "checksum": 1414297223, "seqId": 49927371416, "prevSeqId": 49927371414}], "record_time": 1742554959.510795, "EXCHANGE": "OKX"}
{"arg": {"channel": "books", "instId": "BTC-USDT"}, "action": "update", "data": [{"asks": [["84106.8", "0.0005775", "0", "1"], ["84228.3", "0.01188438", "0", "1"], ["84233.5", "0.00002296", "0", "1"], ["84256.2", "0", "0", "0"], ["84257.6", "0", "0", "0"]], "bids": [["84040.2", "0.1054", "0", "2"], ["84037.9", "0.01188438", "0", "1"], ["83936.1", "0", "0", "0"]], "ts": "1742554959604", "checksum": 1414297223, "seqId": 49927371422, "prevSeqId": 49927371416}], "record_time": 1742554959.604275, "EXCHANGE": "OKX"}
{"arg": {"channel": "books", "instId": "BTC-USDT"}, "action": "update", "data": [{"asks": [["84106.8", "0", "0", "0"], ["84107.1", "0.0002355", "0", "1"]], "bids": [["83939.1", "0.10703", "0", "1"], ["83936.8", "0", "0", "0"]], "ts": "1742554959804", "checksum": 1414297223, "seqId": 49927371432, "prevSeqId": 49927371422}], "record_time": 1742554959.803403, "EXCHANGE": "OKX"}
{"arg": {"channel": "books", "instId": "BTC-USDT"}, "action": "update", "data": [{"asks": [["84113.6", "0.23795705", "0", "1"]], "bids": [["84078.7", "0.35676", "0", "1"], ["84076.2", "0", "0", "0"], ["83987", "0.0061", "0", "1"], ["83938.2", "0", "0", "0"]], "ts": "1742554959904", "checksum": 506640177, "seqId": 49927371447, "prevSeqId": 49927371432}], "record_time": 1742554959.908744, "EXCHANGE": "OKX"}
{"arg": {"channel": "books", "instId": "BTC-USDT"}, "action": "update", "data": [{"asks": [["84112.3", "0.25835142", "0", "4"], ["84113.6", "0", "0", "0"], ["84125", "0", "0", "0"], ["84256.2", "0.2025", "0", "1"], ["84257.6", "0.00008291", "0", "1"]], "bids": [["84086.6", "0.11898202", "0", "1"], ["84084", "0.20623029", "0", "4"], ["84083.9", "0.01596287", "0", "1"], ["84078.7", "0.53514", "0", "2"], ["84056.4", "0", "0", "0"], ["84054.9", "0.23795732", "0", "1"], ["83938.4", "0", "0", "0"]], "ts": "1742554960004", "checksum": -541707458, "seqId": 49927371476, "prevSeqId": 49927371447}], "record_time": 1742554960.004085, "EXCHANGE": "OKX"}
{"arg": {"channel": "books", "instId": "BTC-USDT"}, "action": "update", "data": [{"asks": [["84112.3", "0.0203941", "0", "3"], ["84113.6", "0.23795686", "0", "1"], ["84116.4", "0.133783", "0", "1"], ["84129.6", "0", "0", "0"], ["84130.4", "0.33453712", "0", "5"], ["84131.2", "0.03999999", "0", "1"], ["84256.2", "0", "0", "0"], ["84257.6", "0", "0", "0"]], "bids": [["84090", "0.85757868", "0", "21"], ["84056.4", "0.23795708", "0", "1"], ["84054.9", "0", "0", "0"], ["84038", "0.01832237", "0", "1"], ["84037.6", "0", "0", "0"]], "ts": "1742554960104", "checksum": -2052473877, "seqId": 49927371501, "prevSeqId": 49927371476}], "record_time": 1742554960.103582, "EXCHANGE": "OKX"}
{"arg": {"channel": "books", "instId": "BTC-USDT"}, "action": "update", "data": [{"asks": [["84116.3", "0.01774536", "0", "1"], ["84116.5", "0", "0", "0"], ["84129.6", "0.08", "0", "2"], ["84130.4", "0.29453712", "0", "4"], ["84131.2", "0", "0", "0"]], "bids": [["84076.2", "0.35676", "0", "1"], ["83939.1", "0", "0", "0"]], "ts": "1742554960204", "checksum": -2052473877, "seqId": 49927371513, "prevSeqId": 49927371501}], "record_time": 1742554960.205329, "EXCHANGE": "OKX"}
{"arg": {"channel": "books", "instId": "BTC-USDT"}, "action": "update", "data": [{"asks": [["84107.1", "0", "0", "0"], ["84113.6", "0.23795622", "0", "1"], ["84256.2", "0.2025", "0", "1"]], "bids": [["84056.4", "0.23795622", "0", "1"], ["84051", "0.2", "0", "1"], ["83939.5", "0", "0", "0"]], "ts": "1742554960304", "checksum": -2052473877, "seqId": 49927371530, "prevSeqId": 49927371513}], "record_time": 1742554960.3059, "EXCHANGE": "OKX"}
{"arg": {"channel": "books", "instId": "BTC-USDT"}, "action": "update", "data": [{"asks": [["84113.6", "0.23795522", "0", "1"], ["84119", "0.23631349", "0", "1"], ["84256.2", "0", "0", "0"]], "bids": [["84058.8", "0.44149517", "0", "3"], ["84051", "0", "0", "0"], ["84020.4", "0.04947623", "0", "1"]], "ts": "1742554960404", "checksum": -2052473877, "seqId": 49927371542, "prevSeqId": 49927371530}], "record_time": 1742554960.404989, "EXCHANGE": "OKX"}
{"arg": {"channel": "books", "instId": "BTC-USDT"}, "action": "update", "data": [{"asks": [["84099.3", "0.003567", "0", "1"], ["84104.1", "0.004461", "0", "1"], ["84113.6", "0", "0", "0"], ["84115.3", "0.23795483", "0", "1"], ["84132", "0.2", "0", "1"], ["84215.9", "0.183152", "0", "1"], ["84236.7", "0", "0", "0"], ["84254.5", "0", "0", "0"], ["84255", "0", "0", "0"], ["84255.6", "0", "0", "0"]], "bids": [["84086.6", "0", "0", "0"], ["84084.8", "0.11898462", "0", "1"]], "ts": "1742554960504", "checksum": -1604494519, "seqId": 49927371551, "prevSeqId": 49927371542}], "record_time": 1742554960.507967, "EXCHANGE": "OKX"}
{"arg": {"channel": "books", "instId": "BTC-USDT"}, "action": "update", "data": [{"asks": [["84155.8", "0", "0", "0"], ["84156.2", "0.01126156", "0", "1"]], "bids": [["84090", "0.85829868", "0", "22"], ["84076.2", "0", "0", "0"], ["84038", "0.0183223", "0", "1"], ["83966.9", "0.183223", "0", "1"], ["83939.5", "0.00007329", "0", "1"]], "ts": "1742554960604", "checksum": -1868717019, "seqId": 49927371567, "prevSeqId": 49927371551}], "record_time": 1742554960.603892, "EXCHANGE": "OKX"}
{"arg": {"channel": "books", "instId": "BTC-USDT"}, "action": "update", "data": [{"asks": [["84090.1", "0.33110655", "0", "3"], ["84103.4", "0", "0", "0"], ["84110.4", "0", "0", "0"], ["84117.4", "0.00420403", "0", "1"], ["84254.5", "0.00001063", "0", "1"], ["84255", "0.00001181", "0", "1"]], "bids": [["84076.1", "0.1871514", "0", "2"], ["84069.1", "0", "0", "0"], ["84062.1", "0", "0", "0"], ["83939.1", "0.10703", "0", "1"], ["83938.4", "0.00001883", "0", "1"]], "ts": "1742554960704", "checksum": -1109096128, "seqId": 49927371581, "prevSeqId": 49927371567}], "record_time": 1742554960.703802, "EXCHANGE": "OKX"}
{"arg": {"channel": "books", "instId": "BTC-USDT"}, "action": "update", "data": [{"asks": [["84099.3", "0", "0", "0"], ["84126.7", "0.003567", "0", "1"]], "bids": [], "ts": "1742554960804", "checksum": -791406297, "seqId": 49927371588, "prevSeqId": 49927371581}], "record_time": 1742554960.805257, "EXCHANGE": "OKX"}
{"arg": {"channel": "books", "instId": "BTC-USDT"}, "action": "update", "data": [{"asks": [["84132", "0", "0", "0"], ["84255.6", "0.01493332", "0", "1"]], "bids": [], "ts": "1742554960904", "checksum": -791406297, "seqId": 49927371590, "prevSeqId": 49927371588}], "record_time": 1742554960.904907, "EXCHANGE": "OKX"}
{"arg": {"channel": "books", "instId": "BTC-USDT"}, "action": "update", "data": [{"asks": [["84104.1", "0", "0", "0"], ["84172.1", "0.0712826", "0", "1"], ["84256.2", "0.2025", "0", "1"]], "bids": [["84077.8", "0.03713992", "0", "1"], ["84076.2", "1", "0", "1"], ["84007", "0.07142254", "0", "1"], ["83938.4", "0", "0", "0"]], "ts": "1742554961004", "checksum": -535822492, "seqId": 49927371600, "prevSeqId": 49927371590}], "record_time": 1742554961.003845, "EXCHANGE": "OKX"}
{"arg": {"channel": "books", "instId": "BTC-USDT"}, "action": "update", "data": [{"asks": [["84105", "0.004446", "0", "1"], ["84113.6", "0.23795535", "0", "1"], ["84115.3", "0", "0", "0"], ["84168.4", "0.08045081", "0", "1"], ["84172.1", "0", "0", "0"]], "bids": [["84090", "0.85830868", "0", "23"], ["84077.5", "1", "0", "1"], ["84076.2", "0", "0", "0"], ["84053.6", "0.066", "0", "3"], ["84052.8", "0.013", "0", "1"], ["84052", "0", "0", "0"], ["84036.3", "0.59964265", "0", "1"], ["84036.2", "0", "0", "0"], ["84007", "0", "0", "0"], ["83938.4", "0.00001883", "0", "1"], ["83938.2", "0.6000735", "0", "2"]], "ts": "1742554961104", "checksum": 1918387162, "seqId": 49927371624, "prevSeqId": 49927371600}], "record_time": 1742554961.10369, "EXCHANGE": "OKX"}
{"arg": {"channel": "books", "instId": "BTC-USDT"}, "action": "update", "data": [{"asks": [["84113.6", "0.23795501", "0", "1"]], "bids": [], "ts": "1742554961204", "checksum": 1918387162, "seqId": 49927371637, "prevSeqId": 49927371624}], "record_time": 1742554961.20613, "EXCHANGE": "OKX"}
{"arg": {"channel": "books", "instId": "BTC-USDT"}, "action": "update", "data": [{"asks": [["84098.2", "0.00772906", "0", "1"], ["84104.4", "0.03728865", "0", "1"], ["84113.6", "0", "0", "0"], ["84115.3", "0.23795498", "0", "1"], ["84116.9", "0", "0", "0"], ["84144", "0", "0", "0"], ["84146.4", "0", "0", "0"], ["84257.6", "0.00008291", "0", "1"], ["84258.1", "0.00003542", "0", "1"]], "bids": [["84066.3", "0.35217178", "0", "2"], ["84064.5", "0", "0", "0"], ["83995.5", "0.48279807", "0", "1"]], "ts": "1742554961304", "checksum": -1990928560, "seqId": 49927371651, "prevSeqId": 49927371637}], "record_time": 1742554961.304496, "EXCHANGE": "OKX"}
{"arg": {"channel": "books", "instId": "BTC-USDT"}, "action": "update", "data": [{"asks": [["84090.1", "0.12135601", "0", "2"], ["84100.4", "0", "0", "0"], ["84102.8", "0.05421531", "0", "1"], ["84102.9", "0", "0", "0"], ["84103.4", "0.01055", "0", "1"], ["84103.7", "0", "0", "0"], ["84103.9", "0", "0", "0"], ["84105", "0.03259713", "0", "1"], ["84105.1", "0.70320327", "0", "2"], ["84105.7", "0.032977", "0", "1"], ["84106.2", "0", "0", "0"], ["84108.3", "0.0076605", "0", "1"], ["84109.7", "0.03166", "0", "1"], ["84110.2", "0.00001197", "0", "1"], ["84112", "0.10733597", "0", "4"], ["84112.4", "0", "0", "0"], ["84112.5", "0.00006", "0", "1"], ["84113.7", "0.2893381", "0", "2"], ["84113.8", "0.03480256", "0", "1"], ["84116.3", "0", "0", "0"], ["84116.9", "1.5839555", "0", "1"], ["84119", "0", "0", "0"], ["84119.1", "0.11893621", "0", "1"], ["84119.7", "0", "0", "0"], ["84120.5", "0.06168573", "0", "1"], ["84121.2", "0", "0", "0"], ["84121.4", "0.06187795", "0", "1"], ["84122.1", "0.01774536", "0", "1"], ["84122.5", "0.06395155", "0", "1"], ["84126.5", "0.31770325", "0", "1"], ["84127", "0.03693417", "0", "1"], ["84143.3", "0.27006173", "0", "1"], ["84144", "0.00004312", "0", "1"], ["84146.4", "2.9335945", "0", "1"], ["84165.3", "0.14257672", "0", "2"], ["84215.3", "0.13346719", "0", "2"], ["84256.2", "0", "0", "0"], ["84257.6", "0", "0", "0"], ["84258.1", "0", "0", "0"]], "bids": [["84090", "1.15830868", "0", "25"], ["84089.9", "0.01339", "0", "1"], ["84086.8", "0", "0", "0"], ["84083.6", "0.04019", "0", "1"], ["84079.5", "0", "0", "0"], ["84077.7", "0", "0", "0"], ["84077", "0.03076188", "0", "1"], ["84076.4", "0.03210912", "0", "1"], ["84076.3", "0.03545937", "0", "1"], ["84075.7", "0", "0", "0"], ["84075", "0", "0", "0"], ["84074.5", "0", "0", "0"], ["84070", "0.03779297", "0", "3"], ["84068.2", "0.03102136", "0", "1"], ["84067.6", "0.03515185", "0", "1"], ["84066.9", "0", "0", "0"], ["84066.3", "0.44789141", "0", "2"], ["84064.7", "0", "0", "0"], ["84064.5", "1.60633751", "0", "1"], ["84061", "0.06426162", "0", "1"], ["84060.5", "0.06396632", "0", "1"], ["84059.6", "0", "0", "0"], ["84059.5", "0.06500013", "0", "1"], ["84058.9", "0.23795461", "0", "1"], ["84058.8", "0.37452203", "0", "2"], ["84058.2", "0", "0", "0"], ["84056.4", "0", "0", "0"], ["84051", "0.2", "0", "1"], ["84049.7", "0.01774536", "0", "1"], ["84037.4", "0.59149287", "0", "1"], ["84035.1", "0", "0", "0"], ["84011.1", "0.56046965", "0", "2"], ["84000.2", "0.14285662", "0", "2"], ["83938.4", "0", "0", "0"], ["83938.2", "0", "0", "0"]], "ts": "1742554961404", "checksum": -741419116, "seqId": 49927371745, "prevSeqId": 49927371651}], "record_time": 1742554961.406585, "EXCHANGE": "OKX"}
{"arg": {"channel": "books", "instId": "BTC-USDT"}, "action": "update", "data": [{"asks": [["84107.5", "0.00352393", "0", "1"], ["84108.3", "0", "0", "0"], ["84129.6", "0", "0", "0"], ["84130.4", "0.33453712", "0", "5"], ["84131.2", "0.03999999", "0", "1"]], "bids": [["84083.3", "0.00866551", "0", "3"], ["84051", "0", "0", "0"], ["83995", "0.0061", "0", "1"], ["83987.1", "0.0061", "0", "1"], ["83939.1", "0", "0", "0"]], "ts": "1742554961504", "checksum": -2120904939, "seqId": 49927371758, "prevSeqId": 49927371745}], "record_time": 1742554961.503944, "EXCHANGE": "OKX"}
{"arg": {"channel": "books", "instId": "BTC-USDT"}, "action": "update", "data": [{"asks": [["84105.7", "0.037438", "0", "2"], ["84116.3", "0.01774536", "0", "1"], ["84122.1", "0", "0", "0"], ["84129.6", "0.08", "0", "2"], ["84130.4", "0.29453712", "0", "4"], ["84131.2", "0", "0", "0"]], "bids": [["84090", "1.15827668", "0", "25"], ["84083.3", "0.00833551", "0", "2"], ["84064.7", "0.01774536", "0", "1"], ["84049.7", "0", "0", "0"], ["84037.4", "1.41816122", "0", "2"], ["84036.2", "2.85930339", "0", "1"], ["83995.5", "0", "0", "0"]], "ts": "1742554961604", "checksum": -1959001904, "seqId": 49927371774, "prevSeqId": 49927371758}], "record_time": 1742554961.603724, "EXCHANGE": "OKX"}
{"arg": {"channel": "books", "instId": "BTC-USDT"}, "action": "update", "data": [{"asks": [["84105", "0.03338518", "0", "1"], ["84105.1", "0.4468265", "0", "2"], ["84105.4", "0.15043589", "0", "2"], ["84105.7", "0.03261564", "0", "1"], ["84108.2", "0.05203713", "0", "2"], ["84109.4", "0.50268699", "0", "2"], ["84110.1", "1.22932713", "0", "5"], ["84112", "0.10626393", "0", "4"], ["84112.4", "0.03192166", "0", "1"], ["84113.7", "0.29254382", "0", "2"], ["84113.8", "0.03182497", "0", "1"], ["84115.3", "0", "0", "0"], ["84116.3", "0.25569304", "0", "2"], ["84119.4", "0.07005711", "0", "1"], ["84120.5", "0.06401066", "0", "1"], ["84121.4", "0.06743588", "0", "1"], ["84122.5", "0.06759908", "0", "1"], ["84126.7", "0", "0", "0"]], "bids": [["84084.8", "0", "0", "0"], ["84083.4", "0.0000225", "0", "1"], ["84078.9", "1", "0", "1"], ["84078.1", "0.0418016", "0", "3"], ["84077.5", "0", "0", "0"], ["84077", "0.03239575", "0", "1"], ["84076.4", "0.03228726", "0", "1"], ["84076.3", "0.03159167", "0", "1"], ["84071.1", "0.03270012", "0", "1"], ["84070", "0.03981445", "0", "3"], ["84068.2", "0.0327104", "0", "1"], ["84067.6", "0.03179182", "0", "1"], ["84064.1", "0.06147928", "0", "1"], ["84061", "0.07029784", "0", "1"], ["84060.5", "0.06780963", "0", "1"], ["84059.5", "0.06183406", "0", "1"], ["83939.7", "0", "0", "0"], ["83939.5", "0", "0", "0"]], "ts": "1742554961704", "checksum": -934746196, "seqId": 49927371849, "prevSeqId": 49927371774}], "record_time": 1742554961.705068, "EXCHANGE": "OKX"}
{"arg": {"channel": "books", "instId": "BTC-USDT"}, "action": "update", "data": [{"asks": [["84107.8", "0.000024", "0", "1"], ["84108.8", "1", "0", "1"], ["84110.1", "0.22932713", "0", "4"], ["84255", "0", "0", "0"], ["84255.6", "0", "0", "0"]], "bids": [["84090", "0.95827668", "0", "24"], ["84062", "0", "0", "0"], ["84059", "1", "0", "1"], ["84057.8", "0.11902285", "0", "1"], ["84053.5", "0", "0", "0"], ["83939.7", "0.03", "0", "1"]], "ts": "1742554961804", "checksum": -1204713922, "seqId": 49927371858, "prevSeqId": 49927371849}], "record_time": 1742554961.805623, "EXCHANGE": "OKX"}
{"arg": {"channel": "books", "instId": "BTC-USDT"}, "action": "update", "data": [{"asks": [["84105.1", "0.70307542", "0", "3"], ["84109.4", "0.24074734", "0", "1"], ["84206.1", "0", "0", "0"], ["84255", "0.00001181", "0", "1"]], "bids": [["84044", "0.0111", "0", "1"], ["84039.8", "0.19112431", "0", "3"], ["84035.6", "0.00576762", "0", "1"], ["83939.8", "0", "0", "0"], ["83939.7", "0", "0", "0"]], "ts": "1742554961904", "checksum": -1839514688, "seqId": 49927371868, "prevSeqId": 49927371858}], "record_time": 1742554961.905026, "EXCHANGE": "OKX"}
{"arg": {"channel": "books", "instId": "BTC-USDT"}, "action": "update", "data": [{"asks": [["84107.8", "0", "0", "0"], ["84115.3", "0.23795024", "0", "1"], ["84116.3", "0.01774536", "0", "1"], ["84133", "0.20001", "0", "2"], ["84146.2", "0", "0", "0"], ["84150.4", "0", "0", "0"], ["84154.6", "0", "0", "0"], ["84255.6", "0.01493332", "0", "1"], ["84256.2", "0.2025", "0", "1"], ["84257.2", "0.6", "0", "1"]], "bids": [["84059.6", "0.23795024", "0", "1"], ["84058.9", "0", "0", "0"]], "ts": "1742554962004", "checksum": -1839514688, "seqId": 49927371879, "prevSeqId": 49927371868}], "record_time": 1742554962.006401, "EXCHANGE": "OKX"}
{"arg": {"channel": "books", "instId": "BTC-USDT"}, "action": "update", "data": [{"asks": [["84107.8", "0.0000225", "0", "1"], ["84156.2", "0", "0", "0"], ["84157.4", "0.01126195", "0", "1"], ["84257.2", "0", "0", "0"]], "bids": [["84040.9", "0.01832212", "0", "1"], ["84038", "0", "0", "0"], ["83969.4", "0.18322126", "0", "1"], ["83966.9", "0", "0", "0"]], "ts": "1742554962104", "checksum": -1839514688, "seqId": 49927371891, "prevSeqId": 49927371879}], "record_time": 1742554962.104067, "EXCHANGE": "OKX"}
{"arg": {"channel": "books", "instId": "BTC-USDT"}, "action": "update", "data": [{"asks": [["84115.3", "0.23795356", "0", "1"], ["84128.2", "0.00927163", "0", "1"], ["84129.6", "0", "0", "0"], ["84130.4", "0.33453712", "0", "5"], ["84131.2", "0.03999999", "0", "1"], ["84132.4", "0.01473762", "0", "3"], ["84136.6", "0.00576762", "0", "1"], ["84255.6", "0", "0", "0"], ["84256.2", "0", "0", "0"]], "bids": [["84078.9", "0", "0", "0"], ["84077.5", "1", "0", "1"], ["84059.6", "0", "0", "0"], ["84056.4", "0.23795461", "0", "1"]], "ts": "1742554962204", "checksum": -1839514688, "seqId": 49927371911, "prevSeqId": 49927371891}], "record_time": 1742554962.234283, "EXCHANGE": "OKX"}
{"arg": {"channel": "books", "instId": "BTC-USDT"}, "action": "update", "data": [{"asks": [], "bids": [["84057.9", "0.23795337", "0", "1"], ["84056.4", "0", "0", "0"]], "ts": "1742554962304", "checksum": -1839514688, "seqId": 49927371913, "prevSeqId": 49927371911}], "record_time": 1742554962.304781, "EXCHANGE": "OKX"}
{"arg": {"channel": "books", "instId": "BTC-USDT"}, "action": "update", "data": [{"asks": [["84097.2", "0.12645231", "0", "1"], ["84097.3", "0.2", "0", "1"], ["84097.4", "0", "0", "0"], ["84105.3", "0.21243603", "0", "2"], ["84105.4", "0.11895551", "0", "1"], ["84105.6", "0.03430687", "0", "1"], ["84105.7", "0", "0", "0"], ["84111.9", "0.03488348", "0", "1"], ["84112", "0.0746", "0", "3"], ["84112.3", "0.05242598", "0", "4"], ["84112.4", "0", "0", "0"], ["84119.3", "0.06775396", "0", "1"], ["84119.4", "0", "0", "0"], ["84131", "1", "0", "1"], ["84133", "0.00001", "0", "1"], ["84254.5", "0", "0", "0"], ["84255", "0", "0", "0"]], "bids": [["84086.1", "0.01189796", "0", "1"], ["84083.8", "0", "0", "0"], ["84078.1", "0.01", "0", "2"], ["84078", "0.03083934", "0", "1"], ["84076.3", "0", "0", "0"], ["84076.2", "0.03323395", "0", "1"], ["84071.1", "0", "0", "0"], ["84071", "0.03906606", "0", "3"], ["84070", "0.005", "0", "2"], ["84069.9", "0.38768475", "0", "2"], ["84066.3", "0.93751048", "0", "1"], ["84064.1", "0", "0", "0"], ["84064", "0.06407108", "0", "1"], ["84011.1", "0.00001196", "0", "1"]], "ts": "1742554962404", "checksum": 544977154, "seqId": 49927371948, "prevSeqId": 49927371913}], "record_time": 1742554962.404865, "EXCHANGE": "OKX"}
{"arg": {"channel": "books", "instId": "BTC-USDT"}, "action": "update", "data": [{"asks": [["84131", "0", "0", "0"], ["84254.5", "0.00001063", "0", "1"]], "bids": [["84051", "0.2", "0", "1"], ["83940.4", "0", "0", "0"]], "ts": "1742554962504", "checksum": 544977154, "seqId": 49927371952, "prevSeqId": 49927371948}], "record_time": 1742554962.504035, "EXCHANGE": "OKX"}
{"arg": {"channel": "books", "instId": "BTC-USDT"}, "action": "update", "data": [{"asks": [["84097.2", "0.06645231", "0", "1"], ["84097.3", "0", "0", "0"], ["84105.3", "0.17821722", "0", "1"], ["84105.4", "0.15055035", "0", "2"], ["84105.6", "0", "0", "0"], ["84105.7", "0.03517106", "0", "1"], ["84111.9", "0", "0", "0"], ["84112", "0.10888225", "0", "4"], ["84112.3", "0.0203941", "0", "3"], ["84112.4", "0.0344242", "0", "1"], ["84119.3", "0", "0", "0"], ["84119.4", "0.06420232", "0", "1"], ["84255", "0.00001181", "0", "1"]], "bids": [["84078.1", "0.04270278", "0", "3"], ["84078", "0", "0", "0"], ["84076.3", "0.03292732", "0", "1"], ["84076.2", "0", "0", "0"], ["84071.1", "0.03090856", "0", "1"], ["84071", "0.005", "0", "2"], ["84070", "0.03851557", "0", "3"], ["84069.9", "0.35641581", "0", "1"], ["84064.1", "0.06820915", "0", "1"], ["84064", "0", "0", "0"]], "ts": "1742554962604", "checksum": 1192972721, "seqId": 49927371979, "prevSeqId": 49927371952}], "record_time": 1742554962.604743, "EXCHANGE": "OKX"}
{"arg": {"channel": "books", "instId": "BTC-USDT"}, "action": "update", "data": [{"asks": [["84098.4", "0", "0", "0"], ["84115.3", "0.23795187", "0", "1"], ["84165.3", "0.07128836", "0", "1"], ["84255.6", "0.01493332", "0", "1"]], "bids": [["84085.7", "0.1349462", "0", "2"], ["84074.3", "0.04", "0", "1"], ["84057.9", "0.23795187", "0", "1"], ["84000.2", "0.07142831", "0", "1"]], "ts": "1742554962804", "checksum": -1471836060, "seqId": 49927372010, "prevSeqId": 49927371979}], "record_time": 1742554962.804095, "EXCHANGE": "OKX"}
{"arg": {"channel": "books", "instId": "BTC-USDT"}, "action": "update", "data": [{"asks": [["84129.6", "0.08", "0", "2"], ["84130.4", "0.29453712", "0", "4"], ["84131.2", "0", "0", "0"], ["84165.3", "0.14257672", "0", "2"]], "bids": [["84000.2", "0.14285662", "0", "2"]], "ts": "1742554962904", "checksum": -1471836060, "seqId": 49927372022, "prevSeqId": 49927372010}], "record_time": 1742554962.905025, "EXCHANGE": "OKX"}
{"arg": {"channel": "books", "instId": "BTC-USDT"}, "action": "update", "data": [{"asks": [["84109", "0.35676", "0", "1"], ["84255.6", "0", "0", "0"]], "bids": [], "ts": "1742554963004", "checksum": -1471836060, "seqId": 49927372031, "prevSeqId": 49927372022}], "record_time": 1742554963.00437, "EXCHANGE": "OKX"}
{"arg": {"channel": "books", "instId": "BTC-USDT"}, "action": "update", "data": [{"asks": [["84115.3", "0.23795244", "0", "1"], ["84121.8", "0", "0", "0"], ["84131.9", "0", "0", "0"], ["84165.3", "0.07128836", "0", "1"], ["84255.6", "0.01493332", "0", "1"], ["84256.2", "0.2025", "0", "1"]], "bids": [["84057.9", "0.23795244", "0", "1"], ["84000.2", "0.07142831", "0", "1"]], "ts": "1742554963104", "checksum": -1471836060, "seqId": 49927372050, "prevSeqId": 49927372031}], "record_time": 1742554963.106231, "EXCHANGE": "OKX"}
{"arg": {"channel": "books", "instId": "BTC-USDT"}, "action": "update", "data": [{"asks": [["84090.1", "0.12102304", "0", "2"], ["84179.2", "0.0142553", "0", "1"], ["84256.2", "0", "0", "0"]], "bids": [["84090", "1.15827668", "0", "25"], ["84057.9", "0", "0", "0"], ["84056.4", "0.23795275", "0", "1"]], "ts": "1742554963204", "checksum": 2146549903, "seqId": 49927372058, "prevSeqId": 49927372050}], "record_time": 1742554963.207654, "EXCHANGE": "OKX"}
{"arg": {"channel": "books", "instId": "BTC-USDT"}, "action": "update", "data": [{"asks": [["84115.3", "0", "0", "0"], ["84116.3", "0.25569508", "0", "2"], ["84165.3", "0.14257672", "0", "2"], ["84257.2", "0.6", "0", "1"]], "bids": [["84078.9", "1", "0", "1"], ["84077.5", "0", "0", "0"], ["84059.6", "0.23794972", "0", "1"], ["84056.4", "0", "0", "0"], ["84000.2", "0.14285662", "0", "2"]], "ts": "1742554963304", "checksum": 2146549903, "seqId": 49927372071, "prevSeqId": 49927372058}], "record_time": 1742554963.304255, "EXCHANGE": "OKX"}
{"arg": {"channel": "books", "instId": "BTC-USDT"}, "action": "update", "data": [{"asks": [["84092", "0", "0", "0"], ["84103.5", "0.002", "0", "1"], ["84105", "0", "0", "0"], ["84105.1", "0.70283978", "0", "3"], ["84105.2", "0.0319898", "0", "2"], ["84105.4", "0.11895551", "0", "1"], ["84105.5", "0.05881355", "0", "2"], ["84105.7", "0", "0", "0"], ["84105.8", "0.03175418", "0", "1"], ["84112", "0.0746", "0", "3"], ["84112.1", "0.03191437", "0", "1"], ["84112.4", "0", "0", "0"], ["84112.5", "0.03249104", "0", "2"], ["84113.5", "0.002", "0", "1"], ["84113.7", "0.76476578", "0", "2"], ["84113.8", "0", "0", "0"], ["84113.9", "0.03153718", "0", "1"], ["84114", "0.03225866", "0", "1"], ["84116.3", "0.01774536", "0", "1"], ["84119.4", "0.23794453", "0", "1"], ["84119.5", "0.0651203", "0", "1"], ["84120.5", "0", "0", "0"], ["84120.6", "0.06732929", "0", "1"], ["84121.4", "0", "0", "0"], ["84121.6", "0.06610741", "0", "1"], ["84122.5", "0", "0", "0"], ["84122.6", "0.15535607", "0", "2"], ["84132", "0.2", "0", "1"], ["84143.3", "1.07964964", "0", "2"], ["84255.6", "0", "0", "0"], ["84257.2", "0", "0", "0"]], "bids": [["84088.2", "0.12897976", "0", "3"], ["84088.1", "0.002", "0", "1"], ["84085.7", "0.01596287", "0", "1"], ["84078.2", "0.30256657", "0", "5"], ["84078.1", "0.01", "0", "2"], ["84078", "0.002", "0", "1"], ["84077.1", "0.06000242", "0", "2"], ["84077", "0", "0", "0"], ["84076.5", "0.03508474", "0", "1"], ["84076.4", "0.03337363", "0", "1"], ["84076.3", "0", "0", "0"], ["84071.2", "0.39151241", "0", "2"], ["84071.1", "0", "0", "0"], ["84070.1", "0.03437164", "0", "1"], ["84070", "0.005", "0", "2"], ["84068.4", "0.03317467", "0", "1"], ["84068.2", "0", "0", "0"], ["84067.8", "0.03171231", "0", "1"], ["84067.6", "0", "0", "0"], ["84067.4", "0.29241011", "0", "2"], ["84064.2", "0.06490183", "0", "1"], ["84064.1", "0", "0", "0"], ["84062.8", "0.5636576", "0", "2"], ["84061.5", "0.23794453", "0", "1"], ["84061.1", "0.06307624", "0", "1"], ["84061", "0", "0", "0"], ["84060.7", "0.06641729", "0", "2"], ["84060.5", "0", "0", "0"], ["84059.6", "0.06168776", "0", "1"], ["84059.5", "0", "0", "0"]], "ts": "1742554963404", "checksum": 1745567221, "seqId": 49927372147, "prevSeqId": 49927372071}], "record_time": 1742554963.457539, "EXCHANGE": "OKX"}
{"arg": {"channel": "books", "instId": "BTC-USDT"}, "action": "update", "data": [{"asks": [["84107.5", "0", "0", "0"], ["84107.8", "0", "0", "0"], ["84119", "0.23794757", "0", "1"], ["84119.4", "0", "0", "0"], ["84132", "1.2", "0", "2"], ["84255.6", "0.01493332", "0", "1"], ["84256.2", "0.2025", "0", "1"]], "bids": [["84078.7", "0.35676", "0", "1"], ["84061.5", "0", "0", "0"], ["84059.7", "0.23794757", "0", "1"], ["84051", "0", "0", "0"], ["83940.4", "0.00002279", "0", "1"]], "ts": "1742554963504", "checksum": 1745567221, "seqId": 49927372159, "prevSeqId": 49927372147}], "record_time": 1742554963.50411, "EXCHANGE": "OKX"}
{"arg": {"channel": "books", "instId": "BTC-USDT"}, "action": "update", "data": [{"asks": [["84119", "0.23794846", "0", "1"], ["84129.6", "0", "0", "0"], ["84130.4", "0.33453712", "0", "5"], ["84131.2", "0.03999999", "0", "1"], ["84132", "0", "0", "0"], ["84257.2", "0.6", "0", "1"]], "bids": [["84090", "1.15834586", "0", "26"], ["84084", "0.26575265", "0", "5"], ["84081.2", "0.17838", "0", "1"], ["84062.8", "0.17552246", "0", "1"], ["84059.7", "0.23794846", "0", "1"], ["84059", "0", "0", "0"], ["84057.8", "0", "0", "0"], ["84054.4", "0", "0", "0"], ["84053.6", "0.106", "0", "4"], ["84052.8", "0.053", "0", "2"], ["83939.8", "2.4621163", "0", "2"], ["83939.7", "0.03", "0", "1"]], "ts": "1742554963604", "checksum": -1615074835, "seqId": 49927372187, "prevSeqId": 49927372159}], "record_time": 1742554963.604336, "EXCHANGE": "OKX"}
{"arg": {"channel": "books", "instId": "BTC-USDT"}, "action": "update", "data": [{"asks": [["84108.4", "0.0034911", "0", "1"], ["84119", "0", "0", "0"], ["84120.2", "0.23794334", "0", "1"], ["84130.4", "0.25453713", "0", "3"], ["84131.2", "0.07999999", "0", "2"], ["84132", "0.03999999", "0", "1"], ["84256.2", "0", "0", "0"], ["84257.2", "0", "0", "0"]], "bids": [["84070.8", "0.11900436", "0", "1"], ["84061.5", "0.23794334", "0", "1"], ["84059.7", "0", "0", "0"], ["84058.8", "0.25478762", "0", "1"], ["83939.7", "0", "0", "0"]], "ts": "1742554963704", "checksum": -1615074835, "seqId": 49927372200, "prevSeqId": 49927372187}], "record_time": 1742554963.706974, "EXCHANGE": "OKX"}
{"arg": {"channel": "books", "instId": "BTC-USDT"}, "action": "update", "data": [{"asks": [["84107.8", "0.0000165", "0", "1"], ["84255.6", "0", "0", "0"]], "bids": [["84078.7", "0.53514", "0", "2"]], "ts": "1742554963804", "checksum": -1615074835, "seqId": 49927372203, "prevSeqId": 49927372200}], "record_time": 1742554963.806898, "EXCHANGE": "OKX"}
{"arg": {"channel": "books", "instId": "BTC-USDT"}, "action": "update", "data": [{"asks": [["84092.5", "0", "0", "0"], ["84092.6", "0", "0", "0"], ["84094.8", "0.01189785", "0", "1"], ["84105.1", "0.67029436", "0", "2"], ["84105.2", "0.00001197", "0", "1"], ["84105.5", "0.02379687", "0", "1"], ["84105.8", "0", "0", "0"], ["84112.1", "0", "0", "0"], ["84112.5", "0.00006", "0", "1"], ["84113.9", "0", "0", "0"], ["84114", "0", "0", "0"], ["84119.5", "0", "0", "0"], ["84120.6", "0", "0", "0"], ["84121.6", "0", "0", "0"], ["84122.6", "0.08991011", "0", "1"], ["84130.4", "0.33453713", "0", "5"], ["84131.2", "0.03999999", "0", "1"], ["84132", "0", "0", "0"], ["84255.6", "0.01493332", "0", "1"], ["84256.2", "0.2025", "0", "1"], ["84257.2", "0.6", "0", "1"], ["84257.6", "0.00008291", "0", "1"], ["84258.1", "0.00003542", "0", "1"], ["84258.2", "0.35579296", "0", "1"], ["84258.3", "0.00002584", "0", "1"], ["84258.9", "0.00001016", "0", "1"], ["84259", "0.00011161", "0", "1"]], "bids": [["84090", "0.95834586", "0", "25"], ["84078.2", "0.27018009", "0", "4"], ["84077.1", "0.02846459", "0", "1"], ["84076.5", "0", "0", "0"], ["84076.4", "0", "0", "0"], ["84071.2", "0.35787758", "0", "1"], ["84070.1", "0", "0", "0"], ["84068.4", "0", "0", "0"], ["84067.8", "0", "0", "0"], ["84064.2", "0", "0", "0"], ["84061.1", "0", "0", "0"], ["84060.7", "0.00001197", "0", "1"], ["84059.6", "0", "0", "0"], ["84054.4", "0.08", "0", "2"], ["84053.6", "0.066", "0", "3"], ["84052.8", "0.013", "0", "1"], ["83939.7", "0.03", "0", "1"], ["83939.5", "0.00007329", "0", "1"], ["83939.1", "0.10703", "0", "1"], ["83938.4", "0.00001883", "0", "1"], ["83938.2", "0.6000735", "0", "2"], ["83936.8", "0.00001197", "0", "1"], ["83936.1", "0.0000442", "0", "1"]], "ts": "1742554963904", "checksum": 1191715355, "seqId": 49927372241, "prevSeqId": 49927372203}], "record_time": 1742554963.905168, "EXCHANGE": "OKX"}
{"arg": {"channel": "books", "instId": "BTC-USDT"}, "action": "update", "data": [{"asks": [["84093.9", "0.01266506", "0", "1"], ["84105.2", "0.03492115", "0", "2"], ["84105.3", "0.20903906", "0", "2"], ["84105.6", "0.03280886", "0", "1"], ["84105.9", "0.03412637", "0", "1"], ["84112.2", "0.03288023", "0", "1"], ["84112.6", "0.03445649", "0", "1"], ["84114", "0.03308568", "0", "1"], ["84114.1", "0.03277693", "0", "1"], ["84119.6", "0.06322817", "0", "1"], ["84120.2", "0", "0", "0"], ["84120.6", "0.23794243", "0", "1"], ["84120.7", "0.07328623", "0", "2"], ["84121.6", "0.06293091", "0", "1"], ["84122.7", "0.06156268", "0", "1"], ["84255", "0", "0", "0"], ["84255.6", "0", "0", "0"], ["84256.2", "0", "0", "0"], ["84257.2", "0", "0", "0"], ["84257.6", "0", "0", "0"], ["84258.1", "0", "0", "0"], ["84258.2", "0", "0", "0"], ["84258.3", "0", "0", "0"], ["84258.9", "0", "0", "0"], ["84259", "0", "0", "0"]], "bids": [["84078.3", "0.03495863", "0", "1"], ["84077.2", "0.13264725", "0", "3"], ["84076.6", "0.03603615", "0", "2"], ["84076.5", "0.03434514", "0", "1"], ["84071.3", "0.03732464", "0", "2"], ["84070.2", "0.0588504", "0", "2"], ["84068.5", "0.03321515", "0", "1"], ["84067.9", "0.031245", "0", "1"], ["84064.3", "0.0638767", "0", "1"], ["84061.2", "0.06254969", "0", "2"], ["84060.7", "0.06455356", "0", "2"], ["84059.7", "0.07000776", "0", "1"], ["84054.4", "0", "0", "0"], ["84053.6", "0.106", "0", "4"], ["84052.8", "0.053", "0", "2"], ["83939.1", "0", "0", "0"], ["83938.4", "0", "0", "0"], ["83938.2", "0", "0", "0"], ["83936.8", "0", "0", "0"], ["83936.1", "0", "0", "0"]], "ts": "1742554964004", "checksum": 1732064900, "seqId": 49927372309, "prevSeqId": 49927372241}], "record_time": 1742554964.010401, "EXCHANGE": "OKX"}
{"arg": {"channel": "books", "instId": "BTC-USDT"}, "action": "update", "data": [{"asks": [["84120.6", "0", "0", "0"], ["84121.5", "0.23805346", "0", "2"], ["84157.4", "0", "0", "0"], ["84159.9", "0.0112626", "0", "1"], ["84255", "0.00001181", "0", "1"]], "bids": [["84062.6", "0.23805388", "0", "2"], ["84061.5", "0", "0", "0"], ["84043.1", "0.01832159", "0", "1"], ["84040.9", "0", "0", "0"], ["83986.6", "0.12492367", "0", "2"], ["83971.5", "0.18322791", "0", "2"], ["83969.4", "0", "0", "0"], ["83939.1", "0.10703", "0", "1"], ["83938.4", "0.00001883", "0", "1"]], "ts": "1742554964104", "checksum": 1732064900, "seqId": 49927372342, "prevSeqId": 49927372309}], "record_time": 1742554964.107379, "EXCHANGE": "OKX"}
{"arg": {"channel": "books", "instId": "BTC-USDT"}, "action": "update", "data": [{"asks": [["84121.5", "0.23805316", "0", "2"], ["84165.3", "0.07128836", "0", "1"]], "bids": [["84078.9", "0", "0", "0"], ["84077.6", "1", "0", "1"], ["84062.9", "0.23794155", "0", "1"], ["84062.6", "0.00011161", "0", "1"], ["84000.2", "0.07142831", "0", "1"], ["83938.4", "0", "0", "0"]], "ts": "1742554964204", "checksum": 1732064900, "seqId": 49927372358, "prevSeqId": 49927372342}], "record_time": 1742554964.204047, "EXCHANGE": "OKX"}
{"arg": {"channel": "books", "instId": "BTC-USDT"}, "action": "update", "data": [{"asks": [["84090.1", "0.11948477", "0", "2"], ["84105.2", "0.00001197", "0", "1"], ["84120.2", "0.23794318", "0", "1"], ["84121.5", "0.00011161", "0", "1"], ["84121.6", "0", "0", "0"], ["84122.7", "0", "0", "0"], ["84165.3", "0.14257672", "0", "2"], ["84255.6", "0.01493332", "0", "1"]], "bids": [["84090", "1.15834586", "0", "26"], ["84077.2", "0.102", "0", "2"], ["84062.9", "0", "0", "0"], ["84061.5", "0.23794318", "0", "1"], ["84060.7", "0.00001197", "0", "1"], ["84059.7", "0", "0", "0"], ["84054.4", "0.08", "0", "2"], ["84053.6", "0.066", "0", "3"], ["84052.8", "0.013", "0", "1"], ["84000.2", "0.14285662", "0", "2"]], "ts": "1742554964304", "checksum": -529275733, "seqId": 49927372397, "prevSeqId": 49927372358}], "record_time": 1742554964.304538, "EXCHANGE": "OKX"}
{"arg": {"channel": "books", "instId": "BTC-USDT"}, "action": "update", "data": [{"asks": [["84092", "0.0146", "0", "1"], ["84104.8", "0.0005946", "0", "1"], ["84105.3", "0.17821722", "0", "1"], ["84105.6", "0", "0", "0"], ["84105.9", "0", "0", "0"], ["84112.2", "0", "0", "0"], ["84112.6", "0", "0", "0"], ["84114", "0", "0", "0"], ["84114.1", "0", "0", "0"], ["84118.9", "0.30549286", "0", "1"], ["84119.6", "0", "0", "0"], ["84119.8", "0.23794478", "0", "1"], ["84120.2", "0", "0", "0"], ["84120.7", "0.0054", "0", "1"], ["84257.6", "0.00008291", "0", "1"], ["84258.1", "0.00003542", "0", "1"], ["84258.2", "0.35579296", "0", "1"], ["84258.3", "0.00002584", "0", "1"]], "bids": [["84090", "0.95834586", "0", "25"], ["84078.3", "0", "0", "0"], ["84076.6", "0.00420551", "0", "1"], ["84076.5", "0", "0", "0"], ["84071.3", "0.00475787", "0", "1"], ["84070.2", "0.02379623", "0", "1"], ["84068.5", "0", "0", "0"], ["84067.9", "0", "0", "0"], ["84064.3", "0", "0", "0"], ["84062.8", "0.26130847", "0", "2"], ["84061.5", "0.23794478", "0", "1"], ["84061.2", "0.00005328", "0", "1"], ["83938.4", "0.00001883", "0", "1"], ["83938.2", "0.6000735", "0", "2"], ["83936.8", "0.00001197", "0", "1"], ["83936.1", "0.0000442", "0", "1"], ["83935.6", "0.00001925", "0", "1"]], "ts": "1742554964404", "checksum": -75243957, "seqId": 49927372443, "prevSeqId": 49927372397}], "record_time": 1742554964.410851, "EXCHANGE": "OKX"}
{"arg": {"channel": "books", "instId": "BTC-USDT"}, "action": "update", "data": [{"asks": [["84105.1", "0.70183625", "0", "3"], ["84105.2", "0.03184629", "0", "2"], ["84105.4", "0.15271288", "0", "2"], ["84105.8", "0.03344669", "0", "1"], ["84112.1", "0.03280581", "0", "1"], ["84112.4", "0.03096483", "0", "1"], ["84113.8", "0.03086589", "0", "1"], ["84113.9", "0.03190145", "0", "1"], ["84119.4", "0.06752229", "0", "1"], ["84120.6", "0.0657701", "0", "1"], ["84121.5", "0.06393442", "0", "2"], ["84122.6", "0.15894631", "0", "2"], ["84130.4", "0.25453713", "0", "3"], ["84131.2", "0.07999999", "0", "2"], ["84132", "0.03999999", "0", "1"], ["84254.3", "0", "0", "0"], ["84254.5", "0", "0", "0"], ["84255", "0", "0", "0"], ["84255.6", "0", "0", "0"], ["84257.6", "0", "0", "0"], ["84258.1", "0", "0", "0"], ["84258.2", "0", "0", "0"], ["84258.3", "0", "0", "0"]], "bids": [["84090", "0.96545586", "0", "26"], ["84078.1", "0.04234839", "0", "3"], ["84077.1", "0.06157006", "0", "2"], ["84076.5", "0.03325155", "0", "1"], ["84076.4", "0.03157282", "0", "1"], ["84071.1", "0.03173692", "0", "1"], ["84070.1", "0.03095882", "0", "1"], ["84068.3", "0.03109998", "0", "1"], ["84067.7", "0.03463783", "0", "2"], ["84064.1", "0.06706419", "0", "1"], ["84061.1", "0.07006079", "0", "1"], ["84060.6", "0.06467138", "0", "1"], ["84059.6", "0.06956668", "0", "1"], ["84054.4", "0", "0", "0"], ["84053.6", "0.106", "0", "4"], ["84053.3", "0.18669947", "0", "1"], ["84052.8", "0.053", "0", "2"], ["83939.7", "0", "0", "0"], ["83939.5", "0", "0", "0"], ["83939.1", "0", "0", "0"], ["83938.4", "0", "0", "0"], ["83938.2", "0", "0", "0"], ["83936.8", "0", "0", "0"], ["83936.1", "0", "0", "0"], ["83935.6", "0", "0", "0"]], "ts": "1742554964504", "checksum": 35604860, "seqId": 49927372491, "prevSeqId": 49927372443}], "record_time": 1742554964.503833, "EXCHANGE": "OKX"}
{"arg": {"channel": "books", "instId": "BTC-USDT"}, "action": "update", "data": [{"asks": [["84119.8", "0", "0", "0"], ["84121.4", "0.23794272", "0", "1"], ["84130.4", "0.33453713", "0", "5"], ["84131.2", "0.03999999", "0", "1"], ["84132", "0", "0", "0"], ["84133", "1.00001", "0", "2"], ["84134", "0.2", "0", "1"]], "bids": [["84059", "1", "0", "1"], ["83939.8", "0", "0", "0"]], "ts": "1742554964604", "checksum": 35604860, "seqId": 49927372501, "prevSeqId": 49927372491}], "record_time": 1742554964.60442, "EXCHANGE": "OKX"}
{"arg": {"channel": "books", "instId": "BTC-USDT"}, "action": "update", "data": [{"asks": [["84220.2", "0", "0", "0"], ["84229.2", "0.00594543", "0", "1"], ["84238.8", "0", "0", "0"], ["84247.2", "0.00153761", "0", "2"], ["84254.3", "0.00001034", "0", "1"], ["84254.5", "0.00001063", "0", "1"]], "bids": [["84011.4", "0", "0", "0"], ["84000.1", "0", "0", "0"], ["83991.3", "0.00001196", "0", "1"], ["83982.9", "0", "0", "0"], ["83974.5", "0", "0", "0"], ["83939.8", "2.4621163", "0", "2"], ["83939.7", "0.03", "0", "1"], ["83939.5", "0.00007329", "0", "1"], ["83939.1", "0.10703", "0", "1"]], "ts": "1742554964704", "checksum": 35604860, "seqId": 49927372513, "prevSeqId": 49927372501}], "record_time": 1742554964.704224, "EXCHANGE": "OKX"}
{"arg": {"channel": "books", "instId": "BTC-USDT"}, "action": "update", "data": [{"asks": [["84092", "0", "0", "0"], ["84105.1", "0.67029436", "0", "2"], ["84105.2", "0.00001197", "0", "1"], ["84105.3", "0.24768297", "0", "3"], ["84105.4", "0.11895551", "0", "1"], ["84105.6", "0.03093084", "0", "1"], ["84105.8", "0", "0", "0"], ["84105.9", "0.03214599", "0", "1"], ["84112.1", "0", "0", "0"], ["84112.2", "0.03152814", "0", "1"], ["84112.4", "0", "0", "0"], ["84112.6", "0.03319296", "0", "1"], ["84113.8", "0", "0", "0"], ["84113.9", "0", "0", "0"], ["84114", "0.03514841", "0", "1"], ["84114.1", "0.031436", "0", "1"], ["84118.9", "0", "0", "0"], ["84119.4", "0", "0", "0"], ["84119.6", "0.06351641", "0", "1"], ["84120.6", "0", "0", "0"], ["84120.7", "0.07451726", "0", "2"], ["84121.4", "0", "0", "0"], ["84121.5", "0.00011161", "0", "1"], ["84121.6", "0.23794068", "0", "1"], ["84121.7", "0.06431232", "0", "1"], ["84122.6", "0.08991011", "0", "1"], ["84122.8", "0.06283013", "0", "1"], ["84133", "0.00001", "0", "1"]], "bids": [["84078.3", "0.03225129", "0", "1"], ["84078.1", "0.01", "0", "2"], ["84077.3", "0.03464019", "0", "1"], ["84077.1", "0.02846459", "0", "1"], ["84076.6", "0.03750552", "0", "2"], ["84076.5", "0.03321006", "0", "1"], ["84076.4", "0", "0", "0"], ["84071.3", "0.03630428", "0", "2"], ["84071.1", "0", "0", "0"], ["84070.2", "0.05650605", "0", "2"], ["84070.1", "0", "0", "0"], ["84068.5", "0.03274731", "0", "1"], ["84068.3", "0", "0", "0"], ["84067.9", "0.03202639", "0", "1"], ["84067.7", "0.00001501", "0", "1"], ["84064.3", "0.069775", "0", "1"], ["84064.1", "0", "0", "0"], ["84063.2", "0.23794068", "0", "1"], ["84061.5", "0", "0", "0"], ["84061.2", "0.0684144", "0", "2"], ["84061.1", "0", "0", "0"], ["84060.8", "0.06182004", "0", "1"], ["84060.6", "0", "0", "0"], ["84059.8", "0.06903332", "0", "1"], ["84059.6", "0", "0", "0"], ["83938.4", "0.00001883", "0", "1"]], "ts": "1742554964804", "checksum": -2008744388, "seqId": 49927372580, "prevSeqId": 49927372513}], "record_time": 1742554964.803998, "EXCHANGE": "OKX"}
{"arg": {"channel": "books", "instId": "BTC-USDT"}, "action": "update", "data": [{"asks": [["84121.6", "0.23794117", "0", "1"], ["84134", "0", "0", "0"], ["84255", "0.00001181", "0", "1"]], "bids": [["84063.2", "0.23794117", "0", "1"], ["84050.4", "0.01785561", "0", "1"], ["84049.6", "1.19631356", "0", "3"], ["84048.8", "0.05", "0", "1"], ["83938.4", "0", "0", "0"]], "ts": "1742554964904", "checksum": -2008744388, "seqId": 49927372603, "prevSeqId": 49927372580}], "record_time": 1742554964.904044, "EXCHANGE": "OKX"}
{"arg": {"channel": "books", "instId": "BTC-USDT"}, "action": "update", "data": [{"asks": [["84090.1", "0", "0", "0"], ["84093.9", "0", "0", "0"], ["84094", "0", "0", "0"], ["84094.5", "0", "0", "0"], ["84094.8", "0", "0", "0"], ["84096", "0", "0", "0"], ["84097.2", "0", "0", "0"], ["84097.8", "0", "0", "0"], ["84098.2", "0", "0", "0"], ["84099", "0", "0", "0"], ["84099.1", "0", "0", "0"], ["84100", "0.05721886", "0", "5"], ["84100.3", "0", "0", "0"], ["84102", "0.0146", "0", "1"], ["84103.2", "0.00056587", "0", "1"], ["84103.4", "0", "0", "0"], ["84104.4", "0", "0", "0"], ["84105.1", "0.03950276", "0", "1"], ["84105.2", "0", "0", "0"], ["84105.3", "0", "0", "0"], ["84105.4", "0", "0", "0"], ["84105.5", "0", "0", "0"], ["84105.6", "0", "0", "0"], ["84105.9", "0", "0", "0"], ["84106.4", "0", "0", "0"], ["84106.5", "0.0297729", "0", "1"], ["84107.8", "0", "0", "0"], ["84108", "0", "0", "0"], ["84108.2", "0", "0", "0"], ["84108.8", "0", "0", "0"], ["84109", "0", "0", "0"], ["84109.2", "0.07795953", "0", "1"], ["84109.4", "0", "0", "0"], ["84109.7", "0", "0", "0"], ["84110.1", "0.00214", "0", "1"], ["84111.4", "0", "0", "0"], ["84111.5", "0", "0", "0"], ["84111.8", "0", "0", "0"], ["84112.2", "0", "0", "0"], ["84112.3", "0.01", "0", "2"], ["84112.6", "0", "0", "0"], ["84112.7", "0.03854779", "0", "1"], ["84113.7", "0.25869987", "0", "1"], ["84114", "0", "0", "0"], ["84114.1", "0", "0", "0"], ["84114.3", "0.04", "0", "1"], ["84114.9", "0.03258578", "0", "1"], ["84115", "0.06577529", "0", "3"], ["84115.4", "0.20542894", "0", "4"], ["84116.4", "0", "0", "0"], ["84116.8", "0.0103941", "0", "1"], ["84116.9", "0", "0", "0"], ["84118.3", "0.11893729", "0", "1"], ["84119", "0.45389354", "0", "2"], ["84119.4", "1", "0", "1"], ["84119.6", "0", "0", "0"], ["84120.7", "0.0054", "0", "1"], ["84121.6", "0", "0", "0"], ["84121.7", "0.03343041", "0", "1"], ["84122", "0.03450583", "0", "1"], ["84122.4", "0", "0", "0"], ["84122.6", "0", "0", "0"], ["84122.8", "0", "0", "0"], ["84123.7", "0.03077928", "0", "1"], ["84123.8", "0.03319615", "0", "1"], ["84123.9", "0", "0", "0"], ["84126.5", "0", "0", "0"], ["84128.2", "0.09533163", "0", "2"], ["84128.3", "0", "0", "0"], ["84128.8", "0", "0", "0"], ["84129", "0.06654239", "0", "1"], ["84129.1", "0", "0", "0"], ["84130.4", "0.31815821", "0", "4"], ["84131.2", "0", "0", "0"], ["84132.4", "0.07933044", "0", "4"], ["84132.7", "0.23790926", "0", "1"], ["84133.6", "0.08", "0", "2"], ["84134.4", "0.21821721", "0", "2"], ["84136.7", "0.35672", "0", "1"], ["84143.3", "0.27006173", "0", "1"], ["84146.4", "0", "0", "0"], ["84149.2", "0.02376732", "0", "2"], ["84149.9", "0.01250197", "0", "3"], ["84150", "0.01188355", "0", "1"], ["84150.2", "0.00420106", "0", "1"], ["84150.9", "0.03", "0", "1"], ["84153.6", "0", "0", "0"], ["84158.8", "0", "0", "0"], ["84164.6", "0.01188343", "0", "1"], ["84167.5", "0.76493443", "0", "2"], ["84168.4", "0.05350541", "0", "1"], ["84170", "0", "0", "0"], ["84170.8", "0.01188341", "0", "1"], ["84184.5", "0", "0", "0"], ["84187.3", "0", "0", "0"], ["84193.2", "0.02875979", "0", "1"], ["84193.9", "0", "0", "0"], ["84203.3", "0", "0", "0"], ["84206.4", "0", "0", "0"], ["84208.5", "0.00040805", "0", "13"], ["84220.7", "0.07125036", "0", "1"], ["84223.5", "0.12458429", "0", "1"], ["84223.7", "0.00594149", "0", "1"], ["84230.2", "0", "0", "0"], ["84232.5", "0", "0", "0"], ["84245.7", "0", "0", "0"], ["84252.5", "0.00002342", "0", "2"], ["84256.2", "0.2025", "0", "1"], ["84257.6", "0.00008291", "0", "1"], ["84258.1", "0.00003542", "0", "1"], ["84258.2", "0.35579296", "0", "1"], ["84258.3", "0.00002584", "0", "1"], ["84258.9", "0.00001016", "0", "1"], ["84259", "0.00011161", "0", "1"], ["84259.2", "0.00001197", "0", "1"], ["84259.4", "0.0852", "0", "6"], ["84259.5", "0.0142", "0", "1"], ["84259.7", "0.00419094", "0", "1"], ["84259.9", "0.00018194", "0", "1"], ["84260", "0.00033268", "0", "4"], ["84260.2", "0.00168601", "0", "1"], ["84260.6", "0.0000142", "0", "1"], ["84260.8", "0.00001852", "0", "1"], ["84261.1", "0.01299784", "0", "1"], ["84262.2", "0.00003778", "0", "1"], ["84262.4", "0.0000221", "0", "1"], ["84262.9", "0.17821722", "0", "1"], ["84263.9", "0.00003969", "0", "2"], ["84264", "0.00074396", "0", "1"], ["84264.7", "0.2025", "0", "1"], ["84264.9", "0.00031778", "0", "3"], ["84265.1", "0.00418989", "0", "1"], ["84265.8", "0.00001156", "0", "1"], ["84266", "0.11878326", "0", "1"], ["84266.2", "0.14240602", "0", "2"], ["84266.4", "0.00001402", "0", "1"], ["84266.5", "0.00054835", "0", "1"], ["84266.6", "0.01217191", "0", "13"], ["84266.7", "0.00002129", "0", "1"], ["84266.9", "0.00013853", "0", "2"], ["84267.3", "0.35615346", "0", "2"], ["84268", "0.00118668", "0", "1"]], "bids": [["84099.9", "2.05715472", "0", "18"], ["84098", "0.0146", "0", "1"], ["84094.8", "0.23369062", "0", "1"], ["84094.5", "0.2", "0", "1"], ["84094.4", "0.42289424", "0", "5"], ["84094.1", "0.0969807", "0", "1"], ["84094", "0.0146", "0", "1"], ["84093.1", "0.03854779", "0", "1"], ["84090.2", "0.18541095", "0", "1"], ["84090", "0.29972918", "0", "14"], ["84089.9", "0", "0", "0"], ["84089.7", "0.04018", "0", "1"], ["84088.8", "0", "0", "0"], ["84088.6", "0.08991011", "0", "1"], ["84088.2", "0.01", "0", "2"], ["84087.7", "0.03143069", "0", "1"], ["84086.9", "0.0308868", "0", "1"], ["84086.4", "0.02846459", "0", "1"], ["84086.3", "0.03129608", "0", "1"], ["84086.2", "0.34861111", "0", "2"], ["84086.1", "0", "0", "0"], ["84086", "0.03515247", "0", "1"], ["84085.8", "0", "0", "0"], ["84085.7", "0.05320517", "0", "2"], ["84084.7", "0.04420528", "0", "2"], ["84084.1", "1", "0", "1"], ["84084", "0.35062464", "0", "4"], ["84083.6", "0", "0", "0"], ["84083.4", "0", "0", "0"], ["84082", "0.57656011", "0", "2"], ["84081.2", "0", "0", "0"], ["84080.7", "0.03101566", "0", "1"], ["84079.7", "0.17469185", "0", "2"], ["84079.6", "0.3725695", "0", "1"], ["84078.7", "0", "0", "0"], ["84078.4", "0.38386845", "0", "2"], ["84078.3", "0", "0", "0"], ["84078.2", "0.26160729", "0", "4"], ["84077.8", "0", "0", "0"], ["84077.6", "0.03170737", "0", "1"], ["84077.3", "0", "0", "0"], ["84077.1", "0", "0", "0"], ["84076.6", "0.00420551", "0", "1"], ["84076.5", "0", "0", "0"], ["84076.2", "0.23790926", "0", "1"], ["84075.8", "0.51699", "0", "1"], ["84075.1", "0.00475765", "0", "1"], ["84073.7", "0.06700262", "0", "1"], ["84071.9", "0.00713675", "0", "1"], ["84071.3", "0", "0", "0"], ["84070.2", "0", "0", "0"], ["84069.8", "0", "0", "0"], ["84068.5", "0", "0", "0"], ["84067.9", "0", "0", "0"], ["84067.5", "0.17821722", "0", "1"], ["84067", "0.02817312", "0", "1"], ["84066.2", "0", "0", "0"], ["84066.1", "0", "0", "0"], ["84065.2", "0", "0", "0"], ["84064.3", "0", "0", "0"], ["84063.2", "0", "0", "0"], ["84062.8", "0", "0", "0"], ["84062.5", "0", "0", "0"], ["84061.2", "0.00005328", "0", "1"], ["84060.8", "0", "0", "0"], ["84059.8", "0", "0", "0"], ["84059", "0", "0", "0"], ["84058.8", "0", "0", "0"], ["84058.5", "0.53493722", "0", "2"], ["84056.3", "0", "0", "0"], ["84055.2", "0.08", "0", "2"], ["84054.4", "0.04", "0", "1"], ["84053.6", "0.026", "0", "2"], ["84052.8", "0.013", "0", "1"], ["84051.2", "0.1", "0", "2"], ["84050.4", "0.06785561", "0", "2"], ["84049.6", "1.09631356", "0", "1"], ["84048.8", "0", "0", "0"], ["84046", "0.03", "0", "1"], ["84045.1", "0.00005207", "0", "1"], ["84040.8", "0", "0", "0"], ["84040.6", "0", "0", "0"], ["84040", "0.00001", "0", "1"], ["84034.4", "0", "0", "0"], ["84032.6", "0.17587928", "0", "1"], ["84029.2", "0.12268543", "0", "1"], ["84027.5", "0.03", "0", "1"], ["84024.3", "0", "0", "0"], ["84020.4", "0.13405981", "0", "2"], ["84014.1", "0", "0", "0"], ["84013.2", "0.1422735", "0", "2"], ["83996.9", "0.01189485", "0", "1"], ["83995.5", "1.03155422", "0", "1"], ["83994.8", "0.2025", "0", "1"], ["83981.1", "0", "0", "0"], ["83980.6", "0.00001196", "0", "1"], ["83961.7", "0.01188366", "0", "1"], ["83959.4", "0.01188343", "0", "1"], ["83941.9", "0.01188355", "0", "1"], ["83938.4", "0.00001883", "0", "1"], ["83938.2", "0.6000735", "0", "2"], ["83936.1", "0.0000442", "0", "1"]], "ts": "1742554965004", "checksum": -48303096, "seqId": 49927373306, "prevSeqId": 49927372603}], "record_time": 1742554965.005385, "EXCHANGE": "OKX"}
{"arg": {"channel": "books", "instId": "BTC-USDT"}, "action": "update", "data": [{"asks": [["84100", "0.52599509", "0", "8"], ["84102.8", "0.02281186", "0", "1"], ["84104.7", "0", "0", "0"], ["84105.1", "0.07924399", "0", "2"], ["84106.5", "0", "0", "0"], ["84108.1", "0", "0", "0"], ["84108.5", "0.2025", "0", "1"], ["84108.7", "0.03854779", "0", "1"], ["84109.2", "0.10959908", "0", "2"], ["84110.6", "0.0297729", "0", "1"], ["84110.9", "0.06", "0", "2"], ["84112.7", "0", "0", "0"], ["84112.9", "0.03714986", "0", "1"], ["84113.2", "0.03196964", "0", "1"], ["84113.6", "0.06324788", "0", "2"], ["84113.8", "0.03391035", "0", "1"], ["84114.9", "0", "0", "0"], ["84115", "0.00001501", "0", "1"], ["84115.4", "0.17169022", "0", "3"], ["84116.3", "0", "0", "0"], ["84117.9", "0.97433595", "0", "2"], ["84118", "1", "0", "1"], ["84118.9", "0.01774536", "0", "1"], ["84119", "0", "0", "0"], ["84119.3", "1.54324731", "0", "1"], ["84119.4", "0", "0", "0"], ["84120.1", "0.03248595", "0", "2"], ["84120.2", "0.03487821", "0", "1"], ["84121.7", "0", "0", "0"], ["84122", "0", "0", "0"], ["84122.3", "0.03238902", "0", "1"], ["84122.4", "0.03220997", "0", "1"], ["84123.7", "0", "0", "0"], ["84123.8", "0", "0", "0"], ["84126.9", "0.23792626", "0", "1"], ["84127.2", "0.06577299", "0", "1"], ["84129", "0.06785914", "0", "1"], ["84129.6", "0.06554512", "0", "1"], ["84130.2", "0", "0", "0"], ["84130.4", "0.25453713", "0", "3"], ["84131.1", "0.06367519", "0", "1"], ["84132.4", "0.01473762", "0", "3"], ["84132.7", "0", "0", "0"], ["84133.3", "0.00101534", "0", "2"], ["84133.6", "0", "0", "0"], ["84134.4", "0.17821722", "0", "1"], ["84134.6", "0", "0", "0"], ["84135.2", "0.07999999", "0", "2"], ["84136", "0.03999999", "0", "1"], ["84136.7", "0", "0", "0"], ["84139", "0.1", "0", "1"], ["84145.4", "0.25755", "0", "1"], ["84148.7", "2.70949488", "0", "1"], ["84149.6", "0.06", "0", "2"], ["84153", "0.06", "0", "2"], ["84154.4", "0.17836", "0", "1"], ["84171.5", "0", "0", "0"], ["84180.9", "0.00012217", "0", "1"], ["84228.3", "0", "0", "0"], ["84233.8", "0.01191902", "0", "2"], ["84266", "0", "0", "0"], ["84266.2", "0", "0", "0"], ["84266.4", "0", "0", "0"], ["84266.5", "0", "0", "0"], ["84266.6", "0", "0", "0"], ["84266.7", "0", "0", "0"], ["84266.9", "0", "0", "0"], ["84267.3", "0", "0", "0"], ["84268", "0", "0", "0"]], "bids": [["84099.9", "0.8496036", "0", "8"], ["84094.8", "0.14247494", "0", "1"], ["84094.5", "0.00111905", "0", "1"], ["84094.4", "0.42176868", "0", "4"], ["84094.1", "0", "0", "0"], ["84088.6", "0", "0", "0"], ["84087.7", "0", "0", "0"], ["84086.9", "0", "0", "0"], ["84086.3", "0", "0", "0"], ["84086", "0", "0", "0"], ["84085.9", "0.03235324", "0", "1"], ["84085.6", "0.0307519", "0", "1"], ["84084.9", "0.03210109", "0", "1"], ["84084.4", "0.0321911", "0", "1"], ["84080.7", "0", "0", "0"], ["84079.7", "0.1403523", "0", "1"], ["84078.9", "0.03346848", "0", "1"], ["84078.4", "0.35641581", "0", "1"], ["84078.2", "0.23018009", "0", "3"], ["84078.1", "0.04296545", "0", "3"], ["84077.6", "0", "0", "0"], ["84076.8", "0.03328141", "0", "1"], ["84076.2", "0.03087649", "0", "1"], ["84073.7", "0", "0", "0"], ["84071.9", "0.07645971", "0", "2"], ["84070", "0.24292677", "0", "3"], ["84069.5", "0.06305632", "0", "1"], ["84068.7", "0.06192521", "0", "1"], ["84068.1", "0.06206592", "0", "1"], ["84067.1", "0.02745264", "0", "1"], ["84064.7", "0", "0", "0"], ["84057.4", "0.20908", "0", "1"], ["84049.7", "0.01774536", "0", "1"], ["84049.2", "0", "0", "0"], ["84047.5", "0.17836", "0", "1"], ["84045.1", "0.01193567", "0", "2"], ["84044.6", "0.1", "0", "1"], ["84040.9", "0.17836", "0", "1"], ["84040.2", "0.0054", "0", "1"], ["84037.9", "0", "0", "0"], ["84037.5", "0.06237771", "0", "2"], ["84033.9", "0.00105177", "0", "1"], ["84027.6", "0", "0", "0"], ["84023.4", "0", "0", "0"], ["84017", "0.014", "0", "1"], ["84007.6", "0", "0", "0"], ["83969.4", "0.00201369", "0", "1"], ["83958.9", "0", "0", "0"], ["83938.2", "0", "0", "0"], ["83936.1", "0", "0", "0"]], "ts": "1742554965104", "checksum": 1718217963, "seqId": 49927373539, "prevSeqId": 49927373306}], "record_time": 1742554965.105924, "EXCHANGE": "OKX"}
{"arg": {"channel": "books", "instId": "BTC-USDT"}, "action": "update", "data": [{"asks": [["84108.7", "0.04909779", "0", "2"], ["84114.3", "0.1", "0", "3"], ["84115", "0.03167501", "0", "2"], ["84119.4", "0.13379", "0", "1"], ["84129.1", "0.12485", "0", "1"], ["84139", "0", "0", "0"], ["84144", "0", "0", "0"], ["84144.6", "0.1", "0", "1"], ["84148.7", "2.709538", "0", "2"], ["84150.2", "0.12905106", "0", "2"], ["84154.4", "0", "0", "0"]], "bids": [["84090", "0.29966", "0", "13"], ["84067.1", "0", "0", "0"], ["84066.1", "0.12485", "0", "1"], ["84058", "0.03784674", "0", "2"], ["84045.1", "0.13678567", "0", "3"], ["84044.6", "0", "0", "0"], ["84040.9", "0", "0", "0"], ["84040.8", "0.918304", "0", "1"], ["84003.9", "0.00016258", "0", "1"], ["84000.5", "0.00001501", "0", "1"]], "ts": "1742554965204", "checksum": -465117638, "seqId": 49927373569, "prevSeqId": 49927373539}], "record_time": 1742554965.204204, "EXCHANGE": "OKX"}
{"arg": {"channel": "books", "instId": "BTC-USDT"}, "action": "update", "data": [{"asks": [["84106.4", "0.17836", "0", "1"], ["84108.4", "0", "0", "0"], ["84112.7", "0.0000225", "0", "1"], ["84117.1", "0.01774536", "0", "1"], ["84118.9", "0", "0", "0"], ["84134.4", "0.25821722", "0", "3"], ["84135.2", "0.03999999", "0", "1"], ["84136", "0", "0", "0"], ["84139.2", "0.35672", "0", "1"], ["84148.7", "2.70949488", "0", "1"], ["84153.6", "0.00004312", "0", "1"], ["84170.4", "0.2497", "0", "1"], ["84264.9", "0", "0", "0"], ["84265.1", "0", "0", "0"], ["84265.8", "0", "0", "0"]], "bids": [["84099.9", "0.84967417", "0", "9"], ["84086.4", "0.02848559", "0", "2"], ["84083.7", "0.17836", "0", "1"], ["84056", "0.08", "0", "2"], ["84055.2", "0.04", "0", "1"], ["84054.4", "0", "0", "0"], ["84052", "0.1", "0", "2"], ["84051.2", "0.05", "0", "1"], ["84050.4", "0.01785561", "0", "1"], ["84050.1", "0.10100367", "0", "2"], ["84023.2", "0.2497", "0", "1"], ["84010.5", "0.00016257", "0", "1"], ["84003.9", "0", "0", "0"], ["84002.9", "0.059998", "0", "1"], ["83982.6", "0", "0", "0"], ["83966", "0.183166", "0", "1"], ["83939.7", "0", "0", "0"], ["83939.5", "0", "0", "0"], ["83939.1", "0", "0", "0"], ["83938.4", "0", "0", "0"]], "ts": "1742554965304", "checksum": 2280846, "seqId": 49927373610, "prevSeqId": 49927373569}], "record_time": 1742554965.306579, "EXCHANGE": "OKX"}
{"arg": {"channel": "books", "instId": "BTC-USDT"}, "action": "update", "data": [{"asks": [["84100", "0.28057886", "0", "4"], ["84105.1", "0.12346634", "0", "1"], ["84108.7", "0.03854779", "0", "1"], ["84111.1", "0.01055", "0", "1"], ["84113.2", "0", "0", "0"], ["84113.5", "0.03300173", "0", "2"], ["84113.8", "0", "0", "0"], ["84113.9", "0.03167223", "0", "1"], ["84120.1", "0.00001197", "0", "1"], ["84120.2", "0.03091895", "0", "1"], ["84120.5", "0.03068796", "0", "1"], ["84127.2", "0", "0", "0"], ["84127.5", "0.06278805", "0", "1"], ["84129.6", "0", "0", "0"], ["84130.2", "0.37803235", "0", "1"], ["84159.9", "0", "0", "0"], ["84163.7", "0.01126286", "0", "1"], ["84264.7", "0", "0", "0"]], "bids": [["84099.9", "0.94967417", "0", "10"], ["84086.2", "0.08782151", "0", "2"], ["84085.9", "0", "0", "0"], ["84084.5", "0.03248165", "0", "2"], ["84084.4", "0", "0", "0"], ["84084.1", "0", "0", "0"], ["84084", "0.66523537", "0", "3"], ["84082.6", "1", "0", "1"], ["84079.2", "0.03067432", "0", "1"], ["84078.9", "0", "0", "0"], ["84078.2", "0.26449168", "0", "4"], ["84078.1", "0.01", "0", "2"], ["84072.2", "0.06659646", "0", "1"], ["84071.9", "0.00713675", "0", "1"], ["84068.7", "0", "0", "0"], ["84061.5", "0.11630795", "0", "1"], ["84061.3", "0.0054", "0", "1"], ["84056", "0", "0", "0"], ["84055.2", "0.08", "0", "2"], ["84054.4", "0.04", "0", "1"], ["84049.6", "1.10171356", "0", "2"], ["84046.7", "0.01832061", "0", "1"], ["84043.1", "0", "0", "0"], ["84040.2", "0", "0", "0"], ["84020.1", "0.0054", "0", "1"], ["84018", "0.12485", "0", "1"], ["84016.6", "0.00060645", "0", "1"], ["83975.2", "0.18320617", "0", "1"], ["83971.5", "0.00001197", "0", "1"], ["83971.3", "0", "0", "0"], ["83939.8", "0", "0", "0"]], "ts": "1742554965404", "checksum": 947465112, "seqId": 49927373674, "prevSeqId": 49927373610}], "record_time": 1742554965.416593, "EXCHANGE": "OKX"}
{"arg": {"channel": "books", "instId": "BTC-USDT"}, "action": "update", "data": [{"asks": [["84102.7", "0.00772873", "0", "1"], ["84105.1", "0.13536291", "0", "2"], ["84123.7", "0.02379314", "0", "1"], ["84129.7", "0.06707804", "0", "1"], ["84180.6", "0.19170269", "0", "1"], ["84190.3", "0.0001965", "0", "1"], ["84262.4", "0", "0", "0"], ["84262.9", "0", "0", "0"], ["84263.9", "0", "0", "0"], ["84264", "0", "0", "0"]], "bids": [["84090.5", "0.00001197", "0", "1"], ["84090", "0.29182", "0", "10"], ["84086.2", "0.49642493", "0", "2"], ["84085.1", "1", "0", "1"], ["84084", "0.39502822", "0", "3"], ["84082.6", "0", "0", "0"], ["84068.8", "0.06838243", "0", "1"], ["84064.7", "0.01774536", "0", "1"], ["84049.7", "0", "0", "0"], ["83941.1", "0", "0", "0"], ["83940.4", "0", "0", "0"]], "ts": "1742554965504", "checksum": 60271561, "seqId": 49927373698, "prevSeqId": 49927373674}], "record_time": 1742554965.505731, "EXCHANGE": "OKX"}
{"arg": {"channel": "books", "instId": "BTC-USDT"}, "action": "update", "data": [{"asks": [["84100", "0.29156355", "0", "5"], ["84101", "0.06819896", "0", "1"], ["84101.1", "0.11896161", "0", "1"], ["84102.8", "0", "0", "0"], ["84113.3", "0.03366009", "0", "1"], ["84113.5", "0.002", "0", "1"], ["84114.9", "0.00352358", "0", "1"], ["84120.3", "0.17514271", "0", "2"], ["84120.5", "0", "0", "0"], ["84127.3", "0.06979261", "0", "1"], ["84127.5", "0", "0", "0"], ["84129.6", "0.06612935", "0", "1"], ["84129.7", "0", "0", "0"], ["84261.1", "0", "0", "0"], ["84262.2", "0", "0", "0"]], "bids": [["84099.9", "0.84967417", "0", "9"], ["84095.5", "0.11896945", "0", "1"], ["84086.2", "0.46557732", "0", "1"], ["84086", "0.03295481", "0", "1"], ["84079.2", "0", "0", "0"], ["84079", "0.03154199", "0", "1"], ["84072.2", "0", "0", "0"], ["84072", "0.07213211", "0", "2"], ["84068.8", "0", "0", "0"], ["84068.7", "0.067411", "0", "1"], ["84056", "0.08", "0", "2"], ["84055.2", "0.04", "0", "1"], ["84054.4", "0", "0", "0"], ["83941.8", "0", "0", "0"]], "ts": "1742554965604", "checksum": -1722764361, "seqId": 49927373729, "prevSeqId": 49927373698}], "record_time": 1742554965.605229, "EXCHANGE": "OKX"}
{"arg": {"channel": "books", "instId": "BTC-USDT"}, "action": "update", "data": [{"asks": [["84205.9", "0.00298666", "0", "1"], ["84214.9", "0.00597332", "0", "1"], ["84224.2", "0.00899001", "0", "3"], ["84233.5", "0.01196961", "0", "2"], ["84242.1", "0.10237332", "0", "2"], ["84260.6", "0", "0", "0"], ["84260.8", "0", "0", "0"]], "bids": [["83994.6", "0.00298666", "0", "1"], ["83986.2", "0.00597332", "0", "1"], ["83977.8", "0.24145999", "0", "3"], ["83969.4", "0.01396034", "0", "2"], ["83961", "0.03275466", "0", "2"], ["83942", "0", "0", "0"], ["83941.9", "0", "0", "0"]], "ts": "1742554965704", "checksum": -1722764361, "seqId": 49927373741, "prevSeqId": 49927373729}], "record_time": 1742554965.703889, "EXCHANGE": "OKX"}
{"arg": {"channel": "books", "instId": "BTC-USDT"}, "action": "update", "data": [{"asks": [["84100", "0", "0", "0"], ["84101", "0", "0", "0"], ["84101.1", "0", "0", "0"], ["84102", "0", "0", "0"], ["84102.3", "0.01237886", "0", "3"], ["84102.7", "0", "0", "0"], ["84103.8", "0", "0", "0"], ["84104", "0", "0", "0"], ["84105.1", "0.05486477", "0", "2"], ["84106.4", "0", "0", "0"], ["84108", "0.0146", "0", "1"], ["84108.5", "0", "0", "0"], ["84108.7", "0", "0", "0"], ["84108.9", "0.04", "0", "1"], ["84110.1", "0", "0", "0"], ["84111.1", "0", "0", "0"], ["84112", "0.0146", "0", "1"], ["84112.7", "0", "0", "0"], ["84113.3", "0", "0", "0"], ["84113.6", "0", "0", "0"], ["84113.7", "0.11504279", "0", "1"], ["84113.9", "0", "0", "0"], ["84114.3", "0.06", "0", "2"], ["84114.9", "0", "0", "0"], ["84115", "0.00001501", "0", "1"], ["84115.4", "0.11228184", "0", "2"], ["84117.2", "0", "0", "0"], ["84117.8", "0.06905786", "0", "2"], ["84117.9", "0.56028071", "0", "2"], ["84118", "0", "0", "0"], ["84118.3", "0.19349592", "0", "3"], ["84119.4", "0", "0", "0"], ["84120.1", "0.05942035", "0", "2"], ["84120.2", "0", "0", "0"], ["84120.3", "0.1720023", "0", "2"], ["84122.3", "0", "0", "0"], ["84122.4", "0", "0", "0"], ["84124.6", "0.03471853", "0", "1"], ["84124.9", "0.03354359", "0", "1"], ["84126.5", "0.03493302", "0", "1"], ["84126.6", "0.03293209", "0", "1"], ["84126.9", "1", "0", "1"], ["84127.3", "0", "0", "0"], ["84129", "0", "0", "0"], ["84129.1", "0", "0", "0"], ["84129.6", "0", "0", "0"], ["84131.1", "0", "0", "0"], ["84131.9", "0.06624849", "0", "1"], ["84133.2", "0.06991401", "0", "1"], ["84134.4", "0.17821722", "0", "1"], ["84134.7", "0", "0", "0"], ["84135.2", "0", "0", "0"], ["84135.9", "0.23790227", "0", "1"], ["84137.6", "0.07999999", "0", "2"], ["84138.3", "0", "0", "0"], ["84138.4", "0.03999999", "0", "1"], ["84139.2", "0", "0", "0"], ["84139.8", "0.0585862", "0", "1"], ["84149.2", "0", "0", "0"], ["84149.9", "0.00061841", "0", "2"], ["84150", "0", "0", "0"], ["84152.1", "0", "0", "0"], ["84152.5", "0", "0", "0"], ["84153.6", "0", "0", "0"], ["84160.3", "0.917", "0", "1"], ["84164.6", "0", "0", "0"], ["84169.9", "0.01188309", "0", "1"], ["84170.4", "0", "0", "0"], ["84170.8", "0", "0", "0"], ["84190.8", "0.041883", "0", "2"], ["84193.7", "0.01188298", "0", "1"], ["84196.5", "0.01188297", "0", "1"], ["84199.3", "0.01188295", "0", "1"], ["84215.4", "0.13067811", "0", "3"], ["84224.3", "0.0004", "0", "1"], ["84260.6", "0.0000142", "0", "1"], ["84260.8", "0.00001852", "0", "1"], ["84261.1", "0.01299784", "0", "1"], ["84262.2", "0.00003778", "0", "1"], ["84262.4", "0.0000221", "0", "1"], ["84262.9", "0.17821722", "0", "1"], ["84263.9", "0.00003969", "0", "2"], ["84264", "0.00074396", "0", "1"], ["84264.7", "0.2025", "0", "1"], ["84264.9", "0.00031778", "0", "3"], ["84265.1", "0.00418989", "0", "1"], ["84265.8", "0.00001156", "0", "1"], ["84266", "0.11878326", "0", "1"], ["84266.2", "0.14240602", "0", "2"], ["84266.4", "0.00001402", "0", "1"], ["84266.5", "0.00054835", "0", "1"], ["84266.6", "0.01217191", "0", "13"], ["84266.7", "0.00002129", "0", "1"], ["84266.9", "0.00013853", "0", "2"], ["84267.3", "0.35615346", "0", "2"], ["84268", "0.00118668", "0", "1"]], "bids": [["84102.2", "1.67422831", "0", "16"], ["84102", "0.0146", "0", "1"], ["84101.1", "0.35159543", "0", "1"], ["84101", "0.2025", "0", "1"], ["84100.5", "0.08991011", "0", "1"], ["84100", "0.01461", "0", "2"], ["84099.9", "0.05203344", "0", "3"], ["84097.1", "0.01339", "0", "1"], ["84097", "0.03854779", "0", "1"], ["84095.5", "0", "0", "0"], ["84095.4", "0.00001197", "0", "1"], ["84094.8", "0.23238505", "0", "2"], ["84094.4", "0.40837868", "0", "3"], ["84094.1", "0.04018", "0", "1"], ["84093.9", "0.00772798", "0", "1"], ["84093.1", "0", "0", "0"], ["84092.9", "0.000015", "0", "1"], ["84090.6", "0.03229695", "0", "1"], ["84090.2", "0.4208348", "0", "2"], ["84089.8", "0.03330353", "0", "1"], ["84089.7", "0", "0", "0"], ["84089.1", "0.03083046", "0", "1"], ["84088.9", "0.03453447", "0", "1"], ["84088.7", "1.17821722", "0", "2"], ["84087.1", "0.07547216", "0", "1"], ["84086.4", "0.02846459", "0", "1"], ["84086.2", "0", "0", "0"], ["84086", "0", "0", "0"], ["84085.6", "0", "0", "0"], ["84085.1", "0", "0", "0"], ["84084.9", "0", "0", "0"], ["84084.6", "0", "0", "0"], ["84084.5", "0.000015", "0", "1"], ["84084.4", "0.01339", "0", "1"], ["84083.8", "0.02817312", "0", "1"], ["84083.7", "0", "0", "0"], ["84083.6", "0.0345409", "0", "1"], ["84083.3", "0.00060645", "0", "1"], ["84083.1", "0.05596287", "0", "2"], ["84082.6", "0.03438549", "0", "1"], ["84081.2", "0.045", "0", "1"], ["84081.1", "0.00475731", "0", "1"], ["84081", "0.03103562", "0", "1"], ["84080.4", "0.03290442", "0", "1"], ["84079.8", "0", "0", "0"], ["84079", "0", "0", "0"], ["84078.2", "0.23018009", "0", "3"], ["84077.8", "0.23790227", "0", "1"], ["84077.7", "0.17836", "0", "1"], ["84076.8", "0", "0", "0"], ["84076.6", "0.06802292", "0", "2"], ["84076.2", "0", "0", "0"], ["84075.1", "0", "0", "0"], ["84074.3", "0", "0", "0"], ["84073.8", "0.20380003", "0", "5"], ["84073.7", "0.06246247", "0", "1"], ["84073.6", "0.02745264", "0", "1"], ["84072.4", "0.05729124", "0", "1"], ["84072", "0.0025", "0", "1"], ["84071.9", "0", "0", "0"], ["84071.2", "0", "0", "0"], ["84070.8", "0", "0", "0"], ["84070", "0.005", "0", "2"], ["84069.5", "0.00357", "0", "1"], ["84068.7", "0", "0", "0"], ["84068.1", "0", "0", "0"], ["84067.3", "0.00420625", "0", "1"], ["84067", "0", "0", "0"], ["84066.4", "0.01774536", "0", "1"], ["84066.1", "0", "0", "0"], ["84064.7", "0", "0", "0"], ["84058", "0.0103941", "0", "1"], ["84057.6", "0.08", "0", "2"], ["84056.8", "0.04", "0", "1"], ["84056", "0", "0", "0"], ["84055.2", "0.1", "0", "2"], ["84054.4", "0.05", "0", "1"], ["84052", "0", "0", "0"], ["84051.2", "0", "0", "0"], ["84047.5", "0", "0", "0"], ["84045.1", "0.01193567", "0", "2"], ["84040.8", "0", "0", "0"], ["84036.8", "0", "0", "0"], ["84028.2", "0.01188256", "0", "1"], ["84023.2", "0", "0", "0"], ["84020.4", "0.04947623", "0", "1"], ["84018", "0", "0", "0"], ["84010.5", "0.01204523", "0", "2"], ["84007.7", "0.01188267", "0", "1"], ["84004.9", "0.01188267", "0", "1"], ["84002.9", "0", "0", "0"], ["84000.5", "0.00601505", "0", "2"], ["83995.5", "0", "0", "0"], ["83983.6", "0.1901", "0", "2"], ["83961.7", "0", "0", "0"], ["83959.4", "0", "0", "0"], ["83943.1", "0", "0", "0"]], "ts": "1742554965804", "checksum": -1901294262, "seqId": 49927374272, "prevSeqId": 49927373741}], "record_time": 1742554965.804584, "EXCHANGE": "OKX"}
{"arg": {"channel": "books", "instId": "BTC-USDT"}, "action": "update", "data": [{"asks": [["84105.1", "0", "0", "0"], ["84105.9", "0.0207645", "0", "1"], ["84109.2", "0.07795953", "0", "1"], ["84110.6", "0", "0", "0"], ["84116.7", "0.06", "0", "2"], ["84117.1", "0.04751826", "0", "2"], ["84117.8", "0", "0", "0"], ["84117.9", "0.52691225", "0", "1"], ["84118.3", "0.15893729", "0", "2"], ["84118.5", "0.03061221", "0", "1"], ["84118.6", "0.03403232", "0", "1"], ["84118.7", "0.03486012", "0", "1"], ["84119", "0.03197433", "0", "1"], ["84122.1", "0.0012675", "0", "1"], ["84124.6", "0", "0", "0"], ["84124.9", "0.13379", "0", "1"], ["84125.3", "0.0501612", "0", "2"], ["84125.5", "0.03269646", "0", "1"], ["84126.5", "0", "0", "0"], ["84126.6", "0", "0", "0"], ["84126.9", "0", "0", "0"], ["84127.4", "0.03441753", "0", "1"], ["84127.5", "1.0346082", "0", "2"], ["84131.9", "0", "0", "0"], ["84132.4", "0.25264966", "0", "4"], ["84132.5", "0.06622729", "0", "1"], ["84133.2", "0", "0", "0"], ["84134.1", "0.06361811", "0", "1"], ["84134.8", "0.06871396", "0", "1"], ["84135.9", "0", "0", "0"], ["84136.1", "0.06457917", "0", "1"], ["84137.6", "0", "0", "0"], ["84138.4", "0", "0", "0"], ["84139.2", "0.07999999", "0", "2"], ["84140", "0.04006695", "0", "4"], ["84144.6", "0", "0", "0"], ["84145", "0.20001197", "0", "2"], ["84146.9", "0.1", "0", "1"], ["84153", "0.06214", "0", "3"], ["84153.6", "0.00004312", "0", "1"], ["84163.7", "0", "0", "0"], ["84165.3", "0.07128836", "0", "1"], ["84168.3", "0.01125987", "0", "1"], ["84169.9", "0", "0", "0"], ["84179.2", "0", "0", "0"], ["84180.9", "0", "0", "0"], ["84182.9", "0.00012217", "0", "1"], ["84183", "0", "0", "0"], ["84193.7", "0", "0", "0"], ["84199.3", "0", "0", "0"], ["84232.8", "0.01188277", "0", "1"], ["84235.2", "0.29933821", "0", "3"], ["84237.6", "0.01188274", "0", "1"], ["84268", "0", "0", "0"]], "bids": [["84102.2", "1.69206531", "0", "17"], ["84101.1", "0.11206737", "0", "1"], ["84100.5", "0", "0", "0"], ["84095.8", "0.0000165", "0", "1"], ["84093.9", "0.04497028", "0", "2"], ["84091.2", "0.03299046", "0", "1"], ["84090.6", "0.03280642", "0", "1"], ["84090.2", "0.44669297", "0", "2"], ["84090.1", "0.04", "0", "1"], ["84090", "0.3067835", "0", "10"], ["84089.8", "0", "0", "0"], ["84089.6", "0.03438149", "0", "1"], ["84089.1", "0", "0", "0"], ["84088.9", "0", "0", "0"], ["84088.7", "0.17821722", "0", "1"], ["84088.4", "1", "0", "1"], ["84087.2", "0.11947916", "0", "1"], ["84087.1", "0", "0", "0"], ["84086.4", "0", "0", "0"], ["84085.7", "0.01596287", "0", "1"], ["84084.7", "0.00420528", "0", "1"], ["84084.6", "0.102", "0", "2"], ["84084.2", "0.03170653", "0", "1"], ["84084.1", "0.11898554", "0", "1"], ["84083.8", "0", "0", "0"], ["84083.6", "0", "0", "0"], ["84083.3", "0.03452769", "0", "2"], ["84082.6", "0", "0", "0"], ["84081.9", "0.0333603", "0", "1"], ["84081.3", "0.16615885", "0", "2"], ["84081.2", "0.138", "0", "3"], ["84081.1", "0", "0", "0"], ["84081", "0", "0", "0"], ["84080.4", "0", "0", "0"], ["84077.8", "0", "0", "0"], ["84077.2", "0.12225857", "0", "2"], ["84076.6", "0.00420551", "0", "1"], ["84074.7", "0.23791204", "0", "1"], ["84074.6", "0.06353238", "0", "1"], ["84073.9", "0.06371784", "0", "2"], ["84073.7", "0", "0", "0"], ["84073.1", "0.06383488", "0", "1"], ["84072.8", "0.02817312", "0", "1"], ["84060.1", "0.12842", "0", "2"], ["84058.5", "0.17821722", "0", "1"], ["84052.4", "0.1", "0", "1"], ["84050.5", "0.01833392", "0", "2"], ["84050.1", "0.00100367", "0", "1"], ["84046.7", "0", "0", "0"], ["84037.6", "0.0028518", "0", "1"], ["84037.5", "0.05952577", "0", "1"], ["84035.9", "0.00106359", "0", "2"], ["84035.1", "0.01", "0", "1"], ["84033.9", "0", "0", "0"], ["84014.7", "0", "0", "0"], ["84005", "0", "0", "0"], ["84000.2", "0.07142831", "0", "1"], ["83997", "0.00579988", "0", "1"], ["83996.3", "0.01189488", "0", "2"], ["83979.8", "0.18318929", "0", "1"], ["83975.2", "0", "0", "0"], ["83971.5", "0.00202451", "0", "2"], ["83969.4", "0.01194665", "0", "1"]], "ts": "1742554965904", "checksum": -229466444, "seqId": 49927374509, "prevSeqId": 49927374272}], "record_time": 1742554965.904676, "EXCHANGE": "OKX"}
{"arg": {"channel": "books", "instId": "BTC-USDT"}, "action": "update", "data": [{"asks": [["84105.9", "0", "0", "0"], ["84107.7", "0.0186986", "0", "1"], ["84107.8", "0.00772868", "0", "1"], ["84110.9", "0", "0", "0"], ["84113.1", "0.01055", "0", "1"], ["84114.3", "0", "0", "0"], ["84116", "0.03854779", "0", "1"], ["84116.9", "0.00772868", "0", "1"], ["84117.3", "0.01055", "0", "1"], ["84118.3", "0.11893729", "0", "1"], ["84118.5", "0", "0", "0"], ["84118.6", "0", "0", "0"], ["84118.7", "0", "0", "0"], ["84118.9", "0.03371466", "0", "1"], ["84119", "0.032726", "0", "1"], ["84119.7", "0.06", "0", "2"], ["84121", "0.0035789", "0", "1"], ["84121.6", "0.04", "0", "1"], ["84122.1", "0", "0", "0"], ["84125.3", "0.01603713", "0", "1"], ["84125.5", "0", "0", "0"], ["84127.4", "0", "0", "0"], ["84127.5", "1", "0", "1"], ["84132.4", "0.01473762", "0", "3"], ["84132.5", "0", "0", "0"], ["84132.8", "0.23791268", "0", "1"], ["84134.1", "0", "0", "0"], ["84134.4", "0.24312299", "0", "2"], ["84134.8", "0", "0", "0"], ["84136.1", "0", "0", "0"], ["84136.4", "0.06668757", "0", "1"], ["84139.2", "0", "0", "0"], ["84140", "0.08006695", "0", "5"], ["84140.8", "0.15846251", "0", "2"], ["84145", "0.00001197", "0", "1"], ["84148", "0", "0", "0"], ["84180.9", "0.07127514", "0", "1"], ["84190.8", "0.03", "0", "1"], ["84196.5", "0", "0", "0"], ["84199.2", "1.89141891", "0", "2"], ["84201.9", "0.06118762", "0", "3"], ["84215.4", "0.11879524", "0", "2"], ["84229.2", "0", "0", "0"], ["84238.6", "0.00594514", "0", "1"], ["84244.5", "0.05865156", "0", "2"], ["84246", "0", "0", "0"], ["84249", "0.01188267", "0", "1"], ["84255.5", "0.01783542", "0", "3"], ["84268.4", "0.00001026", "0", "1"], ["84268.5", "0.00002533", "0", "1"]], "bids": [["84102.2", "1.71329531", "0", "19"], ["84101.1", "0.08107734", "0", "1"], ["84099.9", "0.05196287", "0", "2"], ["84097.1", "0", "0", "0"], ["84095.1", "0.02846459", "0", "1"], ["84091.2", "0", "0", "0"], ["84090.9", "0.03272656", "0", "1"], ["84090.6", "0", "0", "0"], ["84090.3", "0.03283631", "0", "1"], ["84090", "0.273983", "0", "9"], ["84089.6", "0", "0", "0"], ["84084.2", "0", "0", "0"], ["84083.3", "0.00060645", "0", "1"], ["84083.2", "0.042", "0", "1"], ["84081.9", "0", "0", "0"], ["84081.3", "0.133783", "0", "1"], ["84077.2", "0", "0", "0"], ["84074.9", "0.06952572", "0", "1"], ["84074.7", "0", "0", "0"], ["84074.6", "0", "0", "0"], ["84074.1", "0.06498348", "0", "1"], ["84073.9", "0.23796595", "0", "2"], ["84073.8", "0.15880003", "0", "4"], ["84073.4", "0.06481727", "0", "1"], ["84073.1", "0", "0", "0"], ["84067.6", "0.01774536", "0", "1"], ["84066.4", "0", "0", "0"], ["84061.8", "0.00356658", "0", "1"], ["84042.5", "0.00237069", "0", "2"], ["84031.2", "0.01901497", "0", "1"], ["84015.8", "0.07141506", "0", "1"], ["84007.7", "0.07187667", "0", "2"], ["83996.9", "0", "0", "0"], ["83970.8", "0.01189549", "0", "1"], ["83943.8", "0", "0", "0"], ["83943.1", "0.01775819", "0", "1"]], "ts": "1742554966004", "checksum": -130011888, "seqId": 49927374703, "prevSeqId": 49927374509}], "record_time": 1742554966.004455, "EXCHANGE": "OKX"}
{"arg": {"channel": "books", "instId": "BTC-USDT"}, "action": "update", "data": [{"asks": [["84104", "0.0146", "0", "1"], ["84106.6", "0", "0", "0"], ["84107.7", "0", "0", "0"], ["84107.8", "0", "0", "0"], ["84108.9", "0", "0", "0"], ["84109.2", "0.0561993", "0", "1"], ["84112.9", "0", "0", "0"], ["84114.1", "0.01189528", "0", "1"], ["84115.5", "0.04", "0", "1"], ["84116.7", "0", "0", "0"], ["84116.8", "0", "0", "0"], ["84117.9", "0.26888154", "0", "1"], ["84118.9", "0", "0", "0"], ["84119", "0", "0", "0"], ["84119.1", "0.36188915", "0", "4"], ["84119.3", "0", "0", "0"], ["84119.4", "0.07201386", "0", "2"], ["84119.5", "0.06", "0", "2"], ["84119.7", "0.0940604", "0", "3"], ["84120", "0.11896403", "0", "3"], ["84121", "0", "0", "0"], ["84122.2", "0.29684137", "0", "1"], ["84122.9", "0.06", "0", "2"], ["84123.1", "0.0103941", "0", "1"], ["84123.7", "0", "0", "0"], ["84124.9", "0", "0", "0"], ["84125.1", "0.17822919", "0", "2"], ["84126", "0.03236811", "0", "1"], ["84126.4", "0.03257134", "0", "1"], ["84127.4", "0.10168196", "0", "2"], ["84127.5", "0", "0", "0"], ["84127.8", "0.0338565", "0", "1"], ["84127.9", "0.03400457", "0", "1"], ["84128.1", "0.23791065", "0", "1"], ["84128.2", "0.08606", "0", "1"], ["84132.4", "0.03276057", "0", "3"], ["84132.8", "0", "0", "0"], ["84133.4", "0.0698595", "0", "1"], ["84134.4", "0.17821722", "0", "1"], ["84134.5", "0.06826892", "0", "1"], ["84135.4", "0.06595622", "0", "1"], ["84136.4", "0", "0", "0"], ["84136.6", "0.06744095", "0", "1"], ["84139.8", "0", "0", "0"], ["84140", "0.00006696", "0", "3"], ["84140.3", "0.0004", "0", "1"], ["84140.8", "0.11846252", "0", "1"], ["84141.6", "0.07999999", "0", "2"], ["84142.4", "0.03999999", "0", "1"], ["84144.1", "0", "0", "0"], ["84144.6", "0.0004", "0", "1"], ["84147.9", "0", "0", "0"], ["84148.7", "0", "0", "0"], ["84148.8", "0.0104", "0", "2"], ["84149.3", "0", "0", "0"], ["84149.6", "0.03", "0", "1"], ["84150.2", "0.00420106", "0", "1"], ["84153.6", "0", "0", "0"], ["84156.2", "0.00004312", "0", "1"], ["84157.7", "0.01188246", "0", "1"], ["84160.3", "0", "0", "0"], ["84165.3", "0", "0", "0"], ["84167.3", "0.916924", "0", "1"], ["84167.5", "0.2025", "0", "1"], ["84168.3", "0", "0", "0"], ["84173.8", "0.0112737", "0", "2"], ["84180.9", "0.14255028", "0", "2"], ["84182.9", "0", "0", "0"], ["84183.2", "0.00012217", "0", "1"], ["84185", "0.08697303", "0", "1"], ["84187.5", "0", "0", "0"], ["84198.8", "0", "0", "0"], ["84201.9", "1.43600862", "0", "4"], ["84212.8", "0.001965", "0", "1"], ["84232.8", "0", "0", "0"], ["84235.2", "0.28745545", "0", "2"], ["84237.6", "0", "0", "0"], ["84268.8", "0.08991011", "0", "1"], ["84269.1", "0.00002271", "0", "1"], ["84269.2", "0.72153373", "0", "1"], ["84269.9", "0.00001012", "0", "1"], ["84270.6", "0.08741", "0", "1"]], "bids": [["84102.2", "1.83232638", "0", "21"], ["84101.7", "0.09382994", "0", "2"], ["84101.6", "0.03854779", "0", "1"], ["84101.1", "0", "0", "0"], ["84097", "0", "0", "0"], ["84092.1", "0.03263902", "0", "1"], ["84091.7", "0.54409397", "0", "1"], ["84091.6", "1", "0", "1"], ["84091.1", "0.03446133", "0", "1"], ["84090.9", "0", "0", "0"], ["84090.4", "0.03133852", "0", "1"], ["84090.3", "0.03354458", "0", "1"], ["84090.2", "0", "0", "0"], ["84088.8", "0.17835", "0", "1"], ["84088.4", "0", "0", "0"], ["84085.1", "0.03180313", "0", "1"], ["84084", "0.42760206", "0", "4"], ["84081.7", "0.03431501", "0", "1"], ["84080.3", "0.17835", "0", "1"], ["84078.1", "0.07645183", "0", "3"], ["84077.7", "0", "0", "0"], ["84075.5", "0", "0", "0"], ["84075", "0.06249144", "0", "1"], ["84074.9", "0.23791065", "0", "1"], ["84074.5", "0.06938295", "0", "1"], ["84074.1", "0", "0", "0"], ["84073.9", "0.00005327", "0", "1"], ["84073.8", "0.06580003", "0", "2"], ["84073.4", "0", "0", "0"], ["84072.4", "0", "0", "0"], ["84068", "0.0542", "0", "1"], ["84066.3", "0", "0", "0"], ["84064.5", "0", "0", "0"], ["84061.8", "0", "0", "0"], ["84057.5", "0.01839356", "0", "2"], ["84053.6", "0.0378824", "0", "3"], ["84052", "0.93006463", "0", "2"], ["84050.5", "0.000015", "0", "1"], ["84049.6", "1.12547888", "0", "4"], ["84048.5", "0", "0", "0"], ["84046.3", "0.01188267", "0", "1"], ["84043.1", "0.01188268", "0", "1"], ["84028.2", "0", "0", "0"], ["84015.8", "0.14283012", "0", "2"], ["84012.8", "0.00016257", "0", "1"], ["84010.5", "0", "0", "0"], ["84007.7", "0", "0", "0"], ["84004.9", "0", "0", "0"], ["84000.2", "0", "0", "0"], ["83996.3", "0.00001196", "0", "1"], ["83984", "0.18318629", "0", "1"], ["83983.6", "0.17821722", "0", "1"], ["83979.8", "0", "0", "0"], ["83968.3", "0.01188257", "0", "1"], ["83953.8", "0", "0", "0"], ["83943.8", "0.2025", "0", "1"]], "ts": "1742554966104", "checksum": 1966896611, "seqId": 49927375075, "prevSeqId": 49927374703}], "record_time": 1742554966.10701, "EXCHANGE": "OKX"}
{"arg": {"channel": "books", "instId": "BTC-USDT"}, "action": "update", "data": [{"asks": [["84102.3", "0.27687886", "0", "6"], ["84104.6", "0.03586536", "0", "1"], ["84104.7", "0.11895659", "0", "1"], ["84109.2", "0.10992439", "0", "2"], ["84110.8", "0.2025", "0", "1"], ["84114.1", "0", "0", "0"], ["84115.8", "0.03330992", "0", "1"], ["84115.9", "0.06695463", "0", "2"], ["84116.2", "0.03272095", "0", "1"], ["84117.1", "0.0297729", "0", "1"], ["84119.1", "0.29728621", "0", "2"], ["84119.4", "0.03714986", "0", "1"], ["84119.7", "0.06", "0", "2"], ["84122.2", "0.61259524", "0", "2"], ["84122.5", "0.03131969", "0", "1"], ["84122.8", "0.03061354", "0", "1"], ["84123.9", "1", "0", "1"], ["84124.6", "0.03271392", "0", "1"], ["84124.7", "0.03429174", "0", "1"], ["84126", "0", "0", "0"], ["84126.4", "0", "0", "0"], ["84126.9", "0.23791997", "0", "1"], ["84127.4", "0.04574294", "0", "1"], ["84127.8", "0", "0", "0"], ["84127.9", "0", "0", "0"], ["84128.1", "0", "0", "0"], ["84129.1", "0.12485", "0", "1"], ["84129.5", "0.13379", "0", "1"], ["84129.8", "0.06118005", "0", "1"], ["84130.5", "1.53328625", "0", "1"], ["84131.3", "0.0690056", "0", "1"], ["84132", "0.0657547", "0", "1"], ["84133.4", "0.06417273", "0", "1"], ["84134.5", "0", "0", "0"], ["84134.9", "0", "0", "0"], ["84135.4", "0", "0", "0"], ["84136.6", "0", "0", "0"], ["84137", "0", "0", "0"], ["84143.4", "0.92051147", "0", "2"], ["84149.6", "0", "0", "0"], ["84150.2", "0.12905106", "0", "2"], ["84152.2", "0", "0", "0"], ["84160", "2.8123547", "0", "2"], ["84160.1", "0.7", "0", "1"], ["84166.6", "0.00104525", "0", "3"], ["84171.5", "0.0112587", "0", "1"], ["84173", "0.01774536", "0", "1"], ["84173.1", "0.22037851", "0", "1"], ["84173.8", "0.000015", "0", "1"], ["84174.4", "0", "0", "0"], ["84206.9", "0", "0", "0"], ["84248.6", "0.03", "0", "1"], ["84268.5", "0", "0", "0"], ["84268.8", "0", "0", "0"], ["84269.1", "0", "0", "0"], ["84269.2", "0", "0", "0"], ["84269.9", "0", "0", "0"], ["84270.6", "0", "0", "0"]], "bids": [["84102.2", "1.59632638", "0", "19"], ["84101.6", "0", "0", "0"], ["84097.6", "0.03854779", "0", "1"], ["84094.8", "0.14247494", "0", "1"], ["84092.1", "0", "0", "0"], ["84091.7", "0.22368525", "0", "1"], ["84091.6", "0", "0", "0"], ["84091.1", "0.11897566", "0", "1"], ["84090.4", "0", "0", "0"], ["84090.3", "0", "0", "0"], ["84088.5", "0.03059203", "0", "1"], ["84088.2", "0.43091556", "0", "3"], ["84087.9", "0.03484062", "0", "1"], ["84087.2", "0.03278887", "0", "1"], ["84086.8", "0.03419936", "0", "1"], ["84086.6", "1", "0", "1"], ["84085.1", "0", "0", "0"], ["84084", "0.39502822", "0", "3"], ["84082", "0.08991011", "0", "1"], ["84081.7", "0", "0", "0"], ["84081.5", "0.03221819", "0", "1"], ["84080.5", "0.03222158", "0", "2"], ["84079.1", "0.03269266", "0", "1"], ["84078.5", "0.03094626", "0", "1"], ["84078.1", "0.01", "0", "2"], ["84075.8", "0", "0", "0"], ["84075", "0", "0", "0"], ["84074.9", "0", "0", "0"], ["84074.6", "1.60180306", "0", "1"], ["84074.5", "0.06224731", "0", "1"], ["84073.8", "0.02380003", "0", "1"], ["84073.6", "0", "0", "0"], ["84071.8", "0.07043534", "0", "1"], ["84071.2", "0.23791997", "0", "1"], ["84071.1", "0.06697868", "0", "1"], ["84070.4", "0.06588396", "0", "1"], ["84068", "0", "0", "0"], ["84066.1", "0.12485", "0", "1"], ["84057.7", "0.02745264", "0", "1"], ["84057.5", "0.00007494", "0", "1"], ["84054.9", "0.01831855", "0", "1"], ["84049.6", "0.02916532", "0", "3"], ["84048.3", "0", "0", "0"], ["84045.1", "0.13678567", "0", "3"], ["84031.5", "0.00103791", "0", "1"], ["84005.5", "0", "0", "0"], ["83984", "0", "0", "0"], ["83983.7", "0.1890006", "0", "3"], ["83945.8", "0", "0", "0"]], "ts": "1742554966204", "checksum": -2030361820, "seqId": 49927375292, "prevSeqId": 49927375075}], "record_time": 1742554966.204549, "EXCHANGE": "OKX"}
{"arg": {"channel": "books", "instId": "BTC-USDT"}, "action": "update", "data": [{"asks": [["84102.3", "0.47015423", "0", "8"], ["84113.2", "0.01055", "0", "1"], ["84115.5", "0.07220623", "0", "2"], ["84115.8", "0", "0", "0"], ["84116.1", "0.03103781", "0", "1"], ["84116.2", "0", "0", "0"], ["84117.3", "0", "0", "0"], ["84122.4", "0.03482817", "0", "1"], ["84122.5", "0.03102243", "0", "1"], ["84122.8", "0", "0", "0"], ["84129.5", "0.19909088", "0", "2"], ["84129.8", "0", "0", "0"], ["84131.9", "0.06856687", "0", "1"], ["84132", "0", "0", "0"], ["84149.3", "0.35671", "0", "1"], ["84153", "0.00214", "0", "1"], ["84170.4", "0.2497", "0", "1"], ["84191.4", "0.2497", "0", "1"], ["84268.4", "0", "0", "0"]], "bids": [["84102.2", "1.30539638", "0", "16"], ["84099.7", "0.01339", "0", "1"], ["84098.9", "0.00772868", "0", "1"], ["84090", "0.27256914", "0", "8"], ["84088.5", "0", "0", "0"], ["84088.2", "0.46484729", "0", "4"], ["84086.8", "0", "0", "0"], ["84086.7", "0.03253455", "0", "1"], ["84084", "0.3086945", "0", "3"], ["84081.5", "0", "0", "0"], ["84081.2", "0.17094347", "0", "4"], ["84080.5", "0.00001197", "0", "1"], ["84080.4", "0.03156294", "0", "1"], ["84074.5", "0", "0", "0"], ["84074.2", "0.06246461", "0", "1"], ["84071.1", "0", "0", "0"], ["84071", "0.07316467", "0", "3"], ["84067.6", "0", "0", "0"], ["84058.5", "0.53492722", "0", "2"], ["84058.4", "0.1", "0", "2"], ["84057.6", "0.13", "0", "3"], ["84055.2", "0", "0", "0"], ["84054.9", "0", "0", "0"], ["84054.4", "0", "0", "0"], ["84052.6", "0.01831988", "0", "1"], ["84044", "0", "0", "0"], ["84039.8", "0.18535669", "0", "2"], ["84037.6", "0.02059716", "0", "2"], ["84035.6", "0", "0", "0"], ["84023.2", "0.2497", "0", "1"], ["84011.4", "0.059992", "0", "1"], ["83983.7", "0.00581501", "0", "2"], ["83979.8", "0.18319886", "0", "1"], ["83942", "0.00007352", "0", "1"]], "ts": "1742554966304", "checksum": 790688872, "seqId": 49927375358, "prevSeqId": 49927375292}], "record_time": 1742554966.30572, "EXCHANGE": "OKX"}
{"arg": {"channel": "books", "instId": "BTC-USDT"}, "action": "update", "data": [{"asks": [["84113.7", "0.25501976", "0", "2"], ["84116.5", "0.35641581", "0", "1"], ["84121", "0.0035118", "0", "1"], ["84130.2", "0.81359207", "0", "2"], ["84146.4", "0.06158295", "0", "1"], ["84159.9", "1.04524909", "0", "1"], ["84160.1", "0", "0", "0"], ["84160.2", "0", "0", "0"], ["84173", "0", "0", "0"], ["84181", "0.03567366", "0", "1"], ["84201.8", "0.4826249", "0", "2"], ["84212.4", "0", "0", "0"], ["84242.1", "0.01493332", "0", "1"], ["84267.2", "0.01774536", "0", "1"], ["84267.3", "0", "0", "0"]], "bids": [["84102.2", "1.20539638", "0", "15"], ["84090", "0.26746538", "0", "5"], ["84079", "0.05879676", "0", "1"], ["84074.7", "0.61257469", "0", "1"], ["84061.5", "0.51630795", "0", "2"], ["84055.2", "0.01153357", "0", "1"], ["84051", "0.00576678", "0", "1"], ["84046.8", "0.00576678", "0", "1"], ["84045.2", "0.47301352", "0", "1"], ["84021.7", "0", "0", "0"], ["84020.4", "0.21444756", "0", "2"], ["83995.8", "0", "0", "0"], ["83973.5", "0", "0", "0"], ["83943.5", "0", "0", "0"], ["83943.1", "0", "0", "0"], ["83942", "0", "0", "0"]], "ts": "1742554966404", "checksum": -1036702465, "seqId": 49927375396, "prevSeqId": 49927375358}], "record_time": 1742554966.407593, "EXCHANGE": "OKX"}
{"arg": {"channel": "books", "instId": "BTC-USDT"}, "action": "update", "data": [{"asks": [["84102.3", "0.58911412", "0", "9"], ["84104.6", "0", "0", "0"], ["84104.7", "0", "0", "0"], ["84109.9", "0.00772868", "0", "1"], ["84140.8", "0.19846252", "0", "3"], ["84141.6", "0.03999999", "0", "1"], ["84142.4", "0", "0", "0"], ["84267.3", "0.35615346", "0", "2"], ["84268.4", "0.00001026", "0", "1"]], "bids": [["84102.2", "1.20540638", "0", "16"], ["84101.7", "0.03941554", "0", "1"], ["84101", "0", "0", "0"], ["84086.6", "0", "0", "0"], ["84086.4", "1", "0", "1"], ["84062.4", "0.08", "0", "2"], ["84061.6", "0.04", "0", "1"], ["84057.6", "0.05", "0", "1"], ["84056.8", "0", "0", "0"], ["84055", "0.2", "0", "1"], ["84045.9", "0.01774536", "0", "1"], ["84037.6", "0.0028518", "0", "1"], ["83944.6", "0", "0", "0"], ["83943.8", "0", "0", "0"]], "ts": "1742554966504", "checksum": -251417536, "seqId": 49927375423, "prevSeqId": 49927375396}], "record_time": 1742554966.503936, "EXCHANGE": "OKX"}
{"arg": {"channel": "books", "instId": "BTC-USDT"}, "action": "update", "data": [{"asks": [["84102.3", "0.47015423", "0", "8"], ["84104.1", "0.03586556", "0", "1"], ["84104.2", "0.11895727", "0", "1"], ["84116.5", "0.71312581", "0", "2"], ["84170.4", "0", "0", "0"], ["84191.4", "0", "0", "0"]], "bids": [["84091.7", "0.61420635", "0", "1"], ["84088.8", "0.53506", "0", "2"], ["84088.6", "1", "0", "1"], ["84088.2", "0.18463669", "0", "4"], ["84086.4", "0", "0", "0"], ["84055", "0", "0", "0"], ["84023.2", "0", "0", "0"], ["83944.6", "0.00421935", "0", "1"], ["83943.8", "0.2025", "0", "1"]], "ts": "1742554966604", "checksum": -1266423973, "seqId": 49927375443, "prevSeqId": 49927375423}], "record_time": 1742554966.604251, "EXCHANGE": "OKX"}
{"arg": {"channel": "books", "instId": "BTC-USDT"}, "action": "update", "data": [{"asks": [["84112.3", "0.04854779", "0", "3"], ["84116", "0", "0", "0"], ["84126.9", "0", "0", "0"], ["84129", "0.23791602", "0", "1"], ["84140.8", "0.19846251", "0", "3"], ["84149.3", "0", "0", "0"], ["84268.5", "0.00002533", "0", "1"], ["84268.8", "0.08991011", "0", "1"]], "bids": [["84091.7", "0.34191907", "0", "1"], ["84088.6", "0", "0", "0"], ["84088.2", "0.46704857", "0", "5"], ["84085.9", "1", "0", "1"], ["84072.9", "0.23791602", "0", "1"], ["84071.2", "0", "0", "0"], ["84058.5", "0.17821722", "0", "1"]], "ts": "1742554966704", "checksum": -276561659, "seqId": 49927375469, "prevSeqId": 49927375443}], "record_time": 1742554966.70434, "EXCHANGE": "OKX"}
{"arg": {"channel": "books", "instId": "BTC-USDT"}, "action": "update", "data": [{"asks": [["84102.4", "0.11895987", "0", "1"], ["84104.1", "0", "0", "0"], ["84104.2", "0", "0", "0"], ["84128.3", "0.2497", "0", "1"], ["84132.4", "0.00897", "0", "2"], ["84149.3", "0.2497", "0", "1"], ["84268.8", "0", "0", "0"]], "bids": [["84102.2", "1.08397638", "0", "15"], ["84085.9", "0", "0", "0"], ["84084.5", "1.000015", "0", "2"], ["84065.2", "0.2497", "0", "1"]], "ts": "1742554966804", "checksum": 1185141056, "seqId": 49927375494, "prevSeqId": 49927375469}], "record_time": 1742554966.807952, "EXCHANGE": "OKX"}
{"arg": {"channel": "books", "instId": "BTC-USDT"}, "action": "update", "data": [{"asks": [["84105.7", "0.01232893", "0", "1"], ["84105.8", "0.01189644", "0", "1"], ["84123.6", "0.03379289", "0", "2"], ["84140", "0.08006696", "0", "5"], ["84140.8", "0.15846251", "0", "2"], ["84141.6", "0", "0", "0"], ["84229.9", "0.6", "0", "1"], ["84268.4", "0", "0", "0"], ["84268.5", "0", "0", "0"]], "bids": [["84097.1", "0.01189644", "0", "1"], ["84087.6", "1", "0", "1"], ["84084.5", "0.000015", "0", "1"], ["83944.6", "0", "0", "0"], ["83943.8", "0", "0", "0"]], "ts": "1742554966904", "checksum": 1046279856, "seqId": 49927375508, "prevSeqId": 49927375494}], "record_time": 1742554966.904847, "EXCHANGE": "OKX"}
{"arg": {"channel": "books", "instId": "BTC-USDT"}, "action": "update", "data": [{"asks": [["84102.3", "0.48412005", "0", "9"], ["84140", "0.00006696", "0", "3"], ["84140.8", "0.19846251", "0", "3"], ["84141", "1", "0", "1"], ["84141.6", "0.03999999", "0", "1"], ["84147", "0.31228184", "0", "3"], ["84267.2", "0", "0", "0"], ["84267.3", "0", "0", "0"]], "bids": [["84102.2", "1.08725638", "0", "16"], ["84087.6", "0", "0", "0"], ["84085.3", "1", "0", "1"], ["84048.4", "0.59964265", "0", "1"], ["84037.4", "0.59149287", "0", "1"], ["84036.3", "0", "0", "0"], ["84006.4", "0.59432247", "0", "1"], ["83994.2", "0.0214", "0", "1"], ["83944.8", "0", "0", "0"]], "ts": "1742554967004", "checksum": 322696691, "seqId": 49927375538, "prevSeqId": 49927375508}], "record_time": 1742554967.003611, "EXCHANGE": "OKX"}
{"arg": {"channel": "books", "instId": "BTC-USDT"}, "action": "update", "data": [{"asks": [["84102.3", "0.51176808", "0", "10"], ["84109.1", "0.02528966", "0", "1"], ["84112.3", "0.01", "0", "2"], ["84140", "0.08006696", "0", "5"], ["84140.8", "0.15846251", "0", "2"], ["84141", "0", "0", "0"], ["84141.6", "0", "0", "0"], ["84147", "0.11228184", "0", "2"], ["84158.3", "0.03", "0", "1"]], "bids": [["84097.6", "0.02528966", "0", "1"], ["84091.7", "0.6123587", "0", "2"], ["84088.4", "1", "0", "1"], ["84088.2", "0.18463669", "0", "4"], ["84085.3", "0", "0", "0"], ["84061.6", "0.066", "0", "3"], ["84060.8", "0.013", "0", "1"], ["84053.6", "0.0118824", "0", "1"], ["84052.8", "0", "0", "0"], ["84045.9", "0", "0", "0"], ["84000.1", "0.01774536", "0", "1"]], "ts": "1742554967104", "checksum": -1569559276, "seqId": 49927375567, "prevSeqId": 49927375538}], "record_time": 1742554967.104835, "EXCHANGE": "OKX"}
{"arg": {"channel": "books", "instId": "BTC-USDT"}, "action": "update", "data": [{"asks": [["84127", "0", "0", "0"], ["84130.2", "0.37803235", "0", "1"], ["84130.5", "0", "0", "0"], ["84144.1", "0.04756118", "0", "1"], ["84159.9", "0", "0", "0"], ["84160", "0.00004", "0", "1"], ["84267.3", "0.35615346", "0", "2"], ["84267.7", "0.01774536", "0", "1"]], "bids": [["84101.7", "0.04043329", "0", "2"], ["84074.7", "0", "0", "0"], ["84074.6", "0", "0", "0"], ["84037.4", "0", "0", "0"], ["84036.2", "0", "0", "0"], ["83944.8", "0.00011161", "0", "1"], ["83944.6", "0.00421935", "0", "1"], ["83943.8", "0.2025", "0", "1"], ["83943.5", "0.03", "0", "1"]], "ts": "1742554967204", "checksum": -1448184387, "seqId": 49927375584, "prevSeqId": 49927375567}], "record_time": 1742554967.20535, "EXCHANGE": "OKX"}
{"arg": {"channel": "books", "instId": "BTC-USDT"}, "action": "update", "data": [{"asks": [["84102.3", "0.53052602", "0", "11"], ["84122.6", "1", "0", "1"], ["84123.9", "0", "0", "0"], ["84129.2", "1.5913632", "0", "1"], ["84139.2", "0.07999999", "0", "2"], ["84140", "0.04006695", "0", "4"], ["84140.8", "0.11846252", "0", "1"], ["84158.7", "2.83083656", "0", "1"], ["84161.6", "0.03", "0", "1"], ["84266.7", "0", "0", "0"], ["84266.9", "0", "0", "0"], ["84267.3", "0", "0", "0"], ["84267.7", "0", "0", "0"]], "bids": [["84091.7", "0.34191907", "0", "1"], ["84088.4", "0", "0", "0"], ["84088.2", "0.46704857", "0", "5"], ["84084.3", "1", "0", "1"], ["84075.8", "1.58638802", "0", "1"], ["84059.2", "0.1", "0", "2"], ["84058.4", "0.05", "0", "1"], ["84057.6", "0", "0", "0"], ["84046.4", "2.79219103", "0", "2"], ["83943.5", "0", "0", "0"]], "ts": "1742554967304", "checksum": 1649995166, "seqId": 49927375612, "prevSeqId": 49927375584}], "record_time": 1742554967.304282, "EXCHANGE": "OKX"}
{"arg": {"channel": "books", "instId": "BTC-USDT"}, "action": "update", "data": [{"asks": [], "bids": [["84101.7", "0.04145105", "0", "3"]], "ts": "1742554967404", "checksum": -149580415, "seqId": 49927375615, "prevSeqId": 49927375612}], "record_time": 1742554967.406593, "EXCHANGE": "OKX"}
{"arg": {"channel": "books", "instId": "BTC-USDT"}, "action": "update", "data": [{"asks": [["84127.4", "0.74097975", "0", "2"], ["84128.1", "0.23791919", "0", "1"], ["84129", "0", "0", "0"], ["84155.4", "0.9850368", "0", "2"], ["84161.6", "0.06", "0", "2"], ["84206.4", "0.06217667", "0", "1"], ["84255.4", "0.089727", "0", "1"], ["84266.5", "0", "0", "0"], ["84266.6", "0", "0", "0"]], "bids": [["84102.2", "0.77248313", "0", "13"], ["84079.6", "0.78048658", "0", "2"], ["84072.9", "0", "0", "0"], ["84071.1", "0.23791919", "0", "1"], ["84048.5", "1.02287657", "0", "1"], ["84000.1", "2.70935015", "0", "2"], ["83943.8", "0", "0", "0"]], "ts": "1742554967504", "checksum": -114177651, "seqId": 49927375636, "prevSeqId": 49927375615}], "record_time": 1742554967.5121, "EXCHANGE": "OKX"}
{"arg": {"channel": "books", "instId": "BTC-USDT"}, "action": "update", "data": [{"asks": [["84111", "0.01055", "0", "1"], ["84113.2", "0", "0", "0"], ["84255.4", "0", "0", "0"], ["84266.5", "0.00054835", "0", "1"]], "bids": [["84101.7", "0.00203551", "0", "2"], ["84100.5", "0.0418433", "0", "1"], ["84099.7", "0", "0", "0"], ["84097.4", "0.01339", "0", "1"], ["84053.4", "0.01774536", "0", "1"], ["84000.1", "2.69160479", "0", "1"], ["83944.8", "0", "0", "0"], ["83944.6", "0", "0", "0"]], "ts": "1742554967604", "checksum": 2065750256, "seqId": 49927375651, "prevSeqId": 49927375636}], "record_time": 1742554967.605851, "EXCHANGE": "OKX"}
{"arg": {"channel": "books", "instId": "BTC-USDT"}, "action": "update", "data": [{"asks": [["84102.3", "0.57016953", "0", "13"], ["84138.4", "0.08", "0", "2"], ["84139.2", "0.03999999", "0", "1"], ["84140", "0.00006696", "0", "3"], ["84266.5", "0", "0", "0"]], "bids": [["84102.2", "0.71942026", "0", "11"], ["84100.5", "0.0310433", "0", "1"], ["84099.9", "0.01596287", "0", "1"], ["84063.2", "0.08", "0", "2"], ["84062.4", "0.04", "0", "1"], ["84061.6", "0.026", "0", "2"], ["83945.1", "0", "0", "0"]], "ts": "1742554967704", "checksum": 1952356175, "seqId": 49927375666, "prevSeqId": 49927375651}], "record_time": 1742554967.703825, "EXCHANGE": "OKX"}
{"arg": {"channel": "books", "instId": "BTC-USDT"}, "action": "update", "data": [{"asks": [["84124.5", "0.23792486", "0", "1"], ["84128.1", "0", "0", "0"], ["84174.1", "0.059876", "0", "1"], ["84210.5", "0.08991167", "0", "3"], ["84266.4", "0", "0", "0"]], "bids": [["84071.1", "0", "0", "0"], ["84067.6", "0.23792486", "0", "1"], ["84063.2", "0", "0", "0"], ["84062.4", "0.08", "0", "2"], ["84061.6", "0.066", "0", "3"], ["83945.1", "0.002378", "0", "1"]], "ts": "1742554967804", "checksum": 1952356175, "seqId": 49927375682, "prevSeqId": 49927375666}], "record_time": 1742554967.804938, "EXCHANGE": "OKX"}
{"arg": {"channel": "books", "instId": "BTC-USDT"}, "action": "update", "data": [{"asks": [["84124.5", "0", "0", "0"], ["84127.3", "0.23792128", "0", "1"], ["84138.4", "0", "0", "0"], ["84139.2", "0.07999999", "0", "2"], ["84140", "0.04006695", "0", "4"], ["84174.1", "0", "0", "0"], ["84210.5", "0.00013667", "0", "2"], ["84266.4", "0.00001402", "0", "1"], ["84266.5", "0.00054835", "0", "1"]], "bids": [["84100.5", "0", "0", "0"], ["84099.9", "0", "0", "0"], ["84095.8", "0", "0", "0"], ["84086.1", "1", "0", "1"], ["84084.3", "0", "0", "0"], ["84071.1", "0.23792128", "0", "1"], ["84067.6", "0", "0", "0"], ["84059.2", "0", "0", "0"], ["84058.4", "0.1", "0", "2"], ["84057.6", "0.05", "0", "1"], ["83944.8", "0.00011161", "0", "1"], ["83944.6", "0.00421935", "0", "1"], ["83943.5", "0.03", "0", "1"]], "ts": "1742554967904", "checksum": -1352772395, "seqId": 49927375705, "prevSeqId": 49927375682}], "record_time": 1742554967.906241, "EXCHANGE": "OKX"}
{"arg": {"channel": "books", "instId": "BTC-USDT"}, "action": "update", "data": [{"asks": [["84120", "0.11894903", "0", "2"]], "bids": [["84102.2", "0.68598026", "0", "11"], ["84088.2", "0.46705907", "0", "6"], ["84086.1", "0", "0", "0"], ["84084.2", "1", "0", "1"], ["84084", "0.24756839", "0", "3"], ["84082", "0", "0", "0"], ["84080.3", "0", "0", "0"], ["83943.8", "0.2025", "0", "1"], ["83943.1", "0.01775819", "0", "1"]], "ts": "1742554968004", "checksum": -1014758747, "seqId": 49927375720, "prevSeqId": 49927375705}], "record_time": 1742554968.02098, "EXCHANGE": "OKX"}
{"arg": {"channel": "books", "instId": "BTC-USDT"}, "action": "update", "data": [{"asks": [["84113.2", "0.005625", "0", "1"], ["84127.3", "0.23792205", "0", "1"], ["84136", "0.059903", "0", "1"], ["84140", "1.04006695", "0", "5"], ["84158.3", "0.06", "0", "2"], ["84167.2", "0.0112574", "0", "1"], ["84171.5", "0", "0", "0"], ["84172.3", "0.089816", "0", "1"], ["84266.2", "0", "0", "0"], ["84266.4", "0", "0", "0"], ["84266.5", "0", "0", "0"]], "bids": [["84077.7", "0.17835", "0", "1"], ["84071.1", "0", "0", "0"], ["84070.5", "0.23792229", "0", "1"], ["84052.6", "0", "0", "0"], ["84050.5", "0.0183352", "0", "2"], ["83979.8", "0", "0", "0"], ["83978.3", "0.183202", "0", "1"]], "ts": "1742554968104", "checksum": -1846181833, "seqId": 49927375780, "prevSeqId": 49927375720}], "record_time": 1742554968.10391, "EXCHANGE": "OKX"}
{"arg": {"channel": "books", "instId": "BTC-USDT"}, "action": "update", "data": [{"asks": [["84102.3", "0.56516953", "0", "12"], ["84112.3", "0.005", "0", "1"], ["84113.2", "0", "0", "0"], ["84114.3", "0.01189471", "0", "1"], ["84122.6", "0", "0", "0"], ["84124.1", "1.15638943", "0", "3"], ["84127.3", "0.23792041", "0", "1"], ["84140", "0.04006695", "0", "4"], ["84266.2", "0.14240602", "0", "2"]], "bids": [["84100.1", "0.02625443", "0", "1"], ["84088.2", "0.46205907", "0", "5"], ["84085.7", "0.02786162", "0", "2"], ["84084.8", "1", "0", "1"], ["84084.2", "0", "0", "0"], ["84078.1", "0.005", "0", "1"], ["84072.8", "0", "0", "0"], ["84071.1", "0.23792041", "0", "1"], ["84070.5", "0", "0", "0"], ["84062", "0.02817312", "0", "1"], ["83943.1", "0", "0", "0"]], "ts": "1742554968204", "checksum": 198809009, "seqId": 49927375819, "prevSeqId": 49927375780}], "record_time": 1742554968.204109, "EXCHANGE": "OKX"}
{"arg": {"channel": "books", "instId": "BTC-USDT"}, "action": "update", "data": [{"asks": [["84113.2", "0.00564", "0", "1"], ["84122.6", "1", "0", "1"], ["84124", "0.23792586", "0", "1"], ["84124.1", "0.15638943", "0", "2"], ["84127.3", "0", "0", "0"], ["84266", "0", "0", "0"], ["84266.2", "0", "0", "0"]], "bids": [["84091.7", "0.24658874", "0", "1"], ["84088.8", "0.17835", "0", "1"], ["84088.2", "0.17964719", "0", "4"], ["84084.8", "0", "0", "0"], ["84084", "0.53065758", "0", "4"], ["84082.9", "1", "0", "1"], ["84077.7", "0", "0", "0"], ["84071.1", "0", "0", "0"], ["84067.7", "0.23794147", "0", "2"], ["83943.1", "0.01775819", "0", "1"], ["83942", "0.00007352", "0", "1"]], "ts": "1742554968304", "checksum": -217186261, "seqId": 49927375846, "prevSeqId": 49927375819}], "record_time": 1742554968.304392, "EXCHANGE": "OKX"}
{"arg": {"channel": "books", "instId": "BTC-USDT"}, "action": "update", "data": [{"asks": [["84111.5", "0.03714986", "0", "1"], ["84119.4", "0", "0", "0"]], "bids": [["84088.2", "0.2726417", "0", "5"], ["84086.3", "0.17835", "0", "1"], ["84086.2", "0.35671", "0", "1"], ["84075.2", "0.17835", "0", "1"], ["84049.6", "0.01728266", "0", "2"], ["84021.6", "0.01188266", "0", "1"], ["83943.8", "0", "0", "0"], ["83943.5", "0", "0", "0"], ["83943.1", "0", "0", "0"], ["83942", "0", "0", "0"]], "ts": "1742554968404", "checksum": 61260810, "seqId": 49927375857, "prevSeqId": 49927375846}], "record_time": 1742554968.408638, "EXCHANGE": "OKX"}
{"arg": {"channel": "books", "instId": "BTC-USDT"}, "action": "update", "data": [{"asks": [["84102.3", "0.57556363", "0", "13"], ["84105.2", "0.01991583", "0", "1"], ["84105.3", "0.02528966", "0", "1"], ["84105.7", "0", "0", "0"], ["84109.1", "0", "0", "0"], ["84115.4", "0.14394184", "0", "3"], ["84120.3", "0.1403523", "0", "1"], ["84122.2", "0.29684137", "0", "1"], ["84122.6", "0", "0", "0"], ["84123.1", "0", "0", "0"], ["84123.4", "1.000015", "0", "2"], ["84124", "0", "0", "0"], ["84127.3", "0.23792155", "0", "1"], ["84134.9", "0.19293114", "0", "1"], ["84150.8", "0.01917563", "0", "1"], ["84161.5", "0.19146517", "0", "1"], ["84166.8", "0.01188311", "0", "1"], ["84173", "0.01188308", "0", "1"], ["84179.1", "0.07130876", "0", "2"], ["84196.5", "0.01188297", "0", "1"], ["84199.3", "0.01188295", "0", "1"], ["84217.9", "0.01607653", "0", "2"], ["84244.5", "0.04676886", "0", "1"], ["84249", "0", "0", "0"], ["84264.7", "0", "0", "0"], ["84264.9", "0", "0", "0"], ["84265.1", "0", "0", "0"], ["84265.8", "0", "0", "0"]], "bids": [["84102.2", "0.64319326", "0", "8"], ["84102", "0", "0", "0"], ["84100.1", "0", "0", "0"], ["84097.6", "0", "0", "0"], ["84095.1", "0", "0", "0"], ["84094.1", "0", "0", "0"], ["84093.4", "0.02528966", "0", "1"], ["84089.2", "0.04018", "0", "1"], ["84088.6", "0.02846459", "0", "1"], ["84088.2", "0.34373482", "0", "4"], ["84083.1", "1.05596287", "0", "3"], ["84082.9", "0", "0", "0"], ["84081.8", "0.00475727", "0", "1"], ["84071.1", "0.23792166", "0", "1"], ["84070", "0.32682826", "0", "3"], ["84067.7", "0.00001501", "0", "1"], ["84057.7", "0", "0", "0"], ["84053.6", "0", "0", "0"], ["84052", "0.918182", "0", "1"], ["84051.9", "0.02745264", "0", "1"], ["84049.6", "0.0054", "0", "1"], ["84046.3", "0", "0", "0"], ["84043.1", "0", "0", "0"], ["84029.2", "0.45768629", "0", "2"], ["84021.6", "0", "0", "0"], ["84018.6", "0.01188252", "0", "1"], ["84015.7", "0.01188305", "0", "1"], ["83996.3", "0.02377722", "0", "3"], ["83975.9", "0.01188274", "0", "1"], ["83971.1", "0.10179288", "0", "2"], ["83943.8", "0.2025", "0", "1"], ["83943.5", "0.03", "0", "1"]], "ts": "1742554968504", "checksum": -1705998314, "seqId": 49927375977, "prevSeqId": 49927375857}], "record_time": 1742554968.510809, "EXCHANGE": "OKX"}
{"arg": {"channel": "books", "instId": "BTC-USDT"}, "action": "update", "data": [{"asks": [["84121.8", "1", "0", "1"], ["84123.4", "0.000015", "0", "1"], ["84150.8", "0", "0", "0"]], "bids": [["84102.2", "0.63591908", "0", "8"], ["84100.3", "0.11896263", "0", "1"], ["84075.2", "0", "0", "0"], ["84053", "0.2", "0", "1"], ["83943.5", "0", "0", "0"]], "ts": "1742554968604", "checksum": 2133000434, "seqId": 49927376012, "prevSeqId": 49927375977}], "record_time": 1742554968.605283, "EXCHANGE": "OKX"}
{"arg": {"channel": "books", "instId": "BTC-USDT"}, "action": "update", "data": [{"asks": [["84102.3", "0.63144839", "0", "14"], ["84117.9", "0.59833038", "0", "2"], ["84138.4", "0.08", "0", "2"], ["84139.2", "0.03999999", "0", "1"], ["84140", "0.00006696", "0", "3"], ["84264", "0", "0", "0"]], "bids": [["84102.2", "0.75487912", "0", "9"], ["84100.3", "0", "0", "0"], ["84083.1", "0.05596287", "0", "2"], ["84081.5", "1", "0", "1"], ["84077.7", "0.17835", "0", "1"], ["83943.8", "0", "0", "0"]], "ts": "1742554968704", "checksum": 1638646556, "seqId": 49927376026, "prevSeqId": 49927376012}], "record_time": 1742554968.705578, "EXCHANGE": "OKX"}
{"arg": {"channel": "books", "instId": "BTC-USDT"}, "action": "update", "data": [{"asks": [["84102.3", "0.58949113", "0", "10"], ["84102.7", "0.01311137", "0", "1"], ["84102.8", "0.01055", "0", "1"], ["84104", "0.0196", "0", "2"], ["84105", "0.0103941", "0", "1"], ["84105.2", "0.05032845", "0", "2"], ["84105.3", "0", "0", "0"], ["84105.8", "0", "0", "0"], ["84105.9", "0.02528966", "0", "1"], ["84109.2", "0.18827744", "0", "2"], ["84111", "0", "0", "0"], ["84112.6", "0.03291902", "0", "1"], ["84113.2", "0.03636454", "0", "2"], ["84113.3", "0.0647607", "0", "2"], ["84113.7", "0.380863", "0", "1"], ["84114.1", "0.005", "0", "1"], ["84114.4", "0.04", "0", "1"], ["84115.4", "0.11228184", "0", "2"], ["84115.5", "0.04", "0", "1"], ["84115.9", "0", "0", "0"], ["84116.1", "0", "0", "0"], ["84116.5", "0.35641581", "0", "1"], ["84119.6", "0.07005637", "0", "2"], ["84120.1", "0.00001197", "0", "1"], ["84121.5", "1.00011161", "0", "2"], ["84121.6", "0", "0", "0"], ["84121.8", "0", "0", "0"], ["84121.9", "0.03315622", "0", "1"], ["84122", "0.0339169", "0", "1"], ["84122.4", "0", "0", "0"], ["84122.5", "0", "0", "0"], ["84124.1", "0.24629954", "0", "3"], ["84124.6", "0", "0", "0"], ["84124.7", "0", "0", "0"], ["84126.5", "0.2379225", "0", "1"], ["84126.6", "0.06380622", "0", "1"], ["84127.3", "0", "0", "0"], ["84128.7", "0.06815542", "0", "1"], ["84129.5", "0.13379", "0", "1"], ["84131.3", "0", "0", "0"], ["84131.9", "0", "0", "0"], ["84133.4", "0", "0", "0"], ["84138.4", "0.27782292", "0", "1"], ["84139.2", "0.07999999", "0", "2"], ["84139.9", "0.05979184", "0", "1"], ["84140", "0.04006695", "0", "4"], ["84146.4", "0", "0", "0"], ["84150.2", "0.14093458", "0", "3"], ["84150.3", "0.0118835", "0", "1"], ["84150.9", "0.04188342", "0", "2"], ["84151", "0.01188341", "0", "1"], ["84179.1", "0.05942571", "0", "1"], ["84196.5", "0", "0", "0"], ["84199.3", "0", "0", "0"], ["84217.9", "0.00419368", "0", "1"], ["84264", "0.00074396", "0", "1"]], "bids": [["84102.2", "0.00792103", "0", "3"], ["84098.9", "0", "0", "0"], ["84097.4", "0", "0", "0"], ["84097.1", "0", "0", "0"], ["84096.9", "0.03800894", "0", "1"], ["84096.8", "0.00772868", "0", "1"], ["84096.7", "0.1189678", "0", "1"], ["84094.4", "0.37237868", "0", "2"], ["84094.1", "0.0118969", "0", "1"], ["84093.9", "0.00772798", "0", "1"], ["84093.8", "0.005", "0", "1"], ["84093.7", "0.02528966", "0", "1"], ["84093.4", "0", "0", "0"], ["84091.1", "0", "0", "0"], ["84090.1", "0", "0", "0"], ["84089.3", "0.01339", "0", "1"], ["84089.2", "0", "0", "0"], ["84088.2", "0.30980309", "0", "3"], ["84087.9", "0", "0", "0"], ["84087.2", "0", "0", "0"], ["84087.1", "0.0372423", "0", "1"], ["84086.7", "0", "0", "0"], ["84086.2", "0.39671", "0", "2"], ["84085.3", "0.03206711", "0", "1"], ["84085.2", "0.03200071", "0", "1"], ["84084.6", "0.13623994", "0", "3"], ["84084", "0.53450218", "0", "4"], ["84083.9", "0.05104126", "0", "2"], ["84083.8", "0.005", "0", "1"], ["84083", "0.04019", "0", "1"], ["84081.8", "0", "0", "0"], ["84081.5", "0", "0", "0"], ["84081.2", "0.138", "0", "3"], ["84080.4", "0", "0", "0"], ["84080.3", "1", "0", "1"], ["84079.1", "0", "0", "0"], ["84079", "0", "0", "0"], ["84078.5", "0", "0", "0"], ["84078.3", "0.03198426", "0", "1"], ["84078.2", "0.34917405", "0", "4"], ["84077.7", "0", "0", "0"], ["84077.6", "0.03335239", "0", "1"], ["84076.4", "0.0325239", "0", "1"], ["84075.8", "1.61906288", "0", "2"], ["84074.2", "0", "0", "0"], ["84072.5", "0.05994939", "0", "1"], ["84071.8", "0", "0", "0"], ["84071.4", "0.2379225", "0", "1"], ["84071.3", "0.06673407", "0", "1"], ["84071.1", "0", "0", "0"], ["84071", "0.005", "0", "2"], ["84070.4", "0", "0", "0"], ["84070", "0.005", "0", "2"], ["84069.2", "0.06986012", "0", "1"], ["84067.4", "0.2025", "0", "1"], ["84062", "0", "0", "0"], ["84054.9", "0.02817312", "0", "1"], ["84053", "0", "0", "0"], ["84052", "0", "0", "0"], ["84046.5", "0.918241", "0", "1"], ["84018.6", "0", "0", "0"], ["84015.7", "0", "0", "0"], ["84013.2", "0", "0", "0"], ["83996.3", "0.00001196", "0", "1"], ["83982.9", "0.07102314", "0", "1"], ["83981.7", "0.07125036", "0", "1"], ["83975.9", "0", "0", "0"], ["83971.1", "0.08991011", "0", "1"], ["83943.8", "0.2025", "0", "1"], ["83943.5", "0.03", "0", "1"], ["83943.1", "0.01775819", "0", "1"], ["83942", "0.00007352", "0", "1"]], "ts": "1742554968804", "checksum": 1465791804, "seqId": 49927376344, "prevSeqId": 49927376026}], "record_time": 1742554968.807207, "EXCHANGE": "OKX"}
