{"arg": {"channel": "books", "instId": "BTC-USDT"}, "action": "snapshot", "data": [{"asks": [["83553.7", "2.09746757", "0", "26"], ["83553.8", "0.1", "0", "1"], ["83553.9", "0.25122194", "0", "3"], ["83554", "0.53968075", "0", "2"], ["83554.1", "0.10471446", "0", "3"], ["83554.6", "0.00171265", "0", "1"], ["83556.3", "0.0002", "0", "2"], ["83556.4", "0.012", "0", "1"], ["83556.5", "0.00897", "0", "1"], ["83557.8", "0.00897", "0", "1"], ["83558.3", "0.00777928", "0", "1"], ["83559", "0.23939447", "0", "1"], ["83559.1", "0.19815648", "0", "1"], ["83559.2", "0.05584247", "0", "1"], ["83560", "0.20874362", "0", "2"], ["83560.2", "0.0007425", "0", "1"], ["83561", "0.04", "0", "1"], ["83561.2", "0.35905", "0", "1"], ["83562", "0.002", "0", "1"], ["83562.1", "0.005", "0", "1"], ["83562.4", "0.00001501", "0", "1"], ["83562.8", "0.02692", "0", "1"], ["83563.3", "0.23883849", "0", "2"], ["83563.6", "0.00001205", "0", "1"], ["83564", "0.35972754", "0", "1"], ["83564.1", "0.14992025", "0", "2"], ["83564.2", "0.20953", "0", "2"], ["83564.5", "0.00777884", "0", "1"], ["83566.6", "0.09663454", "0", "1"], ["83566.8", "0.08991011", "0", "1"], ["83567.3", "0.01196682", "0", "1"], ["83567.4", "0.12", "0", "4"], ["83567.7", "0.0910977", "0", "1"], ["83567.9", "0.93974302", "0", "2"], ["83568", "0.0905681", "0", "1"], ["83568.1", "0.03604266", "0", "1"], ["83568.4", "0.00425986", "0", "1"], ["83568.5", "0.09572068", "0", "1"], ["83568.6", "0.00001205", "0", "1"], ["83569", "0.04", "0", "1"], ["83570", "0.17953568", "0", "1"], ["83570.1", "0.2025", "0", "1"], ["83570.3", "0.11965737", "0", "1"], ["83570.4", "0.09611633", "0", "3"], ["83570.7", "0.00001501", "0", "1"], ["83571.6", "1.61407269", "0", "1"], ["83571.7", "0.32856412", "0", "3"], ["83571.8", "0.133483", "0", "1"], ["83572.1", "0.002", "0", "1"], ["83572.2", "0.005", "0", "1"], ["83573.2", "0.35972754", "0", "1"], ["83573.6", "0.00001205", "0", "1"], ["83574.1", "0.0071856", "0", "1"], ["83574.7", "0.15017035", "0", "1"], ["83575.4", "0.16745601", "0", "1"], ["83575.5", "0.14699704", "0", "1"], ["83575.7", "0.11992025", "0", "1"], ["83575.9", "0.0005145", "0", "1"], ["83576.5", "0.15203961", "0", "1"], ["83576.8", "0.11964811", "0", "1"], ["83577", "0.1900928", "0", "1"], ["83578", "0.02334141", "0", "1"], ["83578.3", "0.02674576", "0", "1"], ["83578.4", "0.00425928", "0", "1"], ["83578.6", "0.00001205", "0", "1"], ["83579", "0.00551501", "0", "2"], ["83580", "0.02137958", "0", "2"], ["83580.3", "0.10534", "0", "1"], ["83580.8", "0.01219896", "0", "1"], ["83580.9", "0.24183424", "0", "3"], ["83581.1", "0.0090755", "0", "1"], ["83581.3", "0.24381375", "0", "1"], ["83581.5", "0.00358151", "0", "1"], ["83581.6", "0.23163407", "0", "1"], ["83582.5", "0.23882035", "0", "1"], ["83582.9", "0.17953568", "0", "1"], ["83583", "0.35972754", "0", "1"], ["83583.3", "0.00060612", "0", "1"], ["83583.4", "0.23659964", "0", "1"], ["83583.6", "0.20251205", "0", "2"], ["83584", "0.02392756", "0", "1"], ["83584.2", "0.00580462", "0", "1"], ["83584.5", "0.08936016", "0", "1"], ["83584.6", "0.25134", "0", "1"], ["83585.2", "0.23733477", "0", "1"], ["83585.8", "0.00598314", "0", "1"], ["83586.1", "0.1900928", "0", "1"], ["83586.7", "0.10527", "0", "1"], ["83587.1", "0.08991011", "0", "1"], ["83587.2", "0.11992025", "0", "1"], ["83587.3", "0.00001501", "0", "1"], ["83587.6", "0.01796", "0", "1"], ["83588.2", "0.00425833", "0", "1"], ["83588.4", "0.00580462", "0", "1"], ["83588.6", "0.00001205", "0", "1"], ["83589.3", "0.03287853", "0", "1"], ["83589.6", "0.05987175", "0", "1"], ["83589.9", "0.41173325", "0", "2"], ["83590.2", "0.474817", "0", "1"], ["83590.9", "0.495456", "0", "1"], ["83591.2", "0.01872442", "0", "1"], ["83591.3", "0.00011142", "0", "1"], ["83591.4", "0.15351024", "0", "3"], ["83591.8", "0.35972754", "0", "1"], ["83593.6", "0.248564", "0", "1"], ["83593.7", "0.00001204", "0", "1"], ["83593.9", "0.03", "0", "1"], ["83594.4", "0.2025", "0", "1"], ["83594.7", "0.47212", "0", "1"], ["83595.2", "0.25953567", "0", "3"], ["83595.6", "0.00001501", "0", "1"], ["83595.7", "0.0055", "0", "1"], ["83596", "0.03999999", "0", "1"], ["83596.4", "0.00425694", "0", "1"], ["83596.5", "0.00001501", "0", "1"], ["83596.6", "0.01794412", "0", "1"], ["83596.7", "0.11992025", "0", "1"], ["83596.8", "0.36230375", "0", "1"], ["83597", "1", "0", "1"], ["83598", "0.1", "0", "1"], ["83598.7", "0.00001204", "0", "1"], ["83599.9", "0.01504349", "0", "5"], ["83600", "0.03083288", "0", "4"], ["83600.7", "0.35972754", "0", "1"], ["83601.2", "1.37389583", "0", "1"], ["83601.3", "2.8406635", "0", "1"], ["83601.8", "0.24183424", "0", "3"], ["83602.2", "0.00104746", "0", "1"], ["83602.3", "0.016386", "0", "1"], ["83602.4", "0.05512266", "0", "2"], ["83603.2", "0.51891", "0", "1"], ["83603.7", "0.00001204", "0", "1"], ["83603.9", "0.17955068", "0", "2"], ["83604", "0.2025", "0", "1"], ["83604.3", "0.05525", "0", "1"], ["83605.1", "0.00425619", "0", "1"], ["83605.5", "0.37125025", "0", "2"], ["83605.7", "0.37623074", "0", "1"], ["83605.8", "0.580223", "0", "1"], ["83606", "0.00021614", "0", "1"], ["83606.5", "0.08991011", "0", "1"], ["83607.4", "0.02392084", "0", "1"], ["83607.5", "0.1900928", "0", "1"], ["83608.2", "0.01", "0", "1"], ["83608.7", "0.00001204", "0", "1"], ["83609.2", "0.00364754", "0", "1"], ["83609.3", "0.35972754", "0", "1"], ["83609.5", "0.18754193", "0", "1"], ["83610", "0.03", "0", "1"], ["83611", "0.00012142", "0", "2"], ["83611.7", "0.00425574", "0", "1"], ["83612.1", "0.00001103", "0", "1"], ["83612.2", "0.00024501", "0", "3"], ["83612.3", "0.15235055", "0", "5"], ["83612.5", "0.00002335", "0", "1"], ["83612.6", "0.04468027", "0", "2"], ["83612.7", "0.06", "0", "2"], ["83612.9", "0.0002493", "0", "2"], ["83613", "0.00318148", "0", "2"], ["83613.1", "0.00001007", "0", "1"], ["83613.2", "0.00002092", "0", "2"], ["83613.3", "0.03", "0", "1"], ["83613.6", "0.29270015", "0", "2"], ["83613.7", "0.00002246", "0", "2"], ["83613.9", "0.11992025", "0", "1"], ["83614.1", "0.0000105", "0", "1"], ["83614.2", "0.00011204", "0", "1"], ["83614.3", "0.00004772", "0", "2"], ["83614.7", "0.00004811", "0", "1"], ["83614.8", "0.00088831", "0", "1"], ["83615", "0.00001004", "0", "1"], ["83615.2", "0.00537288", "0", "2"], ["83615.3", "0.00050039", "0", "2"], ["83615.4", "0.00001009", "0", "1"], ["83615.5", "0.00002498", "0", "1"], ["83615.7", "0.00211734", "0", "2"], ["83616", "0.00001004", "0", "1"], ["83616.1", "0.00005004", "0", "2"], ["83616.5", "0.00001206", "0", "1"], ["83616.6", "0.00785243", "0", "5"], ["83616.8", "0.00009302", "0", "1"], ["83616.9", "0.0004148", "0", "3"], ["83617.1", "0.20251011", "0", "2"], ["83617.5", "0.03715474", "0", "2"], ["83617.6", "0.00003256", "0", "1"], ["83618.1", "0.00700251", "0", "4"], ["83618.2", "0.0000951", "0", "1"], ["83618.3", "0.04786735", "0", "1"], ["83618.6", "0.00425502", "0", "1"], ["83618.8", "0.1636516", "0", "3"], ["83618.9", "0.35972754", "0", "1"], ["83619", "0.01419169", "0", "3"], ["83619.1", "0.00719489", "0", "2"], ["83619.2", "0.00002324", "0", "1"], ["83619.4", "0.03", "0", "1"], ["83619.5", "0.00488686", "0", "5"], ["83619.8", "0.00002668", "0", "1"], ["83619.9", "0.00031373", "0", "4"], ["83620", "0.00181427", "0", "5"], ["83620.1", "0.00041143", "0", "2"], ["83620.3", "0.0000665", "0", "1"], ["83620.4", "0.0039259", "0", "1"], ["83620.5", "0.00126872", "0", "2"], ["83620.6", "0.00003153", "0", "2"], ["83620.8", "0.00002253", "0", "1"], ["83621", "0.00024051", "0", "2"], ["83621.1", "0.10001017", "0", "2"], ["83621.2", "0.00006289", "0", "1"], ["83621.3", "0.00001186", "0", "1"], ["83621.5", "0.00006121", "0", "1"], ["83621.7", "0.01994695", "0", "2"], ["83622.1", "0.00002874", "0", "2"], ["83622.2", "0.00090335", "0", "2"], ["83622.4", "0.97416647", "0", "5"], ["83622.5", "0.12060156", "0", "2"], ["83622.7", "0.00001011", "0", "1"], ["83622.8", "0.10004182", "0", "3"], ["83622.9", "0.00010351", "0", "3"], ["83623", "0.00001097", "0", "1"], ["83623.1", "0.00015386", "0", "2"], ["83623.4", "0.17953568", "0", "1"], ["83623.6", "0.71229745", "0", "2"], ["83623.7", "0.00029822", "0", "6"], ["83623.8", "0.00001002", "0", "1"], ["83624.1", "0.11751671", "0", "1"], ["83624.3", "0.00230564", "0", "1"], ["83624.5", "0.00012233", "0", "1"], ["83625", "0.00937173", "0", "14"], ["83625.1", "0.00011938", "0", "1"], ["83625.3", "0.00008", "0", "1"], ["83625.4", "0.00001004", "0", "1"], ["83625.7", "0.00100987", "0", "1"], ["83625.9", "0.00032751", "0", "1"], ["83626", "0.00159033", "0", "1"], ["83626.1", "0.00003828", "0", "2"], ["83626.3", "0.00002453", "0", "2"], ["83626.4", "0.00011621", "0", "2"], ["83626.6", "0.00001286", "0", "1"], ["83626.8", "0.02393658", "0", "1"], ["83627.1", "0.00066173", "0", "1"], ["83627.2", "0.00001016", "0", "1"], ["83627.9", "0.00003987", "0", "2"], ["83628", "0.00001033", "0", "1"], ["83628.1", "0.28663035", "0", "3"], ["83628.2", "0.36060062", "0", "9"], ["83628.3", "0.1", "0", "1"], ["83628.4", "0.00016982", "0", "1"], ["83628.5", "0.00001067", "0", "1"], ["83628.6", "0.0000528", "0", "4"], ["83628.7", "0.2025", "0", "1"], ["83628.8", "0.00002707", "0", "2"], ["83629.2", "0.00001206", "0", "1"], ["83629.4", "0.00001001", "0", "1"], ["83629.5", "0.00437872", "0", "2"], ["83629.9", "0.00002782", "0", "1"], ["83630.1", "0.3", "0", "1"], ["83630.2", "0.00428793", "0", "3"], ["83630.5", "0.00003988", "0", "1"], ["83630.6", "0.00011142", "0", "1"], ["83630.7", "0.0000484", "0", "1"], ["83630.8", "0.07535642", "0", "2"], ["83630.9", "0.11992025", "0", "1"], ["83631", "0.0001205", "0", "1"], ["83631.1", "0.00001167", "0", "1"], ["83631.4", "0.00048794", "0", "12"], ["83631.5", "0.00011899", "0", "1"], ["83631.6", "0.00010045", "0", "6"], ["83631.7", "0.0000222", "0", "2"], ["83631.8", "0.00002533", "0", "1"], ["83632.3", "0.00052889", "0", "1"], ["83632.5", "0.00022484", "0", "8"], ["83632.6", "0.0001078", "0", "1"], ["83632.7", "0.09280047", "0", "12"], ["83632.8", "0.0717422", "0", "1"], ["83633.3", "0.00826413", "0", "10"], ["83633.6", "0.00005892", "0", "2"], ["83633.8", "0.00047398", "0", "2"], ["83633.9", "0.00012242", "0", "1"], ["83634", "0.03002119", "0", "2"], ["83634.1", "0.00015261", "0", "2"], ["83634.4", "0.00001007", "0", "1"], ["83634.9", "0.00001013", "0", "1"], ["83635.6", "0.00006617", "0", "3"], ["83635.7", "0.00009649", "0", "1"], ["83635.8", "0.05263157", "0", "1"], ["83635.9", "0.00114411", "0", "2"], ["83636", "0.0388564", "0", "3"], ["83636.3", "0.00729904", "0", "42"], ["83636.4", "0.07173911", "0", "1"], ["83636.5", "0.00004661", "0", "3"], ["83636.6", "0.22585002", "0", "1"], ["83636.7", "0.35972754", "0", "1"], ["83636.8", "0.00008298", "0", "2"], ["83636.9", "0.00021657", "0", "3"], ["83637", "0.17953568", "0", "1"], ["83637.1", "0.202515", "0", "2"], ["83637.5", "0.00553713", "0", "4"], ["83637.7", "0.00001535", "0", "1"], ["83638", "0.00586617", "0", "1"], ["83638.1", "0.00001501", "0", "1"], ["83638.2", "0.00003082", "0", "3"], ["83638.3", "0.00458615", "0", "3"], ["83638.6", "0.03995476", "0", "2"], ["83638.7", "0.0000323", "0", "2"], ["83638.8", "0.00016242", "0", "2"], ["83639", "0.01196895", "0", "1"], ["83639.3", "0.00001506", "0", "1"], ["83639.4", "0.00001413", "0", "1"], ["83639.5", "0.00009389", "0", "1"], ["83639.6", "0.00008291", "0", "1"], ["83639.8", "0.0054784", "0", "2"], ["83639.9", "0.00164572", "0", "7"], ["83640", "0.02421692", "0", "8"], ["83640.2", "0.07252595", "0", "1"], ["83640.3", "0.09121445", "0", "2"], ["83640.6", "0.00001222", "0", "1"], ["83640.7", "0.00019202", "0", "2"], ["83640.8", "0.0047713", "0", "1"], ["83641.1", "0.00223045", "0", "5"], ["83641.2", "0.00008941", "0", "2"], ["83641.4", "0.00106671", "0", "1"], ["83641.6", "0.000024", "0", "1"], ["83641.8", "0.00001206", "0", "1"], ["83642.1", "0.87070085", "0", "4"], ["83642.4", "0.00001363", "0", "1"], ["83642.6", "0.00007243", "0", "1"], ["83642.7", "0.00001063", "0", "1"], ["83642.8", "0.00026749", "0", "3"], ["83643.1", "0.01471384", "0", "2"], ["83643.2", "0.00001083", "0", "1"], ["83643.5", "0.00009814", "0", "2"], ["83643.7", "0.00001765", "0", "1"], ["83643.9", "0.00006945", "0", "4"], ["83644.1", "0.00006478", "0", "2"], ["83644.2", "0.00037", "0", "2"], ["83644.3", "0.00025953", "0", "1"], ["83644.4", "0.00004793", "0", "1"], ["83644.5", "0.00002848", "0", "1"], ["83644.7", "0.00012868", "0", "5"], ["83645", "0.00032869", "0", "5"], ["83645.1", "0.00025232", "0", "2"], ["83645.2", "0.00831387", "0", "1"], ["83645.4", "0.20955069", "0", "3"], ["83645.5", "0.2025", "0", "1"], ["83645.9", "0.00011938", "0", "1"], ["83646", "0.00001662", "0", "1"], ["83646.1", "0.00002251", "0", "1"], ["83646.2", "0.00007236", "0", "1"], ["83646.3", "0.00008354", "0", "6"], ["83646.6", "0.00023688", "0", "1"], ["83646.7", "0.00437", "0", "2"], ["83646.8", "0.19208368", "0", "2"], ["83647", "0.00600976", "0", "2"], ["83647.1", "0.00064438", "0", "1"], ["83647.2", "0.00016135", "0", "1"], ["83647.3", "0.0000374", "0", "2"], ["83647.5", "0.00001332", "0", "1"], ["83647.7", "0.0002648", "0", "4"], ["83648.1", "0.13354606", "0", "2"], ["83648.2", "0.00126251", "0", "2"], ["83648.6", "0.09", "0", "3"], ["83648.8", "0.00002559", "0", "2"], ["83649.1", "0.00002611", "0", "1"], ["83649.5", "0.00009917", "0", "1"], ["83649.6", "0.00589905", "0", "1"], ["83649.8", "0.00001027", "0", "1"], ["83649.9", "0.3604642", "0", "4"], ["83650", "0.19911751", "0", "11"], ["83650.1", "0.05804867", "0", "3"], ["83650.2", "0.00011142", "0", "1"], ["83650.4", "0.00009255", "0", "2"], ["83650.6", "0.00002227", "0", "1"], ["83650.8", "0.00003672", "0", "1"], ["83651", "0.00040029", "0", "4"], ["83651.1", "0.00261733", "0", "9"], ["83651.2", "0.00002038", "0", "2"], ["83651.4", "0.00153151", "0", "1"], ["83651.7", "0.00488104", "0", "2"], ["83651.8", "0.00298983", "0", "1"], ["83651.9", "0.00491409", "0", "1"], ["83652", "0.0001236", "0", "1"], ["83652.1", "0.00009949", "0", "3"], ["83652.4", "0.00074386", "0", "1"], ["83652.6", "0.00168601", "0", "1"], ["83652.7", "0.00046457", "0", "2"], ["83652.9", "0.02393367", "0", "1"], ["83653.1", "0.00002037", "0", "2"], ["83653.2", "0.00017548", "0", "2"], ["83653.5", "0.00012652", "0", "1"], ["83653.7", "0.00601467", "0", "2"], ["83653.8", "0.17965004", "0", "5"], ["83653.9", "0.20251206", "0", "2"], ["83654", "0.00251676", "0", "1"], ["83654.4", "0.00121706", "0", "2"], ["83654.8", "0.00002052", "0", "2"], ["83655.1", "0.00447503", "0", "2"], ["83655.2", "0.00597", "0", "1"], ["83656.1", "0.00007092", "0", "1"], ["83656.2", "0.00300703", "0", "3"], ["83656.3", "0.01074264", "0", "3"]], "bids": [["83553.6", "0.52037898", "0", "4"], ["83552.3", "0.005", "0", "1"], ["83552.2", "0.002", "0", "1"], ["83552", "0.0567", "0", "1"], ["83551.8", "0.005", "0", "1"], ["83550.1", "0.00777939", "0", "1"], ["83550", "0.0567", "0", "1"], ["83549.9", "0.00080612", "0", "3"], ["83549.1", "0.07725823", "0", "1"], ["83548.6", "0.00001205", "0", "1"], ["83548.1", "0.08174533", "0", "1"], ["83548", "0.0567", "0", "1"], ["83546.7", "0.00777902", "0", "1"], ["83546.1", "0.00085843", "0", "1"], ["83545.7", "0.000015", "0", "1"], ["83545.3", "0.11115932", "0", "2"], ["83543.6", "0.00001205", "0", "1"], ["83543.3", "0.17953", "0", "1"], ["83542.3", "0.00719453", "0", "2"], ["83542.2", "0.005", "0", "1"], ["83542.1", "0.002", "0", "1"], ["83541.8", "0.48813166", "0", "2"], ["83541.7", "0.35972754", "0", "1"], ["83541.3", "0.01", "0", "1"], ["83541.2", "0.09032423", "0", "1"], ["83541.1", "0.35905", "0", "1"], ["83540.9", "0.05523185", "0", "1"], ["83540.7", "0.11575733", "0", "2"], ["83540.1", "0.17953568", "0", "1"], ["83540", "0.00001", "0", "1"], ["83539.8", "0.0003", "0", "1"], ["83539.7", "0.31842991", "0", "2"], ["83539.4", "0.01197081", "0", "1"], ["83539.3", "0.0896495", "0", "1"], ["83539.2", "0.33160424", "0", "3"], ["83538.6", "0.00001205", "0", "1"], ["83538", "0.04788571", "0", "1"], ["83537.6", "0.18605494", "0", "1"], ["83537.4", "0.00001501", "0", "1"], ["83537.2", "0.02490748", "0", "1"], ["83536.1", "0.0000225", "0", "1"], ["83535.7", "0.133492", "0", "1"], ["83534.9", "0.04", "0", "1"], ["83534.7", "0.02983444", "0", "1"], ["83534.5", "0.075", "0", "1"], ["83534.4", "0.066", "0", "1"], ["83534.2", "0.35308896", "0", "2"], ["83533.6", "0.00001205", "0", "1"], ["83533.3", "0.00101501", "0", "2"], ["83532.8", "0.58675076", "0", "1"], ["83532.7", "0.15981872", "0", "1"], ["83532.4", "0.00011142", "0", "1"], ["83532", "0.17282105", "0", "2"], ["83531.8", "0.57295718", "0", "2"], ["83531.7", "0.35972754", "0", "1"], ["83531.3", "0.2025", "0", "1"], ["83531.1", "0.05987175", "0", "1"], ["83531", "0.36347501", "0", "5"], ["83530.9", "0.00426154", "0", "1"], ["83530.8", "0.00356428", "0", "1"], ["83530.7", "0.1900928", "0", "1"], ["83529.4", "0.11971588", "0", "1"], ["83529.3", "0.37966141", "0", "1"], ["83529.2", "0.36038", "0", "1"], ["83529.1", "0.00001501", "0", "1"], ["83529", "0.17953568", "0", "1"], ["83528.9", "0.04", "0", "1"], ["83528.8", "0.15207424", "0", "2"], ["83528.6", "0.00001205", "0", "1"], ["83527.9", "0.016", "0", "1"], ["83527.8", "0.01596", "0", "1"], ["83527.2", "0.26681652", "0", "1"], ["83526", "0.25261734", "0", "1"], ["83525.6", "0.02078895", "0", "2"], ["83524.8", "0.30889328", "0", "1"], ["83523.9", "0.2656362", "0", "1"], ["83523.7", "0.05195734", "0", "2"], ["83523.6", "0.00001205", "0", "1"], ["83523.5", "0.12339425", "0", "2"], ["83522.4", "0.2025", "0", "1"], ["83522.3", "0.35972754", "0", "1"], ["83522.2", "0.26334387", "0", "1"], ["83522.1", "0.1900928", "0", "1"], ["83521.9", "0.25134", "0", "1"], ["83521.6", "0.00426233", "0", "1"], ["83521.5", "0.0479", "0", "1"], ["83521", "0.0025", "0", "1"], ["83520.8", "0.00001501", "0", "1"], ["83520.6", "0.23149302", "0", "3"], ["83520.1", "0.01097934", "0", "1"], ["83520", "0.00251", "0", "2"], ["83519.9", "0.05195734", "0", "2"], ["83519", "0.00302221", "0", "1"], ["83518.6", "0.00001205", "0", "1"], ["83518.4", "0.15207424", "0", "2"], ["83518.3", "0.08976", "0", "1"], ["83516.9", "0.01219896", "0", "1"], ["83516.8", "1.31844771", "0", "1"], ["83516.7", "1.24", "0", "1"], ["83516.6", "0.00060612", "0", "1"], ["83516", "0.01344072", "0", "2"], ["83515.7", "0.44213", "0", "1"], ["83515.6", "0.3", "0", "1"], ["83515.4", "0.05195734", "0", "2"], ["83515.2", "0.11992025", "0", "1"], ["83514.8", "0.475245", "0", "1"], ["83514.3", "0.495484", "0", "1"], ["83513.7", "0.61418488", "0", "4"], ["83513.5", "0.58087605", "0", "2"], ["83513.2", "0.000015", "0", "1"], ["83513.1", "0.02068", "0", "1"], ["83512.8", "0.00011142", "0", "1"], ["83512.7", "0.7273945", "0", "2"], ["83512.6", "1.59337855", "0", "1"], ["83512.5", "0.00001501", "0", "1"], ["83512", "0.21549302", "0", "2"], ["83511.8", "0.016", "0", "1"], ["83510.5", "0.51", "0", "1"], ["83510.2", "0.00199193", "0", "2"], ["83510", "0.0056", "0", "1"], ["83508.7", "0.02229595", "0", "1"], ["83508.5", "0.00001206", "0", "1"], ["83508", "0.10186506", "0", "1"], ["83507.9", "0.15207424", "0", "2"], ["83507.6", "0.00426392", "0", "1"], ["83507.2", "0.05571", "0", "1"], ["83505.6", "0.1", "0", "1"], ["83504.6", "0.11992025", "0", "1"], ["83504.4", "1.10822887", "0", "1"], ["83504.3", "3.04956", "0", "1"], ["83504.2", "0.000015", "0", "1"], ["83503.6", "0.17953568", "0", "1"], ["83503.5", "0.00001206", "0", "1"], ["83502.3", "0.01", "0", "1"], ["83501.4", "0.05985407", "0", "1"], ["83501.2", "0.23939447", "0", "1"], ["83501", "0.25133", "0", "1"], ["83500.8", "0.08991011", "0", "1"], ["83500.5", "0.35972754", "0", "1"], ["83500.1", "0.17007038", "0", "1"], ["83500", "0.11039676", "0", "8"], ["83499.9", "0.00195701", "0", "4"], ["83499.8", "0.2025", "0", "1"], ["83499.4", "0.02395177", "0", "1"], ["83499.2", "0.0004", "0", "1"], ["83499.1", "0.02395184", "0", "1"], ["83498.5", "0.00001205", "0", "1"], ["83497.6", "0.002513", "0", "1"], ["83497.4", "0.08976", "0", "1"], ["83497.2", "0.0019859", "0", "1"], ["83497.1", "0.0042648", "0", "1"], ["83496.8", "0.08", "0", "2"], ["83496.4", "0.00435429", "0", "1"], ["83496.2", "0.11992025", "0", "1"], ["83496", "0.15179806", "0", "5"], ["83495.9", "0.000015", "0", "1"], ["83495.6", "0.00367", "0", "1"], ["83495.3", "0.08813676", "0", "2"], ["83495.2", "0.076", "0", "3"], ["83495", "0.0075", "0", "3"], ["83494.4", "0.013", "0", "1"], ["83493.7", "0.03", "0", "1"], ["83493.5", "0.00001206", "0", "1"], ["83493.4", "0.01843307", "0", "1"], ["83493.3", "0.0056", "0", "1"], ["83493.2", "0.00011142", "0", "1"], ["83493.1", "0.00040555", "0", "1"], ["83492.2", "0.00459383", "0", "2"], ["83491.8", "0.12", "0", "4"], ["83491.3", "0.00609899", "0", "1"], ["83491.2", "0.2025", "0", "1"], ["83490.9", "1.00900964", "0", "2"], ["83489.7", "0.00380585", "0", "1"], ["83489.2", "0.17965545", "0", "2"], ["83489.1", "0.35972754", "0", "1"], ["83488.7", "0.00609899", "0", "1"], ["83488.5", "0.00199469", "0", "2"], ["83488.4", "2.8837667", "0", "2"], ["83488", "0.01451882", "0", "3"], ["83487.6", "0.00001501", "0", "1"], ["83487.5", "0.06984286", "0", "1"], ["83487.4", "0.08991011", "0", "1"], ["83486.7", "0.00011134", "0", "1"], ["83486.5", "0.01196264", "0", "1"], ["83486.2", "0.11992025", "0", "1"], ["83485.9", "0.00426613", "0", "1"], ["83485.7", "0.00069259", "0", "1"], ["83485.3", "0.00609899", "0", "1"], ["83485.2", "0.00589903", "0", "1"], ["83484.3", "0.00589903", "0", "1"], ["83483.5", "0.00001206", "0", "1"], ["83483.3", "0.00060612", "0", "1"], ["83483.1", "0.6027093", "0", "2"], ["83482.9", "0.00609899", "0", "1"], ["83482.7", "0.871617", "0", "1"], ["83482.2", "0.00598446", "0", "1"], ["83482", "0.2025", "0", "1"], ["83481.6", "0.04787131", "0", "1"], ["83481.4", "0.713153", "0", "1"], ["83480.7", "0.00609899", "0", "1"], ["83480.2", "0.00598446", "0", "1"], ["83479.9", "0.00009543", "0", "1"], ["83479.6", "0.00589903", "0", "1"], ["83479.5", "0.022", "0", "1"], ["83479.3", "0.000015", "0", "1"], ["83478.5", "0.00001206", "0", "1"], ["83478.1", "0.16911297", "0", "1"], ["83477.7", "0.00609899", "0", "1"], ["83477.6", "0.00609899", "0", "1"], ["83477.5", "0.00598446", "0", "1"], ["83477.4", "0.05989522", "0", "1"], ["83477.3", "0.0186", "0", "1"], ["83476.6", "0.11992025", "0", "1"], ["83476.5", "0.00598446", "0", "1"], ["83475.7", "0.35972754", "0", "1"], ["83473.5", "0.00012348", "0", "2"], ["83473.2", "0.00478732", "0", "1"], ["83473.1", "0.19468306", "0", "1"], ["83473", "0.32113688", "0", "1"], ["83472.9", "0.17953568", "0", "1"], ["83472.5", "0.07187994", "0", "1"], ["83472.2", "0.00021412", "0", "2"], ["83471.7", "0.00426695", "0", "1"], ["83471.6", "0.00001501", "0", "1"], ["83471", "0.000015", "0", "1"], ["83470.3", "0.03609899", "0", "2"], ["83470.2", "0.00609899", "0", "1"], ["83470.1", "0.00589903", "0", "1"], ["83470", "0.03592486", "0", "1"], ["83469.6", "0.2025", "0", "1"], ["83469.3", "1.0261527", "0", "1"], ["83468.9", "0.07188304", "0", "1"], ["83468.6", "3.55241", "0", "1"], ["83468.5", "0.00001206", "0", "1"], ["83468.3", "0.0027474", "0", "1"], ["83468.2", "0.11992025", "0", "1"], ["83466.6", "0.00519975", "0", "8"], ["83466.5", "0.00131657", "0", "1"], ["83466.3", "0.01796958", "0", "1"], ["83465.8", "0.01196917", "0", "1"], ["83464.9", "0.00008817", "0", "1"], ["83464.8", "0.02167064", "0", "2"], ["83464.4", "0.04981217", "0", "2"], ["83464.2", "0.00005282", "0", "1"], ["83463.5", "0.00001206", "0", "1"], ["83463.4", "0.11809701", "0", "4"], ["83463.3", "0.05555555", "0", "1"], ["83462.7", "0.000015", "0", "1"], ["83462.4", "0.19542125", "0", "2"], ["83462.3", "0.35972754", "0", "1"], ["83460.6", "0.00298666", "0", "1"], ["83459.8", "0.06", "0", "2"], ["83458.9", "0.01795244", "0", "1"], ["83458.7", "0.2025", "0", "1"], ["83458.4", "0.00036265", "0", "2"], ["83458.3", "0.08991011", "0", "1"], ["83456.6", "0.03", "0", "1"], ["83456.4", "0.00589903", "0", "1"], ["83456.3", "0.06081719", "0", "1"], ["83456.2", "0.01219798", "0", "2"], ["83456.1", "0.17953568", "0", "1"], ["83454.6", "0.00056778", "0", "1"], ["83454.5", "0.00003889", "0", "1"], ["83454.4", "0.00611412", "0", "2"], ["83454.2", "0.00426953", "0", "1"], ["83453.9", "0.00011142", "0", "1"], ["83453.4", "0.00001204", "0", "1"], ["83453.2", "0.2528961", "0", "1"], ["83453.1", "0.57386936", "0", "1"], ["83452.8", "0.0001189", "0", "1"], ["83452.7", "0.00001204", "0", "1"], ["83452.3", "0.0114", "0", "1"], ["83452.1", "0.02393724", "0", "1"], ["83451.5", "0.01739806", "0", "3"], ["83451.4", "0.21992025", "0", "2"], ["83451.3", "0.00597332", "0", "1"], ["83450", "0.00013604", "0", "2"], ["83449.9", "0.00060612", "0", "1"], ["83449.3", "0.00609899", "0", "1"], ["83449.2", "0.00609899", "0", "1"], ["83449.1", "0.1", "0", "1"], ["83449", "0.15732368", "0", "1"], ["83448.9", "0.35972754", "0", "1"], ["83448.2", "0.00015588", "0", "1"], ["83446.8", "0.0042696", "0", "1"], ["83446.6", "0.00589903", "0", "1"], ["83446.5", "0.01179806", "0", "2"], ["83446.4", "0.07252595", "0", "1"], ["83446.1", "0.000015", "0", "1"], ["83445.8", "0.01199827", "0", "2"], ["83445.7", "0.05802294", "0", "1"], ["83444.9", "0.21311169", "0", "1"], ["83444.7", "0.00002396", "0", "1"], ["83444.5", "0.07216343", "0", "1"], ["83443.4", "0.00001204", "0", "1"], ["83442.9", "0.00317332", "0", "1"], ["83442.7", "0.11992025", "0", "1"], ["83442", "0.2025", "0", "1"], ["83441.4", "0.00609899", "0", "1"], ["83441.3", "0.00589903", "0", "1"], ["83441.2", "0.00609899", "0", "1"], ["83441.1", "0.01179806", "0", "2"], ["83440.8", "0.18849567", "0", "2"], ["83440.1", "0.00001204", "0", "1"], ["83440", "0.00308005", "0", "1"], ["83439.2", "0.009093", "0", "1"], ["83439", "0.29445377", "0", "1"], ["83438.4", "0.00001629", "0", "1"], ["83438.2", "0.009093", "0", "1"], ["83437.8", "0.03001501", "0", "2"], ["83437.4", "0.00427082", "0", "1"], ["83435.9", "0.00020004", "0", "1"], ["83435.6", "0.00001", "0", "1"], ["83435.5", "0.35972754", "0", "1"], ["83435.4", "0.001189", "0", "1"], ["83434.7", "0.00598386", "0", "1"], ["83434.3", "0.03", "0", "1"], ["83434.2", "0.00011142", "0", "1"], ["83433.9", "0.03", "0", "1"], ["83433.6", "0.2025", "0", "1"], ["83433.4", "0.00001205", "0", "1"], ["83433.3", "0.00101501", "0", "2"], ["83432.4", "0.01194665", "0", "1"], ["83432.1", "0.2155", "0", "1"], ["83431.9", "0.00006004", "0", "1"], ["83431.7", "0.00017505", "0", "1"], ["83430.1", "0.00427258", "0", "1"], ["83430", "0.000015", "0", "1"], ["83429.5", "0.00005501", "0", "2"], ["83428.4", "0.00001205", "0", "1"], ["83428.1", "0.11986127", "0", "1"], ["83428", "0.00007368", "0", "1"], ["83427.5", "0.00001205", "0", "1"], ["83427.2", "0.17953568", "0", "1"], ["83426.8", "0.22204", "0", "1"], ["83426.6", "0.03", "0", "1"], ["83426.5", "0.35972754", "0", "1"], ["83426.4", "0.11992025", "0", "1"], ["83426.2", "0.00002851", "0", "1"], ["83425.2", "0.2025", "0", "1"], ["83425", "0.00009272", "0", "1"], ["83424.1", "0.00001001", "0", "1"], ["83423.9", "0.05389011", "0", "1"], ["83422.7", "0.192677", "0", "1"], ["83422.5", "0.18433078", "0", "1"], ["83422.4", "0.08333333", "0", "1"], ["83421.2", "0.00001501", "0", "1"], ["83420.8", "0.00002397", "0", "1"], ["83420.7", "0.00427296", "0", "1"], ["83420.1", "0.00068075", "0", "1"], ["83419.7", "0.01493332", "0", "1"], ["83419.3", "0.00001894", "0", "1"], ["83419.2", "0.01438518", "0", "1"], ["83418.9", "0.03", "0", "1"], ["83418.4", "0.00001205", "0", "1"], ["83418.2", "0.3015217", "0", "1"], ["83417.9", "0.01795158", "0", "3"], ["83417.7", "0.0123", "0", "1"], ["83416.8", "0.2025", "0", "1"], ["83416.6", "0.00154812", "0", "3"], ["83416.1", "0.00079489", "0", "1"], ["83415.8", "0.00001499", "0", "1"], ["83415", "0.0096", "0", "1"], ["83414.9", "0.00001205", "0", "1"], ["83414.6", "0.00011142", "0", "1"], ["83413.8", "0.00035965", "0", "1"], ["83413.4", "0.00003545", "0", "1"], ["83413.2", "0.01196166", "0", "1"], ["83413.1", "0.35972754", "0", "1"], ["83412.7", "0.00624904", "0", "1"], ["83412.2", "0.00427383", "0", "1"], ["83411.7", "0.00001807", "0", "1"], ["83411.3", "0.58013535", "0", "1"], ["83410.4", "0.17953568", "0", "1"], ["83410.2", "0.00009235", "0", "1"], ["83410", "0.00005457", "0", "1"], ["83409.7", "0.00021823", "0", "1"], ["83409.6", "0.11992025", "0", "1"], ["83408.4", "0.20251205", "0", "2"], ["83407.9", "0.00008801", "0", "1"], ["83405", "0.00599", "0", "1"], ["83403.7", "0.00427466", "0", "1"], ["83403.4", "0.00241105", "0", "2"], ["83402.6", "0.00024991", "0", "1"], ["83402.3", "0.00001205", "0", "1"], ["83401.5", "0.00012658", "0", "1"], ["83401.4", "0.03", "0", "1"], ["83400.6", "0.00599", "0", "1"], ["83400.3", "0.35972754", "0", "1"], ["83400.2", "0.17953568", "0", "1"], ["83400.1", "0.11992025", "0", "1"], ["83400", "10.17407135", "0", "47"], ["83399.9", "0.06795845", "0", "7"], ["83399", "0.00599556", "0", "1"], ["83398.4", "0.00010523", "0", "1"], ["83398", "0.04437308", "0", "3"], ["83396.7", "0.00008", "0", "1"], ["83396.4", "0.01588198", "0", "1"], ["83395.7", "0.00444738", "0", "2"], ["83395.5", "0.05555555", "0", "1"]], "ts": "1742377117202", "checksum": 606595488, "seqId": 49713534419, "prevSeqId": -1}], "record_time": 1742377118.066656}
{"arg": {"channel": "books", "instId": "BTC-USDT"}, "action": "update", "data": [{"asks": [["83556.2", "0.012", "0", "1"], ["83556.3", "0", "0", "0"], ["83556.4", "0.0002", "0", "2"]], "bids": [["83549.9", "0.00060612", "0", "1"], ["83549.8", "0.0002", "0", "2"], ["83545.3", "0.05689323", "0", "1"], ["83538.6", "0.35906205", "0", "2"], ["83520.1", "0", "0", "0"]], "ts": "1742377117302", "checksum": 693004076, "seqId": 49713534448, "prevSeqId": 49713534419}], "record_time": 1742377118.161422}
{"arg": {"channel": "books", "instId": "BTC-USDT"}, "action": "update", "data": [{"asks": [["83556.5", "0.09888011", "0", "2"], ["83560.2", "0", "0", "0"], ["83580.8", "0", "0", "0"], ["83589.8", "0.01219896", "0", "1"], ["83656.4", "0.00599857", "0", "2"]], "bids": [["83552", "0", "0", "0"], ["83549.8", "0.0001", "0", "1"], ["83549.6", "0.0001", "0", "1"], ["83536.1", "0", "0", "0"], ["83516", "1.01344072", "0", "3"], ["83501.2", "0", "0", "0"], ["83499.5", "0.23939856", "0", "1"], ["83395", "0.00017369", "0", "2"]], "ts": "1742377117402", "checksum": 924264361, "seqId": 49713534473, "prevSeqId": 49713534448}], "record_time": 1742377118.260652}
{"arg": {"channel": "books", "instId": "BTC-USDT"}, "action": "update", "data": [{"asks": [["83556", "0.0000105", "0", "1"], ["83581.5", "0", "0", "0"], ["83586.7", "0", "0", "0"], ["83656.5", "0.0002003", "0", "1"]], "bids": [["83549.8", "0.0002", "0", "2"], ["83549.6", "0", "0", "0"], ["83535", "0.17953", "0", "1"], ["83531.8", "0.57310718", "0", "3"], ["83516", "0.01344072", "0", "2"]], "ts": "1742377117502", "checksum": -506568177, "seqId": 49713534485, "prevSeqId": 49713534473}], "record_time": 1742377118.360577}
{"arg": {"channel": "books", "instId": "BTC-USDT"}, "action": "update", "data": [{"asks": [], "bids": [["83516", "0.01345072", "0", "3"], ["83510", "0.2056", "0", "2"]], "ts": "1742377117602", "checksum": -506568177, "seqId": 49713534495, "prevSeqId": 49713534485}], "record_time": 1742377118.463295}
{"arg": {"channel": "books", "instId": "BTC-USDT"}, "action": "update", "data": [{"asks": [], "bids": [["83549.9", "0.00070612", "0", "2"], ["83549.8", "0.0001", "0", "1"]], "ts": "1742377117702", "checksum": -2017793546, "seqId": 49713534507, "prevSeqId": 49713534495}], "record_time": 1742377118.563335}
{"arg": {"channel": "books", "instId": "BTC-USDT"}, "action": "update", "data": [{"asks": [["83555.9", "0.012", "0", "1"], ["83556.2", "0", "0", "0"], ["83570.4", "0.03693196", "0", "2"], ["83581", "1", "0", "1"], ["83656.5", "0", "0", "0"]], "bids": [["83549.9", "0.00080612", "0", "3"], ["83549.8", "0", "0", "0"], ["83394.9", "0.00078135", "0", "2"]], "ts": "1742377117802", "checksum": 851470474, "seqId": 49713534524, "prevSeqId": 49713534507}], "record_time": 1742377118.660657}
{"arg": {"channel": "books", "instId": "BTC-USDT"}, "action": "update", "data": [{"asks": [["83565.6", "0.06041699", "0", "1"], ["83580.8", "0.01219896", "0", "1"], ["83581", "0", "0", "0"], ["83589.8", "0", "0", "0"], ["83592", "0.08", "0", "2"], ["83592.8", "0.03999999", "0", "1"], ["83595.2", "0.17953568", "0", "1"], ["83596", "0", "0", "0"], ["83656.4", "0", "0", "0"]], "bids": [["83520.2", "0.01097934", "0", "1"], ["83497.6", "0.082513", "0", "3"], ["83496.8", "0.04", "0", "1"], ["83496", "0.11179806", "0", "4"], ["83394.9", "0", "0", "0"]], "ts": "1742377117902", "checksum": 851470474, "seqId": 49713534552, "prevSeqId": 49713534524}], "record_time": 1742377118.762456}
{"arg": {"channel": "books", "instId": "BTC-USDT"}, "action": "update", "data": [{"asks": [["83603.3", "0.00007342", "0", "1"], ["83656.3", "0", "0", "0"]], "bids": [["83496.8", "0.14", "0", "3"], ["83496", "0.06179806", "0", "3"], ["83495.2", "0.026", "0", "2"]], "ts": "1742377118002", "checksum": 851470474, "seqId": 49713534569, "prevSeqId": 49713534552}], "record_time": 1742377118.863325}
{"arg": {"channel": "books", "instId": "BTC-USDT"}, "action": "update", "data": [{"asks": [["83556.3", "0.0002", "0", "2"], ["83556.4", "0", "0", "0"], ["83562.1", "0", "0", "0"], ["83572.2", "0", "0", "0"], ["83580.8", "0", "0", "0"], ["83581.5", "0.00351478", "0", "1"], ["83584.5", "0.26561569", "0", "2"], ["83589.8", "0.01219896", "0", "1"], ["83608.1", "0.0036477", "0", "1"], ["83609.2", "0", "0", "0"], ["83619.8", "0.00015935", "0", "2"], ["83619.9", "0.00018106", "0", "3"], ["83656.3", "0.01074264", "0", "3"]], "bids": [["83552.3", "0", "0", "0"], ["83552", "0.0567", "0", "1"], ["83550", "0.0568", "0", "2"], ["83549.9", "0.00070612", "0", "2"], ["83545.3", "0.11115932", "0", "2"], ["83545.2", "0.2025", "0", "1"], ["83542.2", "0", "0", "0"], ["83535", "0", "0", "0"], ["83524.8", "0.48943825", "0", "2"], ["83510", "0.0056", "0", "1"], ["83501.1", "0.23939416", "0", "1"], ["83500.1", "0.23907092", "0", "2"], ["83499.5", "0", "0", "0"], ["83497.5", "0.00198595", "0", "1"], ["83497.2", "0", "0", "0"], ["83493.4", "0", "0", "0"], ["83492.3", "0.01843316", "0", "1"], ["83422.5", "0", "0", "0"], ["83420.8", "0.18435558", "0", "2"], ["83394.9", "0.00078135", "0", "2"], ["83394.3", "0.03", "0", "1"]], "ts": "1742377118102", "checksum": 1998586493, "seqId": 49713534618, "prevSeqId": 49713534569}], "record_time": 1742377118.962167}
{"arg": {"channel": "books", "instId": "BTC-USDT"}, "action": "update", "data": [{"asks": [["83556.3", "0.0001", "0", "1"], ["83556.5", "0.09898011", "0", "3"], ["83559", "0.23939323", "0", "1"]], "bids": [["83553.6", "0.50978198", "0", "4"], ["83550", "0.0567", "0", "1"], ["83549.9", "0.00060612", "0", "1"], ["83546.1", "0.00105843", "0", "3"], ["83545.3", "0.10965932", "0", "2"], ["83531.8", "0.57295718", "0", "2"], ["83510", "0", "0", "0"], ["83501.5", "0.23939303", "0", "1"], ["83501.1", "0", "0", "0"], ["83493.3", "0", "0", "0"], ["83479.1", "0.0056", "0", "1"], ["83451.5", "0.01179806", "0", "2"], ["83445.7", "0.06362294", "0", "2"], ["83394.1", "0.00399952", "0", "1"]], "ts": "1742377118202", "checksum": 1905973746, "seqId": 49713534653, "prevSeqId": 49713534618}], "record_time": 1742377119.06103}
{"arg": {"channel": "books", "instId": "BTC-USDT"}, "action": "update", "data": [{"asks": [["83556.3", "0.0002", "0", "2"], ["83556.5", "0.09888011", "0", "2"], ["83559", "0", "0", "0"], ["83559.9", "0.23939187", "0", "1"]], "bids": [["83553.6", "0.51438198", "0", "5"], ["83546.1", "0.00085843", "0", "1"], ["83546", "0.0001", "0", "1"], ["83545.8", "0.0001", "0", "1"], ["83545.2", "0.11969329", "0", "1"], ["83533.8", "0.001071", "0", "1"], ["83501.4", "0", "0", "0"], ["83394.3", "0", "0", "0"], ["83394.1", "0", "0", "0"]], "ts": "1742377118302", "checksum": 1758398603, "seqId": 49713534682, "prevSeqId": 49713534653}], "record_time": 1742377119.161039}
{"arg": {"channel": "books", "instId": "BTC-USDT"}, "action": "update", "data": [{"asks": [["83556.3", "0", "0", "0"], ["83556.4", "0.0002", "0", "2"], ["83559", "0.23939356", "0", "1"], ["83559.9", "0", "0", "0"]], "bids": [["83553.6", "0.52038198", "0", "6"], ["83546", "0", "0", "0"], ["83545.9", "0.0002", "0", "2"], ["83545.8", "0", "0", "0"], ["83501.5", "0", "0", "0"], ["83501.1", "0.23939356", "0", "1"], ["83497", "0.05847155", "0", "1"]], "ts": "1742377118402", "checksum": 1986868795, "seqId": 49713534704, "prevSeqId": 49713534682}], "record_time": 1742377119.261341}
{"arg": {"channel": "books", "instId": "BTC-USDT"}, "action": "update", "data": [{"asks": [["83559", "0.23939624", "0", "1"]], "bids": [["83541.9", "0.35972754", "0", "1"], ["83541.7", "0", "0", "0"], ["83517", "1", "0", "1"], ["83501.1", "0", "0", "0"], ["83500.2", "0.23939624", "0", "1"], ["83394.9", "0", "0", "0"]], "ts": "1742377118502", "checksum": -1522169260, "seqId": 49713534718, "prevSeqId": 49713534704}], "record_time": 1742377119.365696}
{"arg": {"channel": "books", "instId": "BTC-USDT"}, "action": "update", "data": [{"asks": [], "bids": [["83535", "0.17953", "0", "1"], ["83517.1", "0.01219896", "0", "1"], ["83516.9", "0", "0", "0"], ["83395", "0", "0", "0"]], "ts": "1742377118602", "checksum": -1522169260, "seqId": 49713534723, "prevSeqId": 49713534718}], "record_time": 1742377119.460864}
{"arg": {"channel": "books", "instId": "BTC-USDT"}, "action": "update", "data": [{"asks": [["83559", "0", "0", "0"], ["83559.9", "0.23939268", "0", "1"]], "bids": [["83545.9", "0.0001", "0", "1"], ["83545.7", "0.000115", "0", "2"], ["83501.1", "0.23939268", "0", "1"], ["83500.2", "0", "0", "0"]], "ts": "1742377118702", "checksum": -1663882532, "seqId": 49713534742, "prevSeqId": 49713534723}], "record_time": 1742377119.560525}
{"arg": {"channel": "books", "instId": "BTC-USDT"}, "action": "update", "data": [{"asks": [], "bids": [["83545.9", "0.0002", "0", "2"], ["83545.7", "0.000015", "0", "1"]], "ts": "1742377118802", "checksum": -1439397952, "seqId": 49713534745, "prevSeqId": 49713534742}], "record_time": 1742377119.661161}
{"arg": {"channel": "books", "instId": "BTC-USDT"}, "action": "update", "data": [{"asks": [["83553.7", "2.09890357", "0", "27"], ["83562.1", "0.005", "0", "1"], ["83572.2", "0.005", "0", "1"], ["83580", "1.02137958", "0", "3"], ["83591.4", "0.15207424", "0", "2"], ["83656.2", "0", "0", "0"], ["83656.3", "0", "0", "0"]], "bids": [["83551.9", "0.005", "0", "1"], ["83546.1", "0.00105843", "0", "3"], ["83545.9", "0", "0", "0"], ["83541.8", "0.49313166", "0", "3"]], "ts": "1742377118902", "checksum": 1430141274, "seqId": 49713534769, "prevSeqId": 49713534745}], "record_time": 1742377119.760191}
{"arg": {"channel": "books", "instId": "BTC-USDT"}, "action": "update", "data": [{"asks": [["83578", "0", "0", "0"], ["83579.9", "0.01219896", "0", "1"], ["83589.8", "0", "0", "0"], ["83632.8", "0", "0", "0"], ["83656.2", "0.00300703", "0", "3"], ["83656.3", "0.01074264", "0", "3"]], "bids": [["83517", "0", "0", "0"], ["83468.9", "0", "0", "0"], ["83395", "0.00017369", "0", "2"], ["83394.9", "0.00078135", "0", "2"]], "ts": "1742377119002", "checksum": 1430141274, "seqId": 49713534784, "prevSeqId": 49713534769}], "record_time": 1742377119.860905}
{"arg": {"channel": "books", "instId": "BTC-USDT"}, "action": "update", "data": [{"asks": [["83553.9", "0.24882828", "0", "2"], ["83576.9", "0.43806103", "0", "1"], ["83578", "0.2", "0", "1"], ["83588.6", "0.02335346", "0", "2"], ["83624.8", "0.07174907", "0", "1"], ["83636.4", "0", "0", "0"], ["83656.2", "0", "0", "0"], ["83656.3", "0", "0", "0"]], "bids": [["83531.8", "0.57056289", "0", "1"], ["83520.7", "0.16254246", "0", "1"], ["83520", "0.00501", "0", "3"], ["83517.1", "0", "0", "0"], ["83516.9", "0.01219896", "0", "1"], ["83472.5", "0", "0", "0"], ["83460.9", "0.07188992", "0", "1"], ["83394.9", "0", "0", "0"]], "ts": "1742377119102", "checksum": -775357443, "seqId": 49713534810, "prevSeqId": 49713534784}], "record_time": 1742377119.960298}
{"arg": {"channel": "books", "instId": "BTC-USDT"}, "action": "update", "data": [{"asks": [], "bids": [["83510", "0.2", "0", "1"], ["83395", "0", "0", "0"]], "ts": "1742377119202", "checksum": -775357443, "seqId": 49713534814, "prevSeqId": 49713534810}], "record_time": 1742377120.060577}
{"arg": {"channel": "books", "instId": "BTC-USDT"}, "action": "update", "data": [{"asks": [], "bids": [["83546.1", "0.00095843", "0", "2"], ["83545.7", "0.000115", "0", "2"], ["83500.8", "0.09071011", "0", "3"], ["83500", "0.10999676", "0", "7"], ["83499.2", "0", "0", "0"], ["83395", "0.00017369", "0", "2"]], "ts": "1742377119302", "checksum": 947964766, "seqId": 49713534835, "prevSeqId": 49713534814}], "record_time": 1742377120.164761}
{"arg": {"channel": "books", "instId": "BTC-USDT"}, "action": "update", "data": [{"asks": [["83553.9", "0.25122194", "0", "3"], ["83559.9", "0.23939297", "0", "1"], ["83624.8", "0.14349814", "0", "2"]], "bids": [["83553.6", "0.51973478", "0", "6"], ["83546.1", "0.00105843", "0", "3"], ["83545.7", "0.000015", "0", "1"], ["83531.8", "0.57295718", "0", "2"], ["83460.9", "0.14377984", "0", "2"], ["83440.2", "0.43", "0", "1"], ["83395", "0", "0", "0"]], "ts": "1742377119402", "checksum": -218438042, "seqId": 49713534872, "prevSeqId": 49713534835}], "record_time": 1742377120.260555}
{"arg": {"channel": "books", "instId": "BTC-USDT"}, "action": "update", "data": [{"asks": [["83553.7", "1.86805803", "0", "24"], ["83556.4", "0", "0", "0"], ["83556.5", "0.09908011", "0", "4"], ["83559", "0.23939492", "0", "1"], ["83559.9", "0", "0", "0"], ["83563.2", "0.003591", "0", "1"], ["83563.9", "0.01097934", "0", "1"], ["83581.5", "0", "0", "0"], ["83643.1", "0.00008565", "0", "1"]], "bids": [["83552", "0", "0", "0"], ["83546.9", "0.0001", "0", "1"], ["83546.8", "0.0001", "0", "1"], ["83546.1", "0.00085843", "0", "1"], ["83500.8", "0.08991011", "0", "1"], ["83500", "0.11039676", "0", "8"], ["83499.2", "0.0004", "0", "1"], ["83395.7", "0", "0", "0"], ["83395.5", "0", "0", "0"]], "ts": "1742377119502", "checksum": -1143696533, "seqId": 49713534918, "prevSeqId": 49713534872}], "record_time": 1742377120.360792}
{"arg": {"channel": "books", "instId": "BTC-USDT"}, "action": "update", "data": [{"asks": [["83553.7", "1.87903737", "0", "25"], ["83563.9", "0", "0", "0"], ["83581.5", "0.00363472", "0", "1"], ["83618.8", "0.17828474", "0", "4"]], "bids": [["83553.6", "0.52038478", "0", "7"], ["83546.9", "0.0002", "0", "2"], ["83546.8", "0", "0", "0"], ["83500.8", "0.09071011", "0", "3"], ["83500", "0.10999676", "0", "7"], ["83499.2", "0", "0", "0"], ["83395.7", "0.00444738", "0", "2"], ["83395.5", "0.05555555", "0", "1"]], "ts": "1742377119602", "checksum": 948456078, "seqId": 49713534934, "prevSeqId": 49713534918}], "record_time": 1742377120.460217}
{"arg": {"channel": "books", "instId": "BTC-USDT"}, "action": "update", "data": [{"asks": [["83556.5", "0.00917", "0", "3"], ["83559", "0", "0", "0"], ["83559.9", "0.23939178", "0", "1"]], "bids": [["83552", "0.0567", "0", "1"], ["83547", "0.0001", "0", "1"], ["83546.9", "0.0001", "0", "1"], ["83545.2", "0.32219329", "0", "2"], ["83395.7", "0", "0", "0"], ["83395.5", "0", "0", "0"]], "ts": "1742377119702", "checksum": -692937112, "seqId": 49713534948, "prevSeqId": 49713534934}], "record_time": 1742377120.563927}
{"arg": {"channel": "books", "instId": "BTC-USDT"}, "action": "update", "data": [{"asks": [], "bids": [["83545.2", "0.11969329", "0", "1"], ["83500.8", "0.08991011", "0", "1"], ["83500", "0.11039676", "0", "8"], ["83499.2", "0.0004", "0", "1"], ["83396.4", "0", "0", "0"]], "ts": "1742377119802", "checksum": 1279782829, "seqId": 49713534959, "prevSeqId": 49713534948}], "record_time": 1742377120.660483}
{"arg": {"channel": "books", "instId": "BTC-USDT"}, "action": "update", "data": [{"asks": [["83565.6", "0", "0", "0"], ["83656.2", "0.00300703", "0", "3"]], "bids": [], "ts": "1742377119902", "checksum": 1279782829, "seqId": 49713534971, "prevSeqId": 49713534959}], "record_time": 1742377120.760957}
{"arg": {"channel": "books", "instId": "BTC-USDT"}, "action": "update", "data": [{"asks": [["83553.8", "0.103591", "0", "2"], ["83556.5", "0.00907", "0", "2"], ["83556.6", "0.0001", "0", "1"], ["83559.1", "0.27454457", "0", "2"], ["83561.4", "0.0571599", "0", "1"], ["83563.2", "0", "0", "0"], ["83576.9", "0", "0", "0"], ["83578", "0", "0", "0"], ["83580", "0.02137958", "0", "2"], ["83656.3", "0.01074264", "0", "3"]], "bids": [["83552", "0", "0", "0"], ["83547", "0", "0", "0"], ["83546.9", "0", "0", "0"], ["83546.7", "0.00797902", "0", "3"], ["83517", "1", "0", "1"], ["83396.4", "0.01588198", "0", "1"], ["83395.7", "0.00444738", "0", "2"]], "ts": "1742377120002", "checksum": 1579067376, "seqId": 49713535007, "prevSeqId": 49713534971}], "record_time": 1742377120.860547}
{"arg": {"channel": "books", "instId": "BTC-USDT"}, "action": "update", "data": [{"asks": [["83556.4", "0.0001", "0", "1"], ["83556.6", "0", "0", "0"], ["83562", "0.004", "0", "2"], ["83572.1", "0.004", "0", "2"], ["83576.4", "0.15590766", "0", "1"], ["83579.9", "0", "0", "0"], ["83589.8", "0.01219896", "0", "1"], ["83619.4", "0.03013267", "0", "2"], ["83619.8", "0.00002668", "0", "1"], ["83656.3", "0", "0", "0"]], "bids": [["83553.6", "0.51911866", "0", "7"], ["83551.8", "0.007", "0", "2"], ["83546.9", "0.0001", "0", "1"], ["83546.8", "0.0001", "0", "1"], ["83546.7", "0.00777902", "0", "1"], ["83541.7", "0.002", "0", "1"], ["83520.7", "0.44663434", "0", "2"], ["83517.1", "0.01219896", "0", "1"], ["83516.9", "0", "0", "0"], ["83514.3", "0", "0", "0"], ["83503.4", "0.495466", "0", "1"], ["83396.7", "0", "0", "0"], ["83396.4", "0", "0", "0"], ["83395.7", "0", "0", "0"]], "ts": "1742377120102", "checksum": -976278869, "seqId": 49713535043, "prevSeqId": 49713535007}], "record_time": 1742377120.960202}
{"arg": {"channel": "books", "instId": "BTC-USDT"}, "action": "update", "data": [{"asks": [["83556.4", "0.0002", "0", "2"], ["83556.5", "0.00897", "0", "1"]], "bids": [["83553.6", "0.52037866", "0", "8"], ["83546.9", "0", "0", "0"], ["83546.8", "0.0002", "0", "2"], ["83396.7", "0.00008", "0", "1"]], "ts": "1742377120202", "checksum": -496828739, "seqId": 49713535067, "prevSeqId": 49713535043}], "record_time": 1742377121.060426}
{"arg": {"channel": "books", "instId": "BTC-USDT"}, "action": "update", "data": [{"asks": [["83559.9", "0.23939218", "0", "1"], ["83571.6", "0", "0", "0"], ["83601.3", "0", "0", "0"], ["83656.3", "0.01074264", "0", "3"], ["83656.4", "0.00599857", "0", "2"]], "bids": [["83512.7", "0.01796216", "0", "1"], ["83512.6", "0", "0", "0"], ["83489.7", "0", "0", "0"], ["83488.4", "0.00001013", "0", "1"], ["83419.2", "0", "0", "0"], ["83396.4", "0.01588198", "0", "1"], ["83395.7", "0.00444738", "0", "2"], ["83395.5", "0.05555555", "0", "1"]], "ts": "1742377120302", "checksum": 1575071486, "seqId": 49713535090, "prevSeqId": 49713535067}], "record_time": 1742377121.160076}
{"arg": {"channel": "books", "instId": "BTC-USDT"}, "action": "update", "data": [{"asks": [["83556.4", "0", "0", "0"], ["83556.5", "0.00917", "0", "3"], ["83559.9", "0.23939042", "0", "1"], ["83564.9", "1.5581502", "0", "1"], ["83567.9", "0.24157301", "0", "1"], ["83589.8", "0", "0", "0"], ["83594.7", "3.24279212", "0", "2"], ["83601.2", "0.38248281", "0", "1"], ["83622.3", "0.01219896", "0", "1"]], "bids": [["83512.4", "1.57644423", "0", "1"], ["83504.4", "0", "0", "0"], ["83504.3", "0", "0", "0"], ["83503.7", "0.23939035", "0", "1"], ["83501.1", "0", "0", "0"], ["83490.9", "0.19411509", "0", "1"], ["83488.5", "0.00001206", "0", "1"], ["83488.1", "0.00198266", "0", "1"], ["83482.7", "3.75240798", "0", "2"], ["83473.1", "1.03881171", "0", "2"], ["83472.6", "3.03864", "0", "1"], ["83395.5", "0", "0", "0"]], "ts": "1742377120402", "checksum": 902293331, "seqId": 49713535136, "prevSeqId": 49713535090}], "record_time": 1742377121.260572}
{"arg": {"channel": "books", "instId": "BTC-USDT"}, "action": "update", "data": [{"asks": [["83553.8", "0.1", "0", "1"], ["83556.4", "0.0001", "0", "1"], ["83556.5", "0.00907", "0", "2"], ["83559.9", "0.23939218", "0", "1"], ["83563.3", "0.75123429", "0", "1"], ["83656.4", "0", "0", "0"]], "bids": [["83546.8", "0", "0", "0"], ["83546.7", "0.00787902", "0", "2"], ["83546.5", "0.0001", "0", "1"], ["83520.7", "0.16254246", "0", "1"], ["83517", "0", "0", "0"], ["83503.7", "0", "0", "0"], ["83501.1", "0.23939102", "0", "1"], ["83395.5", "0.05555555", "0", "1"]], "ts": "1742377120502", "checksum": 643514592, "seqId": 49713535163, "prevSeqId": 49713535136}], "record_time": 1742377121.361291}
{"arg": {"channel": "books", "instId": "BTC-USDT"}, "action": "update", "data": [{"asks": [["83553.7", "2.29209097", "0", "27"], ["83554.4", "0.00777943", "0", "1"], ["83556.4", "0.0002", "0", "2"], ["83556.5", "0.00897", "0", "1"], ["83556.9", "0.08991011", "0", "1"], ["83559.8", "0.04", "0", "1"], ["83559.9", "0", "0", "0"], ["83564.5", "0", "0", "0"], ["83569", "0", "0", "0"], ["83589.8", "0.01219896", "0", "1"], ["83605.7", "0", "0", "0"], ["83605.8", "0", "0", "0"], ["83622.3", "0", "0", "0"], ["83656.4", "0.00599857", "0", "2"], ["83656.5", "0.0002003", "0", "1"]], "bids": [["83550.1", "0", "0", "0"], ["83549.1", "0", "0", "0"], ["83548.1", "0", "0", "0"], ["83547.2", "0.05449833", "0", "1"], ["83546.7", "0.00777902", "0", "1"], ["83546.5", "0", "0", "0"], ["83545.9", "0.00777984", "0", "1"], ["83545.8", "0.0001", "0", "1"], ["83545.6", "0.0001", "0", "1"], ["83545.4", "0.06259516", "0", "1"], ["83545.3", "0", "0", "0"], ["83545.2", "0", "0", "0"], ["83543.3", "0", "0", "0"], ["83543", "0.20144394", "0", "2"], ["83541.9", "0", "0", "0"], ["83540.7", "0.09085578", "0", "1"], ["83539.4", "0", "0", "0"], ["83537.7", "0.02490908", "0", "1"], ["83537.2", "0", "0", "0"], ["83535.7", "0", "0", "0"], ["83533.8", "0", "0", "0"], ["83533.5", "0.02490908", "0", "1"], ["83531.8", "0.00239429", "0", "1"], ["83530.8", "0", "0", "0"], ["83530.2", "0.000495", "0", "1"], ["83527.7", "0.01197249", "0", "1"], ["83520.2", "0", "0", "0"], ["83517.1", "0", "0", "0"], ["83516.9", "0.01219896", "0", "1"], ["83515.1", "0.57327126", "0", "1"], ["83501.1", "0", "0", "0"], ["83497", "0", "0", "0"], ["83496.3", "0.23941163", "0", "1"], ["83491.2", "0.26115835", "0", "2"], ["83395", "0.00017369", "0", "2"], ["83394.9", "0.00078135", "0", "2"], ["83394.3", "0.03", "0", "1"], ["83393.4", "0.00001205", "0", "1"]], "ts": "1742377120602", "checksum": 507290582, "seqId": 49713535253, "prevSeqId": 49713535163}], "record_time": 1742377121.460902}
{"arg": {"channel": "books", "instId": "BTC-USDT"}, "action": "update", "data": [{"asks": [["83553.7", "2.06834467", "0", "27"], ["83554.1", "0.08392837", "0", "2"], ["83556.8", "0.23940289", "0", "1"], ["83599.9", "0.59530749", "0", "6"], ["83656.5", "0", "0", "0"]], "bids": [["83545.9", "0.00797984", "0", "3"], ["83545.8", "0", "0", "0"], ["83545.6", "0", "0", "0"], ["83545.4", "0.13381117", "0", "1"], ["83543.1", "0.27755506", "0", "2"], ["83541.9", "0.35972754", "0", "1"], ["83534.5", "0.208393", "0", "2"], ["83522.2", "0.26714822", "0", "2"], ["83510", "0", "0", "0"], ["83499.2", "0.23980289", "0", "2"], ["83496.3", "0", "0", "0"], ["83451.7", "0.01437956", "0", "1"], ["83426.4", "0.12391779", "0", "2"], ["83393.1", "0.00001731", "0", "1"]], "ts": "1742377120702", "checksum": -531581020, "seqId": 49713535286, "prevSeqId": 49713535253}], "record_time": 1742377121.561701}
{"arg": {"channel": "books", "instId": "BTC-USDT"}, "action": "update", "data": [{"asks": [["83556.4", "0.0001", "0", "1"], ["83556.5", "0.00907", "0", "2"], ["83556.8", "0.23939875", "0", "1"], ["83580.3", "0.68130909", "0", "2"], ["83622.4", "0.39914095", "0", "4"]], "bids": [["83545.9", "0.00777984", "0", "1"], ["83545.7", "0.000115", "0", "2"], ["83545.6", "0.0001", "0", "1"], ["83541.1", "0", "0", "0"], ["83500.6", "0.23939875", "0", "1"], ["83499.2", "0.0004", "0", "1"], ["83393.1", "0", "0", "0"]], "ts": "1742377120802", "checksum": -2143464687, "seqId": 49713535312, "prevSeqId": 49713535286}], "record_time": 1742377121.660615}
{"arg": {"channel": "books", "instId": "BTC-USDT"}, "action": "update", "data": [{"asks": [["83556.3", "0.0001", "0", "1"], ["83556.5", "0.00897", "0", "1"], ["83556.8", "0", "0", "0"], ["83556.9", "0", "0", "0"], ["83559", "0.23939779", "0", "1"], ["83580.2", "0.01219896", "0", "1"], ["83589.8", "0", "0", "0"]], "bids": [["83547.2", "0", "0", "0"], ["83545.9", "0.00797984", "0", "3"], ["83545.7", "0.000015", "0", "1"], ["83545.6", "0", "0", "0"], ["83545.1", "0.11969331", "0", "1"], ["83543", "0.0817475", "0", "1"], ["83529.8", "0.00360959", "0", "1"], ["83501.1", "0.23939779", "0", "1"], ["83500.6", "0", "0", "0"]], "ts": "1742377120902", "checksum": -1973448414, "seqId": 49713535337, "prevSeqId": 49713535312}], "record_time": 1742377121.766174}
{"arg": {"channel": "books", "instId": "BTC-USDT"}, "action": "update", "data": [{"asks": [["83556.3", "0", "0", "0"], ["83556.5", "0.00907", "0", "2"], ["83581", "1", "0", "1"], ["83586", "0.2", "0", "1"], ["83656.4", "0", "0", "0"]], "bids": [["83546.1", "0.00105843", "0", "3"], ["83545.9", "0.00777984", "0", "1"], ["83533.2", "0.0000525", "0", "1"], ["83530.2", "0", "0", "0"], ["83515.1", "0", "0", "0"], ["83501.9", "0.57263787", "0", "1"]], "ts": "1742377121002", "checksum": -1068608595, "seqId": 49713535354, "prevSeqId": 49713535337}], "record_time": 1742377121.863029}
{"arg": {"channel": "books", "instId": "BTC-USDT"}, "action": "update", "data": [{"asks": [["83556.4", "0", "0", "0"], ["83556.5", "0.00917", "0", "3"], ["83581", "0", "0", "0"], ["83586", "0", "0", "0"], ["83656.4", "0.00599857", "0", "2"], ["83656.5", "0.0002003", "0", "1"], ["83656.6", "0.00012", "0", "1"]], "bids": [], "ts": "1742377121102", "checksum": 1004312159, "seqId": 49713535362, "prevSeqId": 49713535354}], "record_time": 1742377121.960295}
{"arg": {"channel": "books", "instId": "BTC-USDT"}, "action": "update", "data": [{"asks": [["83556.3", "0.0001", "0", "1"], ["83556.4", "0.0001", "0", "1"], ["83556.5", "0.00897", "0", "1"], ["83593.6", "1.10967685", "0", "2"], ["83656.5", "0", "0", "0"], ["83656.6", "0", "0", "0"]], "bids": [["83546.1", "0.00085843", "0", "1"], ["83546", "0.0001", "0", "1"], ["83545.9", "0.00787984", "0", "2"], ["83545.6", "0.10422748", "0", "1"], ["83545.5", "0.13877753", "0", "1"], ["83545.4", "0", "0", "0"], ["83543.1", "0", "0", "0"], ["83537.7", "0", "0", "0"], ["83512.5", "0.70268255", "0", "2"]], "ts": "1742377121302", "checksum": -1087365074, "seqId": 49713535392, "prevSeqId": 49713535362}], "record_time": 1742377122.160605}
{"arg": {"channel": "books", "instId": "BTC-USDT"}, "action": "update", "data": [{"asks": [["83553.7", "2.17380684", "0", "28"], ["83556.3", "0", "0", "0"], ["83556.4", "0", "0", "0"], ["83556.5", "0.00917", "0", "3"], ["83558.1", "0.2394025", "0", "1"], ["83558.2", "0.08991011", "0", "1"], ["83559", "0", "0", "0"], ["83634", "0.00002119", "0", "1"], ["83656.5", "0.0002003", "0", "1"]], "bids": [["83546.2", "0.0001", "0", "1"], ["83546.1", "0.00095843", "0", "2"], ["83546", "0", "0", "0"], ["83545.9", "0.00777984", "0", "1"], ["83501.1", "0", "0", "0"], ["83497.7", "0.23940366", "0", "1"]], "ts": "1742377121402", "checksum": -389218024, "seqId": 49713535435, "prevSeqId": 49713535392}], "record_time": 1742377122.260393}
{"arg": {"channel": "books", "instId": "BTC-USDT"}, "action": "update", "data": [{"asks": [["83553.8", "0.103591", "0", "2"], ["83556.4", "0.0002", "0", "2"], ["83556.5", "0.00897", "0", "1"], ["83558.1", "0.2394045", "0", "1"], ["83656.5", "0", "0", "0"]], "bids": [["83550", "0", "0", "0"], ["83546.2", "0", "0", "0"], ["83546.1", "0.00085843", "0", "1"], ["83545.8", "0.0001", "0", "1"], ["83545.6", "0.10432748", "0", "2"], ["83533.2", "0", "0", "0"], ["83529.8", "0", "0", "0"], ["83528.9", "0", "0", "0"], ["83526.7", "0.04", "0", "1"], ["83515", "1", "0", "1"], ["83413.2", "0", "0", "0"], ["83405.3", "0.01196303", "0", "1"], ["83393.1", "0.00001731", "0", "1"], ["83393", "0.01489957", "0", "2"]], "ts": "1742377121502", "checksum": 897040225, "seqId": 49713535467, "prevSeqId": 49713535435}], "record_time": 1742377122.362044}
{"arg": {"channel": "books", "instId": "BTC-USDT"}, "action": "update", "data": [{"asks": [["83581.5", "0", "0", "0"], ["83656.2", "0.00002037", "0", "2"], ["83656.5", "0.0002003", "0", "1"]], "bids": [["83546.1", "0.00105843", "0", "3"], ["83545.8", "0", "0", "0"], ["83545.6", "0.10422748", "0", "1"], ["83538.4", "0.02490908", "0", "1"], ["83529.5", "0.00351299", "0", "1"], ["83527.5", "0.004302", "0", "1"], ["83500.6", "0.2393983", "0", "1"], ["83497.7", "0", "0", "0"], ["83460.6", "0", "0", "0"], ["83451.3", "0", "0", "0"], ["83440.8", "0.17953568", "0", "1"], ["83432.4", "0", "0", "0"], ["83419.7", "0", "0", "0"], ["83392.9", "0.0429", "0", "3"], ["83392.8", "0.0286", "0", "2"]], "ts": "1742377121602", "checksum": -844720673, "seqId": 49713535503, "prevSeqId": 49713535467}], "record_time": 1742377122.462175}
{"arg": {"channel": "books", "instId": "BTC-USDT"}, "action": "update", "data": [{"asks": [], "bids": [["83550", "0.0567", "0", "1"], ["83529.5", "0", "0", "0"], ["83505", "0.2", "0", "1"], ["83392.8", "0", "0", "0"]], "ts": "1742377121702", "checksum": -1382513424, "seqId": 49713535514, "prevSeqId": 49713535503}], "record_time": 1742377122.560975}
{"arg": {"channel": "books", "instId": "BTC-USDT"}, "action": "update", "data": [{"asks": [["83553.7", "2.06898324", "0", "28"], ["83556.4", "0", "0", "0"], ["83556.5", "0.00917", "0", "3"], ["83656.6", "0.00012", "0", "1"]], "bids": [["83515", "0", "0", "0"], ["83505", "0", "0", "0"], ["83500.6", "0", "0", "0"], ["83499.2", "0.23980166", "0", "2"], ["83392.8", "0.0286", "0", "2"], ["83391.6", "0.2025", "0", "1"], ["83391", "0.10497659", "0", "2"]], "ts": "1742377121802", "checksum": 924014980, "seqId": 49713535541, "prevSeqId": 49713535514}], "record_time": 1742377122.661616}
{"arg": {"channel": "books", "instId": "BTC-USDT"}, "action": "update", "data": [{"asks": [], "bids": [["83527.5", "0", "0", "0"], ["83390.9", "0.00427658", "0", "1"]], "ts": "1742377121902", "checksum": 924014980, "seqId": 49713535549, "prevSeqId": 49713535541}], "record_time": 1742377122.760456}
{"arg": {"channel": "books", "instId": "BTC-USDT"}, "action": "update", "data": [{"asks": [], "bids": [["83499.2", "0.0004", "0", "1"], ["83497.7", "0.23940289", "0", "1"], ["83488.8", "0.01196303", "0", "1"], ["83486.5", "0", "0", "0"], ["83390.9", "0", "0", "0"]], "ts": "1742377122002", "checksum": 924014980, "seqId": 49713535559, "prevSeqId": 49713535549}], "record_time": 1742377122.862547}
{"arg": {"channel": "books", "instId": "BTC-USDT"}, "action": "update", "data": [{"asks": [["83553.7", "2.4387176", "0", "30"], ["83558.1", "0", "0", "0"], ["83619.3", "0.00013267", "0", "1"], ["83619.4", "0.03", "0", "1"], ["83624.8", "0.07174907", "0", "1"], ["83649.8", "0.00299693", "0", "2"]], "bids": [["83550", "0", "0", "0"], ["83545.6", "0.0956886", "0", "2"], ["83545.1", "0", "0", "0"], ["83542.7", "0.11969685", "0", "1"], ["83538.4", "0", "0", "0"], ["83531.7", "0.35975004", "0", "2"], ["83497.7", "0.23940429", "0", "1"], ["83492.3", "0", "0", "0"], ["83491.9", "0.01843387", "0", "1"], ["83460.9", "0.07188992", "0", "1"], ["83454.2", "0.00725619", "0", "2"], ["83440.9", "0.00597332", "0", "1"], ["83429.5", "0.009015", "0", "3"], ["83420.5", "0.01194665", "0", "1"], ["83412.2", "0.01920715", "0", "2"]], "ts": "1742377122102", "checksum": -1535358149, "seqId": 49713535640, "prevSeqId": 49713535559}], "record_time": 1742377122.963718}
{"arg": {"channel": "books", "instId": "BTC-USDT"}, "action": "update", "data": [{"asks": [["83553.7", "2.06898324", "0", "28"], ["83556.4", "0.0001", "0", "1"], ["83556.5", "0.00907", "0", "2"], ["83558.2", "0", "0", "0"], ["83559.7", "0.23939239", "0", "1"], ["83581.5", "0.00354603", "0", "1"], ["83619.3", "0", "0", "0"], ["83624.8", "0.14349814", "0", "2"], ["83656.6", "0", "0", "0"]], "bids": [["83552", "0.0567", "0", "1"], ["83548.1", "0.01934371", "0", "1"], ["83545.6", "0.06831948", "0", "1"], ["83542.7", "0", "0", "0"], ["83538.4", "0.02490908", "0", "1"], ["83529", "0.18318333", "0", "2"], ["83521.1", "0.01097934", "0", "1"], ["83502", "0.23939344", "0", "1"], ["83497.7", "0", "0", "0"], ["83460.9", "0.14377984", "0", "2"], ["83392.8", "0", "0", "0"], ["83391.6", "0", "0", "0"], ["83391", "0", "0", "0"]], "ts": "1742377122202", "checksum": 1301404571, "seqId": 49713535706, "prevSeqId": 49713535640}], "record_time": 1742377123.060727}
{"arg": {"channel": "books", "instId": "BTC-USDT"}, "action": "update", "data": [{"asks": [["83553.7", "1.89533345", "0", "27"], ["83556.4", "0.0002", "0", "2"], ["83556.5", "0.00897", "0", "1"], ["83559.7", "0", "0", "0"], ["83560.9", "0.23938911", "0", "1"], ["83580.2", "0.74033261", "0", "2"], ["83581.6", "0", "0", "0"], ["83605.4", "0.31463323", "0", "1"], ["83619.3", "0.00013267", "0", "1"], ["83656.5", "0", "0", "0"]], "bids": [["83546.7", "0.00797902", "0", "3"], ["83546.1", "0.00085843", "0", "1"], ["83503.7", "0.23938911", "0", "1"], ["83503.5", "0.60555155", "0", "2"], ["83502", "0", "0", "0"]], "ts": "1742377122302", "checksum": -8227673, "seqId": 49713535740, "prevSeqId": 49713535706}], "record_time": 1742377123.160486}
{"arg": {"channel": "books", "instId": "BTC-USDT"}, "action": "update", "data": [{"asks": [["83556.4", "0", "0", "0"], ["83556.5", "0.00917", "0", "3"], ["83656.5", "0.0002003", "0", "1"]], "bids": [], "ts": "1742377122402", "checksum": -1653708537, "seqId": 49713535751, "prevSeqId": 49713535740}], "record_time": 1742377123.261463}
{"arg": {"channel": "books", "instId": "BTC-USDT"}, "action": "update", "data": [{"asks": [["83553.8", "0.1", "0", "1"], ["83556.3", "0.0001", "0", "1"], ["83556.5", "0.00907", "0", "2"], ["83656.5", "0", "0", "0"]], "bids": [["83546.9", "0.0001", "0", "1"], ["83546.7", "0.00777902", "0", "1"], ["83546.5", "0.0001", "0", "1"], ["83393", "0", "0", "0"], ["83392.9", "0", "0", "0"]], "ts": "1742377122502", "checksum": 965876281, "seqId": 49713535769, "prevSeqId": 49713535751}], "record_time": 1742377123.361517}
{"arg": {"channel": "books", "instId": "BTC-USDT"}, "action": "update", "data": [{"asks": [["83556.3", "0.0002", "0", "2"], ["83556.5", "0.00897", "0", "1"], ["83560.9", "0", "0", "0"], ["83562.7", "0.23938708", "0", "1"]], "bids": [["83546.9", "0.0002", "0", "2"], ["83546.5", "0", "0", "0"], ["83545.6", "0.12052955", "0", "2"], ["83545.2", "0.2025", "0", "1"], ["83504.7", "0.23938708", "0", "1"], ["83503.7", "0", "0", "0"]], "ts": "1742377122602", "checksum": 1545763732, "seqId": 49713535790, "prevSeqId": 49713535769}], "record_time": 1742377123.460662}
{"arg": {"channel": "books", "instId": "BTC-USDT"}, "action": "update", "data": [{"asks": [["83553.7", "1.88272345", "0", "26"], ["83556.3", "0", "0", "0"], ["83556.5", "0.00917", "0", "3"], ["83656.5", "0.0002003", "0", "1"]], "bids": [["83551", "0.05500345", "0", "1"], ["83546.9", "0", "0", "0"], ["83546.8", "0.0001", "0", "1"], ["83546.7", "0.00787902", "0", "2"], ["83545.6", "0.06831948", "0", "1"], ["83545.5", "0", "0", "0"]], "ts": "1742377122702", "checksum": -1387050155, "seqId": 49713535819, "prevSeqId": 49713535790}], "record_time": 1742377123.562252}
{"arg": {"channel": "books", "instId": "BTC-USDT"}, "action": "update", "data": [{"asks": [["83556.4", "0.0001", "0", "1"], ["83556.5", "0.00907", "0", "2"], ["83656.5", "0", "0", "0"]], "bids": [["83546.8", "0.0002", "0", "2"], ["83546.7", "0.00777902", "0", "1"], ["83518", "1", "0", "1"], ["83511", "0.2", "0", "1"], ["83393.4", "0", "0", "0"], ["83393.1", "0", "0", "0"]], "ts": "1742377122802", "checksum": -1564441622, "seqId": 49713535847, "prevSeqId": 49713535819}], "record_time": 1742377123.661744}
{"arg": {"channel": "books", "instId": "BTC-USDT"}, "action": "update", "data": [{"asks": [["83556.4", "0.0002", "0", "2"], ["83556.5", "0.00897", "0", "1"]], "bids": [["83546.8", "0.0001", "0", "1"], ["83546.7", "0.00787902", "0", "2"], ["83545.6", "0.13275529", "0", "2"], ["83543.3", "0.17953", "0", "1"], ["83535", "0", "0", "0"], ["83531.7", "0.35972754", "0", "1"], ["83518.5", "0.01219896", "0", "1"], ["83518", "0", "0", "0"], ["83516.9", "0", "0", "0"], ["83511", "0", "0", "0"], ["83393.4", "0.00001205", "0", "1"], ["83393.1", "0.00001731", "0", "1"]], "ts": "1742377122902", "checksum": 519565483, "seqId": 49713535872, "prevSeqId": 49713535847}], "record_time": 1742377123.760914}
{"arg": {"channel": "books", "instId": "BTC-USDT"}, "action": "update", "data": [{"asks": [["83553.7", "1.87174411", "0", "25"], ["83556.4", "0", "0", "0"], ["83556.5", "0.00917", "0", "3"], ["83561.5", "0.01097934", "0", "1"]], "bids": [["83546.8", "0.0002", "0", "2"], ["83546.7", "0.00777902", "0", "1"]], "ts": "1742377123002", "checksum": 642207772, "seqId": 49713535893, "prevSeqId": 49713535872}], "record_time": 1742377123.860275}
{"arg": {"channel": "books", "instId": "BTC-USDT"}, "action": "update", "data": [{"asks": [["83553.7", "1.88272345", "0", "26"], ["83556.4", "0.0002", "0", "2"], ["83556.5", "0.00897", "0", "1"], ["83561.5", "0", "0", "0"], ["83581", "1", "0", "1"], ["83585", "0.2", "0", "1"], ["83656.3", "0", "0", "0"], ["83656.4", "0", "0", "0"]], "bids": [["83551", "0", "0", "0"], ["83546.8", "0", "0", "0"], ["83546.7", "0.00787902", "0", "2"], ["83546.6", "0.0001", "0", "1"], ["83545.6", "0.16975294", "0", "2"], ["83545.2", "0", "0", "0"], ["83543.7", "0.18704797", "0", "1"], ["83534.2", "0.35309946", "0", "3"], ["83518.5", "0", "0", "0"], ["83516.9", "0.01219896", "0", "1"], ["83393", "0.01489957", "0", "2"]], "ts": "1742377123102", "checksum": 1175635259, "seqId": 49713535928, "prevSeqId": 49713535893}], "record_time": 1742377123.960571}
{"arg": {"channel": "books", "instId": "BTC-USDT"}, "action": "update", "data": [{"asks": [["83556.4", "0", "0", "0"], ["83556.5", "0.00917", "0", "3"], ["83581", "0", "0", "0"], ["83585", "0", "0", "0"], ["83656.3", "0.01074264", "0", "3"], ["83656.4", "0.00599857", "0", "2"], ["83656.5", "0.0002003", "0", "1"]], "bids": [["83546.8", "0.0002", "0", "2"], ["83546.7", "0.00777902", "0", "1"], ["83546.6", "0", "0", "0"], ["83541.1", "0.35905", "0", "1"], ["83393", "0", "0", "0"]], "ts": "1742377123202", "checksum": 1428502007, "seqId": 49713535946, "prevSeqId": 49713535928}], "record_time": 1742377124.060748}
{"arg": {"channel": "books", "instId": "BTC-USDT"}, "action": "update", "data": [{"asks": [["83556.4", "0.0001", "0", "1"], ["83556.5", "0.00907", "0", "2"], ["83563.3", "0.31131039", "0", "1"], ["83564.9", "0", "0", "0"], ["83593.6", "0.248564", "0", "1"], ["83594.7", "0.47212", "0", "1"], ["83596.8", "0.58047602", "0", "2"]], "bids": [["83553.6", "0.51999781", "0", "8"], ["83546.8", "0", "0", "0"], ["83546.5", "0.0001", "0", "1"], ["83546.2", "0.0001", "0", "1"], ["83545.6", "0.10791343", "0", "1"], ["83544.8", "0.11969379", "0", "1"], ["83543.7", "0", "0", "0"], ["83538.6", "0.00001205", "0", "1"], ["83512.5", "0.00001501", "0", "1"], ["83512.4", "0", "0", "0"], ["83508", "0.18867351", "0", "2"], ["83483.1", "0", "0", "0"], ["83482.7", "0.871617", "0", "1"], ["83393", "0.01489957", "0", "2"]], "ts": "1742377123302", "checksum": 1310030180, "seqId": 49713535985, "prevSeqId": 49713535946}], "record_time": 1742377124.161105}
{"arg": {"channel": "books", "instId": "BTC-USDT"}, "action": "update", "data": [{"asks": [["83553.7", "1.88158144", "0", "26"], ["83556.3", "0.0001", "0", "1"], ["83556.5", "0.00897", "0", "1"], ["83559.1", "0.74446192", "0", "1"], ["83562.3", "1.55981524", "0", "1"], ["83580.2", "0.72813365", "0", "1"], ["83592", "2.86645917", "0", "3"], ["83628", "0.01220929", "0", "2"], ["83656.4", "0", "0", "0"], ["83656.5", "0", "0", "0"]], "bids": [["83553.6", "0.52037781", "0", "9"], ["83550.9", "0.05500411", "0", "1"], ["83546.8", "0.0001", "0", "1"], ["83546.6", "0.0001", "0", "1"], ["83546.5", "0", "0", "0"], ["83546.2", "0", "0", "0"], ["83516.9", "0", "0", "0"], ["83515", "1.57404439", "0", "1"], ["83485.3", "2.75713434", "0", "2"], ["83473.2", "0.01698628", "0", "2"], ["83393", "0", "0", "0"]], "ts": "1742377123402", "checksum": -549548429, "seqId": 49713536021, "prevSeqId": 49713535985}], "record_time": 1742377124.260788}
{"arg": {"channel": "books", "instId": "BTC-USDT"}, "action": "update", "data": [{"asks": [["83556.3", "0", "0", "0"], ["83556.4", "0.0002", "0", "2"], ["83656.4", "0.00599857", "0", "2"]], "bids": [["83547", "0.0001", "0", "1"], ["83546.9", "0.0001", "0", "1"], ["83546.8", "0", "0", "0"], ["83546.6", "0", "0", "0"], ["83538.6", "0.35906205", "0", "2"]], "ts": "1742377123502", "checksum": 1615464749, "seqId": 49713536052, "prevSeqId": 49713536021}], "record_time": 1742377124.360044}
{"arg": {"channel": "books", "instId": "BTC-USDT"}, "action": "update", "data": [{"asks": [["83558.1", "0.003591", "0", "1"], ["83656.4", "0", "0", "0"]], "bids": [], "ts": "1742377123602", "checksum": 620023851, "seqId": 49713536056, "prevSeqId": 49713536052}], "record_time": 1742377124.460457}
{"arg": {"channel": "books", "instId": "BTC-USDT"}, "action": "update", "data": [{"asks": [["83580.1", "0.01219896", "0", "1"], ["83628", "0.00001033", "0", "1"], ["83656.3", "0", "0", "0"]], "bids": [["83516.9", "0.01219896", "0", "1"], ["83473.2", "0.00478732", "0", "1"], ["83393.1", "0", "0", "0"]], "ts": "1742377123702", "checksum": 620023851, "seqId": 49713536061, "prevSeqId": 49713536056}], "record_time": 1742377124.560534}
{"arg": {"channel": "books", "instId": "BTC-USDT"}, "action": "update", "data": [{"asks": [["83553.7", "1.78704554", "0", "23"], ["83556.4", "0", "0", "0"], ["83556.5", "0.00917", "0", "3"], ["83562.7", "0", "0", "0"], ["83566.5", "0.23938472", "0", "1"], ["83656.3", "0.01074264", "0", "3"]], "bids": [["83550.3", "0.0002", "0", "2"], ["83547", "0", "0", "0"], ["83546.9", "0", "0", "0"], ["83505.7", "0.23938472", "0", "1"], ["83504.7", "0", "0", "0"], ["83393.1", "0.00001731", "0", "1"]], "ts": "1742377123802", "checksum": -1823194473, "seqId": 49713536085, "prevSeqId": 49713536061}], "record_time": 1742377124.660855}
{"arg": {"channel": "books", "instId": "BTC-USDT"}, "action": "update", "data": [{"asks": [["83553.7", "1.85004554", "0", "25"], ["83563.9", "0.23938594", "0", "1"], ["83566.5", "0", "0", "0"]], "bids": [["83518", "1", "0", "1"], ["83510", "0.06373443", "0", "1"], ["83393.4", "0", "0", "0"], ["83393.1", "0", "0", "0"]], "ts": "1742377123902", "checksum": -493576908, "seqId": 49713536103, "prevSeqId": 49713536085}], "record_time": 1742377124.760404}
{"arg": {"channel": "books", "instId": "BTC-USDT"}, "action": "update", "data": [{"asks": [["83624.8", "0.07174907", "0", "1"]], "bids": [["83518.5", "0.01219896", "0", "1"], ["83516.9", "0", "0", "0"], ["83510", "0", "0", "0"], ["83460.9", "0.07188992", "0", "1"], ["83393.4", "0.00001205", "0", "1"]], "ts": "1742377124002", "checksum": -493576908, "seqId": 49713536116, "prevSeqId": 49713536103}], "record_time": 1742377124.860156}
{"arg": {"channel": "books", "instId": "BTC-USDT"}, "action": "update", "data": [{"asks": [["83553.9", "0.24882828", "0", "2"], ["83558.1", "0", "0", "0"], ["83560.9", "0.23938954", "0", "1"], ["83563.9", "0", "0", "0"], ["83570.3", "0.12324837", "0", "2"], ["83624.8", "0", "0", "0"], ["83656.4", "0.00599857", "0", "2"], ["83656.5", "0.0002003", "0", "1"]], "bids": [["83531.8", "0", "0", "0"], ["83505.7", "0", "0", "0"], ["83503.7", "0.23938954", "0", "1"], ["83492.3", "0.01843277", "0", "1"], ["83491.9", "0", "0", "0"], ["83460.9", "0", "0", "0"], ["83393.1", "0.00001731", "0", "1"], ["83393", "0.01489957", "0", "2"]], "ts": "1742377124102", "checksum": -1153410982, "seqId": 49713536145, "prevSeqId": 49713536116}], "record_time": 1742377124.960954}
{"arg": {"channel": "books", "instId": "BTC-USDT"}, "action": "update", "data": [{"asks": [["83553.9", "0.25122194", "0", "3"], ["83556.4", "0.0002", "0", "2"], ["83556.5", "0.00897", "0", "1"], ["83560.9", "0", "0", "0"], ["83562.2", "0.23938729", "0", "1"], ["83578", "0.1", "0", "1"], ["83581", "1", "0", "1"], ["83624.8", "0.14349814", "0", "2"], ["83656.2", "0", "0", "0"], ["83656.3", "0", "0", "0"], ["83656.4", "0", "0", "0"], ["83656.5", "0", "0", "0"]], "bids": [["83535", "0.17953", "0", "1"], ["83531.8", "0.00239429", "0", "1"], ["83508", "0.10186506", "0", "1"], ["83504.7", "0.23938729", "0", "1"], ["83503.7", "0", "0", "0"], ["83460.9", "0.14377984", "0", "2"], ["83393.4", "0", "0", "0"], ["83393.1", "0", "0", "0"], ["83393", "0", "0", "0"]], "ts": "1742377124202", "checksum": -881820549, "seqId": 49713536178, "prevSeqId": 49713536145}], "record_time": 1742377125.060653}
{"arg": {"channel": "books", "instId": "BTC-USDT"}, "action": "update", "data": [{"asks": [["83553.8", "0.103591", "0", "2"], ["83562.2", "0", "0", "0"], ["83566.5", "0.23938455", "0", "1"], ["83570.3", "0.11965737", "0", "1"], ["83589.9", "1.25874428", "0", "1"]], "bids": [["83535", "0", "0", "0"], ["83520.7", "0.44334054", "0", "2"], ["83504.7", "0.23938546", "0", "1"], ["83487.5", "0.88642311", "0", "2"], ["83393.4", "0.00001205", "0", "1"]], "ts": "1742377124302", "checksum": -160467353, "seqId": 49713536213, "prevSeqId": 49713536178}], "record_time": 1742377125.160451}
{"arg": {"channel": "books", "instId": "BTC-USDT"}, "action": "update", "data": [{"asks": [["83562.2", "0.23938785", "0", "1"], ["83566.5", "0", "0", "0"]], "bids": [["83504.7", "0", "0", "0"], ["83503.7", "0.23938845", "0", "1"]], "ts": "1742377124402", "checksum": 89334625, "seqId": 49713536229, "prevSeqId": 49713536213}], "record_time": 1742377125.264114}
{"arg": {"channel": "books", "instId": "BTC-USDT"}, "action": "update", "data": [{"asks": [["83552.3", "1.81020594", "0", "17"], ["83553.3", "0.23940407", "0", "1"], ["83553.4", "0.1", "0", "1"], ["83553.5", "1.43708736", "0", "2"], ["83553.6", "0.42", "0", "1"], ["83553.7", "0.65479608", "0", "5"], ["83553.8", "0", "0", "0"], ["83553.9", "0.00239366", "0", "1"], ["83554", "0.42", "0", "1"], ["83554.4", "0", "0", "0"], ["83555.9", "0.01977956", "0", "2"], ["83556.4", "0.0001", "0", "1"], ["83556.5", "0.08991011", "0", "1"], ["83556.8", "0.02692", "0", "1"], ["83558.3", "0.00787928", "0", "2"], ["83558.9", "0.0538607", "0", "1"], ["83559", "0.17953568", "0", "1"], ["83560", "0.02921362", "0", "1"], ["83561.2", "0", "0", "0"], ["83562.2", "0", "0", "0"], ["83562.8", "0", "0", "0"], ["83564.2", "0.03", "0", "1"], ["83566.6", "0", "0", "0"], ["83567.7", "0", "0", "0"], ["83568", "0", "0", "0"], ["83568.5", "0", "0", "0"], ["83574.7", "0", "0", "0"], ["83575.4", "0", "0", "0"], ["83575.5", "0", "0", "0"], ["83576.5", "0", "0", "0"], ["83580.9", "0.15207424", "0", "2"], ["83581.3", "0", "0", "0"], ["83582.5", "0", "0", "0"], ["83583.4", "0", "0", "0"], ["83584.6", "0", "0", "0"], ["83585.2", "0", "0", "0"], ["83591.2", "0.09872442", "0", "3"], ["83592", "2.82645916", "0", "2"], ["83592.8", "0", "0", "0"], ["83601.8", "0.15207424", "0", "2"], ["83656.2", "0.00002037", "0", "2"], ["83656.3", "0.01074264", "0", "3"], ["83656.4", "0.00599857", "0", "2"], ["83656.5", "0.0002003", "0", "1"], ["83656.6", "0.00012", "0", "1"], ["83656.8", "0.02178805", "0", "6"], ["83657", "0.04306939", "0", "4"], ["83657.1", "0.04397404", "0", "7"], ["83657.2", "0.00014", "0", "1"], ["83657.4", "0.00005997", "0", "1"], ["83657.8", "0.00074148", "0", "1"]], "bids": [["83553.6", "0", "0", "0"], ["83552", "0", "0", "0"], ["83550.9", "0", "0", "0"], ["83550.3", "0.0001", "0", "1"], ["83550.2", "0.0001", "0", "1"], ["83548.1", "0", "0", "0"], ["83548", "0", "0", "0"], ["83545.7", "0", "0", "0"], ["83545.6", "0", "0", "0"], ["83544.9", "0.4887538", "0", "3"], ["83543.4", "0.13877753", "0", "1"], ["83543.3", "0", "0", "0"], ["83542.3", "0.00120954", "0", "1"], ["83541.2", "0", "0", "0"], ["83541.1", "0", "0", "0"], ["83540.7", "0", "0", "0"], ["83539.7", "0.22922139", "0", "1"], ["83539.3", "0", "0", "0"], ["83539.2", "0.15207424", "0", "2"], ["83538.6", "0.00001205", "0", "1"], ["83538.4", "0", "0", "0"], ["83534.2", "0.1900928", "0", "1"], ["83532.7", "0", "0", "0"], ["83532", "0.01596", "0", "1"], ["83531", "0.213", "0", "4"], ["83530.8", "0.00718298", "0", "1"], ["83527.8", "0", "0", "0"], ["83527.2", "0", "0", "0"], ["83526", "0", "0", "0"], ["83525", "0.01596", "0", "1"], ["83523.9", "0", "0", "0"], ["83522.2", "0.00380435", "0", "1"], ["83521.9", "0", "0", "0"], ["83518.3", "0", "0", "0"], ["83518", "0", "0", "0"], ["83503.7", "0", "0", "0"], ["83497.7", "0.23940407", "0", "1"], ["83497.4", "0", "0", "0"], ["83393.1", "0.00001731", "0", "1"], ["83393", "0.01489957", "0", "2"], ["83392.9", "0.0429", "0", "3"], ["83392.8", "0.0286", "0", "2"], ["83391.6", "0.2025", "0", "1"], ["83391", "0.10497659", "0", "2"], ["83390.9", "0.00427658", "0", "1"], ["83390.5", "0.01316", "0", "1"], ["83390", "0.0000721", "0", "1"], ["83389.5", "0.03", "0", "1"], ["83389.3", "0.0000913", "0", "1"], ["83388.8", "0.35972754", "0", "1"], ["83388.7", "0.17953568", "0", "1"], ["83388.6", "0.11992025", "0", "1"], ["83388.4", "0.00001501", "0", "1"], ["83387.2", "0.00062604", "0", "1"], ["83386.5", "0.01797732", "0", "1"]], "ts": "1742377124502", "checksum": 754975060, "seqId": 49713536409, "prevSeqId": 49713536229}], "record_time": 1742377125.366745}
{"arg": {"channel": "books", "instId": "BTC-USDT"}, "action": "update", "data": [{"asks": [["83548.1", "1.90409158", "0", "17"], ["83550", "0.0002", "0", "2"], ["83551.7", "0.60343158", "0", "1"], ["83552", "0.001795", "0", "1"], ["83552.2", "0.42", "0", "1"], ["83552.3", "0.72417503", "0", "5"], ["83553.3", "0", "0", "0"], ["83553.4", "0", "0", "0"], ["83553.5", "0.35972754", "0", "1"], ["83553.7", "0.23479608", "0", "4"], ["83554", "0", "0", "0"], ["83556.4", "0.09396452", "0", "1"], ["83558.3", "0.00777928", "0", "1"], ["83558.5", "0.00001205", "0", "1"], ["83558.9", "0", "0", "0"], ["83559.1", "0.53731387", "0", "1"], ["83559.9", "0.09582887", "0", "1"], ["83560.9", "0.23939627", "0", "1"], ["83561.3", "0.09823637", "0", "1"], ["83561.6", "0.18403283", "0", "2"], ["83563.3", "0.22846103", "0", "1"], ["83566.6", "0.00060612", "0", "1"], ["83567.9", "0.34761545", "0", "2"], ["83568.3", "0.15878413", "0", "1"], ["83568.5", "0.0071856", "0", "1"], ["83568.6", "0.15335736", "0", "2"], ["83568.7", "0.16599766", "0", "1"], ["83570.1", "0.36855195", "0", "2"], ["83571.7", "0.3110314", "0", "3"], ["83574.1", "0", "0", "0"], ["83574.9", "0.24227745", "0", "1"], ["83575.6", "0.25190357", "0", "1"], ["83576.4", "0.27295988", "0", "2"], ["83576.7", "0.24956024", "0", "1"], ["83578.8", "0.25761497", "0", "1"], ["83584.5", "0.08936016", "0", "1"], ["83589.6", "0.13987175", "0", "3"], ["83590.4", "0.03999999", "0", "1"], ["83591.2", "0.01872442", "0", "1"], ["83592", "2.78645917", "0", "1"], ["83598", "0", "0", "0"], ["83626.4", "0.25146621", "0", "3"], ["83627.1", "0.0604498", "0", "2"], ["83655.2", "0", "0", "0"], ["83656.1", "0", "0", "0"], ["83656.2", "0", "0", "0"], ["83656.3", "0", "0", "0"], ["83656.4", "0", "0", "0"], ["83656.5", "0", "0", "0"], ["83656.6", "0", "0", "0"], ["83656.8", "0", "0", "0"], ["83657", "0", "0", "0"], ["83657.1", "0", "0", "0"], ["83657.2", "0", "0", "0"], ["83657.4", "0", "0", "0"], ["83657.8", "0", "0", "0"]], "bids": [["83552.2", "0", "0", "0"], ["83551.9", "0", "0", "0"], ["83551.8", "0", "0", "0"], ["83550.3", "0", "0", "0"], ["83550.2", "0", "0", "0"], ["83549.9", "0", "0", "0"], ["83548.6", "0", "0", "0"], ["83548", "0.1117", "0", "2"], ["83546.7", "0", "0", "0"], ["83546", "0.0567", "0", "1"], ["83545.9", "0", "0", "0"], ["83544.9", "0.05768842", "0", "2"], ["83544.8", "0", "0", "0"], ["83544.2", "0.0001", "0", "1"], ["83544.1", "0.00787995", "0", "2"], ["83543.4", "0", "0", "0"], ["83542.7", "0.11969679", "0", "1"], ["83542", "0.31379954", "0", "1"], ["83541.8", "0.01", "0", "2"], ["83538.5", "0.02490976", "0", "1"], ["83536.8", "0.00777995", "0", "1"], ["83534.3", "0.09772798", "0", "1"], ["83534", "0.0914705", "0", "1"], ["83533.3", "0.09206487", "0", "3"], ["83532.9", "0.09694537", "0", "1"], ["83532.8", "0.3165307", "0", "1"], ["83531.1", "0.06054675", "0", "2"], ["83530.8", "0", "0", "0"], ["83529.3", "0.23532782", "0", "1"], ["83527.3", "0.16392919", "0", "1"], ["83526.3", "0.15138984", "0", "1"], ["83525.3", "0.15308621", "0", "1"], ["83524.8", "0.30889328", "0", "1"], ["83524.6", "0.15815354", "0", "1"], ["83520.7", "0.26147001", "0", "2"], ["83520.3", "0.23576382", "0", "1"], ["83519.6", "0.26133262", "0", "1"], ["83518.5", "0", "0", "0"], ["83517.2", "0.24082916", "0", "1"], ["83516.9", "0.01219896", "0", "1"], ["83515.8", "0.25492762", "0", "1"], ["83512.1", "0.22973427", "0", "1"], ["83505.6", "0", "0", "0"], ["83504.2", "0.100015", "0", "2"], ["83502", "0.23939627", "0", "1"], ["83497.7", "0", "0", "0"], ["83497.6", "0.002513", "0", "1"], ["83497.5", "0", "0", "0"], ["83496.8", "0.08", "0", "2"], ["83496.4", "0", "0", "0"], ["83496", "0.15179806", "0", "5"], ["83495.2", "0.076", "0", "3"], ["83492.2", "0.00023954", "0", "1"], ["83491.9", "0.00198603", "0", "1"], ["83488.1", "0", "0", "0"], ["83488", "0.01016453", "0", "2"], ["83483", "0.00198273", "0", "1"], ["83482.8", "0.5643656", "0", "1"], ["83480.1", "0.25135", "0", "1"], ["83468.3", "0", "0", "0"], ["83464.9", "0", "0", "0"], ["83445", "0.1851011", "0", "1"], ["83389.3", "0", "0", "0"], ["83388.8", "0", "0", "0"], ["83388.7", "0", "0", "0"], ["83388.6", "0", "0", "0"], ["83388.4", "0", "0", "0"], ["83387.2", "0", "0", "0"], ["83386.5", "0", "0", "0"]], "ts": "1742377124602", "checksum": 1929158143, "seqId": 49713536967, "prevSeqId": 49713536409}], "record_time": 1742377125.46071}
{"arg": {"channel": "books", "instId": "BTC-USDT"}, "action": "update", "data": [{"asks": [["83548.1", "1.37329391", "0", "16"], ["83550", "0", "0", "0"], ["83550.4", "0.0001", "0", "1"], ["83550.9", "0.0001", "0", "1"], ["83552.3", "0.71520503", "0", "4"], ["83553.5", "0", "0", "0"], ["83553.7", "0.23415751", "0", "3"], ["83559.9", "0", "0", "0"], ["83560.3", "0.09571407", "0", "1"], ["83561.3", "0", "0", "0"], ["83561.6", "0", "0", "0"], ["83561.7", "0.10126427", "0", "1"], ["83561.9", "0.1794525", "0", "2"], ["83567.9", "0.3397915", "0", "2"], ["83568.3", "0", "0", "0"], ["83568.6", "0.14783169", "0", "2"], ["83568.7", "0", "0", "0"], ["83568.9", "0.15707996", "0", "1"], ["83569", "0.16667865", "0", "1"], ["83570.1", "0.2025", "0", "1"], ["83570.4", "0.18422118", "0", "3"], ["83571.7", "0.19192881", "0", "2"], ["83574.9", "0", "0", "0"], ["83575.2", "0.24672345", "0", "1"], ["83575.6", "0", "0", "0"], ["83575.9", "0.26717163", "0", "2"], ["83576.4", "0.24313471", "0", "2"], ["83576.7", "0", "0", "0"], ["83577.1", "0.23854003", "0", "1"], ["83578", "0", "0", "0"], ["83578.8", "0", "0", "0"], ["83579.2", "0.25302818", "0", "1"], ["83580.2", "0.51236653", "0", "1"], ["83581", "0", "0", "0"], ["83586.3", "0.35907", "0", "1"], ["83655.2", "0.00597", "0", "1"], ["83656.1", "0.00007092", "0", "1"]], "bids": [["83548", "0.15049227", "0", "3"], ["83546.4", "0.0001", "0", "1"], ["83545.6", "0.0001", "0", "1"], ["83544.2", "0", "0", "0"], ["83544.1", "0.00777995", "0", "1"], ["83534.6", "0.09212364", "0", "1"], ["83534.4", "0.15645448", "0", "2"], ["83534.3", "0", "0", "0"], ["83534", "0", "0", "0"], ["83533.7", "0.09352909", "0", "1"], ["83533.3", "0.00101501", "0", "2"], ["83533.2", "0.09403097", "0", "1"], ["83532.9", "0", "0", "0"], ["83529.3", "0.34909551", "0", "2"], ["83527.6", "0.1475096", "0", "1"], ["83527.3", "0", "0", "0"], ["83526.6", "0.16192901", "0", "1"], ["83526.3", "0", "0", "0"], ["83525.6", "0.18862922", "0", "3"], ["83525.3", "0", "0", "0"], ["83524.9", "0.15248826", "0", "1"], ["83524.6", "0", "0", "0"], ["83520.7", "0.34112905", "0", "2"], ["83520.6", "0.48102516", "0", "4"], ["83520.3", "0", "0", "0"], ["83519.9", "0.29613208", "0", "3"], ["83519.6", "0", "0", "0"], ["83517.6", "0.26754711", "0", "1"], ["83517.2", "0", "0", "0"], ["83516.2", "0.24054572", "0", "1"], ["83515.8", "0", "0", "0"], ["83513.5", "0.93994605", "0", "3"], ["83504.2", "0.000015", "0", "1"], ["83495.5", "0.00002637", "0", "1"], ["83491.3", "0.00612536", "0", "2"], ["83487.1", "0.00002637", "0", "1"], ["83466.7", "0.00274762", "0", "1"], ["83389.5", "0", "0", "0"]], "ts": "1742377124702", "checksum": -149191071, "seqId": 49713537092, "prevSeqId": 49713536967}], "record_time": 1742377125.56145}
{"arg": {"channel": "books", "instId": "BTC-USDT"}, "action": "update", "data": [{"asks": [["83548.1", "1.79393996", "0", "18"], ["83550.4", "0", "0", "0"], ["83550.8", "0.0001", "0", "1"], ["83551.7", "0.16086652", "0", "1"], ["83552.3", "0.29520503", "0", "3"], ["83553.6", "0", "0", "0"], ["83555.8", "0.012", "0", "1"], ["83555.9", "0.00777956", "0", "1"], ["83556.4", "0.15401275", "0", "2"], ["83558.9", "0.23940061", "0", "1"], ["83560.2", "0.09359427", "0", "1"], ["83560.3", "0", "0", "0"], ["83560.9", "0", "0", "0"], ["83561.7", "0.10088119", "0", "1"], ["83561.8", "0.08786276", "0", "1"], ["83561.9", "0", "0", "0"], ["83562", "0.09578265", "0", "3"], ["83567.9", "0.34011472", "0", "2"], ["83568.6", "0.16698094", "0", "2"], ["83568.8", "0.14965093", "0", "1"], ["83568.9", "0", "0", "0"], ["83569", "0.14777114", "0", "1"], ["83570.4", "0.19248588", "0", "3"], ["83571.7", "0.31485277", "0", "3"], ["83575.2", "0", "0", "0"], ["83575.3", "0.24505086", "0", "1"], ["83575.8", "0.26186805", "0", "1"], ["83575.9", "0.0005145", "0", "1"], ["83576.4", "0.25376498", "0", "2"], ["83577", "0.4532689", "0", "2"], ["83577.1", "0", "0", "0"], ["83579.2", "0.26382635", "0", "1"], ["83580.1", "0", "0", "0"], ["83584.5", "0.22673426", "0", "2"], ["83589.5", "0.01219896", "0", "1"], ["83592.4", "0.1", "0", "1"], ["83613.8", "0.00013267", "0", "1"], ["83619.3", "0", "0", "0"], ["83656.1", "0", "0", "0"]], "bids": [["83548", "0.1301", "0", "2"], ["83546.7", "0.0001", "0", "1"], ["83546.4", "0", "0", "0"], ["83546.3", "0.0001", "0", "1"], ["83546.1", "0.17459209", "0", "3"], ["83545.6", "0", "0", "0"], ["83544.9", "0", "0", "0"], ["83543", "0", "0", "0"], ["83542.2", "0.42", "0", "1"], ["83538.5", "0", "0", "0"], ["83534.6", "0", "0", "0"], ["83534.5", "0.30208418", "0", "3"], ["83534.4", "0.066", "0", "1"], ["83534.3", "0.10139969", "0", "1"], ["83533.7", "0.09487087", "0", "1"], ["83533.5", "0", "0", "0"], ["83533.3", "0.09852922", "0", "3"], ["83533.2", "0", "0", "0"], ["83529.3", "0.34372167", "0", "2"], ["83527.6", "0", "0", "0"], ["83527.5", "0.1468752", "0", "1"], ["83526.6", "0.15728298", "0", "1"], ["83525.6", "0.17599686", "0", "3"], ["83524.9", "0.16186963", "0", "1"], ["83520.7", "0.26664982", "0", "2"], ["83520.6", "0.23149302", "0", "3"], ["83520.5", "0.25460638", "0", "1"], ["83520", "0.26383887", "0", "4"], ["83519.9", "0.05195734", "0", "2"], ["83517.6", "0", "0", "0"], ["83517.5", "0.25838351", "0", "1"], ["83516.2", "0.26150155", "0", "1"], ["83502", "0", "0", "0"], ["83500.6", "0.23940061", "0", "1"], ["83500", "0.21039676", "0", "9"], ["83389.5", "0.03", "0", "1"], ["83389.3", "0.0000913", "0", "1"], ["83388.8", "0.35972754", "0", "1"]], "ts": "1742377124802", "checksum": 1873226001, "seqId": 49713537215, "prevSeqId": 49713537092}], "record_time": 1742377125.660468}
{"arg": {"channel": "books", "instId": "BTC-USDT"}, "action": "update", "data": [{"asks": [["83548.1", "0.96665133", "0", "16"], ["83550.8", "0", "0", "0"], ["83550.9", "0", "0", "0"], ["83551.1", "0.0001", "0", "1"], ["83551.7", "0.29164935", "0", "2"], ["83552.3", "0.05204266", "0", "2"], ["83553.3", "0.0001", "0", "1"], ["83556.2", "0.16575776", "0", "1"], ["83556.3", "0.23939873", "0", "1"], ["83556.4", "0", "0", "0"], ["83558.9", "0", "0", "0"], ["83560", "0.20875362", "0", "2"], ["83560.2", "0", "0", "0"], ["83560.6", "0.09554704", "0", "1"], ["83561.7", "0", "0", "0"], ["83561.8", "0.09022234", "0", "1"], ["83562", "0.004", "0", "2"], ["83562.1", "0.09822451", "0", "2"], ["83562.4", "0.08869139", "0", "2"], ["83564.2", "0.20954", "0", "2"], ["83567.9", "0.34829293", "0", "2"], ["83568.6", "0.00001205", "0", "1"], ["83568.8", "0.16096616", "0", "1"], ["83569", "0", "0", "0"], ["83569.3", "0.16450105", "0", "1"], ["83569.4", "0.15584597", "0", "1"], ["83570.4", "0.03693196", "0", "2"], ["83570.6", "0.16589238", "0", "1"], ["83571.7", "0.19192881", "0", "2"], ["83575.3", "0", "0", "0"], ["83575.4", "0.25103845", "0", "1"], ["83575.8", "0", "0", "0"], ["83576.2", "0.32145544", "0", "2"], ["83576.4", "0.24579748", "0", "1"], ["83577", "0.1900928", "0", "1"], ["83577.4", "0.2636239", "0", "1"], ["83579.2", "0", "0", "0"], ["83579.3", "0.24040073", "0", "1"], ["83655.1", "0", "0", "0"], ["83655.2", "0", "0", "0"]], "bids": [["83548", "0.169", "0", "3"], ["83546.6", "0.0001", "0", "1"], ["83546.3", "0", "0", "0"], ["83539.2", "0.33161424", "0", "3"], ["83537.6", "0.28161961", "0", "2"], ["83535.1", "0.09997835", "0", "1"], ["83535", "0.17954", "0", "1"], ["83534.7", "0.12979189", "0", "2"], ["83534.5", "0.208393", "0", "2"], ["83534.3", "0", "0", "0"], ["83533.8", "0.09466394", "0", "1"], ["83533.7", "0", "0", "0"], ["83533.4", "0.09776934", "0", "1"], ["83533.3", "0.00101501", "0", "2"], ["83529.3", "0.35584969", "0", "2"], ["83528.1", "0.15663541", "0", "1"], ["83527.5", "0", "0", "0"], ["83527.1", "0.01596", "0", "1"], ["83526.8", "0.16049962", "0", "1"], ["83526.6", "0", "0", "0"], ["83525.9", "0.1666978", "0", "1"], ["83525.6", "0.02078895", "0", "2"], ["83525.1", "0.15133972", "0", "1"], ["83525", "0", "0", "0"], ["83524.9", "0", "0", "0"], ["83521.2", "0.28755089", "0", "1"], ["83521.1", "0.2620867", "0", "2"], ["83520.7", "0", "0", "0"], ["83520.5", "0", "0", "0"], ["83520.1", "0.25489864", "0", "1"], ["83520", "0.00501", "0", "3"], ["83517.9", "0.25033241", "0", "1"], ["83517.5", "0", "0", "0"], ["83516.3", "0.24149312", "0", "1"], ["83516.2", "0", "0", "0"], ["83501.1", "0.23939873", "0", "1"], ["83500.6", "0", "0", "0"], ["83389.5", "0", "0", "0"], ["83389.3", "0", "0", "0"], ["83388.8", "0", "0", "0"]], "ts": "1742377124902", "checksum": 1108830699, "seqId": 49713537350, "prevSeqId": 49713537215}], "record_time": 1742377125.76142}
{"arg": {"channel": "books", "instId": "BTC-USDT"}, "action": "update", "data": [{"asks": [["83548.1", "1.05466923", "0", "17"], ["83552.3", "0.03604266", "0", "1"], ["83553.7", "0.21815751", "0", "2"]], "bids": [["83547", "0.0001", "0", "1"], ["83546.9", "0.0001", "0", "1"], ["83546.7", "0", "0", "0"], ["83546.6", "0", "0", "0"], ["83510", "0.06374837", "0", "1"], ["83452.8", "0", "0", "0"], ["83443.6", "0.0001189", "0", "1"], ["83390", "0", "0", "0"]], "ts": "1742377125002", "checksum": -1842307191, "seqId": 49713537369, "prevSeqId": 49713537350}], "record_time": 1742377125.868626}
{"arg": {"channel": "books", "instId": "BTC-USDT"}, "action": "update", "data": [{"asks": [["83551.1", "0", "0", "0"], ["83551.2", "0.0002", "0", "2"], ["83553.3", "0", "0", "0"], ["83581.5", "0", "0", "0"], ["83655.1", "0.00447503", "0", "2"], ["83655.2", "0.00597", "0", "1"]], "bids": [["83496.8", "0.18", "0", "4"], ["83496", "0.10179806", "0", "4"], ["83495.2", "0.026", "0", "2"]], "ts": "1742377125102", "checksum": -2093627673, "seqId": 49713537381, "prevSeqId": 49713537369}], "record_time": 1742377125.960337}
{"arg": {"channel": "books", "instId": "BTC-USDT"}, "action": "update", "data": [{"asks": [["83551.2", "0", "0", "0"], ["83552.7", "0.0002", "0", "2"], ["83553.5", "0.00354567", "0", "1"], ["83555.8", "0.18009554", "0", "2"], ["83555.9", "0.24718083", "0", "2"], ["83556.2", "0", "0", "0"], ["83556.3", "0", "0", "0"], ["83580.9", "0.24184424", "0", "3"], ["83601.8", "0.24184424", "0", "3"], ["83656.1", "0.00007092", "0", "1"]], "bids": [["83547", "0", "0", "0"], ["83546.6", "0.0001", "0", "1"], ["83531.1", "0.05987175", "0", "1"], ["83518.3", "0.08977", "0", "1"], ["83510", "0", "0", "0"], ["83501.1", "0", "0", "0"], ["83500.1", "0.33036718", "0", "1"], ["83499.5", "0.23940127", "0", "1"], ["83497.4", "0.08977", "0", "1"], ["83390.5", "0", "0", "0"]], "ts": "1742377125202", "checksum": -1989611017, "seqId": 49713537429, "prevSeqId": 49713537381}], "record_time": 1742377126.060256}
{"arg": {"channel": "books", "instId": "BTC-USDT"}, "action": "snapshot", "data": [{"asks": [["83474", "3.23077229", "0", "66"], ["83474.1", "0.11980645", "0", "2"], ["83474.2", "0.14804031", "0", "1"], ["83474.8", "0.00239593", "0", "1"], ["83475", "0.00171354", "0", "1"], ["83475.6", "0.0314628", "0", "1"], ["83475.7", "0.002", "0", "1"], ["83475.8", "0.00916", "0", "1"], ["83475.9", "0.23962712", "0", "1"], ["83476", "0.0567", "0", "1"], ["83476.9", "0.0002", "0", "2"], ["83477.7", "0.00598989", "0", "1"], ["83478", "0.14661011", "0", "2"], ["83479.4", "0.35939", "0", "1"], ["83479.6", "0.8834588", "0", "2"], ["83479.7", "0.04", "0", "1"], ["83479.9", "0.000033", "0", "1"], ["83480", "0.41646754", "0", "3"], ["83481", "0.132716", "0", "1"], ["83481.4", "0.35939", "0", "1"], ["83481.8", "0.18150381", "0", "2"], ["83481.9", "0.31025882", "0", "3"], ["83482", "0.0567", "0", "1"], ["83482.1", "0.02748", "0", "1"], ["83482.7", "1.57096624", "0", "1"], ["83482.9", "0.04", "0", "1"], ["83483.3", "0.00560612", "0", "2"], ["83483.4", "0.00001206", "0", "1"], ["83483.5", "0.16224935", "0", "1"], ["83483.7", "0.00916", "0", "1"], ["83484", "0.0567", "0", "1"], ["83484.2", "0.005", "0", "1"], ["83484.9", "0.10188862", "0", "2"], ["83485", "0.00426837", "0", "1"], ["83485.8", "0.06109124", "0", "2"], ["83486", "0.0567", "0", "1"], ["83486.8", "0.09402978", "0", "1"], ["83487", "0.15199316", "0", "2"], ["83487.7", "0.09427937", "0", "2"], ["83487.9", "0.08920944", "0", "1"], ["83488", "0.0567", "0", "1"], ["83488.2", "0.08873984", "0", "1"], ["83488.4", "0.00001206", "0", "1"], ["83488.8", "0.3742586", "0", "1"], ["83489.7", "0.00366233", "0", "1"], ["83490", "0.03", "0", "1"], ["83490.1", "0.03", "0", "1"], ["83490.2", "0.11973173", "0", "1"], ["83490.3", "0.2025", "0", "1"], ["83490.4", "0.03", "0", "1"], ["83490.7", "0.00884137", "0", "1"], ["83490.8", "0.35972754", "0", "1"], ["83490.9", "0.17953568", "0", "1"], ["83491.1", "0.02362006", "0", "1"], ["83491.8", "0.21851574", "0", "2"], ["83492.9", "0.02332", "0", "1"], ["83493.2", "0.00011142", "0", "1"], ["83493.3", "0.095", "0", "4"], ["83493.4", "0.00001206", "0", "1"], ["83494.2", "0.005", "0", "1"], ["83494.7", "0.1550273", "0", "1"], ["83494.9", "0.16139261", "0", "1"], ["83495.5", "0.16738103", "0", "2"], ["83495.9", "0.11976401", "0", "1"], ["83496", "0.000015", "0", "1"], ["83496.5", "0.47263097", "0", "1"], ["83496.6", "0.14720697", "0", "1"], ["83497.4", "0.15199316", "0", "2"], ["83497.7", "0.08991011", "0", "1"], ["83498", "0.0055", "0", "1"], ["83498.4", "0.00001206", "0", "1"], ["83498.6", "0.01219896", "0", "1"], ["83498.7", "0.580967", "0", "1"], ["83499.7", "0.5", "0", "1"], ["83499.8", "0.35972754", "0", "1"], ["83499.9", "0.18055069", "0", "3"], ["83500", "0.20279558", "0", "3"], ["83501.1", "0.51806255", "0", "1"], ["83501.2", "0.475323", "0", "1"], ["83501.5", "0.25499221", "0", "1"], ["83501.6", "0.02960533", "0", "1"], ["83501.7", "0.37845301", "0", "2"], ["83502", "0.59809338", "0", "3"], ["83502.1", "0.0602412", "0", "2"], ["83502.3", "0.18999146", "0", "1"], ["83503.2", "0.02395072", "0", "1"], ["83503.4", "0.00001206", "0", "1"], ["83503.5", "0.00367", "0", "1"], ["83503.6", "0.25238216", "0", "1"], ["83503.9", "0.25158", "0", "1"], ["83504.1", "0.0042666", "0", "1"], ["83504.3", "0.000015", "0", "1"], ["83504.4", "0.40444037", "0", "2"], ["83504.5", "0.18999146", "0", "1"], ["83504.9", "0.10922", "0", "1"], ["83505.4", "0.2628306", "0", "1"], ["83505.9", "0.000025", "0", "1"], ["83506.7", "0.01797", "0", "1"], ["83507.3", "0.53385", "0", "1"], ["83507.6", "0.11858075", "0", "1"], ["83507.8", "0.15199316", "0", "2"], ["83508.2", "0.01", "0", "1"], ["83508.4", "0.00001206", "0", "1"], ["83510", "0.000025", "0", "1"], ["83511", "1.29443759", "0", "1"], ["83511.1", "0.11973173", "0", "1"], ["83511.2", "0.575976", "0", "3"], ["83511.3", "0.35972754", "0", "1"], ["83511.6", "0.2025", "0", "1"], ["83511.9", "2.89004267", "0", "1"], ["83512", "0.03999999", "0", "1"], ["83512.1", "0.0042653", "0", "1"], ["83512.3", "0.18999146", "0", "1"], ["83512.5", "0.17953568", "0", "1"], ["83512.6", "0.00001501", "0", "1"], ["83512.8", "0.00011142", "0", "1"], ["83512.9", "0.00367", "0", "1"], ["83513.3", "0.000015", "0", "1"], ["83513.4", "0.00001206", "0", "1"], ["83514.2", "0.000025", "0", "1"], ["83514.7", "0.0055", "0", "1"], ["83515.2", "0.02715487", "0", "1"], ["83515.3", "0.08991011", "0", "1"], ["83516.6", "0.00060612", "0", "1"], ["83518.2", "0.1", "0", "1"], ["83518.3", "0.15199316", "0", "2"], ["83518.5", "0.00001206", "0", "1"], ["83519.5", "0.00426493", "0", "1"], ["83520", "0.00004", "0", "1"], ["83520.1", "0.2515", "0", "1"], ["83520.9", "0.00001501", "0", "1"], ["83521.4", "0.26297214", "0", "1"], ["83521.5", "0.17953568", "0", "1"], ["83521.7", "0.35972754", "0", "1"], ["83522.2", "0.2025", "0", "1"], ["83522.4", "0.02743036", "0", "1"], ["83523", "0.00001", "0", "1"], ["83523.5", "0.00001206", "0", "1"], ["83523.9", "0.11973173", "0", "1"], ["83525.9", "0.08323379", "0", "2"], ["83526", "0.05514", "0", "1"], ["83527.6", "0.01476", "0", "1"], ["83528", "0.05205602", "0", "2"], ["83528.5", "0.00001206", "0", "1"], ["83528.7", "0.15199316", "0", "2"], ["83529", "0.00426114", "0", "1"], ["83529.1", "0.01795842", "0", "1"], ["83529.2", "0.000015", "0", "1"], ["83531.2", "0.00013267", "0", "1"], ["83531.3", "0.03377451", "0", "2"], ["83531.4", "0.03", "0", "1"], ["83531.8", "0.35972754", "0", "1"], ["83532", "0.59247844", "0", "1"], ["83532.4", "0.00011142", "0", "1"], ["83532.8", "0.01197727", "0", "1"], ["83533.2", "0.01", "0", "1"], ["83533.3", "0.00504349", "0", "4"], ["83533.5", "0.00001206", "0", "1"], ["83533.6", "0.871087", "0", "1"], ["83534", "0.31973043", "0", "4"], ["83534.6", "0.12", "0", "4"], ["83534.8", "0.347462", "0", "1"], ["83534.9", "3.14824", "0", "1"], ["83536.3", "0.24178754", "0", "1"], ["83536.4", "0.2025", "0", "1"], ["83538.2", "0.00366", "0", "1"], ["83538.3", "0.04791219", "0", "1"], ["83538.5", "0.00001206", "0", "1"], ["83539.1", "0.15199316", "0", "2"], ["83540", "0.00004", "0", "1"], ["83540.2", "0.35972754", "0", "1"], ["83541.2", "0.02395978", "0", "1"], ["83542.4", "0.00426114", "0", "1"], ["83542.8", "0.29945593", "0", "2"], ["83543.5", "0.00001205", "0", "1"], ["83544.8", "1.215112", "0", "3"], ["83545.5", "0.0132", "0", "1"], ["83545.6", "0.14363414", "0", "2"], ["83546.1", "0.48567152", "0", "1"], ["83547.9", "0.00426114", "0", "1"], ["83548.3", "0.1", "0", "1"], ["83548.5", "0.00001206", "0", "1"], ["83548.9", "0.1", "0", "1"], ["83549.6", "0.07599658", "0", "1"], ["83549.9", "0.00060612", "0", "1"], ["83550.4", "0.35984814", "0", "2"], ["83550.8", "0.05984266", "0", "1"], ["83550.9", "0.32078228", "0", "1"], ["83551", "0.30455441", "0", "1"], ["83552.1", "0.00011142", "0", "1"], ["83553.1", "0.29945593", "0", "2"], ["83553.5", "0.00001206", "0", "1"], ["83553.7", "0.35964043", "0", "1"], ["83554.1", "0.1", "0", "1"], ["83554.4", "0.0055", "0", "1"], ["83554.9", "0.00001501", "0", "1"], ["83556.1", "0.003", "0", "1"], ["83556.2", "0.00589893", "0", "1"], ["83556.3", "0.00426114", "0", "1"], ["83556.7", "0.02607399", "0", "1"], ["83558.1", "0.198", "0", "1"], ["83558.4", "0.01464357", "0", "1"], ["83558.5", "0.00001206", "0", "1"], ["83559.3", "0.01179616", "0", "2"], ["83559.8", "0.02004994", "0", "2"], ["83559.9", "0.56222754", "0", "2"], ["83560", "0.02541154", "0", "2"], ["83562.1", "0.00589893", "0", "1"], ["83562.2", "0.01474447", "0", "2"], ["83562.4", "0.00122101", "0", "2"], ["83563", "0.07266955", "0", "2"], ["83563.6", "0.00001205", "0", "1"], ["83564", "0.00002", "0", "1"], ["83564.4", "0.00426154", "0", "1"], ["83566.6", "0.00101501", "0", "2"], ["83566.7", "0.17953568", "0", "1"], ["83566.9", "0.11992025", "0", "1"], ["83568.6", "0.00001205", "0", "1"], ["83570.7", "0.000015", "0", "1"], ["83571", "0.0000129", "0", "1"], ["83571.1", "0.01199783", "0", "2"], ["83571.2", "0.05395611", "0", "2"], ["83571.3", "0.03", "0", "1"], ["83571.4", "0.09060238", "0", "2"], ["83571.6", "0.0002405", "0", "1"], ["83571.7", "0.00011142", "0", "1"], ["83572.4", "0.06589893", "0", "3"], ["83572.7", "0.00298666", "0", "1"], ["83572.8", "0.39564356", "0", "2"], ["83573.6", "0.00001205", "0", "1"], ["83574.4", "0.06", "0", "2"], ["83575.1", "0.17953568", "0", "1"], ["83575.2", "0.2025", "0", "1"], ["83575.3", "0.00425925", "0", "1"], ["83575.5", "0.05802294", "0", "1"], ["83576.4", "0.0183989", "0", "2"], ["83576.6", "0.17432902", "0", "2"], ["83576.7", "0.0909904", "0", "1"], ["83576.9", "0.11992025", "0", "1"], ["83577", "0.07216343", "0", "1"], ["83578.1", "0.00589893", "0", "1"], ["83578.6", "0.00001205", "0", "1"], ["83579", "0.000015", "0", "1"], ["83580", "0.22043", "0", "1"], ["83580.5", "3.51879", "0", "1"], ["83581", "0.00597332", "0", "1"], ["83581.3", "0.35972754", "0", "1"], ["83582.8", "0.086", "0", "4"], ["83583.3", "0.0015477", "0", "3"], ["83583.6", "0.00001205", "0", "1"], ["83584.3", "0.17953568", "0", "1"], ["83584.5", "0.2025", "0", "1"], ["83584.9", "0.19526321", "0", "1"], ["83585.1", "0.0002632", "0", "1"], ["83587.2", "0.11992025", "0", "1"], ["83588", "1", "0", "1"], ["83588.2", "0.00425833", "0", "1"], ["83588.6", "0.00599781", "0", "2"], ["83589.4", "0.00895999", "0", "1"], ["83590", "0.07939163", "0", "1"], ["83591.3", "0.00609718", "0", "2"], ["83591.8", "0.35972754", "0", "1"], ["83593.3", "0.00009539", "0", "1"], ["83593.7", "0.00001204", "0", "1"], ["83593.8", "0.192879", "0", "1"], ["83594.1", "0.11962331", "0", "1"], ["83594.2", "0.00598576", "0", "1"], ["83594.4", "0.2025", "0", "1"], ["83594.7", "0.7", "0", "1"], ["83595.1", "0.00598576", "0", "1"], ["83595.2", "0.17953568", "0", "1"], ["83595.6", "0.00001501", "0", "1"], ["83596.4", "0.0102427", "0", "2"], ["83596.5", "0.00001501", "0", "1"], ["83596.7", "0.11992025", "0", "1"], ["83597.1", "0.00598643", "0", "1"], ["83597.7", "0.01194665", "0", "1"], ["83598.7", "0.00001204", "0", "1"], ["83599.1", "0.00598576", "0", "1"], ["83599.2", "0.00598608", "0", "1"], ["83599.9", "0.00504349", "0", "4"], ["83600", "0.00600725", "0", "5"], ["83600.3", "0.71384904", "0", "1"], ["83600.7", "0.57534954", "0", "2"], ["83602.2", "0.00104746", "0", "1"], ["83603.3", "0.00007342", "0", "1"], ["83603.7", "0.00001204", "0", "1"], ["83603.9", "0.17953568", "0", "1"], ["83604", "0.2025", "0", "1"], ["83605.1", "0.00425619", "0", "1"], ["83605.5", "0.11992025", "0", "1"], ["83606", "0.00021614", "0", "1"], ["83606.1", "0.01493332", "0", "1"], ["83607.7", "0.08991011", "0", "1"], ["83607.8", "0.0143", "0", "1"], ["83607.9", "0.0858", "0", "5"], ["83608.1", "0.0286", "0", "1"], ["83608.7", "0.00001204", "0", "1"], ["83609.3", "0.35972754", "0", "1"], ["83611", "0.00011142", "0", "1"], ["83611.1", "0.00204502", "0", "3"], ["83611.7", "0.00425574", "0", "1"], ["83612.1", "0.00001103", "0", "1"], ["83612.2", "0.00024501", "0", "3"], ["83612.3", "0.00027631", "0", "3"], ["83612.5", "0.00002335", "0", "1"], ["83612.6", "0.04468027", "0", "2"], ["83612.9", "0.0002493", "0", "2"], ["83613", "0.00318148", "0", "2"], ["83613.1", "0.00001007", "0", "1"], ["83613.2", "0.00002092", "0", "2"], ["83613.6", "0.20953568", "0", "2"], ["83613.7", "0.00002246", "0", "2"], ["83613.8", "0.03", "0", "1"], ["83613.9", "0.11992025", "0", "1"], ["83614.1", "0.0000105", "0", "1"], ["83614.2", "0.00011204", "0", "1"], ["83614.3", "0.00004772", "0", "2"], ["83614.5", "0.05387403", "0", "1"], ["83614.7", "0.00004811", "0", "1"], ["83614.8", "0.00088831", "0", "1"], ["83614.9", "0.00599008", "0", "1"], ["83615", "0.00001004", "0", "1"], ["83615.2", "0.03537288", "0", "3"], ["83615.3", "0.00050039", "0", "2"], ["83615.4", "0.00001009", "0", "1"], ["83615.5", "0.00241998", "0", "2"], ["83615.7", "0.00211734", "0", "2"], ["83616", "0.00001004", "0", "1"], ["83616.1", "0.00005004", "0", "2"], ["83616.5", "0.00001206", "0", "1"], ["83616.6", "0.00785243", "0", "5"], ["83616.8", "0.00009302", "0", "1"], ["83616.9", "0.0004148", "0", "3"], ["83617.1", "0.23251011", "0", "3"], ["83617.2", "0.03", "0", "1"], ["83617.5", "0.03715474", "0", "2"], ["83617.6", "0.00003256", "0", "1"], ["83618.1", "0.00700251", "0", "4"], ["83618.2", "0.0000951", "0", "1"], ["83618.6", "0.00425502", "0", "1"], ["83618.8", "0.00037987", "0", "2"], ["83618.9", "0.35972754", "0", "1"], ["83619", "0.01419169", "0", "3"], ["83619.1", "0.00719489", "0", "2"], ["83619.2", "0.00002324", "0", "1"], ["83619.5", "0.00488686", "0", "5"], ["83619.8", "0.00002668", "0", "1"], ["83619.9", "0.00018106", "0", "3"], ["83620", "0.00181427", "0", "5"], ["83620.1", "0.00041143", "0", "2"], ["83620.3", "0.0000665", "0", "1"], ["83620.4", "0.0039259", "0", "1"], ["83620.5", "0.00125371", "0", "1"], ["83620.6", "0.00003153", "0", "2"], ["83620.8", "0.00002253", "0", "1"], ["83621", "0.00024051", "0", "2"], ["83621.1", "0.01512856", "0", "2"], ["83621.2", "0.00006289", "0", "1"], ["83621.3", "0.00001186", "0", "1"], ["83621.5", "0.00006121", "0", "1"], ["83621.7", "0.01994695", "0", "2"], ["83622.1", "0.00002874", "0", "2"], ["83622.2", "0.00090335", "0", "2"], ["83622.4", "0.00002707", "0", "2"], ["83622.5", "0.12060156", "0", "2"], ["83622.7", "0.00001011", "0", "1"], ["83622.8", "0.00004182", "0", "2"], ["83622.9", "0.00010351", "0", "3"], ["83623", "0.00001097", "0", "1"], ["83623.1", "0.00015386", "0", "2"], ["83623.4", "0.17953568", "0", "1"], ["83623.6", "0.00035745", "0", "1"], ["83623.7", "0.00029822", "0", "6"], ["83623.8", "0.00001002", "0", "1"], ["83624.3", "0.00230564", "0", "1"], ["83624.5", "0.00012233", "0", "1"], ["83625", "0.00937173", "0", "14"], ["83625.1", "0.00011938", "0", "1"], ["83625.3", "0.00008", "0", "1"], ["83625.4", "0.00001004", "0", "1"], ["83625.5", "0.2025", "0", "1"], ["83625.7", "0.00100987", "0", "1"], ["83625.9", "0.00032751", "0", "1"], ["83626", "0.00159033", "0", "1"], ["83626.1", "0.00003828", "0", "2"], ["83626.3", "0.00002453", "0", "2"], ["83626.4", "0.00011621", "0", "2"], ["83626.6", "0.00001286", "0", "1"], ["83627.1", "0.00066173", "0", "1"], ["83627.2", "0.00001016", "0", "1"], ["83627.9", "0.00003987", "0", "2"], ["83628", "0.00001033", "0", "1"], ["83628.2", "0.36060062", "0", "9"], ["83628.4", "0.00016982", "0", "1"], ["83628.5", "0.00001067", "0", "1"], ["83628.6", "0.0000528", "0", "4"], ["83628.8", "0.00002707", "0", "2"], ["83629.4", "0.00001001", "0", "1"], ["83629.5", "0.00437872", "0", "2"]], "bids": [["83473.9", "0.66492161", "0", "7"], ["83472.2", "0.005", "0", "1"], ["83472.1", "0.007", "0", "2"], ["83471.4", "0.00071174", "0", "1"], ["83470", "0.0567", "0", "1"], ["83468", "0.0567", "0", "1"], ["83466.8", "0.16602269", "0", "1"], ["83466.5", "0.00217617", "0", "2"], ["83466.4", "0.07914148", "0", "1"], ["83466.1", "0.1198067", "0", "1"], ["83465.9", "0.0314628", "0", "1"], ["83464.4", "0.0002", "0", "2"], ["83464.2", "0.00005282", "0", "1"], ["83464", "0.0567", "0", "1"], ["83463.5", "0.00001206", "0", "1"], ["83463.3", "0.05555555", "0", "1"], ["83462.7", "0.000015", "0", "1"], ["83462.1", "0.01", "0", "2"], ["83462", "0.01766", "0", "2"], ["83461.5", "0.18159046", "0", "2"], ["83461.3", "0.00778685", "0", "1"], ["83460.9", "0.09858164", "0", "1"], ["83460.8", "0.0003", "0", "1"], ["83460.7", "0.00778687", "0", "1"], ["83460.4", "0.09621364", "0", "1"], ["83460", "0.00001", "0", "1"], ["83459.9", "0.09813739", "0", "1"], ["83459.5", "0.08950298", "0", "1"], ["83458.7", "0.2025", "0", "1"], ["83458.4", "0.00036265", "0", "2"], ["83457.4", "0.20922443", "0", "1"], ["83457.3", "0.35972754", "0", "1"], ["83455.8", "0.15199316", "0", "2"], ["83454.6", "0.00056778", "0", "1"], ["83454.5", "0.00003889", "0", "1"], ["83454.4", "0.00001501", "0", "1"], ["83454.3", "0.01566", "0", "1"], ["83454.2", "0.00426953", "0", "1"], ["83453.9", "0.51645973", "0", "4"], ["83453.8", "0.24999146", "0", "2"], ["83453.4", "0.16640949", "0", "2"], ["83453.2", "0.000015", "0", "1"], ["83452.9", "0.15610694", "0", "1"], ["83452.7", "0.0024086", "0", "2"], ["83452.1", "0.15546733", "0", "1"], ["83452", "0.05420836", "0", "1"], ["83451.3", "0.36038", "0", "1"], ["83451.1", "0.15799991", "0", "1"], ["83450.9", "0.14469651", "0", "2"], ["83450.5", "0.189", "0", "4"], ["83450", "0.00013604", "0", "2"], ["83449.9", "0.00060612", "0", "1"], ["83449.6", "0.01", "0", "1"], ["83449.2", "0.69976216", "0", "2"], ["83448.9", "0.35972754", "0", "1"], ["83448.2", "0.00015588", "0", "1"], ["83448", "0.047", "0", "1"], ["83447.5", "0.18999146", "0", "1"], ["83447", "0.02956077", "0", "1"], ["83446.9", "0.01198396", "0", "1"], ["83446.8", "0.7942696", "0", "2"], ["83446.6", "0.18999146", "0", "1"], ["83446.4", "0.24594043", "0", "1"], ["83446.2", "0.236709", "0", "1"], ["83446.1", "0.000015", "0", "1"], ["83445.8", "0.12337654", "0", "2"], ["83445.3", "0.13432907", "0", "2"], ["83445", "0.00367", "0", "1"], ["83444.7", "0.00002396", "0", "1"], ["83444.2", "0.2747533", "0", "1"], ["83444.1", "0.24060911", "0", "1"], ["83444", "0.00001", "0", "1"], ["83443.4", "0.00001204", "0", "1"], ["83443.3", "0.00479367", "0", "1"], ["83442.6", "0.07081917", "0", "2"], ["83442.4", "0.27725957", "0", "2"], ["83442.3", "0.11984077", "0", "1"], ["83442", "0.2025", "0", "1"], ["83440.8", "0.17953568", "0", "1"], ["83440.1", "0.00904721", "0", "2"], ["83440", "0.00309005", "0", "2"], ["83438.4", "0.00001629", "0", "1"], ["83437.8", "0.00001501", "0", "1"], ["83437.4", "0.00427082", "0", "1"], ["83435.9", "0.00020004", "0", "1"], ["83435.7", "0.01219896", "0", "1"], ["83435.6", "1.13813024", "0", "3"], ["83435.5", "0.35972754", "0", "1"], ["83435.4", "0.04", "0", "1"], ["83435.1", "0.11973173", "0", "1"], ["83435", "1", "0", "1"], ["83434.9", "0.15199316", "0", "2"], ["83434.2", "0.00011142", "0", "1"], ["83433.6", "0.2025", "0", "1"], ["83433.4", "0.00001205", "0", "1"], ["83433.3", "0.00101501", "0", "2"], ["83433.1", "1.58974381", "0", "3"], ["83433", "0.48724", "0", "1"], ["83431.9", "0.00006004", "0", "1"], ["83431.7", "0.00017505", "0", "1"], ["83430.1", "0.00427258", "0", "1"], ["83430", "0.17551347", "0", "2"], ["83429.9", "0.5835019", "0", "1"], ["83429.5", "0.00005501", "0", "2"], ["83429.2", "0.001438", "0", "1"], ["83428.4", "0.00001205", "0", "1"], ["83428", "0.00007368", "0", "1"], ["83427.5", "0.69811271", "0", "3"], ["83427.4", "0.495938", "0", "1"], ["83427.2", "0.17953568", "0", "1"], ["83427.1", "0.00367", "0", "1"], ["83427", "0.04", "0", "1"], ["83426.5", "0.35972754", "0", "1"], ["83426.4", "0.11992025", "0", "1"], ["83426.2", "0.00002851", "0", "1"], ["83425.9", "0.1", "0", "1"], ["83425.8", "0.475752", "0", "1"], ["83425.6", "0.52594", "0", "1"], ["83425.3", "0.01179894", "0", "2"], ["83425.2", "0.2025", "0", "1"], ["83425", "0.00009272", "0", "1"], ["83424.6", "0.01", "0", "1"], ["83424.1", "0.00001001", "0", "1"], ["83423.2", "0.0008", "0", "2"], ["83423", "0.00015417", "0", "1"], ["83422.4", "0.08373328", "0", "2"], ["83421.6", "0.18", "0", "4"], ["83421.3", "0.0126", "0", "1"], ["83421.2", "0.00001501", "0", "1"], ["83420.9", "0.00589947", "0", "1"], ["83420.8", "0.09002397", "0", "3"], ["83420.7", "0.00427296", "0", "1"], ["83420.4", "0.05993611", "0", "1"], ["83420.1", "0.24030789", "0", "2"], ["83420", "0.05492", "0", "2"], ["83419.8", "0.02397461", "0", "1"], ["83419.3", "0.00001894", "0", "1"], ["83419.2", "0.026", "0", "2"], ["83418.8", "0.58167717", "0", "2"], ["83418.4", "0.07290336", "0", "3"], ["83418.3", "0.15957085", "0", "1"], ["83418.2", "0.3015217", "0", "1"], ["83416.9", "0.00589947", "0", "1"], ["83416.8", "0.2025", "0", "1"], ["83416.6", "0.00154812", "0", "3"], ["83416.1", "0.00079489", "0", "1"], ["83415.8", "0.00001499", "0", "1"], ["83415", "0.0096", "0", "1"], ["83414.9", "0.00001205", "0", "1"], ["83414.6", "0.00026559", "0", "2"], ["83414.4", "0.00589947", "0", "1"], ["83413.8", "0.00035965", "0", "1"], ["83413.4", "0.00003545", "0", "1"], ["83413.2", "0.00589947", "0", "1"], ["83413.1", "0.35972754", "0", "1"], ["83412.9", "0.00001501", "0", "1"], ["83412.2", "0.00427383", "0", "1"], ["83411.8", "0.35163706", "0", "3"], ["83411.7", "0.00001807", "0", "1"], ["83411.2", "0.06", "0", "2"], ["83410.4", "0.17953568", "0", "1"], ["83410.2", "0.00009235", "0", "1"], ["83410", "0.00005457", "0", "1"], ["83409.8", "0.59656877", "0", "1"], ["83409.7", "0.01866931", "0", "2"], ["83409.6", "0.11992025", "0", "1"], ["83409.1", "0.00198597", "0", "1"], ["83409", "0.0056", "0", "1"], ["83408.4", "0.20251205", "0", "2"], ["83407.9", "0.00008801", "0", "1"], ["83407.8", "0.00589947", "0", "1"], ["83406.3", "0.01197486", "0", "1"], ["83405", "0.00599", "0", "1"], ["83404.6", "0.00001501", "0", "1"], ["83404", "0.84438945", "0", "1"], ["83403.9", "2.81035683", "0", "1"], ["83403.7", "0.00427466", "0", "1"], ["83403.4", "0.00001206", "0", "1"], ["83402.7", "2.05037485", "0", "2"], ["83402.6", "3.02234991", "0", "2"], ["83402.3", "0.00001205", "0", "1"], ["83401.9", "0.10608079", "0", "1"], ["83401.5", "0.00012658", "0", "1"], ["83400.6", "0.00599", "0", "1"], ["83400.3", "0.35972754", "0", "1"], ["83400.2", "0.17953568", "0", "1"], ["83400.1", "0.11992025", "0", "1"], ["83400", "0.61170205", "0", "47"], ["83399.9", "0.06795845", "0", "7"], ["83399.3", "0.11892466", "0", "1"], ["83398.4", "0.00010523", "0", "1"], ["83398.1", "0.00023981", "0", "1"], ["83398", "0.00007308", "0", "1"], ["83397.9", "0.00589947", "0", "1"], ["83397.1", "0.3", "0", "1"], ["83396.7", "0.00008", "0", "1"], ["83396.3", "0.00001501", "0", "1"], ["83395.7", "0.00444738", "0", "2"], ["83395.5", "0.05555555", "0", "1"], ["83395", "0.00017369", "0", "2"], ["83394.9", "0.00078135", "0", "2"], ["83393.9", "0.03594115", "0", "1"], ["83393.6", "0.0060994", "0", "1"], ["83393.5", "0.00779888", "0", "2"], ["83393.4", "0.00001205", "0", "1"], ["83393.1", "0.00001731", "0", "1"], ["83393", "0.00059957", "0", "1"], ["83392.8", "0.03595752", "0", "1"], ["83392.5", "0.11022827", "0", "1"], ["83391.7", "0.00589887", "0", "1"], ["83391.6", "0.20839947", "0", "2"], ["83391.3", "0.0186", "0", "1"], ["83391", "0.13497659", "0", "3"], ["83390.9", "0.00427658", "0", "1"], ["83390.7", "0.01198007", "0", "1"], ["83390.5", "0.01316", "0", "1"], ["83390.4", "0.03", "0", "1"], ["83390", "0.0000721", "0", "1"], ["83389.4", "0.00275989", "0", "1"], ["83389.3", "0.0000913", "0", "1"], ["83388.9", "0.44934924", "0", "3"], ["83388.8", "0.35972754", "0", "1"], ["83388.7", "0.17953568", "0", "1"], ["83388.6", "0.11992025", "0", "1"], ["83388.4", "0.00002707", "0", "2"], ["83388", "0.00001501", "0", "1"], ["83387.9", "0.01798641", "0", "1"], ["83387.7", "0.872611", "0", "1"], ["83385.7", "0.0060994", "0", "1"], ["83385.6", "1.15488079", "0", "3"], ["83385.5", "3.49303", "0", "1"], ["83385.4", "0.00589947", "0", "1"], ["83385.3", "0.08991011", "0", "1"], ["83384", "0.00589887", "0", "1"], ["83383.4", "0.00001205", "0", "1"], ["83383.3", "0.00419962", "0", "2"], ["83383.2", "0.2025", "0", "1"], ["83382.7", "0.03", "0", "1"], ["83382", "0.09632375", "0", "1"], ["83381.9", "0.1439161", "0", "2"], ["83381.6", "0.00614803", "0", "2"], ["83381.5", "0.03", "0", "1"], ["83380.4", "0.02224508", "0", "2"], ["83380", "0.00270576", "0", "4"], ["83379.9", "0.01219877", "0", "2"], ["83379.8", "0.00617647", "0", "3"], ["83379.7", "0.00001501", "0", "1"], ["83379.5", "0.00012802", "0", "1"], ["83379.3", "0.00610571", "0", "2"], ["83379.1", "0.22311", "0", "1"], ["83379", "0.005", "0", "2"], ["83378.4", "0.00001206", "0", "1"], ["83377.8", "0.00589887", "0", "1"], ["83377.7", "0.05555555", "0", "1"], ["83377.6", "0.00111285", "0", "1"], ["83376.6", "0.18444276", "0", "1"], ["83376.5", "0.35972754", "0", "1"], ["83376", "0.00001154", "0", "1"], ["83375.6", "0.0056", "0", "1"], ["83375.3", "0.00011142", "0", "1"], ["83375", "0.02598001", "0", "4"], ["83374.8", "0.22060001", "0", "2"], ["83374.6", "0.00147067", "0", "2"], ["83374.3", "0.09089194", "0", "1"], ["83374.1", "0.02395969", "0", "1"], ["83374", "0.00023936", "0", "1"], ["83373.4", "0.00001206", "0", "1"], ["83373.3", "0.00591602", "0", "2"], ["83373.2", "0.01829757", "0", "3"], ["83373.1", "0.0119977", "0", "2"], ["83373", "0.00500625", "0", "2"], ["83372.8", "0.03", "0", "1"], ["83372", "0.13125658", "0", "1"], ["83371.9", "0.17953568", "0", "1"], ["83371.8", "0.11992025", "0", "1"], ["83371.2", "0.00030552", "0", "1"], ["83370.8", "0.10609945", "0", "2"], ["83370.7", "0.0060994", "0", "1"], ["83370.6", "0.00609883", "0", "1"], ["83370.5", "0.00609883", "0", "1"], ["83370.4", "0.00609883", "0", "1"], ["83370.3", "0.00427848", "0", "1"], ["83369", "0.00020419", "0", "1"], ["83368.4", "0.00001205", "0", "1"], ["83368.2", "0.30681583", "0", "1"], ["83368.1", "0.58099347", "0", "3"], ["83367.5", "0.00589947", "0", "1"], ["83367.4", "0.17500771", "0", "1"], ["83367.3", "0.00226132", "0", "3"], ["83366.8", "0.00001527", "0", "1"], ["83366.6", "0.04870448", "0", "8"], ["83366.4", "0.2025", "0", "1"], ["83366.1", "0.00010118", "0", "1"], ["83365.5", "0.00609931", "0", "1"], ["83365.1", "0.00609937", "0", "1"], ["83365", "0.00589933", "0", "1"], ["83364.9", "0.11997608", "0", "2"], ["83363.9", "0.00597332", "0", "1"], ["83363.6", "0.00021066", "0", "2"], ["83363.4", "0.00611143", "0", "2"], ["83363.3", "0.00609937", "0", "1"], ["83363.2", "0.22904174", "0", "1"], ["83363.1", "0.35972754", "0", "1"], ["83362.5", "0.1", "0", "1"], ["83362.4", "0.17953568", "0", "1"], ["83362.3", "0.11992025", "0", "1"], ["83361.9", "0.00001", "0", "1"], ["83361.7", "0.004279", "0", "1"], ["83360.9", "0.1", "0", "1"], ["83360.5", "0.32367639", "0", "1"], ["83360", "0.00039876", "0", "2"], ["83359.2", "0.07216343", "0", "1"], ["83358.4", "0.00001206", "0", "1"], ["83358.2", "0.00121963", "0", "1"], ["83358", "0.2025", "0", "1"], ["83357.4", "0.05573758", "0", "2"], ["83357.1", "0.00021765", "0", "2"], ["83356", "0.00599008", "0", "1"], ["83355.8", "0.00112942", "0", "1"], ["83355.7", "0.00011142", "0", "1"], ["83355", "0.00038593", "0", "1"], ["83354.5", "0.00119", "0", "1"], ["83354.2", "0.00427924", "0", "1"], ["83353.8", "0.00350324", "0", "1"], ["83353.7", "0.03", "0", "1"], ["83353.6", "0.07252595", "0", "1"], ["83353.4", "0.00001206", "0", "1"], ["83352.9", "0.00002905", "0", "1"], ["83352.8", "0.05802294", "0", "1"], ["83352.7", "0.00009399", "0", "1"], ["83352.4", "0.00723661", "0", "1"], ["83351.9", "0.00001206", "0", "1"], ["83350.9", "0.0159", "0", "1"], ["83350.7", "0.00895999", "0", "1"], ["83350.5", "0.00005519", "0", "1"], ["83350", "0.00042048", "0", "3"], ["83349.9", "0.00060612", "0", "1"], ["83349.8", "0.00003456", "0", "1"], ["83349.7", "0.35972754", "0", "1"], ["83349.6", "0.2025", "0", "1"], ["83348.3", "0.0000168", "0", "1"], ["83348.2", "0.00001999", "0", "1"], ["83347.9", "0.00138026", "0", "1"], ["83347.2", "0.00003367", "0", "1"], ["83346.9", "0.00001009", "0", "1"], ["83346.1", "0.05395322", "0", "2"], ["83345.6", "0.18579029", "0", "2"], ["83345.5", "0.11992025", "0", "1"], ["83345.2", "0.00002639", "0", "1"], ["83344.9", "0.00428047", "0", "1"], ["83344.4", "0.01798608", "0", "1"], ["83343.7", "0.00001559", "0", "1"], ["83343.4", "0.00001206", "0", "1"], ["83342.8", "0.0000216", "0", "1"], ["83341.5", "0.215554", "0", "1"], ["83341.4", "0.00428113", "0", "1"], ["83341.2", "0.2025", "0", "1"], ["83341.1", "0.01194665", "0", "1"], ["83341", "0.03", "0", "1"], ["83340.4", "0.00002331", "0", "1"], ["83340", "0.00012743", "0", "1"], ["83339.6", "0.00004266", "0", "1"], ["83339.4", "0.00001206", "0", "1"], ["83339.3", "0.01797024", "0", "3"], ["83339.1", "0.00155799", "0", "1"], ["83339", "0.03", "0", "1"], ["83338.2", "0.18450283", "0", "1"], ["83338.1", "0.00053529", "0", "1"], ["83337.5", "0.0000267", "0", "1"], ["83337.3", "0.03", "0", "1"], ["83337.1", "0.002396", "0", "1"], ["83337", "0.00005177", "0", "1"], ["83336.6", "0.00004163", "0", "1"], ["83336.5", "0.192867", "0", "1"], ["83336.3", "0.35972754", "0", "1"], ["83336.1", "0.00011142", "0", "1"], ["83336", "0.00002125", "0", "1"], ["83335.3", "0.00018", "0", "1"], ["83334.7", "0.03", "0", "1"], ["83334.6", "0.00002208", "0", "1"], ["83334.3", "0.00041207", "0", "1"], ["83333.9", "1.53241978", "0", "2"], ["83333.4", "0.00001206", "0", "1"], ["83333.3", "0.00771586", "0", "19"], ["83333.1", "0.00002212", "0", "1"], ["83332.9", "0.00002031", "0", "1"], ["83332.8", "0.2025", "0", "1"], ["83332.7", "0.01536105", "0", "2"], ["83332.6", "0.00001302", "0", "1"], ["83332.3", "0.00001364", "0", "1"], ["83332.2", "0.28", "0", "1"], ["83331.2", "0.00005685", "0", "1"], ["83331", "0.00001097", "0", "1"], ["83330.8", "0.035909", "0", "1"], ["83330.6", "0.00001852", "0", "1"], ["83330.1", "0.00003016", "0", "2"], ["83329.7", "0.00008173", "0", "1"], ["83329.3", "0.00428218", "0", "1"], ["83328.8", "0.17953568", "0", "1"], ["83328.7", "0.11992025", "0", "1"]], "ts": "1742377412402", "checksum": 2040187449, "seqId": 49713703269, "prevSeqId": -1}], "record_time": 1742377413.275636}
{"arg": {"channel": "books", "instId": "BTC-USDT"}, "action": "update", "data": [{"asks": [["83531.7", "0.347462", "0", "1"], ["83550.9", "0", "0", "0"]], "bids": [["83430.1", "0.32249395", "0", "2"], ["83430", "0.475743", "0", "2"], ["83425.8", "0", "0", "0"], ["83328.4", "0.00001206", "0", "1"]], "ts": "1742377412502", "checksum": 2040187449, "seqId": 49713703283, "prevSeqId": 49713703269}], "record_time": 1742377413.368922}
{"arg": {"channel": "books", "instId": "BTC-USDT"}, "action": "update", "data": [{"asks": [["83475.5", "0.2396283", "0", "1"], ["83475.9", "0", "0", "0"]], "bids": [["83466.8", "0", "0", "0"], ["83464.5", "0.0002", "0", "2"], ["83464.4", "0", "0", "0"], ["83420.1", "0.00068075", "0", "1"], ["83419.3", "0.23964724", "0", "2"], ["83328.3", "0.0004012", "0", "1"]], "ts": "1742377412602", "checksum": 330868856, "seqId": 49713703314, "prevSeqId": 49713703283}], "record_time": 1742377413.468993}
{"arg": {"channel": "books", "instId": "BTC-USDT"}, "action": "update", "data": [{"asks": [], "bids": [["83464.5", "0.0001", "0", "1"], ["83464.2", "0.00015282", "0", "2"], ["83458.8", "0.17953568", "0", "1"], ["83422.4", "0.16373328", "0", "4"], ["83421.6", "0.14", "0", "3"], ["83420.8", "0.05002397", "0", "2"], ["83328.3", "0", "0", "0"]], "ts": "1742377412702", "checksum": 412734978, "seqId": 49713703327, "prevSeqId": 49713703314}], "record_time": 1742377413.569735}
{"arg": {"channel": "books", "instId": "BTC-USDT"}, "action": "update", "data": [{"asks": [], "bids": [["83464.5", "0", "0", "0"], ["83464.2", "0.00025282", "0", "3"], ["83328.3", "0.0004012", "0", "1"]], "ts": "1742377412802", "checksum": 1267992702, "seqId": 49713703337, "prevSeqId": 49713703327}], "record_time": 1742377413.668864}
{"arg": {"channel": "books", "instId": "BTC-USDT"}, "action": "update", "data": [{"asks": [["83494", "0.2", "0", "1"], ["83496.5", "0.91017975", "0", "2"], ["83498", "1.0055", "0", "2"], ["83534.8", "0", "0", "0"], ["83576.6", "0.0215", "0", "1"]], "bids": [["83424", "0.2", "0", "1"], ["83422.4", "0.08373328", "0", "2"], ["83421.6", "0.18", "0", "4"], ["83420.8", "0.09002397", "0", "3"], ["83328.3", "0", "0", "0"]], "ts": "1742377412902", "checksum": 1267992702, "seqId": 49713703351, "prevSeqId": 49713703337}], "record_time": 1742377413.768706}
{"arg": {"channel": "books", "instId": "BTC-USDT"}, "action": "update", "data": [{"asks": [["83475.5", "0", "0", "0"], ["83475.9", "0.23962761", "0", "1"], ["83497.9", "0.01219896", "0", "1"], ["83498.6", "0", "0", "0"]], "bids": [["83473.9", "0.66371364", "0", "6"], ["83464.2", "0.00005282", "0", "1"], ["83464.1", "0.0002", "0", "2"], ["83424", "0.09999999", "0", "1"], ["83422.4", "0.16373328", "0", "4"], ["83421.6", "0.14", "0", "3"], ["83420.8", "0.05002397", "0", "2"], ["83419.9", "0.23962761", "0", "1"], ["83419.3", "0.00001894", "0", "1"], ["83328.7", "0", "0", "0"], ["83328.4", "0", "0", "0"]], "ts": "1742377413002", "checksum": -1374742608, "seqId": 49713703377, "prevSeqId": 49713703351}], "record_time": 1742377413.869188}
{"arg": {"channel": "books", "instId": "BTC-USDT"}, "action": "update", "data": [{"asks": [["83474", "3.13330718", "0", "57"], ["83475.9", "0", "0", "0"], ["83477.9", "0.23962555", "0", "1"], ["83494", "0.1", "0", "1"], ["83501.2", "0", "0", "0"], ["83629.9", "0.00002782", "0", "1"]], "bids": [["83473.9", "0.66491364", "0", "7"], ["83434", "0.0037297", "0", "1"], ["83433.1", "0.00199381", "0", "2"], ["83427.5", "0.47497554", "0", "2"], ["83427.4", "0", "0", "0"], ["83424", "0", "0", "0"], ["83420.9", "0.24552502", "0", "2"], ["83419.9", "0", "0", "0"], ["83419.4", "0.495954", "0", "1"], ["83364.7", "0.01439458", "0", "1"]], "ts": "1742377413102", "checksum": 925626752, "seqId": 49713703420, "prevSeqId": 49713703377}], "record_time": 1742377413.969386}
{"arg": {"channel": "books", "instId": "BTC-USDT"}, "action": "update", "data": [{"asks": [["83474", "3.23077229", "0", "66"], ["83475.5", "0.23962813", "0", "1"], ["83477.9", "0", "0", "0"], ["83479.6", "0.47105021", "0", "1"], ["83482.7", "0", "0", "0"], ["83505.5", "0.475298", "0", "1"], ["83511", "0", "0", "0"], ["83511.9", "0", "0", "0"], ["83572.7", "0.2729787", "0", "2"], ["83630.2", "0.00428793", "0", "3"], ["83630.5", "0.00003988", "0", "1"]], "bids": [["83464.1", "0", "0", "0"], ["83463.7", "0.0002", "0", "2"], ["83435.7", "0", "0", "0"], ["83435.6", "0.41296742", "0", "2"], ["83433.8", "1.56821913", "0", "1"], ["83420.9", "0.00589947", "0", "1"], ["83420.5", "0.23962813", "0", "1"], ["83404.1", "0.01219896", "0", "1"], ["83404", "0", "0", "0"], ["83403.9", "0", "0", "0"]], "ts": "1742377413202", "checksum": 1625747492, "seqId": 49713703478, "prevSeqId": 49713703420}], "record_time": 1742377414.06897}
{"arg": {"channel": "books", "instId": "BTC-USDT"}, "action": "update", "data": [{"asks": [["83479.6", "0.87516301", "0", "2"], ["83482.7", "1.5433136", "0", "1"], ["83494", "0", "0", "0"], ["83496.5", "0.47263097", "0", "1"], ["83497.9", "0", "0", "0"], ["83498", "0.0055", "0", "1"], ["83511.9", "2.73125651", "0", "1"], ["83531.6", "0.01219896", "0", "1"], ["83630.5", "0", "0", "0"]], "bids": [["83473.9", "0.53491364", "0", "5"], ["83464", "0.0568", "0", "2"], ["83463.7", "0.0001", "0", "1"], ["83420.5", "0", "0", "0"], ["83418.9", "0.23963083", "0", "1"], ["83404.7", "0.87267749", "0", "1"], ["83404.6", "2.89245136", "0", "2"], ["83328.8", "0", "0", "0"]], "ts": "1742377413302", "checksum": -2091672446, "seqId": 49713703500, "prevSeqId": 49713703478}], "record_time": 1742377414.171975}
{"arg": {"channel": "books", "instId": "BTC-USDT"}, "action": "update", "data": [{"asks": [["83475.3", "0.0002", "0", "2"], ["83476.9", "0", "0", "0"]], "bids": [["83463.7", "0", "0", "0"], ["83463.5", "0.00011206", "0", "2"], ["83435.7", "0.01219896", "0", "1"], ["83404.1", "0", "0", "0"], ["83328.8", "0.17953568", "0", "1"]], "ts": "1742377413402", "checksum": 1243412680, "seqId": 49713703519, "prevSeqId": 49713703500}], "record_time": 1742377414.271734}
{"arg": {"channel": "books", "instId": "BTC-USDT"}, "action": "update", "data": [{"asks": [["83474", "3.73077229", "0", "67"], ["83474.2", "0.13915071", "0", "2"], ["83475.3", "0", "0", "0"], ["83475.5", "0.23963246", "0", "1"], ["83475.8", "0.00936", "0", "3"], ["83498.6", "0.01219896", "0", "1"], ["83511.2", "1.68819687", "0", "4"], ["83531.6", "0", "0", "0"], ["83534.8", "0.19940211", "0", "1"]], "bids": [["83470", "0", "0", "0"], ["83466.5", "0.13123059", "0", "3"], ["83464", "0.0567", "0", "1"], ["83463.5", "0.00001206", "0", "1"], ["83463.1", "0.0001", "0", "1"], ["83462.6", "0.0001", "0", "1"], ["83435.6", "1.13338989", "0", "3"], ["83418.9", "0", "0", "0"], ["83418.4", "0.31253582", "0", "4"]], "ts": "1742377413502", "checksum": -983384983, "seqId": 49713703566, "prevSeqId": 49713703519}], "record_time": 1742377414.36898}
{"arg": {"channel": "books", "instId": "BTC-USDT"}, "action": "update", "data": [{"asks": [["83474", "4.15077229", "0", "68"]], "bids": [["83466.6", "0.12905442", "0", "1"], ["83465.7", "0.0001", "0", "1"], ["83463.1", "0", "0", "0"], ["83462.9", "0.0001", "0", "1"], ["83462.6", "0", "0", "0"], ["83418.4", "0.07290336", "0", "3"], ["83416.9", "0.24553106", "0", "2"], ["83328.8", "0", "0", "0"]], "ts": "1742377413602", "checksum": -2114536999, "seqId": 49713703585, "prevSeqId": 49713703566}], "record_time": 1742377414.469296}
{"arg": {"channel": "books", "instId": "BTC-USDT"}, "action": "update", "data": [{"asks": [["83475.5", "0", "0", "0"], ["83475.9", "0.23962966", "0", "1"]], "bids": [["83465.7", "0", "0", "0"], ["83463.9", "0.0002", "0", "2"], ["83462.9", "0", "0", "0"], ["83419.3", "0.2396486", "0", "2"], ["83416.9", "0.00589947", "0", "1"], ["83328.8", "0.17953568", "0", "1"]], "ts": "1742377413702", "checksum": 2121502957, "seqId": 49713703595, "prevSeqId": 49713703585}], "record_time": 1742377414.569495}
{"arg": {"channel": "books", "instId": "BTC-USDT"}, "action": "update", "data": [{"asks": [["83475.9", "0", "0", "0"], ["83477.9", "0.2396288", "0", "1"]], "bids": [["83419.5", "0.2396288", "0", "1"], ["83419.3", "0.00001894", "0", "1"], ["83328.8", "0", "0", "0"]], "ts": "1742377413802", "checksum": 1350932296, "seqId": 49713703607, "prevSeqId": 49713703595}], "record_time": 1742377414.669261}
{"arg": {"channel": "books", "instId": "BTC-USDT"}, "action": "update", "data": [{"asks": [["83481", "0", "0", "0"], ["83630.5", "0.00003988", "0", "1"]], "bids": [["83466.5", "0.00217617", "0", "2"], ["83463.9", "0", "0", "0"], ["83463.6", "0.0002", "0", "2"]], "ts": "1742377413902", "checksum": -1030622961, "seqId": 49713703618, "prevSeqId": 49713703607}], "record_time": 1742377414.769067}
{"arg": {"channel": "books", "instId": "BTC-USDT"}, "action": "update", "data": [{"asks": [["83475.5", "0.23963076", "0", "1"], ["83477.9", "0", "0", "0"], ["83481.2", "0.132717", "0", "1"], ["83481.4", "0", "0", "0"], ["83558.4", "0", "0", "0"], ["83630.6", "0.00011142", "0", "1"]], "bids": [["83464", "0.0568", "0", "2"], ["83463.9", "0.0001", "0", "1"], ["83463.6", "0", "0", "0"], ["83422.4", "0.08373328", "0", "2"], ["83421.6", "0.18", "0", "4"], ["83420.8", "0.09002397", "0", "3"], ["83419.5", "0", "0", "0"], ["83418.5", "0.23963076", "0", "1"], ["83352.4", "0", "0", "0"], ["83328.8", "0.17953568", "0", "1"]], "ts": "1742377414002", "checksum": -1094864567, "seqId": 49713703647, "prevSeqId": 49713703618}], "record_time": 1742377414.869043}
{"arg": {"channel": "books", "instId": "BTC-USDT"}, "action": "update", "data": [{"asks": [["83475.5", "0.23963193", "0", "1"], ["83531.1", "0.0037803", "0", "1"], ["83531.3", "0.03", "0", "1"], ["83630.6", "0", "0", "0"]], "bids": [["83464.1", "0.0002", "0", "2"], ["83464", "0.0567", "0", "1"], ["83463.9", "0", "0", "0"], ["83422.4", "0.16373328", "0", "4"], ["83421.6", "0.14", "0", "3"], ["83420.8", "0.05002397", "0", "2"], ["83418.5", "0", "0", "0"], ["83418.4", "0.31253517", "0", "4"], ["83409.7", "0.00021823", "0", "1"], ["83408.5", "0.01845128", "0", "1"], ["83338.2", "0", "0", "0"], ["83337.4", "0.18451283", "0", "1"]], "ts": "1742377414102", "checksum": -1487943559, "seqId": 49713703692, "prevSeqId": 49713703647}], "record_time": 1742377414.96969}
{"arg": {"channel": "books", "instId": "BTC-USDT"}, "action": "update", "data": [{"asks": [["83474", "3.73077229", "0", "67"], ["83475.8", "0.00916", "0", "1"], ["83475.9", "0.0002", "0", "2"], ["83483.3", "0.00060612", "0", "1"], ["83493.3", "0.09", "0", "3"], ["83527.7", "0.01464894", "0", "1"], ["83630.2", "0", "0", "0"], ["83630.5", "0", "0", "0"]], "bids": [["83472.1", "0.002", "0", "1"], ["83462.1", "0.005", "0", "1"], ["83424", "0.2", "0", "1"], ["83382.9", "0.00723397", "0", "1"], ["83329.3", "0", "0", "0"], ["83328.8", "0", "0", "0"]], "ts": "1742377414202", "checksum": 994944549, "seqId": 49713703709, "prevSeqId": 49713703692}], "record_time": 1742377415.069162}
{"arg": {"channel": "books", "instId": "BTC-USDT"}, "action": "update", "data": [{"asks": [["83475.5", "0.23963054", "0", "1"], ["83475.8", "0.00936", "0", "3"], ["83475.9", "0", "0", "0"], ["83489", "0.1", "0", "1"], ["83497", "1", "0", "1"], ["83629.9", "0", "0", "0"]], "bids": [["83418.9", "0.23963054", "0", "1"], ["83418.4", "0.07290336", "0", "3"], ["83329.7", "0", "0", "0"]], "ts": "1742377414302", "checksum": -200374763, "seqId": 49713703726, "prevSeqId": 49713703709}], "record_time": 1742377415.170558}
{"arg": {"channel": "books", "instId": "BTC-USDT"}, "action": "update", "data": [{"asks": [["83483.3", "0.00560612", "0", "2"], ["83493.3", "0.095", "0", "4"]], "bids": [["83472.1", "0.007", "0", "2"], ["83462.1", "0.01", "0", "2"]], "ts": "1742377414402", "checksum": -1496110429, "seqId": 49713703734, "prevSeqId": 49713703726}], "record_time": 1742377415.269602}
{"arg": {"channel": "books", "instId": "BTC-USDT"}, "action": "update", "data": [{"asks": [["83475.5", "0", "0", "0"], ["83475.9", "0.23962816", "0", "1"]], "bids": [["83419.9", "0.23962812", "0", "1"], ["83418.9", "0", "0", "0"]], "ts": "1742377414502", "checksum": -1114062304, "seqId": 49713703744, "prevSeqId": 49713703734}], "record_time": 1742377415.370739}
{"arg": {"channel": "books", "instId": "BTC-USDT"}, "action": "update", "data": [{"asks": [["83475.5", "0.23963019", "0", "1"], ["83475.9", "0", "0", "0"], ["83496.5", "0.91017975", "0", "2"], ["83525.9", "0.10978642", "0", "3"], ["83572.7", "0.00298666", "0", "1"]], "bids": [["83466.8", "0.16471633", "0", "1"], ["83466.7", "0.42", "0", "1"], ["83466.6", "0", "0", "0"], ["83464.2", "0.00025282", "0", "3"], ["83464.1", "0", "0", "0"], ["83440.9", "0.05879252", "0", "1"], ["83424", "0.09999999", "0", "1"], ["83419.9", "0", "0", "0"], ["83418.9", "0.23963019", "0", "1"], ["83413.2", "0.11510438", "0", "2"], ["83330.1", "0", "0", "0"]], "ts": "1742377414602", "checksum": 166068772, "seqId": 49713703767, "prevSeqId": 49713703744}], "record_time": 1742377415.469697}
{"arg": {"channel": "books", "instId": "BTC-USDT"}, "action": "update", "data": [{"asks": [["83474", "3.71887229", "0", "66"]], "bids": [["83466.8", "0", "0", "0"], ["83466.7", "0", "0", "0"], ["83466.5", "0.13123059", "0", "3"], ["83464.2", "0.00005282", "0", "1"], ["83463.4", "0.0002", "0", "2"], ["83330.1", "0.00003016", "0", "2"]], "ts": "1742377414702", "checksum": -1808706002, "seqId": 49713703783, "prevSeqId": 49713703767}], "record_time": 1742377415.569313}
{"arg": {"channel": "books", "instId": "BTC-USDT"}, "action": "update", "data": [{"asks": [["83474", "3.73077229", "0", "67"], ["83475.8", "0.00926", "0", "2"], ["83476", "0.0568", "0", "2"]], "bids": [["83466.6", "0.12905442", "0", "1"], ["83464.1", "0.0001", "0", "1"], ["83463.4", "0", "0", "0"], ["83463.1", "0.0001", "0", "1"], ["83422.4", "0.08373328", "0", "2"], ["83421.6", "0.18", "0", "4"], ["83420.8", "0.09002397", "0", "3"], ["83330.6", "0", "0", "0"], ["83330.1", "0", "0", "0"]], "ts": "1742377414802", "checksum": -766827786, "seqId": 49713703886, "prevSeqId": 49713703783}], "record_time": 1742377415.669558}
{"arg": {"channel": "books", "instId": "BTC-USDT"}, "action": "update", "data": [{"asks": [["83475.8", "0.00936", "0", "3"], ["83476", "0.0567", "0", "1"], ["83527.7", "0", "0", "0"], ["83545.6", "0.07181707", "0", "1"], ["83629.9", "0.00002782", "0", "1"]], "bids": [["83464.1", "0", "0", "0"], ["83463.3", "0.05575555", "0", "3"], ["83463.1", "0", "0", "0"], ["83422.4", "0.16373328", "0", "4"], ["83421.6", "0.14", "0", "3"], ["83420.8", "0.05002397", "0", "2"], ["83382.9", "0", "0", "0"], ["83381.9", "0.07195805", "0", "1"], ["83330.6", "0.00001852", "0", "1"], ["83330.1", "0.00003016", "0", "2"], ["83329.7", "0.00008173", "0", "1"]], "ts": "1742377414902", "checksum": 1274295096, "seqId": 49713703909, "prevSeqId": 49713703886}], "record_time": 1742377415.768881}
{"arg": {"channel": "books", "instId": "BTC-USDT"}, "action": "update", "data": [{"asks": [], "bids": [["83463.8", "0.0002", "0", "2"], ["83463.3", "0.05555555", "0", "1"], ["83329.7", "0", "0", "0"]], "ts": "1742377415002", "checksum": -1943110044, "seqId": 49713703919, "prevSeqId": 49713703909}], "record_time": 1742377415.869111}
{"arg": {"channel": "books", "instId": "BTC-USDT"}, "action": "update", "data": [{"asks": [], "bids": [["83422.4", "0.08373328", "0", "2"], ["83421.6", "0.18", "0", "4"], ["83420.8", "0.09002397", "0", "3"]], "ts": "1742377415102", "checksum": -1943110044, "seqId": 49713703924, "prevSeqId": 49713703919}], "record_time": 1742377415.968765}
{"arg": {"channel": "books", "instId": "BTC-USDT"}, "action": "update", "data": [{"asks": [["83545.6", "0", "0", "0"], ["83630.2", "0.00428793", "0", "3"]], "bids": [["83463.8", "0", "0", "0"], ["83463.4", "0.0002", "0", "2"], ["83422.4", "0.16373328", "0", "4"], ["83421.6", "0.14", "0", "3"], ["83420.8", "0.05002397", "0", "2"], ["83381.9", "0", "0", "0"], ["83329.7", "0.00008173", "0", "1"]], "ts": "1742377415202", "checksum": 503595782, "seqId": 49713703991, "prevSeqId": 49713703924}], "record_time": 1742377416.068898}
{"arg": {"channel": "books", "instId": "BTC-USDT"}, "action": "update", "data": [{"asks": [["83474", "4.1547149", "0", "69"], ["83474.2", "0.07686968", "0", "1"], ["83475.5", "0", "0", "0"], ["83475.8", "0.00926", "0", "2"], ["83476.1", "0.0001", "0", "1"], ["83534.8", "0", "0", "0"], ["83545.6", "0.14363414", "0", "2"], ["83555", "0.01464558", "0", "1"], ["83630.2", "0", "0", "0"]], "bids": [["83471.5", "0.0001", "0", "1"], ["83470", "0.0046", "0", "1"], ["83466.5", "0.00217617", "0", "2"], ["83466.4", "0", "0", "0"], ["83464", "0.0568", "0", "2"], ["83463.4", "0", "0", "0"], ["83435.6", "0.41296742", "0", "2"], ["83435", "0", "0", "0"], ["83434", "0", "0", "0"], ["83433.8", "0", "0", "0"], ["83418.9", "0", "0", "0"], ["83416.9", "0.24553275", "0", "2"], ["83404.7", "0", "0", "0"], ["83404.6", "0.00001501", "0", "1"], ["83381.9", "0.1439161", "0", "2"], ["83364.7", "0", "0", "0"], ["83355.6", "0.00723634", "0", "1"], ["83329.3", "0.00428218", "0", "1"], ["83328.8", "0.17953568", "0", "1"], ["83328.7", "0.11992025", "0", "1"], ["83328.4", "0.00001206", "0", "1"]], "ts": "1742377415302", "checksum": 756306275, "seqId": 49713704064, "prevSeqId": 49713703991}], "record_time": 1742377416.170011}
{"arg": {"channel": "books", "instId": "BTC-USDT"}, "action": "update", "data": [{"asks": [["83474", "4.1545807", "0", "69"], ["83475.8", "0.00916", "0", "1"], ["83476.1", "0", "0", "0"], ["83476.4", "0.0002", "0", "2"], ["83489", "0.2", "0", "2"], ["83496.5", "0.47263097", "0", "1"], ["83497", "0", "0", "0"], ["83507.6", "0.14601111", "0", "2"], ["83522.4", "0", "0", "0"], ["83550.9", "0.04617467", "0", "1"], ["83630.2", "0.00428793", "0", "3"]], "bids": [["83472.2", "0.0051", "0", "2"], ["83472.1", "0.0071", "0", "3"], ["83471.5", "0", "0", "0"], ["83468", "0", "0", "0"], ["83467", "0.27654519", "0", "1"], ["83466.9", "0.28269064", "0", "1"], ["83466.6", "0", "0", "0"], ["83466.1", "0", "0", "0"], ["83464.1", "0.11980952", "0", "1"], ["83464", "0.0567", "0", "1"], ["83458.8", "0", "0", "0"], ["83438.7", "0.00372944", "0", "1"], ["83435.7", "0", "0", "0"], ["83416.9", "0.00589947", "0", "1"], ["83413.4", "0.23967388", "0", "2"], ["83402.8", "0.01219896", "0", "1"], ["83385.6", "1.15479249", "0", "2"], ["83369.2", "0.01439379", "0", "1"]], "ts": "1742377415402", "checksum": -1330253169, "seqId": 49713704131, "prevSeqId": 49713704064}], "record_time": 1742377416.271191}
{"arg": {"channel": "books", "instId": "BTC-USDT"}, "action": "update", "data": [{"asks": [["83474", "4.5745807", "0", "70"], ["83475.3", "0.0001", "0", "1"], ["83475.6", "0.0315628", "0", "2"], ["83476.4", "0", "0", "0"], ["83489", "0", "0", "0"], ["83511.2", "1.68819686", "0", "4"], ["83630.5", "0.00003988", "0", "1"]], "bids": [["83473.9", "0.48701364", "0", "5"], ["83472.2", "0.005", "0", "1"], ["83472.1", "0.007", "0", "2"], ["83470.1", "0.0001", "0", "1"], ["83469.8", "0.0001", "0", "1"], ["83467.1", "0.27039974", "0", "1"], ["83467", "0", "0", "0"], ["83466.9", "0", "0", "0"], ["83464.2", "0.06968046", "0", "2"], ["83461.5", "0.11140162", "0", "1"], ["83458.7", "0", "0", "0"], ["83457.1", "0.2025", "0", "1"], ["83433.2", "1.60495693", "0", "1"], ["83430.1", "0.00427258", "0", "1"], ["83429.9", "0", "0", "0"], ["83416.7", "0.57318027", "0", "1"], ["83413.4", "0.00003545", "0", "1"], ["83413.3", "0.23963832", "0", "1"], ["83404", "2.87690727", "0", "1"], ["83385.6", "1.1548808", "0", "3"], ["83329.3", "0", "0", "0"], ["83328.8", "0", "0", "0"], ["83328.7", "0", "0", "0"], ["83328.4", "0", "0", "0"]], "ts": "1742377415502", "checksum": 369010315, "seqId": 49713704201, "prevSeqId": 49713704131}], "record_time": 1742377416.371352}
{"arg": {"channel": "books", "instId": "BTC-USDT"}, "action": "update", "data": [{"asks": [["83475.3", "0.0002", "0", "2"], ["83475.6", "0.0314628", "0", "1"], ["83518.2", "0.22234755", "0", "2"]], "bids": [["83473.9", "0.53491364", "0", "6"], ["83470.4", "0.0001", "0", "1"], ["83470.2", "0.0001", "0", "1"], ["83470.1", "0", "0", "0"], ["83469.8", "0", "0", "0"], ["83435.6", "0.84329232", "0", "3"], ["83424", "0.2", "0", "2"], ["83413.3", "0.23963903", "0", "1"], ["83404.1", "0.87655354", "0", "2"], ["83402.8", "0", "0", "0"]], "ts": "1742377415602", "checksum": -2122098782, "seqId": 49713704232, "prevSeqId": 49713704201}], "record_time": 1742377416.469379}
{"arg": {"channel": "books", "instId": "BTC-USDT"}, "action": "update", "data": [{"asks": [], "bids": [["83473.9", "0.52100364", "0", "5"], ["83470.2", "0", "0", "0"], ["83470.1", "0.0001", "0", "1"], ["83416.8", "0.44213735", "0", "2"], ["83413.3", "0", "0", "0"], ["83329.3", "0.00428218", "0", "1"]], "ts": "1742377415702", "checksum": -924235376, "seqId": 49713704252, "prevSeqId": 49713704232}], "record_time": 1742377416.569856}
{"arg": {"channel": "books", "instId": "BTC-USDT"}, "action": "update", "data": [{"asks": [], "bids": [["83470.4", "0.0002", "0", "2"], ["83470.1", "0", "0", "0"], ["83424", "0.09999999", "0", "1"], ["83328.8", "0.17953568", "0", "1"]], "ts": "1742377415802", "checksum": 1443955408, "seqId": 49713704260, "prevSeqId": 49713704252}], "record_time": 1742377416.669853}
{"arg": {"channel": "books", "instId": "BTC-USDT"}, "action": "update", "data": [{"asks": [], "bids": [["83416.8", "0.2025", "0", "1"], ["83413.3", "0.23963804", "0", "1"], ["83328.8", "0", "0", "0"]], "ts": "1742377415902", "checksum": 1443955408, "seqId": 49713704264, "prevSeqId": 49713704260}], "record_time": 1742377416.769583}
{"arg": {"channel": "books", "instId": "BTC-USDT"}, "action": "update", "data": [{"asks": [["83482.7", "0", "0", "0"], ["83511.2", "0.57597599", "0", "3"], ["83511.9", "0", "0", "0"], ["83544.7", "0.5572853", "0", "1"], ["83576.6", "0.17432902", "0", "2"], ["83630.6", "0.00011142", "0", "1"]], "bids": [["83470.5", "0.0002", "0", "2"], ["83470.4", "0", "0", "0"], ["83416.8", "0.44213745", "0", "2"], ["83413.3", "0", "0", "0"], ["83328.8", "0.17953568", "0", "1"]], "ts": "1742377416002", "checksum": 280678342, "seqId": 49713704289, "prevSeqId": 49713704264}], "record_time": 1742377416.870406}
{"arg": {"channel": "books", "instId": "BTC-USDT"}, "action": "update", "data": [{"asks": [["83475.3", "0", "0", "0"], ["83475.4", "0.0002", "0", "2"], ["83479.6", "0.47105021", "0", "1"], ["83483.5", "0.60348507", "0", "2"], ["83484.8", "1.53838963", "0", "1"], ["83498.6", "0", "0", "0"], ["83514", "2.70974463", "0", "1"], ["83531.6", "0.01219896", "0", "1"], ["83630.5", "0", "0", "0"], ["83630.6", "0", "0", "0"]], "bids": [["83470.6", "0.0002", "0", "2"], ["83470.5", "0", "0", "0"], ["83435.6", "0.41296742", "0", "2"], ["83433.2", "0", "0", "0"], ["83418.5", "0.23963417", "0", "1"], ["83416.8", "0.2025", "0", "1"], ["83404.1", "0.01219896", "0", "1"], ["83404", "0", "0", "0"], ["83400.7", "2.73844039", "0", "1"]], "ts": "1742377416102", "checksum": 1826403045, "seqId": 49713704336, "prevSeqId": 49713704289}], "record_time": 1742377416.969351}
{"arg": {"channel": "books", "instId": "BTC-USDT"}, "action": "update", "data": [{"asks": [["83475.3", "0.0002", "0", "2"], ["83475.4", "0", "0", "0"]], "bids": [["83473.9", "0.53212364", "0", "6"], ["83470.6", "0", "0", "0"], ["83470.5", "0.0001", "0", "1"], ["83470.4", "0.0001", "0", "1"], ["83422.4", "0.08373328", "0", "2"], ["83421.6", "0.18", "0", "4"], ["83420.8", "0.09002397", "0", "3"], ["83418.5", "0", "0", "0"], ["83416.9", "0.24553593", "0", "2"], ["83404.1", "0", "0", "0"], ["83402.8", "0.01219896", "0", "1"]], "ts": "1742377416202", "checksum": 1616925790, "seqId": 49713704374, "prevSeqId": 49713704336}], "record_time": 1742377417.073527}
{"arg": {"channel": "books", "instId": "BTC-USDT"}, "action": "update", "data": [{"asks": [["83474", "4.57211287", "0", "70"], ["83475.3", "0", "0", "0"], ["83475.5", "0.0002", "0", "2"], ["83498.6", "0.01219896", "0", "1"], ["83531.6", "0", "0", "0"]], "bids": [["83472.9", "0.0002", "0", "2"], ["83470.5", "0", "0", "0"], ["83470.4", "0", "0", "0"], ["83429.9", "1.53350151", "0", "1"], ["83428", "1.00007368", "0", "2"]], "ts": "1742377416302", "checksum": 874578433, "seqId": 49713704414, "prevSeqId": 49713704374}], "record_time": 1742377417.169536}
{"arg": {"channel": "books", "instId": "BTC-USDT"}, "action": "update", "data": [{"asks": [["83499", "1", "0", "1"], ["83630.2", "0", "0", "0"]], "bids": [["83472.9", "0", "0", "0"], ["83472.8", "0.0002", "0", "2"], ["83438.7", "0", "0", "0"], ["83416.9", "0.00589947", "0", "1"], ["83413.3", "0.23963819", "0", "1"], ["83391", "0.10497659", "0", "2"], ["83369.2", "0", "0", "0"], ["83328.7", "0.11992025", "0", "1"]], "ts": "1742377416402", "checksum": -476693824, "seqId": 49713704433, "prevSeqId": 49713704414}], "record_time": 1742377417.269041}
{"arg": {"channel": "books", "instId": "BTC-USDT"}, "action": "update", "data": [{"asks": [["83479.9", "0", "0", "0"], ["83499", "0", "0", "0"], ["83630.2", "0.00428793", "0", "3"], ["83630.5", "0.00003988", "0", "1"]], "bids": [["83472.9", "0.0002", "0", "2"], ["83472.8", "0", "0", "0"], ["83430.1", "0.01647154", "0", "2"], ["83422.4", "0.16373328", "0", "4"], ["83421.6", "0.14", "0", "3"], ["83420.8", "0.05002397", "0", "2"], ["83416.9", "0.24553513", "0", "2"], ["83413.3", "0", "0", "0"], ["83409", "0", "0", "0"], ["83406.3", "0", "0", "0"], ["83405.5", "0.01197473", "0", "1"], ["83402.8", "0", "0", "0"], ["83399.3", "0.12452466", "0", "2"], ["83375.6", "0", "0", "0"], ["83365.9", "0.0056", "0", "1"], ["83328.4", "0.00001206", "0", "1"], ["83328.3", "0.0004012", "0", "1"], ["83326.8", "0.00001206", "0", "1"]], "ts": "1742377416502", "checksum": -1262451808, "seqId": 49713704478, "prevSeqId": 49713704433}], "record_time": 1742377417.373933}
{"arg": {"channel": "books", "instId": "BTC-USDT"}, "action": "update", "data": [{"asks": [["83474", "4.57316287", "0", "71"], ["83513.9", "0.84173576", "0", "1"], ["83515.2", "0", "0", "0"], ["83539", "0.16071614", "0", "1"], ["83576.6", "0.0215", "0", "1"], ["83630.5", "0", "0", "0"]], "bids": [["83428.1", "0.76598981", "0", "1"], ["83427.5", "0.00001205", "0", "1"], ["83422.4", "0.08373328", "0", "2"], ["83421.6", "0.18", "0", "4"], ["83420.8", "0.09002397", "0", "3"], ["83409.1", "0", "0", "0"], ["83408.6", "0.00198624", "0", "1"], ["83402.7", "2.7103105", "0", "3"], ["83377.8", "0.03589887", "0", "2"], ["83326.8", "0", "0", "0"]], "ts": "1742377416602", "checksum": -1403934762, "seqId": 49713704502, "prevSeqId": 49713704478}], "record_time": 1742377417.469194}
{"arg": {"channel": "books", "instId": "BTC-USDT"}, "action": "update", "data": [{"asks": [["83474", "4.57223587", "0", "71"], ["83491.1", "0", "0", "0"], ["83575.5", "0", "0", "0"], ["83630.5", "0.00003988", "0", "1"], ["83630.6", "0.00011142", "0", "1"]], "bids": [["83473.9", "0.50217415", "0", "7"], ["83438.7", "0.00372944", "0", "1"], ["83422.4", "0.16373328", "0", "4"], ["83421.6", "0.14", "0", "3"], ["83420.8", "0.05002397", "0", "2"], ["83369.4", "0.01439377", "0", "1"], ["83352.8", "0", "0", "0"], ["83328.3", "0", "0", "0"]], "ts": "1742377416702", "checksum": 1745289598, "seqId": 49713704538, "prevSeqId": 49713704502}], "record_time": 1742377417.569884}
{"arg": {"channel": "books", "instId": "BTC-USDT"}, "action": "update", "data": [{"asks": [["83475.3", "0.0002", "0", "2"], ["83475.5", "0", "0", "0"]], "bids": [["83473.9", "0.53220342", "0", "9"], ["83472.9", "0", "0", "0"], ["83467.5", "0.24581794", "0", "1"], ["83467.2", "0.0002", "0", "2"], ["83467.1", "0", "0", "0"], ["83424", "0.2", "0", "2"], ["83422.4", "0.08373328", "0", "2"], ["83421.6", "0.18", "0", "4"], ["83420.8", "0.09002397", "0", "3"], ["83416.9", "0.00589947", "0", "1"], ["83416.8", "0.4421366", "0", "2"]], "ts": "1742377416802", "checksum": 753752949, "seqId": 49713704585, "prevSeqId": 49713704538}], "record_time": 1742377417.671155}
{"arg": {"channel": "books", "instId": "BTC-USDT"}, "action": "update", "data": [{"asks": [], "bids": [["83467.3", "0.0002", "0", "2"], ["83467.2", "0", "0", "0"]], "ts": "1742377416902", "checksum": 919252325, "seqId": 49713704601, "prevSeqId": 49713704585}], "record_time": 1742377417.769182}
{"arg": {"channel": "books", "instId": "BTC-USDT"}, "action": "update", "data": [{"asks": [["83474", "4.57225687", "0", "71"]], "bids": [], "ts": "1742377417002", "checksum": -1374436107, "seqId": 49713704606, "prevSeqId": 49713704601}], "record_time": 1742377417.868872}
{"arg": {"channel": "books", "instId": "BTC-USDT"}, "action": "update", "data": [{"asks": [["83475.7", "0", "0", "0"], ["83485.8", "0.05909124", "0", "1"], ["83630.7", "0.0000484", "0", "1"]], "bids": [["83472.1", "0.005", "0", "1"], ["83462", "0.01566", "0", "1"], ["83450.9", "0.132715", "0", "1"], ["83448.8", "0.01198182", "0", "1"], ["83424", "0.09999999", "0", "1"], ["83416.8", "0.2025", "0", "1"], ["83413.3", "0.23963787", "0", "1"], ["83328.7", "0", "0", "0"], ["83328.4", "0", "0", "0"]], "ts": "1742377417102", "checksum": -1361561222, "seqId": 49713704620, "prevSeqId": 49713704606}], "record_time": 1742377417.969191}
{"arg": {"channel": "books", "instId": "BTC-USDT"}, "action": "update", "data": [{"asks": [["83479.5", "0.025", "0", "1"], ["83545.6", "0.07181707", "0", "1"], ["83630.7", "0", "0", "0"]], "bids": [["83416.8", "0.44213671", "0", "2"], ["83413.3", "0", "0", "0"], ["83381.9", "0.07195805", "0", "1"], ["83328.7", "0.11992025", "0", "1"]], "ts": "1742377417202", "checksum": 2134302368, "seqId": 49713704638, "prevSeqId": 49713704620}], "record_time": 1742377418.073943}
{"arg": {"channel": "books", "instId": "BTC-USDT"}, "action": "update", "data": [{"asks": [["83474", "4.6886463", "0", "72"], ["83474.8", "0", "0", "0"], ["83475.3", "0.0001", "0", "1"], ["83475.6", "0.0315628", "0", "2"], ["83544.7", "0", "0", "0"], ["83545.6", "0", "0", "0"], ["83630.7", "0.0000484", "0", "1"], ["83630.8", "0.00110397", "0", "1"], ["83630.9", "0.11992025", "0", "1"]], "bids": [["83467.3", "0", "0", "0"], ["83466.9", "0.0002", "0", "2"], ["83452.7", "0.00001204", "0", "1"], ["83381.9", "0", "0", "0"], ["83328.4", "0.00001206", "0", "1"]], "ts": "1742377417302", "checksum": -1975511179, "seqId": 49713704666, "prevSeqId": 49713704638}], "record_time": 1742377418.169298}
{"arg": {"channel": "books", "instId": "BTC-USDT"}, "action": "update", "data": [{"asks": [["83474.8", "0.00239593", "0", "1"], ["83475.3", "0.0002", "0", "2"], ["83475.6", "0.0314628", "0", "1"], ["83545.6", "0.14363414", "0", "2"], ["83630.8", "0", "0", "0"], ["83630.9", "0", "0", "0"]], "bids": [["83473.9", "0.50224392", "0", "9"], ["83466.9", "0", "0", "0"], ["83464.2", "0.00005282", "0", "1"], ["83462.8", "0.0001", "0", "1"], ["83462.4", "0.0001", "0", "1"], ["83452.7", "0.0024086", "0", "2"], ["83438.7", "0", "0", "0"], ["83381.9", "0.1439161", "0", "2"], ["83369.4", "0", "0", "0"]], "ts": "1742377417402", "checksum": -1079566906, "seqId": 49713704713, "prevSeqId": 49713704666}], "record_time": 1742377418.269156}
{"arg": {"channel": "books", "instId": "BTC-USDT"}, "action": "update", "data": [{"asks": [["83475.7", "0.002", "0", "1"], ["83485.8", "0.06109124", "0", "2"], ["83488", "0.2567", "0", "2"], ["83491.8", "0.49079256", "0", "1"], ["83495", "1", "0", "1"], ["83630.6", "0", "0", "0"], ["83630.7", "0", "0", "0"]], "bids": [["83473.9", "0.53220392", "0", "10"], ["83472.1", "0.007", "0", "2"], ["83463.4", "0.0001", "0", "1"], ["83463.3", "0.05565555", "0", "2"], ["83462.8", "0", "0", "0"], ["83462.4", "0", "0", "0"], ["83462", "0.01766", "0", "2"], ["83433.7", "0.00372966", "0", "1"], ["83422.4", "0.16373328", "0", "4"], ["83421.6", "0.14", "0", "3"], ["83420.8", "0.05002397", "0", "2"], ["83364.4", "0.01439463", "0", "1"], ["83328.4", "0", "0", "0"]], "ts": "1742377417502", "checksum": 1589467373, "seqId": 49713704753, "prevSeqId": 49713704713}], "record_time": 1742377418.370231}
{"arg": {"channel": "books", "instId": "BTC-USDT"}, "action": "update", "data": [{"asks": [["83511.1", "0.58536845", "0", "2"], ["83531.7", "0", "0", "0"], ["83630.6", "0.00011142", "0", "1"]], "bids": [["83473.9", "0.53208595", "0", "10"], ["83463.5", "0.00021206", "0", "3"], ["83463.4", "0", "0", "0"], ["83463.3", "0.05555555", "0", "1"], ["83430.1", "0.6196928", "0", "3"], ["83422.4", "0.08373328", "0", "2"], ["83421.6", "0.18", "0", "4"], ["83420.8", "0.09002397", "0", "3"], ["83416.9", "0.24553542", "0", "2"], ["83416.8", "0.2025", "0", "1"], ["83328.4", "0.00001206", "0", "1"]], "ts": "1742377417602", "checksum": -968337949, "seqId": 49713704782, "prevSeqId": 49713704753}], "record_time": 1742377418.469365}
{"arg": {"channel": "books", "instId": "BTC-USDT"}, "action": "update", "data": [{"asks": [["83511.2", "0.495976", "0", "1"], ["83512", "0.07999999", "0", "2"], ["83512.8", "0.04011141", "0", "2"]], "bids": [["83473.9", "0.53220595", "0", "11"], ["83465.9", "0", "0", "0"], ["83463.5", "0.00011206", "0", "2"], ["83463.4", "0.0001", "0", "1"], ["83462.6", "0.0314628", "0", "1"], ["83416.9", "0.2455348", "0", "2"], ["83328.4", "0", "0", "0"]], "ts": "1742377417702", "checksum": -316983071, "seqId": 49713704820, "prevSeqId": 49713704782}], "record_time": 1742377418.56928}
{"arg": {"channel": "books", "instId": "BTC-USDT"}, "action": "update", "data": [{"asks": [], "bids": [["83464.1", "0", "0", "0"], ["83463.7", "0.07417362", "0", "1"], ["83463.6", "0.16", "0", "1"], ["83463.5", "0.00021206", "0", "3"], ["83463.4", "0", "0", "0"], ["83462", "0.1374725", "0", "3"], ["83446.8", "0.0042696", "0", "1"], ["83416.9", "0.00589947", "0", "1"], ["83416.8", "0.44213674", "0", "2"]], "ts": "1742377417802", "checksum": -1328330135, "seqId": 49713704858, "prevSeqId": 49713704820}], "record_time": 1742377418.669049}
{"arg": {"channel": "books", "instId": "BTC-USDT"}, "action": "update", "data": [{"asks": [["83474", "4.68861037", "0", "72"], ["83475.3", "0", "0", "0"], ["83475.8", "0.00936", "0", "3"], ["83504", "0.495956", "0", "1"], ["83511.1", "0.11973173", "0", "1"], ["83511.2", "0.08", "0", "2"], ["83512", "0.03999999", "0", "1"], ["83512.8", "0.00011142", "0", "1"], ["83534.8", "0.14313993", "0", "1"], ["83630.6", "0", "0", "0"]], "bids": [["83465.8", "0.0002", "0", "2"], ["83463.7", "0", "0", "0"], ["83463.6", "0", "0", "0"], ["83463.5", "0.00001206", "0", "1"], ["83461.3", "0", "0", "0"], ["83460.7", "0", "0", "0"], ["83459", "0.00778686", "0", "1"], ["83451.1", "0.16578677", "0", "2"], ["83450.9", "0", "0", "0"], ["83421.6", "0.08", "0", "2"], ["83420.8", "0.14002397", "0", "4"], ["83420", "0.10492", "0", "3"], ["83328.4", "0.00001206", "0", "1"], ["83328.3", "0.0004012", "0", "1"], ["83326.8", "0.00001206", "0", "1"]], "ts": "1742377417902", "checksum": -1388102974, "seqId": 49713704906, "prevSeqId": 49713704858}], "record_time": 1742377418.776888}
{"arg": {"channel": "books", "instId": "BTC-USDT"}, "action": "update", "data": [{"asks": [["83475.6", "0.0316628", "0", "3"], ["83475.8", "0.00916", "0", "1"]], "bids": [["83416.9", "0.24553493", "0", "2"], ["83416.8", "0.2025", "0", "1"]], "ts": "1742377418002", "checksum": -2016201277, "seqId": 49713704924, "prevSeqId": 49713704906}], "record_time": 1742377418.869412}
{"arg": {"channel": "books", "instId": "BTC-USDT"}, "action": "update", "data": [{"asks": [["83466.6", "2.27210055", "0", "13"], ["83467.4", "0.10903643", "0", "1"], ["83467.6", "0.15790557", "0", "3"], ["83467.9", "0.0001", "0", "1"], ["83468", "0.17408639", "0", "2"], ["83469.3", "0.0314628", "0", "1"], ["83471.2", "0.0001", "0", "1"], ["83471.9", "0.2396361", "0", "1"], ["83472", "0.0567", "0", "1"], ["83472.1", "0.5315442", "0", "1"], ["83472.2", "0.01694745", "0", "2"], ["83472.3", "0.6745", "0", "4"], ["83472.4", "0.35964043", "0", "1"], ["83472.8", "0.17953568", "0", "1"], ["83474", "1.47126561", "0", "29"], ["83474.1", "0.00001121", "0", "1"], ["83474.2", "0", "0", "0"], ["83475.6", "0", "0", "0"], ["83475.7", "0.04606459", "0", "2"], ["83475.8", "0", "0", "0"], ["83477.8", "0.02748", "0", "1"], ["83477.9", "0.10066786", "0", "1"], ["83478", "0.0567", "0", "1"], ["83478.4", "0.00001206", "0", "1"], ["83478.7", "0.08792548", "0", "1"], ["83479.1", "0.09270358", "0", "1"], ["83479.4", "0.359405", "0", "2"], ["83479.5", "0.11420962", "0", "2"], ["83479.6", "0.35264355", "0", "1"], ["83481.9", "0.30247196", "0", "2"], ["83482.1", "0", "0", "0"], ["83485.7", "0.16752998", "0", "1"], ["83486.1", "0.16424895", "0", "1"], ["83486.6", "0.1640207", "0", "1"], ["83486.8", "0", "0", "0"], ["83487.7", "0.000015", "0", "1"], ["83487.9", "0.16447454", "0", "1"], ["83488", "0.0567", "0", "1"], ["83488.2", "0", "0", "0"], ["83492.7", "0.2379107", "0", "1"], ["83492.8", "0.24575718", "0", "1"], ["83494.7", "0.24339639", "0", "1"], ["83494.9", "0", "0", "0"], ["83495", "0", "0", "0"], ["83495.5", "0.00426766", "0", "1"], ["83496.6", "0.26523418", "0", "1"], ["83501.5", "0", "0", "0"], ["83501.7", "0.11973173", "0", "1"], ["83502", "0.47833808", "0", "2"], ["83503.6", "0", "0", "0"], ["83505.4", "0", "0", "0"], ["83508.8", "0.08", "0", "2"], ["83509.6", "0.03999999", "0", "1"], ["83511.2", "0", "0", "0"], ["83512", "0", "0", "0"], ["83513.9", "0", "0", "0"], ["83518.2", "0.12234755", "0", "1"], ["83525.9", "0.0239442", "0", "1"], ["83528.6", "0.00378045", "0", "1"], ["83531", "0.00013267", "0", "1"], ["83531.1", "0", "0", "0"], ["83531.2", "0", "0", "0"], ["83534.8", "0", "0", "0"], ["83539", "0", "0", "0"], ["83550.9", "0", "0", "0"], ["83556.1", "0", "0", "0"], ["83558.1", "0", "0", "0"], ["83559.8", "0.18658232", "0", "3"], ["83584.4", "0.4566615", "0", "1"], ["83628.5", "0", "0", "0"], ["83628.6", "0", "0", "0"], ["83628.8", "0", "0", "0"], ["83629.4", "0", "0", "0"], ["83629.5", "0", "0", "0"], ["83629.9", "0", "0", "0"], ["83630.2", "0", "0", "0"], ["83630.5", "0", "0", "0"]], "bids": [["83473.9", "0", "0", "0"], ["83472.2", "0", "0", "0"], ["83472.1", "0", "0", "0"], ["83471.4", "0", "0", "0"], ["83470", "0", "0", "0"], ["83467.5", "0", "0", "0"], ["83466.5", "0.07557617", "0", "3"], ["83465.8", "0", "0", "0"], ["83464", "0", "0", "0"], ["83463.4", "0.01667117", "0", "1"], ["83462.6", "0", "0", "0"], ["83462.1", "0.0707896", "0", "3"], ["83462", "0.1941725", "0", "4"], ["83461.6", "0.0001", "0", "1"], ["83461.5", "0", "0", "0"], ["83460.9", "0", "0", "0"], ["83460.8", "0", "0", "0"], ["83460.6", "0.0001", "0", "1"], ["83460.4", "0", "0", "0"], ["83459.9", "0", "0", "0"], ["83459.5", "0.0314628", "0", "1"], ["83457.4", "0.15498357", "0", "1"], ["83457.1", "0", "0", "0"], ["83454.3", "0", "0", "0"], ["83453.9", "0.36439118", "0", "3"], ["83453.4", "0.00001204", "0", "1"], ["83452.9", "0", "0", "0"], ["83452.4", "0.0003", "0", "1"], ["83452.1", "0", "0", "0"], ["83452", "0.15284551", "0", "2"], ["83451.8", "0.01566", "0", "1"], ["83451.4", "0.09997288", "0", "1"], ["83451.1", "0.09893041", "0", "1"], ["83450.8", "0.09256799", "0", "1"], ["83450.7", "0.2025", "0", "1"], ["83449.2", "0.4652951", "0", "2"], ["83448.8", "0", "0", "0"], ["83446.7", "0.01198212", "0", "1"], ["83446.4", "0", "0", "0"], ["83446.2", "0", "0", "0"], ["83445.8", "0.11983573", "0", "1"], ["83445.5", "0.30176415", "0", "2"], ["83445.1", "0.00719036", "0", "1"], ["83445", "0", "0", "0"], ["83444.4", "0.14881022", "0", "1"], ["83444.2", "0", "0", "0"], ["83444.1", "0.15997633", "0", "1"], ["83443.2", "0.16751211", "0", "1"], ["83442.4", "0.02396812", "0", "1"], ["83437.5", "0.24919864", "0", "1"], ["83437.4", "0.24582584", "0", "2"], ["83435.2", "0.23569013", "0", "1"], ["83433.6", "0.46706282", "0", "2"], ["83428.1", "0", "0", "0"], ["83428", "0.00007368", "0", "1"], ["83425.9", "0", "0", "0"], ["83423.2", "0", "0", "0"], ["83422.4", "0.08413328", "0", "3"], ["83421.6", "0.08039996", "0", "3"], ["83418.9", "0.2396361", "0", "1"], ["83416.9", "0.00589947", "0", "1"], ["83408.5", "0", "0", "0"], ["83405.6", "0.01845186", "0", "1"], ["83401.4", "0.00367", "0", "1"], ["83337.4", "0", "0", "0"], ["83334.8", "0.18451869", "0", "1"], ["83325", "0.05558344", "0", "3"], ["83324.6", "0.03", "0", "1"], ["83324.4", "0.2025", "0", "1"], ["83324.3", "0.00088173", "0", "2"], ["83323.7", "0.0132", "0", "1"], ["83323.6", "0.00001079", "0", "1"], ["83322.7", "0.05263157", "0", "1"], ["83322.5", "0.00004003", "0", "1"], ["83322", "0.01198548", "0", "2"]], "ts": "1742377418102", "checksum": -603797443, "seqId": 49713705512, "prevSeqId": 49713704924}], "record_time": 1742377418.970235}
{"arg": {"channel": "books", "instId": "BTC-USDT"}, "action": "update", "data": [{"asks": [["83467.6", "0.15574857", "0", "2"], ["83467.9", "0", "0", "0"], ["83468.9", "0.0002", "0", "2"], ["83471.2", "0", "0", "0"], ["83474", "1.47044626", "0", "27"], ["83474.1", "0", "0", "0"], ["83475.7", "0.09749334", "0", "3"], ["83477.9", "0", "0", "0"], ["83478.2", "0.10013586", "0", "1"], ["83478.7", "0", "0", "0"], ["83479", "0.08965357", "0", "1"], ["83479.1", "0", "0", "0"], ["83479.4", "0.45661314", "0", "3"], ["83479.5", "0.025", "0", "1"], ["83479.8", "0.09610239", "0", "1"], ["83485.7", "0", "0", "0"], ["83486", "0.21141456", "0", "2"], ["83486.1", "0", "0", "0"], ["83486.5", "0.15947184", "0", "1"], ["83486.6", "0", "0", "0"], ["83487", "0.31417326", "0", "3"], ["83487.9", "0", "0", "0"], ["83488.2", "0.15993289", "0", "1"], ["83491.8", "0", "0", "0"], ["83492.7", "0", "0", "0"], ["83492.8", "0", "0", "0"], ["83493", "0.26704446", "0", "1"], ["83493.1", "0.25900174", "0", "1"], ["83493.2", "0.10973142", "0", "2"], ["83494.7", "0", "0", "0"], ["83495", "0.26279571", "0", "1"], ["83496.6", "0", "0", "0"], ["83496.9", "0.2502384", "0", "1"], ["83498.6", "0", "0", "0"], ["83510.4", "0.002157", "0", "1"], ["83516.5", "0.1", "0", "1"], ["83531.7", "0.01219896", "0", "1"], ["83555", "0", "0", "0"], ["83628.5", "0.00001067", "0", "1"], ["83628.6", "0.0000528", "0", "4"], ["83628.8", "0.00001501", "0", "1"], ["83629.4", "0.00001001", "0", "1"]], "bids": [["83466.5", "0.07761617", "0", "4"], ["83463.6", "0.12905442", "0", "1"], ["83461.6", "0", "0", "0"], ["83460.6", "0", "0", "0"], ["83460.5", "0.0001", "0", "1"], ["83460.4", "0.0001", "0", "1"], ["83457.7", "0.25677878", "0", "1"], ["83457.6", "0.17953568", "0", "1"], ["83457.4", "0", "0", "0"], ["83452.3", "0.09138779", "0", "1"], ["83452", "0.05420836", "0", "1"], ["83451.7", "0.09838195", "0", "1"], ["83451.4", "0.0956317", "0", "1"], ["83451.1", "0.09651722", "0", "1"], ["83450.8", "0", "0", "0"], ["83445.7", "0.00361981", "0", "1"], ["83445.5", "0.41959551", "0", "3"], ["83444.7", "0.15805245", "0", "2"], ["83444.5", "0.15777857", "0", "1"], ["83444.4", "0", "0", "0"], ["83444.1", "0", "0", "0"], ["83443.6", "0.14996208", "0", "1"], ["83443.2", "0", "0", "0"], ["83442.7", "0.16284372", "0", "1"], ["83437.8", "0.25167219", "0", "2"], ["83437.7", "0.25761748", "0", "1"], ["83437.5", "0", "0", "0"], ["83437.4", "0.00427082", "0", "1"], ["83435.5", "0.59920008", "0", "2"], ["83435.2", "0", "0", "0"], ["83433.9", "0.26437152", "0", "1"], ["83433.6", "0.2025", "0", "1"], ["83433.1", "0", "0", "0"], ["83430.1", "0.60749384", "0", "2"], ["83424.7", "0.0019939", "0", "2"], ["83424", "0.2", "0", "2"], ["83418.9", "0", "0", "0"], ["83416.9", "0.24553633", "0", "2"], ["83408.6", "0", "0", "0"], ["83405.7", "0.01221188", "0", "1"], ["83402.8", "0.01219896", "0", "1"], ["83401.6", "0.00198627", "0", "1"], ["83389.4", "0", "0", "0"], ["83382.8", "0.00276185", "0", "1"], ["83368.1", "0.58087447", "0", "2"], ["83360.7", "0.000119", "0", "1"], ["83355.8", "0", "0", "0"], ["83355.6", "0", "0", "0"], ["83348", "0.00112962", "0", "1"], ["83323.7", "0", "0", "0"], ["83323.6", "0", "0", "0"], ["83322.7", "0", "0", "0"], ["83322.5", "0", "0", "0"], ["83322", "0", "0", "0"]], "ts": "1742377418202", "checksum": -2008476306, "seqId": 49713705720, "prevSeqId": 49713705512}], "record_time": 1742377419.071972}
{"arg": {"channel": "books", "instId": "BTC-USDT"}, "action": "update", "data": [{"asks": [["83466.6", "2.28126055", "0", "14"], ["83467.4", "0.16814429", "0", "3"], ["83468.8", "0.0023961", "0", "1"], ["83471", "0.23964264", "0", "1"], ["83471.1", "0.02748", "0", "1"], ["83471.9", "0", "0", "0"], ["83472.2", "0.00778745", "0", "1"], ["83473.5", "0.11979615", "0", "1"], ["83473.9", "0.04", "0", "1"], ["83474.7", "0.01197997", "0", "1"], ["83474.8", "0", "0", "0"], ["83475.7", "0.08601761", "0", "2"], ["83477.4", "0.09092677", "0", "1"], ["83477.8", "0", "0", "0"], ["83478.2", "0", "0", "0"], ["83478.3", "0.09910286", "0", "1"], ["83478.5", "0.09503678", "0", "1"], ["83478.9", "0.08988339", "0", "1"], ["83479", "0", "0", "0"], ["83479.4", "0.359405", "0", "2"], ["83479.8", "0", "0", "0"], ["83480.2", "0.03", "0", "1"], ["83482.9", "0", "0", "0"], ["83483.6", "0.03", "0", "1"], ["83484.9", "0.08991011", "0", "1"], ["83485.3", "0.15466449", "0", "1"], ["83485.5", "0.16241366", "0", "1"], ["83486", "0.0567", "0", "1"], ["83486.1", "0.16890311", "0", "1"], ["83486.5", "0", "0", "0"], ["83487", "0.15199316", "0", "2"], ["83487.2", "0.16388449", "0", "1"], ["83488.2", "0", "0", "0"], ["83492.2", "0.2392682", "0", "1"], ["83492.3", "0.25973698", "0", "1"], ["83493", "0", "0", "0"], ["83493.1", "0", "0", "0"], ["83494.2", "0.26059108", "0", "2"], ["83495", "0", "0", "0"], ["83496", "0.24133377", "0", "2"], ["83496.9", "0", "0", "0"], ["83500", "0.22733089", "0", "4"], ["83516.5", "0", "0", "0"], ["83520.5", "0.01465163", "0", "1"], ["83523.8", "0.00013267", "0", "1"], ["83525.8", "0.00378045", "0", "1"], ["83528.6", "0", "0", "0"], ["83531", "0", "0", "0"], ["83603.7", "0.00600246", "0", "2"], ["83614.9", "0", "0", "0"], ["83620.4", "0.02189716", "0", "4"], ["83628.5", "0", "0", "0"], ["83628.6", "0", "0", "0"], ["83628.8", "0", "0", "0"], ["83629.4", "0", "0", "0"]], "bids": [["83466.5", "0.00421617", "0", "3"], ["83463.6", "0", "0", "0"], ["83463.4", "0", "0", "0"], ["83462.7", "0", "0", "0"], ["83462.2", "0.38719758", "0", "3"], ["83462.1", "0.03955669", "0", "3"], ["83462", "0.0587", "0", "2"], ["83460.5", "0", "0", "0"], ["83460.4", "0", "0", "0"], ["83459.4", "0.0001", "0", "1"], ["83459.3", "0.0001", "0", "1"], ["83457.9", "0.15968157", "0", "1"], ["83457.7", "0", "0", "0"], ["83457.6", "0", "0", "0"], ["83456.8", "0.01566", "0", "1"], ["83453.2", "0", "0", "0"], ["83452.7", "0.00001204", "0", "1"], ["83452.3", "0", "0", "0"], ["83451.8", "0", "0", "0"], ["83451.7", "0", "0", "0"], ["83451.5", "0.09915789", "0", "1"], ["83451.4", "0", "0", "0"], ["83451.1", "0", "0", "0"], ["83451", "0.08935497", "0", "1"], ["83450.5", "0.28303352", "0", "5"], ["83450.2", "0.09223979", "0", "1"], ["83448", "0", "0", "0"], ["83446.7", "0.00239673", "0", "1"], ["83445.7", "0", "0", "0"], ["83445.6", "0.01198084", "0", "1"], ["83445.5", "0.4773238", "0", "3"], ["83445.1", "0.02286036", "0", "2"], ["83444.7", "0.00002396", "0", "1"], ["83444.5", "0.01198244", "0", "1"], ["83444", "0.14968227", "0", "2"], ["83443.6", "0", "0", "0"], ["83443.5", "0.15146443", "0", "1"], ["83443", "0.04701", "0", "1"], ["83442.7", "0.14755795", "0", "1"], ["83442.4", "0", "0", "0"], ["83441.7", "0.15624575", "0", "1"], ["83440.1", "0.00001204", "0", "1"], ["83437.8", "0.00001501", "0", "1"], ["83437.7", "0", "0", "0"], ["83437", "0.26769959", "0", "1"], ["83436.9", "0.26672864", "0", "1"], ["83435.5", "0.35972754", "0", "1"], ["83434.7", "0.24450528", "0", "1"], ["83433.9", "0", "0", "0"], ["83433", "0.72994889", "0", "2"], ["83427", "0", "0", "0"], ["83425.8", "0.04", "0", "1"], ["83422.4", "0.08333333", "0", "1"], ["83421.6", "0", "0", "0"], ["83420.8", "0.00002397", "0", "1"], ["83420", "0.05492", "0", "2"], ["83419.2", "0", "0", "0"], ["83418.5", "0.1", "0", "1"], ["83418.4", "0.05990336", "0", "2"], ["83417", "0.02397543", "0", "1"], ["83416.9", "0.00589947", "0", "1"], ["83416.8", "0.2033", "0", "3"], ["83416", "0.08039998", "0", "3"], ["83415.4", "0.23964264", "0", "1"], ["83415.2", "0.14", "0", "3"], ["83414.4", "0.05589947", "0", "2"], ["83413.6", "0.026", "0", "2"], ["83412.8", "0.013", "0", "1"], ["83405.6", "0", "0", "0"], ["83403.8", "0.01845256", "0", "1"], ["83385.6", "1.15479249", "0", "2"], ["83377.9", "0.00008831", "0", "1"], ["83372.4", "0.00723594", "0", "1"], ["83356", "0", "0", "0"], ["83344.8", "0.00599042", "0", "1"], ["83339.3", "0", "0", "0"], ["83334.8", "0", "0", "0"], ["83332.9", "0.18454593", "0", "2"], ["83328.1", "0.01797126", "0", "3"], ["83324.4", "0", "0", "0"], ["83324.3", "0", "0", "0"]], "ts": "1742377418302", "checksum": -2014981861, "seqId": 49713706175, "prevSeqId": 49713705720}], "record_time": 1742377419.16921}
{"arg": {"channel": "books", "instId": "BTC-USDT"}, "action": "update", "data": [{"asks": [["83467.4", "0.09129222", "0", "3"], ["83467.6", "0.11980457", "0", "1"], ["83471", "0", "0", "0"], ["83471.9", "0.23963757", "0", "1"], ["83472.1", "0.79084058", "0", "2"], ["83475.7", "0.13980332", "0", "3"], ["83479.4", "0.000015", "0", "1"], ["83480.3", "0.03", "0", "1"], ["83483.6", "0.09", "0", "3"], ["83488.8", "0", "0", "0"], ["83490", "0", "0", "0"], ["83493.3", "0.035", "0", "2"], ["83508", "0.08", "0", "2"], ["83508.8", "0.03999999", "0", "1"], ["83509.6", "0", "0", "0"], ["83510.8", "0.1", "0", "1"]], "bids": [["83466.5", "0.07761617", "0", "4"], ["83462.1", "0.01", "0", "2"], ["83461.7", "0.00778755", "0", "1"], ["83459.5", "0.0315628", "0", "2"], ["83459.3", "0", "0", "0"], ["83445.6", "0", "0", "0"], ["83443.9", "0.00358495", "0", "1"], ["83424", "0.09999999", "0", "1"], ["83417.1", "0.23963757", "0", "1"], ["83415.4", "0", "0", "0"]], "ts": "1742377418402", "checksum": -1615873253, "seqId": 49713706233, "prevSeqId": 49713706175}], "record_time": 1742377419.269103}
{"arg": {"channel": "books", "instId": "BTC-USDT"}, "action": "update", "data": [{"asks": [["83467.4", "0.0631563", "0", "2"], ["83468", "0.0567", "0", "1"], ["83471.9", "0", "0", "0"], ["83472.1", "0.5315442", "0", "1"], ["83472.3", "0.2545", "0", "3"], ["83472.4", "0.01198084", "0", "1"], ["83473.8", "0.23963549", "0", "1"], ["83474", "1.05044626", "0", "26"], ["83475.5", "0.21554013", "0", "1"], ["83475.7", "0.002", "0", "1"], ["83476.9", "0.35943", "0", "1"], ["83477.4", "0", "0", "0"], ["83478.3", "0", "0", "0"], ["83478.4", "0.09125439", "0", "2"], ["83478.5", "0", "0", "0"], ["83478.9", "0", "0", "0"], ["83479.2", "0.09582239", "0", "1"], ["83479.6", "0.44412444", "0", "2"], ["83480", "0.51582669", "0", "4"], ["83483.6", "0.12", "0", "4"], ["83485.3", "0", "0", "0"], ["83485.5", "0", "0", "0"], ["83486.1", "0", "0", "0"], ["83486.2", "0.15135807", "0", "1"], ["83486.6", "0.15130641", "0", "1"], ["83487.1", "0.16004739", "0", "1"], ["83487.2", "0", "0", "0"], ["83488.4", "0.15673615", "0", "2"], ["83490.1", "0", "0", "0"], ["83490.4", "0", "0", "0"], ["83492.2", "0", "0", "0"], ["83492.3", "0", "0", "0"], ["83493.2", "0.36646328", "0", "3"], ["83493.3", "0.24244302", "0", "2"], ["83494.2", "0.005", "0", "1"], ["83495.2", "0.26274046", "0", "1"], ["83496", "0.000015", "0", "1"], ["83497.1", "0.26388643", "0", "1"], ["83628.5", "0.00001067", "0", "1"], ["83628.6", "0.0000528", "0", "4"], ["83628.8", "0.00001501", "0", "1"], ["83629.4", "0.00001001", "0", "1"]], "bids": [["83464.2", "0.14161957", "0", "2"], ["83462.8", "0.0001", "0", "1"], ["83462.7", "0.0001", "0", "1"], ["83462.3", "0.42", "0", "1"], ["83462.2", "0", "0", "0"], ["83461.1", "0.11981388", "0", "1"], ["83459.5", "0.0314628", "0", "1"], ["83459.4", "0", "0", "0"], ["83452.5", "0.09169629", "0", "1"], ["83451.9", "0.09532741", "0", "1"], ["83451.6", "0.09159113", "0", "1"], ["83451.5", "0", "0", "0"], ["83451.3", "0.45099179", "0", "2"], ["83451", "0", "0", "0"], ["83450.5", "0.189", "0", "4"], ["83450.2", "0", "0", "0"], ["83447.4", "0.000015", "0", "1"], ["83445.5", "0.49143507", "0", "3"], ["83444.9", "0.15676546", "0", "1"], ["83444.6", "0.16438491", "0", "1"], ["83444", "0.00001", "0", "1"], ["83443.7", "0.1684301", "0", "1"], ["83443.5", "0", "0", "0"], ["83442.9", "0.15881257", "0", "1"], ["83442.7", "0", "0", "0"], ["83441.7", "0", "0", "0"], ["83438", "0.2380373", "0", "1"], ["83437.9", "0.24410592", "0", "1"], ["83437", "0", "0", "0"], ["83436.9", "0", "0", "0"], ["83435.7", "0.24324414", "0", "1"], ["83434.7", "0", "0", "0"], ["83434.1", "0.26424575", "0", "1"], ["83433", "0.48724", "0", "1"], ["83418.3", "0.39920634", "0", "2"], ["83417.1", "0", "0", "0"], ["83328.1", "0", "0", "0"], ["83326.8", "0", "0", "0"], ["83325", "0", "0", "0"], ["83324.6", "0", "0", "0"]], "ts": "1742377418502", "checksum": -688438171, "seqId": 49713706406, "prevSeqId": 49713706233}], "record_time": 1742377419.36946}
{"arg": {"channel": "books", "instId": "BTC-USDT"}, "action": "update", "data": [{"asks": [["83468.9", "0", "0", "0"], ["83469.5", "0.0002", "0", "2"], ["83473.4", "0.00001206", "0", "1"], ["83493.1", "0.30021165", "0", "1"], ["83496.4", "0.01219896", "0", "1"], ["83525.9", "0.11280294", "0", "2"], ["83531.7", "0", "0", "0"], ["83628.8", "0", "0", "0"], ["83629.4", "0", "0", "0"]], "bids": [["83462.8", "0.0002", "0", "2"], ["83462.7", "0", "0", "0"], ["83426.6", "0.38160056", "0", "1"], ["83424", "0", "0", "0"], ["83328.1", "0.01797126", "0", "3"]], "ts": "1742377418602", "checksum": 1554209454, "seqId": 49713706431, "prevSeqId": 49713706406}], "record_time": 1742377419.469385}
{"arg": {"channel": "books", "instId": "BTC-USDT"}, "action": "update", "data": [{"asks": [["83479.6", "0.35264355", "0", "1"], ["83479.7", "0.14098748", "0", "2"], ["83486.6", "0", "0", "0"], ["83486.7", "0.16230488", "0", "1"], ["83497.1", "0", "0", "0"], ["83497.2", "0.23745117", "0", "1"]], "bids": [["83466.5", "0.08261617", "0", "5"], ["83451.7", "0.097447", "0", "1"], ["83451.6", "0", "0", "0"], ["83444.7", "0.14645536", "0", "2"], ["83444.6", "0", "0", "0"], ["83434.2", "0.25554828", "0", "2"], ["83434.1", "0", "0", "0"], ["83326.8", "0.00001206", "0", "1"], ["83325", "0.05558344", "0", "3"]], "ts": "1742377418702", "checksum": 998500965, "seqId": 49713706455, "prevSeqId": 49713706431}], "record_time": 1742377419.568825}
{"arg": {"channel": "books", "instId": "BTC-USDT"}, "action": "update", "data": [{"asks": [["83466.6", "1.52235055", "0", "9"], ["83469.3", "0.00916", "0", "1"], ["83471.1", "0", "0", "0"], ["83472.3", "0.2339628", "0", "2"], ["83472.4", "0", "0", "0"], ["83472.8", "0", "0", "0"], ["83473.8", "0", "0", "0"], ["83474", "0.99844626", "0", "24"], ["83475.3", "0.24409697", "0", "1"], ["83475.5", "0.02748", "0", "1"], ["83477.9", "0.23962429", "0", "1"], ["83478.4", "0.00001206", "0", "1"], ["83479.2", "0", "0", "0"], ["83479.6", "0.25072529", "0", "1"], ["83479.7", "0.04", "0", "1"], ["83480", "0.05674", "0", "2"], ["83484.9", "0", "0", "0"], ["83486.2", "0", "0", "0"], ["83486.7", "0", "0", "0"], ["83487.1", "0", "0", "0"], ["83488.4", "0.00001206", "0", "1"], ["83493", "0.01219896", "0", "1"], ["83493.1", "0", "0", "0"], ["83493.2", "0.10973142", "0", "2"], ["83493.3", "0.005", "0", "1"], ["83495.2", "0", "0", "0"], ["83496.4", "0", "0", "0"], ["83497.2", "0", "0", "0"], ["83504.9", "0", "0", "0"], ["83628.8", "0.00001501", "0", "1"], ["83629.4", "0.00001001", "0", "1"], ["83629.5", "0.00437872", "0", "2"], ["83629.9", "0.00002782", "0", "1"], ["83630.2", "0.00428793", "0", "3"], ["83630.5", "0.00003988", "0", "1"], ["83630.6", "0.00011142", "0", "1"], ["83630.7", "0.0000484", "0", "1"], ["83630.8", "0.00110397", "0", "1"], ["83630.9", "0.11992025", "0", "1"], ["83631.1", "0.00001167", "0", "1"]], "bids": [["83466.5", "0.60282663", "0", "10"], ["83466", "0.0567", "0", "1"], ["83464.3", "0.12160813", "0", "1"], ["83464.2", "0.00005282", "0", "1"], ["83464", "0.0567", "0", "1"], ["83463.5", "0.1198225", "0", "2"], ["83463.2", "0.0001", "0", "1"], ["83463.1", "0.0001", "0", "1"], ["83462.9", "0.0314628", "0", "1"], ["83462.8", "0", "0", "0"], ["83462.4", "0.19677712", "0", "1"], ["83461.1", "0", "0", "0"], ["83459.5", "0", "0", "0"], ["83458", "0.17953568", "0", "1"], ["83452.5", "0", "0", "0"], ["83451.9", "0", "0", "0"], ["83451.7", "0", "0", "0"], ["83451.3", "0.36038", "0", "1"], ["83449.5", "0.01566", "0", "1"], ["83447.1", "0.01198206", "0", "1"], ["83445.5", "0.44281527", "0", "3"], ["83445.1", "0.00719036", "0", "1"], ["83444.9", "0", "0", "0"], ["83444.7", "0.00002396", "0", "1"], ["83444.5", "0", "0", "0"], ["83443.7", "0", "0", "0"], ["83442.9", "0", "0", "0"], ["83438", "0", "0", "0"], ["83437.9", "0", "0", "0"], ["83435.7", "0", "0", "0"], ["83434.2", "0.00011142", "0", "1"], ["83420.5", "0.2396306", "0", "1"], ["83418.3", "0.15957085", "0", "1"], ["83413.6", "0", "0", "0"], ["83412.8", "0.026", "0", "2"], ["83412", "0.013", "0", "1"], ["83324.6", "0.03", "0", "1"], ["83324.3", "0.00088173", "0", "2"]], "ts": "1742377418802", "checksum": -945518265, "seqId": 49713706608, "prevSeqId": 49713706455}], "record_time": 1742377419.670133}
{"arg": {"channel": "books", "instId": "BTC-USDT"}, "action": "update", "data": [{"asks": [["83466.6", "1.00307429", "0", "6"], ["83469.5", "0", "0", "0"], ["83471.3", "0.0001", "0", "1"], ["83471.4", "0.0001", "0", "1"], ["83475.3", "0.15249359", "0", "1"], ["83477.9", "0", "0", "0"], ["83479.3", "0.45429155", "0", "2"], ["83479.4", "0.33316134", "0", "3"], ["83479.6", "0", "0", "0"], ["83480.3", "0.12409862", "0", "2"], ["83480.5", "0.0925026", "0", "1"], ["83480.8", "0.09385551", "0", "1"], ["83487.3", "0.15867005", "0", "1"], ["83487.5", "0.16083217", "0", "1"], ["83488.1", "0.15878456", "0", "1"], ["83489.2", "0.15772543", "0", "1"], ["83494.1", "0.25556577", "0", "1"], ["83494.3", "0.24307624", "0", "1"], ["83496.2", "0.23647097", "0", "1"], ["83498", "0.25032605", "0", "2"], ["83629.5", "0", "0", "0"], ["83629.9", "0", "0", "0"], ["83630.2", "0", "0", "0"], ["83630.5", "0", "0", "0"], ["83630.6", "0", "0", "0"], ["83630.7", "0", "0", "0"], ["83630.8", "0", "0", "0"], ["83630.9", "0", "0", "0"], ["83631.1", "0", "0", "0"]], "bids": [["83466.5", "0.65756441", "0", "13"], ["83464.3", "0.0791381", "0", "1"], ["83463.3", "0.05565555", "0", "2"], ["83463.1", "0", "0", "0"], ["83454.5", "0.00012439", "0", "2"], ["83453.5", "0.0986221", "0", "1"], ["83453", "0.0962519", "0", "1"], ["83452.5", "0.0903821", "0", "1"], ["83452.1", "0.09801533", "0", "1"], ["83447.4", "0", "0", "0"], ["83447.1", "0", "0", "0"], ["83446", "0.15527465", "0", "1"], ["83445.5", "0.46608205", "0", "3"], ["83444.7", "0.15833264", "0", "2"], ["83443.7", "0.16718931", "0", "1"], ["83439", "0.24645442", "0", "1"], ["83438.8", "0.25096323", "0", "1"], ["83436.7", "0.26309377", "0", "1"], ["83435", "0.2495211", "0", "1"], ["83422.5", "0.23962238", "0", "1"], ["83420.5", "0", "0", "0"], ["83413.6", "0.026", "0", "2"], ["83412.8", "0.013", "0", "1"], ["83412", "0", "0", "0"], ["83328.4", "0", "0", "0"], ["83328.3", "0", "0", "0"], ["83328.1", "0", "0", "0"], ["83326.8", "0", "0", "0"], ["83325", "0", "0", "0"], ["83324.6", "0", "0", "0"], ["83324.3", "0", "0", "0"]], "ts": "1742377418902", "checksum": 864871095, "seqId": 49713706690, "prevSeqId": 49713706608}], "record_time": 1742377419.770074}
{"arg": {"channel": "books", "instId": "BTC-USDT"}, "action": "update", "data": [{"asks": [["83466.6", "1.00296407", "0", "6"], ["83469.2", "0.0001", "0", "1"], ["83469.3", "0.00926", "0", "2"], ["83471.3", "0", "0", "0"], ["83471.4", "0", "0", "0"], ["83476.8", "0.23962448", "0", "1"], ["83479.4", "0.09353896", "0", "2"], ["83483.5", "0.16224935", "0", "1"], ["83484.8", "0", "0", "0"], ["83493", "0", "0", "0"], ["83495.8", "0.01219896", "0", "1"], ["83507.2", "0.08", "0", "2"], ["83508", "0.03999999", "0", "1"], ["83508.8", "0", "0", "0"], ["83514", "0", "0", "0"], ["83629.5", "0.00437872", "0", "2"], ["83629.9", "0.00002782", "0", "1"]], "bids": [["83466.5", "0.63893615", "0", "12"], ["83465.2", "0.0001", "0", "1"], ["83464.9", "0.0001", "0", "1"], ["83463.3", "0.05555555", "0", "1"], ["83463.2", "0", "0", "0"], ["83430.1", "0.00427258", "0", "1"], ["83429.9", "0", "0", "0"], ["83422.5", "0", "0", "0"], ["83420.5", "0.23962448", "0", "1"], ["83402.7", "2.05037485", "0", "2"], ["83400.7", "0", "0", "0"], ["83328.4", "0.00001206", "0", "1"]], "ts": "1742377419002", "checksum": -1270517530, "seqId": 49713706731, "prevSeqId": 49713706690}], "record_time": 1742377419.869649}
{"arg": {"channel": "books", "instId": "BTC-USDT"}, "action": "update", "data": [{"asks": [["83468", "0.0568", "0", "2"], ["83469.2", "0", "0", "0"], ["83469.3", "0", "0", "0"], ["83469.4", "0.0001", "0", "1"], ["83472.1", "0.36335947", "0", "1"], ["83472.3", "0.0314628", "0", "1"], ["83472.4", "0.00916", "0", "1"], ["83479.3", "0.77974161", "0", "2"], ["83479.4", "1.64222716", "0", "3"], ["83493", "0.1", "0", "1"], ["83498", "1.25032605", "0", "3"], ["83508.6", "2.7808212", "0", "1"], ["83629.5", "0", "0", "0"], ["83629.9", "0", "0", "0"]], "bids": [["83466.5", "0.63844874", "0", "12"], ["83466.3", "0.2521481", "0", "1"], ["83466.2", "0.52", "0", "1"], ["83464.9", "0", "0", "0"], ["83464.3", "0", "0", "0"], ["83462.8", "0.0001", "0", "1"], ["83452.7", "0.01567204", "0", "2"], ["83449.5", "0", "0", "0"], ["83433", "1.48724", "0", "2"], ["83428.3", "1.55895952", "0", "1"], ["83416.8", "0.20329998", "0", "3"], ["83399.1", "2.81341879", "0", "1"], ["83328.7", "0", "0", "0"], ["83328.4", "0", "0", "0"]], "ts": "1742377419102", "checksum": -1677956333, "seqId": 49713706776, "prevSeqId": 49713706731}], "record_time": 1742377419.969456}
{"arg": {"channel": "books", "instId": "BTC-USDT"}, "action": "update", "data": [{"asks": [["83466.6", "0.99076429", "0", "5"], ["83467.4", "0.00071271", "0", "1"], ["83468", "0.0569", "0", "3"], ["83469.4", "0", "0", "0"], ["83472.1", "0", "0", "0"], ["83472.3", "0", "0", "0"], ["83475.3", "0.31323749", "0", "2"], ["83475.5", "0.0589428", "0", "2"], ["83475.9", "0.23962644", "0", "1"], ["83476.8", "0", "0", "0"], ["83479.2", "0.35972754", "0", "1"], ["83479.3", "0.79172245", "0", "3"], ["83629.5", "0.00437872", "0", "2"], ["83629.9", "0.00002782", "0", "1"]], "bids": [["83466.5", "0.84095874", "0", "14"], ["83465.9", "0.0314628", "0", "1"], ["83465.2", "0", "0", "0"], ["83462.9", "0", "0", "0"], ["83462.8", "0.0002", "0", "2"], ["83435.7", "0.01219896", "0", "1"], ["83402.8", "0", "0", "0"], ["83328.7", "0.11992025", "0", "1"]], "ts": "1742377419202", "checksum": 1194734999, "seqId": 49713706815, "prevSeqId": 49713706776}], "record_time": 1742377420.069507}
{"arg": {"channel": "books", "instId": "BTC-USDT"}, "action": "update", "data": [{"asks": [["83468", "0.0568", "0", "2"], ["83468.3", "0.0001", "0", "1"], ["83473.9", "0.34364193", "0", "2"], ["83475.3", "0.21475866", "0", "1"], ["83479.2", "0", "0", "0"], ["83479.3", "0.77974161", "0", "2"], ["83481.2", "0", "0", "0"], ["83630.2", "0.00428793", "0", "3"]], "bids": [["83433", "0.48724", "0", "1"]], "ts": "1742377419302", "checksum": -1593482153, "seqId": 49713706845, "prevSeqId": 49713706815}], "record_time": 1742377420.169902}
{"arg": {"channel": "books", "instId": "BTC-USDT"}, "action": "update", "data": [{"asks": [["83467.4", "0", "0", "0"], ["83467.5", "0.0537302", "0", "1"], ["83468", "0.0567", "0", "1"], ["83468.3", "0.0002", "0", "2"], ["83479", "0.132718", "0", "1"], ["83493", "0", "0", "0"], ["83498", "0.25032605", "0", "2"]], "bids": [["83462.8", "0", "0", "0"], ["83462.6", "0.0002", "0", "2"], ["83435.7", "0", "0", "0"], ["83402.8", "0.01219896", "0", "1"]], "ts": "1742377419402", "checksum": -155591914, "seqId": 49713706863, "prevSeqId": 49713706845}], "record_time": 1742377420.269413}
{"arg": {"channel": "books", "instId": "BTC-USDT"}, "action": "update", "data": [{"asks": [["83467.9", "0.0001", "0", "1"], ["83468.3", "0.0001", "0", "1"], ["83475.3", "0.35502419", "0", "2"], ["83475.5", "0.0314628", "0", "1"], ["83479.2", "0.36077754", "0", "2"], ["83480.4", "0.02748", "0", "1"], ["83629.5", "0", "0", "0"], ["83629.9", "0", "0", "0"], ["83630.2", "0", "0", "0"]], "bids": [["83466.5", "1.26095874", "0", "15"], ["83466.4", "0.42", "0", "1"], ["83462.8", "0.0002", "0", "2"], ["83462.6", "0", "0", "0"], ["83462.4", "0.02539412", "0", "1"], ["83462.3", "0", "0", "0"], ["83448.1", "0.047", "0", "1"], ["83443", "0", "0", "0"]], "ts": "1742377419502", "checksum": 223312537, "seqId": 49713706892, "prevSeqId": 49713706863}], "record_time": 1742377420.37052}
{"arg": {"channel": "books", "instId": "BTC-USDT"}, "action": "update", "data": [{"asks": [["83467.5", "0.05444541", "0", "2"], ["83468", "0.0568", "0", "2"], ["83468.3", "0", "0", "0"], ["83504.4", "1.27723655", "0", "1"], ["83534.8", "1.07775826", "0", "1"], ["83566.6", "0.09085179", "0", "3"], ["83594.7", "0", "0", "0"], ["83629.5", "0.00437872", "0", "2"]], "bids": [["83438.7", "0.00877548", "0", "1"], ["83428.4", "0.93428789", "0", "2"], ["83428", "0.10007368", "0", "2"], ["83426.6", "0", "0", "0"], ["83399.3", "0.94468471", "0", "3"], ["83332.2", "0", "0", "0"], ["83328.4", "0.00001206", "0", "1"]], "ts": "1742377419602", "checksum": -1059498459, "seqId": 49713706924, "prevSeqId": 49713706892}], "record_time": 1742377420.471373}
{"arg": {"channel": "books", "instId": "BTC-USDT"}, "action": "update", "data": [{"asks": [["83466.6", "0.3923398", "0", "2"], ["83467.9", "0", "0", "0"], ["83468", "0.0567", "0", "1"], ["83468.2", "0.0002", "0", "2"], ["83472.4", "0", "0", "0"], ["83473.9", "0.25157193", "0", "2"], ["83474", "0.69154626", "0", "10"], ["83475.2", "0.00916", "0", "1"], ["83475.3", "0.21475866", "0", "1"], ["83479.2", "0", "0", "0"], ["83574.4", "0", "0", "0"], ["83629.9", "0.00002782", "0", "1"], ["83630.2", "0.00428793", "0", "3"]], "bids": [["83463.3", "0.05575555", "0", "3"], ["83462.8", "0", "0", "0"], ["83455.4", "0.01566", "0", "1"], ["83452.7", "0.00001204", "0", "1"]], "ts": "1742377419802", "checksum": -84425101, "seqId": 49713706971, "prevSeqId": 49713706924}], "record_time": 1742377420.670024}
{"arg": {"channel": "books", "instId": "BTC-USDT"}, "action": "update", "data": [{"asks": [["83466.6", "0", "0", "0"], ["83467.5", "0", "0", "0"], ["83468", "0", "0", "0"], ["83468.2", "0", "0", "0"], ["83469.9", "0.0001", "0", "1"], ["83470", "0.0567", "0", "1"], ["83470.4", "0.01097934", "0", "1"], ["83470.6", "0.0001", "0", "1"], ["83473.9", "0.21157193", "0", "1"], ["83474", "0.63557252", "0", "9"], ["83475.2", "0", "0", "0"], ["83475.5", "0", "0", "0"], ["83475.9", "0", "0", "0"], ["83476", "0.0967", "0", "2"], ["83477.7", "0", "0", "0"], ["83479.3", "0.39534673", "0", "2"], ["83479.4", "0.000015", "0", "1"], ["83480.3", "0.03", "0", "1"], ["83480.4", "0", "0", "0"], ["83480.5", "0", "0", "0"], ["83480.8", "0", "0", "0"], ["83481.5", "0.23960925", "0", "1"], ["83481.6", "0.08843307", "0", "1"], ["83481.7", "0.05597374", "0", "1"], ["83482", "0.0881628", "0", "2"], ["83482.3", "0.09573265", "0", "2"], ["83482.7", "0.08927031", "0", "1"], ["83482.8", "0.09124733", "0", "1"], ["83487.2", "0.02748", "0", "1"], ["83487.3", "0", "0", "0"], ["83487.5", "0", "0", "0"], ["83488.1", "0", "0", "0"], ["83489.2", "0", "0", "0"], ["83489.4", "0.14822726", "0", "1"], ["83489.8", "0.16545728", "0", "1"], ["83490.3", "0.35894135", "0", "2"], ["83491.1", "0.1592617", "0", "1"], ["83494.1", "0", "0", "0"], ["83494.3", "0", "0", "0"], ["83496", "0.24920107", "0", "2"], ["83496.2", "0", "0", "0"], ["83496.8", "0.26631079", "0", "1"], ["83497.7", "0", "0", "0"], ["83498", "0.0055", "0", "1"], ["83498.4", "0.26588797", "0", "2"], ["83499.8", "0.62633118", "0", "2"], ["83501.6", "0", "0", "0"], ["83507.2", "0", "0", "0"], ["83507.6", "0.11858075", "0", "1"], ["83508", "0", "0", "0"], ["83508.8", "0.07999999", "0", "2"], ["83509.6", "0.03999999", "0", "1"], ["83510.8", "0", "0", "0"], ["83515.2", "0.02960533", "0", "1"], ["83516.7", "0.02743036", "0", "1"], ["83589.9", "0.13356491", "0", "1"], ["83630.5", "0.00003988", "0", "1"], ["83630.6", "0.00011142", "0", "1"], ["83630.7", "0.0000484", "0", "1"]], "bids": [["83467.5", "1.75687922", "0", "18"], ["83467.4", "0.73082444", "0", "5"], ["83466.8", "0.0001", "0", "1"], ["83466.6", "0.35972754", "0", "1"], ["83466.5", "0.68344828", "0", "11"], ["83466.4", "0", "0", "0"], ["83466.3", "0", "0", "0"], ["83463.5", "0.00001206", "0", "1"], ["83463.3", "0.05555555", "0", "1"], ["83462.4", "0.04919289", "0", "2"], ["83459.9", "0.05420836", "0", "1"], ["83459", "0.09769697", "0", "2"], ["83457.9", "0.26967845", "0", "2"], ["83455.7", "0.091122", "0", "1"], ["83455.5", "0.09361718", "0", "1"], ["83454.9", "0.047", "0", "1"], ["83454.5", "0.00003889", "0", "1"], ["83454.3", "0.09834393", "0", "1"], ["83454", "0.08744715", "0", "1"], ["83453.5", "0", "0", "0"], ["83453", "0", "0", "0"], ["83452.5", "0", "0", "0"], ["83452.1", "0", "0", "0"], ["83452", "0", "0", "0"], ["83449.2", "0.5990403", "0", "3"], ["83448.5", "0.15461068", "0", "1"], ["83448.1", "0", "0", "0"], ["83447.4", "0.1602875", "0", "1"], ["83447", "0", "0", "0"], ["83446.9", "0.17027353", "0", "2"], ["83446.1", "0.00720527", "0", "2"], ["83446", "0", "0", "0"], ["83445.6", "0.15866978", "0", "1"], ["83445.5", "0.30176415", "0", "2"], ["83445.1", "0", "0", "0"], ["83444.7", "0.00002396", "0", "1"], ["83443.7", "0", "0", "0"], ["83441.5", "0.23803444", "0", "1"], ["83440.7", "0.2611307", "0", "1"], ["83440.4", "0.08991011", "0", "1"], ["83439", "0", "0", "0"], ["83438.9", "0.24640273", "0", "1"], ["83438.8", "0", "0", "0"], ["83436.8", "0.26130736", "0", "1"], ["83436.7", "0", "0", "0"], ["83435", "0", "0", "0"], ["83428", "0.00007368", "0", "1"], ["83426.6", "0.23960925", "0", "1"], ["83420.5", "0", "0", "0"], ["83418.5", "0", "0", "0"], ["83328.4", "0", "0", "0"]], "ts": "1742377419902", "checksum": 997557619, "seqId": 49713707340, "prevSeqId": 49713706971}], "record_time": 1742377420.769979}
{"arg": {"channel": "books", "instId": "BTC-USDT"}, "action": "update", "data": [{"asks": [["83469.5", "0.0002", "0", "2"], ["83469.9", "0", "0", "0"], ["83470.6", "0", "0", "0"], ["83478.9", "0.23961429", "0", "1"], ["83479.3", "0.84629832", "0", "1"], ["83479.4", "1.55679943", "0", "2"], ["83481.4", "0.00916", "0", "1"], ["83481.5", "0", "0", "0"], ["83490.8", "0.35973754", "0", "2"], ["83598.9", "0.03", "0", "1"], ["83630.7", "0", "0", "0"]], "bids": [["83467.5", "1.63810794", "0", "17"], ["83466.8", "0", "0", "0"], ["83466.5", "0.68354828", "0", "12"], ["83459.9", "0.06986836", "0", "2"], ["83458", "0.18058568", "0", "2"], ["83457.7", "0.02956077", "0", "1"], ["83455.4", "0", "0", "0"], ["83426.6", "0", "0", "0"], ["83422.5", "0.23961429", "0", "1"], ["83419.4", "0.595954", "0", "2"], ["83328.4", "0.00001206", "0", "1"]], "ts": "1742377420002", "checksum": 1643164403, "seqId": 49713707382, "prevSeqId": 49713707340}], "record_time": 1742377420.869914}
{"arg": {"channel": "books", "instId": "BTC-USDT"}, "action": "update", "data": [{"asks": [["83469.5", "0", "0", "0"], ["83469.6", "0.0001", "0", "1"], ["83469.7", "0.0001", "0", "1"], ["83473.5", "0", "0", "0"], ["83478.9", "0.23961399", "0", "1"], ["83482.3", "0.09558265", "0", "1"], ["83482.8", "0", "0", "0"], ["83482.9", "0.09007852", "0", "1"], ["83484.9", "0.0013305", "0", "1"], ["83489.8", "0", "0", "0"], ["83489.9", "0.14801355", "0", "1"], ["83490.3", "0.2025", "0", "1"], ["83490.4", "0.14760195", "0", "1"], ["83491", "0.11977102", "0", "1"], ["83496.8", "0", "0", "0"], ["83496.9", "0.25899027", "0", "1"], ["83511.8", "0.1", "0", "1"], ["83523.8", "0", "0", "0"], ["83525.7", "0.00013267", "0", "1"], ["83525.8", "0", "0", "0"], ["83528.6", "0.00378258", "0", "1"], ["83629.9", "0", "0", "0"], ["83630.2", "0", "0", "0"], ["83630.5", "0", "0", "0"], ["83630.6", "0", "0", "0"]], "bids": [["83467.5", "1.75791265", "0", "18"], ["83466.5", "0.67649828", "0", "9"], ["83459", "0.00778686", "0", "1"], ["83455.6", "0.09787305", "0", "1"], ["83455.5", "0", "0", "0"], ["83448.6", "0.1658606", "0", "1"], ["83448.5", "0", "0", "0"], ["83447", "0.15715546", "0", "1"], ["83446.9", "0.01198396", "0", "1"], ["83441.6", "0.26101464", "0", "1"], ["83441.5", "0", "0", "0"], ["83422.5", "0.23961399", "0", "1"], ["83419.4", "0.495954", "0", "1"], ["83405.8", "0.01844981", "0", "1"], ["83405.7", "0", "0", "0"], ["83403.8", "0", "0", "0"], ["83402.7", "2.05236097", "0", "3"], ["83401.6", "0", "0", "0"], ["83379.2", "0.00008831", "0", "1"], ["83377.9", "0", "0", "0"], ["83334.8", "0.18449812", "0", "1"], ["83332.9", "0.00002031", "0", "1"]], "ts": "1742377420102", "checksum": -2011751509, "seqId": 49713707493, "prevSeqId": 49713707382}], "record_time": 1742377420.969211}
{"arg": {"channel": "books", "instId": "BTC-USDT"}, "action": "update", "data": [{"asks": [["83467.6", "0", "0", "0"], ["83468.8", "0", "0", "0"], ["83469.6", "0", "0", "0"], ["83469.7", "0", "0", "0"], ["83469.8", "0.11980148", "0", "1"], ["83472", "0.0568", "0", "2"], ["83472.2", "0", "0", "0"], ["83472.7", "0.0001", "0", "1"], ["83473.5", "0.00778734", "0", "1"], ["83479.2", "0.00916", "0", "1"], ["83481.4", "0", "0", "0"], ["83481.6", "0", "0", "0"], ["83482.3", "0", "0", "0"], ["83482.7", "0", "0", "0"], ["83482.9", "0", "0", "0"], ["83483.2", "0.09955248", "0", "1"], ["83483.7", "0", "0", "0"], ["83484", "0.1481448", "0", "2"], ["83484.2", "0.01416", "0", "2"], ["83484.4", "0.18477762", "0", "2"], ["83484.9", "0", "0", "0"], ["83489.4", "0", "0", "0"], ["83489.9", "0", "0", "0"], ["83490.2", "0.38084741", "0", "2"], ["83490.4", "0", "0", "0"], ["83491", "0.28285162", "0", "2"], ["83491.1", "0", "0", "0"], ["83491.4", "0.16098224", "0", "1"], ["83491.9", "0.15306646", "0", "1"], ["83492.7", "0.15406121", "0", "1"], ["83496", "0.000015", "0", "1"], ["83496.9", "0", "0", "0"], ["83497.7", "0.26009255", "0", "1"], ["83498.4", "0.26044167", "0", "2"], ["83499.8", "0.35972754", "0", "1"], ["83500", "0.47040022", "0", "5"], ["83501.5", "0.2522043", "0", "1"], ["83508.8", "0", "0", "0"], ["83509.6", "0", "0", "0"], ["83510.4", "0.08215699", "0", "3"], ["83511.2", "0.03999999", "0", "1"], ["83511.8", "0", "0", "0"], ["83528.6", "0", "0", "0"], ["83531.2", "0.00378288", "0", "1"], ["83589.9", "0", "0", "0"], ["83629.9", "0.00002782", "0", "1"], ["83630.2", "0.00428793", "0", "3"], ["83630.5", "0.00003988", "0", "1"], ["83630.6", "0.00011142", "0", "1"], ["83630.7", "0.0000484", "0", "1"], ["83630.8", "0.00110397", "0", "1"], ["83630.9", "0.11992025", "0", "1"], ["83631.1", "0.00001167", "0", "1"], ["83631.4", "0.00048794", "0", "12"]], "bids": [["83469.7", "0.97508714", "0", "12"], ["83469", "0.11980251", "0", "1"], ["83468.9", "0.32033958", "0", "1"], ["83468.7", "0.5034628", "0", "4"], ["83468.4", "0.0001", "0", "1"], ["83468.3", "0.0001", "0", "1"], ["83468", "0.0567", "0", "1"], ["83467.5", "0.42", "0", "1"], ["83467.4", "0.10169672", "0", "3"], ["83466.6", "0.64335315", "0", "2"], ["83466.5", "0.25629828", "0", "6"], ["83465.9", "0", "0", "0"], ["83458", "0.17953568", "0", "1"], ["83457.9", "0.27615659", "0", "2"], ["83457.3", "0.46074622", "0", "2"], ["83457.1", "0.09417705", "0", "1"], ["83456", "0.09132794", "0", "1"], ["83455.7", "0.09169962", "0", "1"], ["83455.6", "0", "0", "0"], ["83454.3", "0", "0", "0"], ["83454", "0", "0", "0"], ["83450.1", "0.1603604", "0", "1"], ["83449.2", "0.4652951", "0", "2"], ["83449", "0.14776374", "0", "1"], ["83448.6", "0", "0", "0"], ["83448.5", "0.16109618", "0", "1"], ["83448.3", "0.00719008", "0", "1"], ["83447.4", "0", "0", "0"], ["83447.2", "0.16644994", "0", "1"], ["83447", "0", "0", "0"], ["83446.1", "0.000015", "0", "1"], ["83445.6", "0", "0", "0"], ["83443.1", "0.23864057", "0", "1"], ["83442.4", "0.25553858", "0", "1"], ["83441.6", "0", "0", "0"], ["83440.7", "0", "0", "0"], ["83440.5", "0.26027317", "0", "1"], ["83438.9", "0", "0", "0"], ["83438.5", "0.26370647", "0", "1"], ["83436.8", "0", "0", "0"], ["83408", "0.01845022", "0", "1"], ["83405.8", "0", "0", "0"], ["83403.8", "0.00198612", "0", "1"], ["83402.7", "2.05037485", "0", "2"], ["83350.6", "0.00112953", "0", "1"], ["83348", "0", "0", "0"], ["83337.2", "0.18450222", "0", "1"], ["83334.8", "0", "0", "0"], ["83330.6", "0", "0", "0"], ["83330.1", "0", "0", "0"], ["83329.7", "0", "0", "0"], ["83329.3", "0", "0", "0"], ["83328.8", "0", "0", "0"], ["83328.7", "0", "0", "0"], ["83328.4", "0", "0", "0"]], "ts": "1742377420202", "checksum": 223670805, "seqId": 49713707826, "prevSeqId": 49713707493}], "record_time": 1742377421.073848}
{"arg": {"channel": "books", "instId": "BTC-USDT"}, "action": "update", "data": [{"asks": [["83469.8", "0.12219755", "0", "2"], ["83471.8", "0.0002", "0", "2"], ["83472", "0.0567", "0", "1"], ["83472.7", "0", "0", "0"], ["83478.9", "0.0314628", "0", "1"], ["83482", "0.0567", "0", "1"], ["83483.1", "0.23961139", "0", "1"], ["83495.8", "0", "0", "0"], ["83496.4", "0.01219896", "0", "1"], ["83528.9", "0.00378288", "0", "1"], ["83531.2", "0", "0", "0"], ["83631.4", "0", "0", "0"]], "bids": [["83469.7", "0.85638258", "0", "11"], ["83469.5", "0.0002", "0", "2"], ["83468.4", "0", "0", "0"], ["83468.3", "0", "0", "0"], ["83436", "1", "0", "1"], ["83425.9", "0.23961139", "0", "1"], ["83422.5", "0", "0", "0"], ["83420.7", "0.10427296", "0", "2"], ["83408", "0", "0", "0"], ["83405.6", "0.01844995", "0", "1"], ["83384.1", "0.0027609", "0", "1"], ["83382.8", "0", "0", "0"], ["83337.2", "0", "0", "0"], ["83336.6", "0.18454117", "0", "2"], ["83330.6", "0.00001852", "0", "1"]], "ts": "1742377420302", "checksum": -1638891892, "seqId": 49713707879, "prevSeqId": 49713707826}], "record_time": 1742377421.173853}
{"arg": {"channel": "books", "instId": "BTC-USDT"}, "action": "update", "data": [{"asks": [["83471.8", "0", "0", "0"], ["83471.9", "0.0001", "0", "1"], ["83472", "0.0568", "0", "2"], ["83478.8", "0.23961259", "0", "1"], ["83483.1", "0", "0", "0"], ["83485.5", "0.000132", "0", "1"], ["83514", "0.1", "0", "1"], ["83525.7", "0", "0", "0"], ["83527.5", "0.00013267", "0", "1"], ["83630.9", "0", "0", "0"], ["83631.1", "0", "0", "0"]], "bids": [["83469.5", "0", "0", "0"], ["83468.1", "0.0002", "0", "2"], ["83458.9", "0.000798", "0", "1"], ["83436.1", "0.01219896", "0", "1"], ["83425.9", "0", "0", "0"], ["83422.5", "0.23961261", "0", "1"], ["83421.7", "0.1", "0", "1"], ["83420.7", "0.00427296", "0", "1"], ["83402.8", "0", "0", "0"], ["83380.5", "0.00008831", "0", "1"], ["83379.2", "0", "0", "0"], ["83330.8", "0", "0", "0"], ["83330.6", "0", "0", "0"]], "ts": "1742377420402", "checksum": 300403163, "seqId": 49713707931, "prevSeqId": 49713707879}], "record_time": 1742377421.271844}
{"arg": {"channel": "books", "instId": "BTC-USDT"}, "action": "update", "data": [{"asks": [["83471.8", "0.0002", "0", "2"], ["83471.9", "0", "0", "0"], ["83472", "0.0567", "0", "1"], ["83572.4", "0.03589893", "0", "2"]], "bids": [["83468.7", "0.0834628", "0", "3"], ["83468.1", "0.0001", "0", "1"], ["83467.8", "0.0001", "0", "1"], ["83331", "0", "0", "0"]], "ts": "1742377420502", "checksum": -714945375, "seqId": 49713707947, "prevSeqId": 49713707931}], "record_time": 1742377421.369051}
{"arg": {"channel": "books", "instId": "BTC-USDT"}, "action": "update", "data": [{"asks": [], "bids": [["83469.7", "0.86321258", "0", "12"]], "ts": "1742377420602", "checksum": -1096370800, "seqId": 49713707954, "prevSeqId": 49713707947}], "record_time": 1742377421.470858}
