{"arg": {"channel": "books", "instId": "BTC-USDT"}, "action": "snapshot", "data": [{"asks": [["84071.9", "0.73770508", "0", "20"], ["84072.1", "0.0011894", "0", "1"], ["84073.3", "0.11900096", "0", "1"], ["84073.5", "0.17098616", "0", "2"], ["84073.6", "0.042", "0", "2"], ["84074.9", "0.08991011", "0", "1"], ["84075.5", "0.39276638", "0", "3"], ["84076.7", "0.01717916", "0", "1"], ["84076.8", "0.02534", "0", "1"], ["84077.6", "0.00262029", "0", "1"], ["84079.1", "0.02930357", "0", "1"], ["84079.4", "0.03", "0", "1"], ["84079.9", "0.23255832", "0", "1"], ["84080.1", "0.036", "0", "1"], ["84080.2", "0.01189953", "0", "1"], ["84080.4", "0.00001197", "0", "1"], ["84080.7", "0.04", "0", "1"], ["84081.4", "0.11898946", "0", "1"], ["84081.8", "0.03", "0", "1"], ["84082", "0.10531028", "0", "5"], ["84082.2", "0.17898725", "0", "1"], ["84082.8", "0.09", "0", "3"], ["84083", "0.000015", "0", "1"], ["84083.2", "0.00844", "0", "1"], ["84083.8", "0.2385", "0", "2"], ["84084.9", "0.47627664", "0", "1"], ["84085", "1", "0", "1"], ["84085.1", "0.03", "0", "1"], ["84085.4", "0.00001197", "0", "1"], ["84086.2", "0.39164723", "0", "2"], ["84086.8", "0.08991011", "0", "1"], ["84087.1", "0.04", "0", "1"], ["84087.3", "0.0000195", "0", "1"], ["84088.1", "0.036", "0", "1"], ["84088.2", "0.1696415", "0", "1"], ["84088.3", "0.13251", "0", "1"], ["84088.7", "0.07136512", "0", "2"], ["84089.7", "0.00005", "0", "1"], ["84090.4", "0.00001197", "0", "1"], ["84091.2", "0.14043175", "0", "1"], ["84091.4", "0.04166806", "0", "2"], ["84091.9", "0.11890769", "0", "1"], ["84093.2", "0.63612679", "0", "2"], ["84093.4", "1.60057555", "0", "1"], ["84094.4", "0.1123454", "0", "2"], ["84094.8", "0.17898725", "0", "1"], ["84095.3", "0.00001197", "0", "1"], ["84095.5", "0.35564723", "0", "1"], ["84095.9", "0.35684", "0", "1"], ["84096.2", "0.05946452", "0", "1"], ["84096.6", "0.67109566", "0", "2"], ["84096.9", "0.08991011", "0", "1"], ["84097.1", "0.18724233", "0", "1"], ["84097.6", "0.14043175", "0", "1"], ["84098.2", "0.036", "0", "1"], ["84099.2", "0.01189072", "0", "1"], ["84099.3", "0.01545262", "0", "2"], ["84099.8", "0.00001501", "0", "1"], ["84099.9", "0.23862283", "0", "2"], ["84100", "0.53839", "0", "1"], ["84100.3", "0.00001197", "0", "1"], ["84100.4", "0.11890769", "0", "1"], ["84100.6", "0.01189053", "0", "1"], ["84100.7", "0.17322", "0", "2"], ["84101", "0.11693971", "0", "1"], ["84101.8", "0.01189036", "0", "1"], ["84101.9", "0.00011161", "0", "1"], ["84102.1", "0.01", "0", "1"], ["84102.3", "0.01", "0", "2"], ["84104.5", "0.2079", "0", "1"], ["84104.9", "0.1123454", "0", "2"], ["84105", "0.35212879", "0", "2"], ["84105.2", "0.00001197", "0", "1"], ["84105.4", "0.036", "0", "1"], ["84105.7", "0.02379103", "0", "1"], ["84106.2", "0.002", "0", "1"], ["84106.4", "0.69188858", "0", "7"], ["84107.2", "0.0004", "0", "1"], ["84107.4", "0.01188957", "0", "1"], ["84107.7", "0.06142207", "0", "1"], ["84107.9", "0.00594645", "0", "1"], ["84108.2", "0.20356501", "0", "2"], ["84108.3", "0.036", "0", "1"], ["84108.8", "0.01908", "0", "1"], ["84109.9", "0.11890769", "0", "1"], ["84110", "0.34605272", "0", "1"], ["84110.1", "0.21438918", "0", "2"], ["84110.2", "0.00001197", "0", "1"], ["84110.6", "0.08991011", "0", "1"], ["84111.3", "0.02973226", "0", "1"], ["84112", "0.07999999", "0", "2"], ["84112.2", "0.00308666", "0", "1"], ["84112.3", "0.01", "0", "2"], ["84112.4", "0.5916", "0", "1"], ["84112.8", "0.03999999", "0", "1"], ["84113.8", "0.18425879", "0", "1"], ["84115.2", "0.00001197", "0", "1"], ["84115.4", "0.1123454", "0", "2"], ["84115.8", "0.00206993", "0", "2"], ["84115.9", "0.0015", "0", "1"], ["84116.2", "0.002", "0", "1"], ["84116.4", "0.1", "0", "1"], ["84116.6", "0.00062145", "0", "2"], ["84117.3", "0.35564723", "0", "1"], ["84117.7", "0.09260866", "0", "1"], ["84118.6", "0.02042556", "0", "1"], ["84119.7", "0.02973226", "0", "1"], ["84120", "0.00067701", "0", "2"], ["84120.1", "0.00001197", "0", "1"], ["84120.9", "0.11890769", "0", "1"], ["84121", "0.17898725", "0", "1"], ["84121.5", "0.00011161", "0", "1"], ["84121.6", "0.02428514", "0", "1"], ["84122.4", "0.838778", "0", "1"], ["84122.7", "0.0001693", "0", "1"], ["84122.9", "1.05811859", "0", "1"], ["84123", "2.80269235", "0", "1"], ["84124.4", "0.01153774", "0", "1"], ["84124.5", "0.05385", "0", "1"], ["84125", "0.000015", "0", "1"], ["84125.1", "0.00001197", "0", "1"], ["84125.8", "0.35564723", "0", "1"], ["84125.9", "0.2025", "0", "1"], ["84126.9", "0.27071013", "0", "1"], ["84127", "0.57446019", "0", "1"], ["84127.3", "0.01", "0", "1"], ["84128.6", "0.00576887", "0", "1"], ["84129", "0.00002157", "0", "1"], ["84129.1", "0.03", "0", "1"], ["84129.4", "0.11890769", "0", "1"], ["84129.5", "0.17898725", "0", "1"], ["84130.1", "0.00001197", "0", "1"], ["84130.4", "0.05777166", "0", "1"], ["84130.5", "0.10774868", "0", "2"], ["84130.9", "0.03", "0", "1"], ["84131", "0.03001", "0", "2"], ["84132.8", "0.00576887", "0", "1"], ["84133.1", "0.01118245", "0", "1"], ["84133.2", "0.00589967", "0", "1"], ["84133.3", "0.00101534", "0", "2"], ["84133.4", "0.00001501", "0", "1"], ["84133.5", "0.02378318", "0", "1"], ["84134.2", "0.04757772", "0", "1"], ["84134.8", "0.22692083", "0", "1"], ["84134.9", "0.35564723", "0", "1"], ["84135", "0.00001197", "0", "1"], ["84135.1", "0.02205931", "0", "1"], ["84135.2", "0.2385", "0", "2"], ["84136.4", "0.00594717", "0", "1"], ["84136.5", "0.02124", "0", "1"], ["84137.1", "0.000015", "0", "1"], ["84138.4", "0.00579968", "0", "1"], ["84138.5", "0.11890769", "0", "1"], ["84139", "0.001694", "0", "1"], ["84140", "0.00005196", "0", "2"], ["84140.4", "0.21009027", "0", "2"], ["84141.2", "0.06011161", "0", "3"], ["84141.3", "0.03", "0", "1"], ["84141.4", "0.17898725", "0", "1"], ["84141.6", "0.00589922", "0", "1"], ["84141.8", "0.000015", "0", "1"], ["84141.9", "0.44835", "0", "1"], ["84143.4", "0.39305706", "0", "1"], ["84143.5", "0.35564723", "0", "1"], ["84143.7", "0.2025", "0", "1"], ["84144.7", "0.470942", "0", "1"], ["84145", "0.00001196", "0", "1"], ["84145.6", "0.02378886", "0", "1"], ["84147.3", "0.044921", "0", "1"], ["84147.4", "0.07130346", "0", "1"], ["84147.5", "0.00579968", "0", "1"], ["84148.7", "0.04421263", "0", "1"], ["84148.8", "0.11890769", "0", "1"], ["84149.9", "0.00061841", "0", "2"], ["84150.2", "0.000015", "0", "1"], ["84151.6", "0.39645293", "0", "2"], ["84151.7", "0.17898725", "0", "1"], ["84152.2", "0.00712993", "0", "1"], ["84152.5", "0.39164723", "0", "2"], ["84152.7", "0.0076", "0", "1"], ["84152.9", "0.2025", "0", "1"], ["84153", "0.00036", "0", "1"], ["84153.3", "0.00002848", "0", "1"], ["84154", "0.00036", "0", "1"], ["84154.1", "0.07129778", "0", "1"], ["84154.9", "0.00001196", "0", "1"], ["84155", "0.00036", "0", "1"], ["84155.6", "0.00579968", "0", "1"], ["84155.7", "0.04811752", "0", "1"], ["84157", "0.00036", "0", "1"], ["84157.4", "0.01674532", "0", "2"], ["84157.8", "0.0000218", "0", "1"], ["84157.9", "0.0015", "0", "1"], ["84158.3", "0.11890769", "0", "1"], ["84158.6", "0.00001501", "0", "1"], ["84159.1", "0.01", "0", "1"], ["84159.2", "0.01148", "0", "1"], ["84159.8", "1.16092566", "0", "3"], ["84159.9", "0.00009539", "0", "1"], ["84160", "0.00029859", "0", "2"], ["84160.7", "0.01169935", "0", "2"], ["84160.8", "0.04982517", "0", "2"], ["84161.4", "3.83309", "0", "2"], ["84162", "0.00054", "0", "1"], ["84163.4", "1.259055", "0", "2"], ["84163.9", "0.28629088", "0", "2"], ["84164", "0.17898725", "0", "1"], ["84164.8", "0.00001198", "0", "1"], ["84165.7", "0.00698781", "0", "2"], ["84165.8", "0.03", "0", "1"], ["84165.9", "0.08323361", "0", "3"], ["84166", "0.00036", "0", "1"], ["84166.1", "0.35564723", "0", "1"], ["84166.5", "0.00338211", "0", "1"], ["84166.6", "0.00120585", "0", "6"], ["84167", "0.08790501", "0", "3"], ["84167.3", "0.00589976", "0", "1"], ["84167.7", "0.00589967", "0", "1"], ["84167.8", "0.03567917", "0", "1"], ["84167.9", "0.11890769", "0", "1"], ["84168", "0.05768575", "0", "2"], ["84169.9", "0.00003262", "0", "1"], ["84170", "0.00041452", "0", "2"], ["84170.3", "0.08827015", "0", "1"], ["84170.4", "0.20839976", "0", "2"], ["84170.8", "0.0015", "0", "1"], ["84171.1", "0.00023801", "0", "1"], ["84171.4", "0.00001675", "0", "1"], ["84171.5", "0.0214", "0", "1"], ["84171.8", "0.0214", "0", "1"], ["84172.1", "0.00579968", "0", "1"], ["84172.2", "0.03", "0", "1"], ["84173", "0.00589976", "0", "1"], ["84173.1", "0.38583759", "0", "2"], ["84173.2", "0.01425631", "0", "1"], ["84173.5", "0.00579938", "0", "1"], ["84173.6", "0.03", "0", "1"], ["84173.7", "0.17898725", "0", "1"], ["84174.5", "0.00589967", "0", "1"], ["84174.6", "0.35564723", "0", "1"], ["84174.7", "0.00001198", "0", "1"], ["84174.9", "0.00594", "0", "1"], ["84175", "0.00005354", "0", "1"], ["84175.4", "0.00001501", "0", "1"], ["84175.5", "0.74169976", "0", "2"], ["84175.9", "0.1001749", "0", "2"], ["84176.3", "0.00579968", "0", "1"], ["84176.4", "0.10579913", "0", "2"], ["84176.5", "0.00589952", "0", "1"], ["84176.6", "0.00589976", "0", "1"], ["84176.7", "0.00075763", "0", "1"], ["84176.8", "1.41958335", "0", "1"], ["84177.9", "0.18310769", "0", "4"], ["84178.3", "0.00001198", "0", "1"], ["84178.8", "0.2025", "0", "1"], ["84179.1", "0.00001501", "0", "1"], ["84179.4", "3.95285", "0", "1"], ["84180.4", "0.00011161", "0", "1"], ["84180.5", "0.00579938", "0", "1"], ["84180.6", "0.09", "0", "3"], ["84181", "0.00018", "0", "1"], ["84181.5", "0.00589976", "0", "1"], ["84181.7", "0.0842769", "0", "1"], ["84181.8", "0.08996575", "0", "3"], ["84182.2", "0.17898725", "0", "1"], ["84182.7", "0.00003999", "0", "1"], ["84182.8", "0.00003453", "0", "1"], ["84183", "0.00004916", "0", "1"], ["84183.1", "0.00589952", "0", "1"], ["84183.2", "0.00589922", "0", "1"], ["84183.3", "0.00060645", "0", "1"], ["84183.8", "0.00001501", "0", "1"], ["84184.3", "0.00579924", "0", "1"], ["84184.6", "0.00009227", "0", "1"], ["84184.7", "0.00001198", "0", "1"], ["84185", "0.0025", "0", "1"], ["84185.3", "0.0054", "0", "1"], ["84185.4", "0.17749964", "0", "1"], ["84185.5", "0.35564723", "0", "1"], ["84185.6", "0.1", "0", "1"], ["84185.9", "0.00579938", "0", "1"], ["84186", "0.0025", "0", "1"], ["84186.1", "0.00579984", "0", "1"], ["84186.2", "0.00023777", "0", "1"], ["84187", "0.0025", "0", "1"], ["84187.3", "0.2025", "0", "1"], ["84187.5", "0.00002668", "0", "1"], ["84188.4", "0.067349", "0", "1"], ["84188.6", "0.11597977", "0", "1"], ["84189.6", "0.00001198", "0", "1"], ["84189.7", "0.00589976", "0", "1"], ["84189.8", "0.07822244", "0", "2"], ["84189.9", "0.05942854", "0", "1"], ["84190.6", "0.00001198", "0", "1"], ["84191.3", "0.00001363", "0", "1"], ["84191.5", "0.01159922", "0", "2"], ["84191.6", "0.07166249", "0", "1"], ["84191.7", "0.11890769", "0", "1"], ["84192.2", "0.00001501", "0", "1"], ["84193.2", "0.28405282", "0", "1"], ["84193.7", "0.17898725", "0", "1"], ["84194", "0.09252", "0", "3"], ["84194.2", "0.00005735", "0", "1"], ["84195.5", "0.00002206", "0", "1"], ["84195.8", "0.2025", "0", "1"], ["84196.2", "0.00589976", "0", "1"], ["84196.3", "0.36144661", "0", "2"], ["84196.7", "0.0426", "0", "3"], ["84196.9", "0.183181", "0", "1"], ["84197.6", "0.00579984", "0", "1"], ["84198.5", "0.00594729", "0", "1"], ["84198.8", "0.20304806", "0", "1"], ["84199.2", "0.0015", "0", "1"], ["84199.4", "0.014", "0", "1"], ["84199.6", "0.00001198", "0", "1"], ["84199.9", "0.01238119", "0", "8"], ["84200", "0.36957363", "0", "48"], ["84200.1", "0.00311161", "0", "3"], ["84200.4", "0.11890769", "0", "1"], ["84200.6", "0.000015", "0", "1"], ["84201.6", "0.57763939", "0", "2"], ["84201.7", "0.4", "0", "1"], ["84201.8", "0.07165719", "0", "1"], ["84202.8", "0.00002241", "0", "1"], ["84202.9", "0.03", "0", "1"], ["84203", "0.00001198", "0", "1"], ["84203.1", "0.0284", "0", "2"], ["84203.2", "0.0284", "0", "2"], ["84203.9", "0.00589976", "0", "1"], ["84204", "0.2978036", "0", "2"], ["84204.3", "0.2025", "0", "1"], ["84204.5", "0.00024979", "0", "1"], ["84204.9", "0.56973123", "0", "2"], ["84206.3", "0.03", "0", "1"], ["84206.8", "0.00579958", "0", "1"], ["84206.9", "0.03", "0", "1"], ["84207.7", "0.01511839", "0", "1"], ["84208.7", "0.08992107", "0", "2"], ["84209", "0.000015", "0", "1"], ["84209.2", "0.00023771", "0", "1"], ["84209.3", "0.00011444", "0", "1"], ["84209.5", "0.00001198", "0", "1"], ["84211.1", "0.00589976", "0", "1"], ["84211.7", "0.00001678", "0", "1"], ["84211.9", "0.00589997", "0", "1"], ["84212.5", "0.17898725", "0", "1"], ["84212.8", "0.204", "0", "2"], ["84213.5", "0.35564723", "0", "1"], ["84214.2", "0.00001575", "0", "1"], ["84214.5", "0.00001197", "0", "1"], ["84214.6", "0.05351571", "0", "1"], ["84214.8", "0.00032751", "0", "1"], ["84215.4", "0.01785384", "0", "4"], ["84215.5", "3.95285", "0", "1"], ["84216", "0.00001565", "0", "1"], ["84216.5", "0.00589971", "0", "1"], ["84216.6", "0.00060645", "0", "1"], ["84217.3", "0.11890769", "0", "1"], ["84217.4", "0.00001501", "0", "1"], ["84219.3", "0.00007814", "0", "1"], ["84219.7", "0.00011161", "0", "1"], ["84220", "0.0015", "0", "1"], ["84221.1", "0.000015", "0", "1"], ["84221.2", "0.00079131", "0", "1"], ["84221.3", "0.29036549", "0", "3"], ["84221.9", "0.17898725", "0", "1"], ["84222", "0.35576691", "0", "2"], ["84223.5", "0.2163", "0", "1"], ["84223.8", "0.00024832", "0", "1"], ["84224.4", "0.00001197", "0", "1"], ["84225", "0.002379", "0", "1"], ["84225.8", "0.000015", "0", "1"], ["84225.9", "0.0015", "0", "1"], ["84226", "0.03", "0", "1"], ["84226.6", "0.00001653", "0", "1"], ["84227.5", "0.01182404", "0", "1"], ["84228.4", "0.00010514", "0", "1"], ["84228.5", "0.00002372", "0", "1"], ["84228.9", "0.00008", "0", "1"], ["84229.2", "1.62656", "0", "1"], ["84229.8", "0.2025", "0", "1"], ["84230.4", "0.17898725", "0", "1"], ["84230.5", "0.35564723", "0", "1"], ["84232.3", "0.08419319", "0", "1"], ["84233.1", "0.11890769", "0", "1"], ["84233.2", "0.25056475", "0", "1"], ["84233.3", "0.00101534", "0", "2"], ["84233.5", "0.00002296", "0", "1"], ["84233.8", "0.00003542", "0", "1"], ["84234.2", "0.00001501", "0", "1"], ["84234.4", "0.00001197", "0", "1"], ["84234.7", "0.03", "0", "1"], ["84235.2", "0.00002902", "0", "1"], ["84236.8", "0.00001738", "0", "1"], ["84237.2", "0.00001115", "0", "1"], ["84237.8", "0.00005956", "0", "1"], ["84238.1", "0.00006534", "0", "2"], ["84238.3", "0.20843858", "0", "2"], ["84238.4", "0.03", "0", "1"], ["84238.9", "0.17898725", "0", "1"]], "bids": [["84071.8", "0.01126075", "0", "4"], ["84070.6", "0.00001197", "0", "1"], ["84070", "0.0439", "0", "1"], ["84068", "0.0439", "0", "1"], ["84066.9", "0.00055967", "0", "1"], ["84066.6", "0.00504382", "0", "4"], ["84066", "0.0439", "0", "1"], ["84065.7", "0.00001197", "0", "1"], ["84063.4", "0.09445362", "0", "1"], ["84063.3", "0.2025", "0", "1"], ["84063", "0.1123454", "0", "2"], ["84062.6", "0.00011161", "0", "1"], ["84060.7", "0.00001197", "0", "1"], ["84060", "0.00001", "0", "1"], ["84058.6", "0.16664397", "0", "1"], ["84058", "0.01674", "0", "1"], ["84057.5", "0.0044625", "0", "1"], ["84057.1", "0.01190158", "0", "1"], ["84056.9", "0.01674", "0", "1"], ["84056.7", "0.02799005", "0", "1"], ["84056.6", "0.00364185", "0", "1"], ["84055.7", "0.00001197", "0", "1"], ["84055.5", "0.00037094", "0", "1"], ["84054.7", "0.42764723", "0", "2"], ["84054.6", "0.34123686", "0", "2"], ["84054.3", "0.2425", "0", "2"], ["84054.2", "0.05580216", "0", "2"], ["84052.9", "0.17898725", "0", "1"], ["84052.5", "0.1123454", "0", "2"], ["84052.3", "0.18725734", "0", "2"], ["84051.1", "0.04283411", "0", "1"], ["84050.8", "0.00001197", "0", "1"], ["84050.5", "0.05024", "0", "1"], ["84049.9", "0.00060645", "0", "1"], ["84049.8", "0.04", "0", "1"], ["84049.7", "0.47655421", "0", "1"], ["84049.6", "1", "0", "1"], ["84049.4", "0.00713866", "0", "1"], ["84048.8", "0.063", "0", "1"], ["84048.7", "0.17990399", "0", "4"], ["84047.9", "0.17842", "0", "1"], ["84046.8", "0.00773148", "0", "1"], ["84046.5", "0.01188815", "0", "1"], ["84046.4", "0.14043175", "0", "1"], ["84046.2", "0.82453865", "0", "1"], ["84046.1", "0.02380217", "0", "1"], ["84045.8", "0.00001198", "0", "1"], ["84045", "0.05944201", "0", "1"], ["84044.6", "0.01774536", "0", "1"], ["84044.5", "0.471001", "0", "1"], ["84044.2", "0.35564723", "0", "1"], ["84044", "0.2025", "0", "1"], ["84043.9", "0.12381692", "0", "3"], ["84043.7", "0.000015", "0", "1"], ["84043.4", "1.24", "0", "1"], ["84043.2", "0.01", "0", "1"], ["84043", "0.00011161", "0", "1"], ["84042.9", "0.132521", "0", "1"], ["84042.2", "0.23801638", "0", "1"], ["84042.1", "0.17898725", "0", "1"], ["84042", "0.1123454", "0", "2"], ["84041.6", "0.02380915", "0", "1"], ["84041.5", "0.72687633", "0", "2"], ["84041.1", "0.01153238", "0", "1"], ["84040.9", "0.00001198", "0", "1"], ["84040.2", "0.00054348", "0", "1"], ["84040", "0.00001", "0", "1"], ["84039.8", "0.14043175", "0", "1"], ["84039.2", "0.53039", "0", "1"], ["84038.9", "1.59300086", "0", "1"], ["84037.8", "0.02738023", "0", "2"], ["84037.4", "0.17842", "0", "1"], ["84037.3", "0.43800274", "0", "1"], ["84037.2", "0.59328", "0", "1"], ["84036.8", "0.06060207", "0", "1"], ["84036.6", "0.04498", "0", "1"], ["84036.4", "0.11890769", "0", "1"], ["84036", "0.00054348", "0", "1"], ["84035.9", "0.00151198", "0", "2"], ["84035.6", "0.01", "0", "1"], ["84035.5", "0.00001501", "0", "1"], ["84034.9", "0.17842", "0", "1"], ["84034.6", "0.35564723", "0", "1"], ["84034.5", "0.12485", "0", "1"], ["84034.4", "0.08079864", "0", "4"], ["84033.9", "0.2025", "0", "1"], ["84033.6", "0.04039865", "0", "2"], ["84033.4", "0.25810119", "0", "3"], ["84033.3", "0.00101534", "0", "2"], ["84032.8", "0.026", "0", "2"], ["84032", "0.013", "0", "1"], ["84031.8", "0.00054348", "0", "1"], ["84031.5", "0.11338331", "0", "3"], ["84031", "0.00001", "0", "1"], ["84030.9", "0.00001198", "0", "1"], ["84030.7", "0.12484", "0", "1"], ["84030.5", "0.17898725", "0", "1"], ["84030.4", "0.1", "0", "2"], ["84030.3", "0.05279", "0", "1"], ["84029.6", "0.05", "0", "1"], ["84029.3", "0.3146556", "0", "3"], ["84029.2", "0.58297907", "0", "1"], ["84028.5", "0.01189071", "0", "1"], ["84028.3", "0.01189072", "0", "1"], ["84028.2", "0.0015", "0", "1"], ["84028.1", "0.01189053", "0", "1"], ["84027.3", "0.01189041", "0", "1"], ["84027.1", "0.00001501", "0", "1"], ["84026", "0.00001198", "0", "1"], ["84025.8", "0.11890769", "0", "1"], ["84025.7", "0.35564723", "0", "1"], ["84025.5", "0.27711", "0", "1"], ["84025.3", "0.00107", "0", "1"], ["84025.2", "0.35684", "0", "1"], ["84023.3", "0.10011161", "0", "2"], ["84022.2", "0.22496723", "0", "2"], ["84022.1", "0.2025", "0", "1"], ["84021.5", "0.34265986", "0", "2"], ["84021.4", "0.03", "0", "1"], ["84021.3", "0.00357", "0", "1"], ["84021", "0.26715102", "0", "5"], ["84020.9", "0.2911286", "0", "1"], ["84020", "0.00001", "0", "1"], ["84018.7", "0.01787731", "0", "2"], ["84017.5", "0.01179846", "0", "2"], ["84017.4", "0.00594645", "0", "1"], ["84017.3", "0.11890769", "0", "1"], ["84017.2", "0.53463448", "0", "2"], ["84017", "0.29461771", "0", "1"], ["84016.6", "0.00640613", "0", "2"], ["84016.1", "0.00001198", "0", "1"], ["84015.8", "0.00589923", "0", "1"], ["84015.7", "0.07186723", "0", "3"], ["84015.6", "0.08925", "0", "1"], ["84013.6", "0.01832806", "0", "1"], ["84013.5", "0.00218418", "0", "1"], ["84013.4", "0.13083645", "0", "2"], ["84013.3", "0.0015", "0", "1"], ["84012.8", "0.00589923", "0", "1"], ["84012.6", "0.00579968", "0", "1"], ["84011.8", "1.26012857", "0", "2"], ["84011.7", "0.56", "0", "1"], ["84011.6", "0.839884", "0", "1"], ["84011.1", "0.00001198", "0", "1"], ["84010.7", "0.00005963", "0", "1"], ["84010.3", "0.00001501", "0", "1"], ["84009.9", "0.00589923", "0", "1"], ["84009.7", "0.13066968", "0", "2"], ["84009.3", "2.78662213", "0", "1"], ["84009.1", "0.067493", "0", "1"], ["84008.6", "0.00579968", "0", "1"], ["84008.5", "0.00594657", "0", "1"], ["84008.1", "0.30035582", "0", "2"], ["84008", "0.11890769", "0", "1"], ["84007.3", "0.00589967", "0", "1"], ["84007.2", "0.00714224", "0", "1"], ["84007.1", "0.20839923", "0", "2"], ["84006.8", "0.05954756", "0", "1"], ["84006.6", "0.17898725", "0", "1"], ["84006.2", "0.00001198", "0", "1"], ["84005.5", "0.4", "0", "1"], ["84005.3", "0.00001196", "0", "1"], ["84004.3", "0.35564723", "0", "1"], ["84003.7", "0.00011161", "0", "1"], ["84003.2", "0.00579968", "0", "1"], ["84003.1", "0.1245477", "0", "1"], ["84003", "0.21197", "0", "1"], ["84002.4", "0.00594717", "0", "1"], ["84002.2", "0.00589967", "0", "1"], ["84002.1", "0.08991011", "0", "1"], ["84001.9", "0.000015", "0", "1"], ["84001.6", "0.00001501", "0", "1"], ["84001.1", "0.00008", "0", "1"], ["84000.9", "0.00589923", "0", "1"], ["84000", "0.26158901", "0", "7"], ["83999.9", "0.00511262", "0", "6"], ["83999.5", "0.00595", "0", "1"], ["83999", "0.28269555", "0", "2"], ["83998.9", "0.11890769", "0", "1"], ["83997.1", "0.17898725", "0", "1"], ["83996.3", "0.00001196", "0", "1"], ["83996", "0.00100351", "0", "1"], ["83995.8", "0.35564723", "0", "1"], ["83995.7", "1.16529151", "0", "2"], ["83995.6", "0.2025", "0", "1"], ["83995.2", "0.00579968", "0", "1"], ["83995", "3.53763", "0", "1"], ["83994.2", "0.0117989", "0", "2"], ["83994.1", "0.00005456", "0", "1"], ["83994", "0.0015", "0", "1"], ["83993.5", "0.000015", "0", "1"], ["83993", "0.00001196", "0", "1"], ["83992.1", "0.01673577", "0", "1"], ["83991.9", "0.83843", "0", "1"], ["83991.3", "0.11744135", "0", "1"], ["83990.5", "0.10002", "0", "2"], ["83989.7", "0.00005329", "0", "1"], ["83989.2", "0.07143774", "0", "1"], ["83989", "0.08928", "0", "1"], ["83987.8", "0.00587276", "0", "2"], ["83987.7", "0.11890769", "0", "1"], ["83987.5", "0.00589967", "0", "1"], ["83987.4", "0.27886427", "0", "1"], ["83987.3", "0.35564723", "0", "1"], ["83987.2", "0.18488648", "0", "2"], ["83986.9", "0.2025", "0", "1"], ["83986.4", "0.0014501", "0", "1"], ["83986.3", "0.12001196", "0", "5"], ["83985.1", "0.000015", "0", "1"], ["83984.4", "0.03572133", "0", "1"], ["83984.1", "0.00011161", "0", "1"], ["83983.5", "0.00018398", "0", "1"], ["83983.4", "0.00004752", "0", "1"], ["83983.3", "0.00060645", "0", "1"], ["83983.2", "0.03", "0", "1"], ["83983.1", "0.03", "0", "1"], ["83982.7", "0.00595", "0", "1"], ["83982.5", "0.15019596", "0", "2"], ["83981.8", "0.04001565", "0", "1"], ["83981.5", "0.00005685", "0", "1"], ["83981.4", "0.00001197", "0", "1"], ["83981.3", "0.01159936", "0", "2"], ["83980.6", "0.00001197", "0", "1"], ["83979.8", "0.09580978", "0", "2"], ["83979.5", "0.00004344", "0", "1"], ["83979.3", "0.00589923", "0", "1"], ["83979.1", "0.11890769", "0", "1"], ["83977.9", "0.60405441", "0", "1"], ["83977.8", "1.28412186", "0", "2"], ["83977.3", "0.53463448", "0", "2"], ["83976.7", "0.00001501", "0", "1"], ["83976.5", "0.183144", "0", "1"], ["83974.8", "0.01159936", "0", "2"], ["83974.3", "0.00003395", "0", "1"], ["83974.1", "1.25594668", "0", "1"], ["83974", "3.95749", "0", "1"], ["83973.9", "0.2025", "0", "1"], ["83973.8", "0.014", "0", "1"], ["83971.5", "0.01181087", "0", "3"], ["83971.4", "0.00068806", "0", "1"], ["83970.5", "0.00579968", "0", "1"], ["83970.4", "0.0057991", "0", "1"], ["83970.3", "0.1508833", "0", "3"], ["83970.2", "0.11890769", "0", "1"], ["83969", "0.00005519", "0", "1"], ["83968.6", "0.08368884", "0", "1"], ["83968.5", "0.00213766", "0", "1"], ["83968.3", "0.00001197", "0", "1"], ["83968.1", "0.01636305", "0", "1"], ["83967.9", "0.35564723", "0", "1"], ["83967.4", "0.05746457", "0", "2"], ["83967.2", "0.00001508", "0", "1"], ["83966.6", "0.00460884", "0", "3"], ["83965.6", "0.00579968", "0", "1"], ["83965.5", "0.18638548", "0", "1"], ["83965.4", "0.2025", "0", "1"], ["83964.9", "0.00031805", "0", "3"], ["83964.8", "0.01759858", "0", "3"], ["83964.7", "0.00302704", "0", "2"], ["83964.4", "0.23242581", "0", "2"], ["83964.2", "0.25064974", "0", "2"], ["83963.7", "0.00001972", "0", "1"], ["83963.6", "0.00001046", "0", "1"], ["83963.5", "0.00006364", "0", "3"], ["83963.2", "0.00004579", "0", "2"], ["83963", "0.07165719", "0", "1"], ["83962.9", "0.00350324", "0", "1"], ["83962.7", "0.02378931", "0", "1"], ["83962.5", "0.00014323", "0", "1"], ["83962.3", "0.00024071", "0", "2"], ["83961.7", "0.11890769", "0", "1"], ["83961.6", "0.00002224", "0", "2"], ["83961.5", "0.00005515", "0", "1"], ["83960.7", "0.61754217", "0", "2"], ["83960.6", "0.214056", "0", "1"], ["83960.5", "0.00002513", "0", "1"], ["83960.3", "0.00040843", "0", "13"], ["83960.1", "0.00017621", "0", "1"], ["83960", "0.00254156", "0", "17"], ["83959.9", "0.00003121", "0", "3"], ["83959.8", "0.00002916", "0", "1"], ["83959.5", "0.00001501", "0", "1"], ["83959.4", "0.35802623", "0", "2"], ["83959.3", "0.00032129", "0", "2"], ["83959.1", "0.00001009", "0", "1"], ["83958.3", "1.55480126", "0", "4"], ["83957.3", "0.00002976", "0", "1"], ["83957", "0.00003106", "0", "1"], ["83956.9", "0.2025", "0", "1"], ["83956.8", "0.10699", "0", "1"], ["83956.6", "0.00001197", "0", "1"], ["83956.5", "0.00535577", "0", "1"], ["83956", "0.00144641", "0", "1"], ["83955.9", "0.00001197", "0", "1"], ["83955.5", "0.00001157", "0", "1"], ["83954.9", "0.00147218", "0", "3"], ["83954.8", "0.17898725", "0", "1"], ["83954.6", "0.00036601", "0", "2"], ["83954.5", "0.00001009", "0", "1"], ["83953.9", "0.01", "0", "1"], ["83953.8", "0.0000101", "0", "1"], ["83953.2", "0.00011436", "0", "7"], ["83953", "3.49531", "0", "1"], ["83952.8", "0.00162451", "0", "1"], ["83952.7", "0.00001065", "0", "1"], ["83952.5", "0.00004799", "0", "2"], ["83952.1", "0.00054879", "0", "1"], ["83952", "0.03001325", "0", "2"], ["83951.9", "0.00001838", "0", "1"], ["83951.6", "0.00001", "0", "1"], ["83951.5", "0.00012612", "0", "1"], ["83951.4", "0.00001016", "0", "1"], ["83951.3", "0.11917375", "0", "1"], ["83950.8", "0.00002671", "0", "1"], ["83950.4", "0.00003672", "0", "2"], ["83950.3", "0.11890769", "0", "1"], ["83950.1", "0.35564723", "0", "1"], ["83950", "0.80472764", "0", "11"], ["83949.9", "0.00164688", "0", "3"], ["83949.7", "0.05515272", "0", "2"], ["83949.5", "0.00002536", "0", "1"], ["83949", "0.00002064", "0", "2"], ["83948.9", "0.00002541", "0", "2"], ["83948.6", "0.00063143", "0", "3"], ["83948.4", "0.20290063", "0", "5"], ["83948.1", "0.08991011", "0", "1"], ["83947.7", "0.58226341", "0", "1"], ["83947.3", "0.00117469", "0", "3"], ["83947.2", "0.00030759", "0", "1"], ["83946.7", "0.00002763", "0", "2"], ["83946.4", "0.17898725", "0", "1"], ["83945.9", "0.00010228", "0", "3"], ["83945.4", "0.03", "0", "1"], ["83945.3", "0.03", "0", "1"], ["83945.1", "0.08932", "0", "1"], ["83944.8", "0.00161161", "0", "2"], ["83944.6", "0.00001182", "0", "1"], ["83944.4", "0.03012711", "0", "4"], ["83944.1", "0.0597095", "0", "2"], ["83943.8", "0.18328061", "0", "1"], ["83943.7", "0.00088289", "0", "6"], ["83943.6", "0.00001557", "0", "1"], ["83943.5", "0.00001026", "0", "1"], ["83942.8", "0.00001728", "0", "1"], ["83942.4", "0.05358201", "0", "1"], ["83942", "0.08939352", "0", "2"], ["83941.8", "0.00001197", "0", "1"], ["83941.5", "0.00619931", "0", "5"], ["83941.3", "0.00021424", "0", "3"], ["83941.2", "0.00620925", "0", "1"], ["83941.1", "0.0000293", "0", "2"], ["83940.9", "0.00001025", "0", "1"], ["83940.4", "0.00002279", "0", "1"], ["83940", "0.00001141", "0", "1"], ["83939.9", "0.22042779", "0", "3"], ["83939.8", "0.00001033", "0", "1"], ["83939.3", "0.0046949", "0", "3"], ["83938.9", "0.00548453", "0", "3"], ["83938.5", "0.03", "0", "1"], ["83938.4", "0.00001883", "0", "1"], ["83938.2", "0.0001735", "0", "1"], ["83938", "0.00005329", "0", "1"], ["83937.9", "0.17899743", "0", "2"], ["83937.5", "0.00104504", "0", "2"], ["83937.2", "0.00002851", "0", "1"], ["83937.1", "0.11890769", "0", "1"], ["83936.9", "0.35564723", "0", "1"], ["83936.8", "0.00001197", "0", "1"], ["83936.6", "0.00019721", "0", "4"], ["83936.5", "0.00006433", "0", "3"], ["83936.2", "0.00005179", "0", "3"], ["83936.1", "0.0000442", "0", "1"], ["83935.6", "0.00001925", "0", "1"], ["83935.5", "0.01189232", "0", "1"], ["83935.4", "0.00001471", "0", "1"], ["83934.8", "0.00002382", "0", "1"], ["83934.5", "0.01784253", "0", "1"], ["83934.4", "0.00003782", "0", "1"], ["83933.8", "0.00011948", "0", "1"], ["83933.7", "0.00013585", "0", "4"], ["83933.4", "0.00002942", "0", "1"], ["83933.3", "0.00927632", "0", "11"], ["83932.9", "0.00001845", "0", "1"], ["83932.7", "0.00001063", "0", "1"], ["83932.6", "2.09738", "0", "1"], ["83932.2", "0.01568", "0", "1"], ["83931.9", "0.00002667", "0", "2"], ["83931.4", "0.2025", "0", "1"], ["83931.3", "0.00001197", "0", "1"], ["83930.8", "0.00008931", "0", "3"], ["83930.7", "0.00020738", "0", "5"], ["83930.5", "0.00001316", "0", "1"], ["83930.2", "0.00011454", "0", "1"], ["83930", "0.00012899", "0", "1"], ["83929.9", "0.00007149", "0", "1"], ["83929.8", "0.00011809", "0", "3"], ["83929.5", "0.17898725", "0", "1"], ["83929.1", "0.00016972", "0", "1"], ["83928.5", "0.03374921", "0", "4"], ["83927.9", "0.00199404", "0", "5"]], "ts": "1742584881306", "checksum": -1695371613, "seqId": 49948774908, "prevSeqId": -1}], "record_time": 1742584881.393182, "EXCHANGE": "OKX"}
{"arg": {"channel": "books", "instId": "BTC-USDT"}, "action": "update", "data": [{"asks": [["84095.9", "0", "0", "0"], ["84102.4", "0.0008", "0", "2"], ["84103.2", "0.0004", "0", "1"], ["84106.4", "0.69108858", "0", "5"], ["84107.2", "0", "0", "0"], ["84109.6", "0.08", "0", "2"], ["84110.4", "0.03999999", "0", "1"], ["84112", "0", "0", "0"], ["84112.8", "0", "0", "0"]], "bids": [["84071.8", "0.01582134", "0", "6"], ["84069.1", "0.11900676", "0", "1"], ["84063.4", "0.09024067", "0", "2"], ["84059.5", "0.01190125", "0", "1"], ["84057.5", "0", "0", "0"], ["84057.1", "0", "0", "0"], ["84054.7", "0.43537871", "0", "3"], ["84042.4", "0.11904459", "0", "1"], ["84034.9", "0", "0", "0"], ["84025.2", "0", "0", "0"], ["83927.6", "0.00022298", "0", "2"]], "ts": "1742584881406", "checksum": 1395181608, "seqId": 49948774945, "prevSeqId": 49948774908}], "record_time": 1742584881.491726, "EXCHANGE": "OKX"}
{"arg": {"channel": "books", "instId": "BTC-USDT"}, "action": "update", "data": [{"asks": [["84071.9", "0.7261727", "0", "19"], ["84074.9", "0", "0", "0"], ["84075.3", "0.01153238", "0", "1"], ["84076.7", "0.13108376", "0", "2"], ["84078.2", "0.35684", "0", "1"], ["84085", "0", "0", "0"], ["84086.8", "1.08991011", "0", "2"], ["84099.9", "0.00060645", "0", "1"], ["84104.4", "0.23800892", "0", "1"], ["84172.8", "0.00298666", "0", "1"], ["84181.2", "0.00597332", "0", "1"], ["84189.7", "0.01485975", "0", "2"], ["84198.1", "0.01194665", "0", "1"], ["84206.5", "0.01493332", "0", "1"], ["84237.8", "0", "0", "0"], ["84238.1", "0", "0", "0"], ["84238.3", "0", "0", "0"], ["84238.4", "0", "0", "0"], ["84238.9", "0", "0", "0"]], "bids": [["84071.8", "0.02040446", "0", "10"], ["84059.6", "0.004935", "0", "1"], ["84054.6", "0.58583886", "0", "3"], ["84051.5", "1", "0", "1"], ["84049.7", "0.24795689", "0", "1"], ["84049.6", "0", "0", "0"], ["84046.5", "0.24989707", "0", "2"], ["84045.4", "0.35684", "0", "1"], ["84042.2", "0", "0", "0"], ["84035.6", "0", "0", "0"], ["83965.8", "0.00298666", "0", "1"], ["83957.2", "0.00597332", "0", "1"], ["83948.6", "0.00959142", "0", "4"], ["83940.2", "0.01194665", "0", "1"], ["83931.8", "0.01493332", "0", "1"], ["83929.1", "0", "0", "0"], ["83928.5", "0", "0", "0"], ["83927.9", "0", "0", "0"], ["83927.6", "0", "0", "0"]], "ts": "1742584881506", "checksum": -1412485014, "seqId": 49948774996, "prevSeqId": 49948774945}], "record_time": 1742584881.592027, "EXCHANGE": "OKX"}
{"arg": {"channel": "books", "instId": "BTC-USDT"}, "action": "update", "data": [{"asks": [["84071.9", "0.7083297", "0", "18"]], "bids": [["84055.4", "0.04283411", "0", "1"], ["84051.1", "0", "0", "0"], ["84046.5", "0.23800892", "0", "1"], ["84045.5", "0.01774536", "0", "1"], ["84044.6", "0", "0", "0"], ["84037.4", "0", "0", "0"], ["84035.2", "0.0008", "0", "2"], ["84034.4", "0.08039864", "0", "3"], ["84033.6", "0.04", "0", "1"], ["84030.1", "0.01189047", "0", "1"], ["84023.3", "0.00011161", "0", "1"], ["84000", "0.01179901", "0", "6"], ["83929.5", "0", "0", "0"]], "ts": "1742584881606", "checksum": -1698827725, "seqId": 49948775015, "prevSeqId": 49948774996}], "record_time": 1742584881.691271, "EXCHANGE": "OKX"}
{"arg": {"channel": "books", "instId": "BTC-USDT"}, "action": "update", "data": [{"asks": [], "bids": [["84042.1", "0.42877725", "0", "2"], ["84010", "0.2", "0", "1"], ["83929.8", "0", "0", "0"]], "ts": "1742584881706", "checksum": -1698827725, "seqId": 49948775027, "prevSeqId": 49948775015}], "record_time": 1742584881.791925, "EXCHANGE": "OKX"}
{"arg": {"channel": "books", "instId": "BTC-USDT"}, "action": "update", "data": [{"asks": [["84082", "0.07691028", "0", "3"], ["84099.9", "0.23862103", "0", "2"], ["84104.4", "0", "0", "0"], ["84116.4", "0", "0", "0"], ["84237.8", "0.00005956", "0", "1"], ["84238.1", "0.00006534", "0", "2"]], "bids": [["84071.8", "0.10815024", "0", "12"], ["84071.3", "0.11900371", "0", "1"], ["84069.1", "0", "0", "0"], ["84055.7", "0.1190377", "0", "2"], ["84049.7", "0.17298776", "0", "1"], ["84046.5", "0", "0", "0"], ["84043.5", "0.23801458", "0", "1"], ["84042.4", "0", "0", "0"], ["84025.8", "0.21890769", "0", "2"], ["84010", "0", "0", "0"], ["83929.8", "0.00011809", "0", "3"], ["83929.5", "0.17898725", "0", "1"]], "ts": "1742584881806", "checksum": 1329026959, "seqId": 49948775044, "prevSeqId": 49948775027}], "record_time": 1742584881.892258, "EXCHANGE": "OKX"}
{"arg": {"channel": "books", "instId": "BTC-USDT"}, "action": "update", "data": [{"asks": [["84071.9", "0.59206605", "0", "16"], ["84102.4", "0", "0", "0"], ["84103.2", "0.0008", "0", "2"], ["84104", "0.0004", "0", "1"], ["84109.6", "0", "0", "0"], ["84110.4", "0.07999999", "0", "2"], ["84111.2", "0.03999999", "0", "1"], ["84116.5", "0.1", "0", "1"], ["84238.1", "0", "0", "0"]], "bids": [["84039.9", "0.17842", "0", "1"], ["84025.8", "0.11890769", "0", "1"], ["83929.5", "0", "0", "0"]], "ts": "1742584881906", "checksum": 1420843244, "seqId": 49948775059, "prevSeqId": 49948775044}], "record_time": 1742584881.991566, "EXCHANGE": "OKX"}
{"arg": {"channel": "books", "instId": "BTC-USDT"}, "action": "update", "data": [{"asks": [["84071.9", "0.59801605", "0", "17"], ["84085.6", "1", "0", "1"], ["84086.8", "0.08991011", "0", "1"], ["84237.8", "0", "0", "0"]], "bids": [["84071.8", "0.02155024", "0", "11"], ["84059.6", "0", "0", "0"], ["84044.6", "0.2380135", "0", "1"], ["84043.5", "0", "0", "0"], ["84027.3", "0.11189041", "0", "2"], ["83929.5", "0.17898725", "0", "1"]], "ts": "1742584882006", "checksum": -1663152843, "seqId": 49948775076, "prevSeqId": 49948775059}], "record_time": 1742584882.091644, "EXCHANGE": "OKX"}
{"arg": {"channel": "books", "instId": "BTC-USDT"}, "action": "update", "data": [{"asks": [["84071.9", "0.79801605", "0", "18"], ["84106.2", "0", "0", "0"], ["84116.2", "0", "0", "0"], ["84127.2", "0.00002157", "0", "1"], ["84129", "0", "0", "0"], ["84132.7", "0.01118245", "0", "1"], ["84133.1", "0", "0", "0"], ["84237.8", "0.00005956", "0", "1"], ["84238.1", "0.00006534", "0", "2"]], "bids": [["84071.3", "0", "0", "0"], ["84069.2", "0.11900666", "0", "1"], ["84063.6", "0.15445362", "0", "1"], ["84063.5", "0.2", "0", "1"], ["84063.4", "0", "0", "0"], ["84061", "0.0001545", "0", "1"], ["84044.6", "0", "0", "0"], ["84043.5", "0.23801348", "0", "1"], ["84013.8", "0.01832712", "0", "1"], ["84013.7", "0.00218405", "0", "1"], ["84013.6", "0", "0", "0"], ["84013.5", "0", "0", "0"], ["84011.7", "0", "0", "0"], ["83996", "0", "0", "0"], ["83995.9", "0.00100348", "0", "1"], ["83944.2", "0.18327123", "0", "1"], ["83943.8", "0", "0", "0"], ["83929.5", "0", "0", "0"]], "ts": "1742584882106", "checksum": 907358157, "seqId": 49948775117, "prevSeqId": 49948775076}], "record_time": 1742584882.191547, "EXCHANGE": "OKX"}
{"arg": {"channel": "books", "instId": "BTC-USDT"}, "action": "update", "data": [{"asks": [["84132.7", "0", "0", "0"], ["84133.1", "0.01118258", "0", "1"]], "bids": [["84016.7", "0.01832714", "0", "1"], ["84013.8", "0", "0", "0"], ["84013.7", "0", "0", "0"], ["84013.5", "0.00218405", "0", "1"], ["83945.4", "0.21327143", "0", "2"], ["83944.2", "0", "0", "0"], ["83929.5", "0.17898725", "0", "1"]], "ts": "1742584882206", "checksum": 907358157, "seqId": 49948775131, "prevSeqId": 49948775117}], "record_time": 1742584882.291316, "EXCHANGE": "OKX"}
{"arg": {"channel": "books", "instId": "BTC-USDT"}, "action": "update", "data": [{"asks": [["84071.9", "0.81585905", "0", "19"]], "bids": [["84063.6", "0.09445362", "0", "1"], ["84063.5", "0", "0", "0"], ["84039.9", "0", "0", "0"], ["83929.1", "0.00016972", "0", "1"], ["83928.5", "0.03374921", "0", "4"]], "ts": "1742584882306", "checksum": 1850580636, "seqId": 49948775145, "prevSeqId": 49948775131}], "record_time": 1742584882.394572, "EXCHANGE": "OKX"}
{"arg": {"channel": "books", "instId": "BTC-USDT"}, "action": "update", "data": [{"asks": [["84071.9", "0.81229198", "0", "18"], ["84098.4", "0.003567", "0", "1"], ["84132.7", "0.01118487", "0", "1"], ["84133.1", "0", "0", "0"], ["84238.1", "0", "0", "0"]], "bids": [["84043.5", "0", "0", "0"], ["84042.2", "0.23801491", "0", "1"], ["84037.4", "0.17842", "0", "1"], ["84016.7", "0", "0", "0"], ["84013.6", "0.01832716", "0", "1"], ["83945.4", "0.03", "0", "1"], ["83944.2", "0.18327164", "0", "1"], ["83929.1", "0", "0", "0"], ["83928.5", "0", "0", "0"]], "ts": "1742584882406", "checksum": 1920331792, "seqId": 49948775156, "prevSeqId": 49948775145}], "record_time": 1742584882.491602, "EXCHANGE": "OKX"}
{"arg": {"channel": "books", "instId": "BTC-USDT"}, "action": "update", "data": [{"asks": [["84071.9", "0.81585898", "0", "19"], ["84084.1", "0.47627664", "0", "1"], ["84084.2", "1", "0", "1"], ["84084.9", "0", "0", "0"], ["84085.6", "0", "0", "0"], ["84088", "0.2", "0", "1"], ["84088.2", "0.43027819", "0", "2"], ["84089", "1", "0", "1"], ["84098.4", "0", "0", "0"], ["84099.9", "0.23862436", "0", "2"], ["84109.6", "0.08", "0", "2"], ["84110.4", "0.03999999", "0", "1"], ["84111.2", "0", "0", "0"], ["84237.8", "0", "0", "0"]], "bids": [["84054.6", "0.34123686", "0", "2"], ["84051.5", "0", "0", "0"], ["84050.3", "0.4851697", "0", "1"], ["84050.2", "1", "0", "1"], ["84049.7", "0", "0", "0"], ["84042.2", "0.23801547", "0", "1"], ["84029", "1", "0", "1"], ["84013.6", "0.01832728", "0", "1"], ["84011.3", "0.01", "0", "1"], ["83944.2", "0.18327289", "0", "1"], ["83929.8", "0", "0", "0"], ["83929.5", "0", "0", "0"]], "ts": "1742584882506", "checksum": 1869303295, "seqId": 49948775199, "prevSeqId": 49948775156}], "record_time": 1742584882.590723, "EXCHANGE": "OKX"}
{"arg": {"channel": "books", "instId": "BTC-USDT"}, "action": "update", "data": [{"asks": [["84075.3", "0", "0", "0"], ["84088", "0", "0", "0"], ["84088.2", "0.1696415", "0", "1"], ["84089", "0", "0", "0"], ["84090.6", "0.01153238", "0", "1"], ["84096.1", "0.23802076", "0", "1"], ["84099.9", "0.00060645", "0", "1"], ["84102.4", "0.0008", "0", "2"], ["84103.2", "0.0004", "0", "1"], ["84104", "0", "0", "0"], ["84237.8", "0.00005956", "0", "1"]], "bids": [["84070", "0", "0", "0"], ["84063.6", "0.03370362", "0", "1"], ["84063.3", "0", "0", "0"], ["84061", "0", "0", "0"], ["84042.2", "0", "0", "0"], ["84039.9", "0.23801854", "0", "1"], ["84029", "0", "0", "0"], ["83929.8", "0.00011809", "0", "3"], ["83929.5", "0.17898725", "0", "1"], ["83929.1", "0.00016972", "0", "1"], ["83928.5", "0.03374921", "0", "4"]], "ts": "1742584882706", "checksum": -508017267, "seqId": 49948775231, "prevSeqId": 49948775199}], "record_time": 1742584882.791725, "EXCHANGE": "OKX"}
{"arg": {"channel": "books", "instId": "BTC-USDT"}, "action": "update", "data": [{"asks": [["84096.1", "0", "0", "0"], ["84097.5", "0.23801931", "0", "1"], ["84173.4", "0.1", "0", "1"], ["84237.8", "0", "0", "0"]], "bids": [["84056.9", "0.016755", "0", "2"]], "ts": "1742584882806", "checksum": -1764628321, "seqId": 49948775240, "prevSeqId": 49948775231}], "record_time": 1742584882.891539, "EXCHANGE": "OKX"}
{"arg": {"channel": "books", "instId": "BTC-USDT"}, "action": "update", "data": [{"asks": [["84071.9", "0.81229198", "0", "18"], ["84080.2", "0.01389953", "0", "2"], ["84090.2", "0.002", "0", "1"], ["84097.5", "0.23801837", "0", "1"], ["84097.8", "0.003567", "0", "1"], ["84105", "0.49082817", "0", "3"], ["84106.8", "0.471112", "0", "1"], ["84143.4", "0.17458442", "0", "1"], ["84144.7", "0", "0", "0"], ["84185.6", "0", "0", "0"], ["84237.2", "0", "0", "0"]], "bids": [["84071.6", "0.0495", "0", "1"], ["84069.9", "0.002", "0", "1"], ["84067.3", "0.07425", "0", "1"], ["84063.6", "0.09024067", "0", "2"], ["84063.3", "0.2025", "0", "1"], ["84059.8", "0.002", "0", "1"], ["84039.9", "0.23801837", "0", "1"], ["83929.9", "0", "0", "0"], ["83929.8", "0", "0", "0"], ["83929.5", "0", "0", "0"], ["83929.1", "0", "0", "0"], ["83928.5", "0", "0", "0"]], "ts": "1742584882906", "checksum": 1718778932, "seqId": 49948775264, "prevSeqId": 49948775240}], "record_time": 1742584882.991718, "EXCHANGE": "OKX"}
{"arg": {"channel": "books", "instId": "BTC-USDT"}, "action": "update", "data": [{"asks": [["84093.2", "0.17823329", "0", "1"], ["84093.4", "0", "0", "0"], ["84097.5", "0", "0", "0"], ["84098.1", "0.23801333", "0", "1"], ["84122.9", "0", "0", "0"], ["84123", "0", "0", "0"], ["84237.2", "0.00001115", "0", "1"], ["84237.8", "0.00005956", "0", "1"], ["84238.1", "0.00006534", "0", "2"]], "bids": [["84070", "0.0439", "0", "1"], ["84054.6", "0.57298863", "0", "3"], ["84051.5", "1", "0", "1"], ["84050.3", "0.1851697", "0", "1"], ["84050.2", "0", "0", "0"], ["84044.6", "0.23801333", "0", "1"], ["84041.5", "0.28287066", "0", "1"], ["84039.9", "0", "0", "0"], ["84038.9", "0", "0", "0"], ["84011.8", "0.31973363", "0", "1"], ["84009.3", "0", "0", "0"], ["83929.9", "0.00007149", "0", "1"]], "ts": "1742584883006", "checksum": 752227273, "seqId": 49948775291, "prevSeqId": 49948775264}], "record_time": 1742584883.091538, "EXCHANGE": "OKX"}
{"arg": {"channel": "books", "instId": "BTC-USDT"}, "action": "update", "data": [{"asks": [["84071.9", "0.87534378", "0", "20"], ["84084.1", "0.88148305", "0", "2"], ["84084.2", "0", "0", "0"], ["84085.6", "1", "0", "1"], ["84087.4", "1.54913662", "0", "1"], ["84088.7", "0.01189221", "0", "1"], ["84097.8", "0", "0", "0"], ["84098.1", "0", "0", "0"], ["84099.9", "0.23861888", "0", "2"], ["84102.4", "0", "0", "0"], ["84103.2", "0.0008", "0", "2"], ["84104", "0.0004", "0", "1"], ["84109.6", "0", "0", "0"], ["84110.4", "0.07999999", "0", "2"], ["84111.2", "0.03999999", "0", "1"], ["84117", "2.79255249", "0", "1"]], "bids": [["84071.2", "0.11900379", "0", "1"], ["84069.2", "0", "0", "0"], ["84045.5", "0", "0", "0"], ["84045.1", "0.23801243", "0", "1"], ["84044.6", "0", "0", "0"], ["84037.3", "0.91873709", "0", "2"], ["84036.2", "1.62092201", "0", "1"], ["84006.6", "3.18028831", "0", "2"], ["83996", "0.00100351", "0", "1"], ["83995.9", "0.01774536", "0", "1"], ["83929.9", "0", "0", "0"]], "ts": "1742584883106", "checksum": 1477086614, "seqId": 49948775324, "prevSeqId": 49948775291}], "record_time": 1742584883.191396, "EXCHANGE": "OKX"}
{"arg": {"channel": "books", "instId": "BTC-USDT"}, "action": "update", "data": [{"asks": [], "bids": [["84045.1", "0", "0", "0"], ["84044.3", "0.2380137", "0", "1"], ["84042.5", "0.17842", "0", "1"], ["84037.4", "0", "0", "0"]], "ts": "1742584883206", "checksum": 1477086614, "seqId": 49948775328, "prevSeqId": 49948775324}], "record_time": 1742584883.293638, "EXCHANGE": "OKX"}
{"arg": {"channel": "books", "instId": "BTC-USDT"}, "action": "update", "data": [{"asks": [["84109.6", "0.08", "0", "2"], ["84110.4", "0.03999999", "0", "1"], ["84111.2", "0", "0", "0"]], "bids": [], "ts": "1742584883306", "checksum": 1477086614, "seqId": 49948775334, "prevSeqId": 49948775328}], "record_time": 1742584883.39233, "EXCHANGE": "OKX"}
{"arg": {"channel": "books", "instId": "BTC-USDT"}, "action": "update", "data": [{"asks": [["84147.4", "0", "0", "0"], ["84238.3", "0.20843858", "0", "2"]], "bids": [["84045.5", "0.01774536", "0", "1"], ["84042.5", "0", "0", "0"], ["84037.4", "0.17842", "0", "1"], ["83995.9", "0", "0", "0"], ["83982.5", "0.07875252", "0", "1"]], "ts": "1742584883406", "checksum": 1477086614, "seqId": 49948775345, "prevSeqId": 49948775334}], "record_time": 1742584883.491571, "EXCHANGE": "OKX"}
{"arg": {"channel": "books", "instId": "BTC-USDT"}, "action": "update", "data": [{"asks": [["84084.3", "1", "0", "1"], ["84085.6", "0", "0", "0"], ["84097.5", "0.23801882", "0", "1"], ["84099.9", "0.00060645", "0", "1"], ["84147.4", "0.07130346", "0", "1"], ["84154.1", "0", "0", "0"], ["84238.3", "0", "0", "0"]], "bids": [["84054.6", "0.34123686", "0", "2"], ["84051.5", "0", "0", "0"], ["84050.3", "0.46202349", "0", "2"], ["84049.8", "1.04", "0", "2"], ["84044.3", "0", "0", "0"], ["84039.9", "0.23801882", "0", "1"], ["83989.2", "0", "0", "0"], ["83982.5", "0.15019596", "0", "2"], ["83929.9", "0.00007149", "0", "1"], ["83929.8", "0.00011809", "0", "3"]], "ts": "1742584883506", "checksum": 1477086614, "seqId": 49948775370, "prevSeqId": 49948775345}], "record_time": 1742584883.593317, "EXCHANGE": "OKX"}
{"arg": {"channel": "books", "instId": "BTC-USDT"}, "action": "update", "data": [{"asks": [["84097.5", "0.23801895", "0", "1"], ["84101", "0.12883018", "0", "2"], ["84110.1", "0.2025", "0", "1"], ["84147.4", "0.14260692", "0", "2"]], "bids": [["84071.2", "0", "0", "0"], ["84069", "0.11900698", "0", "1"], ["84054.6", "0.57298863", "0", "3"], ["84050.8", "1.00001197", "0", "2"], ["84050.3", "0.1851697", "0", "1"], ["84049.8", "0.04", "0", "1"], ["84039.9", "0.23801895", "0", "1"], ["83982.6", "0.12457285", "0", "1"], ["83982.5", "0.14288688", "0", "2"], ["83929.8", "0", "0", "0"]], "ts": "1742584883606", "checksum": 407901636, "seqId": 49948775406, "prevSeqId": 49948775370}], "record_time": 1742584883.691276, "EXCHANGE": "OKX"}
{"arg": {"channel": "books", "instId": "BTC-USDT"}, "action": "update", "data": [{"asks": [["84087", "1.2", "0", "2"], ["84097.5", "0", "0", "0"], ["84099.9", "0.23862341", "0", "2"], ["84100", "0.55028061", "0", "2"], ["84107.4", "0", "0", "0"], ["84238.3", "0.20843858", "0", "2"]], "bids": [["84041.6", "0.26182611", "0", "2"], ["84039.9", "0", "0", "0"], ["84027.5", "0.01189061", "0", "1"], ["84027.3", "0.1", "0", "1"], ["84023", "1", "0", "1"], ["83929.9", "0", "0", "0"]], "ts": "1742584883706", "checksum": 407901636, "seqId": 49948775423, "prevSeqId": 49948775406}], "record_time": 1742584883.791412, "EXCHANGE": "OKX"}
{"arg": {"channel": "books", "instId": "BTC-USDT"}, "action": "update", "data": [{"asks": [["84147.4", "0.07130346", "0", "1"]], "bids": [["84041.6", "0.02380915", "0", "1"], ["84039.9", "0.23801741", "0", "1"], ["84023", "0", "0", "0"], ["83982.5", "0.07144344", "0", "1"]], "ts": "1742584883806", "checksum": 407901636, "seqId": 49948775435, "prevSeqId": 49948775423}], "record_time": 1742584883.891209, "EXCHANGE": "OKX"}
{"arg": {"channel": "books", "instId": "BTC-USDT"}, "action": "update", "data": [{"asks": [["84091.8", "0.11897478", "0", "1"], ["84093.2", "0.25040775", "0", "2"], ["84106.4", "0.57213448", "0", "4"], ["84122.3", "0.43875277", "0", "1"], ["84147.4", "0", "0", "0"], ["84238.3", "0", "0", "0"]], "bids": [["83982.6", "0", "0", "0"], ["83982.5", "0", "0", "0"], ["83929.9", "0.00007149", "0", "1"], ["83929.8", "0.00011809", "0", "3"]], "ts": "1742584883906", "checksum": 407901636, "seqId": 49948775447, "prevSeqId": 49948775435}], "record_time": 1742584883.99191, "EXCHANGE": "OKX"}
{"arg": {"channel": "books", "instId": "BTC-USDT"}, "action": "update", "data": [{"asks": [["84147.3", "0.12530531", "0", "2"], ["84147.4", "0.14260692", "0", "2"], ["84148.7", "0", "0", "0"]], "bids": [["84062", "0.01190107", "0", "1"], ["84059.5", "0", "0", "0"], ["84041.7", "0.2380166", "0", "1"], ["84039.9", "0", "0", "0"], ["83982.5", "0.14288688", "0", "2"], ["83929.8", "0", "0", "0"]], "ts": "1742584884006", "checksum": -309091743, "seqId": 49948775467, "prevSeqId": 49948775447}], "record_time": 1742584884.09165, "EXCHANGE": "OKX"}
{"arg": {"channel": "books", "instId": "BTC-USDT"}, "action": "update", "data": [{"asks": [["84071.9", "0.67534378", "0", "19"], ["84079.9", "0.52045626", "0", "2"], ["84080.2", "0.002", "0", "1"], ["84082.9", "1", "0", "1"], ["84084.3", "0", "0", "0"]], "bids": [["84048.7", "0.168", "0", "3"], ["84041.7", "0", "0", "0"], ["84039.9", "0.23801749", "0", "1"], ["84015.7", "0.0901946", "0", "4"], ["84013.7", "0.00218403", "0", "1"], ["84013.6", "0", "0", "0"], ["84013.5", "0", "0", "0"], ["83996", "0", "0", "0"], ["83995.9", "0.00100352", "0", "1"], ["83929.8", "0.00011809", "0", "3"]], "ts": "1742584884106", "checksum": -1201815664, "seqId": 49948775485, "prevSeqId": 49948775467}], "record_time": 1742584884.191174, "EXCHANGE": "OKX"}
{"arg": {"channel": "books", "instId": "BTC-USDT"}, "action": "update", "data": [{"asks": [["84071.9", "0.67177678", "0", "18"], ["84079.9", "0.23255832", "0", "1"], ["84082.9", "0", "0", "0"], ["84084.3", "1", "0", "1"], ["84087", "0", "0", "0"], ["84099.9", "0.23862274", "0", "2"], ["84102.4", "0.0008", "0", "2"], ["84102.5", "0.003567", "0", "1"], ["84103.2", "0.0004", "0", "1"], ["84104", "0", "0", "0"], ["84147.3", "0.044921", "0", "1"], ["84147.4", "0.07130346", "0", "1"], ["84165.7", "0.00579968", "0", "1"], ["84173.2", "0", "0", "0"], ["84238.3", "0.20843858", "0", "2"]], "bids": [["84041.7", "0.23801679", "0", "1"], ["84039.9", "0", "0", "0"], ["83982.5", "0.07144344", "0", "1"], ["83968.5", "0", "0", "0"], ["83968.1", "0", "0", "0"], ["83929.5", "0.17898725", "0", "1"], ["83929.1", "0.00016972", "0", "1"]], "ts": "1742584884206", "checksum": -1844883190, "seqId": 49948775522, "prevSeqId": 49948775485}], "record_time": 1742584884.292166, "EXCHANGE": "OKX"}
{"arg": {"channel": "books", "instId": "BTC-USDT"}, "action": "update", "data": [{"asks": [["84146.1", "0.0011884", "0", "1"], ["84147.4", "0.14260692", "0", "2"], ["84153.7", "0.01425961", "0", "1"], ["84220.3", "0.00118736", "0", "1"], ["84237.8", "0", "0", "0"], ["84238.1", "0", "0", "0"], ["84238.3", "0", "0", "0"]], "bids": [["84054.6", "0.34123686", "0", "2"], ["84050.8", "0.00001197", "0", "1"], ["84043.5", "0.23801651", "0", "1"], ["84041.7", "0", "0", "0"], ["83982.5", "0.14288688", "0", "2"], ["83982.3", "0.00213719", "0", "1"], ["83981.9", "0.01636052", "0", "1"], ["83929.5", "0", "0", "0"], ["83929.1", "0", "0", "0"]], "ts": "1742584884306", "checksum": -1844883190, "seqId": 49948775549, "prevSeqId": 49948775522}], "record_time": 1742584884.391899, "EXCHANGE": "OKX"}
{"arg": {"channel": "books", "instId": "BTC-USDT"}, "action": "update", "data": [{"asks": [["84098.1", "0.23801707", "0", "1"], ["84099.9", "0.00060645", "0", "1"], ["84154", "0", "0", "0"]], "bids": [["84054.6", "0.57298863", "0", "3"], ["84051.8", "1", "0", "1"], ["84043.5", "0", "0", "0"], ["84041.7", "0.23801703", "0", "1"], ["83929.8", "0", "0", "0"]], "ts": "1742584884406", "checksum": -1844883190, "seqId": 49948775558, "prevSeqId": 49948775549}], "record_time": 1742584884.49185, "EXCHANGE": "OKX"}
{"arg": {"channel": "books", "instId": "BTC-USDT"}, "action": "update", "data": [{"asks": [["84098.1", "0", "0", "0"], ["84099.9", "0.23862266", "0", "2"], ["84102.4", "0", "0", "0"], ["84103.2", "0.0008", "0", "2"], ["84104", "0.0004", "0", "1"], ["84153", "0", "0", "0"], ["84237.8", "0.00005956", "0", "1"], ["84238.1", "0.00006534", "0", "2"]], "bids": [["84071.8", "0.14055329", "0", "12"], ["84069", "0", "0", "0"], ["83929.8", "0.00011809", "0", "3"]], "ts": "1742584884506", "checksum": -344372130, "seqId": 49948775569, "prevSeqId": 49948775558}], "record_time": 1742584884.59196, "EXCHANGE": "OKX"}
{"arg": {"channel": "books", "instId": "BTC-USDT"}, "action": "update", "data": [{"asks": [["84084.3", "0", "0", "0"], ["84085.7", "1", "0", "1"], ["84099.9", "0.23862005", "0", "2"], ["84100.9", "0.01189048", "0", "1"], ["84101.8", "0", "0", "0"], ["84156", "0.00036", "0", "1"], ["84238.1", "0", "0", "0"]], "bids": [["84044.6", "0.2380136", "0", "1"], ["84041.7", "0", "0", "0"], ["84030.1", "0.02378095", "0", "2"], ["84029.3", "0.30276524", "0", "2"]], "ts": "1742584884606", "checksum": -344372130, "seqId": 49948775594, "prevSeqId": 49948775569}], "record_time": 1742584884.691816, "EXCHANGE": "OKX"}
{"arg": {"channel": "books", "instId": "BTC-USDT"}, "action": "update", "data": [{"asks": [["84071.9", "0.67534378", "0", "19"], ["84102.5", "0", "0", "0"], ["84238.1", "0.00006534", "0", "2"]], "bids": [["84044.6", "0", "0", "0"], ["84042.2", "0.238016", "0", "1"]], "ts": "1742584884706", "checksum": -2059106388, "seqId": 49948775600, "prevSeqId": 49948775594}], "record_time": 1742584884.791824, "EXCHANGE": "OKX"}
{"arg": {"channel": "books", "instId": "BTC-USDT"}, "action": "update", "data": [{"asks": [["84071.9", "0.53719603", "0", "16"], ["84084.1", "0.47627664", "0", "1"], ["84085.7", "0", "0", "0"], ["84088.2", "0.45218846", "0", "2"], ["84089.2", "1", "0", "1"], ["84098.7", "0.003567", "0", "1"], ["84099.9", "0.00060645", "0", "1"], ["84104.4", "0.23800847", "0", "1"], ["84109.6", "0", "0", "0"], ["84110.4", "0.07999999", "0", "2"], ["84111.2", "0.03999999", "0", "1"], ["84237.8", "0", "0", "0"], ["84238.1", "0", "0", "0"]], "bids": [["84056.9", "0.01674", "0", "1"], ["84053.4", "1", "0", "1"], ["84051.8", "0", "0", "0"], ["84046.5", "0.23800847", "0", "1"], ["84042.2", "0", "0", "0"], ["84037.4", "0", "0", "0"], ["84032", "1.013", "0", "2"], ["83929.5", "0.17898725", "0", "1"]], "ts": "1742584884806", "checksum": -1699721903, "seqId": 49948775623, "prevSeqId": 49948775600}], "record_time": 1742584884.891763, "EXCHANGE": "OKX"}
{"arg": {"channel": "books", "instId": "BTC-USDT"}, "action": "update", "data": [{"asks": [["84071.9", "0.29794054", "0", "12"], ["84073.3", "0", "0", "0"], ["84075.9", "0.11899737", "0", "1"], ["84076.8", "0", "0", "0"], ["84079.6", "0.00844", "0", "1"], ["84081.4", "0", "0", "0"], ["84085.9", "0.02534", "0", "1"], ["84086.8", "0", "0", "0"], ["84095.3", "0.11898185", "0", "2"], ["84101", "0.18897525", "0", "3"], ["84237.8", "0.00005956", "0", "1"]], "bids": [["84071.8", "0.42110303", "0", "15"], ["84064.6", "0.01190069", "0", "1"], ["84062.6", "0.00537361", "0", "2"], ["84062", "0", "0", "0"], ["84060.7", "0.00002697", "0", "2"], ["84060.3", "0.020697", "0", "1"], ["84060.2", "0.01674", "0", "1"], ["84059.6", "0.05024", "0", "1"], ["84058", "0", "0", "0"], ["84050.5", "0", "0", "0"], ["84033.4", "0.49334104", "0", "2"], ["84016", "0.2", "0", "1"], ["84008.1", "1.26984892", "0", "3"], ["83982.6", "0.13012216", "0", "1"], ["83929.9", "0", "0", "0"], ["83929.8", "0", "0", "0"], ["83929.5", "0", "0", "0"]], "ts": "1742584884906", "checksum": 1015730614, "seqId": 49948775661, "prevSeqId": 49948775623}], "record_time": 1742584884.99223, "EXCHANGE": "OKX"}
{"arg": {"channel": "books", "instId": "BTC-USDT"}, "action": "update", "data": [{"asks": [["84073.9", "0.11900018", "0", "1"], ["84075.9", "0", "0", "0"], ["84100.6", "0", "0", "0"], ["84238.1", "0.00006534", "0", "2"]], "bids": [["84059", "0.04283411", "0", "1"], ["84055.4", "0", "0", "0"], ["84048.8", "0.30100571", "0", "2"], ["84046.5", "0", "0", "0"], ["84045.4", "0", "0", "0"], ["84042.5", "0.17842", "0", "1"], ["84028.1", "0", "0", "0"], ["84016", "0", "0", "0"], ["83976.5", "0", "0", "0"], ["83937.2", "0.18323851", "0", "2"], ["83929.9", "0.00007149", "0", "1"], ["83929.8", "0.00011809", "0", "3"], ["83929.5", "0.17898725", "0", "1"], ["83929.1", "0.00016972", "0", "1"]], "ts": "1742584885006", "checksum": -1707881741, "seqId": 49948775675, "prevSeqId": 49948775661}], "record_time": 1742584885.091673, "EXCHANGE": "OKX"}
{"arg": {"channel": "books", "instId": "BTC-USDT"}, "action": "update", "data": [{"asks": [["84071.9", "0.31578354", "0", "13"], ["84099.7", "0.01189065", "0", "1"], ["84238.1", "0", "0", "0"]], "bids": [["84066.3", "0.01674", "0", "1"], ["84060.2", "0", "0", "0"], ["84048.8", "0.063", "0", "1"], ["84046.5", "0.23800755", "0", "1"], ["84045.5", "0", "0", "0"], ["84044.6", "0.01774536", "0", "1"], ["84028.9", "0.01189065", "0", "1"], ["83929.5", "0", "0", "0"], ["83929.1", "0", "0", "0"]], "ts": "1742584885106", "checksum": 156920658, "seqId": 49948775688, "prevSeqId": 49948775675}], "record_time": 1742584885.191724, "EXCHANGE": "OKX"}
{"arg": {"channel": "books", "instId": "BTC-USDT"}, "action": "update", "data": [{"asks": [["84071.9", "0.29794054", "0", "12"], ["84079.9", "0.54118956", "0", "2"], ["84082", "0.27691028", "0", "4"], ["84083", "1.000015", "0", "2"], ["84084.1", "0.86211202", "0", "2"], ["84087.1", "1.04", "0", "2"], ["84088.2", "0.1696415", "0", "1"], ["84089.2", "0", "0", "0"], ["84238.1", "0.00006534", "0", "2"]], "bids": [["84062.6", "0.00011161", "0", "1"], ["84054.6", "0.34123686", "0", "2"], ["84053.4", "0", "0", "0"], ["84051.6", "1", "0", "1"]], "ts": "1742584885206", "checksum": -1032471548, "seqId": 49948775708, "prevSeqId": 49948775688}], "record_time": 1742584885.291736, "EXCHANGE": "OKX"}
{"arg": {"channel": "books", "instId": "BTC-USDT"}, "action": "update", "data": [{"asks": [["84100.9", "0.2499024", "0", "2"], ["84101", "0.12883018", "0", "2"], ["84104.4", "0", "0", "0"], ["84238.3", "0.20843858", "0", "2"]], "bids": [["84064.4", "0.0000225", "0", "1"], ["84051.6", "0", "0", "0"], ["84050.2", "1", "0", "1"], ["84046.5", "0", "0", "0"], ["84045.5", "0.2380121", "0", "1"], ["84045.4", "0.35684", "0", "1"], ["84033.4", "0.01804", "0", "1"], ["84032", "0.013", "0", "1"], ["83929.9", "0", "0", "0"], ["83929.8", "0", "0", "0"]], "ts": "1742584885306", "checksum": -1612543594, "seqId": 49948775737, "prevSeqId": 49948775708}], "record_time": 1742584885.39171, "EXCHANGE": "OKX"}
{"arg": {"channel": "books", "instId": "BTC-USDT"}, "action": "update", "data": [{"asks": [["84071.9", "0.31578354", "0", "13"], ["84099.3", "0.00356191", "0", "1"], ["84100.1", "0.0118906", "0", "1"], ["84185", "0", "0", "0"]], "bids": [["84045.6", "0.01774536", "0", "1"], ["84044.6", "0", "0", "0"], ["84028.5", "0", "0", "0"], ["84027.6", "0.0118906", "0", "1"]], "ts": "1742584885406", "checksum": 627099803, "seqId": 49948775751, "prevSeqId": 49948775737}], "record_time": 1742584885.4918, "EXCHANGE": "OKX"}
{"arg": {"channel": "books", "instId": "BTC-USDT"}, "action": "update", "data": [{"asks": [["84098.7", "0", "0", "0"], ["84099.1", "0.01189074", "0", "1"], ["84099.2", "0", "0", "0"], ["84116", "0.003567", "0", "1"], ["84186", "0", "0", "0"], ["84238.4", "0.03", "0", "1"]], "bids": [["84028.3", "0.01189074", "0", "1"]], "ts": "1742584885506", "checksum": 627099803, "seqId": 49948775762, "prevSeqId": 49948775751}], "record_time": 1742584885.594445, "EXCHANGE": "OKX"}
{"arg": {"channel": "books", "instId": "BTC-USDT"}, "action": "update", "data": [{"asks": [["84087.9", "0.01189232", "0", "1"], ["84088.7", "0", "0", "0"], ["84100.9", "0.24990229", "0", "2"], ["84194", "0.09002", "0", "2"]], "bids": [["84045.5", "0.23801181", "0", "1"]], "ts": "1742584885606", "checksum": 627099803, "seqId": 49948775781, "prevSeqId": 49948775762}], "record_time": 1742584885.691714, "EXCHANGE": "OKX"}
{"arg": {"channel": "books", "instId": "BTC-USDT"}, "action": "update", "data": [{"asks": [["84100.9", "0.01189048", "0", "1"], ["84104.4", "0.23801149", "0", "1"], ["84194", "0.08752", "0", "1"], ["84238.4", "0", "0", "0"]], "bids": [["84046.5", "0.23801145", "0", "1"], ["84045.5", "0", "0", "0"]], "ts": "1742584885706", "checksum": 627099803, "seqId": 49948775793, "prevSeqId": 49948775781}], "record_time": 1742584885.791745, "EXCHANGE": "OKX"}
{"arg": {"channel": "books", "instId": "BTC-USDT"}, "action": "update", "data": [{"asks": [["84073.4", "0.2", "0", "1"], ["84104.4", "0.23801094", "0", "1"], ["84187", "0", "0", "0"]], "bids": [["84054.6", "0.55791663", "0", "3"], ["84051.6", "1", "0", "1"], ["84050.2", "0", "0", "0"], ["84046.5", "0.23801094", "0", "1"], ["84045.6", "0", "0", "0"], ["84045.5", "0.01774536", "0", "1"]], "ts": "1742584885806", "checksum": -1825357938, "seqId": 49948775809, "prevSeqId": 49948775793}], "record_time": 1742584885.893194, "EXCHANGE": "OKX"}
{"arg": {"channel": "books", "instId": "BTC-USDT"}, "action": "update", "data": [{"asks": [["84071.9", "0.61828354", "0", "15"], ["84072.1", "0.12019213", "0", "2"], ["84073.9", "0", "0", "0"], ["84076", "0.00844", "0", "1"], ["84079.6", "0", "0", "0"], ["84081", "0.02534", "0", "1"], ["84085.3", "1", "0", "1"], ["84085.9", "0", "0", "0"], ["84087.1", "0.04", "0", "1"], ["84100.3", "0.23802512", "0", "2"], ["84104.4", "0", "0", "0"], ["84238.4", "0.03", "0", "1"]], "bids": [["84071.8", "0.14055329", "0", "12"], ["84066.3", "0", "0", "0"], ["84062.4", "0.01674", "0", "1"], ["84060.3", "0.01345323", "0", "1"], ["84059.6", "0", "0", "0"], ["84054.7", "0.48561871", "0", "4"], ["84054.6", "0.34123686", "0", "2"], ["84051.6", "0", "0", "0"], ["84050.3", "0.45845229", "0", "2"], ["84050.1", "1", "0", "1"], ["84046.5", "0", "0", "0"], ["84044.1", "0.23801315", "0", "1"], ["83929.9", "0.00007149", "0", "1"]], "ts": "1742584885906", "checksum": -641195828, "seqId": 49948775840, "prevSeqId": 49948775809}], "record_time": 1742584885.991216, "EXCHANGE": "OKX"}
{"arg": {"channel": "books", "instId": "BTC-USDT"}, "action": "update", "data": [{"asks": [["84099.9", "0.23862077", "0", "2"], ["84100.3", "0.00001197", "0", "1"], ["84102.4", "0.0008", "0", "2"], ["84103.2", "0.0004", "0", "1"], ["84104", "0", "0", "0"], ["84109.6", "0.08", "0", "2"], ["84110.4", "0.03999999", "0", "1"], ["84111.2", "0", "0", "0"], ["84113.8", "0.98746229", "0", "2"], ["84147.3", "0.12530531", "0", "2"]], "bids": [["84050.1", "0", "0", "0"], ["84048.6", "1", "0", "1"], ["84044.1", "0", "0", "0"], ["84042.2", "0.23801517", "0", "1"], ["84031.6", "0.19314105", "0", "1"], ["83929.9", "0", "0", "0"]], "ts": "1742584886006", "checksum": -641195828, "seqId": 49948775865, "prevSeqId": 49948775840}], "record_time": 1742584886.106198, "EXCHANGE": "OKX"}
{"arg": {"channel": "books", "instId": "BTC-USDT"}, "action": "update", "data": [{"asks": [["84071.9", "0.81828354", "0", "16"], ["84072.7", "0.00844", "0", "1"], ["84076", "0", "0", "0"]], "bids": [["84062.4", "0", "0", "0"], ["84059.1", "0.01674", "0", "1"], ["84042.2", "0.23801492", "0", "1"], ["84031.2", "0.1", "0", "2"], ["84030.4", "0.05", "0", "1"], ["84029.6", "0", "0", "0"], ["84015.7", "0.07186723", "0", "3"], ["84013.8", "0.01832714", "0", "1"], ["84013.7", "0", "0", "0"], ["84013.5", "0.00218392", "0", "1"], ["83944.2", "0", "0", "0"], ["83943.8", "0.18327149", "0", "1"], ["83930", "0", "0", "0"]], "ts": "1742584886106", "checksum": 1708080074, "seqId": 49948775889, "prevSeqId": 49948775865}], "record_time": 1742584886.19226, "EXCHANGE": "OKX"}
{"arg": {"channel": "books", "instId": "BTC-USDT"}, "action": "update", "data": [{"asks": [["84071.9", "0.61828354", "0", "15"], ["84073.3", "0.17898725", "0", "1"], ["84102.4", "0", "0", "0"], ["84103.2", "0.0008", "0", "2"], ["84104", "0.0004", "0", "1"], ["84109.6", "0", "0", "0"], ["84110.4", "0.07999999", "0", "2"], ["84111.2", "0.03999999", "0", "1"], ["84238.4", "0", "0", "0"]], "bids": [["84031.2", "0", "0", "0"], ["84030.4", "0.1", "0", "2"], ["84029.6", "0.05", "0", "1"], ["84014", "0.01832721", "0", "1"], ["84013.9", "0.00218392", "0", "1"], ["84013.8", "0", "0", "0"], ["84013.5", "0", "0", "0"], ["83943.9", "0.18327216", "0", "1"], ["83943.8", "0", "0", "0"]], "ts": "1742584886206", "checksum": -1349245074, "seqId": 49948775942, "prevSeqId": 49948775889}], "record_time": 1742584886.291596, "EXCHANGE": "OKX"}
{"arg": {"channel": "books", "instId": "BTC-USDT"}, "action": "update", "data": [{"asks": [["84099.9", "0.00060645", "0", "1"], ["84100.3", "0.23802563", "0", "2"]], "bids": [["84044.1", "0.2380134", "0", "1"], ["84042.2", "0", "0", "0"], ["84030", "1", "0", "1"], ["84015.9", "0.01832714", "0", "1"], ["84014", "0", "0", "0"], ["83944.5", "0.18327148", "0", "1"], ["83943.9", "0", "0", "0"], ["83930.2", "0", "0", "0"]], "ts": "1742584886306", "checksum": -1349245074, "seqId": 49948775968, "prevSeqId": 49948775942}], "record_time": 1742584886.391274, "EXCHANGE": "OKX"}
{"arg": {"channel": "books", "instId": "BTC-USDT"}, "action": "update", "data": [{"asks": [["84071.9", "0.41578354", "0", "14"]], "bids": [["84049.9", "1.00060645", "0", "2"], ["84048.6", "0", "0", "0"], ["83930.2", "0.00011454", "0", "1"]], "ts": "1742584886406", "checksum": 561622318, "seqId": 49948775975, "prevSeqId": 49948775968}], "record_time": 1742584886.491702, "EXCHANGE": "OKX"}
{"arg": {"channel": "books", "instId": "BTC-USDT"}, "action": "update", "data": [{"asks": [["84071.9", "0.61828354", "0", "15"], ["84147.3", "0.044921", "0", "1"], ["84147.4", "0.07130346", "0", "1"]], "bids": [["83982.5", "0.07144344", "0", "1"]], "ts": "1742584886606", "checksum": -1349245074, "seqId": 49948775988, "prevSeqId": 49948775975}], "record_time": 1742584886.692045, "EXCHANGE": "OKX"}
{"arg": {"channel": "books", "instId": "BTC-USDT"}, "action": "update", "data": [{"asks": [["84099.9", "0.23862039", "0", "2"], ["84100.3", "0.00001197", "0", "1"], ["84102.4", "0.0008", "0", "2"], ["84103.2", "0.0004", "0", "1"], ["84104", "0", "0", "0"], ["84109.6", "0.08", "0", "2"], ["84110.4", "0.03999999", "0", "1"], ["84111.2", "0", "0", "0"], ["84147.4", "0.14260692", "0", "2"]], "bids": [["84044.1", "0", "0", "0"], ["84042.5", "0", "0", "0"], ["84041.7", "0.23801545", "0", "1"], ["84031.2", "0.1", "0", "2"], ["84030.4", "0.05", "0", "1"], ["84029.6", "0", "0", "0"], ["84015.9", "0", "0", "0"], ["84014", "0.01832728", "0", "1"], ["83982.6", "0.0872561", "0", "1"], ["83982.5", "0.14288688", "0", "2"], ["83944.5", "0", "0", "0"], ["83943.8", "0.18327287", "0", "1"], ["83930", "0.00012899", "0", "1"]], "ts": "1742584886706", "checksum": -1349245074, "seqId": 49948776032, "prevSeqId": 49948775988}], "record_time": 1742584886.791412, "EXCHANGE": "OKX"}
{"arg": {"channel": "books", "instId": "BTC-USDT"}, "action": "update", "data": [{"asks": [["84079.9", "0.81128276", "0", "1"], ["84081", "0.11525011", "0", "2"], ["84081.8", "0.033567", "0", "2"], ["84083.8", "1.2385", "0", "3"], ["84084.1", "0.47627664", "0", "1"], ["84085.3", "0", "0", "0"], ["84094.3", "0.23802665", "0", "1"], ["84099.9", "0.00060645", "0", "1"], ["84116", "0", "0", "0"], ["84238.4", "0.03", "0", "1"]], "bids": [["84070", "0", "0", "0"], ["84063.6", "0.03370362", "0", "1"], ["84063.3", "0", "0", "0"], ["84049.9", "0.00060645", "0", "1"], ["84047.8", "1", "0", "1"], ["84041.7", "0", "0", "0"], ["84040", "0.17843", "0", "2"], ["84036.5", "0.23802665", "0", "1"], ["84031.2", "0", "0", "0"], ["84030.4", "0.1", "0", "2"], ["84030", "0", "0", "0"], ["84029.6", "0.05", "0", "1"], ["83929.9", "0.00007149", "0", "1"], ["83929.8", "0.00011809", "0", "3"]], "ts": "1742584886806", "checksum": -1363080414, "seqId": 49948776065, "prevSeqId": 49948776032}], "record_time": 1742584886.891853, "EXCHANGE": "OKX"}
{"arg": {"channel": "books", "instId": "BTC-USDT"}, "action": "update", "data": [{"asks": [["84073.2", "0.27109912", "0", "1"], ["84073.5", "0", "0", "0"], ["84074.4", "0.08991011", "0", "1"], ["84094.3", "0", "0", "0"], ["84096.1", "0.23802433", "0", "1"], ["84238.4", "0", "0", "0"]], "bids": [["84064.6", "0", "0", "0"], ["84064.4", "0", "0", "0"], ["84062", "0.01190109", "0", "1"], ["84037.9", "0.23802433", "0", "1"], ["84036.5", "0", "0", "0"], ["83929.5", "0.17898725", "0", "1"]], "ts": "1742584886906", "checksum": -1506435135, "seqId": 49948776088, "prevSeqId": 49948776065}], "record_time": 1742584886.992198, "EXCHANGE": "OKX"}
{"arg": {"channel": "books", "instId": "BTC-USDT"}, "action": "update", "data": [{"asks": [["84093.2", "0.34848421", "0", "1"], ["84096.1", "0", "0", "0"], ["84097", "0.23802158", "0", "1"], ["84147.3", "0.12530531", "0", "2"]], "bids": [["84056.7", "0.03988463", "0", "2"], ["84040", "0.00001", "0", "1"], ["84039.3", "0.23802158", "0", "1"], ["84037.9", "0", "0", "0"], ["84037.4", "0.17842", "0", "1"], ["83929.5", "0", "0", "0"]], "ts": "1742584887006", "checksum": 231758620, "seqId": 49948776101, "prevSeqId": 49948776088}], "record_time": 1742584887.090867, "EXCHANGE": "OKX"}
{"arg": {"channel": "books", "instId": "BTC-USDT"}, "action": "update", "data": [{"asks": [["84071.9", "0.81828354", "0", "16"], ["84073.4", "0", "0", "0"], ["84097", "0", "0", "0"], ["84099.9", "0.23862518", "0", "2"], ["84238.4", "0.03", "0", "1"], ["84238.9", "0.17898725", "0", "1"]], "bids": [["84049.1", "1", "0", "1"], ["84047.8", "0", "0", "0"], ["84042.2", "0.23801482", "0", "1"], ["84039.3", "0", "0", "0"], ["84030.1", "0.02378096", "0", "2"], ["84017", "0.49461771", "0", "2"]], "ts": "1742584887106", "checksum": 726499757, "seqId": 49948776121, "prevSeqId": 49948776101}], "record_time": 1742584887.191708, "EXCHANGE": "OKX"}
{"arg": {"channel": "books", "instId": "BTC-USDT"}, "action": "update", "data": [{"asks": [["84071.9", "0.29794054", "0", "12"], ["84072.1", "0.0011894", "0", "1"], ["84072.7", "0", "0", "0"], ["84073.2", "0.18412609", "0", "1"], ["84073.6", "0.006", "0", "1"], ["84074.4", "0", "0", "0"], ["84076.6", "0.00844", "0", "1"], ["84079.9", "0.57893145", "0", "1"], ["84081", "0.02534", "0", "1"], ["84083.8", "0.2385", "0", "2"], ["84087.3", "0", "0", "0"], ["84090.6", "0", "0", "0"], ["84092.6", "0.000045", "0", "1"], ["84093.4", "1", "0", "1"], ["84096.9", "0", "0", "0"], ["84099.9", "0.00060645", "0", "1"], ["84102.4", "0", "0", "0"], ["84103.2", "0", "0", "0"], ["84104", "0.01233238", "0", "3"], ["84104.8", "0.0004", "0", "1"], ["84107.6", "0.23799538", "0", "1"], ["84109.6", "0", "0", "0"], ["84110.4", "0.07999999", "0", "2"], ["84111.2", "0.03999999", "0", "1"], ["84239", "0.35564723", "0", "1"]], "bids": [["84071.8", "0.28182518", "0", "13"], ["84070", "0.0439", "0", "1"], ["84065.7", "0.00447447", "0", "2"], ["84065.4", "0.0119006", "0", "1"], ["84063.6", "0.09024067", "0", "2"], ["84063.3", "0.2025", "0", "1"], ["84062.9", "0.01674", "0", "1"], ["84062", "0", "0", "0"], ["84059.1", "0", "0", "0"], ["84058.8", "0.21401978", "0", "1"], ["84058.6", "0", "0", "0"], ["84056.7", "0.02799005", "0", "1"], ["84054.6", "0.55791663", "0", "3"], ["84053.7", "1", "0", "1"], ["84050.4", "0.23799569", "0", "1"], ["84050.3", "0.1851697", "0", "1"], ["84049.1", "0", "0", "0"], ["84042.2", "0", "0", "0"], ["84037.4", "0", "0", "0"], ["84035.2", "0", "0", "0"], ["84034.4", "0.08079864", "0", "4"], ["84033.6", "0.04039865", "0", "2"]], "ts": "1742584887206", "checksum": 46372141, "seqId": 49948776225, "prevSeqId": 49948776121}], "record_time": 1742584887.294291, "EXCHANGE": "OKX"}
{"arg": {"channel": "books", "instId": "BTC-USDT"}, "action": "update", "data": [{"asks": [["84071.9", "0.50044054", "0", "13"], ["84079.1", "0", "0", "0"], ["84085.9", "0.02930357", "0", "1"], ["84088.2", "0.44516109", "0", "2"], ["84092", "1", "0", "1"], ["84093.4", "0", "0", "0"], ["84104.4", "0.23800297", "0", "1"], ["84107.6", "0", "0", "0"]], "bids": [["84068.2", "0.01190044", "0", "1"], ["84065.4", "0", "0", "0"], ["84053.7", "0", "0", "0"], ["84051.5", "1", "0", "1"], ["84050.4", "0", "0", "0"], ["84048.9", "0.23800297", "0", "1"], ["84042.5", "0.17842", "0", "1"], ["84017", "0.29461771", "0", "1"], ["83929.8", "0", "0", "0"]], "ts": "1742584887306", "checksum": 1912628553, "seqId": 49948776241, "prevSeqId": 49948776225}], "record_time": 1742584887.391733, "EXCHANGE": "OKX"}
{"arg": {"channel": "books", "instId": "BTC-USDT"}, "action": "update", "data": [{"asks": [["84077.8", "0.11899461", "0", "1"], ["84090.6", "1", "0", "1"], ["84092", "0", "0", "0"], ["84239", "0", "0", "0"]], "bids": [["84052.9", "1.17898725", "0", "2"], ["84051.5", "0", "0", "0"], ["83986.4", "0", "0", "0"], ["83984.5", "0.00144987", "0", "1"], ["83929.8", "0.00011809", "0", "3"]], "ts": "1742584887406", "checksum": 187934195, "seqId": 49948776252, "prevSeqId": 49948776241}], "record_time": 1742584887.491106, "EXCHANGE": "OKX"}
{"arg": {"channel": "books", "instId": "BTC-USDT"}, "action": "update", "data": [{"asks": [["84072.1", "0", "0", "0"], ["84103.2", "0.0008", "0", "2"], ["84104", "0.01193238", "0", "2"], ["84104.8", "0", "0", "0"], ["84239", "0.35564723", "0", "1"]], "bids": [["84065.7", "0.00001197", "0", "1"], ["84052.9", "0.17898725", "0", "1"], ["84051.6", "1", "0", "1"], ["84048.9", "0", "0", "0"], ["84046.5", "0.23800686", "0", "1"], ["84035.2", "0.0008", "0", "2"], ["84034.4", "0.08039864", "0", "3"], ["84033.6", "0.04", "0", "1"], ["83929.9", "0", "0", "0"], ["83929.8", "0", "0", "0"]], "ts": "1742584887506", "checksum": -1757531428, "seqId": 49948776268, "prevSeqId": 49948776252}], "record_time": 1742584887.591948, "EXCHANGE": "OKX"}
{"arg": {"channel": "books", "instId": "BTC-USDT"}, "action": "update", "data": [{"asks": [["84071.9", "0.51828354", "0", "14"], ["84081.8", "0.03", "0", "1"], ["84089", "1", "0", "1"], ["84090.6", "0", "0", "0"], ["84099.9", "0.23861957", "0", "2"], ["84104.4", "0", "0", "0"], ["84108.9", "0.003567", "0", "1"]], "bids": [["84046.5", "0", "0", "0"], ["84043.5", "0.23801312", "0", "1"]], "ts": "1742584887606", "checksum": -1366098356, "seqId": 49948776285, "prevSeqId": 49948776268}], "record_time": 1742584887.691303, "EXCHANGE": "OKX"}
{"arg": {"channel": "books", "instId": "BTC-USDT"}, "action": "update", "data": [{"asks": [["84084.1", "0.86686293", "0", "2"], ["84087.6", "1", "0", "1"], ["84088.2", "0.1696415", "0", "1"], ["84089", "0", "0", "0"]], "bids": [["84063.4", "0.000051", "0", "1"], ["83930", "0", "0", "0"]], "ts": "1742584887706", "checksum": -2035443565, "seqId": 49948776290, "prevSeqId": 49948776285}], "record_time": 1742584887.791285, "EXCHANGE": "OKX"}
{"arg": {"channel": "books", "instId": "BTC-USDT"}, "action": "update", "data": [{"asks": [["84099.9", "0.00060645", "0", "1"], ["84104.4", "0.23800964", "0", "1"], ["84239", "0", "0", "0"]], "bids": [["84046.5", "0.23800964", "0", "1"], ["84043.5", "0", "0", "0"], ["84032", "1.013", "0", "2"], ["83986.4", "0.00144991", "0", "1"], ["83984.5", "0", "0", "0"]], "ts": "1742584887806", "checksum": -2035443565, "seqId": 49948776303, "prevSeqId": 49948776290}], "record_time": 1742584887.891531, "EXCHANGE": "OKX"}
{"arg": {"channel": "books", "instId": "BTC-USDT"}, "action": "update", "data": [{"asks": [], "bids": [["84032.1", "0.49720409", "0", "1"], ["84031.6", "0", "0", "0"]], "ts": "1742584887906", "checksum": -2035443565, "seqId": 49948776306, "prevSeqId": 49948776303}], "record_time": 1742584887.991544, "EXCHANGE": "OKX"}
{"arg": {"channel": "books", "instId": "BTC-USDT"}, "action": "update", "data": [{"asks": [["84086.3", "1", "0", "1"], ["84087.6", "0", "0", "0"], ["84101", "0.19243532", "0", "3"], ["84147.3", "0.10391427", "0", "2"], ["84147.4", "0.07130346", "0", "1"]], "bids": [["83982.5", "0.07144344", "0", "1"]], "ts": "1742584888006", "checksum": -2035443565, "seqId": 49948776317, "prevSeqId": 49948776306}], "record_time": 1742584888.091664, "EXCHANGE": "OKX"}
{"arg": {"channel": "books", "instId": "BTC-USDT"}, "action": "update", "data": [{"asks": [["84071.9", "0.61828354", "0", "15"], ["84074", "0.00844", "0", "1"], ["84076", "0.11899718", "0", "1"], ["84076.6", "0", "0", "0"], ["84077.8", "0", "0", "0"], ["84085", "1", "0", "1"], ["84086.3", "0", "0", "0"], ["84092.6", "0", "0", "0"], ["84100.6", "0.23801235", "0", "1"], ["84101", "0.12883018", "0", "2"], ["84102.3", "0", "0", "0"], ["84104.4", "0", "0", "0"], ["84112.3", "0", "0", "0"], ["84147.3", "0.044921", "0", "1"], ["84239", "0.35564723", "0", "1"], ["84239.3", "0.00011161", "0", "1"], ["84240", "0.00001197", "0", "1"]], "bids": [["84071.8", "0.13055329", "0", "10"], ["84063.6", "0.03370362", "0", "1"], ["84063.3", "0", "0", "0"], ["84062.9", "0", "0", "0"], ["84060.4", "0.01674", "0", "1"], ["84054.6", "0.34123686", "0", "2"], ["84051.6", "0", "0", "0"], ["84050.3", "0.45845229", "0", "2"], ["84049.6", "1", "0", "1"], ["84046.5", "0", "0", "0"], ["84044.6", "0.23801228", "0", "1"], ["84032.1", "0", "0", "0"], ["84032", "0.013", "0", "1"], ["84014.1", "0.00218389", "0", "1"], ["84013.9", "0", "0", "0"], ["83930", "0.00012899", "0", "1"], ["83929.9", "0.00007149", "0", "1"]], "ts": "1742584888106", "checksum": -713648133, "seqId": 49948776388, "prevSeqId": 49948776317}], "record_time": 1742584888.191618, "EXCHANGE": "OKX"}
{"arg": {"channel": "books", "instId": "BTC-USDT"}, "action": "update", "data": [{"asks": [["84086.9", "0.003234", "0", "1"], ["84099.9", "0.23861975", "0", "2"], ["84100.6", "0", "0", "0"], ["84147.4", "0.14260692", "0", "2"]], "bids": [["84063.6", "0.09025597", "0", "2"], ["84063.3", "0.2025", "0", "1"], ["84044.6", "0", "0", "0"], ["84042.6", "0.23801387", "0", "1"], ["83982.5", "0.14288688", "0", "2"], ["83929.9", "0", "0", "0"]], "ts": "1742584888206", "checksum": -158275876, "seqId": 49948776412, "prevSeqId": 49948776388}], "record_time": 1742584888.291326, "EXCHANGE": "OKX"}
{"arg": {"channel": "books", "instId": "BTC-USDT"}, "action": "update", "data": [{"asks": [["84071.9", "0.62426854", "0", "16"], ["84073.6", "0", "0", "0"], ["84086.1", "0.005", "0", "1"], ["84096.1", "0.005", "0", "1"], ["84240", "0", "0", "0"]], "bids": [["84070", "0.0489", "0", "2"], ["84059.9", "0.005", "0", "1"], ["83930", "0", "0", "0"]], "ts": "1742584888306", "checksum": 2031270672, "seqId": 49948776422, "prevSeqId": 49948776412}], "record_time": 1742584888.391025, "EXCHANGE": "OKX"}
{"arg": {"channel": "books", "instId": "BTC-USDT"}, "action": "update", "data": [{"asks": [["84099.9", "0.00060645", "0", "1"], ["84100.6", "0.23801247", "0", "1"], ["84232", "0.00118464", "0", "1"], ["84239", "0", "0", "0"], ["84239.3", "0", "0", "0"]], "bids": [["84068.2", "0", "0", "0"], ["84065.4", "0.01190085", "0", "1"], ["84044.6", "0.23801247", "0", "1"], ["84042.6", "0", "0", "0"]], "ts": "1742584888406", "checksum": -1253450873, "seqId": 49948776437, "prevSeqId": 49948776422}], "record_time": 1742584888.49189, "EXCHANGE": "OKX"}
{"arg": {"channel": "books", "instId": "BTC-USDT"}, "action": "update", "data": [{"asks": [["84100.6", "0", "0", "0"], ["84104.4", "0.23801161", "0", "1"]], "bids": [["84054.6", "0.55791663", "0", "3"], ["84051.1", "1", "0", "1"], ["84050.3", "0.1851697", "0", "1"], ["84049.6", "0", "0", "0"], ["84045.5", "0.25575697", "0", "2"], ["84044.6", "0", "0", "0"], ["83930", "0.00012899", "0", "1"]], "ts": "1742584888506", "checksum": -1253450873, "seqId": 49948776453, "prevSeqId": 49948776437}], "record_time": 1742584888.591258, "EXCHANGE": "OKX"}
{"arg": {"channel": "books", "instId": "BTC-USDT"}, "action": "update", "data": [{"asks": [["84100.9", "0.24990232", "0", "2"], ["84104.4", "0", "0", "0"], ["84239", "0.35564723", "0", "1"]], "bids": [], "ts": "1742584888606", "checksum": -1253450873, "seqId": 49948776459, "prevSeqId": 49948776453}], "record_time": 1742584888.690761, "EXCHANGE": "OKX"}
{"arg": {"channel": "books", "instId": "BTC-USDT"}, "action": "update", "data": [{"asks": [["84086.1", "0.01", "0", "2"], ["84096.1", "0.01", "0", "2"], ["84100.9", "0.01189048", "0", "1"], ["84104.4", "0.23801159", "0", "1"], ["84239", "0", "0", "0"]], "bids": [["84070", "0.0539", "0", "3"], ["84060.5", "0.02147523", "0", "1"], ["84060.3", "0", "0", "0"], ["84059.9", "0.01", "0", "2"]], "ts": "1742584888706", "checksum": 816591449, "seqId": 49948776469, "prevSeqId": 49948776459}], "record_time": 1742584888.791628, "EXCHANGE": "OKX"}
{"arg": {"channel": "books", "instId": "BTC-USDT"}, "action": "update", "data": [{"asks": [["84084.1", "0.47627664", "0", "1"], ["84085", "0", "0", "0"], ["84086.4", "1", "0", "1"], ["84087.4", "0", "0", "0"], ["84099.9", "0.23861768", "0", "2"], ["84104.4", "0", "0", "0"], ["84113.8", "0.18425879", "0", "1"], ["84117", "0", "0", "0"], ["84239", "0.35564723", "0", "1"], ["84239.3", "0.00011161", "0", "1"], ["84240", "0.00001197", "0", "1"]], "bids": [["84036.2", "0", "0", "0"], ["84008.1", "0.30035582", "0", "2"], ["84006.6", "0.17898725", "0", "1"], ["83929.9", "0.00007149", "0", "1"]], "ts": "1742584888806", "checksum": 64890171, "seqId": 49948776480, "prevSeqId": 49948776469}], "record_time": 1742584888.89183, "EXCHANGE": "OKX"}
{"arg": {"channel": "books", "instId": "BTC-USDT"}, "action": "update", "data": [{"asks": [["84084.1", "0.87799001", "0", "2"], ["84085", "1", "0", "1"], ["84086.4", "0", "0", "0"], ["84087.3", "1.57299287", "0", "1"], ["84116.7", "2.86383169", "0", "1"], ["84239.3", "0", "0", "0"], ["84240", "0", "0", "0"]], "bids": [["84039.6", "1.52816754", "0", "1"], ["84037.3", "0.43800274", "0", "1"], ["84010.1", "2.6731817", "0", "1"], ["83930", "0", "0", "0"], ["83929.9", "0", "0", "0"]], "ts": "1742584888906", "checksum": 989792805, "seqId": 49948776492, "prevSeqId": 49948776480}], "record_time": 1742584888.991396, "EXCHANGE": "OKX"}
{"arg": {"channel": "books", "instId": "BTC-USDT"}, "action": "update", "data": [{"asks": [["84071.9", "0.42176854", "0", "15"], ["84073.1", "0.2", "0", "1"], ["84085", "0", "0", "0"], ["84086.5", "1", "0", "1"], ["84086.9", "0", "0", "0"], ["84099.9", "0.00060645", "0", "1"], ["84104.4", "0.23801153", "0", "1"], ["84239", "0", "0", "0"]], "bids": [], "ts": "1742584889006", "checksum": -2003377812, "seqId": 49948776501, "prevSeqId": 49948776492}], "record_time": 1742584889.091164, "EXCHANGE": "OKX"}
{"arg": {"channel": "books", "instId": "BTC-USDT"}, "action": "update", "data": [{"asks": [["84071.9", "0.40392554", "0", "14"], ["84073.1", "0", "0", "0"], ["84077.8", "0.01189987", "0", "1"], ["84089.2", "0.000015", "0", "1"], ["84100.9", "0.02378096", "0", "2"], ["84101", "0.17754542", "0", "2"], ["84147.3", "0.12530531", "0", "2"], ["84238.9", "0", "0", "0"]], "bids": [["84044.7", "0.01190456", "0", "1"], ["84041.5", "0.63618138", "0", "2"], ["84031", "1.00001", "0", "2"], ["84011.8", "1.08172144", "0", "2"], ["83930.2", "0", "0", "0"]], "ts": "1742584889106", "checksum": 899137268, "seqId": 49948776518, "prevSeqId": 49948776501}], "record_time": 1742584889.216034, "EXCHANGE": "OKX"}
{"arg": {"channel": "books", "instId": "BTC-USDT"}, "action": "update", "data": [{"asks": [["84071.9", "0.42176854", "0", "15"], ["84099.1", "0.02378148", "0", "2"], ["84100", "0.53839", "0", "1"]], "bids": [["84028.3", "0.02378148", "0", "2"], ["84027.5", "0", "0", "0"], ["83930.2", "0.00011454", "0", "1"]], "ts": "1742584889206", "checksum": -3510340, "seqId": 49948776528, "prevSeqId": 49948776518}], "record_time": 1742584889.301523, "EXCHANGE": "OKX"}
{"arg": {"channel": "books", "instId": "BTC-USDT"}, "action": "update", "data": [{"asks": [["84147.3", "0.044921", "0", "1"], ["84147.4", "0.07130346", "0", "1"]], "bids": [["84020", "0.20001", "0", "2"], ["83982.5", "0.07144344", "0", "1"]], "ts": "1742584889306", "checksum": -3510340, "seqId": 49948776537, "prevSeqId": 49948776528}], "record_time": 1742584889.391406, "EXCHANGE": "OKX"}
{"arg": {"channel": "books", "instId": "BTC-USDT"}, "action": "update", "data": [{"asks": [["84147.4", "0", "0", "0"], ["84238.9", "0.17898725", "0", "1"]], "bids": [["83982.5", "0", "0", "0"], ["83930", "0.00012899", "0", "1"]], "ts": "1742584889406", "checksum": -3510340, "seqId": 49948776543, "prevSeqId": 49948776537}], "record_time": 1742584889.491445, "EXCHANGE": "OKX"}
{"arg": {"channel": "books", "instId": "BTC-USDT"}, "action": "update", "data": [{"asks": [["84147.4", "0.14260692", "0", "2"], ["84238.9", "0", "0", "0"]], "bids": [["83982.5", "0.14288688", "0", "2"], ["83930", "0", "0", "0"]], "ts": "1742584889506", "checksum": -3510340, "seqId": 49948776555, "prevSeqId": 49948776543}], "record_time": 1742584889.590903, "EXCHANGE": "OKX"}
{"arg": {"channel": "books", "instId": "BTC-USDT"}, "action": "update", "data": [{"asks": [["84071.9", "0.40392554", "0", "14"], ["84103.2", "0", "0", "0"], ["84104", "0.01233238", "0", "3"], ["84104.8", "0.0004", "0", "1"], ["84147.4", "0.07130346", "0", "1"]], "bids": [["84035.2", "0", "0", "0"], ["84034.4", "0.08079864", "0", "4"], ["84033.6", "0.04039865", "0", "2"], ["83982.5", "0.07144344", "0", "1"], ["83930", "0.00012899", "0", "1"]], "ts": "1742584889606", "checksum": 899137268, "seqId": 49948776571, "prevSeqId": 49948776555}], "record_time": 1742584889.695419, "EXCHANGE": "OKX"}
{"arg": {"channel": "books", "instId": "BTC-USDT"}, "action": "update", "data": [{"asks": [["84086.4", "1", "0", "1"], ["84086.5", "0", "0", "0"]], "bids": [], "ts": "1742584889706", "checksum": 899137268, "seqId": 49948776575, "prevSeqId": 49948776571}], "record_time": 1742584889.79276, "EXCHANGE": "OKX"}
{"arg": {"channel": "books", "instId": "BTC-USDT"}, "action": "update", "data": [{"asks": [["84071.9", "0.42176854", "0", "15"]], "bids": [["84044.5", "0", "0", "0"], ["84020.1", "0.471152", "0", "1"]], "ts": "1742584889806", "checksum": -3510340, "seqId": 49948776582, "prevSeqId": 49948776575}], "record_time": 1742584889.890954, "EXCHANGE": "OKX"}
{"arg": {"channel": "books", "instId": "BTC-USDT"}, "action": "update", "data": [{"asks": [["84071.9", "0.62176854", "0", "16"], ["84072.4", "0.01190094", "0", "1"], ["84084.9", "1", "0", "1"], ["84086.4", "0", "0", "0"], ["84100.3", "0.23802548", "0", "2"], ["84101", "0.11693971", "0", "1"], ["84103.2", "0.0008", "0", "2"], ["84104", "0.01193238", "0", "2"], ["84104.4", "0", "0", "0"], ["84104.8", "0", "0", "0"], ["84147.4", "0.14260692", "0", "2"]], "bids": [["84054.6", "0.34123686", "0", "2"], ["84051.1", "0", "0", "0"], ["84048.9", "1", "0", "1"], ["84045.5", "0.01774536", "0", "1"], ["84044.3", "0.23801386", "0", "1"], ["84035.2", "0.0008", "0", "2"], ["84034.4", "0.08039864", "0", "3"], ["84033.6", "0.04", "0", "1"], ["84031", "0.00001", "0", "1"], ["84020", "0.00001", "0", "1"], ["83982.5", "0.14288688", "0", "2"], ["83930.2", "0", "0", "0"], ["83930", "0", "0", "0"]], "ts": "1742584890006", "checksum": 691553644, "seqId": 49948776636, "prevSeqId": 49948776582}], "record_time": 1742584890.091388, "EXCHANGE": "OKX"}
{"arg": {"channel": "books", "instId": "BTC-USDT"}, "action": "update", "data": [{"asks": [["84099.9", "0.23862043", "0", "2"], ["84100.3", "0.00001197", "0", "1"], ["84100.9", "0.01189048", "0", "1"], ["84101.8", "0.01189036", "0", "1"], ["84113.8", "1.00777595", "0", "2"], ["84147.4", "0.07130346", "0", "1"], ["84238.4", "0", "0", "0"]], "bids": [["84050.3", "0.45845229", "0", "2"], ["84048.9", "0", "0", "0"], ["84048.4", "1", "0", "1"], ["84044.3", "0", "0", "0"], ["84042.6", "0.23801468", "0", "1"], ["84030.1", "0.01189048", "0", "1"], ["84029.3", "0.3146556", "0", "3"], ["84015.9", "0.01832715", "0", "1"], ["84014", "0", "0", "0"], ["83982.5", "0.07144344", "0", "1"], ["83944.5", "0.1832715", "0", "1"], ["83943.8", "0", "0", "0"]], "ts": "1742584890106", "checksum": 691553644, "seqId": 49948776710, "prevSeqId": 49948776636}], "record_time": 1742584890.19197, "EXCHANGE": "OKX"}
{"arg": {"channel": "books", "instId": "BTC-USDT"}, "action": "update", "data": [{"asks": [["84099.9", "0.00060645", "0", "1"], ["84100.6", "0.23801322", "0", "1"], ["84238.3", "0", "0", "0"]], "bids": [["84044.3", "0.23801322", "0", "1"], ["84042.6", "0", "0", "0"], ["84014.1", "0", "0", "0"], ["84013.5", "0.00218393", "0", "1"]], "ts": "1742584890206", "checksum": 691553644, "seqId": 49948776722, "prevSeqId": 49948776710}], "record_time": 1742584890.298573, "EXCHANGE": "OKX"}
{"arg": {"channel": "books", "instId": "BTC-USDT"}, "action": "update", "data": [{"asks": [["84147.4", "0.14260692", "0", "2"]], "bids": [["84031.2", "0.1", "0", "2"], ["84030.4", "0.05", "0", "1"], ["84029.6", "0", "0", "0"], ["83982.5", "0.14288688", "0", "2"]], "ts": "1742584890306", "checksum": 691553644, "seqId": 49948776736, "prevSeqId": 49948776722}], "record_time": 1742584890.39172, "EXCHANGE": "OKX"}
{"arg": {"channel": "books", "instId": "BTC-USDT"}, "action": "update", "data": [{"asks": [["84071.9", "0.42176854", "0", "15"]], "bids": [], "ts": "1742584890406", "checksum": -1008581260, "seqId": 49948776737, "prevSeqId": 49948776736}], "record_time": 1742584890.491159, "EXCHANGE": "OKX"}
{"arg": {"channel": "books", "instId": "BTC-USDT"}, "action": "update", "data": [{"asks": [["84084.9", "0", "0", "0"], ["84086.9", "1", "0", "1"], ["84099.7", "0", "0", "0"], ["84100.6", "0", "0", "0"], ["84104.4", "0.23801107", "0", "1"], ["84238.3", "0.00593858", "0", "1"]], "bids": [["84049.7", "1", "0", "1"], ["84048.4", "0", "0", "0"], ["84046.5", "0.23801107", "0", "1"], ["84044.3", "0", "0", "0"], ["84028.9", "0", "0", "0"], ["83930.2", "0.00011454", "0", "1"]], "ts": "1742584890506", "checksum": -1008581260, "seqId": 49948776748, "prevSeqId": 49948776737}], "record_time": 1742584890.592189, "EXCHANGE": "OKX"}
{"arg": {"channel": "books", "instId": "BTC-USDT"}, "action": "update", "data": [{"asks": [["84071.9", "0.32176854", "0", "14"], ["84074", "0", "0", "0"], ["84076.9", "0.00844", "0", "1"], ["84100.6", "0.01189053", "0", "1"], ["84238.3", "0", "0", "0"]], "bids": [["84071.8", "0.27282518", "0", "11"], ["84063.2", "0.01674", "0", "1"], ["84060.4", "0", "0", "0"], ["84054.6", "0.55791663", "0", "3"], ["84051.1", "1", "0", "1"], ["84050.3", "0.1851697", "0", "1"], ["84049.7", "0", "0", "0"], ["84046.5", "0", "0", "0"], ["84045.5", "0.25575633", "0", "2"], ["84031.2", "0", "0", "0"], ["84030.4", "0.1", "0", "2"], ["84029.6", "0.05", "0", "1"], ["84028.1", "0.01189053", "0", "1"]], "ts": "1742584890606", "checksum": -607512146, "seqId": 49948776769, "prevSeqId": 49948776748}], "record_time": 1742584890.69176, "EXCHANGE": "OKX"}
{"arg": {"channel": "books", "instId": "BTC-USDT"}, "action": "update", "data": [{"asks": [["84071.9", "0.32150691", "0", "14"], ["84073.1", "0.2", "0", "1"], ["84238.1", "0", "0", "0"]], "bids": [], "ts": "1742584890706", "checksum": -2023319058, "seqId": 49948776772, "prevSeqId": 49948776769}], "record_time": 1742584890.791358, "EXCHANGE": "OKX"}
{"arg": {"channel": "books", "instId": "BTC-USDT"}, "action": "update", "data": [{"asks": [["84085.6", "1", "0", "1"], ["84086.9", "0", "0", "0"], ["84099.3", "0.01545262", "0", "2"], ["84100.1", "0", "0", "0"], ["84238.1", "0.00006534", "0", "2"]], "bids": [["84051.1", "0", "0", "0"], ["84049.7", "1", "0", "1"], ["84028.5", "0.01189071", "0", "1"], ["84027.6", "0", "0", "0"]], "ts": "1742584890906", "checksum": -2023319058, "seqId": 49948776784, "prevSeqId": 49948776772}], "record_time": 1742584890.991004, "EXCHANGE": "OKX"}
{"arg": {"channel": "books", "instId": "BTC-USDT"}, "action": "update", "data": [{"asks": [["84071.9", "0.52150691", "0", "15"]], "bids": [["84054.6", "0.34123686", "0", "2"], ["84031", "1.00001", "0", "2"], ["84020.9", "0.46009216", "0", "2"], ["84019", "0.2", "0", "1"], ["83930.2", "0", "0", "0"]], "ts": "1742584891006", "checksum": -1766851742, "seqId": 49948776797, "prevSeqId": 49948776784}], "record_time": 1742584891.091365, "EXCHANGE": "OKX"}
{"arg": {"channel": "books", "instId": "BTC-USDT"}, "action": "update", "data": [{"asks": [["84074.2", "0.11899966", "0", "1"], ["84076", "0", "0", "0"], ["84101", "0.18111239", "0", "2"], ["84147.3", "0.12530531", "0", "2"]], "bids": [["84031.1", "0.45555891", "0", "1"], ["83930.5", "0", "0", "0"]], "ts": "1742584891106", "checksum": 43341279, "seqId": 49948776810, "prevSeqId": 49948776797}], "record_time": 1742584891.191183, "EXCHANGE": "OKX"}
{"arg": {"channel": "books", "instId": "BTC-USDT"}, "action": "update", "data": [{"asks": [["84071.9", "0.82400691", "0", "17"], ["84073.6", "0.00844", "0", "1"], ["84076.9", "0", "0", "0"], ["84099.9", "0.23862055", "0", "2"], ["84101", "0.11693971", "0", "1"], ["84102.4", "0.0008", "0", "2"], ["84103.2", "0.0004", "0", "1"], ["84104", "0.01153238", "0", "1"], ["84104.4", "0", "0", "0"], ["84109.6", "0.08", "0", "2"], ["84110.4", "0.03999999", "0", "1"], ["84111.2", "0", "0", "0"]], "bids": [["84071.8", "0.13055329", "0", "10"], ["84063.2", "0", "0", "0"], ["84060", "0.01675", "0", "2"], ["84050.3", "0.45845229", "0", "2"], ["84045.5", "0.01774536", "0", "1"], ["84042.6", "0.23801535", "0", "1"], ["84042.5", "0", "0", "0"], ["84031.2", "0.1", "0", "2"], ["84030.4", "0.05", "0", "1"], ["84029.6", "0", "0", "0"], ["83930.5", "0.00001316", "0", "1"]], "ts": "1742584891206", "checksum": 1783131983, "seqId": 49948776847, "prevSeqId": 49948776810}], "record_time": 1742584891.294668, "EXCHANGE": "OKX"}
{"arg": {"channel": "books", "instId": "BTC-USDT"}, "action": "update", "data": [{"asks": [["84071.9", "0.62150691", "0", "16"], ["84078.1", "0.003567", "0", "1"], ["84099.9", "0.00060645", "0", "1"], ["84100.3", "0.238026", "0", "2"], ["84102.4", "0", "0", "0"], ["84103.2", "0.0008", "0", "2"], ["84104", "0.01193238", "0", "2"], ["84108.9", "0", "0", "0"], ["84109.6", "0", "0", "0"], ["84110.4", "0.07999999", "0", "2"], ["84111.2", "0.03999999", "0", "1"], ["84238.3", "0.20843858", "0", "2"]], "bids": [["84044.1", "0.23801403", "0", "1"], ["84042.6", "0", "0", "0"], ["84031.2", "0", "0", "0"], ["84030.4", "0.1", "0", "2"], ["84029.6", "0.05", "0", "1"], ["84015.9", "0", "0", "0"], ["84013.6", "0.01832724", "0", "1"], ["83944.5", "0", "0", "0"], ["83943.8", "0.18327245", "0", "1"]], "ts": "1742584891306", "checksum": 53238979, "seqId": 49948776872, "prevSeqId": 49948776847}], "record_time": 1742584891.391044, "EXCHANGE": "OKX"}
{"arg": {"channel": "books", "instId": "BTC-USDT"}, "action": "update", "data": [{"asks": [["84100.3", "0.00001197", "0", "1"], ["84104.4", "0.23801196", "0", "1"], ["84238.3", "0", "0", "0"]], "bids": [["84054.6", "0.55791663", "0", "3"], ["84051", "1", "0", "1"], ["84050.3", "0.1851697", "0", "1"], ["84049.7", "0", "0", "0"], ["84045.1", "0.23801196", "0", "1"], ["84044.1", "0", "0", "0"], ["84042.5", "0.17842", "0", "1"], ["83930.5", "0", "0", "0"]], "ts": "1742584891406", "checksum": 53238979, "seqId": 49948776893, "prevSeqId": 49948776872}], "record_time": 1742584891.490599, "EXCHANGE": "OKX"}
{"arg": {"channel": "books", "instId": "BTC-USDT"}, "action": "update", "data": [{"asks": [["84147.3", "0.044921", "0", "1"], ["84147.4", "0.07130346", "0", "1"]], "bids": [["84031.1", "0", "0", "0"], ["84031", "0.00001", "0", "1"], ["84019", "0", "0", "0"], ["83982.5", "0.07144344", "0", "1"], ["83930.5", "0.00001316", "0", "1"], ["83930.2", "0.00011454", "0", "1"]], "ts": "1742584891606", "checksum": 53238979, "seqId": 49948776905, "prevSeqId": 49948776893}], "record_time": 1742584891.691051, "EXCHANGE": "OKX"}
{"arg": {"channel": "books", "instId": "BTC-USDT"}, "action": "update", "data": [{"asks": [["84084.1", "0.47627664", "0", "1"], ["84087.3", "0", "0", "0"], ["84099.9", "0.23861869", "0", "2"], ["84104.4", "0", "0", "0"], ["84113.8", "0.18425879", "0", "1"], ["84116.7", "0", "0", "0"], ["84238.3", "0.20843858", "0", "2"], ["84238.4", "0.03", "0", "1"], ["84238.9", "0.17898725", "0", "1"]], "bids": [["84045.1", "0.23801224", "0", "1"], ["84041.5", "0.28287066", "0", "1"], ["84039.6", "0", "0", "0"], ["84011.8", "0.31973363", "0", "1"], ["84010.1", "0", "0", "0"], ["83930", "0.00012899", "0", "1"], ["83929.9", "0.00007149", "0", "1"]], "ts": "1742584891706", "checksum": 53238979, "seqId": 49948776940, "prevSeqId": 49948776905}], "record_time": 1742584891.791578, "EXCHANGE": "OKX"}
{"arg": {"channel": "books", "instId": "BTC-USDT"}, "action": "update", "data": [{"asks": [["84084.1", "0.86583273", "0", "2"], ["84087.3", "1.53570262", "0", "1"], ["84099.9", "0.00060645", "0", "1"], ["84104.4", "0.23801213", "0", "1"], ["84116.7", "2.76987328", "0", "1"], ["84238.3", "0", "0", "0"], ["84238.4", "0", "0", "0"], ["84238.9", "0", "0", "0"]], "bids": [["84045.5", "0", "0", "0"], ["84039.5", "1.55832721", "0", "1"], ["84010.1", "2.83040573", "0", "1"], ["83995.9", "0.01874888", "0", "2"], ["83929.9", "0", "0", "0"]], "ts": "1742584891806", "checksum": 53238979, "seqId": 49948776953, "prevSeqId": 49948776940}], "record_time": 1742584891.891724, "EXCHANGE": "OKX"}
{"arg": {"channel": "books", "instId": "BTC-USDT"}, "action": "update", "data": [{"asks": [["84099.9", "0.23862079", "0", "2"], ["84104.4", "0", "0", "0"], ["84238.3", "0.20843858", "0", "2"]], "bids": [["84045.1", "0", "0", "0"], ["84044.1", "0.23801434", "0", "1"]], "ts": "1742584891906", "checksum": 53238979, "seqId": 49948776966, "prevSeqId": 49948776953}], "record_time": 1742584891.991653, "EXCHANGE": "OKX"}
{"arg": {"channel": "books", "instId": "BTC-USDT"}, "action": "update", "data": [{"asks": [["84099.9", "0.00060645", "0", "1"], ["84104.4", "0.23801187", "0", "1"], ["84147.4", "0.14260692", "0", "2"], ["84238.3", "0", "0", "0"]], "bids": [["84045.5", "0.25575723", "0", "2"], ["84044.1", "0", "0", "0"], ["83995.9", "0.00100352", "0", "1"], ["83982.5", "0.14288688", "0", "2"]], "ts": "1742584892006", "checksum": 53238979, "seqId": 49948776979, "prevSeqId": 49948776966}], "record_time": 1742584892.092525, "EXCHANGE": "OKX"}
{"arg": {"channel": "books", "instId": "BTC-USDT"}, "action": "update", "data": [{"asks": [["84100.9", "0.24990283", "0", "2"], ["84104.4", "0", "0", "0"], ["84147.3", "0.10391427", "0", "2"], ["84147.4", "0.07130346", "0", "1"], ["84238.3", "0.20843858", "0", "2"]], "bids": [["84045.5", "0.01774536", "0", "1"], ["84045.1", "0.23801235", "0", "1"], ["84041.5", "0.64522928", "0", "2"], ["84015.9", "0.01832699", "0", "1"], ["84013.7", "0.00218393", "0", "1"], ["84013.6", "0", "0", "0"], ["84013.5", "0", "0", "0"], ["84011.8", "1.12888865", "0", "2"], ["83982.5", "0.07144344", "0", "1"], ["83944.5", "0.18326998", "0", "1"], ["83943.8", "0", "0", "0"], ["83930", "0", "0", "0"]], "ts": "1742584892106", "checksum": 53238979, "seqId": 49948777023, "prevSeqId": 49948776979}], "record_time": 1742584892.191455, "EXCHANGE": "OKX"}
{"arg": {"channel": "books", "instId": "BTC-USDT"}, "action": "update", "data": [{"asks": [["84071.9", "0.62400691", "0", "16"], ["84078.1", "0", "0", "0"], ["84100.6", "0.24990342", "0", "2"], ["84100.9", "0.01189048", "0", "1"], ["84102.4", "0.0008", "0", "2"], ["84103.2", "0.0004", "0", "1"], ["84104", "0.01153238", "0", "1"], ["84109.6", "0.08", "0", "2"], ["84110.4", "0.03999999", "0", "1"], ["84111.2", "0", "0", "0"], ["84118.3", "0.003567", "0", "1"], ["84147.4", "0.14260692", "0", "2"], ["84238.3", "0", "0", "0"]], "bids": [["84045.1", "0", "0", "0"], ["84044.3", "0.23801289", "0", "1"], ["84031.2", "0.1", "0", "2"], ["84030.4", "0.05", "0", "1"], ["84029.6", "0", "0", "0"], ["84013.7", "0", "0", "0"], ["84013.5", "0.00218393", "0", "1"], ["83982.5", "0.14288688", "0", "2"]], "ts": "1742584892206", "checksum": 282829037, "seqId": 49948777053, "prevSeqId": 49948777023}], "record_time": 1742584892.291004, "EXCHANGE": "OKX"}
{"arg": {"channel": "books", "instId": "BTC-USDT"}, "action": "update", "data": [{"asks": [["84071.9", "0.42150691", "0", "15"], ["84100.6", "0.01189053", "0", "1"], ["84100.9", "0.24990257", "0", "2"]], "bids": [["84045.5", "0.25575745", "0", "2"], ["84044.3", "0", "0", "0"], ["84015.9", "0", "0", "0"], ["84013.6", "0.01832705", "0", "1"], ["83944.5", "0", "0", "0"], ["83943.8", "0.18327054", "0", "1"], ["83930", "0.00012899", "0", "1"]], "ts": "1742584892306", "checksum": 1536527079, "seqId": 49948777062, "prevSeqId": 49948777053}], "record_time": 1742584892.391314, "EXCHANGE": "OKX"}
{"arg": {"channel": "books", "instId": "BTC-USDT"}, "action": "update", "data": [{"asks": [["84071.9", "0.13776325", "0", "8"], ["84072.4", "0", "0", "0"], ["84073.1", "0", "0", "0"], ["84073.2", "0", "0", "0"], ["84073.3", "0", "0", "0"], ["84073.6", "0", "0", "0"], ["84074.2", "0", "0", "0"], ["84075.5", "0.01396938", "0", "2"], ["84075.6", "0.04283411", "0", "1"], ["84079.9", "0.19945935", "0", "1"], ["84080.1", "0", "0", "0"], ["84080.4", "0.20251197", "0", "2"], ["84081", "0", "0", "0"], ["84082", "0.0375", "0", "2"], ["84083", "0.000015", "0", "1"], ["84083.8", "0.036", "0", "1"], ["84084.1", "0.47627664", "0", "1"], ["84085.6", "0", "0", "0"], ["84086.7", "0.02534", "0", "1"], ["84089.2", "0", "0", "0"], ["84092.8", "0.61137788", "0", "1"], ["84093.2", "0", "0", "0"], ["84094.5", "1", "0", "1"], ["84100.9", "0.01189048", "0", "1"], ["84102.4", "0", "0", "0"], ["84103.2", "0.0008", "0", "2"], ["84104", "0.01193238", "0", "2"], ["84108.1", "0.23799164", "0", "1"], ["84109.6", "0", "0", "0"], ["84110.4", "0.07999999", "0", "2"], ["84111.2", "0.03999999", "0", "1"], ["84116.2", "0.002498", "0", "1"], ["84122.3", "0", "0", "0"], ["84122.4", "0", "0", "0"], ["84147.3", "0.05899327", "0", "1"], ["84238.3", "0.20843858", "0", "2"], ["84238.4", "0.03", "0", "1"], ["84238.9", "0.17898725", "0", "1"], ["84239", "0.35564723", "0", "1"], ["84239.3", "0.00011161", "0", "1"], ["84240", "0.00001197", "0", "1"], ["84240.1", "0.03001005", "0", "2"], ["84240.9", "0.014", "0", "1"]], "bids": [["84071.8", "0.57938072", "0", "27"], ["84071.7", "0.06706859", "0", "1"], ["84069.9", "0.01390018", "0", "2"], ["84065.4", "0", "0", "0"], ["84063.8", "0.25988126", "0", "1"], ["84063.7", "0.53463448", "0", "2"], ["84063.6", "0", "0", "0"], ["84063.2", "0.01674", "0", "1"], ["84062.7", "0.04239308", "0", "1"], ["84062.6", "0.0361992", "0", "2"], ["84061", "0.08991011", "0", "1"], ["84060.5", "0.05024", "0", "1"], ["84060", "0.00001", "0", "1"], ["84059.5", "0.00773148", "0", "1"], ["84059", "0", "0", "0"], ["84058.8", "0.55073348", "0", "2"], ["84057.7", "1", "0", "1"], ["84056.7", "0", "0", "0"], ["84055.2", "0.02380037", "0", "1"], ["84054.7", "0.43537871", "0", "3"], ["84054.6", "0.34123686", "0", "2"], ["84054.2", "0.01593112", "0", "1"], ["84053", "0.23799164", "0", "1"], ["84051", "0", "0", "0"], ["84046.8", "0", "0", "0"], ["84046.3", "0.11890769", "0", "1"], ["84046.2", "0.91444876", "0", "2"], ["84046.1", "0", "0", "0"], ["84045.5", "0.01774536", "0", "1"], ["84042.9", "0", "0", "0"], ["84036.8", "0", "0", "0"], ["84036.6", "0", "0", "0"], ["84031.6", "0.21799418", "0", "1"], ["84031.2", "0", "0", "0"], ["84030.4", "0.1", "0", "2"], ["84029.6", "0.05", "0", "1"], ["84021.5", "0.36614971", "0", "3"], ["84011.6", "0", "0", "0"], ["83930", "0", "0", "0"]], "ts": "1742584892406", "checksum": -564907882, "seqId": 49948777207, "prevSeqId": 49948777062}], "record_time": 1742584892.491543, "EXCHANGE": "OKX"}
{"arg": {"channel": "books", "instId": "BTC-USDT"}, "action": "update", "data": [{"asks": [["84071.9", "0.07590317", "0", "6"], ["84073.5", "0.00262029", "0", "1"], ["84075.5", "0.00111915", "0", "1"], ["84075.6", "0", "0", "0"], ["84076.7", "0.01717916", "0", "1"], ["84078.2", "0", "0", "0"], ["84079.9", "0.16232548", "0", "2"], ["84080.7", "0.08283411", "0", "2"], ["84082", "0.0015", "0", "1"], ["84086.7", "0", "0", "0"], ["84087.9", "0", "0", "0"], ["84089.6", "0.03764015", "0", "1"], ["84090.5", "0.01189195", "0", "1"], ["84092.8", "0.5568858", "0", "2"], ["84094.5", "0", "0", "0"], ["84096.2", "1", "0", "1"], ["84096.4", "0.000132", "0", "1"], ["84103.2", "0", "0", "0"], ["84104", "0.01153238", "0", "1"], ["84105.6", "0.0008", "0", "2"], ["84106.4", "0.57253448", "0", "5"], ["84108.1", "0", "0", "0"], ["84109.8", "0.23798702", "0", "1"], ["84110.4", "0", "0", "0"], ["84111.2", "0", "0", "0"], ["84112.8", "0.07999999", "0", "2"], ["84113.6", "0.03999999", "0", "1"], ["84132.7", "0", "0", "0"], ["84134.7", "0.0111855", "0", "1"], ["84154.2", "0.044918", "0", "1"]], "bids": [["84071.8", "0.78309072", "0", "29"], ["84069.3", "0.03292505", "0", "2"], ["84063.4", "0", "0", "0"], ["84062.8", "0.04283411", "0", "1"], ["84062.7", "0.35353619", "0", "2"], ["84059", "1", "0", "1"], ["84058.8", "0.21401978", "0", "1"], ["84057.7", "0", "0", "0"], ["84055.3", "0.23798702", "0", "1"], ["84053", "0", "0", "0"], ["84047.9", "0", "0", "0"], ["84045.4", "0", "0", "0"], ["84044.7", "0.05688056", "0", "2"], ["84041.8", "0.132543", "0", "1"], ["84041.3", "0.05714202", "0", "1"], ["84035.2", "0", "0", "0"], ["84034.4", "0.00079864", "0", "2"], ["84033.6", "0.08039865", "0", "3"], ["84032.8", "0.066", "0", "3"], ["84027.1", "0.02572715", "0", "2"], ["84017.6", "0.01832611", "0", "1"], ["84013.6", "0", "0", "0"], ["83946.5", "0.18326112", "0", "1"], ["83943.8", "0", "0", "0"]], "ts": "1742584892506", "checksum": 1957209731, "seqId": 49948777322, "prevSeqId": 49948777207}], "record_time": 1742584892.591587, "EXCHANGE": "OKX"}
{"arg": {"channel": "books", "instId": "BTC-USDT"}, "action": "update", "data": [{"asks": [["84082.5", "0.11898793", "0", "1"], ["84083.3", "0.35684", "0", "1"], ["84085.2", "0.00844", "0", "1"], ["84091.6", "0.02534", "0", "1"], ["84096.2", "0", "0", "0"], ["84096.4", "1.000132", "0", "2"], ["84128.5", "0.838717", "0", "1"], ["84134.7", "0", "0", "0"], ["84138.3", "0.0111855", "0", "1"], ["84239.3", "0", "0", "0"], ["84240", "0", "0", "0"], ["84240.1", "0", "0", "0"], ["84240.9", "0", "0", "0"]], "bids": [["84071.6", "0.06624", "0", "2"], ["84065.3", "0.05023", "0", "1"], ["84063.2", "0", "0", "0"], ["84062.7", "0.04239308", "0", "1"], ["84060.5", "0", "0", "0"], ["84059", "0", "0", "0"], ["84058.8", "0.4709384", "0", "2"], ["84057.4", "1", "0", "1"], ["84055.3", "0", "0", "0"], ["84053", "0.23798849", "0", "1"], ["84047.9", "0.35684", "0", "1"], ["84045.5", "0", "0", "0"], ["84044.3", "0.01774536", "0", "1"], ["84030.1", "0.0118902", "0", "1"], ["84021.4", "0.0477916", "0", "2"], ["84021", "0.28547623", "0", "6"], ["84019.1", "0.839809", "0", "1"], ["84017.6", "0", "0", "0"], ["83948.7", "0.18325216", "0", "1"], ["83946.5", "0", "0", "0"]], "ts": "1742584892606", "checksum": -2109035816, "seqId": 49948777381, "prevSeqId": 49948777322}], "record_time": 1742584892.691208, "EXCHANGE": "OKX"}
{"arg": {"channel": "books", "instId": "BTC-USDT"}, "action": "update", "data": [{"asks": [["84071.9", "0.01203891", "0", "3"], ["84073.5", "0", "0", "0"], ["84076.7", "0", "0", "0"], ["84077.8", "0", "0", "0"], ["84079.9", "0", "0", "0"], ["84080.4", "0.00001197", "0", "1"], ["84080.7", "0", "0", "0"], ["84082.2", "0", "0", "0"], ["84082.5", "0", "0", "0"], ["84082.7", "0.1365885", "0", "1"], ["84083.8", "0", "0", "0"], ["84084.1", "0.15282083", "0", "1"], ["84085.2", "0", "0", "0"], ["84085.3", "0.04283411", "0", "1"], ["84085.9", "0", "0", "0"], ["84086.2", "0.35564723", "0", "1"], ["84086.6", "0.01189862", "0", "1"], ["84087.1", "0", "0", "0"], ["84087.3", "0", "0", "0"], ["84088.2", "0.06724853", "0", "1"], ["84088.3", "0", "0", "0"], ["84089.5", "0.04", "0", "1"], ["84089.6", "0", "0", "0"], ["84090.5", "0", "0", "0"], ["84091.6", "0", "0", "0"], ["84091.8", "0", "0", "0"], ["84091.9", "0", "0", "0"], ["84092.8", "0.20588863", "0", "1"], ["84094.6", "0.02930357", "0", "1"], ["84095.3", "0.00001197", "0", "1"], ["84096.4", "0", "0", "0"], ["84096.6", "0.40049913", "0", "2"], ["84099.1", "0", "0", "0"], ["84099.3", "0.00356191", "0", "1"], ["84100", "0", "0", "0"], ["84100.6", "0", "0", "0"], ["84100.7", "0.08692", "0", "1"], ["84100.9", "0", "0", "0"], ["84101", "0.11695921", "0", "2"], ["84101.8", "0", "0", "0"], ["84103.6", "0.0988801", "0", "2"], ["84104", "0", "0", "0"], ["84105", "0.60978438", "0", "4"], ["84105.6", "0", "0", "0"], ["84105.7", "0", "0", "0"], ["84106.4", "0.57213448", "0", "4"], ["84107.7", "0", "0", "0"], ["84107.9", "0", "0", "0"], ["84109.6", "0.0008", "0", "2"], ["84109.8", "0", "0", "0"], ["84110", "0", "0", "0"], ["84110.4", "0.0004", "0", "1"], ["84110.6", "0", "0", "0"], ["84111.3", "0", "0", "0"], ["84112.8", "0", "0", "0"], ["84113.6", "0", "0", "0"], ["84114.5", "0.05915134", "0", "1"], ["84114.9", "0.02377702", "0", "2"], ["84115.1", "0.01188848", "0", "1"], ["84115.3", "0.23796369", "0", "1"], ["84115.5", "0.01188842", "0", "1"], ["84116.7", "2.78176153", "0", "2"], ["84116.8", "0.07999999", "0", "2"], ["84117.5", "0.01188814", "0", "1"], ["84117.6", "0.03999999", "0", "1"], ["84118.3", "0", "0", "0"], ["84119.4", "0.53969", "0", "1"], ["84121.6", "0", "0", "0"], ["84125.9", "0.28236238", "0", "3"], ["84128.5", "0", "0", "0"], ["84133.2", "0.02968292", "0", "2"], ["84135.1", "0", "0", "0"], ["84145.6", "0", "0", "0"], ["84154.2", "0", "0", "0"], ["84158.8", "0.02378868", "0", "1"], ["84159.8", "1.20584066", "0", "4"], ["84227.5", "0", "0", "0"], ["84239.2", "0.01182404", "0", "1"], ["84239.3", "0.00011161", "0", "1"], ["84240", "0.00001197", "0", "1"], ["84240.1", "0.03001005", "0", "2"], ["84240.9", "0.014", "0", "1"], ["84242", "0.0000185", "0", "1"], ["84242.5", "0.00011938", "0", "1"], ["84242.6", "0.00001501", "0", "1"], ["84243.4", "0.01299784", "0", "1"], ["84243.7", "0.00355122", "0", "1"], ["84243.8", "0.0015", "0", "1"], ["84244.3", "0.00012088", "0", "1"], ["84245.5", "0.00009384", "0", "1"], ["84245.9", "0.03", "0", "1"], ["84246.5", "0.00001992", "0", "1"], ["84246.8", "0.2025", "0", "1"], ["84247.2", "0.00070761", "0", "1"], ["84247.5", "0.00001525", "0", "1"], ["84248.3", "0.14243616", "0", "2"], ["84248.5", "0.35564723", "0", "1"], ["84248.8", "0.08758125", "0", "2"], ["84249.1", "0.17898725", "0", "1"], ["84249.3", "0.00002525", "0", "2"], ["84249.4", "0.00003193", "0", "1"]], "bids": [["84071.8", "0.88057667", "0", "33"], ["84071.7", "0.17390929", "0", "1"], ["84071.6", "0.06774863", "0", "3"], ["84071.4", "0.00552558", "0", "1"], ["84070.6", "0.04284608", "0", "2"], ["84069.3", "0.02799005", "0", "1"], ["84069.1", "0.08991011", "0", "1"], ["84066.7", "0.23796369", "0", "1"], ["84065.8", "0.5770559", "0", "1"], ["84065.7", "1.00001197", "0", "2"], ["84063.8", "0", "0", "0"], ["84063.7", "0.55843228", "0", "3"], ["84062.8", "0.04", "0", "1"], ["84062.6", "0.00011161", "0", "1"], ["84059.9", "0.05", "0", "3"], ["84058.8", "0.21401978", "0", "1"], ["84057.4", "0", "0", "0"], ["84055.8", "0.01190298", "0", "1"], ["84055.2", "0.003567", "0", "1"], ["84055", "0.00475879", "0", "1"], ["84054.7", "0.42764723", "0", "2"], ["84054.3", "0.2025", "0", "1"], ["84053", "0.17842", "0", "1"], ["84050.3", "0.2301427", "0", "2"], ["84049.8", "0", "0", "0"], ["84046.2", "0.08991011", "0", "1"], ["84044.7", "0", "0", "0"], ["84043.9", "0.1190575", "0", "2"], ["84043.4", "0", "0", "0"], ["84041.3", "0", "0", "0"], ["84041.1", "0", "0", "0"], ["84039.7", "0.01189072", "0", "1"], ["84038.4", "0.02571214", "0", "1"], ["84037.7", "0.02348985", "0", "1"], ["84034.4", "0", "0", "0"], ["84033.6", "0", "0", "0"], ["84032.8", "0.00079865", "0", "2"], ["84032", "0.08039866", "0", "3"], ["84031.2", "0.066", "0", "3"], ["84030.4", "0.013", "0", "1"], ["84029.6", "0", "0", "0"], ["84028.8", "0.1", "0", "2"], ["84028", "0.05", "0", "1"], ["84027.1", "0.00001501", "0", "1"], ["84021.5", "0.34265986", "0", "2"], ["84019.1", "0", "0", "0"], ["83998.7", "0.04076278", "0", "1"], ["83997.6", "0.07165719", "0", "1"], ["83996.9", "0.07166249", "0", "1"], ["83981.8", "0", "0", "0"], ["83977.9", "0.17101131", "0", "1"], ["83977.8", "0.02378886", "0", "1"], ["83964.2", "0.17898725", "0", "1"], ["83963", "0", "0", "0"], ["83935.5", "0", "0", "0"], ["83930.2", "0", "0", "0"]], "ts": "1742584892706", "checksum": 792591876, "seqId": 49948777690, "prevSeqId": 49948777381}], "record_time": 1742584892.79176, "EXCHANGE": "OKX"}
{"arg": {"channel": "books", "instId": "BTC-USDT"}, "action": "update", "data": [{"asks": [["84071.9", "0", "0", "0"], ["84075.5", "0.00349861", "0", "2"], ["84077.6", "0", "0", "0"], ["84079.4", "0", "0", "0"], ["84081.8", "0", "0", "0"], ["84082.7", "0", "0", "0"], ["84082.8", "0", "0", "0"], ["84083", "0", "0", "0"], ["84083.2", "0", "0", "0"], ["84083.3", "0", "0", "0"], ["84085.1", "0", "0", "0"], ["84088.1", "0", "0", "0"], ["84088.2", "0.02765101", "0", "1"], ["84089.2", "0.00844", "0", "1"], ["84091.2", "0", "0", "0"], ["84093.2", "0.04", "0", "1"], ["84094.8", "0.23898725", "0", "3"], ["84094.9", "0.03", "0", "1"], ["84096.6", "0.78889126", "0", "3"], ["84096.9", "0.02533", "0", "1"], ["84098.1", "0.03764015", "0", "1"], ["84099.3", "1.55392197", "0", "2"], ["84100.7", "0", "0", "0"], ["84101", "0.19395164", "0", "3"], ["84103.6", "0.0118901", "0", "1"], ["84105.7", "0.08699", "0", "1"], ["84107.8", "0.11895213", "0", "1"], ["84108.2", "0.00001501", "0", "1"], ["84108.3", "0.04753238", "0", "2"], ["84109.6", "0", "0", "0"], ["84110.4", "0", "0", "0"], ["84110.7", "0.14043175", "0", "1"], ["84112", "0.0008", "0", "2"], ["84112.8", "0.0004", "0", "1"], ["84115.3", "0", "0", "0"], ["84116.8", "0", "0", "0"], ["84117", "0.20355", "0", "1"], ["84117.6", "0", "0", "0"], ["84118.4", "0.07999999", "0", "2"], ["84119.2", "0.03999999", "0", "1"], ["84124.4", "0.24949361", "0", "2"], ["84126.1", "0.24978", "0", "1"], ["84138.3", "0", "0", "0"], ["84143.3", "0.0111855", "0", "1"], ["84146.1", "0", "0", "0"], ["84153.7", "0", "0", "0"], ["84198.5", "0", "0", "0"], ["84201.6", "0.16817033", "0", "1"], ["84201.7", "0", "0", "0"], ["84208.2", "0.00594729", "0", "1"], ["84215.4", "0.00001197", "0", "1"], ["84220.3", "0", "0", "0"], ["84225", "0.02022087", "0", "4"], ["84227.8", "0.00001197", "0", "1"], ["84232", "0", "0", "0"], ["84238.5", "0.0011871", "0", "1"], ["84249.9", "6.47528899", "0", "3"], ["84250", "0.12668757", "0", "26"], ["84251.9", "0.0015", "0", "1"], ["84252", "0.00001957", "0", "1"], ["84252.1", "0.00002281", "0", "1"], ["84252.4", "0.08991011", "0", "1"], ["84252.5", "0.00001145", "0", "1"]], "bids": [["84075.4", "1.44972028", "0", "15"], ["84074", "0.0439", "0", "1"], ["84072", "0.14025422", "0", "1"], ["84071.9", "0.21153238", "0", "2"], ["84071.8", "0.28579286", "0", "14"], ["84071.7", "0", "0", "0"], ["84071.6", "0.05100863", "0", "2"], ["84070.7", "0.05023", "0", "1"], ["84069.9", "0.002", "0", "1"], ["84069.6", "0.14220182", "0", "1"], ["84067.4", "0.2379559", "0", "1"], ["84066.7", "0", "0", "0"], ["84065.8", "0.54681816", "0", "2"], ["84065.7", "0.00001197", "0", "1"], ["84065.4", "1", "0", "1"], ["84065.3", "0", "0", "0"], ["84063", "0.1290854", "0", "3"], ["84062.7", "0.07421847", "0", "2"], ["84059.6", "0.054", "0", "1"], ["84059.5", "0", "0", "0"], ["84059.1", "0.123", "0", "2"], ["84057.6", "0.11902312", "0", "1"], ["84056.9", "0", "0", "0"], ["84054.6", "0.26910992", "0", "2"], ["84053", "0", "0", "0"], ["84049.4", "0", "0", "0"], ["84048.7", "0.108", "0", "2"], ["84047.9", "0", "0", "0"], ["84043.9", "0.00001501", "0", "1"], ["84042.5", "0", "0", "0"], ["84037.4", "0.27711", "0", "1"], ["84025.9", "0.0183225", "0", "1"], ["84025.5", "0", "0", "0"], ["84021", "0.26715102", "0", "5"], ["84015.7", "0.03846506", "0", "2"], ["84013.4", "0.00594645", "0", "1"], ["83982.3", "0", "0", "0"], ["83955", "0.18322506", "0", "1"], ["83948.7", "0", "0", "0"], ["83930.7", "0", "0", "0"], ["83930.5", "0", "0", "0"]], "ts": "1742584892806", "checksum": 812934869, "seqId": 49948777920, "prevSeqId": 49948777690}], "record_time": 1742584892.891626, "EXCHANGE": "OKX"}
{"arg": {"channel": "books", "instId": "BTC-USDT"}, "action": "update", "data": [{"asks": [["84084.1", "0.11326735", "0", "1"], ["84085.3", "0", "0", "0"], ["84086.4", "0.132543", "0", "1"], ["84088.2", "0.04604487", "0", "2"], ["84089.5", "0", "0", "0"], ["84089.6", "0.04283411", "0", "1"], ["84091.4", "0.07166806", "0", "3"], ["84091.6", "0.03", "0", "1"], ["84092.1", "0.04", "0", "1"], ["84093.1", "0.11897296", "0", "1"], ["84094.6", "0", "0", "0"], ["84100.8", "0.02930357", "0", "1"], ["84103.6", "0", "0", "0"], ["84105", "0.62167428", "0", "5"], ["84106.7", "0.08753", "0", "1"], ["84108.3", "0.036", "0", "1"], ["84108.7", "0.01153238", "0", "1"], ["84115.8", "0", "0", "0"], ["84116.5", "0", "0", "0"], ["84118.4", "0", "0", "0"], ["84119.1", "0.23796034", "0", "1"], ["84119.2", "0.07999999", "0", "2"], ["84120", "0.040677", "0", "3"], ["84120.1", "0.10001197", "0", "2"], ["84124.4", "0.01153774", "0", "1"], ["84126.3", "0.00206991", "0", "2"], ["84136.9", "0.838634", "0", "1"], ["84164.6", "0.00118814", "0", "1"], ["84172.3", "0.01425647", "0", "1"], ["84250", "0", "0", "0"], ["84251.9", "0", "0", "0"], ["84252", "0", "0", "0"], ["84252.1", "0", "0", "0"], ["84252.4", "0", "0", "0"], ["84252.5", "0", "0", "0"]], "bids": [["84075.4", "1.51884033", "0", "18"], ["84074.5", "0.04283411", "0", "1"], ["84072.3", "0.29718485", "0", "1"], ["84072.2", "0.53463448", "0", "2"], ["84072.1", "0.01153238", "0", "1"], ["84072", "0", "0", "0"], ["84071.9", "0.2", "0", "1"], ["84071.8", "0.28382336", "0", "13"], ["84070.9", "0.00773114", "0", "1"], ["84070.6", "0.00001197", "0", "1"], ["84069.6", "0.07081505", "0", "1"], ["84069.3", "0", "0", "0"], ["84067.4", "0", "0", "0"], ["84063.8", "0.23796034", "0", "1"], ["84063.2", "0.072", "0", "1"], ["84063", "0.1890854", "0", "4"], ["84062.7", "0.1934863", "0", "1"], ["84061.3", "0.00773114", "0", "1"], ["84060.6", "0.35682", "0", "1"], ["84060.5", "0.17841", "0", "1"], ["84055", "0", "0", "0"], ["84050", "0.17841", "0", "1"], ["84048.8", "0", "0", "0"], ["84048.7", "0.054", "0", "1"], ["84044.3", "0", "0", "0"], ["84042.2", "0.01774536", "0", "1"], ["84038.4", "0", "0", "0"], ["84035.8", "0.02571214", "0", "1"], ["84030.9", "0.10001198", "0", "2"], ["84027.4", "0.839726", "0", "1"], ["84027.3", "0", "0", "0"], ["83999.6", "0.00100289", "0", "1"], ["83995.9", "0", "0", "0"], ["83993.8", "1.260093", "0", "1"], ["83989.8", "0.00144941", "0", "1"], ["83986.4", "0", "0", "0"], ["83981.9", "0", "0", "0"], ["83934.7", "0.00122355", "0", "1"], ["83932.6", "0", "0", "0"], ["83932.2", "0", "0", "0"], ["83931.9", "0", "0", "0"], ["83931.8", "0", "0", "0"], ["83931.4", "0", "0", "0"], ["83931.3", "0", "0", "0"], ["83930.8", "0", "0", "0"]], "ts": "1742584892906", "checksum": 1227170864, "seqId": 49948778045, "prevSeqId": 49948777920}], "record_time": 1742584892.991424, "EXCHANGE": "OKX"}
{"arg": {"channel": "books", "instId": "BTC-USDT"}, "action": "update", "data": [{"asks": [["84081.3", "0.00262029", "0", "1"], ["84084.1", "0.192568", "0", "2"], ["84086.1", "0.18898725", "0", "3"], ["84090.6", "0.00844", "0", "1"], ["84090.9", "0.00262029", "0", "1"], ["84092.8", "0.31580336", "0", "2"], ["84094.8", "0.26898725", "0", "4"], ["84116.6", "0.23858433", "0", "3"], ["84119.1", "0", "0", "0"], ["84122.7", "0", "0", "0"], ["84135", "0.00018137", "0", "2"], ["84249.9", "0", "0", "0"]], "bids": [["84075.4", "1.52330133", "0", "19"], ["84071.9", "0", "0", "0"], ["84063.8", "0", "0", "0"], ["84062.7", "0.32200903", "0", "2"], ["84061.1", "0.23796288", "0", "1"], ["84059.7", "0.054", "0", "1"], ["84054.7", "0.35564723", "0", "1"], ["84050.3", "0.044973", "0", "1"], ["84050", "0", "0", "0"], ["84049.5", "0.06089551", "0", "1"], ["84048.7", "0", "0", "0"], ["84006.9", "0.00213646", "0", "1"]], "ts": "1742584893006", "checksum": 459339977, "seqId": 49948778077, "prevSeqId": 49948778045}], "record_time": 1742584893.091434, "EXCHANGE": "OKX"}
{"arg": {"channel": "books", "instId": "BTC-USDT"}, "action": "update", "data": [{"asks": [["84088.2", "0.09175644", "0", "1"], ["84091.2", "0.11897574", "0", "1"], ["84093.1", "0", "0", "0"], ["84116.6", "0.00062145", "0", "2"], ["84116.7", "0.01188825", "0", "1"], ["84119.6", "0.23796093", "0", "1"], ["84249.4", "0", "0", "0"]], "bids": [["84075.4", "1.51884033", "0", "18"], ["84069.6", "0.35356615", "0", "2"], ["84067.2", "1", "0", "1"], ["84065.8", "0.2820779", "0", "1"], ["84065.4", "0", "0", "0"], ["84063.8", "0.23796093", "0", "1"], ["84062.7", "0.1934863", "0", "1"], ["84061.1", "0", "0", "0"], ["84060.5", "0", "0", "0"], ["84055.5", "0.12526094", "0", "2"], ["84054.6", "0.20910992", "0", "1"], ["84052.6", "0.17841", "0", "1"], ["84044.3", "0.33814706", "0", "1"], ["83995.7", "1.61670922", "0", "1"], ["83932.7", "0", "0", "0"]], "ts": "1742584893106", "checksum": -889781557, "seqId": 49948778106, "prevSeqId": 49948778077}], "record_time": 1742584893.19437, "EXCHANGE": "OKX"}
{"arg": {"channel": "books", "instId": "BTC-USDT"}, "action": "update", "data": [{"asks": [["84080.2", "0", "0", "0"], ["84088.2", "0.06181933", "0", "1"], ["84090.2", "0", "0", "0"], ["84091.2", "0", "0", "0"], ["84092.1", "0", "0", "0"], ["84094.4", "0.1523454", "0", "3"], ["84105", "0.60978438", "0", "4"], ["84106.1", "0.01188975", "0", "1"], ["84116.9", "0.23796276", "0", "1"], ["84119.6", "0", "0", "0"], ["84119.7", "0", "0", "0"], ["84136", "2.85699908", "0", "1"], ["84249.4", "0.00003193", "0", "1"], ["84249.9", "6.47528899", "0", "3"], ["84250", "0.12668757", "0", "26"]], "bids": [["84075.4", "1.53633371", "0", "21"], ["84072.1", "0", "0", "0"], ["84069.9", "0", "0", "0"], ["84067.2", "0", "0", "0"], ["84066.8", "1", "0", "1"], ["84065.8", "0.39626044", "0", "2"], ["84064.8", "0.04", "0", "1"], ["84063.8", "0", "0", "0"], ["84063", "0.3674954", "0", "5"], ["84062.7", "0.26788599", "0", "2"], ["84061.1", "0.23796276", "0", "1"], ["84059.9", "0.01475851", "0", "3"], ["84059.8", "0", "0", "0"], ["84044.4", "0.01774536", "0", "1"], ["84042.2", "0", "0", "0"], ["84035.8", "0", "0", "0"], ["84007.5", "0.01635535", "0", "1"], ["83992.6", "0.01999866", "0", "1"], ["83977.8", "0", "0", "0"], ["83932.7", "0.00001063", "0", "1"], ["83932.6", "2.09738", "0", "1"]], "ts": "1742584893206", "checksum": 634755226, "seqId": 49948778148, "prevSeqId": 49948778106}], "record_time": 1742584893.291336, "EXCHANGE": "OKX"}
{"arg": {"channel": "books", "instId": "BTC-USDT"}, "action": "update", "data": [{"asks": [["84075.5", "0", "0", "0"], ["84080.4", "0", "0", "0"], ["84081.3", "0", "0", "0"], ["84082", "0", "0", "0"], ["84084.1", "0", "0", "0"], ["84085.4", "0", "0", "0"], ["84086.1", "0.05112054", "0", "5"], ["84086.2", "0", "0", "0"], ["84086.4", "0", "0", "0"], ["84088.2", "0.0158371", "0", "1"], ["84089.6", "0", "0", "0"], ["84090.6", "0", "0", "0"], ["84091.4", "0.04166806", "0", "2"], ["84091.6", "0", "0", "0"], ["84092.8", "0.2064546", "0", "2"], ["84093.2", "0", "0", "0"], ["84093.4", "0.04283411", "0", "1"], ["84094.3", "0.01", "0", "1"], ["84094.4", "0.0561727", "0", "1"], ["84094.8", "0.17898725", "0", "1"], ["84094.9", "0", "0", "0"], ["84096.6", "0.29324545", "0", "2"], ["84096.9", "0", "0", "0"], ["84097.1", "0", "0", "0"], ["84097.5", "0.04", "0", "1"], ["84097.6", "0.04", "0", "1"], ["84099.3", "0", "0", "0"], ["84101", "0.22257864", "0", "2"], ["84105", "0.77272663", "0", "1"], ["84106.1", "0", "0", "0"], ["84107.3", "0.18724233", "0", "1"], ["84107.5", "0.0036555", "0", "1"], ["84108.1", "0.14043175", "0", "1"], ["84108.7", "0", "0", "0"], ["84110", "1", "0", "1"], ["84110.9", "0.01188907", "0", "1"], ["84112", "0", "0", "0"], ["84112.1", "0.05944201", "0", "1"], ["84112.4", "0", "0", "0"], ["84112.8", "0", "0", "0"], ["84114.5", "0", "0", "0"], ["84116", "0.0008", "0", "2"], ["84116.8", "0.0004", "0", "1"], ["84116.9", "0", "0", "0"], ["84117.9", "0.01153238", "0", "1"], ["84118.5", "0.11893703", "0", "1"], ["84118.6", "0", "0", "0"], ["84119.2", "0", "0", "0"], ["84120", "0.00067701", "0", "2"], ["84120.1", "0.00001197", "0", "1"], ["84120.2", "0.06105901", "0", "1"], ["84123.2", "0.07999999", "0", "2"], ["84124", "0.03999999", "0", "1"], ["84124.4", "0.24948865", "0", "2"], ["84124.5", "0", "0", "0"], ["84127.2", "0", "0", "0"], ["84132.3", "0.59015", "0", "1"], ["84136", "0", "0", "0"], ["84136.5", "0.0774127", "0", "2"], ["84147.3", "0.08914715", "0", "2"], ["84148.5", "0.05379", "0", "1"], ["84159.1", "0", "0", "0"], ["84159.8", "1.16092566", "0", "3"], ["84171.5", "0", "0", "0"], ["84171.8", "0", "0", "0"], ["84189.2", "0.0214", "0", "1"], ["84189.5", "0.0214", "0", "1"], ["84196.7", "0", "0", "0"], ["84214.5", "0.04261197", "0", "4"], ["84215.5", "0", "0", "0"], ["84239.2", "0", "0", "0"], ["84251.9", "0.0015", "0", "1"], ["84252", "0.00001957", "0", "1"], ["84252.1", "0.00002281", "0", "1"], ["84252.4", "0.08991011", "0", "1"], ["84252.5", "0.00001145", "0", "1"], ["84252.7", "0.00001362", "0", "1"], ["84253.3", "0.00001026", "0", "1"], ["84253.5", "0.00001097", "0", "1"], ["84253.7", "0.0000821", "0", "1"], ["84254.3", "0.00001034", "0", "1"], ["84255.3", "0.2025", "0", "1"], ["84258.1", "0.00003542", "0", "1"], ["84258.3", "0.00002584", "0", "1"], ["84258.9", "0.00001016", "0", "1"]], "bids": [["84086", "0.91690542", "0", "14"], ["84084.1", "0.00111915", "0", "1"], ["84084", "0.0439", "0", "1"], ["84082", "0.18449927", "0", "1"], ["84081.9", "0.25193112", "0", "3"], ["84081.2", "0.11665643", "0", "5"], ["84080.3", "0.2025", "0", "1"], ["84080", "0.04391", "0", "2"], ["84078.5", "0.02792374", "0", "1"], ["84078.4", "0.04283411", "0", "1"], ["84077.5", "0.00001501", "0", "1"], ["84076.4", "0.05023", "0", "1"], ["84075.6", "0.48552695", "0", "2"], ["84075.5", "0.21153238", "0", "2"], ["84075.4", "0.76305756", "0", "8"], ["84074.5", "0", "0", "0"], ["84073", "0.023795", "0", "1"], ["84072.3", "0", "0", "0"], ["84071.9", "0.04", "0", "1"], ["84071.6", "0.0495", "0", "1"], ["84071.4", "0", "0", "0"], ["84070.7", "0", "0", "0"], ["84070.5", "0.42300477", "0", "1"], ["84070.4", "1", "0", "1"], ["84069.6", "0", "0", "0"], ["84069.1", "0.000015", "0", "1"], ["84067.4", "0.23795091", "0", "1"], ["84066.9", "0.38681504", "0", "1"], ["84066.8", "0", "0", "0"], ["84065.8", "0", "0", "0"], ["84063.7", "0.53463448", "0", "2"], ["84063", "0.1890854", "0", "4"], ["84062.8", "0", "0", "0"], ["84062.7", "0.07439969", "0", "1"], ["84061.3", "0", "0", "0"], ["84061.1", "0", "0", "0"], ["84060.6", "0", "0", "0"], ["84059.9", "0.01", "0", "2"], ["84055.7", "0.00001197", "0", "1"], ["84054.8", "0.11890769", "0", "1"], ["84052.7", "0.53169", "0", "1"], ["84052.6", "0", "0", "0"], ["84052.5", "0.13805754", "0", "3"], ["84050.3", "0", "0", "0"], ["84047.7", "0.00357", "0", "1"], ["84047.6", "0.02348985", "0", "1"], ["84039.2", "0", "0", "0"], ["84037.7", "0", "0", "0"], ["84036.9", "0.01785844", "0", "1"], ["84030.9", "0.00001198", "0", "1"], ["84021.3", "0", "0", "0"], ["84018.7", "0.000015", "0", "1"], ["84009.1", "0", "0", "0"], ["84008.1", "0.30135857", "0", "3"], ["83999.6", "0", "0", "0"], ["83995.9", "0.0014493", "0", "1"], ["83989.8", "0", "0", "0"], ["83981.2", "0.02378537", "0", "1"], ["83962.7", "0", "0", "0"], ["83951.4", "0.00595674", "0", "2"], ["83941.5", "0.00025214", "0", "4"], ["83934.6", "0.01783974", "0", "3"], ["83933.8", "0", "0", "0"], ["83933.7", "0", "0", "0"], ["83933.4", "0", "0", "0"], ["83933.3", "0", "0", "0"], ["83932.9", "0", "0", "0"], ["83932.7", "0", "0", "0"], ["83932.6", "0", "0", "0"]], "ts": "1742584893306", "checksum": 698757518, "seqId": 49948778668, "prevSeqId": 49948778148}], "record_time": 1742584893.397364, "EXCHANGE": "OKX"}
{"arg": {"channel": "books", "instId": "BTC-USDT"}, "action": "update", "data": [{"asks": [["84086.1", "0.01222054", "0", "3"], ["84086.6", "0", "0", "0"], ["84088.2", "0", "0", "0"], ["84089.2", "0", "0", "0"], ["84091.3", "0.01250042", "0", "1"], ["84092.8", "0.11279573", "0", "2"], ["84093.4", "0", "0", "0"], ["84094.3", "0", "0", "0"], ["84094.4", "0", "0", "0"], ["84094.8", "0", "0", "0"], ["84095.1", "0.00844", "0", "1"], ["84096.6", "0.01575916", "0", "1"], ["84097.3", "0.01189711", "0", "1"], ["84097.5", "0", "0", "0"], ["84097.6", "0", "0", "0"], ["84098.1", "0", "0", "0"], ["84098.2", "0", "0", "0"], ["84100.4", "0", "0", "0"], ["84100.6", "0.04", "0", "1"], ["84100.8", "0", "0", "0"], ["84101", "0.11693971", "0", "1"], ["84102.2", "0.04", "0", "1"], ["84102.5", "0.09", "0", "3"], ["84103.7", "0.03", "0", "1"], ["84104.6", "0.00354153", "0", "1"], ["84105", "0.52774655", "0", "1"], ["84105.7", "0", "0", "0"], ["84106.7", "0", "0", "0"], ["84107.5", "0", "0", "0"], ["84107.8", "0", "0", "0"], ["84108.8", "0", "0", "0"], ["84109.8", "0.16088065", "0", "1"], ["84110", "0", "0", "0"], ["84110.9", "0", "0", "0"], ["84113.1", "0.01188876", "0", "1"], ["84115.3", "0.08701", "0", "1"], ["84116", "0", "0", "0"], ["84116.8", "0", "0", "0"], ["84117", "0.40355", "0", "2"], ["84117.6", "0.0008", "0", "2"], ["84118", "1", "0", "1"], ["84118.4", "0.0004", "0", "1"], ["84123.2", "0", "0", "0"], ["84124", "0.07999999", "0", "2"], ["84124.4", "0.01153774", "0", "1"], ["84124.7", "0.23793491", "0", "1"], ["84124.8", "0.03999999", "0", "1"], ["84129.1", "0.05042556", "0", "2"], ["84133.2", "0.02378325", "0", "1"], ["84134.2", "0", "0", "0"], ["84136.4", "0", "0", "0"], ["84136.5", "0.1335854", "0", "3"], ["84136.9", "0", "0", "0"], ["84138.4", "0", "0", "0"], ["84139.2", "0.0186161", "0", "1"], ["84143.3", "0", "0", "0"], ["84147.5", "0", "0", "0"], ["84148.4", "0.01118398", "0", "1"], ["84151.1", "0.04756997", "0", "1"], ["84155.6", "0", "0", "0"], ["84160.7", "0", "0", "0"], ["84163.4", "0.0015", "0", "1"], ["84165.7", "0", "0", "0"], ["84166", "0.045271", "0", "2"], ["84167.7", "0", "0", "0"], ["84172.1", "0", "0", "0"], ["84174.5", "0", "0", "0"], ["84175.8", "0.00589977", "0", "1"], ["84176.3", "0", "0", "0"], ["84176.4", "0.1", "0", "1"], ["84183", "0.00594893", "0", "2"], ["84185", "0.0025", "0", "1"], ["84188.4", "0", "0", "0"], ["84189.8", "0.08412221", "0", "3"], ["84191.6", "0.07756226", "0", "2"], ["84193.1", "0.00579977", "0", "1"], ["84201.6", "0.3493815", "0", "2"], ["84221.2", "0", "0", "0"], ["84230.3", "0.00079138", "0", "1"], ["84240.2", "0.00001197", "0", "1"], ["84249.6", "0.01182404", "0", "1"], ["84249.9", "0.00063636", "0", "2"], ["84259", "0.00011161", "0", "1"], ["84259.2", "0.00001197", "0", "1"], ["84259.9", "0.00018194", "0", "1"], ["84260", "0.0002038", "0", "3"], ["84260.2", "0.00168601", "0", "1"], ["84260.6", "0.0000142", "0", "1"], ["84260.8", "0.00001852", "0", "1"], ["84262.1", "3.72", "0", "1"], ["84262.2", "0.11890769", "0", "1"], ["84262.3", "0.35564723", "0", "1"], ["84262.4", "0.17900935", "0", "2"], ["84263.1", "0.000015", "0", "1"], ["84263.8", "0.2025", "0", "1"]], "bids": [["84086", "1.25640332", "0", "18"], ["84083.2", "0.04283411", "0", "1"], ["84081.5", "0.0077292", "0", "1"], ["84081.2", "0.06867112", "0", "3"], ["84078.5", "0.0150735", "0", "1"], ["84078.4", "0", "0", "0"], ["84075.6", "0.72916499", "0", "3"], ["84075.4", "0.73456951", "0", "6"], ["84074.2", "1", "0", "1"], ["84073.1", "0.23793491", "0", "1"], ["84071", "0.04", "0", "1"], ["84070.6", "0.17840197", "0", "2"], ["84070.5", "0.0516195", "0", "1"], ["84070.4", "0", "0", "0"], ["84068.9", "0.01674", "0", "1"], ["84067.4", "0", "0", "0"], ["84066.9", "0.39871645", "0", "2"], ["84066.1", "0.00475816", "0", "1"], ["84065.6", "0.35678", "0", "1"], ["84064.9", "0.054", "0", "1"], ["84064.8", "0", "0", "0"], ["84063", "0.1723454", "0", "3"], ["84057.3", "0.132543", "0", "1"], ["84056.6", "0", "0", "0"], ["84056.1", "0.04497", "0", "1"], ["84055.8", "0", "0", "0"], ["84055.1", "0.17839", "0", "1"], ["84053.4", "0.12487", "0", "1"], ["84049.5", "0", "0", "0"], ["84041.8", "0", "0", "0"], ["84039.3", "0.08925", "0", "1"], ["84031.7", "0.01832157", "0", "1"], ["84027.4", "0", "0", "0"], ["84025.9", "0", "0", "0"], ["84023.4", "0.00218339", "0", "1"], ["84022.4", "0.067482", "0", "1"], ["84021", "0.01741102", "0", "4"], ["84013.5", "0", "0", "0"], ["84009.7", "0.00579968", "0", "1"], ["84000.1", "0.00144924", "0", "1"], ["83995.9", "0", "0", "0"], ["83969.8", "0.0054", "0", "1"], ["83960.1", "0.18339194", "0", "2"], ["83955", "0", "0", "0"], ["83942", "0.00007352", "0", "1"], ["83935.4", "0", "0", "0"], ["83934.8", "0", "0", "0"], ["83934.7", "0", "0", "0"], ["83934.6", "0", "0", "0"], ["83934.5", "0", "0", "0"], ["83934.4", "0", "0", "0"]], "ts": "1742584893406", "checksum": -800732661, "seqId": 49948778861, "prevSeqId": 49948778668}], "record_time": 1742584893.491945, "EXCHANGE": "OKX"}
{"arg": {"channel": "books", "instId": "BTC-USDT"}, "action": "update", "data": [{"asks": [["84089.7", "0", "0", "0"], ["84091.3", "0", "0", "0"], ["84091.4", "0.04165306", "0", "1"], ["84091.9", "0.00262029", "0", "1"], ["84096.4", "0.132543", "0", "1"], ["84096.6", "0", "0", "0"], ["84100.3", "0.00006197", "0", "2"], ["84100.6", "0", "0", "0"], ["84100.7", "0.03568865", "0", "1"], ["84100.8", "0.11896215", "0", "1"], ["84101", "0.16246022", "0", "2"], ["84101.1", "0.00844", "0", "1"], ["84102", "0.03", "0", "1"], ["84102.1", "0.04", "0", "2"], ["84102.3", "0.04", "0", "1"], ["84104.5", "0", "0", "0"], ["84104.6", "0", "0", "0"], ["84106.3", "0.03764015", "0", "1"], ["84107.4", "0.02533", "0", "1"], ["84108", "0.02930357", "0", "1"], ["84109.5", "0.63568234", "0", "1"], ["84109.6", "1.59453854", "0", "1"], ["84109.8", "0", "0", "0"], ["84112.4", "0.0000225", "0", "1"], ["84113.1", "0", "0", "0"], ["84113.5", "0.0118887", "0", "1"], ["84115.3", "0.17457", "0", "2"], ["84116.2", "0.02629167", "0", "2"], ["84117", "0.2", "0", "1"], ["84117.6", "0", "0", "0"], ["84117.9", "0", "0", "0"], ["84118.4", "0.0008", "0", "2"], ["84119.2", "0.0004", "0", "1"], ["84121.8", "0.11893243", "0", "1"], ["84124", "0", "0", "0"], ["84124.7", "0", "0", "0"], ["84124.8", "0", "0", "0"], ["84125.6", "0.07999999", "0", "2"], ["84126.4", "0.03999999", "0", "1"], ["84128.4", "0.20355", "0", "1"], ["84129", "0.23793447", "0", "1"], ["84129.1", "0.02042556", "0", "1"], ["84130.7", "0.1", "0", "1"], ["84136.8", "0.00002157", "0", "1"], ["84139.1", "2.94490166", "0", "1"], ["84140.4", "0.08255471", "0", "1"], ["84141.9", "0", "0", "0"], ["84162", "0.44889", "0", "2"], ["84166", "0.00036", "0", "1"], ["84208.2", "0", "0", "0"], ["84218.2", "0.00594629", "0", "1"], ["84225", "0.002379", "0", "1"], ["84235", "0.01783887", "0", "3"], ["84260", "0", "0", "0"], ["84260.2", "0", "0", "0"], ["84260.6", "0", "0", "0"], ["84260.8", "0", "0", "0"], ["84262.1", "0", "0", "0"], ["84262.2", "0", "0", "0"], ["84262.3", "0", "0", "0"], ["84262.4", "0", "0", "0"], ["84263.1", "0", "0", "0"], ["84263.8", "0", "0", "0"]], "bids": [["84086", "1.30113337", "0", "20"], ["84085.4", "0.005262", "0", "1"], ["84081.2", "0.10215112", "0", "3"], ["84078.5", "0", "0", "0"], ["84076.4", "0", "0", "0"], ["84075.5", "1.21153238", "0", "3"], ["84074.2", "0", "0", "0"], ["84073.5", "0.1123454", "0", "2"], ["84073.1", "0.23793447", "0", "1"], ["84071.8", "0.27811698", "0", "10"], ["84071.4", "0.14043175", "0", "1"], ["84070.7", "0.11016209", "0", "1"], ["84070.5", "0", "0", "0"], ["84068.4", "0.072", "0", "1"], ["84068.3", "0.06", "0", "1"], ["84067.4", "0.02571214", "0", "1"], ["84066.1", "0", "0", "0"], ["84065.6", "0", "0", "0"], ["84063", "0.1123454", "0", "2"], ["84059.6", "0", "0", "0"], ["84056.7", "0.05817704", "0", "1"], ["84056.1", "0", "0", "0"], ["84055.1", "0", "0", "0"], ["84054", "0.59184", "0", "1"], ["84052.5", "0.1650754", "0", "3"], ["84047.7", "0.28068", "0", "2"], ["84046.4", "0", "0", "0"], ["84043.2", "0.11", "0", "3"], ["84042.4", "0.05", "0", "1"], ["84041.5", "0.74522928", "0", "3"], ["84037.4", "0", "0", "0"], ["84037.3", "0", "0", "0"], ["84037.2", "0", "0", "0"], ["84036.2", "0.0177916", "0", "1"], ["84033.5", "0.01", "0", "1"], ["84030.3", "0", "0", "0"], ["84028.8", "0", "0", "0"], ["84028", "0", "0", "0"], ["84021.4", "0.03", "0", "1"], ["84016.3", "0.03878958", "0", "1"], ["84014", "0.83843", "0", "1"], ["84011.8", "0", "0", "0"], ["84011.3", "0", "0", "0"], ["84010.1", "0", "0", "0"], ["83998.7", "0", "0", "0"], ["83992.7", "0.00018395", "0", "1"], ["83991.9", "0", "0", "0"], ["83983.5", "0", "0", "0"], ["83941.2", "0", "0", "0"], ["83935.4", "0.00001471", "0", "1"], ["83934.8", "0.00002382", "0", "1"], ["83934.7", "0.00122355", "0", "1"], ["83934.6", "0.01783974", "0", "3"], ["83934.5", "0.01784253", "0", "1"], ["83934.4", "0.00003782", "0", "1"], ["83933.8", "0.00011948", "0", "1"], ["83933.7", "0.00013585", "0", "4"]], "ts": "1742584893506", "checksum": -1416688958, "seqId": 49948779010, "prevSeqId": 49948778861}], "record_time": 1742584893.591742, "EXCHANGE": "OKX"}
{"arg": {"channel": "books", "instId": "BTC-USDT"}, "action": "update", "data": [{"asks": [["84092.8", "0.00056597", "0", "1"], ["84095.5", "0", "0", "0"], ["84096.3", "0.0397629", "0", "1"], ["84096.4", "0", "0", "0"], ["84097.2", "0.0166244", "0", "1"], ["84100.7", "0", "0", "0"], ["84100.8", "0", "0", "0"], ["84101", "0.11693971", "0", "1"], ["84101.3", "0.04283411", "0", "1"], ["84102.2", "0", "0", "0"], ["84102.3", "0", "0", "0"], ["84102.5", "0", "0", "0"], ["84104.3", "0.04", "0", "1"], ["84105.2", "0.04001197", "0", "2"], ["84107.1", "0.06", "0", "2"], ["84112.1", "0", "0", "0"], ["84113.5", "0", "0", "0"], ["84116", "0.05944201", "0", "1"], ["84117", "0", "0", "0"], ["84117.6", "0.01188812", "0", "1"], ["84118", "0", "0", "0"], ["84118.4", "0", "0", "0"], ["84119.2", "0", "0", "0"], ["84120.2", "0", "0", "0"], ["84121.6", "0.0008", "0", "2"], ["84122.4", "0.0004", "0", "1"], ["84125.6", "0", "0", "0"], ["84126.3", "0", "0", "0"], ["84126.4", "0", "0", "0"], ["84128", "0.07999999", "0", "2"], ["84128.8", "0.03999999", "0", "1"], ["84135", "0.00225115", "0", "4"], ["84139", "0", "0", "0"], ["84140.3", "0.03", "0", "1"], ["84145.4", "0.838549", "0", "1"], ["84147.4", "0", "0", "0"], ["84157.1", "0.001694", "0", "1"], ["84158.8", "0", "0", "0"], ["84168", "0.00036", "0", "1"], ["84172.3", "0.03804109", "0", "2"], ["84177.9", "0.11890769", "0", "1"], ["84179.1", "1.25733501", "0", "2"], ["84195.1", "0.05732575", "0", "1"], ["84196.1", "0.0642", "0", "3"], ["84203.1", "0", "0", "0"], ["84203.2", "0", "0", "0"], ["84221.3", "0.30456549", "0", "4"], ["84221.4", "0.0426", "0", "3"], ["84238.3", "0.2025", "0", "1"], ["84255.8", "0.00593734", "0", "1"], ["84260", "0.0002038", "0", "3"], ["84260.2", "0.00168601", "0", "1"], ["84260.6", "0.0000142", "0", "1"], ["84260.8", "0.00001852", "0", "1"]], "bids": [["84085.5", "0.00203378", "0", "1"], ["84085.4", "0", "0", "0"], ["84082.2", "0.23616261", "0", "1"], ["84082.1", "0.53463448", "0", "2"], ["84082", "0", "0", "0"], ["84077.3", "0.30000359", "0", "1"], ["84077.2", "1", "0", "1"], ["84075.6", "0.76916499", "0", "4"], ["84075.5", "0.21153238", "0", "2"], ["84071.8", "0.2723881", "0", "5"], ["84071", "0", "0", "0"], ["84070.7", "0.11491999", "0", "2"], ["84070.6", "0.00001197", "0", "1"], ["84067.4", "0", "0", "0"], ["84065.7", "0.06301197", "0", "2"], ["84065.1", "0.06", "0", "1"], ["84064.9", "0.108", "0", "2"], ["84063.2", "0", "0", "0"], ["84059.7", "0", "0", "0"], ["84059.1", "0.063", "0", "1"], ["84057.1", "1.61492172", "0", "1"], ["84044.4", "0", "0", "0"], ["84043.2", "0.01", "0", "1"], ["84042.4", "0.1", "0", "2"], ["84041.6", "0.07380915", "0", "2"], ["84040", "0.20001", "0", "3"], ["84035.4", "0.839646", "0", "1"], ["84024.8", "3.54626", "0", "1"], ["83995.9", "0.01774536", "0", "1"], ["83995.7", "0", "0", "0"], ["83995", "0", "0", "0"], ["83982.5", "0", "0", "0"], ["83945.2", "0.00620814", "0", "1"], ["83933.7", "0", "0", "0"]], "ts": "1742584893606", "checksum": 675913269, "seqId": 49948779172, "prevSeqId": 49948779010}], "record_time": 1742584893.69212, "EXCHANGE": "OKX"}
{"arg": {"channel": "books", "instId": "BTC-USDT"}, "action": "update", "data": [{"asks": [["84096.3", "0", "0", "0"], ["84097.2", "0", "0", "0"], ["84101", "0.06411934", "0", "1"], ["84102", "0", "0", "0"], ["84102.1", "0.142543", "0", "2"], ["84103.7", "0", "0", "0"], ["84106", "0.35678", "0", "1"], ["84106.6", "0.03", "0", "1"], ["84106.7", "0.03", "0", "1"], ["84121.6", "0", "0", "0"], ["84122.4", "0.0008", "0", "2"], ["84123.2", "0.0004", "0", "1"], ["84128", "0", "0", "0"], ["84128.8", "0.07999999", "0", "2"], ["84129.6", "0.03999999", "0", "1"], ["84147.3", "0.05899327", "0", "1"], ["84148.4", "0", "0", "0"], ["84154.9", "0.01119505", "0", "2"], ["84169.9", "0.14260156", "0", "3"], ["84172.4", "0.044908", "0", "1"], ["84206.2", "0.067335", "0", "1"]], "bids": [["84086", "1.31501325", "0", "22"], ["84075.5", "0.2", "0", "1"], ["84073.2", "0.35678", "0", "1"], ["84073.1", "0.41632447", "0", "2"], ["84062.7", "0", "0", "0"], ["84062.6", "0.17850161", "0", "2"], ["84062.5", "0.044966", "0", "1"], ["84060.1", "0.02571214", "0", "1"], ["84040", "0.00001", "0", "1"], ["84037", "0.0183202", "0", "1"], ["84031.7", "0", "0", "0"], ["84004.8", "0.1428488", "0", "2"], ["83965.9", "0.18320208", "0", "1"], ["83960.1", "0.00017621", "0", "1"], ["83934.6", "0", "0", "0"], ["83934.5", "0", "0", "0"], ["83934.4", "0", "0", "0"], ["83933.8", "0", "0", "0"]], "ts": "1742584893706", "checksum": -894310987, "seqId": 49948779215, "prevSeqId": 49948779172}], "record_time": 1742584893.791528, "EXCHANGE": "OKX"}
{"arg": {"channel": "books", "instId": "BTC-USDT"}, "action": "update", "data": [{"asks": [["84090.9", "0", "0", "0"], ["84091.9", "0", "0", "0"], ["84101", "0.09586732", "0", "2"], ["84101.1", "0", "0", "0"], ["84102.1", "0.132543", "0", "1"], ["84103.1", "0.01189651", "0", "1"], ["84104.3", "0", "0", "0"], ["84106", "0", "0", "0"], ["84106.3", "0.15659442", "0", "2"], ["84107.4", "0", "0", "0"], ["84108.1", "0.1439258", "0", "2"], ["84109.5", "0.14848817", "0", "1"], ["84109.6", "0", "0", "0"], ["84109.8", "0.04", "0", "1"], ["84110", "0.03", "0", "1"], ["84112.9", "0.02533", "0", "1"], ["84115.3", "0", "0", "0"], ["84116.2", "0.002498", "0", "1"], ["84122.4", "0", "0", "0"], ["84123.2", "0", "0", "0"], ["84124", "0.0008", "0", "2"], ["84124.8", "0.0004", "0", "1"], ["84127.8", "0.08701", "0", "1"], ["84128.8", "0", "0", "0"], ["84129.6", "0", "0", "0"], ["84130.4", "0.13777165", "0", "3"], ["84130.5", "0.01783857", "0", "1"], ["84131", "0.00001", "0", "1"], ["84131.2", "0.03999999", "0", "1"], ["84139.1", "0", "0", "0"], ["84145.4", "0", "0", "0"], ["84152.9", "1.040974", "0", "2"], ["84172.4", "0", "0", "0"], ["84256", "0.00118464", "0", "1"], ["84262.2", "0.11890769", "0", "1"], ["84262.3", "0.35564723", "0", "1"], ["84262.4", "0.17900935", "0", "2"], ["84263.1", "0.000015", "0", "1"], ["84263.8", "0.2025", "0", "1"], ["84263.9", "0.00003969", "0", "2"]], "bids": [["84086", "1.31856264", "0", "23"], ["84082.2", "0.61418972", "0", "1"], ["84081.2", "1.10215112", "0", "4"], ["84080.8", "0.04", "0", "1"], ["84078.7", "0.01200809", "0", "1"], ["84077.3", "0", "0", "0"], ["84077.2", "0", "0", "0"], ["84073.1", "0.23793447", "0", "1"], ["84072.4", "0.18724233", "0", "1"], ["84071.9", "0", "0", "0"], ["84070.9", "0", "0", "0"], ["84063.1", "0.24974", "0", "1"], ["84062.5", "0", "0", "0"], ["84059.1", "0", "0", "0"], ["84056.7", "0", "0", "0"], ["84055.2", "0", "0", "0"], ["84054.9", "0.00356684", "0", "1"], ["84052.3", "0.00001501", "0", "1"], ["84042.5", "0.839575", "0", "1"], ["84035.4", "0", "0", "0"], ["84008.7", "1.259869", "0", "1"], ["83995.9", "0", "0", "0"], ["83993.8", "0", "0", "0"], ["83969.7", "0.58226341", "0", "1"], ["83947.7", "0", "0", "0"], ["83934.6", "0.01783974", "0", "3"], ["83934.5", "0.01784253", "0", "1"], ["83934.4", "0.00003782", "0", "1"], ["83933.8", "0.00011948", "0", "1"]], "ts": "1742584893806", "checksum": 1009797408, "seqId": 49948779316, "prevSeqId": 49948779215}], "record_time": 1742584893.893604, "EXCHANGE": "OKX"}
{"arg": {"channel": "books", "instId": "BTC-USDT"}, "action": "update", "data": [{"asks": [["84086.1", "0", "0", "0"], ["84090.4", "0", "0", "0"], ["84093.2", "0.002", "0", "1"], ["84095.1", "0", "0", "0"], ["84095.3", "0", "0", "0"], ["84101", "0.01958467", "0", "1"], ["84102.1", "0", "0", "0"], ["84102.2", "0.00844", "0", "1"], ["84103.1", "0", "0", "0"], ["84103.2", "0.002", "0", "1"], ["84104.9", "0", "0", "0"], ["84105", "0.33977514", "0", "1"], ["84105.2", "0.00001197", "0", "1"], ["84105.4", "0", "0", "0"], ["84105.6", "0.01189617", "0", "1"], ["84106", "0.27318", "0", "1"], ["84106.3", "0", "0", "0"], ["84106.4", "0.53613448", "0", "3"], ["84106.8", "0", "0", "0"], ["84107.1", "0", "0", "0"], ["84108", "0", "0", "0"], ["84108.1", "0", "0", "0"], ["84109.2", "0.04", "0", "1"], ["84109.8", "0", "0", "0"], ["84109.9", "0", "0", "0"], ["84111.4", "0.03", "0", "1"], ["84112.1", "0.04", "0", "1"], ["84112.4", "0", "0", "0"], ["84116", "0", "0", "0"], ["84117.2", "1.57439212", "0", "1"], ["84117.6", "0", "0", "0"], ["84117.7", "0.31130041", "0", "2"], ["84119.1", "0.14043175", "0", "1"], ["84122", "0.0118875", "0", "1"], ["84124", "0", "0", "0"], ["84124.8", "0.0008", "0", "2"], ["84125.6", "0.0004", "0", "1"], ["84127", "0", "0", "0"], ["84127.8", "0.17457", "0", "2"], ["84129", "0", "0", "0"], ["84130.4", "0.05777166", "0", "1"], ["84130.7", "0", "0", "0"], ["84130.9", "0", "0", "0"], ["84131.2", "0", "0", "0"], ["84132", "0.07999999", "0", "2"], ["84132.8", "0.04576886", "0", "2"], ["84134.7", "0.23791703", "0", "1"], ["84135.3", "0.471165", "0", "1"], ["84136.9", "0.57389177", "0", "1"], ["84141.6", "0", "0", "0"], ["84146.6", "2.77361992", "0", "1"], ["84147", "0.1123454", "0", "2"], ["84165.9", "0.05944704", "0", "2"], ["84176.5", "0", "0", "0"], ["84180.1", "0.044904", "0", "1"], ["84183.1", "0", "0", "0"], ["84183.2", "0", "0", "0"], ["84183.8", "0.02379963", "0", "2"], ["84184.3", "0", "0", "0"], ["84239.3", "0.00012358", "0", "2"], ["84249.6", "0", "0", "0"], ["84264", "0.00224396", "0", "2"], ["84265.8", "0.03", "0", "1"], ["84266.6", "0.0121482", "0", "12"], ["84266.9", "0.0000201", "0", "1"], ["84267.5", "0.002379", "0", "1"], ["84269.1", "0.00002271", "0", "1"], ["84270", "0.00003103", "0", "1"], ["84270.2", "0.5999", "0", "1"], ["84271.2", "0.17898725", "0", "1"], ["84271.4", "0.00006532", "0", "1"], ["84271.6", "0.35564723", "0", "1"]], "bids": [["84091.3", "1.05711303", "0", "17"], ["84091.2", "0.08991011", "0", "1"], ["84090.4", "0.20104067", "0", "1"], ["84090.3", "0.62623558", "0", "7"], ["84090", "0.0439", "0", "1"], ["84087.4", "0.04283411", "0", "1"], ["84086.8", "0.00772968", "0", "1"], ["84086.3", "0.42866078", "0", "2"], ["84086.1", "0.21153238", "0", "2"], ["84086", "0.33990057", "0", "7"], ["84085.6", "0.05022", "0", "1"], ["84083.2", "0", "0", "0"], ["84082.2", "0.26779437", "0", "1"], ["84081.9", "0.05193112", "0", "2"], ["84081.7", "0.02379234", "0", "1"], ["84081.2", "0.05193112", "0", "2"], ["84080.8", "0", "0", "0"], ["84080.5", "0.00001197", "0", "1"], ["84078.7", "0.09020419", "0", "2"], ["84076", "0.01674", "0", "1"], ["84075.7", "0.24891703", "0", "2"], ["84075.5", "0", "0", "0"], ["84073.1", "0", "0", "0"], ["84073", "0", "0", "0"], ["84071.9", "0.11900283", "0", "1"], ["84071.7", "0.002", "0", "1"], ["84070.7", "0.08281099", "0", "2"], ["84069.7", "0.044963", "0", "1"], ["84068.9", "0", "0", "0"], ["84068", "0", "0", "0"], ["84066.8", "0.14043175", "0", "1"], ["84066", "0", "0", "0"], ["84065.2", "0.17838", "0", "1"], ["84063.5", "0.02380293", "0", "1"], ["84062.6", "0.00011161", "0", "1"], ["84061.7", "0.002", "0", "1"], ["84057.6", "0", "0", "0"], ["84056.2", "0.00357", "0", "1"], ["84045", "0", "0", "0"], ["84041.5", "0.64522928", "0", "2"], ["84039.8", "0", "0", "0"], ["84037.8", "0", "0", "0"], ["84035.9", "0.06898298", "0", "3"], ["84022.4", "0", "0", "0"], ["83969.7", "0", "0", "0"], ["83960.7", "0.62348808", "0", "3"], ["83959.9", "0.58229462", "0", "4"], ["83951.4", "0.00001016", "0", "1"], ["83943.9", "0.01783773", "0", "3"], ["83936.8", "0", "0", "0"], ["83935.6", "0", "0", "0"], ["83935.4", "0", "0", "0"], ["83934.8", "0", "0", "0"], ["83934.7", "0", "0", "0"], ["83934.6", "0", "0", "0"], ["83934.5", "0", "0", "0"], ["83934.4", "0", "0", "0"], ["83933.8", "0", "0", "0"]], "ts": "1742584893906", "checksum": -4617906, "seqId": 49948779611, "prevSeqId": 49948779316}], "record_time": 1742584893.99183, "EXCHANGE": "OKX"}
{"arg": {"channel": "books", "instId": "BTC-USDT"}, "action": "update", "data": [{"asks": [["84097.2", "0.00262029", "0", "1"], ["84097.3", "0", "0", "0"], ["84099.8", "0", "0", "0"], ["84101", "0", "0", "0"], ["84101.3", "0", "0", "0"], ["84103", "0.0606", "0", "1"], ["84103.1", "0.2", "0", "1"], ["84105.1", "0.04283411", "0", "1"], ["84105.6", "0", "0", "0"], ["84105.9", "0.132543", "0", "1"], ["84106.6", "0", "0", "0"], ["84106.7", "0", "0", "0"], ["84106.8", "0.00262029", "0", "1"], ["84108.5", "0.00844", "0", "1"], ["84109.5", "0.09927859", "0", "1"], ["84110", "0", "0", "0"], ["84110.1", "0.2143953", "0", "2"], ["84110.7", "0", "0", "0"], ["84110.8", "0.11894797", "0", "1"], ["84112.1", "0", "0", "0"], ["84113.8", "0.6124716", "0", "2"], ["84114.9", "0.08377702", "0", "4"], ["84115.2", "0.04001197", "0", "2"], ["84116.4", "0.03764015", "0", "1"], ["84117.7", "0.20031401", "0", "1"], ["84118.5", "0", "0", "0"], ["84118.6", "0.02930357", "0", "1"], ["84119.4", "0", "0", "0"], ["84121.6", "0.0018615", "0", "1"], ["84122", "0", "0", "0"], ["84123.8", "0.01188725", "0", "1"], ["84124.4", "0", "0", "0"], ["84124.7", "0.05944201", "0", "1"], ["84124.8", "0", "0", "0"], ["84125.6", "0", "0", "0"], ["84126.9", "0", "0", "0"], ["84127.2", "0.0008", "0", "2"], ["84128", "0.0004", "0", "1"], ["84128.4", "0", "0", "0"], ["84128.6", "0", "0", "0"], ["84129.1", "0", "0", "0"], ["84130.2", "0.14043175", "0", "1"], ["84130.5", "0", "0", "0"], ["84132", "0", "0", "0"], ["84132.8", "0", "0", "0"], ["84133.6", "0.19891588", "0", "3"], ["84134.3", "0.23791129", "0", "1"], ["84134.4", "0.03999999", "0", "1"], ["84134.7", "0", "0", "0"], ["84137.8", "0.53969", "0", "1"], ["84139.2", "0", "0", "0"], ["84139.8", "0.20355", "0", "1"], ["84140.8", "0.02042556", "0", "1"], ["84141.2", "0.03011161", "0", "2"], ["84148.7", "0.01783471", "0", "1"], ["84159.2", "0", "0", "0"], ["84173.1", "0.24492198", "0", "1"], ["84175.5", "0.00589976", "0", "1"], ["84180.4", "0.00601133", "0", "2"], ["84188.5", "0.00589972", "0", "1"], ["84191.6", "0.00589977", "0", "1"], ["84195.7", "0.00589972", "0", "1"], ["84202.8", "0.00592213", "0", "2"], ["84203.8", "0.00579973", "0", "1"], ["84207.1", "0.7358", "0", "1"], ["84207.7", "0", "0", "0"], ["84222", "0.4274294", "0", "3"], ["84230.3", "0", "0", "0"], ["84240", "0.00080322", "0", "2"], ["84256", "0", "0", "0"], ["84262.9", "0.01182404", "0", "1"], ["84271.9", "0.00002221", "0", "1"]], "bids": [["84091.3", "1.13798505", "0", "21"], ["84090.4", "0.1302144", "0", "1"], ["84090.3", "0.39014799", "0", "5"], ["84086.4", "0.07408037", "0", "1"], ["84086.3", "0", "0", "0"], ["84086.1", "0", "0", "0"], ["84086", "0.31191052", "0", "6"], ["84082.3", "0.23791129", "0", "1"], ["84080.5", "0.04001197", "0", "2"], ["84078.7", "0.01190012", "0", "1"], ["84076.4", "0.01190007", "0", "1"], ["84075.7", "0.011", "0", "1"], ["84075.6", "0.72916499", "0", "3"], ["84075.2", "0.123", "0", "2"], ["84073.2", "0", "0", "0"], ["84072.4", "0.24668434", "0", "2"], ["84072", "0.054", "0", "1"], ["84070.7", "0.07805309", "0", "1"], ["84069", "0.53169", "0", "1"], ["84068.6", "1", "0", "1"], ["84067", "0.11890769", "0", "1"], ["84066.9", "0.38681504", "0", "1"], ["84065.2", "0", "0", "0"], ["84065.1", "0", "0", "0"], ["84064.9", "0.054", "0", "1"], ["84052.7", "0.02348985", "0", "1"], ["84047.6", "0", "0", "0"], ["84045.8", "0.10001198", "0", "2"], ["84034.5", "0", "0", "0"], ["84032.1", "0.00218322", "0", "1"], ["84023.4", "0", "0", "0"], ["84014.1", "0.00100238", "0", "1"], ["84011", "3.94794", "0", "1"], ["84008.1", "0.30035582", "0", "2"], ["84008", "0.14269116", "0", "2"], ["84004.9", "0.00144892", "0", "1"], ["84000.1", "0", "0", "0"], ["83992.6", "0", "0", "0"], ["83988.1", "1.5547", "0", "1"], ["83960.7", "0.17866838", "0", "2"], ["83958.3", "0.00010126", "0", "3"], ["83936.5", "0", "0", "0"], ["83936.2", "0", "0", "0"], ["83936.1", "0", "0", "0"]], "ts": "1742584894006", "checksum": -42816523, "seqId": 49948779797, "prevSeqId": 49948779611}], "record_time": 1742584894.091424, "EXCHANGE": "OKX"}
{"arg": {"channel": "books", "instId": "BTC-USDT"}, "action": "update", "data": [{"asks": [["84105", "0.35167137", "0", "2"], ["84110.8", "0", "0", "0"], ["84111.5", "0.03", "0", "1"], ["84111.6", "0.03", "0", "1"], ["84118.5", "0.17457", "0", "2"], ["84125", "0.01154738", "0", "2"], ["84127.2", "0", "0", "0"], ["84128", "0", "0", "0"], ["84128.8", "0.0008", "0", "2"], ["84129.6", "0.0004", "0", "1"], ["84132.2", "0.23791983", "0", "1"], ["84133.6", "0.11891589", "0", "1"], ["84134.3", "0", "0", "0"], ["84134.4", "0", "0", "0"], ["84134.8", "0.76710993", "0", "2"], ["84135", "0.00018137", "0", "2"], ["84135.2", "0.31849999", "0", "4"], ["84136", "0.13999999", "0", "2"], ["84136.8", "0", "0", "0"], ["84144.4", "0.00206971", "0", "2"], ["84147.2", "0.00002157", "0", "1"], ["84154.9", "0.00001196", "0", "1"], ["84163.3", "0.01117419", "0", "1"], ["84240", "0.00001197", "0", "1"], ["84240.8", "0.00079125", "0", "1"], ["84270.2", "0", "0", "0"], ["84271.2", "0", "0", "0"], ["84271.4", "0", "0", "0"], ["84271.6", "0", "0", "0"], ["84271.9", "0", "0", "0"]], "bids": [["84091.3", "1.12119067", "0", "19"], ["84082.9", "0.66176677", "0", "1"], ["84082.8", "1", "0", "1"], ["84082.3", "0", "0", "0"], ["84082.2", "0", "0", "0"], ["84079.9", "0.01153238", "0", "1"], ["84078.7", "0.16972495", "0", "2"], ["84078.6", "0.23791937", "0", "1"], ["84078.5", "0.06", "0", "1"], ["84075.7", "0", "0", "0"], ["84075.1", "0.054", "0", "1"], ["84068.6", "0", "0", "0"], ["84064.9", "0", "0", "0"], ["84064.2", "0.06195588", "0", "1"], ["84060.1", "0", "0", "0"], ["84058.8", "0.68489995", "0", "2"], ["84057.4", "0.01774536", "0", "1"], ["84052", "0.1", "0", "2"], ["84051.2", "0.05", "0", "1"], ["84047.7", "0.30639214", "0", "3"], ["84046.4", "0.01831964", "0", "1"], ["84045.8", "0.00001198", "0", "1"], ["84042.4", "0", "0", "0"], ["84041.6", "0.02380915", "0", "1"], ["84037", "0", "0", "0"], ["84034.5", "0.12486", "0", "1"], ["84033.6", "0.00218316", "0", "1"], ["84032.1", "0", "0", "0"], ["84031.7", "0.21783508", "0", "1"], ["84005.6", "0.00144889", "0", "1"], ["84004.9", "0", "0", "0"], ["84002.5", "0.00018395", "0", "1"], ["83992.7", "0", "0", "0"], ["83991.3", "0.54773985", "0", "2"], ["83974.9", "0.18319649", "0", "1"], ["83965.9", "0", "0", "0"], ["83937.5", "0", "0", "0"], ["83937.2", "0", "0", "0"], ["83937.1", "0", "0", "0"], ["83936.9", "0", "0", "0"], ["83936.6", "0", "0", "0"]], "ts": "1742584894106", "checksum": -968990513, "seqId": 49948779955, "prevSeqId": 49948779797}], "record_time": 1742584894.193473, "EXCHANGE": "OKX"}
{"arg": {"channel": "books", "instId": "BTC-USDT"}, "action": "update", "data": [{"asks": [["84104.9", "0.11895625", "0", "1"], ["84108.5", "0", "0", "0"], ["84114.9", "0.11377702", "0", "5"], ["84135", "0.00001197", "0", "1"], ["84141.2", "0.00011161", "0", "1"], ["84141.3", "0", "0", "0"], ["84141.9", "0.00285", "0", "1"], ["84144.3", "0.0001694", "0", "1"], ["84146.1", "0.00576753", "0", "1"], ["84150.3", "0.00285", "0", "1"], ["84216.1", "0.01511839", "0", "1"], ["84266.9", "0", "0", "0"], ["84267.5", "0", "0", "0"], ["84269.1", "0", "0", "0"], ["84270", "0", "0", "0"]], "bids": [["84091.3", "1.12127617", "0", "20"], ["84090.4", "0.12012605", "0", "2"], ["84086.4", "0.11349499", "0", "2"], ["84082.8", "0", "0", "0"], ["84081.1", "1", "0", "1"], ["84078.7", "0.26478531", "0", "3"], ["84078.2", "0.53513", "0", "2"], ["84068.4", "0", "0", "0"], ["84067.7", "0.17838", "0", "1"], ["84065.7", "0.00001197", "0", "1"], ["84046.8", "0.1", "0", "1"], ["84046.4", "0", "0", "0"], ["84044.4", "0.01831974", "0", "1"], ["83974.9", "0", "0", "0"], ["83974.2", "0.18319747", "0", "1"], ["83938", "0", "0", "0"], ["83937.9", "0", "0", "0"]], "ts": "1742584894206", "checksum": -1917811491, "seqId": 49948779994, "prevSeqId": 49948779955}], "record_time": 1742584894.291016, "EXCHANGE": "OKX"}
{"arg": {"channel": "books", "instId": "BTC-USDT"}, "action": "update", "data": [{"asks": [["84091.4", "0.04170631", "0", "2"], ["84102.2", "0", "0", "0"], ["84103", "0.09228074", "0", "2"], ["84106", "0", "0", "0"], ["84107.6", "0.00844", "0", "1"], ["84121.6", "0", "0", "0"], ["84127.8", "0.08756", "0", "1"], ["84130.8", "0.05690874", "0", "1"], ["84132.2", "0", "0", "0"], ["84134.7", "0.23791367", "0", "1"], ["84136.9", "0", "0", "0"], ["84140.4", "0", "0", "0"], ["84162.2", "0.58725197", "0", "1"], ["84164.6", "0", "0", "0"], ["84238.5", "0", "0", "0"], ["84266.9", "0.0000201", "0", "1"], ["84267.5", "0.002379", "0", "1"], ["84269.1", "0.00002271", "0", "1"], ["84270", "0.00003103", "0", "1"]], "bids": [["84086.4", "0.12347818", "0", "1"], ["84086", "0.31432099", "0", "7"], ["84083.9", "0.36678788", "0", "1"], ["84082.9", "0", "0", "0"], ["84081.3", "0.01674", "0", "1"], ["84081.1", "0", "0", "0"], ["84080.6", "0.23791367", "0", "1"], ["84078.6", "0", "0", "0"], ["84076", "0", "0", "0"], ["84068.8", "1", "0", "1"], ["84068.3", "0", "0", "0"], ["84058.9", "0.01774536", "0", "1"], ["84057.4", "0", "0", "0"], ["84053.6", "0.1", "0", "2"], ["84052.8", "0.05", "0", "1"], ["84052", "0", "0", "0"], ["84051.2", "0", "0", "0"], ["84002.5", "0", "0", "0"], ["83938", "0.00005329", "0", "1"], ["83937.9", "0.17899743", "0", "2"]], "ts": "1742584894306", "checksum": 607955819, "seqId": 49948780056, "prevSeqId": 49948779994}], "record_time": 1742584894.391444, "EXCHANGE": "OKX"}
{"arg": {"channel": "books", "instId": "BTC-USDT"}, "action": "update", "data": [{"asks": [["84091.4", "0", "0", "0"], ["84092.8", "0", "0", "0"], ["84093.2", "0", "0", "0"], ["84097.2", "0", "0", "0"], ["84103", "0", "0", "0"], ["84103.1", "0", "0", "0"], ["84104.9", "0", "0", "0"], ["84105", "0.33977514", "0", "1"], ["84107.3", "0", "0", "0"], ["84108.3", "0.00844", "0", "1"], ["84108.6", "0.01189572", "0", "1"], ["84109.1", "0.11895039", "0", "1"], ["84109.5", "0.19446236", "0", "2"], ["84111", "0.35675", "0", "1"], ["84118.5", "0", "0", "0"], ["84120.5", "0.0044805", "0", "1"], ["84123.7", "0.18724233", "0", "1"], ["84131.1", "0.08707", "0", "1"], ["84134.7", "0", "0", "0"], ["84135.2", "0.2385", "0", "2"], ["84136", "0.17999999", "0", "3"], ["84136.8", "0.03999999", "0", "1"], ["84138.4", "0.23790459", "0", "1"], ["84153.7", "0.4", "0", "1"], ["84270.2", "0.5999", "0", "1"]], "bids": [["84096", "0.41472232", "0", "7"], ["84095.8", "0.35964043", "0", "1"], ["84093.2", "0.1", "0", "1"], ["84093.1", "0.14334", "0", "4"], ["84092.8", "0.85506602", "0", "6"], ["84092.7", "0.37853112", "0", "6"], ["84092", "0.0439", "0", "1"], ["84091.7", "0.11897482", "0", "1"], ["84091.6", "0.58752507", "0", "1"], ["84091.5", "0.35564723", "0", "1"], ["84091.4", "0.2", "0", "1"], ["84091.3", "0.12799062", "0", "6"], ["84090.4", "0", "0", "0"], ["84090.3", "0.25443112", "0", "3"], ["84086.4", "0.4080434", "0", "2"], ["84086.3", "1", "0", "1"], ["84086", "0.14179098", "0", "6"], ["84085.5", "0.00204575", "0", "2"], ["84082.2", "0.23790509", "0", "1"], ["84080.6", "0", "0", "0"], ["84077.3", "0.054", "0", "1"], ["84075.6", "0.73392261", "0", "4"], ["84072", "0", "0", "0"], ["84070.3", "0.00713688", "0", "1"], ["84070.2", "0.17838", "0", "1"], ["84070", "0.01", "0", "2"], ["84068.8", "0", "0", "0"], ["84067.7", "0", "0", "0"], ["84003.3", "0.00018401", "0", "1"], ["83943.6", "0.00002754", "0", "2"], ["83940.4", "0", "0", "0"], ["83940.2", "0", "0", "0"], ["83940", "0", "0", "0"], ["83939.9", "0", "0", "0"], ["83939.8", "0", "0", "0"], ["83939.3", "0", "0", "0"], ["83938.9", "0", "0", "0"], ["83938.5", "0", "0", "0"], ["83938.4", "0", "0", "0"], ["83938.2", "0", "0", "0"], ["83938", "0", "0", "0"], ["83937.9", "0", "0", "0"]], "ts": "1742584894406", "checksum": 979544958, "seqId": 49948780250, "prevSeqId": 49948780056}], "record_time": 1742584894.494508, "EXCHANGE": "OKX"}
{"arg": {"channel": "books", "instId": "BTC-USDT"}, "action": "update", "data": [{"asks": [["84100.3", "0.00001197", "0", "1"], ["84101.5", "0.00056587", "0", "1"], ["84101.9", "0.0027319", "0", "2"], ["84108.3", "0", "0", "0"], ["84108.6", "0", "0", "0"], ["84110.3", "0.00005", "0", "1"], ["84111.6", "0.04189529", "0", "2"], ["84112.9", "0", "0", "0"], ["84117.4", "0.02533", "0", "1"], ["84120.5", "0", "0", "0"], ["84123.8", "0.01224275", "0", "2"], ["84127.3", "0", "0", "0"], ["84127.9", "0.01", "0", "1"], ["84128.8", "0", "0", "0"], ["84129.6", "0", "0", "0"], ["84130.4", "0.05857166", "0", "3"], ["84131.2", "0.0004", "0", "1"], ["84136", "0", "0", "0"], ["84136.8", "0", "0", "0"], ["84137.4", "0.1", "0", "1"], ["84137.6", "0.07999999", "0", "2"], ["84138.4", "0.03999999", "0", "1"], ["84139.7", "0.23790357", "0", "1"], ["84172.3", "0.02378462", "0", "1"], ["84183.1", "0.00118788", "0", "1"], ["84240.8", "0", "0", "0"], ["84242.4", "0.00079122", "0", "1"], ["84257.2", "0.00118684", "0", "1"], ["84270.2", "0", "0", "0"]], "bids": [["84096", "0.61463649", "0", "12"], ["84095.9", "0.24849347", "0", "1"], ["84093.2", "0", "0", "0"], ["84093.1", "0.01674", "0", "1"], ["84092.8", "0.2", "0", "1"], ["84092.7", "0.25305672", "0", "4"], ["84091.7", "0", "0", "0"], ["84091.6", "0.28316654", "0", "1"], ["84091.3", "0.08000667", "0", "4"], ["84091.1", "0.05022", "0", "1"], ["84086.3", "0", "0", "0"], ["84085.9", "0.00001501", "0", "1"], ["84085.6", "0", "0", "0"], ["84085.5", "0.00001197", "0", "1"], ["84084.9", "1", "0", "1"], ["84084.1", "0.23790357", "0", "1"], ["84084", "0.1000727", "0", "2"], ["84082.2", "0", "0", "0"], ["84080.7", "0.17837", "0", "1"], ["84078.2", "0.35675", "0", "1"], ["84074", "0", "0", "0"], ["84073", "0.132543", "0", "1"], ["84070.3", "0", "0", "0"], ["84069", "0.54169", "0", "2"], ["84064.6", "0.00357", "0", "1"], ["84057.3", "0", "0", "0"], ["84048.2", "0.1", "0", "1"], ["84047.7", "0.30282214", "0", "2"], ["84046.8", "0", "0", "0"], ["84043.2", "0", "0", "0"], ["84034.5", "0", "0", "0"], ["84034", "0.00218317", "0", "1"], ["84033.6", "0", "0", "0"], ["84020.2", "0.00100238", "0", "1"], ["84014.1", "0", "0", "0"], ["84008.8", "0.00144898", "0", "1"], ["84005.6", "0", "0", "0"], ["83940.4", "0.00002279", "0", "1"], ["83940.2", "0.01194665", "0", "1"], ["83940", "0.00001141", "0", "1"]], "ts": "1742584894506", "checksum": 239631692, "seqId": 49948780380, "prevSeqId": 49948780250}], "record_time": 1742584894.591787, "EXCHANGE": "OKX"}
{"arg": {"channel": "books", "instId": "BTC-USDT"}, "action": "update", "data": [{"asks": [["84096.1", "0", "0", "0"], ["84100.3", "0", "0", "0"], ["84101.9", "0.00011161", "0", "1"], ["84105", "0", "0", "0"], ["84105.1", "0", "0", "0"], ["84105.2", "0", "0", "0"], ["84105.9", "0", "0", "0"], ["84106.4", "0.0015", "0", "1"], ["84107.6", "0", "0", "0"], ["84109.1", "0", "0", "0"], ["84109.4", "0.04283411", "0", "1"], ["84109.5", "0.17335653", "0", "2"], ["84110.1", "0.0118953", "0", "1"], ["84110.9", "0.17898725", "0", "1"], ["84111.4", "0", "0", "0"], ["84111.6", "0.03", "0", "1"], ["84111.9", "0.00844", "0", "1"], ["84113.8", "0.26712351", "0", "3"], ["84115.2", "0.00001197", "0", "1"], ["84116.7", "0", "0", "0"], ["84116.9", "0.2025", "0", "1"], ["84117.2", "0", "0", "0"], ["84117.7", "0.14052926", "0", "1"], ["84119.1", "0", "0", "0"], ["84121.8", "0", "0", "0"], ["84123.1", "0.27244217", "0", "1"], ["84123.8", "0.01188725", "0", "1"], ["84125", "0.000015", "0", "1"], ["84127.9", "0.4415016", "0", "2"], ["84128", "1", "0", "1"], ["84130.4", "0.26043514", "0", "2"], ["84130.8", "0", "0", "0"], ["84131.2", "0", "0", "0"], ["84132.8", "0.0008", "0", "2"], ["84133.2", "0", "0", "0"], ["84133.4", "0.00124963", "0", "2"], ["84133.5", "0.01188588", "0", "1"], ["84133.6", "0.11931589", "0", "2"], ["84136.3", "0.11891188", "0", "1"], ["84137.4", "0", "0", "0"], ["84137.6", "0", "0", "0"], ["84138.4", "0", "0", "0"], ["84139.2", "0.07999999", "0", "2"], ["84139.7", "0.23216739", "0", "1"], ["84140", "0.04005195", "0", "3"], ["84140.2", "0.23789991", "0", "1"], ["84140.7", "0.1", "0", "1"], ["84146.6", "0", "0", "0"], ["84152.9", "0.2025", "0", "1"], ["84157.3", "0.02377645", "0", "1"], ["84163.3", "0", "0", "0"], ["84165.7", "0.01117254", "0", "1"], ["84167.8", "0", "0", "0"], ["84179.1", "0.00001501", "0", "1"], ["84180.1", "0", "0", "0"], ["84183.2", "0.01652", "0", "1"], ["84191.2", "0.01425326", "0", "1"], ["84193.7", "0.21465544", "0", "2"], ["84206.2", "0", "0", "0"], ["84207", "0.24783006", "0", "1"], ["84212.4", "0.22159507", "0", "1"], ["84218.2", "0", "0", "0"], ["84230.2", "0.00594531", "0", "1"], ["84235", "0", "0", "0"], ["84242.4", "0", "0", "0"], ["84245.4", "0.00079122", "0", "1"], ["84247", "0.01783593", "0", "3"], ["84270.2", "0.5999", "0", "1"], ["84271.2", "0.17898725", "0", "1"], ["84271.4", "0.00006532", "0", "1"], ["84271.6", "0.35564723", "0", "1"], ["84271.9", "0.00002221", "0", "1"], ["84272.7", "0.00006691", "0", "2"], ["84273.2", "0.03", "0", "1"]], "bids": [["84099.8", "0.92001621", "0", "14"], ["84099.6", "0.07358517", "0", "1"], ["84099.5", "0.20138391", "0", "1"], ["84098", "0.0439", "0", "1"], ["84096.2", "0.29096207", "0", "1"], ["84096", "0.1327148", "0", "5"], ["84095.9", "0", "0", "0"], ["84095.2", "0.00772812", "0", "1"], ["84094.8", "0.04283411", "0", "1"], ["84093.1", "0", "0", "0"], ["84092.8", "0.2011191", "0", "2"], ["84092.7", "0.25193112", "0", "3"], ["84091.7", "0.17898725", "0", "1"], ["84091.4", "0.20005325", "0", "2"], ["84091.3", "0.07992117", "0", "3"], ["84091.2", "0", "0", "0"], ["84087.9", "0.46812989", "0", "1"], ["84087.4", "0", "0", "0"], ["84086.4", "0", "0", "0"], ["84085.6", "0.01674", "0", "1"], ["84085", "0.23789991", "0", "1"], ["84084.9", "0", "0", "0"], ["84084.1", "0", "0", "0"], ["84084", "0.1562454", "0", "3"], ["84081.5", "0", "0", "0"], ["84081.3", "0", "0", "0"], ["84078.7", "0.16972495", "0", "2"], ["84078.2", "0", "0", "0"], ["84077.4", "0.00713628", "0", "1"], ["84076.5", "0.12486", "0", "1"], ["84070.7", "0.24503635", "0", "2"], ["84070.2", "0", "0", "0"], ["84069.7", "0", "0", "0"], ["84062.8", "0.02571214", "0", "1"], ["84062.1", "0.03590773", "0", "1"], ["84058.8", "0.21401978", "0", "1"], ["84057.1", "0", "0", "0"], ["84056.2", "0", "0", "0"], ["84054.6", "0.41501492", "0", "2"], ["84051.1", "0.0177916", "0", "1"], ["84047.8", "0.17181069", "0", "2"], ["84047.7", "0.27711", "0", "1"], ["84044.4", "0", "0", "0"], ["84042.5", "0", "0", "0"], ["84041.5", "0", "0", "0"], ["84039.8", "0.03034222", "0", "1"], ["84039.5", "0", "0", "0"], ["84037", "0.00218308", "0", "1"], ["84036.2", "0", "0", "0"], ["84036", "0.18868705", "0", "2"], ["84034", "0", "0", "0"], ["84030.8", "0.00357", "0", "1"], ["84024.9", "1.24168275", "0", "1"], ["84022.2", "0", "0", "0"], ["84015.7", "0.28592923", "0", "3"], ["84011.1", "1.56984531", "0", "2"], ["84008.1", "0.42499582", "0", "3"], ["83995.7", "0.07152476", "0", "1"], ["83974.9", "0.18318717", "0", "1"], ["83974.2", "0", "0", "0"], ["83974.1", "0", "0", "0"], ["83974", "0", "0", "0"], ["83969.4", "0.00594531", "0", "1"], ["83965.5", "0", "0", "0"], ["83960.7", "0", "0", "0"], ["83952.6", "0.01783593", "0", "3"], ["83943.9", "0", "0", "0"], ["83943.6", "0.00001557", "0", "1"], ["83939.9", "0.22042779", "0", "3"], ["83939.8", "0.00001033", "0", "1"]], "ts": "1742584894606", "checksum": 241974466, "seqId": 49948780678, "prevSeqId": 49948780380}], "record_time": 1742584894.691896, "EXCHANGE": "OKX"}
{"arg": {"channel": "books", "instId": "BTC-USDT"}, "action": "update", "data": [{"asks": [["84099.9", "0", "0", "0"], ["84101.5", "0", "0", "0"], ["84101.9", "0", "0", "0"], ["84103.2", "0", "0", "0"], ["84106.4", "0", "0", "0"], ["84106.8", "0", "0", "0"], ["84108.2", "0", "0", "0"], ["84109.2", "0", "0", "0"], ["84109.4", "0", "0", "0"], ["84109.5", "0", "0", "0"], ["84110.1", "0.04156728", "0", "2"], ["84110.2", "0.00056579", "0", "1"], ["84111", "0", "0", "0"], ["84113.7", "0.04283411", "0", "1"], ["84113.8", "0.25522853", "0", "2"], ["84114.9", "0.10188851", "0", "4"], ["84115.2", "0", "0", "0"], ["84115.4", "0", "0", "0"], ["84116.4", "0", "0", "0"], ["84117.4", "0", "0", "0"], ["84117.7", "0.09839973", "0", "1"], ["84118.6", "0", "0", "0"], ["84119.1", "0.11893622", "0", "1"], ["84120", "0.03067701", "0", "3"], ["84120.3", "0.01189386", "0", "1"], ["84121.2", "0.04", "0", "1"], ["84122.1", "0.04", "0", "1"], ["84123.1", "0.69681126", "0", "2"], ["84123.8", "0", "0", "0"], ["84123.9", "0.03764015", "0", "1"], ["84124.7", "0", "0", "0"], ["84124.9", "1.60744632", "0", "1"], ["84126.1", "0", "0", "0"], ["84126.9", "0.02930357", "0", "1"], ["84130.4", "0", "0", "0"], ["84130.5", "0.0044595", "0", "1"], ["84131", "0.10818055", "0", "2"], ["84131.1", "0.09895622", "0", "2"], ["84131.5", "0.14043175", "0", "1"], ["84132.3", "0", "0", "0"], ["84132.8", "0", "0", "0"], ["84133.5", "1.01188588", "0", "2"], ["84133.6", "0.11891589", "0", "1"], ["84134.8", "0.42085075", "0", "1"], ["84135.9", "0.05944201", "0", "1"], ["84137.8", "0", "0", "0"], ["84139", "0.01153238", "0", "1"], ["84139.2", "0.0008", "0", "2"], ["84139.7", "0.1493629", "0", "1"], ["84140", "0.01233692", "0", "4"], ["84140.2", "0", "0", "0"], ["84140.3", "0", "0", "0"], ["84140.7", "0", "0", "0"], ["84143.2", "0.20355337", "0", "1"], ["84143.4", "0", "0", "0"], ["84144.5", "0.1", "0", "1"], ["84146.4", "0.07999999", "0", "2"], ["84147.2", "0.03999999", "0", "1"], ["84147.3", "0.24214658", "0", "2"], ["84148.5", "0", "0", "0"], ["84151.1", "0.23787716", "0", "1"], ["84151.2", "0.59015", "0", "1"], ["84151.5", "0.00002157", "0", "1"], ["84151.6", "1.2877912", "0", "3"], ["84153.7", "0.93969", "0", "2"], ["84154.7", "2.93239828", "0", "1"], ["84155.7", "0.07670301", "0", "2"], ["84157.5", "0.1123454", "0", "2"], ["84159.8", "0.37734833", "0", "2"], ["84159.9", "0.0238711", "0", "2"], ["84161.4", "0.2025", "0", "1"], ["84163.9", "0.44544888", "0", "1"], ["84164.2", "0.838361", "0", "1"], ["84167", "0.00037501", "0", "2"], ["84168.9", "0.04755804", "0", "1"], ["84169.8", "0.13282804", "0", "1"], ["84170.3", "0", "0", "0"], ["84171.9", "0.05379", "0", "1"], ["84172.1", "0.00579954", "0", "1"], ["84172.3", "0", "0", "0"], ["84173.5", "0", "0", "0"], ["84175.8", "0", "0", "0"], ["84180.3", "0.00579954", "0", "1"], ["84180.5", "0", "0", "0"], ["84183", "0.00004916", "0", "1"], ["84185.9", "0", "0", "0"], ["84186.1", "0", "0", "0"], ["84186.5", "0.01879738", "0", "1"], ["84187.2", "0.01169901", "0", "2"], ["84189.2", "0", "0", "0"], ["84189.5", "0", "0", "0"], ["84189.8", "0.05351306", "0", "1"], ["84191.5", "0", "0", "0"], ["84191.6", "0", "0", "0"], ["84193.1", "0", "0", "0"], ["84193.6", "0.00579954", "0", "1"], ["84195", "0.00589947", "0", "1"], ["84196.3", "0.35564723", "0", "1"], ["84197.6", "0", "0", "0"], ["84198.1", "1.26898265", "0", "2"], ["84198.8", "1.21278503", "0", "2"], ["84199.5", "3.59602", "0", "1"], ["84200", "0.37537317", "0", "49"], ["84201.6", "0.35528097", "0", "3"], ["84201.8", "0", "0", "0"], ["84204.9", "0.35564723", "0", "1"], ["84206.2", "0.02719954", "0", "2"], ["84206.4", "0.0214", "0", "1"], ["84208.6", "0.00589947", "0", "1"], ["84211", "0.01159902", "0", "2"], ["84214.5", "0.0583374", "0", "2"], ["84216.1", "0", "0", "0"], ["84221.2", "0.28607464", "0", "1"], ["84228.2", "0.07165719", "0", "1"], ["84230.2", "0", "0", "0"], ["84231.5", "0.0142", "0", "1"], ["84231.7", "0.0284", "0", "2"], ["84232", "0.214039", "0", "1"], ["84232.1", "0.01511839", "0", "1"], ["84233.1", "0.124853", "0", "2"], ["84245.4", "0", "0", "0"], ["84248.3", "0", "0", "0"], ["84248.7", "0.00079117", "0", "1"], ["84262.9", "0", "0", "0"], ["84268.1", "0.01182404", "0", "1"], ["84272.3", "0.2025", "0", "1"], ["84273.3", "0.00009539", "0", "1"], ["84274.1", "0.00001197", "0", "1"], ["84275", "0.00028628", "0", "2"], ["84275.1", "0.00001034", "0", "1"]], "bids": [["84110", "1.14669413", "0", "18"], ["84109.6", "0.01189427", "0", "1"], ["84106.9", "0.08429874", "0", "1"], ["84106.3", "0.05193112", "0", "2"], ["84106", "0.0439", "0", "1"], ["84104.1", "0.02634", "0", "1"], ["84104", "0.0439", "0", "1"], ["84102.4", "0.01153238", "0", "1"], ["84102.1", "0.02799005", "0", "1"], ["84102", "0.0439", "0", "1"], ["84100.1", "0.24305333", "0", "1"], ["84100", "0.04391", "0", "2"], ["84099.8", "0.42671014", "0", "7"], ["84099.6", "0", "0", "0"], ["84098.8", "0.04283411", "0", "1"], ["84096.8", "0.23787374", "0", "1"], ["84096.7", "0.05021", "0", "1"], ["84096.2", "0.45638145", "0", "2"], ["84096", "0.09583112", "0", "3"], ["84095.8", "0", "0", "0"], ["84094.9", "1.04", "0", "2"], ["84094.8", "0", "0", "0"], ["84094.5", "0.0561727", "0", "1"], ["84094.3", "0.000015", "0", "1"], ["84092.8", "0.2", "0", "1"], ["84092.7", "0.05193112", "0", "2"], ["84092.1", "0.33021255", "0", "1"], ["84091.6", "0", "0", "0"], ["84091.4", "0.00005325", "0", "1"], ["84091.3", "0.05193112", "0", "2"], ["84091.1", "0.02378964", "0", "1"], ["84087.9", "0.31586238", "0", "2"], ["84087.6", "0.00713542", "0", "1"], ["84087.2", "0.072", "0", "1"], ["84087", "0.06", "0", "1"], ["84086.8", "0", "0", "0"], ["84086.6", "0.01189862", "0", "1"], ["84086", "0.05789098", "0", "4"], ["84085.7", "0.17835", "0", "1"], ["84085", "0", "0", "0"], ["84084.8", "0.53169", "0", "1"], ["84084", "0.1123454", "0", "2"], ["84083.9", "0.27347818", "0", "2"], ["84083.3", "0.00060645", "0", "1"], ["84082.3", "0.00011161", "0", "1"], ["84081.7", "0.054", "0", "1"], ["84080.7", "0", "0", "0"], ["84080.5", "0.00001197", "0", "1"], ["84080", "0.00001", "0", "1"], ["84079.9", "0", "0", "0"], ["84078", "0.02571214", "0", "1"], ["84077.4", "0", "0", "0"], ["84076.4", "0", "0", "0"], ["84075.7", "0.13665305", "0", "2"], ["84075.6", "0.72916499", "0", "3"], ["84075.2", "0.12657", "0", "3"], ["84075.1", "0", "0", "0"], ["84072.5", "0.59184", "0", "1"], ["84071.9", "0", "0", "0"], ["84071.7", "0.05473", "0", "2"], ["84071.2", "0.02348985", "0", "1"], ["84070.9", "0.59231567", "0", "1"], ["84070.7", "0.64276747", "0", "1"], ["84069", "0.01", "0", "1"], ["84068.2", "1.61868975", "0", "1"], ["84066.5", "0.01188487", "0", "1"], ["84062.8", "0", "0", "0"], ["84058.9", "0", "0", "0"], ["84057.7", "0.01153301", "0", "1"], ["84056.8", "0.0178542", "0", "1"], ["84054.9", "0", "0", "0"], ["84054.6", "0.46643737", "0", "2"], ["84054", "0", "0", "0"], ["84053.5", "0.0057665", "0", "1"], ["84053.2", "0.839468", "0", "1"], ["84052.7", "0", "0", "0"], ["84052.5", "0.1123454", "0", "2"], ["84051.5", "0.1", "0", "1"], ["84049.3", "0.0057665", "0", "1"], ["84048.2", "0", "0", "0"], ["84044", "0.40249999", "0", "2"], ["84042.2", "0.00218297", "0", "1"], ["84040.2", "0", "0", "0"], ["84039.8", "0.90425707", "0", "2"], ["84038.4", "2.9256921", "0", "1"], ["84037", "0", "0", "0"], ["84036.9", "0", "0", "0"], ["84036", "0.18814357", "0", "1"], ["84031.8", "0", "0", "0"], ["84031.5", "0.00103791", "0", "1"], ["84030.8", "0", "0", "0"], ["84030.5", "0.17998931", "0", "2"], ["84029.3", "0.19653402", "0", "2"], ["84029.2", "0", "0", "0"], ["84028.5", "0.01903114", "0", "2"], ["84028.3", "0.01189074", "0", "1"], ["84020.2", "0", "0", "0"], ["84017.6", "0.00144873", "0", "1"], ["84010.1", "0.03571042", "0", "1"], ["84008.8", "0", "0", "0"], ["84008.2", "0.00018401", "0", "1"], ["84007.5", "0", "0", "0"], ["84007.2", "0", "0", "0"], ["84006.9", "0", "0", "0"], ["84003.3", "0", "0", "0"], ["84001.6", "0.02379445", "0", "2"], ["83999.1", "0.05732575", "0", "1"], ["83991.3", "0.23318134", "0", "2"], ["83987.4", "0", "0", "0"], ["83984.4", "0", "0", "0"], ["83981.2", "0", "0", "0"], ["83980.1", "0.00001", "0", "1"], ["83979.6", "0.11913366", "0", "1"], ["83977.9", "0", "0", "0"], ["83977", "0.58226341", "0", "1"], ["83976.1", "0.05356052", "0", "1"], ["83970.3", "0.00706785", "0", "2"], ["83967.4", "0.00013882", "0", "1"], ["83959.9", "0.00003121", "0", "3"], ["83955.9", "0", "0", "0"], ["83951.6", "0", "0", "0"], ["83951.3", "0", "0", "0"], ["83942.8", "0", "0", "0"], ["83942.4", "0", "0", "0"], ["83942", "0", "0", "0"], ["83941.8", "0", "0", "0"], ["83941.5", "0", "0", "0"], ["83941.3", "0", "0", "0"], ["83941.1", "0", "0", "0"], ["83940.9", "0", "0", "0"], ["83940.4", "0", "0", "0"], ["83940.2", "0", "0", "0"], ["83940", "0", "0", "0"], ["83939.9", "0", "0", "0"], ["83939.8", "0", "0", "0"]], "ts": "1742584894706", "checksum": 1641139044, "seqId": 49948781385, "prevSeqId": 49948780678}], "record_time": 1742584894.792297, "EXCHANGE": "OKX"}
{"arg": {"channel": "books", "instId": "BTC-USDT"}, "action": "update", "data": [{"asks": [["84110.1", "0", "0", "0"], ["84110.2", "0.11216578", "0", "2"], ["84110.3", "0", "0", "0"], ["84110.9", "0", "0", "0"], ["84111.5", "0", "0", "0"], ["84111.6", "0", "0", "0"], ["84111.9", "0", "0", "0"], ["84113.7", "0", "0", "0"], ["84113.8", "0.18425879", "0", "1"], ["84114.8", "0.132539", "0", "1"], ["84114.9", "0.01188851", "0", "1"], ["84116.9", "0", "0", "0"], ["84117.6", "0.00844", "0", "1"], ["84118.6", "0.04283411", "0", "1"], ["84118.9", "0.00056571", "0", "1"], ["84119", "0.11893634", "0", "1"], ["84119.1", "0", "0", "0"], ["84120", "0.00067701", "0", "2"], ["84120.2", "0.009", "0", "1"], ["84120.9", "0", "0", "0"], ["84122.1", "0", "0", "0"], ["84124", "0.04844", "0", "2"], ["84124.4", "0.00005", "0", "1"], ["84125.6", "0.03", "0", "1"], ["84125.7", "0.03", "0", "1"], ["84126.1", "0.24967", "0", "1"], ["84127.8", "0", "0", "0"], ["84128", "0", "0", "0"], ["84130.5", "0", "0", "0"], ["84131", "0.10817055", "0", "1"], ["84131.1", "0.08707", "0", "1"], ["84132.2", "0.01188606", "0", "1"], ["84133.5", "0.01188588", "0", "1"], ["84134.4", "0.71575175", "0", "2"], ["84134.8", "0", "0", "0"], ["84138.3", "0.08763", "0", "1"], ["84139.2", "0", "0", "0"], ["84139.7", "0", "0", "0"], ["84139.8", "0", "0", "0"], ["84140", "0.01193692", "0", "3"], ["84140.8", "0", "0", "0"], ["84141.3", "0.05467568", "0", "1"], ["84141.6", "0.0008", "0", "2"], ["84141.7", "0.05814941", "0", "1"], ["84142.4", "0.0004", "0", "1"], ["84144.3", "0", "0", "0"], ["84144.4", "0", "0", "0"], ["84144.5", "0", "0", "0"], ["84146.4", "0", "0", "0"], ["84147.2", "0.24967", "0", "1"], ["84147.3", "0.3572717", "0", "1"], ["84148.7", "0.25570901", "0", "2"], ["84148.8", "0.19890768", "0", "3"], ["84149.5", "0.20355", "0", "1"], ["84149.6", "0.03999999", "0", "1"], ["84151.1", "0", "0", "0"], ["84151.5", "0", "0", "0"], ["84151.8", "0.02042556", "0", "1"], ["84153.1", "0.00206948", "0", "2"], ["84154.7", "3.03239828", "0", "2"], ["84155.4", "0.0001694", "0", "1"], ["84155.6", "0.00002157", "0", "1"], ["84155.7", "0.0822095", "0", "1"], ["84157.1", "0", "0", "0"], ["84159.8", "0.25974803", "0", "2"], ["84162", "0.00054", "0", "1"], ["84165.7", "0", "0", "0"], ["84170.3", "0.01117114", "0", "1"], ["84171.7", "0.001694", "0", "1"], ["84181.7", "0.21735885", "0", "2"], ["84183.2", "0.46487", "0", "2"], ["84191.8", "0.044898", "0", "1"], ["84211.3", "0.0842014", "0", "1"], ["84225.9", "0.068819", "0", "2"], ["84232.3", "0", "0", "0"], ["84248.7", "0", "0", "0"], ["84258.9", "0.00080133", "0", "2"], ["84275.2", "0.00001058", "0", "1"]], "bids": [["84110.1", "1.22859735", "0", "11"], ["84110", "0.198849", "0", "3"], ["84106.9", "0", "0", "0"], ["84106.4", "0.02874934", "0", "1"], ["84104.1", "0.04775446", "0", "2"], ["84103.6", "0.04283411", "0", "1"], ["84100.3", "0.4078884", "0", "1"], ["84100.2", "0.35564723", "0", "1"], ["84100.1", "0", "0", "0"], ["84099.8", "0.40998014", "0", "6"], ["84098.8", "0", "0", "0"], ["84096.8", "0", "0", "0"], ["84096.6", "1", "0", "1"], ["84096.2", "0.40815516", "0", "2"], ["84094.9", "0.04", "0", "1"], ["84094.6", "0.2378743", "0", "1"], ["84094.5", "0.1123454", "0", "2"], ["84091.1", "0.04052964", "0", "2"], ["84087.6", "0", "0", "0"], ["84087.3", "0.063", "0", "1"], ["84087.2", "0.132", "0", "2"], ["84085.7", "0", "0", "0"], ["84085.6", "0", "0", "0"], ["84084.1", "0.24967", "0", "1"], ["84083.9", "0.26872103", "0", "1"], ["84083.7", "0.054", "0", "1"], ["84079.7", "0.044957", "0", "1"], ["84078.7", "0.09772495", "0", "1"], ["84077.3", "0", "0", "0"], ["84075.2", "0.06657", "0", "2"], ["84071.8", "0.2363881", "0", "4"], ["84067.5", "0.00356632", "0", "1"], ["84067.4", "0.022", "0", "1"], ["84065.6", "0.27711", "0", "1"], ["84053.7", "0.0183156", "0", "1"], ["84051.5", "0", "0", "0"], ["84051.2", "0.00218271", "0", "1"], ["84047.8", "0.06264534", "0", "1"], ["84047.7", "0", "0", "0"], ["84044", "0.2025", "0", "1"], ["84042.2", "0", "0", "0"], ["84034", "0.00100201", "0", "1"], ["84033.6", "0.03646696", "0", "1"], ["84032", "0.51605912", "0", "4"], ["84031.9", "0.83843", "0", "1"], ["84031.7", "0", "0", "0"], ["84030.5", "0.17898725", "0", "1"], ["84025.8", "0.19528128", "0", "2"], ["84022.2", "0.00144866", "0", "1"], ["84020.9", "0.52009216", "0", "4"], ["84017.6", "0", "0", "0"], ["84016.3", "0", "0", "0"], ["84015.7", "0.03846506", "0", "2"], ["84014.4", "0.01736", "0", "1"], ["84014", "0", "0", "0"], ["84011.1", "1.57002932", "0", "3"], ["84008.2", "0", "0", "0"], ["83999", "0.20305585", "0", "1"], ["83981.4", "0.18316802", "0", "2"], ["83974.9", "0", "0", "0"], ["83964.7", "2.10040704", "0", "3"], ["83961", "0.00122318", "0", "1"], ["83944.4", "0", "0", "0"], ["83944.1", "0", "0", "0"], ["83943.7", "0", "0", "0"], ["83943.6", "0", "0", "0"], ["83943.5", "0", "0", "0"]], "ts": "1742584894806", "checksum": -1848311275, "seqId": 49948781716, "prevSeqId": 49948781385}], "record_time": 1742584894.892047, "EXCHANGE": "OKX"}
{"arg": {"channel": "books", "instId": "BTC-USDT"}, "action": "update", "data": [{"asks": [["84110.2", "0.48012078", "0", "6"], ["84111.2", "0.44462217", "0", "1"], ["84111.3", "1", "0", "1"], ["84112.5", "0.17898725", "0", "1"], ["84113.8", "0.12844655", "0", "1"], ["84114.3", "0.01189493", "0", "1"], ["84114.8", "0", "0", "0"], ["84119", "0", "0", "0"], ["84122.6", "0.03", "0", "1"], ["84122.7", "0.03", "0", "1"], ["84125.6", "0.06", "0", "2"], ["84126", "0.21819367", "0", "1"], ["84127.9", "0.01", "0", "1"], ["84130.9", "0.02533", "0", "1"], ["84131.8", "0.000081", "0", "1"], ["84134.4", "0.47514485", "0", "1"], ["84146.9", "0.23788124", "0", "1"], ["84148.7", "0.01783471", "0", "1"], ["84154.7", "2.93239828", "0", "1"], ["84155.6", "0", "0", "0"], ["84163.8", "0.00002157", "0", "1"], ["84170.3", "0", "0", "0"], ["84174.5", "0.01117114", "0", "1"], ["84254.2", "0.00001197", "0", "1"], ["84264.9", "0.00001197", "0", "1"], ["84271.6", "0", "0", "0"], ["84271.9", "0", "0", "0"], ["84272.3", "0", "0", "0"], ["84272.7", "0", "0", "0"], ["84273.2", "0", "0", "0"], ["84273.3", "0", "0", "0"], ["84274.1", "0", "0", "0"], ["84275", "0", "0", "0"], ["84275.1", "0", "0", "0"], ["84275.2", "0", "0", "0"]], "bids": [["84110.1", "0.49609378", "0", "6"], ["84110", "0.162849", "0", "2"], ["84109.6", "0", "0", "0"], ["84106.4", "0.01317", "0", "1"], ["84106.3", "0", "0", "0"], ["84104.7", "0.01189493", "0", "1"], ["84102.4", "0", "0", "0"], ["84100.3", "0.25949093", "0", "1"], ["84099.5", "0", "0", "0"], ["84098.5", "0.01153238", "0", "1"], ["84096.7", "0", "0", "0"], ["84096.6", "0", "0", "0"], ["84096.2", "0.12702116", "0", "2"], ["84094.6", "0", "0", "0"], ["84092.8", "0.23788668", "0", "1"], ["84088.3", "0.35668", "0", "1"], ["84087.2", "0.186", "0", "3"], ["84081.7", "0", "0", "0"], ["84080.3", "0.38084", "0", "2"], ["84078.5", "0", "0", "0"], ["84078", "0", "0", "0"], ["84074.4", "0.12484", "0", "1"], ["84073", "0", "0", "0"], ["84071.2", "0", "0", "0"], ["84064.7", "0.02571214", "0", "1"], ["84062.1", "0.17448821", "0", "2"], ["84060.8", "0.02348985", "0", "1"], ["84059", "0.471152", "0", "1"], ["84056.9", "0.01831704", "0", "1"], ["84053.7", "0", "0", "0"], ["84042.1", "0.17898725", "0", "1"], ["84034.1", "0.01635174", "0", "1"], ["84030.7", "0", "0", "0"], ["84029.5", "0.00213588", "0", "1"], ["84020.9", "0.3811286", "0", "4"], ["84020.2", "0.000184", "0", "1"], ["84020.1", "0", "0", "0"], ["84011.1", "1.56984531", "0", "2"], ["83991.3", "0.53327236", "0", "1"], ["83987.4", "0.26814788", "0", "1"], ["83983.4", "0.18321792", "0", "2"], ["83981.4", "0.00001197", "0", "1"], ["83944.4", "0.03012711", "0", "4"], ["83944.1", "0.0597095", "0", "2"], ["83943.7", "0.00088289", "0", "6"]], "ts": "1742584894906", "checksum": 100859113, "seqId": 49948781866, "prevSeqId": 49948781716}], "record_time": 1742584894.99136, "EXCHANGE": "OKX"}
{"arg": {"channel": "books", "instId": "BTC-USDT"}, "action": "update", "data": [{"asks": [["84110.2", "0.68012078", "0", "7"], ["84115.5", "0.01450871", "0", "2"], ["84115.8", "0.00844", "0", "1"], ["84124", "0.04", "0", "1"], ["84125.1", "0.00263226", "0", "2"], ["84125.9", "0.31236238", "0", "4"], ["84154.8", "0.1", "0", "1"], ["84159.7", "0.02428514", "0", "1"], ["84162.3", "0.01861174", "0", "1"], ["84270", "0", "0", "0"], ["84270.2", "0", "0", "0"], ["84271.2", "0", "0", "0"], ["84271.4", "0", "0", "0"]], "bids": [["84110.1", "0.49589378", "0", "6"], ["84088.3", "0.53502", "0", "2"], ["84081.7", "0.132539", "0", "1"], ["84075.2", "0.00357", "0", "1"], ["84071.8", "0.23627312", "0", "3"], ["84065.5", "0.1", "0", "1"], ["84020.9", "0.4111286", "0", "5"], ["83944.1", "0", "0", "0"], ["83943.7", "0", "0", "0"]], "ts": "1742584895006", "checksum": 2085763780, "seqId": 49948781885, "prevSeqId": 49948781866}], "record_time": 1742584895.092532, "EXCHANGE": "OKX"}
{"arg": {"channel": "books", "instId": "BTC-USDT"}, "action": "update", "data": [{"asks": [["84114.6", "0.04283411", "0", "1"], ["84118.6", "0", "0", "0"], ["84119.7", "0.132539", "0", "1"], ["84122.1", "0.02533", "0", "1"], ["84129.1", "0.00349619", "0", "1"], ["84130.9", "0", "0", "0"], ["84172.8", "0", "0", "0"], ["84181.2", "0", "0", "0"], ["84189.7", "0.00589976", "0", "1"], ["84198.1", "1.257036", "0", "1"], ["84206.5", "0", "0", "0"], ["84270", "0.00003103", "0", "1"]], "bids": [["84110.1", "0.56679975", "0", "5"], ["84105.1", "0.0077278", "0", "1"], ["84103.6", "0", "0", "0"], ["84102", "0.06063", "0", "2"], ["84100", "0.08674411", "0", "3"], ["84095.7", "0.05021", "0", "1"], ["84060.8", "0", "0", "0"], ["83965.8", "0", "0", "0"], ["83957.2", "0", "0", "0"], ["83948.6", "0.00063143", "0", "3"], ["83944.1", "0.0597095", "0", "2"], ["83943.7", "0.00088289", "0", "6"]], "ts": "1742584895106", "checksum": 1619832194, "seqId": 49948781914, "prevSeqId": 49948781885}], "record_time": 1742584895.193662, "EXCHANGE": "OKX"}
{"arg": {"channel": "books", "instId": "BTC-USDT"}, "action": "update", "data": [{"asks": [["84111.2", "0.300926", "0", "1"]], "bids": [["84092.8", "0", "0", "0"], ["84092.1", "0.48140977", "0", "2"], ["84090.4", "0.23788817", "0", "1"]], "ts": "1742584895206", "checksum": 1451873934, "seqId": 49948781921, "prevSeqId": 49948781914}], "record_time": 1742584895.29162, "EXCHANGE": "OKX"}
{"arg": {"channel": "books", "instId": "BTC-USDT"}, "action": "update", "data": [{"asks": [["84110.1", "3.40764003", "0", "25"], ["84110.2", "0.03831546", "0", "3"], ["84111.2", "0.09874602", "0", "2"], ["84111.3", "0", "0", "0"], ["84112.1", "0.11894616", "0", "1"], ["84114.3", "0", "0", "0"], ["84115.8", "0", "0", "0"], ["84117.5", "0.03721814", "0", "2"], ["84118.9", "0", "0", "0"], ["84122.1", "0", "0", "0"], ["84131.8", "0", "0", "0"], ["84133.8", "0.00356552", "0", "1"], ["84141.3", "0.13689438", "0", "2"], ["84141.6", "0.23869446", "0", "3"], ["84146.9", "0", "0", "0"], ["84148", "0.07999999", "0", "2"], ["84148.8", "0.15890768", "0", "2"], ["84149.6", "0", "0", "0"], ["84159.2", "0.02205931", "0", "1"], ["84270.2", "0.5999", "0", "1"], ["84271.2", "0.17898725", "0", "1"], ["84271.4", "0.00006532", "0", "1"]], "bids": [["84110.1", "0", "0", "0"], ["84110", "0.118949", "0", "1"], ["84109.4", "0.04300001", "0", "1"], ["84108.1", "0.04442605", "0", "2"], ["84108", "0.0439", "0", "1"], ["84106.4", "0", "0", "0"], ["84105.1", "0.07222782", "0", "2"], ["84104.7", "0", "0", "0"], ["84102.1", "0.03988535", "0", "2"], ["84102", "0.0439", "0", "1"], ["84101.4", "0.00056578", "0", "1"], ["84100.3", "0.09063728", "0", "1"], ["84100.2", "0", "0", "0"], ["84099.8", "0.17098214", "0", "3"], ["84098.5", "0", "0", "0"], ["84097.4", "0.01673", "0", "1"], ["84095.7", "0", "0", "0"], ["84095.1", "0.01153238", "0", "1"], ["84091.1", "0.09074964", "0", "3"], ["84090.4", "0", "0", "0"], ["84088.4", "0.23789446", "0", "1"], ["84088.3", "0.17834", "0", "1"], ["84087.6", "0.00713542", "0", "1"], ["84086.9", "0.00475698", "0", "1"], ["84071.6", "0", "0", "0"], ["84068.8", "0.08", "0", "2"], ["84068", "0.04", "0", "1"], ["84067.5", "0", "0", "0"], ["84067.3", "0", "0", "0"], ["84064.7", "0", "0", "0"], ["84042.1", "0.42865725", "0", "2"], ["84032", "0.43605912", "0", "2"], ["84031.2", "0.026", "0", "2"]], "ts": "1742584895306", "checksum": 279423799, "seqId": 49948782064, "prevSeqId": 49948781921}], "record_time": 1742584895.406693, "EXCHANGE": "OKX"}
{"arg": {"channel": "books", "instId": "BTC-USDT"}, "action": "update", "data": [{"asks": [["84110.1", "3.13969749", "0", "23"], ["84110.2", "0.036", "0", "1"], ["84146.4", "0.08", "0", "2"], ["84147.2", "0.28966999", "0", "2"], ["84148", "0", "0", "0"], ["84148.8", "0.11890769", "0", "1"], ["84154.7", "3.03239828", "0", "2"], ["84154.8", "0", "0", "0"], ["84271.6", "0.35564723", "0", "1"]], "bids": [["84110", "0.162849", "0", "2"], ["84104.1", "0.09325603", "0", "1"], ["84101.5", "0.2025", "0", "1"], ["84095.4", "0.00001197", "0", "1"], ["84090.5", "0.00001197", "0", "1"], ["84087.9", "0.49784552", "0", "3"], ["84085.8", "0.35668", "0", "1"], ["84077.8", "0.17834", "0", "1"], ["84069.6", "0.08", "0", "2"], ["84068.8", "0.04", "0", "1"], ["84068", "0", "0", "0"], ["84065.5", "0", "0", "0"], ["84065.4", "0.1", "0", "1"], ["84020", "0", "0", "0"], ["83944.6", "0", "0", "0"], ["83944.4", "0", "0", "0"], ["83944.1", "0", "0", "0"], ["83943.7", "0", "0", "0"]], "ts": "1742584895406", "checksum": 436935863, "seqId": 49948782101, "prevSeqId": 49948782064}], "record_time": 1742584895.491482, "EXCHANGE": "OKX"}
{"arg": {"channel": "books", "instId": "BTC-USDT"}, "action": "update", "data": [{"asks": [["84110.1", "2.97678749", "0", "23"], ["84110.2", "0.04070823", "0", "4"], ["84111.1", "0.009", "0", "1"], ["84120.2", "0", "0", "0"], ["84146.4", "0", "0", "0"], ["84147.2", "0.32966999", "0", "3"], ["84148", "0.03999999", "0", "1"], ["84164.8", "0.01001198", "0", "2"]], "bids": [["84085.7", "0.17834", "0", "1"], ["84069.6", "0", "0", "0"], ["84068.8", "0.08", "0", "2"], ["84068", "0.04", "0", "1"], ["84065.6", "0.37711", "0", "3"], ["84064.8", "0.05", "0", "1"], ["84055.4", "0.01", "0", "1"], ["84053.6", "0", "0", "0"], ["84053", "0.00001", "0", "1"], ["84052.8", "0", "0", "0"], ["84033.5", "0", "0", "0"], ["84031", "0", "0", "0"], ["83993.1", "0.1", "0", "1"], ["83944.8", "0", "0", "0"]], "ts": "1742584895506", "checksum": 1542293385, "seqId": 49948782135, "prevSeqId": 49948782101}], "record_time": 1742584895.591504, "EXCHANGE": "OKX"}
{"arg": {"channel": "books", "instId": "BTC-USDT"}, "action": "update", "data": [{"asks": [["84110.1", "3.07679749", "0", "25"], ["84110.2", "0.04541648", "0", "7"], ["84117.5", "0.02533", "0", "1"], ["84123", "0.01", "0", "1"], ["84143", "0.01188453", "0", "1"], ["84271.4", "0", "0", "0"], ["84271.6", "0", "0", "0"]], "bids": [["84110", "0.118949", "0", "1"], ["84072.2", "0.54651901", "0", "3"], ["84069", "1.01", "0", "2"], ["84029.3", "0.18464366", "0", "1"]], "ts": "1742584895606", "checksum": 520385647, "seqId": 49948782151, "prevSeqId": 49948782135}], "record_time": 1742584895.691647, "EXCHANGE": "OKX"}
{"arg": {"channel": "books", "instId": "BTC-USDT"}, "action": "update", "data": [{"asks": [["84126.3", "0.004935", "0", "1"], ["84141.3", "0.05467568", "0", "1"], ["84141.6", "0.0008", "0", "2"], ["84146.9", "0.23789109", "0", "1"], ["84270.2", "0", "0", "0"], ["84271.2", "0", "0", "0"]], "bids": [["84104.1", "0.03847534", "0", "1"], ["84101.5", "0", "0", "0"], ["84099", "0.004956", "0", "1"], ["84090.4", "0.23789109", "0", "1"], ["84088.4", "0", "0", "0"], ["84087.9", "0.90059962", "0", "2"], ["84087.7", "1.24", "0", "1"], ["83987.4", "0", "0", "0"]], "ts": "1742584895706", "checksum": -1913772551, "seqId": 49948782174, "prevSeqId": 49948782151}], "record_time": 1742584895.791109, "EXCHANGE": "OKX"}
{"arg": {"channel": "books", "instId": "BTC-USDT"}, "action": "update", "data": [{"asks": [["84127", "1", "0", "1"], ["84153", "0.00001", "0", "1"], ["84269.1", "0", "0", "0"], ["84270", "0", "0", "0"]], "bids": [["84109.4", "0", "0", "0"], ["84104.1", "0.09441592", "0", "2"], ["84101.5", "0.2025", "0", "1"], ["84061", "0.28991011", "0", "2"]], "ts": "1742584895806", "checksum": 115537921, "seqId": 49948782185, "prevSeqId": 49948782174}], "record_time": 1742584895.890922, "EXCHANGE": "OKX"}
{"arg": {"channel": "books", "instId": "BTC-USDT"}, "action": "update", "data": [{"asks": [["84126", "0.49344882", "0", "2"]], "bids": [["84100.4", "0.00001197", "0", "1"], ["83945.1", "0", "0", "0"]], "ts": "1742584895906", "checksum": 254791842, "seqId": 49948782192, "prevSeqId": 49948782185}], "record_time": 1742584895.991766, "EXCHANGE": "OKX"}
{"arg": {"channel": "books", "instId": "BTC-USDT"}, "action": "update", "data": [{"asks": [["84143.4", "0.23789333", "0", "1"], ["84146.9", "0", "0", "0"], ["84206.5", "0.00298666", "0", "1"], ["84220.2", "0.00597332", "0", "1"], ["84229.2", "1.63551999", "0", "2"], ["84237.6", "0.01194665", "0", "1"], ["84246.2", "0.01493332", "0", "1"], ["84266.6", "0", "0", "0"], ["84266.9", "0", "0", "0"], ["84267.5", "0", "0", "0"], ["84268.1", "0", "0", "0"]], "bids": [["84090.4", "0", "0", "0"], ["84088.4", "0.23789333", "0", "1"], ["84028.1", "0", "0", "0"], ["84002.3", "0.00298666", "0", "1"], ["83993.9", "0.00597332", "0", "1"], ["83985.5", "0.00895999", "0", "1"], ["83977.1", "0.01194665", "0", "1"], ["83968.6", "0.09862216", "0", "2"], ["83945.4", "0", "0", "0"], ["83945.3", "0", "0", "0"], ["83945.2", "0", "0", "0"]], "ts": "1742584896006", "checksum": 254791842, "seqId": 49948782208, "prevSeqId": 49948782192}], "record_time": 1742584896.091424, "EXCHANGE": "OKX"}
{"arg": {"channel": "books", "instId": "BTC-USDT"}, "action": "update", "data": [{"asks": [["84115.5", "0.00262029", "0", "1"], ["84126", "0.21819367", "0", "1"], ["84126.3", "0", "0", "0"], ["84127", "0", "0", "0"], ["84141.9", "0.01473469", "0", "2"], ["84143.4", "0", "0", "0"], ["84143.6", "0.23789295", "0", "1"], ["84163.8", "0", "0", "0"], ["84165.7", "0.00002157", "0", "1"], ["84266.6", "0.0121482", "0", "12"], ["84266.9", "0.0000201", "0", "1"]], "bids": [["84110", "0.11906398", "0", "2"], ["84071.1", "0.01188469", "0", "1"], ["84034.2", "0.00100217", "0", "1"], ["84034", "0", "0", "0"], ["84023.4", "0.00144873", "0", "1"], ["84022.2", "0.00018415", "0", "1"], ["84020.2", "0", "0", "0"], ["83985.6", "0.18317867", "0", "1"], ["83983.4", "0.00004752", "0", "1"], ["83946.4", "0", "0", "0"], ["83945.9", "0", "0", "0"]], "ts": "1742584896106", "checksum": -953709709, "seqId": 49948782254, "prevSeqId": 49948782208}], "record_time": 1742584896.191574, "EXCHANGE": "OKX"}
{"arg": {"channel": "books", "instId": "BTC-USDT"}, "action": "update", "data": [{"asks": [["84126", "0.22314967", "0", "2"], ["84143.1", "0.23789277", "0", "1"], ["84143.6", "0", "0", "0"], ["84183.1", "0", "0", "0"], ["84191.2", "0", "0", "0"], ["84257.2", "0", "0", "0"], ["84267.5", "0.002379", "0", "1"], ["84268.1", "0.01182404", "0", "1"], ["84269.1", "0.00002271", "0", "1"]], "bids": [["84110", "0.11778179", "0", "2"], ["84104.1", "0.03847534", "0", "1"], ["84101.5", "0", "0", "0"], ["84096.2", "0.06360589", "0", "1"], ["84096", "0.05983112", "0", "2"], ["84088.4", "0.23789286", "0", "1"], ["84069", "0.01", "0", "1"], ["84061", "0.08991011", "0", "1"], ["84034.1", "0", "0", "0"], ["84029.5", "0", "0", "0"], ["83961", "0", "0", "0"], ["83946.4", "0.17898725", "0", "1"], ["83945.9", "0.00010228", "0", "3"], ["83945.4", "0.03", "0", "1"], ["83945.3", "0.03", "0", "1"]], "ts": "1742584896206", "checksum": 1052195474, "seqId": 49948782278, "prevSeqId": 49948782254}], "record_time": 1742584896.291709, "EXCHANGE": "OKX"}
{"arg": {"channel": "books", "instId": "BTC-USDT"}, "action": "update", "data": [{"asks": [], "bids": [["84104.1", "0.09441592", "0", "2"], ["84101.5", "0.2025", "0", "1"], ["83945.3", "0", "0", "0"]], "ts": "1742584896306", "checksum": -1003279803, "seqId": 49948782283, "prevSeqId": 49948782278}], "record_time": 1742584896.391804, "EXCHANGE": "OKX"}
{"arg": {"channel": "books", "instId": "BTC-USDT"}, "action": "update", "data": [{"asks": [["84115.1", "0", "0", "0"], ["84142.3", "0.01188463", "0", "1"], ["84143.1", "0.23789334", "0", "1"], ["84153", "0.00037", "0", "2"]], "bids": [["84088.4", "0.23789334", "0", "1"], ["84071.5", "0.01188463", "0", "1"], ["84028.5", "0.00714043", "0", "1"], ["83945.4", "0", "0", "0"]], "ts": "1742584896406", "checksum": -238090763, "seqId": 49948782304, "prevSeqId": 49948782283}], "record_time": 1742584896.490636, "EXCHANGE": "OKX"}
{"arg": {"channel": "books", "instId": "BTC-USDT"}, "action": "update", "data": [{"asks": [["84110.1", "3.07929549", "0", "26"], ["84114.9", "0", "0", "0"], ["84116.2", "0", "0", "0"], ["84140", "0.01273692", "0", "5"], ["84140.8", "0.0004", "0", "1"], ["84141.6", "0", "0", "0"], ["84142.4", "0", "0", "0"], ["84143", "0.02376906", "0", "2"], ["84154", "0.00036", "0", "1"], ["84192.8", "0.014253", "0", "1"], ["84259.3", "0.00118681", "0", "1"]], "bids": [["84108.1", "0.06180511", "0", "1"], ["84105", "0.06450007", "0", "1"], ["84070.5", "0.01188453", "0", "1"], ["84069.6", "0.0008", "0", "2"], ["84068.8", "0.08039848", "0", "3"], ["84032.8", "0", "0", "0"], ["84032", "0.43566046", "0", "1"], ["84028.3", "0", "0", "0"], ["83956.3", "0.00122324", "0", "1"], ["83946.4", "0", "0", "0"], ["83945.9", "0", "0", "0"]], "ts": "1742584896506", "checksum": 1558005188, "seqId": 49948782333, "prevSeqId": 49948782304}], "record_time": 1742584896.591578, "EXCHANGE": "OKX"}
{"arg": {"channel": "books", "instId": "BTC-USDT"}, "action": "update", "data": [{"asks": [["84185.1", "0.00118785", "0", "1"], ["84269.1", "0", "0", "0"]], "bids": [["84108", "0", "0", "0"], ["84104.1", "0.03847534", "0", "1"], ["84101.5", "0", "0", "0"], ["84099", "0", "0", "0"], ["84095.1", "0", "0", "0"], ["84090.8", "0.01153238", "0", "1"], ["84086", "0.05548051", "0", "3"], ["84064.2", "0", "0", "0"], ["84027.4", "0.00213592", "0", "1"], ["84027", "0.01635311", "0", "1"], ["83946.4", "0.17898725", "0", "1"], ["83945.9", "0.00010228", "0", "3"]], "ts": "1742584896606", "checksum": 1933370983, "seqId": 49948782350, "prevSeqId": 49948782333}], "record_time": 1742584896.691018, "EXCHANGE": "OKX"}
{"arg": {"channel": "books", "instId": "BTC-USDT"}, "action": "update", "data": [{"asks": [["84126", "0.21819367", "0", "1"]], "bids": [["84108", "0.0439", "0", "1"], ["84097.6", "0.003108", "0", "1"], ["84059.9", "0.06940567", "0", "3"], ["83946.4", "0", "0", "0"], ["83945.9", "0", "0", "0"]], "ts": "1742584896706", "checksum": 402346277, "seqId": 49948782355, "prevSeqId": 49948782350}], "record_time": 1742584896.790902, "EXCHANGE": "OKX"}
{"arg": {"channel": "books", "instId": "BTC-USDT"}, "action": "update", "data": [{"asks": [["84125.4", "0.004935", "0", "1"], ["84268.1", "0", "0", "0"]], "bids": [], "ts": "1742584896806", "checksum": 402346277, "seqId": 49948782357, "prevSeqId": 49948782355}], "record_time": 1742584896.890695, "EXCHANGE": "OKX"}
{"arg": {"channel": "books", "instId": "BTC-USDT"}, "action": "update", "data": [{"asks": [["84111.1", "0.05183411", "0", "2"], ["84114.6", "0", "0", "0"], ["84268.1", "0.01182404", "0", "1"]], "bids": [], "ts": "1742584896906", "checksum": 1225592186, "seqId": 49948782359, "prevSeqId": 49948782357}], "record_time": 1742584896.991106, "EXCHANGE": "OKX"}
{"arg": {"channel": "books", "instId": "BTC-USDT"}, "action": "update", "data": [{"asks": [["84111", "0.009", "0", "1"], ["84111.1", "0.04283411", "0", "1"], ["84169.9", "0.07131709", "0", "2"], ["84268.1", "0", "0", "0"]], "bids": [["84090.4", "0.2378915", "0", "1"], ["84088.4", "0", "0", "0"], ["84004.8", "0.0714244", "0", "1"]], "ts": "1742584897006", "checksum": -686755677, "seqId": 49948782369, "prevSeqId": 49948782359}], "record_time": 1742584897.091222, "EXCHANGE": "OKX"}
{"arg": {"channel": "books", "instId": "BTC-USDT"}, "action": "update", "data": [{"asks": [["84127", "1", "0", "1"], ["84169.8", "0.09056556", "0", "1"], ["84169.9", "0.00003262", "0", "1"], ["84267.5", "0", "0", "0"]], "bids": [["84090.4", "0", "0", "0"], ["84088.4", "0.23789381", "0", "1"], ["84034.2", "0", "0", "0"], ["84034", "0.00100227", "0", "1"], ["84022.2", "0", "0", "0"], ["84004.8", "0", "0", "0"], ["83946.4", "0.17898725", "0", "1"], ["83945.9", "0.00010228", "0", "3"]], "ts": "1742584897106", "checksum": -686755677, "seqId": 49948782384, "prevSeqId": 49948782369}], "record_time": 1742584897.190887, "EXCHANGE": "OKX"}
{"arg": {"channel": "books", "instId": "BTC-USDT"}, "action": "update", "data": [{"asks": [["84126", "0.49196832", "0", "2"], ["84143.1", "0", "0", "0"], ["84146.9", "0.23789214", "0", "1"], ["84182.9", "0.1425469", "0", "2"], ["84266.9", "0", "0", "0"]], "bids": [["84100", "0.04391", "0", "2"], ["84096.5", "0.04283411", "0", "1"], ["84090.1", "0.23789214", "0", "1"], ["84088.4", "0", "0", "0"], ["84022.2", "0.00018416", "0", "1"], ["84017.8", "0.14282672", "0", "2"], ["83946.7", "0", "0", "0"], ["83946.4", "0", "0", "0"], ["83945.9", "0", "0", "0"]], "ts": "1742584897206", "checksum": 562752693, "seqId": 49948782410, "prevSeqId": 49948782384}], "record_time": 1742584897.29169, "EXCHANGE": "OKX"}
